[275, ["11281.30000", "11281.40000", "1596614334.352726", "2.32591201", "0.05407292"], "spread", "XBT/USD"]
[275, ["11281.30000", "11281.40000", "1596614335.631846", "4.32591201", "0.05407292"], "spread", "XBT/USD"]
[275, ["11281.30000", "11281.40000", "1596614337.335118", "3.82591201", "0.05407292"], "spread", "XBT/USD"]
[275, ["11281.30000", "11281.40000", "1596614337.422651", "1.82591201", "0.05407292"], "spread", "XBT/USD"]
[275, ["11281.30000", "11281.40000", "1596614337.629156", "1.82133103", "0.05407292"], "spread", "XBT/USD"]
[275, ["11281.30000", "11281.40000", "1596614339.391006", "1.82591201", "0.05407292"], "spread", "XBT/USD"]
[275, ["11281.30000", "11281.40000", "1596614339.661666", "2.32591201", "0.05407292"], "spread", "XBT/USD"]
[275, ["11281.30000", "11281.40000", "1596614340.107424", "4.32591201", "0.05407292"], "spread", "XBT/USD"]
[275, ["11281.30000", "11281.40000", "1596614342.682283", "2.32591201", "0.05407292"], "spread", "XBT/USD"]
[275, ["11281.30000", "11281.40000", "1596614344.598517", "4.32591201", "0.05407292"], "spread", "XBT/USD"]
[275, ["11281.30000", "11281.40000", "1596614348.463712", "4.72591201", "0.05407292"], "spread", "XBT/USD"]
[275, ["11281.30000", "11281.40000", "1596614356.463734", "4.32591201", "0.05407292"], "spread", "XBT/USD"]
[275, ["11281.30000", "11281.40000", "1596614361.717115", "2.32591201", "0.05407292"], "spread", "XBT/USD"]
[271, [["11281.40000", "0.00431010", "1596614362.657364", "b", "l", ""]], "trade", "XBT/USD"]
[275, ["11281.30000", "11281.40000", "1596614362.657364", "2.32591201", "0.04976282"], "spread", "XBT/USD"]
[271, [["11281.40000", "0.02276450", "1596614363.083126", "b", "l", ""]], "trade", "XBT/USD"]
[275, ["11281.30000", "11281.40000", "1596614363.083126", "2.32591201", "0.02699832"], "spread", "XBT/USD"]
[271, [["11281.40000", "0.00250660", "1596614363.618509", "b", "l", ""]], "trade", "XBT/USD"]
[275, ["11281.30000", "11281.40000", "1596614363.618509", "2.32591201", "0.02449172"], "spread", "XBT/USD"]
[271, [["11281.40000", "0.00517640", "1596614364.128717", "b", "l", ""]], "trade", "XBT/USD"]
[275, ["11281.30000", "11281.40000", "1596614364.128717", "2.32591201", "0.01931532"], "spread", "XBT/USD"]
[275, ["11281.30000", "11281.40000", "1596614364.213813", "1.82591201", "0.01931532"], "spread", "XBT/USD"]
[271, [["11281.40000", "0.00505060", "1596614364.596602", "b", "l", ""]], "trade", "XBT/USD"]
[275, ["11281.30000", "11281.40000", "1596614364.596602", "1.82591201", "0.01426472"], "spread", "XBT/USD"]
[275, ["11281.30000", "11281.40000", "1596614364.668561", "1.23812532", "0.01426472"], "spread", "XBT/USD"]
[275, ["11281.30000", "11281.40000", "1596614367.526033", "0.83812532", "0.01426472"], "spread", "XBT/USD"]
[271, [["11281.40000", "0.01426472", "1596614368.689689", "b", "l", ""], ["11281.50000", "0.00354100", "1596614368.695873", "b", "l", ""], ["11281.70000", "0.03119808", "1596614368.697290", "b", "l", ""]], "trade", "XBT/USD"]
[275, ["11281.30000", "11281.70000", "1596614368.697290", "0.83812532", "1.25092092"], "spread", "XBT/USD"]
[275, ["11281.30000", "11281.40000", "1596614368.893634", "0.83812532", "1.76400000"], "spread", "XBT/USD"]
[275, ["11281.30000", "11281.40000", "1596614369.209969", "0.83812532", "1.82272558"], "spread", "XBT/USD"]
[275, ["11281.30000", "11281.40000", "1596614370.561509", "0.83812532", "1.89228622"], "spread", "XBT/USD"]
[275, ["11281.30000", "11281.40000", "1596614370.563304", "0.83812532", "1.97639886"], "spread", "XBT/USD"]
[275, ["11281.30000", "11281.40000", "1596614372.836042", "2.83812532", "1.97639886"], "spread", "XBT/USD"]
[275, ["11281.30000", "11281.40000", "1596614372.954539", "0.83812532", "1.97639886"], "spread", "XBT/USD"]
[271, [["11281.40000", "0.01202080", "1596614375.072801", "b", "l", ""]], "trade", "XBT/USD"]
[275, ["11281.30000", "11281.40000", "1596614375.072801", "0.83812532", "1.96437806"], "spread", "XBT/USD"]
[275, ["11281.30000", "11281.40000", "1596614375.945985", "2.83812532", "1.96437806"], "spread", "XBT/USD"]
[275, ["11281.30000", "11281.40000", "1596614376.479460", "2.83812532", "0.21239886"], "spread", "XBT/USD"]
[275, ["11281.30000", "11281.40000", "1596614377.142037", "0.83812532", "0.21239886"], "spread", "XBT/USD"]
[275, ["11281.30000", "11281.40000", "1596614377.672695", "2.83812532", "0.21239886"], "spread", "XBT/USD"]
[275, ["11281.30000", "11281.40000", "1596614377.874516", "0.83812532", "0.21239886"], "spread", "XBT/USD"]
[275, ["11281.30000", "11281.40000", "1596614378.049733", "0.83812532", "0.67074601"], "spread", "XBT/USD"]
[275, ["11281.30000", "11281.40000", "1596614378.389395", "0.83812532", "2.67074601"], "spread", "XBT/USD"]
[275, ["11281.30000", "11281.40000", "1596614378.799221", "0.83812532", "0.67074601"], "spread", "XBT/USD"]
[275, ["11281.30000", "11281.40000", "1596614380.971767", "0.83812532", "2.43474601"], "spread", "XBT/USD"]
[275, ["11281.30000", "11281.40000", "1596614381.113008", "0.83812532", "2.48554217"], "spread", "XBT/USD"]
[275, ["11281.30000", "11281.40000", "1596614382.802530", "0.83812532", "4.48554217"], "spread", "XBT/USD"]
[271, [["11281.40000", "0.05400000", "1596614383.150433", "b", "l", ""]], "trade", "XBT/USD"]
[275, ["11281.30000", "11281.40000", "1596614383.150434", "0.83812532", "4.43154217"], "spread", "XBT/USD"]
[275, ["11281.30000", "11281.40000", "1596614383.595873", "0.83812532", "2.43154217"], "spread", "XBT/USD"]
[275, ["11281.30000", "11281.40000", "1596614383.875370", "2.83812532", "2.43154217"], "spread", "XBT/USD"]
[275, ["11281.30000", "11281.40000", "1596614384.370416", "0.83812532", "2.43154217"], "spread", "XBT/USD"]
[275, ["11281.30000", "11281.40000", "1596614384.544724", "0.83812532", "0.66754217"], "spread", "XBT/USD"]
[275, ["11281.30000", "11281.40000", "1596614385.231890", "2.83812532", "0.66754217"], "spread", "XBT/USD"]
[271, [["11281.40000", "0.00472558", "1596614385.362202", "b", "m", ""], ["11281.40000", "0.04527442", "1596614385.377075", "b", "m", ""]], "trade", "XBT/USD"]
[275, ["11281.30000", "11281.40000", "1596614385.377075", "2.83812532", "0.61754217"], "spread", "XBT/USD"]
[275, ["11281.30000", "11281.40000", "1596614385.682877", "2.83812532", "0.59325595"], "spread", "XBT/USD"]
[275, ["11281.30000", "11281.40000", "1596614385.683019", "2.83812532", "0.54245979"], "spread", "XBT/USD"]
[275, ["11281.30000", "11281.40000", "1596614385.683279", "2.83812532", "0.45834715"], "spread", "XBT/USD"]
[275, ["11281.30000", "11281.40000", "1596614385.992418", "0.83812532", "0.45834715"], "spread", "XBT/USD"]
[275, ["11281.30000", "11281.40000", "1596614386.958716", "1.29312532", "0.45834715"], "spread", "XBT/USD"]
[275, ["11281.30000", "11281.40000", "1596614387.267153", "3.29312532", "0.45834715"], "spread", "XBT/USD"]
[275, ["11281.30000", "11281.40000", "1596614387.934910", "1.29312532", "0.45834715"], "spread", "XBT/USD"]
[275, ["11281.30000", "11281.40000", "1596614387.991254", "1.29312532", "0.62031417"], "spread", "XBT/USD"]
[275, ["11281.30000", "11281.40000", "1596614389.378704", "3.29312532", "0.62031417"], "spread", "XBT/USD"]
[275, ["11281.30000", "11281.40000", "1596614390.743814", "3.29312532", "0.16196702"], "spread", "XBT/USD"]
[275, ["11281.30000", "11281.40000", "1596614393.419858", "3.79312532", "0.16196702"], "spread", "XBT/USD"]
[275, ["11281.30000", "11281.50000", "1596614393.419858", "3.79312532", "3.78364700"], "spread", "XBT/USD"]
[275, ["11281.30000", "11281.50000", "1596614393.424158", "4.19312532", "3.78364700"], "spread", "XBT/USD"]
[275, ["11281.30000", "11281.50000", "1596614393.472598", "3.69312532", "3.78364700"], "spread", "XBT/USD"]
[275, ["11281.40000", "11281.50000", "1596614393.518418", "0.82500000", "3.78364700"], "spread", "XBT/USD"]
[275, ["11281.40000", "11281.50000", "1596614393.579382", "3.82500000", "3.78364700"], "spread", "XBT/USD"]
[275, ["11281.40000", "11281.50000", "1596614393.586282", "3.82958098", "3.78364700"], "spread", "XBT/USD"]
[275, ["11281.40000", "11281.50000", "1596614393.638005", "0.82958098", "3.78364700"], "spread", "XBT/USD"]
[275, ["11281.40000", "11281.50000", "1596614393.656743", "2.82958098", "3.78364700"], "spread", "XBT/USD"]
[275, ["11281.40000", "11281.50000", "1596614394.502215", "3.32958098", "3.78364700"], "spread", "XBT/USD"]
[275, ["11281.40000", "11281.50000", "1596614395.608657", "3.33158098", "3.78364700"], "spread", "XBT/USD"]
[271, [["11281.50000", "0.00300000", "1596614396.883195", "b", "l", ""]], "trade", "XBT/USD"]
[275, ["11281.40000", "11281.50000", "1596614396.883195", "3.33158098", "3.78064700"], "spread", "XBT/USD"]
[271, [["11281.40000", "0.00927604", "1596614397.842031", "s", "m", ""], ["11281.40000", "0.00002396", "1596614397.850768", "s", "m", ""]], "trade", "XBT/USD"]
[275, ["11281.40000", "11281.50000", "1596614397.850768", "3.32228098", "3.78064700"], "spread", "XBT/USD"]
[275, ["11281.40000", "11281.50000", "1596614398.233850", "1.32228098", "3.78064700"], "spread", "XBT/USD"]
[275, ["11281.40000", "11281.50000", "1596614398.435862", "0.82228098", "3.78064700"], "spread", "XBT/USD"]
[275, ["11281.40000", "11281.50000", "1596614398.919913", "0.82228098", "4.33506792"], "spread", "XBT/USD"]
[275, ["11281.40000", "11281.50000", "1596614398.974734", "0.82228098", "4.47842550"], "spread", "XBT/USD"]
[275, ["11281.40000", "11281.50000", "1596614399.232569", "0.82228098", "6.47842550"], "spread", "XBT/USD"]
[275, ["11281.40000", "11281.50000", "1596614399.354326", "0.82228098", "4.47842550"], "spread", "XBT/USD"]
[275, ["11281.40000", "11281.50000", "1596614402.265724", "0.82228098", "6.47842550"], "spread", "XBT/USD"]
[275, ["11281.40000", "11281.50000", "1596614402.395205", "0.82228098", "4.47842550"], "spread", "XBT/USD"]
[275, ["11281.40000", "11281.50000", "1596614402.813253", "2.82228098", "4.47842550"], "spread", "XBT/USD"]
[275, ["11281.40000", "11281.50000", "1596614403.127272", "0.82228098", "4.47842550"], "spread", "XBT/USD"]
[275, ["11281.40000", "11281.50000", "1596614404.380736", "0.82228098", "6.47842550"], "spread", "XBT/USD"]
[275, ["11281.40000", "11281.50000", "1596614404.868189", "0.82228098", "4.47842550"], "spread", "XBT/USD"]
[275, ["11281.40000", "11281.50000", "1596614405.645283", "1.32228098", "4.47842550"], "spread", "XBT/USD"]
[275, ["11281.40000", "11281.50000", "1596614405.796433", "1.32228098", "4.33506792"], "spread", "XBT/USD"]
[275, ["11281.40000", "11281.50000", "1596614405.835129", "0.82228098", "4.33506792"], "spread", "XBT/USD"]
[275, ["11281.40000", "11281.50000", "1596614406.314727", "2.82228098", "4.33506792"], "spread", "XBT/USD"]
[275, ["11281.40000", "11281.50000", "1596614407.052041", "3.32228098", "4.33506792"], "spread", "XBT/USD"]
[275, ["11281.40000", "11281.50000", "1596614407.429297", "1.32228098", "4.33506792"], "spread", "XBT/USD"]
[275, ["11281.40000", "11281.50000", "1596614407.451289", "0.82228098", "4.33506792"], "spread", "XBT/USD"]
322.60000", "4.90000000", "1596614335.424167"]], "c": "1642879414"}, "book-100", "XBT/USD"]
[270, {"b": [["11248.30000", "0.00000000", "1596614335.482404"], ["11242.10000", "1.60000000", "1596613995.043083", "r"]], "c": "1642879414"}, "book-100", "XBT/USD"]
[270, {"a": [["11305.60000", "0.77031363", "1596614335.486640"]], "c": "1642879414"}, "book-100", "XBT/USD"]
[270, {"b": [["11248.50000", "0.77031363", "1596614335.514915"]], "c": "1642879414"}, "book-100", "XBT/USD"]
[270, {"b": [["11281.30000", "4.32591201", "1596614335.631846"]], "c": "613404594"}, "book-100", "XBT/USD"]
[270, {"b": [["11249.70000", "2.57538832", "1596614335.892944"]], "c": "613404594"}, "book-100", "XBT/USD"]
[270, {"a": [["11317.80000", "0.00000000", "1596614336.055368"], ["11324.20000", "2.55812676", "1596614082.540158", "r"]], "c": "613404594"}, "book-100", "XBT/USD"]
[270, {"b": [["11249.20000", "0.32734536", "1596614336.161681"]], "c": "613404594"}, "book-100", "XBT/USD"]
[270, {"b": [["11278.70000", "0.54836991", "1596614336.228417"]], "c": "3360970366"}, "book-100", "XBT/USD"]
[270, {"b": [["11278.90000", "0.26728132", "1596614336.327819"]], "c": "1625149994"}, "book-100", "XBT/USD"]
[270, {"a": [["11283.20000", "0.00000000", "1596614336.426451"], ["11324.50000", "0.35808343", "1596614329.525171", "r"]], "c": "3239984611"}, "book-100", "XBT/USD"]
[270, {"a": [["11284.20000", "0.26726986", "1596614336.526389"]], "c": "1428586544"}, "book-100", "XBT/USD"]
[270, {"b": [["11277.20000", "0.01359221", "1596614336.696561"]], "c": "1428586544"}, "book-100", "XBT/USD"]
[270, {"b": [["11276.90000", "0.00000000", "1596614337.114974"], ["11242.40000", "17.61000000", "1596614214.288907", "r"]], "c": "1428586544"}, "book-100", "XBT/USD"]
[270, {"b": [["11278.30000", "1.57500000", "1596614337.166591"]], "c": "1428586544"}, "book-100", "XBT/USD"]
[270, {"a": [["11289.90000", "0.00000000", "1596614337.183725"], ["11324.50000", "0.35808343", "1596614329.525171", "r"]], "c": "1428586544"}, "book-100", "XBT/USD"]
[270, {"b": [["11281.30000", "3.82591201", "1596614337.335118"]], "c": "1991199882"}, "book-100", "XBT/USD"]
[270, {"a": [["11317.90000", "0.28000000", "1596614337.361390"]], "c": "1991199882"}, "book-100", "XBT/USD"]
[270, {"b": [["11281.30000", "1.82591201", "1596614337.422651"]], "c": "2881905070"}, "book-100", "XBT/USD"]
[270, {"b": [["11275.70000", "0.34571734", "1596614337.503279"]], "c": "2881905070"}, "book-100", "XBT/USD"]
[270, {"b": [["11281.30000", "1.82133103", "1596614337.629156"]], "c": "1960251316"}, "book-100", "XBT/USD"]
[270, {"a": [["11287.80000", "0.00000000", "1596614337.640635"], ["11324.50000", "0.35808343", "1596614329.525171", "r"]], "c": "1960251316"}, "book-100", "XBT/USD"]
[270, {"b": [["11278.70000", "0.09621094", "1596614337.721282"]], "c": "580073157"}, "book-100", "XBT/USD"]
[270, {"a": [["11302.80000", "0.00000000", "1596614337.721483"], ["11324.60000", "0.75800000", "1596613975.970924", "r"]], "c": "580073157"}, "book-100", "XBT/USD"]
[270, {"a": [["11291.10000", "0.00000000", "1596614337.721572"], ["11325.00000", "0.18439000", "1596614047.980595", "r"]], "c": "580073157"}, "book-100", "XBT/USD"]
[270, {"a": [["11322.50000", "2.31199347", "1596614337.839676"]], "c": "580073157"}, "book-100", "XBT/USD"]
[270, {"a": [["11303.40000", "6.44625279", "1596614337.873404"]], "c": "580073157"}, "book-100", "XBT/USD"]
[270, {"a": [["11303.30000", "2.22997602", "1596614337.912631"]], "c": "580073157"}, "book-100", "XBT/USD"]
[270, {"b": [["11276.60000", "0.57666493", "1596614337.913045"]], "c": "580073157"}, "book-100", "XBT/USD"]
[270, {"a": [["11292.10000", "0.50702516", "1596614337.915253"]], "c": "580073157"}, "book-100", "XBT/USD"]
[270, {"b": [["11264.00000", "0.00000000", "1596614337.969152"], ["11242.60000", "1.21153343", "1596614089.433787", "r"]], "c": "580073157"}, "book-100", "XBT/USD"]
[270, {"a": [["11316.00000", "0.01000000", "1596614338.005642"]], "c": "580073157"}, "book-100", "XBT/USD"]
[270, {"b": [["11262.60000", "0.00443938", "1596614338.317244"]], "c": "580073157"}, "book-100", "XBT/USD"]
[270, {"b": [["11278.90000", "0.00000000", "1596614338.400451"], ["11242.60000", "1.21153343", "1596614089.433787", "r"]], "c": "547128936"}, "book-100", "XBT/USD"]
[270, {"b": [["11278.80000", "1.38248453", "1596614338.500950"]], "c": "2344503490"}, "book-100", "XBT/USD"]
[270, {"a": [["11284.20000", "0.00000000", "1596614338.600490"], ["11324.50000", "0.35808343", "1596614329.525171", "r"]], "c": "528938257"}, "book-100", "XBT/USD"]
[270, {"a": [["11283.20000", "0.26728523", "1596614338.699611"]], "c": "2330915525"}, "book-100", "XBT/USD"]
[270, {"a": [["11292.30000", "0.00000000", "1596614338.849155"], ["11324.50000", "0.35808343", "1596614329.525171", "r"]], "c": "2330915525"}, "book-100", "XBT/USD"]
[270, {"b": [["11276.60000", "0.00000000", "1596614339.116035"], ["11242.40000", "17.61000000", "1596614214.288907", "r"]], "c": "2330915525"}, "book-100", "XBT/USD"]
[270, {"b": [["11264.50000", "0.50000000", "1596614339.136296"]], "c": "2330915525"}, "book-100", "XBT/USD"]
[270, {"b": [["11281.30000", "1.82591201", "1596614339.391006"]], "c": "1442815199"}, "book-100", "XBT/USD"]
[270, {"b": [["11279.10000", "0.00000000", "1596614339.654672"], ["11242.40000", "17.61000000", "1596614214.288907", "r"]], "c": "252156673"}, "book-100", "XBT/USD"]
[270, {"b": [["11281.30000", "2.32591201", "1596614339.661666"]], "c": "2534360104"}, "book-100", "XBT/USD"]
[270, {"b": [["11278.40000", "0.46846470", "1596614339.727843"]], "c": "510899097"}, "book-100", "XBT/USD"]
[270, {"b": [["11278.80000", "2.88248453", "1596614339.810702"]], "c": "1835376283"}, "book-100", "XBT/USD"]
[270, {"b": [["11281.30000", "4.32591201", "1596614340.107424"]], "c": "3247941930"}, "book-100", "XBT/USD"]
[270, {"a": [["11289.20000", "2.00000000", "1596614340.394766"]], "c": "3247941930"}, "book-100", "XBT/USD"]
[270, {"a": [["11283.20000", "0.00000000", "1596614340.790152"], ["11324.50000", "0.35808343", "1596614329.525171", "r"]], "c": "383451106"}, "book-100", "XBT/USD"]
[270, {"a": [["11283.20000", "0.26728009", "1596614340.875981"]], "c": "3588903330"}, "book-100", "XBT/USD"]
[270, {"b": [["11257.50000", "0.55438414", "1596614340.983395"]], "c": "3588903330"}, "book-100", "XBT/USD"]
[270, {"a": [["11292.10000", "0.00000000", "1596614341.567968"], ["11324.50000", "0.35808343", "1596614329.525171", "r"]], "c": "3588903330"}, "book-100", "XBT/USD"]
[270, {"a": [["11291.10000", "0.51905678", "1596614341.763210"]], "c": "3588903330"}, "book-100", "XBT/USD"]
[270, {"b": [["11278.80000", "2.61519939", "1596614341.763519"]], "c": "2334591535"}, "book-100", "XBT/USD"]
[270, {"b": [["11278.70000", "0.36349796", "1596614341.864919"]], "c": "3946222691"}, "book-100", "XBT/USD"]
[270, {"b": [["11278.30000", "0.22500000", "1596614341.908209"]], "c": "4190649285"}, "book-100", "XBT/USD"]
[270, {"a": [["11305.50000", "0.77031207", "1596614342.150143"]], "c": "4190649285"}, "book-100", "XBT/USD"]
[270, {"a": [["11305.60000", "0.00000000", "1596614342.158242"], ["11324.20000", "2.55812676", "1596614082.540158", "r"]], "c": "4190649285"}, "book-100", "XBT/USD"]
[270, {"b": [["11278.70000", "0.45970890", "1596614342.302482"]], "c": "3983687827"}, "book-100", "XBT/USD"]
[270, {"a": [["11295.50000", "0.00000000", "1596614342.309510"], ["11324.50000", "0.35808343", "1596614329.525171", "r"]], "c": "3983687827"}, "book-100", "XBT/USD"]
[270, {"a": [["11295.50000", "0.01801864", "1596614342.310501"]], "c": "3983687827"}, "book-100", "XBT/USD"]
[270, {"a": [["11294.80000", "2.00000000", "1596614342.402580"]], "c": "3983687827"}, "book-100", "XBT/USD"]
[270, {"a": [["11287.00000", "0.88871000", "1596614342.451706"]], "c": "3983687827"}, "book-100", "XBT/USD"]
[270, {"a": [["11287.00000", "0.98492094", "1596614342.541303"]], "c": "3983687827"}, "book-100", "XBT/USD"]
[270, {"a": [["11284.30000", "0.00000000", "1596614342.552651"], ["11324.20000", "2.55812676", "1596614082.540158", "r"]], "c": "3330632251"}, "book-100", "XBT/USD"]
[270, {"a": [["11286.40000", "0.66499039", "1596614342.608766"]], "c": "3224198894"}, "book-100", "XBT/USD"]
[270, {"b": [["11281.30000", "2.32591201", "1596614342.682283"]], "c": "1826580831"}, "book-100", "XBT/USD"]
[270, {"a": [["11286.40000", "0.00000000", "1596614342.707879"], ["11324.20000", "2.55812676", "1596614082.540158", "r"]], "c": "1786207626"}, "book-100", "XBT/USD"]
[270, {"b": [["11278.70000", "0.36349796", "1596614342.741323"]], "c": "2127374044"}, "book-100", "XBT/USD"]
[270, {"a": [["11283.20000", "0.00000000", "1596614342.949677"], ["11324.50000", "0.35808343", "1596614329.525171", "r"]], "c": "2202355869"}, "book-100", "XBT/USD"]
[270, {"a": [["11284.60000", "0.26727460", "1596614343.051374"]], "c": "2266064649"}, "book-100", "XBT/USD"]
[270, {"a": [["11297.70000", "0.00000000", "1596614343.323745"], ["11324.50000", "0.35808343", "1596614329.525171", "r"]], "c": "2266064649"}, "book-100", "XBT/USD"]
[270, {"b": [["11277.70000", "0.00000000", "1596614343.373065"], ["11242.40000", "17.61000000", "1596614214.288907", "r"]], "c": "2266064649"}, "book-100", "XBT/USD"]
[270, {"a": [["11289.20000", "0.00000000", "1596614343.539263"], ["11324.60000", "0.75800000", "1596613975.970924", "r"]], "c": "2266064649"}, "book-100", "XBT/USD"]
[270, {"a": [["11298.30000", "0.00533242", "1596614343.563594"]], "c": "2266064649"}, "book-100", "XBT/USD"]
[270, {"b": [["11262.60000", "0.00000000", "1596614343.933582"], ["11242.10000", "1.60000000", "1596613995.043083", "r"]], "c": "2266064649"}, "book-100", "XBT/USD"]
[270, {"b": [["11278.70000", "0.09621094", "1596614343.938265"]], "c": "821613399"}, "book-100", "XBT/USD"]
[270, {"b": [["11278.80000", "2.81519939", "1596614344.002492"]], "c": "1640388283"}, "book-100", "XBT/USD"]
[270, {"b": [["11278.90000", "0.26726782", "1596614344.047021"]], "c": "3118902660"}, "book-100", "XBT/USD"]
[270, {"b": [["11273.10000", "0.00000000", "1596614344.090808"], ["11242.10000", "1.60000000", "1596613995.043083", "r"]], "c": "3118902660"}, "book-100", "XBT/USD"]
[270, {"b": [["11261.60000", "0.00455307", "1596614344.117402"]], "c": "3118902660"}, "book-100", "XBT/USD"]
[270, {"b": [["11261.60000", "0.00000000", "1596614344.305457"], ["11242.10000", "1.60000000", "1596613995.043083", "r"]], "c": "3118902660"}, "book-100", "XBT/USD"]
[270, {"a": [["11284.70000", "5.08899903", "1596614344.353909"]], "c": "29747412"}, "book-100", "XBT/USD"]
[270, {"b": [["11262.60000", "0.00453130", "1596614344.503175"]], "c": "29747412"}, "book-100", "XBT/USD"]
[270, {"a": [["11285.50000", "0.20873236", "1596614344.529706"]], "c": "800283928"}, "book-100", "XBT/USD"]
[270, {"a": [["11284.70000", "4.42400000", "1596614344.578419"]], "c": "2244011013"}, "book-100", "XBT/USD"]
[270, {"b": [["11281.30000", "4.32591201", "1596614344.598517"]], "c": "3406697774"}, "book-100", "XBT/USD"]
[270, {"a": [["11287.00000", "1.64987858", "1596614344.711317"]], "c": "3406697774"}, "book-100", "XBT/USD"]
[270, {"a": [["11295.50000", "0.04847623", "1596614344.730143"]], "c": "3406697774"}, "book-100", "XBT/USD"]
[270, {"a": [["11295.50000", "0.03045759", "1596614344.838234"]], "c": "3406697774"}, "book-100", "XBT/USD"]
[270, {"a": [["11303.40000", "6.40000000", "1596614344.929878"]], "c": "3406697774"}, "book-100", "XBT/USD"]
[270, {"a": [["11291.10000", "0.00000000", "1596614345.006576"], ["11324.50000", "0.35808343", "1596614329.525171", "r"]], "c": "3406697774"}, "book-100", "XBT/USD"]
[270, {"a": [["11303.30000", "0.00000000", "1596614345.007528"], ["11324.60000", "0.75800000", "1596613975.970924", "r"]], "c": "3406697774"}, "book-100", "XBT/USD"]
[270, {"b": [["11277.80000", "2.00000000", "1596614345.138558"]], "c": "3406697774"}, "book-100", "XBT/USD"]
[270, {"a": [["11287.80000", "0.04624643", "1596614345.144053"]], "c": "3406697774"}, "book-100", "XBT/USD"]
[270, {"b": [["11278.40000", "0.00000000", "1596614345.346009"], ["11242.40000", "17.61000000", "1596614214.288907", "r"]], "c": "2690705979"}, "book-100", "XBT/USD"]
[270, {"a": [["11285.30000", "0.66499039", "1596614345.358472"]], "c": "1079545816"}, "book-100", "XBT/USD"]
