[275, ["11284.00000", "11284.10000", "1596617350.102791", "1.89723692", "0.20932973"], "spread", "XBT/USD"]
[275, ["11284.00000", "11284.10000", "1596617352.729303", "1.23230439", "0.20932973"], "spread", "XBT/USD"]
[275, ["11284.00000", "11284.10000", "1596617352.762663", "0.83230439", "0.20932973"], "spread", "XBT/USD"]
[275, ["11284.00000", "11284.10000", "1596617352.857945", "2.83230439", "0.20932973"], "spread", "XBT/USD"]
[275, ["11284.00000", "11284.10000", "1596617353.345793", "0.83230439", "0.20932973"], "spread", "XBT/USD"]
[275, ["11284.00000", "11284.10000", "1596617353.968035", "0.83230439", "0.87431975"], "spread", "XBT/USD"]
[275, ["11284.00000", "11284.10000", "1596617354.592088", "0.83230439", "4.13763499"], "spread", "XBT/USD"]
[275, ["11284.00000", "11284.10000", "1596617354.644821", "0.33230439", "4.13763499"], "spread", "XBT/USD"]
[275, ["11284.00000", "11284.10000", "1596617354.660161", "0.32624789", "4.13763499"], "spread", "XBT/USD"]
[275, ["11284.00000", "11284.10000", "1596617355.827492", "2.32624789", "4.13763499"], "spread", "XBT/USD"]
[275, ["11284.00000", "11284.10000", "1596617355.918179", "2.33230439", "4.13763499"], "spread", "XBT/USD"]
[275, ["11284.00000", "11284.10000", "1596617356.354635", "2.33230439", "3.47264497"], "spread", "XBT/USD"]
[275, ["11284.00000", "11284.10000", "1596617357.032257", "2.83230439", "3.47264497"], "spread", "XBT/USD"]
[275, ["11284.00000", "11284.10000", "1596617361.188136", "2.83230439", "3.70264497"], "spread", "XBT/USD"]
[275, ["11284.00000", "11284.10000", "1596617363.738190", "2.83230439", "3.71805557"], "spread", "XBT/USD"]
[275, ["11284.00000", "11284.10000", "1596617365.468019", "0.83230439", "3.71805557"], "spread", "XBT/USD"]
[275, ["11284.00000", "11284.10000", "1596617365.540883", "0.82624789", "3.71805557"], "spread", "XBT/USD"]
[275, ["11284.00000", "11284.10000", "1596617366.286874", "2.82624789", "3.71805557"], "spread", "XBT/USD"]
[275, ["11284.00000", "11284.10000", "1596617366.363531", "2.83230439", "3.71805557"], "spread", "XBT/USD"]
[275, ["11284.00000", "11284.10000", "1596617371.732770", "3.49716976", "3.71805557"], "spread", "XBT/USD"]
[275, ["11284.00000", "11284.10000", "1596617377.116423", "2.83230439", "3.71805557"], "spread", "XBT/USD"]
[275, ["11284.00000", "11284.10000", "1596617377.179211", "0.83230439", "3.71805557"], "spread", "XBT/USD"]
[275, ["11284.00000", "11284.10000", "1596617379.903802", "2.83230439", "3.71805557"], "spread", "XBT/USD"]
[275, ["11284.00000", "11284.10000", "1596617382.075894", "3.49725086", "3.71805557"], "spread", "XBT/USD"]
[275, ["11284.00000", "11284.10000", "1596617382.724367", "3.62825086", "3.71805557"], "spread", "XBT/USD"]
[275, ["11284.00000", "11284.10000", "1596617382.849516", "4.53689086", "3.71805557"], "spread", "XBT/USD"]
[275, ["11284.00000", "11284.10000", "1596617384.551932", "4.53689086", "3.48805557"], "spread", "XBT/USD"]
[275, ["11284.00000", "11284.10000", "1596617387.560352", "4.53689086", "3.49097266"], "spread", "XBT/USD"]
[275, ["11284.00000", "11284.10000", "1596617388.555484", "4.53689086", "3.48805557"], "spread", "XBT/USD"]
[275, ["11284.00000", "11284.10000", "1596617388.802105", "4.53689086", "3.49025365"], "spread", "XBT/USD"]
[275, ["11284.00000", "11284.10000", "1596617389.005000", "3.62825086", "3.49025365"], "spread", "XBT/USD"]
[275, ["11284.00000", "11284.10000", "1596617393.218182", "4.60066086", "3.49025365"], "spread", "XBT/USD"]
[275, ["11284.00000", "11284.10000", "1596617393.344950", "4.60066086", "3.47484305"], "spread", "XBT/USD"]
[275, ["11284.00000", "11284.10000", "1596617393.477694", "5.00066086", "3.47484305"], "spread", "XBT/USD"]
[275, ["11284.00000", "11284.10000", "1596617394.650803", "4.86966086", "3.47484305"], "spread", "XBT/USD"]
[275, ["11284.00000", "11284.10000", "1596617394.661820", "4.86966086", "3.97484305"], "spread", "XBT/USD"]
[275, ["11284.00000", "11284.10000", "1596617394.721208", "2.86966086", "3.97484305"], "spread", "XBT/USD"]
[275, ["11284.00000", "11284.10000", "1596617394.735824", "2.86966086", "5.97484305"], "spread", "XBT/USD"]
[275, ["11284.00000", "11284.10000", "1596617394.778526", "2.36966086", "5.97484305"], "spread", "XBT/USD"]
[275, ["11284.00000", "11284.10000", "1596617394.826426", "2.36966086", "6.21484305"], "spread", "XBT/USD"]
[275, ["11284.00000", "11284.10000", "1596617394.936135", "1.96966086", "6.21484305"], "spread", "XBT/USD"]
[275, ["11284.00000", "11284.10000", "1596617395.006805", "1.96360436", "6.21484305"], "spread", "XBT/USD"]
[275, ["11284.00000", "11284.10000", "1596617395.245702", "1.96360436", "4.21484305"], "spread", "XBT/USD"]
[275, ["11284.00000", "11284.10000", "1596617395.303279", "1.96360436", "3.71484305"], "spread", "XBT/USD"]
[275, ["11284.00000", "11284.10000", "1596617395.305515", "2.46360436", "3.71484305"], "spread", "XBT/USD"]
[275, ["11284.00000", "11284.10000", "1596617395.310033", "1.79865789", "3.71484305"], "spread", "XBT/USD"]
[275, ["11284.00000", "11284.10000", "1596617395.314071", "1.80471439", "3.71484305"], "spread", "XBT/USD"]
[275, ["11284.00000", "11284.10000", "1596617395.437620", "0.83230439", "3.71484305"], "spread", "XBT/USD"]
[275, ["11284.00000", "11284.10000", "1596617396.607566", "0.96330439", "3.71484305"], "spread", "XBT/USD"]
[275, ["11284.00000", "11284.10000", "1596617396.751365", "1.36330439", "3.71484305"], "spread", "XBT/USD"]
[275, ["11284.00000", "11284.10000", "1596617397.059158", "1.36330439", "5.78027557"], "spread", "XBT/USD"]
[275, ["11284.00000", "11284.10000", "1596617397.865976", "3.36330439", "5.78027557"], "spread", "XBT/USD"]
[275, ["11284.00000", "11284.10000", "1596617398.365869", "3.36330439", "2.51696033"], "spread", "XBT/USD"]
[275, ["11284.00000", "11284.10000", "1596617402.590077", "3.36330439", "2.27696033"], "spread", "XBT/USD"]
[275, ["11284.00000", "11284.10000", "1596617404.751408", "2.96330439", "2.27696033"], "spread", "XBT/USD"]
[275, ["11284.00000", "11284.10000", "1596617406.127452", "3.36330439", "2.27696033"], "spread", "XBT/USD"]
[275, ["11284.00000", "11284.10000", "1596617407.347546", "3.36330439", "2.07696033"], "spread", "XBT/USD"]
[275, ["11284.00000", "11284.10000", "1596617407.362261", "3.36330439", "0.01152781"], "spread", "XBT/USD"]
[275, ["11284.00000", "11284.10000", "1596617407.623112", "4.08755439", "0.01152781"], "spread", "XBT/USD"]
[275, ["11284.00000", "11284.10000", "1596617407.727598", "4.08755439", "0.00932973"], "spread", "XBT/USD"]
[275, ["11284.00000", "11284.10000", "1596617407.737198", "4.29755439", "0.00932973"], "spread", "XBT/USD"]
[275, ["11284.00000", "11284.10000", "1596617407.836066", "4.56469753", "0.00932973"], "spread", "XBT/USD"]
[275, ["11284.00000", "11284.10000", "1596617408.363225", "6.91469753", "0.00932973"], "spread", "XBT/USD"]
[275, ["11284.00000", "11284.10000", "1596617409.530971", "7.25907131", "0.00932973"], "spread", "XBT/USD"]
[271, [["11284.10000", "0.00932973", "1596617409.558266", "b", "l", ""], ["11288.20000", "0.00218527", "1596617409.562478", "b", "l", ""]], "trade", "XBT/USD"]
[275, ["11284.00000", "11288.20000", "1596617409.562478", "7.25907131", "4.88705376"], "spread", "XBT/USD"]
[275, ["11284.00000", "11288.20000", "1596617409.623465", "6.75907131", "4.88705376"], "spread", "XBT/USD"]
[275, ["11288.10000", "11288.20000", "1596617409.624159", "0.50000000", "4.88705376"], "spread", "XBT/USD"]
[275, ["11288.10000", "11288.20000", "1596617409.762832", "0.50605650", "4.88705376"], "spread", "XBT/USD"]
[275, ["11288.10000", "11288.20000", "1596617409.800397", "2.50605650", "4.88705376"], "spread", "XBT/USD"]
[275, ["11288.10000", "11288.20000", "1596617410.101730", "2.63705650", "4.88705376"], "spread", "XBT/USD"]
[275, ["11288.10000", "11288.20000", "1596617410.285667", "3.19194615", "4.88705376"], "spread", "XBT/USD"]
[275, ["11288.10000", "11288.20000", "1596617411.231223", "3.64194615", "4.88705376"], "spread", "XBT/USD"]
[275, ["11288.10000", "11288.20000", "1596617416.421037", "3.64194615", "4.88952470"], "spread", "XBT/USD"]
[275, ["11288.10000", "11288.20000", "1596617417.634681", "3.64194615", "0.00247094"], "spread", "XBT/USD"]
[275, ["11288.10000", "11288.20000", "1596617422.632825", "4.04194615", "0.00247094"], "spread", "XBT/USD"]
[275, ["11288.10000", "11289.30000", "1596617422.632825", "4.04194615", "1.82791962"], "spread", "XBT/USD"]
[275, ["11288.10000", "11289.30000", "1596617422.855525", "4.14394615", "1.82791962"], "spread", "XBT/USD"]
[275, ["11289.20000", "11289.30000", "1596617422.894748", "0.50000000", "1.82791962"], "spread", "XBT/USD"]
[275, ["11289.20000", "11289.30000", "1596617422.960604", "2.85000000", "1.82791962"], "spread", "XBT/USD"]
[275, ["11289.20000", "11289.30000", "1596617423.046660", "0.50000000", "1.82791962"], "spread", "XBT/USD"]
[275, ["11289.20000", "11289.30000", "1596617423.051681", "2.50000000", "1.82791962"], "spread", "XBT/USD"]
[275, ["11289.20000", "11290.80000", "1596617423.051681", "2.50000000", "1.16900000"], "spread", "XBT/USD"]
[275, ["11290.70000", "11290.80000", "1596617423.169980", "0.50000000", "1.16900000"], "spread", "XBT/USD"]
[275, ["11290.70000", "11290.80000", "1596617423.218202", "0.50000000", "0.97900000"], "spread", "XBT/USD"]
[275, ["11290.70000", "11290.80000", "1596617423.414526", "0.90000000", "0.97900000"], "spread", "XBT/USD"]
[275, ["11290.70000", "11290.80000", "1596617423.415318", "2.90000000", "0.97900000"], "spread", "XBT/USD"]
[275, ["11290.70000", "11292.80000", "1596617423.415318", "2.90000000", "3.71767533"], "spread", "XBT/USD"]
[275, ["11290.70000", "11292.80000", "1596617423.471780", "3.33179953", "3.71767533"], "spread", "XBT/USD"]
[275, ["11290.70000", "11292.80000", "1596617423.503722", "2.83179953", "3.71767533"], "spread", "XBT/USD"]
[275, ["11292.70000", "11292.80000", "1596617423.504634", "0.50000000", "3.71767533"], "spread", "XBT/USD"]
[275, ["11292.70000", "11292.80000", "1596617423.667525", "2.50000000", "3.71767533"], "spread", "XBT/USD"]
[275, ["11292.70000", "11292.80000", "1596617424.101805", "2.63100000", "3.71767533"], "spread", "XBT/USD"]
[275, ["11292.70000", "11292.80000", "1596617424.184286", "3.08290236", "3.71767533"], "spread", "XBT/USD"]
[275, ["11292.70000", "11292.80000", "1596617424.611349", "3.08895886", "3.71767533"], "spread", "XBT/USD"]
[275, ["11292.70000", "11292.80000", "1596617424.747907", "3.33895886", "3.71767533"], "spread", "XBT/USD"]
[275, ["11292.70000", "11295.20000", "1596617424.747907", "3.33895886", "0.84537318"], "spread", "XBT/USD"]
[275, ["11292.80000", "11295.20000", "1596617424.879718", "0.47693517", "0.84537318"], "spread", "XBT/USD"]
[275, ["11292.80000", "11295.20000", "1596617424.881957", "1.06033517", "0.84537318"], "spread", "XBT/USD"]
[275, ["11295.10000", "11295.20000", "1596617424.888733", "0.50000000", "0.84537318"], "spread", "XBT/USD"]
.30000", "0.00525234", "1596614889.087583", "r"]], "c": "4200288508"}, "book-100", "XBT/USD"]
[270, {"a": [["11290.60000", "0.15000000", "1596617351.679204"]], "c": "4200288508"}, "book-100", "XBT/USD"]
[270, {"b": [["11282.70000", "0.26719199", "1596617351.777014"]], "c": "3441079029"}, "book-100", "XBT/USD"]
[270, {"a": [["11288.30000", "0.00000000", "1596617351.877174"], ["11335.00000", "5.80000000", "1596617011.074269", "r"]], "c": "745018086"}, "book-100", "XBT/USD"]
[270, {"a": [["11287.30000", "1.64392751", "1596617351.882819"]], "c": "206332815"}, "book-100", "XBT/USD"]
[270, {"a": [["11287.80000", "0.26719041", "1596617351.976465"]], "c": "40780494"}, "book-100", "XBT/USD"]
[270, {"a": [["11287.30000", "0.97900000", "1596617352.452088"]], "c": "575288231"}, "book-100", "XBT/USD"]
[270, {"b": [["11256.60000", "0.50000000", "1596617352.634143"]], "c": "575288231"}, "book-100", "XBT/USD"]
[270, {"b": [["11282.70000", "0.00000000", "1596617352.647996"], ["11244.80000", "6.00000000", "1596616713.695896", "r"]], "c": "353096110"}, "book-100", "XBT/USD"]
[270, {"b": [["11282.40000", "0.26720395", "1596617352.669228"]], "c": "751496332"}, "book-100", "XBT/USD"]
[270, {"b": [["11278.50000", "0.30000000", "1596617352.677452"]], "c": "751496332"}, "book-100", "XBT/USD"]
[270, {"a": [["11295.90000", "0.55779880", "1596617352.707039"]], "c": "751496332"}, "book-100", "XBT/USD"]
[270, {"b": [["11271.10000", "0.27100000", "1596617352.707871"]], "c": "751496332"}, "book-100", "XBT/USD"]
[270, {"a": [["11286.30000", "0.00000000", "1596617352.728427"], ["11335.00000", "5.80000000", "1596617011.074269", "r"]], "c": "4128411658"}, "book-100", "XBT/USD"]
[270, {"b": [["11284.00000", "1.23230439", "1596617352.729303"]], "c": "3244923456"}, "book-100", "XBT/USD"]
[270, {"a": [["11294.90000", "0.00600000", "1596617352.754709"]], "c": "3244923456"}, "book-100", "XBT/USD"]
[270, {"b": [["11270.10000", "3.31908957", "1596617352.755678"]], "c": "3244923456"}, "book-100", "XBT/USD"]
[270, {"b": [["11284.00000", "0.83230439", "1596617352.762663"]], "c": "1119725007"}, "book-100", "XBT/USD"]
[270, {"b": [["11284.00000", "2.83230439", "1596617352.857945"]], "c": "2387732370"}, "book-100", "XBT/USD"]
[270, {"b": [["11276.80000", "2.16292451", "1596617352.927613"]], "c": "2387732370"}, "book-100", "XBT/USD"]
[270, {"b": [["11283.40000", "0.49133443", "1596617352.959424"]], "c": "1275821370"}, "book-100", "XBT/USD"]
[270, {"a": [["11296.80000", "0.00000000", "1596617352.960695"], ["11335.00000", "5.80000000", "1596617011.074269", "r"]], "c": "1275821370"}, "book-100", "XBT/USD"]
[270, {"a": [["11309.60000", "0.00000000", "1596617353.003310"], ["11336.20000", "8.33564637", "1596617100.773211", "r"]], "c": "1275821370"}, "book-100", "XBT/USD"]
[270, {"b": [["11282.90000", "0.00000000", "1596617353.068343"], ["11244.80000", "6.00000000", "1596616713.695896", "r"]], "c": "4038507490"}, "book-100", "XBT/USD"]
[270, {"b": [["11284.00000", "0.83230439", "1596617353.345793"]], "c": "277050198"}, "book-100", "XBT/USD"]
[270, {"b": [["11279.70000", "0.00000000", "1596617353.374360"], ["11244.30000", "0.00525234", "1596614889.087583", "r"]], "c": "277050198"}, "book-100", "XBT/USD"]
[270, {"a": [["11288.00000", "0.00000000", "1596617353.379536"], ["11336.40000", "6.52255842", "1596617141.728207", "r"]], "c": "1561358157"}, "book-100", "XBT/USD"]
[270, {"a": [["11303.40000", "5.12046521", "1596617353.404104"]], "c": "1561358157"}, "book-100", "XBT/USD"]
[270, {"b": [["11266.10000", "0.00451949", "1596617353.404509"]], "c": "1561358157"}, "book-100", "XBT/USD"]
[270, {"a": [["11310.80000", "0.37797385", "1596617353.415248"]], "c": "1561358157"}, "book-100", "XBT/USD"]
[270, {"b": [["11282.40000", "0.00000000", "1596617353.444660"], ["11244.30000", "0.00525234", "1596614889.087583", "r"]], "c": "3463063264"}, "book-100", "XBT/USD"]
[270, {"b": [["11281.30000", "0.26721247", "1596617353.464997"]], "c": "649025036"}, "book-100", "XBT/USD"]
[270, {"a": [["11285.20000", "0.00000000", "1596617353.517475"], ["11337.00000", "0.18439000", "1596616205.519680", "r"]], "c": "1146371839"}, "book-100", "XBT/USD"]
[270, {"a": [["11317.30000", "0.00000000", "1596617353.547406"], ["11337.50000", "11.29950000", "1596616920.969883", "r"]], "c": "1146371839"}, "book-100", "XBT/USD"]
[270, {"a": [["11287.60000", "0.94159000", "1596617353.587916"]], "c": "2693373471"}, "book-100", "XBT/USD"]
[270, {"a": [["11303.30000", "0.00565586", "1596617353.592170"]], "c": "2693373471"}, "book-100", "XBT/USD"]
[270, {"b": [["11279.20000", "0.00000000", "1596617353.679993"], ["11244.30000", "0.00525234", "1596614889.087583", "r"]], "c": "2693373471"}, "book-100", "XBT/USD"]
[270, {"b": [["11277.30000", "0.00000000", "1596617353.698653"], ["11242.90000", "0.75800000", "1596616873.974166", "r"]], "c": "2693373471"}, "book-100", "XBT/USD"]
[270, {"a": [["11319.10000", "0.01971858", "1596617353.786121"]], "c": "2693373471"}, "book-100", "XBT/USD"]
[270, {"a": [["11284.10000", "0.87431975", "1596617353.968035"]], "c": "2295536979"}, "book-100", "XBT/USD"]
[270, {"a": [["11284.50000", "0.66499002", "1596617353.968520"]], "c": "1621581073"}, "book-100", "XBT/USD"]
[270, {"b": [["11282.30000", "0.79349002", "1596617353.970715"]], "c": "1226472666"}, "book-100", "XBT/USD"]
[270, {"b": [["11282.60000", "3.20900159", "1596617353.974347"]], "c": "1343576327"}, "book-100", "XBT/USD"]
[270, {"b": [["11270.00000", "0.88665337", "1596617353.983096"]], "c": "1343576327"}, "book-100", "XBT/USD"]
[270, {"a": [["11286.50000", "0.88665337", "1596617353.983197"]], "c": "3584270990"}, "book-100", "XBT/USD"]
[270, {"a": [["11287.80000", "0.00000000", "1596617354.051722"], ["11335.00000", "5.80000000", "1596617011.074269", "r"]], "c": "3286556529"}, "book-100", "XBT/USD"]
[270, {"a": [["11287.20000", "0.26721061", "1596617354.151168"]], "c": "3470271199"}, "book-100", "XBT/USD"]
[270, {"b": [["11267.50000", "2.22292857", "1596617354.588350"]], "c": "3470271199"}, "book-100", "XBT/USD"]
[270, {"a": [["11284.10000", "4.13763499", "1596617354.592088"]], "c": "2112218455"}, "book-100", "XBT/USD"]
[270, {"a": [["11307.50000", "2.27475317", "1596617354.643410"]], "c": "2112218455"}, "book-100", "XBT/USD"]
[270, {"b": [["11284.00000", "0.33230439", "1596617354.644821"]], "c": "2280736973"}, "book-100", "XBT/USD"]
[270, {"b": [["11284.00000", "0.32624789", "1596617354.660161"]], "c": "3744784810"}, "book-100", "XBT/USD"]
[270, {"a": [["11317.60000", "1.25608332", "1596617354.718411"]], "c": "3744784810"}, "book-100", "XBT/USD"]
[270, {"b": [["11273.30000", "0.00000000", "1596617354.774642"], ["11244.30000", "0.00525234", "1596614889.087583", "r"]], "c": "3744784810"}, "book-100", "XBT/USD"]
[270, {"b": [["11273.30000", "0.01876000", "1596617354.775197"]], "c": "3744784810"}, "book-100", "XBT/USD"]
[270, {"a": [["11310.90000", "0.00000000", "1596617355.114354"], ["11334.00000", "1.10447869", "1596616895.153868", "r"]], "c": "3744784810"}, "book-100", "XBT/USD"]
[270, {"a": [["11288.40000", "0.88657671", "1596617355.125155"]], "c": "1262179384"}, "book-100", "XBT/USD"]
[270, {"a": [["11287.10000", "4.42700000", "1596617355.132751"]], "c": "1285112228"}, "book-100", "XBT/USD"]
[270, {"b": [["11283.90000", "0.00000000", "1596617355.251255"], ["11244.30000", "0.00525234", "1596614889.087583", "r"]], "c": "518809001"}, "book-100", "XBT/USD"]
[270, {"a": [["11303.40000", "0.00000000", "1596617355.638258"], ["11334.00000", "1.10447869", "1596616895.153868", "r"]], "c": "518809001"}, "book-100", "XBT/USD"]
[270, {"a": [["11299.10000", "5.12241386", "1596617355.716876"]], "c": "518809001"}, "book-100", "XBT/USD"]
[270, {"b": [["11282.70000", "0.03750000", "1596617355.773537"]], "c": "1142815530"}, "book-100", "XBT/USD"]
[270, {"b": [["11284.00000", "2.32624789", "1596617355.827492"]], "c": "1961568011"}, "book-100", "XBT/USD"]
[270, {"a": [["11303.30000", "0.00000000", "1596617355.902701"], ["11334.00000", "1.10447869", "1596616895.153868", "r"]], "c": "1961568011"}, "book-100", "XBT/USD"]
[270, {"b": [["11284.00000", "2.33230439", "1596617355.918179"]], "c": "741248620"}, "book-100", "XBT/USD"]
[270, {"b": [["11280.80000", "0.10300000", "1596617355.936459"]], "c": "741248620"}, "book-100", "XBT/USD"]
[270, {"a": [["11317.70000", "3.83255021", "1596617355.957655"]], "c": "741248620"}, "book-100", "XBT/USD"]
[270, {"a": [["11303.40000", "0.00566682", "1596617356.087603"]], "c": "741248620"}, "book-100", "XBT/USD"]
[270, {"a": [["11287.80000", "0.01541006", "1596617356.146899"]], "c": "3380410302"}, "book-100", "XBT/USD"]
[270, {"b": [["11272.00000", "0.01541006", "1596617356.162230"]], "c": "3380410302"}, "book-100", "XBT/USD"]
[270, {"a": [["11286.80000", "0.07705031", "1596617356.163419"]], "c": "1695293644"}, "book-100", "XBT/USD"]
[270, {"b": [["11270.40000", "4.46810311", "1596617356.209022"]], "c": "1695293644"}, "book-100", "XBT/USD"]
[270, {"a": [["11287.10000", "4.61192425", "1596617356.209113"]], "c": "2253374590"}, "book-100", "XBT/USD"]
[270, {"b": [["11280.00000", "1.84325766", "1596617356.226327"]], "c": "2253374590"}, "book-100", "XBT/USD"]
[270, {"a": [["11287.20000", "0.00000000", "1596617356.226404"], ["11333.00000", "1.51500000", "1596616898.638139", "r"]], "c": "3826835911"}, "book-100", "XBT/USD"]
[270, {"b": [["11268.90000", "0.18492375", "1596617356.267202"]], "c": "3826835911"}, "book-100", "XBT/USD"]
[270, {"a": [["11287.00000", "0.26720947", "1596617356.326607"]], "c": "553600215"}, "book-100", "XBT/USD"]
[270, {"b": [["11282.30000", "0.12850000", "1596617356.353869"]], "c": "155346204"}, "book-100", "XBT/USD"]
[270, {"a": [["11284.10000", "3.47264497", "1596617356.354635"]], "c": "2004490202"}, "book-100", "XBT/USD"]
[270, {"b": [["11266.50000", "0.00000000", "1596617356.363206"], ["11245.60000", "1.10610000", "1596616875.821274", "r"]], "c": "2004490202"}, "book-100", "XBT/USD"]
[270, {"a": [["11297.80000", "0.88662099", "1596617356.409782"]], "c": "2004490202"}, "book-100", "XBT/USD"]
[270, {"b": [["11283.20000", "0.66496574", "1596617356.411340"]], "c": "327322"}, "book-100", "XBT/USD"]
[270, {"b": [["11281.30000", "0.00000000", "1596617356.426672"], ["11245.60000", "1.10610000", "1596616875.821274", "r"]], "c": "3501310539"}, "book-100", "XBT/USD"]
[270, {"a": [["11297.80000", "0.00000000", "1596617356.481412"], ["11332.80000", "14.80000000", "1596616404.177610", "r"]], "c": "3501310539"}, "book-100", "XBT/USD"]
[270, {"b": [["11249.30000", "0.00000000", "1596617356.510328"], ["11244.80000", "6.00000000", "1596616713.695896", "r"]], "c": "3501310539"}, "book-100", "XBT/USD"]
[270, {"a": [["11306.90000", "0.77011787", "1596617356.513726"]], "c": "3501310539"}, "book-100", "XBT/USD"]
[270, {"b": [["11266.10000", "0.00000000", "1596617356.518347"], ["11244.30000", "0.00525234", "1596614889.087583", "r"]], "c": "3501310539"}, "book-100", "XBT/USD"]
[270, {"b": [["11249.50000", "0.77011787", "1596617356.524615"]], "c": "3501310539"}, "book-100", "XBT/USD"]
[270, {"b": [["11282.40000", "0.26720115", "1596617356.526264"]], "c": "881706265"}, "book-100", "XBT/USD"]
[270, {"a": [["11307.00000", "0.00000000", "1596617356.528288"], ["11332.80000", "14.80000000", "1596616404.177610", "r"]], "c": "881706265"}, "book-100", "XBT/USD"]
[270, {"b": [["11250.60000", "0.00000000", "1596617356.800041"], ["11244.80000", "6.00000000", "1596616713.695896", "r"]], "c": "881706265"}, "book-100", "XBT/USD"]
[270, {"b": [["11253.10000", "0.01791104", "1596617357.030584"]], "c": "881706265"}, "book-100", "XBT/USD"]
[270, {"b": [["11284.00000", "2.83230439", "1596617357.032257"]], "c": "3466160259"}, "book-100", "XBT/USD"]
[270, {"b": [["11279.20000", "0.20514000", "1596617357.247718"]], "c": "3466160259"}, "book-100", "XBT/USD"]
[270, {"a": [["11284.50000", "0.00000000", "1596617357.363308"], ["11333.00000", "1.51500000", "1596616898.638139", "r"]], "c": "3441636456"}, "book-100", "XBT/USD"]
[270, {"b": [["11270.00000", "0.00000000", "1596617357.364360"], ["11245.60000", "1.10610000", "1596616875.821274", "r"]], "c": "3441636456"}, "book-100", "XBT/USD"]
