[275, ["11293.00000", "11293.10000", "1596616919.630513", "1.08097008", "3.04478455"], "spread", "XBT/USD"]
[275, ["11293.00000", "11293.10000", "1596616921.652965", "0.58097008", "3.04478455"], "spread", "XBT/USD"]
[275, ["11293.00000", "11293.10000", "1596616921.677035", "0.58097008", "5.04478455"], "spread", "XBT/USD"]
[275, ["11293.00000", "11293.10000", "1596616921.755859", "1.08097008", "5.04478455"], "spread", "XBT/USD"]
[275, ["11293.00000", "11293.10000", "1596616921.760946", "0.58007699", "5.04478455"], "spread", "XBT/USD"]
[275, ["11293.00000", "11293.10000", "1596616922.469689", "0.58007699", "5.06848456"], "spread", "XBT/USD"]
[275, ["11293.00000", "11293.10000", "1596616923.156407", "0.08007699", "5.06848456"], "spread", "XBT/USD"]
[275, ["11293.00000", "11293.10000", "1596616923.536938", "0.08007699", "9.48548456"], "spread", "XBT/USD"]
[275, ["11293.00000", "11293.10000", "1596616924.987292", "0.08007699", "9.39848456"], "spread", "XBT/USD"]
[275, ["11293.00000", "11293.10000", "1596616925.184454", "0.08007699", "9.66559783"], "spread", "XBT/USD"]
[275, ["11293.00000", "11293.10000", "1596616925.250985", "0.08007699", "11.43459783"], "spread", "XBT/USD"]
[275, ["11293.00000", "11293.10000", "1596616925.992011", "0.08007699", "11.83459783"], "spread", "XBT/USD"]
[275, ["11293.00000", "11293.10000", "1596616926.938244", "0.08007699", "11.88070890"], "spread", "XBT/USD"]
[275, ["11293.00000", "11293.10000", "1596616927.012412", "0.08007699", "12.03070890"], "spread", "XBT/USD"]
[275, ["11293.00000", "11293.10000", "1596616927.188093", "0.08007699", "12.53070890"], "spread", "XBT/USD"]
[275, ["11293.00000", "11293.10000", "1596616929.903370", "0.08007699", "12.03070890"], "spread", "XBT/USD"]
[275, ["11293.00000", "11293.10000", "1596616930.223330", "0.08007699", "12.39970890"], "spread", "XBT/USD"]
[275, ["11293.00000", "11293.10000", "1596616931.601323", "0.09907699", "12.39970890"], "spread", "XBT/USD"]
[275, ["11293.00000", "11293.10000", "1596616931.615741", "0.09907699", "12.89970890"], "spread", "XBT/USD"]
[275, ["11293.00000", "11293.10000", "1596616932.111549", "0.09907699", "12.39970890"], "spread", "XBT/USD"]
[275, ["11293.00000", "11293.10000", "1596616932.400187", "0.09907699", "11.99970890"], "spread", "XBT/USD"]
[275, ["11293.00000", "11293.10000", "1596616943.204546", "0.09907699", "11.63070890"], "spread", "XBT/USD"]
[275, ["11293.00000", "11293.10000", "1596616945.287734", "0.09907699", "11.99970890"], "spread", "XBT/USD"]
[275, ["11293.00000", "11293.10000", "1596616945.352475", "0.09907699", "12.07655683"], "spread", "XBT/USD"]
[275, ["11293.00000", "11293.10000", "1596616945.690201", "0.09907699", "11.70755683"], "spread", "XBT/USD"]
[275, ["11293.00000", "11293.10000", "1596616949.665145", "0.09907699", "11.70319383"], "spread", "XBT/USD"]
[275, ["11293.00000", "11293.10000", "1596616950.669660", "0.09907699", "11.71180683"], "spread", "XBT/USD"]
[275, ["11293.00000", "11293.10000", "1596616950.864164", "0.09907699", "12.08080683"], "spread", "XBT/USD"]
[275, ["11293.00000", "11293.10000", "1596616956.896774", "0.09907699", "11.71180683"], "spread", "XBT/USD"]
[275, ["11293.00000", "11293.10000", "1596616964.161346", "0.09907699", "9.94280683"], "spread", "XBT/USD"]
[275, ["11293.00000", "11293.10000", "1596616970.868827", "0.09907699", "10.31180683"], "spread", "XBT/USD"]
[275, ["11293.00000", "11293.10000", "1596616971.114092", "0.09907699", "9.94280683"], "spread", "XBT/USD"]
[275, ["11293.00000", "11293.10000", "1596616977.985828", "0.09907699", "11.69980683"], "spread", "XBT/USD"]
[275, ["11293.00000", "11293.10000", "1596616982.289877", "0.09907699", "11.78835687"], "spread", "XBT/USD"]
[275, ["11293.00000", "11293.10000", "1596616984.560428", "0.09907699", "11.63835687"], "spread", "XBT/USD"]
[275, ["11293.00000", "11293.10000", "1596616989.653697", "0.09907699", "12.00735687"], "spread", "XBT/USD"]
[275, ["11293.00000", "11293.10000", "1596616994.332197", "0.09907699", "14.07827122"], "spread", "XBT/USD"]
[275, ["11293.00000", "11293.10000", "1596616998.789807", "0.09907699", "14.08129248"], "spread", "XBT/USD"]
[275, ["11293.00000", "11293.10000", "1596617004.723916", "0.09907699", "14.08341965"], "spread", "XBT/USD"]
[275, ["11293.00000", "11293.10000", "1596617010.669704", "0.09907699", "14.07480665"], "spread", "XBT/USD"]
[275, ["11293.00000", "11293.10000", "1596617012.858688", "0.09907699", "14.22480665"], "spread", "XBT/USD"]
[275, ["11293.00000", "11293.10000", "1596617012.869271", "0.09907699", "14.72480665"], "spread", "XBT/USD"]
[275, ["11293.00000", "11293.10000", "1596617013.075872", "0.09907699", "14.22480665"], "spread", "XBT/USD"]
[275, ["11293.00000", "11293.10000", "1596617013.565050", "0.09907699", "14.23341965"], "spread", "XBT/USD"]
[275, ["11293.00000", "11293.10000", "1596617025.437267", "0.09907699", "14.18730858"], "spread", "XBT/USD"]
[275, ["11293.00000", "11293.10000", "1596617026.273181", "0.09907699", "14.18428732"], "spread", "XBT/USD"]
[275, ["11293.00000", "11293.10000", "1596617026.462408", "0.09907699", "14.18216015"], "spread", "XBT/USD"]
[275, ["11293.00000", "11293.10000", "1596617026.894140", "0.09907699", "14.18451571"], "spread", "XBT/USD"]
[275, ["11293.00000", "11293.10000", "1596617028.496220", "0.09907699", "13.81551571"], "spread", "XBT/USD"]
[275, ["11293.00000", "11293.10000", "1596617030.129177", "0.09907699", "13.62551571"], "spread", "XBT/USD"]
[275, ["11293.00000", "11293.10000", "1596617030.133450", "0.09907699", "12.62651571"], "spread", "XBT/USD"]
[275, ["11293.00000", "11293.10000", "1596617031.268733", "0.09907699", "10.62651571"], "spread", "XBT/USD"]
[275, ["11293.00000", "11293.10000", "1596617031.390269", "0.09907699", "10.62416015"], "spread", "XBT/USD"]
[275, ["11293.00000", "11293.10000", "1596617031.465737", "0.09907699", "8.86716015"], "spread", "XBT/USD"]
[275, ["11293.00000", "11293.10000", "1596617031.471028", "1.09395699", "8.86716015"], "spread", "XBT/USD"]
[275, ["11293.00000", "11293.10000", "1596617031.540221", "1.09395699", "8.85854715"], "spread", "XBT/USD"]
[275, ["11293.00000", "11293.10000", "1596617031.741802", "1.09395699", "8.83484714"], "spread", "XBT/USD"]
[275, ["11293.00000", "11293.10000", "1596617032.039171", "1.59395699", "8.83484714"], "spread", "XBT/USD"]
[275, ["11293.00000", "11293.10000", "1596617032.448601", "1.59395699", "8.33484714"], "spread", "XBT/USD"]
[275, ["11293.00000", "11293.10000", "1596617032.575405", "1.59395699", "10.33484714"], "spread", "XBT/USD"]
[275, ["11293.00000", "11293.10000", "1596617032.600916", "2.05641980", "10.33484714"], "spread", "XBT/USD"]
[275, ["11293.00000", "11293.10000", "1596617032.643135", "2.05641980", "10.34346014"], "spread", "XBT/USD"]
[275, ["11293.00000", "11293.10000", "1596617032.736257", "2.05641980", "8.34346014"], "spread", "XBT/USD"]
[275, ["11293.00000", "11293.10000", "1596617032.789911", "2.05641980", "8.15900837"], "spread", "XBT/USD"]
[275, ["11293.00000", "11293.10000", "1596617032.912883", "2.05641980", "8.14363794"], "spread", "XBT/USD"]
[275, ["11293.00000", "11293.10000", "1596617033.358546", "2.05641980", "7.87652467"], "spread", "XBT/USD"]
[275, ["11293.00000", "11293.10000", "1596617033.459020", "2.05641980", "8.14358656"], "spread", "XBT/USD"]
[275, ["11293.00000", "11293.10000", "1596617033.689494", "2.46141980", "8.14358656"], "spread", "XBT/USD"]
[275, ["11293.00000", "11293.10000", "1596617033.756839", "2.46141980", "8.13497356"], "spread", "XBT/USD"]
[275, ["11293.00000", "11293.10000", "1596617034.228607", "4.46141980", "8.13497356"], "spread", "XBT/USD"]
[275, ["11293.00000", "11293.10000", "1596617034.348502", "4.46141980", "6.06405921"], "spread", "XBT/USD"]
[275, ["11293.00000", "11293.10000", "1596617034.366449", "2.46141980", "6.06405921"], "spread", "XBT/USD"]
[275, ["11293.00000", "11293.10000", "1596617034.428687", "2.46141980", "1.64705921"], "spread", "XBT/USD"]
[275, ["11293.00000", "11293.10000", "1596617034.901678", "2.46141980", "1.49705921"], "spread", "XBT/USD"]
[275, ["11293.00000", "11293.10000", "1596617034.971655", "2.47353280", "1.49705921"], "spread", "XBT/USD"]
[275, ["11293.00000", "11293.10000", "1596617035.067681", "2.47353280", "0.83245986"], "spread", "XBT/USD"]
[275, ["11293.00000", "11293.10000", "1596617035.534561", "2.47353280", "0.56539797"], "spread", "XBT/USD"]
[275, ["11293.00000", "11293.10000", "1596617036.760951", "2.76453280", "0.56539797"], "spread", "XBT/USD"]
[275, ["11293.00000", "11293.10000", "1596617037.972081", "2.76453280", "2.56539797"], "spread", "XBT/USD"]
[275, ["11293.00000", "11293.10000", "1596617038.216507", "2.76453280", "2.47684793"], "spread", "XBT/USD"]
[275, ["11293.00000", "11293.10000", "1596617039.644946", "2.76453280", "2.40000000"], "spread", "XBT/USD"]
[275, ["11293.00000", "11293.10000", "1596617040.872965", "2.76453280", "2.90000000"], "spread", "XBT/USD"]
[275, ["11293.00000", "11293.10000", "1596617041.026148", "2.35953280", "2.90000000"], "spread", "XBT/USD"]
[271, [["11293.10000", "0.20000000", "1596617045.818277", "b", "m", ""], ["11293.10000", "0.20000000", "1596617045.822924", "b", "m", ""], ["11293.10000", "0.86370527", "1596617045.824506", "b", "m", ""]], "trade", "XBT/USD"]
[275, ["11293.00000", "11293.10000", "1596617045.824506", "2.35953280", "1.63629473"], "spread", "XBT/USD"]
[275, ["11293.00000", "11293.10000", "1596617046.004525", "2.35953280", "0.50000000"], "spread", "XBT/USD"]
[275, ["11293.00000", "11293.10000", "1596617046.237708", "4.35953280", "0.50000000"], "spread", "XBT/USD"]
[271, [["11293.10000", "0.14726330", "1596617046.762405", "b", "l", ""]], "trade", "XBT/USD"]
[275, ["11293.00000", "11293.10000", "1596617046.762405", "4.35953280", "0.35273670"], "spread", "XBT/USD"]
[275, ["11293.00000", "11293.10000", "1596617047.416610", "4.60953280", "0.35273670"], "spread", "XBT/USD"]
[275, ["11293.00000", "11293.20000", "1596617047.416610", "4.60953280", "0.66454413"], "spread", "XBT/USD"]
[275, ["11293.00000", "11293.20000", "1596617048.137888", "4.10953280", "0.66454413"], "spread", "XBT/USD"]
[275, ["11293.10000", "11293.20000", "1596617048.139637", "0.50000000", "0.66454413"], "spread", "XBT/USD"]
[275, ["11293.10000", "11293.20000", "1596617048.212389", "0.51211301", "0.66454413"], "spread", "XBT/USD"]
[275, ["11293.10000", "11293.20000", "1596617048.305921", "1.31211301", "0.66454413"], "spread", "XBT/USD"]
[275, ["11293.10000", "11293.20000", "1596617048.370494", "1.31211301", "2.42854413"], "spread", "XBT/USD"]
[275, ["11293.10000", "11293.20000", "1596617050.091988", "1.31211301", "2.92854413"], "spread", "XBT/USD"]
[275, ["11293.10000", "11293.20000", "1596617050.874892", "1.31211301", "4.92854413"], "spread", "XBT/USD"]
[271, [["11293.10000", "0.50000000", "1596617050.966172", "s", "l", ""], ["11293.10000", "0.01211301", "1596617050.972239", "s", "l", ""], ["11293.10000", "0.80000000", "1596617050.973763", "s", "l", ""]], "trade", "XBT/USD"]
[275, ["11293.00000", "11293.10000", "1596617050.965446", "0.85253980", "0.65508479"], "spread", "XBT/USD"]
, "c": "3131140300"}, "book-100", "XBT/USD"]
[270, {"b": [["11279.50000", "0.09800000", "1596616920.140701"]], "c": "3131140300"}, "book-100", "XBT/USD"]
[270, {"a": [["11335.10000", "0.00000000", "1596616920.307587"], ["11343.00000", "0.18439000", "1596616173.961275", "r"]], "c": "3131140300"}, "book-100", "XBT/USD"]
[270, {"b": [["11284.90000", "0.00000000", "1596616920.326970"], ["11246.10000", "3.80151848", "1596616862.441779", "r"]], "c": "3131140300"}, "book-100", "XBT/USD"]
[270, {"b": [["11287.90000", "4.41500000", "1596616920.333834"]], "c": "3365401229"}, "book-100", "XBT/USD"]
[270, {"b": [["11279.60000", "3.56225338", "1596616920.338416"]], "c": "3365401229"}, "book-100", "XBT/USD"]
[270, {"a": [["11296.10000", "4.42300000", "1596616920.343752"]], "c": "450560687"}, "book-100", "XBT/USD"]
[270, {"a": [["11335.70000", "0.38840986", "1596616920.360608"]], "c": "450560687"}, "book-100", "XBT/USD"]
[270, {"a": [["11326.50000", "6.20000000", "1596616920.432987"]], "c": "450560687"}, "book-100", "XBT/USD"]
[270, {"b": [["11286.50000", "0.00000000", "1596616920.437286"], ["11246.50000", "0.75800000", "1596616899.108476", "r"]], "c": "450560687"}, "book-100", "XBT/USD"]
[270, {"b": [["11278.70000", "1.69284916", "1596616920.470778"]], "c": "450560687"}, "book-100", "XBT/USD"]
[270, {"b": [["11282.10000", "1.13059929", "1596616920.475077"]], "c": "450560687"}, "book-100", "XBT/USD"]
[270, {"b": [["11284.00000", "0.15289819", "1596616920.490402"]], "c": "450560687"}, "book-100", "XBT/USD"]
[270, {"b": [["11281.80000", "1.07049605", "1596616920.491702"]], "c": "450560687"}, "book-100", "XBT/USD"]
[270, {"b": [["11276.70000", "0.38000000", "1596616920.494976"]], "c": "450560687"}, "book-100", "XBT/USD"]
[270, {"a": [["11293.30000", "0.66461532", "1596616920.532581"]], "c": "1187937319"}, "book-100", "XBT/USD"]
[270, {"b": [["11289.00000", "0.66454136", "1596616920.533532"]], "c": "1456779307"}, "book-100", "XBT/USD"]
[270, {"a": [["11306.80000", "0.88600083", "1596616920.536739"]], "c": "1456779307"}, "book-100", "XBT/USD"]
[270, {"b": [["11286.20000", "0.88600083", "1596616920.536866"]], "c": "1456779307"}, "book-100", "XBT/USD"]
[270, {"b": [["11288.40000", "0.26703684", "1596616920.537485"]], "c": "77028214"}, "book-100", "XBT/USD"]
[270, {"a": [["11293.40000", "0.66461532", "1596616920.559977"]], "c": "3425323798"}, "book-100", "XBT/USD"]
[270, {"b": [["11282.30000", "0.07250000", "1596616920.561201"]], "c": "3425323798"}, "book-100", "XBT/USD"]
[270, {"b": [["11287.50000", "0.66461532", "1596616920.588088"]], "c": "3425323798"}, "book-100", "XBT/USD"]
[270, {"a": [["11296.80000", "0.18522000", "1596616920.589031"]], "c": "3425323798"}, "book-100", "XBT/USD"]
[270, {"b": [["11282.90000", "0.55989584", "1596616920.589678"]], "c": "3425323798"}, "book-100", "XBT/USD"]
[270, {"a": [["11293.70000", "0.00000000", "1596616920.671210"], ["11340.90000", "1.02486589", "1596616899.842274", "r"]], "c": "2017475259"}, "book-100", "XBT/USD"]
[270, {"a": [["11293.80000", "0.09621094", "1596616920.687435"]], "c": "1071130380"}, "book-100", "XBT/USD"]
[270, {"a": [["11305.60000", "0.88610141", "1596616920.719583"]], "c": "1071130380"}, "book-100", "XBT/USD"]
[270, {"b": [["11274.70000", "0.88606829", "1596616920.727546"]], "c": "1071130380"}, "book-100", "XBT/USD"]
[270, {"b": [["11282.90000", "0.46368490", "1596616920.782148"]], "c": "1071130380"}, "book-100", "XBT/USD"]
[270, {"b": [["11285.50000", "0.09621094", "1596616920.800057"]], "c": "1071130380"}, "book-100", "XBT/USD"]
[270, {"a": [["11294.70000", "0.26704072", "1596616920.835527"]], "c": "3125776549"}, "book-100", "XBT/USD"]
[270, {"a": [["11313.40000", "0.00000000", "1596616920.855997"], ["11338.90000", "5.60000000", "1596616712.065179", "r"]], "c": "3125776549"}, "book-100", "XBT/USD"]
[270, {"a": [["11312.90000", "0.76926222", "1596616920.858059"]], "c": "3125776549"}, "book-100", "XBT/USD"]
[270, {"a": [["11331.40000", "0.00000000", "1596616920.884947"], ["11338.90000", "5.60000000", "1596616712.065179", "r"]], "c": "3125776549"}, "book-100", "XBT/USD"]
[270, {"a": [["11329.80000", "2.30883184", "1596616920.887515"]], "c": "3125776549"}, "book-100", "XBT/USD"]
[270, {"a": [["11293.60000", "0.00000000", "1596616920.918560"], ["11338.90000", "5.60000000", "1596616712.065179", "r"]], "c": "576371829"}, "book-100", "XBT/USD"]
[270, {"b": [["11284.20000", "0.00000000", "1596616920.968555"], ["11253.20000", "0.01000000", "1596616916.775626", "r"]], "c": "576371829"}, "book-100", "XBT/USD"]
[270, {"a": [["11337.50000", "11.29950000", "1596616920.969883"]], "c": "576371829"}, "book-100", "XBT/USD"]
[270, {"b": [["11272.50000", "6.40000000", "1596616920.984309"]], "c": "576371829"}, "book-100", "XBT/USD"]
[270, {"b": [["11286.20000", "2.38600083", "1596616921.115720"]], "c": "576371829"}, "book-100", "XBT/USD"]
[270, {"b": [["11279.40000", "0.00000000", "1596616921.169027"], ["11252.90000", "5.60000000", "1596616073.488797", "r"]], "c": "576371829"}, "book-100", "XBT/USD"]
[270, {"b": [["11274.20000", "0.13827570", "1596616921.173904"]], "c": "576371829"}, "book-100", "XBT/USD"]
[270, {"a": [["11296.10000", "0.00000000", "1596616921.202997"], ["11338.90000", "5.60000000", "1596616712.065179", "r"]], "c": "4231425357"}, "book-100", "XBT/USD"]
[270, {"a": [["11294.60000", "4.42400000", "1596616921.204108"]], "c": "3125108371"}, "book-100", "XBT/USD"]
[270, {"b": [["11276.00000", "3.27880383", "1596616921.403295"]], "c": "3125108371"}, "book-100", "XBT/USD"]
[270, {"a": [["11300.70000", "0.45323155", "1596616921.424940"]], "c": "3125108371"}, "book-100", "XBT/USD"]
[270, {"b": [["11288.40000", "0.73815649", "1596616921.425187"]], "c": "59707426"}, "book-100", "XBT/USD"]
[270, {"b": [["11273.10000", "0.00000000", "1596616921.466921"], ["11252.90000", "5.60000000", "1596616073.488797", "r"]], "c": "59707426"}, "book-100", "XBT/USD"]
[270, {"b": [["11281.90000", "0.25678439", "1596616921.542855"]], "c": "59707426"}, "book-100", "XBT/USD"]
[270, {"b": [["11278.50000", "1.70960652", "1596616921.549901"]], "c": "59707426"}, "book-100", "XBT/USD"]
[270, {"a": [["11297.00000", "0.00000000", "1596616921.611190"], ["11338.80000", "0.00890818", "1596616878.609006", "r"]], "c": "59707426"}, "book-100", "XBT/USD"]
[270, {"a": [["11301.60000", "0.70111000", "1596616921.614290"]], "c": "59707426"}, "book-100", "XBT/USD"]
[270, {"b": [["11290.00000", "0.00000000", "1596616921.618199"], ["11252.90000", "5.60000000", "1596616073.488797", "r"]], "c": "3930785948"}, "book-100", "XBT/USD"]
[270, {"b": [["11293.00000", "0.58097008", "1596616921.652965"]], "c": "1054657897"}, "book-100", "XBT/USD"]
[270, {"b": [["11284.00000", "0.00000000", "1596616921.654602"], ["11252.30000", "3.56995229", "1596616555.819245", "r"]], "c": "1054657897"}, "book-100", "XBT/USD"]
[270, {"b": [["11291.50000", "0.00000000", "1596616921.673744"], ["11252.00000", "0.76926222", "1596616920.881000", "r"]], "c": "3003153748"}, "book-100", "XBT/USD"]
[270, {"a": [["11293.10000", "5.04478455", "1596616921.677035"]], "c": "664243378"}, "book-100", "XBT/USD"]
[270, {"b": [["11289.10000", "0.57470000", "1596616921.704283"]], "c": "1634658681"}, "book-100", "XBT/USD"]
[270, {"b": [["11290.70000", "0.00000000", "1596616921.711236"], ["11252.00000", "0.76926222", "1596616920.881000", "r"]], "c": "90037325"}, "book-100", "XBT/USD"]
[270, {"b": [["11286.70000", "0.00000000", "1596616921.737791"], ["11251.60000", "0.10875320", "1596616891.421287", "r"]], "c": "90037325"}, "book-100", "XBT/USD"]
[270, {"b": [["11293.00000", "1.08097008", "1596616921.755859"]], "c": "355757121"}, "book-100", "XBT/USD"]
[270, {"b": [["11293.00000", "0.58007699", "1596616921.760946"]], "c": "2449857207"}, "book-100", "XBT/USD"]
[270, {"a": [["11295.60000", "0.25000000", "1596616921.860926"]], "c": "610707088"}, "book-100", "XBT/USD"]
[270, {"b": [["11288.70000", "0.45000000", "1596616921.916784"]], "c": "3819950849"}, "book-100", "XBT/USD"]
[270, {"a": [["11316.00000", "0.18439000", "1596616921.917176"]], "c": "3819950849"}, "book-100", "XBT/USD"]
[270, {"b": [["11283.30000", "1.03918446", "1596616921.967895"]], "c": "3819950849"}, "book-100", "XBT/USD"]
[270, {"a": [["11333.80000", "0.00000000", "1596616922.109062"], ["11337.50000", "11.29950000", "1596616920.969883", "r"]], "c": "3819950849"}, "book-100", "XBT/USD"]
[270, {"a": [["11318.70000", "10.04221267", "1596616922.181646"]], "c": "3819950849"}, "book-100", "XBT/USD"]
[270, {"a": [["11294.60000", "0.00000000", "1596616922.214023"], ["11338.00000", "9.36624624", "1596616895.330372", "r"]], "c": "2572164204"}, "book-100", "XBT/USD"]
[270, {"a": [["11293.30000", "5.08861532", "1596616922.230189"]], "c": "451936429"}, "book-100", "XBT/USD"]
[270, {"b": [["11288.40000", "0.47111965", "1596616922.296501"]], "c": "3137021637"}, "book-100", "XBT/USD"]
[270, {"b": [["11288.10000", "0.40757110", "1596616922.317068"]], "c": "2948154183"}, "book-100", "XBT/USD"]
[270, {"b": [["11280.70000", "0.00000000", "1596616922.429247"], ["11251.60000", "0.10875320", "1596616891.421287", "r"]], "c": "2948154183"}, "book-100", "XBT/USD"]
[270, {"b": [["11279.70000", "0.04220262", "1596616922.430740"]], "c": "2948154183"}, "book-100", "XBT/USD"]
[270, {"b": [["11288.70000", "0.00000000", "1596616922.462522"], ["11251.60000", "0.10875320", "1596616891.421287", "r"]], "c": "3425728178"}, "book-100", "XBT/USD"]
[270, {"a": [["11293.10000", "5.06848456", "1596616922.469689"]], "c": "1652570603"}, "book-100", "XBT/USD"]
[270, {"a": [["11295.60000", "0.00000000", "1596616922.550593"], ["11338.80000", "0.00890818", "1596616878.609006", "r"]], "c": "3790256233"}, "book-100", "XBT/USD"]
[270, {"b": [["11288.10000", "0.37007110", "1596616922.553882"]], "c": "3474074575"}, "book-100", "XBT/USD"]
[270, {"b": [["11289.50000", "0.45000000", "1596616922.723700"]], "c": "2105771753"}, "book-100", "XBT/USD"]
[270, {"b": [["11289.60000", "0.57470000", "1596616922.774224"]], "c": "876763809"}, "book-100", "XBT/USD"]
[270, {"b": [["11289.10000", "0.00000000", "1596616922.783713"], ["11252.00000", "0.76926222", "1596616920.881000", "r"]], "c": "2912685978"}, "book-100", "XBT/USD"]
[270, {"a": [["11293.30000", "0.66461532", "1596616922.855353"]], "c": "32848749"}, "book-100", "XBT/USD"]
[270, {"b": [["11273.30000", "0.00000000", "1596616922.863961"], ["11251.60000", "0.10875320", "1596616891.421287", "r"]], "c": "32848749"}, "book-100", "XBT/USD"]
[270, {"a": [["11296.50000", "0.25000000", "1596616922.902066"]], "c": "1195487805"}, "book-100", "XBT/USD"]
[270, {"a": [["11294.70000", "0.00000000", "1596616922.910166"], ["11338.80000", "0.00890818", "1596616878.609006", "r"]], "c": "552227107"}, "book-100", "XBT/USD"]
[270, {"a": [["11293.70000", "0.26705905", "1596616923.007201"]], "c": "2976057121"}, "book-100", "XBT/USD"]
[270, {"a": [["11306.80000", "0.00000000", "1596616923.008049"], ["11338.80000", "0.00890818", "1596616878.609006", "r"]], "c": "2976057121"}, "book-100", "XBT/USD"]
[270, {"a": [["11302.30000", "4.03411371", "1596616923.027175"]], "c": "2976057121"}, "book-100", "XBT/USD"]
[270, {"a": [["11293.90000", "0.88611804", "1596616923.067090"]], "c": "3390493540"}, "book-100", "XBT/USD"]
[270, {"a": [["11296.50000", "0.00000000", "1596616923.122033"], ["11338.80000", "0.00890818", "1596616878.609006", "r"]], "c": "3659200832"}, "book-100", "XBT/USD"]
[270, {"b": [["11289.50000", "0.00000000", "1596616923.124736"], ["11251.40000", "0.80800000", "1596616536.000084", "r"]], "c": "442086648"}, "book-100", "XBT/USD"]
[270, {"b": [["11293.00000", "0.08007699", "1596616923.156407"]], "c": "61549093"}, "book-100", "XBT/USD"]
[270, {"b": [["11289.10000", "0.57470000", "1596616923.170118"]], "c": "729957510"}, "book-100", "XBT/USD"]
[270, {"a": [["11293.40000", "3.59167318", "1596616923.197126"]], "c": "1175830900"}, "book-100", "XBT/USD"]
