[275, ["11308.50000", "11308.60000", "1596614706.603093", "0.00458098", "0.57856608"], "spread", "XBT/USD"]
[275, ["11308.50000", "11308.60000", "1596614707.768999", "0.50458098", "0.57856608"], "spread", "XBT/USD"]
[275, ["11308.50000", "11308.60000", "1596614709.056737", "0.50458098", "2.57856608"], "spread", "XBT/USD"]
[275, ["11308.50000", "11308.60000", "1596614709.181857", "0.50458098", "0.57856608"], "spread", "XBT/USD"]
[275, ["11308.50000", "11308.60000", "1596614710.074603", "0.50458098", "0.34356608"], "spread", "XBT/USD"]
[275, ["11308.50000", "11308.60000", "1596614711.562317", "2.50458098", "0.34356608"], "spread", "XBT/USD"]
[275, ["11308.50000", "11308.60000", "1596614712.015379", "3.26010020", "0.34356608"], "spread", "XBT/USD"]
[275, ["11308.50000", "11308.60000", "1596614712.603512", "3.46010020", "0.34356608"], "spread", "XBT/USD"]
[275, ["11308.50000", "11308.60000", "1596614712.895975", "4.03657169", "0.34356608"], "spread", "XBT/USD"]
[275, ["11308.50000", "11308.60000", "1596614713.372764", "3.28105247", "0.34356608"], "spread", "XBT/USD"]
[275, ["11308.50000", "11308.60000", "1596614714.930902", "1.28105247", "0.34356608"], "spread", "XBT/USD"]
[275, ["11308.50000", "11308.60000", "1596614715.503188", "2.03657169", "0.34356608"], "spread", "XBT/USD"]
[275, ["11308.50000", "11308.60000", "1596614715.545853", "1.28105247", "0.34356608"], "spread", "XBT/USD"]
[275, ["11308.50000", "11308.60000", "1596614716.323103", "0.78105247", "0.34356608"], "spread", "XBT/USD"]
[275, ["11308.50000", "11308.60000", "1596614717.497271", "1.28105247", "0.34356608"], "spread", "XBT/USD"]
[275, ["11308.50000", "11308.60000", "1596614718.265620", "0.70458098", "0.34356608"], "spread", "XBT/USD"]
[275, ["11308.50000", "11308.60000", "1596614723.190431", "1.24500850", "0.34356608"], "spread", "XBT/USD"]
[275, ["11308.50000", "11308.60000", "1596614723.812724", "1.24500850", "2.34356608"], "spread", "XBT/USD"]
[275, ["11308.50000", "11308.60000", "1596614724.021220", "1.24500850", "0.34356608"], "spread", "XBT/USD"]
[275, ["11308.50000", "11308.60000", "1596614724.799665", "0.70458098", "0.34356608"], "spread", "XBT/USD"]
[275, ["11308.50000", "11308.60000", "1596614726.298213", "0.20458098", "0.34356608"], "spread", "XBT/USD"]
[275, ["11308.50000", "11308.60000", "1596614727.449790", "0.84211571", "0.34356608"], "spread", "XBT/USD"]
[275, ["11308.50000", "11308.60000", "1596614727.461879", "1.34211571", "0.34356608"], "spread", "XBT/USD"]
[275, ["11308.50000", "11308.60000", "1596614729.853597", "1.89634111", "0.34356608"], "spread", "XBT/USD"]
[275, ["11308.50000", "11308.60000", "1596614731.019373", "3.89634111", "0.34356608"], "spread", "XBT/USD"]
[275, ["11308.50000", "11308.60000", "1596614731.486638", "4.16291726", "0.34356608"], "spread", "XBT/USD"]
[275, ["11308.50000", "11308.60000", "1596614731.810296", "4.61839698", "0.34356608"], "spread", "XBT/USD"]
[275, ["11308.50000", "11308.60000", "1596614731.899157", "5.28180418", "0.34356608"], "spread", "XBT/USD"]
[275, ["11308.50000", "11308.60000", "1596614731.954921", "5.68180418", "0.34356608"], "spread", "XBT/USD"]
[275, ["11308.50000", "11308.60000", "1596614731.956505", "5.67722320", "0.34356608"], "spread", "XBT/USD"]
[275, ["11308.50000", "11308.60000", "1596614732.012562", "5.22174348", "0.34356608"], "spread", "XBT/USD"]
[275, ["11308.50000", "11308.60000", "1596614732.108166", "5.72174348", "0.34356608"], "spread", "XBT/USD"]
[275, ["11308.50000", "11308.60000", "1596614732.609407", "6.17792890", "0.34356608"], "spread", "XBT/USD"]
[275, ["11308.50000", "11308.60000", "1596614733.835063", "5.72174348", "0.34356608"], "spread", "XBT/USD"]
[275, ["11308.50000", "11308.60000", "1596614735.684672", "5.72632446", "0.34356608"], "spread", "XBT/USD"]
[275, ["11308.50000", "11308.60000", "1596614735.834719", "5.22632446", "0.34356608"], "spread", "XBT/USD"]
[275, ["11308.50000", "11308.60000", "1596614737.003006", "5.72632446", "0.34356608"], "spread", "XBT/USD"]
[275, ["11308.50000", "11308.60000", "1596614739.954966", "5.32632446", "0.34356608"], "spread", "XBT/USD"]
[275, ["11308.50000", "11308.60000", "1596614740.654166", "8.17632446", "0.34356608"], "spread", "XBT/USD"]
[275, ["11308.50000", "11308.60000", "1596614741.878824", "8.40132446", "0.34356608"], "spread", "XBT/USD"]
[275, ["11308.50000", "11308.60000", "1596614742.115370", "5.55132446", "0.34356608"], "spread", "XBT/USD"]
[271, [["11308.60000", "0.11448715", "1596614742.433666", "b", "l", ""], ["11308.60000", "0.05874384", "1596614742.438966", "b", "l", ""]], "trade", "XBT/USD"]
[275, ["11308.50000", "11308.60000", "1596614742.438967", "5.55132446", "0.17033509"], "spread", "XBT/USD"]
[275, ["11308.50000", "11308.60000", "1596614742.794882", "9.45132446", "0.17033509"], "spread", "XBT/USD"]
[275, ["11308.50000", "11308.60000", "1596614744.993199", "5.55132446", "0.17033509"], "spread", "XBT/USD"]
[275, ["11308.50000", "11308.60000", "1596614745.388062", "5.05132446", "0.17033509"], "spread", "XBT/USD"]
[275, ["11308.50000", "11308.60000", "1596614746.024721", "5.80684368", "0.17033509"], "spread", "XBT/USD"]
[275, ["11308.50000", "11308.60000", "1596614746.182048", "5.05132446", "0.17033509"], "spread", "XBT/USD"]
[275, ["11308.50000", "11308.60000", "1596614746.365802", "9.30132446", "0.17033509"], "spread", "XBT/USD"]
[275, ["11308.50000", "11308.60000", "1596614746.559774", "9.80132446", "0.17033509"], "spread", "XBT/USD"]
[275, ["11308.50000", "11308.60000", "1596614746.970751", "10.55684368", "0.17033509"], "spread", "XBT/USD"]
[275, ["11308.50000", "11308.60000", "1596614747.020739", "9.80132446", "0.17033509"], "spread", "XBT/USD"]
[275, ["11308.50000", "11308.60000", "1596614748.499960", "10.10132446", "0.17033509"], "spread", "XBT/USD"]
[275, ["11308.50000", "11308.60000", "1596614748.503096", "10.85684368", "0.17033509"], "spread", "XBT/USD"]
[275, ["11308.50000", "11308.60000", "1596614751.007245", "10.10132446", "0.17033509"], "spread", "XBT/USD"]
[275, ["11308.50000", "11308.60000", "1596614751.055013", "10.85684368", "0.17033509"], "spread", "XBT/USD"]
[275, ["11308.50000", "11308.60000", "1596614752.625273", "12.35684368", "0.17033509"], "spread", "XBT/USD"]
[275, ["11308.50000", "11308.60000", "1596614755.029098", "11.85684368", "0.17033509"], "spread", "XBT/USD"]
[275, ["11308.50000", "11308.60000", "1596614756.198229", "12.35684368", "0.17033509"], "spread", "XBT/USD"]
[275, ["11308.50000", "11308.60000", "1596614758.216651", "12.75684368", "0.17033509"], "spread", "XBT/USD"]
[271, [["11308.60000", "0.08515643", "1596614758.749412", "b", "l", ""]], "trade", "XBT/USD"]
[275, ["11308.50000", "11308.60000", "1596614758.749412", "12.75684368", "0.08517866"], "spread", "XBT/USD"]
[275, ["11308.50000", "11308.60000", "1596614764.586422", "12.25684368", "0.08517866"], "spread", "XBT/USD"]
[275, ["11308.50000", "11308.60000", "1596614765.757629", "12.75684368", "0.08517866"], "spread", "XBT/USD"]
[275, ["11308.50000", "11308.60000", "1596614766.215740", "12.35684368", "0.08517866"], "spread", "XBT/USD"]
[275, ["11308.50000", "11308.60000", "1596614769.065811", "11.60132446", "0.08517866"], "spread", "XBT/USD"]
[275, ["11308.50000", "11308.60000", "1596614769.110289", "12.35684368", "0.08517866"], "spread", "XBT/USD"]
[275, ["11308.50000", "11308.60000", "1596614770.325290", "12.85684368", "0.08517866"], "spread", "XBT/USD"]
[275, ["11308.50000", "11308.60000", "1596614774.135329", "12.35684368", "0.08517866"], "spread", "XBT/USD"]
[275, ["11308.50000", "11308.60000", "1596614774.343432", "12.35684368", "0.12089842"], "spread", "XBT/USD"]
[275, ["11308.50000", "11308.60000", "1596614775.304667", "12.85684368", "0.12089842"], "spread", "XBT/USD"]
[275, ["11308.50000", "11308.60000", "1596614775.847994", "13.35184368", "0.12089842"], "spread", "XBT/USD"]
[275, ["11308.50000", "11308.60000", "1596614776.484107", "12.59632446", "0.12089842"], "spread", "XBT/USD"]
[275, ["11308.50000", "11308.60000", "1596614776.616631", "13.35184368", "0.12089842"], "spread", "XBT/USD"]
[275, ["11308.50000", "11308.60000", "1596614777.256027", "12.59632446", "0.12089842"], "spread", "XBT/USD"]
[275, ["11308.50000", "11308.60000", "1596614777.374084", "13.35184368", "0.12089842"], "spread", "XBT/USD"]
[275, ["11308.50000", "11308.60000", "1596614780.022575", "12.59632446", "0.12089842"], "spread", "XBT/USD"]
[275, ["11308.50000", "11308.60000", "1596614780.143592", "13.35184368", "0.12089842"], "spread", "XBT/USD"]
[275, ["11308.50000", "11308.60000", "1596614780.353716", "12.59632446", "0.12089842"], "spread", "XBT/USD"]
[275, ["11308.50000", "11308.60000", "1596614780.397676", "13.35184368", "0.12089842"], "spread", "XBT/USD"]
[275, ["11308.50000", "11308.60000", "1596614781.436574", "12.59632446", "0.12089842"], "spread", "XBT/USD"]
[275, ["11308.50000", "11308.60000", "1596614781.490304", "12.10132446", "0.12089842"], "spread", "XBT/USD"]
[275, ["11308.50000", "11308.60000", "1596614781.614561", "17.10132446", "0.12089842"], "spread", "XBT/USD"]
[275, ["11308.50000", "11308.60000", "1596614781.674080", "17.59632446", "0.12089842"], "spread", "XBT/USD"]
[275, ["11308.50000", "11308.60000", "1596614781.986162", "17.69632446", "0.12089842"], "spread", "XBT/USD"]
[275, ["11308.50000", "11308.60000", "1596614782.108298", "18.09632446", "0.12089842"], "spread", "XBT/USD"]
[275, ["11308.50000", "11308.60000", "1596614782.212490", "18.85184368", "0.12089842"], "spread", "XBT/USD"]
[275, ["11308.50000", "11308.60000", "1596614782.329856", "19.05184368", "0.12089842"], "spread", "XBT/USD"]
[275, ["11308.50000", "11308.60000", "1596614783.068161", "18.55684368", "0.12089842"], "spread", "XBT/USD"]
[275, ["11308.50000", "11308.60000", "1596614783.260905", "19.05184368", "0.12089842"], "spread", "XBT/USD"]
[275, ["11308.50000", "11308.60000", "1596614783.435132", "18.85184368", "0.12089842"], "spread", "XBT/USD"]
[275, ["11308.50000", "11308.60000", "1596614783.611136", "19.05184368", "0.12089842"], "spread", "XBT/USD"]
[275, ["11308.50000", "11308.60000", "1596614783.682141", "18.55184368", "0.12089842"], "spread", "XBT/USD"]
[275, ["11308.50000", "11308.60000", "1596614784.845546", "19.05184368", "0.12089842"], "spread", "XBT/USD"]
[275, ["11308.50000", "11308.60000", "1596614785.591471", "18.85184368", "0.12089842"], "spread", "XBT/USD"]
[275, ["11308.50000", "11308.60000", "1596614785.828766", "20.61784368", "0.12089842"], "spread", "XBT/USD"]
[275, ["11308.50000", "11308.60000", "1596614786.032676", "20.81784368", "0.12089842"], "spread", "XBT/USD"]
[275, ["11308.50000", "11308.60000", "1596614786.253622", "20.90627235", "0.12089842"], "spread", "XBT/USD"]
[275, ["11308.50000", "11308.60000", "1596614786.323238", "20.70627235", "0.12089842"], "spread", "XBT/USD"]
[275, ["11308.50000", "11308.60000", "1596614786.481621", "20.90627235", "0.12089842"], "spread", "XBT/USD"]
7.881734"], ["11352.00000", "0.18439000", "1596614637.886152", "r"]], "c": "876170022"}, "book-100", "XBT/USD"]
[270, {"b": [["11308.20000", "0.00000000", "1596614707.881990"], ["11259.10000", "1.06000000", "1596614685.211772", "r"]], "c": "4100064220"}, "book-100", "XBT/USD"]
[270, {"a": [["11324.40000", "3.48553788", "1596614707.882061"]], "c": "4100064220"}, "book-100", "XBT/USD"]
[270, {"b": [["11304.00000", "0.88486608", "1596614708.022970"]], "c": "4100064220"}, "book-100", "XBT/USD"]
[270, {"b": [["11282.20000", "1.45078734", "1596614708.076251"]], "c": "4100064220"}, "book-100", "XBT/USD"]
[270, {"b": [["11306.50000", "0.88466896", "1596614708.433568"]], "c": "2609362547"}, "book-100", "XBT/USD"]
[270, {"a": [["11319.90000", "0.88487024", "1596614708.484242"]], "c": "2609362547"}, "book-100", "XBT/USD"]
[270, {"b": [["11295.10000", "0.00000000", "1596614708.485080"], ["11259.10000", "1.06000000", "1596614685.211772", "r"]], "c": "2609362547"}, "book-100", "XBT/USD"]
[270, {"a": [["11318.90000", "0.00600000", "1596614708.537398"]], "c": "2609362547"}, "book-100", "XBT/USD"]
[270, {"b": [["11294.10000", "0.03700000", "1596614708.537485"]], "c": "2609362547"}, "book-100", "XBT/USD"]
[270, {"b": [["11291.30000", "0.00000000", "1596614708.604887"], ["11259.10000", "1.06000000", "1596614685.211772", "r"]], "c": "2609362547"}, "book-100", "XBT/USD"]
[270, {"b": [["11305.40000", "0.21264000", "1596614708.696556"]], "c": "2609362547"}, "book-100", "XBT/USD"]
[270, {"b": [["11304.80000", "1.36830000", "1596614708.845994"]], "c": "2609362547"}, "book-100", "XBT/USD"]
[270, {"b": [["11305.50000", "0.00000000", "1596614708.942941"], ["11257.90000", "2.57244282", "1596614451.809026", "r"]], "c": "1977862788"}, "book-100", "XBT/USD"]
[270, {"b": [["11305.60000", "0.00000000", "1596614708.943859"], ["11256.90000", "6.70000000", "1596614697.228065", "r"]], "c": "235940643"}, "book-100", "XBT/USD"]
[270, {"b": [["11304.00000", "5.88486608", "1596614708.948078"]], "c": "235940643"}, "book-100", "XBT/USD"]
[270, {"b": [["11304.80000", "1.16830000", "1596614708.972218"]], "c": "1278553182"}, "book-100", "XBT/USD"]
[270, {"b": [["11295.90000", "0.00000000", "1596614708.982379"], ["11256.60000", "2.30794357", "1596614707.592798", "r"]], "c": "1278553182"}, "book-100", "XBT/USD"]
[270, {"b": [["11299.70000", "1.02458000", "1596614708.986792"]], "c": "1278553182"}, "book-100", "XBT/USD"]
[270, {"a": [["11319.80000", "0.00000000", "1596614708.991880"], ["11352.00000", "0.18439000", "1596614637.886152", "r"]], "c": "1278553182"}, "book-100", "XBT/USD"]
[270, {"a": [["11331.00000", "0.18439000", "1596614709.024098"]], "c": "1278553182"}, "book-100", "XBT/USD"]
[270, {"b": [["11308.40000", "1.29945320", "1596614709.027243"]], "c": "2195351025"}, "book-100", "XBT/USD"]
[270, {"a": [["11324.00000", "0.88465427", "1596614709.027892"]], "c": "2195351025"}, "book-100", "XBT/USD"]
[270, {"a": [["11312.60000", "0.88471835", "1596614709.042284"]], "c": "2161809467"}, "book-100", "XBT/USD"]
[270, {"b": [["11305.50000", "0.26662439", "1596614709.043260"]], "c": "948576041"}, "book-100", "XBT/USD"]
[270, {"a": [["11308.60000", "2.57856608", "1596614709.056737"]], "c": "2584409191"}, "book-100", "XBT/USD"]
[270, {"b": [["11305.40000", "0.00000000", "1596614709.062394"], ["11256.90000", "6.70000000", "1596614697.228065", "r"]], "c": "4050767453"}, "book-100", "XBT/USD"]
[270, {"b": [["11294.10000", "0.00000000", "1596614709.082033"], ["11256.60000", "2.30794357", "1596614707.592798", "r"]], "c": "4050767453"}, "book-100", "XBT/USD"]
[270, {"a": [["11318.90000", "0.00000000", "1596614709.082845"], ["11350.60000", "1.12397623", "1596614443.006639", "r"]], "c": "4050767453"}, "book-100", "XBT/USD"]
[270, {"b": [["11307.00000", "0.88651922", "1596614709.087859"]], "c": "831550939"}, "book-100", "XBT/USD"]
[270, {"b": [["11305.60000", "0.21864000", "1596614709.118053"]], "c": "2621719419"}, "book-100", "XBT/USD"]
[270, {"b": [["11307.00000", "0.13100000", "1596614709.131076"]], "c": "3348326404"}, "book-100", "XBT/USD"]
[270, {"b": [["11295.10000", "0.03700000", "1596614709.131462"]], "c": "3348326404"}, "book-100", "XBT/USD"]
[270, {"a": [["11319.90000", "0.89087024", "1596614709.132768"]], "c": "3348326404"}, "book-100", "XBT/USD"]
[270, {"b": [["11305.50000", "0.46662439", "1596614709.149872"]], "c": "33317251"}, "book-100", "XBT/USD"]
[270, {"a": [["11308.60000", "0.57856608", "1596614709.181857"]], "c": "2742848205"}, "book-100", "XBT/USD"]
[270, {"a": [["11320.40000", "0.51346215", "1596614709.189617"]], "c": "2742848205"}, "book-100", "XBT/USD"]
[270, {"b": [["11307.00000", "0.88651922", "1596614709.384429"]], "c": "4171997618"}, "book-100", "XBT/USD"]
[270, {"a": [["11344.20000", "0.28000000", "1596614709.391128"]], "c": "4171997618"}, "book-100", "XBT/USD"]
[270, {"a": [["11324.00000", "0.00000000", "1596614709.397997"], ["11350.40000", "0.00407007", "1596614698.445422", "r"]], "c": "4171997618"}, "book-100", "XBT/USD"]
[270, {"a": [["11319.90000", "0.88487024", "1596614709.440737"]], "c": "4171997618"}, "book-100", "XBT/USD"]
[270, {"b": [["11295.10000", "0.00000000", "1596614709.441688"], ["11256.90000", "6.70000000", "1596614697.228065", "r"]], "c": "4171997618"}, "book-100", "XBT/USD"]
[270, {"a": [["11318.90000", "0.00600000", "1596614709.490031"]], "c": "4171997618"}, "book-100", "XBT/USD"]
[270, {"b": [["11294.10000", "0.03700000", "1596614709.531991"]], "c": "4171997618"}, "book-100", "XBT/USD"]
[270, {"a": [["11347.20000", "0.53087902", "1596614709.609036"]], "c": "4171997618"}, "book-100", "XBT/USD"]
[270, {"b": [["11289.60000", "0.00000000", "1596614709.646849"], ["11256.90000", "6.70000000", "1596614697.228065", "r"]], "c": "4171997618"}, "book-100", "XBT/USD"]
[270, {"b": [["11286.00000", "0.00000000", "1596614709.686353"], ["11256.60000", "2.30794357", "1596614707.592798", "r"]], "c": "4171997618"}, "book-100", "XBT/USD"]
[270, {"b": [["11283.10000", "0.00000000", "1596614709.686862"], ["11255.00000", "0.05000000", "1596613962.090152", "r"]], "c": "4171997618"}, "book-100", "XBT/USD"]
[270, {"b": [["11283.60000", "0.00000000", "1596614709.699507"], ["11253.90000", "0.48980000", "1596614469.798378", "r"]], "c": "4171997618"}, "book-100", "XBT/USD"]
[270, {"b": [["11288.50000", "4.50000000", "1596614709.774266"]], "c": "4171997618"}, "book-100", "XBT/USD"]
[270, {"b": [["11285.70000", "0.00000000", "1596614709.776023"], ["11253.40000", "6.40000000", "1596614703.084678", "r"]], "c": "4171997618"}, "book-100", "XBT/USD"]
[270, {"a": [["11326.10000", "2.00521591", "1596614709.792887"]], "c": "4171997618"}, "book-100", "XBT/USD"]
[270, {"b": [["11292.10000", "0.50000000", "1596614709.803238"]], "c": "4171997618"}, "book-100", "XBT/USD"]
[270, {"a": [["11339.40000", "1.06486596", "1596614709.849332"]], "c": "4171997618"}, "book-100", "XBT/USD"]
[270, {"a": [["11332.40000", "0.00000000", "1596614709.885032"], ["11350.20000", "4.98770000", "1596614486.656272", "r"]], "c": "4171997618"}, "book-100", "XBT/USD"]
[270, {"a": [["11310.80000", "0.00000000", "1596614709.933457"], ["11350.40000", "0.00407007", "1596614698.445422", "r"]], "c": "1588942318"}, "book-100", "XBT/USD"]
[270, {"a": [["11336.20000", "0.00000000", "1596614709.977434"], ["11350.60000", "1.12397623", "1596614443.006639", "r"]], "c": "1588942318"}, "book-100", "XBT/USD"]
[270, {"a": [["11332.90000", "0.00000000", "1596614709.981842"], ["11351.00000", "0.91874831", "1596614502.373790", "r"]], "c": "1588942318"}, "book-100", "XBT/USD"]
[270, {"b": [["11307.00000", "0.13100000", "1596614709.982287"]], "c": "90341009"}, "book-100", "XBT/USD"]
[270, {"b": [["11278.10000", "6.54191430", "1596614709.992976"]], "c": "90341009"}, "book-100", "XBT/USD"]
[270, {"b": [["11282.60000", "1.85608744", "1596614710.016591"]], "c": "90341009"}, "book-100", "XBT/USD"]
[270, {"b": [["11285.80000", "0.34531537", "1596614710.024978"]], "c": "90341009"}, "book-100", "XBT/USD"]
[270, {"a": [["11310.80000", "0.26661985", "1596614710.031465"]], "c": "983820487"}, "book-100", "XBT/USD"]
[270, {"b": [["11281.70000", "0.00000000", "1596614710.048921"], ["11253.90000", "0.48980000", "1596614469.798378", "r"]], "c": "983820487"}, "book-100", "XBT/USD"]
[270, {"b": [["11278.10000", "7.10391954", "1596614710.051321"]], "c": "983820487"}, "book-100", "XBT/USD"]
[270, {"a": [["11308.60000", "0.34356608", "1596614710.074603"]], "c": "857862833"}, "book-100", "XBT/USD"]
[270, {"b": [["11307.00000", "0.88651922", "1596614710.075964"]], "c": "1761008078"}, "book-100", "XBT/USD"]
[270, {"b": [["11282.50000", "0.15287764", "1596614710.094053"]], "c": "1761008078"}, "book-100", "XBT/USD"]
[270, {"a": [["11332.80000", "0.00000000", "1596614710.123220"], ["11351.00000", "0.91874831", "1596614502.373790", "r"]], "c": "1761008078"}, "book-100", "XBT/USD"]
[270, {"b": [["11281.80000", "0.00000000", "1596614710.130107"], ["11253.90000", "0.48980000", "1596614469.798378", "r"]], "c": "1761008078"}, "book-100", "XBT/USD"]
[270, {"a": [["11339.50000", "0.25542160", "1596614710.130369"]], "c": "1761008078"}, "book-100", "XBT/USD"]
[270, {"a": [["11320.30000", "0.00000000", "1596614710.219242"], ["11352.00000", "0.18439000", "1596614637.886152", "r"]], "c": "1761008078"}, "book-100", "XBT/USD"]
[270, {"b": [["11276.80000", "4.29193845", "1596614710.222549"]], "c": "1761008078"}, "book-100", "XBT/USD"]
[270, {"a": [["11338.40000", "1.44359636", "1596614710.256648"]], "c": "1761008078"}, "book-100", "XBT/USD"]
[270, {"a": [["11336.10000", "0.72194463", "1596614710.259710"]], "c": "1761008078"}, "book-100", "XBT/USD"]
[270, {"a": [["11332.80000", "0.34388326", "1596614710.260184"]], "c": "1761008078"}, "book-100", "XBT/USD"]
[270, {"a": [["11332.70000", "0.08191390", "1596614710.615159"]], "c": "1761008078"}, "book-100", "XBT/USD"]
[270, {"b": [["11302.00000", "1.76400000", "1596614710.720612"]], "c": "1761008078"}, "book-100", "XBT/USD"]
[270, {"a": [["11310.00000", "1.76800000", "1596614710.734271"]], "c": "2783805365"}, "book-100", "XBT/USD"]
[270, {"b": [["11307.00000", "0.13100000", "1596614710.787842"]], "c": "4265235658"}, "book-100", "XBT/USD"]
[270, {"b": [["11307.10000", "0.75551922", "1596614710.832083"]], "c": "3419422656"}, "book-100", "XBT/USD"]
[270, {"b": [["11307.10000", "0.00000000", "1596614710.877200"], ["11255.00000", "0.05000000", "1596613962.090152", "r"]], "c": "4265235658"}, "book-100", "XBT/USD"]
[270, {"a": [["11324.30000", "0.00000000", "1596614711.000238"], ["11350.20000", "4.98770000", "1596614486.656272", "r"]]}, {"b": [["11278.80000", "0.00000000", "1596614711.000185"], ["11253.90000", "0.48980000", "1596614469.798378", "r"]], "c": "4265235658"}, "book-100", "XBT/USD"]
[270, {"b": [["11305.50000", "0.20000000", "1596614711.118326"]], "c": "4251842042"}, "book-100", "XBT/USD"]
[270, {"b": [["11305.60000", "0.00000000", "1596614711.137438"], ["11253.40000", "6.40000000", "1596614703.084678", "r"]], "c": "673398245"}, "book-100", "XBT/USD"]
[270, {"b": [["11307.00000", "0.88651922", "1596614711.183935"]], "c": "3905062499"}, "book-100", "XBT/USD"]
[270, {"b": [["11306.70000", "2.82419475", "1596614711.219393"]], "c": "2125140723"}, "book-100", "XBT/USD"]
[270, {"a": [["11310.00000", "0.00000000", "1596614711.332168"], ["11350.40000", "0.00407007", "1596614698.445422", "r"]], "c": "3115426273"}, "book-100", "XBT/USD"]
[270, {"a": [["11310.40000", "1.76700000", "1596614711.343250"]], "c": "2524712946"}, "book-100", "XBT/USD"]
[270, {"b": [["11308.50000", "2.50458098", "1596614711.562317"]], "c": "4002666998"}, "book-100", "XBT/USD"]
[270, {"b": [["11304.90000", "0.21856000", "1596614711.626143"]], "c": "881795457"}, "book-100", "XBT/USD"]
[270, {"b": [["11306.90000", "0.00000000", "1596614711.632466"], ["11253.40000", "6.40000000", "1596614703.084678", "r"]], "c": "2134347834"}, "book-100", "XBT/USD"]
[270, {"a": [["11310.10000", "0.70396000", "1596614711.632542"]], "c": "1664328907"}, "book-100", "XBT/USD"]
[270, {"b": [["11307.00000", "0.13100000", "1596614711.672243"]], "c": "2748456781"}, "book-100", "XBT/USD"]
[270, {"b": [["11294.10000", "0.00000000", "1596614711.677953"], ["11252.80000", "4.44333854", "1596614660.747396", "r"]], "c": "2748456781"}, "book-100", "XBT/USD"]
[270, {"a": [["11318.90000", "0.00000000", "1596614711.678685"], ["11350.40000", "0.00407007", "1596614698.445422", "r"]], "c": "2748456781"}, "book-100", "XBT/USD"]
