[275, ["11292.50000", "11292.60000", "1596613975.128755", "0.09426602", "10.16691246"], "spread", "XBT/USD"]
[275, ["11292.50000", "11292.60000", "1596613975.360395", "0.09426602", "9.86691246"], "spread", "XBT/USD"]
[275, ["11292.50000", "11292.60000", "1596613975.366634", "0.09426602", "10.86691246"], "spread", "XBT/USD"]
[271, [["11292.50000", "0.03731735", "1596613975.379390", "s", "l", ""], ["11292.50000", "0.03855001", "1596613975.382468", "s", "l", ""], ["11292.50000", "0.01613264", "1596613975.384564", "s", "l", ""]], "trade", "XBT/USD"]
[275, ["11292.50000", "11292.60000", "1596613975.384564", "0.00226602", "10.86691246"], "spread", "XBT/USD"]
[275, ["11292.50000", "11292.60000", "1596613975.414391", "0.00226602", "10.88612922"], "spread", "XBT/USD"]
[275, ["11292.50000", "11292.60000", "1596613975.447264", "0.00226602", "13.08612922"], "spread", "XBT/USD"]
[275, ["11292.50000", "11292.60000", "1596613975.860188", "0.00226602", "13.38612922"], "spread", "XBT/USD"]
[275, ["11292.50000", "11292.60000", "1596613977.040585", "0.00226602", "14.28612922"], "spread", "XBT/USD"]
[275, ["11292.50000", "11292.60000", "1596613978.024182", "0.00226602", "17.23612922"], "spread", "XBT/USD"]
[275, ["11292.50000", "11292.60000", "1596613978.774708", "0.00226602", "17.23987062"], "spread", "XBT/USD"]
[275, ["11292.50000", "11292.60000", "1596613978.897711", "0.00226602", "17.23612922"], "spread", "XBT/USD"]
[275, ["11292.50000", "11292.60000", "1596613979.015054", "0.00226602", "18.08612922"], "spread", "XBT/USD"]
[271, [["11292.50000", "0.00200000", "1596613979.152223", "s", "l", ""]], "trade", "XBT/USD"]
[275, ["11292.50000", "11292.60000", "1596613979.152223", "0.00026602", "18.08612922"], "spread", "XBT/USD"]
[275, ["11292.50000", "11292.60000", "1596613979.352174", "0.00026602", "17.78612922"], "spread", "XBT/USD"]
[275, ["11292.50000", "11292.60000", "1596613981.762133", "0.00026602", "17.38612922"], "spread", "XBT/USD"]
[275, ["11292.50000", "11292.60000", "1596613981.780164", "0.00026602", "17.78612922"], "spread", "XBT/USD"]
[275, ["11292.50000", "11292.60000", "1596613981.889600", "0.00026602", "16.46622922"], "spread", "XBT/USD"]
[275, ["11292.50000", "11292.60000", "1596613982.155039", "0.00026602", "16.76622922"], "spread", "XBT/USD"]
[275, ["11292.50000", "11292.60000", "1596613982.360354", "0.00026602", "16.73100922"], "spread", "XBT/USD"]
[275, ["11292.50000", "11292.60000", "1596613986.586194", "0.00026602", "26.73100922"], "spread", "XBT/USD"]
[271, [["11292.50000", "0.00026602", "1596613987.251806", "s", "l", ""]], "trade", "XBT/USD"]
[275, ["11287.00000", "11292.50000", "1596613987.250609", "0.40000000", "0.09973398"], "spread", "XBT/USD"]
[275, ["11287.00000", "11287.10000", "1596613987.309570", "0.40000000", "0.27193902"], "spread", "XBT/USD"]
[275, ["11287.00000", "11287.10000", "1596613987.446101", "0.40000000", "0.53921493"], "spread", "XBT/USD"]
[275, ["11287.00000", "11287.10000", "1596613987.447403", "0.40000000", "0.83921493"], "spread", "XBT/USD"]
[275, ["11287.00000", "11287.10000", "1596613987.453657", "0.40000000", "2.83921493"], "spread", "XBT/USD"]
[275, ["11287.00000", "11287.10000", "1596613987.494535", "0.40000000", "3.03521493"], "spread", "XBT/USD"]
[275, ["11287.00000", "11287.10000", "1596613987.504517", "0.40000000", "3.71970493"], "spread", "XBT/USD"]
[275, ["11287.00000", "11287.10000", "1596613987.536979", "0.40000000", "4.38483829"], "spread", "XBT/USD"]
[275, ["11287.00000", "11287.10000", "1596613987.549183", "0.40000000", "4.08483829"], "spread", "XBT/USD"]
[275, ["11287.00000", "11287.10000", "1596613987.572699", "0.40000000", "4.10405505"], "spread", "XBT/USD"]
[275, ["11287.00000", "11287.10000", "1596613987.680232", "0.40000000", "5.10405505"], "spread", "XBT/USD"]
[275, ["11287.00000", "11287.10000", "1596613987.825949", "0.40000000", "5.14258631"], "spread", "XBT/USD"]
[271, [["11287.00000", "0.07087680", "1596613987.867941", "s", "l", ""]], "trade", "XBT/USD"]
[275, ["11287.00000", "11287.10000", "1596613987.867942", "0.32912320", "5.14258631"], "spread", "XBT/USD"]
[275, ["11287.00000", "11287.10000", "1596613987.910681", "0.32912320", "9.57458631"], "spread", "XBT/USD"]
[275, ["11287.00000", "11287.10000", "1596613987.932253", "0.32912320", "10.42458631"], "spread", "XBT/USD"]
[275, ["11287.00000", "11287.10000", "1596613987.993680", "0.32912320", "9.57458631"], "spread", "XBT/USD"]
[275, ["11287.00000", "11287.10000", "1596613988.131360", "0.32912320", "10.07458631"], "spread", "XBT/USD"]
[275, ["11287.00000", "11287.10000", "1596613989.562144", "0.32912320", "10.07590635"], "spread", "XBT/USD"]
[275, ["11287.00000", "11287.10000", "1596613992.226254", "0.32912320", "11.92537452"], "spread", "XBT/USD"]
[275, ["11287.00000", "11287.10000", "1596613992.770208", "0.32912320", "12.22537452"], "spread", "XBT/USD"]
[275, ["11287.00000", "11287.10000", "1596613992.906700", "0.32912320", "12.50111626"], "spread", "XBT/USD"]
[275, ["11287.00000", "11287.10000", "1596613993.783545", "0.72912320", "12.50111626"], "spread", "XBT/USD"]
[275, ["11287.00000", "11287.10000", "1596613993.797494", "0.32912320", "12.50111626"], "spread", "XBT/USD"]
[275, ["11287.00000", "11287.10000", "1596613993.854632", "0.72912320", "12.50111626"], "spread", "XBT/USD"]
[275, ["11287.00000", "11287.10000", "1596613993.904085", "1.12912320", "12.50111626"], "spread", "XBT/USD"]
[275, ["11287.00000", "11287.10000", "1596613993.906545", "1.12912320", "12.00111626"], "spread", "XBT/USD"]
[275, ["11287.00000", "11287.10000", "1596613993.922830", "1.12912320", "10.15164809"], "spread", "XBT/USD"]
[275, ["11287.00000", "11287.10000", "1596613993.938011", "3.12912320", "10.15164809"], "spread", "XBT/USD"]
[275, ["11287.00000", "11287.10000", "1596613993.942904", "3.12912320", "8.15164809"], "spread", "XBT/USD"]
[275, ["11287.00000", "11287.10000", "1596613994.075742", "3.12912320", "7.48651473"], "spread", "XBT/USD"]
[275, ["11287.00000", "11287.10000", "1596613994.123323", "3.12912320", "3.05451473"], "spread", "XBT/USD"]
[275, ["11287.00000", "11287.10000", "1596613994.200711", "1.12912320", "3.05451473"], "spread", "XBT/USD"]
[275, ["11287.00000", "11287.10000", "1596613994.322486", "1.12912320", "2.37002473"], "spread", "XBT/USD"]
[275, ["11287.00000", "11287.10000", "1596613994.323260", "1.12912320", "6.79702473"], "spread", "XBT/USD"]
[275, ["11287.00000", "11287.10000", "1596613994.395780", "1.12912320", "2.37002473"], "spread", "XBT/USD"]
[275, ["11287.00000", "11287.10000", "1596613994.411732", "1.12912320", "2.07002473"], "spread", "XBT/USD"]
[275, ["11287.00000", "11287.10000", "1596613994.718282", "1.12912320", "4.34992473"], "spread", "XBT/USD"]
[275, ["11287.00000", "11287.10000", "1596613995.664469", "1.12912320", "3.34992473"], "spread", "XBT/USD"]
[275, ["11287.00000", "11287.10000", "1596613995.955147", "1.12912320", "3.15392473"], "spread", "XBT/USD"]
[275, ["11287.00000", "11287.10000", "1596613995.973198", "1.12912320", "7.57492473"], "spread", "XBT/USD"]
[275, ["11287.00000", "11287.10000", "1596613996.533952", "1.12912320", "7.77492473"], "spread", "XBT/USD"]
[275, ["11287.00000", "11287.10000", "1596613996.628536", "0.32912320", "7.77492473"], "spread", "XBT/USD"]
[275, ["11287.00000", "11287.10000", "1596613996.787484", "0.32912320", "8.07492473"], "spread", "XBT/USD"]
[275, ["11287.00000", "11287.10000", "1596613996.804606", "0.32912320", "8.57492473"], "spread", "XBT/USD"]
[275, ["11287.00000", "11287.10000", "1596613996.868598", "0.32912320", "8.07492473"], "spread", "XBT/USD"]
[275, ["11287.00000", "11287.10000", "1596613997.332796", "0.32912320", "10.07492473"], "spread", "XBT/USD"]
[275, ["11287.00000", "11287.10000", "1596613997.957676", "0.32912320", "10.57492473"], "spread", "XBT/USD"]
[275, ["11287.00000", "11287.10000", "1596613999.040864", "0.32912320", "8.29502473"], "spread", "XBT/USD"]
[275, ["11287.00000", "11287.10000", "1596613999.083175", "0.32912320", "10.05502473"], "spread", "XBT/USD"]
[275, ["11287.00000", "11287.10000", "1596613999.703958", "0.32912320", "10.07039630"], "spread", "XBT/USD"]
[275, ["11287.00000", "11287.10000", "1596614002.849142", "0.32912320", "10.26639630"], "spread", "XBT/USD"]
[275, ["11287.00000", "11287.10000", "1596614003.628658", "0.32912320", "11.26639630"], "spread", "XBT/USD"]
[275, ["11287.00000", "11287.10000", "1596614005.340124", "0.32912320", "10.96639630"], "spread", "XBT/USD"]
[275, ["11287.00000", "11287.10000", "1596614005.825534", "0.32912320", "11.26639630"], "spread", "XBT/USD"]
[275, ["11287.00000", "11287.10000", "1596614005.876669", "0.32912320", "10.76639630"], "spread", "XBT/USD"]
[275, ["11287.00000", "11287.10000", "1596614006.176599", "0.32912320", "10.46639630"], "spread", "XBT/USD"]
[275, ["11287.00000", "11287.10000", "1596614006.674030", "0.32912320", "10.76639630"], "spread", "XBT/USD"]
[275, ["11287.00000", "11287.10000", "1596614010.200137", "0.32912320", "10.85499341"], "spread", "XBT/USD"]
[275, ["11287.00000", "11287.10000", "1596614010.777074", "0.32912320", "10.55499341"], "spread", "XBT/USD"]
[275, ["11287.00000", "11287.10000", "1596614011.276095", "0.32912320", "10.85499341"], "spread", "XBT/USD"]
[275, ["11287.00000", "11287.10000", "1596614013.633715", "0.32912320", "10.55499341"], "spread", "XBT/USD"]
[275, ["11287.00000", "11287.10000", "1596614014.133573", "0.32912320", "10.85499341"], "spread", "XBT/USD"]
[275, ["11287.00000", "11287.10000", "1596614017.400005", "0.32912320", "10.55499341"], "spread", "XBT/USD"]
[275, ["11287.00000", "11287.10000", "1596614017.901475", "0.32912320", "10.85499341"], "spread", "XBT/USD"]
[275, ["11287.00000", "11287.10000", "1596614019.818602", "0.72912320", "10.85499341"], "spread", "XBT/USD"]
[275, ["11287.00000", "11287.10000", "1596614027.836639", "0.32912320", "10.85499341"], "spread", "XBT/USD"]
[271, [["11287.10000", "0.27193902", "1596614029.725097", "b", "m", ""], ["11287.10000", "0.26727591", "1596614029.731871", "b", "m", ""], ["11287.10000", "0.01921676", "1596614029.733995", "b", "m", ""], ["11287.10000", "0.03853126", "1596614029.736580", "b", "m", ""], ["11287.10000", "0.00132004", "1596614029.739330", "b", "m", ""], ["11287.10000", "0.27574174", "1596614029.741031", "b", "m", ""], ["11287.10000", "0.12597527", "1596614029.742612", "b", "m", ""]], "trade", "XBT/USD"]
[275, ["11287.00000", "11287.10000", "1596614029.742612", "0.32912320", "9.85499341"], "spread", "XBT/USD"]
[275, ["11287.00000", "11287.10000", "1596614029.876673", "0.32912320", "7.85499341"], "spread", "XBT/USD"]
[271, [["11287.10000", "0.36000000", "1596614030.900121", "b", "m", ""]], "trade", "XBT/USD"]
[275, ["11287.00000", "11287.10000", "1596614030.900121", "0.32912320", "7.49499341"], "spread", "XBT/USD"]
[275, ["11287.00000", "11287.10000", "1596614032.067453", "0.32912320", "7.50460179"], "spread", "XBT/USD"]
[275, ["11287.00000", "11287.10000", "1596614032.478438", "0.32912320", "9.50460179"], "spread", "XBT/USD"]
[275, ["11287.00000", "11287.10000", "1596614033.813636", "0.32912320", "9.77187935"], "spread", "XBT/USD"]
[275, ["11287.00000", "11287.10000", "1596614034.656532", "0.32912320", "10.27187935"], "spread", "XBT/USD"]
[275, ["11287.00000", "11287.10000", "1596614034.761838", "0.32912320", "10.77187935"], "spread", "XBT/USD"]
, "s", "l", ""]], "trade", "XBT/USD"]
[270, {"b": [["11292.50000", "0.05694867", "1596613975.379391"], ["11292.50000", "0.01839866", "1596613975.382468"], ["11292.50000", "0.00226602", "1596613975.384564"]], "c": "2414513194"}, "book-100", "XBT/USD"]
[270, {"a": [["11292.70000", "4.68677561", "1596613975.397432"]], "c": "4050111807"}, "book-100", "XBT/USD"]
[270, {"a": [["11293.00000", "5.80462017", "1596613975.398217"]], "c": "966807158"}, "book-100", "XBT/USD"]
[270, {"a": [["11301.30000", "0.00000000", "1596613975.402191"], ["11335.60000", "0.48800000", "1596613131.975628", "r"]], "c": "966807158"}, "book-100", "XBT/USD"]
[270, {"a": [["11292.60000", "10.88612922", "1596613975.414391"]], "c": "3333736497"}, "book-100", "XBT/USD"]
[270, {"b": [["11270.70000", "4.30175957", "1596613975.430061"]], "c": "3333736497"}, "book-100", "XBT/USD"]
[270, {"a": [["11292.60000", "13.08612922", "1596613975.447264"]], "c": "165745319"}, "book-100", "XBT/USD"]
[270, {"b": [["11284.30000", "0.48270000", "1596613975.536579"]], "c": "1721902622"}, "book-100", "XBT/USD"]
[270, {"b": [["11284.00000", "0.27116000", "1596613975.553541"]], "c": "816042606"}, "book-100", "XBT/USD"]
[270, {"b": [["11272.60000", "1.13222032", "1596613975.559727"]], "c": "816042606"}, "book-100", "XBT/USD"]
[270, {"b": [["11284.40000", "0.00000000", "1596613975.571796"], ["11243.90000", "0.75800000", "1596613974.983535", "r"]], "c": "1616753302"}, "book-100", "XBT/USD"]
[270, {"b": [["11284.00000", "0.07116000", "1596613975.751113"]], "c": "640047279"}, "book-100", "XBT/USD"]
[270, {"a": [["11292.60000", "13.38612922", "1596613975.860188"]], "c": "2808329477"}, "book-100", "XBT/USD"]
[270, {"a": [["11298.60000", "0.00000000", "1596613975.880922"], ["11337.00000", "2.74026360", "1596613855.319380", "r"]], "c": "2808329477"}, "book-100", "XBT/USD"]
[270, {"b": [["11283.40000", "0.20000000", "1596613975.922164"]], "c": "2284189422"}, "book-100", "XBT/USD"]
[270, {"a": [["11307.00000", "0.18439000", "1596613975.935547"]], "c": "2284189422"}, "book-100", "XBT/USD"]
[270, {"a": [["11296.30000", "1.89900000", "1596613975.935721"]], "c": "2284189422"}, "book-100", "XBT/USD"]
[270, {"a": [["11324.60000", "0.75800000", "1596613975.970924"]], "c": "2284189422"}, "book-100", "XBT/USD"]
[270, {"a": [["11293.70000", "0.33491762", "1596613976.257615"]], "c": "4252242986"}, "book-100", "XBT/USD"]
[270, {"b": [["11266.90000", "0.00000000", "1596613976.309097"], ["11243.90000", "0.75800000", "1596613974.983535", "r"]], "c": "4252242986"}, "book-100", "XBT/USD"]
[270, {"a": [["11302.60000", "0.00000000", "1596613976.312513"], ["11335.30000", "20.00000000", "1596613945.191313", "r"]], "c": "4252242986"}, "book-100", "XBT/USD"]
[270, {"b": [["11269.80000", "0.50000000", "1596613976.427386"]], "c": "4252242986"}, "book-100", "XBT/USD"]
[270, {"b": [["11274.00000", "6.95348739", "1596613976.516631"]], "c": "4252242986"}, "book-100", "XBT/USD"]
[270, {"b": [["11282.50000", "2.66400000", "1596613976.550500"]], "c": "1357556047"}, "book-100", "XBT/USD"]
[270, {"a": [["11299.20000", "0.57295589", "1596613976.644878"]], "c": "1357556047"}, "book-100", "XBT/USD"]
[270, {"b": [["11280.00000", "0.70000000", "1596613976.645111"]], "c": "1357556047"}, "book-100", "XBT/USD"]
[270, {"a": [["11293.20000", "1.73473371", "1596613976.798844"]], "c": "1520725358"}, "book-100", "XBT/USD"]
[270, {"b": [["11280.30000", "1.50000000", "1596613976.801379"]], "c": "1520725358"}, "book-100", "XBT/USD"]
[270, {"b": [["11283.80000", "0.66503266", "1596613976.886852"]], "c": "134106570"}, "book-100", "XBT/USD"]
[270, {"b": [["11270.00000", "0.88672533", "1596613976.887075"]], "c": "134106570"}, "book-100", "XBT/USD"]
[270, {"b": [["11283.20000", "0.66503266", "1596613976.887578"]], "c": "1566382899"}, "book-100", "XBT/USD"]
[270, {"b": [["11278.10000", "0.88676307", "1596613976.888225"]], "c": "1566382899"}, "book-100", "XBT/USD"]
[270, {"a": [["11333.90000", "0.23957082", "1596613976.981011"]], "c": "1566382899"}, "book-100", "XBT/USD"]
[270, {"a": [["11292.60000", "14.28612922", "1596613977.040585"]], "c": "890753383"}, "book-100", "XBT/USD"]
[270, {"a": [["11307.00000", "0.00000000", "1596613977.140781"], ["11335.60000", "0.48800000", "1596613131.975628", "r"]], "c": "890753383"}, "book-100", "XBT/USD"]
[270, {"a": [["11293.20000", "0.23473371", "1596613977.246309"]], "c": "2252859771"}, "book-100", "XBT/USD"]
[270, {"a": [["11293.80000", "0.79899642", "1596613977.270608"]], "c": "2252859771"}, "book-100", "XBT/USD"]
[270, {"b": [["11284.90000", "0.00000000", "1596613977.270687"], ["11245.70000", "5.90000000", "1596612820.405386", "r"]], "c": "1775366540"}, "book-100", "XBT/USD"]
[270, {"b": [["11284.70000", "2.00000000", "1596613977.319187"]], "c": "1196857406"}, "book-100", "XBT/USD"]
[270, {"b": [["11284.80000", "0.62960000", "1596613977.371491"]], "c": "2198462151"}, "book-100", "XBT/USD"]
[270, {"b": [["11284.30000", "0.00000000", "1596613977.379878"], ["11245.80000", "6.39461152", "1596613526.295255", "r"]], "c": "532591601"}, "book-100", "XBT/USD"]
[270, {"a": [["11294.70000", "2.38630662", "1596613977.470722"]], "c": "532591601"}, "book-100", "XBT/USD"]
[270, {"b": [["11254.60000", "0.00000000", "1596613977.472090"], ["11245.70000", "5.90000000", "1596612820.405386", "r"]], "c": "532591601"}, "book-100", "XBT/USD"]
[270, {"b": [["11253.50000", "0.76985850", "1596613977.473297"]], "c": "532591601"}, "book-100", "XBT/USD"]
[270, {"a": [["11313.60000", "0.76985850", "1596613977.474011"]], "c": "532591601"}, "book-100", "XBT/USD"]
[270, {"a": [["11314.40000", "0.00000000", "1596613977.474485"], ["11335.60000", "0.48800000", "1596613131.975628", "r"]], "c": "532591601"}, "book-100", "XBT/USD"]
[270, {"b": [["11283.50000", "0.03750000", "1596613977.498245"]], "c": "4084988627"}, "book-100", "XBT/USD"]
[270, {"b": [["11280.50000", "0.00000000", "1596613977.558366"], ["11245.80000", "6.39461152", "1596613526.295255", "r"]], "c": "4084988627"}, "book-100", "XBT/USD"]
[270, {"b": [["11280.40000", "0.26721350", "1596613977.661197"]], "c": "4084988627"}, "book-100", "XBT/USD"]
[270, {"a": [["11301.10000", "2.00000000", "1596613977.786799"]], "c": "4084988627"}, "book-100", "XBT/USD"]
[270, {"b": [["11279.50000", "0.00000000", "1596613977.851668"], ["11245.80000", "6.39461152", "1596613526.295255", "r"]], "c": "4084988627"}, "book-100", "XBT/USD"]
[270, {"a": [["11293.20000", "0.13852277", "1596613977.871140"]], "c": "3334662311"}, "book-100", "XBT/USD"]
[270, {"b": [["11259.50000", "7.19775834", "1596613977.893823"]], "c": "3334662311"}, "book-100", "XBT/USD"]
[270, {"a": [["11292.60000", "17.23612922", "1596613978.024182"]], "c": "2690132138"}, "book-100", "XBT/USD"]
[270, {"b": [["11279.70000", "0.00000000", "1596613978.085809"], ["11245.80000", "6.39461152", "1596613526.295255", "r"]], "c": "2690132138"}, "book-100", "XBT/USD"]
[270, {"b": [["11279.30000", "0.00000000", "1596613978.088302"], ["11245.70000", "5.90000000", "1596612820.405386", "r"]], "c": "2690132138"}, "book-100", "XBT/USD"]
[270, {"a": [["11307.30000", "0.00000000", "1596613978.299178"], ["11335.60000", "0.48800000", "1596613131.975628", "r"]], "c": "2690132138"}, "book-100", "XBT/USD"]
[270, {"a": [["11301.80000", "0.04606954", "1596613978.300393"]], "c": "2690132138"}, "book-100", "XBT/USD"]
[270, {"b": [["11280.40000", "0.45619350", "1596613978.412485"]], "c": "2690132138"}, "book-100", "XBT/USD"]
[270, {"b": [["11280.40000", "0.26721350", "1596613978.530340"]], "c": "2690132138"}, "book-100", "XBT/USD"]
[270, {"b": [["11281.50000", "0.00000000", "1596613978.614854"], ["11245.00000", "3.80189035", "1596613945.191407", "r"]], "c": "2690132138"}, "book-100", "XBT/USD"]
[270, {"a": [["11294.70000", "0.88630662", "1596613978.646657"]], "c": "2690132138"}, "book-100", "XBT/USD"]
[270, {"b": [["11265.50000", "0.88454000", "1596613978.686869"]], "c": "2690132138"}, "book-100", "XBT/USD"]
[270, {"b": [["11270.20000", "0.70660000", "1596613978.697060"]], "c": "2690132138"}, "book-100", "XBT/USD"]
[270, {"b": [["11283.80000", "0.00000000", "1596613978.758911"], ["11245.00000", "3.80189035", "1596613945.191407", "r"]], "c": "4193168440"}, "book-100", "XBT/USD"]
[270, {"a": [["11301.80000", "0.00000000", "1596613978.773551"], ["11335.60000", "0.48800000", "1596613131.975628", "r"]], "c": "4193168440"}, "book-100", "XBT/USD"]
[270, {"a": [["11292.60000", "17.23987062", "1596613978.774708"]], "c": "3177929838"}, "book-100", "XBT/USD"]
[270, {"a": [["11293.20000", "1.63852277", "1596613978.801302"]], "c": "791344424"}, "book-100", "XBT/USD"]
[270, {"b": [["11284.30000", "0.65600000", "1596613978.812127"]], "c": "288411690"}, "book-100", "XBT/USD"]
[270, {"a": [["11301.20000", "0.00000000", "1596613978.816080"], ["11337.00000", "2.74026360", "1596613855.319380", "r"]], "c": "288411690"}, "book-100", "XBT/USD"]
[270, {"b": [["11284.80000", "0.00000000", "1596613978.819058"], ["11245.00000", "3.80189035", "1596613945.191407", "r"]], "c": "1930146468"}, "book-100", "XBT/USD"]
[270, {"b": [["11276.60000", "0.18898000", "1596613978.844833"]], "c": "1930146468"}, "book-100", "XBT/USD"]
[270, {"b": [["11279.40000", "0.63581358", "1596613978.872792"]], "c": "1930146468"}, "book-100", "XBT/USD"]
[270, {"a": [["11292.60000", "17.23612922", "1596613978.897711"]], "c": "4048012181"}, "book-100", "XBT/USD"]
[270, {"a": [["11301.80000", "0.04606954", "1596613978.901131"]], "c": "4048012181"}, "book-100", "XBT/USD"]
[270, {"b": [["11273.40000", "0.00000000", "1596613978.913379"], ["11245.70000", "5.90000000", "1596612820.405386", "r"]], "c": "4048012181"}, "book-100", "XBT/USD"]
[270, {"b": [["11273.00000", "0.00000000", "1596613978.914319"], ["11245.00000", "3.80189035", "1596613945.191407", "r"]], "c": "4048012181"}, "book-100", "XBT/USD"]
[270, {"b": [["11281.60000", "0.00000000", "1596613978.946905"], ["11244.80000", "1.51500000", "1596613533.988674", "r"]], "c": "4048012181"}, "book-100", "XBT/USD"]
[270, {"b": [["11274.60000", "0.50000000", "1596613978.954074"]], "c": "4048012181"}, "book-100", "XBT/USD"]
[270, {"a": [["11297.80000", "1.49816397", "1596613978.968794"]], "c": "4048012181"}, "book-100", "XBT/USD"]
[270, {"b": [["11269.20000", "0.30000000", "1596613979.004951"]], "c": "4048012181"}, "book-100", "XBT/USD"]
[270, {"b": [["11274.90000", "0.00000000", "1596613979.007335"], ["11244.80000", "1.51500000", "1596613533.988674", "r"]], "c": "4048012181"}, "book-100", "XBT/USD"]
[270, {"b": [["11273.10000", "0.00000000", "1596613979.008112"], ["11244.40000", "1.04640000", "1596613107.587746", "r"]], "c": "4048012181"}, "book-100", "XBT/USD"]
[270, {"b": [["11269.40000", "3.56835295", "1596613979.011386"]], "c": "4048012181"}, "book-100", "XBT/USD"]
[270, {"a": [["11292.60000", "18.08612922", "1596613979.015054"]], "c": "1073473576"}, "book-100", "XBT/USD"]
[270, {"b": [["11276.40000", "0.00000000", "1596613979.018589"], ["11244.30000", "0.00525234", "1596613333.987036", "r"]], "c": "1073473576"}, "book-100", "XBT/USD"]
[270, {"b": [["11284.80000", "0.65600000", "1596613979.029417"]], "c": "4088995610"}, "book-100", "XBT/USD"]
[270, {"b": [["11269.40000", "0.00000000", "1596613979.033394"], ["11244.30000", "0.00525234", "1596613333.987036", "r"]], "c": "4088995610"}, "book-100", "XBT/USD"]
[270, {"b": [["11275.40000", "0.00000000", "1596613979.040978"], ["11243.90000", "0.75800000", "1596613974.983535", "r"]], "c": "4088995610"}, "book-100", "XBT/USD"]
[270, {"b": [["11278.60000", "0.88600284", "1596613979.048631"]], "c": "4088995610"}, "book-100", "XBT/USD"]
[270, {"b": [["11284.30000", "0.00000000", "1596613979.075394"], ["11242.40000", "17.60000000", "1596613517.808330", "r"]], "c": "152128587"}, "book-100", "XBT/USD"]
[270, {"b": [["11281.80000", "0.00000000", "1596613979.078507"], ["11241.50000", "4.50000000", "1596613851.617903", "r"]], "c": "152128587"}, "book-100", "XBT/USD"]
