[275, ["11321.30000", "11321.40000", "1596615085.297067", "4.50302153", "0.30051097"], "spread", "XBT/USD"]
[275, ["11321.30000", "11321.40000", "1596615087.584444", "4.10302153", "0.30051097"], "spread", "XBT/USD"]
[275, ["11321.30000", "11321.40000", "1596615089.628638", "3.60302153", "0.30051097"], "spread", "XBT/USD"]
[275, ["11321.30000", "11321.40000", "1596615090.950083", "4.10302153", "0.30051097"], "spread", "XBT/USD"]
[275, ["11321.30000", "11321.40000", "1596615096.586693", "4.10302153", "0.30334467"], "spread", "XBT/USD"]
[275, ["11321.30000", "11321.40000", "1596615096.684041", "4.47802153", "0.30334467"], "spread", "XBT/USD"]
[275, ["11321.30000", "11321.40000", "1596615099.325647", "3.97802153", "0.30334467"], "spread", "XBT/USD"]
[275, ["11321.30000", "11321.40000", "1596615100.517402", "4.47802153", "0.30334467"], "spread", "XBT/USD"]
[275, ["11321.30000", "11321.40000", "1596615100.727035", "4.47802153", "0.30051097"], "spread", "XBT/USD"]
[275, ["11321.30000", "11321.40000", "1596615100.929427", "4.47802153", "0.30251159"], "spread", "XBT/USD"]
[275, ["11321.30000", "11321.40000", "1596615100.981481", "4.47802153", "0.30463873"], "spread", "XBT/USD"]
[275, ["11321.30000", "11321.40000", "1596615102.116448", "4.74429476", "0.30463873"], "spread", "XBT/USD"]
[275, ["11321.30000", "11321.40000", "1596615103.051160", "5.14429476", "0.30463873"], "spread", "XBT/USD"]
[275, ["11321.30000", "11321.40000", "1596615103.833355", "5.89981398", "0.30463873"], "spread", "XBT/USD"]
[275, ["11321.30000", "11321.40000", "1596615104.154079", "6.57285074", "0.30463873"], "spread", "XBT/USD"]
[275, ["11321.30000", "11321.40000", "1596615104.255153", "7.06785074", "0.30463873"], "spread", "XBT/USD"]
[275, ["11321.30000", "11321.40000", "1596615104.259836", "6.31233152", "0.30463873"], "spread", "XBT/USD"]
[275, ["11321.30000", "11321.40000", "1596615104.302885", "7.06785074", "0.30463873"], "spread", "XBT/USD"]
[275, ["11321.30000", "11321.40000", "1596615105.445698", "6.31233152", "0.30463873"], "spread", "XBT/USD"]
[275, ["11321.30000", "11321.40000", "1596615105.632477", "7.06785074", "0.30463873"], "spread", "XBT/USD"]
[275, ["11321.30000", "11321.40000", "1596615106.069311", "6.57285074", "0.30463873"], "spread", "XBT/USD"]
[275, ["11321.30000", "11321.40000", "1596615106.251605", "7.06785074", "0.30463873"], "spread", "XBT/USD"]
[271, [["11321.40000", "0.30051097", "1596615107.214845", "b", "m", ""], ["11321.40000", "0.00200062", "1596615107.223665", "b", "m", ""], ["11321.40000", "0.00212714", "1596615107.225320", "b", "m", ""], ["11323.00000", "0.08832869", "1596615107.226977", "b", "m", ""], ["11326.50000", "0.01536714", "1596615107.228683", "b", "m", ""], ["11326.70000", "0.26625442", "1596615107.230390", "b", "m", ""], ["11326.80000", "0.20873236", "1596615107.231817", "b", "m", ""], ["11326.90000", "0.52167866", "1596615107.233367", "b", "m", ""]], "trade", "XBT/USD"]
[275, ["11321.30000", "11326.90000", "1596615107.233367", "7.06785074", "0.14088375"], "spread", "XBT/USD"]
[275, ["11321.40000", "11326.90000", "1596615107.300374", "0.61280000", "0.14088375"], "spread", "XBT/USD"]
[275, ["11321.40000", "11326.90000", "1596615107.334933", "1.42780000", "0.14088375"], "spread", "XBT/USD"]
[275, ["11321.50000", "11326.90000", "1596615107.350403", "0.75551922", "0.14088375"], "spread", "XBT/USD"]
[275, ["11321.50000", "11326.80000", "1596615107.395508", "0.75551922", "0.08830724"], "spread", "XBT/USD"]
[275, ["11321.50000", "11326.80000", "1596615107.396170", "1.25551922", "0.08830724"], "spread", "XBT/USD"]
[275, ["11324.10000", "11326.80000", "1596615107.424264", "0.66251973", "0.08830724"], "spread", "XBT/USD"]
[275, ["11324.20000", "11326.80000", "1596615107.491684", "0.75551922", "0.08830724"], "spread", "XBT/USD"]
[275, ["11324.60000", "11326.80000", "1596615107.557064", "2.00000000", "0.08830724"], "spread", "XBT/USD"]
[275, ["11324.70000", "11326.80000", "1596615107.658277", "0.75551922", "0.08830724"], "spread", "XBT/USD"]
[275, ["11324.70000", "11326.80000", "1596615107.804364", "0.75551922", "0.09041222"], "spread", "XBT/USD"]
[275, ["11325.20000", "11326.80000", "1596615107.805304", "2.00000000", "0.09041222"], "spread", "XBT/USD"]
[275, ["11325.20000", "11326.40000", "1596615107.887516", "2.00000000", "2.00000000"], "spread", "XBT/USD"]
[275, ["11325.30000", "11326.40000", "1596615107.900315", "0.75551922", "2.00000000"], "spread", "XBT/USD"]
[275, ["11325.30000", "11326.40000", "1596615108.121112", "0.75551922", "2.00322134"], "spread", "XBT/USD"]
[275, ["11325.30000", "11326.40000", "1596615108.481932", "2.75551922", "2.00322134"], "spread", "XBT/USD"]
[275, ["11325.30000", "11326.40000", "1596615108.493678", "2.75551922", "0.00322134"], "spread", "XBT/USD"]
[275, ["11325.30000", "11326.30000", "1596615108.495970", "2.75551922", "0.08829359"], "spread", "XBT/USD"]
[275, ["11325.30000", "11326.30000", "1596615108.523615", "2.00000000", "0.08829359"], "spread", "XBT/USD"]
[275, ["11325.40000", "11326.30000", "1596615108.598992", "0.75551922", "0.08829359"], "spread", "XBT/USD"]
[275, ["11325.40000", "11326.30000", "1596615108.839638", "2.75551922", "0.08829359"], "spread", "XBT/USD"]
[275, ["11325.40000", "11326.30000", "1596615108.880066", "2.00000000", "0.08829359"], "spread", "XBT/USD"]
[275, ["11325.50000", "11326.30000", "1596615108.927014", "0.75551922", "0.08829359"], "spread", "XBT/USD"]
[275, ["11325.40000", "11326.30000", "1596615108.880066", "2.00000000", "0.08829359"], "spread", "XBT/USD"]
[275, ["11325.60000", "11326.30000", "1596615109.013078", "0.75551922", "0.08829359"], "spread", "XBT/USD"]
[275, ["11325.40000", "11326.30000", "1596615108.880066", "2.00000000", "0.08829359"], "spread", "XBT/USD"]
[275, ["11325.90000", "11326.30000", "1596615109.075602", "2.00000000", "0.08829359"], "spread", "XBT/USD"]
[275, ["11326.00000", "11326.30000", "1596615109.185896", "0.75551922", "0.08829359"], "spread", "XBT/USD"]
[275, ["11325.90000", "11326.30000", "1596615109.075602", "2.00000000", "0.08829359"], "spread", "XBT/USD"]
[275, ["11326.10000", "11326.30000", "1596615109.269548", "0.75551922", "0.08829359"], "spread", "XBT/USD"]
[275, ["11325.90000", "11326.30000", "1596615109.075602", "2.00000000", "0.08829359"], "spread", "XBT/USD"]
[275, ["11326.10000", "11326.30000", "1596615109.331502", "2.65000000", "0.08829359"], "spread", "XBT/USD"]
[275, ["11326.10000", "11326.30000", "1596615109.442117", "2.65000000", "0.09151493"], "spread", "XBT/USD"]
[275, ["11326.20000", "11326.30000", "1596615109.443513", "0.75551922", "0.09151493"], "spread", "XBT/USD"]
[275, ["11326.20000", "11326.30000", "1596615109.498234", "0.75551922", "0.09361991"], "spread", "XBT/USD"]
[275, ["11326.20000", "11326.30000", "1596615109.542593", "1.55551922", "0.09361991"], "spread", "XBT/USD"]
[275, ["11326.20000", "11326.30000", "1596615109.552446", "0.80000000", "0.09361991"], "spread", "XBT/USD"]
[275, ["11326.20000", "11326.30000", "1596615109.810013", "2.80000000", "0.09361991"], "spread", "XBT/USD"]
[275, ["11326.20000", "11326.30000", "1596615109.812784", "2.00000000", "0.09361991"], "spread", "XBT/USD"]
[275, ["11324.20000", "11326.30000", "1596615110.077838", "0.53750000", "0.09361991"], "spread", "XBT/USD"]
[275, ["11324.30000", "11326.30000", "1596615110.524100", "0.61280000", "0.09361991"], "spread", "XBT/USD"]
[275, ["11324.40000", "11326.30000", "1596615110.621849", "0.38000000", "0.09361991"], "spread", "XBT/USD"]
[275, ["11324.70000", "11326.30000", "1596615110.775415", "0.66251973", "0.09361991"], "spread", "XBT/USD"]
[275, ["11325.40000", "11326.30000", "1596615110.798188", "0.66251973", "0.09361991"], "spread", "XBT/USD"]
[275, ["11325.40000", "11326.30000", "1596615111.127481", "0.66251973", "0.09039857"], "spread", "XBT/USD"]
[275, ["11325.40000", "11326.30000", "1596615111.286598", "0.66251973", "0.08829359"], "spread", "XBT/USD"]
[275, ["11325.40000", "11326.30000", "1596615111.527570", "0.66251973", "0.09035109"], "spread", "XBT/USD"]
[275, ["11325.90000", "11326.30000", "1596615112.801464", "2.00000000", "0.09035109"], "spread", "XBT/USD"]
[275, ["11326.10000", "11326.30000", "1596615112.923922", "0.66248931", "0.09035109"], "spread", "XBT/USD"]
[275, ["11326.20000", "11326.30000", "1596615113.059309", "2.00000000", "0.09035109"], "spread", "XBT/USD"]
[275, ["11326.20000", "11326.30000", "1596615113.121960", "3.10000000", "0.09035109"], "spread", "XBT/USD"]
[275, ["11326.20000", "11326.30000", "1596615113.897137", "3.55000000", "0.09035109"], "spread", "XBT/USD"]
[275, ["11326.20000", "11326.30000", "1596615114.222281", "5.10000000", "0.09035109"], "spread", "XBT/USD"]
[275, ["11326.20000", "11326.30000", "1596615115.253896", "3.10000000", "0.09035109"], "spread", "XBT/USD"]
[275, ["11326.20000", "11326.30000", "1596615115.791896", "2.65000000", "0.09035109"], "spread", "XBT/USD"]
[275, ["11326.20000", "11326.30000", "1596615116.001541", "3.40551922", "0.09035109"], "spread", "XBT/USD"]
[275, ["11326.20000", "11326.30000", "1596615116.104279", "2.65000000", "0.09035109"], "spread", "XBT/USD"]
[275, ["11326.20000", "11326.30000", "1596615116.189456", "3.40551922", "0.09035109"], "spread", "XBT/USD"]
[275, ["11326.20000", "11326.30000", "1596615116.597649", "2.65000000", "0.09035109"], "spread", "XBT/USD"]
[275, ["11326.20000", "11326.30000", "1596615117.598253", "4.65000000", "0.09035109"], "spread", "XBT/USD"]
[275, ["11326.20000", "11326.30000", "1596615118.173895", "3.10000000", "0.09035109"], "spread", "XBT/USD"]
[275, ["11326.20000", "11326.30000", "1596615118.233324", "2.00000000", "0.09035109"], "spread", "XBT/USD"]
[275, ["11326.20000", "11326.30000", "1596615119.663426", "2.50000000", "0.09035109"], "spread", "XBT/USD"]
[275, ["11326.20000", "11326.30000", "1596615120.392648", "2.50484441", "0.09035109"], "spread", "XBT/USD"]
[275, ["11326.20000", "11326.30000", "1596615120.404292", "0.50484441", "0.09035109"], "spread", "XBT/USD"]
[275, ["11326.20000", "11326.30000", "1596615125.144029", "0.50484441", "0.08829359"], "spread", "XBT/USD"]
[275, ["11326.20000", "11326.30000", "1596615125.381562", "2.50484441", "0.08829359"], "spread", "XBT/USD"]
[275, ["11326.20000", "11326.30000", "1596615128.858113", "0.50484441", "0.08829359"], "spread", "XBT/USD"]
[275, ["11326.20000", "11326.30000", "1596615131.487512", "2.50484441", "0.08829359"], "spread", "XBT/USD"]
[275, ["11326.20000", "11326.30000", "1596615132.885727", "0.50484441", "0.08829359"], "spread", "XBT/USD"]
[275, ["11326.20000", "11326.30000", "1596615138.724223", "2.50484441", "0.08829359"], "spread", "XBT/USD"]
[275, ["11326.20000", "11326.30000", "1596615140.853031", "0.50484441", "0.08829359"], "spread", "XBT/USD"]
[275, ["11326.20000", "11326.30000", "1596615142.308885", "1.16728042", "0.08829359"], "spread", "XBT/USD"]
[275, ["11326.20000", "11326.30000", "1596615142.811316", "1.66728042", "0.08829359"], "spread", "XBT/USD"]
[275, ["11326.20000", "11326.30000", "1596615143.644545", "3.66728042", "0.08829359"], "spread", "XBT/USD"]
[275, ["11326.20000", "11326.30000", "1596615145.411890", "1.66728042", "0.08829359"], "spread", "XBT/USD"]
[275, ["11326.20000", "11326.30000", "1596615145.787898", "1.00484441", "0.08829359"], "spread", "XBT/USD"]
, "0.00000000", "1596615088.014647"], ["11362.90000", "7.81592326", "1596614940.029634", "r"]], "c": "1828425748"}, "book-100", "XBT/USD"]
[270, {"a": [["11323.50000", "0.02286477", "1596615088.016882"]], "c": "994306180"}, "book-100", "XBT/USD"]
[270, {"a": [["11325.40000", "0.20873236", "1596615088.041441"]], "c": "1741337298"}, "book-100", "XBT/USD"]
[270, {"a": [["11324.00000", "0.03472695", "1596615088.144626"]], "c": "630771733"}, "book-100", "XBT/USD"]
[270, {"a": [["11323.50000", "0.00000000", "1596615088.144724"], ["11362.30000", "0.48750000", "1596614817.139382", "r"]], "c": "696974126"}, "book-100", "XBT/USD"]
[270, {"a": [["11331.60000", "0.00000000", "1596615088.198781"], ["11362.50000", "43.00000000", "1596614838.237086", "r"]], "c": "696974126"}, "book-100", "XBT/USD"]
[270, {"a": [["11330.90000", "0.00600000", "1596615088.249255"]], "c": "696974126"}, "book-100", "XBT/USD"]
[270, {"a": [["11324.80000", "0.04612054", "1596615088.348280"]], "c": "1840515409"}, "book-100", "XBT/USD"]
[270, {"a": [["11323.50000", "0.02286477", "1596615088.394937"]], "c": "2290364010"}, "book-100", "XBT/USD"]
[270, {"a": [["11324.00000", "0.00000000", "1596615088.396996"], ["11362.10000", "0.75800000", "1596614794.970433", "r"]], "c": "2737936445"}, "book-100", "XBT/USD"]
[270, {"b": [["11307.60000", "0.04612054", "1596615088.466077"]], "c": "2737936445"}, "book-100", "XBT/USD"]
[270, {"a": [["11329.20000", "0.00000000", "1596615088.727323"], ["11362.30000", "0.48750000", "1596614817.139382", "r"]], "c": "2737936445"}, "book-100", "XBT/USD"]
[270, {"b": [["11294.60000", "0.50000000", "1596615088.778529"]], "c": "2737936445"}, "book-100", "XBT/USD"]
[270, {"a": [["11330.90000", "0.00000000", "1596615088.783686"], ["11362.50000", "43.00000000", "1596614838.237086", "r"]], "c": "2737936445"}, "book-100", "XBT/USD"]
[270, {"a": [["11332.40000", "1.88780000", "1596615088.787065"]], "c": "2737936445"}, "book-100", "XBT/USD"]
[270, {"a": [["11326.00000", "0.80103141", "1596615088.824309"]], "c": "2737936445"}, "book-100", "XBT/USD"]
[270, {"a": [["11331.60000", "0.00600000", "1596615088.833820"]], "c": "2737936445"}, "book-100", "XBT/USD"]
[270, {"b": [["11310.90000", "1.76400000", "1596615089.227645"]], "c": "2737936445"}, "book-100", "XBT/USD"]
[270, {"a": [["11326.90000", "1.75300000", "1596615089.234616"]], "c": "2737936445"}, "book-100", "XBT/USD"]
[270, {"a": [["11331.60000", "0.00000000", "1596615089.338568"], ["11362.10000", "0.75800000", "1596614794.970433", "r"]], "c": "2737936445"}, "book-100", "XBT/USD"]
[270, {"a": [["11330.90000", "0.00600000", "1596615089.389693"]], "c": "2737936445"}, "book-100", "XBT/USD"]
[270, {"b": [["11321.30000", "3.60302153", "1596615089.628638"]], "c": "1285256566"}, "book-100", "XBT/USD"]
[270, {"a": [["11323.60000", "0.00000000", "1596615089.835266"], ["11362.10000", "0.75800000", "1596614794.970433", "r"]], "c": "1750792701"}, "book-100", "XBT/USD"]
[270, {"a": [["11325.40000", "0.00000000", "1596615089.886855"], ["11362.30000", "0.48750000", "1596614817.139382", "r"]], "c": "3810914823"}, "book-100", "XBT/USD"]
[270, {"a": [["11324.60000", "0.66268837", "1596615089.892642"]], "c": "297932028"}, "book-100", "XBT/USD"]
[270, {"b": [["11310.90000", "0.00000000", "1596615089.936348"], ["11269.90000", "0.07676998", "1596614355.604603", "r"]], "c": "297932028"}, "book-100", "XBT/USD"]
[270, {"b": [["11315.50000", "1.76600000", "1596615089.947100"]], "c": "297932028"}, "book-100", "XBT/USD"]
[270, {"a": [["11326.90000", "0.00000000", "1596615089.951978"], ["11362.30000", "0.48750000", "1596614817.139382", "r"]], "c": "297932028"}, "book-100", "XBT/USD"]
[270, {"a": [["11324.00000", "0.02286376", "1596615089.961351"]], "c": "413473279"}, "book-100", "XBT/USD"]
[270, {"a": [["11323.50000", "0.00000000", "1596615089.961409"], ["11362.30000", "0.48750000", "1596614817.139382", "r"]], "c": "2158632052"}, "book-100", "XBT/USD"]
[270, {"a": [["11323.50000", "1.75300000", "1596615089.964136"]], "c": "2653144752"}, "book-100", "XBT/USD"]
[270, {"a": [["11330.90000", "0.00000000", "1596615090.031927"], ["11362.30000", "0.48750000", "1596614817.139382", "r"]], "c": "2653144752"}, "book-100", "XBT/USD"]
[270, {"a": [["11326.40000", "1.09234698", "1596615090.051525"]], "c": "2653144752"}, "book-100", "XBT/USD"]
[270, {"a": [["11331.60000", "0.00600000", "1596615090.090534"]], "c": "2653144752"}, "book-100", "XBT/USD"]
[270, {"a": [["11324.00000", "0.00000000", "1596615090.213301"], ["11362.30000", "0.48750000", "1596614817.139382", "r"]], "c": "1884229365"}, "book-100", "XBT/USD"]
[270, {"a": [["11323.40000", "0.02286497", "1596615090.214112"]], "c": "2860543541"}, "book-100", "XBT/USD"]
[270, {"b": [["11316.50000", "0.32121094", "1596615090.238805"]], "c": "2860543541"}, "book-100", "XBT/USD"]
[270, {"b": [["11298.40000", "0.50000000", "1596615090.437341"]], "c": "2860543541"}, "book-100", "XBT/USD"]
[270, {"b": [["11316.50000", "0.09621094", "1596615090.700205"]], "c": "2860543541"}, "book-100", "XBT/USD"]
[270, {"a": [["11324.80000", "0.14233148", "1596615090.760912"]], "c": "1168921296"}, "book-100", "XBT/USD"]
[270, {"b": [["11321.30000", "4.10302153", "1596615090.950083"]], "c": "2852568987"}, "book-100", "XBT/USD"]
[270, {"a": [["11348.00000", "0.55829039", "1596615091.002031"]], "c": "2852568987"}, "book-100", "XBT/USD"]
[270, {"b": [["11319.60000", "0.22500000", "1596615091.021226"]], "c": "3375655902"}, "book-100", "XBT/USD"]
[270, {"a": [["11324.10000", "0.00000000", "1596615091.176183"], ["11362.30000", "0.48750000", "1596614817.139382", "r"]], "c": "435859882"}, "book-100", "XBT/USD"]
[270, {"a": [["11357.90000", "0.00000000", "1596615091.501088"], ["11362.50000", "43.00000000", "1596614838.237086", "r"]], "c": "435859882"}, "book-100", "XBT/USD"]
[270, {"a": [["11341.00000", "0.00000000", "1596615091.501539"], ["11362.90000", "7.81592326", "1596614940.029634", "r"]], "c": "435859882"}, "book-100", "XBT/USD"]
[270, {"b": [["11283.30000", "0.00000000", "1596615091.502413"], ["11273.10000", "8.39756621", "1596614911.304937", "r"]], "c": "435859882"}, "book-100", "XBT/USD"]
[270, {"a": [["11359.70000", "2.30353374", "1596615091.509745"]], "c": "435859882"}, "book-100", "XBT/USD"]
[270, {"a": [["11342.70000", "0.76749698", "1596615091.527022"]], "c": "435859882"}, "book-100", "XBT/USD"]
[270, {"b": [["11284.40000", "4.37016540", "1596615091.533771"]], "c": "435859882"}, "book-100", "XBT/USD"]
[270, {"a": [["11326.40000", "0.88361462", "1596615091.549545"]], "c": "435859882"}, "book-100", "XBT/USD"]
[270, {"a": [["11325.60000", "4.41218836", "1596615091.791615"]], "c": "1016460981"}, "book-100", "XBT/USD"]
[270, {"a": [["11325.00000", "0.00000000", "1596615091.922238"], ["11362.50000", "43.00000000", "1596614838.237086", "r"]], "c": "1256582784"}, "book-100", "XBT/USD"]
[270, {"a": [["11325.50000", "0.26628837", "1596615092.023954"]], "c": "387639416"}, "book-100", "XBT/USD"]
[270, {"b": [["11306.20000", "0.00000000", "1596615092.132923"], ["11272.50000", "6.40000000", "1596614421.465855", "r"]], "c": "387639416"}, "book-100", "XBT/USD"]
[270, {"a": [["11347.90000", "0.28000000", "1596615092.242836"]], "c": "387639416"}, "book-100", "XBT/USD"]
[270, {"b": [["11306.80000", "0.13835896", "1596615092.340414"]], "c": "387639416"}, "book-100", "XBT/USD"]
[270, {"a": [["11361.40000", "0.00000000", "1596615092.863589"], ["11362.30000", "0.48750000", "1596614817.139382", "r"]], "c": "387639416"}, "book-100", "XBT/USD"]
[270, {"a": [["11325.10000", "5.06866269", "1596615092.881997"]], "c": "1364697167"}, "book-100", "XBT/USD"]
[270, {"a": [["11322.40000", "0.76800000", "1596615092.940126"]], "c": "4017041854"}, "book-100", "XBT/USD"]
[270, {"a": [["11322.40000", "0.00000000", "1596615092.943392"], ["11362.50000", "43.00000000", "1596614838.237086", "r"]], "c": "4024330726"}, "book-100", "XBT/USD"]
[270, {"a": [["11325.70000", "0.19200000", "1596615092.990176"]], "c": "1338283734"}, "book-100", "XBT/USD"]
[270, {"a": [["11325.70000", "0.95000000", "1596615093.249433"]], "c": "2936697415"}, "book-100", "XBT/USD"]
[270, {"a": [["11325.50000", "0.00000000", "1596615094.101399"], ["11362.50000", "43.00000000", "1596614838.237086", "r"]], "c": "1939135135"}, "book-100", "XBT/USD"]
[270, {"a": [["11325.00000", "0.26629056", "1596615094.204624"]], "c": "3021425742"}, "book-100", "XBT/USD"]
[270, {"b": [["11304.50000", "0.00000000", "1596615094.357955"], ["11272.50000", "6.40000000", "1596614421.465855", "r"]], "c": "3021425742"}, "book-100", "XBT/USD"]
[270, {"a": [["11347.80000", "0.30000000", "1596615094.360922"]], "c": "3021425742"}, "book-100", "XBT/USD"]
[270, {"b": [["11303.60000", "0.73718548", "1596615094.363662"]], "c": "3021425742"}, "book-100", "XBT/USD"]
[270, {"a": [["11348.30000", "0.99800000", "1596615094.367299"]], "c": "3021425742"}, "book-100", "XBT/USD"]
[270, {"b": [["11318.90000", "0.00000000", "1596615094.500841"], ["11269.90000", "0.07676998", "1596614355.604603", "r"]], "c": "2722631562"}, "book-100", "XBT/USD"]
[270, {"a": [["11337.20000", "0.00523352", "1596615094.575701"]], "c": "2722631562"}, "book-100", "XBT/USD"]
[270, {"b": [["11300.50000", "0.00480224", "1596615094.576178"]], "c": "2722631562"}, "book-100", "XBT/USD"]
[270, {"b": [["11318.10000", "1.92500000", "1596615094.697438"]], "c": "3082952120"}, "book-100", "XBT/USD"]
[270, {"a": [["11323.50000", "0.00000000", "1596615094.820339"], ["11362.10000", "0.75800000", "1596614794.970433", "r"]], "c": "3198803873"}, "book-100", "XBT/USD"]
[270, {"a": [["11323.20000", "1.75500000", "1596615094.835011"]], "c": "27157181"}, "book-100", "XBT/USD"]
[270, {"a": [["11323.40000", "0.00000000", "1596615094.951714"], ["11362.10000", "0.75800000", "1596614794.970433", "r"]], "c": "4293445520"}, "book-100", "XBT/USD"]
[270, {"a": [["11324.50000", "0.02286275", "1596615094.952160"]], "c": "114577972"}, "book-100", "XBT/USD"]
[270, {"a": [["11326.00000", "0.66267097", "1596615095.349880"]], "c": "114577972"}, "book-100", "XBT/USD"]
[270, {"b": [["11302.40000", "0.03618932", "1596615095.553439"]], "c": "114577972"}, "book-100", "XBT/USD"]
[270, {"b": [["11303.60000", "0.70100000", "1596615095.554717"]], "c": "114577972"}, "book-100", "XBT/USD"]
[270, {"b": [["11307.60000", "0.00000000", "1596615095.574687"], ["11272.50000", "6.40000000", "1596614421.465855", "r"]], "c": "114577972"}, "book-100", "XBT/USD"]
[270, {"a": [["11327.40000", "0.13835196", "1596615095.575268"]], "c": "114577972"}, "book-100", "XBT/USD"]
[270, {"b": [["11308.30000", "0.04611734", "1596615095.813782"]], "c": "114577972"}, "book-100", "XBT/USD"]
[270, {"a": [["11347.90000", "0.00000000", "1596615096.246036"], ["11362.00000", "2.04004533", "1596614787.685009", "r"]], "c": "114577972"}, "book-100", "XBT/USD"]
[270, {"b": [["11298.40000", "0.00000000", "1596615096.310826"], ["11272.50000", "6.40000000", "1596614421.465855", "r"]], "c": "114577972"}, "book-100", "XBT/USD"]
[270, {"a": [["11325.00000", "0.00000000", "1596615096.380151"], ["11362.10000", "0.75800000", "1596614794.970433", "r"]], "c": "540107340"}, "book-100", "XBT/USD"]
[270, {"a": [["11358.00000", "0.68439000", "1596615096.448061"]], "c": "540107340"}, "book-100", "XBT/USD"]
[270, {"a": [["11325.50000", "0.26628815", "1596615096.484480"]], "c": "177063842"}, "book-100", "XBT/USD"]
[270, {"a": [["11321.40000", "0.30334467", "1596615096.586693"]], "c": "2498902625"}, "book-100", "XBT/USD"]
[270, {"b": [["11321.30000", "4.47802153", "1596615096.684041"]], "c": "2333547495"}, "book-100", "XBT/USD"]
[270, {"b": [["11291.80000", "0.39117162", "1596615096.730223"]], "c": "2333547495"}, "book-100", "XBT/USD"]
[270, {"b": [["11319.20000", "0.46481111", "1596615096.756746"]], "c": "1364781869"}, "book-100", "XBT/USD"]
[270, {"b": [["11310.40000", "0.00000000", "1596615096.757253"], ["11272.50000", "6.40000000", "1596614421.465855", "r"]], "c": "1364781869"}, "book-100", "XBT/USD"]
