[275, ["11316.90000", "11317.00000", "1596615809.965833", "0.98984366", "3.65926723"], "spread", "XBT/USD"]
[275, ["11316.90000", "11317.00000", "1596615811.348264", "0.98984366", "2.10388223"], "spread", "XBT/USD"]
[275, ["11316.90000", "11317.00000", "1596615811.848040", "0.98984366", "2.19530623"], "spread", "XBT/USD"]
[275, ["11316.90000", "11317.00000", "1596615812.215797", "0.98984366", "0.19530623"], "spread", "XBT/USD"]
[275, ["11316.90000", "11317.00000", "1596615814.681577", "0.98984366", "2.19530623"], "spread", "XBT/USD"]
[275, ["11316.90000", "11317.00000", "1596615815.143539", "0.98984366", "0.19530623"], "spread", "XBT/USD"]
[275, ["11316.90000", "11317.00000", "1596615817.882412", "1.65284330", "0.19530623"], "spread", "XBT/USD"]
[275, ["11316.90000", "11317.00000", "1596615818.349061", "1.65284330", "0.10388223"], "spread", "XBT/USD"]
[275, ["11316.90000", "11317.00000", "1596615818.852643", "1.65284330", "1.58867523"], "spread", "XBT/USD"]
[275, ["11316.90000", "11317.00000", "1596615824.356976", "1.78384330", "1.58867523"], "spread", "XBT/USD"]
[275, ["11316.90000", "11317.00000", "1596615824.426261", "2.51384330", "1.58867523"], "spread", "XBT/USD"]
[275, ["11316.90000", "11317.00000", "1596615824.426412", "2.91384330", "1.58867523"], "spread", "XBT/USD"]
[275, ["11316.90000", "11317.00000", "1596615824.840356", "4.91384330", "1.58867523"], "spread", "XBT/USD"]
[275, ["11316.90000", "11317.00000", "1596615824.857967", "4.91384330", "0.10388223"], "spread", "XBT/USD"]
[275, ["11316.90000", "11317.00000", "1596615825.700310", "4.91384330", "0.18557823"], "spread", "XBT/USD"]
[275, ["11316.90000", "11317.00000", "1596615828.717053", "5.16384330", "0.18557823"], "spread", "XBT/USD"]
[275, ["11316.90000", "11317.00000", "1596615829.795814", "4.91384330", "0.18557823"], "spread", "XBT/USD"]
[275, ["11316.90000", "11317.00000", "1596615831.346138", "4.91384330", "0.10388223"], "spread", "XBT/USD"]
[275, ["11316.90000", "11317.00000", "1596615831.849011", "4.91384330", "1.62404223"], "spread", "XBT/USD"]
[275, ["11316.90000", "11317.00000", "1596615832.426446", "4.51384330", "1.62404223"], "spread", "XBT/USD"]
[275, ["11316.90000", "11317.00000", "1596615832.874026", "4.38284330", "1.62404223"], "spread", "XBT/USD"]
[271, [["11317.00000", "0.01859323", "1596615833.860193", "b", "l", ""], ["11317.00000", "0.00405617", "1596615833.871352", "b", "l", ""]], "trade", "XBT/USD"]
[275, ["11316.90000", "11317.00000", "1596615833.871352", "4.38284330", "1.60139283"], "spread", "XBT/USD"]
[275, ["11316.90000", "11317.00000", "1596615833.933656", "8.23284330", "1.60139283"], "spread", "XBT/USD"]
[275, ["11316.90000", "11317.00000", "1596615834.069716", "8.36384330", "1.60139283"], "spread", "XBT/USD"]
[275, ["11316.90000", "11317.00000", "1596615834.260336", "4.51384330", "1.60139283"], "spread", "XBT/USD"]
[271, [["11316.90000", "0.00100000", "1596615835.353072", "s", "l", ""]], "trade", "XBT/USD"]
[275, ["11316.90000", "11317.00000", "1596615835.353072", "4.51284330", "1.60139283"], "spread", "XBT/USD"]
[275, ["11316.90000", "11317.00000", "1596615836.616917", "4.91284330", "1.60139283"], "spread", "XBT/USD"]
[271, [["11317.00000", "0.02837083", "1596615836.850464", "b", "l", ""], ["11317.00000", "0.05286200", "1596615836.855245", "b", "l", ""], ["11317.00000", "0.92876717", "1596615836.856970", "b", "l", ""]], "trade", "XBT/USD"]
[275, ["11316.90000", "11317.00000", "1596615836.856970", "4.91284330", "0.59139283"], "spread", "XBT/USD"]
[275, ["11316.90000", "11317.00000", "1596615836.925248", "8.76284330", "0.59139283"], "spread", "XBT/USD"]
[275, ["11316.90000", "11318.20000", "1596615836.925248", "8.76284330", "0.20000000"], "spread", "XBT/USD"]
[275, ["11317.00000", "11318.20000", "1596615838.398854", "0.75551922", "0.20000000"], "spread", "XBT/USD"]
[275, ["11318.10000", "11318.20000", "1596615838.407579", "0.50000000", "0.20000000"], "spread", "XBT/USD"]
[275, ["11318.10000", "11318.20000", "1596615838.470230", "1.30000000", "0.20000000"], "spread", "XBT/USD"]
[275, ["11318.10000", "11318.20000", "1596615838.556978", "3.30000000", "0.20000000"], "spread", "XBT/USD"]
[275, ["11318.10000", "11318.20000", "1596615838.747168", "3.31554450", "0.20000000"], "spread", "XBT/USD"]
[275, ["11318.10000", "11318.20000", "1596615838.976516", "3.88767828", "0.20000000"], "spread", "XBT/USD"]
[275, ["11318.10000", "11318.20000", "1596615839.426654", "3.08767828", "0.20000000"], "spread", "XBT/USD"]
[275, ["11318.10000", "11318.20000", "1596615839.702342", "3.75055828", "0.20000000"], "spread", "XBT/USD"]
[275, ["11318.10000", "11318.20000", "1596615839.844363", "3.75055828", "1.91607700"], "spread", "XBT/USD"]
[275, ["11318.10000", "11318.20000", "1596615840.334403", "1.75055828", "1.91607700"], "spread", "XBT/USD"]
[275, ["11318.10000", "11318.20000", "1596615840.820103", "2.77555828", "1.91607700"], "spread", "XBT/USD"]
[275, ["11318.10000", "11318.20000", "1596615840.852248", "2.77555828", "1.93324200"], "spread", "XBT/USD"]
[275, ["11318.10000", "11318.20000", "1596615841.485764", "2.77555828", "2.33324200"], "spread", "XBT/USD"]
[275, ["11318.10000", "11318.20000", "1596615841.487454", "2.77555828", "1.93324200"], "spread", "XBT/USD"]
[275, ["11318.10000", "11318.20000", "1596615842.544668", "4.77555828", "1.93324200"], "spread", "XBT/USD"]
[275, ["11318.10000", "11318.20000", "1596615842.800998", "4.81876364", "1.93324200"], "spread", "XBT/USD"]
[275, ["11318.10000", "11318.20000", "1596615843.032932", "4.81876364", "2.33324200"], "spread", "XBT/USD"]
[275, ["11318.10000", "11318.20000", "1596615843.162415", "2.81876364", "2.33324200"], "spread", "XBT/USD"]
[275, ["11318.10000", "11318.20000", "1596615844.921527", "2.24662986", "2.33324200"], "spread", "XBT/USD"]
[275, ["11318.10000", "11318.20000", "1596615845.699809", "1.58374986", "2.33324200"], "spread", "XBT/USD"]
[275, ["11318.10000", "11318.20000", "1596615847.356293", "1.58374986", "4.33324200"], "spread", "XBT/USD"]
[275, ["11318.10000", "11318.20000", "1596615848.342320", "0.55874986", "4.33324200"], "spread", "XBT/USD"]
[275, ["11318.10000", "11318.20000", "1596615848.363163", "0.55874986", "5.16021200"], "spread", "XBT/USD"]
[275, ["11318.10000", "11318.20000", "1596615848.365665", "0.05874986", "5.16021200"], "spread", "XBT/USD"]
[275, ["11318.10000", "11318.20000", "1596615848.538678", "0.05874986", "5.66021200"], "spread", "XBT/USD"]
[275, ["11318.10000", "11318.20000", "1596615848.863667", "0.05874986", "6.32322598"], "spread", "XBT/USD"]
[275, ["11318.10000", "11318.20000", "1596615849.847317", "0.05874986", "6.52322598"], "spread", "XBT/USD"]
[275, ["11318.10000", "11318.20000", "1596615849.928052", "0.05874986", "6.78972008"], "spread", "XBT/USD"]
[275, ["11318.10000", "11318.20000", "1596615850.086216", "0.05874986", "7.15872008"], "spread", "XBT/USD"]
[275, ["11318.10000", "11318.20000", "1596615851.012319", "0.05874986", "7.55872008"], "spread", "XBT/USD"]
[275, ["11318.10000", "11318.20000", "1596615851.032962", "0.05874986", "7.15872008"], "spread", "XBT/USD"]
[275, ["11318.10000", "11318.20000", "1596615851.118795", "0.05874986", "8.92572008"], "spread", "XBT/USD"]
[275, ["11318.10000", "11318.20000", "1596615853.250019", "0.05874986", "8.94109896"], "spread", "XBT/USD"]
[275, ["11318.10000", "11318.20000", "1596615853.876624", "0.05874986", "8.92393396"], "spread", "XBT/USD"]
[275, ["11318.10000", "11318.20000", "1596615853.983388", "0.05874986", "7.20785696"], "spread", "XBT/USD"]
[275, ["11318.10000", "11318.20000", "1596615855.400191", "0.05874986", "7.24535696"], "spread", "XBT/USD"]
[275, ["11318.10000", "11318.20000", "1596615858.242116", "0.05874986", "7.43735696"], "spread", "XBT/USD"]
[275, ["11318.10000", "11318.20000", "1596615859.012353", "0.05874986", "7.03735696"], "spread", "XBT/USD"]
[275, ["11318.10000", "11318.20000", "1596615859.891018", "0.05874986", "8.00235696"], "spread", "XBT/USD"]
[275, ["11318.10000", "11318.20000", "1596615873.887770", "0.05874986", "8.00537821"], "spread", "XBT/USD"]
[275, ["11318.10000", "11318.20000", "1596615876.974442", "0.05874986", "7.81337821"], "spread", "XBT/USD"]
[275, ["11318.10000", "11318.20000", "1596615877.138000", "0.05874986", "6.84837821"], "spread", "XBT/USD"]
[275, ["11318.10000", "11318.20000", "1596615885.954144", "0.05874986", "7.24837821"], "spread", "XBT/USD"]
[275, ["11318.10000", "11318.20000", "1596615893.954090", "0.05874986", "6.84837821"], "spread", "XBT/USD"]
[275, ["11318.10000", "11318.20000", "1596615894.175833", "0.05874986", "7.04037821"], "spread", "XBT/USD"]
[275, ["11318.10000", "11318.20000", "1596615894.386364", "0.05874986", "7.44037821"], "spread", "XBT/USD"]
[275, ["11318.10000", "11318.20000", "1596615894.727492", "0.05874986", "8.40537821"], "spread", "XBT/USD"]
[275, ["11318.10000", "11318.20000", "1596615896.073712", "0.05874986", "8.40756785"], "spread", "XBT/USD"]
[275, ["11318.10000", "11318.20000", "1596615898.547240", "0.05874986", "8.40454660"], "spread", "XBT/USD"]
[275, ["11318.10000", "11318.20000", "1596615898.747230", "0.04320536", "8.40454660"], "spread", "XBT/USD"]
[275, ["11318.10000", "11318.20000", "1596615898.842845", "0.04320536", "8.40720939"], "spread", "XBT/USD"]
[275, ["11318.10000", "11318.20000", "1596615899.639938", "0.05874986", "8.40720939"], "spread", "XBT/USD"]
[275, ["11318.10000", "11318.20000", "1596615900.564806", "0.05874986", "8.00720939"], "spread", "XBT/USD"]
[275, ["11318.10000", "11318.20000", "1596615906.034978", "0.05874986", "8.00501975"], "spread", "XBT/USD"]
[275, ["11318.10000", "11318.20000", "1596615906.473019", "0.05874986", "8.00727675"], "spread", "XBT/USD"]
[275, ["11318.10000", "11318.20000", "1596615907.413206", "0.05874986", "8.00934367"], "spread", "XBT/USD"]
[275, ["11318.10000", "11318.20000", "1596615915.672137", "0.05874986", "7.97184367"], "spread", "XBT/USD"]
[271, [["11318.20000", "0.20000000", "1596615917.240560", "b", "l", ""], ["11318.20000", "0.57831100", "1596615917.257513", "b", "l", ""]], "trade", "XBT/USD"]
[275, ["11318.10000", "11318.20000", "1596615917.257513", "0.05874986", "7.19353267"], "spread", "XBT/USD"]
[275, ["11318.10000", "11318.20000", "1596615918.406931", "0.05874986", "7.43353267"], "spread", "XBT/USD"]
[275, ["11318.10000", "11318.20000", "1596615922.522303", "0.05874986", "7.52188633"], "spread", "XBT/USD"]
[275, ["11318.10000", "11318.20000", "1596615922.717671", "0.05874986", "7.72188633"], "spread", "XBT/USD"]
[275, ["11318.10000", "11318.20000", "1596615922.842388", "0.05874986", "7.52188633"], "spread", "XBT/USD"]
[275, ["11318.10000", "11318.20000", "1596615922.842586", "0.05874986", "7.51962933"], "spread", "XBT/USD"]
[275, ["11318.10000", "11318.20000", "1596615923.045164", "0.05874986", "7.71962933"], "spread", "XBT/USD"]
[275, ["11318.10000", "11318.20000", "1596615923.101353", "0.05874986", "12.96962933"], "spread", "XBT/USD"]
[275, ["11318.10000", "11318.20000", "1596615923.234190", "0.05874986", "13.46962933"], "spread", "XBT/USD"]
1333.80000", "0.00000000", "1596615811.860490"], ["11360.00000", "0.01780000", "1596615623.316281", "r"]], "c": "186326437"}, "book-100", "XBT/USD"]
[270, {"b": [["11280.30000", "0.00000000", "1596615811.907923"], ["11271.90000", "3.79281727", "1596615642.436821", "r"]], "c": "186326437"}, "book-100", "XBT/USD"]
[270, {"b": [["11280.40000", "0.76746190", "1596615811.910149"]], "c": "186326437"}, "book-100", "XBT/USD"]
[270, {"a": [["11318.30000", "0.00000000", "1596615811.988812"], ["11361.00000", "0.18439000", "1596613113.794584", "r"]], "c": "245639126"}, "book-100", "XBT/USD"]
[270, {"b": [["11305.90000", "0.72346811", "1596615812.064120"]], "c": "245639126"}, "book-100", "XBT/USD"]
[270, {"a": [["11334.10000", "0.72166808", "1596615812.069003"]], "c": "245639126"}, "book-100", "XBT/USD"]
[270, {"b": [["11309.10000", "0.84441114", "1596615812.069883"]], "c": "245639126"}, "book-100", "XBT/USD"]
[270, {"a": [["11330.80000", "0.34375155", "1596615812.077231"]], "c": "245639126"}, "book-100", "XBT/USD"]
[270, {"a": [["11318.10000", "0.26645833", "1596615812.088281"]], "c": "3274765520"}, "book-100", "XBT/USD"]
[270, {"a": [["11317.00000", "0.19530623", "1596615812.215797"]], "c": "3333622656"}, "book-100", "XBT/USD"]
[270, {"a": [["11320.80000", "0.96500000", "1596615812.242397"]], "c": "3333622656"}, "book-100", "XBT/USD"]
[270, {"a": [["11318.30000", "0.19200000", "1596615812.251339"]], "c": "849855050"}, "book-100", "XBT/USD"]
[270, {"a": [["11320.80000", "0.00000000", "1596615812.511670"], ["11359.10000", "3.40080754", "1596615619.494056", "r"]], "c": "849855050"}, "book-100", "XBT/USD"]
[270, {"b": [["11313.70000", "0.22500000", "1596615812.777989"]], "c": "4015455354"}, "book-100", "XBT/USD"]
[270, {"b": [["11313.90000", "0.26645590", "1596615812.879144"]], "c": "2185242524"}, "book-100", "XBT/USD"]
[270, {"b": [["11299.30000", "7.16431469", "1596615813.053591"]], "c": "2185242524"}, "book-100", "XBT/USD"]
[270, {"a": [["11336.30000", "3.55705928", "1596615813.078602"]], "c": "2185242524"}, "book-100", "XBT/USD"]
[270, {"a": [["11318.30000", "1.15700000", "1596615813.296263"]], "c": "3828485025"}, "book-100", "XBT/USD"]
[270, {"b": [["11312.80000", "0.00000000", "1596615813.301113"], ["11274.20000", "15.10000000", "1596614778.354676", "r"]], "c": "3828485025"}, "book-100", "XBT/USD"]
[270, {"b": [["11304.20000", "1.32404189", "1596615813.729140"]], "c": "3828485025"}, "book-100", "XBT/USD"]
[270, {"b": [["11306.50000", "2.15251541", "1596615814.119534"]], "c": "3828485025"}, "book-100", "XBT/USD"]
[270, {"b": [["11313.50000", "0.00000000", "1596615814.286231"], ["11273.20000", "0.75800000", "1596615511.639275", "r"]], "c": "3828485025"}, "book-100", "XBT/USD"]
[270, {"a": [["11336.20000", "0.28000000", "1596615814.333149"]], "c": "3828485025"}, "book-100", "XBT/USD"]
[270, {"b": [["11311.00000", "0.13371094", "1596615814.337783"]], "c": "3828485025"}, "book-100", "XBT/USD"]
[270, {"a": [["11321.20000", "0.00000000", "1596615814.346944"], ["11359.10000", "3.40080754", "1596615619.494056", "r"]], "c": "3828485025"}, "book-100", "XBT/USD"]
[270, {"a": [["11319.40000", "0.11158683", "1596615814.466363"]], "c": "3353407406"}, "book-100", "XBT/USD"]
[270, {"a": [["11336.30000", "0.00000000", "1596615814.571419"], ["11359.90000", "0.05000000", "1596614932.787513", "r"]], "c": "3353407406"}, "book-100", "XBT/USD"]
[270, {"a": [["11317.00000", "2.19530623", "1596615814.681577"]], "c": "2895003045"}, "book-100", "XBT/USD"]
[270, {"a": [["11334.90000", "3.63018458", "1596615814.792985"]], "c": "2895003045"}, "book-100", "XBT/USD"]
[270, {"b": [["11313.90000", "0.00000000", "1596615814.954526"], ["11272.50000", "6.40000000", "1596614421.465855", "r"]], "c": "867009576"}, "book-100", "XBT/USD"]
[270, {"b": [["11313.70000", "0.49146194", "1596615815.053651"]], "c": "3823558525"}, "book-100", "XBT/USD"]
[270, {"a": [["11333.80000", "0.00525469", "1596615815.058904"]], "c": "3823558525"}, "book-100", "XBT/USD"]
[270, {"b": [["11289.00000", "0.00000000", "1596615815.059120"], ["11271.90000", "3.79281727", "1596615642.436821", "r"]], "c": "3823558525"}, "book-100", "XBT/USD"]
[270, {"a": [["11320.40000", "0.04611624", "1596615815.134834"]], "c": "3823558525"}, "book-100", "XBT/USD"]
[270, {"a": [["11317.00000", "0.19530623", "1596615815.143539"]], "c": "2290617718"}, "book-100", "XBT/USD"]
[270, {"a": [["11355.70000", "0.00000000", "1596615815.279434"], ["11358.90000", "4.40000000", "1596615106.457198", "r"]], "c": "2290617718"}, "book-100", "XBT/USD"]
[270, {"b": [["11304.70000", "0.04611661", "1596615815.352323"]], "c": "2290617718"}, "book-100", "XBT/USD"]
[270, {"b": [["11315.10000", "0.00000000", "1596615815.509523"], ["11271.90000", "3.79281727", "1596615642.436821", "r"]], "c": "3150606928"}, "book-100", "XBT/USD"]
[270, {"b": [["11311.30000", "0.45291428", "1596615815.514869"]], "c": "3150606928"}, "book-100", "XBT/USD"]
[270, {"a": [["11320.70000", "0.13834723", "1596615815.569040"]], "c": "3150606928"}, "book-100", "XBT/USD"]
[270, {"b": [["11316.70000", "0.00000000", "1596615815.570296"], ["11271.90000", "3.79281727", "1596615642.436821", "r"]], "c": "1073355511"}, "book-100", "XBT/USD"]
[270, {"a": [["11319.20000", "0.69450000", "1596615815.570975"]], "c": "3234724586"}, "book-100", "XBT/USD"]
[270, {"a": [["11317.40000", "0.66303527", "1596615815.627328"]], "c": "407179237"}, "book-100", "XBT/USD"]
[270, {"b": [["11302.80000", "0.88404703", "1596615815.629363"]], "c": "407179237"}, "book-100", "XBT/USD"]
[270, {"a": [["11320.70000", "0.00000000", "1596615815.725530"], ["11358.10000", "17.70000000", "1596614868.797705", "r"]], "c": "407179237"}, "book-100", "XBT/USD"]
[270, {"a": [["11323.00000", "0.13838795", "1596615815.950026"]], "c": "407179237"}, "book-100", "XBT/USD"]
[270, {"a": [["11317.40000", "0.00000000", "1596615816.432905"], ["11358.10000", "17.70000000", "1596614868.797705", "r"]], "c": "3234724586"}, "book-100", "XBT/USD"]
[270, {"a": [["11319.20000", "0.00000000", "1596615816.449827"], ["11358.90000", "4.40000000", "1596615106.457198", "r"]], "c": "990746645"}, "book-100", "XBT/USD"]
[270, {"b": [["11293.60000", "0.05425954", "1596615816.645284"]], "c": "990746645"}, "book-100", "XBT/USD"]
[270, {"b": [["11302.80000", "0.00000000", "1596615816.669449"], ["11271.90000", "3.79281727", "1596615642.436821", "r"]], "c": "990746645"}, "book-100", "XBT/USD"]
[270, {"a": [["11337.70000", "0.76746642", "1596615816.739077"]], "c": "990746645"}, "book-100", "XBT/USD"]
[270, {"a": [["11317.80000", "0.00000000", "1596615816.933359"], ["11359.10000", "3.40080754", "1596615619.494056", "r"]], "c": "2338740154"}, "book-100", "XBT/USD"]
[270, {"a": [["11331.60000", "0.00000000", "1596615816.964295"], ["11359.90000", "0.05000000", "1596614932.787513", "r"]], "c": "2338740154"}, "book-100", "XBT/USD"]
[270, {"b": [["11313.70000", "0.22500000", "1596615817.135547"]], "c": "1916677995"}, "book-100", "XBT/USD"]
[270, {"b": [["11313.70000", "0.00000000", "1596615817.137078"], ["11270.40000", "2.56723579", "1596615800.029383", "r"]], "c": "821773008"}, "book-100", "XBT/USD"]
[270, {"b": [["11313.50000", "0.22500000", "1596615817.137295"]], "c": "1793375126"}, "book-100", "XBT/USD"]
[270, {"b": [["11306.50000", "0.15251541", "1596615817.189655"]], "c": "1793375126"}, "book-100", "XBT/USD"]
[270, {"a": [["11336.30000", "1.44305605", "1596615817.193660"]], "c": "1793375126"}, "book-100", "XBT/USD"]
[270, {"b": [["11313.20000", "0.22500000", "1596615817.219178"]], "c": "2359046366"}, "book-100", "XBT/USD"]
[270, {"b": [["11280.40000", "0.00000000", "1596615817.268236"], ["11271.90000", "3.79281727", "1596615642.436821", "r"]], "c": "2359046366"}, "book-100", "XBT/USD"]
[270, {"b": [["11313.70000", "0.26645848", "1596615817.277717"]], "c": "3735124886"}, "book-100", "XBT/USD"]
[270, {"b": [["11297.40000", "0.98400000", "1596615817.467403"]], "c": "3735124886"}, "book-100", "XBT/USD"]
[270, {"b": [["11303.70000", "0.20500000", "1596615817.474069"]], "c": "3735124886"}, "book-100", "XBT/USD"]
[270, {"b": [["11293.80000", "0.50000000", "1596615817.829753"]], "c": "3735124886"}, "book-100", "XBT/USD"]
[270, {"a": [["11318.20000", "0.86299964", "1596615817.881931"]], "c": "3258132289"}, "book-100", "XBT/USD"]
[270, {"b": [["11316.90000", "1.65284330", "1596615817.882412"]], "c": "2205252730"}, "book-100", "XBT/USD"]
[270, {"a": [["11319.70000", "0.66299964", "1596615817.883190"]], "c": "1915071795"}, "book-100", "XBT/USD"]
[270, {"a": [["11331.30000", "0.88399952", "1596615817.883919"]], "c": "1915071795"}, "book-100", "XBT/USD"]
[270, {"a": [["11319.50000", "0.00000000", "1596615817.953104"], ["11358.90000", "4.40000000", "1596615106.457198", "r"]], "c": "405115510"}, "book-100", "XBT/USD"]
[270, {"a": [["11319.60000", "4.41100000", "1596615818.213842"]], "c": "1848298374"}, "book-100", "XBT/USD"]
[270, {"b": [["11298.60000", "0.00442118", "1596615818.280743"]], "c": "1848298374"}, "book-100", "XBT/USD"]
[270, {"a": [["11337.70000", "0.00000000", "1596615818.294748"], ["11358.90000", "4.40000000", "1596615106.457198", "r"]], "c": "1848298374"}, "book-100", "XBT/USD"]
[270, {"a": [["11337.10000", "0.76746149", "1596615818.298030"]], "c": "1848298374"}, "book-100", "XBT/USD"]
[270, {"b": [["11280.00000", "0.76746149", "1596615818.299119"]], "c": "1848298374"}, "book-100", "XBT/USD"]
[270, {"a": [["11317.00000", "0.10388223", "1596615818.349061"]], "c": "3056544493"}, "book-100", "XBT/USD"]
[270, {"a": [["11338.90000", "6.17000000", "1596615818.617708"]], "c": "3056544493"}, "book-100", "XBT/USD"]
[270, {"a": [["11317.00000", "1.58867523", "1596615818.852643"]], "c": "56120648"}, "book-100", "XBT/USD"]
[270, {"a": [["11318.10000", "0.00000000", "1596615819.098995"], ["11358.90000", "4.40000000", "1596615106.457198", "r"]], "c": "1006458238"}, "book-100", "XBT/USD"]
[270, {"b": [["11313.70000", "0.00000000", "1596615819.301152"], ["11275.00000", "0.25780659", "1596614977.276342", "r"]], "c": "1774198326"}, "book-100", "XBT/USD"]
[270, {"a": [["11318.10000", "0.26645569", "1596615819.372472"]], "c": "2001967681"}, "book-100", "XBT/USD"]
[270, {"b": [["11313.90000", "0.26645554", "1596615819.397612"]], "c": "1149336814"}, "book-100", "XBT/USD"]
[270, {"b": [["11298.60000", "0.00000000", "1596615820.631597"], ["11275.00000", "0.25780659", "1596614977.276342", "r"]], "c": "1149336814"}, "book-100", "XBT/USD"]
[270, {"b": [["11306.50000", "2.15251541", "1596615820.742871"]], "c": "1149336814"}, "book-100", "XBT/USD"]
[270, {"b": [["11297.60000", "0.00462393", "1596615820.816037"]], "c": "1149336814"}, "book-100", "XBT/USD"]
[270, {"b": [["11297.60000", "0.00000000", "1596615821.634343"], ["11275.00000", "0.25780659", "1596614977.276342", "r"]], "c": "1149336814"}, "book-100", "XBT/USD"]
[270, {"a": [["11330.90000", "0.00000000", "1596615821.664291"], ["11358.90000", "4.40000000", "1596615106.457198", "r"]], "c": "1149336814"}, "book-100", "XBT/USD"]
[270, {"b": [["11313.90000", "0.00000000", "1596615821.671073"], ["11274.20000", "15.10000000", "1596614778.354676", "r"]], "c": "2001967681"}, "book-100", "XBT/USD"]
[270, {"a": [["11330.90000", "5.73935132", "1596615821.746504"]], "c": "2001967681"}, "book-100", "XBT/USD"]
[270, {"b": [["11313.70000", "0.26645786", "1596615821.773252"]], "c": "3232565588"}, "book-100", "XBT/USD"]
[270, {"a": [["11318.70000", "0.00000000", "1596615822.822149"], ["11358.90000", "4.40000000", "1596615106.457198", "r"]], "c": "2627700538"}, "book-100", "XBT/USD"]
[270, {"b": [["11288.90000", "0.00000000", "1596615822.845508"], ["11274.20000", "15.10000000", "1596614778.354676", "r"]], "c": "2627700538"}, "book-100", "XBT/USD"]
[270, {"a": [["11317.90000", "0.66300162", "1596615822.883773"]], "c": "2468409533"}, "book-100", "XBT/USD"]
[270, {"a": [["11318.10000", "0.00000000", "1596615822.957581"], ["11358.90000", "4.40000000", "1596615106.457198", "r"]], "c": "3025394052"}, "book-100", "XBT/USD"]
[270, {"a": [["11317.80000", "0.26646332", "1596615823.084429"]], "c": "3525973032"}, "book-100", "XBT/USD"]
