[270, {"a": [["11316.00000", "0.00000000", "1596616224.047035"], ["11336.90000", "1.67596120", "1596616212.693801", "r"]], "c": "2763437366"}, "book-100", "XBT/USD"]
[270, {"a": [["11310.70000", "0.33395722", "1596616224.047192"]], "c": "2763437366"}, "book-100", "XBT/USD"]
[270, {"a": [["11298.00000", "1.75600000", "1596616224.052181"]], "c": "3471750949"}, "book-100", "XBT/USD"]
[270, {"b": [["11292.70000", "15.88090233", "1596616224.062974"]], "c": "2895458756"}, "book-100", "XBT/USD"]
[270, {"b": [["11291.50000", "0.00000000", "1596616224.068100"], ["11252.90000", "5.60000000", "1596616073.488797", "r"]], "c": "1638576082"}, "book-100", "XBT/USD"]
[270, {"a": [["11298.20000", "0.00000000", "1596616224.197754"], ["11336.90000", "1.67596120", "1596616212.693801", "r"]], "c": "3093346153"}, "book-100", "XBT/USD"]
[270, {"a": [["11292.90000", "1.52572800", "1596616224.346046"]], "c": "1737035367"}, "book-100", "XBT/USD"]
[270, {"a": [["11297.40000", "0.25000000", "1596616224.376997"]], "c": "1662684719"}, "book-100", "XBT/USD"]
[270, {"b": [["11290.40000", "0.45000000", "1596616224.377512"]], "c": "1662684719"}, "book-100", "XBT/USD"]
[270, {"a": [["11315.70000", "0.00000000", "1596616224.511718"], ["11336.90000", "1.67596120", "1596616212.693801", "r"]], "c": "1662684719"}, "book-100", "XBT/USD"]
[270, {"b": [["11272.80000", "0.05433331", "1596616224.518182"]], "c": "1662684719"}, "book-100", "XBT/USD"]
[270, {"b": [["11292.70000", "16.14785432", "1596616224.712093"]], "c": "3897160769"}, "book-100", "XBT/USD"]
[270, {"a": [["11292.80000", "0.10973080", "1596616224.734617"]], "c": "3034519744"}, "book-100", "XBT/USD"]
[270, {"a": [["11292.80000", "0.10309350", "1596616224.739188"], ["11292.80000", "0.09791200", "1596616224.741109"], ["11292.80000", "0.03221250", "1596616224.742811"]], "c": "1609485163"}, "book-100", "XBT/USD"]
[270, {"b": [["11290.40000", "0.00000000", "1596616224.876312"], ["11252.90000", "5.60000000", "1596616073.488797", "r"]], "c": "1609485163"}, "book-100", "XBT/USD"]
[270, {"a": [["11292.80000", "0.00000000", "1596616224.881557"], ["11337.00000", "0.18439000", "1596616205.519680", "r"], ["11292.90000", "1.27376070", "1596616224.884403"]], "c": "2068448164"}, "book-100", "XBT/USD"]
[270, {"a": [["11297.40000", "0.00000000", "1596616224.887805"], ["11338.20000", "0.00890818", "1596616219.066416", "r"]], "c": "2674315212"}, "book-100", "XBT/USD"]
[270, {"a": [["11292.90000", "1.24073220", "1596616224.888411"]], "c": "4141979330"}, "book-100", "XBT/USD"]
[270, {"b": [["11272.50000", "6.90000000", "1596616224.917404"]], "c": "4141979330"}, "book-100", "XBT/USD"]
[270, {"b": [["11292.70000", "15.39233510", "1596616224.943002"]], "c": "3818271049"}, "book-100", "XBT/USD"]
[270, {"b": [["11292.70000", "14.89333510", "1596616224.943574"]], "c": "1570396004"}, "book-100", "XBT/USD"]
[270, {"b": [["11292.80000", "0.50000000", "1596616224.944636"]], "c": "1416613634"}, "book-100", "XBT/USD"]
[270, {"b": [["11292.70000", "10.79333510", "1596616224.945076"]], "c": "3592736358"}, "book-100", "XBT/USD"]
[270, {"b": [["11292.80000", "1.30000000", "1596616224.946407"]], "c": "550462869"}, "book-100", "XBT/USD"]
[270, {"b": [["11292.70000", "10.37333510", "1596616224.984173"]], "c": "4210221260"}, "book-100", "XBT/USD"]
[270, {"b": [["11292.80000", "2.32500000", "1596616224.986852"]], "c": "4036423932"}, "book-100", "XBT/USD"]
[270, {"b": [["11292.80000", "3.08051922", "1596616224.987234"]], "c": "601020112"}, "book-100", "XBT/USD"]
[270, {"a": [["11296.90000", "0.00000000", "1596616225.006858"], ["11338.30000", "3.14019941", "1596616204.151178", "r"]], "c": "1840604791"}, "book-100", "XBT/USD"]
[270, {"b": [["11292.70000", "10.24233510", "1596616225.010646"]], "c": "1305174165"}, "book-100", "XBT/USD"]
[270, {"b": [["11282.30000", "0.50000000", "1596616225.079439"]], "c": "1305174165"}, "book-100", "XBT/USD"]
[270, {"b": [["11291.60000", "1.10057833", "1596616225.079888"]], "c": "2055102846"}, "book-100", "XBT/USD"]
[270, {"b": [["11292.70000", "10.07380120", "1596616225.094837"]], "c": "2321436741"}, "book-100", "XBT/USD"]
[270, {"a": [["11298.50000", "0.25000000", "1596616225.099242"]], "c": "3821600030"}, "book-100", "XBT/USD"]
[270, {"b": [["11292.70000", "9.72889608", "1596616225.106165"]], "c": "2254163739"}, "book-100", "XBT/USD"]
[270, {"a": [["11297.90000", "0.26695035", "1596616225.106288"]], "c": "2289762063"}, "book-100", "XBT/USD"]
[270, {"b": [["11271.50000", "0.00000000", "1596616225.111527"], ["11253.40000", "0.48980000", "1596616176.764416", "r"]], "c": "2289762063"}, "book-100", "XBT/USD"]
[270, {"b": [["11291.60000", "0.45000000", "1596616225.128567"]], "c": "1297515898"}, "book-100", "XBT/USD"]
[270, {"a": [["11292.90000", "1.16321390", "1596616225.137619"]], "c": "1569922581"}, "book-100", "XBT/USD"]
[270, {"b": [["11292.80000", "5.08051922", "1596616225.142852"]], "c": "324923198"}, "book-100", "XBT/USD"]
[270, {"b": [["11292.80000", "8.38051922", "1596616225.200735"]], "c": "459499061"}, "book-100", "XBT/USD"]
[270, {"a": [["11300.20000", "0.00000000", "1596616225.211666"], ["11338.20000", "0.00890818", "1596616219.066416", "r"]], "c": "677654746"}, "book-100", "XBT/USD"]
[270, {"a": [["11336.00000", "0.00000000", "1596616225.270976"], ["11338.30000", "3.14019941", "1596616204.151178", "r"]], "c": "677654746"}, "book-100", "XBT/USD"]
[270, {"b": [["11258.10000", "0.00000000", "1596616225.279991"], ["11252.90000", "5.60000000", "1596616073.488797", "r"]], "c": "677654746"}, "book-100", "XBT/USD"]
[270, {"a": [["11318.40000", "0.00000000", "1596616225.289170"], ["11338.80000", "6.51799662", "1596616217.554099", "r"]], "c": "677654746"}, "book-100", "XBT/USD"]
[270, {"a": [["11317.90000", "1.49112307", "1596616225.303772"]], "c": "677654746"}, "book-100", "XBT/USD"]
[270, {"b": [["11292.80000", "9.07824983", "1596616225.315927"]], "c": "2507030267"}, "book-100", "XBT/USD"]
[270, {"b": [["11258.60000", "0.76845707", "1596616225.320651"]], "c": "2507030267"}, "book-100", "XBT/USD"]
[270, {"b": [["11292.70000", "9.71917409", "1596616225.468606"]], "c": "1276097529"}, "book-100", "XBT/USD"]
[270, {"a": [["11300.00000", "0.76213485", "1596616225.515012"]], "c": "2167216554"}, "book-100", "XBT/USD"]
[270, {"a": [["11292.90000", "1.15821390", "1596616225.786268"]], "c": "569161024"}, "book-100", "XBT/USD"]
[270, {"b": [["11292.80000", "9.08797182", "1596616225.954173"]], "c": "2280216493"}, "book-100", "XBT/USD"]
[270, {"a": [["11334.90000", "2.30641532", "1596616226.019999"]], "c": "2280216493"}, "book-100", "XBT/USD"]
[270, {"b": [["11289.90000", "0.78455573", "1596616226.025255"]], "c": "2280216493"}, "book-100", "XBT/USD"]
[270, {"a": [["11319.00000", "0.33675591", "1596616226.032832"]], "c": "2280216493"}, "book-100", "XBT/USD"]
[270, {"b": [["11292.80000", "9.21897182", "1596616226.104355"]], "c": "2636730939"}, "book-100", "XBT/USD"]
[270, {"b": [["11292.80000", "9.38750572", "1596616226.107944"]], "c": "2413523506"}, "book-100", "XBT/USD"]
[270, {"a": [["11316.70000", "0.00000000", "1596616226.156818"], ["11338.80000", "6.51799662", "1596616217.554099", "r"]], "c": "2413523506"}, "book-100", "XBT/USD"]
[270, {"b": [["11275.10000", "0.00000000", "1596616226.160777"], ["11252.90000", "5.60000000", "1596616073.488797", "r"]], "c": "2413523506"}, "book-100", "XBT/USD"]
[270, {"a": [["11318.70000", "2.39200000", "1596616226.161838"]], "c": "2413523506"}, "book-100", "XBT/USD"]
[270, {"b": [["11277.00000", "0.66800000", "1596616226.162508"]], "c": "2413523506"}, "book-100", "XBT/USD"]
[270, {"b": [["11291.80000", "0.00000000", "1596616226.315132"], ["11252.90000", "5.60000000", "1596616073.488797", "r"]], "c": "3562341556"}, "book-100", "XBT/USD"]
[270, {"a": [["11308.60000", "0.48424022", "1596616226.370722"]], "c": "3562341556"}, "book-100", "XBT/USD"]
[270, {"b": [["11292.80000", "10.88750572", "1596616226.462924"]], "c": "782900823"}, "book-100", "XBT/USD"]
[270, {"a": [["11309.20000", "0.56020536", "1596616226.563504"]], "c": "782900823"}, "book-100", "XBT/USD"]
[270, {"a": [["11292.90000", "1.14671490", "1596616226.777190"]], "c": "3223710857"}, "book-100", "XBT/USD"]
[270, {"b": [["11292.70000", "9.45222210", "1596616226.811845"]], "c": "378171411"}, "book-100", "XBT/USD"]
[270, {"a": [["11317.90000", "0.72266600", "1596616226.922284"]], "c": "378171411"}, "book-100", "XBT/USD"]
[270, {"a": [["11314.90000", "0.00000000", "1596616226.951971"], ["11338.90000", "5.60000000", "1596615838.844261", "r"]], "c": "378171411"}, "book-100", "XBT/USD"]
[270, {"b": [["11292.80000", "11.23242881", "1596616226.976265"]], "c": "2380769646"}, "book-100", "XBT/USD"]
[270, {"a": [["11292.90000", "0.16442590", "1596616227.365414"]], "c": "2611471766"}, "book-100", "XBT/USD"]
[270, {"b": [["11292.80000", "11.49937917", "1596616227.365581"]], "c": "3060245932"}, "book-100", "XBT/USD"]
[270, {"a": [["11292.90000", "0.00000000", "1596616227.469066"], ["11340.00000", "1.44239000", "1596616170.462982", "r"]], "c": "253096040"}, "book-100", "XBT/USD"]
[270, {"b": [["11292.80000", "10.74385995", "1596616227.516141"]], "c": "2711404087"}, "book-100", "XBT/USD"]
[270, {"b": [["11292.90000", "0.57330000", "1596616227.517923"]], "c": "2991024795"}, "book-100", "XBT/USD"]
[270, {"b": [["11292.10000", "0.10200000", "1596616227.539230"]], "c": "1961283533"}, "book-100", "XBT/USD"]
[270, {"a": [["11300.00000", "0.66413485", "1596616227.548803"]], "c": "2111889369"}, "book-100", "XBT/USD"]
[270, {"b": [["11292.80000", "10.57532605", "1596616227.556881"]], "c": "1814429681"}, "book-100", "XBT/USD"]
[270, {"b": [["11258.60000", "0.00000000", "1596616227.557340"], ["11253.40000", "0.48980000", "1596616176.764416", "r"]], "c": "1814429681"}, "book-100", "XBT/USD"]
[270, {"a": [["11315.00000", "0.34424635", "1596616227.557834"]], "c": "1814429681"}, "book-100", "XBT/USD"]
[270, {"b": [["11291.10000", "0.00000000", "1596616227.576464"], ["11252.90000", "5.60000000", "1596616073.488797", "r"]], "c": "1814429681"}, "book-100", "XBT/USD"]
[270, {"b": [["11292.90000", "1.32881922", "1596616227.576769"]], "c": "2183204428"}, "book-100", "XBT/USD"]
[270, {"b": [["11292.90000", "2.35381922", "1596616227.577764"]], "c": "2676522634"}, "book-100", "XBT/USD"]
[270, {"b": [["11292.80000", "10.44432605", "1596616227.585509"]], "c": "3517744088"}, "book-100", "XBT/USD"]
[270, {"b": [["11292.80000", "9.41932605", "1596616227.609646"]], "c": "356191660"}, "book-100", "XBT/USD"]
[270, {"a": [["11298.50000", "0.00000000", "1596616227.618350"], ["11340.00000", "1.44239000", "1596616170.462982", "r"]], "c": "2630586166"}, "book-100", "XBT/USD"]
[270, {"b": [["11291.60000", "0.00000000", "1596616227.618815"], ["11252.50000", "3.79935632", "1596616207.982034", "r"]], "c": "2798698745"}, "book-100", "XBT/USD"]
[270, {"b": [["11292.90000", "1.59830000", "1596616227.621007"]], "c": "2618910396"}, "book-100", "XBT/USD"]
[270, {"b": [["11293.00000", "0.57330000", "1596616227.629504"]], "c": "1834655935"}, "book-100", "XBT/USD"]
[270, {"b": [["11292.90000", "1.02500000", "1596616227.635511"]], "c": "608087404"}, "book-100", "XBT/USD"]
