[275, ["11299.00000", "11299.10000", "1596616574.123630", "0.44274497", "2.01538752"], "spread", "XBT/USD"]
[275, ["11299.00000", "11299.10000", "1596616575.718843", "0.44274497", "0.01538752"], "spread", "XBT/USD"]
[275, ["11299.00000", "11299.10000", "1596616577.671964", "0.44274497", "0.67956426"], "spread", "XBT/USD"]
[275, ["11299.00000", "11299.10000", "1596616578.050442", "0.44274497", "2.67956426"], "spread", "XBT/USD"]
[275, ["11299.00000", "11299.10000", "1596616578.901841", "0.44274497", "0.67956426"], "spread", "XBT/USD"]
[275, ["11299.00000", "11299.10000", "1596616579.641020", "0.44274497", "0.01538752"], "spread", "XBT/USD"]
[275, ["11299.00000", "11299.10000", "1596616582.042081", "0.44274497", "2.01538752"], "spread", "XBT/USD"]
[275, ["11299.00000", "11299.10000", "1596616582.062790", "0.44274497", "2.51538752"], "spread", "XBT/USD"]
[275, ["11299.00000", "11299.10000", "1596616582.163820", "0.44274497", "0.51538752"], "spread", "XBT/USD"]
[275, ["11299.00000", "11299.10000", "1596616583.361079", "0.44274497", "2.51538752"], "spread", "XBT/USD"]
[275, ["11299.00000", "11299.10000", "1596616583.901834", "0.44274497", "0.51538752"], "spread", "XBT/USD"]
[275, ["11299.00000", "11299.10000", "1596616585.189959", "0.44274497", "2.51538752"], "spread", "XBT/USD"]
[275, ["11299.00000", "11299.10000", "1596616587.197278", "0.44274497", "0.51538752"], "spread", "XBT/USD"]
[275, ["11299.00000", "11299.10000", "1596616589.070284", "0.44274497", "2.51538752"], "spread", "XBT/USD"]
[275, ["11299.00000", "11299.10000", "1596616590.127841", "0.01572600", "2.51538752"], "spread", "XBT/USD"]
[275, ["11297.60000", "11299.10000", "1596616589.070284", "0.08849518", "2.51538752"], "spread", "XBT/USD"]
[275, ["11297.70000", "11299.10000", "1596616590.443459", "0.01572601", "2.51538752"], "spread", "XBT/USD"]
[275, ["11297.80000", "11299.10000", "1596616590.678686", "0.50276965", "2.51538752"], "spread", "XBT/USD"]
[275, ["11297.90000", "11299.10000", "1596616590.755710", "0.01572600", "2.51538752"], "spread", "XBT/USD"]
[275, ["11297.90000", "11298.50000", "1596616590.776419", "0.01572600", "0.24000000"], "spread", "XBT/USD"]
[275, ["11298.00000", "11298.50000", "1596616591.398173", "0.56416555", "0.24000000"], "spread", "XBT/USD"]
[275, ["11298.10000", "11298.50000", "1596616591.937692", "0.01572600", "0.24000000"], "spread", "XBT/USD"]
[275, ["11298.10000", "11298.50000", "1596616592.881028", "0.01572600", "0.90419431"], "spread", "XBT/USD"]
[275, ["11298.20000", "11298.50000", "1596616592.906244", "0.56546866", "0.90419431"], "spread", "XBT/USD"]
[275, ["11298.30000", "11298.50000", "1596616593.135183", "0.01572600", "0.90419431"], "spread", "XBT/USD"]
[275, ["11298.40000", "11298.50000", "1596616593.704685", "0.53711316", "0.90419431"], "spread", "XBT/USD"]
[275, ["11298.40000", "11298.50000", "1596616593.888425", "0.53711316", "2.90419431"], "spread", "XBT/USD"]
[271, [["11298.40000", "0.02370000", "1596616594.018563", "s", "l", ""]], "trade", "XBT/USD"]
[275, ["11298.40000", "11298.50000", "1596616594.018563", "0.51341316", "2.90419431"], "spread", "XBT/USD"]
[275, ["11298.40000", "11298.50000", "1596616594.089588", "0.51341316", "6.20419431"], "spread", "XBT/USD"]
[275, ["11298.40000", "11298.50000", "1596616594.150476", "0.51341316", "2.90419431"], "spread", "XBT/USD"]
[275, ["11298.40000", "11298.50000", "1596616594.307986", "0.52913917", "2.90419431"], "spread", "XBT/USD"]
[275, ["11298.40000", "11298.50000", "1596616596.063308", "0.52913917", "3.40419431"], "spread", "XBT/USD"]
[275, ["11298.40000", "11298.50000", "1596616596.587947", "0.51341316", "3.40419431"], "spread", "XBT/USD"]
[275, ["11298.40000", "11298.50000", "1596616597.955156", "0.51341316", "2.90419431"], "spread", "XBT/USD"]
[275, ["11298.40000", "11298.50000", "1596616599.089705", "0.52913917", "2.90419431"], "spread", "XBT/USD"]
[275, ["11298.40000", "11298.50000", "1596616600.446631", "0.52913917", "0.90419431"], "spread", "XBT/USD"]
[275, ["11298.40000", "11298.50000", "1596616601.055315", "2.52913917", "0.90419431"], "spread", "XBT/USD"]
[275, ["11298.40000", "11298.50000", "1596616601.160880", "2.52913917", "0.66419431"], "spread", "XBT/USD"]
[275, ["11298.40000", "11299.10000", "1596616601.055315", "2.52913917", "0.01538752"], "spread", "XBT/USD"]
[275, ["11298.50000", "11299.10000", "1596616601.478523", "0.42000000", "0.01538752"], "spread", "XBT/USD"]
[275, ["11298.50000", "11299.10000", "1596616601.502311", "1.17551922", "0.01538752"], "spread", "XBT/USD"]
[275, ["11298.50000", "11299.10000", "1596616601.547570", "0.42000000", "0.01538752"], "spread", "XBT/USD"]
[275, ["11298.60000", "11299.10000", "1596616601.562723", "0.01572600", "0.01538752"], "spread", "XBT/USD"]
[275, ["11299.00000", "11299.10000", "1596616601.579319", "0.50000000", "0.01538752"], "spread", "XBT/USD"]
[275, ["11299.00000", "11299.10000", "1596616601.637274", "2.50000000", "0.01538752"], "spread", "XBT/USD"]
[275, ["11299.00000", "11299.10000", "1596616601.688800", "4.50000000", "0.01538752"], "spread", "XBT/USD"]
[275, ["11299.00000", "11299.10000", "1596616601.730341", "4.51572601", "0.01538752"], "spread", "XBT/USD"]
[275, ["11299.00000", "11299.10000", "1596616601.734563", "4.68072601", "0.01538752"], "spread", "XBT/USD"]
[275, ["11299.00000", "11299.50000", "1596616601.734563", "4.68072601", "0.07693761"], "spread", "XBT/USD"]
[275, ["11299.40000", "11299.50000", "1596616601.875250", "0.50000000", "0.07693761"], "spread", "XBT/USD"]
[275, ["11299.40000", "11299.50000", "1596616601.945776", "1.30000000", "0.07693761"], "spread", "XBT/USD"]
[275, ["11299.40000", "11299.50000", "1596616602.032870", "3.30000000", "0.07693761"], "spread", "XBT/USD"]
[275, ["11299.40000", "11299.50000", "1596616602.231529", "3.70000000", "0.07693761"], "spread", "XBT/USD"]
[275, ["11299.40000", "11299.50000", "1596616602.443852", "2.90000000", "0.07693761"], "spread", "XBT/USD"]
[275, ["11299.40000", "11299.50000", "1596616602.731604", "2.91572600", "0.07693761"], "spread", "XBT/USD"]
[275, ["11299.40000", "11299.50000", "1596616602.788645", "3.34512084", "0.07693761"], "spread", "XBT/USD"]
[275, ["11299.40000", "11299.50000", "1596616602.806124", "3.47612084", "0.07693761"], "spread", "XBT/USD"]
[275, ["11299.40000", "11299.70000", "1596616602.806124", "3.47612084", "0.09621094"], "spread", "XBT/USD"]
[275, ["11299.40000", "11299.70000", "1596616603.440290", "2.97612084", "0.09621094"], "spread", "XBT/USD"]
[275, ["11299.60000", "11299.70000", "1596616603.440525", "0.50000000", "0.09621094"], "spread", "XBT/USD"]
[275, ["11299.60000", "11299.70000", "1596616603.499721", "2.45000000", "0.09621094"], "spread", "XBT/USD"]
[275, ["11299.60000", "11299.70000", "1596616603.521197", "2.46572601", "0.09621094"], "spread", "XBT/USD"]
[275, ["11299.60000", "11299.70000", "1596616603.610785", "4.46572601", "0.09621094"], "spread", "XBT/USD"]
[275, ["11299.60000", "11299.70000", "1596616604.044555", "4.96276994", "0.09621094"], "spread", "XBT/USD"]
[275, ["11299.60000", "11299.70000", "1596616605.151353", "5.98776994", "0.09621094"], "spread", "XBT/USD"]
[275, ["11299.60000", "11299.70000", "1596616606.056577", "6.11876994", "0.09621094"], "spread", "XBT/USD"]
[271, [["11299.70000", "0.09621094", "1596616606.492555", "b", "l", ""], ["11301.90000", "0.31331886", "1596616606.497383", "b", "l", ""]], "trade", "XBT/USD"]
[275, ["11299.60000", "11301.90000", "1596616606.497383", "6.11876994", "0.35064822"], "spread", "XBT/USD"]
[275, ["11299.60000", "11301.90000", "1596616606.554937", "5.61876994", "0.35064822"], "spread", "XBT/USD"]
[275, ["11301.80000", "11301.90000", "1596616606.555822", "0.50000000", "0.35064822"], "spread", "XBT/USD"]
[275, ["11301.80000", "11301.90000", "1596616606.628983", "0.51572600", "0.35064822"], "spread", "XBT/USD"]
[275, ["11301.80000", "11301.90000", "1596616606.728504", "2.51572600", "0.35064822"], "spread", "XBT/USD"]
[275, ["11301.80000", "11301.90000", "1596616607.100588", "3.10707542", "0.35064822"], "spread", "XBT/USD"]
[275, ["11301.80000", "11301.90000", "1596616607.898410", "1.10707542", "0.35064822"], "spread", "XBT/USD"]
[275, ["11301.80000", "11301.90000", "1596616607.997377", "1.63707542", "0.35064822"], "spread", "XBT/USD"]
[271, [["11301.90000", "0.00539960", "1596616610.947744", "b", "l", ""]], "trade", "XBT/USD"]
[275, ["11301.80000", "11301.90000", "1596616610.947744", "1.63707542", "0.34524862"], "spread", "XBT/USD"]
[275, ["11301.80000", "11301.90000", "1596616614.801313", "1.63707542", "0.34820738"], "spread", "XBT/USD"]
[275, ["11301.80000", "11301.90000", "1596616616.716312", "1.63707542", "2.34820738"], "spread", "XBT/USD"]
[275, ["11301.80000", "11301.90000", "1596616616.882555", "1.13707542", "2.34820738"], "spread", "XBT/USD"]
[275, ["11301.80000", "11301.90000", "1596616617.958337", "0.60707542", "2.34820738"], "spread", "XBT/USD"]
[275, ["11301.80000", "11301.90000", "1596616618.030835", "0.01572600", "2.34820738"], "spread", "XBT/USD"]
[275, ["11299.80000", "11301.90000", "1596616616.716312", "0.50310000", "2.34820738"], "spread", "XBT/USD"]
[275, ["11299.60000", "11301.90000", "1596616616.937957", "2.00000000", "2.34820738"], "spread", "XBT/USD"]
[275, ["11299.70000", "11301.90000", "1596616618.208880", "0.01572600", "2.34820738"], "spread", "XBT/USD"]
[275, ["11299.90000", "11301.90000", "1596616618.233904", "0.01572601", "2.34820738"], "spread", "XBT/USD"]
[275, ["11299.90000", "11300.80000", "1596616618.359827", "0.01572601", "0.24000000"], "spread", "XBT/USD"]
[275, ["11299.90000", "11300.80000", "1596616618.564425", "0.49442224", "0.24000000"], "spread", "XBT/USD"]
[275, ["11299.90000", "11300.80000", "1596616618.855043", "0.49442224", "0.24295876"], "spread", "XBT/USD"]
[275, ["11299.90000", "11300.00000", "1596616618.856438", "0.49442224", "3.42350500"], "spread", "XBT/USD"]
[275, ["11299.90000", "11300.00000", "1596616618.905108", "0.01572601", "3.42350500"], "spread", "XBT/USD"]
[275, ["11299.90000", "11300.00000", "1596616618.915957", "0.01572601", "5.47350500"], "spread", "XBT/USD"]
[275, ["11299.90000", "11300.00000", "1596616619.007992", "0.01572601", "7.47350500"], "spread", "XBT/USD"]
[275, ["11299.70000", "11300.00000", "1596616619.007992", "0.01572600", "7.47350500"], "spread", "XBT/USD"]
[275, ["11296.80000", "11300.00000", "1596616619.042193", "0.03750000", "7.47350500"], "spread", "XBT/USD"]
[275, ["11298.10000", "11300.00000", "1596616619.391610", "0.13100000", "7.47350500"], "spread", "XBT/USD"]
[275, ["11298.10000", "11300.00000", "1596616619.400146", "0.13100000", "11.88950500"], "spread", "XBT/USD"]
[275, ["11298.20000", "11300.00000", "1596616619.461044", "0.01572601", "11.88950500"], "spread", "XBT/USD"]
[275, ["11298.20000", "11298.50000", "1596616619.652028", "0.01572601", "0.24000000"], "spread", "XBT/USD"]
T/USD"]
[270, {"b": [["11293.00000", "0.86250000", "1596616575.916548"]], "c": "1300171157"}, "book-100", "XBT/USD"]
[270, {"a": [["11302.90000", "2.15000000", "1596616575.919087"]], "c": "1300171157"}, "book-100", "XBT/USD"]
[270, {"b": [["11278.90000", "0.00000000", "1596616576.007700"], ["11259.40000", "2.87122823", "1596616432.583060", "r"]], "c": "1300171157"}, "book-100", "XBT/USD"]
[270, {"b": [["11278.60000", "0.00448589", "1596616576.195522"]], "c": "1300171157"}, "book-100", "XBT/USD"]
[270, {"a": [["11300.20000", "0.04617403", "1596616576.316440"]], "c": "3937485551"}, "book-100", "XBT/USD"]
[270, {"a": [["11300.90000", "0.00000000", "1596616576.535602"], ["11340.00000", "1.44239000", "1596616170.462982", "r"]], "c": "1025008297"}, "book-100", "XBT/USD"]
[270, {"a": [["11300.10000", "9.24741147", "1596616576.633494"]], "c": "1036022048"}, "book-100", "XBT/USD"]
[270, {"a": [["11322.00000", "0.18439000", "1596616576.662763"]], "c": "1036022048"}, "book-100", "XBT/USD"]
[270, {"b": [["11294.70000", "0.00000000", "1596616576.931139"], ["11259.40000", "2.87122823", "1596616432.583060", "r"]], "c": "1036022048"}, "book-100", "XBT/USD"]
[270, {"b": [["11294.50000", "0.26692035", "1596616577.030461"]], "c": "1036022048"}, "book-100", "XBT/USD"]
[270, {"a": [["11321.60000", "0.00000000", "1596616577.501695"], ["11340.00000", "1.44239000", "1596616170.462982", "r"]], "c": "1036022048"}, "book-100", "XBT/USD"]
[270, {"a": [["11300.10000", "8.58322144", "1596616577.595755"]], "c": "2630385999"}, "book-100", "XBT/USD"]
[270, {"b": [["11290.70000", "0.15278383", "1596616577.596802"]], "c": "2630385999"}, "book-100", "XBT/USD"]
[270, {"b": [["11298.00000", "0.00000000", "1596616577.614218"], ["11259.40000", "2.87122823", "1596616432.583060", "r"]], "c": "1831772938"}, "book-100", "XBT/USD"]
[270, {"b": [["11295.60000", "0.66417674", "1596616577.671427"]], "c": "2376663920"}, "book-100", "XBT/USD"]
[270, {"a": [["11299.10000", "0.67956426", "1596616577.671964"]], "c": "2980718684"}, "book-100", "XBT/USD"]
[270, {"a": [["11336.50000", "0.00000000", "1596616577.683431"], ["11341.10000", "1.99183479", "1596616551.311893", "r"]], "c": "2980718684"}, "book-100", "XBT/USD"]
[270, {"a": [["11299.30000", "0.50000000", "1596616577.766725"]], "c": "977214976"}, "book-100", "XBT/USD"]
[270, {"a": [["11329.70000", "0.05405534", "1596616578.048139"]], "c": "977214976"}, "book-100", "XBT/USD"]
[270, {"a": [["11299.10000", "2.67956426", "1596616578.050442"]], "c": "1915727428"}, "book-100", "XBT/USD"]
[270, {"a": [["11310.60000", "0.00000000", "1596616578.198126"], ["11341.10000", "1.99183479", "1596616551.311893", "r"]], "c": "1915727428"}, "book-100", "XBT/USD"]
[270, {"b": [["11293.00000", "0.09202000", "1596616578.244482"]], "c": "1915727428"}, "book-100", "XBT/USD"]
[270, {"a": [["11313.90000", "5.51716077", "1596616578.278873"]], "c": "1915727428"}, "book-100", "XBT/USD"]
[270, {"a": [["11301.30000", "1.37528000", "1596616578.343664"]], "c": "1915727428"}, "book-100", "XBT/USD"]
[270, {"a": [["11313.00000", "0.00000000", "1596616578.440076"], ["11342.30000", "15.90000000", "1596616084.694837", "r"]], "c": "1915727428"}, "book-100", "XBT/USD"]
[270, {"a": [["11313.90000", "5.51191399", "1596616578.597471"]], "c": "1915727428"}, "book-100", "XBT/USD"]
[270, {"b": [["11282.50000", "0.00000000", "1596616578.656702"], ["11259.40000", "2.87122823", "1596616432.583060", "r"]], "c": "1915727428"}, "book-100", "XBT/USD"]
[270, {"b": [["11295.40000", "0.00000000", "1596616578.703437"], ["11257.10000", "1.13241994", "1596616129.546772", "r"]], "c": "1915727428"}, "book-100", "XBT/USD"]
[270, {"b": [["11294.50000", "0.83509167", "1596616578.708482"]], "c": "1915727428"}, "book-100", "XBT/USD"]
[270, {"b": [["11282.60000", "2.09370241", "1596616578.779152"]], "c": "1915727428"}, "book-100", "XBT/USD"]
[270, {"a": [["11313.80000", "0.00523982", "1596616578.783335"]], "c": "1915727428"}, "book-100", "XBT/USD"]
[270, {"a": [["11299.10000", "0.67956426", "1596616578.901841"]], "c": "977214976"}, "book-100", "XBT/USD"]
[270, {"a": [["11321.70000", "0.28000000", "1596616578.970958"]], "c": "977214976"}, "book-100", "XBT/USD"]
[270, {"b": [["11282.70000", "0.13848319", "1596616579.007573"]], "c": "977214976"}, "book-100", "XBT/USD"]
[270, {"a": [["11300.10000", "8.31630000", "1596616579.007755"]], "c": "306304872"}, "book-100", "XBT/USD"]
[270, {"b": [["11284.10000", "0.18465474", "1596616579.068218"]], "c": "306304872"}, "book-100", "XBT/USD"]
[270, {"b": [["11294.50000", "0.56817132", "1596616579.204030"]], "c": "306304872"}, "book-100", "XBT/USD"]
[270, {"b": [["11295.40000", "0.26689787", "1596616579.303591"]], "c": "306304872"}, "book-100", "XBT/USD"]
[270, {"b": [["11295.80000", "0.00000000", "1596616579.310498"], ["11259.40000", "2.87122823", "1596616432.583060", "r"]], "c": "1366741756"}, "book-100", "XBT/USD"]
[270, {"b": [["11294.50000", "0.00000000", "1596616579.331495"], ["11257.10000", "1.13241994", "1596616129.546772", "r"]], "c": "1366741756"}, "book-100", "XBT/USD"]
[270, {"b": [["11278.60000", "0.00000000", "1596616579.346512"], ["11257.00000", "1.20912214", "1596616220.892073", "r"]], "c": "1366741756"}, "book-100", "XBT/USD"]
[270, {"a": [["11313.80000", "0.00000000", "1596616579.346807"], ["11341.10000", "1.99183479", "1596616551.311893", "r"]], "c": "1366741756"}, "book-100", "XBT/USD"]
[270, {"a": [["11299.20000", "0.02370000", "1596616579.400387"]], "c": "4085789950"}, "book-100", "XBT/USD"]
[270, {"a": [["11301.20000", "0.26690021", "1596616579.406799"]], "c": "4085789950"}, "book-100", "XBT/USD"]
[270, {"b": [["11288.10000", "1.76300000", "1596616579.411980"]], "c": "4085789950"}, "book-100", "XBT/USD"]
[270, {"a": [["11304.10000", "1.76600000", "1596616579.415391"]], "c": "4085789950"}, "book-100", "XBT/USD"]
[270, {"b": [["11296.30000", "0.92907305", "1596616579.493797"]], "c": "292433992"}, "book-100", "XBT/USD"]
[270, {"b": [["11295.70000", "0.45088904", "1596616579.522949"]], "c": "3882552143"}, "book-100", "XBT/USD"]
[270, {"a": [["11299.10000", "0.01538752", "1596616579.641020"]], "c": "680931151"}, "book-100", "XBT/USD"]
[270, {"b": [["11295.70000", "0.00000000", "1596616579.765228"], ["11257.10000", "1.13241994", "1596616129.546772", "r"]], "c": "3734180936"}, "book-100", "XBT/USD"]
[270, {"b": [["11294.50000", "0.49662449", "1596616579.766766"]], "c": "3734180936"}, "book-100", "XBT/USD"]
[270, {"a": [["11301.30000", "1.00628000", "1596616579.772137"]], "c": "3734180936"}, "book-100", "XBT/USD"]
[270, {"b": [["11295.60000", "0.00000000", "1596616579.820116"], ["11257.10000", "1.13241994", "1596616129.546772", "r"]], "c": "4230867804"}, "book-100", "XBT/USD"]
[270, {"b": [["11298.00000", "0.66416698", "1596616579.878736"]], "c": "1783967482"}, "book-100", "XBT/USD"]
[270, {"a": [["11314.10000", "2.60326702", "1596616579.942237"]], "c": "1783967482"}, "book-100", "XBT/USD"]
[270, {"a": [["11314.10000", "0.00000000", "1596616579.942360"], ["11339.40000", "7.13898822", "1596616240.060841", "r"]], "c": "1783967482"}, "book-100", "XBT/USD"]
[270, {"b": [["11288.10000", "0.00000000", "1596616579.984288"], ["11257.10000", "1.13241994", "1596616129.546772", "r"]], "c": "1783967482"}, "book-100", "XBT/USD"]
[270, {"a": [["11308.00000", "0.00000000", "1596616580.003472"], ["11340.00000", "1.44239000", "1596616170.462982", "r"]], "c": "1783967482"}, "book-100", "XBT/USD"]
[270, {"a": [["11300.40000", "2.70523423", "1596616580.006535"]], "c": "2590389998"}, "book-100", "XBT/USD"]
[270, {"a": [["11299.30000", "0.00000000", "1596616580.041387"], ["11341.10000", "1.99183479", "1596616551.311893", "r"]], "c": "2565564782"}, "book-100", "XBT/USD"]
[270, {"a": [["11301.90000", "0.88557978", "1596616580.112148"]], "c": "2565564782"}, "book-100", "XBT/USD"]
[270, {"a": [["11307.80000", "0.46150960", "1596616580.195799"]], "c": "2565564782"}, "book-100", "XBT/USD"]
[270, {"b": [["11282.40000", "0.50000000", "1596616580.350963"]], "c": "2565564782"}, "book-100", "XBT/USD"]
[270, {"a": [["11301.30000", "0.00000000", "1596616580.354567"], ["11340.00000", "1.44239000", "1596616170.462982", "r"]], "c": "2565564782"}, "book-100", "XBT/USD"]
[270, {"a": [["11303.70000", "0.77170000", "1596616580.358957"]], "c": "2565564782"}, "book-100", "XBT/USD"]
[270, {"a": [["11307.80000", "0.00000000", "1596616580.392689"], ["11340.00000", "1.44239000", "1596616170.462982", "r"]], "c": "2565564782"}, "book-100", "XBT/USD"]
[270, {"a": [["11307.80000", "0.46330997", "1596616580.582030"]], "c": "2565564782"}, "book-100", "XBT/USD"]
[270, {"a": [["11323.00000", "0.76867787", "1596616580.705343"]], "c": "2565564782"}, "book-100", "XBT/USD"]
[270, {"a": [["11322.10000", "0.00000000", "1596616580.714521"], ["11339.40000", "7.13898822", "1596616240.060841", "r"]], "c": "2565564782"}, "book-100", "XBT/USD"]
[270, {"b": [["11261.90000", "0.00000000", "1596616580.714903"], ["11257.10000", "1.13241994", "1596616129.546772", "r"]], "c": "2565564782"}, "book-100", "XBT/USD"]
[270, {"a": [["11308.10000", "0.00000000", "1596616580.726553"], ["11340.00000", "1.44239000", "1596616170.462982", "r"]], "c": "2565564782"}, "book-100", "XBT/USD"]
[270, {"b": [["11261.10000", "0.76867787", "1596616580.827452"]], "c": "2565564782"}, "book-100", "XBT/USD"]
[270, {"b": [["11282.70000", "0.00000000", "1596616580.920520"], ["11257.10000", "1.13241994", "1596616129.546772", "r"]], "c": "2565564782"}, "book-100", "XBT/USD"]
[270, {"a": [["11304.40000", "0.64515428", "1596616580.971569"]], "c": "2565564782"}, "book-100", "XBT/USD"]
[270, {"b": [["11286.90000", "2.65331870", "1596616581.038604"]], "c": "2565564782"}, "book-100", "XBT/USD"]
[270, {"a": [["11304.10000", "0.00000000", "1596616581.049543"], ["11340.00000", "1.44239000", "1596616170.462982", "r"]], "c": "2565564782"}, "book-100", "XBT/USD"]
[270, {"a": [["11303.10000", "2.01300000", "1596616581.059058"]], "c": "2565564782"}, "book-100", "XBT/USD"]
[270, {"b": [["11282.10000", "3.41495460", "1596616581.152926"]], "c": "2565564782"}, "book-100", "XBT/USD"]
[270, {"b": [["11295.40000", "0.00000000", "1596616581.376629"], ["11257.00000", "1.20912214", "1596616220.892073", "r"]], "c": "1147059565"}, "book-100", "XBT/USD"]
[270, {"a": [["11300.70000", "0.26690765", "1596616581.578280"]], "c": "1343047016"}, "book-100", "XBT/USD"]
[270, {"a": [["11301.20000", "0.00000000", "1596616581.591197"], ["11340.00000", "1.44239000", "1596616170.462982", "r"]], "c": "1343047016"}, "book-100", "XBT/USD"]
[270, {"b": [["11295.10000", "0.26690593", "1596616581.678301"]], "c": "1343047016"}, "book-100", "XBT/USD"]
[270, {"b": [["11290.80000", "0.00000000", "1596616581.736480"], ["11257.00000", "1.20912214", "1596616220.892073", "r"]], "c": "1343047016"}, "book-100", "XBT/USD"]
[270, {"a": [["11310.40000", "3.00000000", "1596616581.742631"]], "c": "1343047016"}, "book-100", "XBT/USD"]
[270, {"b": [["11290.80000", "0.09621094", "1596616581.850367"]], "c": "1343047016"}, "book-100", "XBT/USD"]
[270, {"a": [["11299.10000", "2.01538752", "1596616582.042081"]], "c": "3719040507"}, "book-100", "XBT/USD"]
[270, {"a": [["11299.10000", "2.51538752", "1596616582.062790"]], "c": "284845503"}, "book-100", "XBT/USD"]
[270, {"a": [["11299.10000", "0.51538752", "1596616582.163820"]], "c": "2994498072"}, "book-100", "XBT/USD"]
[270, {"a": [["11300.90000", "0.87670000", "1596616582.242904"]], "c": "2994498072"}, "book-100", "XBT/USD"]
[270, {"b": [["11285.50000", "0.00000000", "1596616582.356846"], ["11257.00000", "1.20912214", "1596616220.892073", "r"]], "c": "2994498072"}, "book-100", "XBT/USD"]
[270, {"b": [["11284.10000", "0.00000000", "1596616582.356952"], ["11256.80000", "5.90000000", "1596615923.474855", "r"]], "c": "2994498072"}, "book-100", "XBT/USD"]
[270, {"b": [["11294.50000", "4.90962449", "1596616582.657108"]], "c": "2994498072"}, "book-100", "XBT/USD"]
[270, {"b": [["11289.80000", "0.00000000", "1596616582.740993"], ["11256.60000", "3.79797248", "1596616513.236472", "r"]], "c": "2994498072"}, "book-100", "XBT/USD"]
[270, {"b": [["11293.20000", "1.50000000", "1596616582.751532"]], "c": "2994498072"}, "book-100", "XBT/USD"]
[270, {"a": [["11299.10000", "2.51538752", "1596616583.361079"]], "c": "284845503"}, "book-100", "XBT/USD"]
[270, {"b": [["11298.00000", "0.00000000", "1596616583.657111"], ["11256.40000", "2.57132519", "1596616490.638616", "r"]], "c": "4252324262"}, "book-100", "XBT/USD"]
