[275, ["11317.60000", "11318.20000", "1596615445.411259", "0.01036301", "2.00000000"], "spread", "XBT/USD"]
[275, ["11317.60000", "11318.20000", "1596615447.851128", "0.01036301", "2.66298483"], "spread", "XBT/USD"]
[275, ["11317.60000", "11318.10000", "1596615463.935681", "0.01036301", "0.26647543"], "spread", "XBT/USD"]
[275, ["11317.60000", "11317.90000", "1596615464.056633", "0.01036301", "0.66304554"], "spread", "XBT/USD"]
[275, ["11317.60000", "11317.70000", "1596615464.191991", "0.01036301", "2.00000000"], "spread", "XBT/USD"]
[275, ["11317.60000", "11317.70000", "1596615472.719774", "0.01036301", "2.26650047"], "spread", "XBT/USD"]
[275, ["11317.60000", "11317.70000", "1596615477.559896", "0.01036301", "2.26964667"], "spread", "XBT/USD"]
[275, ["11317.60000", "11317.70000", "1596615479.159015", "0.01036301", "4.02764667"], "spread", "XBT/USD"]
[275, ["11317.60000", "11317.70000", "1596615487.421228", "0.01036301", "4.42764667"], "spread", "XBT/USD"]
[275, ["11317.60000", "11317.70000", "1596615490.014477", "0.01036301", "4.92764667"], "spread", "XBT/USD"]
[275, ["11317.60000", "11317.70000", "1596615490.262990", "0.01036301", "5.29664667"], "spread", "XBT/USD"]
[275, ["11317.60000", "11317.70000", "1596615490.568970", "0.01036301", "5.59664667"], "spread", "XBT/USD"]
[275, ["11317.60000", "11317.70000", "1596615491.305974", "0.01036301", "11.14664667"], "spread", "XBT/USD"]
[275, ["11317.50000", "11317.70000", "1596615491.305974", "0.14250000", "11.14664667"], "spread", "XBT/USD"]
[275, ["11317.50000", "11317.70000", "1596615491.665259", "0.14250000", "11.23500424"], "spread", "XBT/USD"]
[275, ["11317.50000", "11317.70000", "1596615491.760698", "0.14250000", "10.73500424"], "spread", "XBT/USD"]
[275, ["11317.50000", "11317.60000", "1596615491.915994", "0.14250000", "0.50000000"], "spread", "XBT/USD"]
[275, ["11317.50000", "11317.60000", "1596615491.924732", "0.14250000", "0.53750000"], "spread", "XBT/USD"]
[271, [["11317.50000", "0.14250000", "1596615491.941890", "s", "l", ""]], "trade", "XBT/USD"]
[275, ["11315.60000", "11317.50000", "1596615491.941424", "0.15966872", "0.00750000"], "spread", "XBT/USD"]
[275, ["11315.60000", "11317.50000", "1596615492.004728", "0.15966872", "7.80750000"], "spread", "XBT/USD"]
[275, ["11315.60000", "11317.40000", "1596615492.088320", "0.15966872", "0.01036300"], "spread", "XBT/USD"]
[275, ["11315.60000", "11317.00000", "1596615492.090087", "0.15966872", "0.50000000"], "spread", "XBT/USD"]
[275, ["11315.60000", "11317.00000", "1596615492.152707", "0.15966872", "2.50000000"], "spread", "XBT/USD"]
[275, ["11315.60000", "11316.90000", "1596615492.168338", "0.15966872", "0.01036300"], "spread", "XBT/USD"]
[275, ["11315.60000", "11316.90000", "1596615492.503029", "0.15966872", "0.67373676"], "spread", "XBT/USD"]
[275, ["11315.60000", "11316.90000", "1596615492.515666", "0.15966872", "0.67688296"], "spread", "XBT/USD"]
[275, ["11315.60000", "11316.50000", "1596615492.577598", "0.15966872", "5.00000000"], "spread", "XBT/USD"]
[275, ["11315.60000", "11316.40000", "1596615492.651805", "0.15966872", "2.00000000"], "spread", "XBT/USD"]
[275, ["11315.60000", "11316.30000", "1596615493.003030", "0.15966872", "0.50000000"], "spread", "XBT/USD"]
[275, ["11315.60000", "11315.70000", "1596615493.052581", "0.15966872", "5.00000000"], "spread", "XBT/USD"]
[275, ["11315.60000", "11315.70000", "1596615493.112262", "0.15966872", "5.66341140"], "spread", "XBT/USD"]
[275, ["11315.60000", "11315.70000", "1596615493.118428", "0.15966872", "11.51341140"], "spread", "XBT/USD"]
[275, ["11315.60000", "11315.70000", "1596615493.221134", "0.15966872", "13.51341140"], "spread", "XBT/USD"]
[275, ["11315.60000", "11315.70000", "1596615493.261462", "0.15966872", "13.52377440"], "spread", "XBT/USD"]
[275, ["11315.60000", "11315.70000", "1596615493.277294", "0.15966872", "17.94377440"], "spread", "XBT/USD"]
[275, ["11315.60000", "11315.70000", "1596615493.347126", "0.15966872", "21.41571991"], "spread", "XBT/USD"]
[275, ["11315.60000", "11315.70000", "1596615493.590678", "0.15966872", "21.41886611"], "spread", "XBT/USD"]
[275, ["11315.60000", "11315.70000", "1596615493.789858", "0.15966872", "15.56886611"], "spread", "XBT/USD"]
[275, ["11315.60000", "11315.70000", "1596615494.021073", "0.15966872", "15.93786611"], "spread", "XBT/USD"]
[275, ["11315.60000", "11315.70000", "1596615494.151425", "0.15966872", "16.43786611"], "spread", "XBT/USD"]
[275, ["11315.60000", "11315.70000", "1596615494.269921", "0.15966872", "16.70446966"], "spread", "XBT/USD"]
[275, ["11315.60000", "11315.70000", "1596615494.392229", "0.15966872", "17.20446966"], "spread", "XBT/USD"]
[275, ["11315.60000", "11315.70000", "1596615495.072258", "0.15966872", "17.20132346"], "spread", "XBT/USD"]
[275, ["11315.60000", "11315.70000", "1596615495.510722", "0.15966872", "17.20438278"], "spread", "XBT/USD"]
[275, ["11315.60000", "11315.70000", "1596615495.513694", "0.15966872", "16.70438278"], "spread", "XBT/USD"]
[275, ["11315.60000", "11315.70000", "1596615495.884183", "0.15966872", "17.10438278"], "spread", "XBT/USD"]
[275, ["11315.60000", "11315.70000", "1596615495.899920", "0.15966872", "17.60438278"], "spread", "XBT/USD"]
[271, [["11315.70000", "0.65772157", "1596615496.336499", "b", "m", ""]], "trade", "XBT/USD"]
[275, ["11315.60000", "11315.70000", "1596615496.336499", "0.15966872", "16.94666121"], "spread", "XBT/USD"]
[275, ["11315.60000", "11315.70000", "1596615496.396620", "0.15966872", "16.44666121"], "spread", "XBT/USD"]
[275, ["11315.60000", "11315.70000", "1596615496.508775", "0.15966872", "18.21266121"], "spread", "XBT/USD"]
[275, ["11315.60000", "11315.70000", "1596615496.512511", "0.15966872", "18.30103439"], "spread", "XBT/USD"]
[275, ["11315.60000", "11315.70000", "1596615496.864660", "0.15966872", "18.30320319"], "spread", "XBT/USD"]
[275, ["11315.60000", "11315.70000", "1596615497.362987", "0.15966872", "18.50320319"], "spread", "XBT/USD"]
[275, ["11315.60000", "11315.70000", "1596615501.486555", "0.15966872", "18.50014387"], "spread", "XBT/USD"]
[275, ["11315.60000", "11315.70000", "1596615501.887791", "0.15966872", "18.50318944"], "spread", "XBT/USD"]
[275, ["11315.60000", "11315.70000", "1596615503.884107", "0.15966872", "18.10318944"], "spread", "XBT/USD"]
[275, ["11315.60000", "11315.70000", "1596615506.173670", "0.15966872", "18.10014387"], "spread", "XBT/USD"]
[271, [["11315.60000", "0.10000000", "1596615506.488506", "s", "l", ""]], "trade", "XBT/USD"]
[275, ["11315.60000", "11315.70000", "1596615506.488506", "0.05966872", "18.10014387"], "spread", "XBT/USD"]
[275, ["11315.60000", "11315.70000", "1596615506.585509", "0.05966872", "18.10314545"], "spread", "XBT/USD"]
[271, [["11315.60000", "0.05966872", "1596615506.837519", "s", "l", ""], ["11311.70000", "0.04033128", "1596615506.841559", "s", "l", ""]], "trade", "XBT/USD"]
[275, ["11311.70000", "11315.70000", "1596615506.841559", "0.43396872", "18.10314545"], "spread", "XBT/USD"]
[275, ["11311.70000", "11315.70000", "1596615506.896943", "0.43396872", "18.50314545"], "spread", "XBT/USD"]
[275, ["11311.70000", "11315.60000", "1596615506.908896", "0.43396872", "7.80000000"], "spread", "XBT/USD"]
[275, ["11311.70000", "11315.50000", "1596615506.978559", "0.43396872", "0.01036300"], "spread", "XBT/USD"]
[275, ["11311.70000", "11314.00000", "1596615507.002768", "0.43396872", "0.88448315"], "spread", "XBT/USD"]
[275, ["11311.70000", "11313.70000", "1596615507.002872", "0.43396872", "0.66336236"], "spread", "XBT/USD"]
[271, [["11311.70000", "0.10000000", "1596615507.086584", "s", "l", ""]], "trade", "XBT/USD"]
[275, ["11311.70000", "11313.70000", "1596615507.086584", "0.33396872", "0.66336236"], "spread", "XBT/USD"]
[275, ["11311.70000", "11313.60000", "1596615507.122905", "0.33396872", "0.26659784"], "spread", "XBT/USD"]
[275, ["11311.70000", "11313.60000", "1596615507.137118", "0.33396872", "0.27696084"], "spread", "XBT/USD"]
[275, ["11311.70000", "11313.50000", "1596615507.138959", "0.33396872", "2.00000000"], "spread", "XBT/USD"]
[275, ["11311.70000", "11313.00000", "1596615507.202694", "0.33396872", "0.01538101"], "spread", "XBT/USD"]
[275, ["11311.70000", "11313.00000", "1596615507.531311", "0.33396872", "0.98138101"], "spread", "XBT/USD"]
[275, ["11311.70000", "11313.00000", "1596615507.555505", "0.33396872", "0.98354981"], "spread", "XBT/USD"]
[275, ["11311.70000", "11312.50000", "1596615507.671293", "0.33396872", "2.00000000"], "spread", "XBT/USD"]
[271, [["11311.70000", "0.10000000", "1596615507.680039", "s", "l", ""]], "trade", "XBT/USD"]
[275, ["11311.70000", "11312.50000", "1596615507.680039", "0.23396872", "2.00000000"], "spread", "XBT/USD"]
[271, [["11311.70000", "0.10000000", "1596615507.984748", "s", "l", ""]], "trade", "XBT/USD"]
[275, ["11311.70000", "11312.50000", "1596615507.984748", "0.13396872", "2.00000000"], "spread", "XBT/USD"]
[275, ["11311.70000", "11312.40000", "1596615508.257798", "0.13396872", "0.01036300"], "spread", "XBT/USD"]
[271, [["11311.70000", "0.10000000", "1596615508.286068", "s", "l", ""]], "trade", "XBT/USD"]
[275, ["11311.70000", "11312.40000", "1596615508.286068", "0.03396872", "0.01036300"], "spread", "XBT/USD"]
[271, [["11311.70000", "0.03396872", "1596615508.593813", "s", "l", ""], ["11308.80000", "0.03750000", "1596615508.596182", "s", "l", ""], ["11308.70000", "0.02853128", "1596615508.598420", "s", "l", ""]], "trade", "XBT/USD"]
[275, ["11308.70000", "11312.40000", "1596615508.598420", "0.07146872", "0.01036300"], "spread", "XBT/USD"]
[275, ["11308.00000", "11312.40000", "1596615508.257798", "10.66333035", "0.01036300"], "spread", "XBT/USD"]
[275, ["11309.20000", "11312.40000", "1596615508.774261", "2.00000000", "0.01036300"], "spread", "XBT/USD"]
[275, ["11309.20000", "11312.40000", "1596615508.787358", "2.00000000", "0.01253180"], "spread", "XBT/USD"]
[275, ["11309.20000", "11312.30000", "1596615509.033220", "2.00000000", "0.03750000"], "spread", "XBT/USD"]
[275, ["11309.20000", "11312.20000", "1596615509.104593", "2.00000000", "0.01036300"], "spread", "XBT/USD"]
[275, ["11309.20000", "11311.60000", "1596615509.887898", "2.00000000", "0.66337936"], "spread", "XBT/USD"]
[275, ["11309.20000", "11310.80000", "1596615509.888062", "2.00000000", "0.66337936"], "spread", "XBT/USD"]
[275, ["11309.20000", "11310.80000", "1596615510.196787", "2.00000000", "0.66634779"], "spread", "XBT/USD"]
[271, [["11309.20000", "0.10000000", "1596615510.287135", "s", "l", ""]], "trade", "XBT/USD"]
[275, ["11309.20000", "11310.80000", "1596615510.287135", "1.90000000", "0.66634779"], "spread", "XBT/USD"]
[275, ["11309.20000", "11310.70000", "1596615510.314224", "1.90000000", "0.01036300"], "spread", "XBT/USD"]
[275, ["11309.30000", "11310.70000", "1596615510.573204", "2.00000000", "0.01036300"], "spread", "XBT/USD"]
[271, [["11309.30000", "0.04433262", "1596615510.686312", "s", "l", ""]], "trade", "XBT/USD"]
XBT/USD"]
[270, {"a": [["11356.90000", "0.53042671", "1596615446.235961"]], "c": "1190512326"}, "book-100", "XBT/USD"]
[270, {"a": [["11318.90000", "0.00000000", "1596615446.479683"], ["11359.60000", "20.00000000", "1596615290.415297", "r"]], "c": "2705288838"}, "book-100", "XBT/USD"]
[270, {"b": [["11312.70000", "0.00000000", "1596615446.913915"], ["11272.50000", "6.40000000", "1596614421.465855", "r"]], "c": "2705288838"}, "book-100", "XBT/USD"]
[270, {"a": [["11326.10000", "0.00000000", "1596615446.913990"], ["11359.90000", "0.05000000", "1596614932.787513", "r"]], "c": "2705288838"}, "book-100", "XBT/USD"]
[270, {"a": [["11319.30000", "4.41100000", "1596615446.970637"]], "c": "1426743708"}, "book-100", "XBT/USD"]
[270, {"a": [["11356.90000", "0.00000000", "1596615447.068448"], ["11359.90000", "0.05000000", "1596614932.787513", "r"]], "c": "1426743708"}, "book-100", "XBT/USD"]
[270, {"a": [["11319.30000", "4.56100000", "1596615447.089301"]], "c": "3556404105"}, "book-100", "XBT/USD"]
[270, {"b": [["11307.20000", "0.50793952", "1596615447.107946"]], "c": "3556404105"}, "book-100", "XBT/USD"]
[270, {"a": [["11342.20000", "2.24001725", "1596615447.175027"]], "c": "3556404105"}, "book-100", "XBT/USD"]
[270, {"a": [["11319.00000", "0.15000000", "1596615447.370908"]], "c": "295051752"}, "book-100", "XBT/USD"]
[270, {"a": [["11319.30000", "4.41100000", "1596615447.381079"]], "c": "3623140911"}, "book-100", "XBT/USD"]
[270, {"a": [["11342.20000", "0.00000000", "1596615447.399265"], ["11359.60000", "20.00000000", "1596615290.415297", "r"]], "c": "3623140911"}, "book-100", "XBT/USD"]
[270, {"a": [["11320.10000", "0.00000000", "1596615447.466484"], ["11359.90000", "0.05000000", "1596614932.787513", "r"]], "c": "3119140971"}, "book-100", "XBT/USD"]
[270, {"a": [["11318.90000", "0.15000000", "1596615447.578691"]], "c": "3485868042"}, "book-100", "XBT/USD"]
[270, {"a": [["11326.10000", "0.61211386", "1596615447.590835"]], "c": "3485868042"}, "book-100", "XBT/USD"]
[270, {"a": [["11319.00000", "0.00000000", "1596615447.643762"], ["11359.60000", "20.00000000", "1596615290.415297", "r"]], "c": "2555412780"}, "book-100", "XBT/USD"]
[270, {"a": [["11321.30000", "0.07687879", "1596615447.644161"]], "c": "2555412780"}, "book-100", "XBT/USD"]
[270, {"a": [["11318.90000", "0.00000000", "1596615447.708785"], ["11359.60000", "20.00000000", "1596615290.415297", "r"]], "c": "1841620304"}, "book-100", "XBT/USD"]
[270, {"b": [["11306.30000", "0.18450909", "1596615447.804885"]], "c": "1841620304"}, "book-100", "XBT/USD"]
[270, {"a": [["11318.20000", "2.66298483", "1596615447.851128"]], "c": "928936362"}, "book-100", "XBT/USD"]
[270, {"b": [["11314.40000", "0.66298525", "1596615447.852044"]], "c": "3515727448"}, "book-100", "XBT/USD"]
[270, {"a": [["11318.30000", "0.66298483", "1596615447.852215"]], "c": "171077543"}, "book-100", "XBT/USD"]
[270, {"a": [["11318.80000", "0.66295096", "1596615447.852393"]], "c": "589641057"}, "book-100", "XBT/USD"]
[270, {"b": [["11302.20000", "0.88401062", "1596615447.852963"]], "c": "589641057"}, "book-100", "XBT/USD"]
[270, {"a": [["11320.20000", "0.88397977", "1596615447.855500"]], "c": "56464586"}, "book-100", "XBT/USD"]
[270, {"b": [["11314.50000", "0.47460000", "1596615447.902679"]], "c": "1635985196"}, "book-100", "XBT/USD"]
[270, {"b": [["11314.30000", "0.00000000", "1596615447.946013"], ["11275.00000", "0.25780659", "1596614977.276342", "r"]], "c": "3347169950"}, "book-100", "XBT/USD"]
[270, {"b": [["11303.60000", "6.48393461", "1596615447.991586"]], "c": "3347169950"}, "book-100", "XBT/USD"]
[270, {"b": [["11314.20000", "0.00000000", "1596615448.007269"], ["11274.20000", "15.10000000", "1596614778.354676", "r"]], "c": "3012691027"}, "book-100", "XBT/USD"]
[270, {"b": [["11314.20000", "0.26644583", "1596615448.105743"]], "c": "3548660467"}, "book-100", "XBT/USD"]
[270, {"a": [["11320.00000", "0.00000000", "1596615448.403398"], ["11358.10000", "17.70000000", "1596614868.797705", "r"]], "c": "1892269737"}, "book-100", "XBT/USD"]
[270, {"a": [["11319.30000", "4.67744806", "1596615448.502915"]], "c": "409271261"}, "book-100", "XBT/USD"]
[270, {"b": [["11307.20000", "0.00000000", "1596615448.592697"], ["11274.20000", "15.10000000", "1596614778.354676", "r"]], "c": "409271261"}, "book-100", "XBT/USD"]
[270, {"b": [["11312.70000", "0.47739318", "1596615448.593146"]], "c": "409271261"}, "book-100", "XBT/USD"]
[270, {"a": [["11356.20000", "0.00000000", "1596615448.661610"], ["11358.90000", "4.40000000", "1596615106.457198", "r"]], "c": "409271261"}, "book-100", "XBT/USD"]
[270, {"a": [["11337.90000", "0.00000000", "1596615448.663089"], ["11359.60000", "20.00000000", "1596615290.415297", "r"]], "c": "409271261"}, "book-100", "XBT/USD"]
[270, {"b": [["11279.50000", "0.00000000", "1596615448.666365"], ["11274.20000", "15.10000000", "1596614778.354676", "r"]], "c": "409271261"}, "book-100", "XBT/USD"]
[270, {"a": [["11339.20000", "4.31110776", "1596615448.667193"]], "c": "409271261"}, "book-100", "XBT/USD"]
[270, {"b": [["11280.20000", "0.76780649", "1596615448.706925"]], "c": "409271261"}, "book-100", "XBT/USD"]
[270, {"a": [["11356.10000", "2.30446270", "1596615448.708134"]], "c": "409271261"}, "book-100", "XBT/USD"]
[270, {"a": [["11335.10000", "0.00000000", "1596615449.038578"], ["11359.60000", "20.00000000", "1596615290.415297", "r"]], "c": "409271261"}, "book-100", "XBT/USD"]
[270, {"a": [["11324.70000", "0.00000000", "1596615449.048992"], ["11359.90000", "0.05000000", "1596614932.787513", "r"]], "c": "409271261"}, "book-100", "XBT/USD"]
[270, {"a": [["11323.10000", "0.00000000", "1596615449.061818"], ["11360.00000", "0.01780000", "1596615238.579506", "r"]], "c": "409271261"}, "book-100", "XBT/USD"]
[270, {"a": [["11322.90000", "0.13838406", "1596615449.278028"]], "c": "409271261"}, "book-100", "XBT/USD"]
[270, {"b": [["11289.30000", "4.03000000", "1596615449.383136"]], "c": "409271261"}, "book-100", "XBT/USD"]
[270, {"b": [["11310.40000", "0.00000000", "1596615449.404284"], ["11275.00000", "0.25780659", "1596614977.276342", "r"]], "c": "409271261"}, "book-100", "XBT/USD"]
[270, {"b": [["11315.80000", "0.00000000", "1596615449.404343"], ["11274.20000", "15.10000000", "1596614778.354676", "r"]], "c": "16888619"}, "book-100", "XBT/USD"]
[270, {"a": [["11324.80000", "0.00000000", "1596615449.404402"], ["11360.00000", "0.01780000", "1596615238.579506", "r"]], "c": "16888619"}, "book-100", "XBT/USD"]
[270, {"a": [["11324.90000", "1.59169000", "1596615449.404469"]], "c": "16888619"}, "book-100", "XBT/USD"]
[270, {"b": [["11314.20000", "0.00000000", "1596615449.457152"], ["11273.20000", "8.32187112", "1596615244.265959", "r"]], "c": "29747089"}, "book-100", "XBT/USD"]
[270, {"b": [["11313.50000", "0.26646282", "1596615449.490683"]], "c": "29747089"}, "book-100", "XBT/USD"]
[270, {"b": [["11313.40000", "0.00000000", "1596615449.542639"], ["11273.20000", "8.32187112", "1596615244.265959", "r"]], "c": "29747089"}, "book-100", "XBT/USD"]
[270, {"b": [["11314.60000", "0.03750000", "1596615449.620343"]], "c": "872756865"}, "book-100", "XBT/USD"]
[270, {"a": [["11324.10000", "0.03750000", "1596615449.621128"]], "c": "872756865"}, "book-100", "XBT/USD"]
[270, {"a": [["11324.10000", "0.07272000", "1596615449.623359"]], "c": "872756865"}, "book-100", "XBT/USD"]
[270, {"b": [["11308.60000", "0.07250000", "1596615449.623518"]], "c": "872756865"}, "book-100", "XBT/USD"]
[270, {"b": [["11314.40000", "1.06298525", "1596615449.820540"]], "c": "1211194765"}, "book-100", "XBT/USD"]
[270, {"a": [["11330.80000", "0.00000000", "1596615449.843266"], ["11360.00000", "0.01780000", "1596615238.579506", "r"]], "c": "1211194765"}, "book-100", "XBT/USD"]
[270, {"a": [["11321.60000", "0.96041000", "1596615449.850572"]], "c": "1211194765"}, "book-100", "XBT/USD"]
[270, {"b": [["11305.80000", "3.19498183", "1596615449.878925"]], "c": "1211194765"}, "book-100", "XBT/USD"]
[270, {"a": [["11320.40000", "2.93552106", "1596615449.879318"]], "c": "2746756758"}, "book-100", "XBT/USD"]
[270, {"b": [["11314.10000", "0.00000000", "1596615450.212581"], ["11275.00000", "0.25780659", "1596614977.276342", "r"]], "c": "2449584357"}, "book-100", "XBT/USD"]
[270, {"b": [["11313.90000", "0.00000000", "1596615450.221666"], ["11274.20000", "15.10000000", "1596614778.354676", "r"]], "c": "814497801"}, "book-100", "XBT/USD"]
[270, {"a": [["11335.00000", "6.08000000", "1596615450.281823"]], "c": "814497801"}, "book-100", "XBT/USD"]
[270, {"a": [["11319.30000", "4.41100000", "1596615450.574988"]], "c": "2104041801"}, "book-100", "XBT/USD"]
[270, {"a": [["11318.60000", "0.26646843", "1596615450.674650"]], "c": "4083924157"}, "book-100", "XBT/USD"]
[270, {"b": [["11312.60000", "0.00000000", "1596615450.739293"], ["11273.20000", "8.32187112", "1596615244.265959", "r"]], "c": "4083924157"}, "book-100", "XBT/USD"]
[270, {"b": [["11306.40000", "0.00735916", "1596615450.866267"]], "c": "4083924157"}, "book-100", "XBT/USD"]
[270, {"b": [["11305.40000", "0.00000000", "1596615450.867505"], ["11273.20000", "8.32187112", "1596615244.265959", "r"]], "c": "4083924157"}, "book-100", "XBT/USD"]
[270, {"b": [["11311.20000", "2.14716000", "1596615451.074984"]], "c": "4083924157"}, "book-100", "XBT/USD"]
[270, {"b": [["11313.50000", "0.00000000", "1596615451.597618"], ["11273.10000", "6.88256621", "1596615245.078605", "r"]], "c": "2953360951"}, "book-100", "XBT/USD"]
[270, {"b": [["11312.90000", "0.26646576", "1596615451.661295"]], "c": "1902389859"}, "book-100", "XBT/USD"]
[270, {"a": [["11321.30000", "0.00000000", "1596615451.725275"], ["11359.60000", "20.00000000", "1596615290.415297", "r"]], "c": "1902389859"}, "book-100", "XBT/USD"]
[270, {"b": [["11306.30000", "0.19186825", "1596615451.725525"]], "c": "1902389859"}, "book-100", "XBT/USD"]
[270, {"b": [["11306.40000", "0.00000000", "1596615451.726697"], ["11273.10000", "6.88256621", "1596615245.078605", "r"]], "c": "1902389859"}, "book-100", "XBT/USD"]
[270, {"b": [["11277.40000", "0.00000000", "1596615451.757641"], ["11272.50000", "6.40000000", "1596614421.465855", "r"]], "c": "1902389859"}, "book-100", "XBT/USD"]
[270, {"b": [["11315.40000", "0.00000000", "1596615451.837806"], ["11269.90000", "0.07676998", "1596615167.215147", "r"]], "c": "1671875851"}, "book-100", "XBT/USD"]
[270, {"b": [["11313.80000", "0.00000000", "1596615451.849496"], ["11269.70000", "1.10610000", "1596615299.492285", "r"]], "c": "1058802497"}, "book-100", "XBT/USD"]
[270, {"b": [["11313.00000", "0.47460000", "1596615451.903847"]], "c": "4019206103"}, "book-100", "XBT/USD"]
[270, {"a": [["11330.70000", "0.00000000", "1596615451.911009"], ["11359.90000", "0.05000000", "1596614932.787513", "r"]], "c": "4019206103"}, "book-100", "XBT/USD"]
[270, {"b": [["11314.50000", "0.00000000", "1596615451.946167"], ["11269.70000", "1.10610000", "1596615299.492285", "r"]], "c": "2617692900"}, "book-100", "XBT/USD"]
[270, {"b": [["11313.10000", "0.66303679", "1596615452.029604"]], "c": "308251657"}, "book-100", "XBT/USD"]
[270, {"a": [["11320.00000", "0.88404906", "1596615452.029714"]], "c": "1844079016"}, "book-100", "XBT/USD"]
[270, {"b": [["11313.20000", "0.47460000", "1596615452.073606"]], "c": "4269860498"}, "book-100", "XBT/USD"]
[270, {"b": [["11313.00000", "0.00000000", "1596615452.120052"], ["11269.90000", "0.07676998", "1596615167.215147", "r"]], "c": "2338741452"}, "book-100", "XBT/USD"]
[270, {"b": [["11314.80000", "0.66303679", "1596615452.333003"]], "c": "3485578556"}, "book-100", "XBT/USD"]
[270, {"b": [["11314.40000", "0.40000000", "1596615452.375681"]], "c": "68205923"}, "book-100", "XBT/USD"]
[270, {"a": [["11334.30000", "0.00000000", "1596615452.452778"], ["11359.90000", "0.05000000", "1596614932.787513", "r"]], "c": "68205923"}, "book-100", "XBT/USD"]
[270, {"b": [["11288.60000", "0.00000000", "1596615452.530103"], ["11269.90000", "0.07676998", "1596615167.215147", "r"]], "c": "68205923"}, "book-100", "XBT/USD"]
[270, {"b": [["11285.40000", "5.53507561", "1596615452.629421"]], "c": "68205923"}, "book-100", "XBT/USD"]
[270, {"a": [["11330.60000", "5.07725844", "1596615452.711155"]], "c": "68205923"}, "book-100", "XBT/USD"]
[270, {"b": [["11304.70000", "0.00000000", "1596615452.784589"], ["11269.90000", "0.07676998", "1596615167.215147", "r"]], "c": "68205923"}, "book-100", "XBT/USD"]
[270, {"a": [["11318.60000", "0.00000000", "1596615452.848535"], ["11359.90000", "0.05000000", "1596614932.787513", "r"]], "c": "4178519792"}, "book-100", "XBT/USD"]
[270, {"a": [["11318.60000", "0.26647139", "1596615452.954954"]], "c": "2509870389"}, "book-100", "XBT/USD"]
[270, {"b": [["11298.10000", "0.75132820", "1596615453.206899"]], "c": "2509870389"}, "book-100", "XBT/USD"]
