[270, {"as": [["11640.10000", "0.52820000", "1596666683.086466"], ["11643.10000", "0.01100000", "1596666695.906610"], ["11645.20000", "0.45006451", "1596666697.613084"], ["11646.00000", "0.00860968", "1596666698.505971"], ["11646.10000", "0.41352978", "1596666698.365075"], ["11646.80000", "0.25887819", "1596666698.570899"], ["11646.90000", "1.50000000", "1596666698.116857"], ["11647.70000", "0.04051069", "1596666697.698162"], ["11647.90000", "2.71417128", "1596666698.390763"], ["11648.00000", "0.85889676", "1596666656.959643"], ["11648.10000", "0.85893954", "1596666685.285601"], ["11650.00000", "0.50000000", "1596666696.475214"], ["11650.10000", "0.87728628", "1596666698.173591"], ["11650.20000", "0.33272870", "1596666698.202743"], ["11650.30000", "1.39141436", "1596666697.533050"], ["11652.80000", "0.10500000", "1596666697.769506"], ["11653.10000", "0.70560000", "1596666648.801020"], ["11653.70000", "3.05642687", "1596666698.173194"], ["11653.90000", "0.85907465", "1596666694.798514"], ["11655.10000", "1.56702951", "1596666697.822287"], ["11655.30000", "0.43900000", "1596666696.874748"], ["11655.40000", "0.70012295", "1596666695.905110"], ["11656.80000", "1.76210000", "1596666697.634727"], ["11656.90000", "0.45302121", "1596666697.217655"], ["11657.00000", "6.74297857", "1596666647.424855"], ["11657.10000", "8.00000000", "1596666651.589440"], ["11658.70000", "0.30000000", "1596666698.540453"], ["11659.00000", "2.31118332", "1596666695.481889"], ["11659.90000", "0.38000000", "1596666698.492639"], ["11660.30000", "0.90050722", "1596666698.457831"], ["11660.70000", "0.24963448", "1596666697.804732"], ["11662.40000", "2.00740726", "1596666697.361855"], ["11662.50000", "6.20129004", "1596666685.370724"], ["11662.60000", "7.08817619", "1596666664.057829"], ["11662.70000", "3.20448514", "1596666667.988421"], ["11663.20000", "1.21045325", "1596666676.238161"], ["11663.40000", "7.89544419", "1596666658.694779"], ["11665.00000", "2.87310296", "1596666660.873426"], ["11665.40000", "0.34934746", "1596666698.602284"], ["11665.50000", "0.90009831", "1596666652.970956"], ["11665.60000", "0.99495771", "1596666652.904937"], ["11665.70000", "0.78900000", "1596666691.321584"], ["11665.80000", "3.53578904", "1596666654.046724"], ["11666.20000", "0.10000000", "1596666658.023831"], ["11667.20000", "2.00641794", "1596666640.856278"], ["11667.50000", "0.02823595", "1596666686.378911"], ["11668.70000", "0.30000000", "1596666620.329289"], ["11668.80000", "0.53689408", "1596666697.552164"], ["11668.90000", "7.10000000", "1596666615.323647"], ["11670.90000", "0.99700000", "1596666647.563999"], ["11672.60000", "1.90500004", "1596666648.565477"], ["11672.70000", "0.89954311", "1596666645.120723"], ["11673.20000", "1.96313720", "1596666640.967696"], ["11673.30000", "6.40263452", "1596666660.805065"], ["11674.00000", "0.89759217", "1596666645.870424"], ["11674.20000", "7.08113307", "1596666661.174851"], ["11674.30000", "8.20000000", "1596666586.476219"], ["11674.50000", "1.00700000", "1596666608.634364"], ["11674.80000", "1.50897932", "1596666697.932984"], ["11674.90000", "3.58632191", "1596666652.232052"], ["11675.00000", "3.55092158", "1596666615.295050"], ["11676.20000", "2.25250602", "1596666691.246001"], ["11676.60000", "2.45000000", "1596666698.250852"], ["11676.70000", "1.17156292", "1596666614.241363"], ["11676.90000", "2.65562658", "1596666697.995501"], ["11677.60000", "1.49117015", "1596666647.403719"], ["11678.70000", "0.30000000", "1596666687.956527"], ["11678.80000", "6.14262875", "1596666654.290994"], ["11679.90000", "0.75800000", "1596666644.966068"], ["11680.20000", "7.40000000", "1596666456.805183"], ["11680.80000", "2.00447354", "1596666615.358517"], ["11681.20000", "0.02573600", "1596666155.937991"], ["11683.20000", "1.11290000", "1596666604.536339"], ["11684.60000", "20.90000000", "1596666588.554214"], ["11685.00000", "0.10000000", "1596666615.423939"], ["11685.30000", "2.00382222", "1596666648.908664"], ["11686.10000", "6.40000000", "1596665948.627247"], ["11686.50000", "2.31282854", "1596666676.241914"], ["11686.60000", "3.52920504", "1596666615.289128"], ["11689.60000", "0.80800000", "1596666616.212332"], ["11689.90000", "0.85800000", "1596666646.492151"], ["11690.00000", "0.04000000", "1596666607.383587"], ["11690.10000", "1.51500000", "1596666588.962892"], ["11691.30000", "2.00311243", "1596666619.337977"], ["11691.60000", "2.80491857", "1596666648.819519"], ["11691.90000", "0.89806591", "1596666649.630348"], ["11692.30000", "8.50000000", "1596666502.813701"], ["11692.70000", "1.75400000", "1596666164.005133"], ["11695.10000", "0.35368913", "1596666684.533099"], ["11698.00000", "6.50000000", "1596665849.372318"], ["11699.50000", "2.48018651", "1596666596.614575"], ["11699.90000", "0.10000000", "1596666079.896762"], ["11700.00000", "0.52000000", "1596666697.653648"], ["11701.10000", "0.01796445", "1596665962.941606"], ["11701.40000", "23.40000000", "1596666447.014661"], ["11702.50000", "23.57900000", "1596666155.599282"], ["11703.00000", "0.17085000", "1596666664.476467"], ["11704.10000", "8.30000000", "1596666665.290916"], ["11704.20000", "1.06000000", "1596666647.223134"], ["11705.90000", "4.41315145", "1596666428.485819"]], "bs": [["11640.00000", "1.17942622", "1596666698.463653"], ["11639.10000", "0.25000000", "1596666698.174288"], ["11639.00000", "0.09621094", "1596666698.506823"], ["11638.90000", "1.75150000", "1596666698.200499"], ["11638.00000", "0.75019000", "1596666698.020388"], ["11637.70000", "0.30000000", "1596666697.443410"], ["11637.60000", "0.10000000", "1596666696.525194"], ["11637.50000", "1.39095700", "1596666698.551963"], ["11637.40000", "3.20678059", "1596666698.287495"], ["11637.20000", "0.09800000", "1596666698.552394"], ["11637.10000", "4.28900000", "1596666695.826991"], ["11637.00000", "9.99987003", "1596666698.388679"], ["11636.90000", "1.44000000", "1596666696.312484"], ["11636.60000", "0.00576065", "1596666690.489101"], ["11635.40000", "0.17321000", "1596666686.890493"], ["11635.20000", "0.17324000", "1596666683.765832"], ["11635.10000", "0.94495263", "1596666680.081164"], ["11634.50000", "0.10100000", "1596666697.568321"], ["11633.80000", "1.00000000", "1596666683.482454"], ["11633.60000", "0.17324000", "1596666690.186531"], ["11633.50000", "0.30000000", "1596666694.426118"], ["11632.70000", "0.85914894", "1596666640.205173"], ["11632.50000", "0.98492000", "1596666694.544197"], ["11632.10000", "0.10000000", "1596666692.156347"], ["11631.70000", "0.47225421", "1596666695.073235"], ["11631.50000", "0.85923883", "1596666656.788173"], ["11630.10000", "8.60000000", "1596666698.077254"], ["11630.00000", "0.30000000", "1596666676.494774"], ["11629.20000", "0.09900000", "1596666691.409059"], ["11628.60000", "0.85951202", "1596666623.381791"], ["11628.50000", "0.95064000", "1596666698.584142"], ["11625.50000", "0.50000000", "1596666697.416928"], ["11624.70000", "0.02742397", "1596666698.569791"], ["11624.60000", "0.38000000", "1596666696.460532"], ["11624.00000", "8.00000000", "1596666650.300615"], ["11623.80000", "0.49928068", "1596666697.876987"], ["11622.50000", "0.58900000", "1596666685.532719"], ["11622.40000", "0.28050000", "1596666687.699925"], ["11619.80000", "3.21629798", "1596666690.624324"], ["11619.50000", "7.11449423", "1596666685.519053"], ["11619.00000", "7.00000000", "1596666643.822659"], ["11618.30000", "0.99770000", "1596666678.285323"], ["11618.00000", "0.99905987", "1596666687.946623"], ["11617.60000", "0.34015474", "1596666689.179830"], ["11617.10000", "0.08297882", "1596666687.737069"], ["11616.10000", "3.14997071", "1596666602.345081"], ["11615.60000", "0.20000000", "1596666623.308321"], ["11614.90000", "4.00000000", "1596666646.640419"], ["11614.80000", "3.08717099", "1596666614.428153"], ["11614.30000", "0.71452792", "1596666689.169698"], ["11613.50000", "0.10389717", "1596666686.687631"], ["11612.30000", "7.00000000", "1596666617.080387"], ["11612.00000", "1.42933890", "1596666689.182445"], ["11611.20000", "0.72742428", "1596666686.688751"], ["11610.00000", "0.17085000", "1596666698.121910"], ["11609.70000", "0.49800000", "1596666694.828428"], ["11608.70000", "0.90440049", "1596666696.921247"], ["11607.70000", "8.40000000", "1596666633.346482"], ["11607.40000", "2.01708019", "1596666696.933605"], ["11607.20000", "0.25076396", "1596666687.910297"], ["11606.30000", "7.12378609", "1596666643.144121"], ["11606.20000", "1.49997820", "1596666641.625234"], ["11605.80000", "2.78000000", "1596666659.526232"], ["11605.50000", "6.44110207", "1596666642.601067"], ["11605.40000", "1.21644536", "1596666686.683313"], ["11605.00000", "1.80455545", "1596666683.714398"], ["11604.30000", "0.90468260", "1596666688.107888"], ["11604.00000", "0.17085000", "1596666686.515375"], ["11603.70000", "0.35117543", "1596666687.911443"], ["11603.00000", "1.11290000", "1596666610.452721"], ["11602.50000", "3.55476989", "1596666683.737909"], ["11602.20000", "2.01681621", "1596666634.588713"], ["11602.10000", "7.70000000", "1596666410.902600"], ["11601.00000", "0.17085000", "1596666692.102814"], ["11600.90000", "1.03470000", "1596666687.748237"], ["11600.60000", "0.90503198", "1596666696.888622"], ["11600.10000", "0.07890841", "1596666687.893138"], ["11600.00000", "0.02931034", "1596666606.295532"], ["11599.50000", "2.70685593", "1596666647.527050"], ["11599.40000", "2.01816894", "1596666683.573480"], ["11598.80000", "3.66224205", "1596666696.914192"], ["11598.00000", "0.17085000", "1596666641.450096"], ["11597.80000", "0.57725260", "1596666687.091206"], ["11597.40000", "0.75048332", "1596666695.481975"], ["11596.40000", "6.55047894", "1596666692.660633"], ["11596.30000", "33.34869208", "1596666658.255922"], ["11595.50000", "7.80000000", "1596666166.613679"], ["11595.00000", "0.17085000", "1596666619.902340"], ["11594.10000", "0.48610000", "1596666616.025674"], ["11593.90000", "0.75800000", "1596666637.971081"], ["11592.90000", "0.80800000", "1596666471.264849"], ["11592.20000", "1.51929508", "1596666651.006521"], ["11592.00000", "0.17085000", "1596666664.321680"], ["11591.20000", "0.36910979", "1596666656.146173"], ["11590.20000", "0.90571082", "1596666644.915161"], ["11590.10000", "1.51500000", "1596666649.220608"], ["11590.00000", "1.97724585", "1596666646.997760"], ["11589.90000", "6.90000000", "1596666166.290818"], ["11589.40000", "0.90410776", "1596666642.290517"], ["11589.00000", "0.17085000", "1596666680.844319"]]}, "book-100", "XBT/USD"]
[270, {"a": [["11646.90000", "0.00000000", "1596666698.661190"], ["11706.00000", "0.17085000", "1596666669.832774", "r"]], "c": "4131924453"}, "book-100", "XBT/USD"]
[270, {"a": [["11659.60000", "0.10348648", "1596666698.681813"]], "c": "4131924453"}, "book-100", "XBT/USD"]
[270, {"a": [["11661.90000", "0.72426246", "1596666698.686038"]], "c": "4131924453"}, "book-100", "XBT/USD"]
[270, {"a": [["11664.20000", "3.53657250", "1596666698.751976"]], "c": "4131924453"}, "book-100", "XBT/USD"]
[270, {"a": [["11664.20000", "4.03412406", "1596666698.767277"]], "c": "4131924453"}, "book-100", "XBT/USD"]
[270, {"b": [["11640.00000", "1.57942622", "1596666698.790302"]], "c": "3435430246"}, "book-100", "XBT/USD"]
[270, {"b": [["11639.60000", "0.10000000", "1596666698.800300"]], "c": "38027548"}, "book-100", "XBT/USD"]
[270, {"a": [["11648.10000", "0.00000000", "1596666698.805125"], ["11704.20000", "1.06000000", "1596666647.223134", "r"]], "c": "1047363772"}, "book-100", "XBT/USD"]
[270, {"a": [["11648.70000", "1.50000000", "1596666698.816706"]], "c": "716383003"}, "book-100", "XBT/USD"]
[270, {"a": [["11648.00000", "0.00000000", "1596666698.852017"], ["11704.20000", "1.06000000", "1596666647.223134", "r"]], "c": "1533875763"}, "book-100", "XBT/USD"]
[270, {"a": [["11657.00000", "8.91147292", "1596666698.870770"]], "c": "1533875763"}, "book-100", "XBT/USD"]
[270, {"a": [["11645.20000", "0.00000000", "1596666698.872442"], ["11705.90000", "4.41315145", "1596666428.485819", "r"]], "c": "2542761552"}, "book-100", "XBT/USD"]
[270, {"a": [["11665.40000", "1.24946098", "1596666698.899262"]], "c": "2542761552"}, "book-100", "XBT/USD"]
[270, {"b": [["11640.00000", "2.06992622", "1596666698.912540"]], "c": "1278313610"}, "book-100", "XBT/USD"]
[270, {"b": [["11629.20000", "0.00000000", "1596666698.971062"], ["11589.00000", "0.17085000", "1596666680.844319", "r"]], "c": "1278313610"}, "book-100", "XBT/USD"]
[270, {"a": [["11653.70000", "0.00000000", "1596666699.006171"], ["11706.00000", "0.17085000", "1596666669.832774", "r"]], "c": "1278313610"}, "book-100", "XBT/USD"]
[270, {"b": [["11637.10000", "0.00000000", "1596666699.026024"], ["11588.60000", "0.75800000", "1596666599.475365", "r"]], "c": "1278313610"}, "book-100", "XBT/USD"]
[270, {"b": [["11640.00000", "6.36192622", "1596666699.048471"]], "c": "1035943715"}, "book-100", "XBT/USD"]
[270, {"a": [["11646.80000", "4.54487819", "1596666699.052438"]], "c": "1573375349"}, "book-100", "XBT/USD"]
[270, {"a": [["11657.10000", "0.00000000", "1596666699.061432"], ["11706.10000", "3.50960038", "1596666142.533745", "r"]], "c": "1573375349"}, "book-100", "XBT/USD"]
[270, {"b": [["11638.50000", "0.15000000", "1596666699.086081"]], "c": "20758814"}, "book-100", "XBT/USD"]
[270, {"a": [["11647.50000", "0.45120003", "1596666699.129891"]], "c": "4171714658"}, "book-100", "XBT/USD"]
[270, {"a": [["11650.30000", "1.49441436", "1596666699.213126"]], "c": "4171714658"}, "book-100", "XBT/USD"]
[270, {"a": [["11647.90000", "0.71417128", "1596666699.218144"]], "c": "840432129"}, "book-100", "XBT/USD"]
[270, {"a": [["11703.00000", "0.00000000", "1596666699.282726"], ["11706.10000", "3.50960038", "1596666142.533745", "r"]], "c": "840432129"}, "book-100", "XBT/USD"]
[270, {"b": [["11639.50000", "0.23000000", "1596666699.302672"]], "c": "4045252049"}, "book-100", "XBT/USD"]
[270, {"a": [["11662.70000", "0.00000000", "1596666699.320368"], ["11709.00000", "0.17085000", "1596666698.599816", "r"]], "c": "4045252049"}, "book-100", "XBT/USD"]
[270, {"a": [["11662.60000", "0.00000000", "1596666699.331204"], ["11709.60000", "4.27000068", "1596666650.408245", "r"]], "c": "4045252049"}, "book-100", "XBT/USD"]
[270, {"a": [["11662.40000", "0.00000000", "1596666699.336814"], ["11709.70000", "7.20507863", "1596666620.257365", "r"]], "c": "4045252049"}, "book-100", "XBT/USD"]
[270, {"b": [["11640.00000", "5.87142622", "1596666699.414326"]], "c": "1896443429"}, "book-100", "XBT/USD"]
[270, {"a": [["11706.00000", "0.00000000", "1596666699.443326"], ["11711.00000", "3.52207482", "1596666594.088624", "r"]], "c": "1896443429"}, "book-100", "XBT/USD"]
[270, {"a": [["11676.60000", "0.00000000", "1596666699.561466"], ["11711.10000", "2.97327583", "1596666596.503005", "r"]], "c": "1896443429"}, "book-100", "XBT/USD"]
[270, {"a": [["11649.40000", "1.71000000", "1596666699.802182"]], "c": "2685978949"}, "book-100", "XBT/USD"]
[270, {"a": [["11655.10000", "0.85899436", "1596666699.831754"]], "c": "2685978949"}, "book-100", "XBT/USD"]
[270, {"b": [["11640.00000", "6.51553838", "1596666699.857094"]], "c": "1589295908"}, "book-100", "XBT/USD"]
[270, {"a": [["11650.60000", "0.85872032", "1596666699.858543"]], "c": "1589295908"}, "book-100", "XBT/USD"]
[270, {"b": [["11639.90000", "0.64411216", "1596666699.887213"]], "c": "696851154"}, "book-100", "XBT/USD"]
[270, {"a": [["11658.90000", "0.85881622", "1596666699.901804"]], "c": "696851154"}, "book-100", "XBT/USD"]
