[270, {"as": [["11666.50000", "0.19544011", "1596666998.248958"], ["11667.80000", "0.02764903", "1596666998.445045"], ["11667.90000", "0.64282560", "1596666975.236148"], ["11668.00000", "0.12000000", "1596666994.583815"], ["11668.90000", "0.64288645", "1596667000.977468"], ["11670.00000", "0.09621094", "1596666982.531479"], ["11670.50000", "0.25833860", "1596666998.708217"], ["11670.60000", "1.80888398", "1596666997.899184"], ["11670.70000", "1.58865550", "1596666996.769623"], ["11670.80000", "0.88017947", "1596666979.528845"], ["11670.90000", "0.33193667", "1596666980.449613"], ["11671.30000", "0.04250000", "1596666995.918835"], ["11671.40000", "0.85710080", "1596666975.249633"], ["11672.10000", "4.27500000", "1596666996.420639"], ["11672.20000", "0.72019392", "1596666993.945230"], ["11672.40000", "0.01000000", "1596666998.018717"], ["11672.50000", "0.43900000", "1596666995.891833"], ["11672.60000", "0.10200000", "1596666989.037567"], ["11673.80000", "1.49615342", "1596666993.976009"], ["11674.20000", "0.85695011", "1596666972.749349"], ["11674.60000", "0.04473563", "1596666997.604023"], ["11675.00000", "0.78782000", "1596666998.442984"], ["11675.20000", "1.63421006", "1596666998.064975"], ["11676.00000", "2.10000000", "1596666963.340394"], ["11676.20000", "0.69949543", "1596666989.359499"], ["11676.70000", "0.44910055", "1596667000.025650"], ["11677.20000", "0.64364408", "1596666994.158183"], ["11677.30000", "0.85681389", "1596666966.214822"], ["11677.60000", "1.95494000", "1596667000.532607"], ["11678.40000", "1.15716573", "1596666972.591096"], ["11679.00000", "0.50000000", "1596666995.539128"], ["11679.90000", "2.12614305", "1596666999.599590"], ["11680.00000", "43.90525970", "1596666934.954962"], ["11680.20000", "0.71023319", "1596666979.434646"], ["11680.80000", "0.10327671", "1596666995.880094"], ["11681.20000", "0.02573600", "1596666963.469772"], ["11681.50000", "6.28000000", "1596666973.702817"], ["11681.70000", "0.10200000", "1596666976.431178"], ["11681.80000", "0.89844448", "1596666988.278195"], ["11682.10000", "0.70560000", "1596666963.036670"], ["11682.50000", "1.66928606", "1596666981.457983"], ["11683.30000", "0.65244654", "1596666961.695141"], ["11683.50000", "0.72259683", "1596666974.745058"], ["11683.70000", "0.49664476", "1596666985.726936"], ["11684.10000", "3.52933869", "1596666988.162945"], ["11685.00000", "0.10000000", "1596666964.589719"], ["11685.50000", "0.00438186", "1596667000.706612"], ["11685.60000", "6.01756039", "1596666873.650668"], ["11685.70000", "0.74860074", "1596666999.191410"], ["11686.00000", "1.24671103", "1596666979.754603"], ["11687.00000", "6.30000000", "1596666872.144615"], ["11688.50000", "0.51420804", "1596666994.159157"], ["11688.60000", "10.26851387", "1596666992.225451"], ["11688.70000", "0.30000000", "1596666965.080034"], ["11688.80000", "6.07329377", "1596666995.862423"], ["11688.90000", "3.79419758", "1596666913.244785"], ["11689.10000", "1.20742921", "1596666912.854645"], ["11689.90000", "3.62758759", "1596666988.157784"], ["11690.00000", "0.61255608", "1596666984.945895"], ["11692.30000", "8.50000000", "1596666844.698621"], ["11692.90000", "0.99253037", "1596666889.050049"], ["11693.10000", "1.02430000", "1596666778.415300"], ["11693.20000", "0.89759385", "1596666889.133439"], ["11693.50000", "0.65900000", "1596666992.351992"], ["11695.40000", "2.29920000", "1596666835.136695"], ["11695.60000", "0.00300000", "1596666867.549789"], ["11696.50000", "2.00135674", "1596666889.096876"], ["11698.00000", "6.50000000", "1596665849.372318"], ["11698.60000", "2.36678272", "1596666961.629651"], ["11698.70000", "0.30000000", "1596666969.814595"], ["11699.50000", "0.02826428", "1596666985.773599"], ["11699.90000", "0.10000000", "1596666079.896762"], ["11700.00000", "0.52000000", "1596666975.426937"], ["11700.10000", "2.00000000", "1596666984.399405"], ["11700.20000", "0.89705684", "1596666885.896079"], ["11700.60000", "1.95840740", "1596666921.338521"], ["11700.70000", "1.85666144", "1596666849.618097"], ["11700.90000", "0.89559657", "1596666820.585109"], ["11701.10000", "0.01796445", "1596666765.631617"], ["11701.90000", "1.48811037", "1596666805.943268"], ["11702.30000", "0.35510864", "1596666958.160334"], ["11702.50000", "9.91072811", "1596666888.698590"], ["11702.60000", "7.06311509", "1596666895.330579"], ["11702.80000", "2.67052797", "1596666959.870495"], ["11703.60000", "21.70000000", "1596666980.106096"], ["11704.10000", "8.30000000", "1596666665.290916"], ["11705.60000", "1.98337449", "1596666820.829303"], ["11706.20000", "0.75800000", "1596666915.495628"], ["11708.20000", "1.99935679", "1596666889.096786"], ["11709.00000", "0.75800000", "1596666994.886300"], ["11709.70000", "7.20507863", "1596666814.449677"], ["11709.90000", "3.52186457", "1596666773.954225"], ["11710.10000", "0.89650546", "1596666771.484931"], ["11710.40000", "1.16811308", "1596666772.597033"], ["11710.60000", "2.80039129", "1596666770.582883"], ["11710.70000", "3.52183532", "1596666711.393054"], ["11711.50000", "1.99898326", "1596666797.632161"], ["11712.00000", "0.17085000", "1596666981.360184"], ["11713.90000", "2.30673040", "1596666889.279950"], ["11715.00000", "0.17085000", "1596666969.869642"]], "bs": [["11666.40000", "0.59213147", "1596666999.031202"], ["11666.20000", "17.55438413", "1596666996.409194"], ["11665.70000", "1.17000000", "1596666962.187793"], ["11665.50000", "0.64281997", "1596666996.554070"], ["11664.80000", "0.64285416", "1596666994.452980"], ["11663.80000", "0.64290778", "1596666991.190535"], ["11663.50000", "0.75000000", "1596667000.019384"], ["11663.00000", "0.85693587", "1596666972.710636"], ["11662.20000", "0.85712227", "1596666971.976548"], ["11661.90000", "0.12500000", "1596666995.913999"], ["11661.80000", "0.10000000", "1596666988.275884"], ["11661.50000", "0.57230000", "1596666972.864995"], ["11661.40000", "0.09621094", "1596666982.531541"], ["11661.30000", "0.30000000", "1596666968.700652"], ["11661.10000", "0.73681000", "1596666988.609933"], ["11660.20000", "1.19596353", "1596666999.812196"], ["11659.90000", "0.85714254", "1596666943.808451"], ["11659.40000", "0.10100000", "1596666951.478896"], ["11658.90000", "0.30000000", "1596666871.102749"], ["11658.70000", "1.50000000", "1596666992.502880"], ["11658.20000", "0.73521750", "1596666994.232684"], ["11658.00000", "0.85725743", "1596666982.201928"], ["11657.80000", "0.81533000", "1596666979.014946"], ["11657.40000", "0.45424100", "1596666977.051380"], ["11657.00000", "0.09700000", "1596666992.354350"], ["11656.50000", "1.67830000", "1596666997.190762"], ["11656.40000", "0.10347830", "1596666990.394659"], ["11656.10000", "0.71172565", "1596667000.015910"], ["11655.00000", "0.85676910", "1596666966.214567"], ["11654.40000", "0.04473579", "1596666997.785273"], ["11654.30000", "5.95681167", "1596666992.251303"], ["11654.10000", "0.72449107", "1596666961.522827"], ["11654.00000", "0.50000000", "1596666962.607821"], ["11653.90000", "1.42369601", "1596666965.087001"], ["11653.10000", "0.13421006", "1596666998.183295"], ["11652.00000", "0.04220025", "1596666994.452244"], ["11651.90000", "3.53903132", "1596666961.694054"], ["11651.60000", "0.49804102", "1596666961.004995"], ["11650.90000", "4.00000000", "1596666973.145433"], ["11650.80000", "1.25057999", "1596666988.695561"], ["11650.50000", "6.70000000", "1596666959.838253"], ["11649.90000", "0.38000000", "1596666973.516075"], ["11648.90000", "0.30000000", "1596666965.511465"], ["11648.70000", "7.09540431", "1596666963.023083"], ["11648.60000", "0.43800000", "1596667001.099850"], ["11648.30000", "6.42865876", "1596666961.886369"], ["11648.20000", "0.00430308", "1596667000.731162"], ["11648.10000", "1.79746335", "1596666973.881461"], ["11647.70000", "0.94200000", "1596666992.267174"], ["11647.00000", "3.69719373", "1596666941.933464"], ["11646.20000", "0.57472278", "1596666964.462229"], ["11646.10000", "3.57179383", "1596666986.743909"], ["11646.00000", "1.01250000", "1596666975.298218"], ["11645.80000", "0.99650529", "1596666964.069875"], ["11645.40000", "6.10000000", "1596666958.213890"], ["11644.70000", "0.05287327", "1596666881.642051"], ["11644.50000", "0.90137060", "1596666959.920860"], ["11642.50000", "2.01063979", "1596666964.270069"], ["11640.90000", "1.96862341", "1596666833.326570"], ["11640.00000", "7.10000000", "1596666918.899653"], ["11639.20000", "0.90010710", "1596666964.458405"], ["11637.50000", "2.38000000", "1596666984.618398"], ["11636.90000", "1.51331483", "1596666962.158790"], ["11636.50000", "1.49606191", "1596666961.284185"], ["11636.20000", "0.90201354", "1596666912.913762"], ["11635.60000", "2.01177390", "1596666832.580746"], ["11635.10000", "7.30000000", "1596666778.438111"], ["11634.90000", "0.70560000", "1596666827.003823"], ["11634.60000", "0.00900000", "1596666867.710971"], ["11633.50000", "7.10476877", "1596666920.068029"], ["11633.10000", "6.42340457", "1596666918.795843"], ["11633.00000", "3.54487233", "1596666918.280890"], ["11632.90000", "0.90232376", "1596666857.959009"], ["11631.70000", "6.41170771", "1596666989.695399"], ["11631.60000", "2.81964866", "1596666851.487838"], ["11630.90000", "1.11290000", "1596666962.030868"], ["11630.80000", "2.32247796", "1596666847.806192"], ["11630.10000", "8.60000000", "1596666873.959071"], ["11630.00000", "0.10583740", "1596666770.171499"], ["11628.00000", "2.29920000", "1596666964.114703"], ["11626.90000", "2.01356225", "1596666858.488093"], ["11625.70000", "1.17681430", "1596666784.127703"], ["11625.20000", "3.54843693", "1596666975.670995"], ["11625.10000", "0.00856780", "1596666864.899828"], ["11625.00000", "0.25000000", "1596666972.706285"], ["11624.90000", "0.75800000", "1596666962.971699"], ["11624.70000", "10.60000000", "1596666766.391904"], ["11624.20000", "1.99713250", "1596666977.539549"], ["11624.00000", "8.00000000", "1596667000.507795"], ["11623.00000", "1.03040000", "1596666778.422874"], ["11620.80000", "0.02000000", "1596666785.453825"], ["11619.00000", "7.17085000", "1596666993.726725"], ["11618.90000", "0.48560000", "1596666782.022335"], ["11618.80000", "13.92168021", "1596666987.857282"], ["11617.50000", "2.49761864", "1596666811.445738"], ["11617.40000", "0.75800000", "1596666775.482846"], ["11616.00000", "0.17085000", "1596666933.189049"], ["11615.60000", "0.20000000", "1596666623.308321"], ["11614.80000", "3.08717099", "1596666746.879208"], ["11613.60000", "3.55198121", "1596666780.634357"]]}, "book-100", "XBT/USD"]
[270, {"a": [["11670.10000", "0.85649075", "1596667001.629591"]], "c": "2112227048"}, "book-100", "XBT/USD"]
[270, {"a": [["11670.50000", "0.00000000", "1596667001.642692"], ["11715.00000", "0.17085000", "1596666969.869642", "r"]], "c": "3551214585"}, "book-100", "XBT/USD"]
[270, {"a": [["11685.70000", "0.00000000", "1596667001.663359"], ["11715.30000", "6.10000000", "1596666635.445451", "r"]], "c": "3551214585"}, "book-100", "XBT/USD"]
[270, {"a": [["11670.60000", "2.06721963", "1596667001.670707"]], "c": "2740273798"}, "book-100", "XBT/USD"]
[270, {"b": [["11648.20000", "0.00000000", "1596667001.889104"], ["11613.00000", "0.17085000", "1596666927.656692", "r"]], "c": "2740273798"}, "book-100", "XBT/USD"]
[270, {"b": [["11665.50000", "0.00000000", "1596667001.903645"], ["11612.30000", "7.00000000", "1596666617.080387", "r"]], "c": "935496490"}, "book-100", "XBT/USD"]
[270, {"b": [["11665.30000", "0.64284442", "1596667002.134914"]], "c": "1191491623"}, "book-100", "XBT/USD"]
[270, {"a": [["11667.30000", "0.64284142", "1596667002.135129"]], "c": "3178072735"}, "book-100", "XBT/USD"]
[270, {"b": [["11666.40000", "1.09213147", "1596667002.135222"]], "c": "2064478208"}, "book-100", "XBT/USD"]
[270, {"b": [["11666.40000", "1.30323147", "1596667002.161044"]], "c": "3311525880"}, "book-100", "XBT/USD"]
[270, {"a": [["11673.60000", "0.15000000", "1596667002.216637"]], "c": "3311525880"}, "book-100", "XBT/USD"]
[270, {"b": [["11666.40000", "1.70323147", "1596667002.277009"]], "c": "230819110"}, "book-100", "XBT/USD"]
[270, {"b": [["11624.90000", "1.50657838", "1596667002.286225"]], "c": "230819110"}, "book-100", "XBT/USD"]
[270, {"a": [["11673.70000", "0.15000000", "1596667002.302334"]], "c": "230819110"}, "book-100", "XBT/USD"]
[270, {"a": [["11686.50000", "0.74857838", "1596667002.414016"]], "c": "230819110"}, "book-100", "XBT/USD"]
[270, {"a": [["11673.60000", "0.00000000", "1596667003.345710"], ["11712.00000", "0.17085000", "1596666981.360184", "r"]], "c": "230819110"}, "book-100", "XBT/USD"]
[270, {"a": [["11672.40000", "0.00000000", "1596667003.401366"], ["11713.90000", "2.30673040", "1596666889.279950", "r"]], "c": "230819110"}, "book-100", "XBT/USD"]
[270, {"a": [["11672.50000", "0.44900000", "1596667003.455679"]], "c": "230819110"}, "book-100", "XBT/USD"]
[270, {"a": [["11670.60000", "1.80888398", "1596667003.733375"]], "c": "3725079974"}, "book-100", "XBT/USD"]
[271, [["11666.40000", "0.02332600", "1596667004.055669", "s", "l", ""]], "trade", "XBT/USD"]
[270, {"b": [["11666.40000", "1.67990547", "1596667004.055669"]], "c": "79558348"}, "book-100", "XBT/USD"]
[270, {"b": [["11663.70000", "1.00073000", "1596667004.256045"]], "c": "3871122664"}, "book-100", "XBT/USD"]
[270, {"a": [["11675.00000", "0.01821000", "1596667004.259533"]], "c": "3871122664"}, "book-100", "XBT/USD"]
[270, {"a": [["11670.70000", "1.84699005", "1596667004.430339"]], "c": "1448561004"}, "book-100", "XBT/USD"]
[270, {"a": [["11675.20000", "0.13421006", "1596667004.976574"]], "c": "1448561004"}, "book-100", "XBT/USD"]
[270, {"a": [["11672.50000", "0.43900000", "1596667005.033112"]], "c": "1448561004"}, "book-100", "XBT/USD"]
[270, {"b": [["11664.80000", "0.00000000", "1596667005.058899"], ["11613.00000", "0.17085000", "1596666927.656692", "r"]], "c": "4197159493"}, "book-100", "XBT/USD"]
[270, {"a": [["11673.60000", "0.01000000", "1596667005.083798"]], "c": "4197159493"}, "book-100", "XBT/USD"]
[270, {"b": [["11665.80000", "0.64282193", "1596667005.116163"]], "c": "817794523"}, "book-100", "XBT/USD"]
[270, {"a": [["11674.20000", "2.35695011", "1596667005.126361"]], "c": "817794523"}, "book-100", "XBT/USD"]
[271, [["11666.50000", "0.04938047", "1596667005.599532", "b", "m", ""]], "trade", "XBT/USD"]
[270, {"a": [["11666.50000", "0.14605964", "1596667005.599532"]], "c": "3504388487"}, "book-100", "XBT/USD"]
[270, {"b": [["11639.30000", "0.00439976", "1596667005.604479"]], "c": "3504388487"}, "book-100", "XBT/USD"]
[270, {"a": [["11685.50000", "0.00000000", "1596667005.661449"], ["11713.90000", "2.30673040", "1596666889.279950", "r"]], "c": "3504388487"}, "book-100", "XBT/USD"]
[270, {"b": [["11666.40000", "4.92990547", "1596667005.663799"]], "c": "2973308005"}, "book-100", "XBT/USD"]
[270, {"b": [["11653.10000", "0.00000000", "1596667005.928809"], ["11613.60000", "3.55198121", "1596666780.634357", "r"]], "c": "2973308005"}, "book-100", "XBT/USD"]
[270, {"b": [["11666.40000", "1.67990547", "1596667005.935681"]], "c": "3504388487"}, "book-100", "XBT/USD"]
[270, {"a": [["11667.30000", "0.00000000", "1596667006.053140"], ["11715.00000", "0.17085000", "1596666969.869642", "r"]], "c": "730225346"}, "book-100", "XBT/USD"]
[271, [["11666.40000", "0.02332600", "1596667006.121184", "s", "l", ""]], "trade", "XBT/USD"]
[270, {"b": [["11666.40000", "1.65657947", "1596667006.121184"]], "c": "862834582"}, "book-100", "XBT/USD"]
[270, {"b": [["11653.70000", "0.13420340", "1596667006.156034"]], "c": "862834582"}, "book-100", "XBT/USD"]
[270, {"a": [["11673.90000", "0.15000000", "1596667006.188730"]], "c": "862834582"}, "book-100", "XBT/USD"]
[270, {"a": [["11673.70000", "0.00000000", "1596667006.194020"], ["11715.00000", "0.17085000", "1596666969.869642", "r"]], "c": "862834582"}, "book-100", "XBT/USD"]
[270, {"a": [["11670.70000", "1.58865550", "1596667006.717771"]], "c": "4030651201"}, "book-100", "XBT/USD"]
[270, {"a": [["11670.80000", "1.13851117", "1596667006.730609"]], "c": "548564210"}, "book-100", "XBT/USD"]
[270, {"a": [["11674.00000", "0.15000000", "1596667006.731991"]], "c": "548564210"}, "book-100", "XBT/USD"]
[270, {"a": [["11674.10000", "0.15000000", "1596667007.192964"]], "c": "548564210"}, "book-100", "XBT/USD"]
[270, {"a": [["11669.90000", "0.64280495", "1596667007.208582"]], "c": "3150985461"}, "book-100", "XBT/USD"]
[270, {"a": [["11673.30000", "0.15000000", "1596667007.667844"]], "c": "3150985461"}, "book-100", "XBT/USD"]
[270, {"a": [["11673.60000", "0.00000000", "1596667007.720180"], ["11711.50000", "1.99898326", "1596666797.632161", "r"]], "c": "3150985461"}, "book-100", "XBT/USD"]
[270, {"a": [["11673.30000", "0.00000000", "1596667007.767374"], ["11712.00000", "0.17085000", "1596666981.360184", "r"]], "c": "3150985461"}, "book-100", "XBT/USD"]
[270, {"a": [["11673.10000", "0.01000000", "1596667007.779677"]], "c": "3150985461"}, "book-100", "XBT/USD"]
[270, {"b": [["11625.00000", "0.99857678", "1596667008.622428"]], "c": "3150985461"}, "book-100", "XBT/USD"]
[270, {"a": [["11686.50000", "0.00000000", "1596667008.623465"], ["11712.00000", "0.17085000", "1596666981.360184", "r"]], "c": "3150985461"}, "book-100", "XBT/USD"]
[270, {"a": [["11673.20000", "0.15000000", "1596667008.680150"]], "c": "3150985461"}, "book-100", "XBT/USD"]
[270, {"b": [["11665.80000", "2.34782193", "1596667008.737018"]], "c": "1597091492"}, "book-100", "XBT/USD"]
[270, {"a": [["11674.00000", "1.86200000", "1596667008.761809"]], "c": "1597091492"}, "book-100", "XBT/USD"]
[270, {"a": [["11673.20000", "0.00000000", "1596667008.793743"], ["11712.00000", "0.17085000", "1596666981.360184", "r"]], "c": "1597091492"}, "book-100", "XBT/USD"]
[270, {"a": [["11673.10000", "0.00000000", "1596667008.854516"], ["11713.90000", "2.30673040", "1596666889.279950", "r"]], "c": "1597091492"}, "book-100", "XBT/USD"]
[270, {"a": [["11673.60000", "0.15000000", "1596667008.856913"]], "c": "1597091492"}, "book-100", "XBT/USD"]
[270, {"a": [["11676.20000", "0.00000000", "1596667008.871327"], ["11713.90000", "2.30673040", "1596666889.279950", "r"]], "c": "1597091492"}, "book-100", "XBT/USD"]
[270, {"a": [["11674.00000", "1.71200000", "1596667008.874829"]], "c": "1597091492"}, "book-100", "XBT/USD"]
[270, {"a": [["11673.90000", "0.00000000", "1596667008.876398"], ["11715.00000", "0.17085000", "1596666969.869642", "r"]], "c": "1597091492"}, "book-100", "XBT/USD"]
[270, {"a": [["11674.10000", "0.00000000", "1596667008.877520"], ["11715.30000", "6.10000000", "1596666635.445451", "r"]], "c": "1597091492"}, "book-100", "XBT/USD"]
[270, {"a": [["11670.80000", "0.88017947", "1596667008.904474"]], "c": "1597091492"}, "book-100", "XBT/USD"]
[270, {"a": [["11679.90000", "2.82552606", "1596667008.940271"]], "c": "1597091492"}, "book-100", "XBT/USD"]
[270, {"a": [["11682.50000", "1.42018672", "1596667008.943513"]], "c": "1597091492"}, "book-100", "XBT/USD"]
[270, {"a": [["11680.80000", "0.00000000", "1596667008.951082"], ["11717.80000", "1.99812614", "1596666759.535617", "r"]], "c": "1597091492"}, "book-100", "XBT/USD"]
[270, {"a": [["11671.20000", "0.25832927", "1596667008.983588"]], "c": "1597091492"}, "book-100", "XBT/USD"]
[270, {"b": [["11631.70000", "0.02875288", "1596667009.000100"]], "c": "1597091492"}, "book-100", "XBT/USD"]
[270, {"b": [["11639.30000", "0.00000000", "1596667009.035434"], ["11613.60000", "3.55198121", "1596666780.634357", "r"]], "c": "1597091492"}, "book-100", "XBT/USD"]
[270, {"a": [["11681.80000", "0.00000000", "1596667009.035891"], ["11717.80000", "1.99812614", "1596666759.535617", "r"]], "c": "1597091492"}, "book-100", "XBT/USD"]
[270, {"b": [["11656.10000", "0.00000000", "1596667009.058123"], ["11613.00000", "0.17085000", "1596666927.656692", "r"]], "c": "1597091492"}, "book-100", "XBT/USD"]
[270, {"b": [["11633.00000", "0.00000000", "1596667009.062481"], ["11612.30000", "7.00000000", "1596666617.080387", "r"]], "c": "1597091492"}, "book-100", "XBT/USD"]
[270, {"a": [["11673.60000", "0.00000000", "1596667009.065217"], ["11718.00000", "0.17085000", "1596666994.200702", "r"]], "c": "1597091492"}, "book-100", "XBT/USD"]
[270, {"b": [["11660.20000", "0.85716573", "1596667009.069009"]], "c": "1597091492"}, "book-100", "XBT/USD"]
[270, {"b": [["11653.90000", "0.00000000", "1596667009.070918"], ["11611.90000", "1.06000000", "1596666780.430510", "r"]], "c": "1597091492"}, "book-100", "XBT/USD"]
[270, {"a": [["11676.70000", "0.33831906", "1596667009.076407"]], "c": "1597091492"}, "book-100", "XBT/USD"]
[270, {"a": [["11680.20000", "0.00000000", "1596667009.076466"], ["11718.40000", "0.48360000", "1596666846.374528", "r"]], "c": "1597091492"}, "book-100", "XBT/USD"]
[270, {"a": [["11676.70000", "0.00000000", "1596667009.087638"], ["11718.50000", "24.30000000", "1596666641.380470", "r"]], "c": "1597091492"}, "book-100", "XBT/USD"]
[270, {"a": [["11685.30000", "0.24903596", "1596667009.094912"]], "c": "1597091492"}, "book-100", "XBT/USD"]
[270, {"b": [["11644.50000", "0.00000000", "1596667009.106092"], ["11610.00000", "0.17085000", "1596666865.604704", "r"]], "c": "1597091492"}, "book-100", "XBT/USD"]
[270, {"a": [["11667.90000", "0.00000000", "1596667009.158014"], ["11718.50000", "24.30000000", "1596666641.380470", "r"]], "c": "1047969977"}, "book-100", "XBT/USD"]
[270, {"b": [["11663.50000", "0.00000000", "1596667009.200029"], ["11609.80000", "21.20000000", "1596666704.766154", "r"]], "c": "2121941905"}, "book-100", "XBT/USD"]
[270, {"b": [["11624.90000", "0.75800000", "1596667009.201422"]], "c": "2121941905"}, "book-100", "XBT/USD"]
[270, {"a": [["11703.90000", "2.24674744", "1596667009.201570"]], "c": "2121941905"}, "book-100", "XBT/USD"]
[270, {"a": [["11686.40000", "0.74857678", "1596667009.201719"]], "c": "2121941905"}, "book-100", "XBT/USD"]
[270, {"a": [["11670.70000", "0.73139807", "1596667009.204718"]], "c": "1402564081"}, "book-100", "XBT/USD"]
[270, {"a": [["11673.60000", "0.01000000", "1596667009.222145"]], "c": "1402564081"}, "book-100", "XBT/USD"]
[270, {"a": [["11674.00000", "0.00000000", "1596667009.225440"], ["11718.00000", "0.17085000", "1596666994.200702", "r"]], "c": "1402564081"}, "book-100", "XBT/USD"]
[270, {"b": [["11637.70000", "3.54328411", "1596667009.282829"]], "c": "1402564081"}, "book-100", "XBT/USD"]
[270, {"a": [["11667.90000", "0.02764879", "1596667009.288630"]], "c": "34215703"}, "book-100", "XBT/USD"]
[270, {"a": [["11667.80000", "0.00000000", "1596667009.288782"], ["11718.00000", "0.17085000", "1596666994.200702", "r"]], "c": "1586443951"}, "book-100", "XBT/USD"]
[270, {"b": [["11666.10000", "0.75000000", "1596667009.358427"]], "c": "1554586534"}, "book-100", "XBT/USD"]
[270, {"a": [["11700.70000", "0.00000000", "1596667009.360722"], ["11718.40000", "0.48360000", "1596666846.374528", "r"]], "c": "1554586534"}, "book-100", "XBT/USD"]
[270, {"a": [["11668.90000", "0.00000000", "1596667009.363792"], ["11718.50000", "24.30000000", "1596666641.380470", "r"]], "c": "4063297927"}, "book-100", "XBT/USD"]
[270, {"b": [["11663.80000", "0.00000000", "1596667009.364048"], ["11610.00000", "0.17085000", "1596666865.604704", "r"]], "c": "244015967"}, "book-100", "XBT/USD"]
[270, {"a": [["11685.60000", "0.00000000", "1596667009.367253"], ["11719.60000", "2.98021891", "1596666782.974175", "r"]], "c": "244015967"}, "book-100", "XBT/USD"]
[270, {"a": [["11682.40000", "0.10324964", "1596667009.399096"]], "c": "244015967"}, "book-100", "XBT/USD"]
