[270, {"as": [["11633.60000", "0.16532959", "1596668514.369299"], ["11633.70000", "0.01229100", "1596668495.970283"], ["11633.80000", "1.67592910", "1596668463.392306"], ["11635.10000", "4.95141277", "1596668496.680979"], ["11635.20000", "0.07645158", "1596668495.753454"], ["11639.90000", "0.71160000", "1596668384.046991"], ["11641.00000", "4.54144597", "1596668524.610136"], ["11641.20000", "0.70560000", "1596668496.506808"], ["11641.50000", "0.01000000", "1596668509.790222"], ["11641.60000", "0.74322733", "1596668512.334673"], ["11641.70000", "0.64426454", "1596668506.483434"], ["11642.70000", "0.64429759", "1596668502.506841"], ["11643.00000", "0.76417000", "1596668516.919269"], ["11643.30000", "0.21976352", "1596668499.894310"], ["11643.40000", "1.21337175", "1596668506.780715"], ["11644.30000", "0.49173985", "1596668497.050177"], ["11644.40000", "0.10200000", "1596668501.297416"], ["11644.60000", "1.50000000", "1596668515.360175"], ["11644.80000", "1.71500000", "1596668516.465411"], ["11645.60000", "0.85896977", "1596668505.202038"], ["11646.10000", "0.72008000", "1596668511.822801"], ["11646.80000", "0.09621094", "1596668506.099171"], ["11647.50000", "0.47660030", "1596668499.703323"], ["11647.60000", "0.14982169", "1596668507.719056"], ["11648.10000", "0.85946361", "1596668496.574342"], ["11648.40000", "0.63721560", "1596668522.798152"], ["11648.50000", "1.01004000", "1596668502.505060"], ["11649.80000", "0.48244652", "1596668522.663765"], ["11649.90000", "0.85932744", "1596668499.255515"], ["11650.30000", "2.99949434", "1596668512.820094"], ["11650.50000", "0.13446207", "1596668508.048084"], ["11650.80000", "3.19588352", "1596668511.163203"], ["11651.00000", "0.85925576", "1596668501.576843"], ["11651.50000", "0.09600000", "1596668500.739506"], ["11652.00000", "0.71240446", "1596668501.561731"], ["11652.30000", "0.76645242", "1596668511.378362"], ["11652.70000", "4.50208724", "1596668517.387174"], ["11652.80000", "4.33163873", "1596668500.322657"], ["11653.00000", "0.70019375", "1596668511.214209"], ["11653.30000", "0.05313798", "1596668523.719224"], ["11653.40000", "0.33899510", "1596668511.753865"], ["11654.00000", "2.00000000", "1596668503.831889"], ["11654.80000", "0.85906346", "1596668502.206173"], ["11654.90000", "0.85906346", "1596668502.206472"], ["11655.10000", "0.10346516", "1596668500.286356"], ["11656.80000", "0.71168206", "1596668511.754783"], ["11656.90000", "0.75334027", "1596668520.155961"], ["11657.00000", "6.34137411", "1596668519.823718"], ["11657.10000", "9.66070000", "1596668499.743918"], ["11657.50000", "1.10410700", "1596668501.506426"], ["11657.70000", "1.42335705", "1596668517.114339"], ["11658.70000", "1.16096270", "1596668517.969290"], ["11659.10000", "0.20000000", "1596668257.402509"], ["11660.00000", "6.53675501", "1596668500.466755"], ["11660.40000", "0.30000000", "1596668038.851611"], ["11660.80000", "0.49752326", "1596668510.622842"], ["11661.20000", "1.26059228", "1596668500.231342"], ["11661.80000", "0.43900000", "1596668523.841682"], ["11662.10000", "2.89138672", "1596668522.695341"], ["11662.20000", "5.70000000", "1596668067.708048"], ["11663.80000", "6.32557658", "1596668503.894852"], ["11663.90000", "1.48503180", "1596668150.753515"], ["11664.00000", "7.08675655", "1596668505.172355"], ["11664.20000", "1.20959793", "1596668502.222704"], ["11664.30000", "5.21134315", "1596668516.830009"], ["11665.40000", "0.05300810", "1596668303.354734"], ["11666.30000", "6.80000000", "1596667942.286965"], ["11666.40000", "0.02828925", "1596668495.651157"], ["11667.30000", "2.00829310", "1596668413.858512"], ["11667.70000", "0.61700000", "1596668518.695297"], ["11669.30000", "0.10000000", "1596667725.682463"], ["11669.50000", "0.77518919", "1596668504.791028"], ["11670.00000", "43.90525970", "1596668081.156110"], ["11670.40000", "0.30000000", "1596668342.304150"], ["11670.80000", "1.80844262", "1596668100.724141"], ["11671.00000", "1.11290000", "1596668343.145669"], ["11671.80000", "5.20000000", "1596668116.651465"], ["11673.10000", "6.53305518", "1596668074.955254"], ["11674.40000", "1.96304237", "1596668077.818638"], ["11674.80000", "2.25204666", "1596668524.089980"], ["11675.00000", "0.01821000", "1596668321.418820"], ["11675.20000", "20.10000000", "1596668314.503495"], ["11675.60000", "13.48242016", "1596668079.276816"], ["11676.00000", "5.10000000", "1596667950.984665"], ["11676.20000", "0.75800000", "1596668279.433026"], ["11677.00000", "0.75800000", "1596668347.098169"], ["11678.90000", "2.00629837", "1596668074.674665"], ["11681.20000", "0.02573600", "1596667743.443916"], ["11681.90000", "8.00000000", "1596667893.353561"], ["11682.50000", "0.95690000", "1596668422.715986"], ["11682.60000", "20.00000000", "1596668348.586622"], ["11682.70000", "0.48430000", "1596668063.968111"], ["11684.70000", "5.84205810", "1596668075.446389"], ["11684.80000", "4.06670802", "1596668074.975205"], ["11685.10000", "1.60000000", "1596668456.087815"], ["11686.00000", "2.80639281", "1596668077.802339"], ["11686.50000", "1.51500000", "1596668107.208493"], ["11687.00000", "22.20000000", "1596668508.426544"], ["11687.30000", "8.20000000", "1596667061.296774"], ["11689.90000", "0.10000000", "1596667326.899060"]], "bs": [["11633.50000", "9.95705929", "1596668517.536596"], ["11633.40000", "2.92443269", "1596668496.790838"], ["11633.30000", "0.01493999", "1596668509.004188"], ["11633.00000", "0.64360621", "1596668522.798741"], ["11632.90000", "0.95535680", "1596668506.116124"], ["11632.80000", "0.64456495", "1596668508.864132"], ["11632.50000", "5.90000000", "1596668513.573032"], ["11632.20000", "0.64459771", "1596668500.095218"], ["11631.90000", "1.44000000", "1596668505.171764"], ["11631.80000", "0.85925576", "1596668510.114998"], ["11631.30000", "0.40364246", "1596668521.536823"], ["11631.20000", "0.74068237", "1596668524.526322"], ["11631.10000", "2.56836139", "1596668499.897039"], ["11630.20000", "0.71337418", "1596668522.311386"], ["11629.90000", "2.00000000", "1596668492.445213"], ["11629.80000", "0.85927662", "1596668488.351800"], ["11629.20000", "1.77113081", "1596668497.437622"], ["11629.10000", "0.25023805", "1596668518.083506"], ["11629.00000", "1.63932827", "1596668517.565073"], ["11628.90000", "1.42667212", "1596668517.494350"], ["11628.10000", "0.09700000", "1596668506.757192"], ["11627.40000", "0.04228954", "1596668517.534363"], ["11627.30000", "6.68000000", "1596668501.488459"], ["11626.80000", "0.45827117", "1596668475.292505"], ["11626.70000", "0.79895229", "1596668517.541062"], ["11626.60000", "3.54651725", "1596668517.591288"], ["11626.40000", "0.85944353", "1596668437.372768"], ["11626.20000", "1.57000000", "1596668517.216837"], ["11625.90000", "1.72590000", "1596668517.220929"], ["11625.80000", "0.85942174", "1596668487.896644"], ["11625.60000", "0.44843875", "1596668517.776155"], ["11625.50000", "0.91396263", "1596668517.504135"], ["11625.00000", "0.25000000", "1596668499.585575"], ["11623.80000", "1.96330000", "1596668500.316215"], ["11623.20000", "3.22863815", "1596668517.569959"], ["11622.90000", "0.54200000", "1596668518.778320"], ["11622.80000", "6.90000000", "1596668499.924331"], ["11621.60000", "1.80170088", "1596668506.684476"], ["11620.70000", "2.88294620", "1596668389.651958"], ["11620.60000", "7.11303174", "1596668409.481610"], ["11620.50000", "2.93673521", "1596668524.341733"], ["11620.30000", "3.21545476", "1596668523.879661"], ["11620.00000", "0.57614019", "1596668498.298478"], ["11619.80000", "0.99863861", "1596668496.736564"], ["11618.30000", "0.50000000", "1596668493.165415"], ["11618.20000", "3.54935783", "1596668489.595367"], ["11617.70000", "6.10000000", "1596668348.496250"], ["11617.40000", "0.91448205", "1596668406.949032"], ["11616.10000", "0.99580000", "1596668422.711613"], ["11615.60000", "0.20000000", "1596668504.739520"], ["11615.10000", "0.03200000", "1596668499.912034"], ["11613.80000", "2.01675517", "1596668407.022830"], ["11613.10000", "0.90232045", "1596668406.769779"], ["11612.30000", "7.00000000", "1596668338.304191"], ["11611.30000", "2.71204536", "1596668358.712473"], ["11611.20000", "1.11290000", "1596668386.895067"], ["11610.40000", "0.91503340", "1596668406.941682"], ["11610.00000", "0.17085000", "1596668521.088579"], ["11609.90000", "2.00000000", "1596668468.252598"], ["11609.80000", "1.97364809", "1596668422.140750"], ["11609.30000", "7.80000000", "1596668504.418558"], ["11609.00000", "7.12013926", "1596668409.480078"], ["11608.30000", "0.49800000", "1596668523.067980"], ["11607.90000", "1.51640032", "1596668407.066320"], ["11607.70000", "8.40000000", "1596666861.504830"], ["11607.00000", "0.17085000", "1596668504.604452"], ["11606.80000", "0.05303136", "1596668335.299482"], ["11606.60000", "5.91474364", "1596668519.741733"], ["11606.50000", "2.01641365", "1596668465.433825"], ["11606.40000", "6.43902428", "1596668343.959742"], ["11606.10000", "3.55318009", "1596668343.516075"], ["11605.90000", "1.49964739", "1596668343.425472"], ["11605.80000", "0.50000000", "1596668508.608435"], ["11605.60000", "1.04116415", "1596668333.053853"], ["11604.00000", "0.17085000", "1596668498.844043"], ["11602.10000", "7.70000000", "1596668438.926770"], ["11601.60000", "0.70560000", "1596668341.812612"], ["11601.00000", "2.18978979", "1596668390.155010"], ["11600.10000", "0.05000000", "1596668505.440803"], ["11600.00000", "0.46774162", "1596668343.049400"], ["11598.90000", "2.32833724", "1596668406.664867"], ["11598.00000", "0.19968745", "1596668499.688407"], ["11597.40000", "1.17953473", "1596668346.326152"], ["11597.30000", "18.40000000", "1596668078.198778"], ["11597.20000", "3.55598197", "1596668068.386899"], ["11597.00000", "0.10605034", "1596668339.780487"], ["11596.90000", "0.91616873", "1596668342.116131"], ["11596.10000", "5.80000000", "1596667570.336610"], ["11595.00000", "0.17085000", "1596668422.586649"], ["11594.70000", "0.98770000", "1596668422.720337"], ["11594.40000", "0.75800000", "1596668346.986271"], ["11594.30000", "2.82809595", "1596668347.321275"], ["11593.70000", "0.50000000", "1596668514.403243"], ["11593.10000", "0.48610000", "1596668339.984871"], ["11593.00000", "0.75034027", "1596668519.968582"], ["11592.90000", "0.80800000", "1596668169.200165"], ["11592.80000", "13.95290335", "1596668505.329182"], ["11592.70000", "0.00900000", "1596668468.753375"], ["11592.20000", "2.00189295", "1596668342.448058"], ["11592.00000", "0.17085000", "1596668497.071892"]]}, "book-100", "XBT/USD"]
[270, {"a": [["11653.40000", "0.00000000", "1596668525.459874"], ["11690.00000", "0.04000000", "1596668498.502545", "r"]], "c": "1699749477"}, "book-100", "XBT/USD"]
[270, {"a": [["11656.80000", "0.00000000", "1596668525.475357"], ["11690.10000", "0.80800000", "1596668331.301180", "r"]], "c": "1699749477"}, "book-100", "XBT/USD"]
[270, {"a": [["11644.70000", "0.96000000", "1596668525.559705"]], "c": "1699749477"}, "book-100", "XBT/USD"]
[270, {"b": [["11631.20000", "0.00000000", "1596668525.587142"], ["11591.10000", "5.40000000", "1596668457.950409", "r"]], "c": "1699749477"}, "book-100", "XBT/USD"]
[270, {"a": [["11653.30000", "0.00000000", "1596668525.591269"], ["11690.10000", "0.80800000", "1596668331.301180", "r"]], "c": "1699749477"}, "book-100", "XBT/USD"]
[270, {"a": [["11653.90000", "0.05313798", "1596668525.593371"]], "c": "1699749477"}, "book-100", "XBT/USD"]
[270, {"b": [["11619.90000", "0.00434188", "1596668525.653763"]], "c": "1699749477"}, "book-100", "XBT/USD"]
[270, {"a": [["11658.60000", "0.00438186", "1596668525.655409"]], "c": "1699749477"}, "book-100", "XBT/USD"]
[270, {"b": [["11632.30000", "0.74068237", "1596668525.728242"]], "c": "2305973836"}, "book-100", "XBT/USD"]
[270, {"a": [["11652.90000", "0.33904025", "1596668525.835400"]], "c": "2305973836"}, "book-100", "XBT/USD"]
[270, {"a": [["11656.30000", "0.71177684", "1596668525.838764"]], "c": "2305973836"}, "book-100", "XBT/USD"]
[270, {"b": [["11593.00000", "0.00000000", "1596668526.128116"], ["11592.00000", "0.17085000", "1596668497.071892", "r"]], "c": "2305973836"}, "book-100", "XBT/USD"]
[270, {"b": [["11593.10000", "1.23644646", "1596668526.131122"]], "c": "2305973836"}, "book-100", "XBT/USD"]
[270, {"a": [["11657.30000", "0.75034646", "1596668526.131978"]], "c": "2305973836"}, "book-100", "XBT/USD"]
[270, {"a": [["11656.90000", "0.00300000", "1596668526.133774"]], "c": "2305973836"}, "book-100", "XBT/USD"]
[270, {"a": [["11644.60000", "0.00000000", "1596668526.212473"], ["11687.00000", "22.20000000", "1596668508.426544", "r"]], "c": "2305973836"}, "book-100", "XBT/USD"]
[270, {"b": [["11619.90000", "0.00000000", "1596668526.344820"], ["11591.10000", "5.40000000", "1596668457.950409", "r"]], "c": "2305973836"}, "book-100", "XBT/USD"]
[270, {"a": [["11658.60000", "0.00000000", "1596668526.345265"], ["11687.30000", "8.20000000", "1596667061.296774", "r"]], "c": "2305973836"}, "book-100", "XBT/USD"]
[270, {"a": [["11643.10000", "1.50000000", "1596668526.357982"]], "c": "2305973836"}, "book-100", "XBT/USD"]
[270, {"b": [["11601.20000", "0.50000000", "1596668526.452353"]], "c": "2305973836"}, "book-100", "XBT/USD"]
[270, {"a": [["11653.90000", "0.00000000", "1596668526.621079"], ["11687.30000", "8.20000000", "1596667061.296774", "r"]], "c": "2305973836"}, "book-100", "XBT/USD"]
[270, {"a": [["11651.90000", "0.03003051", "1596668526.622408"]], "c": "2305973836"}, "book-100", "XBT/USD"]
[270, {"b": [["11605.80000", "0.00000000", "1596668526.630254"], ["11591.10000", "5.40000000", "1596668457.950409", "r"]], "c": "2305973836"}, "book-100", "XBT/USD"]
[270, {"a": [["11641.70000", "0.00000000", "1596668526.938963"], ["11687.30000", "8.20000000", "1596667061.296774", "r"]], "c": "2305973836"}, "book-100", "XBT/USD"]
[270, {"a": [["11641.00000", "5.18569749", "1596668526.994437"]], "c": "279175030"}, "book-100", "XBT/USD"]
[270, {"a": [["11654.90000", "0.00000000", "1596668527.253030"], ["11689.90000", "0.10000000", "1596667326.899060", "r"]], "c": "279175030"}, "book-100", "XBT/USD"]
[270, {"b": [["11620.60000", "0.00000000", "1596668527.290200"], ["11589.90000", "0.02000000", "1596668257.590733", "r"]], "c": "279175030"}, "book-100", "XBT/USD"]
[270, {"a": [["11657.50000", "0.38000000", "1596668527.291248"]], "c": "279175030"}, "book-100", "XBT/USD"]
[270, {"b": [["11606.10000", "0.00000000", "1596668527.291878"], ["11589.00000", "0.17085000", "1596668407.303259", "r"]], "c": "279175030"}, "book-100", "XBT/USD"]
[270, {"b": [["11618.20000", "0.00000000", "1596668527.296054"], ["11588.70000", "2.02109260", "1596668343.237067", "r"]], "c": "279175030"}, "book-100", "XBT/USD"]
[270, {"a": [["11655.10000", "0.00000000", "1596668527.300167"], ["11690.00000", "0.04000000", "1596668498.502545", "r"]], "c": "279175030"}, "book-100", "XBT/USD"]
[270, {"b": [["11592.20000", "0.00000000", "1596668527.300315"], ["11588.10000", "0.75800000", "1596668064.554859", "r"]], "c": "279175030"}, "book-100", "XBT/USD"]
[270, {"b": [["11617.40000", "0.00000000", "1596668527.311107"], ["11587.50000", "0.00859556", "1596668354.836788", "r"]], "c": "279175030"}, "book-100", "XBT/USD"]
[270, {"b": [["11605.90000", "0.00000000", "1596668527.315908"], ["11586.90000", "5.90000000", "1596667875.878899", "r"]], "c": "279175030"}, "book-100", "XBT/USD"]
[270, {"b": [["11606.40000", "0.00000000", "1596668527.317254"], ["11585.70000", "3.55951165", "1596668068.336711", "r"]], "c": "279175030"}, "book-100", "XBT/USD"]
[270, {"b": [["11630.20000", "0.00000000", "1596668527.321706"], ["11585.50000", "0.00509766", "1596667865.110519", "r"]], "c": "279175030"}, "book-100", "XBT/USD"]
[270, {"b": [["11613.80000", "0.00000000", "1596668527.321907"], ["11585.20000", "2.29920000", "1596668343.394695", "r"]], "c": "279175030"}, "book-100", "XBT/USD"]
[270, {"b": [["11620.30000", "0.00000000", "1596668527.352506"], ["11583.70000", "3.54717352", "1596668022.773351", "r"]], "c": "279175030"}, "book-100", "XBT/USD"]
[270, {"a": [["11656.70000", "0.10344203", "1596668527.421849"]], "c": "279175030"}, "book-100", "XBT/USD"]
[270, {"a": [["11659.10000", "0.92394516", "1596668527.422756"]], "c": "279175030"}, "book-100", "XBT/USD"]
[270, {"b": [["11619.20000", "0.91438283", "1596668527.540021"]], "c": "279175030"}, "book-100", "XBT/USD"]
[270, {"b": [["11615.80000", "2.01659215", "1596668527.587097"]], "c": "279175030"}, "book-100", "XBT/USD"]
[270, {"b": [["11609.90000", "5.55168426", "1596668527.611093"]], "c": "279175030"}, "book-100", "XBT/USD"]
[270, {"b": [["11610.00000", "1.66990421", "1596668527.663735"]], "c": "279175030"}, "book-100", "XBT/USD"]
[270, {"b": [["11598.40000", "2.00073797", "1596668527.667939"]], "c": "279175030"}, "book-100", "XBT/USD"]
[270, {"b": [["11610.00000", "8.10611795", "1596668527.714261"]], "c": "279175030"}, "book-100", "XBT/USD"]
[270, {"b": [["11621.50000", "3.21492241", "1596668527.727216"]], "c": "279175030"}, "book-100", "XBT/USD"]
[270, {"b": [["11629.60000", "0.71332189", "1596668527.803793"]], "c": "279175030"}, "book-100", "XBT/USD"]
[270, {"b": [["11619.20000", "4.46328519", "1596668527.829807"]], "c": "279175030"}, "book-100", "XBT/USD"]
[270, {"a": [["11643.00000", "0.00000000", "1596668528.363926"], ["11690.00000", "0.04000000", "1596668498.502545", "r"]], "c": "279175030"}, "book-100", "XBT/USD"]
[270, {"a": [["11651.90000", "0.00000000", "1596668528.686281"], ["11690.10000", "0.80800000", "1596668331.301180", "r"]], "c": "279175030"}, "book-100", "XBT/USD"]
[270, {"a": [["11654.70000", "0.05313798", "1596668528.689424"]], "c": "279175030"}, "book-100", "XBT/USD"]
[270, {"a": [["11645.30000", "0.85900203", "1596668529.202761"]], "c": "279175030"}, "book-100", "XBT/USD"]
[270, {"b": [["11620.50000", "0.50433062", "1596668529.308891"]], "c": "279175030"}, "book-100", "XBT/USD"]
[270, {"a": [["11643.80000", "1.71600000", "1596668529.426358"]], "c": "279175030"}, "book-100", "XBT/USD"]
[270, {"a": [["11644.80000", "0.00000000", "1596668529.427970"], ["11689.90000", "0.10000000", "1596667326.899060", "r"]], "c": "279175030"}, "book-100", "XBT/USD"]
[270, {"b": [["11621.50000", "10.32676364", "1596668529.436477"]], "c": "279175030"}, "book-100", "XBT/USD"]
[270, {"b": [["11633.50000", "11.66505929", "1596668529.446263"]], "c": "2630019467"}, "book-100", "XBT/USD"]
[270, {"a": [["11674.80000", "0.00000000", "1596668529.501846"], ["11690.00000", "0.04000000", "1596668498.502545", "r"]], "c": "2630019467"}, "book-100", "XBT/USD"]
[270, {"b": [["11620.50000", "0.66130025", "1596668529.553952"]], "c": "2630019467"}, "book-100", "XBT/USD"]
[270, {"a": [["11649.80000", "0.00000000", "1596668529.556470"], ["11690.10000", "0.80800000", "1596668331.301180", "r"]], "c": "2630019467"}, "book-100", "XBT/USD"]
[270, {"a": [["11657.30000", "0.00000000", "1596668529.701481"], ["11690.60000", "2.00429046", "1596668444.785677", "r"]], "c": "2630019467"}, "book-100", "XBT/USD"]
[270, {"a": [["11662.10000", "2.29920000", "1596668529.771865"]], "c": "2630019467"}, "book-100", "XBT/USD"]
[270, {"a": [["11674.40000", "2.30796902", "1596668529.773542"]], "c": "2630019467"}, "book-100", "XBT/USD"]
[270, {"b": [["11633.00000", "0.00000000", "1596668529.822537"], ["11586.90000", "5.90000000", "1596667875.878899", "r"]], "c": "4223919503"}, "book-100", "XBT/USD"]
[270, {"b": [["11593.10000", "0.48610000", "1596668529.825225"]], "c": "4223919503"}, "book-100", "XBT/USD"]
[270, {"a": [["11662.10000", "2.88887752", "1596668529.959051"]], "c": "4223919503"}, "book-100", "XBT/USD"]
[270, {"a": [["11641.50000", "0.00000000", "1596668530.000556"], ["11691.20000", "2.13300000", "1596668335.920068", "r"]], "c": "2206733923"}, "book-100", "XBT/USD"]
[270, {"a": [["11649.80000", "0.48495838", "1596668530.021356"]], "c": "2206733923"}, "book-100", "XBT/USD"]
[270, {"a": [["11641.10000", "0.01000000", "1596668530.055650"]], "c": "3427146593"}, "book-100", "XBT/USD"]
[270, {"a": [["11670.90000", "2.13000000", "1596668530.137353"]], "c": "3427146593"}, "book-100", "XBT/USD"]
[270, {"b": [["11633.50000", "12.34164253", "1596668530.242794"]], "c": "3757077131"}, "book-100", "XBT/USD"]
[270, {"a": [["11642.70000", "0.79429759", "1596668530.302295"]], "c": "3757077131"}, "book-100", "XBT/USD"]
[270, {"b": [["11625.80000", "0.00000000", "1596668530.379082"], ["11585.70000", "3.55951165", "1596668068.336711", "r"]], "c": "3757077131"}, "book-100", "XBT/USD"]
[270, {"a": [["11641.00000", "4.54144597", "1596668530.379296"]], "c": "426080952"}, "book-100", "XBT/USD"]
[270, {"b": [["11620.50000", "2.93673521", "1596668530.459416"]], "c": "426080952"}, "book-100", "XBT/USD"]
[270, {"b": [["11620.50000", "2.77976558", "1596668530.799868"]], "c": "426080952"}, "book-100", "XBT/USD"]
[270, {"b": [["11633.40000", "0.64453269", "1596668530.818816"]], "c": "2304863318"}, "book-100", "XBT/USD"]
[270, {"a": [["11647.00000", "2.50668400", "1596668530.890088"]], "c": "2304863318"}, "book-100", "XBT/USD"]
[270, {"a": [["11650.30000", "0.30000000", "1596668531.035443"]], "c": "2304863318"}, "book-100", "XBT/USD"]
[270, {"b": [["11609.90000", "3.55168426", "1596668531.078906"]], "c": "2304863318"}, "book-100", "XBT/USD"]
[270, {"b": [["11620.50000", "2.93673521", "1596668531.240127"]], "c": "2304863318"}, "book-100", "XBT/USD"]
[270, {"b": [["11608.30000", "0.00000000", "1596668531.269533"], ["11585.50000", "0.00509766", "1596667865.110519", "r"]], "c": "2304863318"}, "book-100", "XBT/USD"]
[270, {"a": [["11654.70000", "0.00000000", "1596668531.708553"], ["11690.00000", "0.04000000", "1596668498.502545", "r"]], "c": "2304863318"}, "book-100", "XBT/USD"]
[270, {"a": [["11642.00000", "0.64423412", "1596668532.206630"]], "c": "2304863318"}, "book-100", "XBT/USD"]
[270, {"a": [["11657.70000", "0.00000000", "1596668532.263947"], ["11690.00000", "0.04000000", "1596668498.502545", "r"]], "c": "2304863318"}, "book-100", "XBT/USD"]
[270, {"a": [["11650.40000", "0.08250000", "1596668532.341560"]], "c": "2304863318"}, "book-100", "XBT/USD"]
[270, {"a": [["11652.90000", "0.00000000", "1596668532.462497"], ["11690.00000", "0.04000000", "1596668498.502545", "r"]], "c": "2304863318"}, "book-100", "XBT/USD"]
[270, {"b": [["11629.60000", "0.00000000", "1596668532.471077"], ["11585.20000", "2.29920000", "1596668343.394695", "r"]], "c": "2304863318"}, "book-100", "XBT/USD"]
[270, {"a": [["11644.20000", "0.04250000", "1596668532.471501"]], "c": "2304863318"}, "book-100", "XBT/USD"]
[270, {"a": [["11652.70000", "4.39130575", "1596668532.477413"]], "c": "2304863318"}, "book-100", "XBT/USD"]
[270, {"a": [["11650.20000", "0.03003489", "1596668532.498762"]], "c": "2304863318"}, "book-100", "XBT/USD"]
[270, {"b": [["11608.30000", "0.49800000", "1596668532.514199"]], "c": "2304863318"}, "book-100", "XBT/USD"]
[270, {"a": [["11656.30000", "0.00000000", "1596668532.525445"], ["11689.90000", "0.10000000", "1596667326.899060", "r"]], "c": "2304863318"}, "book-100", "XBT/USD"]
[270, {"b": [["11633.50000", "13.20062649", "1596668532.546486"]], "c": "2710949868"}, "book-100", "XBT/USD"]
[270, {"b": [["11606.60000", "0.00000000", "1596668532.608669"], ["11585.20000", "2.29920000", "1596668343.394695", "r"]], "c": "2710949868"}, "book-100", "XBT/USD"]
[270, {"b": [["11601.90000", "0.50000000", "1596668532.611673"]], "c": "2710949868"}, "book-100", "XBT/USD"]
[270, {"a": [["11656.80000", "0.75035337", "1596668532.678914"]], "c": "2710949868"}, "book-100", "XBT/USD"]
[270, {"b": [["11592.40000", "0.75035337", "1596668532.681189"]], "c": "2710949868"}, "book-100", "XBT/USD"]
