[270, {"as": [["11690.00000", "0.04000000", "1596670054.298672"], ["11691.10000", "0.47610000", "1596670050.177538"], ["11692.20000", "0.63853793", "1596670050.565850"], ["11693.70000", "0.64144597", "1596670053.210352"], ["11693.80000", "0.25726957", "1596670053.075293"], ["11693.90000", "0.04250000", "1596670052.184212"], ["11694.30000", "0.64144597", "1596670053.210254"], ["11695.00000", "5.14625246", "1596670051.543923"], ["11695.20000", "0.03666545", "1596670053.039335"], ["11695.30000", "1.50000000", "1596670050.962143"], ["11695.60000", "0.15000000", "1596670052.749747"], ["11695.90000", "0.49180175", "1596670052.781638"], ["11696.10000", "0.46919426", "1596670050.317581"], ["11696.40000", "0.36976352", "1596670051.258287"], ["11697.00000", "0.47964166", "1596670050.307662"], ["11697.50000", "0.11303354", "1596670053.312311"], ["11697.60000", "0.33685725", "1596670054.299466"], ["11697.90000", "0.85601682", "1596670050.672236"], ["11698.60000", "0.70782138", "1596670054.301476"], ["11698.80000", "0.10319466", "1596670052.497393"], ["11699.10000", "3.12485688", "1596670050.826027"], ["11699.70000", "2.00000000", "1596669996.761388"], ["11699.90000", "0.10000000", "1596670051.399195"], ["11700.00000", "3.62000000", "1596670053.514997"], ["11700.70000", "0.10300000", "1596670000.644649"], ["11701.00000", "0.70719466", "1596670053.708131"], ["11701.10000", "1.64898257", "1596670052.494639"], ["11701.30000", "0.70560000", "1596669999.207040"], ["11701.70000", "0.50000000", "1596670053.019406"], ["11701.80000", "5.91149795", "1596670000.581354"], ["11702.80000", "1.78320000", "1596670053.483939"], ["11703.00000", "0.85566010", "1596670022.930967"], ["11703.40000", "3.91417906", "1596670053.704051"], ["11703.50000", "7.80000000", "1596670007.738251"], ["11703.60000", "0.09700000", "1596670051.744485"], ["11703.90000", "6.60332011", "1596670041.147203"], ["11704.00000", "3.20214001", "1596670009.882149"], ["11704.20000", "1.20715543", "1596670009.512911"], ["11704.60000", "7.96989819", "1596670052.613582"], ["11704.70000", "1.45702644", "1596670052.373927"], ["11705.40000", "0.85537785", "1596670053.210126"], ["11705.70000", "3.52364385", "1596670053.907311"], ["11705.80000", "3.52294451", "1596670011.749638"], ["11706.00000", "0.95910000", "1596669999.449509"], ["11706.50000", "1.23529838", "1596670053.469680"], ["11707.10000", "3.31242515", "1596670054.305096"], ["11707.20000", "0.85524377", "1596670053.225725"], ["11708.00000", "1.90004241", "1596670008.135989"], ["11708.20000", "0.57162352", "1596670008.208794"], ["11708.50000", "6.50000000", "1596670013.236047"], ["11709.20000", "1.78357471", "1596670053.672709"], ["11709.30000", "2.00609860", "1596670026.080794"], ["11709.70000", "0.00507863", "1596669999.427798"], ["11710.40000", "0.30000000", "1596669699.630555"], ["11713.00000", "2.29920000", "1596669999.432984"], ["11713.20000", "0.89433888", "1596670009.327839"], ["11713.30000", "0.62734917", "1596670039.786735"], ["11713.40000", "6.60000000", "1596669290.909645"], ["11714.90000", "1.95574787", "1596670011.926118"], ["11715.10000", "7.05504351", "1596670014.023956"], ["11715.20000", "3.52011779", "1596670011.753087"], ["11715.30000", "2.46698388", "1596670051.696411"], ["11715.70000", "6.39783037", "1596670016.072100"], ["11717.10000", "0.90762471", "1596669998.832367"], ["11717.30000", "0.37307444", "1596670022.364732"], ["11717.50000", "0.02837833", "1596670006.086722"], ["11718.10000", "0.62800000", "1596670042.633884"], ["11718.50000", "2.99015371", "1596669998.587909"], ["11718.60000", "7.00000000", "1596670001.996056"], ["11720.40000", "0.30000000", "1596669979.221687"], ["11721.00000", "2.00109909", "1596670029.130704"], ["11722.10000", "0.08250000", "1596670044.508452"], ["11722.40000", "10.20622867", "1596669999.579154"], ["11722.50000", "1.11290000", "1596669952.857569"], ["11723.70000", "6.20000000", "1596670000.585086"], ["11723.90000", "2.00000000", "1596670001.976606"], ["11724.90000", "0.05279415", "1596670003.910269"], ["11727.10000", "1.52800000", "1596669319.663928"], ["11727.20000", "1.99969538", "1596669879.170789"], ["11727.60000", "7.88340000", "1596669695.835251"], ["11727.70000", "23.57900000", "1596669699.691613"], ["11729.00000", "9.65281076", "1596669927.670686"], ["11730.00000", "18.80000000", "1596670052.355241"], ["11730.20000", "1.99947970", "1596669927.935538"], ["11730.40000", "0.30000000", "1596670051.231373"], ["11731.20000", "0.01000000", "1596669946.343744"], ["11732.60000", "7.20000000", "1596669559.647810"], ["11732.70000", "1.51500000", "1596669535.007964"], ["11733.00000", "0.17085000", "1596670039.920199"], ["11733.20000", "0.90637929", "1596669999.044187"], ["11733.60000", "3.51464653", "1596670000.572390"], ["11733.70000", "3.47053635", "1596670003.876671"], ["11734.00000", "0.75800000", "1596670000.703471"], ["11734.30000", "3.51413556", "1596669879.712785"], ["11734.60000", "4.77254742", "1596670000.689854"], ["11734.80000", "2.47300093", "1596669874.881702"], ["11736.00000", "0.17085000", "1596669720.570820"], ["11738.10000", "8.91067094", "1596669833.982166"], ["11738.30000", "1.46266141", "1596669559.966249"], ["11738.90000", "0.75800000", "1596669999.477236"]], "bs": [["11689.90000", "2.35643278", "1596670053.210762"], ["11689.80000", "0.64143283", "1596670053.210011"], ["11689.40000", "0.64153339", "1596670053.210983"], ["11689.10000", "4.27400000", "1596670053.373584"], ["11688.90000", "1.48000000", "1596670050.694193"], ["11688.60000", "0.85519469", "1596670053.210664"], ["11688.50000", "0.74068237", "1596670050.803701"], ["11688.30000", "0.85529838", "1596670053.210583"], ["11687.90000", "0.10200000", "1596670050.669142"], ["11686.90000", "0.93473000", "1596670050.498778"], ["11686.00000", "0.20816000", "1596670047.802211"], ["11685.80000", "0.85547653", "1596670044.961813"], ["11685.50000", "0.20798000", "1596670040.502330"], ["11685.20000", "1.81300000", "1596670050.127812"], ["11685.00000", "0.77159287", "1596670050.738635"], ["11684.10000", "0.04250000", "1596670052.182713"], ["11684.00000", "0.85549737", "1596670045.335462"], ["11683.90000", "0.85552319", "1596670039.204918"], ["11683.60000", "0.08250000", "1596670044.503260"], ["11683.50000", "0.89471000", "1596670029.092926"], ["11683.30000", "1.55000000", "1596670044.191450"], ["11682.60000", "0.10200000", "1596670033.175744"], ["11682.50000", "0.01488303", "1596670050.464313"], ["11682.30000", "0.43800000", "1596670046.349554"], ["11681.90000", "0.07441394", "1596670050.492873"], ["11681.50000", "0.85537698", "1596670001.227142"], ["11680.80000", "2.35472328", "1596670054.304317"], ["11680.70000", "0.66715028", "1596670022.544014"], ["11680.30000", "0.43049043", "1596670049.504429"], ["11680.20000", "2.09800000", "1596670007.554584"], ["11680.10000", "0.20000000", "1596670052.602997"], ["11680.00000", "2.19124918", "1596670008.839271"], ["11679.90000", "2.00000000", "1596669996.091339"], ["11679.70000", "0.01812200", "1596670003.973262"], ["11679.50000", "0.47331962", "1596669999.025841"], ["11677.70000", "0.17858835", "1596670050.568493"], ["11677.50000", "0.70861783", "1596670053.706828"], ["11677.40000", "6.70000000", "1596669991.213694"], ["11675.90000", "1.99930000", "1596670050.745623"], ["11675.70000", "0.50000000", "1596669990.800676"], ["11675.10000", "1.41752700", "1596670053.701733"], ["11675.00000", "0.10339516", "1596670033.098282"], ["11674.80000", "0.91084474", "1596670052.402795"], ["11673.80000", "0.38000000", "1596670053.481572"], ["11672.90000", "0.29144205", "1596670052.263886"], ["11672.80000", "5.90000000", "1596669980.015710"], ["11672.70000", "0.72390873", "1596670033.098764"], ["11672.10000", "0.03300000", "1596670051.616725"], ["11671.30000", "3.92043183", "1596670052.412138"], ["11670.90000", "1.02810000", "1596670036.965297"], ["11670.50000", "4.03133168", "1596670041.611582"], ["11670.10000", "0.38000000", "1596670008.485546"], ["11669.40000", "0.34914899", "1596670033.479979"], ["11669.30000", "1.78967316", "1596670053.701020"], ["11669.10000", "6.00000000", "1596670050.491380"], ["11669.00000", "2.10892760", "1596670052.807282"], ["11667.00000", "0.04300000", "1596670047.892952"], ["11666.90000", "4.42338160", "1596670034.846100"], ["11666.70000", "3.53542285", "1596670053.924979"], ["11666.20000", "7.08541948", "1596670032.048869"], ["11665.20000", "0.01054570", "1596670052.181681"], ["11664.80000", "0.57382811", "1596670033.482553"], ["11664.70000", "0.99516443", "1596670032.795945"], ["11664.60000", "0.05282352", "1596670033.030988"], ["11664.50000", "6.30000000", "1596669972.381575"], ["11663.80000", "0.91174329", "1596670032.215413"], ["11663.30000", "2.00000000", "1596670039.251636"], ["11662.00000", "2.83219056", "1596669947.157989"], ["11660.40000", "7.80000000", "1596669971.776753"], ["11659.30000", "2.01115096", "1596670030.207028"], ["11657.80000", "0.89870505", "1596670033.484330"], ["11657.40000", "0.00103961", "1596670007.759098"], ["11657.30000", "5.99571043", "1596670032.022222"], ["11657.20000", "11.51232065", "1596670037.753137"], ["11656.00000", "2.74107572", "1596670020.760855"], ["11655.90000", "5.30000000", "1596670017.434103"], ["11655.60000", "0.49800000", "1596670049.801510"], ["11655.50000", "1.96069520", "1596670036.294260"], ["11655.40000", "1.49393773", "1596670032.797903"], ["11655.30000", "8.20515297", "1596670039.243515"], ["11655.20000", "11.48284272", "1596670036.174947"], ["11653.10000", "0.10562058", "1596670017.217351"], ["11651.20000", "6.50000000", "1596670006.735481"], ["11650.00000", "1.10300429", "1596669914.853814"], ["11649.80000", "0.75800000", "1596670000.645121"], ["11649.70000", "0.02875427", "1596670009.378578"], ["11648.00000", "18.00000000", "1596669953.610788"], ["11647.70000", "2.01315388", "1596670030.215913"], ["11647.00000", "7.70000000", "1596669855.368110"], ["11646.50000", "2.29920000", "1596670047.476637"], ["11644.70000", "0.74753288", "1596670052.373438"], ["11643.80000", "1.99390140", "1596670032.798163"], ["11643.60000", "2.32229741", "1596670033.101601"], ["11643.10000", "0.48510000", "1596670050.417956"], ["11642.60000", "1.04470000", "1596669948.426594"], ["11641.90000", "0.91345840", "1596670029.990277"], ["11641.40000", "8.10000000", "1596668956.340593"], ["11641.00000", "0.00855607", "1596670017.216987"], ["11639.70000", "13.89668273", "1596670014.977556"], ["11637.90000", "1.17526287", "1596670024.893294"]]}, "book-100", "XBT/USD"]
[270, {"a": [["11695.80000", "2.21774400", "1596670054.507146"]], "c": "247217010"}, "book-100", "XBT/USD"]
[270, {"b": [["11685.00000", "0.76203578", "1596670054.512842"]], "c": "247217010"}, "book-100", "XBT/USD"]
[270, {"b": [["11670.10000", "0.00000000", "1596670054.592395"], ["11637.80000", "2.81728421", "1596670023.589784", "r"]], "c": "247217010"}, "book-100", "XBT/USD"]
[270, {"a": [["11699.10000", "0.85595768", "1596670054.652405"]], "c": "247217010"}, "book-100", "XBT/USD"]
[270, {"a": [["11695.50000", "0.03666451", "1596670054.741797"]], "c": "247217010"}, "book-100", "XBT/USD"]
[270, {"b": [["11683.60000", "0.12250000", "1596670054.754423"]], "c": "247217010"}, "book-100", "XBT/USD"]
[270, {"b": [["11683.60000", "0.04000000", "1596670054.762924"]], "c": "247217010"}, "book-100", "XBT/USD"]
[270, {"a": [["11722.10000", "0.00000000", "1596670054.769188"], ["11738.30000", "1.46266141", "1596669559.966249", "r"]], "c": "247217010"}, "book-100", "XBT/USD"]
[270, {"a": [["11695.20000", "0.00000000", "1596670054.775854"], ["11738.90000", "0.75800000", "1596669999.477236", "r"]], "c": "2512449797"}, "book-100", "XBT/USD"]
[271, [["11690.00000", "0.04000000", "1596670054.896291", "b", "m", ""], ["11691.10000", "0.47610000", "1596670054.925350", "b", "m", ""], ["11692.20000", "0.43390000", "1596670054.928364", "b", "m", ""]], "trade", "XBT/USD"]
[270, {"a": [["11690.00000", "0.00000000", "1596670054.896291"], ["11739.00000", "0.17085000", "1596669876.029945", "r"], ["11691.10000", "0.00000000", "1596670054.925350"], ["11739.50000", "1.00310000", "1596669998.571647", "r"], ["11692.20000", "0.20463793", "1596670054.928364"]], "c": "3884112277"}, "book-100", "XBT/USD"]
[270, {"b": [["11689.90000", "1.85643278", "1596670054.984423"]], "c": "2139752124"}, "book-100", "XBT/USD"]
[270, {"b": [["11690.00000", "0.75551922", "1596670054.988079"]], "c": "2888475759"}, "book-100", "XBT/USD"]
[270, {"b": [["11690.00000", "1.34551922", "1596670055.039126"]], "c": "3236680315"}, "book-100", "XBT/USD"]
[270, {"b": [["11690.00000", "0.59000000", "1596670055.039445"]], "c": "1640734340"}, "book-100", "XBT/USD"]
[270, {"b": [["11689.90000", "1.59916311", "1596670055.051498"]], "c": "3054808326"}, "book-100", "XBT/USD"]
[270, {"b": [["11690.10000", "0.75551922", "1596670055.085025"]], "c": "365576928"}, "book-100", "XBT/USD"]
[270, {"b": [["11689.90000", "1.00916311", "1596670055.091053"]], "c": "4010821856"}, "book-100", "XBT/USD"]
[270, {"b": [["11688.90000", "0.40000000", "1596670055.113386"]], "c": "4185904613"}, "book-100", "XBT/USD"]
[270, {"b": [["11690.10000", "0.00000000", "1596670055.131282"], ["11637.90000", "1.17526287", "1596670024.893294", "r"]], "c": "2494704296"}, "book-100", "XBT/USD"]
[270, {"a": [["11693.80000", "0.00000000", "1596670055.151384"], ["11742.00000", "0.17085000", "1596669544.988601", "r"]], "c": "1192359415"}, "book-100", "XBT/USD"]
[270, {"b": [["11690.10000", "5.00000000", "1596670055.153128"]], "c": "1869846781"}, "book-100", "XBT/USD"]
[270, {"b": [["11690.20000", "0.75551922", "1596670055.197904"]], "c": "256627701"}, "book-100", "XBT/USD"]
[270, {"b": [["11689.90000", "0.36762972", "1596670055.198617"]], "c": "2755109929"}, "book-100", "XBT/USD"]
[270, {"b": [["11689.90000", "0.35962972", "1596670055.203847"]], "c": "2192708637"}, "book-100", "XBT/USD"]
[270, {"b": [["11689.90000", "0.35762972", "1596670055.220598"]], "c": "2795441937"}, "book-100", "XBT/USD"]
[270, {"b": [["11689.90000", "0.00000000", "1596670055.236790"], ["11639.70000", "13.89668273", "1596670014.977556", "r"]], "c": "3423884326"}, "book-100", "XBT/USD"]
[270, {"b": [["11690.00000", "5.69000000", "1596670055.237235"]], "c": "879717713"}, "book-100", "XBT/USD"]
[270, {"b": [["11689.40000", "0.00000000", "1596670055.240267"], ["11637.90000", "1.17526287", "1596670024.893294", "r"]], "c": "2765250418"}, "book-100", "XBT/USD"]
[270, {"b": [["11690.20000", "0.00000000", "1596670055.245873"], ["11637.80000", "2.81728421", "1596670023.589784", "r"]], "c": "1777291828"}, "book-100", "XBT/USD"]
[270, {"a": [["11693.60000", "0.25728116", "1596670055.255231"]], "c": "4242031695"}, "book-100", "XBT/USD"]
[270, {"b": [["11690.30000", "0.75551922", "1596670055.294248"]], "c": "4119954311"}, "book-100", "XBT/USD"]
[270, {"b": [["11690.00000", "0.59000000", "1596670055.309716"]], "c": "3245713716"}, "book-100", "XBT/USD"]
[270, {"b": [["11691.00000", "1.08000000", "1596670055.321740"]], "c": "348791499"}, "book-100", "XBT/USD"]
[270, {"a": [["11700.00000", "4.60593000", "1596670055.327115"]], "c": "348791499"}, "book-100", "XBT/USD"]
[270, {"b": [["11690.30000", "0.00000000", "1596670055.338743"], ["11637.90000", "1.17526287", "1596670024.893294", "r"]], "c": "3250266761"}, "book-100", "XBT/USD"]
[270, {"b": [["11690.20000", "0.25728103", "1596670055.355770"]], "c": "1275890439"}, "book-100", "XBT/USD"]
[270, {"b": [["11690.40000", "0.75551922", "1596670055.385740"]], "c": "2170776268"}, "book-100", "XBT/USD"]
[270, {"b": [["11690.40000", "0.00000000", "1596670055.428943"], ["11639.70000", "13.89668273", "1596670014.977556", "r"]], "c": "1275890439"}, "book-100", "XBT/USD"]
[270, {"b": [["11690.50000", "0.75551922", "1596670055.471776"]], "c": "3058931780"}, "book-100", "XBT/USD"]
[270, {"b": [["11690.50000", "0.00000000", "1596670055.519338"], ["11639.70000", "13.89668273", "1596670014.977556", "r"]], "c": "1275890439"}, "book-100", "XBT/USD"]
[270, {"b": [["11691.10000", "0.75551922", "1596670055.565835"]], "c": "1663964889"}, "book-100", "XBT/USD"]
[270, {"b": [["11691.10000", "0.00000000", "1596670055.607961"], ["11639.70000", "13.89668273", "1596670014.977556", "r"]], "c": "1275890439"}, "book-100", "XBT/USD"]
[270, {"a": [["11695.60000", "0.00000000", "1596670055.613992"], ["11742.00000", "0.17085000", "1596669544.988601", "r"]], "c": "626219546"}, "book-100", "XBT/USD"]
[270, {"b": [["11690.00000", "0.59200000", "1596670055.625184"]], "c": "2742847128"}, "book-100", "XBT/USD"]
[270, {"b": [["11688.50000", "0.00000000", "1596670055.639530"], ["11637.90000", "1.17526287", "1596670024.893294", "r"]], "c": "3223835203"}, "book-100", "XBT/USD"]
[270, {"b": [["11691.20000", "0.75551922", "1596670055.652854"]], "c": "698210977"}, "book-100", "XBT/USD"]
[270, {"a": [["11695.90000", "1.13322305", "1596670055.654690"]], "c": "1852415729"}, "book-100", "XBT/USD"]
[270, {"b": [["11690.00000", "0.00200000", "1596670055.658480"]], "c": "1340463644"}, "book-100", "XBT/USD"]
[270, {"a": [["11693.90000", "0.00000000", "1596670055.674470"], ["11742.20000", "6.50000000", "1596669945.169110", "r"]], "c": "2680665624"}, "book-100", "XBT/USD"]
[270, {"a": [["11701.20000", "0.08250000", "1596670055.674774"]], "c": "2680665624"}, "book-100", "XBT/USD"]
[270, {"b": [["11684.10000", "0.00000000", "1596670055.674983"], ["11637.90000", "1.17526287", "1596670024.893294", "r"]], "c": "2680665624"}, "book-100", "XBT/USD"]
[270, {"b": [["11686.10000", "0.08250000", "1596670055.675837"]], "c": "2680665624"}, "book-100", "XBT/USD"]
[270, {"b": [["11691.20000", "0.00000000", "1596670055.699500"], ["11637.90000", "1.17526287", "1596670024.893294", "r"]], "c": "3690636265"}, "book-100", "XBT/USD"]
[270, {"b": [["11691.10000", "0.64146322", "1596670055.716272"]], "c": "2944325093"}, "book-100", "XBT/USD"]
[270, {"b": [["11690.10000", "0.00000000", "1596670055.723923"], ["11637.90000", "1.17526287", "1596670024.893294", "r"]], "c": "2374514393"}, "book-100", "XBT/USD"]
[270, {"a": [["11695.60000", "0.15000000", "1596670055.730372"]], "c": "3099270748"}, "book-100", "XBT/USD"]
[270, {"b": [["11690.40000", "0.64146322", "1596670055.736269"]], "c": "3503409326"}, "book-100", "XBT/USD"]
[270, {"a": [["11695.30000", "0.00000000", "1596670055.738593"], ["11742.00000", "0.17085000", "1596669544.988601", "r"]], "c": "4157239787"}, "book-100", "XBT/USD"]
[270, {"a": [["11695.70000", "0.03666388", "1596670055.744245"]], "c": "3589730739"}, "book-100", "XBT/USD"]
[270, {"a": [["11695.50000", "0.00000000", "1596670055.745548"], ["11742.00000", "0.17085000", "1596669544.988601", "r"]], "c": "1562392735"}, "book-100", "XBT/USD"]
[270, {"a": [["11692.10000", "0.13066051", "1596670055.748523"]], "c": "1453498931"}, "book-100", "XBT/USD"]
[270, {"b": [["11667.00000", "0.04755609", "1596670055.775018"]], "c": "1453498931"}, "book-100", "XBT/USD"]
[270, {"a": [["11692.10000", "0.68831081", "1596670055.775116"]], "c": "2004044106"}, "book-100", "XBT/USD"]
[270, {"b": [["11690.00000", "0.00000000", "1596670055.775409"], ["11637.90000", "1.17526287", "1596670024.893294", "r"]], "c": "2762696860"}, "book-100", "XBT/USD"]
[270, {"a": [["11712.90000", "0.00438186", "1596670055.778035"]], "c": "2762696860"}, "book-100", "XBT/USD"]
[270, {"b": [["11689.10000", "5.01468237", "1596670055.793914"]], "c": "2837170357"}, "book-100", "XBT/USD"]
[270, {"a": [["11700.90000", "0.53423943", "1596670055.865833"]], "c": "2837170357"}, "book-100", "XBT/USD"]
[270, {"a": [["11694.90000", "0.04250000", "1596670055.873155"]], "c": "205880948"}, "book-100", "XBT/USD"]
[270, {"b": [["11685.30000", "0.04250000", "1596670055.873344"]], "c": "205880948"}, "book-100", "XBT/USD"]
[270, {"a": [["11694.80000", "1.50000000", "1596670055.890258"]], "c": "798503448"}, "book-100", "XBT/USD"]
[270, {"b": [["11691.00000", "1.08200000", "1596670056.037243"]], "c": "3346625607"}, "book-100", "XBT/USD"]
[270, {"b": [["11667.00000", "0.04300000", "1596670056.060116"]], "c": "3346625607"}, "book-100", "XBT/USD"]
[270, {"a": [["11712.90000", "0.00000000", "1596670056.060555"], ["11738.30000", "1.46266141", "1596669559.966249", "r"]], "c": "3346625607"}, "book-100", "XBT/USD"]
[270, {"b": [["11691.00000", "1.08000000", "1596670056.170389"]], "c": "798503448"}, "book-100", "XBT/USD"]
[270, {"a": [["11692.10000", "0.55765030", "1596670056.232992"]], "c": "1011468644"}, "book-100", "XBT/USD"]
[270, {"a": [["11692.00000", "0.13065769", "1596670056.360962"]], "c": "2873674035"}, "book-100", "XBT/USD"]
[270, {"b": [["11691.10000", "0.64346322", "1596670056.438160"]], "c": "1510796451"}, "book-100", "XBT/USD"]
[270, {"b": [["11681.50000", "6.75537698", "1596670056.444320"]], "c": "1510796451"}, "book-100", "XBT/USD"]
[270, {"b": [["11663.80000", "0.00000000", "1596670056.516685"], ["11637.90000", "1.17526287", "1596670024.893294", "r"]], "c": "1510796451"}, "book-100", "XBT/USD"]
[270, {"a": [["11706.90000", "0.34807109", "1596670056.583422"]], "c": "1510796451"}, "book-100", "XBT/USD"]
[270, {"a": [["11703.40000", "4.16287562", "1596670056.585855"]], "c": "1510796451"}, "book-100", "XBT/USD"]
[270, {"b": [["11670.50000", "0.49733493", "1596670056.704772"]], "c": "1510796451"}, "book-100", "XBT/USD"]
[270, {"b": [["11640.00000", "0.17085000", "1596670056.718129"]], "c": "1510796451"}, "book-100", "XBT/USD"]
[270, {"a": [["11692.20000", "0.00000000", "1596670056.756291"], ["11738.10000", "8.91067094", "1596669833.982166", "r"]], "c": "4044407248"}, "book-100", "XBT/USD"]
[270, {"b": [["11680.70000", "0.00000000", "1596670056.757984"], ["11637.90000", "1.17526287", "1596670024.893294", "r"]], "c": "4044407248"}, "book-100", "XBT/USD"]
[270, {"b": [["11668.60000", "0.91138799", "1596670056.828923"]], "c": "4044407248"}, "book-100", "XBT/USD"]
[270, {"a": [["11730.00000", "18.97085000", "1596670056.873883"]], "c": "4044407248"}, "book-100", "XBT/USD"]
[270, {"a": [["11695.60000", "0.00000000", "1596670056.918595"], ["11738.30000", "1.46266141", "1596669559.966249", "r"]], "c": "1915351583"}, "book-100", "XBT/USD"]
[270, {"b": [["11673.40000", "3.53339368", "1596670056.944746"]], "c": "1915351583"}, "book-100", "XBT/USD"]
[270, {"b": [["11681.60000", "0.65310408", "1596670056.973806"]], "c": "1915351583"}, "book-100", "XBT/USD"]
[270, {"b": [["11659.30000", "0.00000000", "1596670056.997091"], ["11640.00000", "0.17085000", "1596670056.718129", "r"]], "c": "1915351583"}, "book-100", "XBT/USD"]
[270, {"b": [["11666.20000", "0.00000000", "1596670057.043694"], ["11639.70000", "13.89668273", "1596670014.977556", "r"]], "c": "1915351583"}, "book-100", "XBT/USD"]
[270, {"a": [["11695.90000", "0.98322305", "1596670057.089912"]], "c": "1915351583"}, "book-100", "XBT/USD"]
[270, {"a": [["11691.50000", "2.00000000", "1596670057.170471"]], "c": "155434016"}, "book-100", "XBT/USD"]
[270, {"b": [["11646.70000", "3.54149397", "1596670057.245802"]], "c": "155434016"}, "book-100", "XBT/USD"]
[270, {"b": [["11644.70000", "0.00000000", "1596670057.255488"], ["11639.70000", "13.89668273", "1596670014.977556", "r"]], "c": "155434016"}, "book-100", "XBT/USD"]
[270, {"a": [["11704.70000", "0.70949356", "1596670057.279151"]], "c": "155434016"}, "book-100", "XBT/USD"]
[270, {"b": [["11641.00000", "2.02290858", "1596670057.281800"]], "c": "155434016"}, "book-100", "XBT/USD"]
