[270, {"as": [["11679.20000", "2.05522131", "1596669750.341037"], ["11679.40000", "0.08562707", "1596669726.331671"], ["11681.20000", "0.02573600", "1596669734.375757"], ["11681.40000", "0.26654316", "1596669749.396789"], ["11681.50000", "0.64193981", "1596669748.199302"], ["11682.00000", "0.64201134", "1596669730.122253"], ["11682.20000", "0.75680000", "1596669697.448211"], ["11683.00000", "0.88729466", "1596669726.431147"], ["11683.50000", "0.04250000", "1596669719.443776"], ["11683.90000", "0.92780123", "1596669719.051726"], ["11684.10000", "0.63486775", "1596669720.082881"], ["11684.40000", "0.85602350", "1596669733.802939"], ["11685.10000", "1.50000000", "1596669736.882823"], ["11685.50000", "0.94000000", "1596669747.813680"], ["11686.30000", "0.09621094", "1596669747.240034"], ["11686.40000", "0.09700000", "1596669714.910015"], ["11686.60000", "0.85659783", "1596669715.303177"], ["11686.90000", "2.69684683", "1596669718.734923"], ["11687.00000", "0.45348827", "1596669674.135850"], ["11687.10000", "0.92536352", "1596669717.629373"], ["11687.90000", "0.85643635", "1596669626.726598"], ["11688.80000", "0.09200000", "1596669599.972191"], ["11689.40000", "1.00256000", "1596669732.323127"], ["11689.60000", "0.04468259", "1596669749.804171"], ["11689.90000", "0.19328149", "1596669750.304536"], ["11690.00000", "0.04000000", "1596669697.702091"], ["11690.30000", "0.50000000", "1596669695.827579"], ["11690.60000", "0.69906226", "1596669717.568157"], ["11690.70000", "2.00000000", "1596669700.956231"], ["11690.90000", "3.29486088", "1596669699.158616"], ["11691.10000", "0.85609838", "1596669717.621039"], ["11692.30000", "0.10500000", "1596669714.879170"], ["11692.60000", "0.10323675", "1596669750.296884"], ["11693.00000", "4.72122940", "1596669627.789136"], ["11693.30000", "6.80000000", "1596669695.964860"], ["11693.50000", "0.85609838", "1596669719.108524"], ["11693.90000", "0.13404865", "1596669749.705175"], ["11694.70000", "0.85605742", "1596669730.459932"], ["11694.90000", "6.82066561", "1596669749.872182"], ["11695.00000", "0.97134814", "1596669720.911833"], ["11695.10000", "4.83976547", "1596669750.201434"], ["11695.60000", "1.41498158", "1596669741.259139"], ["11696.70000", "0.43900000", "1596669749.725884"], ["11697.20000", "4.02094313", "1596669720.536630"], ["11697.40000", "0.38000000", "1596669718.463562"], ["11698.00000", "6.50000000", "1596669345.547690"], ["11698.50000", "1.81754660", "1596669717.894802"], ["11698.60000", "0.34823826", "1596669718.131509"], ["11698.80000", "2.77509736", "1596669717.826744"], ["11699.00000", "0.57210430", "1596669608.934300"], ["11699.10000", "0.00300000", "1596669569.603913"], ["11699.70000", "0.00438186", "1596669749.634078"], ["11699.80000", "3.52420991", "1596669699.061161"], ["11699.90000", "2.39920000", "1596669699.777542"], ["11700.00000", "2.12000000", "1596669703.195911"], ["11700.40000", "0.30000000", "1596669591.016963"], ["11701.00000", "3.20346863", "1596669739.748048"], ["11701.10000", "2.02034735", "1596669508.820583"], ["11701.20000", "7.06386896", "1596669743.241840"], ["11701.50000", "2.32006520", "1596669737.697764"], ["11701.80000", "2.00370644", "1596669745.334280"], ["11702.70000", "0.90817451", "1596669698.025874"], ["11703.00000", "7.60000000", "1596669679.333642"], ["11705.00000", "1.95723116", "1596669582.194951"], ["11705.50000", "7.88991872", "1596669698.032623"], ["11705.60000", "2.00000000", "1596669742.794666"], ["11706.00000", "0.89494148", "1596669698.976837"], ["11707.70000", "7.05942158", "1596669724.567425"], ["11707.90000", "0.02838351", "1596669703.300315"], ["11708.00000", "0.05283540", "1596669724.511844"], ["11708.10000", "3.52171156", "1596669699.854710"], ["11708.20000", "1.50484919", "1596669699.070959"], ["11708.30000", "0.36523955", "1596669705.798039"], ["11708.50000", "6.50000000", "1596669551.845161"], ["11709.60000", "0.92700000", "1596669750.435640"], ["11709.70000", "0.00507863", "1596668161.410923"], ["11710.40000", "0.30000000", "1596669699.630555"], ["11710.90000", "2.00073047", "1596669552.176694"], ["11712.60000", "10.20623047", "1596669705.355233"], ["11713.40000", "6.60000000", "1596669290.909645"], ["11714.50000", "2.24529073", "1596669749.360303"], ["11714.80000", "2.30647591", "1596669698.977277"], ["11714.90000", "1.16749833", "1596669559.964833"], ["11715.30000", "20.70000000", "1596669563.717179"], ["11715.80000", "2.79838949", "1596669235.319856"], ["11716.00000", "5.50001032", "1596669213.205923"], ["11716.10000", "0.90704220", "1596669213.128971"], ["11718.00000", "0.17085000", "1596669733.320626"], ["11718.60000", "7.00000000", "1596668600.575780"], ["11720.40000", "0.30000000", "1596669715.018015"], ["11720.60000", "0.75800000", "1596669478.451007"], ["11720.70000", "0.80800000", "1596668633.562131"], ["11721.00000", "0.17085000", "1596669727.617120"], ["11721.30000", "1.04370000", "1596669685.088868"], ["11721.70000", "1.99888196", "1596669241.115770"], ["11723.70000", "6.20000000", "1596668832.529205"], ["11724.00000", "0.17085000", "1596669695.995407"], ["11724.90000", "10.88860000", "1596669411.292608"], ["11725.10000", "0.75800000", "1596669744.968401"], ["11727.00000", "0.17085000", "1596669684.559277"]], "bs": [["11679.10000", "1.27700000", "1596669748.841392"], ["11678.80000", "0.89948809", "1596669749.583519"], ["11678.70000", "0.47343237", "1596669743.748138"], ["11677.80000", "0.64196444", "1596669745.870840"], ["11677.70000", "0.09621094", "1596669747.237590"], ["11676.90000", "0.75551922", "1596669750.371127"], ["11676.80000", "1.11422231", "1596669745.108371"], ["11676.70000", "0.22500000", "1596669743.296484"], ["11676.50000", "4.27500000", "1596669745.163441"], ["11676.10000", "0.74068237", "1596669749.322579"], ["11675.90000", "0.46135945", "1596669745.107112"], ["11675.80000", "2.59299000", "1596669749.696787"], ["11675.00000", "2.00000000", "1596669722.160397"], ["11674.80000", "0.08250000", "1596669734.400817"], ["11674.60000", "0.85603213", "1596669739.083345"], ["11674.10000", "0.04250000", "1596669726.942726"], ["11673.90000", "0.65475519", "1596669745.870532"], ["11673.80000", "0.85603389", "1596669717.486295"], ["11673.40000", "8.46732000", "1596669745.589085"], ["11672.90000", "0.10200000", "1596669713.372969"], ["11672.70000", "0.04468485", "1596669747.704639"], ["11672.10000", "1.78651221", "1596669717.666910"], ["11671.40000", "0.85603389", "1596669737.466369"], ["11671.20000", "0.13405454", "1596669748.268526"], ["11670.70000", "1.02087000", "1596669713.057387"], ["11670.40000", "0.43800000", "1596669724.923952"], ["11670.20000", "0.50000000", "1596669747.990286"], ["11670.00000", "0.85557145", "1596669716.402306"], ["11669.80000", "0.85595628", "1596669693.189322"], ["11669.40000", "0.85599655", "1596669704.313005"], ["11669.20000", "0.52500000", "1596669726.397462"], ["11669.00000", "0.09946044", "1596669696.522604"], ["11668.90000", "7.60000000", "1596669713.211644"], ["11667.00000", "0.04300000", "1596669660.854379"], ["11665.30000", "0.33777546", "1596669741.266188"], ["11665.20000", "0.01054570", "1596669697.497098"], ["11665.00000", "0.02500000", "1596669670.872006"], ["11663.90000", "5.90000000", "1596669607.743459"], ["11663.50000", "0.38000000", "1596669737.465287"], ["11663.10000", "0.10200000", "1596669699.458173"], ["11662.40000", "0.00435803", "1596669731.387407"], ["11662.30000", "1.98900000", "1596669714.876711"], ["11662.00000", "2.83219056", "1596669706.528800"], ["11661.90000", "0.70953526", "1596669741.267164"], ["11661.40000", "0.10343068", "1596669608.623398"], ["11660.40000", "8.52478129", "1596669739.926985"], ["11660.20000", "0.91165776", "1596669709.849915"], ["11659.40000", "1.41918609", "1596669608.880687"], ["11659.30000", "0.24958797", "1596669608.897858"], ["11658.00000", "0.04217853", "1596669727.686508"], ["11657.90000", "3.53763461", "1596669711.037156"], ["11657.40000", "0.00103961", "1596669562.204435"], ["11657.30000", "3.33582883", "1596669739.664886"], ["11657.00000", "0.49772707", "1596669608.564503"], ["11656.70000", "2.91193149", "1596669721.845663"], ["11655.90000", "5.30000000", "1596669695.956929"], ["11655.80000", "0.34952808", "1596669608.885830"], ["11654.70000", "1.79201886", "1596669711.075258"], ["11654.50000", "1.21150757", "1596669709.850832"], ["11654.10000", "0.03200000", "1596669673.172128"], ["11653.60000", "3.21622728", "1596669745.755547"], ["11653.00000", "7.09396207", "1596669467.511118"], ["11652.70000", "2.01076767", "1596669462.416813"], ["11651.20000", "6.50000000", "1596669709.621778"], ["11650.50000", "1.57057923", "1596669462.183218"], ["11649.30000", "0.05283936", "1596669719.810645"], ["11649.20000", "6.64325646", "1596669745.372504"], ["11649.10000", "0.91230337", "1596669586.900850"], ["11649.00000", "3.53957860", "1596669461.587656"], ["11647.90000", "2.01150279", "1596669467.524023"], ["11647.60000", "0.49800000", "1596669745.160594"], ["11647.30000", "2.03862741", "1596669599.190314"], ["11647.20000", "17.80000000", "1596669594.864646"], ["11647.00000", "7.70000000", "1596668960.228136"], ["11645.10000", "0.91283989", "1596669709.849993"], ["11644.60000", "0.89971493", "1596669740.325061"], ["11644.30000", "0.70560000", "1596669699.698145"], ["11641.40000", "8.10000000", "1596668956.340593"], ["11641.00000", "1.51268822", "1596669462.010073"], ["11639.50000", "0.02879565", "1596669707.327698"], ["11639.30000", "6.43971242", "1596669469.954411"], ["11639.00000", "1.11290000", "1596669601.804463"], ["11638.30000", "7.10136377", "1596669456.025338"], ["11637.70000", "2.25355357", "1596669593.248247"], ["11637.50000", "1.96860663", "1596669401.981533"], ["11637.30000", "0.10574244", "1596669539.321928"], ["11637.20000", "3.54305085", "1596669401.701365"], ["11636.80000", "6.40000000", "1596669707.106342"], ["11635.10000", "17.66702998", "1596669251.957495"], ["11632.60000", "2.29920000", "1596669699.780857"], ["11632.50000", "0.75800000", "1596669684.008513"], ["11632.00000", "6.20000000", "1596669421.111869"], ["11631.90000", "1.03910000", "1596669649.182025"], ["11631.60000", "2.01418770", "1596669711.322426"], ["11631.10000", "14.39225790", "1596669696.977615"], ["11629.40000", "0.02000000", "1596669708.912531"], ["11628.80000", "3.54648721", "1596669713.085494"], ["11628.60000", "0.00856523", "1596669697.743562"], ["11628.50000", "1.17613319", "1596669716.001731"], ["11628.20000", "2.81951588", "1596669460.124744"]]}, "book-100", "XBT/USD"]
[270, {"a": [["11695.70000", "0.69900575", "1596669750.453476"]], "c": "467140950"}, "book-100", "XBT/USD"]
[270, {"a": [["11702.40000", "1.78454947", "1596669750.851062"]], "c": "467140950"}, "book-100", "XBT/USD"]
[270, {"a": [["11694.20000", "0.70758145", "1596669750.851743"]], "c": "467140950"}, "book-100", "XBT/USD"]
[270, {"a": [["11690.80000", "0.33704154", "1596669750.852113"]], "c": "467140950"}, "book-100", "XBT/USD"]
[270, {"a": [["11689.40000", "0.00000000", "1596669750.864098"], ["11724.00000", "0.17085000", "1596669695.995407", "r"]], "c": "467140950"}, "book-100", "XBT/USD"]
[270, {"a": [["11692.10000", "0.65291000", "1596669750.870653"]], "c": "467140950"}, "book-100", "XBT/USD"]
[270, {"a": [["11679.20000", "0.05522131", "1596669750.875792"]], "c": "4021506480"}, "book-100", "XBT/USD"]
[270, {"a": [["11679.20000", "0.05313798", "1596669750.957770"]], "c": "469487946"}, "book-100", "XBT/USD"]
[270, {"a": [["11679.50000", "0.08562267", "1596669751.045406"]], "c": "861323089"}, "book-100", "XBT/USD"]
[270, {"b": [["11670.70000", "0.00000000", "1596669751.117183"], ["11628.00000", "0.17085000", "1596669738.502730", "r"]], "c": "861323089"}, "book-100", "XBT/USD"]
[270, {"b": [["11679.10000", "2.13631000", "1596669751.119128"]], "c": "3452365232"}, "book-100", "XBT/USD"]
[270, {"a": [["11683.40000", "0.64192317", "1596669751.204895"]], "c": "4047661227"}, "book-100", "XBT/USD"]
[270, {"a": [["11682.00000", "0.00000000", "1596669751.313878"], ["11721.70000", "1.99888196", "1596669241.115770", "r"]], "c": "4077371201"}, "book-100", "XBT/USD"]
[270, {"b": [["11668.00000", "0.57700000", "1596669751.665774"]], "c": "4077371201"}, "book-100", "XBT/USD"]
[270, {"b": [["11676.50000", "0.00000000", "1596669751.705692"], ["11628.00000", "0.17085000", "1596669738.502730", "r"]], "c": "2209305955"}, "book-100", "XBT/USD"]
[270, {"b": [["11677.90000", "4.27600000", "1596669751.712132"]], "c": "4180143558"}, "book-100", "XBT/USD"]
[270, {"b": [["11676.90000", "0.00000000", "1596669751.756963"], ["11628.00000", "0.17085000", "1596669738.502730", "r"]], "c": "3456817753"}, "book-100", "XBT/USD"]
[270, {"a": [["11681.40000", "0.00900000", "1596669751.948902"]], "c": "2052940367"}, "book-100", "XBT/USD"]
[270, {"a": [["11698.50000", "0.90881988", "1596669751.952928"]], "c": "2052940367"}, "book-100", "XBT/USD"]
[270, {"a": [["11681.40000", "0.26653694", "1596669752.046485"]], "c": "1087936246"}, "book-100", "XBT/USD"]
[270, {"b": [["11677.40000", "1.55000000", "1596669752.394637"]], "c": "3315145883"}, "book-100", "XBT/USD"]
[270, {"a": [["11681.50000", "0.00000000", "1596669752.395559"], ["11723.70000", "6.20000000", "1596668832.529205", "r"]], "c": "4133245366"}, "book-100", "XBT/USD"]
[270, {"a": [["11704.90000", "0.90853154", "1596669752.450339"]], "c": "4133245366"}, "book-100", "XBT/USD"]
[270, {"a": [["11683.00000", "0.00000000", "1596669752.617715"], ["11723.70000", "6.20000000", "1596668832.529205", "r"]], "c": "2847585708"}, "book-100", "XBT/USD"]
[270, {"b": [["11667.80000", "2.00000000", "1596669752.812940"]], "c": "2847585708"}, "book-100", "XBT/USD"]
[271, [["11679.20000", "0.05313798", "1596669752.873876", "b", "l", ""], ["11679.40000", "0.08562707", "1596669752.878314", "b", "l", ""], ["11679.50000", "0.08562267", "1596669752.879888", "b", "l", ""]], "trade", "XBT/USD"]
[270, {"a": [["11679.20000", "0.00000000", "1596669752.873876"], ["11724.00000", "0.17085000", "1596669695.995407", "r"], ["11679.40000", "0.00000000", "1596669752.878314"], ["11724.90000", "10.88860000", "1596669411.292608", "r"], ["11679.50000", "0.00000000", "1596669752.879888"], ["11725.10000", "0.75800000", "1596669744.968401", "r"]]}, {"b": [["11680.00000", "1.27561228", "1596669752.873455"]], "c": "940842875"}, "book-100", "XBT/USD"]
[270, {"b": [["11680.10000", "0.75551922", "1596669752.932710"]], "c": "3081249481"}, "book-100", "XBT/USD"]
[270, {"b": [["11679.10000", "1.63631000", "1596669752.936270"]], "c": "19830512"}, "book-100", "XBT/USD"]
[270, {"b": [["11679.20000", "3.35000000", "1596669752.945368"]], "c": "2352227595"}, "book-100", "XBT/USD"]
[270, {"b": [["11678.70000", "0.00000000", "1596669752.952288"], ["11628.80000", "3.54648721", "1596669713.085494", "r"]], "c": "1115902707"}, "book-100", "XBT/USD"]
[270, {"b": [["11680.10000", "0.00000000", "1596669752.980888"], ["11628.60000", "0.00856523", "1596669697.743562", "r"]], "c": "2012164798"}, "book-100", "XBT/USD"]
[270, {"b": [["11679.20000", "3.94000000", "1596669752.994003"]], "c": "1232094431"}, "book-100", "XBT/USD"]
[270, {"b": [["11679.20000", "0.59000000", "1596669753.004147"]], "c": "5778386"}, "book-100", "XBT/USD"]
[270, {"a": [["11683.90000", "0.82880123", "1596669753.005286"]], "c": "221541747"}, "book-100", "XBT/USD"]
[270, {"a": [["11681.10000", "0.04249882", "1596669753.020640"]], "c": "718845713"}, "book-100", "XBT/USD"]
[270, {"b": [["11679.10000", "1.26131000", "1596669753.034192"]], "c": "3460689124"}, "book-100", "XBT/USD"]
[270, {"a": [["11683.30000", "0.08560398", "1596669753.082702"]], "c": "3801315433"}, "book-100", "XBT/USD"]
[270, {"a": [["11692.10000", "0.00000000", "1596669753.091056"], ["11724.90000", "10.88860000", "1596669411.292608", "r"]], "c": "3801315433"}, "book-100", "XBT/USD"]
[270, {"b": [["11679.10000", "1.25931000", "1596669753.170096"]], "c": "2562865014"}, "book-100", "XBT/USD"]
[270, {"b": [["11670.00000", "0.76990000", "1596669753.217519"]], "c": "2562865014"}, "book-100", "XBT/USD"]
[270, {"b": [["11679.90000", "0.56700000", "1596669753.288978"]], "c": "3752900672"}, "book-100", "XBT/USD"]
[270, {"a": [["11681.10000", "0.09563680", "1596669753.487082"]], "c": "2805874439"}, "book-100", "XBT/USD"]
[270, {"a": [["11681.10000", "0.05313798", "1596669753.489565"]], "c": "1502250703"}, "book-100", "XBT/USD"]
[270, {"a": [["11683.40000", "0.00000000", "1596669753.528095"], ["11725.10000", "0.75800000", "1596669744.968401", "r"]], "c": "1492356330"}, "book-100", "XBT/USD"]
[270, {"b": [["11647.60000", "0.00000000", "1596669753.589786"], ["11628.60000", "0.00856523", "1596669697.743562", "r"]], "c": "1492356330"}, "book-100", "XBT/USD"]
[270, {"b": [["11651.30000", "2.03664012", "1596669753.593183"]], "c": "1492356330"}, "book-100", "XBT/USD"]
[270, {"b": [["11679.20000", "1.23197115", "1596669753.593443"]], "c": "4213249432"}, "book-100", "XBT/USD"]
[270, {"a": [["11681.00000", "0.12996434", "1596669753.596506"]], "c": "3652794794"}, "book-100", "XBT/USD"]
[270, {"a": [["11680.60000", "0.64197115", "1596669753.608062"]], "c": "762473146"}, "book-100", "XBT/USD"]
[270, {"b": [["11679.90000", "0.00000000", "1596669753.608595"], ["11628.60000", "0.00856523", "1596669697.743562", "r"]], "c": "3452496634"}, "book-100", "XBT/USD"]
[270, {"a": [["11681.00000", "0.77192320", "1596669753.608818"]], "c": "2317201626"}, "book-100", "XBT/USD"]
[270, {"a": [["11682.20000", "1.39877768", "1596669753.609828"]], "c": "3826120176"}, "book-100", "XBT/USD"]
[270, {"b": [["11676.10000", "0.00000000", "1596669753.652313"], ["11628.50000", "1.17613319", "1596669716.001731", "r"]], "c": "3826120176"}, "book-100", "XBT/USD"]
[270, {"a": [["11680.60000", "2.64197115", "1596669753.657605"]], "c": "455886227"}, "book-100", "XBT/USD"]
[270, {"a": [["11681.10000", "0.65036195", "1596669753.658809"]], "c": "3534420285"}, "book-100", "XBT/USD"]
[270, {"a": [["11681.40000", "0.25753694", "1596669753.660265"]], "c": "2486564682"}, "book-100", "XBT/USD"]
[270, {"b": [["11680.50000", "0.50000000", "1596669753.684181"]], "c": "3947820020"}, "book-100", "XBT/USD"]
[270, {"a": [["11680.90000", "0.00900000", "1596669753.714663"]], "c": "2912769575"}, "book-100", "XBT/USD"]
[270, {"a": [["11681.10000", "0.59722397", "1596669753.739536"]], "c": "1877790297"}, "book-100", "XBT/USD"]
[270, {"b": [["11647.30000", "0.00000000", "1596669753.759349"], ["11628.50000", "1.17613319", "1596669716.001731", "r"]], "c": "1877790297"}, "book-100", "XBT/USD"]
[270, {"b": [["11679.20000", "0.64197115", "1596669753.779426"]], "c": "985340114"}, "book-100", "XBT/USD"]
[270, {"b": [["11676.70000", "0.96568237", "1596669753.797695"]], "c": "985340114"}, "book-100", "XBT/USD"]
[270, {"b": [["11680.00000", "1.27761228", "1596669753.835699"]], "c": "2552714509"}, "book-100", "XBT/USD"]
[270, {"b": [["11679.10000", "0.40000000", "1596669753.861387"]], "c": "933013649"}, "book-100", "XBT/USD"]
[270, {"b": [["11679.10000", "0.00000000", "1596669753.877292"], ["11628.20000", "2.81951588", "1596669460.124744", "r"]], "c": "1336317307"}, "book-100", "XBT/USD"]
[270, {"b": [["11678.80000", "0.64194608", "1596669753.923197"]], "c": "195047981"}, "book-100", "XBT/USD"]
[270, {"a": [["11680.60000", "3.14197115", "1596669753.948844"]], "c": "219475891"}, "book-100", "XBT/USD"]
[270, {"b": [["11680.50000", "0.00000000", "1596669753.949144"], ["11628.00000", "0.17085000", "1596669738.502730", "r"]], "c": "3054760841"}, "book-100", "XBT/USD"]
[270, {"b": [["11676.70000", "0.22500000", "1596669753.965755"]], "c": "3205163696"}, "book-100", "XBT/USD"]
[270, {"b": [["11680.00000", "1.27561228", "1596669753.968661"]], "c": "1313787680"}, "book-100", "XBT/USD"]
[270, {"a": [["11681.10000", "0.00000000", "1596669753.977960"], ["11724.00000", "0.17085000", "1596669695.995407", "r"]], "c": "640744290"}, "book-100", "XBT/USD"]
[270, {"a": [["11694.70000", "0.00000000", "1596669753.983622"], ["11724.90000", "10.88860000", "1596669411.292608", "r"]], "c": "640744290"}, "book-100", "XBT/USD"]
[270, {"b": [["11679.20000", "0.00000000", "1596669753.984028"], ["11627.70000", "0.37365782", "1596669727.959638", "r"]], "c": "3833529795"}, "book-100", "XBT/USD"]
[270, {"a": [["11680.90000", "0.00000000", "1596669754.005386"], ["11725.10000", "0.75800000", "1596669744.968401", "r"]], "c": "4149255190"}, "book-100", "XBT/USD"]
[270, {"a": [["11680.60000", "2.64197115", "1596669754.010279"]], "c": "4165453101"}, "book-100", "XBT/USD"]
[270, {"b": [["11678.00000", "0.25754373", "1596669754.023164"]], "c": "539511431"}, "book-100", "XBT/USD"]
[270, {"a": [["11691.00000", "0.45472036", "1596669754.034128"]], "c": "539511431"}, "book-100", "XBT/USD"]
[270, {"a": [["11702.90000", "0.62041184", "1596669754.034202"]], "c": "539511431"}, "book-100", "XBT/USD"]
[270, {"b": [["11677.90000", "0.00000000", "1596669754.041726"], ["11627.70000", "0.37365782", "1596669727.959638", "r"]], "c": "676078510"}, "book-100", "XBT/USD"]
[270, {"b": [["11673.40000", "0.96732000", "1596669754.063508"]], "c": "676078510"}, "book-100", "XBT/USD"]
[270, {"a": [["11681.00000", "0.64195886", "1596669754.080140"]], "c": "3895141998"}, "book-100", "XBT/USD"]
[270, {"a": [["11680.50000", "0.27000000", "1596669754.086042"]], "c": "1554549899"}, "book-100", "XBT/USD"]
[270, {"b": [["11678.80000", "0.00000000", "1596669754.090193"], ["11627.40000", "0.01715774", "1596669689.864876", "r"]], "c": "1751850990"}, "book-100", "XBT/USD"]
[270, {"a": [["11693.50000", "0.00000000", "1596669754.090420"], ["11724.00000", "0.17085000", "1596669695.995407", "r"]], "c": "1751850990"}, "book-100", "XBT/USD"]
[270, {"a": [["11680.90000", "0.05313798", "1596669754.093630"]], "c": "3174133321"}, "book-100", "XBT/USD"]
[270, {"a": [["11680.50000", "0.27900000", "1596669754.096852"]], "c": "3161166178"}, "book-100", "XBT/USD"]
[270, {"b": [["11676.90000", "4.27700000", "1596669754.103247"]], "c": "3292832819"}, "book-100", "XBT/USD"]
[270, {"b": [["11675.10000", "0.74068237", "1596669754.109113"]], "c": "3292832819"}, "book-100", "XBT/USD"]
[270, {"a": [["11681.40000", "0.00000000", "1596669754.121510"], ["11724.00000", "0.17085000", "1596669695.995407", "r"]], "c": "3951379424"}, "book-100", "XBT/USD"]
[270, {"a": [["11682.20000", "0.75680000", "1596669754.136974"]], "c": "681686843"}, "book-100", "XBT/USD"]
[270, {"a": [["11680.10000", "0.50000000", "1596669754.153159"]], "c": "1340577557"}, "book-100", "XBT/USD"]
[270, {"b": [["11677.80000", "0.00000000", "1596669754.158910"], ["11627.70000", "0.37365782", "1596669727.959638", "r"]], "c": "2609728454"}, "book-100", "XBT/USD"]
[270, {"b": [["11675.80000", "0.88199000", "1596669754.164487"]], "c": "119812522"}, "book-100", "XBT/USD"]
[270, {"b": [["11668.80000", "2.00810251", "1596669754.178136"]], "c": "119812522"}, "book-100", "XBT/USD"]
[270, {"a": [["11688.90000", "1.00424000", "1596669754.212938"]], "c": "119812522"}, "book-100", "XBT/USD"]
[270, {"a": [["11680.40000", "0.05313798", "1596669754.226837"]], "c": "640169622"}, "book-100", "XBT/USD"]
[270, {"a": [["11688.00000", "0.87873631", "1596669754.228681"]], "c": "640169622"}, "book-100", "XBT/USD"]
[270, {"a": [["11680.90000", "0.00000000", "1596669754.228961"], ["11721.30000", "1.04370000", "1596669685.088868", "r"]], "c": "871038818"}, "book-100", "XBT/USD"]
