{"type":"l2update","product_id":"BTC-USD","changes":[["buy","9102.07","0.00000000"]],"time":"2020-06-30T19:23:06.608285Z"}
{"type":"heartbeat","last_trade_id":0,"product_id":"BTC-USD","sequence":180759244,"time":"2020-06-30T19:23:06.735114Z"}
{"type":"l2update","product_id":"BTC-USD","changes":[["buy","9127.81","0.00000000"]],"time":"2020-06-30T19:23:07.091654Z"}
{"type":"l2update","product_id":"BTC-USD","changes":[["sell","9151.04","0.02360000"]],"time":"2020-06-30T19:23:07.524312Z"}
{"type":"heartbeat","last_trade_id":0,"product_id":"BTC-USD","sequence":180759247,"time":"2020-06-30T19:23:07.735105Z"}
{"type":"l2update","product_id":"BTC-USD","changes":[["sell","9170.84","0.01570000"]],"time":"2020-06-30T19:23:08.119754Z"}
{"type":"l2update","product_id":"BTC-USD","changes":[["sell","9134.77","3005.98430000"]],"time":"2020-06-30T19:23:08.381696Z"}
{"type":"l2update","product_id":"BTC-USD","changes":[["sell","9163.75","0.00000000"]],"time":"2020-06-30T19:23:08.585854Z"}
{"type":"heartbeat","last_trade_id":0,"product_id":"BTC-USD","sequence":180759253,"time":"2020-06-30T19:23:08.735116Z"}
{"type":"heartbeat","last_trade_id":0,"product_id":"BTC-USD","sequence":180759253,"time":"2020-06-30T19:23:09.735111Z"}
{"type":"l2update","product_id":"BTC-USD","changes":[["buy","9130.67","0.06570000"]],"time":"2020-06-30T19:23:09.808339Z"}
{"type":"l2update","product_id":"BTC-USD","changes":[["buy","9131.86","0.00000000"]],"time":"2020-06-30T19:23:10.286881Z"}
{"type":"heartbeat","last_trade_id":0,"product_id":"BTC-USD","sequence":180759256,"time":"2020-06-30T19:23:10.735113Z"}
{"type":"l2update","product_id":"BTC-USD","changes":[["sell","9134.77","3005.23430000"]],"time":"2020-06-30T19:23:10.969976Z"}
{"type":"l2update","product_id":"BTC-USD","changes":[["buy","9128.26","0.03060000"]],"time":"2020-06-30T19:23:11.241196Z"}
{"type":"l2update","product_id":"BTC-USD","changes":[["buy","9134.75","3009.99900000"]],"time":"2020-06-30T19:23:11.485175Z"}
{"type":"l2update","product_id":"BTC-USD","changes":[["sell","9138.79","0.15610000"]],"time":"2020-06-30T19:23:11.534333Z"}
{"type":"heartbeat","last_trade_id":0,"product_id":"BTC-USD","sequence":180759266,"time":"2020-06-30T19:23:11.735112Z"}
{"type":"l2update","product_id":"BTC-USD","changes":[["buy","9093.06","0.07610000"]],"time":"2020-06-30T19:23:11.789120Z"}
{"type":"l2update","product_id":"BTC-USD","changes":[["buy","9128.09","0.00000000"]],"time":"2020-06-30T19:23:12.214248Z"}
{"type":"l2update","product_id":"BTC-USD","changes":[["sell","9162.49","0.01000000"]],"time":"2020-06-30T19:23:12.360127Z"}
{"type":"l2update","product_id":"BTC-USD","changes":[["sell","9183.05","0.00000000"]],"time":"2020-06-30T19:23:12.556910Z"}
{"type":"heartbeat","last_trade_id":0,"product_id":"BTC-USD","sequence":180759272,"time":"2020-06-30T19:23:12.735119Z"}
{"type":"l2update","product_id":"BTC-USD","changes":[["sell","9134.77","3005.10930000"]],"time":"2020-06-30T19:23:12.886780Z"}
{"type":"l2update","product_id":"BTC-USD","changes":[["sell","9134.77","3004.56830000"]],"time":"2020-06-30T19:23:13.159884Z"}
{"type":"l2update","product_id":"BTC-USD","changes":[["sell","9134.77","3004.44330000"]],"time":"2020-06-30T19:23:13.454784Z"}
{"type":"l2update","product_id":"BTC-USD","changes":[["buy","9130.67","0.00000000"]],"time":"2020-06-30T19:23:13.609828Z"}
{"type":"heartbeat","last_trade_id":0,"product_id":"BTC-USD","sequence":180759282,"time":"2020-06-30T19:23:13.735120Z"}
{"type":"l2update","product_id":"BTC-USD","changes":[["buy","100.00","114.95500000"]],"time":"2020-06-30T19:23:14.021006Z"}
{"type":"l2update","product_id":"BTC-USD","changes":[["buy","100.00","114.94500000"]],"time":"2020-06-30T19:23:14.027933Z"}
{"type":"l2update","product_id":"BTC-USD","changes":[["buy","9116.70","0.04120000"]],"time":"2020-06-30T19:23:14.265946Z"}
{"type":"l2update","product_id":"BTC-USD","changes":[["buy","9101.75","0.01000000"]],"time":"2020-06-30T19:23:14.558446Z"}
{"type":"heartbeat","last_trade_id":0,"product_id":"BTC-USD","sequence":180759289,"time":"2020-06-30T19:23:14.735115Z"}
{"type":"l2update","product_id":"BTC-USD","changes":[["sell","9181.51","0.02220000"]],"time":"2020-06-30T19:23:14.830816Z"}
{"type":"l2update","product_id":"BTC-USD","changes":[["sell","9136.40","0.00000000"]],"time":"2020-06-30T19:23:15.302229Z"}
{"type":"l2update","product_id":"BTC-USD","changes":[["sell","9134.77","3004.31570000"]],"time":"2020-06-30T19:23:15.455976Z"}
{"type":"l2update","product_id":"BTC-USD","changes":[["buy","9129.71","0.00000000"]],"time":"2020-06-30T19:23:15.680259Z"}
{"type":"heartbeat","last_trade_id":0,"product_id":"BTC-USD","sequence":180759296,"time":"2020-06-30T19:23:15.735055Z"}
{"type":"l2update","product_id":"BTC-USD","changes":[["sell","9134.77","3004.26570000"]],"time":"2020-06-30T19:23:15.947581Z"}
{"type":"heartbeat","last_trade_id":0,"product_id":"BTC-USD","sequence":180759299,"time":"2020-06-30T19:23:16.735110Z"}
{"type":"l2update","product_id":"BTC-USD","changes":[["buy","9131.49","0.00000000"]],"time":"2020-06-30T19:23:16.951520Z"}
{"type":"l2update","product_id":"BTC-USD","changes":[["sell","9147.51","0.03250000"]],"time":"2020-06-30T19:23:17.053430Z"}
{"type":"l2update","product_id":"BTC-USD","changes":[["sell","9134.77","3004.21570000"]],"time":"2020-06-30T19:23:17.593075Z"}
{"type":"heartbeat","last_trade_id":0,"product_id":"BTC-USD","sequence":180759305,"time":"2020-06-30T19:23:17.735066Z"}
{"type":"l2update","product_id":"BTC-USD","changes":[["buy","9093.06","0.00000000"]],"time":"2020-06-30T19:23:17.803228Z"}
{"type":"l2update","product_id":"BTC-USD","changes":[["sell","9138.82","0.05000000"]],"time":"2020-06-30T19:23:17.889982Z"}
{"type":"l2update","product_id":"BTC-USD","changes":[["buy","9119.07","0.50000000"]],"time":"2020-06-30T19:23:18.156362Z"}
{"type":"l2update","product_id":"BTC-USD","changes":[["buy","9128.26","0.00000000"]],"time":"2020-06-30T19:23:18.385329Z"}
{"type":"l2update","product_id":"BTC-USD","changes":[["buy","9127.99","0.06570000"]],"time":"2020-06-30T19:23:18.710084Z"}
{"type":"heartbeat","last_trade_id":0,"product_id":"BTC-USD","sequence":180759313,"time":"2020-06-30T19:23:18.735050Z"}
{"type":"l2update","product_id":"BTC-USD","changes":[["sell","9163.82","0.01000000"]],"time":"2020-06-30T19:23:18.984086Z"}
{"type":"l2update","product_id":"BTC-USD","changes":[["sell","9170.84","0.00000000"]],"time":"2020-06-30T19:23:19.220959Z"}
{"type":"l2update","product_id":"BTC-USD","changes":[["sell","9151.41","1.18870000"]],"time":"2020-06-30T19:23:19.280802Z"}
{"type":"heartbeat","last_trade_id":0,"product_id":"BTC-USD","sequence":180759318,"time":"2020-06-30T19:23:19.735051Z"}
{"type":"l2update","product_id":"BTC-USD","changes":[["buy","9128.06","0.06570000"]],"time":"2020-06-30T19:23:19.832806Z"}
{"type":"l2update","product_id":"BTC-USD","changes":[["sell","9134.77","3004.16570000"]],"time":"2020-06-30T19:23:20.123513Z"}
{"type":"l2update","product_id":"BTC-USD","changes":[["sell","9164.84","0.01000000"]],"time":"2020-06-30T19:23:20.397054Z"}
{"type":"l2update","product_id":"BTC-USD","changes":[["sell","9138.72","0.00110000"]],"time":"2020-06-30T19:23:20.648222Z"}
{"type":"heartbeat","last_trade_id":0,"product_id":"BTC-USD","sequence":180759327,"time":"2020-06-30T19:23:20.735096Z"}
{"type":"l2update","product_id":"BTC-USD","changes":[["sell","9151.41","0.00000000"]],"time":"2020-06-30T19:23:20.876996Z"}
{"type":"l2update","product_id":"BTC-USD","changes":[["sell","9138.42","0.05000000"]],"time":"2020-06-30T19:23:21.463819Z"}
{"type":"heartbeat","last_trade_id":0,"product_id":"BTC-USD","sequence":180759330,"time":"2020-06-30T19:23:21.735115Z"}
{"type":"l2update","product_id":"BTC-USD","changes":[["sell","9163.82","0.00000000"]],"time":"2020-06-30T19:23:22.464771Z"}
{"type":"l2update","product_id":"BTC-USD","changes":[["sell","9138.72","0.05110000"]],"time":"2020-06-30T19:23:22.564250Z"}
{"type":"heartbeat","last_trade_id":0,"product_id":"BTC-USD","sequence":180759333,"time":"2020-06-30T19:23:22.735068Z"}
{"type":"l2update","product_id":"BTC-USD","changes":[["buy","8992.14","0.01000000"]],"time":"2020-06-30T19:23:23.135695Z"}
{"type":"l2update","product_id":"BTC-USD","changes":[["sell","9145.17","0.02360000"]],"time":"2020-06-30T19:23:23.707022Z"}
{"type":"heartbeat","last_trade_id":0,"product_id":"BTC-USD","sequence":180759337,"time":"2020-06-30T19:23:23.735085Z"}
{"type":"l2update","product_id":"BTC-USD","changes":[["sell","9139.23","0.53630000"]],"time":"2020-06-30T19:23:23.976928Z"}
{"type":"l2update","product_id":"BTC-USD","changes":[["sell","9182.46","0.00000000"]],"time":"2020-06-30T19:23:24.177877Z"}
{"type":"l2update","product_id":"BTC-USD","changes":[["sell","9140.55","0.37030000"]],"time":"2020-06-30T19:23:24.258310Z"}
{"type":"l2update","product_id":"BTC-USD","changes":[["sell","9138.79","0.00000000"]],"time":"2020-06-30T19:23:24.430419Z"}
{"type":"l2update","product_id":"BTC-USD","changes":[["buy","9127.98","0.21910000"]],"time":"2020-06-30T19:23:24.544575Z"}
{"type":"heartbeat","last_trade_id":0,"product_id":"BTC-USD","sequence":180759345,"time":"2020-06-30T19:23:24.735111Z"}
{"type":"l2update","product_id":"BTC-USD","changes":[["buy","9101.75","0.00000000"]],"time":"2020-06-30T19:23:24.999953Z"}
{"type":"heartbeat","last_trade_id":0,"product_id":"BTC-USD","sequence":180759346,"time":"2020-06-30T19:23:25.735127Z"}
{"type":"l2update","product_id":"BTC-USD","changes":[["sell","9179.47","0.05270000"]],"time":"2020-06-30T19:23:26.050609Z"}
{"type":"l2update","product_id":"BTC-USD","changes":[["sell","9151.04","0.00000000"]],"time":"2020-06-30T19:23:26.514994Z"}
{"type":"heartbeat","last_trade_id":0,"product_id":"BTC-USD","sequence":180759349,"time":"2020-06-30T19:23:26.735113Z"}
{"type":"l2update","product_id":"BTC-USD","changes":[["buy","9102.50","0.03730000"]],"time":"2020-06-30T19:23:26.960099Z"}
{"type":"heartbeat","last_trade_id":0,"product_id":"BTC-USD","sequence":180759351,"time":"2020-06-30T19:23:27.735113Z"}
{"type":"l2update","product_id":"BTC-USD","changes":[["sell","9179.18","0.12330000"]],"time":"2020-06-30T19:23:28.367897Z"}
{"type":"heartbeat","last_trade_id":0,"product_id":"BTC-USD","sequence":180759353,"time":"2020-06-30T19:23:28.735117Z"}
{"type":"l2update","product_id":"BTC-USD","changes":[["sell","9162.49","0.00000000"]],"time":"2020-06-30T19:23:28.840594Z"}
{"type":"l2update","product_id":"BTC-USD","changes":[["sell","9138.72","0.05000000"]],"time":"2020-06-30T19:23:28.841642Z"}
{"type":"l2update","product_id":"BTC-USD","changes":[["buy","100.00","114.95500000"]],"time":"2020-06-30T19:23:29.026733Z"}
{"type":"l2update","product_id":"BTC-USD","changes":[["buy","100.00","114.94500000"]],"time":"2020-06-30T19:23:29.033605Z"}
{"type":"l2update","product_id":"BTC-USD","changes":[["buy","8938.18","0.00100000"]],"time":"2020-06-30T19:23:29.187162Z"}
{"type":"l2update","product_id":"BTC-USD","changes":[["buy","9131.84","0.04000000"]],"time":"2020-06-30T19:23:29.461582Z"}
{"type":"l2update","product_id":"BTC-USD","changes":[["buy","9127.83","0.00000000"]],"time":"2020-06-30T19:23:29.637317Z"}
{"type":"l2update","product_id":"BTC-USD","changes":[["sell","9134.77","3004.10000000"]],"time":"2020-06-30T19:23:29.734649Z"}
{"type":"heartbeat","last_trade_id":0,"product_id":"BTC-USD","sequence":180759366,"time":"2020-06-30T19:23:29.735123Z"}
{"type":"l2update","product_id":"BTC-USD","changes":[["buy","8992.14","0.00000000"]],"time":"2020-06-30T19:23:29.929169Z"}
{"type":"l2update","product_id":"BTC-USD","changes":[["buy","9127.99","0.00000000"]],"time":"2020-06-30T19:23:29.936530Z"}
{"type":"l2update","product_id":"BTC-USD","changes":[["buy","9116.70","0.00000000"]],"time":"2020-06-30T19:23:29.946491Z"}
{"type":"heartbeat","last_trade_id":0,"product_id":"BTC-USD","sequence":180759369,"time":"2020-06-30T19:23:30.735129Z"}
{"type":"l2update","product_id":"BTC-USD","changes":[["sell","9134.77","3003.04690000"]],"time":"2020-06-30T19:23:30.841226Z"}
{"type":"l2update","product_id":"BTC-USD","changes":[["buy","9128.06","0.00000000"]],"time":"2020-06-30T19:23:31.274579Z"}
{"type":"heartbeat","last_trade_id":0,"product_id":"BTC-USD","sequence":180759373,"time":"2020-06-30T19:23:31.735058Z"}
{"type":"l2update","product_id":"BTC-USD","changes":[["buy","9109.35","0.05260000"]],"time":"2020-06-30T19:23:31.976234Z"}
{"type":"l2update","product_id":"BTC-USD","changes":[["sell","9134.77","3002.99690000"]],"time":"2020-06-30T19:23:32.518131Z"}
{"type":"heartbeat","last_trade_id":0,"product_id":"BTC-USD","sequence":180759378,"time":"2020-06-30T19:23:32.735116Z"}
{"type":"l2update","product_id":"BTC-USD","changes":[["sell","9134.77","3002.94690000"]],"time":"2020-06-30T19:23:32.797599Z"}
{"type":"l2update","product_id":"BTC-USD","changes":[["buy","9127.98","0.00000000"]],"time":"2020-06-30T19:23:33.271641Z"}
{"type":"l2update","product_id":"BTC-USD","changes":[["buy","9119.07","0.00000000"]],"time":"2020-06-30T19:23:33.275338Z"}
{"type":"l2update","product_id":"BTC-USD","changes":[["sell","9180.36","0.01490000"]],"time":"2020-06-30T19:23:33.372244Z"}
{"type":"heartbeat","last_trade_id":0,"product_id":"BTC-USD","sequence":180759385,"time":"2020-06-30T19:23:33.735062Z"}
{"type":"l2update","product_id":"BTC-USD","changes":[["sell","9164.84","0.00000000"]],"time":"2020-06-30T19:23:33.813162Z"}
{"type":"l2update","product_id":"BTC-USD","changes":[["sell","9147.51","0.00000000"]],"time":"2020-06-30T19:23:33.815365Z"}
{"type":"heartbeat","last_trade_id":0,"product_id":"BTC-USD","sequence":180759387,"time":"2020-06-30T19:23:34.735042Z"}
{"type":"l2update","product_id":"BTC-USD","changes":[["sell","9134.77","3002.88120000"]],"time":"2020-06-30T19:23:35.557424Z"}
{"type":"heartbeat","last_trade_id":0,"product_id":"BTC-USD","sequence":180759390,"time":"2020-06-30T19:23:35.735092Z"}
{"type":"l2update","product_id":"BTC-USD","changes":[["buy","9134.31","0.75000000"]],"time":"2020-06-30T19:23:36.400919Z"}
{"type":"l2update","product_id":"BTC-USD","changes":[["sell","9134.77","3002.83120000"]],"time":"2020-06-30T19:23:36.676885Z"}
{"type":"heartbeat","last_trade_id":0,"product_id":"BTC-USD","sequence":180759395,"time":"2020-06-30T19:23:36.735112Z"}
{"type":"l2update","product_id":"BTC-USD","changes":[["buy","9109.35","0.00000000"]],"time":"2020-06-30T19:23:37.107260Z"}
{"type":"l2update","product_id":"BTC-USD","changes":[["buy","9117.86","0.50710000"]],"time":"2020-06-30T19:23:37.232171Z"}
{"type":"heartbeat","last_trade_id":0,"product_id":"BTC-USD","sequence":180759398,"time":"2020-06-30T19:23:37.735008Z"}
{"type":"l2update","product_id":"BTC-USD","changes":[["sell","9134.77","2997.76800000"]],"time":"2020-06-30T19:23:37.786814Z"}
{"type":"l2update","product_id":"BTC-USD","changes":[["sell","9134.77","2997.70230000"]],"time":"2020-06-30T19:23:38.064533Z"}
{"type":"l2update","product_id":"BTC-USD","changes":[["buy","8908.03","0.00000000"]],"time":"2020-06-30T19:23:38.112627Z"}
{"type":"l2update","product_id":"BTC-USD","changes":[["buy","9133.27","0.54100000"]],"time":"2020-06-30T19:23:38.357890Z"}
{"type":"l2update","product_id":"BTC-USD","changes":[["buy","8907.15","0.04481697"]],"time":"2020-06-30T19:23:38.493564Z"}
{"type":"heartbeat","last_trade_id":0,"product_id":"BTC-USD","sequence":180759409,"time":"2020-06-30T19:23:38.735135Z"}
{"type":"l2update","product_id":"BTC-USD","changes":[["sell","9422.09","0.00000000"]],"time":"2020-06-30T19:23:38.793635Z"}
{"type":"l2update","product_id":"BTC-USD","changes":[["buy","9102.50","0.00000000"]],"time":"2020-06-30T19:23:38.805779Z"}
{"type":"l2update","product_id":"BTC-USD","changes":[["buy","9097.62","0.02100000"]],"time":"2020-06-30T19:23:38.919499Z"}
{"type":"l2update","product_id":"BTC-USD","changes":[["sell","9423.02","0.00559783"]],"time":"2020-06-30T19:23:39.017319Z"}
{"type":"l2update","product_id":"BTC-USD","changes":[["sell","9179.03","0.09650000"]],"time":"2020-06-30T19:23:39.476694Z"}
{"type":"l2update","product_id":"BTC-USD","changes":[["sell","9138.82","0.00000000"]],"time":"2020-06-30T19:23:39.725738Z"}
{"type":"l2update","product_id":"BTC-USD","changes":[["sell","9138.72","0.00000000"]],"time":"2020-06-30T19:23:39.735992Z"}
{"type":"heartbeat","last_trade_id":0,"product_id":"BTC-USD","sequence":180759419,"time":"2020-06-30T19:23:39.735123Z"}
{"type":"l2update","product_id":"BTC-USD","changes":[["sell","9134.77","2997.63660000"]],"time":"2020-06-30T19:23:39.778414Z"}
{"type":"l2update","product_id":"BTC-USD","changes":[["sell","9134.77","2997.63560000"]],"time":"2020-06-30T19:23:40.667383Z"}
{"type":"heartbeat","last_trade_id":0,"product_id":"BTC-USD","sequence":180759425,"time":"2020-06-30T19:23:40.735125Z"}
{"type":"heartbeat","last_trade_id":0,"product_id":"BTC-USD","sequence":180759425,"time":"2020-06-30T19:23:41.735116Z"}
{"type":"l2update","product_id":"BTC-USD","changes":[["sell","9134.77","2997.56990000"]],"time":"2020-06-30T19:23:41.885463Z"}
{"type":"l2update","product_id":"BTC-USD","changes":[["sell","9178.60","0.05000000"]],"time":"2020-06-30T19:23:42.096052Z"}
{"type":"l2update","product_id":"BTC-USD","changes":[["sell","9180.36","0.00000000"]],"time":"2020-06-30T19:23:42.272246Z"}
{"type":"l2update","product_id":"BTC-USD","changes":[["sell","9139.23","0.00000000"]],"time":"2020-06-30T19:23:42.332623Z"}
{"type":"heartbeat","last_trade_id":0,"product_id":"BTC-USD","sequence":180759432,"time":"2020-06-30T19:23:42.735118Z"}
{"type":"l2update","product_id":"BTC-USD","changes":[["sell","9177.99","0.01490000"]],"time":"2020-06-30T19:23:43.268095Z"}
{"type":"l2update","product_id":"BTC-USD","changes":[["sell","9138.42","0.00000000"]],"time":"2020-06-30T19:23:43.440687Z"}
{"type":"l2update","product_id":"BTC-USD","changes":[["sell","9183.30","0.00000000"]],"time":"2020-06-30T19:23:43.473630Z"}
{"type":"heartbeat","last_trade_id":0,"product_id":"BTC-USD","sequence":180759436,"time":"2020-06-30T19:23:43.735105Z"}
{"type":"l2update","product_id":"BTC-USD","changes":[["buy","100.00","114.95500000"]],"time":"2020-06-30T19:23:44.039174Z"}
{"type":"l2update","product_id":"BTC-USD","changes":[["buy","100.00","114.94500000"]],"time":"2020-06-30T19:23:44.045680Z"}
{"type":"l2update","product_id":"BTC-USD","changes":[["sell","9178.32","0.05310000"]],"time":"2020-06-30T19:23:44.365759Z"}
{"type":"heartbeat","last_trade_id":0,"product_id":"BTC-USD","sequence":180759441,"time":"2020-06-30T19:23:44.735107Z"}
{"type":"l2update","product_id":"BTC-USD","changes":[["sell","9140.55","0.00000000"]],"time":"2020-06-30T19:23:44.800582Z"}
{"type":"l2update","product_id":"BTC-USD","changes":[["sell","9167.05","0.00000000"]],"time":"2020-06-30T19:23:44.822258Z"}
{"type":"l2update","product_id":"BTC-USD","changes":[["sell","9134.77","2997.50420000"]],"time":"2020-06-30T19:23:45.319077Z"}
{"type":"heartbeat","last_trade_id":0,"product_id":"BTC-USD","sequence":180759446,"time":"2020-06-30T19:23:45.735109Z"}
{"type":"l2update","product_id":"BTC-USD","changes":[["sell","9134.77","2997.43850000"]],"time":"2020-06-30T19:23:46.727273Z"}
{"type":"heartbeat","last_trade_id":0,"product_id":"BTC-USD","sequence":180759449,"time":"2020-06-30T19:23:46.735120Z"}
{"type":"l2update","product_id":"BTC-USD","changes":[["sell","9134.77","2997.37280000"]],"time":"2020-06-30T19:23:47.053568Z"}
{"type":"l2update","product_id":"BTC-USD","changes":[["buy","9131.84","0.00000000"]],"time":"2020-06-30T19:23:47.488816Z"}
{"type":"heartbeat","last_trade_id":0,"product_id":"BTC-USD","sequence":180759453,"time":"2020-06-30T19:23:47.735111Z"}
{"type":"l2update","product_id":"BTC-USD","changes":[["sell","9134.77","2997.30710000"]],"time":"2020-06-30T19:23:47.872624Z"}
{"type":"l2update","product_id":"BTC-USD","changes":[["sell","9179.03","0.19300000"]],"time":"2020-06-30T19:23:48.424528Z"}
{"type":"heartbeat","last_trade_id":0,"product_id":"BTC-USD","sequence":180759458,"time":"2020-06-30T19:23:48.735117Z"}
{"type":"l2update","product_id":"BTC-USD","changes":[["sell","9151.23","0.01760000"]],"time":"2020-06-30T19:23:49.684701Z"}
{"type":"heartbeat","last_trade_id":0,"product_id":"BTC-USD","sequence":180759460,"time":"2020-06-30T19:23:49.735112Z"}
{"type":"l2update","product_id":"BTC-USD","changes":[["sell","9178.32","0.00000000"]],"time":"2020-06-30T19:23:50.158583Z"}
{"type":"heartbeat","last_trade_id":0,"product_id":"BTC-USD","sequence":180759461,"time":"2020-06-30T19:23:50.735112Z"}
{"type":"l2update","product_id":"BTC-USD","changes":[["buy","9131.88","0.04000000"]],"time":"2020-06-30T19:23:50.833900Z"}
{"type":"l2update","product_id":"BTC-USD","changes":[["buy","9097.62","0.00000000"]],"time":"2020-06-30T19:23:51.284986Z"}
{"type":"l2update","product_id":"BTC-USD","changes":[["sell","9178.89","0.06880000"]],"time":"2020-06-30T19:23:51.501448Z"}
{"type":"heartbeat","last_trade_id":0,"product_id":"BTC-USD","sequence":180759466,"time":"2020-06-30T19:23:51.735110Z"}
{"type":"l2update","product_id":"BTC-USD","changes":[["sell","9177.99","0.00000000"]],"time":"2020-06-30T19:23:51.949889Z"}
{"type":"l2update","product_id":"BTC-USD","changes":[["sell","9177.79","0.06880000"]],"time":"2020-06-30T19:23:52.356624Z"}
{"type":"l2update","product_id":"BTC-USD","changes":[["sell","9134.77","2997.25710000"]],"time":"2020-06-30T19:23:52.639576Z"}
{"type":"heartbeat","last_trade_id":0,"product_id":"BTC-USD","sequence":180759472,"time":"2020-06-30T19:23:52.735119Z"}
{"type":"l2update","product_id":"BTC-USD","changes":[["sell","9178.89","0.00000000"]],"time":"2020-06-30T19:23:52.822746Z"}
{"type":"l2update","product_id":"BTC-USD","changes":[["sell","9178.97","0.10580000"]],"time":"2020-06-30T19:23:52.908358Z"}
{"type":"l2update","product_id":"BTC-USD","changes":[["sell","9134.77","2997.19140000"]],"time":"2020-06-30T19:23:53.199432Z"}
{"type":"l2update","product_id":"BTC-USD","changes":[["sell","9181.51","0.00000000"]],"time":"2020-06-30T19:23:53.414769Z"}
{"type":"l2update","product_id":"BTC-USD","changes":[["sell","9136.84","0.55270000"]],"time":"2020-06-30T19:23:53.740891Z"}
{"type":"heartbeat","last_trade_id":0,"product_id":"BTC-USD","sequence":180759481,"time":"2020-06-30T19:23:53.735115Z"}
{"type":"l2update","product_id":"BTC-USD","changes":[["sell","9134.77","2997.14140000"]],"time":"2020-06-30T19:23:54.043127Z"}
{"type":"heartbeat","last_trade_id":0,"product_id":"BTC-USD","sequence":180759484,"time":"2020-06-30T19:23:54.735114Z"}
{"type":"l2update","product_id":"BTC-USD","changes":[["sell","9134.77","2997.07570000"]],"time":"2020-06-30T19:23:55.205884Z"}
{"type":"l2update","product_id":"BTC-USD","changes":[["buy","9133.51","3.00000000"]],"time":"2020-06-30T19:23:55.476756Z"}
{"type":"l2update","product_id":"BTC-USD","changes":[["buy","9117.86","0.00000000"]],"time":"2020-06-30T19:23:55.663156Z"}
{"type":"heartbeat","last_trade_id":0,"product_id":"BTC-USD","sequence":180759490,"time":"2020-06-30T19:23:55.735110Z"}
{"type":"l2update","product_id":"BTC-USD","changes":[["sell","9134.77","2997.01000000"]],"time":"2020-06-30T19:23:55.763104Z"}
{"type":"l2update","product_id":"BTC-USD","changes":[["buy","9133.27","0.00000000"]],"time":"2020-06-30T19:23:55.924543Z"}
{"type":"l2update","product_id":"BTC-USD","changes":[["sell","9178.14","0.06080000"]],"time":"2020-06-30T19:23:56.047511Z"}
{"type":"l2update","product_id":"BTC-USD","changes":[["sell","9134.77","2996.96000000"]],"time":"2020-06-30T19:23:56.324016Z"}
{"type":"l2update","product_id":"BTC-USD","changes":[["sell","9136.84","0.00000000"]],"time":"2020-06-30T19:23:56.475887Z"}
{"type":"heartbeat","last_trade_id":0,"product_id":"BTC-USD","sequence":180759500,"time":"2020-06-30T19:23:56.735116Z"}
{"type":"l2update","product_id":"BTC-USD","changes":[["sell","9134.77","2996.89430000"]],"time":"2020-06-30T19:23:56.888233Z"}
{"type":"l2update","product_id":"BTC-USD","changes":[["sell","9137.32","0.16350000"]],"time":"2020-06-30T19:23:57.150750Z"}
{"type":"l2update","product_id":"BTC-USD","changes":[["sell","9134.77","2996.82860000"]],"time":"2020-06-30T19:23:57.433200Z"}
{"type":"l2update","product_id":"BTC-USD","changes":[["buy","9103.47","0.02070000"]],"time":"2020-06-30T19:23:57.704848Z"}
{"type":"heartbeat","last_trade_id":0,"product_id":"BTC-USD","sequence":180759510,"time":"2020-06-30T19:23:57.735116Z"}
{"type":"l2update","product_id":"BTC-USD","changes":[["sell","9178.33","0.01490000"]],"time":"2020-06-30T19:23:57.991984Z"}
{"type":"l2update","product_id":"BTC-USD","changes":[["sell","9178.97","0.00000000"]],"time":"2020-06-30T19:23:58.416635Z"}
{"type":"l2update","product_id":"BTC-USD","changes":[["sell","9178.14","0.00000000"]],"time":"2020-06-30T19:23:58.430001Z"}
{"type":"l2update","product_id":"BTC-USD","changes":[["sell","9178.60","0.00000000"]],"time":"2020-06-30T19:23:58.440382Z"}
{"type":"heartbeat","last_trade_id":0,"product_id":"BTC-USD","sequence":180759515,"time":"2020-06-30T19:23:58.735113Z"}
{"type":"l2update","product_id":"BTC-USD","changes":[["buy","9039.22","0.00200000"]],"time":"2020-06-30T19:23:58.839971Z"}
{"type":"l2update","product_id":"BTC-USD","changes":[["sell","9151.23","0.00000000"]],"time":"2020-06-30T19:23:58.995571Z"}
{"type":"l2update","product_id":"BTC-USD","changes":[["buy","100.00","114.95500000"]],"time":"2020-06-30T19:23:59.044461Z"}
{"type":"l2update","product_id":"BTC-USD","changes":[["buy","100.00","114.94500000"]],"time":"2020-06-30T19:23:59.051712Z"}
{"type":"l2update","product_id":"BTC-USD","changes":[["sell","9178.41","0.03830000"]],"time":"2020-06-30T19:23:59.117670Z"}
{"type":"l2update","product_id":"BTC-USD","changes":[["sell","9136.84","4.58180000"]],"time":"2020-06-30T19:23:59.713616Z"}
{"type":"heartbeat","last_trade_id":0,"product_id":"BTC-USD","sequence":180759525,"time":"2020-06-30T19:23:59.735125Z"}
{"type":"l2update","product_id":"BTC-USD","changes":[["sell","9179.03","0.09650000"]],"time":"2020-06-30T19:24:00.161273Z"}
{"type":"l2update","product_id":"BTC-USD","changes":[["sell","9179.18","0.00000000"]],"time":"2020-06-30T19:24:00.161401Z"}
{"type":"heartbeat","last_trade_id":0,"product_id":"BTC-USD","sequence":180759527,"time":"2020-06-30T19:24:00.735114Z"}
{"type":"l2update","product_id":"BTC-USD","changes":[["buy","9039.22","0.00000000"]],"time":"2020-06-30T19:24:01.015033Z"}
{"type":"l2update","product_id":"BTC-USD","changes":[["buy","9098.53","0.07370000"]],"time":"2020-06-30T19:24:01.592192Z"}
{"type":"l2update","product_id":"BTC-USD","changes":[["sell","9177.49","0.02220000"]],"time":"2020-06-30T19:24:01.634457Z"}
{"type":"heartbeat","last_trade_id":0,"product_id":"BTC-USD","sequence":180759532,"time":"2020-06-30T19:24:01.735109Z"}
{"type":"l2update","product_id":"BTC-USD","changes":[["buy","9134.31","0.00000000"]],"time":"2020-06-30T19:24:01.848403Z"}
{"type":"l2update","product_id":"BTC-USD","changes":[["sell","9155.95","2.60650000"]],"time":"2020-06-30T19:24:01.889308Z"}
{"type":"l2update","product_id":"BTC-USD","changes":[["sell","9179.03","0.00000000"]],"time":"2020-06-30T19:24:02.124704Z"}
{"type":"l2update","product_id":"BTC-USD","changes":[["sell","9177.79","0.00000000"]],"time":"2020-06-30T19:24:02.187655Z"}
{"type":"l2update","product_id":"BTC-USD","changes":[["sell","9136.84","0.00000000"]],"time":"2020-06-30T19:24:02.630500Z"}
{"type":"heartbeat","last_trade_id":0,"product_id":"BTC-USD","sequence":180759538,"time":"2020-06-30T19:24:02.735117Z"}
{"type":"l2update","product_id":"BTC-USD","changes":[["sell","9134.77","2996.76290000"]],"time":"2020-06-30T19:24:03.292547Z"}
{"type":"l2update","product_id":"BTC-USD","changes":[["sell","9134.77","2996.71290000"]],"time":"2020-06-30T19:24:03.574771Z"}
{"type":"heartbeat","last_trade_id":0,"product_id":"BTC-USD","sequence":180759544,"time":"2020-06-30T19:24:03.735112Z"}
{"type":"l2update","product_id":"BTC-USD","changes":[["buy","9127.79","0.00000000"]],"time":"2020-06-30T19:24:04.014177Z"}
{"type":"heartbeat","last_trade_id":0,"product_id":"BTC-USD","sequence":180759545,"time":"2020-06-30T19:24:04.735067Z"}
{"type":"l2update","product_id":"BTC-USD","changes":[["sell","9134.77","2996.64720000"]],"time":"2020-06-30T19:24:05.050230Z"}
{"type":"l2update","product_id":"BTC-USD","changes":[["sell","9134.77","2996.58150000"]],"time":"2020-06-30T19:24:05.610033Z"}
{"type":"heartbeat","last_trade_id":0,"product_id":"BTC-USD","sequence":180759551,"time":"2020-06-30T19:24:05.735039Z"}
{"type":"l2update","product_id":"BTC-USD","changes":[["buy","9130.66","0.32860000"]],"time":"2020-06-30T19:24:06.436113Z"}
{"type":"l2update","product_id":"BTC-USD","changes":[["sell","9134.77","2996.51580000"]],"time":"2020-06-30T19:24:06.728361Z"}
{"type":"heartbeat","last_trade_id":0,"product_id":"BTC-USD","sequence":180759556,"time":"2020-06-30T19:24:06.735049Z"}
{"type":"l2update","product_id":"BTC-USD","changes":[["buy","8938.18","0.00000000"]],"time":"2020-06-30T19:24:07.135682Z"}
{"type":"l2update","product_id":"BTC-USD","changes":[["sell","9134.77","2996.45010000"]],"time":"2020-06-30T19:24:07.313371Z"}
{"type":"l2update","product_id":"BTC-USD","changes":[["sell","9159.30","0.10890000"]],"time":"2020-06-30T19:24:07.586312Z"}
{"type":"heartbeat","last_trade_id":0,"product_id":"BTC-USD","sequence":180759562,"time":"2020-06-30T19:24:07.735096Z"}
{"type":"l2update","product_id":"BTC-USD","changes":[["sell","9155.95","0.00000000"]],"time":"2020-06-30T19:24:08.054224Z"}
{"type":"l2update","product_id":"BTC-USD","changes":[["sell","9134.77","2996.38440000"]],"time":"2020-06-30T19:24:08.500346Z"}
{"type":"heartbeat","last_trade_id":0,"product_id":"BTC-USD","sequence":180759566,"time":"2020-06-30T19:24:08.735113Z"}
{"type":"l2update","product_id":"BTC-USD","changes":[["sell","9134.77","2996.33440000"]],"time":"2020-06-30T19:24:09.306623Z"}
{"type":"heartbeat","last_trade_id":0,"product_id":"BTC-USD","sequence":180759569,"time":"2020-06-30T19:24:09.735119Z"}
{"type":"l2update","product_id":"BTC-USD","changes":[["buy","9130.66","0.00000000"]],"time":"2020-06-30T19:24:09.788394Z"}
{"type":"l2update","product_id":"BTC-USD","changes":[["sell","9134.77","2996.28440000"]],"time":"2020-06-30T19:24:10.133601Z"}
{"type":"l2update","product_id":"BTC-USD","changes":[["buy","9134.75","3009.99800000"]],"time":"2020-06-30T19:24:10.676269Z"}
{"type":"heartbeat","last_trade_id":0,"product_id":"BTC-USD","sequence":180759576,"time":"2020-06-30T19:24:10.735054Z"}
{"type":"l2update","product_id":"BTC-USD","changes":[["sell","9178.39","0.02220000"]],"time":"2020-06-30T19:24:11.010514Z"}
{"type":"l2update","product_id":"BTC-USD","changes":[["sell","9179.47","0.00000000"]],"time":"2020-06-30T19:24:11.455686Z"}
{"type":"heartbeat","last_trade_id":0,"product_id":"BTC-USD","sequence":180759579,"time":"2020-06-30T19:24:11.735069Z"}
{"type":"l2update","product_id":"BTC-USD","changes":[["sell","9134.77","2996.21870000"]],"time":"2020-06-30T19:24:12.657272Z"}
{"type":"heartbeat","last_trade_id":0,"product_id":"BTC-USD","sequence":180759582,"time":"2020-06-30T19:24:12.735069Z"}
{"type":"l2update","product_id":"BTC-USD","changes":[["sell","9134.77","2996.15300000"]],"time":"2020-06-30T19:24:12.952303Z"}
{"type":"l2update","product_id":"BTC-USD","changes":[["buy","9103.47","0.00000000"]],"time":"2020-06-30T19:24:13.117278Z"}
{"type":"l2update","product_id":"BTC-USD","changes":[["sell","9178.28","0.02220000"]],"time":"2020-06-30T19:24:13.231042Z"}
{"type":"heartbeat","last_trade_id":0,"product_id":"BTC-USD","sequence":180759588,"time":"2020-06-30T19:24:13.735092Z"}
{"type":"l2update","product_id":"BTC-USD","changes":[["sell","9178.26","0.02220000"]],"time":"2020-06-30T19:24:13.788426Z"}
{"type":"l2update","product_id":"BTC-USD","changes":[["buy","100.00","114.95500000"]],"time":"2020-06-30T19:24:14.135387Z"}
{"type":"l2update","product_id":"BTC-USD","changes":[["buy","100.00","114.94500000"]],"time":"2020-06-30T19:24:14.142229Z"}
{"type":"l2update","product_id":"BTC-USD","changes":[["sell","9159.30","0.00000000"]],"time":"2020-06-30T19:24:14.266257Z"}
{"type":"l2update","product_id":"BTC-USD","changes":[["sell","9178.23","0.02220000"]],"time":"2020-06-30T19:24:14.351997Z"}
{"type":"heartbeat","last_trade_id":0,"product_id":"BTC-USD","sequence":180759596,"time":"2020-06-30T19:24:14.735112Z"}
{"type":"l2update","product_id":"BTC-USD","changes":[["sell","9178.21","0.02220000"]],"time":"2020-06-30T19:24:14.893007Z"}
{"type":"l2update","product_id":"BTC-USD","changes":[["sell","9178.23","0.00000000"]],"time":"2020-06-30T19:24:15.323202Z"}
{"type":"l2update","product_id":"BTC-USD","changes":[["sell","9178.26","0.00000000"]],"time":"2020-06-30T19:24:15.327215Z"}
{"type":"heartbeat","last_trade_id":0,"product_id":"BTC-USD","sequence":180759600,"time":"2020-06-30T19:24:15.735027Z"}
{"type":"l2update","product_id":"BTC-USD","changes":[["sell","9134.77","2996.08730000"]],"time":"2020-06-30T19:24:15.752290Z"}
{"type":"l2update","product_id":"BTC-USD","changes":[["buy","9131.88","0.00000000"]],"time":"2020-06-30T19:24:15.848142Z"}
{"type":"l2update","product_id":"BTC-USD","changes":[["buy","9106.22","0.01000000"]],"time":"2020-06-30T19:24:16.021105Z"}
{"type":"l2update","product_id":"BTC-USD","changes":[["sell","9134.77","2996.02160000"]],"time":"2020-06-30T19:24:16.650389Z"}
{"type":"heartbeat","last_trade_id":0,"product_id":"BTC-USD","sequence":180759609,"time":"2020-06-30T19:24:16.735171Z"}
{"type":"l2update","product_id":"BTC-USD","changes":[["sell","9178.10","0.01490000"]],"time":"2020-06-30T19:24:17.187817Z"}
{"type":"l2update","product_id":"BTC-USD","changes":[["sell","9134.77","2995.95590000"]],"time":"2020-06-30T19:24:17.475791Z"}
{"type":"l2update","product_id":"BTC-USD","changes":[["sell","9178.28","0.00000000"]],"time":"2020-06-30T19:24:17.636539Z"}
{"type":"heartbeat","last_trade_id":0,"product_id":"BTC-USD","sequence":180759615,"time":"2020-06-30T19:24:17.735118Z"}
{"type":"l2update","product_id":"BTC-USD","changes":[["sell","9134.77","2995.89020000"]],"time":"2020-06-30T19:24:17.788084Z"}
{"type":"l2update","product_id":"BTC-USD","changes":[["sell","9134.77","2995.27420000"]],"time":"2020-06-30T19:24:18.080746Z"}
{"type":"l2update","product_id":"BTC-USD","changes":[["sell","9134.77","2995.22420000"]],"time":"2020-06-30T19:24:18.474505Z"}
{"type":"heartbeat","last_trade_id":0,"product_id":"BTC-USD","sequence":180759624,"time":"2020-06-30T19:24:18.735114Z"}
{"type":"l2update","product_id":"BTC-USD","changes":[["sell","9134.77","2995.15850000"]],"time":"2020-06-30T19:24:18.940250Z"}
{"type":"heartbeat","last_trade_id":0,"product_id":"BTC-USD","sequence":180759627,"time":"2020-06-30T19:24:19.735055Z"}
{"type":"l2update","product_id":"BTC-USD","changes":[["sell","9134.77","2995.09280000"]],"time":"2020-06-30T19:24:19.838062Z"}
{"type":"l2update","product_id":"BTC-USD","changes":[["sell","9134.77","2995.02710000"]],"time":"2020-06-30T19:24:20.128311Z"}
{"type":"l2update","product_id":"BTC-USD","changes":[["buy","9109.35","0.03250000"]],"time":"2020-06-30T19:24:20.409713Z"}
{"type":"heartbeat","last_trade_id":0,"product_id":"BTC-USD","sequence":180759635,"time":"2020-06-30T19:24:20.735119Z"}
{"type":"l2update","product_id":"BTC-USD","changes":[["buy","9108.69","0.01000000"]],"time":"2020-06-30T19:24:20.970582Z"}
{"type":"l2update","product_id":"BTC-USD","changes":[["buy","9110.18","0.03250000"]],"time":"2020-06-30T19:24:21.245033Z"}
{"type":"heartbeat","last_trade_id":0,"product_id":"BTC-USD","sequence":180759639,"time":"2020-06-30T19:24:21.735120Z"}
{"type":"l2update","product_id":"BTC-USD","changes":[["sell","9134.77","2994.96140000"]],"time":"2020-06-30T19:24:22.156111Z"}
{"type":"l2update","product_id":"BTC-USD","changes":[["sell","9134.77","2994.91140000"]],"time":"2020-06-30T19:24:22.707152Z"}
{"type":"heartbeat","last_trade_id":0,"product_id":"BTC-USD","sequence":180759645,"time":"2020-06-30T19:24:22.735111Z"}
{"type":"l2update","product_id":"BTC-USD","changes":[["buy","9106.62","0.50000000"]],"time":"2020-06-30T19:24:23.345773Z"}
{"type":"heartbeat","last_trade_id":0,"product_id":"BTC-USD","sequence":180759647,"time":"2020-06-30T19:24:23.735069Z"}
{"type":"l2update","product_id":"BTC-USD","changes":[["sell","9140.41","0.37040000"]],"time":"2020-06-30T19:24:23.923214Z"}
{"type":"l2update","product_id":"BTC-USD","changes":[["sell","9145.17","0.00000000"]],"time":"2020-06-30T19:24:24.352593Z"}
{"type":"heartbeat","last_trade_id":0,"product_id":"BTC-USD","sequence":180759650,"time":"2020-06-30T19:24:24.735089Z"}
{"type":"l2update","product_id":"BTC-USD","changes":[["sell","9134.77","2994.86140000"]],"time":"2020-06-30T19:24:24.849666Z"}
{"type":"heartbeat","last_trade_id":0,"product_id":"BTC-USD","sequence":180759653,"time":"2020-06-30T19:24:25.735115Z"}
{"type":"l2update","product_id":"BTC-USD","changes":[["sell","9151.23","0.06760000"]],"time":"2020-06-30T19:24:25.960078Z"}
{"type":"l2update","product_id":"BTC-USD","changes":[["sell","9134.77","2994.81140000"]],"time":"2020-06-30T19:24:26.511182Z"}
{"type":"heartbeat","last_trade_id":0,"product_id":"BTC-USD","sequence":180759658,"time":"2020-06-30T19:24:26.735115Z"}
{"type":"heartbeat","last_trade_id":0,"product_id":"BTC-USD","sequence":180759658,"time":"2020-06-30T19:24:27.735110Z"}
{"type":"l2update","product_id":"BTC-USD","changes":[["buy","9131.28","0.75000000"]],"time":"2020-06-30T19:24:28.334877Z"}
{"type":"l2update","product_id":"BTC-USD","changes":[["sell","9136.84","4.82620000"]],"time":"2020-06-30T19:24:28.613332Z"}
{"type":"heartbeat","last_trade_id":0,"product_id":"BTC-USD","sequence":180759662,"time":"2020-06-30T19:24:28.735117Z"}
{"type":"l2update","product_id":"BTC-USD","changes":[["buy","9106.62","0.00000000"]],"time":"2020-06-30T19:24:28.833670Z"}
{"type":"l2update","product_id":"BTC-USD","changes":[["sell","9140.41","0.00000000"]],"time":"2020-06-30T19:24:29.068048Z"}
{"type":"l2update","product_id":"BTC-USD","changes":[["buy","100.00","114.95500000"]],"time":"2020-06-30T19:24:29.160652Z"}
{"type":"l2update","product_id":"BTC-USD","changes":[["buy","100.00","114.94500000"]],"time":"2020-06-30T19:24:29.169755Z"}
{"type":"heartbeat","last_trade_id":0,"product_id":"BTC-USD","sequence":180759667,"time":"2020-06-30T19:24:29.735116Z"}
{"type":"heartbeat","last_trade_id":0,"product_id":"BTC-USD","sequence":180759667,"time":"2020-06-30T19:24:30.735108Z"}
{"type":"heartbeat","last_trade_id":0,"product_id":"BTC-USD","sequence":180759667,"time":"2020-06-30T19:24:31.735112Z"}
{"type":"l2update","product_id":"BTC-USD","changes":[["sell","9134.77","2994.76140000"]],"time":"2020-06-30T19:24:31.860153Z"}
{"type":"l2update","product_id":"BTC-USD","changes":[["buy","9110.18","0.00000000"]],"time":"2020-06-30T19:24:32.287821Z"}
{"type":"l2update","product_id":"BTC-USD","changes":[["buy","9106.22","0.00000000"]],"time":"2020-06-30T19:24:32.291832Z"}
{"type":"l2update","product_id":"BTC-USD","changes":[["sell","9134.77","2994.69570000"]],"time":"2020-06-30T19:24:32.421413Z"}
{"type":"heartbeat","last_trade_id":0,"product_id":"BTC-USD","sequence":180759675,"time":"2020-06-30T19:24:32.735118Z"}
{"type":"l2update","product_id":"BTC-USD","changes":[["sell","9175.49","0.03700000"]],"time":"2020-06-30T19:24:33.287380Z"}
{"type":"l2update","product_id":"BTC-USD","changes":[["sell","9134.77","2994.63000000"]],"time":"2020-06-30T19:24:33.577700Z"}
{"type":"l2update","product_id":"BTC-USD","changes":[["sell","9178.10","0.00000000"]],"time":"2020-06-30T19:24:33.694763Z"}
{"type":"heartbeat","last_trade_id":0,"product_id":"BTC-USD","sequence":180759681,"time":"2020-06-30T19:24:33.735109Z"}
{"type":"l2update","product_id":"BTC-USD","changes":[["buy","9131.28","0.00000000"]],"time":"2020-06-30T19:24:34.012723Z"}
{"type":"l2update","product_id":"BTC-USD","changes":[["sell","9280.52","0.00300000"]],"time":"2020-06-30T19:24:34.402871Z"}
{"type":"l2update","product_id":"BTC-USD","changes":[["sell","9134.77","2994.56430000"]],"time":"2020-06-30T19:24:34.707969Z"}
{"type":"heartbeat","last_trade_id":0,"product_id":"BTC-USD","sequence":180759687,"time":"2020-06-30T19:24:34.735109Z"}
{"type":"l2update","product_id":"BTC-USD","changes":[["buy","9109.99","1.47720000"]],"time":"2020-06-30T19:24:35.005359Z"}
{"type":"heartbeat","last_trade_id":0,"product_id":"BTC-USD","sequence":180759689,"time":"2020-06-30T19:24:35.735109Z"}
{"type":"l2update","product_id":"BTC-USD","changes":[["buy","9111.00","0.03930000"]],"time":"2020-06-30T19:24:35.863056Z"}
{"type":"l2update","product_id":"BTC-USD","changes":[["buy","9133.41","0.75000000"]],"time":"2020-06-30T19:24:36.144199Z"}
{"type":"l2update","product_id":"BTC-USD","changes":[["sell","9175.90","0.10580000"]],"time":"2020-06-30T19:24:36.434173Z"}
{"type":"heartbeat","last_trade_id":0,"product_id":"BTC-USD","sequence":180759695,"time":"2020-06-30T19:24:36.735115Z"}
{"type":"l2update","product_id":"BTC-USD","changes":[["sell","9136.84","9.82860000"]],"time":"2020-06-30T19:24:36.750811Z"}
{"type":"l2update","product_id":"BTC-USD","changes":[["buy","8907.15","0.00000000"]],"time":"2020-06-30T19:24:37.251558Z"}
{"type":"l2update","product_id":"BTC-USD","changes":[["buy","9133.90","0.75000000"]],"time":"2020-06-30T19:24:37.349972Z"}
{"type":"l2update","product_id":"BTC-USD","changes":[["buy","8906.38","0.04491267"]],"time":"2020-06-30T19:24:37.456585Z"}
{"type":"l2update","product_id":"BTC-USD","changes":[["sell","9423.02","0.00000000"]],"time":"2020-06-30T19:24:37.657893Z"}
{"type":"heartbeat","last_trade_id":0,"product_id":"BTC-USD","sequence":180759703,"time":"2020-06-30T19:24:37.735109Z"}
{"type":"l2update","product_id":"BTC-USD","changes":[["sell","9423.84","0.00569155"]],"time":"2020-06-30T19:24:37.845896Z"}
{"type":"l2update","product_id":"BTC-USD","changes":[["sell","9134.77","2994.51430000"]],"time":"2020-06-30T19:24:38.491410Z"}
{"type":"l2update","product_id":"BTC-USD","changes":[["sell","9178.33","0.00000000"]],"time":"2020-06-30T19:24:38.727785Z"}
{"type":"heartbeat","last_trade_id":0,"product_id":"BTC-USD","sequence":180759709,"time":"2020-06-30T19:24:38.735113Z"}
{"type":"l2update","product_id":"BTC-USD","changes":[["sell","9134.77","2994.44860000"]],"time":"2020-06-30T19:24:38.769407Z"}
{"type":"heartbeat","last_trade_id":0,"product_id":"BTC-USD","sequence":180759712,"time":"2020-06-30T19:24:39.735112Z"}
{"type":"l2update","product_id":"BTC-USD","changes":[["sell","9134.77","2994.38290000"]],"time":"2020-06-30T19:24:40.301770Z"}
{"type":"l2update","product_id":"BTC-USD","changes":[["buy","9133.90","0.00000000"]],"time":"2020-06-30T19:24:40.495375Z"}
{"type":"l2update","product_id":"BTC-USD","changes":[["sell","9134.77","2994.31720000"]],"time":"2020-06-30T19:24:40.576998Z"}
{"type":"heartbeat","last_trade_id":0,"product_id":"BTC-USD","sequence":180759719,"time":"2020-06-30T19:24:40.735108Z"}
{"type":"l2update","product_id":"BTC-USD","changes":[["sell","9177.05","0.01490000"]],"time":"2020-06-30T19:24:40.860484Z"}
{"type":"l2update","product_id":"BTC-USD","changes":[["sell","9177.04","0.02220000"]],"time":"2020-06-30T19:24:41.145294Z"}
{"type":"l2update","product_id":"BTC-USD","changes":[["sell","9178.21","0.00000000"]],"time":"2020-06-30T19:24:41.290864Z"}
{"type":"l2update","product_id":"BTC-USD","changes":[["buy","9128.61","0.02220000"]],"time":"2020-06-30T19:24:41.434022Z"}
{"type":"l2update","product_id":"BTC-USD","changes":[["sell","9134.77","2994.31620000"]],"time":"2020-06-30T19:24:41.463893Z"}
{"type":"l2update","product_id":"BTC-USD","changes":[["sell","9177.49","0.00000000"]],"time":"2020-06-30T19:24:41.581182Z"}
{"type":"l2update","product_id":"BTC-USD","changes":[["sell","9134.77","2994.26620000"]],"time":"2020-06-30T19:24:41.710258Z"}
{"type":"heartbeat","last_trade_id":0,"product_id":"BTC-USD","sequence":180759733,"time":"2020-06-30T19:24:41.735113Z"}
{"type":"l2update","product_id":"BTC-USD","changes":[["sell","9134.77","2994.20050000"]],"time":"2020-06-30T19:24:42.670561Z"}
{"type":"heartbeat","last_trade_id":0,"product_id":"BTC-USD","sequence":180759736,"time":"2020-06-30T19:24:42.735113Z"}
{"type":"l2update","product_id":"BTC-USD","changes":[["sell","9141.89","0.00670000"]],"time":"2020-06-30T19:24:42.981951Z"}
{"type":"l2update","product_id":"BTC-USD","changes":[["buy","9128.61","0.00000000"]],"time":"2020-06-30T19:24:43.185881Z"}
{"type":"l2update","product_id":"BTC-USD","changes":[["buy","9098.53","0.00000000"]],"time":"2020-06-30T19:24:43.235852Z"}
{"type":"heartbeat","last_trade_id":0,"product_id":"BTC-USD","sequence":180759740,"time":"2020-06-30T19:24:43.735112Z"}
{"type":"l2update","product_id":"BTC-USD","changes":[["buy","100.00","114.95500000"]],"time":"2020-06-30T19:24:44.019905Z"}
{"type":"l2update","product_id":"BTC-USD","changes":[["buy","100.00","114.94500000"]],"time":"2020-06-30T19:24:44.026020Z"}
{"type":"heartbeat","last_trade_id":0,"product_id":"BTC-USD","sequence":180759743,"time":"2020-06-30T19:24:44.735117Z"}
{"type":"l2update","product_id":"BTC-USD","changes":[["sell","9134.77","2993.38670000"]],"time":"2020-06-30T19:24:45.172235Z"}
{"type":"heartbeat","last_trade_id":0,"product_id":"BTC-USD","sequence":180759746,"time":"2020-06-30T19:24:45.735113Z"}
{"type":"l2update","product_id":"BTC-USD","changes":[["buy","9134.73","6024.83580000"]],"time":"2020-06-30T19:24:46.133152Z"}
{"type":"l2update","product_id":"BTC-USD","changes":[["sell","9164.98","2.40600000"]],"time":"2020-06-30T19:24:46.425854Z"}
{"type":"l2update","product_id":"BTC-USD","changes":[["buy","9133.51","0.00000000"]],"time":"2020-06-30T19:24:46.580748Z"}
{"type":"l2update","product_id":"BTC-USD","changes":[["sell","9161.39","1.50530000"]],"time":"2020-06-30T19:24:46.707453Z"}
{"type":"heartbeat","last_trade_id":0,"product_id":"BTC-USD","sequence":180759753,"time":"2020-06-30T19:24:46.735074Z"}
{"type":"l2update","product_id":"BTC-USD","changes":[["sell","9134.77","2993.32100000"]],"time":"2020-06-30T19:24:46.976407Z"}
{"type":"l2update","product_id":"BTC-USD","changes":[["sell","9134.77","2992.82100000"]],"time":"2020-06-30T19:24:47.267245Z"}
{"type":"heartbeat","last_trade_id":0,"product_id":"BTC-USD","sequence":180759759,"time":"2020-06-30T19:24:47.735077Z"}
{"type":"l2update","product_id":"BTC-USD","changes":[["sell","9165.00","5.00000000"]],"time":"2020-06-30T19:24:47.819099Z"}
{"type":"l2update","product_id":"BTC-USD","changes":[["sell","9178.39","0.00000000"]],"time":"2020-06-30T19:24:48.039716Z"}
{"type":"l2update","product_id":"BTC-USD","changes":[["sell","9178.41","0.00000000"]],"time":"2020-06-30T19:24:48.051130Z"}
{"type":"l2update","product_id":"BTC-USD","changes":[["buy","9132.30","0.81710000"]],"time":"2020-06-30T19:24:48.357726Z"}
{"type":"heartbeat","last_trade_id":0,"product_id":"BTC-USD","sequence":180759765,"time":"2020-06-30T19:24:48.735087Z"}
{"type":"l2update","product_id":"BTC-USD","changes":[["sell","9143.24","1.63140000"]],"time":"2020-06-30T19:24:48.966857Z"}
{"type":"l2update","product_id":"BTC-USD","changes":[["sell","9280.52","0.00000000"]],"time":"2020-06-30T19:24:49.394923Z"}
{"type":"heartbeat","last_trade_id":0,"product_id":"BTC-USD","sequence":180759768,"time":"2020-06-30T19:24:49.735112Z"}
{"type":"l2update","product_id":"BTC-USD","changes":[["sell","9176.76","0.01000000"]],"time":"2020-06-30T19:24:50.071669Z"}
{"type":"l2update","product_id":"BTC-USD","changes":[["sell","9134.77","2988.66050000"]],"time":"2020-06-30T19:24:50.361270Z"}
{"type":"l2update","product_id":"BTC-USD","changes":[["sell","9164.98","0.00000000"]],"time":"2020-06-30T19:24:50.545631Z"}
{"type":"heartbeat","last_trade_id":0,"product_id":"BTC-USD","sequence":180759774,"time":"2020-06-30T19:24:50.735083Z"}
{"type":"l2update","product_id":"BTC-USD","changes":[["sell","9134.77","2984.45000000"]],"time":"2020-06-30T19:24:50.935315Z"}
{"type":"l2update","product_id":"BTC-USD","changes":[["sell","9134.77","2984.40000000"]],"time":"2020-06-30T19:24:51.206854Z"}
{"type":"l2update","product_id":"BTC-USD","changes":[["buy","9132.30","0.00000000"]],"time":"2020-06-30T19:24:51.379161Z"}
{"type":"l2update","product_id":"BTC-USD","changes":[["buy","9134.73","6020.00000000"]],"time":"2020-06-30T19:24:51.382765Z"}
{"type":"heartbeat","last_trade_id":0,"product_id":"BTC-USD","sequence":180759782,"time":"2020-06-30T19:24:51.735094Z"}
{"type":"l2update","product_id":"BTC-USD","changes":[["buy","9113.47","0.02680000"]],"time":"2020-06-30T19:24:51.768408Z"}
{"type":"heartbeat","last_trade_id":0,"product_id":"BTC-USD","sequence":180759784,"time":"2020-06-30T19:24:52.735069Z"}
{"type":"l2update","product_id":"BTC-USD","changes":[["sell","9138.42","4.00000000"]],"time":"2020-06-30T19:24:53.197341Z"}
{"type":"l2update","product_id":"BTC-USD","changes":[["sell","9177.05","0.00000000"]],"time":"2020-06-30T19:24:53.647840Z"}
{"type":"heartbeat","last_trade_id":0,"product_id":"BTC-USD","sequence":180759787,"time":"2020-06-30T19:24:53.735048Z"}
{"type":"l2update","product_id":"BTC-USD","changes":[["buy","9112.64","0.02050000"]],"time":"2020-06-30T19:24:53.750949Z"}
{"type":"l2update","product_id":"BTC-USD","changes":[["sell","9176.44","0.01490000"]],"time":"2020-06-30T19:24:54.022161Z"}
{"type":"l2update","product_id":"BTC-USD","changes":[["buy","9108.69","0.00000000"]],"time":"2020-06-30T19:24:54.181013Z"}
{"type":"l2update","product_id":"BTC-USD","changes":[["buy","9133.41","0.00000000"]],"time":"2020-06-30T19:24:54.185262Z"}
{"type":"l2update","product_id":"BTC-USD","changes":[["sell","9177.04","0.00000000"]],"time":"2020-06-30T19:24:54.228039Z"}
{"type":"l2update","product_id":"BTC-USD","changes":[["buy","9116.70","0.09850000"]],"time":"2020-06-30T19:24:54.588448Z"}
{"type":"heartbeat","last_trade_id":0,"product_id":"BTC-USD","sequence":180759796,"time":"2020-06-30T19:24:54.735094Z"}
{"type":"l2update","product_id":"BTC-USD","changes":[["sell","9138.42","8.04420000"]],"time":"2020-06-30T19:24:55.179978Z"}
{"type":"l2update","product_id":"BTC-USD","changes":[["sell","9151.23","0.00000000"]],"time":"2020-06-30T19:24:55.379464Z"}
{"type":"l2update","product_id":"BTC-USD","changes":[["sell","9137.32","0.00000000"]],"time":"2020-06-30T19:24:55.386500Z"}
{"type":"l2update","product_id":"BTC-USD","changes":[["sell","9138.42","8.17040000"]],"time":"2020-06-30T19:24:55.462242Z"}
{"type":"l2update","product_id":"BTC-USD","changes":[["sell","9134.77","2983.90000000"]],"time":"2020-06-30T19:24:55.716937Z"}
{"type":"heartbeat","last_trade_id":0,"product_id":"BTC-USD","sequence":180759805,"time":"2020-06-30T19:24:55.735059Z"}
{"type":"l2update","product_id":"BTC-USD","changes":[["sell","9134.77","2978.98950000"]],"time":"2020-06-30T19:24:55.927972Z"}
{"type":"l2update","product_id":"BTC-USD","changes":[["sell","9175.49","0.00000000"]],"time":"2020-06-30T19:24:55.941798Z"}
{"type":"l2update","product_id":"BTC-USD","changes":[["buy","9130.18","0.06570000"]],"time":"2020-06-30T19:24:56.234656Z"}
{"type":"l2update","product_id":"BTC-USD","changes":[["sell","9176.34","0.01490000"]],"time":"2020-06-30T19:24:56.611046Z"}
{"type":"heartbeat","last_trade_id":0,"product_id":"BTC-USD","sequence":180759813,"time":"2020-06-30T19:24:56.735104Z"}
{"type":"l2update","product_id":"BTC-USD","changes":[["sell","9176.76","0.00000000"]],"time":"2020-06-30T19:24:57.022697Z"}
{"type":"l2update","product_id":"BTC-USD","changes":[["buy","9128.31","0.03060000"]],"time":"2020-06-30T19:24:57.514241Z"}
{"type":"heartbeat","last_trade_id":0,"product_id":"BTC-USD","sequence":180759816,"time":"2020-06-30T19:24:57.735118Z"}
{"type":"l2update","product_id":"BTC-USD","changes":[["sell","9176.42","0.01000000"]],"time":"2020-06-30T19:24:57.783628Z"}
{"type":"l2update","product_id":"BTC-USD","changes":[["sell","9176.44","0.00000000"]],"time":"2020-06-30T19:24:58.227641Z"}
{"type":"l2update","product_id":"BTC-USD","changes":[["buy","9130.19","0.06570000"]],"time":"2020-06-30T19:24:58.631802Z"}
{"type":"heartbeat","last_trade_id":0,"product_id":"BTC-USD","sequence":180759821,"time":"2020-06-30T19:24:58.735114Z"}
{"type":"l2update","product_id":"BTC-USD","changes":[["buy","9130.05","0.02220000"]],"time":"2020-06-30T19:24:58.938963Z"}
{"type":"l2update","product_id":"BTC-USD","changes":[["sell","9136.84","4.82620000"]],"time":"2020-06-30T19:24:58.955433Z"}
{"type":"l2update","product_id":"BTC-USD","changes":[["buy","100.00","114.95500000"]],"time":"2020-06-30T19:24:59.047292Z"}
{"type":"l2update","product_id":"BTC-USD","changes":[["buy","100.00","114.94500000"]],"time":"2020-06-30T19:24:59.054377Z"}
{"type":"l2update","product_id":"BTC-USD","changes":[["buy","9109.35","0.00000000"]],"time":"2020-06-30T19:24:59.085709Z"}
{"type":"l2update","product_id":"BTC-USD","changes":[["buy","9109.99","0.00000000"]],"time":"2020-06-30T19:24:59.090632Z"}
{"type":"heartbeat","last_trade_id":0,"product_id":"BTC-USD","sequence":180759829,"time":"2020-06-30T19:24:59.735113Z"}
{"type":"l2update","product_id":"BTC-USD","changes":[["sell","9165.77","1.48760000"]],"time":"2020-06-30T19:24:59.766880Z"}
{"type":"l2update","product_id":"BTC-USD","changes":[["buy","9130.13","0.06570000"]],"time":"2020-06-30T19:25:00.068965Z"}
{"type":"l2update","product_id":"BTC-USD","changes":[["sell","9141.89","0.00000000"]],"time":"2020-06-30T19:25:00.226519Z"}
{"type":"heartbeat","last_trade_id":0,"product_id":"BTC-USD","sequence":180759834,"time":"2020-06-30T19:25:00.735114Z"}
{"type":"heartbeat","last_trade_id":0,"product_id":"BTC-USD","sequence":180759834,"time":"2020-06-30T19:25:01.735059Z"}
{"type":"l2update","product_id":"BTC-USD","changes":[["buy","9104.73","0.07360000"]],"time":"2020-06-30T19:25:02.488692Z"}
{"type":"heartbeat","last_trade_id":0,"product_id":"BTC-USD","sequence":180759836,"time":"2020-06-30T19:25:02.735093Z"}
{"type":"l2update","product_id":"BTC-USD","changes":[["buy","9130.13","0.00000000"]],"time":"2020-06-30T19:25:03.006448Z"}
{"type":"l2update","product_id":"BTC-USD","changes":[["buy","9104.78","0.07360000"]],"time":"2020-06-30T19:25:03.085404Z"}
{"type":"heartbeat","last_trade_id":0,"product_id":"BTC-USD","sequence":180759839,"time":"2020-06-30T19:25:03.735114Z"}
{"type":"l2update","product_id":"BTC-USD","changes":[["sell","9134.77","2978.23950000"]],"time":"2020-06-30T19:25:03.779296Z"}
{"type":"l2update","product_id":"BTC-USD","changes":[["buy","9104.73","0.00000000"]],"time":"2020-06-30T19:25:03.860841Z"}
{"type":"l2update","product_id":"BTC-USD","changes":[["sell","9157.86","0.51450000"]],"time":"2020-06-30T19:25:03.936365Z"}
{"type":"l2update","product_id":"BTC-USD","changes":[["sell","9139.84","0.14390000"]],"time":"2020-06-30T19:25:04.528596Z"}
{"type":"heartbeat","last_trade_id":0,"product_id":"BTC-USD","sequence":180759847,"time":"2020-06-30T19:25:04.735113Z"}
{"type":"l2update","product_id":"BTC-USD","changes":[["sell","9161.39","0.00000000"]],"time":"2020-06-30T19:25:04.784641Z"}
{"type":"l2update","product_id":"BTC-USD","changes":[["sell","9138.42","4.12620000"]],"time":"2020-06-30T19:25:04.785886Z"}
{"type":"l2update","product_id":"BTC-USD","changes":[["buy","9104.97","0.03890000"]],"time":"2020-06-30T19:25:04.805723Z"}
{"type":"l2update","product_id":"BTC-USD","changes":[["sell","9144.62","0.00670000"]],"time":"2020-06-30T19:25:05.076171Z"}
{"type":"l2update","product_id":"BTC-USD","changes":[["buy","9103.91","0.10550000"]],"time":"2020-06-30T19:25:05.677837Z"}
{"type":"heartbeat","last_trade_id":0,"product_id":"BTC-USD","sequence":180759855,"time":"2020-06-30T19:25:05.735111Z"}
{"type":"l2update","product_id":"BTC-USD","changes":[["sell","9134.77","2978.13950000"]],"time":"2020-06-30T19:25:06.566094Z"}
{"type":"heartbeat","last_trade_id":0,"product_id":"BTC-USD","sequence":180759858,"time":"2020-06-30T19:25:06.735113Z"}
{"type":"l2update","product_id":"BTC-USD","changes":[["sell","9144.75","0.00670000"]],"time":"2020-06-30T19:25:07.226087Z"}
{"type":"l2update","product_id":"BTC-USD","changes":[["buy","9104.37","0.07360000"]],"time":"2020-06-30T19:25:07.505056Z"}
{"type":"l2update","product_id":"BTC-USD","changes":[["sell","9157.86","0.00000000"]],"time":"2020-06-30T19:25:07.705339Z"}
{"type":"heartbeat","last_trade_id":0,"product_id":"BTC-USD","sequence":180759863,"time":"2020-06-30T19:25:07.735071Z"}
{"type":"l2update","product_id":"BTC-USD","changes":[["sell","9134.77","2977.38950000"]],"time":"2020-06-30T19:25:07.794303Z"}
{"type":"l2update","product_id":"BTC-USD","changes":[["buy","9128.31","0.00000000"]],"time":"2020-06-30T19:25:07.965820Z"}
{"type":"heartbeat","last_trade_id":0,"product_id":"BTC-USD","sequence":180759867,"time":"2020-06-30T19:25:08.735100Z"}
{"type":"l2update","product_id":"BTC-USD","changes":[["sell","9134.77","2976.86450000"]],"time":"2020-06-30T19:25:08.901108Z"}
{"type":"heartbeat","last_trade_id":0,"product_id":"BTC-USD","sequence":180759870,"time":"2020-06-30T19:25:09.735116Z"}
{"type":"l2update","product_id":"BTC-USD","changes":[["buy","9114.70","0.01730000"]],"time":"2020-06-30T19:25:09.773587Z"}
{"type":"l2update","product_id":"BTC-USD","changes":[["buy","9103.75","0.10550000"]],"time":"2020-06-30T19:25:10.307453Z"}
{"type":"l2update","product_id":"BTC-USD","changes":[["buy","9112.23","0.01900000"]],"time":"2020-06-30T19:25:10.605241Z"}
{"type":"heartbeat","last_trade_id":0,"product_id":"BTC-USD","sequence":180759876,"time":"2020-06-30T19:25:10.735116Z"}
{"type":"l2update","product_id":"BTC-USD","changes":[["buy","9116.70","0.00000000"]],"time":"2020-06-30T19:25:10.983594Z"}
{"type":"l2update","product_id":"BTC-USD","changes":[["buy","9134.75","3009.99700000"]],"time":"2020-06-30T19:25:11.279608Z"}
{"type":"heartbeat","last_trade_id":0,"product_id":"BTC-USD","sequence":180759880,"time":"2020-06-30T19:25:11.735113Z"}
{"type":"l2update","product_id":"BTC-USD","changes":[["buy","9041.50","0.00200000"]],"time":"2020-06-30T19:25:12.264586Z"}
{"type":"l2update","product_id":"BTC-USD","changes":[["buy","8950.18","0.01510000"]],"time":"2020-06-30T19:25:12.546532Z"}
{"type":"l2update","product_id":"BTC-USD","changes":[["buy","9112.64","0.00000000"]],"time":"2020-06-30T19:25:12.706683Z"}
{"type":"l2update","product_id":"BTC-USD","changes":[["buy","9113.47","0.00000000"]],"time":"2020-06-30T19:25:12.742834Z"}
{"type":"heartbeat","last_trade_id":0,"product_id":"BTC-USD","sequence":180759886,"time":"2020-06-30T19:25:12.735112Z"}
{"type":"l2update","product_id":"BTC-USD","changes":[["sell","9175.64","0.02220000"]],"time":"2020-06-30T19:25:12.815278Z"}
{"type":"l2update","product_id":"BTC-USD","changes":[["sell","9144.62","0.00000000"]],"time":"2020-06-30T19:25:13.281218Z"}
{"type":"l2update","product_id":"BTC-USD","changes":[["sell","9175.90","0.00000000"]],"time":"2020-06-30T19:25:13.283043Z"}
{"type":"l2update","product_id":"BTC-USD","changes":[["sell","9176.42","0.00000000"]],"time":"2020-06-30T19:25:13.284192Z"}
{"type":"l2update","product_id":"BTC-USD","changes":[["sell","9143.24","0.00000000"]],"time":"2020-06-30T19:25:13.286451Z"}
{"type":"l2update","product_id":"BTC-USD","changes":[["buy","9128.22","0.03060000"]],"time":"2020-06-30T19:25:13.382966Z"}
{"type":"l2update","product_id":"BTC-USD","changes":[["buy","9103.75","0.00000000"]],"time":"2020-06-30T19:25:13.593173Z"}
{"type":"l2update","product_id":"BTC-USD","changes":[["buy","9104.37","0.00000000"]],"time":"2020-06-30T19:25:13.595206Z"}
{"type":"heartbeat","last_trade_id":0,"product_id":"BTC-USD","sequence":180759896,"time":"2020-06-30T19:25:13.735116Z"}
{"type":"l2update","product_id":"BTC-USD","changes":[["buy","100.00","114.95500000"]],"time":"2020-06-30T19:25:14.056006Z"}
{"type":"l2update","product_id":"BTC-USD","changes":[["buy","100.00","114.94500000"]],"time":"2020-06-30T19:25:14.063888Z"}
{"type":"l2update","product_id":"BTC-USD","changes":[["buy","9128.27","0.06570000"]],"time":"2020-06-30T19:25:14.226440Z"}
{"type":"heartbeat","last_trade_id":0,"product_id":"BTC-USD","sequence":180759901,"time":"2020-06-30T19:25:14.735113Z"}
{"type":"l2update","product_id":"BTC-USD","changes":[["buy","9128.27","0.00000000"]],"time":"2020-06-30T19:25:15.315184Z"}
{"type":"heartbeat","last_trade_id":0,"product_id":"BTC-USD","sequence":180759902,"time":"2020-06-30T19:25:15.735115Z"}
{"type":"l2update","product_id":"BTC-USD","changes":[["buy","9104.13","0.03890000"]],"time":"2020-06-30T19:25:16.047161Z"}
{"type":"l2update","product_id":"BTC-USD","changes":[["sell","9175.64","0.03220000"]],"time":"2020-06-30T19:25:16.291614Z"}
{"type":"l2update","product_id":"BTC-USD","changes":[["sell","9139.84","0.00000000"]],"time":"2020-06-30T19:25:16.499669Z"}
{"type":"l2update","product_id":"BTC-USD","changes":[["sell","9165.77","0.00000000"]],"time":"2020-06-30T19:25:16.572391Z"}
{"type":"heartbeat","last_trade_id":0,"product_id":"BTC-USD","sequence":180759908,"time":"2020-06-30T19:25:16.735112Z"}
{"type":"l2update","product_id":"BTC-USD","changes":[["buy","9126.32","0.02220000"]],"time":"2020-06-30T19:25:17.112178Z"}
{"type":"heartbeat","last_trade_id":0,"product_id":"BTC-USD","sequence":180759910,"time":"2020-06-30T19:25:17.735113Z"}
{"type":"l2update","product_id":"BTC-USD","changes":[["sell","9134.77","2971.78650000"]],"time":"2020-06-30T19:25:17.995752Z"}
{"type":"l2update","product_id":"BTC-USD","changes":[["buy","9130.15","0.02220000"]],"time":"2020-06-30T19:25:18.252493Z"}
{"type":"l2update","product_id":"BTC-USD","changes":[["buy","9128.22","0.00000000"]],"time":"2020-06-30T19:25:18.413987Z"}
{"type":"heartbeat","last_trade_id":0,"product_id":"BTC-USD","sequence":180759916,"time":"2020-06-30T19:25:18.735116Z"}
{"type":"l2update","product_id":"BTC-USD","changes":[["buy","9103.83","0.10550000"]],"time":"2020-06-30T19:25:19.422676Z"}
{"type":"heartbeat","last_trade_id":0,"product_id":"BTC-USD","sequence":180759918,"time":"2020-06-30T19:25:19.735113Z"}
{"type":"l2update","product_id":"BTC-USD","changes":[["buy","9130.38","0.06570000"]],"time":"2020-06-30T19:25:20.008632Z"}
{"type":"l2update","product_id":"BTC-USD","changes":[["buy","9104.13","0.00000000"]],"time":"2020-06-30T19:25:20.091777Z"}
{"type":"l2update","product_id":"BTC-USD","changes":[["buy","9130.19","0.00000000"]],"time":"2020-06-30T19:25:20.530720Z"}
{"type":"l2update","product_id":"BTC-USD","changes":[["buy","9041.50","0.00000000"]],"time":"2020-06-30T19:25:20.538099Z"}
{"type":"l2update","product_id":"BTC-USD","changes":[["sell","9139.33","0.14510000"]],"time":"2020-06-30T19:25:20.599769Z"}
{"type":"heartbeat","last_trade_id":0,"product_id":"BTC-USD","sequence":180759925,"time":"2020-06-30T19:25:20.735114Z"}
{"type":"l2update","product_id":"BTC-USD","changes":[["sell","9165.00","0.00000000"]],"time":"2020-06-30T19:25:21.023112Z"}
{"type":"l2update","product_id":"BTC-USD","changes":[["sell","9136.84","0.00000000"]],"time":"2020-06-30T19:25:21.032133Z"}
{"type":"l2update","product_id":"BTC-USD","changes":[["buy","9129.21","0.81300000"]],"time":"2020-06-30T19:25:21.447381Z"}
{"type":"heartbeat","last_trade_id":0,"product_id":"BTC-USD","sequence":180759929,"time":"2020-06-30T19:25:21.735115Z"}
{"type":"l2update","product_id":"BTC-USD","changes":[["buy","9114.70","0.00000000"]],"time":"2020-06-30T19:25:21.871939Z"}
{"type":"l2update","product_id":"BTC-USD","changes":[["buy","9111.00","0.00000000"]],"time":"2020-06-30T19:25:21.886085Z"}
{"type":"l2update","product_id":"BTC-USD","changes":[["buy","9132.56","0.04000000"]],"time":"2020-06-30T19:25:22.033116Z"}
{"type":"l2update","product_id":"BTC-USD","changes":[["buy","9130.05","0.00000000"]],"time":"2020-06-30T19:25:22.473575Z"}
{"type":"heartbeat","last_trade_id":0,"product_id":"BTC-USD","sequence":180759934,"time":"2020-06-30T19:25:22.735112Z"}
{"type":"l2update","product_id":"BTC-USD","changes":[["buy","9130.18","0.00000000"]],"time":"2020-06-30T19:25:23.377734Z"}
{"type":"heartbeat","last_trade_id":0,"product_id":"BTC-USD","sequence":180759935,"time":"2020-06-30T19:25:23.735112Z"}
{"type":"l2update","product_id":"BTC-USD","changes":[["sell","9151.05","0.08900000"]],"time":"2020-06-30T19:25:23.957466Z"}
{"type":"l2update","product_id":"BTC-USD","changes":[["buy","9110.96","0.05000000"]],"time":"2020-06-30T19:25:24.216391Z"}
{"type":"l2update","product_id":"BTC-USD","changes":[["sell","9139.33","0.00000000"]],"time":"2020-06-30T19:25:24.388230Z"}
{"type":"l2update","product_id":"BTC-USD","changes":[["buy","9103.83","0.00000000"]],"time":"2020-06-30T19:25:24.647035Z"}
{"type":"l2update","product_id":"BTC-USD","changes":[["buy","9132.56","0.00000000"]],"time":"2020-06-30T19:25:24.706079Z"}
{"type":"l2update","product_id":"BTC-USD","changes":[["buy","9112.23","0.00000000"]],"time":"2020-06-30T19:25:24.706216Z"}
{"type":"heartbeat","last_trade_id":0,"product_id":"BTC-USD","sequence":180759943,"time":"2020-06-30T19:25:24.735114Z"}
{"type":"l2update","product_id":"BTC-USD","changes":[["sell","9175.17","0.02220000"]],"time":"2020-06-30T19:25:25.085476Z"}
{"type":"l2update","product_id":"BTC-USD","changes":[["sell","9175.15","0.02220000"]],"time":"2020-06-30T19:25:25.652941Z"}
{"type":"heartbeat","last_trade_id":0,"product_id":"BTC-USD","sequence":180759947,"time":"2020-06-30T19:25:25.735108Z"}
{"type":"l2update","product_id":"BTC-USD","changes":[["sell","9134.77","2968.34750000"]],"time":"2020-06-30T19:25:25.870176Z"}
{"type":"l2update","product_id":"BTC-USD","changes":[["sell","9154.81","0.01130000"]],"time":"2020-06-30T19:25:26.261129Z"}
{"type":"l2update","product_id":"BTC-USD","changes":[["sell","9139.80","4.00000000"]],"time":"2020-06-30T19:25:26.537735Z"}
{"type":"l2update","product_id":"BTC-USD","changes":[["sell","9176.34","0.00000000"]],"time":"2020-06-30T19:25:26.711242Z"}
{"type":"heartbeat","last_trade_id":0,"product_id":"BTC-USD","sequence":180759955,"time":"2020-06-30T19:25:26.735067Z"}
{"type":"l2update","product_id":"BTC-USD","changes":[["sell","9139.67","0.16400000"]],"time":"2020-06-30T19:25:27.714890Z"}
{"type":"heartbeat","last_trade_id":0,"product_id":"BTC-USD","sequence":180759957,"time":"2020-06-30T19:25:27.735095Z"}
{"type":"l2update","product_id":"BTC-USD","changes":[["sell","9138.42","0.12620000"]],"time":"2020-06-30T19:25:28.164351Z"}
{"type":"l2update","product_id":"BTC-USD","changes":[["sell","9175.64","0.02220000"]],"time":"2020-06-30T19:25:28.171382Z"}
{"type":"l2update","product_id":"BTC-USD","changes":[["sell","9144.75","0.00000000"]],"time":"2020-06-30T19:25:28.173486Z"}
{"type":"heartbeat","last_trade_id":0,"product_id":"BTC-USD","sequence":180759960,"time":"2020-06-30T19:25:28.735071Z"}
{"type":"l2update","product_id":"BTC-USD","changes":[["buy","100.00","114.95500000"]],"time":"2020-06-30T19:25:29.092873Z"}
{"type":"l2update","product_id":"BTC-USD","changes":[["buy","100.00","114.94500000"]],"time":"2020-06-30T19:25:29.101233Z"}
{"type":"l2update","product_id":"BTC-USD","changes":[["sell","9154.81","0.02260000"]],"time":"2020-06-30T19:25:29.363981Z"}
{"type":"l2update","product_id":"BTC-USD","changes":[["buy","9130.46","0.06570000"]],"time":"2020-06-30T19:25:29.660057Z"}
{"type":"heartbeat","last_trade_id":0,"product_id":"BTC-USD","sequence":180759967,"time":"2020-06-30T19:25:29.735046Z"}
{"type":"heartbeat","last_trade_id":0,"product_id":"BTC-USD","sequence":180759967,"time":"2020-06-30T19:25:30.735012Z"}
{"type":"l2update","product_id":"BTC-USD","changes":[["sell","9198.89","0.10000000"]],"time":"2020-06-30T19:25:30.786588Z"}
{"type":"l2update","product_id":"BTC-USD","changes":[["buy","9112.64","0.03100000"]],"time":"2020-06-30T19:25:31.080512Z"}
{"type":"l2update","product_id":"BTC-USD","changes":[["buy","9130.56","0.06570000"]],"time":"2020-06-30T19:25:31.382288Z"}
{"type":"l2update","product_id":"BTC-USD","changes":[["buy","9130.46","0.00000000"]],"time":"2020-06-30T19:25:31.491207Z"}
{"type":"l2update","product_id":"BTC-USD","changes":[["buy","8950.18","0.00000000"]],"time":"2020-06-30T19:25:31.502728Z"}
{"type":"l2update","product_id":"BTC-USD","changes":[["buy","9130.58","0.06570000"]],"time":"2020-06-30T19:25:31.651942Z"}
{"type":"heartbeat","last_trade_id":0,"product_id":"BTC-USD","sequence":180759977,"time":"2020-06-30T19:25:31.735149Z"}
{"type":"l2update","product_id":"BTC-USD","changes":[["buy","9130.15","0.00000000"]],"time":"2020-06-30T19:25:31.820842Z"}
{"type":"l2update","product_id":"BTC-USD","changes":[["buy","9128.18","0.03060000"]],"time":"2020-06-30T19:25:31.937404Z"}
{"type":"l2update","product_id":"BTC-USD","changes":[["sell","9177.35","0.05450000"]],"time":"2020-06-30T19:25:32.205105Z"}
{"type":"l2update","product_id":"BTC-USD","changes":[["buy","9130.58","0.00000000"]],"time":"2020-06-30T19:25:32.362065Z"}
{"type":"heartbeat","last_trade_id":0,"product_id":"BTC-USD","sequence":180759983,"time":"2020-06-30T19:25:32.735039Z"}
{"type":"l2update","product_id":"BTC-USD","changes":[["sell","9175.17","0.00000000"]],"time":"2020-06-30T19:25:32.839619Z"}
{"type":"l2update","product_id":"BTC-USD","changes":[["sell","9134.77","2967.53370000"]],"time":"2020-06-30T19:25:33.603736Z"}
{"type":"heartbeat","last_trade_id":0,"product_id":"BTC-USD","sequence":180759987,"time":"2020-06-30T19:25:33.735091Z"}
{"type":"l2update","product_id":"BTC-USD","changes":[["sell","9134.77","2967.49370000"]],"time":"2020-06-30T19:25:33.869353Z"}
{"type":"l2update","product_id":"BTC-USD","changes":[["buy","9130.38","0.00000000"]],"time":"2020-06-30T19:25:34.039526Z"}
{"type":"l2update","product_id":"BTC-USD","changes":[["buy","9129.64","0.81410000"]],"time":"2020-06-30T19:25:34.153368Z"}
{"type":"l2update","product_id":"BTC-USD","changes":[["buy","9129.43","0.70800000"]],"time":"2020-06-30T19:25:34.693224Z"}
{"type":"heartbeat","last_trade_id":0,"product_id":"BTC-USD","sequence":180759995,"time":"2020-06-30T19:25:34.735125Z"}
{"type":"l2update","product_id":"BTC-USD","changes":[["sell","9134.77","2967.44370000"]],"time":"2020-06-30T19:25:34.961217Z"}
{"type":"l2update","product_id":"BTC-USD","changes":[["sell","9159.13","1.21590000"]],"time":"2020-06-30T19:25:35.267051Z"}
{"type":"l2update","product_id":"BTC-USD","changes":[["buy","9128.18","0.00000000"]],"time":"2020-06-30T19:25:35.410134Z"}
{"type":"l2update","product_id":"BTC-USD","changes":[["sell","9175.64","0.00000000"]],"time":"2020-06-30T19:25:35.707687Z"}
{"type":"l2update","product_id":"BTC-USD","changes":[["sell","9175.15","0.00000000"]],"time":"2020-06-30T19:25:35.709873Z"}
{"type":"heartbeat","last_trade_id":0,"product_id":"BTC-USD","sequence":180760003,"time":"2020-06-30T19:25:35.735116Z"}
{"type":"l2update","product_id":"BTC-USD","changes":[["buy","9130.69","0.53890000"]],"time":"2020-06-30T19:25:35.818639Z"}
{"type":"l2update","product_id":"BTC-USD","changes":[["sell","9134.77","2967.37800000"]],"time":"2020-06-30T19:25:36.115371Z"}
{"type":"heartbeat","last_trade_id":0,"product_id":"BTC-USD","sequence":180760008,"time":"2020-06-30T19:25:36.735130Z"}
{"type":"heartbeat","last_trade_id":0,"product_id":"BTC-USD","sequence":180760008,"time":"2020-06-30T19:25:37.735117Z"}
{"type":"l2update","product_id":"BTC-USD","changes":[["buy","8906.38","0.00000000"]],"time":"2020-06-30T19:25:38.226597Z"}
{"type":"l2update","product_id":"BTC-USD","changes":[["buy","8905.61","0.04500791"]],"time":"2020-06-30T19:25:38.432092Z"}
{"type":"l2update","product_id":"BTC-USD","changes":[["sell","9169.84","0.01550000"]],"time":"2020-06-30T19:25:38.534150Z"}
{"type":"heartbeat","last_trade_id":0,"product_id":"BTC-USD","sequence":180760013,"time":"2020-06-30T19:25:38.735113Z"}
{"type":"l2update","product_id":"BTC-USD","changes":[["sell","9423.84","0.00000000"]],"time":"2020-06-30T19:25:38.770167Z"}
{"type":"l2update","product_id":"BTC-USD","changes":[["sell","9139.80","0.00000000"]],"time":"2020-06-30T19:25:38.881615Z"}
{"type":"l2update","product_id":"BTC-USD","changes":[["sell","9151.05","0.00000000"]],"time":"2020-06-30T19:25:38.889247Z"}
{"type":"l2update","product_id":"BTC-USD","changes":[["buy","9104.75","0.07360000"]],"time":"2020-06-30T19:25:38.973217Z"}
{"type":"l2update","product_id":"BTC-USD","changes":[["buy","9130.56","0.00000000"]],"time":"2020-06-30T19:25:39.053077Z"}
{"type":"l2update","product_id":"BTC-USD","changes":[["buy","9129.64","0.00000000"]],"time":"2020-06-30T19:25:39.066970Z"}
{"type":"l2update","product_id":"BTC-USD","changes":[["buy","9129.21","0.00000000"]],"time":"2020-06-30T19:25:39.067386Z"}
{"type":"l2update","product_id":"BTC-USD","changes":[["buy","9111.21","0.01990000"]],"time":"2020-06-30T19:25:39.239540Z"}
{"type":"l2update","product_id":"BTC-USD","changes":[["sell","9424.66","0.00578482"]],"time":"2020-06-30T19:25:39.377119Z"}
{"type":"l2update","product_id":"BTC-USD","changes":[["buy","9104.97","0.00000000"]],"time":"2020-06-30T19:25:39.402193Z"}
{"type":"heartbeat","last_trade_id":0,"product_id":"BTC-USD","sequence":180760026,"time":"2020-06-30T19:25:39.735112Z"}
{"type":"l2update","product_id":"BTC-USD","changes":[["buy","9133.68","0.04000000"]],"time":"2020-06-30T19:25:39.811138Z"}
{"type":"l2update","product_id":"BTC-USD","changes":[["buy","9113.27","0.01990000"]],"time":"2020-06-30T19:25:40.097704Z"}
{"type":"l2update","product_id":"BTC-USD","changes":[["buy","9133.68","0.00000000"]],"time":"2020-06-30T19:25:40.562684Z"}
{"type":"l2update","product_id":"BTC-USD","changes":[["buy","9111.21","0.00000000"]],"time":"2020-06-30T19:25:40.563100Z"}
{"type":"l2update","product_id":"BTC-USD","changes":[["sell","9170.60","0.01550000"]],"time":"2020-06-30T19:25:40.664172Z"}
{"type":"heartbeat","last_trade_id":0,"product_id":"BTC-USD","sequence":180760034,"time":"2020-06-30T19:25:40.735113Z"}
{"type":"l2update","product_id":"BTC-USD","changes":[["sell","9159.13","0.00000000"]],"time":"2020-06-30T19:25:41.124506Z"}
{"type":"l2update","product_id":"BTC-USD","changes":[["sell","9134.77","2967.31230000"]],"time":"2020-06-30T19:25:41.607841Z"}
{"type":"l2update","product_id":"BTC-USD","changes":[["sell","9134.77","2967.31130000"]],"time":"2020-06-30T19:25:41.676222Z"}
{"type":"heartbeat","last_trade_id":0,"product_id":"BTC-USD","sequence":180760041,"time":"2020-06-30T19:25:41.735127Z"}
{"type":"l2update","product_id":"BTC-USD","changes":[["buy","9112.64","0.00000000"]],"time":"2020-06-30T19:25:41.799012Z"}
{"type":"l2update","product_id":"BTC-USD","changes":[["buy","9113.27","0.00000000"]],"time":"2020-06-30T19:25:41.811031Z"}
{"type":"l2update","product_id":"BTC-USD","changes":[["buy","9103.91","0.00000000"]],"time":"2020-06-30T19:25:41.850978Z"}
{"type":"l2update","product_id":"BTC-USD","changes":[["buy","9069.90","0.08750000"]],"time":"2020-06-30T19:25:41.878220Z"}
{"type":"l2update","product_id":"BTC-USD","changes":[["sell","9174.24","0.05270000"]],"time":"2020-06-30T19:25:42.725718Z"}
{"type":"heartbeat","last_trade_id":0,"product_id":"BTC-USD","sequence":180760048,"time":"2020-06-30T19:25:42.735071Z"}
{"type":"l2update","product_id":"BTC-USD","changes":[["sell","9138.42","0.00000000"]],"time":"2020-06-30T19:25:42.961799Z"}
{"type":"l2update","product_id":"BTC-USD","changes":[["sell","9198.89","0.00000000"]],"time":"2020-06-30T19:25:42.984436Z"}
{"type":"l2update","product_id":"BTC-USD","changes":[["buy","9108.53","0.03500000"]],"time":"2020-06-30T19:25:43.298703Z"}
{"type":"l2update","product_id":"BTC-USD","changes":[["buy","9069.90","0.00000000"]],"time":"2020-06-30T19:25:43.492322Z"}
{"type":"l2update","product_id":"BTC-USD","changes":[["buy","9104.78","0.00000000"]],"time":"2020-06-30T19:25:43.497505Z"}
{"type":"l2update","product_id":"BTC-USD","changes":[["buy","9129.43","0.00000000"]],"time":"2020-06-30T19:25:43.584240Z"}
{"type":"heartbeat","last_trade_id":0,"product_id":"BTC-USD","sequence":180760055,"time":"2020-06-30T19:25:43.735100Z"}
{"type":"l2update","product_id":"BTC-USD","changes":[["sell","9134.77","2967.24560000"]],"time":"2020-06-30T19:25:43.837566Z"}
{"type":"l2update","product_id":"BTC-USD","changes":[["buy","100.00","114.95500000"]],"time":"2020-06-30T19:25:44.027075Z"}
{"type":"l2update","product_id":"BTC-USD","changes":[["buy","100.00","114.94500000"]],"time":"2020-06-30T19:25:44.034161Z"}
{"type":"l2update","product_id":"BTC-USD","changes":[["sell","9134.77","2967.17990000"]],"time":"2020-06-30T19:25:44.664001Z"}
{"type":"heartbeat","last_trade_id":0,"product_id":"BTC-USD","sequence":180760064,"time":"2020-06-30T19:25:44.735114Z"}
{"type":"l2update","product_id":"BTC-USD","changes":[["buy","9101.15","0.01050000"]],"time":"2020-06-30T19:25:44.937346Z"}
{"type":"l2update","product_id":"BTC-USD","changes":[["buy","9104.75","0.00000000"]],"time":"2020-06-30T19:25:45.360673Z"}
{"type":"l2update","product_id":"BTC-USD","changes":[["sell","9134.77","2967.12990000"]],"time":"2020-06-30T19:25:45.485999Z"}
{"type":"heartbeat","last_trade_id":0,"product_id":"BTC-USD","sequence":180760070,"time":"2020-06-30T19:25:45.735062Z"}
{"type":"l2update","product_id":"BTC-USD","changes":[["buy","9101.80","0.03890000"]],"time":"2020-06-30T19:25:45.764126Z"}
{"type":"l2update","product_id":"BTC-USD","changes":[["buy","9110.96","0.00000000"]],"time":"2020-06-30T19:25:45.897158Z"}
{"type":"l2update","product_id":"BTC-USD","changes":[["sell","9172.59","0.01490000"]],"time":"2020-06-30T19:25:46.608175Z"}
{"type":"heartbeat","last_trade_id":0,"product_id":"BTC-USD","sequence":180760075,"time":"2020-06-30T19:25:46.735096Z"}
{"type":"l2update","product_id":"BTC-USD","changes":[["buy","9102.56","0.07360000"]],"time":"2020-06-30T19:25:46.890089Z"}
{"type":"l2update","product_id":"BTC-USD","changes":[["sell","9174.24","0.00000000"]],"time":"2020-06-30T19:25:47.059757Z"}
{"type":"l2update","product_id":"BTC-USD","changes":[["sell","9134.77","2967.06420000"]],"time":"2020-06-30T19:25:47.454993Z"}
{"type":"l2update","product_id":"BTC-USD","changes":[["sell","9134.77","2967.01420000"]],"time":"2020-06-30T19:25:47.733422Z"}
{"type":"heartbeat","last_trade_id":0,"product_id":"BTC-USD","sequence":180760084,"time":"2020-06-30T19:25:47.735121Z"}
{"type":"l2update","product_id":"BTC-USD","changes":[["buy","9103.34","0.07360000"]],"time":"2020-06-30T19:25:48.021139Z"}
{"type":"l2update","product_id":"BTC-USD","changes":[["sell","9134.77","2966.94850000"]],"time":"2020-06-30T19:25:48.607982Z"}
{"type":"heartbeat","last_trade_id":0,"product_id":"BTC-USD","sequence":180760089,"time":"2020-06-30T19:25:48.735122Z"}
{"type":"l2update","product_id":"BTC-USD","changes":[["buy","9104.02","0.07360000"]],"time":"2020-06-30T19:25:48.882364Z"}
{"type":"l2update","product_id":"BTC-USD","changes":[["sell","9134.77","2966.88280000"]],"time":"2020-06-30T19:25:49.721746Z"}
{"type":"heartbeat","last_trade_id":0,"product_id":"BTC-USD","sequence":180760094,"time":"2020-06-30T19:25:49.735056Z"}
{"type":"l2update","product_id":"BTC-USD","changes":[["buy","9101.15","0.00000000"]],"time":"2020-06-30T19:25:50.163203Z"}
{"type":"l2update","product_id":"BTC-USD","changes":[["buy","9107.71","0.01570000"]],"time":"2020-06-30T19:25:50.282055Z"}
{"type":"heartbeat","last_trade_id":0,"product_id":"BTC-USD","sequence":180760097,"time":"2020-06-30T19:25:50.735101Z"}
{"type":"l2update","product_id":"BTC-USD","changes":[["buy","9108.12","0.04160000"]],"time":"2020-06-30T19:25:50.851112Z"}
{"type":"l2update","product_id":"BTC-USD","changes":[["sell","9134.77","2966.83280000"]],"time":"2020-06-30T19:25:51.120035Z"}
{"type":"l2update","product_id":"BTC-USD","changes":[["buy","9104.02","0.00000000"]],"time":"2020-06-30T19:25:51.531367Z"}
{"type":"l2update","product_id":"BTC-USD","changes":[["buy","9102.56","0.00000000"]],"time":"2020-06-30T19:25:51.582889Z"}
{"type":"heartbeat","last_trade_id":0,"product_id":"BTC-USD","sequence":180760104,"time":"2020-06-30T19:25:51.735121Z"}
{"type":"l2update","product_id":"BTC-USD","changes":[["sell","9134.77","2966.78280000"]],"time":"2020-06-30T19:25:51.975372Z"}
{"type":"heartbeat","last_trade_id":0,"product_id":"BTC-USD","sequence":180760107,"time":"2020-06-30T19:25:52.735118Z"}
{"type":"l2update","product_id":"BTC-USD","changes":[["buy","9092.90","0.03190000"]],"time":"2020-06-30T19:25:52.813238Z"}
{"type":"l2update","product_id":"BTC-USD","changes":[["buy","9103.34","0.00000000"]],"time":"2020-06-30T19:25:53.262770Z"}
{"type":"heartbeat","last_trade_id":0,"product_id":"BTC-USD","sequence":180760110,"time":"2020-06-30T19:25:53.735110Z"}
{"type":"heartbeat","last_trade_id":0,"product_id":"BTC-USD","sequence":180760110,"time":"2020-06-30T19:25:54.735127Z"}
{"type":"l2update","product_id":"BTC-USD","changes":[["sell","9134.77","2966.71710000"]],"time":"2020-06-30T19:25:55.039182Z"}
{"type":"l2update","product_id":"BTC-USD","changes":[["buy","9111.83","0.01990000"]],"time":"2020-06-30T19:25:55.717576Z"}
{"type":"heartbeat","last_trade_id":0,"product_id":"BTC-USD","sequence":180760115,"time":"2020-06-30T19:25:55.735119Z"}
{"type":"l2update","product_id":"BTC-USD","changes":[["buy","9134.58","0.04000000"]],"time":"2020-06-30T19:25:55.996325Z"}
{"type":"l2update","product_id":"BTC-USD","changes":[["buy","9126.32","0.00000000"]],"time":"2020-06-30T19:25:56.139556Z"}
{"type":"l2update","product_id":"BTC-USD","changes":[["buy","9108.53","0.00000000"]],"time":"2020-06-30T19:25:56.144739Z"}
{"type":"l2update","product_id":"BTC-USD","changes":[["buy","9101.45","0.03890000"]],"time":"2020-06-30T19:25:56.581138Z"}
{"type":"heartbeat","last_trade_id":0,"product_id":"BTC-USD","sequence":180760121,"time":"2020-06-30T19:25:56.735114Z"}
{"type":"l2update","product_id":"BTC-USD","changes":[["buy","9101.77","0.03890000"]],"time":"2020-06-30T19:25:56.849384Z"}
{"type":"l2update","product_id":"BTC-USD","changes":[["buy","9111.83","0.03980000"]],"time":"2020-06-30T19:25:57.703012Z"}
{"type":"heartbeat","last_trade_id":0,"product_id":"BTC-USD","sequence":180760125,"time":"2020-06-30T19:25:57.735070Z"}
{"type":"heartbeat","last_trade_id":0,"product_id":"BTC-USD","sequence":180760125,"time":"2020-06-30T19:25:58.735095Z"}
{"type":"l2update","product_id":"BTC-USD","changes":[["buy","100.00","114.95500000"]],"time":"2020-06-30T19:25:59.050334Z"}
{"type":"l2update","product_id":"BTC-USD","changes":[["buy","100.00","114.94500000"]],"time":"2020-06-30T19:25:59.056734Z"}
{"type":"heartbeat","last_trade_id":0,"product_id":"BTC-USD","sequence":180760128,"time":"2020-06-30T19:25:59.735112Z"}
{"type":"l2update","product_id":"BTC-USD","changes":[["sell","9134.77","2966.66710000"]],"time":"2020-06-30T19:25:59.961614Z"}
{"type":"l2update","product_id":"BTC-USD","changes":[["buy","9130.69","0.00000000"]],"time":"2020-06-30T19:26:00.140066Z"}
{"type":"l2update","product_id":"BTC-USD","changes":[["buy","9101.80","0.00000000"]],"time":"2020-06-30T19:26:00.141034Z"}
{"type":"l2update","product_id":"BTC-USD","changes":[["sell","9172.51","0.02220000"]],"time":"2020-06-30T19:26:00.253234Z"}
{"type":"l2update","product_id":"BTC-USD","changes":[["sell","9134.77","2966.61710000"]],"time":"2020-06-30T19:26:00.526084Z"}
{"type":"heartbeat","last_trade_id":0,"product_id":"BTC-USD","sequence":180760138,"time":"2020-06-30T19:26:00.735059Z"}
{"type":"l2update","product_id":"BTC-USD","changes":[["sell","9173.55","0.02220000"]],"time":"2020-06-30T19:26:00.827174Z"}
{"type":"heartbeat","last_trade_id":0,"product_id":"BTC-USD","sequence":180760140,"time":"2020-06-30T19:26:01.735118Z"}
{"type":"l2update","product_id":"BTC-USD","changes":[["sell","9178.98","0.05450000"]],"time":"2020-06-30T19:26:02.543607Z"}
{"type":"heartbeat","last_trade_id":0,"product_id":"BTC-USD","sequence":180760142,"time":"2020-06-30T19:26:02.735117Z"}
{"type":"l2update","product_id":"BTC-USD","changes":[["sell","9154.81","0.01130000"]],"time":"2020-06-30T19:26:03.026127Z"}
{"type":"heartbeat","last_trade_id":0,"product_id":"BTC-USD","sequence":180760143,"time":"2020-06-30T19:26:03.735113Z"}
{"type":"l2update","product_id":"BTC-USD","changes":[["sell","9172.51","0.00000000"]],"time":"2020-06-30T19:26:04.277130Z"}
{"type":"l2update","product_id":"BTC-USD","changes":[["sell","9154.81","0.00000000"]],"time":"2020-06-30T19:26:04.279293Z"}
{"type":"l2update","product_id":"BTC-USD","changes":[["sell","9136.51","0.13750000"]],"time":"2020-06-30T19:26:04.280368Z"}
{"type":"l2update","product_id":"BTC-USD","changes":[["sell","9169.84","0.00000000"]],"time":"2020-06-30T19:26:04.285123Z"}
{"type":"l2update","product_id":"BTC-USD","changes":[["sell","9144.48","0.02360000"]],"time":"2020-06-30T19:26:04.580262Z"}
{"type":"heartbeat","last_trade_id":0,"product_id":"BTC-USD","sequence":180760150,"time":"2020-06-30T19:26:04.735121Z"}
{"type":"l2update","product_id":"BTC-USD","changes":[["sell","9178.98","0.00000000"]],"time":"2020-06-30T19:26:04.754337Z"}
{"type":"l2update","product_id":"BTC-USD","changes":[["buy","8904.65","0.00300000"]],"time":"2020-06-30T19:26:05.526291Z"}
{"type":"heartbeat","last_trade_id":0,"product_id":"BTC-USD","sequence":180760153,"time":"2020-06-30T19:26:05.735121Z"}
{"type":"l2update","product_id":"BTC-USD","changes":[["buy","9134.58","0.00000000"]],"time":"2020-06-30T19:26:05.956728Z"}
{"type":"l2update","product_id":"BTC-USD","changes":[["buy","9125.37","0.03060000"]],"time":"2020-06-30T19:26:06.678582Z"}
{"type":"heartbeat","last_trade_id":0,"product_id":"BTC-USD","sequence":180760156,"time":"2020-06-30T19:26:06.735117Z"}
{"type":"l2update","product_id":"BTC-USD","changes":[["buy","9128.02","0.06570000"]],"time":"2020-06-30T19:26:06.954438Z"}
{"type":"l2update","product_id":"BTC-USD","changes":[["buy","9101.45","0.00000000"]],"time":"2020-06-30T19:26:07.120291Z"}
{"type":"l2update","product_id":"BTC-USD","changes":[["buy","9101.77","0.00000000"]],"time":"2020-06-30T19:26:07.158785Z"}
{"type":"l2update","product_id":"BTC-USD","changes":[["buy","8904.65","0.00000000"]],"time":"2020-06-30T19:26:07.178479Z"}
{"type":"l2update","product_id":"BTC-USD","changes":[["buy","9128.03","0.02220000"]],"time":"2020-06-30T19:26:07.243799Z"}
{"type":"heartbeat","last_trade_id":0,"product_id":"BTC-USD","sequence":180760163,"time":"2020-06-30T19:26:07.735118Z"}
{"type":"l2update","product_id":"BTC-USD","changes":[["buy","9128.02","0.13140000"]],"time":"2020-06-30T19:26:08.344691Z"}
{"type":"l2update","product_id":"BTC-USD","changes":[["buy","9128.04","0.06570000"]],"time":"2020-06-30T19:26:08.628544Z"}
{"type":"heartbeat","last_trade_id":0,"product_id":"BTC-USD","sequence":180760167,"time":"2020-06-30T19:26:08.735127Z"}
{"type":"l2update","product_id":"BTC-USD","changes":[["sell","9136.52","0.13330000"]],"time":"2020-06-30T19:26:09.214087Z"}
{"type":"l2update","product_id":"BTC-USD","changes":[["buy","9125.53","0.03060000"]],"time":"2020-06-30T19:26:09.602938Z"}
{"type":"heartbeat","last_trade_id":0,"product_id":"BTC-USD","sequence":180760171,"time":"2020-06-30T19:26:09.735069Z"}
{"type":"l2update","product_id":"BTC-USD","changes":[["buy","9125.55","0.03060000"]],"time":"2020-06-30T19:26:09.869862Z"}
{"type":"l2update","product_id":"BTC-USD","changes":[["buy","9125.58","0.06570000"]],"time":"2020-06-30T19:26:10.124378Z"}
{"type":"heartbeat","last_trade_id":0,"product_id":"BTC-USD","sequence":180760175,"time":"2020-06-30T19:26:10.735092Z"}
{"type":"l2update","product_id":"BTC-USD","changes":[["sell","9180.20","0.02220000"]],"time":"2020-06-30T19:26:10.985704Z"}
{"type":"l2update","product_id":"BTC-USD","changes":[["buy","9134.75","3009.99600000"]],"time":"2020-06-30T19:26:11.073325Z"}
{"type":"l2update","product_id":"BTC-USD","changes":[["buy","9113.21","0.01990000"]],"time":"2020-06-30T19:26:11.565457Z"}
{"type":"heartbeat","last_trade_id":0,"product_id":"BTC-USD","sequence":180760182,"time":"2020-06-30T19:26:11.735057Z"}
{"type":"l2update","product_id":"BTC-USD","changes":[["sell","9134.77","2965.98500000"]],"time":"2020-06-30T19:26:11.835771Z"}
{"type":"l2update","product_id":"BTC-USD","changes":[["sell","9138.74","0.06570000"]],"time":"2020-06-30T19:26:12.116503Z"}
{"type":"l2update","product_id":"BTC-USD","changes":[["sell","9165.20","1.06720000"]],"time":"2020-06-30T19:26:12.400050Z"}
{"type":"l2update","product_id":"BTC-USD","changes":[["sell","9170.60","0.00000000"]],"time":"2020-06-30T19:26:12.596394Z"}
{"type":"heartbeat","last_trade_id":0,"product_id":"BTC-USD","sequence":180760190,"time":"2020-06-30T19:26:12.735009Z"}
{"type":"l2update","product_id":"BTC-USD","changes":[["sell","9139.67","0.00000000"]],"time":"2020-06-30T19:26:12.840194Z"}
{"type":"l2update","product_id":"BTC-USD","changes":[["sell","9138.24","0.06570000"]],"time":"2020-06-30T19:26:13.546502Z"}
{"type":"heartbeat","last_trade_id":0,"product_id":"BTC-USD","sequence":180760193,"time":"2020-06-30T19:26:13.735120Z"}
{"type":"l2update","product_id":"BTC-USD","changes":[["buy","100.00","114.95500000"]],"time":"2020-06-30T19:26:14.039888Z"}
{"type":"l2update","product_id":"BTC-USD","changes":[["buy","100.00","114.94500000"]],"time":"2020-06-30T19:26:14.045985Z"}
{"type":"l2update","product_id":"BTC-USD","changes":[["buy","9132.95","0.06570000"]],"time":"2020-06-30T19:26:14.386196Z"}
{"type":"heartbeat","last_trade_id":0,"product_id":"BTC-USD","sequence":180760198,"time":"2020-06-30T19:26:14.735063Z"}
{"type":"l2update","product_id":"BTC-USD","changes":[["buy","9113.21","0.00000000"]],"time":"2020-06-30T19:26:14.811818Z"}
{"type":"l2update","product_id":"BTC-USD","changes":[["sell","9135.80","0.90000000"]],"time":"2020-06-30T19:26:15.261366Z"}
{"type":"l2update","product_id":"BTC-USD","changes":[["sell","9135.80","1.80000000"]],"time":"2020-06-30T19:26:15.556691Z"}
{"type":"l2update","product_id":"BTC-USD","changes":[["sell","9173.55","0.00000000"]],"time":"2020-06-30T19:26:15.704669Z"}
{"type":"l2update","product_id":"BTC-USD","changes":[["sell","9180.20","0.00000000"]],"time":"2020-06-30T19:26:15.704809Z"}
{"type":"heartbeat","last_trade_id":0,"product_id":"BTC-USD","sequence":180760205,"time":"2020-06-30T19:26:15.735115Z"}
{"type":"l2update","product_id":"BTC-USD","changes":[["sell","9135.80","2.70000000"]],"time":"2020-06-30T19:26:15.820092Z"}
{"type":"heartbeat","last_trade_id":0,"product_id":"BTC-USD","sequence":180760207,"time":"2020-06-30T19:26:16.735047Z"}
{"type":"l2update","product_id":"BTC-USD","changes":[["buy","9132.79","0.06570000"]],"time":"2020-06-30T19:26:17.333563Z"}
{"type":"l2update","product_id":"BTC-USD","changes":[["sell","9134.77","2965.45900000"]],"time":"2020-06-30T19:26:17.650761Z"}
{"type":"heartbeat","last_trade_id":0,"product_id":"BTC-USD","sequence":180760212,"time":"2020-06-30T19:26:17.735048Z"}
{"type":"l2update","product_id":"BTC-USD","changes":[["buy","9125.55","0.00000000"]],"time":"2020-06-30T19:26:18.119793Z"}
{"type":"l2update","product_id":"BTC-USD","changes":[["buy","9125.58","0.00000000"]],"time":"2020-06-30T19:26:18.148969Z"}
{"type":"l2update","product_id":"BTC-USD","changes":[["sell","9179.74","0.02320000"]],"time":"2020-06-30T19:26:18.498696Z"}
{"type":"heartbeat","last_trade_id":0,"product_id":"BTC-USD","sequence":180760216,"time":"2020-06-30T19:26:18.735001Z"}
{"type":"l2update","product_id":"BTC-USD","changes":[["sell","9144.48","0.00000000"]],"time":"2020-06-30T19:26:19.302130Z"}
{"type":"l2update","product_id":"BTC-USD","changes":[["buy","9133.57","0.05000000"]],"time":"2020-06-30T19:26:19.470150Z"}
{"type":"heartbeat","last_trade_id":0,"product_id":"BTC-USD","sequence":180760219,"time":"2020-06-30T19:26:19.735088Z"}
{"type":"l2update","product_id":"BTC-USD","changes":[["buy","9132.98","0.58000000"]],"time":"2020-06-30T19:26:20.341786Z"}
{"type":"l2update","product_id":"BTC-USD","changes":[["sell","9135.07","0.14150000"]],"time":"2020-06-30T19:26:20.610761Z"}
{"type":"heartbeat","last_trade_id":0,"product_id":"BTC-USD","sequence":180760223,"time":"2020-06-30T19:26:20.735116Z"}
{"type":"l2update","product_id":"BTC-USD","changes":[["buy","9132.79","0.00000000"]],"time":"2020-06-30T19:26:20.800794Z"}
{"type":"l2update","product_id":"BTC-USD","changes":[["buy","9125.53","0.00000000"]],"time":"2020-06-30T19:26:20.801425Z"}
{"type":"l2update","product_id":"BTC-USD","changes":[["buy","9092.90","0.00000000"]],"time":"2020-06-30T19:26:20.823054Z"}
{"type":"l2update","product_id":"BTC-USD","changes":[["sell","9179.74","0.00000000"]],"time":"2020-06-30T19:26:21.088306Z"}
{"type":"l2update","product_id":"BTC-USD","changes":[["buy","9133.23","0.04000000"]],"time":"2020-06-30T19:26:21.222316Z"}
{"type":"l2update","product_id":"BTC-USD","changes":[["sell","9176.71","0.05450000"]],"time":"2020-06-30T19:26:21.486079Z"}
{"type":"l2update","product_id":"BTC-USD","changes":[["buy","9128.04","0.00000000"]],"time":"2020-06-30T19:26:21.652908Z"}
{"type":"heartbeat","last_trade_id":0,"product_id":"BTC-USD","sequence":180760232,"time":"2020-06-30T19:26:21.735115Z"}
{"type":"l2update","product_id":"BTC-USD","changes":[["sell","9139.87","0.82110000"]],"time":"2020-06-30T19:26:21.771311Z"}
{"type":"l2update","product_id":"BTC-USD","changes":[["sell","9138.74","0.00000000"]],"time":"2020-06-30T19:26:22.015677Z"}
{"type":"l2update","product_id":"BTC-USD","changes":[["sell","9179.52","0.02220000"]],"time":"2020-06-30T19:26:22.049775Z"}
{"type":"l2update","product_id":"BTC-USD","changes":[["sell","9134.77","2961.79250000"]],"time":"2020-06-30T19:26:22.410298Z"}
{"type":"heartbeat","last_trade_id":0,"product_id":"BTC-USD","sequence":180760240,"time":"2020-06-30T19:26:22.735113Z"}
{"type":"l2update","product_id":"BTC-USD","changes":[["buy","9128.03","0.00000000"]],"time":"2020-06-30T19:26:22.895815Z"}
{"type":"l2update","product_id":"BTC-USD","changes":[["buy","9132.56","1.63500000"]],"time":"2020-06-30T19:26:23.363623Z"}
{"type":"l2update","product_id":"BTC-USD","changes":[["buy","9132.64","0.06570000"]],"time":"2020-06-30T19:26:23.673593Z"}
{"type":"heartbeat","last_trade_id":0,"product_id":"BTC-USD","sequence":180760245,"time":"2020-06-30T19:26:23.735031Z"}
{"type":"l2update","product_id":"BTC-USD","changes":[["buy","9133.36","0.04000000"]],"time":"2020-06-30T19:26:24.031418Z"}
{"type":"l2update","product_id":"BTC-USD","changes":[["sell","9136.63","0.90000000"]],"time":"2020-06-30T19:26:24.297802Z"}
{"type":"l2update","product_id":"BTC-USD","changes":[["sell","9135.80","1.80000000"]],"time":"2020-06-30T19:26:24.482403Z"}
{"type":"l2update","product_id":"BTC-USD","changes":[["sell","9136.52","0.00000000"]],"time":"2020-06-30T19:26:24.484292Z"}
{"type":"l2update","product_id":"BTC-USD","changes":[["buy","9133.57","0.00000000"]],"time":"2020-06-30T19:26:24.651585Z"}
{"type":"heartbeat","last_trade_id":0,"product_id":"BTC-USD","sequence":180760252,"time":"2020-06-30T19:26:24.735167Z"}
{"type":"l2update","product_id":"BTC-USD","changes":[["sell","9176.71","0.10900000"]],"time":"2020-06-30T19:26:24.872345Z"}
{"type":"l2update","product_id":"BTC-USD","changes":[["sell","9176.71","0.05450000"]],"time":"2020-06-30T19:26:25.380750Z"}
{"type":"heartbeat","last_trade_id":0,"product_id":"BTC-USD","sequence":180760255,"time":"2020-06-30T19:26:25.735114Z"}
{"type":"heartbeat","last_trade_id":0,"product_id":"BTC-USD","sequence":180760255,"time":"2020-06-30T19:26:26.735099Z"}
{"type":"l2update","product_id":"BTC-USD","changes":[["sell","9135.73","0.90000000"]],"time":"2020-06-30T19:26:27.100075Z"}
{"type":"l2update","product_id":"BTC-USD","changes":[["sell","9139.87","0.00000000"]],"time":"2020-06-30T19:26:27.529139Z"}
{"type":"heartbeat","last_trade_id":0,"product_id":"BTC-USD","sequence":180760258,"time":"2020-06-30T19:26:27.735088Z"}
{"type":"l2update","product_id":"BTC-USD","changes":[["sell","9176.18","0.01490000"]],"time":"2020-06-30T19:26:28.397545Z"}
{"type":"l2update","product_id":"BTC-USD","changes":[["sell","9165.20","0.00000000"]],"time":"2020-06-30T19:26:28.601889Z"}
{"type":"l2update","product_id":"BTC-USD","changes":[["sell","9135.73","0.00000000"]],"time":"2020-06-30T19:26:28.633634Z"}
{"type":"heartbeat","last_trade_id":0,"product_id":"BTC-USD","sequence":180760262,"time":"2020-06-30T19:26:28.735096Z"}
{"type":"l2update","product_id":"BTC-USD","changes":[["buy","100.00","114.95500000"]],"time":"2020-06-30T19:26:29.036818Z"}
{"type":"l2update","product_id":"BTC-USD","changes":[["buy","100.00","114.94500000"]],"time":"2020-06-30T19:26:29.043350Z"}
{"type":"l2update","product_id":"BTC-USD","changes":[["sell","9135.73","0.90000000"]],"time":"2020-06-30T19:26:29.228353Z"}
{"type":"l2update","product_id":"BTC-USD","changes":[["sell","9176.18","0.00000000"]],"time":"2020-06-30T19:26:29.643395Z"}
{"type":"l2update","product_id":"BTC-USD","changes":[["sell","9138.24","0.00000000"]],"time":"2020-06-30T19:26:29.643555Z"}
{"type":"heartbeat","last_trade_id":0,"product_id":"BTC-USD","sequence":180760269,"time":"2020-06-30T19:26:29.735117Z"}
{"type":"l2update","product_id":"BTC-USD","changes":[["sell","9135.18","0.14600000"]],"time":"2020-06-30T19:26:30.071303Z"}
{"type":"l2update","product_id":"BTC-USD","changes":[["sell","9176.71","0.10900000"]],"time":"2020-06-30T19:26:30.335621Z"}
{"type":"l2update","product_id":"BTC-USD","changes":[["sell","9136.63","0.00000000"]],"time":"2020-06-30T19:26:30.478542Z"}
{"type":"l2update","product_id":"BTC-USD","changes":[["sell","9135.07","0.00000000"]],"time":"2020-06-30T19:26:30.488319Z"}
{"type":"l2update","product_id":"BTC-USD","changes":[["sell","9136.51","0.00000000"]],"time":"2020-06-30T19:26:30.496806Z"}
{"type":"l2update","product_id":"BTC-USD","changes":[["sell","9135.73","1.80000000"]],"time":"2020-06-30T19:26:30.622193Z"}
{"type":"heartbeat","last_trade_id":0,"product_id":"BTC-USD","sequence":180760278,"time":"2020-06-30T19:26:30.735033Z"}
{"type":"l2update","product_id":"BTC-USD","changes":[["sell","9179.52","0.00000000"]],"time":"2020-06-30T19:26:30.803482Z"}
{"type":"l2update","product_id":"BTC-USD","changes":[["sell","9176.71","0.05450000"]],"time":"2020-06-30T19:26:30.807509Z"}
{"type":"heartbeat","last_trade_id":0,"product_id":"BTC-USD","sequence":180760280,"time":"2020-06-30T19:26:31.735167Z"}
{"type":"l2update","product_id":"BTC-USD","changes":[["sell","9137.77","0.06570000"]],"time":"2020-06-30T19:26:32.327387Z"}
{"type":"l2update","product_id":"BTC-USD","changes":[["buy","9108.94","0.10720000"]],"time":"2020-06-30T19:26:32.591306Z"}
{"type":"heartbeat","last_trade_id":0,"product_id":"BTC-USD","sequence":180760284,"time":"2020-06-30T19:26:32.735118Z"}
{"type":"l2update","product_id":"BTC-USD","changes":[["sell","9135.80","0.90000000"]],"time":"2020-06-30T19:26:32.778088Z"}
{"type":"l2update","product_id":"BTC-USD","changes":[["buy","9111.83","0.01990000"]],"time":"2020-06-30T19:26:32.793537Z"}
{"type":"l2update","product_id":"BTC-USD","changes":[["buy","8861.49","0.01200000"]],"time":"2020-06-30T19:26:33.168375Z"}
{"type":"l2update","product_id":"BTC-USD","changes":[["sell","9135.79","0.05000000"]],"time":"2020-06-30T19:26:33.490536Z"}
{"type":"heartbeat","last_trade_id":0,"product_id":"BTC-USD","sequence":180760290,"time":"2020-06-30T19:26:33.735120Z"}
{"type":"heartbeat","last_trade_id":0,"product_id":"BTC-USD","sequence":180760290,"time":"2020-06-30T19:26:34.735035Z"}
{"type":"l2update","product_id":"BTC-USD","changes":[["sell","9135.78","0.90000000"]],"time":"2020-06-30T19:26:35.617049Z"}
{"type":"heartbeat","last_trade_id":0,"product_id":"BTC-USD","sequence":180760292,"time":"2020-06-30T19:26:35.735178Z"}
{"type":"l2update","product_id":"BTC-USD","changes":[["sell","9172.59","0.00000000"]],"time":"2020-06-30T19:26:35.818741Z"}
{"type":"l2update","product_id":"BTC-USD","changes":[["sell","9177.35","0.00000000"]],"time":"2020-06-30T19:26:35.820134Z"}
{"type":"l2update","product_id":"BTC-USD","changes":[["sell","9135.18","0.00000000"]],"time":"2020-06-30T19:26:35.825257Z"}
{"type":"l2update","product_id":"BTC-USD","changes":[["sell","9135.06","0.09050000"]],"time":"2020-06-30T19:26:35.905176Z"}
{"type":"l2update","product_id":"BTC-USD","changes":[["sell","9134.77","2961.03230000"]],"time":"2020-06-30T19:26:36.260246Z"}
{"type":"l2update","product_id":"BTC-USD","changes":[["sell","9140.79","0.00670000"]],"time":"2020-06-30T19:26:36.509476Z"}
{"type":"l2update","product_id":"BTC-USD","changes":[["buy","9133.36","0.00000000"]],"time":"2020-06-30T19:26:36.656456Z"}
{"type":"heartbeat","last_trade_id":0,"product_id":"BTC-USD","sequence":180760303,"time":"2020-06-30T19:26:36.735116Z"}
{"type":"heartbeat","last_trade_id":0,"product_id":"BTC-USD","sequence":180760303,"time":"2020-06-30T19:26:37.735128Z"}
{"type":"l2update","product_id":"BTC-USD","changes":[["buy","9134.75","3010.12100000"]],"time":"2020-06-30T19:26:38.454770Z"}
{"type":"l2update","product_id":"BTC-USD","changes":[["sell","9134.77","2960.90100000"]],"time":"2020-06-30T19:26:38.720281Z"}
{"type":"heartbeat","last_trade_id":0,"product_id":"BTC-USD","sequence":180760308,"time":"2020-06-30T19:26:38.735123Z"}
{"type":"l2update","product_id":"BTC-USD","changes":[["buy","9108.12","0.00000000"]],"time":"2020-06-30T19:26:38.872074Z"}
{"type":"l2update","product_id":"BTC-USD","changes":[["buy","9132.95","0.00000000"]],"time":"2020-06-30T19:26:38.875139Z"}
{"type":"l2update","product_id":"BTC-USD","changes":[["buy","9108.53","0.54530000"]],"time":"2020-06-30T19:26:39.021732Z"}
{"type":"heartbeat","last_trade_id":0,"product_id":"BTC-USD","sequence":180760312,"time":"2020-06-30T19:26:39.735074Z"}
{"type":"l2update","product_id":"BTC-USD","changes":[["sell","9140.98","0.00670000"]],"time":"2020-06-30T19:26:39.849972Z"}
{"type":"l2update","product_id":"BTC-USD","changes":[["sell","9135.78","0.00000000"]],"time":"2020-06-30T19:26:40.275127Z"}
{"type":"l2update","product_id":"BTC-USD","changes":[["sell","9135.80","0.00000000"]],"time":"2020-06-30T19:26:40.284884Z"}
{"type":"l2update","product_id":"BTC-USD","changes":[["sell","9134.98","0.54650000"]],"time":"2020-06-30T19:26:40.726273Z"}
{"type":"heartbeat","last_trade_id":0,"product_id":"BTC-USD","sequence":180760318,"time":"2020-06-30T19:26:40.735102Z"}
{"type":"l2update","product_id":"BTC-USD","changes":[["sell","9135.79","0.00000000"]],"time":"2020-06-30T19:26:40.922603Z"}
{"type":"l2update","product_id":"BTC-USD","changes":[["sell","9137.77","0.00000000"]],"time":"2020-06-30T19:26:40.957605Z"}
{"type":"l2update","product_id":"BTC-USD","changes":[["sell","9134.77","2960.77600000"]],"time":"2020-06-30T19:26:41.310911Z"}
{"type":"l2update","product_id":"BTC-USD","changes":[["buy","9132.64","0.00000000"]],"time":"2020-06-30T19:26:41.440869Z"}
{"type":"l2update","product_id":"BTC-USD","changes":[["sell","9134.77","2960.77500000"]],"time":"2020-06-30T19:26:41.464108Z"}
{"type":"l2update","product_id":"BTC-USD","changes":[["buy","9125.37","0.00000000"]],"time":"2020-06-30T19:26:41.472509Z"}
{"type":"l2update","product_id":"BTC-USD","changes":[["buy","9128.02","0.06570000"]],"time":"2020-06-30T19:26:41.475102Z"}
{"type":"l2update","product_id":"BTC-USD","changes":[["buy","9134.75","3010.24600000"]],"time":"2020-06-30T19:26:41.722136Z"}
{"type":"heartbeat","last_trade_id":0,"product_id":"BTC-USD","sequence":180760331,"time":"2020-06-30T19:26:41.735117Z"}
{"type":"l2update","product_id":"BTC-USD","changes":[["buy","9108.94","0.00000000"]],"time":"2020-06-30T19:26:41.757215Z"}
{"type":"l2update","product_id":"BTC-USD","changes":[["buy","9107.71","0.00000000"]],"time":"2020-06-30T19:26:41.757428Z"}
{"type":"l2update","product_id":"BTC-USD","changes":[["buy","9134.74","4771.13170000"]],"time":"2020-06-30T19:26:42.546790Z"}
{"type":"heartbeat","last_trade_id":0,"product_id":"BTC-USD","sequence":180760335,"time":"2020-06-30T19:26:42.735118Z"}
{"type":"l2update","product_id":"BTC-USD","changes":[["buy","9134.75","3010.12100000"]],"time":"2020-06-30T19:26:42.962287Z"}
{"type":"l2update","product_id":"BTC-USD","changes":[["sell","9140.85","0.00670000"]],"time":"2020-06-30T19:26:43.124516Z"}
{"type":"l2update","product_id":"BTC-USD","changes":[["sell","9134.98","1.09300000"]],"time":"2020-06-30T19:26:43.716871Z"}
{"type":"heartbeat","last_trade_id":0,"product_id":"BTC-USD","sequence":180760340,"time":"2020-06-30T19:26:43.735120Z"}
{"type":"l2update","product_id":"BTC-USD","changes":[["buy","8905.61","0.00000000"]],"time":"2020-06-30T19:26:43.937079Z"}
{"type":"l2update","product_id":"BTC-USD","changes":[["buy","100.00","114.95500000"]],"time":"2020-06-30T19:26:44.026846Z"}
{"type":"l2update","product_id":"BTC-USD","changes":[["buy","100.00","114.94500000"]],"time":"2020-06-30T19:26:44.032628Z"}
{"type":"l2update","product_id":"BTC-USD","changes":[["buy","9107.30","0.04110000"]],"time":"2020-06-30T19:26:44.037299Z"}
{"type":"l2update","product_id":"BTC-USD","changes":[["sell","9135.18","0.20000000"]],"time":"2020-06-30T19:26:44.037384Z"}
{"type":"l2update","product_id":"BTC-USD","changes":[["buy","8904.84","0.04510269"]],"time":"2020-06-30T19:26:44.232621Z"}
{"type":"l2update","product_id":"BTC-USD","changes":[["sell","9154.32","0.10000000"]],"time":"2020-06-30T19:26:44.341573Z"}
{"type":"l2update","product_id":"BTC-USD","changes":[["sell","9424.66","0.00000000"]],"time":"2020-06-30T19:26:44.459979Z"}
{"type":"l2update","product_id":"BTC-USD","changes":[["sell","9135.73","0.90000000"]],"time":"2020-06-30T19:26:44.488250Z"}
{"type":"l2update","product_id":"BTC-USD","changes":[["sell","9425.47","0.00587763"]],"time":"2020-06-30T19:26:44.650769Z"}
{"type":"heartbeat","last_trade_id":0,"product_id":"BTC-USD","sequence":180760356,"time":"2020-06-30T19:26:44.735122Z"}
{"type":"heartbeat","last_trade_id":0,"product_id":"BTC-USD","sequence":180760356,"time":"2020-06-30T19:26:45.735110Z"}
{"type":"l2update","product_id":"BTC-USD","changes":[["buy","9107.71","0.12530000"]],"time":"2020-06-30T19:26:45.749369Z"}
{"type":"l2update","product_id":"BTC-USD","changes":[["buy","9106.88","0.04250000"]],"time":"2020-06-30T19:26:45.844801Z"}
{"type":"l2update","product_id":"BTC-USD","changes":[["buy","9108.53","0.00000000"]],"time":"2020-06-30T19:26:46.268328Z"}
{"type":"l2update","product_id":"BTC-USD","changes":[["sell","9154.32","0.13620000"]],"time":"2020-06-30T19:26:46.310952Z"}
{"type":"heartbeat","last_trade_id":0,"product_id":"BTC-USD","sequence":180760363,"time":"2020-06-30T19:26:46.735109Z"}
{"type":"l2update","product_id":"BTC-USD","changes":[["buy","7000.00","184.16550000"]],"time":"2020-06-30T19:26:47.282228Z"}
{"type":"l2update","product_id":"BTC-USD","changes":[["buy","9133.23","0.00000000"]],"time":"2020-06-30T19:26:47.480577Z"}
{"type":"heartbeat","last_trade_id":0,"product_id":"BTC-USD","sequence":180760366,"time":"2020-06-30T19:26:47.735109Z"}
{"type":"l2update","product_id":"BTC-USD","changes":[["buy","9107.30","0.00000000"]],"time":"2020-06-30T19:26:48.677328Z"}
{"type":"heartbeat","last_trade_id":0,"product_id":"BTC-USD","sequence":180760367,"time":"2020-06-30T19:26:48.735113Z"}
{"type":"l2update","product_id":"BTC-USD","changes":[["sell","9206.54","0.10000000"]],"time":"2020-06-30T19:26:48.825367Z"}
{"type":"l2update","product_id":"BTC-USD","changes":[["buy","9128.02","0.00000000"]],"time":"2020-06-30T19:26:49.007146Z"}
{"type":"l2update","product_id":"BTC-USD","changes":[["buy","9134.75","3009.95680000"]],"time":"2020-06-30T19:26:49.497113Z"}
{"type":"l2update","product_id":"BTC-USD","changes":[["sell","9135.73","0.00000000"]],"time":"2020-06-30T19:26:49.509085Z"}
{"type":"heartbeat","last_trade_id":0,"product_id":"BTC-USD","sequence":180760374,"time":"2020-06-30T19:26:49.735114Z"}
{"type":"l2update","product_id":"BTC-USD","changes":[["buy","9133.74","0.04000000"]],"time":"2020-06-30T19:26:50.080213Z"}
{"type":"l2update","product_id":"BTC-USD","changes":[["sell","9174.86","0.01490000"]],"time":"2020-06-30T19:26:50.224366Z"}
{"type":"l2update","product_id":"BTC-USD","changes":[["buy","9132.33","2.90000000"]],"time":"2020-06-30T19:26:50.366104Z"}
{"type":"l2update","product_id":"BTC-USD","changes":[["buy","9103.98","0.03290000"]],"time":"2020-06-30T19:26:50.524571Z"}
{"type":"heartbeat","last_trade_id":0,"product_id":"BTC-USD","sequence":180760382,"time":"2020-06-30T19:26:50.735116Z"}
{"type":"l2update","product_id":"BTC-USD","changes":[["buy","9103.98","0.00000000"]],"time":"2020-06-30T19:26:50.785476Z"}
{"type":"l2update","product_id":"BTC-USD","changes":[["buy","7000.00","0.00000000"]],"time":"2020-06-30T19:26:50.836774Z"}
{"type":"heartbeat","last_trade_id":0,"product_id":"BTC-USD","sequence":180760384,"time":"2020-06-30T19:26:51.735118Z"}
{"type":"heartbeat","last_trade_id":0,"product_id":"BTC-USD","sequence":180760384,"time":"2020-06-30T19:26:52.735113Z"}
{"type":"l2update","product_id":"BTC-USD","changes":[["buy","9134.75","3010.00680000"]],"time":"2020-06-30T19:26:52.955445Z"}
{"type":"l2update","product_id":"BTC-USD","changes":[["buy","9107.71","0.14100000"]],"time":"2020-06-30T19:26:53.231575Z"}
{"type":"l2update","product_id":"BTC-USD","changes":[["sell","9135.80","0.85440000"]],"time":"2020-06-30T19:26:53.512266Z"}
{"type":"l2update","product_id":"BTC-USD","changes":[["buy","9133.74","0.00000000"]],"time":"2020-06-30T19:26:53.691072Z"}
{"type":"l2update","product_id":"BTC-USD","changes":[["buy","9132.56","0.00000000"]],"time":"2020-06-30T19:26:53.693029Z"}
{"type":"heartbeat","last_trade_id":0,"product_id":"BTC-USD","sequence":180760392,"time":"2020-06-30T19:26:53.735117Z"}
{"type":"l2update","product_id":"BTC-USD","changes":[["sell","9134.77","2960.65000000"]],"time":"2020-06-30T19:26:54.329952Z"}
{"type":"heartbeat","last_trade_id":0,"product_id":"BTC-USD","sequence":180760395,"time":"2020-06-30T19:26:54.735116Z"}
{"type":"l2update","product_id":"BTC-USD","changes":[["buy","9134.75","3009.95680000"]],"time":"2020-06-30T19:26:54.837492Z"}
{"type":"l2update","product_id":"BTC-USD","changes":[["buy","9134.74","4771.00000000"]],"time":"2020-06-30T19:26:54.876525Z"}
{"type":"l2update","product_id":"BTC-USD","changes":[["buy","9134.74","4771.13590000"]],"time":"2020-06-30T19:26:55.461015Z"}
{"type":"l2update","product_id":"BTC-USD","changes":[["sell","9134.77","2960.52500000"]],"time":"2020-06-30T19:26:55.734058Z"}
{"type":"heartbeat","last_trade_id":0,"product_id":"BTC-USD","sequence":180760402,"time":"2020-06-30T19:26:55.735034Z"}
{"type":"l2update","product_id":"BTC-USD","changes":[["buy","9132.98","0.00000000"]],"time":"2020-06-30T19:26:55.910823Z"}
{"type":"l2update","product_id":"BTC-USD","changes":[["sell","9134.77","2960.40000000"]],"time":"2020-06-30T19:26:56.344788Z"}
{"type":"heartbeat","last_trade_id":0,"product_id":"BTC-USD","sequence":180760406,"time":"2020-06-30T19:26:56.735168Z"}
{"type":"l2update","product_id":"BTC-USD","changes":[["buy","9134.76","0.25000000"]],"time":"2020-06-30T19:26:57.434015Z"}
{"type":"l2update","product_id":"BTC-USD","changes":[["sell","9134.77","2960.27500000"]],"time":"2020-06-30T19:26:57.707026Z"}
{"type":"heartbeat","last_trade_id":0,"product_id":"BTC-USD","sequence":180760411,"time":"2020-06-30T19:26:57.735116Z"}
{"type":"l2update","product_id":"BTC-USD","changes":[["buy","9134.74","4771.00000000"]],"time":"2020-06-30T19:26:57.841622Z"}
{"type":"l2update","product_id":"BTC-USD","changes":[["buy","9134.75","3009.83180000"]],"time":"2020-06-30T19:26:58.075624Z"}
{"type":"heartbeat","last_trade_id":0,"product_id":"BTC-USD","sequence":180760413,"time":"2020-06-30T19:26:58.735127Z"}
{"type":"l2update","product_id":"BTC-USD","changes":[["sell","9140.91","1.63800000"]],"time":"2020-06-30T19:26:58.774150Z"}
{"type":"l2update","product_id":"BTC-USD","changes":[["sell","9134.77","2960.22500000"]],"time":"2020-06-30T19:26:59.044507Z"}
{"type":"l2update","product_id":"BTC-USD","changes":[["buy","100.00","114.95500000"]],"time":"2020-06-30T19:26:59.068199Z"}
{"type":"l2update","product_id":"BTC-USD","changes":[["buy","100.00","114.94500000"]],"time":"2020-06-30T19:26:59.074782Z"}
{"type":"l2update","product_id":"BTC-USD","changes":[["sell","9174.86","0.00000000"]],"time":"2020-06-30T19:26:59.236616Z"}
{"type":"l2update","product_id":"BTC-USD","changes":[["sell","9140.98","0.00000000"]],"time":"2020-06-30T19:26:59.268511Z"}
{"type":"l2update","product_id":"BTC-USD","changes":[["sell","9144.48","0.02360000"]],"time":"2020-06-30T19:26:59.448114Z"}
{"type":"l2update","product_id":"BTC-USD","changes":[["buy","9107.71","0.01570000"]],"time":"2020-06-30T19:26:59.503284Z"}
{"type":"l2update","product_id":"BTC-USD","changes":[["sell","9134.77","2960.10000000"]],"time":"2020-06-30T19:26:59.709066Z"}
{"type":"heartbeat","last_trade_id":0,"product_id":"BTC-USD","sequence":180760429,"time":"2020-06-30T19:26:59.735113Z"}
{"type":"l2update","product_id":"BTC-USD","changes":[["sell","9140.91","0.00000000"]],"time":"2020-06-30T19:26:59.872967Z"}
{"type":"l2update","product_id":"BTC-USD","changes":[["buy","9134.75","3009.88180000"]],"time":"2020-06-30T19:26:59.977538Z"}
{"type":"l2update","product_id":"BTC-USD","changes":[["sell","9134.77","2960.05000000"]],"time":"2020-06-30T19:27:00.550329Z"}
{"type":"heartbeat","last_trade_id":0,"product_id":"BTC-USD","sequence":180760435,"time":"2020-06-30T19:27:00.735071Z"}
{"type":"heartbeat","last_trade_id":0,"product_id":"BTC-USD","sequence":180760435,"time":"2020-06-30T19:27:01.735096Z"}
{"type":"l2update","product_id":"BTC-USD","changes":[["sell","9134.77","2959.94530000"]],"time":"2020-06-30T19:27:01.954569Z"}
{"type":"l2update","product_id":"BTC-USD","changes":[["sell","9136.63","0.13510000"]],"time":"2020-06-30T19:27:02.260953Z"}
{"type":"heartbeat","last_trade_id":0,"product_id":"BTC-USD","sequence":180760440,"time":"2020-06-30T19:27:02.735118Z"}
{"type":"l2update","product_id":"BTC-USD","changes":[["sell","9134.98","0.54650000"]],"time":"2020-06-30T19:27:02.750590Z"}
{"type":"l2update","product_id":"BTC-USD","changes":[["sell","9135.06","0.00000000"]],"time":"2020-06-30T19:27:02.782792Z"}
{"type":"l2update","product_id":"BTC-USD","changes":[["sell","9134.77","2959.84060000"]],"time":"2020-06-30T19:27:03.100451Z"}
{"type":"l2update","product_id":"BTC-USD","changes":[["sell","9134.77","2959.73590000"]],"time":"2020-06-30T19:27:03.388229Z"}
{"type":"l2update","product_id":"BTC-USD","changes":[["buy","9106.88","0.00000000"]],"time":"2020-06-30T19:27:03.566439Z"}
{"type":"heartbeat","last_trade_id":0,"product_id":"BTC-USD","sequence":180760449,"time":"2020-06-30T19:27:03.735116Z"}
{"type":"l2update","product_id":"BTC-USD","changes":[["buy","9134.76","0.00000000"]],"time":"2020-06-30T19:27:03.837905Z"}
{"type":"l2update","product_id":"BTC-USD","changes":[["sell","9148.99","0.02360000"]],"time":"2020-06-30T19:27:03.934108Z"}
{"type":"l2update","product_id":"BTC-USD","changes":[["sell","9144.48","0.00000000"]],"time":"2020-06-30T19:27:04.438587Z"}
{"type":"l2update","product_id":"BTC-USD","changes":[["sell","9178.98","0.05450000"]],"time":"2020-06-30T19:27:04.535160Z"}
{"type":"heartbeat","last_trade_id":0,"product_id":"BTC-USD","sequence":180760455,"time":"2020-06-30T19:27:04.735117Z"}
{"type":"l2update","product_id":"BTC-USD","changes":[["sell","9176.71","0.00000000"]],"time":"2020-06-30T19:27:04.978596Z"}
{"type":"l2update","product_id":"BTC-USD","changes":[["buy","9113.63","0.01000000"]],"time":"2020-06-30T19:27:05.370854Z"}
{"type":"l2update","product_id":"BTC-USD","changes":[["sell","9173.91","0.02220000"]],"time":"2020-06-30T19:27:05.691782Z"}
{"type":"heartbeat","last_trade_id":0,"product_id":"BTC-USD","sequence":180760460,"time":"2020-06-30T19:27:05.735113Z"}
{"type":"heartbeat","last_trade_id":0,"product_id":"BTC-USD","sequence":180760460,"time":"2020-06-30T19:27:06.735059Z"}
{"type":"l2update","product_id":"BTC-USD","changes":[["sell","9143.33","0.02360000"]],"time":"2020-06-30T19:27:06.753431Z"}
{"type":"l2update","product_id":"BTC-USD","changes":[["sell","9134.77","2959.63120000"]],"time":"2020-06-30T19:27:07.073347Z"}
{"type":"l2update","product_id":"BTC-USD","changes":[["sell","9136.51","0.11460000"]],"time":"2020-06-30T19:27:07.633302Z"}
{"type":"heartbeat","last_trade_id":0,"product_id":"BTC-USD","sequence":180760467,"time":"2020-06-30T19:27:07.735120Z"}
{"type":"l2update","product_id":"BTC-USD","changes":[["sell","9135.18","0.00000000"]],"time":"2020-06-30T19:27:08.099092Z"}
{"type":"l2update","product_id":"BTC-USD","changes":[["buy","9127.83","4.04400000"]],"time":"2020-06-30T19:27:08.188794Z"}
{"type":"l2update","product_id":"BTC-USD","changes":[["sell","9134.77","2959.56990000"]],"time":"2020-06-30T19:27:08.735231Z"}
{"type":"heartbeat","last_trade_id":0,"product_id":"BTC-USD","sequence":180760473,"time":"2020-06-30T19:27:08.735114Z"}
{"type":"l2update","product_id":"BTC-USD","changes":[["buy","9134.75","3009.83180000"]],"time":"2020-06-30T19:27:08.950967Z"}
{"type":"l2update","product_id":"BTC-USD","changes":[["buy","9113.63","0.00000000"]],"time":"2020-06-30T19:27:08.984705Z"}
{"type":"l2update","product_id":"BTC-USD","changes":[["sell","9134.77","2959.36540000"]],"time":"2020-06-30T19:27:09.550896Z"}
{"type":"heartbeat","last_trade_id":0,"product_id":"BTC-USD","sequence":180760478,"time":"2020-06-30T19:27:09.735121Z"}
{"type":"l2update","product_id":"BTC-USD","changes":[["buy","9112.64","0.04530000"]],"time":"2020-06-30T19:27:10.152446Z"}
{"type":"l2update","product_id":"BTC-USD","changes":[["sell","9140.85","0.00000000"]],"time":"2020-06-30T19:27:10.239780Z"}
{"type":"heartbeat","last_trade_id":0,"product_id":"BTC-USD","sequence":180760481,"time":"2020-06-30T19:27:10.735120Z"}
{"type":"l2update","product_id":"BTC-USD","changes":[["buy","9134.75","3009.83080000"]],"time":"2020-06-30T19:27:11.475888Z"}
{"type":"heartbeat","last_trade_id":0,"product_id":"BTC-USD","sequence":180760484,"time":"2020-06-30T19:27:11.735120Z"}
{"type":"l2update","product_id":"BTC-USD","changes":[["sell","9175.98","0.09660000"]],"time":"2020-06-30T19:27:11.761951Z"}
{"type":"l2update","product_id":"BTC-USD","changes":[["sell","9134.98","0.00000000"]],"time":"2020-06-30T19:27:12.255495Z"}
{"type":"l2update","product_id":"BTC-USD","changes":[["sell","9180.49","0.05450000"]],"time":"2020-06-30T19:27:12.314666Z"}
{"type":"l2update","product_id":"BTC-USD","changes":[["sell","9136.51","0.00000000"]],"time":"2020-06-30T19:27:12.740969Z"}
{"type":"heartbeat","last_trade_id":0,"product_id":"BTC-USD","sequence":180760490,"time":"2020-06-30T19:27:12.735122Z"}
{"type":"l2update","product_id":"BTC-USD","changes":[["buy","9134.50","0.04000000"]],"time":"2020-06-30T19:27:12.862241Z"}
{"type":"l2update","product_id":"BTC-USD","changes":[["sell","9179.74","0.05450000"]],"time":"2020-06-30T19:27:13.122847Z"}
{"type":"l2update","product_id":"BTC-USD","changes":[["sell","9135.90","0.90000000"]],"time":"2020-06-30T19:27:13.423595Z"}
{"type":"l2update","product_id":"BTC-USD","changes":[["buy","9109.35","0.03410000"]],"time":"2020-06-30T19:27:13.665061Z"}
{"type":"heartbeat","last_trade_id":0,"product_id":"BTC-USD","sequence":180760498,"time":"2020-06-30T19:27:13.735111Z"}
{"type":"l2update","product_id":"BTC-USD","changes":[["buy","100.00","114.95500000"]],"time":"2020-06-30T19:27:14.038207Z"}
{"type":"l2update","product_id":"BTC-USD","changes":[["buy","100.00","114.94500000"]],"time":"2020-06-30T19:27:14.044045Z"}
{"type":"l2update","product_id":"BTC-USD","changes":[["sell","9177.98","0.09660000"]],"time":"2020-06-30T19:27:14.225990Z"}
{"type":"l2update","product_id":"BTC-USD","changes":[["sell","9206.54","0.00000000"]],"time":"2020-06-30T19:27:14.399165Z"}
{"type":"l2update","product_id":"BTC-USD","changes":[["sell","9178.98","0.00000000"]],"time":"2020-06-30T19:27:14.677740Z"}
{"type":"heartbeat","last_trade_id":0,"product_id":"BTC-USD","sequence":180760505,"time":"2020-06-30T19:27:14.735124Z"}
{"type":"l2update","product_id":"BTC-USD","changes":[["sell","9135.65","0.05000000"]],"time":"2020-06-30T19:27:15.602029Z"}
{"type":"l2update","product_id":"BTC-USD","changes":[["sell","9140.79","0.00000000"]],"time":"2020-06-30T19:27:15.743749Z"}
{"type":"l2update","product_id":"BTC-USD","changes":[["sell","9180.49","0.00000000"]],"time":"2020-06-30T19:27:15.745236Z"}
{"type":"heartbeat","last_trade_id":0,"product_id":"BTC-USD","sequence":180760509,"time":"2020-06-30T19:27:15.735119Z"}
{"type":"l2update","product_id":"BTC-USD","changes":[["buy","9124.93","0.01220000"]],"time":"2020-06-30T19:27:15.896775Z"}
{"type":"l2update","product_id":"BTC-USD","changes":[["sell","9135.90","0.00000000"]],"time":"2020-06-30T19:27:16.002731Z"}
{"type":"l2update","product_id":"BTC-USD","changes":[["sell","9142.06","0.00670000"]],"time":"2020-06-30T19:27:16.184569Z"}
{"type":"l2update","product_id":"BTC-USD","changes":[["buy","9127.83","0.00000000"]],"time":"2020-06-30T19:27:16.315907Z"}
{"type":"heartbeat","last_trade_id":0,"product_id":"BTC-USD","sequence":180760515,"time":"2020-06-30T19:27:16.735119Z"}
{"type":"l2update","product_id":"BTC-USD","changes":[["sell","9139.66","1.50000000"]],"time":"2020-06-30T19:27:16.784841Z"}
{"type":"l2update","product_id":"BTC-USD","changes":[["sell","9135.85","0.08100000"]],"time":"2020-06-30T19:27:17.072609Z"}
{"type":"l2update","product_id":"BTC-USD","changes":[["buy","9134.76","0.04050000"]],"time":"2020-06-30T19:27:17.339297Z"}
{"type":"l2update","product_id":"BTC-USD","changes":[["buy","9134.75","3009.87130000"]],"time":"2020-06-30T19:27:17.610127Z"}
{"type":"heartbeat","last_trade_id":0,"product_id":"BTC-USD","sequence":180760523,"time":"2020-06-30T19:27:17.735061Z"}
{"type":"l2update","product_id":"BTC-USD","changes":[["buy","9107.71","0.00000000"]],"time":"2020-06-30T19:27:17.831982Z"}
{"type":"l2update","product_id":"BTC-USD","changes":[["buy","9134.76","0.00000000"]],"time":"2020-06-30T19:27:17.920339Z"}
{"type":"l2update","product_id":"BTC-USD","changes":[["sell","9177.46","0.05450000"]],"time":"2020-06-30T19:27:17.924307Z"}
{"type":"l2update","product_id":"BTC-USD","changes":[["sell","9182.07","0.01490000"]],"time":"2020-06-30T19:27:18.339193Z"}
{"type":"l2update","product_id":"BTC-USD","changes":[["buy","9134.57","0.04000000"]],"time":"2020-06-30T19:27:18.476932Z"}
{"type":"heartbeat","last_trade_id":0,"product_id":"BTC-USD","sequence":180760531,"time":"2020-06-30T19:27:18.735095Z"}
{"type":"l2update","product_id":"BTC-USD","changes":[["sell","9175.19","0.05450000"]],"time":"2020-06-30T19:27:18.751986Z"}
{"type":"l2update","product_id":"BTC-USD","changes":[["buy","9134.50","0.00000000"]],"time":"2020-06-30T19:27:18.905336Z"}
{"type":"l2update","product_id":"BTC-USD","changes":[["buy","9111.83","0.00000000"]],"time":"2020-06-30T19:27:18.906930Z"}
{"type":"l2update","product_id":"BTC-USD","changes":[["buy","9133.92","0.14000000"]],"time":"2020-06-30T19:27:19.037274Z"}
{"type":"l2update","product_id":"BTC-USD","changes":[["sell","9179.74","0.00000000"]],"time":"2020-06-30T19:27:19.200260Z"}
{"type":"l2update","product_id":"BTC-USD","changes":[["sell","9135.80","0.00000000"]],"time":"2020-06-30T19:27:19.201142Z"}
{"type":"l2update","product_id":"BTC-USD","changes":[["buy","9112.64","0.00000000"]],"time":"2020-06-30T19:27:19.332032Z"}
{"type":"l2update","product_id":"BTC-USD","changes":[["sell","9134.77","2959.32490000"]],"time":"2020-06-30T19:27:19.573051Z"}
{"type":"heartbeat","last_trade_id":0,"product_id":"BTC-USD","sequence":180760543,"time":"2020-06-30T19:27:19.735118Z"}
{"type":"l2update","product_id":"BTC-USD","changes":[["buy","9123.96","0.03060000"]],"time":"2020-06-30T19:27:19.887239Z"}
{"type":"l2update","product_id":"BTC-USD","changes":[["sell","9135.82","0.08450000"]],"time":"2020-06-30T19:27:20.152395Z"}
{"type":"l2update","product_id":"BTC-USD","changes":[["buy","8861.49","0.00000000"]],"time":"2020-06-30T19:27:20.351651Z"}
{"type":"l2update","product_id":"BTC-USD","changes":[["sell","9154.32","0.10000000"]],"time":"2020-06-30T19:27:20.623083Z"}
{"type":"heartbeat","last_trade_id":0,"product_id":"BTC-USD","sequence":180760549,"time":"2020-06-30T19:27:20.735130Z"}
{"type":"l2update","product_id":"BTC-USD","changes":[["buy","9134.73","6022.28330000"]],"time":"2020-06-30T19:27:20.806956Z"}
{"type":"l2update","product_id":"BTC-USD","changes":[["buy","9124.93","0.00000000"]],"time":"2020-06-30T19:27:20.849115Z"}
{"type":"heartbeat","last_trade_id":0,"product_id":"BTC-USD","sequence":180760552,"time":"2020-06-30T19:27:21.735120Z"}
{"type":"l2update","product_id":"BTC-USD","changes":[["buy","9132.57","0.06570000"]],"time":"2020-06-30T19:27:21.914524Z"}
{"type":"l2update","product_id":"BTC-USD","changes":[["sell","9134.77","2959.29110000"]],"time":"2020-06-30T19:27:22.197863Z"}
{"type":"l2update","product_id":"BTC-USD","changes":[["buy","9132.33","0.00000000"]],"time":"2020-06-30T19:27:22.346894Z"}
{"type":"l2update","product_id":"BTC-USD","changes":[["buy","9123.96","0.00000000"]],"time":"2020-06-30T19:27:22.353056Z"}
{"type":"heartbeat","last_trade_id":0,"product_id":"BTC-USD","sequence":180760559,"time":"2020-06-30T19:27:22.735120Z"}
{"type":"heartbeat","last_trade_id":0,"product_id":"BTC-USD","sequence":180760559,"time":"2020-06-30T19:27:23.735098Z"}
{"type":"l2update","product_id":"BTC-USD","changes":[["buy","9114.39","0.01990000"]],"time":"2020-06-30T19:27:23.853891Z"}
{"type":"l2update","product_id":"BTC-USD","changes":[["sell","9135.43","0.16260000"]],"time":"2020-06-30T19:27:24.128269Z"}
{"type":"l2update","product_id":"BTC-USD","changes":[["buy","9132.57","0.00000000"]],"time":"2020-06-30T19:27:24.334594Z"}
{"type":"l2update","product_id":"BTC-USD","changes":[["sell","9134.77","2959.24110000"]],"time":"2020-06-30T19:27:24.390395Z"}
{"type":"l2update","product_id":"BTC-USD","changes":[["sell","9182.07","0.00000000"]],"time":"2020-06-30T19:27:24.580450Z"}
{"type":"heartbeat","last_trade_id":0,"product_id":"BTC-USD","sequence":180760568,"time":"2020-06-30T19:27:24.735095Z"}
{"type":"l2update","product_id":"BTC-USD","changes":[["buy","9134.75","3009.83080000"]],"time":"2020-06-30T19:27:24.873568Z"}
{"type":"l2update","product_id":"BTC-USD","changes":[["buy","9114.39","0.00000000"]],"time":"2020-06-30T19:27:24.878226Z"}
{"type":"l2update","product_id":"BTC-USD","changes":[["sell","9134.77","2959.19110000"]],"time":"2020-06-30T19:27:24.970050Z"}
{"type":"l2update","product_id":"BTC-USD","changes":[["buy","9132.39","0.75000000"]],"time":"2020-06-30T19:27:25.507541Z"}
{"type":"heartbeat","last_trade_id":0,"product_id":"BTC-USD","sequence":180760575,"time":"2020-06-30T19:27:25.735113Z"}
{"type":"l2update","product_id":"BTC-USD","changes":[["sell","9134.77","2959.14110000"]],"time":"2020-06-30T19:27:25.795455Z"}
{"type":"l2update","product_id":"BTC-USD","changes":[["buy","9134.73","6020.00000000"]],"time":"2020-06-30T19:27:26.054999Z"}
{"type":"l2update","product_id":"BTC-USD","changes":[["buy","9111.41","0.01570000"]],"time":"2020-06-30T19:27:26.609631Z"}
{"type":"heartbeat","last_trade_id":0,"product_id":"BTC-USD","sequence":180760581,"time":"2020-06-30T19:27:26.735115Z"}
{"type":"l2update","product_id":"BTC-USD","changes":[["buy","9130.50","0.06570000"]],"time":"2020-06-30T19:27:26.940980Z"}
{"type":"l2update","product_id":"BTC-USD","changes":[["sell","9187.69","0.00100000"]],"time":"2020-06-30T19:27:27.455488Z"}
{"type":"heartbeat","last_trade_id":0,"product_id":"BTC-USD","sequence":180760585,"time":"2020-06-30T19:27:27.735115Z"}
{"type":"l2update","product_id":"BTC-USD","changes":[["sell","9148.99","0.00000000"]],"time":"2020-06-30T19:27:27.874876Z"}
{"type":"l2update","product_id":"BTC-USD","changes":[["sell","9185.34","0.02220000"]],"time":"2020-06-30T19:27:28.315781Z"}
{"type":"heartbeat","last_trade_id":0,"product_id":"BTC-USD","sequence":180760588,"time":"2020-06-30T19:27:28.735115Z"}
{"type":"l2update","product_id":"BTC-USD","changes":[["sell","9143.33","0.00000000"]],"time":"2020-06-30T19:27:28.749744Z"}
{"type":"l2update","product_id":"BTC-USD","changes":[["buy","100.00","114.95500000"]],"time":"2020-06-30T19:27:29.018055Z"}
{"type":"l2update","product_id":"BTC-USD","changes":[["buy","100.00","114.94500000"]],"time":"2020-06-30T19:27:29.027536Z"}
{"type":"heartbeat","last_trade_id":0,"product_id":"BTC-USD","sequence":180760592,"time":"2020-06-30T19:27:29.735115Z"}
{"type":"l2update","product_id":"BTC-USD","changes":[["sell","9134.77","2959.09110000"]],"time":"2020-06-30T19:27:29.962492Z"}
{"type":"heartbeat","last_trade_id":0,"product_id":"BTC-USD","sequence":180760595,"time":"2020-06-30T19:27:30.735116Z"}
{"type":"l2update","product_id":"BTC-USD","changes":[["sell","9181.25","0.05450000"]],"time":"2020-06-30T19:27:31.156606Z"}
{"type":"l2update","product_id":"BTC-USD","changes":[["sell","9175.19","0.00000000"]],"time":"2020-06-30T19:27:31.340248Z"}
{"type":"l2update","product_id":"BTC-USD","changes":[["sell","9176.65","0.09660000"]],"time":"2020-06-30T19:27:31.413082Z"}
{"type":"heartbeat","last_trade_id":0,"product_id":"BTC-USD","sequence":180760600,"time":"2020-06-30T19:27:31.735055Z"}
{"type":"l2update","product_id":"BTC-USD","changes":[["sell","9175.98","0.00000000"]],"time":"2020-06-30T19:27:31.857218Z"}
{"type":"l2update","product_id":"BTC-USD","changes":[["sell","9136.63","0.00000000"]],"time":"2020-06-30T19:27:31.863187Z"}
{"type":"heartbeat","last_trade_id":0,"product_id":"BTC-USD","sequence":180760602,"time":"2020-06-30T19:27:32.735067Z"}
{"type":"l2update","product_id":"BTC-USD","changes":[["sell","9185.06","0.06880000"]],"time":"2020-06-30T19:27:32.878467Z"}
{"type":"l2update","product_id":"BTC-USD","changes":[["sell","9135.38","0.03150000"]],"time":"2020-06-30T19:27:33.202261Z"}
{"type":"l2update","product_id":"BTC-USD","changes":[["sell","9135.65","0.00000000"]],"time":"2020-06-30T19:27:33.340419Z"}
{"type":"l2update","product_id":"BTC-USD","changes":[["sell","9139.66","0.00000000"]],"time":"2020-06-30T19:27:33.615680Z"}
{"type":"l2update","product_id":"BTC-USD","changes":[["sell","9181.25","0.00000000"]],"time":"2020-06-30T19:27:33.622626Z"}
{"type":"heartbeat","last_trade_id":0,"product_id":"BTC-USD","sequence":180760609,"time":"2020-06-30T19:27:33.735117Z"}
{"type":"l2update","product_id":"BTC-USD","changes":[["sell","9183.13","0.01490000"]],"time":"2020-06-30T19:27:33.787842Z"}
{"type":"heartbeat","last_trade_id":0,"product_id":"BTC-USD","sequence":180760611,"time":"2020-06-30T19:27:34.735128Z"}
{"type":"l2update","product_id":"BTC-USD","changes":[["buy","9131.86","0.75000000"]],"time":"2020-06-30T19:27:35.358237Z"}
{"type":"l2update","product_id":"BTC-USD","changes":[["sell","9177.34","0.05310000"]],"time":"2020-06-30T19:27:35.629045Z"}
{"type":"heartbeat","last_trade_id":0,"product_id":"BTC-USD","sequence":180760615,"time":"2020-06-30T19:27:35.735101Z"}
{"type":"l2update","product_id":"BTC-USD","changes":[["sell","9149.73","1.08510000"]],"time":"2020-06-30T19:27:35.915287Z"}
{"type":"l2update","product_id":"BTC-USD","changes":[["sell","9177.46","0.00000000"]],"time":"2020-06-30T19:27:36.103127Z"}
{"type":"l2update","product_id":"BTC-USD","changes":[["sell","9183.13","0.00000000"]],"time":"2020-06-30T19:27:36.113195Z"}
{"type":"l2update","product_id":"BTC-USD","changes":[["sell","9135.85","0.00000000"]],"time":"2020-06-30T19:27:36.387934Z"}
{"type":"l2update","product_id":"BTC-USD","changes":[["sell","9135.43","0.28640000"]],"time":"2020-06-30T19:27:36.456018Z"}
{"type":"heartbeat","last_trade_id":0,"product_id":"BTC-USD","sequence":180760622,"time":"2020-06-30T19:27:36.735113Z"}
{"type":"l2update","product_id":"BTC-USD","changes":[["buy","9110.18","0.01570000"]],"time":"2020-06-30T19:27:37.325368Z"}
{"type":"l2update","product_id":"BTC-USD","changes":[["buy","9116.35","1.18580000"]],"time":"2020-06-30T19:27:37.605854Z"}
{"type":"heartbeat","last_trade_id":0,"product_id":"BTC-USD","sequence":180760626,"time":"2020-06-30T19:27:37.735113Z"}
{"type":"l2update","product_id":"BTC-USD","changes":[["buy","9131.86","0.00000000"]],"time":"2020-06-30T19:27:38.041816Z"}
{"type":"l2update","product_id":"BTC-USD","changes":[["buy","9110.18","0.00000000"]],"time":"2020-06-30T19:27:38.049721Z"}
{"type":"l2update","product_id":"BTC-USD","changes":[["sell","9183.13","0.06880000"]],"time":"2020-06-30T19:27:38.498126Z"}
{"type":"heartbeat","last_trade_id":0,"product_id":"BTC-USD","sequence":180760630,"time":"2020-06-30T19:27:38.735115Z"}
{"type":"l2update","product_id":"BTC-USD","changes":[["sell","9134.77","2958.33630000"]],"time":"2020-06-30T19:27:38.748003Z"}
{"type":"l2update","product_id":"BTC-USD","changes":[["sell","9149.73","0.00000000"]],"time":"2020-06-30T19:27:38.932486Z"}
{"type":"l2update","product_id":"BTC-USD","changes":[["sell","9187.69","0.00000000"]],"time":"2020-06-30T19:27:38.933511Z"}
{"type":"l2update","product_id":"BTC-USD","changes":[["buy","9134.57","0.00000000"]],"time":"2020-06-30T19:27:39.179327Z"}
{"type":"heartbeat","last_trade_id":0,"product_id":"BTC-USD","sequence":180760636,"time":"2020-06-30T19:27:39.735113Z"}
{"type":"l2update","product_id":"BTC-USD","changes":[["buy","8904.84","0.00000000"]],"time":"2020-06-30T19:27:40.577819Z"}
{"type":"heartbeat","last_trade_id":0,"product_id":"BTC-USD","sequence":180760637,"time":"2020-06-30T19:27:40.735110Z"}
{"type":"l2update","product_id":"BTC-USD","changes":[["buy","8904.08","0.04519700"]],"time":"2020-06-30T19:27:40.921240Z"}
{"type":"l2update","product_id":"BTC-USD","changes":[["sell","9134.77","2958.33530000"]],"time":"2020-06-30T19:27:41.070296Z"}
{"type":"l2update","product_id":"BTC-USD","changes":[["sell","9425.47","0.00000000"]],"time":"2020-06-30T19:27:41.706554Z"}
{"type":"l2update","product_id":"BTC-USD","changes":[["buy","9126.96","0.02220000"]],"time":"2020-06-30T19:27:41.743008Z"}
{"type":"heartbeat","last_trade_id":0,"product_id":"BTC-USD","sequence":180760645,"time":"2020-06-30T19:27:41.735111Z"}
{"type":"l2update","product_id":"BTC-USD","changes":[["sell","9426.28","0.00596998"]],"time":"2020-06-30T19:27:42.099881Z"}
{"type":"l2update","product_id":"BTC-USD","changes":[["buy","9109.35","0.00000000"]],"time":"2020-06-30T19:27:42.178956Z"}
{"type":"l2update","product_id":"BTC-USD","changes":[["buy","9116.35","0.00000000"]],"time":"2020-06-30T19:27:42.183827Z"}
{"type":"l2update","product_id":"BTC-USD","changes":[["sell","9135.90","0.94550000"]],"time":"2020-06-30T19:27:42.289726Z"}
{"type":"l2update","product_id":"BTC-USD","changes":[["sell","9142.06","0.00000000"]],"time":"2020-06-30T19:27:42.732401Z"}
{"type":"heartbeat","last_trade_id":0,"product_id":"BTC-USD","sequence":180760652,"time":"2020-06-30T19:27:42.735075Z"}
{"type":"l2update","product_id":"BTC-USD","changes":[["buy","9133.67","0.75000000"]],"time":"2020-06-30T19:27:42.880130Z"}
{"type":"l2update","product_id":"BTC-USD","changes":[["sell","9134.77","2958.24180000"]],"time":"2020-06-30T19:27:43.422290Z"}
{"type":"heartbeat","last_trade_id":0,"product_id":"BTC-USD","sequence":180760657,"time":"2020-06-30T19:27:43.735088Z"}
{"type":"l2update","product_id":"BTC-USD","changes":[["buy","100.00","114.95500000"]],"time":"2020-06-30T19:27:44.046779Z"}
{"type":"l2update","product_id":"BTC-USD","changes":[["buy","100.00","114.94500000"]],"time":"2020-06-30T19:27:44.053114Z"}
{"type":"l2update","product_id":"BTC-USD","changes":[["buy","9132.39","0.00000000"]],"time":"2020-06-30T19:27:44.120332Z"}
{"type":"heartbeat","last_trade_id":0,"product_id":"BTC-USD","sequence":180760661,"time":"2020-06-30T19:27:44.735120Z"}
{"type":"l2update","product_id":"BTC-USD","changes":[["sell","9140.44","0.00670000"]],"time":"2020-06-30T19:27:44.824364Z"}
{"type":"l2update","product_id":"BTC-USD","changes":[["sell","9176.65","0.00000000"]],"time":"2020-06-30T19:27:45.342181Z"}
{"type":"heartbeat","last_trade_id":0,"product_id":"BTC-USD","sequence":180760664,"time":"2020-06-30T19:27:45.735099Z"}
{"type":"l2update","product_id":"BTC-USD","changes":[["sell","9183.13","0.00000000"]],"time":"2020-06-30T19:27:45.826522Z"}
{"type":"l2update","product_id":"BTC-USD","changes":[["sell","9138.68","0.06570000"]],"time":"2020-06-30T19:27:46.259843Z"}
{"type":"l2update","product_id":"BTC-USD","changes":[["sell","9134.77","2958.19180000"]],"time":"2020-06-30T19:27:46.729229Z"}
{"type":"heartbeat","last_trade_id":0,"product_id":"BTC-USD","sequence":180760670,"time":"2020-06-30T19:27:46.734995Z"}
{"type":"l2update","product_id":"BTC-USD","changes":[["sell","9184.24","0.06880000"]],"time":"2020-06-30T19:27:46.883999Z"}
{"type":"heartbeat","last_trade_id":0,"product_id":"BTC-USD","sequence":180760672,"time":"2020-06-30T19:27:47.735142Z"}
{"type":"l2update","product_id":"BTC-USD","changes":[["sell","9184.24","0.00000000"]],"time":"2020-06-30T19:27:47.891350Z"}
{"type":"l2update","product_id":"BTC-USD","changes":[["sell","9135.43","0.12380000"]],"time":"2020-06-30T19:27:47.899543Z"}
{"type":"l2update","product_id":"BTC-USD","changes":[["buy","9134.73","6022.33230000"]],"time":"2020-06-30T19:27:48.285739Z"}
{"type":"l2update","product_id":"BTC-USD","changes":[["sell","9177.44","0.02220000"]],"time":"2020-06-30T19:27:48.394391Z"}
{"type":"heartbeat","last_trade_id":0,"product_id":"BTC-USD","sequence":180760678,"time":"2020-06-30T19:27:48.735097Z"}
{"type":"l2update","product_id":"BTC-USD","changes":[["buy","9132.38","3.00000000"]],"time":"2020-06-30T19:27:48.881804Z"}
{"type":"l2update","product_id":"BTC-USD","changes":[["sell","9135.38","0.59300000"]],"time":"2020-06-30T19:27:49.437458Z"}
{"type":"l2update","product_id":"BTC-USD","changes":[["sell","9185.34","0.00000000"]],"time":"2020-06-30T19:27:49.628875Z"}
{"type":"l2update","product_id":"BTC-USD","changes":[["sell","9177.34","0.00000000"]],"time":"2020-06-30T19:27:49.629203Z"}
{"type":"l2update","product_id":"BTC-USD","changes":[["buy","8949.55","0.00400000"]],"time":"2020-06-30T19:27:49.747030Z"}
{"type":"heartbeat","last_trade_id":0,"product_id":"BTC-USD","sequence":180760686,"time":"2020-06-30T19:27:49.734998Z"}
{"type":"l2update","product_id":"BTC-USD","changes":[["sell","9176.01","0.09660000"]],"time":"2020-06-30T19:27:50.000010Z"}
{"type":"l2update","product_id":"BTC-USD","changes":[["sell","9138.66","0.06570000"]],"time":"2020-06-30T19:27:50.304904Z"}
{"type":"l2update","product_id":"BTC-USD","changes":[["sell","9138.68","0.00000000"]],"time":"2020-06-30T19:27:50.454092Z"}
{"type":"l2update","product_id":"BTC-USD","changes":[["buy","9117.68","0.01480000"]],"time":"2020-06-30T19:27:50.567176Z"}
{"type":"heartbeat","last_trade_id":0,"product_id":"BTC-USD","sequence":180760693,"time":"2020-06-30T19:27:50.734989Z"}
{"type":"l2update","product_id":"BTC-USD","changes":[["buy","9133.92","0.00000000"]],"time":"2020-06-30T19:27:51.008141Z"}
{"type":"l2update","product_id":"BTC-USD","changes":[["sell","9135.63","0.09750000"]],"time":"2020-06-30T19:27:51.505125Z"}
{"type":"l2update","product_id":"BTC-USD","changes":[["buy","9126.96","0.00000000"]],"time":"2020-06-30T19:27:51.736168Z"}
{"type":"heartbeat","last_trade_id":0,"product_id":"BTC-USD","sequence":180760697,"time":"2020-06-30T19:27:51.735013Z"}
{"type":"l2update","product_id":"BTC-USD","changes":[["sell","9154.32","0.00000000"]],"time":"2020-06-30T19:27:51.939205Z"}
{"type":"l2update","product_id":"BTC-USD","changes":[["sell","9138.61","0.06570000"]],"time":"2020-06-30T19:27:52.461407Z"}
{"type":"l2update","product_id":"BTC-USD","changes":[["sell","9135.38","0.03150000"]],"time":"2020-06-30T19:27:52.650276Z"}
{"type":"heartbeat","last_trade_id":0,"product_id":"BTC-USD","sequence":180760701,"time":"2020-06-30T19:27:52.735177Z"}
{"type":"l2update","product_id":"BTC-USD","changes":[["buy","9126.96","0.02220000"]],"time":"2020-06-30T19:27:52.748411Z"}
{"type":"l2update","product_id":"BTC-USD","changes":[["buy","9108.94","0.05000000"]],"time":"2020-06-30T19:27:53.027989Z"}
{"type":"l2update","product_id":"BTC-USD","changes":[["buy","9133.67","0.00000000"]],"time":"2020-06-30T19:27:53.227981Z"}
{"type":"l2update","product_id":"BTC-USD","changes":[["buy","9108.94","0.10000000"]],"time":"2020-06-30T19:27:53.297534Z"}
{"type":"heartbeat","last_trade_id":0,"product_id":"BTC-USD","sequence":180760708,"time":"2020-06-30T19:27:53.735114Z"}
{"type":"l2update","product_id":"BTC-USD","changes":[["buy","9110.18","0.05330000"]],"time":"2020-06-30T19:27:54.153647Z"}
{"type":"l2update","product_id":"BTC-USD","changes":[["sell","9139.65","0.10000000"]],"time":"2020-06-30T19:27:54.472796Z"}
{"type":"heartbeat","last_trade_id":0,"product_id":"BTC-USD","sequence":180760712,"time":"2020-06-30T19:27:54.735122Z"}
{"type":"l2update","product_id":"BTC-USD","changes":[["sell","9140.89","0.00670000"]],"time":"2020-06-30T19:27:54.790377Z"}
{"type":"l2update","product_id":"BTC-USD","changes":[["sell","9140.44","0.00000000"]],"time":"2020-06-30T19:27:54.915138Z"}
{"type":"l2update","product_id":"BTC-USD","changes":[["sell","9173.91","0.00000000"]],"time":"2020-06-30T19:27:54.918643Z"}
{"type":"l2update","product_id":"BTC-USD","changes":[["sell","9135.63","0.00000000"]],"time":"2020-06-30T19:27:54.922515Z"}
{"type":"l2update","product_id":"BTC-USD","changes":[["sell","9138.61","0.00000000"]],"time":"2020-06-30T19:27:54.932589Z"}
{"type":"l2update","product_id":"BTC-USD","changes":[["sell","9135.38","0.38240000"]],"time":"2020-06-30T19:27:55.033967Z"}
{"type":"l2update","product_id":"BTC-USD","changes":[["sell","9135.38","0.35090000"]],"time":"2020-06-30T19:27:55.243799Z"}
{"type":"l2update","product_id":"BTC-USD","changes":[["buy","9130.22","2.43000000"]],"time":"2020-06-30T19:27:55.307524Z"}
{"type":"heartbeat","last_trade_id":0,"product_id":"BTC-USD","sequence":180760723,"time":"2020-06-30T19:27:55.735107Z"}
{"type":"l2update","product_id":"BTC-USD","changes":[["buy","9132.38","0.00000000"]],"time":"2020-06-30T19:27:55.779548Z"}
{"type":"l2update","product_id":"BTC-USD","changes":[["sell","9184.38","0.02220000"]],"time":"2020-06-30T19:27:55.886551Z"}
{"type":"l2update","product_id":"BTC-USD","changes":[["sell","9135.38","0.00000000"]],"time":"2020-06-30T19:27:56.314517Z"}
{"type":"l2update","product_id":"BTC-USD","changes":[["sell","9134.77","2957.22280000"]],"time":"2020-06-30T19:27:56.411970Z"}
{"type":"l2update","product_id":"BTC-USD","changes":[["sell","9135.82","0.00000000"]],"time":"2020-06-30T19:27:56.547637Z"}
{"type":"l2update","product_id":"BTC-USD","changes":[["buy","9125.35","0.06570000"]],"time":"2020-06-30T19:27:56.711618Z"}
{"type":"heartbeat","last_trade_id":0,"product_id":"BTC-USD","sequence":180760733,"time":"2020-06-30T19:27:56.735127Z"}
{"type":"l2update","product_id":"BTC-USD","changes":[["buy","9108.94","0.05000000"]],"time":"2020-06-30T19:27:56.884788Z"}
{"type":"l2update","product_id":"BTC-USD","changes":[["sell","9181.09","0.06880000"]],"time":"2020-06-30T19:27:57.257690Z"}
{"type":"l2update","product_id":"BTC-USD","changes":[["sell","9135.43","0.00000000"]],"time":"2020-06-30T19:27:57.692106Z"}
{"type":"heartbeat","last_trade_id":0,"product_id":"BTC-USD","sequence":180760737,"time":"2020-06-30T19:27:57.735117Z"}
{"type":"l2update","product_id":"BTC-USD","changes":[["sell","9179.15","0.06880000"]],"time":"2020-06-30T19:27:58.103283Z"}
{"type":"l2update","product_id":"BTC-USD","changes":[["sell","9185.06","0.00000000"]],"time":"2020-06-30T19:27:58.548582Z"}
{"type":"l2update","product_id":"BTC-USD","changes":[["sell","9181.09","0.00000000"]],"time":"2020-06-30T19:27:58.562114Z"}
{"type":"l2update","product_id":"BTC-USD","changes":[["sell","9138.60","0.84450000"]],"time":"2020-06-30T19:27:58.728445Z"}
{"type":"heartbeat","last_trade_id":0,"product_id":"BTC-USD","sequence":180760743,"time":"2020-06-30T19:27:58.735111Z"}
{"type":"l2update","product_id":"BTC-USD","changes":[["buy","100.00","114.95500000"]],"time":"2020-06-30T19:27:59.040938Z"}
{"type":"l2update","product_id":"BTC-USD","changes":[["buy","100.00","114.94500000"]],"time":"2020-06-30T19:27:59.048033Z"}
{"type":"heartbeat","last_trade_id":0,"product_id":"BTC-USD","sequence":180760746,"time":"2020-06-30T19:27:59.735101Z"}
{"type":"l2update","product_id":"BTC-USD","changes":[["sell","9138.58","0.84450000"]],"time":"2020-06-30T19:27:59.854851Z"}
{"type":"l2update","product_id":"BTC-USD","changes":[["buy","8949.55","0.00000000"]],"time":"2020-06-30T19:27:59.876479Z"}
{"type":"l2update","product_id":"BTC-USD","changes":[["sell","9177.31","0.09660000"]],"time":"2020-06-30T19:28:00.160642Z"}
{"type":"l2update","product_id":"BTC-USD","changes":[["sell","9140.89","0.00000000"]],"time":"2020-06-30T19:28:00.329702Z"}
{"type":"l2update","product_id":"BTC-USD","changes":[["sell","9134.77","2956.75530000"]],"time":"2020-06-30T19:28:00.426872Z"}
{"type":"l2update","product_id":"BTC-USD","changes":[["sell","9139.65","0.00000000"]],"time":"2020-06-30T19:28:00.585087Z"}
{"type":"heartbeat","last_trade_id":0,"product_id":"BTC-USD","sequence":180760756,"time":"2020-06-30T19:28:00.735094Z"}
{"type":"l2update","product_id":"BTC-USD","changes":[["buy","9125.35","0.00000000"]],"time":"2020-06-30T19:28:00.975051Z"}
{"type":"l2update","product_id":"BTC-USD","changes":[["buy","9130.22","0.00000000"]],"time":"2020-06-30T19:28:00.993534Z"}
{"type":"l2update","product_id":"BTC-USD","changes":[["sell","9176.32","0.02780000"]],"time":"2020-06-30T19:28:01.062313Z"}
{"type":"l2update","product_id":"BTC-USD","changes":[["sell","9135.38","0.83400000"]],"time":"2020-06-30T19:28:01.267050Z"}
{"type":"l2update","product_id":"BTC-USD","changes":[["sell","9138.60","0.00000000"]],"time":"2020-06-30T19:28:01.493109Z"}
{"type":"heartbeat","last_trade_id":0,"product_id":"BTC-USD","sequence":180760763,"time":"2020-06-30T19:28:01.735062Z"}
{"type":"l2update","product_id":"BTC-USD","changes":[["sell","9135.38","1.39180000"]],"time":"2020-06-30T19:28:01.916659Z"}
{"type":"l2update","product_id":"BTC-USD","changes":[["sell","9135.38","1.93660000"]],"time":"2020-06-30T19:28:02.158444Z"}
{"type":"l2update","product_id":"BTC-USD","changes":[["sell","9135.90","0.00000000"]],"time":"2020-06-30T19:28:02.346177Z"}
{"type":"l2update","product_id":"BTC-USD","changes":[["sell","9176.32","0.00000000"]],"time":"2020-06-30T19:28:02.693995Z"}
{"type":"heartbeat","last_trade_id":0,"product_id":"BTC-USD","sequence":180760769,"time":"2020-06-30T19:28:02.735119Z"}
{"type":"l2update","product_id":"BTC-USD","changes":[["buy","9130.28","0.06570000"]],"time":"2020-06-30T19:28:02.969961Z"}
{"type":"l2update","product_id":"BTC-USD","changes":[["sell","9138.62","0.84450000"]],"time":"2020-06-30T19:28:03.086500Z"}
{"type":"l2update","product_id":"BTC-USD","changes":[["buy","9117.68","0.00000000"]],"time":"2020-06-30T19:28:03.292106Z"}
{"type":"l2update","product_id":"BTC-USD","changes":[["buy","9134.73","6020.00000000"]],"time":"2020-06-30T19:28:03.305247Z"}
{"type":"heartbeat","last_trade_id":0,"product_id":"BTC-USD","sequence":180760775,"time":"2020-06-30T19:28:03.735126Z"}
{"type":"heartbeat","last_trade_id":0,"product_id":"BTC-USD","sequence":180760775,"time":"2020-06-30T19:28:04.735113Z"}
{"type":"l2update","product_id":"BTC-USD","changes":[["sell","9138.55","0.06570000"]],"time":"2020-06-30T19:28:05.418866Z"}
{"type":"l2update","product_id":"BTC-USD","changes":[["buy","9132.55","0.06570000"]],"time":"2020-06-30T19:28:05.704761Z"}
{"type":"heartbeat","last_trade_id":0,"product_id":"BTC-USD","sequence":180760779,"time":"2020-06-30T19:28:05.735115Z"}
{"type":"l2update","product_id":"BTC-USD","changes":[["buy","9124.36","0.03060000"]],"time":"2020-06-30T19:28:05.916335Z"}
{"type":"l2update","product_id":"BTC-USD","changes":[["buy","9111.41","0.00000000"]],"time":"2020-06-30T19:28:06.114501Z"}
{"type":"l2update","product_id":"BTC-USD","changes":[["buy","9110.18","0.00000000"]],"time":"2020-06-30T19:28:06.323632Z"}
{"type":"l2update","product_id":"BTC-USD","changes":[["sell","9134.77","2956.63030000"]],"time":"2020-06-30T19:28:06.462075Z"}
{"type":"heartbeat","last_trade_id":0,"product_id":"BTC-USD","sequence":180760786,"time":"2020-06-30T19:28:06.735131Z"}
{"type":"l2update","product_id":"BTC-USD","changes":[["sell","9135.38","2.14120000"]],"time":"2020-06-30T19:28:06.769386Z"}
{"type":"l2update","product_id":"BTC-USD","changes":[["buy","9125.38","0.06570000"]],"time":"2020-06-30T19:28:07.053296Z"}
{"type":"l2update","product_id":"BTC-USD","changes":[["sell","9135.38","1.59640000"]],"time":"2020-06-30T19:28:07.221980Z"}
{"type":"l2update","product_id":"BTC-USD","changes":[["sell","9179.15","0.00000000"]],"time":"2020-06-30T19:28:07.233947Z"}
{"type":"l2update","product_id":"BTC-USD","changes":[["buy","9076.00","0.01160000"]],"time":"2020-06-30T19:28:07.318776Z"}
{"type":"l2update","product_id":"BTC-USD","changes":[["sell","9135.38","1.76800000"]],"time":"2020-06-30T19:28:07.607236Z"}
{"type":"heartbeat","last_trade_id":0,"product_id":"BTC-USD","sequence":180760796,"time":"2020-06-30T19:28:07.735118Z"}
{"type":"l2update","product_id":"BTC-USD","changes":[["buy","9126.96","0.00000000"]],"time":"2020-06-30T19:28:07.811990Z"}
{"type":"l2update","product_id":"BTC-USD","changes":[["sell","9135.38","1.21020000"]],"time":"2020-06-30T19:28:08.054910Z"}
{"type":"l2update","product_id":"BTC-USD","changes":[["sell","9184.38","0.00000000"]],"time":"2020-06-30T19:28:08.071548Z"}
{"type":"l2update","product_id":"BTC-USD","changes":[["sell","9154.32","0.01120000"]],"time":"2020-06-30T19:28:08.153241Z"}
{"type":"l2update","product_id":"BTC-USD","changes":[["sell","9181.94","0.02220000"]],"time":"2020-06-30T19:28:08.430302Z"}
{"type":"l2update","product_id":"BTC-USD","changes":[["sell","9176.01","0.00000000"]],"time":"2020-06-30T19:28:08.608682Z"}
{"type":"l2update","product_id":"BTC-USD","changes":[["buy","9110.18","0.07320000"]],"time":"2020-06-30T19:28:08.707389Z"}
{"type":"heartbeat","last_trade_id":0,"product_id":"BTC-USD","sequence":180760806,"time":"2020-06-30T19:28:08.735114Z"}
{"type":"l2update","product_id":"BTC-USD","changes":[["sell","9134.77","2956.16380000"]],"time":"2020-06-30T19:28:08.987229Z"}
{"type":"l2update","product_id":"BTC-USD","changes":[["buy","9109.76","0.54890000"]],"time":"2020-06-30T19:28:09.271272Z"}
{"type":"l2update","product_id":"BTC-USD","changes":[["sell","9135.38","1.74590000"]],"time":"2020-06-30T19:28:09.558157Z"}
{"type":"heartbeat","last_trade_id":0,"product_id":"BTC-USD","sequence":180760813,"time":"2020-06-30T19:28:09.735028Z"}
{"type":"l2update","product_id":"BTC-USD","changes":[["buy","9110.18","0.21840000"]],"time":"2020-06-30T19:28:10.133110Z"}
{"type":"l2update","product_id":"BTC-USD","changes":[["buy","9125.38","0.00000000"]],"time":"2020-06-30T19:28:10.565099Z"}
{"type":"heartbeat","last_trade_id":0,"product_id":"BTC-USD","sequence":180760816,"time":"2020-06-30T19:28:10.735168Z"}
{"type":"l2update","product_id":"BTC-USD","changes":[["buy","9134.75","3009.82980000"]],"time":"2020-06-30T19:28:11.080722Z"}
{"type":"heartbeat","last_trade_id":0,"product_id":"BTC-USD","sequence":180760819,"time":"2020-06-30T19:28:11.735121Z"}
{"type":"heartbeat","last_trade_id":0,"product_id":"BTC-USD","sequence":180760819,"time":"2020-06-30T19:28:12.735114Z"}
{"type":"l2update","product_id":"BTC-USD","changes":[["buy","9109.98","0.01000000"]],"time":"2020-06-30T19:28:13.162112Z"}
{"type":"l2update","product_id":"BTC-USD","changes":[["buy","9132.54","0.06570000"]],"time":"2020-06-30T19:28:13.437631Z"}
{"type":"l2update","product_id":"BTC-USD","changes":[["buy","9076.00","0.00000000"]],"time":"2020-06-30T19:28:13.603432Z"}
{"type":"l2update","product_id":"BTC-USD","changes":[["buy","9109.76","0.00000000"]],"time":"2020-06-30T19:28:13.606666Z"}
{"type":"l2update","product_id":"BTC-USD","changes":[["buy","9110.18","0.14520000"]],"time":"2020-06-30T19:28:13.623987Z"}
{"type":"l2update","product_id":"BTC-USD","changes":[["buy","9110.18","0.00000000"]],"time":"2020-06-30T19:28:13.633004Z"}
{"type":"heartbeat","last_trade_id":0,"product_id":"BTC-USD","sequence":180760827,"time":"2020-06-30T19:28:13.735111Z"}
{"type":"l2update","product_id":"BTC-USD","changes":[["buy","100.00","114.95500000"]],"time":"2020-06-30T19:28:14.021252Z"}
{"type":"l2update","product_id":"BTC-USD","changes":[["buy","100.00","114.94500000"]],"time":"2020-06-30T19:28:14.027069Z"}
{"type":"l2update","product_id":"BTC-USD","changes":[["buy","9108.53","1.21160000"]],"time":"2020-06-30T19:28:14.272438Z"}
{"type":"l2update","product_id":"BTC-USD","changes":[["buy","9132.54","0.00000000"]],"time":"2020-06-30T19:28:14.714543Z"}
{"type":"heartbeat","last_trade_id":0,"product_id":"BTC-USD","sequence":180760833,"time":"2020-06-30T19:28:14.735133Z"}
{"type":"l2update","product_id":"BTC-USD","changes":[["buy","9109.98","0.00000000"]],"time":"2020-06-30T19:28:14.761780Z"}
{"type":"l2update","product_id":"BTC-USD","changes":[["sell","9138.55","0.00000000"]],"time":"2020-06-30T19:28:15.037874Z"}
{"type":"l2update","product_id":"BTC-USD","changes":[["sell","9138.58","0.00000000"]],"time":"2020-06-30T19:28:15.040277Z"}
{"type":"l2update","product_id":"BTC-USD","changes":[["buy","9132.33","3.60420000"]],"time":"2020-06-30T19:28:15.140175Z"}
{"type":"l2update","product_id":"BTC-USD","changes":[["buy","9132.63","0.06570000"]],"time":"2020-06-30T19:28:15.428110Z"}
{"type":"l2update","product_id":"BTC-USD","changes":[["buy","9109.35","0.01570000"]],"time":"2020-06-30T19:28:15.694695Z"}
{"type":"heartbeat","last_trade_id":0,"product_id":"BTC-USD","sequence":180760842,"time":"2020-06-30T19:28:15.735112Z"}
{"type":"l2update","product_id":"BTC-USD","changes":[["sell","9178.23","0.09660000"]],"time":"2020-06-30T19:28:15.972849Z"}
{"type":"l2update","product_id":"BTC-USD","changes":[["sell","9135.38","1.95090000"]],"time":"2020-06-30T19:28:16.539970Z"}
{"type":"heartbeat","last_trade_id":0,"product_id":"BTC-USD","sequence":180760846,"time":"2020-06-30T19:28:16.735115Z"}
{"type":"l2update","product_id":"BTC-USD","changes":[["sell","9151.23","0.01820000"]],"time":"2020-06-30T19:28:17.603974Z"}
{"type":"l2update","product_id":"BTC-USD","changes":[["buy","9134.33","0.75000000"]],"time":"2020-06-30T19:28:17.726833Z"}
{"type":"heartbeat","last_trade_id":0,"product_id":"BTC-USD","sequence":180760850,"time":"2020-06-30T19:28:17.735116Z"}
{"type":"heartbeat","last_trade_id":0,"product_id":"BTC-USD","sequence":180760850,"time":"2020-06-30T19:28:18.735115Z"}
{"type":"heartbeat","last_trade_id":0,"product_id":"BTC-USD","sequence":180760850,"time":"2020-06-30T19:28:19.735119Z"}
{"type":"heartbeat","last_trade_id":0,"product_id":"BTC-USD","sequence":180760850,"time":"2020-06-30T19:28:20.735123Z"}
{"type":"l2update","product_id":"BTC-USD","changes":[["sell","9183.80","0.03700000"]],"time":"2020-06-30T19:28:20.962385Z"}
{"type":"l2update","product_id":"BTC-USD","changes":[["sell","9141.77","0.00670000"]],"time":"2020-06-30T19:28:21.218683Z"}
{"type":"l2update","product_id":"BTC-USD","changes":[["sell","9138.66","0.00000000"]],"time":"2020-06-30T19:28:21.391287Z"}
{"type":"l2update","product_id":"BTC-USD","changes":[["sell","9135.38","1.74590000"]],"time":"2020-06-30T19:28:21.405989Z"}
{"type":"heartbeat","last_trade_id":0,"product_id":"BTC-USD","sequence":180760856,"time":"2020-06-30T19:28:21.735113Z"}
{"type":"l2update","product_id":"BTC-USD","changes":[["sell","9181.60","0.02220000"]],"time":"2020-06-30T19:28:21.796136Z"}
{"type":"l2update","product_id":"BTC-USD","changes":[["buy","9105.04","0.50000000"]],"time":"2020-06-30T19:28:22.413536Z"}
{"type":"heartbeat","last_trade_id":0,"product_id":"BTC-USD","sequence":180760860,"time":"2020-06-30T19:28:22.735111Z"}
{"type":"l2update","product_id":"BTC-USD","changes":[["sell","9177.76","0.03700000"]],"time":"2020-06-30T19:28:23.288089Z"}
{"type":"l2update","product_id":"BTC-USD","changes":[["sell","9178.23","0.00000000"]],"time":"2020-06-30T19:28:23.731214Z"}
{"type":"heartbeat","last_trade_id":0,"product_id":"BTC-USD","sequence":180760863,"time":"2020-06-30T19:28:23.735117Z"}
{"type":"heartbeat","last_trade_id":0,"product_id":"BTC-USD","sequence":180760863,"time":"2020-06-30T19:28:24.735119Z"}
{"type":"l2update","product_id":"BTC-USD","changes":[["sell","9151.23","0.03640000"]],"time":"2020-06-30T19:28:24.785858Z"}
{"type":"l2update","product_id":"BTC-USD","changes":[["sell","9138.62","0.00000000"]],"time":"2020-06-30T19:28:25.166315Z"}
{"type":"l2update","product_id":"BTC-USD","changes":[["sell","9154.32","0.02260000"]],"time":"2020-06-30T19:28:25.374059Z"}
{"type":"l2update","product_id":"BTC-USD","changes":[["sell","9163.27","0.05040000"]],"time":"2020-06-30T19:28:25.644467Z"}
{"type":"heartbeat","last_trade_id":0,"product_id":"BTC-USD","sequence":180760870,"time":"2020-06-30T19:28:25.735116Z"}
{"type":"l2update","product_id":"BTC-USD","changes":[["sell","9163.27","0.15040000"]],"time":"2020-06-30T19:28:25.931015Z"}
{"type":"l2update","product_id":"BTC-USD","changes":[["sell","9176.54","0.02220000"]],"time":"2020-06-30T19:28:26.505174Z"}
{"type":"heartbeat","last_trade_id":0,"product_id":"BTC-USD","sequence":180760874,"time":"2020-06-30T19:28:26.735052Z"}
{"type":"l2update","product_id":"BTC-USD","changes":[["sell","9179.74","0.05450000"]],"time":"2020-06-30T19:28:26.771975Z"}
{"type":"l2update","product_id":"BTC-USD","changes":[["sell","9135.38","1.54130000"]],"time":"2020-06-30T19:28:27.215814Z"}
{"type":"l2update","product_id":"BTC-USD","changes":[["sell","9163.27","0.05040000"]],"time":"2020-06-30T19:28:27.217140Z"}
{"type":"l2update","product_id":"BTC-USD","changes":[["sell","9174.88","0.10580000"]],"time":"2020-06-30T19:28:27.659187Z"}
{"type":"heartbeat","last_trade_id":0,"product_id":"BTC-USD","sequence":180760880,"time":"2020-06-30T19:28:27.735104Z"}
{"type":"l2update","product_id":"BTC-USD","changes":[["sell","9135.38","1.36970000"]],"time":"2020-06-30T19:28:28.086126Z"}
{"type":"heartbeat","last_trade_id":0,"product_id":"BTC-USD","sequence":180760881,"time":"2020-06-30T19:28:28.735082Z"}
{"type":"l2update","product_id":"BTC-USD","changes":[["buy","100.00","114.95500000"]],"time":"2020-06-30T19:28:29.049525Z"}
{"type":"l2update","product_id":"BTC-USD","changes":[["buy","100.00","114.94500000"]],"time":"2020-06-30T19:28:29.055863Z"}
{"type":"l2update","product_id":"BTC-USD","changes":[["buy","9134.05","1.50000000"]],"time":"2020-06-30T19:28:29.315115Z"}
{"type":"heartbeat","last_trade_id":0,"product_id":"BTC-USD","sequence":180760886,"time":"2020-06-30T19:28:29.735091Z"}
{"type":"l2update","product_id":"BTC-USD","changes":[["buy","9132.33","0.00000000"]],"time":"2020-06-30T19:28:29.775134Z"}
{"type":"l2update","product_id":"BTC-USD","changes":[["sell","9134.77","2955.70050000"]],"time":"2020-06-30T19:28:30.132014Z"}
{"type":"l2update","product_id":"BTC-USD","changes":[["buy","9125.35","0.03060000"]],"time":"2020-06-30T19:28:30.406332Z"}
{"type":"l2update","product_id":"BTC-USD","changes":[["buy","9125.39","0.06570000"]],"time":"2020-06-30T19:28:30.705819Z"}
{"type":"heartbeat","last_trade_id":0,"product_id":"BTC-USD","sequence":180760894,"time":"2020-06-30T19:28:30.735066Z"}
{"type":"l2update","product_id":"BTC-USD","changes":[["buy","9130.28","0.00000000"]],"time":"2020-06-30T19:28:30.861503Z"}
{"type":"l2update","product_id":"BTC-USD","changes":[["sell","9177.69","0.03700000"]],"time":"2020-06-30T19:28:30.986158Z"}
{"type":"l2update","product_id":"BTC-USD","changes":[["sell","9176.74","0.06880000"]],"time":"2020-06-30T19:28:31.300760Z"}
{"type":"l2update","product_id":"BTC-USD","changes":[["buy","9125.35","0.00000000"]],"time":"2020-06-30T19:28:31.313350Z"}
{"type":"l2update","product_id":"BTC-USD","changes":[["sell","9151.23","0.01820000"]],"time":"2020-06-30T19:28:31.604437Z"}
{"type":"l2update","product_id":"BTC-USD","changes":[["sell","9177.31","0.00000000"]],"time":"2020-06-30T19:28:31.625187Z"}
{"type":"heartbeat","last_trade_id":0,"product_id":"BTC-USD","sequence":180760902,"time":"2020-06-30T19:28:31.735116Z"}
{"type":"l2update","product_id":"BTC-USD","changes":[["sell","9174.88","0.00000000"]],"time":"2020-06-30T19:28:31.967048Z"}
{"type":"l2update","product_id":"BTC-USD","changes":[["sell","9176.54","0.00000000"]],"time":"2020-06-30T19:28:31.976698Z"}
{"type":"l2update","product_id":"BTC-USD","changes":[["sell","9177.44","0.00000000"]],"time":"2020-06-30T19:28:31.981633Z"}
{"type":"l2update","product_id":"BTC-USD","changes":[["sell","9177.76","0.00000000"]],"time":"2020-06-30T19:28:31.990038Z"}
{"type":"l2update","product_id":"BTC-USD","changes":[["buy","9125.37","0.03060000"]],"time":"2020-06-30T19:28:32.028705Z"}
{"type":"l2update","product_id":"BTC-USD","changes":[["sell","9174.67","0.06880000"]],"time":"2020-06-30T19:28:32.148388Z"}
{"type":"l2update","product_id":"BTC-USD","changes":[["sell","9154.32","0.01120000"]],"time":"2020-06-30T19:28:32.392880Z"}
{"type":"l2update","product_id":"BTC-USD","changes":[["sell","9135.38","0.53570000"]],"time":"2020-06-30T19:28:32.405602Z"}
{"type":"l2update","product_id":"BTC-USD","changes":[["buy","9105.04","0.00000000"]],"time":"2020-06-30T19:28:32.476135Z"}
{"type":"l2update","product_id":"BTC-USD","changes":[["buy","9109.35","0.00000000"]],"time":"2020-06-30T19:28:32.481365Z"}
{"type":"heartbeat","last_trade_id":0,"product_id":"BTC-USD","sequence":180760914,"time":"2020-06-30T19:28:32.735115Z"}
{"type":"l2update","product_id":"BTC-USD","changes":[["sell","9162.78","0.08090000"]],"time":"2020-06-30T19:28:33.035016Z"}
{"type":"l2update","product_id":"BTC-USD","changes":[["sell","9141.75","0.00670000"]],"time":"2020-06-30T19:28:33.305433Z"}
{"type":"l2update","product_id":"BTC-USD","changes":[["sell","9176.74","0.00000000"]],"time":"2020-06-30T19:28:33.505281Z"}
{"type":"l2update","product_id":"BTC-USD","changes":[["sell","9179.74","0.00000000"]],"time":"2020-06-30T19:28:33.513108Z"}
{"type":"heartbeat","last_trade_id":0,"product_id":"BTC-USD","sequence":180760920,"time":"2020-06-30T19:28:33.735069Z"}
{"type":"l2update","product_id":"BTC-USD","changes":[["sell","9151.23","0.00000000"]],"time":"2020-06-30T19:28:34.114022Z"}
{"type":"l2update","product_id":"BTC-USD","changes":[["sell","9141.75","0.00000000"]],"time":"2020-06-30T19:28:34.159157Z"}
{"type":"heartbeat","last_trade_id":0,"product_id":"BTC-USD","sequence":180760922,"time":"2020-06-30T19:28:34.735092Z"}
{"type":"l2update","product_id":"BTC-USD","changes":[["buy","9132.33","2.90000000"]],"time":"2020-06-30T19:28:34.798189Z"}
{"type":"l2update","product_id":"BTC-USD","changes":[["buy","9125.37","0.00000000"]],"time":"2020-06-30T19:28:35.266732Z"}
{"type":"l2update","product_id":"BTC-USD","changes":[["buy","9125.39","0.00000000"]],"time":"2020-06-30T19:28:35.279097Z"}
{"type":"heartbeat","last_trade_id":0,"product_id":"BTC-USD","sequence":180760926,"time":"2020-06-30T19:28:35.735123Z"}
{"type":"l2update","product_id":"BTC-USD","changes":[["sell","9176.29","0.06880000"]],"time":"2020-06-30T19:28:36.518426Z"}
{"type":"heartbeat","last_trade_id":0,"product_id":"BTC-USD","sequence":180760928,"time":"2020-06-30T19:28:36.735111Z"}
{"type":"heartbeat","last_trade_id":0,"product_id":"BTC-USD","sequence":180760928,"time":"2020-06-30T19:28:37.735112Z"}
{"type":"l2update","product_id":"BTC-USD","changes":[["buy","8904.08","0.00000000"]],"time":"2020-06-30T19:28:38.299997Z"}
{"type":"l2update","product_id":"BTC-USD","changes":[["buy","9125.40","0.06570000"]],"time":"2020-06-30T19:28:38.304728Z"}
{"type":"l2update","product_id":"BTC-USD","changes":[["buy","9125.41","0.06570000"]],"time":"2020-06-30T19:28:38.634759Z"}
{"type":"l2update","product_id":"BTC-USD","changes":[["buy","8903.30","0.04529236"]],"time":"2020-06-30T19:28:38.638787Z"}
{"type":"heartbeat","last_trade_id":0,"product_id":"BTC-USD","sequence":180760935,"time":"2020-06-30T19:28:38.735118Z"}
{"type":"l2update","product_id":"BTC-USD","changes":[["sell","9426.28","0.00000000"]],"time":"2020-06-30T19:28:39.022938Z"}
{"type":"l2update","product_id":"BTC-USD","changes":[["buy","9130.50","0.00000000"]],"time":"2020-06-30T19:28:39.071684Z"}
{"type":"l2update","product_id":"BTC-USD","changes":[["buy","9108.94","0.00000000"]],"time":"2020-06-30T19:28:39.075414Z"}
{"type":"l2update","product_id":"BTC-USD","changes":[["buy","9132.55","0.00000000"]],"time":"2020-06-30T19:28:39.079874Z"}
{"type":"l2update","product_id":"BTC-USD","changes":[["sell","9151.23","0.06600000"]],"time":"2020-06-30T19:28:39.211790Z"}
{"type":"l2update","product_id":"BTC-USD","changes":[["sell","9427.09","0.00606334"]],"time":"2020-06-30T19:28:39.443238Z"}
{"type":"l2update","product_id":"BTC-USD","changes":[["sell","9172.11","0.01550000"]],"time":"2020-06-30T19:28:39.484157Z"}
{"type":"l2update","product_id":"BTC-USD","changes":[["sell","9183.80","0.00000000"]],"time":"2020-06-30T19:28:39.697966Z"}
{"type":"heartbeat","last_trade_id":0,"product_id":"BTC-USD","sequence":180760946,"time":"2020-06-30T19:28:39.735111Z"}
{"type":"l2update","product_id":"BTC-USD","changes":[["buy","9134.47","0.75000000"]],"time":"2020-06-30T19:28:39.804784Z"}
{"type":"l2update","product_id":"BTC-USD","changes":[["sell","9172.11","0.00000000"]],"time":"2020-06-30T19:28:40.009589Z"}
{"type":"heartbeat","last_trade_id":0,"product_id":"BTC-USD","sequence":180760949,"time":"2020-06-30T19:28:40.735118Z"}
{"type":"l2update","product_id":"BTC-USD","changes":[["sell","9134.77","2955.69950000"]],"time":"2020-06-30T19:28:40.878986Z"}
{"type":"l2update","product_id":"BTC-USD","changes":[["sell","9135.38","1.10370000"]],"time":"2020-06-30T19:28:41.530327Z"}
{"type":"heartbeat","last_trade_id":0,"product_id":"BTC-USD","sequence":180760954,"time":"2020-06-30T19:28:41.735125Z"}
{"type":"l2update","product_id":"BTC-USD","changes":[["buy","9134.05","0.00000000"]],"time":"2020-06-30T19:28:41.777050Z"}
{"type":"l2update","product_id":"BTC-USD","changes":[["buy","9112.45","0.01000000"]],"time":"2020-06-30T19:28:41.834412Z"}
{"type":"l2update","product_id":"BTC-USD","changes":[["sell","9181.94","0.00000000"]],"time":"2020-06-30T19:28:41.960561Z"}
{"type":"l2update","product_id":"BTC-USD","changes":[["sell","9135.38","1.66520000"]],"time":"2020-06-30T19:28:42.644083Z"}
{"type":"heartbeat","last_trade_id":0,"product_id":"BTC-USD","sequence":180760960,"time":"2020-06-30T19:28:42.735116Z"}
{"type":"l2update","product_id":"BTC-USD","changes":[["sell","9134.77","2954.94950000"]],"time":"2020-06-30T19:28:42.929027Z"}
{"type":"l2update","product_id":"BTC-USD","changes":[["sell","9135.38","2.24110000"]],"time":"2020-06-30T19:28:43.265525Z"}
{"type":"l2update","product_id":"BTC-USD","changes":[["sell","9161.80","0.01650000"]],"time":"2020-06-30T19:28:43.505733Z"}
{"type":"l2update","product_id":"BTC-USD","changes":[["sell","9141.77","0.00000000"]],"time":"2020-06-30T19:28:43.659833Z"}
{"type":"l2update","product_id":"BTC-USD","changes":[["sell","9177.98","0.00000000"]],"time":"2020-06-30T19:28:43.665318Z"}
{"type":"heartbeat","last_trade_id":0,"product_id":"BTC-USD","sequence":180760969,"time":"2020-06-30T19:28:43.735071Z"}
{"type":"l2update","product_id":"BTC-USD","changes":[["sell","9178.55","0.10580000"]],"time":"2020-06-30T19:28:43.789810Z"}
{"type":"l2update","product_id":"BTC-USD","changes":[["sell","9135.38","1.67960000"]],"time":"2020-06-30T19:28:43.923082Z"}
{"type":"l2update","product_id":"BTC-USD","changes":[["buy","100.00","114.95500000"]],"time":"2020-06-30T19:28:44.017952Z"}
{"type":"l2update","product_id":"BTC-USD","changes":[["buy","100.00","114.94500000"]],"time":"2020-06-30T19:28:44.024409Z"}
{"type":"l2update","product_id":"BTC-USD","changes":[["buy","9076.00","0.01000000"]],"time":"2020-06-30T19:28:44.243498Z"}
{"type":"l2update","product_id":"BTC-USD","changes":[["buy","9110.18","0.08510000"]],"time":"2020-06-30T19:28:44.382850Z"}
{"type":"l2update","product_id":"BTC-USD","changes":[["buy","9125.40","0.00000000"]],"time":"2020-06-30T19:28:44.598052Z"}
{"type":"l2update","product_id":"BTC-USD","changes":[["sell","9226.22","0.00200000"]],"time":"2020-06-30T19:28:44.685212Z"}
{"type":"heartbeat","last_trade_id":0,"product_id":"BTC-USD","sequence":180760982,"time":"2020-06-30T19:28:44.735097Z"}
{"type":"l2update","product_id":"BTC-USD","changes":[["sell","9175.79","0.02220000"]],"time":"2020-06-30T19:28:44.942800Z"}
{"type":"l2update","product_id":"BTC-USD","changes":[["sell","9161.80","0.00000000"]],"time":"2020-06-30T19:28:45.112112Z"}
{"type":"l2update","product_id":"BTC-USD","changes":[["sell","9181.60","0.00000000"]],"time":"2020-06-30T19:28:45.114345Z"}
{"type":"l2update","product_id":"BTC-USD","changes":[["sell","9174.67","0.00000000"]],"time":"2020-06-30T19:28:45.382272Z"}
{"type":"heartbeat","last_trade_id":0,"product_id":"BTC-USD","sequence":180760987,"time":"2020-06-30T19:28:45.735109Z"}
{"type":"heartbeat","last_trade_id":0,"product_id":"BTC-USD","sequence":180760987,"time":"2020-06-30T19:28:46.734999Z"}
{"type":"l2update","product_id":"BTC-USD","changes":[["sell","9217.57","0.00110000"]],"time":"2020-06-30T19:28:46.802081Z"}
{"type":"l2update","product_id":"BTC-USD","changes":[["sell","9163.27","0.00000000"]],"time":"2020-06-30T19:28:47.226634Z"}
{"type":"l2update","product_id":"BTC-USD","changes":[["sell","9177.69","0.00000000"]],"time":"2020-06-30T19:28:47.232202Z"}
{"type":"l2update","product_id":"BTC-USD","changes":[["buy","9133.58","0.04000000"]],"time":"2020-06-30T19:28:47.341360Z"}
{"type":"l2update","product_id":"BTC-USD","changes":[["sell","9141.51","0.00670000"]],"time":"2020-06-30T19:28:47.628757Z"}
{"type":"heartbeat","last_trade_id":0,"product_id":"BTC-USD","sequence":180760995,"time":"2020-06-30T19:28:47.735119Z"}
{"type":"l2update","product_id":"BTC-USD","changes":[["sell","9176.19","0.02780000"]],"time":"2020-06-30T19:28:47.902044Z"}
{"type":"l2update","product_id":"BTC-USD","changes":[["sell","9135.38","1.14390000"]],"time":"2020-06-30T19:28:48.327094Z"}
{"type":"heartbeat","last_trade_id":0,"product_id":"BTC-USD","sequence":180760998,"time":"2020-06-30T19:28:48.735116Z"}
{"type":"l2update","product_id":"BTC-USD","changes":[["buy","9104.90","0.50000000"]],"time":"2020-06-30T19:28:48.754061Z"}
{"type":"l2update","product_id":"BTC-USD","changes":[["sell","9174.26","0.01490000"]],"time":"2020-06-30T19:28:49.032316Z"}
{"type":"l2update","product_id":"BTC-USD","changes":[["buy","9124.36","0.00000000"]],"time":"2020-06-30T19:28:49.216399Z"}
{"type":"l2update","product_id":"BTC-USD","changes":[["buy","9132.84","0.06570000"]],"time":"2020-06-30T19:28:49.632483Z"}
{"type":"heartbeat","last_trade_id":0,"product_id":"BTC-USD","sequence":180761005,"time":"2020-06-30T19:28:49.735118Z"}
{"type":"heartbeat","last_trade_id":0,"product_id":"BTC-USD","sequence":180761005,"time":"2020-06-30T19:28:50.735112Z"}
{"type":"l2update","product_id":"BTC-USD","changes":[["sell","9140.43","0.00100000"]],"time":"2020-06-30T19:28:50.876056Z"}
{"type":"l2update","product_id":"BTC-USD","changes":[["sell","9162.78","0.00000000"]],"time":"2020-06-30T19:28:51.081587Z"}
{"type":"l2update","product_id":"BTC-USD","changes":[["sell","9141.51","0.00000000"]],"time":"2020-06-30T19:28:51.085749Z"}
{"type":"l2update","product_id":"BTC-USD","changes":[["sell","9174.26","0.00000000"]],"time":"2020-06-30T19:28:51.091507Z"}
{"type":"heartbeat","last_trade_id":0,"product_id":"BTC-USD","sequence":180761010,"time":"2020-06-30T19:28:51.735120Z"}
{"type":"l2update","product_id":"BTC-USD","changes":[["sell","9177.88","0.06760000"]],"time":"2020-06-30T19:28:52.588499Z"}
{"type":"heartbeat","last_trade_id":0,"product_id":"BTC-USD","sequence":180761012,"time":"2020-06-30T19:28:52.735117Z"}
{"type":"l2update","product_id":"BTC-USD","changes":[["sell","9177.21","0.09660000"]],"time":"2020-06-30T19:28:52.874685Z"}
{"type":"l2update","product_id":"BTC-USD","changes":[["sell","9135.38","0.57590000"]],"time":"2020-06-30T19:28:53.059049Z"}
{"type":"l2update","product_id":"BTC-USD","changes":[["sell","9154.32","0.00000000"]],"time":"2020-06-30T19:28:53.103098Z"}
{"type":"l2update","product_id":"BTC-USD","changes":[["sell","9151.23","0.00000000"]],"time":"2020-06-30T19:28:53.123125Z"}
{"type":"l2update","product_id":"BTC-USD","changes":[["sell","9141.72","0.00670000"]],"time":"2020-06-30T19:28:53.148866Z"}
{"type":"l2update","product_id":"BTC-USD","changes":[["sell","9138.74","0.54100000"]],"time":"2020-06-30T19:28:53.425526Z"}
{"type":"heartbeat","last_trade_id":0,"product_id":"BTC-USD","sequence":180761021,"time":"2020-06-30T19:28:53.735116Z"}
{"type":"l2update","product_id":"BTC-USD","changes":[["sell","9175.79","0.00000000"]],"time":"2020-06-30T19:28:53.900483Z"}
{"type":"l2update","product_id":"BTC-USD","changes":[["sell","9135.38","8.15540000"]],"time":"2020-06-30T19:28:54.600101Z"}
{"type":"heartbeat","last_trade_id":0,"product_id":"BTC-USD","sequence":180761024,"time":"2020-06-30T19:28:54.735121Z"}
{"type":"l2update","product_id":"BTC-USD","changes":[["sell","9177.88","0.00000000"]],"time":"2020-06-30T19:28:55.048086Z"}
{"type":"l2update","product_id":"BTC-USD","changes":[["sell","9151.23","0.01650000"]],"time":"2020-06-30T19:28:55.321236Z"}
{"type":"heartbeat","last_trade_id":0,"product_id":"BTC-USD","sequence":180761027,"time":"2020-06-30T19:28:55.735071Z"}
{"type":"l2update","product_id":"BTC-USD","changes":[["sell","9177.21","0.00000000"]],"time":"2020-06-30T19:28:55.764317Z"}
{"type":"l2update","product_id":"BTC-USD","changes":[["sell","9176.29","0.00000000"]],"time":"2020-06-30T19:28:55.764406Z"}
{"type":"l2update","product_id":"BTC-USD","changes":[["buy","9132.86","0.06570000"]],"time":"2020-06-30T19:28:56.546991Z"}
{"type":"heartbeat","last_trade_id":0,"product_id":"BTC-USD","sequence":180761031,"time":"2020-06-30T19:28:56.735099Z"}
{"type":"heartbeat","last_trade_id":0,"product_id":"BTC-USD","sequence":180761031,"time":"2020-06-30T19:28:57.735111Z"}
{"type":"l2update","product_id":"BTC-USD","changes":[["buy","9132.94","0.06570000"]],"time":"2020-06-30T19:28:58.247778Z"}
{"type":"heartbeat","last_trade_id":0,"product_id":"BTC-USD","sequence":180761033,"time":"2020-06-30T19:28:58.735113Z"}
{"type":"l2update","product_id":"BTC-USD","changes":[["buy","100.00","114.95500000"]],"time":"2020-06-30T19:28:59.019940Z"}
{"type":"l2update","product_id":"BTC-USD","changes":[["buy","100.00","114.94500000"]],"time":"2020-06-30T19:28:59.031236Z"}
{"type":"l2update","product_id":"BTC-USD","changes":[["sell","9174.50","0.06880000"]],"time":"2020-06-30T19:28:59.098387Z"}
{"type":"l2update","product_id":"BTC-USD","changes":[["buy","9133.21","0.04000000"]],"time":"2020-06-30T19:28:59.413487Z"}
{"type":"l2update","product_id":"BTC-USD","changes":[["sell","9226.22","0.00000000"]],"time":"2020-06-30T19:28:59.553349Z"}
{"type":"l2update","product_id":"BTC-USD","changes":[["sell","9140.43","0.00000000"]],"time":"2020-06-30T19:28:59.619699Z"}
{"type":"l2update","product_id":"BTC-USD","changes":[["buy","9132.76","0.06570000"]],"time":"2020-06-30T19:28:59.726715Z"}
{"type":"heartbeat","last_trade_id":0,"product_id":"BTC-USD","sequence":180761044,"time":"2020-06-30T19:28:59.735114Z"}
{"type":"l2update","product_id":"BTC-USD","changes":[["buy","9132.33","0.00000000"]],"time":"2020-06-30T19:28:59.883071Z"}
{"type":"l2update","product_id":"BTC-USD","changes":[["buy","9132.94","0.00000000"]],"time":"2020-06-30T19:28:59.886670Z"}
{"type":"l2update","product_id":"BTC-USD","changes":[["buy","9076.00","0.00000000"]],"time":"2020-06-30T19:29:00.173628Z"}
{"type":"heartbeat","last_trade_id":0,"product_id":"BTC-USD","sequence":180761047,"time":"2020-06-30T19:29:00.735113Z"}
{"type":"l2update","product_id":"BTC-USD","changes":[["buy","9132.81","0.06570000"]],"time":"2020-06-30T19:29:00.912998Z"}
{"type":"l2update","product_id":"BTC-USD","changes":[["buy","9132.76","0.00000000"]],"time":"2020-06-30T19:29:01.438343Z"}
{"type":"l2update","product_id":"BTC-USD","changes":[["buy","9108.53","0.00000000"]],"time":"2020-06-30T19:29:01.439143Z"}
{"type":"heartbeat","last_trade_id":0,"product_id":"BTC-USD","sequence":180761051,"time":"2020-06-30T19:29:01.735117Z"}
{"type":"l2update","product_id":"BTC-USD","changes":[["sell","9136.87","0.54750000"]],"time":"2020-06-30T19:29:02.675862Z"}
{"type":"l2update","product_id":"BTC-USD","changes":[["sell","9141.72","0.00000000"]],"time":"2020-06-30T19:29:02.741812Z"}
{"type":"heartbeat","last_trade_id":0,"product_id":"BTC-USD","sequence":180761054,"time":"2020-06-30T19:29:02.735120Z"}
{"type":"l2update","product_id":"BTC-USD","changes":[["sell","9174.74","0.06760000"]],"time":"2020-06-30T19:29:02.851263Z"}
{"type":"l2update","product_id":"BTC-USD","changes":[["sell","9174.50","0.00000000"]],"time":"2020-06-30T19:29:03.301652Z"}
{"type":"heartbeat","last_trade_id":0,"product_id":"BTC-USD","sequence":180761057,"time":"2020-06-30T19:29:03.735115Z"}
{"type":"l2update","product_id":"BTC-USD","changes":[["sell","9135.38","12.76100000"]],"time":"2020-06-30T19:29:03.756763Z"}
{"type":"l2update","product_id":"BTC-USD","changes":[["sell","9173.63","0.03590000"]],"time":"2020-06-30T19:29:03.897543Z"}
{"type":"l2update","product_id":"BTC-USD","changes":[["sell","9178.55","0.00000000"]],"time":"2020-06-30T19:29:04.289164Z"}
{"type":"l2update","product_id":"BTC-USD","changes":[["sell","9175.00","5.00000000"]],"time":"2020-06-30T19:29:04.646026Z"}
{"type":"heartbeat","last_trade_id":0,"product_id":"BTC-USD","sequence":180761064,"time":"2020-06-30T19:29:04.735118Z"}
{"type":"heartbeat","last_trade_id":0,"product_id":"BTC-USD","sequence":180761064,"time":"2020-06-30T19:29:05.735122Z"}
{"type":"l2update","product_id":"BTC-USD","changes":[["buy","9133.60","0.04000000"]],"time":"2020-06-30T19:29:05.806301Z"}
{"type":"l2update","product_id":"BTC-USD","changes":[["buy","9112.45","0.00000000"]],"time":"2020-06-30T19:29:06.333942Z"}
{"type":"l2update","product_id":"BTC-USD","changes":[["sell","9135.38","17.30310000"]],"time":"2020-06-30T19:29:06.732888Z"}
{"type":"heartbeat","last_trade_id":0,"product_id":"BTC-USD","sequence":180761069,"time":"2020-06-30T19:29:06.735116Z"}
{"type":"l2update","product_id":"BTC-USD","changes":[["sell","9176.57","0.06880000"]],"time":"2020-06-30T19:29:07.009407Z"}
{"type":"l2update","product_id":"BTC-USD","changes":[["sell","9176.19","0.00000000"]],"time":"2020-06-30T19:29:07.204346Z"}
{"type":"l2update","product_id":"BTC-USD","changes":[["sell","9174.74","0.00000000"]],"time":"2020-06-30T19:29:07.445549Z"}
{"type":"l2update","product_id":"BTC-USD","changes":[["sell","9135.38","16.72720000"]],"time":"2020-06-30T19:29:07.448956Z"}
{"type":"heartbeat","last_trade_id":0,"product_id":"BTC-USD","sequence":180761074,"time":"2020-06-30T19:29:07.735113Z"}
{"type":"l2update","product_id":"BTC-USD","changes":[["sell","9135.38","21.26460000"]],"time":"2020-06-30T19:29:07.893247Z"}
{"type":"l2update","product_id":"BTC-USD","changes":[["sell","9173.27","0.05270000"]],"time":"2020-06-30T19:29:08.186765Z"}
{"type":"l2update","product_id":"BTC-USD","changes":[["sell","9138.74","0.00000000"]],"time":"2020-06-30T19:29:08.344580Z"}
{"type":"heartbeat","last_trade_id":0,"product_id":"BTC-USD","sequence":180761079,"time":"2020-06-30T19:29:08.735113Z"}
{"type":"l2update","product_id":"BTC-USD","changes":[["buy","9133.21","0.00000000"]],"time":"2020-06-30T19:29:09.244985Z"}
{"type":"l2update","product_id":"BTC-USD","changes":[["sell","9177.00","0.01000000"]],"time":"2020-06-30T19:29:09.487616Z"}
{"type":"heartbeat","last_trade_id":0,"product_id":"BTC-USD","sequence":180761082,"time":"2020-06-30T19:29:09.735111Z"}
{"type":"l2update","product_id":"BTC-USD","changes":[["sell","9173.63","0.00000000"]],"time":"2020-06-30T19:29:09.920697Z"}
{"type":"l2update","product_id":"BTC-USD","changes":[["sell","9173.27","0.00000000"]],"time":"2020-06-30T19:29:09.920883Z"}
{"type":"l2update","product_id":"BTC-USD","changes":[["sell","9175.00","0.00000000"]],"time":"2020-06-30T19:29:09.922142Z"}
{"type":"l2update","product_id":"BTC-USD","changes":[["sell","9135.89","0.84450000"]],"time":"2020-06-30T19:29:10.056285Z"}
{"type":"l2update","product_id":"BTC-USD","changes":[["sell","9135.38","16.65900000"]],"time":"2020-06-30T19:29:10.260957Z"}
{"type":"heartbeat","last_trade_id":0,"product_id":"BTC-USD","sequence":180761088,"time":"2020-06-30T19:29:10.735124Z"}
{"type":"l2update","product_id":"BTC-USD","changes":[["sell","9173.54","0.06760000"]],"time":"2020-06-30T19:29:11.327149Z"}
{"type":"l2update","product_id":"BTC-USD","changes":[["buy","9134.75","3009.82880000"]],"time":"2020-06-30T19:29:11.683406Z"}
{"type":"heartbeat","last_trade_id":0,"product_id":"BTC-USD","sequence":180761093,"time":"2020-06-30T19:29:11.735113Z"}
{"type":"l2update","product_id":"BTC-USD","changes":[["sell","9134.77","2954.19950000"]],"time":"2020-06-30T19:29:11.805355Z"}
{"type":"l2update","product_id":"BTC-USD","changes":[["sell","9176.87","0.02780000"]],"time":"2020-06-30T19:29:12.327788Z"}
{"type":"heartbeat","last_trade_id":0,"product_id":"BTC-USD","sequence":180761098,"time":"2020-06-30T19:29:12.735067Z"}
{"type":"heartbeat","last_trade_id":0,"product_id":"BTC-USD","sequence":180761098,"time":"2020-06-30T19:29:13.735097Z"}
{"type":"l2update","product_id":"BTC-USD","changes":[["buy","100.00","114.95500000"]],"time":"2020-06-30T19:29:14.061888Z"}
{"type":"l2update","product_id":"BTC-USD","changes":[["buy","100.00","114.94500000"]],"time":"2020-06-30T19:29:14.074680Z"}
{"type":"l2update","product_id":"BTC-USD","changes":[["sell","9154.32","0.04690000"]],"time":"2020-06-30T19:29:14.622645Z"}
{"type":"heartbeat","last_trade_id":0,"product_id":"BTC-USD","sequence":180761103,"time":"2020-06-30T19:29:14.735111Z"}
{"type":"l2update","product_id":"BTC-USD","changes":[["sell","9151.23","0.03410000"]],"time":"2020-06-30T19:29:15.650493Z"}
{"type":"heartbeat","last_trade_id":0,"product_id":"BTC-USD","sequence":180761105,"time":"2020-06-30T19:29:15.735112Z"}
{"type":"l2update","product_id":"BTC-USD","changes":[["sell","9136.87","0.00000000"]],"time":"2020-06-30T19:29:16.075001Z"}
{"type":"l2update","product_id":"BTC-USD","changes":[["sell","9151.23","0.01760000"]],"time":"2020-06-30T19:29:16.094932Z"}
{"type":"l2update","product_id":"BTC-USD","changes":[["sell","9173.86","0.00100000"]],"time":"2020-06-30T19:29:16.265201Z"}
{"type":"heartbeat","last_trade_id":0,"product_id":"BTC-USD","sequence":180761109,"time":"2020-06-30T19:29:16.735114Z"}
{"type":"heartbeat","last_trade_id":0,"product_id":"BTC-USD","sequence":180761109,"time":"2020-06-30T19:29:17.735118Z"}
{"type":"heartbeat","last_trade_id":0,"product_id":"BTC-USD","sequence":180761109,"time":"2020-06-30T19:29:18.735113Z"}
{"type":"l2update","product_id":"BTC-USD","changes":[["sell","9151.23","0.08300000"]],"time":"2020-06-30T19:29:18.758831Z"}
{"type":"l2update","product_id":"BTC-USD","changes":[["sell","9217.57","0.00000000"]],"time":"2020-06-30T19:29:19.197496Z"}
{"type":"l2update","product_id":"BTC-USD","changes":[["sell","9154.32","0.00000000"]],"time":"2020-06-30T19:29:19.207786Z"}
{"type":"l2update","product_id":"BTC-USD","changes":[["sell","9135.38","9.07950000"]],"time":"2020-06-30T19:29:19.211186Z"}
{"type":"heartbeat","last_trade_id":0,"product_id":"BTC-USD","sequence":180761114,"time":"2020-06-30T19:29:19.735137Z"}
{"type":"l2update","product_id":"BTC-USD","changes":[["sell","9217.57","0.00110000"]],"time":"2020-06-30T19:29:20.364136Z"}
{"type":"l2update","product_id":"BTC-USD","changes":[["buy","9134.18","0.75000000"]],"time":"2020-06-30T19:29:20.633216Z"}
{"type":"heartbeat","last_trade_id":0,"product_id":"BTC-USD","sequence":180761118,"time":"2020-06-30T19:29:20.735071Z"}
{"type":"l2update","product_id":"BTC-USD","changes":[["sell","9176.87","0.00000000"]],"time":"2020-06-30T19:29:20.785765Z"}
{"type":"l2update","product_id":"BTC-USD","changes":[["sell","9173.54","0.00000000"]],"time":"2020-06-30T19:29:20.816992Z"}
{"type":"l2update","product_id":"BTC-USD","changes":[["buy","9132.63","0.00000000"]],"time":"2020-06-30T19:29:21.051680Z"}
{"type":"l2update","product_id":"BTC-USD","changes":[["sell","9317.65","0.00400000"]],"time":"2020-06-30T19:29:21.485845Z"}
{"type":"heartbeat","last_trade_id":0,"product_id":"BTC-USD","sequence":180761123,"time":"2020-06-30T19:29:21.735117Z"}
{"type":"l2update","product_id":"BTC-USD","changes":[["sell","9173.86","0.00000000"]],"time":"2020-06-30T19:29:21.962788Z"}
{"type":"heartbeat","last_trade_id":0,"product_id":"BTC-USD","sequence":180761124,"time":"2020-06-30T19:29:22.735080Z"}
{"type":"l2update","product_id":"BTC-USD","changes":[["sell","9140.54","0.00670000"]],"time":"2020-06-30T19:29:22.994218Z"}
{"type":"l2update","product_id":"BTC-USD","changes":[["sell","9317.65","0.00000000"]],"time":"2020-06-30T19:29:23.412507Z"}
{"type":"l2update","product_id":"BTC-USD","changes":[["sell","9217.57","0.00000000"]],"time":"2020-06-30T19:29:23.412588Z"}
{"type":"l2update","product_id":"BTC-USD","changes":[["sell","9178.74","0.06760000"]],"time":"2020-06-30T19:29:23.562596Z"}
{"type":"heartbeat","last_trade_id":0,"product_id":"BTC-USD","sequence":180761130,"time":"2020-06-30T19:29:23.735114Z"}
{"type":"l2update","product_id":"BTC-USD","changes":[["buy","9128.05","0.06570000"]],"time":"2020-06-30T19:29:24.131087Z"}
{"type":"l2update","product_id":"BTC-USD","changes":[["buy","9125.41","0.00000000"]],"time":"2020-06-30T19:29:24.610156Z"}
{"type":"heartbeat","last_trade_id":0,"product_id":"BTC-USD","sequence":180761133,"time":"2020-06-30T19:29:24.735130Z"}
{"type":"l2update","product_id":"BTC-USD","changes":[["sell","9135.38","13.84880000"]],"time":"2020-06-30T19:29:25.393267Z"}
{"type":"heartbeat","last_trade_id":0,"product_id":"BTC-USD","sequence":180761135,"time":"2020-06-30T19:29:25.735129Z"}
{"type":"l2update","product_id":"BTC-USD","changes":[["sell","9138.58","0.84450000"]],"time":"2020-06-30T19:29:25.863371Z"}
{"type":"l2update","product_id":"BTC-USD","changes":[["buy","9106.14","0.01000000"]],"time":"2020-06-30T19:29:26.179675Z"}
{"type":"l2update","product_id":"BTC-USD","changes":[["buy","9132.86","0.00000000"]],"time":"2020-06-30T19:29:26.578874Z"}
{"type":"l2update","product_id":"BTC-USD","changes":[["buy","9134.18","0.00000000"]],"time":"2020-06-30T19:29:26.586086Z"}
{"type":"l2update","product_id":"BTC-USD","changes":[["buy","9128.05","0.00000000"]],"time":"2020-06-30T19:29:26.587544Z"}
{"type":"l2update","product_id":"BTC-USD","changes":[["buy","9134.33","0.00000000"]],"time":"2020-06-30T19:29:26.587973Z"}
{"type":"l2update","product_id":"BTC-USD","changes":[["buy","9110.18","0.00000000"]],"time":"2020-06-30T19:29:26.591862Z"}
{"type":"heartbeat","last_trade_id":0,"product_id":"BTC-USD","sequence":180761144,"time":"2020-06-30T19:29:26.735135Z"}
{"type":"heartbeat","last_trade_id":0,"product_id":"BTC-USD","sequence":180761144,"time":"2020-06-30T19:29:27.735139Z"}
{"type":"l2update","product_id":"BTC-USD","changes":[["sell","9175.40","0.09100000"]],"time":"2020-06-30T19:29:28.185599Z"}
{"type":"l2update","product_id":"BTC-USD","changes":[["sell","9154.32","0.03940000"]],"time":"2020-06-30T19:29:28.467635Z"}
{"type":"heartbeat","last_trade_id":0,"product_id":"BTC-USD","sequence":180761148,"time":"2020-06-30T19:29:28.735151Z"}
{"type":"l2update","product_id":"BTC-USD","changes":[["sell","9174.02","0.01490000"]],"time":"2020-06-30T19:29:28.748888Z"}
{"type":"l2update","product_id":"BTC-USD","changes":[["buy","9103.67","0.01000000"]],"time":"2020-06-30T19:29:29.036202Z"}
{"type":"l2update","product_id":"BTC-USD","changes":[["buy","100.00","114.95500000"]],"time":"2020-06-30T19:29:29.103638Z"}
{"type":"l2update","product_id":"BTC-USD","changes":[["buy","100.00","114.94500000"]],"time":"2020-06-30T19:29:29.109768Z"}
{"type":"l2update","product_id":"BTC-USD","changes":[["sell","9135.38","9.07950000"]],"time":"2020-06-30T19:29:29.204751Z"}
{"type":"l2update","product_id":"BTC-USD","changes":[["sell","9157.64","1.16800000"]],"time":"2020-06-30T19:29:29.310414Z"}
{"type":"l2update","product_id":"BTC-USD","changes":[["buy","9132.81","0.00000000"]],"time":"2020-06-30T19:29:29.460720Z"}
{"type":"heartbeat","last_trade_id":0,"product_id":"BTC-USD","sequence":180761159,"time":"2020-06-30T19:29:29.735183Z"}
{"type":"l2update","product_id":"BTC-USD","changes":[["sell","9151.23","0.01760000"]],"time":"2020-06-30T19:29:30.011138Z"}
{"type":"l2update","product_id":"BTC-USD","changes":[["sell","9135.38","4.53740000"]],"time":"2020-06-30T19:29:30.020081Z"}
{"type":"heartbeat","last_trade_id":0,"product_id":"BTC-USD","sequence":180761161,"time":"2020-06-30T19:29:30.735159Z"}
{"type":"heartbeat","last_trade_id":0,"product_id":"BTC-USD","sequence":180761161,"time":"2020-06-30T19:29:31.735101Z"}
{"type":"l2update","product_id":"BTC-USD","changes":[["sell","9174.83","0.06880000"]],"time":"2020-06-30T19:29:31.879215Z"}
{"type":"l2update","product_id":"BTC-USD","changes":[["sell","9174.40","0.06880000"]],"time":"2020-06-30T19:29:32.167637Z"}
{"type":"l2update","product_id":"BTC-USD","changes":[["sell","9151.23","0.00000000"]],"time":"2020-06-30T19:29:32.338900Z"}
{"type":"l2update","product_id":"BTC-USD","changes":[["sell","9154.32","0.00000000"]],"time":"2020-06-30T19:29:32.367859Z"}
{"type":"l2update","product_id":"BTC-USD","changes":[["sell","9174.83","0.00000000"]],"time":"2020-06-30T19:29:32.405515Z"}
{"type":"l2update","product_id":"BTC-USD","changes":[["sell","9138.69","1.63600000"]],"time":"2020-06-30T19:29:32.486253Z"}
{"type":"l2update","product_id":"BTC-USD","changes":[["sell","9140.43","0.00670000"]],"time":"2020-06-30T19:29:32.616221Z"}
{"type":"heartbeat","last_trade_id":0,"product_id":"BTC-USD","sequence":180761172,"time":"2020-06-30T19:29:32.735156Z"}
{"type":"l2update","product_id":"BTC-USD","changes":[["buy","9103.67","0.02000000"]],"time":"2020-06-30T19:29:33.024260Z"}
{"type":"l2update","product_id":"BTC-USD","changes":[["sell","9136.18","0.54750000"]],"time":"2020-06-30T19:29:33.590535Z"}
{"type":"heartbeat","last_trade_id":0,"product_id":"BTC-USD","sequence":180761176,"time":"2020-06-30T19:29:33.735140Z"}
{"type":"l2update","product_id":"BTC-USD","changes":[["sell","9178.74","0.00000000"]],"time":"2020-06-30T19:29:34.018066Z"}
{"type":"l2update","product_id":"BTC-USD","changes":[["sell","9140.54","0.00000000"]],"time":"2020-06-30T19:29:34.030238Z"}
{"type":"l2update","product_id":"BTC-USD","changes":[["buy","9132.72","0.06570000"]],"time":"2020-06-30T19:29:34.742602Z"}
{"type":"heartbeat","last_trade_id":0,"product_id":"BTC-USD","sequence":180761180,"time":"2020-06-30T19:29:34.735127Z"}
{"type":"l2update","product_id":"BTC-USD","changes":[["buy","9132.84","0.00000000"]],"time":"2020-06-30T19:29:34.904922Z"}
{"type":"l2update","product_id":"BTC-USD","changes":[["buy","9133.60","0.00000000"]],"time":"2020-06-30T19:29:34.914252Z"}
{"type":"l2update","product_id":"BTC-USD","changes":[["buy","9132.74","0.06570000"]],"time":"2020-06-30T19:29:34.990766Z"}
{"type":"l2update","product_id":"BTC-USD","changes":[["buy","9130.44","0.06570000"]],"time":"2020-06-30T19:29:35.261339Z"}
{"type":"l2update","product_id":"BTC-USD","changes":[["buy","9133.58","0.00000000"]],"time":"2020-06-30T19:29:35.474215Z"}
{"type":"l2update","product_id":"BTC-USD","changes":[["sell","9175.18","0.06880000"]],"time":"2020-06-30T19:29:35.556475Z"}
{"type":"heartbeat","last_trade_id":0,"product_id":"BTC-USD","sequence":180761189,"time":"2020-06-30T19:29:35.735126Z"}
{"type":"l2update","product_id":"BTC-USD","changes":[["sell","9136.18","0.00000000"]],"time":"2020-06-30T19:29:35.921050Z"}
{"type":"l2update","product_id":"BTC-USD","changes":[["sell","9138.69","0.00000000"]],"time":"2020-06-30T19:29:35.936336Z"}
{"type":"l2update","product_id":"BTC-USD","changes":[["sell","9173.66","0.01490000"]],"time":"2020-06-30T19:29:36.132767Z"}
{"type":"l2update","product_id":"BTC-USD","changes":[["sell","9138.58","0.00000000"]],"time":"2020-06-30T19:29:36.362127Z"}
{"type":"l2update","product_id":"BTC-USD","changes":[["sell","9161.80","0.01100000"]],"time":"2020-06-30T19:29:36.407357Z"}
{"type":"heartbeat","last_trade_id":0,"product_id":"BTC-USD","sequence":180761196,"time":"2020-06-30T19:29:36.735109Z"}
{"type":"l2update","product_id":"BTC-USD","changes":[["sell","9174.40","0.00000000"]],"time":"2020-06-30T19:29:36.845796Z"}
{"type":"l2update","product_id":"BTC-USD","changes":[["sell","9174.02","0.00000000"]],"time":"2020-06-30T19:29:37.406681Z"}
{"type":"l2update","product_id":"BTC-USD","changes":[["sell","9175.40","0.00000000"]],"time":"2020-06-30T19:29:37.410180Z"}
{"type":"l2update","product_id":"BTC-USD","changes":[["buy","9132.84","0.06570000"]],"time":"2020-06-30T19:29:37.599396Z"}
{"type":"heartbeat","last_trade_id":0,"product_id":"BTC-USD","sequence":180761201,"time":"2020-06-30T19:29:37.735099Z"}
{"type":"l2update","product_id":"BTC-USD","changes":[["buy","9134.47","0.00000000"]],"time":"2020-06-30T19:29:38.057010Z"}
{"type":"heartbeat","last_trade_id":0,"product_id":"BTC-USD","sequence":180761202,"time":"2020-06-30T19:29:38.735107Z"}
{"type":"l2update","product_id":"BTC-USD","changes":[["sell","9173.15","0.06880000"]],"time":"2020-06-30T19:29:38.863431Z"}
{"type":"l2update","product_id":"BTC-USD","changes":[["sell","9138.70","0.82120000"]],"time":"2020-06-30T19:29:39.602620Z"}
{"type":"heartbeat","last_trade_id":0,"product_id":"BTC-USD","sequence":180761206,"time":"2020-06-30T19:29:39.735091Z"}
{"type":"l2update","product_id":"BTC-USD","changes":[["sell","9173.15","0.00000000"]],"time":"2020-06-30T19:29:40.077753Z"}
{"type":"l2update","product_id":"BTC-USD","changes":[["sell","9177.25","0.06880000"]],"time":"2020-06-30T19:29:40.442458Z"}
{"type":"heartbeat","last_trade_id":0,"product_id":"BTC-USD","sequence":180761209,"time":"2020-06-30T19:29:40.735089Z"}
{"type":"l2update","product_id":"BTC-USD","changes":[["sell","9139.81","1.63900000"]],"time":"2020-06-30T19:29:40.995839Z"}
{"type":"l2update","product_id":"BTC-USD","changes":[["sell","9134.77","2954.19850000"]],"time":"2020-06-30T19:29:41.068211Z"}
{"type":"l2update","product_id":"BTC-USD","changes":[["sell","9151.23","0.01760000"]],"time":"2020-06-30T19:29:41.254012Z"}
{"type":"l2update","product_id":"BTC-USD","changes":[["sell","9140.43","0.00000000"]],"time":"2020-06-30T19:29:41.460601Z"}
{"type":"heartbeat","last_trade_id":0,"product_id":"BTC-USD","sequence":180761217,"time":"2020-06-30T19:29:41.735103Z"}
{"type":"l2update","product_id":"BTC-USD","changes":[["sell","9134.77","2953.95700000"]],"time":"2020-06-30T19:29:42.139791Z"}
{"type":"l2update","product_id":"BTC-USD","changes":[["buy","9130.44","0.00000000"]],"time":"2020-06-30T19:29:42.564811Z"}
{"type":"l2update","product_id":"BTC-USD","changes":[["sell","9140.43","0.00670000"]],"time":"2020-06-30T19:29:42.718185Z"}
{"type":"heartbeat","last_trade_id":0,"product_id":"BTC-USD","sequence":180761223,"time":"2020-06-30T19:29:42.735100Z"}
{"type":"l2update","product_id":"BTC-USD","changes":[["sell","9138.70","0.00000000"]],"time":"2020-06-30T19:29:43.138217Z"}
{"type":"l2update","product_id":"BTC-USD","changes":[["sell","9176.57","0.00000000"]],"time":"2020-06-30T19:29:43.144705Z"}
{"type":"l2update","product_id":"BTC-USD","changes":[["sell","9178.75","0.06880000"]],"time":"2020-06-30T19:29:43.371597Z"}
{"type":"heartbeat","last_trade_id":0,"product_id":"BTC-USD","sequence":180761227,"time":"2020-06-30T19:29:43.735107Z"}
{"type":"l2update","product_id":"BTC-USD","changes":[["buy","8903.30","0.00000000"]],"time":"2020-06-30T19:29:44.030189Z"}
{"type":"l2update","product_id":"BTC-USD","changes":[["buy","100.00","114.95500000"]],"time":"2020-06-30T19:29:44.039842Z"}
{"type":"l2update","product_id":"BTC-USD","changes":[["buy","100.00","114.94500000"]],"time":"2020-06-30T19:29:44.048999Z"}
{"type":"l2update","product_id":"BTC-USD","changes":[["sell","9151.23","0.03520000"]],"time":"2020-06-30T19:29:44.222809Z"}
{"type":"l2update","product_id":"BTC-USD","changes":[["buy","8902.54","0.04538720"]],"time":"2020-06-30T19:29:44.644146Z"}
{"type":"heartbeat","last_trade_id":0,"product_id":"BTC-USD","sequence":180761235,"time":"2020-06-30T19:29:44.735096Z"}
{"type":"l2update","product_id":"BTC-USD","changes":[["buy","9133.29","0.66640000"]],"time":"2020-06-30T19:29:44.857220Z"}
{"type":"l2update","product_id":"BTC-USD","changes":[["sell","9427.09","0.00000000"]],"time":"2020-06-30T19:29:44.934671Z"}
{"type":"l2update","product_id":"BTC-USD","changes":[["sell","9427.91","0.00615619"]],"time":"2020-06-30T19:29:45.144928Z"}
{"type":"l2update","product_id":"BTC-USD","changes":[["buy","9106.14","0.00000000"]],"time":"2020-06-30T19:29:45.316320Z"}
{"type":"l2update","product_id":"BTC-USD","changes":[["sell","9173.11","0.01490000"]],"time":"2020-06-30T19:29:45.697955Z"}
{"type":"heartbeat","last_trade_id":0,"product_id":"BTC-USD","sequence":180761243,"time":"2020-06-30T19:29:45.735093Z"}
{"type":"l2update","product_id":"BTC-USD","changes":[["sell","9173.66","0.00000000"]],"time":"2020-06-30T19:29:45.917155Z"}
{"type":"l2update","product_id":"BTC-USD","changes":[["sell","9135.38","0.00000000"]],"time":"2020-06-30T19:29:45.929878Z"}
{"type":"l2update","product_id":"BTC-USD","changes":[["sell","9172.29","0.03700000"]],"time":"2020-06-30T19:29:45.963806Z"}
{"type":"l2update","product_id":"BTC-USD","changes":[["sell","9171.48","0.06880000"]],"time":"2020-06-30T19:29:46.237413Z"}
{"type":"l2update","product_id":"BTC-USD","changes":[["sell","9173.11","0.00000000"]],"time":"2020-06-30T19:29:46.405744Z"}
{"type":"l2update","product_id":"BTC-USD","changes":[["sell","9177.00","0.00000000"]],"time":"2020-06-30T19:29:46.407711Z"}
{"type":"l2update","product_id":"BTC-USD","changes":[["sell","9172.29","0.00000000"]],"time":"2020-06-30T19:29:46.675735Z"}
{"type":"heartbeat","last_trade_id":0,"product_id":"BTC-USD","sequence":180761252,"time":"2020-06-30T19:29:46.735068Z"}
{"type":"heartbeat","last_trade_id":0,"product_id":"BTC-USD","sequence":180761252,"time":"2020-06-30T19:29:47.735030Z"}
{"type":"heartbeat","last_trade_id":0,"product_id":"BTC-USD","sequence":180761252,"time":"2020-06-30T19:29:48.735117Z"}
{"type":"heartbeat","last_trade_id":0,"product_id":"BTC-USD","sequence":180761252,"time":"2020-06-30T19:29:49.735084Z"}
{"type":"l2update","product_id":"BTC-USD","changes":[["buy","9132.94","0.06570000"]],"time":"2020-06-30T19:29:50.091130Z"}
{"type":"l2update","product_id":"BTC-USD","changes":[["buy","9103.67","0.01000000"]],"time":"2020-06-30T19:29:50.314631Z"}
{"type":"l2update","product_id":"BTC-USD","changes":[["buy","9131.03","0.16400000"]],"time":"2020-06-30T19:29:50.367976Z"}
{"type":"heartbeat","last_trade_id":0,"product_id":"BTC-USD","sequence":180761257,"time":"2020-06-30T19:29:50.735089Z"}
{"type":"l2update","product_id":"BTC-USD","changes":[["buy","9132.72","0.00000000"]],"time":"2020-06-30T19:29:50.795407Z"}
{"type":"l2update","product_id":"BTC-USD","changes":[["buy","9105.65","0.12140000"]],"time":"2020-06-30T19:29:51.457835Z"}
{"type":"heartbeat","last_trade_id":0,"product_id":"BTC-USD","sequence":180761260,"time":"2020-06-30T19:29:51.735099Z"}
{"type":"l2update","product_id":"BTC-USD","changes":[["buy","9131.31","1.64000000"]],"time":"2020-06-30T19:29:52.266334Z"}
{"type":"l2update","product_id":"BTC-USD","changes":[["buy","9132.94","0.00000000"]],"time":"2020-06-30T19:29:52.739938Z"}
{"type":"heartbeat","last_trade_id":0,"product_id":"BTC-USD","sequence":180761263,"time":"2020-06-30T19:29:52.735039Z"}
{"type":"l2update","product_id":"BTC-USD","changes":[["buy","9134.75","3003.66520000"]],"time":"2020-06-30T19:29:52.829951Z"}
{"type":"l2update","product_id":"BTC-USD","changes":[["buy","9134.75","2997.77710000"]],"time":"2020-06-30T19:29:53.112215Z"}
{"type":"l2update","product_id":"BTC-USD","changes":[["sell","9161.80","0.02200000"]],"time":"2020-06-30T19:29:53.405418Z"}
{"type":"l2update","product_id":"BTC-USD","changes":[["sell","9157.64","0.00000000"]],"time":"2020-06-30T19:29:53.543588Z"}
{"type":"l2update","product_id":"BTC-USD","changes":[["sell","9151.23","0.01760000"]],"time":"2020-06-30T19:29:53.555427Z"}
{"type":"heartbeat","last_trade_id":0,"product_id":"BTC-USD","sequence":180761273,"time":"2020-06-30T19:29:53.735071Z"}
{"type":"l2update","product_id":"BTC-USD","changes":[["sell","9217.57","0.00110000"]],"time":"2020-06-30T19:29:54.257605Z"}
{"type":"heartbeat","last_trade_id":0,"product_id":"BTC-USD","sequence":180761275,"time":"2020-06-30T19:29:54.735101Z"}
{"type":"l2update","product_id":"BTC-USD","changes":[["sell","9171.01","0.01490000"]],"time":"2020-06-30T19:29:55.378526Z"}
{"type":"heartbeat","last_trade_id":0,"product_id":"BTC-USD","sequence":180761277,"time":"2020-06-30T19:29:55.735090Z"}
{"type":"l2update","product_id":"BTC-USD","changes":[["buy","9131.48","0.04000000"]],"time":"2020-06-30T19:29:56.006787Z"}
{"type":"l2update","product_id":"BTC-USD","changes":[["buy","9132.84","0.00000000"]],"time":"2020-06-30T19:29:56.469381Z"}
{"type":"l2update","product_id":"BTC-USD","changes":[["buy","9103.67","0.00000000"]],"time":"2020-06-30T19:29:56.470736Z"}
{"type":"l2update","product_id":"BTC-USD","changes":[["buy","9130.51","0.06570000"]],"time":"2020-06-30T19:29:56.672478Z"}
{"type":"heartbeat","last_trade_id":0,"product_id":"BTC-USD","sequence":180761283,"time":"2020-06-30T19:29:56.735092Z"}
{"type":"l2update","product_id":"BTC-USD","changes":[["buy","9095.86","0.05500000"]],"time":"2020-06-30T19:29:57.525769Z"}
{"type":"heartbeat","last_trade_id":0,"product_id":"BTC-USD","sequence":180761285,"time":"2020-06-30T19:29:57.735082Z"}
{"type":"l2update","product_id":"BTC-USD","changes":[["buy","9102.56","0.50000000"]],"time":"2020-06-30T19:29:57.805961Z"}
{"type":"l2update","product_id":"BTC-USD","changes":[["buy","9130.51","0.00000000"]],"time":"2020-06-30T19:29:58.344382Z"}
{"type":"l2update","product_id":"BTC-USD","changes":[["buy","9105.65","0.00000000"]],"time":"2020-06-30T19:29:58.357485Z"}
