{"type":"subscriptions","channels":[{"name":"level2","product_ids":["BTC-USD"]},{"name":"heartbeat","product_ids":["BTC-USD"]}]}
{"type":"snapshot","product_id":"BTC-USD","asks":[["9120.82","3008.14800000"],["9120.83","4771.00000000"],["9120.84","6020.00000000"],["9120.85","6989.00000000"],["9120.86","7781.00000000"],["9120.87","8450.00000000"],["9120.88","9030.00000000"],["9120.89","9542.00000000"],["9121.12","0.06590000"],["9145.01","0.05470000"],["9164.12","0.06900000"],["9167.19","0.09620000"],["9170.47","0.07650000"],["9176.59","156.27500000"],["9227.57","0.00100000"],["9299.99","0.00500000"],["9423.42","9999.00000000"],["9434.33","0.00688998"],["9961.44","0.09080013"],["11999.99","0.06000000"],["58000.00","1.88000000"],["200000.00","0.50000000"],["1000000.00","100000.00000000"],["8000070.30","0.02570000"],["9999999.02","0.00100000"],["10000000.00","1.00000000"],["11099891.00","0.05000000"]],"bids":[["9120.80","2895.14400000"],["9120.79","4771.00000000"],["9120.78","6020.00000000"],["9120.77","6989.00000000"],["9120.76","7781.00000000"],["9120.75","8450.00000000"],["9120.74","9030.00000000"],["9120.73","9542.00000000"],["9110.10","0.90000000"],["9110.09","7.87730000"],["9107.72","0.02500000"],["9106.64","0.75000000"],["9105.99","1.09760000"],["9102.76","5.00000000"],["9095.58","0.01020000"],["9089.23","0.10470000"],["9084.81","0.03710000"],["9084.37","0.04390000"],["9082.54","0.03950000"],["9077.66","0.02570000"],["9075.38","0.05600000"],["9000.01","0.00600000"],["8964.07","0.17800000"],["8900.00","0.03000000"],["8896.47","0.04613699"],["8611.00","1.05598206"],["8500.00","12.00500000"],["8150.26","0.11097805"],["8000.00","0.47000000"],["7597.68","0.01100000"],["7400.00","1.00000000"],["5031.00","0.30000000"],["5000.00","0.02450000"],["3660.00","203279.99300000"],["3500.00","25000.00000000"],["3000.00","0.21583329"],["2962.53","0.01100000"],["2000.00","220000.48000000"],["1900.00","1.00000000"],["1090.00","12.00000000"],["1000.00","4.52000000"],["900.00","0.00100000"],["500.00","100.00300000"],["280.00","1.00000000"],["200.00","0.18000000"],["104.50","1.85300000"],["100.00","114.94500000"],["75.00","6.00000000"],["30.00","1934.99132469"],["20.00","10.00000000"],["15.00","5.00000000"],["10.00","107063.84702300"],["7.13","0.00100000"],["4.00","2.00000000"],["2.00","100.28000000"],["1.12","1.00000000"],["1.11","0.02600000"],["1.00","1001054.20200000"],["0.83","1.00000000"],["0.20","0.00400000"],["0.19","1.00000000"],["0.16","12.00000000"],["0.10","0.18330000"],["0.01","10390.79441258"]]}
{"type":"heartbeat","last_trade_id":0,"product_id":"BTC-USD","sequence":180754924,"time":"2020-06-30T19:10:21.735070Z"}
{"type":"l2update","product_id":"BTC-USD","changes":[["buy","9110.00","0.00100000"]],"time":"2020-06-30T19:10:22.381718Z"}
{"type":"heartbeat","last_trade_id":0,"product_id":"BTC-USD","sequence":180754926,"time":"2020-06-30T19:10:22.735092Z"}
{"type":"l2update","product_id":"BTC-USD","changes":[["buy","9077.66","0.00000000"]],"time":"2020-06-30T19:10:22.833144Z"}
{"type":"l2update","product_id":"BTC-USD","changes":[["buy","9107.72","0.00000000"]],"time":"2020-06-30T19:10:22.837265Z"}
{"type":"l2update","product_id":"BTC-USD","changes":[["buy","9084.81","0.00000000"]],"time":"2020-06-30T19:10:22.837345Z"}
{"type":"l2update","product_id":"BTC-USD","changes":[["sell","9137.48","1.01580000"]],"time":"2020-06-30T19:10:23.252314Z"}
{"type":"heartbeat","last_trade_id":0,"product_id":"BTC-USD","sequence":180754931,"time":"2020-06-30T19:10:23.735107Z"}
{"type":"l2update","product_id":"BTC-USD","changes":[["buy","9085.40","0.15650000"]],"time":"2020-06-30T19:10:24.322117Z"}
{"type":"l2update","product_id":"BTC-USD","changes":[["buy","9120.80","2895.07810000"]],"time":"2020-06-30T19:10:24.602001Z"}
{"type":"heartbeat","last_trade_id":0,"product_id":"BTC-USD","sequence":180754936,"time":"2020-06-30T19:10:24.735115Z"}
{"type":"l2update","product_id":"BTC-USD","changes":[["buy","9110.09","2.92180000"]],"time":"2020-06-30T19:10:24.779046Z"}
{"type":"l2update","product_id":"BTC-USD","changes":[["sell","9137.48","0.00000000"]],"time":"2020-06-30T19:10:25.046980Z"}
{"type":"l2update","product_id":"BTC-USD","changes":[["buy","9120.80","2895.02810000"]],"time":"2020-06-30T19:10:25.282011Z"}
{"type":"l2update","product_id":"BTC-USD","changes":[["buy","9079.24","0.06920000"]],"time":"2020-06-30T19:10:25.546819Z"}
{"type":"l2update","product_id":"BTC-USD","changes":[["sell","9164.12","0.00000000"]],"time":"2020-06-30T19:10:25.727819Z"}
{"type":"heartbeat","last_trade_id":0,"product_id":"BTC-USD","sequence":180754944,"time":"2020-06-30T19:10:25.735119Z"}
{"type":"l2update","product_id":"BTC-USD","changes":[["buy","9095.58","0.00000000"]],"time":"2020-06-30T19:10:25.756751Z"}
{"type":"l2update","product_id":"BTC-USD","changes":[["buy","9120.80","2894.87910000"]],"time":"2020-06-30T19:10:25.839564Z"}
{"type":"l2update","product_id":"BTC-USD","changes":[["sell","9145.01","0.00000000"]],"time":"2020-06-30T19:10:26.307894Z"}
{"type":"heartbeat","last_trade_id":0,"product_id":"BTC-USD","sequence":180754949,"time":"2020-06-30T19:10:26.735115Z"}
{"type":"l2update","product_id":"BTC-USD","changes":[["sell","9161.71","0.03520000"]],"time":"2020-06-30T19:10:27.280188Z"}
{"type":"l2update","product_id":"BTC-USD","changes":[["sell","9121.12","0.00000000"]],"time":"2020-06-30T19:10:27.726889Z"}
{"type":"heartbeat","last_trade_id":0,"product_id":"BTC-USD","sequence":180754952,"time":"2020-06-30T19:10:27.735118Z"}
{"type":"l2update","product_id":"BTC-USD","changes":[["sell","9142.68","0.05470000"]],"time":"2020-06-30T19:10:27.826621Z"}
{"type":"l2update","product_id":"BTC-USD","changes":[["buy","9075.47","0.03310000"]],"time":"2020-06-30T19:10:28.118774Z"}
{"type":"l2update","product_id":"BTC-USD","changes":[["sell","9170.47","0.00000000"]],"time":"2020-06-30T19:10:28.261442Z"}
{"type":"l2update","product_id":"BTC-USD","changes":[["buy","9120.80","2894.59240000"]],"time":"2020-06-30T19:10:28.392867Z"}
{"type":"l2update","product_id":"BTC-USD","changes":[["buy","9110.00","0.00000000"]],"time":"2020-06-30T19:10:28.571021Z"}
{"type":"l2update","product_id":"BTC-USD","changes":[["buy","9110.09","0.00000000"]],"time":"2020-06-30T19:10:28.574873Z"}
{"type":"l2update","product_id":"BTC-USD","changes":[["buy","9106.64","0.00000000"]],"time":"2020-06-30T19:10:28.577774Z"}
{"type":"l2update","product_id":"BTC-USD","changes":[["buy","9120.80","2894.52650000"]],"time":"2020-06-30T19:10:28.676726Z"}
{"type":"heartbeat","last_trade_id":0,"product_id":"BTC-USD","sequence":180754966,"time":"2020-06-30T19:10:28.735118Z"}
{"type":"l2update","product_id":"BTC-USD","changes":[["buy","9076.31","0.06920000"]],"time":"2020-06-30T19:10:28.994427Z"}
{"type":"l2update","product_id":"BTC-USD","changes":[["buy","100.00","114.95500000"]],"time":"2020-06-30T19:10:29.090940Z"}
{"type":"l2update","product_id":"BTC-USD","changes":[["buy","100.00","114.94500000"]],"time":"2020-06-30T19:10:29.097959Z"}
{"type":"l2update","product_id":"BTC-USD","changes":[["buy","9085.40","0.00000000"]],"time":"2020-06-30T19:10:29.425063Z"}
{"type":"l2update","product_id":"BTC-USD","changes":[["buy","9075.47","0.00000000"]],"time":"2020-06-30T19:10:29.426088Z"}
{"type":"heartbeat","last_trade_id":0,"product_id":"BTC-USD","sequence":180754973,"time":"2020-06-30T19:10:29.735094Z"}
{"type":"l2update","product_id":"BTC-USD","changes":[["sell","9131.21","0.76320000"]],"time":"2020-06-30T19:10:29.919477Z"}
{"type":"heartbeat","last_trade_id":0,"product_id":"BTC-USD","sequence":180754975,"time":"2020-06-30T19:10:30.735122Z"}
{"type":"l2update","product_id":"BTC-USD","changes":[["buy","9080.54","0.06920000"]],"time":"2020-06-30T19:10:30.775988Z"}
{"type":"l2update","product_id":"BTC-USD","changes":[["buy","9110.10","0.00000000"]],"time":"2020-06-30T19:10:31.257477Z"}
{"type":"l2update","product_id":"BTC-USD","changes":[["buy","9076.31","0.00000000"]],"time":"2020-06-30T19:10:31.261537Z"}
{"type":"l2update","product_id":"BTC-USD","changes":[["buy","9089.23","0.00000000"]],"time":"2020-06-30T19:10:31.294384Z"}
{"type":"l2update","product_id":"BTC-USD","changes":[["buy","9120.80","2890.63980000"]],"time":"2020-06-30T19:10:31.344615Z"}
{"type":"l2update","product_id":"BTC-USD","changes":[["buy","9120.80","2884.55370000"]],"time":"2020-06-30T19:10:31.614624Z"}
{"type":"heartbeat","last_trade_id":0,"product_id":"BTC-USD","sequence":180754986,"time":"2020-06-30T19:10:31.735121Z"}
{"type":"l2update","product_id":"BTC-USD","changes":[["sell","9167.19","0.00000000"]],"time":"2020-06-30T19:10:31.933635Z"}
{"type":"l2update","product_id":"BTC-USD","changes":[["sell","9160.56","0.10000000"]],"time":"2020-06-30T19:10:32.427539Z"}
{"type":"l2update","product_id":"BTC-USD","changes":[["buy","9079.24","0.00000000"]],"time":"2020-06-30T19:10:32.442947Z"}
{"type":"l2update","product_id":"BTC-USD","changes":[["buy","9120.80","2883.05370000"]],"time":"2020-06-30T19:10:32.699106Z"}
{"type":"heartbeat","last_trade_id":0,"product_id":"BTC-USD","sequence":180754993,"time":"2020-06-30T19:10:32.735109Z"}
{"type":"l2update","product_id":"BTC-USD","changes":[["sell","9160.56","0.00000000"]],"time":"2020-06-30T19:10:32.938483Z"}
{"type":"heartbeat","last_trade_id":0,"product_id":"BTC-USD","sequence":180754994,"time":"2020-06-30T19:10:33.735108Z"}
{"type":"l2update","product_id":"BTC-USD","changes":[["buy","9107.06","0.01500000"]],"time":"2020-06-30T19:10:33.782364Z"}
{"type":"l2update","product_id":"BTC-USD","changes":[["buy","9120.80","2882.66640000"]],"time":"2020-06-30T19:10:34.071409Z"}
{"type":"l2update","product_id":"BTC-USD","changes":[["buy","9077.02","0.02350000"]],"time":"2020-06-30T19:10:34.658106Z"}
{"type":"heartbeat","last_trade_id":0,"product_id":"BTC-USD","sequence":180755001,"time":"2020-06-30T19:10:34.735082Z"}
{"type":"heartbeat","last_trade_id":0,"product_id":"BTC-USD","sequence":180755001,"time":"2020-06-30T19:10:35.735068Z"}
{"type":"l2update","product_id":"BTC-USD","changes":[["buy","9106.15","0.25000000"]],"time":"2020-06-30T19:10:35.806899Z"}
{"type":"l2update","product_id":"BTC-USD","changes":[["buy","9079.64","0.06920000"]],"time":"2020-06-30T19:10:36.071893Z"}
{"type":"l2update","product_id":"BTC-USD","changes":[["buy","9105.99","0.00000000"]],"time":"2020-06-30T19:10:36.271365Z"}
{"type":"l2update","product_id":"BTC-USD","changes":[["sell","9136.14","0.04690000"]],"time":"2020-06-30T19:10:36.347327Z"}
{"type":"heartbeat","last_trade_id":0,"product_id":"BTC-USD","sequence":180755008,"time":"2020-06-30T19:10:36.735072Z"}
{"type":"l2update","product_id":"BTC-USD","changes":[["buy","9073.36","0.06920000"]],"time":"2020-06-30T19:10:36.921070Z"}
{"type":"l2update","product_id":"BTC-USD","changes":[["sell","9160.27","0.05310000"]],"time":"2020-06-30T19:10:37.529104Z"}
{"type":"heartbeat","last_trade_id":0,"product_id":"BTC-USD","sequence":180755012,"time":"2020-06-30T19:10:37.735111Z"}
{"type":"l2update","product_id":"BTC-USD","changes":[["buy","9075.42","0.06920000"]],"time":"2020-06-30T19:10:37.749867Z"}
{"type":"l2update","product_id":"BTC-USD","changes":[["buy","9082.54","0.00000000"]],"time":"2020-06-30T19:10:37.963009Z"}
{"type":"heartbeat","last_trade_id":0,"product_id":"BTC-USD","sequence":180755015,"time":"2020-06-30T19:10:38.735121Z"}
{"type":"heartbeat","last_trade_id":0,"product_id":"BTC-USD","sequence":180755015,"time":"2020-06-30T19:10:39.735121Z"}
{"type":"l2update","product_id":"BTC-USD","changes":[["buy","9084.17","0.07770000"]],"time":"2020-06-30T19:10:39.985551Z"}
{"type":"l2update","product_id":"BTC-USD","changes":[["buy","9120.80","2880.66640000"]],"time":"2020-06-30T19:10:40.264902Z"}
{"type":"l2update","product_id":"BTC-USD","changes":[["buy","9083.35","0.02760000"]],"time":"2020-06-30T19:10:40.524143Z"}
{"type":"l2update","product_id":"BTC-USD","changes":[["sell","9131.21","0.00000000"]],"time":"2020-06-30T19:10:40.700324Z"}
{"type":"l2update","product_id":"BTC-USD","changes":[["buy","9075.42","0.00000000"]],"time":"2020-06-30T19:10:40.732615Z"}
{"type":"heartbeat","last_trade_id":0,"product_id":"BTC-USD","sequence":180755024,"time":"2020-06-30T19:10:40.735074Z"}
{"type":"l2update","product_id":"BTC-USD","changes":[["buy","9081.70","0.10640000"]],"time":"2020-06-30T19:10:40.805340Z"}
{"type":"l2update","product_id":"BTC-USD","changes":[["buy","9107.06","0.00000000"]],"time":"2020-06-30T19:10:40.806564Z"}
{"type":"l2update","product_id":"BTC-USD","changes":[["sell","9120.82","3008.14700000"]],"time":"2020-06-30T19:10:41.065112Z"}
{"type":"l2update","product_id":"BTC-USD","changes":[["buy","9120.80","2879.16640000"]],"time":"2020-06-30T19:10:41.086812Z"}
{"type":"l2update","product_id":"BTC-USD","changes":[["buy","9073.70","0.03950000"]],"time":"2020-06-30T19:10:41.361459Z"}
{"type":"l2update","product_id":"BTC-USD","changes":[["buy","9081.12","0.01000000"]],"time":"2020-06-30T19:10:41.639607Z"}
{"type":"heartbeat","last_trade_id":0,"product_id":"BTC-USD","sequence":180755037,"time":"2020-06-30T19:10:41.735094Z"}
{"type":"l2update","product_id":"BTC-USD","changes":[["buy","9079.64","0.00000000"]],"time":"2020-06-30T19:10:42.066149Z"}
{"type":"l2update","product_id":"BTC-USD","changes":[["buy","9075.61","0.06920000"]],"time":"2020-06-30T19:10:42.248407Z"}
{"type":"l2update","product_id":"BTC-USD","changes":[["buy","9104.80","0.75000000"]],"time":"2020-06-30T19:10:42.540444Z"}
{"type":"l2update","product_id":"BTC-USD","changes":[["buy","9084.37","0.00000000"]],"time":"2020-06-30T19:10:42.675489Z"}
{"type":"heartbeat","last_trade_id":0,"product_id":"BTC-USD","sequence":180755043,"time":"2020-06-30T19:10:42.735118Z"}
{"type":"l2update","product_id":"BTC-USD","changes":[["buy","9073.70","0.00000000"]],"time":"2020-06-30T19:10:43.005349Z"}
{"type":"heartbeat","last_trade_id":0,"product_id":"BTC-USD","sequence":180755044,"time":"2020-06-30T19:10:43.735118Z"}
{"type":"l2update","product_id":"BTC-USD","changes":[["buy","9120.80","2879.06020000"]],"time":"2020-06-30T19:10:43.971768Z"}
{"type":"l2update","product_id":"BTC-USD","changes":[["buy","100.00","114.95500000"]],"time":"2020-06-30T19:10:44.041557Z"}
{"type":"l2update","product_id":"BTC-USD","changes":[["buy","100.00","114.94500000"]],"time":"2020-06-30T19:10:44.049095Z"}
{"type":"l2update","product_id":"BTC-USD","changes":[["sell","9161.71","0.00000000"]],"time":"2020-06-30T19:10:44.411176Z"}
{"type":"l2update","product_id":"BTC-USD","changes":[["buy","9080.00","3.12010000"]],"time":"2020-06-30T19:10:44.566797Z"}
{"type":"heartbeat","last_trade_id":0,"product_id":"BTC-USD","sequence":180755053,"time":"2020-06-30T19:10:44.735125Z"}
{"type":"l2update","product_id":"BTC-USD","changes":[["buy","9081.15","0.02350000"]],"time":"2020-06-30T19:10:45.701440Z"}
{"type":"heartbeat","last_trade_id":0,"product_id":"BTC-USD","sequence":180755055,"time":"2020-06-30T19:10:45.735119Z"}
{"type":"l2update","product_id":"BTC-USD","changes":[["buy","9106.15","0.00000000"]],"time":"2020-06-30T19:10:46.187585Z"}
{"type":"l2update","product_id":"BTC-USD","changes":[["buy","9077.81","0.06920000"]],"time":"2020-06-30T19:10:46.417362Z"}
{"type":"l2update","product_id":"BTC-USD","changes":[["buy","9120.80","2879.02770000"]],"time":"2020-06-30T19:10:46.556729Z"}
{"type":"heartbeat","last_trade_id":0,"product_id":"BTC-USD","sequence":180755061,"time":"2020-06-30T19:10:46.735120Z"}
{"type":"l2update","product_id":"BTC-USD","changes":[["sell","9137.65","1.06990000"]],"time":"2020-06-30T19:10:47.116824Z"}
{"type":"l2update","product_id":"BTC-USD","changes":[["buy","9075.46","0.02350000"]],"time":"2020-06-30T19:10:47.429852Z"}
{"type":"l2update","product_id":"BTC-USD","changes":[["sell","9227.57","0.00000000"]],"time":"2020-06-30T19:10:47.534261Z"}
{"type":"heartbeat","last_trade_id":0,"product_id":"BTC-USD","sequence":180755066,"time":"2020-06-30T19:10:47.735089Z"}
{"type":"l2update","product_id":"BTC-USD","changes":[["buy","9084.17","0.15650000"]],"time":"2020-06-30T19:10:47.976363Z"}
{"type":"l2update","product_id":"BTC-USD","changes":[["buy","9105.38","1.75000000"]],"time":"2020-06-30T19:10:48.251971Z"}
{"type":"l2update","product_id":"BTC-USD","changes":[["buy","9084.17","0.07770000"]],"time":"2020-06-30T19:10:48.697551Z"}
{"type":"heartbeat","last_trade_id":0,"product_id":"BTC-USD","sequence":180755071,"time":"2020-06-30T19:10:48.735126Z"}
{"type":"l2update","product_id":"BTC-USD","changes":[["sell","9135.32","0.04500000"]],"time":"2020-06-30T19:10:49.412240Z"}
{"type":"heartbeat","last_trade_id":0,"product_id":"BTC-USD","sequence":180755073,"time":"2020-06-30T19:10:49.735111Z"}
{"type":"l2update","product_id":"BTC-USD","changes":[["buy","9120.80","2879.00610000"]],"time":"2020-06-30T19:10:50.274895Z"}
{"type":"l2update","product_id":"BTC-USD","changes":[["buy","9105.36","0.54800000"]],"time":"2020-06-30T19:10:50.559904Z"}
{"type":"heartbeat","last_trade_id":0,"product_id":"BTC-USD","sequence":180755078,"time":"2020-06-30T19:10:50.735095Z"}
{"type":"l2update","product_id":"BTC-USD","changes":[["buy","9084.17","0.00000000"]],"time":"2020-06-30T19:10:51.006793Z"}
{"type":"l2update","product_id":"BTC-USD","changes":[["buy","9081.70","0.00000000"]],"time":"2020-06-30T19:10:51.008200Z"}
{"type":"heartbeat","last_trade_id":0,"product_id":"BTC-USD","sequence":180755080,"time":"2020-06-30T19:10:51.735114Z"}
{"type":"l2update","product_id":"BTC-USD","changes":[["buy","9098.05","0.80660000"]],"time":"2020-06-30T19:10:52.573038Z"}
{"type":"heartbeat","last_trade_id":0,"product_id":"BTC-USD","sequence":180755082,"time":"2020-06-30T19:10:52.735141Z"}
{"type":"l2update","product_id":"BTC-USD","changes":[["buy","9083.35","0.00000000"]],"time":"2020-06-30T19:10:52.987560Z"}
{"type":"heartbeat","last_trade_id":0,"product_id":"BTC-USD","sequence":180755083,"time":"2020-06-30T19:10:53.735110Z"}
{"type":"l2update","product_id":"BTC-USD","changes":[["sell","9160.01","0.06900000"]],"time":"2020-06-30T19:10:53.761490Z"}
{"type":"l2update","product_id":"BTC-USD","changes":[["buy","9107.06","4.21690000"]],"time":"2020-06-30T19:10:54.623411Z"}
{"type":"heartbeat","last_trade_id":0,"product_id":"BTC-USD","sequence":180755087,"time":"2020-06-30T19:10:54.735122Z"}
{"type":"l2update","product_id":"BTC-USD","changes":[["buy","9098.05","0.00000000"]],"time":"2020-06-30T19:10:55.062105Z"}
{"type":"l2update","product_id":"BTC-USD","changes":[["sell","9159.26","0.06900000"]],"time":"2020-06-30T19:10:55.200688Z"}
{"type":"l2update","product_id":"BTC-USD","changes":[["buy","9103.23","0.90000000"]],"time":"2020-06-30T19:10:55.741559Z"}
{"type":"heartbeat","last_trade_id":0,"product_id":"BTC-USD","sequence":180755092,"time":"2020-06-30T19:10:55.735119Z"}
{"type":"l2update","product_id":"BTC-USD","changes":[["buy","9105.36","0.00000000"]],"time":"2020-06-30T19:10:56.190503Z"}
{"type":"l2update","product_id":"BTC-USD","changes":[["buy","9075.46","0.00000000"]],"time":"2020-06-30T19:10:56.196396Z"}
{"type":"l2update","product_id":"BTC-USD","changes":[["buy","9105.38","0.00000000"]],"time":"2020-06-30T19:10:56.203067Z"}
{"type":"l2update","product_id":"BTC-USD","changes":[["sell","9120.82","3007.89700000"]],"time":"2020-06-30T19:10:56.273878Z"}
{"type":"l2update","product_id":"BTC-USD","changes":[["buy","9075.31","0.06920000"]],"time":"2020-06-30T19:10:56.567504Z"}
{"type":"heartbeat","last_trade_id":0,"product_id":"BTC-USD","sequence":180755100,"time":"2020-06-30T19:10:56.735032Z"}
{"type":"l2update","product_id":"BTC-USD","changes":[["buy","9083.58","0.01000000"]],"time":"2020-06-30T19:10:56.897490Z"}
{"type":"l2update","product_id":"BTC-USD","changes":[["buy","9081.15","0.00000000"]],"time":"2020-06-30T19:10:57.106648Z"}
{"type":"l2update","product_id":"BTC-USD","changes":[["buy","9120.80","2877.36310000"]],"time":"2020-06-30T19:10:57.168103Z"}
{"type":"l2update","product_id":"BTC-USD","changes":[["buy","9086.05","0.01000000"]],"time":"2020-06-30T19:10:57.445699Z"}
{"type":"l2update","product_id":"BTC-USD","changes":[["sell","9153.30","0.06160000"]],"time":"2020-06-30T19:10:57.742154Z"}
{"type":"heartbeat","last_trade_id":0,"product_id":"BTC-USD","sequence":180755110,"time":"2020-06-30T19:10:57.735103Z"}
{"type":"l2update","product_id":"BTC-USD","changes":[["sell","9136.14","0.00000000"]],"time":"2020-06-30T19:10:57.759858Z"}
{"type":"l2update","product_id":"BTC-USD","changes":[["buy","9077.41","0.03680000"]],"time":"2020-06-30T19:10:58.002843Z"}
{"type":"l2update","product_id":"BTC-USD","changes":[["sell","9142.68","0.00000000"]],"time":"2020-06-30T19:10:58.180971Z"}
{"type":"heartbeat","last_trade_id":0,"product_id":"BTC-USD","sequence":180755114,"time":"2020-06-30T19:10:58.735112Z"}
{"type":"l2update","product_id":"BTC-USD","changes":[["buy","8896.47","0.00000000"]],"time":"2020-06-30T19:10:59.000541Z"}
{"type":"l2update","product_id":"BTC-USD","changes":[["buy","100.00","114.95500000"]],"time":"2020-06-30T19:10:59.080840Z"}
{"type":"l2update","product_id":"BTC-USD","changes":[["buy","100.00","114.94500000"]],"time":"2020-06-30T19:10:59.087293Z"}
{"type":"l2update","product_id":"BTC-USD","changes":[["buy","9072.38","0.03950000"]],"time":"2020-06-30T19:10:59.113413Z"}
{"type":"l2update","product_id":"BTC-USD","changes":[["buy","8895.64","0.04623953"]],"time":"2020-06-30T19:10:59.215670Z"}
{"type":"l2update","product_id":"BTC-USD","changes":[["buy","9072.93","0.06920000"]],"time":"2020-06-30T19:10:59.386464Z"}
{"type":"l2update","product_id":"BTC-USD","changes":[["sell","9434.33","0.00000000"]],"time":"2020-06-30T19:10:59.430554Z"}
{"type":"l2update","product_id":"BTC-USD","changes":[["buy","9072.38","0.00000000"]],"time":"2020-06-30T19:10:59.588796Z"}
{"type":"l2update","product_id":"BTC-USD","changes":[["buy","9075.31","0.00000000"]],"time":"2020-06-30T19:10:59.594853Z"}
{"type":"l2update","product_id":"BTC-USD","changes":[["sell","9435.21","0.00699029"]],"time":"2020-06-30T19:10:59.652285Z"}
{"type":"l2update","product_id":"BTC-USD","changes":[["buy","9080.00","0.00000000"]],"time":"2020-06-30T19:10:59.691165Z"}
{"type":"heartbeat","last_trade_id":0,"product_id":"BTC-USD","sequence":180755130,"time":"2020-06-30T19:10:59.735121Z"}
{"type":"l2update","product_id":"BTC-USD","changes":[["sell","9159.17","0.06900000"]],"time":"2020-06-30T19:11:00.253142Z"}
{"type":"l2update","product_id":"BTC-USD","changes":[["buy","9120.80","2877.11310000"]],"time":"2020-06-30T19:11:00.508097Z"}
{"type":"l2update","product_id":"BTC-USD","changes":[["sell","9153.30","0.00000000"]],"time":"2020-06-30T19:11:00.705015Z"}
{"type":"l2update","product_id":"BTC-USD","changes":[["sell","9135.32","0.00000000"]],"time":"2020-06-30T19:11:00.709310Z"}
{"type":"heartbeat","last_trade_id":0,"product_id":"BTC-USD","sequence":180755137,"time":"2020-06-30T19:11:00.735124Z"}
{"type":"heartbeat","last_trade_id":0,"product_id":"BTC-USD","sequence":180755137,"time":"2020-06-30T19:11:01.735115Z"}
{"type":"l2update","product_id":"BTC-USD","changes":[["buy","9078.98","0.06920000"]],"time":"2020-06-30T19:11:02.707085Z"}
{"type":"heartbeat","last_trade_id":0,"product_id":"BTC-USD","sequence":180755139,"time":"2020-06-30T19:11:02.735112Z"}
{"type":"l2update","product_id":"BTC-USD","changes":[["buy","9083.58","0.00000000"]],"time":"2020-06-30T19:11:03.102343Z"}
{"type":"l2update","product_id":"BTC-USD","changes":[["sell","9170.81","0.00200000"]],"time":"2020-06-30T19:11:03.214113Z"}
{"type":"l2update","product_id":"BTC-USD","changes":[["buy","9120.80","2877.06310000"]],"time":"2020-06-30T19:11:03.701089Z"}
{"type":"heartbeat","last_trade_id":0,"product_id":"BTC-USD","sequence":180755145,"time":"2020-06-30T19:11:03.735116Z"}
{"type":"l2update","product_id":"BTC-USD","changes":[["sell","9160.01","0.00000000"]],"time":"2020-06-30T19:11:03.779590Z"}
{"type":"l2update","product_id":"BTC-USD","changes":[["buy","9073.15","0.06920000"]],"time":"2020-06-30T19:11:04.237729Z"}
{"type":"l2update","product_id":"BTC-USD","changes":[["buy","9120.80","2876.99720000"]],"time":"2020-06-30T19:11:04.537931Z"}
{"type":"l2update","product_id":"BTC-USD","changes":[["buy","9086.05","0.00000000"]],"time":"2020-06-30T19:11:04.688158Z"}
{"type":"l2update","product_id":"BTC-USD","changes":[["sell","9120.82","3007.64700000"]],"time":"2020-06-30T19:11:04.740338Z"}
{"type":"heartbeat","last_trade_id":0,"product_id":"BTC-USD","sequence":180755155,"time":"2020-06-30T19:11:04.735116Z"}
{"type":"l2update","product_id":"BTC-USD","changes":[["sell","9159.17","0.00000000"]],"time":"2020-06-30T19:11:04.970237Z"}
{"type":"l2update","product_id":"BTC-USD","changes":[["buy","9074.53","0.02350000"]],"time":"2020-06-30T19:11:05.076867Z"}
{"type":"l2update","product_id":"BTC-USD","changes":[["buy","9120.80","2875.62830000"]],"time":"2020-06-30T19:11:05.355046Z"}
{"type":"l2update","product_id":"BTC-USD","changes":[["buy","9075.63","0.09670000"]],"time":"2020-06-30T19:11:05.627038Z"}
{"type":"heartbeat","last_trade_id":0,"product_id":"BTC-USD","sequence":180755163,"time":"2020-06-30T19:11:05.735117Z"}
{"type":"l2update","product_id":"BTC-USD","changes":[["buy","9104.80","0.00000000"]],"time":"2020-06-30T19:11:06.133029Z"}
{"type":"l2update","product_id":"BTC-USD","changes":[["buy","9077.41","0.00000000"]],"time":"2020-06-30T19:11:06.142747Z"}
{"type":"l2update","product_id":"BTC-USD","changes":[["buy","9102.84","1.29600000"]],"time":"2020-06-30T19:11:06.210842Z"}
{"type":"l2update","product_id":"BTC-USD","changes":[["buy","9072.93","0.00000000"]],"time":"2020-06-30T19:11:06.633046Z"}
{"type":"heartbeat","last_trade_id":0,"product_id":"BTC-USD","sequence":180755168,"time":"2020-06-30T19:11:06.735110Z"}
{"type":"heartbeat","last_trade_id":0,"product_id":"BTC-USD","sequence":180755168,"time":"2020-06-30T19:11:07.735054Z"}
{"type":"l2update","product_id":"BTC-USD","changes":[["buy","9120.80","2874.80970000"]],"time":"2020-06-30T19:11:07.928850Z"}
{"type":"heartbeat","last_trade_id":0,"product_id":"BTC-USD","sequence":180755171,"time":"2020-06-30T19:11:08.735114Z"}
{"type":"l2update","product_id":"BTC-USD","changes":[["buy","9072.54","0.06920000"]],"time":"2020-06-30T19:11:09.004676Z"}
{"type":"l2update","product_id":"BTC-USD","changes":[["buy","9120.80","2874.55970000"]],"time":"2020-06-30T19:11:09.028744Z"}
{"type":"l2update","product_id":"BTC-USD","changes":[["buy","9075.61","0.00000000"]],"time":"2020-06-30T19:11:09.432742Z"}
{"type":"l2update","product_id":"BTC-USD","changes":[["buy","8906.87","0.00300000"]],"time":"2020-06-30T19:11:09.551144Z"}
{"type":"heartbeat","last_trade_id":0,"product_id":"BTC-USD","sequence":180755179,"time":"2020-06-30T19:11:09.735121Z"}
{"type":"l2update","product_id":"BTC-USD","changes":[["sell","9160.07","0.00100000"]],"time":"2020-06-30T19:11:09.817004Z"}
{"type":"l2update","product_id":"BTC-USD","changes":[["buy","9075.63","0.00000000"]],"time":"2020-06-30T19:11:10.016038Z"}
{"type":"l2update","product_id":"BTC-USD","changes":[["buy","9075.15","0.09670000"]],"time":"2020-06-30T19:11:10.101412Z"}
{"type":"l2update","product_id":"BTC-USD","changes":[["sell","9158.32","0.06900000"]],"time":"2020-06-30T19:11:10.384836Z"}
{"type":"l2update","product_id":"BTC-USD","changes":[["buy","8906.87","0.00000000"]],"time":"2020-06-30T19:11:10.535371Z"}
{"type":"heartbeat","last_trade_id":0,"product_id":"BTC-USD","sequence":180755187,"time":"2020-06-30T19:11:10.735120Z"}
{"type":"l2update","product_id":"BTC-USD","changes":[["sell","9158.30","0.06900000"]],"time":"2020-06-30T19:11:10.926110Z"}
{"type":"l2update","product_id":"BTC-USD","changes":[["buy","9120.80","2874.55870000"]],"time":"2020-06-30T19:11:11.087014Z"}
{"type":"l2update","product_id":"BTC-USD","changes":[["sell","9170.81","0.00000000"]],"time":"2020-06-30T19:11:11.372337Z"}
{"type":"l2update","product_id":"BTC-USD","changes":[["buy","9105.08","0.05000000"]],"time":"2020-06-30T19:11:11.504339Z"}
{"type":"heartbeat","last_trade_id":0,"product_id":"BTC-USD","sequence":180755195,"time":"2020-06-30T19:11:11.735119Z"}
{"type":"l2update","product_id":"BTC-USD","changes":[["buy","9105.59","0.05000000"]],"time":"2020-06-30T19:11:12.078992Z"}
{"type":"l2update","product_id":"BTC-USD","changes":[["buy","9120.80","2874.49870000"]],"time":"2020-06-30T19:11:12.327349Z"}
{"type":"l2update","product_id":"BTC-USD","changes":[["buy","9107.06","0.00000000"]],"time":"2020-06-30T19:11:12.526986Z"}
{"type":"heartbeat","last_trade_id":0,"product_id":"BTC-USD","sequence":180755201,"time":"2020-06-30T19:11:12.735117Z"}
{"type":"l2update","product_id":"BTC-USD","changes":[["sell","9158.32","0.00000000"]],"time":"2020-06-30T19:11:12.793837Z"}
{"type":"l2update","product_id":"BTC-USD","changes":[["buy","9120.80","2874.24980000"]],"time":"2020-06-30T19:11:12.924171Z"}
{"type":"l2update","product_id":"BTC-USD","changes":[["sell","9158.20","0.06900000"]],"time":"2020-06-30T19:11:13.200185Z"}
{"type":"l2update","product_id":"BTC-USD","changes":[["buy","9084.17","0.01870000"]],"time":"2020-06-30T19:11:13.464361Z"}
{"type":"heartbeat","last_trade_id":0,"product_id":"BTC-USD","sequence":180755209,"time":"2020-06-30T19:11:13.735106Z"}
{"type":"l2update","product_id":"BTC-USD","changes":[["buy","9074.53","0.00000000"]],"time":"2020-06-30T19:11:13.881698Z"}
{"type":"l2update","product_id":"BTC-USD","changes":[["buy","9084.58","0.09740000"]],"time":"2020-06-30T19:11:14.021656Z"}
{"type":"l2update","product_id":"BTC-USD","changes":[["buy","100.00","114.95500000"]],"time":"2020-06-30T19:11:14.032039Z"}
{"type":"l2update","product_id":"BTC-USD","changes":[["buy","100.00","114.94500000"]],"time":"2020-06-30T19:11:14.039537Z"}
{"type":"l2update","product_id":"BTC-USD","changes":[["buy","9120.80","2874.09850000"]],"time":"2020-06-30T19:11:14.587798Z"}
{"type":"heartbeat","last_trade_id":0,"product_id":"BTC-USD","sequence":180755218,"time":"2020-06-30T19:11:14.735117Z"}
{"type":"l2update","product_id":"BTC-USD","changes":[["sell","9159.26","0.00000000"]],"time":"2020-06-30T19:11:15.031303Z"}
{"type":"l2update","product_id":"BTC-USD","changes":[["sell","9160.27","0.00000000"]],"time":"2020-06-30T19:11:15.032185Z"}
{"type":"l2update","product_id":"BTC-USD","changes":[["buy","9075.50","0.09670000"]],"time":"2020-06-30T19:11:15.171323Z"}
{"type":"l2update","product_id":"BTC-USD","changes":[["buy","9120.80","2874.03850000"]],"time":"2020-06-30T19:11:15.457932Z"}
{"type":"l2update","product_id":"BTC-USD","changes":[["buy","9105.59","0.00000000"]],"time":"2020-06-30T19:11:15.586369Z"}
{"type":"l2update","product_id":"BTC-USD","changes":[["buy","9077.02","0.00000000"]],"time":"2020-06-30T19:11:15.593022Z"}
{"type":"l2update","product_id":"BTC-USD","changes":[["buy","9102.76","0.00000000"]],"time":"2020-06-30T19:11:15.598114Z"}
{"type":"l2update","product_id":"BTC-USD","changes":[["buy","9105.08","0.00000000"]],"time":"2020-06-30T19:11:15.611533Z"}
{"type":"l2update","product_id":"BTC-USD","changes":[["buy","9106.21","0.13570000"]],"time":"2020-06-30T19:11:15.711865Z"}
{"type":"heartbeat","last_trade_id":0,"product_id":"BTC-USD","sequence":180755231,"time":"2020-06-30T19:11:15.735111Z"}
{"type":"l2update","product_id":"BTC-USD","changes":[["buy","9075.50","0.00000000"]],"time":"2020-06-30T19:11:16.163026Z"}
{"type":"l2update","product_id":"BTC-USD","changes":[["buy","9078.98","0.00000000"]],"time":"2020-06-30T19:11:16.168459Z"}
{"type":"heartbeat","last_trade_id":0,"product_id":"BTC-USD","sequence":180755233,"time":"2020-06-30T19:11:16.735025Z"}
{"type":"l2update","product_id":"BTC-USD","changes":[["buy","9106.26","0.10380000"]],"time":"2020-06-30T19:11:17.388227Z"}
{"type":"heartbeat","last_trade_id":0,"product_id":"BTC-USD","sequence":180755235,"time":"2020-06-30T19:11:17.735164Z"}
{"type":"l2update","product_id":"BTC-USD","changes":[["buy","9120.80","2874.01490000"]],"time":"2020-06-30T19:11:18.256737Z"}
{"type":"l2update","product_id":"BTC-USD","changes":[["buy","9120.80","2869.84220000"]],"time":"2020-06-30T19:11:18.513162Z"}
{"type":"heartbeat","last_trade_id":0,"product_id":"BTC-USD","sequence":180755241,"time":"2020-06-30T19:11:18.735082Z"}
{"type":"l2update","product_id":"BTC-USD","changes":[["buy","9043.10","0.08790000"]],"time":"2020-06-30T19:11:18.793416Z"}
{"type":"l2update","product_id":"BTC-USD","changes":[["buy","9105.47","0.12840000"]],"time":"2020-06-30T19:11:19.074403Z"}
{"type":"l2update","product_id":"BTC-USD","changes":[["buy","9103.23","0.00000000"]],"time":"2020-06-30T19:11:19.226160Z"}
{"type":"l2update","product_id":"BTC-USD","changes":[["buy","9080.54","0.00000000"]],"time":"2020-06-30T19:11:19.229293Z"}
{"type":"heartbeat","last_trade_id":0,"product_id":"BTC-USD","sequence":180755247,"time":"2020-06-30T19:11:19.735097Z"}
{"type":"l2update","product_id":"BTC-USD","changes":[["sell","9120.82","3007.39700000"]],"time":"2020-06-30T19:11:19.913837Z"}
{"type":"heartbeat","last_trade_id":0,"product_id":"BTC-USD","sequence":180755250,"time":"2020-06-30T19:11:20.735112Z"}
{"type":"l2update","product_id":"BTC-USD","changes":[["buy","9105.49","0.06590000"]],"time":"2020-06-30T19:11:20.747735Z"}
{"type":"l2update","product_id":"BTC-USD","changes":[["buy","9106.44","0.17050000"]],"time":"2020-06-30T19:11:21.002790Z"}
{"type":"l2update","product_id":"BTC-USD","changes":[["buy","9077.81","0.00000000"]],"time":"2020-06-30T19:11:21.176043Z"}
{"type":"l2update","product_id":"BTC-USD","changes":[["buy","9106.44","4.97010000"]],"time":"2020-06-30T19:11:21.284005Z"}
{"type":"l2update","product_id":"BTC-USD","changes":[["buy","9120.80","2869.59220000"]],"time":"2020-06-30T19:11:21.511701Z"}
{"type":"l2update","product_id":"BTC-USD","changes":[["buy","9043.10","0.00000000"]],"time":"2020-06-30T19:11:21.724742Z"}
{"type":"heartbeat","last_trade_id":0,"product_id":"BTC-USD","sequence":180755261,"time":"2020-06-30T19:11:21.735109Z"}
{"type":"l2update","product_id":"BTC-USD","changes":[["sell","9138.33","1.08190000"]],"time":"2020-06-30T19:11:22.169314Z"}
{"type":"l2update","product_id":"BTC-USD","changes":[["buy","9076.36","0.02350000"]],"time":"2020-06-30T19:11:22.441215Z"}
{"type":"heartbeat","last_trade_id":0,"product_id":"BTC-USD","sequence":180755265,"time":"2020-06-30T19:11:22.735076Z"}
{"type":"l2update","product_id":"BTC-USD","changes":[["sell","9120.82","3007.14700000"]],"time":"2020-06-30T19:11:23.136051Z"}
{"type":"l2update","product_id":"BTC-USD","changes":[["sell","9133.28","1.08490000"]],"time":"2020-06-30T19:11:23.299287Z"}
{"type":"l2update","product_id":"BTC-USD","changes":[["buy","9085.81","0.07880000"]],"time":"2020-06-30T19:11:23.579401Z"}
{"type":"l2update","product_id":"BTC-USD","changes":[["sell","9138.33","0.00000000"]],"time":"2020-06-30T19:11:23.739820Z"}
{"type":"heartbeat","last_trade_id":0,"product_id":"BTC-USD","sequence":180755273,"time":"2020-06-30T19:11:23.735097Z"}
{"type":"l2update","product_id":"BTC-USD","changes":[["buy","9106.44","4.79960000"]],"time":"2020-06-30T19:11:24.026118Z"}
{"type":"l2update","product_id":"BTC-USD","changes":[["buy","9081.12","0.00000000"]],"time":"2020-06-30T19:11:24.029512Z"}
{"type":"l2update","product_id":"BTC-USD","changes":[["buy","9073.15","0.00000000"]],"time":"2020-06-30T19:11:24.049676Z"}
{"type":"l2update","product_id":"BTC-USD","changes":[["buy","9080.87","0.06920000"]],"time":"2020-06-30T19:11:24.680862Z"}
{"type":"heartbeat","last_trade_id":0,"product_id":"BTC-USD","sequence":180755278,"time":"2020-06-30T19:11:24.735116Z"}
{"type":"l2update","product_id":"BTC-USD","changes":[["buy","9120.80","2869.34220000"]],"time":"2020-06-30T19:11:24.814671Z"}
{"type":"l2update","product_id":"BTC-USD","changes":[["buy","9081.28","0.09670000"]],"time":"2020-06-30T19:11:24.962638Z"}
{"type":"l2update","product_id":"BTC-USD","changes":[["buy","9084.17","0.00000000"]],"time":"2020-06-30T19:11:25.384098Z"}
{"type":"l2update","product_id":"BTC-USD","changes":[["sell","9158.17","0.06900000"]],"time":"2020-06-30T19:11:25.522376Z"}
{"type":"heartbeat","last_trade_id":0,"product_id":"BTC-USD","sequence":180755286,"time":"2020-06-30T19:11:25.735116Z"}
{"type":"l2update","product_id":"BTC-USD","changes":[["buy","9072.20","0.06920000"]],"time":"2020-06-30T19:11:25.779954Z"}
{"type":"l2update","product_id":"BTC-USD","changes":[["sell","9133.28","0.00000000"]],"time":"2020-06-30T19:11:25.937417Z"}
{"type":"l2update","product_id":"BTC-USD","changes":[["sell","9157.87","0.06900000"]],"time":"2020-06-30T19:11:26.061457Z"}
{"type":"l2update","product_id":"BTC-USD","changes":[["buy","9073.30","0.06920000"]],"time":"2020-06-30T19:11:26.351961Z"}
{"type":"l2update","product_id":"BTC-USD","changes":[["sell","9157.58","0.06900000"]],"time":"2020-06-30T19:11:26.608493Z"}
{"type":"l2update","product_id":"BTC-USD","changes":[["sell","9120.82","3006.89700000"]],"time":"2020-06-30T19:11:26.629346Z"}
{"type":"heartbeat","last_trade_id":0,"product_id":"BTC-USD","sequence":180755298,"time":"2020-06-30T19:11:26.735131Z"}
{"type":"l2update","product_id":"BTC-USD","changes":[["sell","9158.30","0.00000000"]],"time":"2020-06-30T19:11:27.056209Z"}
{"type":"l2update","product_id":"BTC-USD","changes":[["sell","9157.53","0.06900000"]],"time":"2020-06-30T19:11:27.738735Z"}
{"type":"heartbeat","last_trade_id":0,"product_id":"BTC-USD","sequence":180755301,"time":"2020-06-30T19:11:27.735074Z"}
{"type":"l2update","product_id":"BTC-USD","changes":[["sell","9137.65","0.00000000"]],"time":"2020-06-30T19:11:27.927950Z"}
{"type":"l2update","product_id":"BTC-USD","changes":[["buy","9120.80","2869.09220000"]],"time":"2020-06-30T19:11:28.695417Z"}
{"type":"heartbeat","last_trade_id":0,"product_id":"BTC-USD","sequence":180755305,"time":"2020-06-30T19:11:28.735048Z"}
{"type":"l2update","product_id":"BTC-USD","changes":[["sell","9157.48","0.07000000"]],"time":"2020-06-30T19:11:28.864834Z"}
{"type":"l2update","product_id":"BTC-USD","changes":[["buy","100.00","114.95500000"]],"time":"2020-06-30T19:11:29.030896Z"}
{"type":"l2update","product_id":"BTC-USD","changes":[["buy","100.00","114.94500000"]],"time":"2020-06-30T19:11:29.037894Z"}
{"type":"l2update","product_id":"BTC-USD","changes":[["sell","9157.58","0.00000000"]],"time":"2020-06-30T19:11:29.324946Z"}
{"type":"l2update","product_id":"BTC-USD","changes":[["sell","9157.46","0.06900000"]],"time":"2020-06-30T19:11:29.430872Z"}
{"type":"heartbeat","last_trade_id":0,"product_id":"BTC-USD","sequence":180755313,"time":"2020-06-30T19:11:29.735049Z"}
{"type":"l2update","product_id":"BTC-USD","changes":[["buy","9106.19","0.05000000"]],"time":"2020-06-30T19:11:29.978284Z"}
{"type":"l2update","product_id":"BTC-USD","changes":[["sell","9120.82","3006.64700000"]],"time":"2020-06-30T19:11:30.108579Z"}
{"type":"l2update","product_id":"BTC-USD","changes":[["buy","9072.26","0.10870000"]],"time":"2020-06-30T19:11:30.261557Z"}
{"type":"l2update","product_id":"BTC-USD","changes":[["buy","9072.20","0.00000000"]],"time":"2020-06-30T19:11:30.475334Z"}
{"type":"heartbeat","last_trade_id":0,"product_id":"BTC-USD","sequence":180755321,"time":"2020-06-30T19:11:30.735036Z"}
{"type":"l2update","product_id":"BTC-USD","changes":[["sell","9158.19","0.06900000"]],"time":"2020-06-30T19:11:31.100093Z"}
{"type":"l2update","product_id":"BTC-USD","changes":[["buy","9075.13","0.06920000"]],"time":"2020-06-30T19:11:31.420421Z"}
{"type":"l2update","product_id":"BTC-USD","changes":[["sell","9157.53","0.00000000"]],"time":"2020-06-30T19:11:31.546115Z"}
{"type":"heartbeat","last_trade_id":0,"product_id":"BTC-USD","sequence":180755326,"time":"2020-06-30T19:11:31.735055Z"}
{"type":"l2update","product_id":"BTC-USD","changes":[["buy","9086.05","0.01000000"]],"time":"2020-06-30T19:11:32.217022Z"}
{"type":"l2update","product_id":"BTC-USD","changes":[["buy","9081.28","0.00000000"]],"time":"2020-06-30T19:11:32.445614Z"}
{"type":"l2update","product_id":"BTC-USD","changes":[["buy","9075.15","0.00000000"]],"time":"2020-06-30T19:11:32.448854Z"}
{"type":"l2update","product_id":"BTC-USD","changes":[["buy","9072.54","0.00000000"]],"time":"2020-06-30T19:11:32.450487Z"}
{"type":"heartbeat","last_trade_id":0,"product_id":"BTC-USD","sequence":180755331,"time":"2020-06-30T19:11:32.735177Z"}
{"type":"l2update","product_id":"BTC-USD","changes":[["sell","9157.28","0.06900000"]],"time":"2020-06-30T19:11:33.334895Z"}
{"type":"heartbeat","last_trade_id":0,"product_id":"BTC-USD","sequence":180755333,"time":"2020-06-30T19:11:33.735096Z"}
{"type":"l2update","product_id":"BTC-USD","changes":[["sell","9132.09","1.07250000"]],"time":"2020-06-30T19:11:33.883694Z"}
{"type":"l2update","product_id":"BTC-USD","changes":[["sell","9160.07","0.00000000"]],"time":"2020-06-30T19:11:34.333445Z"}
{"type":"l2update","product_id":"BTC-USD","changes":[["sell","9157.48","0.00000000"]],"time":"2020-06-30T19:11:34.353973Z"}
{"type":"l2update","product_id":"BTC-USD","changes":[["sell","9158.19","0.00000000"]],"time":"2020-06-30T19:11:34.368876Z"}
{"type":"heartbeat","last_trade_id":0,"product_id":"BTC-USD","sequence":180755338,"time":"2020-06-30T19:11:34.735111Z"}
{"type":"l2update","product_id":"BTC-USD","changes":[["sell","9120.82","3006.39700000"]],"time":"2020-06-30T19:11:34.952282Z"}
{"type":"l2update","product_id":"BTC-USD","changes":[["buy","9081.32","0.09670000"]],"time":"2020-06-30T19:11:35.091195Z"}
{"type":"l2update","product_id":"BTC-USD","changes":[["buy","9105.31","0.75000000"]],"time":"2020-06-30T19:11:35.354126Z"}
{"type":"l2update","product_id":"BTC-USD","changes":[["sell","9137.03","1.15180000"]],"time":"2020-06-30T19:11:35.626526Z"}
{"type":"heartbeat","last_trade_id":0,"product_id":"BTC-USD","sequence":180755347,"time":"2020-06-30T19:11:35.735052Z"}
{"type":"l2update","product_id":"BTC-USD","changes":[["buy","9073.30","0.00000000"]],"time":"2020-06-30T19:11:35.799147Z"}
{"type":"l2update","product_id":"BTC-USD","changes":[["buy","9084.58","0.00000000"]],"time":"2020-06-30T19:11:35.803121Z"}
{"type":"l2update","product_id":"BTC-USD","changes":[["buy","9051.56","0.08790000"]],"time":"2020-06-30T19:11:35.896996Z"}
{"type":"l2update","product_id":"BTC-USD","changes":[["buy","9073.36","0.00000000"]],"time":"2020-06-30T19:11:36.342600Z"}
{"type":"l2update","product_id":"BTC-USD","changes":[["buy","9105.47","0.00000000"]],"time":"2020-06-30T19:11:36.344084Z"}
{"type":"l2update","product_id":"BTC-USD","changes":[["buy","9120.80","2866.72720000"]],"time":"2020-06-30T19:11:36.724932Z"}
{"type":"heartbeat","last_trade_id":0,"product_id":"BTC-USD","sequence":180755356,"time":"2020-06-30T19:11:36.735078Z"}
{"type":"l2update","product_id":"BTC-USD","changes":[["sell","9157.93","0.06760000"]],"time":"2020-06-30T19:11:36.999216Z"}
{"type":"l2update","product_id":"BTC-USD","changes":[["sell","9157.46","0.00000000"]],"time":"2020-06-30T19:11:37.144585Z"}
{"type":"l2update","product_id":"BTC-USD","changes":[["buy","9106.00","0.05000000"]],"time":"2020-06-30T19:11:37.268356Z"}
{"type":"heartbeat","last_trade_id":0,"product_id":"BTC-USD","sequence":180755361,"time":"2020-06-30T19:11:37.735127Z"}
{"type":"l2update","product_id":"BTC-USD","changes":[["sell","9137.05","1.00080000"]],"time":"2020-06-30T19:11:38.126708Z"}
{"type":"l2update","product_id":"BTC-USD","changes":[["sell","9157.87","0.00000000"]],"time":"2020-06-30T19:11:38.585846Z"}
{"type":"l2update","product_id":"BTC-USD","changes":[["sell","9158.17","0.00000000"]],"time":"2020-06-30T19:11:38.600782Z"}
{"type":"l2update","product_id":"BTC-USD","changes":[["sell","9157.28","0.00000000"]],"time":"2020-06-30T19:11:38.611186Z"}
{"type":"heartbeat","last_trade_id":0,"product_id":"BTC-USD","sequence":180755366,"time":"2020-06-30T19:11:38.735041Z"}
{"type":"heartbeat","last_trade_id":0,"product_id":"BTC-USD","sequence":180755366,"time":"2020-06-30T19:11:39.735108Z"}
{"type":"l2update","product_id":"BTC-USD","changes":[["buy","9070.69","0.06920000"]],"time":"2020-06-30T19:11:40.353746Z"}
{"type":"heartbeat","last_trade_id":0,"product_id":"BTC-USD","sequence":180755368,"time":"2020-06-30T19:11:40.735074Z"}
{"type":"l2update","product_id":"BTC-USD","changes":[["buy","9106.21","0.00000000"]],"time":"2020-06-30T19:11:40.794351Z"}
{"type":"l2update","product_id":"BTC-USD","changes":[["buy","9105.49","0.00000000"]],"time":"2020-06-30T19:11:40.794576Z"}
{"type":"l2update","product_id":"BTC-USD","changes":[["buy","9080.87","0.00000000"]],"time":"2020-06-30T19:11:40.796701Z"}
{"type":"l2update","product_id":"BTC-USD","changes":[["buy","9086.05","0.00000000"]],"time":"2020-06-30T19:11:40.801583Z"}
{"type":"l2update","product_id":"BTC-USD","changes":[["sell","9120.82","3006.39600000"]],"time":"2020-06-30T19:11:41.676936Z"}
{"type":"heartbeat","last_trade_id":0,"product_id":"BTC-USD","sequence":180755375,"time":"2020-06-30T19:11:41.735023Z"}
{"type":"l2update","product_id":"BTC-USD","changes":[["buy","9073.58","0.06920000"]],"time":"2020-06-30T19:11:41.837071Z"}
{"type":"l2update","product_id":"BTC-USD","changes":[["buy","9106.44","0.00000000"]],"time":"2020-06-30T19:11:42.234868Z"}
{"type":"l2update","product_id":"BTC-USD","changes":[["buy","9074.68","0.06920000"]],"time":"2020-06-30T19:11:42.362172Z"}
{"type":"l2update","product_id":"BTC-USD","changes":[["buy","9081.12","0.01000000"]],"time":"2020-06-30T19:11:42.652903Z"}
{"type":"heartbeat","last_trade_id":0,"product_id":"BTC-USD","sequence":180755382,"time":"2020-06-30T19:11:42.735136Z"}
{"type":"l2update","product_id":"BTC-USD","changes":[["buy","9106.19","0.00000000"]],"time":"2020-06-30T19:11:43.103584Z"}
{"type":"l2update","product_id":"BTC-USD","changes":[["sell","9144.65","4.12020000"]],"time":"2020-06-30T19:11:43.210376Z"}
{"type":"l2update","product_id":"BTC-USD","changes":[["buy","9105.54","1.59600000"]],"time":"2020-06-30T19:11:43.484354Z"}
{"type":"heartbeat","last_trade_id":0,"product_id":"BTC-USD","sequence":180755387,"time":"2020-06-30T19:11:43.735043Z"}
{"type":"l2update","product_id":"BTC-USD","changes":[["buy","9120.80","2866.66130000"]],"time":"2020-06-30T19:11:43.820337Z"}
{"type":"l2update","product_id":"BTC-USD","changes":[["buy","100.00","114.95500000"]],"time":"2020-06-30T19:11:44.027763Z"}
{"type":"l2update","product_id":"BTC-USD","changes":[["buy","100.00","114.94500000"]],"time":"2020-06-30T19:11:44.034834Z"}
{"type":"l2update","product_id":"BTC-USD","changes":[["buy","9092.85","0.02630000"]],"time":"2020-06-30T19:11:44.358975Z"}
{"type":"heartbeat","last_trade_id":0,"product_id":"BTC-USD","sequence":180755395,"time":"2020-06-30T19:11:44.735038Z"}
{"type":"l2update","product_id":"BTC-USD","changes":[["buy","9120.80","2864.66130000"]],"time":"2020-06-30T19:11:45.201406Z"}
{"type":"heartbeat","last_trade_id":0,"product_id":"BTC-USD","sequence":180755398,"time":"2020-06-30T19:11:45.735018Z"}
{"type":"l2update","product_id":"BTC-USD","changes":[["buy","9072.69","0.02790000"]],"time":"2020-06-30T19:11:45.773089Z"}
{"type":"l2update","product_id":"BTC-USD","changes":[["buy","9105.54","0.00000000"]],"time":"2020-06-30T19:11:46.213390Z"}
{"type":"l2update","product_id":"BTC-USD","changes":[["buy","9120.80","2864.11730000"]],"time":"2020-06-30T19:11:46.609863Z"}
{"type":"heartbeat","last_trade_id":0,"product_id":"BTC-USD","sequence":180755404,"time":"2020-06-30T19:11:46.734985Z"}
{"type":"l2update","product_id":"BTC-USD","changes":[["buy","8930.72","0.00400000"]],"time":"2020-06-30T19:11:46.957464Z"}
{"type":"l2update","product_id":"BTC-USD","changes":[["sell","9144.65","0.00000000"]],"time":"2020-06-30T19:11:47.032312Z"}
{"type":"l2update","product_id":"BTC-USD","changes":[["sell","9132.09","0.00000000"]],"time":"2020-06-30T19:11:47.042797Z"}
{"type":"l2update","product_id":"BTC-USD","changes":[["buy","9075.69","0.09670000"]],"time":"2020-06-30T19:11:47.213823Z"}
{"type":"l2update","product_id":"BTC-USD","changes":[["buy","9051.56","0.00000000"]],"time":"2020-06-30T19:11:47.361936Z"}
{"type":"l2update","product_id":"BTC-USD","changes":[["sell","9283.64","0.00300000"]],"time":"2020-06-30T19:11:47.505576Z"}
{"type":"l2update","product_id":"BTC-USD","changes":[["buy","9105.31","0.00000000"]],"time":"2020-06-30T19:11:47.629669Z"}
{"type":"heartbeat","last_trade_id":0,"product_id":"BTC-USD","sequence":180755414,"time":"2020-06-30T19:11:47.735062Z"}
{"type":"l2update","product_id":"BTC-USD","changes":[["buy","9110.07","9.46920000"]],"time":"2020-06-30T19:11:48.053817Z"}
{"type":"l2update","product_id":"BTC-USD","changes":[["buy","9070.69","0.00000000"]],"time":"2020-06-30T19:11:48.496305Z"}
{"type":"heartbeat","last_trade_id":0,"product_id":"BTC-USD","sequence":180755417,"time":"2020-06-30T19:11:48.734983Z"}
{"type":"l2update","product_id":"BTC-USD","changes":[["buy","4560.00","0.25000000"]],"time":"2020-06-30T19:11:49.228458Z"}
{"type":"l2update","product_id":"BTC-USD","changes":[["buy","9073.48","0.03900000"]],"time":"2020-06-30T19:11:49.269944Z"}
{"type":"l2update","product_id":"BTC-USD","changes":[["buy","9106.26","0.00000000"]],"time":"2020-06-30T19:11:49.459625Z"}
{"type":"l2update","product_id":"BTC-USD","changes":[["buy","9085.81","0.00000000"]],"time":"2020-06-30T19:11:49.469535Z"}
{"type":"l2update","product_id":"BTC-USD","changes":[["buy","9074.68","0.00000000"]],"time":"2020-06-30T19:11:49.472695Z"}
{"type":"l2update","product_id":"BTC-USD","changes":[["buy","4560.00","0.00000000"]],"time":"2020-06-30T19:11:49.735908Z"}
{"type":"heartbeat","last_trade_id":0,"product_id":"BTC-USD","sequence":180755425,"time":"2020-06-30T19:11:49.735059Z"}
{"type":"l2update","product_id":"BTC-USD","changes":[["buy","9081.45","0.02790000"]],"time":"2020-06-30T19:11:50.101851Z"}
{"type":"l2update","product_id":"BTC-USD","changes":[["buy","9071.82","0.09670000"]],"time":"2020-06-30T19:11:50.392452Z"}
{"type":"l2update","product_id":"BTC-USD","changes":[["buy","8930.72","0.00000000"]],"time":"2020-06-30T19:11:50.588284Z"}
{"type":"heartbeat","last_trade_id":0,"product_id":"BTC-USD","sequence":180755430,"time":"2020-06-30T19:11:50.735074Z"}
{"type":"l2update","product_id":"BTC-USD","changes":[["buy","9076.36","0.00000000"]],"time":"2020-06-30T19:11:50.824767Z"}
{"type":"l2update","product_id":"BTC-USD","changes":[["buy","9079.19","0.07370000"]],"time":"2020-06-30T19:11:51.238652Z"}
{"type":"l2update","product_id":"BTC-USD","changes":[["buy","4560.00","0.25000000"]],"time":"2020-06-30T19:11:51.310266Z"}
{"type":"l2update","product_id":"BTC-USD","changes":[["buy","4560.00","0.00000000"]],"time":"2020-06-30T19:11:51.398086Z"}
{"type":"l2update","product_id":"BTC-USD","changes":[["buy","9090.34","0.01650000"]],"time":"2020-06-30T19:11:51.500936Z"}
{"type":"heartbeat","last_trade_id":0,"product_id":"BTC-USD","sequence":180755438,"time":"2020-06-30T19:11:51.735069Z"}
{"type":"heartbeat","last_trade_id":0,"product_id":"BTC-USD","sequence":180755438,"time":"2020-06-30T19:11:52.735030Z"}
{"type":"l2update","product_id":"BTC-USD","changes":[["buy","9109.07","0.90000000"]],"time":"2020-06-30T19:11:53.154342Z"}
{"type":"l2update","product_id":"BTC-USD","changes":[["buy","9073.48","0.00000000"]],"time":"2020-06-30T19:11:53.368390Z"}
{"type":"l2update","product_id":"BTC-USD","changes":[["buy","9075.13","0.00000000"]],"time":"2020-06-30T19:11:53.369060Z"}
{"type":"l2update","product_id":"BTC-USD","changes":[["buy","9073.58","0.00000000"]],"time":"2020-06-30T19:11:53.375533Z"}
{"type":"l2update","product_id":"BTC-USD","changes":[["buy","9109.20","1.00000000"]],"time":"2020-06-30T19:11:53.428041Z"}
{"type":"l2update","product_id":"BTC-USD","changes":[["sell","18240.00","0.25000000"]],"time":"2020-06-30T19:11:53.471415Z"}
{"type":"l2update","product_id":"BTC-USD","changes":[["buy","9092.85","0.00000000"]],"time":"2020-06-30T19:11:53.617857Z"}
{"type":"heartbeat","last_trade_id":0,"product_id":"BTC-USD","sequence":180755448,"time":"2020-06-30T19:11:53.735070Z"}
{"type":"l2update","product_id":"BTC-USD","changes":[["sell","18240.00","0.00000000"]],"time":"2020-06-30T19:11:53.963202Z"}
{"type":"heartbeat","last_trade_id":0,"product_id":"BTC-USD","sequence":180755449,"time":"2020-06-30T19:11:54.735073Z"}
{"type":"l2update","product_id":"BTC-USD","changes":[["buy","9120.80","2864.05140000"]],"time":"2020-06-30T19:11:54.877363Z"}
{"type":"l2update","product_id":"BTC-USD","changes":[["buy","9081.27","0.09670000"]],"time":"2020-06-30T19:11:55.162350Z"}
{"type":"l2update","product_id":"BTC-USD","changes":[["sell","18240.00","0.25000000"]],"time":"2020-06-30T19:11:55.563758Z"}
{"type":"l2update","product_id":"BTC-USD","changes":[["buy","9072.26","0.00000000"]],"time":"2020-06-30T19:11:55.625427Z"}
{"type":"l2update","product_id":"BTC-USD","changes":[["buy","9072.69","0.00000000"]],"time":"2020-06-30T19:11:55.626271Z"}
{"type":"l2update","product_id":"BTC-USD","changes":[["sell","18240.00","0.00000000"]],"time":"2020-06-30T19:11:55.642836Z"}
{"type":"heartbeat","last_trade_id":0,"product_id":"BTC-USD","sequence":180755459,"time":"2020-06-30T19:11:55.735087Z"}
{"type":"l2update","product_id":"BTC-USD","changes":[["buy","9107.19","1.50000000"]],"time":"2020-06-30T19:11:55.752108Z"}
{"type":"l2update","product_id":"BTC-USD","changes":[["buy","9090.34","0.00000000"]],"time":"2020-06-30T19:11:55.928385Z"}
{"type":"l2update","product_id":"BTC-USD","changes":[["buy","9120.80","2862.36040000"]],"time":"2020-06-30T19:11:56.021752Z"}
{"type":"l2update","product_id":"BTC-USD","changes":[["sell","9157.93","0.00000000"]],"time":"2020-06-30T19:11:56.469711Z"}
{"type":"l2update","product_id":"BTC-USD","changes":[["sell","9283.64","0.00000000"]],"time":"2020-06-30T19:11:56.471187Z"}
{"type":"l2update","product_id":"BTC-USD","changes":[["buy","9071.02","0.13330000"]],"time":"2020-06-30T19:11:56.558710Z"}
{"type":"l2update","product_id":"BTC-USD","changes":[["buy","9110.07","15.43370000"]],"time":"2020-06-30T19:11:56.714823Z"}
{"type":"heartbeat","last_trade_id":0,"product_id":"BTC-USD","sequence":180755471,"time":"2020-06-30T19:11:56.735073Z"}
{"type":"l2update","product_id":"BTC-USD","changes":[["sell","9157.39","0.02780000"]],"time":"2020-06-30T19:11:57.113082Z"}
{"type":"l2update","product_id":"BTC-USD","changes":[["sell","9158.20","0.00000000"]],"time":"2020-06-30T19:11:57.327004Z"}
{"type":"l2update","product_id":"BTC-USD","changes":[["sell","9132.88","0.24660000"]],"time":"2020-06-30T19:11:57.379082Z"}
{"type":"l2update","product_id":"BTC-USD","changes":[["buy","9076.70","0.06300000"]],"time":"2020-06-30T19:11:57.659567Z"}
{"type":"heartbeat","last_trade_id":0,"product_id":"BTC-USD","sequence":180755478,"time":"2020-06-30T19:11:57.735063Z"}
{"type":"l2update","product_id":"BTC-USD","changes":[["sell","9130.16","1.25050000"]],"time":"2020-06-30T19:11:57.939354Z"}
{"type":"l2update","product_id":"BTC-USD","changes":[["buy","9070.67","0.05510000"]],"time":"2020-06-30T19:11:58.505143Z"}
{"type":"heartbeat","last_trade_id":0,"product_id":"BTC-USD","sequence":180755482,"time":"2020-06-30T19:11:58.735071Z"}
{"type":"l2update","product_id":"BTC-USD","changes":[["buy","9107.79","0.06590000"]],"time":"2020-06-30T19:11:58.785534Z"}
{"type":"l2update","product_id":"BTC-USD","changes":[["buy","8895.64","0.00000000"]],"time":"2020-06-30T19:11:58.825795Z"}
{"type":"l2update","product_id":"BTC-USD","changes":[["buy","9110.07","5.96450000"]],"time":"2020-06-30T19:11:58.962172Z"}
{"type":"l2update","product_id":"BTC-USD","changes":[["buy","100.00","114.95500000"]],"time":"2020-06-30T19:11:59.045206Z"}
{"type":"l2update","product_id":"BTC-USD","changes":[["buy","100.00","114.94500000"]],"time":"2020-06-30T19:11:59.051353Z"}
{"type":"l2update","product_id":"BTC-USD","changes":[["buy","8894.82","0.04634155"]],"time":"2020-06-30T19:11:59.110941Z"}
{"type":"l2update","product_id":"BTC-USD","changes":[["sell","9435.21","0.00000000"]],"time":"2020-06-30T19:11:59.372374Z"}
{"type":"heartbeat","last_trade_id":0,"product_id":"BTC-USD","sequence":180755492,"time":"2020-06-30T19:11:59.735073Z"}
{"type":"l2update","product_id":"BTC-USD","changes":[["buy","9089.10","0.02930000"]],"time":"2020-06-30T19:11:59.889122Z"}
{"type":"l2update","product_id":"BTC-USD","changes":[["sell","9436.09","0.00709009"]],"time":"2020-06-30T19:11:59.924091Z"}
{"type":"l2update","product_id":"BTC-USD","changes":[["sell","9130.16","2.78410000"]],"time":"2020-06-30T19:12:00.163131Z"}
{"type":"l2update","product_id":"BTC-USD","changes":[["buy","9070.67","0.00000000"]],"time":"2020-06-30T19:12:00.326010Z"}
{"type":"l2update","product_id":"BTC-USD","changes":[["buy","9109.07","0.00000000"]],"time":"2020-06-30T19:12:00.328338Z"}
{"type":"l2update","product_id":"BTC-USD","changes":[["buy","9109.20","0.00000000"]],"time":"2020-06-30T19:12:00.341601Z"}
{"type":"l2update","product_id":"BTC-USD","changes":[["buy","9075.69","0.00000000"]],"time":"2020-06-30T19:12:00.346275Z"}
{"type":"heartbeat","last_trade_id":0,"product_id":"BTC-USD","sequence":180755502,"time":"2020-06-30T19:12:00.735067Z"}
{"type":"l2update","product_id":"BTC-USD","changes":[["buy","8938.29","0.00100000"]],"time":"2020-06-30T19:12:01.031086Z"}
{"type":"l2update","product_id":"BTC-USD","changes":[["buy","9107.79","0.00000000"]],"time":"2020-06-30T19:12:01.507984Z"}
{"type":"l2update","product_id":"BTC-USD","changes":[["buy","9096.94","0.02230000"]],"time":"2020-06-30T19:12:01.607456Z"}
{"type":"heartbeat","last_trade_id":0,"product_id":"BTC-USD","sequence":180755507,"time":"2020-06-30T19:12:01.735119Z"}
{"type":"l2update","product_id":"BTC-USD","changes":[["buy","9120.80","2862.03110000"]],"time":"2020-06-30T19:12:01.901623Z"}
{"type":"l2update","product_id":"BTC-USD","changes":[["buy","9076.70","0.00000000"]],"time":"2020-06-30T19:12:02.033946Z"}
{"type":"l2update","product_id":"BTC-USD","changes":[["buy","9081.12","0.00000000"]],"time":"2020-06-30T19:12:02.041696Z"}
{"type":"l2update","product_id":"BTC-USD","changes":[["buy","9104.34","0.03500000"]],"time":"2020-06-30T19:12:02.405446Z"}
{"type":"heartbeat","last_trade_id":0,"product_id":"BTC-USD","sequence":180755514,"time":"2020-06-30T19:12:02.735114Z"}
{"type":"l2update","product_id":"BTC-USD","changes":[["sell","9156.85","0.06900000"]],"time":"2020-06-30T19:12:02.942924Z"}
{"type":"l2update","product_id":"BTC-USD","changes":[["sell","9156.58","0.06900000"]],"time":"2020-06-30T19:12:03.220986Z"}
{"type":"l2update","product_id":"BTC-USD","changes":[["sell","9157.39","0.00000000"]],"time":"2020-06-30T19:12:03.638597Z"}
{"type":"l2update","product_id":"BTC-USD","changes":[["sell","9130.16","1.25050000"]],"time":"2020-06-30T19:12:03.701580Z"}
{"type":"heartbeat","last_trade_id":0,"product_id":"BTC-USD","sequence":180755520,"time":"2020-06-30T19:12:03.735118Z"}
{"type":"l2update","product_id":"BTC-USD","changes":[["sell","9152.59","0.05460000"]],"time":"2020-06-30T19:12:04.412214Z"}
{"type":"l2update","product_id":"BTC-USD","changes":[["buy","9079.57","0.03950000"]],"time":"2020-06-30T19:12:04.663682Z"}
{"type":"heartbeat","last_trade_id":0,"product_id":"BTC-USD","sequence":180755524,"time":"2020-06-30T19:12:04.735134Z"}
{"type":"l2update","product_id":"BTC-USD","changes":[["sell","9130.16","0.00000000"]],"time":"2020-06-30T19:12:04.841506Z"}
{"type":"l2update","product_id":"BTC-USD","changes":[["sell","9151.21","0.05460000"]],"time":"2020-06-30T19:12:04.949092Z"}
{"type":"l2update","product_id":"BTC-USD","changes":[["buy","9071.02","0.00000000"]],"time":"2020-06-30T19:12:05.108897Z"}
{"type":"l2update","product_id":"BTC-USD","changes":[["buy","9105.37","0.18990000"]],"time":"2020-06-30T19:12:05.273902Z"}
{"type":"l2update","product_id":"BTC-USD","changes":[["buy","9104.34","0.00000000"]],"time":"2020-06-30T19:12:05.486665Z"}
{"type":"heartbeat","last_trade_id":0,"product_id":"BTC-USD","sequence":180755531,"time":"2020-06-30T19:12:05.735116Z"}
{"type":"l2update","product_id":"BTC-USD","changes":[["buy","9120.80","2861.96520000"]],"time":"2020-06-30T19:12:06.090621Z"}
{"type":"l2update","product_id":"BTC-USD","changes":[["sell","9137.03","0.00000000"]],"time":"2020-06-30T19:12:06.327956Z"}
{"type":"l2update","product_id":"BTC-USD","changes":[["sell","9128.90","1.21890000"]],"time":"2020-06-30T19:12:06.640961Z"}
{"type":"heartbeat","last_trade_id":0,"product_id":"BTC-USD","sequence":180755537,"time":"2020-06-30T19:12:06.735118Z"}
{"type":"l2update","product_id":"BTC-USD","changes":[["sell","9137.05","0.00000000"]],"time":"2020-06-30T19:12:07.074173Z"}
{"type":"l2update","product_id":"BTC-USD","changes":[["sell","9151.21","0.00000000"]],"time":"2020-06-30T19:12:07.079529Z"}
{"type":"l2update","product_id":"BTC-USD","changes":[["buy","9120.80","2860.32220000"]],"time":"2020-06-30T19:12:07.469138Z"}
{"type":"heartbeat","last_trade_id":0,"product_id":"BTC-USD","sequence":180755542,"time":"2020-06-30T19:12:07.734986Z"}
{"type":"l2update","product_id":"BTC-USD","changes":[["sell","9126.17","0.51450000"]],"time":"2020-06-30T19:12:07.751287Z"}
{"type":"l2update","product_id":"BTC-USD","changes":[["sell","9132.88","0.00000000"]],"time":"2020-06-30T19:12:08.196114Z"}
{"type":"l2update","product_id":"BTC-USD","changes":[["sell","9144.97","0.05470000"]],"time":"2020-06-30T19:12:08.580927Z"}
{"type":"heartbeat","last_trade_id":0,"product_id":"BTC-USD","sequence":180755547,"time":"2020-06-30T19:12:08.735163Z"}
{"type":"l2update","product_id":"BTC-USD","changes":[["buy","9072.43","0.03300000"]],"time":"2020-06-30T19:12:09.566306Z"}
{"type":"heartbeat","last_trade_id":0,"product_id":"BTC-USD","sequence":180755549,"time":"2020-06-30T19:12:09.735122Z"}
{"type":"l2update","product_id":"BTC-USD","changes":[["buy","9096.94","0.00000000"]],"time":"2020-06-30T19:12:09.977164Z"}
{"type":"l2update","product_id":"BTC-USD","changes":[["buy","9073.63","0.03950000"]],"time":"2020-06-30T19:12:10.111408Z"}
{"type":"l2update","product_id":"BTC-USD","changes":[["sell","9177.67","0.10000000"]],"time":"2020-06-30T19:12:10.445517Z"}
{"type":"l2update","product_id":"BTC-USD","changes":[["buy","9102.84","0.00000000"]],"time":"2020-06-30T19:12:10.563708Z"}
{"type":"l2update","product_id":"BTC-USD","changes":[["buy","9120.80","2860.32120000"]],"time":"2020-06-30T19:12:10.671382Z"}
{"type":"heartbeat","last_trade_id":0,"product_id":"BTC-USD","sequence":180755558,"time":"2020-06-30T19:12:10.735113Z"}
{"type":"l2update","product_id":"BTC-USD","changes":[["buy","9102.22","0.54300000"]],"time":"2020-06-30T19:12:10.993246Z"}
{"type":"l2update","product_id":"BTC-USD","changes":[["sell","9140.44","0.05470000"]],"time":"2020-06-30T19:12:11.274724Z"}
{"type":"l2update","product_id":"BTC-USD","changes":[["buy","9081.27","0.00000000"]],"time":"2020-06-30T19:12:11.453048Z"}
{"type":"heartbeat","last_trade_id":0,"product_id":"BTC-USD","sequence":180755563,"time":"2020-06-30T19:12:11.735120Z"}
{"type":"l2update","product_id":"BTC-USD","changes":[["sell","9126.17","1.02900000"]],"time":"2020-06-30T19:12:11.886633Z"}
{"type":"l2update","product_id":"BTC-USD","changes":[["buy","9077.08","0.03950000"]],"time":"2020-06-30T19:12:12.165354Z"}
{"type":"l2update","product_id":"BTC-USD","changes":[["sell","9152.59","0.00000000"]],"time":"2020-06-30T19:12:12.377626Z"}
{"type":"l2update","product_id":"BTC-USD","changes":[["buy","9106.00","0.00000000"]],"time":"2020-06-30T19:12:12.662341Z"}
{"type":"l2update","product_id":"BTC-USD","changes":[["buy","9079.57","0.00000000"]],"time":"2020-06-30T19:12:12.698272Z"}
{"type":"l2update","product_id":"BTC-USD","changes":[["buy","9102.22","0.00000000"]],"time":"2020-06-30T19:12:12.707716Z"}
{"type":"heartbeat","last_trade_id":0,"product_id":"BTC-USD","sequence":180755571,"time":"2020-06-30T19:12:12.735115Z"}
{"type":"l2update","product_id":"BTC-USD","changes":[["buy","9078.86","0.02790000"]],"time":"2020-06-30T19:12:13.267657Z"}
{"type":"l2update","product_id":"BTC-USD","changes":[["buy","9110.07","0.00000000"]],"time":"2020-06-30T19:12:13.457809Z"}
{"type":"l2update","product_id":"BTC-USD","changes":[["buy","8938.29","0.00000000"]],"time":"2020-06-30T19:12:13.464745Z"}
{"type":"heartbeat","last_trade_id":0,"product_id":"BTC-USD","sequence":180755575,"time":"2020-06-30T19:12:13.735123Z"}
{"type":"l2update","product_id":"BTC-USD","changes":[["buy","9073.40","0.09400000"]],"time":"2020-06-30T19:12:13.818583Z"}
{"type":"l2update","product_id":"BTC-USD","changes":[["buy","100.00","114.95500000"]],"time":"2020-06-30T19:12:14.040993Z"}
{"type":"l2update","product_id":"BTC-USD","changes":[["buy","100.00","114.94500000"]],"time":"2020-06-30T19:12:14.048263Z"}
{"type":"l2update","product_id":"BTC-USD","changes":[["buy","9074.08","0.06930000"]],"time":"2020-06-30T19:12:14.099544Z"}
{"type":"l2update","product_id":"BTC-USD","changes":[["buy","9075.31","0.06930000"]],"time":"2020-06-30T19:12:14.655224Z"}
{"type":"heartbeat","last_trade_id":0,"product_id":"BTC-USD","sequence":180755584,"time":"2020-06-30T19:12:14.735120Z"}
{"type":"l2update","product_id":"BTC-USD","changes":[["buy","9082.94","0.02770000"]],"time":"2020-06-30T19:12:14.979584Z"}
{"type":"l2update","product_id":"BTC-USD","changes":[["buy","9089.10","0.00000000"]],"time":"2020-06-30T19:12:15.113411Z"}
{"type":"heartbeat","last_trade_id":0,"product_id":"BTC-USD","sequence":180755587,"time":"2020-06-30T19:12:15.735123Z"}
{"type":"l2update","product_id":"BTC-USD","changes":[["buy","9077.64","0.06930000"]],"time":"2020-06-30T19:12:15.777720Z"}
{"type":"l2update","product_id":"BTC-USD","changes":[["buy","9075.32","0.02300000"]],"time":"2020-06-30T19:12:16.306950Z"}
{"type":"heartbeat","last_trade_id":0,"product_id":"BTC-USD","sequence":180755591,"time":"2020-06-30T19:12:16.735118Z"}
{"type":"l2update","product_id":"BTC-USD","changes":[["buy","9071.88","0.02000000"]],"time":"2020-06-30T19:12:17.507622Z"}
{"type":"heartbeat","last_trade_id":0,"product_id":"BTC-USD","sequence":180755593,"time":"2020-06-30T19:12:17.735115Z"}
{"type":"l2update","product_id":"BTC-USD","changes":[["buy","9073.43","0.03950000"]],"time":"2020-06-30T19:12:17.774166Z"}
{"type":"l2update","product_id":"BTC-USD","changes":[["buy","9105.37","0.00000000"]],"time":"2020-06-30T19:12:18.209016Z"}
{"type":"l2update","product_id":"BTC-USD","changes":[["buy","9074.96","0.02350000"]],"time":"2020-06-30T19:12:18.615434Z"}
{"type":"heartbeat","last_trade_id":0,"product_id":"BTC-USD","sequence":180755598,"time":"2020-06-30T19:12:18.735127Z"}
{"type":"l2update","product_id":"BTC-USD","changes":[["buy","9077.41","0.01000000"]],"time":"2020-06-30T19:12:18.889767Z"}
{"type":"l2update","product_id":"BTC-USD","changes":[["buy","9077.08","0.00000000"]],"time":"2020-06-30T19:12:19.068159Z"}
{"type":"l2update","product_id":"BTC-USD","changes":[["buy","9102.85","0.02500000"]],"time":"2020-06-30T19:12:19.440234Z"}
{"type":"l2update","product_id":"BTC-USD","changes":[["sell","9146.15","0.05470000"]],"time":"2020-06-30T19:12:19.708250Z"}
{"type":"heartbeat","last_trade_id":0,"product_id":"BTC-USD","sequence":180755605,"time":"2020-06-30T19:12:19.735120Z"}
{"type":"l2update","product_id":"BTC-USD","changes":[["sell","9156.85","0.00000000"]],"time":"2020-06-30T19:12:19.914637Z"}
{"type":"heartbeat","last_trade_id":0,"product_id":"BTC-USD","sequence":180755606,"time":"2020-06-30T19:12:20.735124Z"}
{"type":"l2update","product_id":"BTC-USD","changes":[["buy","9073.40","0.00000000"]],"time":"2020-06-30T19:12:20.937686Z"}
{"type":"l2update","product_id":"BTC-USD","changes":[["buy","9085.45","0.02230000"]],"time":"2020-06-30T19:12:21.085475Z"}
{"type":"l2update","product_id":"BTC-USD","changes":[["buy","9075.31","0.00000000"]],"time":"2020-06-30T19:12:21.532468Z"}
{"type":"l2update","product_id":"BTC-USD","changes":[["buy","9082.94","0.00000000"]],"time":"2020-06-30T19:12:21.532748Z"}
{"type":"l2update","product_id":"BTC-USD","changes":[["buy","9074.08","0.00000000"]],"time":"2020-06-30T19:12:21.548080Z"}
{"type":"heartbeat","last_trade_id":0,"product_id":"BTC-USD","sequence":180755612,"time":"2020-06-30T19:12:21.735115Z"}
{"type":"l2update","product_id":"BTC-USD","changes":[["buy","9120.80","2860.27120000"]],"time":"2020-06-30T19:12:21.951229Z"}
{"type":"l2update","product_id":"BTC-USD","changes":[["buy","9084.62","0.09990000"]],"time":"2020-06-30T19:12:22.504634Z"}
{"type":"heartbeat","last_trade_id":0,"product_id":"BTC-USD","sequence":180755617,"time":"2020-06-30T19:12:22.735131Z"}
{"type":"l2update","product_id":"BTC-USD","changes":[["buy","9077.41","0.00000000"]],"time":"2020-06-30T19:12:23.012828Z"}
{"type":"l2update","product_id":"BTC-USD","changes":[["buy","9075.32","0.00000000"]],"time":"2020-06-30T19:12:23.023132Z"}
{"type":"l2update","product_id":"BTC-USD","changes":[["sell","9156.58","0.00000000"]],"time":"2020-06-30T19:12:23.526667Z"}
{"type":"l2update","product_id":"BTC-USD","changes":[["sell","9140.44","0.00000000"]],"time":"2020-06-30T19:12:23.557228Z"}
{"type":"heartbeat","last_trade_id":0,"product_id":"BTC-USD","sequence":180755621,"time":"2020-06-30T19:12:23.735117Z"}
{"type":"l2update","product_id":"BTC-USD","changes":[["sell","9130.65","1.08610000"]],"time":"2020-06-30T19:12:24.463568Z"}
{"type":"heartbeat","last_trade_id":0,"product_id":"BTC-USD","sequence":180755623,"time":"2020-06-30T19:12:24.735122Z"}
{"type":"l2update","product_id":"BTC-USD","changes":[["buy","9120.80","2859.65730000"]],"time":"2020-06-30T19:12:25.394485Z"}
{"type":"heartbeat","last_trade_id":0,"product_id":"BTC-USD","sequence":180755626,"time":"2020-06-30T19:12:25.735031Z"}
{"type":"l2update","product_id":"BTC-USD","changes":[["sell","9203.18","0.00200000"]],"time":"2020-06-30T19:12:26.108072Z"}
{"type":"heartbeat","last_trade_id":0,"product_id":"BTC-USD","sequence":180755628,"time":"2020-06-30T19:12:26.735084Z"}
{"type":"l2update","product_id":"BTC-USD","changes":[["buy","9076.79","0.06920000"]],"time":"2020-06-30T19:12:27.151821Z"}
{"type":"l2update","product_id":"BTC-USD","changes":[["buy","9073.63","0.00000000"]],"time":"2020-06-30T19:12:27.622996Z"}
{"type":"l2update","product_id":"BTC-USD","changes":[["buy","9074.96","0.00000000"]],"time":"2020-06-30T19:12:27.635325Z"}
{"type":"heartbeat","last_trade_id":0,"product_id":"BTC-USD","sequence":180755632,"time":"2020-06-30T19:12:27.735170Z"}
{"type":"l2update","product_id":"BTC-USD","changes":[["buy","9076.76","0.06920000"]],"time":"2020-06-30T19:12:28.059411Z"}
{"type":"l2update","product_id":"BTC-USD","changes":[["buy","9078.86","0.00000000"]],"time":"2020-06-30T19:12:28.234829Z"}
{"type":"l2update","product_id":"BTC-USD","changes":[["buy","9102.85","0.00000000"]],"time":"2020-06-30T19:12:28.240031Z"}
{"type":"l2update","product_id":"BTC-USD","changes":[["sell","9128.82","1.38260000"]],"time":"2020-06-30T19:12:28.336679Z"}
{"type":"l2update","product_id":"BTC-USD","changes":[["buy","9082.16","0.03910000"]],"time":"2020-06-30T19:12:28.611785Z"}
{"type":"heartbeat","last_trade_id":0,"product_id":"BTC-USD","sequence":180755640,"time":"2020-06-30T19:12:28.735118Z"}
{"type":"l2update","product_id":"BTC-USD","changes":[["buy","100.00","114.95500000"]],"time":"2020-06-30T19:12:29.022313Z"}
{"type":"l2update","product_id":"BTC-USD","changes":[["buy","100.00","114.94500000"]],"time":"2020-06-30T19:12:29.028479Z"}
{"type":"l2update","product_id":"BTC-USD","changes":[["buy","9083.39","0.01920000"]],"time":"2020-06-30T19:12:29.161043Z"}
{"type":"l2update","product_id":"BTC-USD","changes":[["buy","9105.00","0.03960000"]],"time":"2020-06-30T19:12:29.486837Z"}
{"type":"l2update","product_id":"BTC-USD","changes":[["buy","9076.76","0.00000000"]],"time":"2020-06-30T19:12:29.602250Z"}
{"type":"l2update","product_id":"BTC-USD","changes":[["sell","9154.90","0.01490000"]],"time":"2020-06-30T19:12:29.725763Z"}
{"type":"heartbeat","last_trade_id":0,"product_id":"BTC-USD","sequence":180755650,"time":"2020-06-30T19:12:29.735125Z"}
{"type":"l2update","product_id":"BTC-USD","changes":[["sell","9130.65","0.00000000"]],"time":"2020-06-30T19:12:30.200512Z"}
{"type":"l2update","product_id":"BTC-USD","changes":[["buy","9074.32","0.03950000"]],"time":"2020-06-30T19:12:30.325875Z"}
{"type":"heartbeat","last_trade_id":0,"product_id":"BTC-USD","sequence":180755653,"time":"2020-06-30T19:12:30.735112Z"}
{"type":"l2update","product_id":"BTC-USD","changes":[["buy","9085.45","0.00000000"]],"time":"2020-06-30T19:12:30.775829Z"}
{"type":"heartbeat","last_trade_id":0,"product_id":"BTC-USD","sequence":180755654,"time":"2020-06-30T19:12:31.735114Z"}
{"type":"l2update","product_id":"BTC-USD","changes":[["buy","9095.58","0.01000000"]],"time":"2020-06-30T19:12:32.288133Z"}
{"type":"l2update","product_id":"BTC-USD","changes":[["buy","9074.32","0.00000000"]],"time":"2020-06-30T19:12:32.720718Z"}
{"type":"l2update","product_id":"BTC-USD","changes":[["buy","9105.00","0.00000000"]],"time":"2020-06-30T19:12:32.732570Z"}
{"type":"l2update","product_id":"BTC-USD","changes":[["buy","9072.43","0.00000000"]],"time":"2020-06-30T19:12:32.739103Z"}
{"type":"heartbeat","last_trade_id":0,"product_id":"BTC-USD","sequence":180755659,"time":"2020-06-30T19:12:32.735118Z"}
{"type":"l2update","product_id":"BTC-USD","changes":[["buy","9078.72","0.02790000"]],"time":"2020-06-30T19:12:32.846519Z"}
{"type":"l2update","product_id":"BTC-USD","changes":[["buy","9072.70","0.04400000"]],"time":"2020-06-30T19:12:33.127143Z"}
{"type":"l2update","product_id":"BTC-USD","changes":[["buy","9107.19","0.00000000"]],"time":"2020-06-30T19:12:33.596318Z"}
{"type":"l2update","product_id":"BTC-USD","changes":[["buy","9077.64","0.00000000"]],"time":"2020-06-30T19:12:33.598750Z"}
{"type":"heartbeat","last_trade_id":0,"product_id":"BTC-USD","sequence":180755665,"time":"2020-06-30T19:12:33.735116Z"}
{"type":"heartbeat","last_trade_id":0,"product_id":"BTC-USD","sequence":180755665,"time":"2020-06-30T19:12:34.735119Z"}
{"type":"l2update","product_id":"BTC-USD","changes":[["buy","9077.09","0.03950000"]],"time":"2020-06-30T19:12:35.163833Z"}
{"type":"l2update","product_id":"BTC-USD","changes":[["buy","9072.70","0.00000000"]],"time":"2020-06-30T19:12:35.384535Z"}
{"type":"l2update","product_id":"BTC-USD","changes":[["buy","9076.79","0.00000000"]],"time":"2020-06-30T19:12:35.395744Z"}
{"type":"heartbeat","last_trade_id":0,"product_id":"BTC-USD","sequence":180755669,"time":"2020-06-30T19:12:35.735114Z"}
{"type":"l2update","product_id":"BTC-USD","changes":[["buy","9082.16","0.00000000"]],"time":"2020-06-30T19:12:36.324102Z"}
{"type":"l2update","product_id":"BTC-USD","changes":[["buy","9071.88","0.00000000"]],"time":"2020-06-30T19:12:36.326729Z"}
{"type":"l2update","product_id":"BTC-USD","changes":[["buy","9104.04","0.04000000"]],"time":"2020-06-30T19:12:36.334115Z"}
{"type":"l2update","product_id":"BTC-USD","changes":[["buy","9073.43","0.00000000"]],"time":"2020-06-30T19:12:36.338215Z"}
{"type":"l2update","product_id":"BTC-USD","changes":[["buy","9077.09","0.00000000"]],"time":"2020-06-30T19:12:36.346717Z"}
{"type":"heartbeat","last_trade_id":0,"product_id":"BTC-USD","sequence":180755675,"time":"2020-06-30T19:12:36.735110Z"}
{"type":"l2update","product_id":"BTC-USD","changes":[["buy","9081.45","0.00000000"]],"time":"2020-06-30T19:12:36.794360Z"}
{"type":"l2update","product_id":"BTC-USD","changes":[["buy","9095.58","0.00000000"]],"time":"2020-06-30T19:12:36.801314Z"}
{"type":"l2update","product_id":"BTC-USD","changes":[["buy","9071.82","0.00000000"]],"time":"2020-06-30T19:12:36.801656Z"}
{"type":"l2update","product_id":"BTC-USD","changes":[["buy","9078.72","0.00000000"]],"time":"2020-06-30T19:12:36.808041Z"}
{"type":"l2update","product_id":"BTC-USD","changes":[["buy","9070.48","0.02350000"]],"time":"2020-06-30T19:12:37.483118Z"}
{"type":"heartbeat","last_trade_id":0,"product_id":"BTC-USD","sequence":180755681,"time":"2020-06-30T19:12:37.735114Z"}
{"type":"l2update","product_id":"BTC-USD","changes":[["buy","9100.22","0.81590000"]],"time":"2020-06-30T19:12:37.748047Z"}
{"type":"l2update","product_id":"BTC-USD","changes":[["buy","9079.19","0.00000000"]],"time":"2020-06-30T19:12:37.898404Z"}
{"type":"l2update","product_id":"BTC-USD","changes":[["buy","9072.52","0.09670000"]],"time":"2020-06-30T19:12:38.308125Z"}
{"type":"l2update","product_id":"BTC-USD","changes":[["buy","9083.39","0.00000000"]],"time":"2020-06-30T19:12:38.729778Z"}
{"type":"heartbeat","last_trade_id":0,"product_id":"BTC-USD","sequence":180755687,"time":"2020-06-30T19:12:38.735119Z"}
{"type":"heartbeat","last_trade_id":0,"product_id":"BTC-USD","sequence":180755687,"time":"2020-06-30T19:12:39.735117Z"}
{"type":"l2update","product_id":"BTC-USD","changes":[["buy","8987.61","0.00200000"]],"time":"2020-06-30T19:12:39.976104Z"}
{"type":"l2update","product_id":"BTC-USD","changes":[["buy","9072.52","0.00000000"]],"time":"2020-06-30T19:12:40.396016Z"}
{"type":"l2update","product_id":"BTC-USD","changes":[["sell","9161.21","0.03830000"]],"time":"2020-06-30T19:12:40.538853Z"}
{"type":"heartbeat","last_trade_id":0,"product_id":"BTC-USD","sequence":180755692,"time":"2020-06-30T19:12:40.735118Z"}
{"type":"l2update","product_id":"BTC-USD","changes":[["buy","9104.61","0.13200000"]],"time":"2020-06-30T19:12:40.798993Z"}
{"type":"l2update","product_id":"BTC-USD","changes":[["sell","9144.97","0.00000000"]],"time":"2020-06-30T19:12:40.971658Z"}
{"type":"l2update","product_id":"BTC-USD","changes":[["buy","9084.62","0.00000000"]],"time":"2020-06-30T19:12:41.041245Z"}
{"type":"l2update","product_id":"BTC-USD","changes":[["sell","9120.82","3006.39500000"]],"time":"2020-06-30T19:12:41.660553Z"}
{"type":"l2update","product_id":"BTC-USD","changes":[["buy","9120.80","2859.59140000"]],"time":"2020-06-30T19:12:41.671465Z"}
{"type":"heartbeat","last_trade_id":0,"product_id":"BTC-USD","sequence":180755702,"time":"2020-06-30T19:12:41.735114Z"}
{"type":"l2update","product_id":"BTC-USD","changes":[["buy","9104.61","0.26500000"]],"time":"2020-06-30T19:12:41.957060Z"}
{"type":"l2update","product_id":"BTC-USD","changes":[["sell","9154.90","0.00000000"]],"time":"2020-06-30T19:12:42.138456Z"}
{"type":"l2update","product_id":"BTC-USD","changes":[["buy","9079.69","0.06610000"]],"time":"2020-06-30T19:12:42.504629Z"}
{"type":"heartbeat","last_trade_id":0,"product_id":"BTC-USD","sequence":180755707,"time":"2020-06-30T19:12:42.735110Z"}
{"type":"l2update","product_id":"BTC-USD","changes":[["sell","9160.24","0.05270000"]],"time":"2020-06-30T19:12:42.779376Z"}
{"type":"l2update","product_id":"BTC-USD","changes":[["buy","9104.04","0.00000000"]],"time":"2020-06-30T19:12:42.918125Z"}
{"type":"l2update","product_id":"BTC-USD","changes":[["buy","8987.61","0.00000000"]],"time":"2020-06-30T19:12:42.931710Z"}
{"type":"l2update","product_id":"BTC-USD","changes":[["buy","9120.80","2857.95940000"]],"time":"2020-06-30T19:12:43.042781Z"}
{"type":"l2update","product_id":"BTC-USD","changes":[["sell","9146.15","0.00000000"]],"time":"2020-06-30T19:12:43.250173Z"}
{"type":"l2update","product_id":"BTC-USD","changes":[["buy","9120.80","2843.29040000"]],"time":"2020-06-30T19:12:43.602392Z"}
{"type":"heartbeat","last_trade_id":0,"product_id":"BTC-USD","sequence":180755718,"time":"2020-06-30T19:12:43.735119Z"}
{"type":"l2update","product_id":"BTC-USD","changes":[["sell","9128.98","1.23090000"]],"time":"2020-06-30T19:12:43.870263Z"}
{"type":"l2update","product_id":"BTC-USD","changes":[["buy","100.00","114.95500000"]],"time":"2020-06-30T19:12:44.059782Z"}
{"type":"l2update","product_id":"BTC-USD","changes":[["buy","100.00","114.94500000"]],"time":"2020-06-30T19:12:44.066515Z"}
{"type":"l2update","product_id":"BTC-USD","changes":[["buy","9120.80","2843.22450000"]],"time":"2020-06-30T19:12:44.159170Z"}
{"type":"l2update","product_id":"BTC-USD","changes":[["buy","9120.80","2843.15860000"]],"time":"2020-06-30T19:12:44.437290Z"}
{"type":"l2update","product_id":"BTC-USD","changes":[["buy","9120.80","2843.10860000"]],"time":"2020-06-30T19:12:44.704867Z"}
{"type":"heartbeat","last_trade_id":0,"product_id":"BTC-USD","sequence":180755732,"time":"2020-06-30T19:12:44.735118Z"}
{"type":"l2update","product_id":"BTC-USD","changes":[["buy","9077.25","0.06930000"]],"time":"2020-06-30T19:12:45.267604Z"}
{"type":"l2update","product_id":"BTC-USD","changes":[["buy","9104.61","0.13300000"]],"time":"2020-06-30T19:12:45.479126Z"}
{"type":"l2update","product_id":"BTC-USD","changes":[["buy","9100.21","0.54400000"]],"time":"2020-06-30T19:12:45.532407Z"}
{"type":"heartbeat","last_trade_id":0,"product_id":"BTC-USD","sequence":180755737,"time":"2020-06-30T19:12:45.735126Z"}
{"type":"l2update","product_id":"BTC-USD","changes":[["sell","9161.08","0.06900000"]],"time":"2020-06-30T19:12:45.804806Z"}
{"type":"l2update","product_id":"BTC-USD","changes":[["buy","9078.91","0.02790000"]],"time":"2020-06-30T19:12:46.074246Z"}
{"type":"l2update","product_id":"BTC-USD","changes":[["sell","9203.18","0.00000000"]],"time":"2020-06-30T19:12:46.222593Z"}
{"type":"l2update","product_id":"BTC-USD","changes":[["sell","9126.17","0.51450000"]],"time":"2020-06-30T19:12:46.234479Z"}
{"type":"l2update","product_id":"BTC-USD","changes":[["buy","9078.09","0.03710000"]],"time":"2020-06-30T19:12:46.356332Z"}
{"type":"l2update","product_id":"BTC-USD","changes":[["buy","9102.52","0.04000000"]],"time":"2020-06-30T19:12:46.631857Z"}
{"type":"heartbeat","last_trade_id":0,"product_id":"BTC-USD","sequence":180755747,"time":"2020-06-30T19:12:46.735113Z"}
{"type":"l2update","product_id":"BTC-USD","changes":[["buy","9120.80","2837.24340000"]],"time":"2020-06-30T19:12:46.901239Z"}
{"type":"l2update","product_id":"BTC-USD","changes":[["sell","9160.69","0.06900000"]],"time":"2020-06-30T19:12:47.462756Z"}
{"type":"l2update","product_id":"BTC-USD","changes":[["buy","9079.69","0.00000000"]],"time":"2020-06-30T19:12:47.650832Z"}
{"type":"heartbeat","last_trade_id":0,"product_id":"BTC-USD","sequence":180755753,"time":"2020-06-30T19:12:47.735028Z"}
{"type":"l2update","product_id":"BTC-USD","changes":[["sell","9160.80","0.01000000"]],"time":"2020-06-30T19:12:47.767828Z"}
{"type":"l2update","product_id":"BTC-USD","changes":[["buy","9103.00","0.04000000"]],"time":"2020-06-30T19:12:48.036515Z"}
{"type":"l2update","product_id":"BTC-USD","changes":[["sell","9160.69","0.00000000"]],"time":"2020-06-30T19:12:48.183224Z"}
{"type":"heartbeat","last_trade_id":0,"product_id":"BTC-USD","sequence":180755758,"time":"2020-06-30T19:12:48.735170Z"}
{"type":"l2update","product_id":"BTC-USD","changes":[["buy","9082.57","0.03140000"]],"time":"2020-06-30T19:12:49.199124Z"}
{"type":"l2update","product_id":"BTC-USD","changes":[["buy","9083.80","0.02960000"]],"time":"2020-06-30T19:12:49.484232Z"}
{"type":"l2update","product_id":"BTC-USD","changes":[["buy","9103.00","0.00000000"]],"time":"2020-06-30T19:12:49.639478Z"}
{"type":"l2update","product_id":"BTC-USD","changes":[["buy","9100.21","0.00000000"]],"time":"2020-06-30T19:12:49.651868Z"}
{"type":"heartbeat","last_trade_id":0,"product_id":"BTC-USD","sequence":180755764,"time":"2020-06-30T19:12:49.735112Z"}
{"type":"l2update","product_id":"BTC-USD","changes":[["buy","9120.80","2837.14340000"]],"time":"2020-06-30T19:12:49.996650Z"}
{"type":"l2update","product_id":"BTC-USD","changes":[["buy","9120.80","2837.09340000"]],"time":"2020-06-30T19:12:50.300073Z"}
{"type":"heartbeat","last_trade_id":0,"product_id":"BTC-USD","sequence":180755770,"time":"2020-06-30T19:12:50.735110Z"}
{"type":"l2update","product_id":"BTC-USD","changes":[["buy","9089.09","0.01120000"]],"time":"2020-06-30T19:12:50.833763Z"}
{"type":"l2update","product_id":"BTC-USD","changes":[["buy","9074.53","0.03310000"]],"time":"2020-06-30T19:12:51.105765Z"}
{"type":"l2update","product_id":"BTC-USD","changes":[["buy","9082.57","0.00000000"]],"time":"2020-06-30T19:12:51.305106Z"}
{"type":"heartbeat","last_trade_id":0,"product_id":"BTC-USD","sequence":180755775,"time":"2020-06-30T19:12:51.735109Z"}
{"type":"l2update","product_id":"BTC-USD","changes":[["buy","9080.31","0.02300000"]],"time":"2020-06-30T19:12:51.944478Z"}
{"type":"l2update","product_id":"BTC-USD","changes":[["buy","9083.80","0.00000000"]],"time":"2020-06-30T19:12:52.375361Z"}
{"type":"l2update","product_id":"BTC-USD","changes":[["buy","9074.53","0.00000000"]],"time":"2020-06-30T19:12:52.379445Z"}
{"type":"l2update","product_id":"BTC-USD","changes":[["buy","9120.80","2837.03120000"]],"time":"2020-06-30T19:12:52.485462Z"}
{"type":"l2update","product_id":"BTC-USD","changes":[["sell","9160.24","0.00000000"]],"time":"2020-06-30T19:12:52.670526Z"}
{"type":"heartbeat","last_trade_id":0,"product_id":"BTC-USD","sequence":180755783,"time":"2020-06-30T19:12:52.735117Z"}
{"type":"l2update","product_id":"BTC-USD","changes":[["sell","9132.33","0.01080000"]],"time":"2020-06-30T19:12:52.757527Z"}
{"type":"l2update","product_id":"BTC-USD","changes":[["buy","9093.04","0.51390000"]],"time":"2020-06-30T19:12:53.040336Z"}
{"type":"l2update","product_id":"BTC-USD","changes":[["sell","9128.98","0.00000000"]],"time":"2020-06-30T19:12:53.185102Z"}
{"type":"l2update","product_id":"BTC-USD","changes":[["buy","9070.48","0.00000000"]],"time":"2020-06-30T19:12:53.273150Z"}
{"type":"l2update","product_id":"BTC-USD","changes":[["sell","9132.33","0.02160000"]],"time":"2020-06-30T19:12:53.343014Z"}
{"type":"heartbeat","last_trade_id":0,"product_id":"BTC-USD","sequence":180755791,"time":"2020-06-30T19:12:53.735118Z"}
{"type":"l2update","product_id":"BTC-USD","changes":[["sell","9126.17","0.00000000"]],"time":"2020-06-30T19:12:54.395555Z"}
{"type":"heartbeat","last_trade_id":0,"product_id":"BTC-USD","sequence":180755792,"time":"2020-06-30T19:12:54.735115Z"}
{"type":"l2update","product_id":"BTC-USD","changes":[["sell","9160.44","0.08140000"]],"time":"2020-06-30T19:12:55.045798Z"}
{"type":"l2update","product_id":"BTC-USD","changes":[["sell","9132.33","0.01080000"]],"time":"2020-06-30T19:12:55.499587Z"}
{"type":"heartbeat","last_trade_id":0,"product_id":"BTC-USD","sequence":180755795,"time":"2020-06-30T19:12:55.735119Z"}
{"type":"l2update","product_id":"BTC-USD","changes":[["buy","9073.03","0.06300000"]],"time":"2020-06-30T19:12:56.452041Z"}
{"type":"heartbeat","last_trade_id":0,"product_id":"BTC-USD","sequence":180755797,"time":"2020-06-30T19:12:56.735112Z"}
{"type":"l2update","product_id":"BTC-USD","changes":[["buy","9074.26","0.12500000"]],"time":"2020-06-30T19:12:57.296347Z"}
{"type":"heartbeat","last_trade_id":0,"product_id":"BTC-USD","sequence":180755799,"time":"2020-06-30T19:12:57.735115Z"}
{"type":"l2update","product_id":"BTC-USD","changes":[["buy","9080.31","0.00000000"]],"time":"2020-06-30T19:12:57.757676Z"}
{"type":"l2update","product_id":"BTC-USD","changes":[["sell","9292.79","0.00400000"]],"time":"2020-06-30T19:12:57.848691Z"}
{"type":"l2update","product_id":"BTC-USD","changes":[["buy","9093.04","0.00000000"]],"time":"2020-06-30T19:12:58.034780Z"}
{"type":"l2update","product_id":"BTC-USD","changes":[["buy","9085.26","0.02830000"]],"time":"2020-06-30T19:12:58.410210Z"}
{"type":"l2update","product_id":"BTC-USD","changes":[["buy","8894.82","0.00000000"]],"time":"2020-06-30T19:12:58.479602Z"}
{"type":"l2update","product_id":"BTC-USD","changes":[["buy","8894.00","0.04644306"]],"time":"2020-06-30T19:12:58.719683Z"}
{"type":"heartbeat","last_trade_id":0,"product_id":"BTC-USD","sequence":180755808,"time":"2020-06-30T19:12:58.735111Z"}
{"type":"l2update","product_id":"BTC-USD","changes":[["buy","9075.05","0.07370000"]],"time":"2020-06-30T19:12:58.984533Z"}
{"type":"l2update","product_id":"BTC-USD","changes":[["buy","100.00","114.95500000"]],"time":"2020-06-30T19:12:59.028498Z"}
{"type":"l2update","product_id":"BTC-USD","changes":[["buy","100.00","114.94500000"]],"time":"2020-06-30T19:12:59.034896Z"}
{"type":"l2update","product_id":"BTC-USD","changes":[["sell","9436.09","0.00000000"]],"time":"2020-06-30T19:12:59.217286Z"}
{"type":"l2update","product_id":"BTC-USD","changes":[["sell","9436.96","0.00718939"]],"time":"2020-06-30T19:12:59.423507Z"}
{"type":"heartbeat","last_trade_id":0,"product_id":"BTC-USD","sequence":180755816,"time":"2020-06-30T19:12:59.735117Z"}
{"type":"l2update","product_id":"BTC-USD","changes":[["buy","9120.80","2834.84220000"]],"time":"2020-06-30T19:12:59.830720Z"}
{"type":"l2update","product_id":"BTC-USD","changes":[["sell","9160.44","0.00000000"]],"time":"2020-06-30T19:13:00.283027Z"}
{"type":"l2update","product_id":"BTC-USD","changes":[["sell","9123.70","2.33610000"]],"time":"2020-06-30T19:13:00.391119Z"}
{"type":"l2update","product_id":"BTC-USD","changes":[["buy","9101.51","0.00320000"]],"time":"2020-06-30T19:13:00.591830Z"}
{"type":"l2update","product_id":"BTC-USD","changes":[["buy","9120.80","2833.34220000"]],"time":"2020-06-30T19:13:00.645986Z"}
{"type":"heartbeat","last_trade_id":0,"product_id":"BTC-USD","sequence":180755827,"time":"2020-06-30T19:13:00.735113Z"}
{"type":"l2update","product_id":"BTC-USD","changes":[["sell","9292.79","0.00000000"]],"time":"2020-06-30T19:13:00.808546Z"}
{"type":"l2update","product_id":"BTC-USD","changes":[["buy","9063.70","0.04670000"]],"time":"2020-06-30T19:13:01.194982Z"}
{"type":"l2update","product_id":"BTC-USD","changes":[["sell","9122.40","2.61070000"]],"time":"2020-06-30T19:13:01.472680Z"}
{"type":"l2update","product_id":"BTC-USD","changes":[["buy","9078.09","0.00000000"]],"time":"2020-06-30T19:13:01.658817Z"}
{"type":"heartbeat","last_trade_id":0,"product_id":"BTC-USD","sequence":180755833,"time":"2020-06-30T19:13:01.735122Z"}
{"type":"l2update","product_id":"BTC-USD","changes":[["sell","9161.21","0.00000000"]],"time":"2020-06-30T19:13:01.898768Z"}
{"type":"l2update","product_id":"BTC-USD","changes":[["sell","9123.70","0.00000000"]],"time":"2020-06-30T19:13:02.034774Z"}
{"type":"l2update","product_id":"BTC-USD","changes":[["buy","9073.09","0.04400000"]],"time":"2020-06-30T19:13:02.733109Z"}
{"type":"heartbeat","last_trade_id":0,"product_id":"BTC-USD","sequence":180755837,"time":"2020-06-30T19:13:02.735118Z"}
{"type":"l2update","product_id":"BTC-USD","changes":[["buy","9089.56","0.73080000"]],"time":"2020-06-30T19:13:02.911801Z"}
{"type":"l2update","product_id":"BTC-USD","changes":[["buy","9089.09","0.00000000"]],"time":"2020-06-30T19:13:03.097308Z"}
{"type":"l2update","product_id":"BTC-USD","changes":[["buy","9120.80","2833.29220000"]],"time":"2020-06-30T19:13:03.432516Z"}
{"type":"l2update","product_id":"BTC-USD","changes":[["buy","9077.25","0.00000000"]],"time":"2020-06-30T19:13:03.491031Z"}
{"type":"l2update","product_id":"BTC-USD","changes":[["buy","9081.32","0.00000000"]],"time":"2020-06-30T19:13:03.498292Z"}
{"type":"l2update","product_id":"BTC-USD","changes":[["buy","9102.52","0.00000000"]],"time":"2020-06-30T19:13:03.515824Z"}
{"type":"l2update","product_id":"BTC-USD","changes":[["buy","9073.09","0.00000000"]],"time":"2020-06-30T19:13:03.519683Z"}
{"type":"l2update","product_id":"BTC-USD","changes":[["buy","9085.01","0.73080000"]],"time":"2020-06-30T19:13:03.707739Z"}
{"type":"heartbeat","last_trade_id":0,"product_id":"BTC-USD","sequence":180755849,"time":"2020-06-30T19:13:03.735118Z"}
{"type":"l2update","product_id":"BTC-USD","changes":[["buy","9120.80","2825.68380000"]],"time":"2020-06-30T19:13:04.247730Z"}
{"type":"l2update","product_id":"BTC-USD","changes":[["buy","9074.75","0.06890000"]],"time":"2020-06-30T19:13:04.520800Z"}
{"type":"l2update","product_id":"BTC-USD","changes":[["sell","9128.82","0.00000000"]],"time":"2020-06-30T19:13:04.714580Z"}
{"type":"l2update","product_id":"BTC-USD","changes":[["sell","9132.33","0.00000000"]],"time":"2020-06-30T19:13:04.722551Z"}
{"type":"l2update","product_id":"BTC-USD","changes":[["buy","9063.70","0.00000000"]],"time":"2020-06-30T19:13:04.731992Z"}
{"type":"heartbeat","last_trade_id":0,"product_id":"BTC-USD","sequence":180755857,"time":"2020-06-30T19:13:04.735034Z"}
{"type":"l2update","product_id":"BTC-USD","changes":[["buy","9075.58","0.06890000"]],"time":"2020-06-30T19:13:04.827873Z"}
{"type":"l2update","product_id":"BTC-USD","changes":[["buy","9093.69","0.13270000"]],"time":"2020-06-30T19:13:05.098251Z"}
{"type":"heartbeat","last_trade_id":0,"product_id":"BTC-USD","sequence":180755861,"time":"2020-06-30T19:13:05.735181Z"}
{"type":"l2update","product_id":"BTC-USD","changes":[["sell","9156.07","0.09640000"]],"time":"2020-06-30T19:13:06.448866Z"}
{"type":"l2update","product_id":"BTC-USD","changes":[["buy","9075.05","0.00000000"]],"time":"2020-06-30T19:13:06.464314Z"}
{"type":"l2update","product_id":"BTC-USD","changes":[["buy","9088.02","1.51540000"]],"time":"2020-06-30T19:13:06.723838Z"}
{"type":"heartbeat","last_trade_id":0,"product_id":"BTC-USD","sequence":180755866,"time":"2020-06-30T19:13:06.735117Z"}
{"type":"l2update","product_id":"BTC-USD","changes":[["buy","9069.93","0.02350000"]],"time":"2020-06-30T19:13:07.297627Z"}
{"type":"l2update","product_id":"BTC-USD","changes":[["buy","9120.80","2825.53380000"]],"time":"2020-06-30T19:13:07.563846Z"}
{"type":"heartbeat","last_trade_id":0,"product_id":"BTC-USD","sequence":180755871,"time":"2020-06-30T19:13:07.735120Z"}
{"type":"l2update","product_id":"BTC-USD","changes":[["buy","9082.32","0.03500000"]],"time":"2020-06-30T19:13:08.116432Z"}
{"type":"l2update","product_id":"BTC-USD","changes":[["buy","9085.01","0.00000000"]],"time":"2020-06-30T19:13:08.323979Z"}
{"type":"l2update","product_id":"BTC-USD","changes":[["buy","9075.58","0.00000000"]],"time":"2020-06-30T19:13:08.328974Z"}
{"type":"l2update","product_id":"BTC-USD","changes":[["buy","9120.80","2824.63380000"]],"time":"2020-06-30T19:13:08.393153Z"}
{"type":"l2update","product_id":"BTC-USD","changes":[["buy","9120.80","2824.62500000"]],"time":"2020-06-30T19:13:08.671949Z"}
{"type":"heartbeat","last_trade_id":0,"product_id":"BTC-USD","sequence":180755881,"time":"2020-06-30T19:13:08.735116Z"}
{"type":"l2update","product_id":"BTC-USD","changes":[["sell","9160.80","0.00000000"]],"time":"2020-06-30T19:13:08.839067Z"}
{"type":"l2update","product_id":"BTC-USD","changes":[["buy","9120.80","2820.63500000"]],"time":"2020-06-30T19:13:09.234697Z"}
{"type":"heartbeat","last_trade_id":0,"product_id":"BTC-USD","sequence":180755885,"time":"2020-06-30T19:13:09.735114Z"}
{"type":"l2update","product_id":"BTC-USD","changes":[["buy","9120.80","2820.52500000"]],"time":"2020-06-30T19:13:10.038766Z"}
{"type":"l2update","product_id":"BTC-USD","changes":[["sell","9122.40","0.00000000"]],"time":"2020-06-30T19:13:10.479351Z"}
{"type":"heartbeat","last_trade_id":0,"product_id":"BTC-USD","sequence":180755889,"time":"2020-06-30T19:13:10.735124Z"}
{"type":"l2update","product_id":"BTC-USD","changes":[["buy","9098.27","13.19920000"]],"time":"2020-06-30T19:13:10.871848Z"}
{"type":"l2update","product_id":"BTC-USD","changes":[["buy","9088.02","0.00000000"]],"time":"2020-06-30T19:13:11.343861Z"}
{"type":"l2update","product_id":"BTC-USD","changes":[["buy","9100.22","0.00000000"]],"time":"2020-06-30T19:13:11.346076Z"}
{"type":"l2update","product_id":"BTC-USD","changes":[["buy","9078.91","0.00000000"]],"time":"2020-06-30T19:13:11.352960Z"}
{"type":"l2update","product_id":"BTC-USD","changes":[["sell","9128.65","0.02960000"]],"time":"2020-06-30T19:13:11.413586Z"}
{"type":"l2update","product_id":"BTC-USD","changes":[["buy","9120.80","2820.52400000"]],"time":"2020-06-30T19:13:11.656504Z"}
{"type":"l2update","product_id":"BTC-USD","changes":[["buy","9092.39","0.32990000"]],"time":"2020-06-30T19:13:11.706722Z"}
{"type":"heartbeat","last_trade_id":0,"product_id":"BTC-USD","sequence":180755901,"time":"2020-06-30T19:13:11.735114Z"}
{"type":"l2update","product_id":"BTC-USD","changes":[["buy","9078.87","0.03560000"]],"time":"2020-06-30T19:13:11.989274Z"}
{"type":"l2update","product_id":"BTC-USD","changes":[["buy","9093.69","0.00000000"]],"time":"2020-06-30T19:13:12.133928Z"}
{"type":"l2update","product_id":"BTC-USD","changes":[["buy","9070.04","0.01570000"]],"time":"2020-06-30T19:13:12.247268Z"}
{"type":"l2update","product_id":"BTC-USD","changes":[["buy","9082.32","0.00000000"]],"time":"2020-06-30T19:13:12.423211Z"}
{"type":"l2update","product_id":"BTC-USD","changes":[["buy","9104.61","0.00000000"]],"time":"2020-06-30T19:13:12.448070Z"}
{"type":"heartbeat","last_trade_id":0,"product_id":"BTC-USD","sequence":180755908,"time":"2020-06-30T19:13:12.735112Z"}
{"type":"l2update","product_id":"BTC-USD","changes":[["sell","9147.85","0.06910000"]],"time":"2020-06-30T19:13:13.413032Z"}
{"type":"heartbeat","last_trade_id":0,"product_id":"BTC-USD","sequence":180755910,"time":"2020-06-30T19:13:13.735109Z"}
{"type":"l2update","product_id":"BTC-USD","changes":[["buy","9078.87","0.06410000"]],"time":"2020-06-30T19:13:13.979538Z"}
{"type":"l2update","product_id":"BTC-USD","changes":[["buy","100.00","114.95500000"]],"time":"2020-06-30T19:13:14.023204Z"}
{"type":"l2update","product_id":"BTC-USD","changes":[["buy","100.00","114.94500000"]],"time":"2020-06-30T19:13:14.030729Z"}
{"type":"l2update","product_id":"BTC-USD","changes":[["buy","9085.26","0.00000000"]],"time":"2020-06-30T19:13:14.356093Z"}
{"type":"l2update","product_id":"BTC-USD","changes":[["buy","9078.87","0.02850000"]],"time":"2020-06-30T19:13:14.418716Z"}
{"type":"l2update","product_id":"BTC-USD","changes":[["buy","9089.56","0.00000000"]],"time":"2020-06-30T19:13:14.421033Z"}
{"type":"heartbeat","last_trade_id":0,"product_id":"BTC-USD","sequence":180755918,"time":"2020-06-30T19:13:14.735119Z"}
{"type":"l2update","product_id":"BTC-USD","changes":[["buy","9120.80","2818.87900000"]],"time":"2020-06-30T19:13:14.790713Z"}
{"type":"l2update","product_id":"BTC-USD","changes":[["sell","9128.90","0.00000000"]],"time":"2020-06-30T19:13:15.220210Z"}
{"type":"l2update","product_id":"BTC-USD","changes":[["buy","9120.80","2817.56460000"]],"time":"2020-06-30T19:13:15.347762Z"}
{"type":"heartbeat","last_trade_id":0,"product_id":"BTC-USD","sequence":180755925,"time":"2020-06-30T19:13:15.735112Z"}
{"type":"l2update","product_id":"BTC-USD","changes":[["sell","9147.85","0.00000000"]],"time":"2020-06-30T19:13:15.801205Z"}
{"type":"l2update","product_id":"BTC-USD","changes":[["sell","9142.83","0.06910000"]],"time":"2020-06-30T19:13:15.912655Z"}
{"type":"l2update","product_id":"BTC-USD","changes":[["sell","9140.87","0.05470000"]],"time":"2020-06-30T19:13:16.475182Z"}
{"type":"heartbeat","last_trade_id":0,"product_id":"BTC-USD","sequence":180755930,"time":"2020-06-30T19:13:16.735116Z"}
{"type":"l2update","product_id":"BTC-USD","changes":[["sell","9135.00","45.00000000"]],"time":"2020-06-30T19:13:17.296605Z"}
{"type":"l2update","product_id":"BTC-USD","changes":[["sell","9156.07","0.00000000"]],"time":"2020-06-30T19:13:17.722513Z"}
{"type":"heartbeat","last_trade_id":0,"product_id":"BTC-USD","sequence":180755933,"time":"2020-06-30T19:13:17.735115Z"}
{"type":"l2update","product_id":"BTC-USD","changes":[["buy","9041.22","0.08800000"]],"time":"2020-06-30T19:13:18.431532Z"}
{"type":"l2update","product_id":"BTC-USD","changes":[["buy","9068.13","0.02000000"]],"time":"2020-06-30T19:13:18.699155Z"}
{"type":"heartbeat","last_trade_id":0,"product_id":"BTC-USD","sequence":180755937,"time":"2020-06-30T19:13:18.735119Z"}
{"type":"l2update","product_id":"BTC-USD","changes":[["buy","9120.80","2812.61040000"]],"time":"2020-06-30T19:13:18.982320Z"}
{"type":"l2update","product_id":"BTC-USD","changes":[["buy","9070.04","0.00000000"]],"time":"2020-06-30T19:13:19.116616Z"}
{"type":"l2update","product_id":"BTC-USD","changes":[["buy","9041.22","0.00000000"]],"time":"2020-06-30T19:13:19.117819Z"}
{"type":"l2update","product_id":"BTC-USD","changes":[["buy","9101.51","0.00000000"]],"time":"2020-06-30T19:13:19.120881Z"}
{"type":"l2update","product_id":"BTC-USD","changes":[["buy","9120.80","2812.19170000"]],"time":"2020-06-30T19:13:19.267099Z"}
{"type":"l2update","product_id":"BTC-USD","changes":[["sell","9140.87","0.00000000"]],"time":"2020-06-30T19:13:19.451407Z"}
{"type":"heartbeat","last_trade_id":0,"product_id":"BTC-USD","sequence":180755947,"time":"2020-06-30T19:13:19.735113Z"}
{"type":"l2update","product_id":"BTC-USD","changes":[["buy","9091.70","2.29050000"]],"time":"2020-06-30T19:13:19.848002Z"}
{"type":"l2update","product_id":"BTC-USD","changes":[["buy","9120.80","2812.04170000"]],"time":"2020-06-30T19:13:20.106139Z"}
{"type":"l2update","product_id":"BTC-USD","changes":[["sell","9141.65","0.05470000"]],"time":"2020-06-30T19:13:20.619062Z"}
{"type":"heartbeat","last_trade_id":0,"product_id":"BTC-USD","sequence":180755954,"time":"2020-06-30T19:13:20.735118Z"}
{"type":"l2update","product_id":"BTC-USD","changes":[["buy","9086.71","0.02830000"]],"time":"2020-06-30T19:13:20.922573Z"}
{"type":"l2update","product_id":"BTC-USD","changes":[["buy","9098.27","0.00000000"]],"time":"2020-06-30T19:13:21.338248Z"}
{"type":"l2update","product_id":"BTC-USD","changes":[["buy","9069.93","0.00000000"]],"time":"2020-06-30T19:13:21.338329Z"}
{"type":"l2update","product_id":"BTC-USD","changes":[["buy","9078.87","0.00000000"]],"time":"2020-06-30T19:13:21.350641Z"}
{"type":"l2update","product_id":"BTC-USD","changes":[["buy","9100.79","3.65000000"]],"time":"2020-06-30T19:13:21.450718Z"}
{"type":"l2update","product_id":"BTC-USD","changes":[["buy","9100.77","3.71820000"]],"time":"2020-06-30T19:13:21.726100Z"}
{"type":"heartbeat","last_trade_id":0,"product_id":"BTC-USD","sequence":180755963,"time":"2020-06-30T19:13:21.735122Z"}
{"type":"l2update","product_id":"BTC-USD","changes":[["buy","9080.10","0.03280000"]],"time":"2020-06-30T19:13:21.996085Z"}
{"type":"heartbeat","last_trade_id":0,"product_id":"BTC-USD","sequence":180755965,"time":"2020-06-30T19:13:22.735117Z"}
{"type":"l2update","product_id":"BTC-USD","changes":[["buy","9120.80","2808.61510000"]],"time":"2020-06-30T19:13:22.819990Z"}
{"type":"l2update","product_id":"BTC-USD","changes":[["buy","9074.75","0.00000000"]],"time":"2020-06-30T19:13:23.016419Z"}
{"type":"l2update","product_id":"BTC-USD","changes":[["buy","9068.13","0.00000000"]],"time":"2020-06-30T19:13:23.524966Z"}
{"type":"heartbeat","last_trade_id":0,"product_id":"BTC-USD","sequence":180755970,"time":"2020-06-30T19:13:23.735117Z"}
{"type":"l2update","product_id":"BTC-USD","changes":[["buy","9100.81","3.14490000"]],"time":"2020-06-30T19:13:24.529808Z"}
{"type":"heartbeat","last_trade_id":0,"product_id":"BTC-USD","sequence":180755972,"time":"2020-06-30T19:13:24.735112Z"}
{"type":"l2update","product_id":"BTC-USD","changes":[["sell","9148.24","0.06910000"]],"time":"2020-06-30T19:13:25.375048Z"}
{"type":"l2update","product_id":"BTC-USD","changes":[["sell","9147.42","0.06910000"]],"time":"2020-06-30T19:13:25.637876Z"}
{"type":"heartbeat","last_trade_id":0,"product_id":"BTC-USD","sequence":180755976,"time":"2020-06-30T19:13:25.735119Z"}
{"type":"l2update","product_id":"BTC-USD","changes":[["sell","9161.08","0.00000000"]],"time":"2020-06-30T19:13:26.078485Z"}
{"type":"l2update","product_id":"BTC-USD","changes":[["sell","9132.67","3.26500000"]],"time":"2020-06-30T19:13:26.200647Z"}
{"type":"l2update","product_id":"BTC-USD","changes":[["sell","9148.24","0.00000000"]],"time":"2020-06-30T19:13:26.346452Z"}
{"type":"l2update","product_id":"BTC-USD","changes":[["sell","9135.00","0.00000000"]],"time":"2020-06-30T19:13:26.356349Z"}
{"type":"l2update","product_id":"BTC-USD","changes":[["buy","9120.80","2807.71510000"]],"time":"2020-06-30T19:13:26.730509Z"}
{"type":"heartbeat","last_trade_id":0,"product_id":"BTC-USD","sequence":180755984,"time":"2020-06-30T19:13:26.735117Z"}
{"type":"l2update","product_id":"BTC-USD","changes":[["sell","9143.91","0.06910000"]],"time":"2020-06-30T19:13:27.572531Z"}
{"type":"heartbeat","last_trade_id":0,"product_id":"BTC-USD","sequence":180755986,"time":"2020-06-30T19:13:27.735116Z"}
{"type":"l2update","product_id":"BTC-USD","changes":[["buy","9120.80","2803.71610000"]],"time":"2020-06-30T19:13:28.115389Z"}
{"type":"l2update","product_id":"BTC-USD","changes":[["buy","9101.31","0.11260000"]],"time":"2020-06-30T19:13:28.677601Z"}
{"type":"heartbeat","last_trade_id":0,"product_id":"BTC-USD","sequence":180755991,"time":"2020-06-30T19:13:28.735117Z"}
{"type":"l2update","product_id":"BTC-USD","changes":[["buy","100.00","114.95500000"]],"time":"2020-06-30T19:13:29.019387Z"}
{"type":"l2update","product_id":"BTC-USD","changes":[["buy","100.00","114.94500000"]],"time":"2020-06-30T19:13:29.028812Z"}
{"type":"l2update","product_id":"BTC-USD","changes":[["buy","9120.80","2801.72670000"]],"time":"2020-06-30T19:13:29.482472Z"}
{"type":"heartbeat","last_trade_id":0,"product_id":"BTC-USD","sequence":180755997,"time":"2020-06-30T19:13:29.735115Z"}
{"type":"l2update","product_id":"BTC-USD","changes":[["sell","9177.67","0.00000000"]],"time":"2020-06-30T19:13:29.899559Z"}
{"type":"l2update","product_id":"BTC-USD","changes":[["buy","9103.86","0.50000000"]],"time":"2020-06-30T19:13:30.046651Z"}
{"type":"l2update","product_id":"BTC-USD","changes":[["buy","9120.80","2801.67670000"]],"time":"2020-06-30T19:13:30.306685Z"}
{"type":"l2update","product_id":"BTC-USD","changes":[["buy","9074.26","0.00000000"]],"time":"2020-06-30T19:13:30.500347Z"}
{"type":"heartbeat","last_trade_id":0,"product_id":"BTC-USD","sequence":180756004,"time":"2020-06-30T19:13:30.735111Z"}
{"type":"l2update","product_id":"BTC-USD","changes":[["buy","9120.80","2801.62670000"]],"time":"2020-06-30T19:13:31.149289Z"}
{"type":"l2update","product_id":"BTC-USD","changes":[["buy","9098.27","1.12200000"]],"time":"2020-06-30T19:13:31.425196Z"}
{"type":"heartbeat","last_trade_id":0,"product_id":"BTC-USD","sequence":180756009,"time":"2020-06-30T19:13:31.735112Z"}
{"type":"l2update","product_id":"BTC-USD","changes":[["buy","9092.39","0.00000000"]],"time":"2020-06-30T19:13:31.905365Z"}
{"type":"l2update","product_id":"BTC-USD","changes":[["buy","9085.40","0.12130000"]],"time":"2020-06-30T19:13:32.543112Z"}
{"type":"heartbeat","last_trade_id":0,"product_id":"BTC-USD","sequence":180756012,"time":"2020-06-30T19:13:32.735108Z"}
{"type":"l2update","product_id":"BTC-USD","changes":[["buy","9120.80","2801.34170000"]],"time":"2020-06-30T19:13:33.399177Z"}
{"type":"l2update","product_id":"BTC-USD","changes":[["buy","9120.80","2801.27580000"]],"time":"2020-06-30T19:13:33.653202Z"}
{"type":"heartbeat","last_trade_id":0,"product_id":"BTC-USD","sequence":180756018,"time":"2020-06-30T19:13:33.735120Z"}
{"type":"l2update","product_id":"BTC-USD","changes":[["sell","9147.42","0.00000000"]],"time":"2020-06-30T19:13:33.841668Z"}
{"type":"l2update","product_id":"BTC-USD","changes":[["sell","9141.65","0.00000000"]],"time":"2020-06-30T19:13:33.904185Z"}
{"type":"l2update","product_id":"BTC-USD","changes":[["buy","9120.80","2800.37580000"]],"time":"2020-06-30T19:13:33.958661Z"}
{"type":"l2update","product_id":"BTC-USD","changes":[["sell","9142.83","0.00000000"]],"time":"2020-06-30T19:13:34.109755Z"}
{"type":"l2update","product_id":"BTC-USD","changes":[["buy","9105.50","18.57460000"]],"time":"2020-06-30T19:13:34.203979Z"}
{"type":"l2update","product_id":"BTC-USD","changes":[["sell","9128.65","0.00000000"]],"time":"2020-06-30T19:13:34.387713Z"}
{"type":"l2update","product_id":"BTC-USD","changes":[["buy","9100.77","0.00000000"]],"time":"2020-06-30T19:13:34.637532Z"}
{"type":"l2update","product_id":"BTC-USD","changes":[["buy","9080.10","0.00000000"]],"time":"2020-06-30T19:13:34.643443Z"}
{"type":"l2update","product_id":"BTC-USD","changes":[["buy","9101.31","0.00000000"]],"time":"2020-06-30T19:13:34.643452Z"}
{"type":"heartbeat","last_trade_id":0,"product_id":"BTC-USD","sequence":180756030,"time":"2020-06-30T19:13:34.735114Z"}
{"type":"l2update","product_id":"BTC-USD","changes":[["buy","9069.48","0.02350000"]],"time":"2020-06-30T19:13:34.759030Z"}
{"type":"l2update","product_id":"BTC-USD","changes":[["sell","9175.49","0.10000000"]],"time":"2020-06-30T19:13:35.019851Z"}
{"type":"l2update","product_id":"BTC-USD","changes":[["buy","9086.59","0.05330000"]],"time":"2020-06-30T19:13:35.292883Z"}
{"type":"l2update","product_id":"BTC-USD","changes":[["buy","9087.82","0.05190000"]],"time":"2020-06-30T19:13:35.570781Z"}
{"type":"heartbeat","last_trade_id":0,"product_id":"BTC-USD","sequence":180756038,"time":"2020-06-30T19:13:35.735106Z"}
{"type":"l2update","product_id":"BTC-USD","changes":[["buy","9105.50","36.58560000"]],"time":"2020-06-30T19:13:35.846353Z"}
{"type":"l2update","product_id":"BTC-USD","changes":[["buy","9105.50","50.49660000"]],"time":"2020-06-30T19:13:36.120019Z"}
{"type":"l2update","product_id":"BTC-USD","changes":[["buy","9120.80","2799.36590000"]],"time":"2020-06-30T19:13:36.396973Z"}
{"type":"l2update","product_id":"BTC-USD","changes":[["buy","9081.72","0.34390000"]],"time":"2020-06-30T19:13:36.663713Z"}
{"type":"heartbeat","last_trade_id":0,"product_id":"BTC-USD","sequence":180756047,"time":"2020-06-30T19:13:36.735091Z"}
{"type":"l2update","product_id":"BTC-USD","changes":[["buy","9069.48","0.00000000"]],"time":"2020-06-30T19:13:37.106482Z"}
{"type":"heartbeat","last_trade_id":0,"product_id":"BTC-USD","sequence":180756048,"time":"2020-06-30T19:13:37.735115Z"}
{"type":"l2update","product_id":"BTC-USD","changes":[["buy","9094.06","0.72770000"]],"time":"2020-06-30T19:13:37.787409Z"}
{"type":"l2update","product_id":"BTC-USD","changes":[["buy","9105.50","67.55760000"]],"time":"2020-06-30T19:13:38.064555Z"}
{"type":"l2update","product_id":"BTC-USD","changes":[["buy","9100.79","0.00000000"]],"time":"2020-06-30T19:13:38.229871Z"}
{"type":"l2update","product_id":"BTC-USD","changes":[["sell","9151.48","0.06910000"]],"time":"2020-06-30T19:13:38.617537Z"}
{"type":"heartbeat","last_trade_id":0,"product_id":"BTC-USD","sequence":180756055,"time":"2020-06-30T19:13:38.735112Z"}
{"type":"l2update","product_id":"BTC-USD","changes":[["sell","9181.63","0.05820000"]],"time":"2020-06-30T19:13:38.953494Z"}
{"type":"l2update","product_id":"BTC-USD","changes":[["sell","9138.72","1.03930000"]],"time":"2020-06-30T19:13:39.497135Z"}
{"type":"heartbeat","last_trade_id":0,"product_id":"BTC-USD","sequence":180756059,"time":"2020-06-30T19:13:39.735069Z"}
{"type":"l2update","product_id":"BTC-USD","changes":[["sell","9132.67","0.00000000"]],"time":"2020-06-30T19:13:39.924164Z"}
{"type":"l2update","product_id":"BTC-USD","changes":[["buy","9120.80","2799.30000000"]],"time":"2020-06-30T19:13:40.056410Z"}
{"type":"l2update","product_id":"BTC-USD","changes":[["buy","9120.80","2799.23410000"]],"time":"2020-06-30T19:13:40.322481Z"}
{"type":"l2update","product_id":"BTC-USD","changes":[["sell","9151.48","0.00000000"]],"time":"2020-06-30T19:13:40.511066Z"}
{"type":"l2update","product_id":"BTC-USD","changes":[["sell","9135.74","0.04500000"]],"time":"2020-06-30T19:13:40.597071Z"}
{"type":"heartbeat","last_trade_id":0,"product_id":"BTC-USD","sequence":180756069,"time":"2020-06-30T19:13:40.735091Z"}
{"type":"l2update","product_id":"BTC-USD","changes":[["sell","9175.49","0.00000000"]],"time":"2020-06-30T19:13:41.033674Z"}
{"type":"l2update","product_id":"BTC-USD","changes":[["buy","9120.80","2799.18410000"]],"time":"2020-06-30T19:13:41.147058Z"}
{"type":"l2update","product_id":"BTC-USD","changes":[["sell","9120.82","3006.39400000"]],"time":"2020-06-30T19:13:41.270741Z"}
{"type":"l2update","product_id":"BTC-USD","changes":[["sell","9133.56","1.13630000"]],"time":"2020-06-30T19:13:41.414959Z"}
{"type":"l2update","product_id":"BTC-USD","changes":[["buy","9105.50","84.05400000"]],"time":"2020-06-30T19:13:41.696726Z"}
{"type":"heartbeat","last_trade_id":0,"product_id":"BTC-USD","sequence":180756080,"time":"2020-06-30T19:13:41.735118Z"}
{"type":"l2update","product_id":"BTC-USD","changes":[["buy","9103.86","0.00000000"]],"time":"2020-06-30T19:13:41.886892Z"}
{"type":"l2update","product_id":"BTC-USD","changes":[["buy","9087.82","0.00000000"]],"time":"2020-06-30T19:13:41.895505Z"}
{"type":"l2update","product_id":"BTC-USD","changes":[["buy","9105.50","70.14300000"]],"time":"2020-06-30T19:13:41.902295Z"}
{"type":"l2update","product_id":"BTC-USD","changes":[["buy","9120.80","2799.11820000"]],"time":"2020-06-30T19:13:41.961708Z"}
{"type":"l2update","product_id":"BTC-USD","changes":[["sell","9135.77","0.01110000"]],"time":"2020-06-30T19:13:42.257577Z"}
{"type":"heartbeat","last_trade_id":0,"product_id":"BTC-USD","sequence":180756088,"time":"2020-06-30T19:13:42.735116Z"}
{"type":"l2update","product_id":"BTC-USD","changes":[["sell","9130.00","5.00000000"]],"time":"2020-06-30T19:13:43.074474Z"}
{"type":"l2update","product_id":"BTC-USD","changes":[["buy","9120.80","2797.47320000"]],"time":"2020-06-30T19:13:43.345554Z"}
{"type":"l2update","product_id":"BTC-USD","changes":[["sell","9138.72","0.00000000"]],"time":"2020-06-30T19:13:43.592833Z"}
{"type":"l2update","product_id":"BTC-USD","changes":[["sell","9181.63","0.00000000"]],"time":"2020-06-30T19:13:43.593612Z"}
{"type":"l2update","product_id":"BTC-USD","changes":[["buy","9105.52","8.05560000"]],"time":"2020-06-30T19:13:43.660666Z"}
{"type":"heartbeat","last_trade_id":0,"product_id":"BTC-USD","sequence":180756097,"time":"2020-06-30T19:13:43.735113Z"}
{"type":"l2update","product_id":"BTC-USD","changes":[["buy","100.00","114.95500000"]],"time":"2020-06-30T19:13:44.062642Z"}
{"type":"l2update","product_id":"BTC-USD","changes":[["buy","100.00","114.94500000"]],"time":"2020-06-30T19:13:44.068801Z"}
{"type":"l2update","product_id":"BTC-USD","changes":[["buy","9105.50","53.08200000"]],"time":"2020-06-30T19:13:44.104906Z"}
{"type":"l2update","product_id":"BTC-USD","changes":[["sell","9128.35","0.10000000"]],"time":"2020-06-30T19:13:44.475096Z"}
{"type":"heartbeat","last_trade_id":0,"product_id":"BTC-USD","sequence":180756103,"time":"2020-06-30T19:13:44.734954Z"}
{"type":"l2update","product_id":"BTC-USD","changes":[["sell","9133.58","0.88210000"]],"time":"2020-06-30T19:13:45.320598Z"}
{"type":"l2update","product_id":"BTC-USD","changes":[["buy","9103.31","0.50000000"]],"time":"2020-06-30T19:13:45.595015Z"}
{"type":"heartbeat","last_trade_id":0,"product_id":"BTC-USD","sequence":180756107,"time":"2020-06-30T19:13:45.735127Z"}
{"type":"l2update","product_id":"BTC-USD","changes":[["buy","9047.28","0.08790000"]],"time":"2020-06-30T19:13:45.873325Z"}
{"type":"l2update","product_id":"BTC-USD","changes":[["sell","9135.77","0.00000000"]],"time":"2020-06-30T19:13:45.919544Z"}
{"type":"l2update","product_id":"BTC-USD","changes":[["buy","9086.71","0.00000000"]],"time":"2020-06-30T19:13:46.022413Z"}
{"type":"l2update","product_id":"BTC-USD","changes":[["buy","9098.27","0.00000000"]],"time":"2020-06-30T19:13:46.032534Z"}
{"type":"l2update","product_id":"BTC-USD","changes":[["buy","9120.80","2792.18450000"]],"time":"2020-06-30T19:13:46.164208Z"}
{"type":"l2update","product_id":"BTC-USD","changes":[["buy","9094.06","0.00000000"]],"time":"2020-06-30T19:13:46.315177Z"}
{"type":"l2update","product_id":"BTC-USD","changes":[["sell","9138.74","1.18950000"]],"time":"2020-06-30T19:13:46.418695Z"}
{"type":"l2update","product_id":"BTC-USD","changes":[["sell","9133.58","0.00000000"]],"time":"2020-06-30T19:13:46.595059Z"}
{"type":"heartbeat","last_trade_id":0,"product_id":"BTC-USD","sequence":180756119,"time":"2020-06-30T19:13:46.735118Z"}
{"type":"l2update","product_id":"BTC-USD","changes":[["buy","9120.80","2792.13450000"]],"time":"2020-06-30T19:13:47.549579Z"}
{"type":"heartbeat","last_trade_id":0,"product_id":"BTC-USD","sequence":180756122,"time":"2020-06-30T19:13:47.735112Z"}
{"type":"l2update","product_id":"BTC-USD","changes":[["buy","9078.84","0.01000000"]],"time":"2020-06-30T19:13:47.818075Z"}
{"type":"l2update","product_id":"BTC-USD","changes":[["sell","9128.35","0.00000000"]],"time":"2020-06-30T19:13:48.017538Z"}
{"type":"l2update","product_id":"BTC-USD","changes":[["buy","9085.40","0.00000000"]],"time":"2020-06-30T19:13:48.269647Z"}
{"type":"l2update","product_id":"BTC-USD","changes":[["buy","9105.50","34.50740000"]],"time":"2020-06-30T19:13:48.269903Z"}
{"type":"heartbeat","last_trade_id":0,"product_id":"BTC-USD","sequence":180756127,"time":"2020-06-30T19:13:48.735111Z"}
{"type":"l2update","product_id":"BTC-USD","changes":[["buy","9105.54","12.54420000"]],"time":"2020-06-30T19:13:49.237680Z"}
{"type":"l2update","product_id":"BTC-USD","changes":[["buy","9105.50","18.01100000"]],"time":"2020-06-30T19:13:49.626063Z"}
{"type":"l2update","product_id":"BTC-USD","changes":[["buy","9100.81","0.00000000"]],"time":"2020-06-30T19:13:49.626375Z"}
{"type":"heartbeat","last_trade_id":0,"product_id":"BTC-USD","sequence":180756131,"time":"2020-06-30T19:13:49.735116Z"}
{"type":"l2update","product_id":"BTC-USD","changes":[["buy","9120.80","2792.08450000"]],"time":"2020-06-30T19:13:49.778529Z"}
{"type":"l2update","product_id":"BTC-USD","changes":[["buy","9120.80","2791.18450000"]],"time":"2020-06-30T19:13:50.057515Z"}
{"type":"l2update","product_id":"BTC-USD","changes":[["buy","9120.80","2790.28450000"]],"time":"2020-06-30T19:13:50.327773Z"}
{"type":"l2update","product_id":"BTC-USD","changes":[["sell","9130.00","0.00000000"]],"time":"2020-06-30T19:13:50.486797Z"}
{"type":"heartbeat","last_trade_id":0,"product_id":"BTC-USD","sequence":180756141,"time":"2020-06-30T19:13:50.735127Z"}
{"type":"l2update","product_id":"BTC-USD","changes":[["buy","9120.80","2790.27140000"]],"time":"2020-06-30T19:13:51.434404Z"}
{"type":"l2update","product_id":"BTC-USD","changes":[["buy","9120.80","2790.21140000"]],"time":"2020-06-30T19:13:51.711751Z"}
{"type":"heartbeat","last_trade_id":0,"product_id":"BTC-USD","sequence":180756147,"time":"2020-06-30T19:13:51.735099Z"}
{"type":"l2update","product_id":"BTC-USD","changes":[["buy","9086.24","0.01000000"]],"time":"2020-06-30T19:13:51.996138Z"}
{"type":"l2update","product_id":"BTC-USD","changes":[["sell","9133.56","0.00000000"]],"time":"2020-06-30T19:13:52.164816Z"}
{"type":"l2update","product_id":"BTC-USD","changes":[["sell","9143.91","0.00000000"]],"time":"2020-06-30T19:13:52.170186Z"}
{"type":"l2update","product_id":"BTC-USD","changes":[["buy","9103.31","0.00000000"]],"time":"2020-06-30T19:13:52.241109Z"}
{"type":"l2update","product_id":"BTC-USD","changes":[["buy","9081.72","0.00000000"]],"time":"2020-06-30T19:13:52.247614Z"}
{"type":"l2update","product_id":"BTC-USD","changes":[["buy","9078.84","0.00000000"]],"time":"2020-06-30T19:13:52.252414Z"}
{"type":"heartbeat","last_trade_id":0,"product_id":"BTC-USD","sequence":180756154,"time":"2020-06-30T19:13:52.735097Z"}
{"type":"l2update","product_id":"BTC-USD","changes":[["buy","9101.96","0.32960000"]],"time":"2020-06-30T19:13:52.925986Z"}
{"type":"l2update","product_id":"BTC-USD","changes":[["buy","9086.24","0.00000000"]],"time":"2020-06-30T19:13:53.347885Z"}
{"type":"l2update","product_id":"BTC-USD","changes":[["buy","9105.50","0.00000000"]],"time":"2020-06-30T19:13:53.349871Z"}
{"type":"heartbeat","last_trade_id":0,"product_id":"BTC-USD","sequence":180756158,"time":"2020-06-30T19:13:53.735126Z"}
{"type":"l2update","product_id":"BTC-USD","changes":[["sell","9160.58","0.07660000"]],"time":"2020-06-30T19:13:53.751732Z"}
{"type":"l2update","product_id":"BTC-USD","changes":[["buy","9120.80","2789.07230000"]],"time":"2020-06-30T19:13:54.030506Z"}
{"type":"l2update","product_id":"BTC-USD","changes":[["buy","9091.33","0.02830000"]],"time":"2020-06-30T19:13:54.284068Z"}
{"type":"l2update","product_id":"BTC-USD","changes":[["buy","9105.54","0.00000000"]],"time":"2020-06-30T19:13:54.715830Z"}
{"type":"l2update","product_id":"BTC-USD","changes":[["buy","9047.28","0.00000000"]],"time":"2020-06-30T19:13:54.723698Z"}
{"type":"heartbeat","last_trade_id":0,"product_id":"BTC-USD","sequence":180756167,"time":"2020-06-30T19:13:54.735115Z"}
{"type":"l2update","product_id":"BTC-USD","changes":[["buy","9073.03","0.00000000"]],"time":"2020-06-30T19:13:54.746044Z"}
{"type":"l2update","product_id":"BTC-USD","changes":[["buy","9120.80","2788.17210000"]],"time":"2020-06-30T19:13:54.836560Z"}
{"type":"l2update","product_id":"BTC-USD","changes":[["buy","9083.72","0.11530000"]],"time":"2020-06-30T19:13:55.251455Z"}
{"type":"heartbeat","last_trade_id":0,"product_id":"BTC-USD","sequence":180756173,"time":"2020-06-30T19:13:55.735096Z"}
{"type":"l2update","product_id":"BTC-USD","changes":[["buy","9120.80","2782.79510000"]],"time":"2020-06-30T19:13:56.335852Z"}
{"type":"heartbeat","last_trade_id":0,"product_id":"BTC-USD","sequence":180756176,"time":"2020-06-30T19:13:56.735096Z"}
{"type":"l2update","product_id":"BTC-USD","changes":[["buy","9120.80","2782.42360000"]],"time":"2020-06-30T19:13:56.971082Z"}
{"type":"l2update","product_id":"BTC-USD","changes":[["buy","9104.30","15.39700000"]],"time":"2020-06-30T19:13:57.251673Z"}
{"type":"l2update","product_id":"BTC-USD","changes":[["buy","9107.79","1.11140000"]],"time":"2020-06-30T19:13:57.518851Z"}
{"type":"heartbeat","last_trade_id":0,"product_id":"BTC-USD","sequence":180756183,"time":"2020-06-30T19:13:57.735099Z"}
{"type":"l2update","product_id":"BTC-USD","changes":[["buy","9120.80","2782.35770000"]],"time":"2020-06-30T19:13:58.346773Z"}
{"type":"l2update","product_id":"BTC-USD","changes":[["buy","8894.00","0.00000000"]],"time":"2020-06-30T19:13:58.507472Z"}
{"type":"l2update","product_id":"BTC-USD","changes":[["buy","9120.80","2781.81270000"]],"time":"2020-06-30T19:13:58.619436Z"}
{"type":"l2update","product_id":"BTC-USD","changes":[["buy","8893.18","0.04654411"]],"time":"2020-06-30T19:13:58.722732Z"}
{"type":"heartbeat","last_trade_id":0,"product_id":"BTC-USD","sequence":180756192,"time":"2020-06-30T19:13:58.735099Z"}
{"type":"l2update","product_id":"BTC-USD","changes":[["sell","9436.96","0.00000000"]],"time":"2020-06-30T19:13:58.981258Z"}
{"type":"l2update","product_id":"BTC-USD","changes":[["buy","100.00","114.95500000"]],"time":"2020-06-30T19:13:59.029105Z"}
{"type":"l2update","product_id":"BTC-USD","changes":[["buy","100.00","114.94500000"]],"time":"2020-06-30T19:13:59.036094Z"}
{"type":"l2update","product_id":"BTC-USD","changes":[["sell","9437.82","0.00728822"]],"time":"2020-06-30T19:13:59.222835Z"}
{"type":"heartbeat","last_trade_id":0,"product_id":"BTC-USD","sequence":180756198,"time":"2020-06-30T19:13:59.735109Z"}
{"type":"l2update","product_id":"BTC-USD","changes":[["buy","9120.80","2781.77680000"]],"time":"2020-06-30T19:14:00.338338Z"}
{"type":"l2update","product_id":"BTC-USD","changes":[["sell","9162.24","0.01490000"]],"time":"2020-06-30T19:14:00.614085Z"}
{"type":"heartbeat","last_trade_id":0,"product_id":"BTC-USD","sequence":180756203,"time":"2020-06-30T19:14:00.735123Z"}
{"type":"l2update","product_id":"BTC-USD","changes":[["sell","9160.58","0.00000000"]],"time":"2020-06-30T19:14:00.781023Z"}
{"type":"l2update","product_id":"BTC-USD","changes":[["buy","9103.25","0.06590000"]],"time":"2020-06-30T19:14:00.909609Z"}
{"type":"l2update","product_id":"BTC-USD","changes":[["sell","9121.50","0.01470000"]],"time":"2020-06-30T19:14:01.187088Z"}
{"type":"l2update","product_id":"BTC-USD","changes":[["buy","9120.80","2781.44750000"]],"time":"2020-06-30T19:14:01.477033Z"}
{"type":"l2update","product_id":"BTC-USD","changes":[["sell","9162.24","0.00000000"]],"time":"2020-06-30T19:14:01.718904Z"}
{"type":"heartbeat","last_trade_id":0,"product_id":"BTC-USD","sequence":180756212,"time":"2020-06-30T19:14:01.735120Z"}
{"type":"l2update","product_id":"BTC-USD","changes":[["sell","9160.96","0.01450000"]],"time":"2020-06-30T19:14:01.844856Z"}
{"type":"l2update","product_id":"BTC-USD","changes":[["sell","9160.25","0.01450000"]],"time":"2020-06-30T19:14:02.534056Z"}
{"type":"heartbeat","last_trade_id":0,"product_id":"BTC-USD","sequence":180756216,"time":"2020-06-30T19:14:02.735115Z"}
{"type":"l2update","product_id":"BTC-USD","changes":[["buy","9120.80","2781.41500000"]],"time":"2020-06-30T19:14:02.858730Z"}
{"type":"heartbeat","last_trade_id":0,"product_id":"BTC-USD","sequence":180756219,"time":"2020-06-30T19:14:03.735022Z"}
{"type":"l2update","product_id":"BTC-USD","changes":[["buy","9120.80","2781.23150000"]],"time":"2020-06-30T19:14:03.754558Z"}
{"type":"l2update","product_id":"BTC-USD","changes":[["buy","9120.80","2781.04800000"]],"time":"2020-06-30T19:14:03.974994Z"}
{"type":"l2update","product_id":"BTC-USD","changes":[["sell","9138.74","0.00000000"]],"time":"2020-06-30T19:14:04.156369Z"}
{"type":"heartbeat","last_trade_id":0,"product_id":"BTC-USD","sequence":180756226,"time":"2020-06-30T19:14:04.735172Z"}
{"type":"l2update","product_id":"BTC-USD","changes":[["sell","9161.82","0.01490000"]],"time":"2020-06-30T19:14:05.376089Z"}
{"type":"l2update","product_id":"BTC-USD","changes":[["buy","9120.80","2780.98210000"]],"time":"2020-06-30T19:14:05.649981Z"}
{"type":"heartbeat","last_trade_id":0,"product_id":"BTC-USD","sequence":180756231,"time":"2020-06-30T19:14:05.735117Z"}
{"type":"l2update","product_id":"BTC-USD","changes":[["sell","9160.96","0.00000000"]],"time":"2020-06-30T19:14:05.787218Z"}
{"type":"l2update","product_id":"BTC-USD","changes":[["buy","9108.48","4.24840000"]],"time":"2020-06-30T19:14:05.923254Z"}
{"type":"l2update","product_id":"BTC-USD","changes":[["buy","9105.52","0.00000000"]],"time":"2020-06-30T19:14:06.360665Z"}
{"type":"l2update","product_id":"BTC-USD","changes":[["buy","9101.96","0.00000000"]],"time":"2020-06-30T19:14:06.365745Z"}
{"type":"l2update","product_id":"BTC-USD","changes":[["buy","9120.80","2780.94620000"]],"time":"2020-06-30T19:14:06.502522Z"}
{"type":"heartbeat","last_trade_id":0,"product_id":"BTC-USD","sequence":180756239,"time":"2020-06-30T19:14:06.735110Z"}
{"type":"l2update","product_id":"BTC-USD","changes":[["sell","9161.34","0.10580000"]],"time":"2020-06-30T19:14:06.771079Z"}
{"type":"heartbeat","last_trade_id":0,"product_id":"BTC-USD","sequence":180756241,"time":"2020-06-30T19:14:07.735109Z"}
{"type":"l2update","product_id":"BTC-USD","changes":[["buy","9084.49","0.05200000"]],"time":"2020-06-30T19:14:08.524968Z"}
{"type":"heartbeat","last_trade_id":0,"product_id":"BTC-USD","sequence":180756243,"time":"2020-06-30T19:14:08.735120Z"}
{"type":"l2update","product_id":"BTC-USD","changes":[["buy","9107.53","0.73080000"]],"time":"2020-06-30T19:14:08.818259Z"}
{"type":"l2update","product_id":"BTC-USD","changes":[["buy","9108.48","0.00000000"]],"time":"2020-06-30T19:14:08.954199Z"}
{"type":"l2update","product_id":"BTC-USD","changes":[["buy","9120.80","2780.88030000"]],"time":"2020-06-30T19:14:09.082399Z"}
{"type":"l2update","product_id":"BTC-USD","changes":[["buy","9104.43","0.06590000"]],"time":"2020-06-30T19:14:09.657535Z"}
{"type":"heartbeat","last_trade_id":0,"product_id":"BTC-USD","sequence":180756251,"time":"2020-06-30T19:14:09.735116Z"}
{"type":"l2update","product_id":"BTC-USD","changes":[["buy","9120.80","2780.84440000"]],"time":"2020-06-30T19:14:10.226392Z"}
{"type":"l2update","product_id":"BTC-USD","changes":[["sell","9160.25","0.00000000"]],"time":"2020-06-30T19:14:10.352411Z"}
{"type":"l2update","product_id":"BTC-USD","changes":[["sell","9143.07","2.23320000"]],"time":"2020-06-30T19:14:10.495330Z"}
{"type":"heartbeat","last_trade_id":0,"product_id":"BTC-USD","sequence":180756257,"time":"2020-06-30T19:14:10.735033Z"}
{"type":"l2update","product_id":"BTC-USD","changes":[["buy","9120.80","2780.84340000"]],"time":"2020-06-30T19:14:10.863252Z"}
{"type":"l2update","product_id":"BTC-USD","changes":[["sell","9161.86","0.06900000"]],"time":"2020-06-30T19:14:11.058101Z"}
{"type":"heartbeat","last_trade_id":0,"product_id":"BTC-USD","sequence":180756262,"time":"2020-06-30T19:14:11.735170Z"}
{"type":"l2update","product_id":"BTC-USD","changes":[["buy","9104.45","0.06590000"]],"time":"2020-06-30T19:14:11.871337Z"}
{"type":"l2update","product_id":"BTC-USD","changes":[["buy","9083.72","0.00000000"]],"time":"2020-06-30T19:14:12.310508Z"}
{"type":"l2update","product_id":"BTC-USD","changes":[["buy","9104.43","0.00000000"]],"time":"2020-06-30T19:14:12.311256Z"}
{"type":"l2update","product_id":"BTC-USD","changes":[["buy","9085.73","0.08880000"]],"time":"2020-06-30T19:14:12.447113Z"}
{"type":"l2update","product_id":"BTC-USD","changes":[["sell","9179.22","0.10000000"]],"time":"2020-06-30T19:14:12.696646Z"}
{"type":"heartbeat","last_trade_id":0,"product_id":"BTC-USD","sequence":180756270,"time":"2020-06-30T19:14:12.735117Z"}
{"type":"l2update","product_id":"BTC-USD","changes":[["buy","9091.33","0.00000000"]],"time":"2020-06-30T19:14:12.870545Z"}
{"type":"l2update","product_id":"BTC-USD","changes":[["buy","9084.49","0.00000000"]],"time":"2020-06-30T19:14:12.888353Z"}
{"type":"l2update","product_id":"BTC-USD","changes":[["buy","9120.80","2780.80750000"]],"time":"2020-06-30T19:14:12.962538Z"}
{"type":"l2update","product_id":"BTC-USD","changes":[["sell","9143.07","0.00000000"]],"time":"2020-06-30T19:14:13.122953Z"}
{"type":"l2update","product_id":"BTC-USD","changes":[["buy","9106.82","0.54800000"]],"time":"2020-06-30T19:14:13.251422Z"}
{"type":"heartbeat","last_trade_id":0,"product_id":"BTC-USD","sequence":180756278,"time":"2020-06-30T19:14:13.735122Z"}
{"type":"l2update","product_id":"BTC-USD","changes":[["buy","9076.86","0.01000000"]],"time":"2020-06-30T19:14:13.820582Z"}
{"type":"l2update","product_id":"BTC-USD","changes":[["buy","100.00","114.95500000"]],"time":"2020-06-30T19:14:14.036182Z"}
{"type":"l2update","product_id":"BTC-USD","changes":[["buy","100.00","114.94500000"]],"time":"2020-06-30T19:14:14.042334Z"}
{"type":"l2update","product_id":"BTC-USD","changes":[["sell","9141.71","0.88830000"]],"time":"2020-06-30T19:14:14.136763Z"}
{"type":"l2update","product_id":"BTC-USD","changes":[["sell","9179.22","0.00000000"]],"time":"2020-06-30T19:14:14.278857Z"}
{"type":"l2update","product_id":"BTC-USD","changes":[["sell","9161.86","0.00000000"]],"time":"2020-06-30T19:14:14.290718Z"}
{"type":"l2update","product_id":"BTC-USD","changes":[["buy","9120.80","2780.63150000"]],"time":"2020-06-30T19:14:14.381414Z"}
{"type":"l2update","product_id":"BTC-USD","changes":[["buy","9104.99","2.39460000"]],"time":"2020-06-30T19:14:14.667761Z"}
{"type":"heartbeat","last_trade_id":0,"product_id":"BTC-USD","sequence":180756292,"time":"2020-06-30T19:14:14.735118Z"}
{"type":"l2update","product_id":"BTC-USD","changes":[["buy","9107.99","0.00240000"]],"time":"2020-06-30T19:14:14.934307Z"}
{"type":"l2update","product_id":"BTC-USD","changes":[["buy","9085.73","0.00000000"]],"time":"2020-06-30T19:14:15.104661Z"}
{"type":"l2update","product_id":"BTC-USD","changes":[["buy","9104.45","0.00000000"]],"time":"2020-06-30T19:14:15.106907Z"}
{"type":"l2update","product_id":"BTC-USD","changes":[["buy","9120.80","2779.73150000"]],"time":"2020-06-30T19:14:15.218020Z"}
{"type":"heartbeat","last_trade_id":0,"product_id":"BTC-USD","sequence":180756299,"time":"2020-06-30T19:14:15.735119Z"}
{"type":"l2update","product_id":"BTC-USD","changes":[["buy","9120.80","2779.61380000"]],"time":"2020-06-30T19:14:15.759072Z"}
{"type":"l2update","product_id":"BTC-USD","changes":[["buy","9086.59","0.00000000"]],"time":"2020-06-30T19:14:15.894116Z"}
{"type":"l2update","product_id":"BTC-USD","changes":[["buy","9120.80","2779.30500000"]],"time":"2020-06-30T19:14:16.612026Z"}
{"type":"heartbeat","last_trade_id":0,"product_id":"BTC-USD","sequence":180756306,"time":"2020-06-30T19:14:16.735120Z"}
{"type":"l2update","product_id":"BTC-USD","changes":[["sell","9161.82","0.00000000"]],"time":"2020-06-30T19:14:17.048941Z"}
{"type":"l2update","product_id":"BTC-USD","changes":[["buy","9120.80","2778.76000000"]],"time":"2020-06-30T19:14:17.411100Z"}
{"type":"l2update","product_id":"BTC-USD","changes":[["buy","9111.62","0.61140000"]],"time":"2020-06-30T19:14:17.692300Z"}
{"type":"heartbeat","last_trade_id":0,"product_id":"BTC-USD","sequence":180756312,"time":"2020-06-30T19:14:17.735115Z"}
{"type":"l2update","product_id":"BTC-USD","changes":[["sell","9161.34","0.00000000"]],"time":"2020-06-30T19:14:17.826571Z"}
{"type":"l2update","product_id":"BTC-USD","changes":[["buy","9120.80","2774.19070000"]],"time":"2020-06-30T19:14:17.971723Z"}
{"type":"l2update","product_id":"BTC-USD","changes":[["buy","9120.80","2774.12490000"]],"time":"2020-06-30T19:14:18.257333Z"}
{"type":"l2update","product_id":"BTC-USD","changes":[["buy","9112.31","0.84440000"]],"time":"2020-06-30T19:14:18.545944Z"}
{"type":"heartbeat","last_trade_id":0,"product_id":"BTC-USD","sequence":180756321,"time":"2020-06-30T19:14:18.735119Z"}
{"type":"l2update","product_id":"BTC-USD","changes":[["buy","9071.43","0.07820000"]],"time":"2020-06-30T19:14:19.244471Z"}
{"type":"l2update","product_id":"BTC-USD","changes":[["buy","9112.31","1.80800000"]],"time":"2020-06-30T19:14:19.520376Z"}
{"type":"heartbeat","last_trade_id":0,"product_id":"BTC-USD","sequence":180756325,"time":"2020-06-30T19:14:19.735123Z"}
{"type":"l2update","product_id":"BTC-USD","changes":[["buy","9120.80","2774.05910000"]],"time":"2020-06-30T19:14:19.809969Z"}
{"type":"l2update","product_id":"BTC-USD","changes":[["buy","9107.53","0.00000000"]],"time":"2020-06-30T19:14:19.937647Z"}
{"type":"l2update","product_id":"BTC-USD","changes":[["sell","9135.74","0.00000000"]],"time":"2020-06-30T19:14:20.222362Z"}
{"type":"l2update","product_id":"BTC-USD","changes":[["buy","9112.31","3.01690000"]],"time":"2020-06-30T19:14:20.364148Z"}
{"type":"heartbeat","last_trade_id":0,"product_id":"BTC-USD","sequence":180756332,"time":"2020-06-30T19:14:20.735119Z"}
{"type":"l2update","product_id":"BTC-USD","changes":[["buy","9112.31","2.05330000"]],"time":"2020-06-30T19:14:20.800086Z"}
{"type":"l2update","product_id":"BTC-USD","changes":[["buy","9112.31","3.50080000"]],"time":"2020-06-30T19:14:21.468359Z"}
{"type":"heartbeat","last_trade_id":0,"product_id":"BTC-USD","sequence":180756335,"time":"2020-06-30T19:14:21.735068Z"}
{"type":"l2update","product_id":"BTC-USD","changes":[["buy","9112.31","3.80180000"]],"time":"2020-06-30T19:14:22.299770Z"}
{"type":"l2update","product_id":"BTC-USD","changes":[["buy","9120.80","2773.80190000"]],"time":"2020-06-30T19:14:22.602868Z"}
{"type":"heartbeat","last_trade_id":0,"product_id":"BTC-USD","sequence":180756340,"time":"2020-06-30T19:14:22.735097Z"}
{"type":"l2update","product_id":"BTC-USD","changes":[["sell","9160.53","0.06900000"]],"time":"2020-06-30T19:14:23.408937Z"}
{"type":"heartbeat","last_trade_id":0,"product_id":"BTC-USD","sequence":180756342,"time":"2020-06-30T19:14:23.735117Z"}
{"type":"l2update","product_id":"BTC-USD","changes":[["buy","9120.80","2772.90190000"]],"time":"2020-06-30T19:14:24.220935Z"}
{"type":"l2update","product_id":"BTC-USD","changes":[["sell","9160.53","0.00000000"]],"time":"2020-06-30T19:14:24.404590Z"}
{"type":"l2update","product_id":"BTC-USD","changes":[["buy","9111.81","0.25250000"]],"time":"2020-06-30T19:14:24.502550Z"}
{"type":"heartbeat","last_trade_id":0,"product_id":"BTC-USD","sequence":180756348,"time":"2020-06-30T19:14:24.735071Z"}
{"type":"l2update","product_id":"BTC-USD","changes":[["buy","9120.80","2771.40190000"]],"time":"2020-06-30T19:14:24.803736Z"}
{"type":"l2update","product_id":"BTC-USD","changes":[["buy","9076.86","0.00000000"]],"time":"2020-06-30T19:14:24.947343Z"}
{"type":"l2update","product_id":"BTC-USD","changes":[["buy","9071.43","0.00000000"]],"time":"2020-06-30T19:14:24.951199Z"}
{"type":"l2update","product_id":"BTC-USD","changes":[["buy","9103.34","0.02230000"]],"time":"2020-06-30T19:14:25.090301Z"}
{"type":"l2update","product_id":"BTC-USD","changes":[["buy","9120.80","2771.35190000"]],"time":"2020-06-30T19:14:25.453276Z"}
{"type":"l2update","product_id":"BTC-USD","changes":[["buy","9107.79","0.00000000"]],"time":"2020-06-30T19:14:25.500113Z"}
{"type":"l2update","product_id":"BTC-USD","changes":[["buy","9112.31","2.59290000"]],"time":"2020-06-30T19:14:25.506593Z"}
{"type":"heartbeat","last_trade_id":0,"product_id":"BTC-USD","sequence":180756360,"time":"2020-06-30T19:14:25.735097Z"}
{"type":"l2update","product_id":"BTC-USD","changes":[["sell","9121.50","0.00000000"]],"time":"2020-06-30T19:14:25.887830Z"}
{"type":"l2update","product_id":"BTC-USD","changes":[["sell","9141.71","0.00000000"]],"time":"2020-06-30T19:14:25.894763Z"}
{"type":"l2update","product_id":"BTC-USD","changes":[["buy","9120.80","2767.11620000"]],"time":"2020-06-30T19:14:26.034592Z"}
{"type":"heartbeat","last_trade_id":0,"product_id":"BTC-USD","sequence":180756365,"time":"2020-06-30T19:14:26.735085Z"}
{"type":"l2update","product_id":"BTC-USD","changes":[["buy","9120.80","2766.21620000"]],"time":"2020-06-30T19:14:26.869619Z"}
{"type":"l2update","product_id":"BTC-USD","changes":[["buy","9103.48","0.02230000"]],"time":"2020-06-30T19:14:27.418122Z"}
{"type":"l2update","product_id":"BTC-USD","changes":[["buy","9074.46","0.07370000"]],"time":"2020-06-30T19:14:27.697449Z"}
{"type":"heartbeat","last_trade_id":0,"product_id":"BTC-USD","sequence":180756372,"time":"2020-06-30T19:14:27.735094Z"}
{"type":"l2update","product_id":"BTC-USD","changes":[["buy","9104.99","0.00000000"]],"time":"2020-06-30T19:14:27.844151Z"}
{"type":"l2update","product_id":"BTC-USD","changes":[["buy","9091.70","0.00000000"]],"time":"2020-06-30T19:14:27.847198Z"}
{"type":"l2update","product_id":"BTC-USD","changes":[["buy","9111.62","0.00000000"]],"time":"2020-06-30T19:14:27.970816Z"}
{"type":"heartbeat","last_trade_id":0,"product_id":"BTC-USD","sequence":180756375,"time":"2020-06-30T19:14:28.735036Z"}
{"type":"l2update","product_id":"BTC-USD","changes":[["buy","100.00","114.95500000"]],"time":"2020-06-30T19:14:29.017442Z"}
{"type":"l2update","product_id":"BTC-USD","changes":[["buy","100.00","114.94500000"]],"time":"2020-06-30T19:14:29.027256Z"}
{"type":"l2update","product_id":"BTC-USD","changes":[["buy","9120.80","2766.21290000"]],"time":"2020-06-30T19:14:29.151322Z"}
{"type":"l2update","product_id":"BTC-USD","changes":[["buy","9107.96","0.79680000"]],"time":"2020-06-30T19:14:29.718794Z"}
{"type":"heartbeat","last_trade_id":0,"product_id":"BTC-USD","sequence":180756383,"time":"2020-06-30T19:14:29.735170Z"}
{"type":"l2update","product_id":"BTC-USD","changes":[["buy","9112.18","1.03390000"]],"time":"2020-06-30T19:14:30.286622Z"}
{"type":"l2update","product_id":"BTC-USD","changes":[["buy","9076.92","0.07370000"]],"time":"2020-06-30T19:14:30.549206Z"}
{"type":"l2update","product_id":"BTC-USD","changes":[["buy","9112.31","1.74850000"]],"time":"2020-06-30T19:14:30.740626Z"}
{"type":"heartbeat","last_trade_id":0,"product_id":"BTC-USD","sequence":180756388,"time":"2020-06-30T19:14:30.735124Z"}
{"type":"heartbeat","last_trade_id":0,"product_id":"BTC-USD","sequence":180756388,"time":"2020-06-30T19:14:31.735122Z"}
{"type":"l2update","product_id":"BTC-USD","changes":[["buy","9103.61","0.04900000"]],"time":"2020-06-30T19:14:32.537210Z"}
{"type":"heartbeat","last_trade_id":0,"product_id":"BTC-USD","sequence":180756390,"time":"2020-06-30T19:14:32.735120Z"}
{"type":"l2update","product_id":"BTC-USD","changes":[["buy","9120.80","2766.16290000"]],"time":"2020-06-30T19:14:33.655116Z"}
{"type":"heartbeat","last_trade_id":0,"product_id":"BTC-USD","sequence":180756393,"time":"2020-06-30T19:14:33.735123Z"}
{"type":"l2update","product_id":"BTC-USD","changes":[["buy","9120.80","2766.11290000"]],"time":"2020-06-30T19:14:34.467518Z"}
{"type":"heartbeat","last_trade_id":0,"product_id":"BTC-USD","sequence":180756396,"time":"2020-06-30T19:14:34.735117Z"}
{"type":"l2update","product_id":"BTC-USD","changes":[["buy","9120.80","2766.11160000"]],"time":"2020-06-30T19:14:34.751308Z"}
{"type":"l2update","product_id":"BTC-USD","changes":[["buy","9120.80","2766.04910000"]],"time":"2020-06-30T19:14:35.358126Z"}
{"type":"heartbeat","last_trade_id":0,"product_id":"BTC-USD","sequence":180756402,"time":"2020-06-30T19:14:35.735121Z"}
{"type":"l2update","product_id":"BTC-USD","changes":[["sell","9161.55","0.01000000"]],"time":"2020-06-30T19:14:35.864324Z"}
{"type":"l2update","product_id":"BTC-USD","changes":[["buy","9111.98","0.05810000"]],"time":"2020-06-30T19:14:36.114301Z"}
{"type":"l2update","product_id":"BTC-USD","changes":[["buy","9111.81","0.00000000"]],"time":"2020-06-30T19:14:36.543502Z"}
{"type":"heartbeat","last_trade_id":0,"product_id":"BTC-USD","sequence":180756407,"time":"2020-06-30T19:14:36.735123Z"}
{"type":"l2update","product_id":"BTC-USD","changes":[["buy","9120.80","2765.99910000"]],"time":"2020-06-30T19:14:36.948050Z"}
{"type":"l2update","product_id":"BTC-USD","changes":[["buy","9071.04","0.08920000"]],"time":"2020-06-30T19:14:37.210819Z"}
{"type":"l2update","product_id":"BTC-USD","changes":[["buy","9104.30","0.00000000"]],"time":"2020-06-30T19:14:37.661616Z"}
{"type":"heartbeat","last_trade_id":0,"product_id":"BTC-USD","sequence":180756413,"time":"2020-06-30T19:14:37.735120Z"}
{"type":"l2update","product_id":"BTC-USD","changes":[["buy","9112.39","7.67780000"]],"time":"2020-06-30T19:14:38.052905Z"}
{"type":"l2update","product_id":"BTC-USD","changes":[["buy","9112.18","0.00000000"]],"time":"2020-06-30T19:14:38.483625Z"}
{"type":"l2update","product_id":"BTC-USD","changes":[["buy","9017.56","0.00200000"]],"time":"2020-06-30T19:14:38.610444Z"}
{"type":"heartbeat","last_trade_id":0,"product_id":"BTC-USD","sequence":180756418,"time":"2020-06-30T19:14:38.735124Z"}
{"type":"l2update","product_id":"BTC-USD","changes":[["sell","9253.18","0.00200000"]],"time":"2020-06-30T19:14:39.191812Z"}
{"type":"heartbeat","last_trade_id":0,"product_id":"BTC-USD","sequence":180756420,"time":"2020-06-30T19:14:39.735127Z"}
{"type":"l2update","product_id":"BTC-USD","changes":[["sell","9160.03","0.01490000"]],"time":"2020-06-30T19:14:40.014121Z"}
{"type":"l2update","product_id":"BTC-USD","changes":[["sell","9159.34","0.06900000"]],"time":"2020-06-30T19:14:40.285582Z"}
{"type":"l2update","product_id":"BTC-USD","changes":[["sell","9158.79","0.01000000"]],"time":"2020-06-30T19:14:40.561373Z"}
{"type":"heartbeat","last_trade_id":0,"product_id":"BTC-USD","sequence":180756426,"time":"2020-06-30T19:14:40.735147Z"}
{"type":"l2update","product_id":"BTC-USD","changes":[["buy","9120.80","2765.93330000"]],"time":"2020-06-30T19:14:41.105068Z"}
{"type":"l2update","product_id":"BTC-USD","changes":[["sell","9142.27","0.04430000"]],"time":"2020-06-30T19:14:41.384645Z"}
{"type":"l2update","product_id":"BTC-USD","changes":[["sell","9120.82","3006.39300000"]],"time":"2020-06-30T19:14:41.464298Z"}
{"type":"heartbeat","last_trade_id":0,"product_id":"BTC-USD","sequence":180756434,"time":"2020-06-30T19:14:41.735130Z"}
{"type":"l2update","product_id":"BTC-USD","changes":[["sell","9159.00","0.06900000"]],"time":"2020-06-30T19:14:41.936733Z"}
{"type":"l2update","product_id":"BTC-USD","changes":[["buy","9120.80","2765.65730000"]],"time":"2020-06-30T19:14:42.506101Z"}
{"type":"heartbeat","last_trade_id":0,"product_id":"BTC-USD","sequence":180756439,"time":"2020-06-30T19:14:42.735134Z"}
{"type":"l2update","product_id":"BTC-USD","changes":[["buy","9120.80","2764.75730000"]],"time":"2020-06-30T19:14:43.036071Z"}
{"type":"l2update","product_id":"BTC-USD","changes":[["buy","9120.80","2763.96040000"]],"time":"2020-06-30T19:14:43.305924Z"}
{"type":"l2update","product_id":"BTC-USD","changes":[["sell","9253.18","0.00000000"]],"time":"2020-06-30T19:14:43.475593Z"}
{"type":"l2update","product_id":"BTC-USD","changes":[["buy","9111.89","0.00120000"]],"time":"2020-06-30T19:14:43.567096Z"}
{"type":"heartbeat","last_trade_id":0,"product_id":"BTC-USD","sequence":180756448,"time":"2020-06-30T19:14:43.735124Z"}
{"type":"l2update","product_id":"BTC-USD","changes":[["buy","9071.54","0.04660000"]],"time":"2020-06-30T19:14:43.853750Z"}
{"type":"l2update","product_id":"BTC-USD","changes":[["buy","9112.31","0.30100000"]],"time":"2020-06-30T19:14:43.978993Z"}
{"type":"l2update","product_id":"BTC-USD","changes":[["buy","9071.04","0.00000000"]],"time":"2020-06-30T19:14:44.052155Z"}
{"type":"l2update","product_id":"BTC-USD","changes":[["buy","100.00","114.95500000"]],"time":"2020-06-30T19:14:44.054993Z"}
{"type":"l2update","product_id":"BTC-USD","changes":[["buy","100.00","114.94500000"]],"time":"2020-06-30T19:14:44.061514Z"}
{"type":"l2update","product_id":"BTC-USD","changes":[["buy","9103.25","0.00000000"]],"time":"2020-06-30T19:14:44.062764Z"}
{"type":"l2update","product_id":"BTC-USD","changes":[["buy","9071.12","0.11750000"]],"time":"2020-06-30T19:14:44.697423Z"}
{"type":"heartbeat","last_trade_id":0,"product_id":"BTC-USD","sequence":180756458,"time":"2020-06-30T19:14:44.735132Z"}
{"type":"l2update","product_id":"BTC-USD","changes":[["buy","9120.80","2763.71040000"]],"time":"2020-06-30T19:14:44.960218Z"}
{"type":"l2update","product_id":"BTC-USD","changes":[["buy","9017.56","0.00000000"]],"time":"2020-06-30T19:14:45.125102Z"}
{"type":"l2update","product_id":"BTC-USD","changes":[["buy","9076.92","0.00000000"]],"time":"2020-06-30T19:14:45.127924Z"}
{"type":"l2update","product_id":"BTC-USD","changes":[["sell","9159.92","0.06900000"]],"time":"2020-06-30T19:14:45.242636Z"}
{"type":"l2update","product_id":"BTC-USD","changes":[["buy","9120.80","2763.26860000"]],"time":"2020-06-30T19:14:45.527244Z"}
{"type":"heartbeat","last_trade_id":0,"product_id":"BTC-USD","sequence":180756468,"time":"2020-06-30T19:14:45.735119Z"}
{"type":"l2update","product_id":"BTC-USD","changes":[["buy","9067.17","0.06300000"]],"time":"2020-06-30T19:14:46.340560Z"}
{"type":"heartbeat","last_trade_id":0,"product_id":"BTC-USD","sequence":180756470,"time":"2020-06-30T19:14:46.735112Z"}
{"type":"l2update","product_id":"BTC-USD","changes":[["buy","9074.46","0.00000000"]],"time":"2020-06-30T19:14:46.789058Z"}
{"type":"l2update","product_id":"BTC-USD","changes":[["buy","9120.80","2763.26730000"]],"time":"2020-06-30T19:14:47.732744Z"}
{"type":"heartbeat","last_trade_id":0,"product_id":"BTC-USD","sequence":180756474,"time":"2020-06-30T19:14:47.735113Z"}
{"type":"l2update","product_id":"BTC-USD","changes":[["buy","9120.80","2763.20150000"]],"time":"2020-06-30T19:14:48.298815Z"}
{"type":"l2update","product_id":"BTC-USD","changes":[["sell","9158.22","0.03830000"]],"time":"2020-06-30T19:14:48.644604Z"}
{"type":"heartbeat","last_trade_id":0,"product_id":"BTC-USD","sequence":180756479,"time":"2020-06-30T19:14:48.735117Z"}
{"type":"l2update","product_id":"BTC-USD","changes":[["sell","9160.03","0.00000000"]],"time":"2020-06-30T19:14:49.040108Z"}
{"type":"heartbeat","last_trade_id":0,"product_id":"BTC-USD","sequence":180756480,"time":"2020-06-30T19:14:49.735116Z"}
{"type":"l2update","product_id":"BTC-USD","changes":[["buy","9078.78","0.01000000"]],"time":"2020-06-30T19:14:49.901239Z"}
{"type":"l2update","product_id":"BTC-USD","changes":[["buy","9071.54","0.00000000"]],"time":"2020-06-30T19:14:50.339418Z"}
{"type":"l2update","product_id":"BTC-USD","changes":[["buy","9073.66","0.02930000"]],"time":"2020-06-30T19:14:50.445902Z"}
{"type":"l2update","product_id":"BTC-USD","changes":[["buy","9100.96","0.03070000"]],"time":"2020-06-30T19:14:50.745442Z"}
{"type":"heartbeat","last_trade_id":0,"product_id":"BTC-USD","sequence":180756487,"time":"2020-06-30T19:14:50.735050Z"}
{"type":"l2update","product_id":"BTC-USD","changes":[["buy","9106.82","0.00000000"]],"time":"2020-06-30T19:14:50.893586Z"}
{"type":"l2update","product_id":"BTC-USD","changes":[["buy","9071.12","0.00000000"]],"time":"2020-06-30T19:14:50.900426Z"}
{"type":"l2update","product_id":"BTC-USD","changes":[["buy","9120.80","2763.13570000"]],"time":"2020-06-30T19:14:51.025892Z"}
{"type":"l2update","product_id":"BTC-USD","changes":[["buy","9120.80","2763.10590000"]],"time":"2020-06-30T19:14:51.291072Z"}
{"type":"l2update","product_id":"BTC-USD","changes":[["sell","9158.22","0.00000000"]],"time":"2020-06-30T19:14:51.465634Z"}
{"type":"heartbeat","last_trade_id":0,"product_id":"BTC-USD","sequence":180756496,"time":"2020-06-30T19:14:51.735109Z"}
{"type":"l2update","product_id":"BTC-USD","changes":[["sell","9161.55","0.00000000"]],"time":"2020-06-30T19:14:51.773364Z"}
{"type":"l2update","product_id":"BTC-USD","changes":[["buy","9120.80","2763.01400000"]],"time":"2020-06-30T19:14:51.844768Z"}
{"type":"l2update","product_id":"BTC-USD","changes":[["buy","9120.80","2762.96400000"]],"time":"2020-06-30T19:14:52.116048Z"}
{"type":"l2update","product_id":"BTC-USD","changes":[["buy","9086.64","0.08700000"]],"time":"2020-06-30T19:14:52.390361Z"}
{"type":"heartbeat","last_trade_id":0,"product_id":"BTC-USD","sequence":180756505,"time":"2020-06-30T19:14:52.735115Z"}
{"type":"l2update","product_id":"BTC-USD","changes":[["buy","9111.89","0.00000000"]],"time":"2020-06-30T19:14:52.888230Z"}
{"type":"l2update","product_id":"BTC-USD","changes":[["buy","9107.99","0.00000000"]],"time":"2020-06-30T19:14:52.918043Z"}
{"type":"l2update","product_id":"BTC-USD","changes":[["sell","9159.51","0.05270000"]],"time":"2020-06-30T19:14:52.961404Z"}
{"type":"l2update","product_id":"BTC-USD","changes":[["sell","9159.34","0.00000000"]],"time":"2020-06-30T19:14:53.471286Z"}
{"type":"l2update","product_id":"BTC-USD","changes":[["buy","9120.80","2762.86600000"]],"time":"2020-06-30T19:14:53.509128Z"}
{"type":"l2update","product_id":"BTC-USD","changes":[["sell","9159.51","0.00000000"]],"time":"2020-06-30T19:14:53.694616Z"}
{"type":"heartbeat","last_trade_id":0,"product_id":"BTC-USD","sequence":180756514,"time":"2020-06-30T19:14:53.735119Z"}
{"type":"l2update","product_id":"BTC-USD","changes":[["buy","9120.80","2762.81600000"]],"time":"2020-06-30T19:14:53.798047Z"}
{"type":"l2update","product_id":"BTC-USD","changes":[["buy","9120.80","2762.80200000"]],"time":"2020-06-30T19:14:54.108260Z"}
{"type":"heartbeat","last_trade_id":0,"product_id":"BTC-USD","sequence":180756520,"time":"2020-06-30T19:14:54.735109Z"}
{"type":"l2update","product_id":"BTC-USD","changes":[["sell","9159.41","0.01490000"]],"time":"2020-06-30T19:14:54.888869Z"}
{"type":"heartbeat","last_trade_id":0,"product_id":"BTC-USD","sequence":180756522,"time":"2020-06-30T19:14:55.735118Z"}
{"type":"l2update","product_id":"BTC-USD","changes":[["sell","9145.45","0.05470000"]],"time":"2020-06-30T19:14:56.552425Z"}
{"type":"heartbeat","last_trade_id":0,"product_id":"BTC-USD","sequence":180756524,"time":"2020-06-30T19:14:56.735115Z"}
{"type":"l2update","product_id":"BTC-USD","changes":[["sell","9159.00","0.00000000"]],"time":"2020-06-30T19:14:56.975564Z"}
{"type":"l2update","product_id":"BTC-USD","changes":[["buy","9120.80","2761.90200000"]],"time":"2020-06-30T19:14:57.113875Z"}
{"type":"l2update","product_id":"BTC-USD","changes":[["sell","9130.30","0.50000000"]],"time":"2020-06-30T19:14:57.366254Z"}
{"type":"l2update","product_id":"BTC-USD","changes":[["sell","9159.41","0.00000000"]],"time":"2020-06-30T19:14:57.565954Z"}
{"type":"heartbeat","last_trade_id":0,"product_id":"BTC-USD","sequence":180756531,"time":"2020-06-30T19:14:57.735117Z"}
{"type":"l2update","product_id":"BTC-USD","changes":[["buy","9112.07","0.05000000"]],"time":"2020-06-30T19:14:57.913136Z"}
{"type":"l2update","product_id":"BTC-USD","changes":[["buy","9120.80","2761.83620000"]],"time":"2020-06-30T19:14:58.185353Z"}
{"type":"l2update","product_id":"BTC-USD","changes":[["buy","9073.66","0.00000000"]],"time":"2020-06-30T19:14:58.361055Z"}
{"type":"l2update","product_id":"BTC-USD","changes":[["buy","8893.18","0.00000000"]],"time":"2020-06-30T19:14:58.599951Z"}
{"type":"heartbeat","last_trade_id":0,"product_id":"BTC-USD","sequence":180756538,"time":"2020-06-30T19:14:58.735115Z"}
{"type":"l2update","product_id":"BTC-USD","changes":[["buy","9120.80","2761.78620000"]],"time":"2020-06-30T19:14:58.766931Z"}
{"type":"l2update","product_id":"BTC-USD","changes":[["buy","8892.39","0.04664204"]],"time":"2020-06-30T19:14:58.836383Z"}
{"type":"l2update","product_id":"BTC-USD","changes":[["buy","9120.80","2761.67220000"]],"time":"2020-06-30T19:14:59.030484Z"}
{"type":"l2update","product_id":"BTC-USD","changes":[["sell","9437.82","0.00000000"]],"time":"2020-06-30T19:14:59.166644Z"}
{"type":"l2update","product_id":"BTC-USD","changes":[["buy","100.00","114.95500000"]],"time":"2020-06-30T19:14:59.185929Z"}
{"type":"l2update","product_id":"BTC-USD","changes":[["buy","100.00","114.94500000"]],"time":"2020-06-30T19:14:59.192136Z"}
{"type":"l2update","product_id":"BTC-USD","changes":[["sell","9438.66","0.00738400"]],"time":"2020-06-30T19:14:59.384034Z"}
{"type":"heartbeat","last_trade_id":0,"product_id":"BTC-USD","sequence":180756552,"time":"2020-06-30T19:14:59.735119Z"}
{"type":"l2update","product_id":"BTC-USD","changes":[["buy","9099.18","0.02230000"]],"time":"2020-06-30T19:15:00.140933Z"}
{"type":"l2update","product_id":"BTC-USD","changes":[["buy","9100.96","0.00000000"]],"time":"2020-06-30T19:15:00.582070Z"}
{"type":"heartbeat","last_trade_id":0,"product_id":"BTC-USD","sequence":180756555,"time":"2020-06-30T19:15:00.735119Z"}
{"type":"l2update","product_id":"BTC-USD","changes":[["buy","9110.69","1.50000000"]],"time":"2020-06-30T19:15:00.825090Z"}
{"type":"l2update","product_id":"BTC-USD","changes":[["buy","9112.39","0.00000000"]],"time":"2020-06-30T19:15:01.289436Z"}
{"type":"l2update","product_id":"BTC-USD","changes":[["buy","9103.65","0.04900000"]],"time":"2020-06-30T19:15:01.320558Z"}
{"type":"l2update","product_id":"BTC-USD","changes":[["buy","9107.96","0.00000000"]],"time":"2020-06-30T19:15:01.334156Z"}
{"type":"heartbeat","last_trade_id":0,"product_id":"BTC-USD","sequence":180756561,"time":"2020-06-30T19:15:01.735115Z"}
{"type":"l2update","product_id":"BTC-USD","changes":[["buy","9112.31","0.00000000"]],"time":"2020-06-30T19:15:01.778104Z"}
{"type":"l2update","product_id":"BTC-USD","changes":[["sell","9158.44","0.04230000"]],"time":"2020-06-30T19:15:01.894592Z"}
{"type":"l2update","product_id":"BTC-USD","changes":[["sell","9159.91","0.04230000"]],"time":"2020-06-30T19:15:02.244869Z"}
{"type":"l2update","product_id":"BTC-USD","changes":[["buy","9112.04","0.02710000"]],"time":"2020-06-30T19:15:02.491142Z"}
{"type":"l2update","product_id":"BTC-USD","changes":[["buy","9120.80","2761.60640000"]],"time":"2020-06-30T19:15:02.742392Z"}
{"type":"heartbeat","last_trade_id":0,"product_id":"BTC-USD","sequence":180756571,"time":"2020-06-30T19:15:02.735115Z"}
{"type":"heartbeat","last_trade_id":0,"product_id":"BTC-USD","sequence":180756571,"time":"2020-06-30T19:15:03.735116Z"}
{"type":"l2update","product_id":"BTC-USD","changes":[["buy","9105.72","0.06580000"]],"time":"2020-06-30T19:15:04.154950Z"}
{"type":"l2update","product_id":"BTC-USD","changes":[["buy","9091.02","0.03830000"]],"time":"2020-06-30T19:15:04.456327Z"}
{"type":"heartbeat","last_trade_id":0,"product_id":"BTC-USD","sequence":180756575,"time":"2020-06-30T19:15:04.735117Z"}
{"type":"l2update","product_id":"BTC-USD","changes":[["sell","9159.39","0.06900000"]],"time":"2020-06-30T19:15:04.956563Z"}
{"type":"l2update","product_id":"BTC-USD","changes":[["buy","9076.11","0.95960000"]],"time":"2020-06-30T19:15:05.269115Z"}
{"type":"l2update","product_id":"BTC-USD","changes":[["buy","9111.57","0.25050000"]],"time":"2020-06-30T19:15:05.531417Z"}
{"type":"heartbeat","last_trade_id":0,"product_id":"BTC-USD","sequence":180756581,"time":"2020-06-30T19:15:05.735123Z"}
{"type":"l2update","product_id":"BTC-USD","changes":[["sell","9157.05","0.06470000"]],"time":"2020-06-30T19:15:05.894732Z"}
{"type":"l2update","product_id":"BTC-USD","changes":[["buy","9111.59","0.26530000"]],"time":"2020-06-30T19:15:06.350476Z"}
{"type":"l2update","product_id":"BTC-USD","changes":[["sell","9130.30","0.00000000"]],"time":"2020-06-30T19:15:06.382489Z"}
{"type":"l2update","product_id":"BTC-USD","changes":[["sell","9159.91","0.00000000"]],"time":"2020-06-30T19:15:06.395279Z"}
{"type":"l2update","product_id":"BTC-USD","changes":[["buy","9103.34","0.00000000"]],"time":"2020-06-30T19:15:06.601451Z"}
{"type":"l2update","product_id":"BTC-USD","changes":[["buy","9120.80","2757.22690000"]],"time":"2020-06-30T19:15:06.637174Z"}
{"type":"heartbeat","last_trade_id":0,"product_id":"BTC-USD","sequence":180756591,"time":"2020-06-30T19:15:06.735115Z"}
{"type":"l2update","product_id":"BTC-USD","changes":[["sell","9126.36","0.02000000"]],"time":"2020-06-30T19:15:06.772930Z"}
{"type":"heartbeat","last_trade_id":0,"product_id":"BTC-USD","sequence":180756593,"time":"2020-06-30T19:15:07.735112Z"}
{"type":"l2update","product_id":"BTC-USD","changes":[["buy","9120.80","2752.72410000"]],"time":"2020-06-30T19:15:07.768205Z"}
{"type":"l2update","product_id":"BTC-USD","changes":[["buy","9111.60","0.25060000"]],"time":"2020-06-30T19:15:08.058861Z"}
{"type":"l2update","product_id":"BTC-USD","changes":[["sell","9159.92","0.00000000"]],"time":"2020-06-30T19:15:08.232029Z"}
{"type":"l2update","product_id":"BTC-USD","changes":[["buy","9120.80","2752.47410000"]],"time":"2020-06-30T19:15:08.329752Z"}
{"type":"l2update","product_id":"BTC-USD","changes":[["buy","9112.04","0.00000000"]],"time":"2020-06-30T19:15:08.496902Z"}
{"type":"l2update","product_id":"BTC-USD","changes":[["buy","9105.72","0.00000000"]],"time":"2020-06-30T19:15:08.505662Z"}
{"type":"l2update","product_id":"BTC-USD","changes":[["buy","9086.64","0.00000000"]],"time":"2020-06-30T19:15:08.508596Z"}
{"type":"l2update","product_id":"BTC-USD","changes":[["buy","9067.17","0.00000000"]],"time":"2020-06-30T19:15:08.517057Z"}
{"type":"heartbeat","last_trade_id":0,"product_id":"BTC-USD","sequence":180756606,"time":"2020-06-30T19:15:08.735114Z"}
{"type":"l2update","product_id":"BTC-USD","changes":[["sell","9157.58","0.05710000"]],"time":"2020-06-30T19:15:08.923744Z"}
{"type":"l2update","product_id":"BTC-USD","changes":[["sell","9157.04","0.03290000"]],"time":"2020-06-30T19:15:09.169948Z"}
{"type":"l2update","product_id":"BTC-USD","changes":[["buy","9077.42","0.01000000"]],"time":"2020-06-30T19:15:09.732453Z"}
{"type":"heartbeat","last_trade_id":0,"product_id":"BTC-USD","sequence":180756612,"time":"2020-06-30T19:15:09.735117Z"}
{"type":"l2update","product_id":"BTC-USD","changes":[["buy","9111.60","0.00000000"]],"time":"2020-06-30T19:15:09.922282Z"}
{"type":"l2update","product_id":"BTC-USD","changes":[["buy","9103.48","0.00000000"]],"time":"2020-06-30T19:15:09.926049Z"}
{"type":"l2update","product_id":"BTC-USD","changes":[["sell","9157.80","0.10580000"]],"time":"2020-06-30T19:15:10.294380Z"}
{"type":"l2update","product_id":"BTC-USD","changes":[["sell","9156.96","0.02780000"]],"time":"2020-06-30T19:15:10.554765Z"}
{"type":"l2update","product_id":"BTC-USD","changes":[["buy","9120.80","2752.47310000"]],"time":"2020-06-30T19:15:10.662974Z"}
{"type":"l2update","product_id":"BTC-USD","changes":[["sell","9157.05","0.00000000"]],"time":"2020-06-30T19:15:10.730343Z"}
{"type":"l2update","product_id":"BTC-USD","changes":[["sell","9157.58","0.00000000"]],"time":"2020-06-30T19:15:10.733574Z"}
{"type":"heartbeat","last_trade_id":0,"product_id":"BTC-USD","sequence":180756623,"time":"2020-06-30T19:15:10.735113Z"}
{"type":"l2update","product_id":"BTC-USD","changes":[["sell","9142.27","0.00000000"]],"time":"2020-06-30T19:15:10.991061Z"}
{"type":"l2update","product_id":"BTC-USD","changes":[["sell","9156.00","0.06900000"]],"time":"2020-06-30T19:15:11.116811Z"}
{"type":"l2update","product_id":"BTC-USD","changes":[["buy","9120.80","2748.00510000"]],"time":"2020-06-30T19:15:11.389422Z"}
{"type":"l2update","product_id":"BTC-USD","changes":[["sell","9158.94","0.01490000"]],"time":"2020-06-30T19:15:11.684010Z"}
{"type":"heartbeat","last_trade_id":0,"product_id":"BTC-USD","sequence":180756631,"time":"2020-06-30T19:15:11.735122Z"}
{"type":"l2update","product_id":"BTC-USD","changes":[["sell","9156.96","0.00000000"]],"time":"2020-06-30T19:15:11.815013Z"}
{"type":"l2update","product_id":"BTC-USD","changes":[["buy","9103.70","0.02230000"]],"time":"2020-06-30T19:15:11.972880Z"}
{"type":"heartbeat","last_trade_id":0,"product_id":"BTC-USD","sequence":180756634,"time":"2020-06-30T19:15:12.735119Z"}
{"type":"l2update","product_id":"BTC-USD","changes":[["buy","9120.80","2747.93930000"]],"time":"2020-06-30T19:15:13.120517Z"}
{"type":"l2update","product_id":"BTC-USD","changes":[["sell","9145.45","0.00000000"]],"time":"2020-06-30T19:15:13.597493Z"}
{"type":"l2update","product_id":"BTC-USD","changes":[["sell","9158.94","0.00000000"]],"time":"2020-06-30T19:15:13.597537Z"}
{"type":"l2update","product_id":"BTC-USD","changes":[["buy","9120.80","2747.87350000"]],"time":"2020-06-30T19:15:13.677245Z"}
{"type":"heartbeat","last_trade_id":0,"product_id":"BTC-USD","sequence":180756642,"time":"2020-06-30T19:15:13.735114Z"}
{"type":"l2update","product_id":"BTC-USD","changes":[["buy","9094.89","2.18790000"]],"time":"2020-06-30T19:15:13.972712Z"}
{"type":"l2update","product_id":"BTC-USD","changes":[["buy","100.00","114.95500000"]],"time":"2020-06-30T19:15:14.038132Z"}
{"type":"l2update","product_id":"BTC-USD","changes":[["buy","100.00","114.94500000"]],"time":"2020-06-30T19:15:14.045145Z"}
{"type":"l2update","product_id":"BTC-USD","changes":[["buy","9120.80","2747.79540000"]],"time":"2020-06-30T19:15:14.228213Z"}
{"type":"heartbeat","last_trade_id":0,"product_id":"BTC-USD","sequence":180756650,"time":"2020-06-30T19:15:14.735120Z"}
{"type":"l2update","product_id":"BTC-USD","changes":[["buy","9120.80","2747.74540000"]],"time":"2020-06-30T19:15:15.593756Z"}
{"type":"heartbeat","last_trade_id":0,"product_id":"BTC-USD","sequence":180756653,"time":"2020-06-30T19:15:15.735128Z"}
{"type":"l2update","product_id":"BTC-USD","changes":[["sell","9156.00","0.00000000"]],"time":"2020-06-30T19:15:16.039775Z"}
{"type":"l2update","product_id":"BTC-USD","changes":[["sell","9159.39","0.00000000"]],"time":"2020-06-30T19:15:16.041118Z"}
{"type":"l2update","product_id":"BTC-USD","changes":[["buy","9111.44","0.00360000"]],"time":"2020-06-30T19:15:16.139417Z"}
{"type":"l2update","product_id":"BTC-USD","changes":[["buy","9120.80","2747.68490000"]],"time":"2020-06-30T19:15:16.418742Z"}
{"type":"l2update","product_id":"BTC-USD","changes":[["buy","9120.80","2747.61240000"]],"time":"2020-06-30T19:15:16.723743Z"}
{"type":"heartbeat","last_trade_id":0,"product_id":"BTC-USD","sequence":180756663,"time":"2020-06-30T19:15:16.735118Z"}
{"type":"l2update","product_id":"BTC-USD","changes":[["buy","9111.44","0.00000000"]],"time":"2020-06-30T19:15:17.438363Z"}
{"type":"l2update","product_id":"BTC-USD","changes":[["sell","9158.79","0.00000000"]],"time":"2020-06-30T19:15:17.691832Z"}
{"type":"l2update","product_id":"BTC-USD","changes":[["sell","9157.04","0.00000000"]],"time":"2020-06-30T19:15:17.704147Z"}
{"type":"heartbeat","last_trade_id":0,"product_id":"BTC-USD","sequence":180756666,"time":"2020-06-30T19:15:17.735095Z"}
{"type":"l2update","product_id":"BTC-USD","changes":[["buy","9085.88","0.50000000"]],"time":"2020-06-30T19:15:18.101437Z"}
{"type":"l2update","product_id":"BTC-USD","changes":[["buy","9110.96","0.03400000"]],"time":"2020-06-30T19:15:18.385962Z"}
{"type":"l2update","product_id":"BTC-USD","changes":[["buy","9077.42","0.00000000"]],"time":"2020-06-30T19:15:18.565254Z"}
{"type":"l2update","product_id":"BTC-USD","changes":[["buy","9103.26","0.04900000"]],"time":"2020-06-30T19:15:18.661278Z"}
{"type":"heartbeat","last_trade_id":0,"product_id":"BTC-USD","sequence":180756673,"time":"2020-06-30T19:15:18.735118Z"}
{"type":"l2update","product_id":"BTC-USD","changes":[["buy","9111.59","0.00000000"]],"time":"2020-06-30T19:15:18.810221Z"}
{"type":"l2update","product_id":"BTC-USD","changes":[["sell","9155.78","0.03290000"]],"time":"2020-06-30T19:15:18.924855Z"}
{"type":"l2update","product_id":"BTC-USD","changes":[["buy","9103.65","0.00000000"]],"time":"2020-06-30T19:15:19.087499Z"}
{"type":"l2update","product_id":"BTC-USD","changes":[["buy","9085.88","0.00000000"]],"time":"2020-06-30T19:15:19.100069Z"}
{"type":"l2update","product_id":"BTC-USD","changes":[["sell","9157.80","0.00000000"]],"time":"2020-06-30T19:15:19.393421Z"}
{"type":"l2update","product_id":"BTC-USD","changes":[["buy","9120.80","2747.54660000"]],"time":"2020-06-30T19:15:19.480345Z"}
{"type":"heartbeat","last_trade_id":0,"product_id":"BTC-USD","sequence":180756682,"time":"2020-06-30T19:15:19.735125Z"}
{"type":"l2update","product_id":"BTC-USD","changes":[["buy","9112.07","0.06480000"]],"time":"2020-06-30T19:15:19.752544Z"}
{"type":"l2update","product_id":"BTC-USD","changes":[["buy","9112.07","0.01480000"]],"time":"2020-06-30T19:15:20.176536Z"}
{"type":"l2update","product_id":"BTC-USD","changes":[["buy","9120.80","2747.48550000"]],"time":"2020-06-30T19:15:20.300074Z"}
{"type":"heartbeat","last_trade_id":0,"product_id":"BTC-USD","sequence":180756688,"time":"2020-06-30T19:15:20.735119Z"}
{"type":"l2update","product_id":"BTC-USD","changes":[["buy","9112.13","0.06390000"]],"time":"2020-06-30T19:15:20.850350Z"}
{"type":"l2update","product_id":"BTC-USD","changes":[["buy","9120.80","2747.43550000"]],"time":"2020-06-30T19:15:21.682395Z"}
{"type":"heartbeat","last_trade_id":0,"product_id":"BTC-USD","sequence":180756693,"time":"2020-06-30T19:15:21.735112Z"}
{"type":"l2update","product_id":"BTC-USD","changes":[["buy","9111.51","0.00120000"]],"time":"2020-06-30T19:15:21.939246Z"}
{"type":"l2update","product_id":"BTC-USD","changes":[["buy","2.00","100.39000000"]],"time":"2020-06-30T19:15:22.507603Z"}
{"type":"l2update","product_id":"BTC-USD","changes":[["buy","9111.57","0.00000000"]],"time":"2020-06-30T19:15:22.699207Z"}
{"type":"heartbeat","last_trade_id":0,"product_id":"BTC-USD","sequence":180756698,"time":"2020-06-30T19:15:22.735121Z"}
{"type":"heartbeat","last_trade_id":0,"product_id":"BTC-USD","sequence":180756698,"time":"2020-06-30T19:15:23.735120Z"}
{"type":"l2update","product_id":"BTC-USD","changes":[["sell","9157.98","0.02780000"]],"time":"2020-06-30T19:15:24.253966Z"}
{"type":"l2update","product_id":"BTC-USD","changes":[["sell","9157.41","0.05950000"]],"time":"2020-06-30T19:15:24.527558Z"}
{"type":"heartbeat","last_trade_id":0,"product_id":"BTC-USD","sequence":180756702,"time":"2020-06-30T19:15:24.735118Z"}
{"type":"l2update","product_id":"BTC-USD","changes":[["buy","9109.32","0.04000000"]],"time":"2020-06-30T19:15:24.818743Z"}
{"type":"l2update","product_id":"BTC-USD","changes":[["sell","9156.73","0.01450000"]],"time":"2020-06-30T19:15:25.124825Z"}
{"type":"l2update","product_id":"BTC-USD","changes":[["buy","9094.89","0.00000000"]],"time":"2020-06-30T19:15:25.261861Z"}
{"type":"heartbeat","last_trade_id":0,"product_id":"BTC-USD","sequence":180756707,"time":"2020-06-30T19:15:25.735121Z"}
{"type":"l2update","product_id":"BTC-USD","changes":[["buy","9103.29","0.04900000"]],"time":"2020-06-30T19:15:26.285237Z"}
{"type":"l2update","product_id":"BTC-USD","changes":[["buy","2.00","100.50000000"]],"time":"2020-06-30T19:15:26.444445Z"}
{"type":"l2update","product_id":"BTC-USD","changes":[["buy","9091.10","0.01000000"]],"time":"2020-06-30T19:15:26.563602Z"}
{"type":"heartbeat","last_trade_id":0,"product_id":"BTC-USD","sequence":180756713,"time":"2020-06-30T19:15:26.735117Z"}
{"type":"l2update","product_id":"BTC-USD","changes":[["buy","9076.11","0.00000000"]],"time":"2020-06-30T19:15:26.755755Z"}
{"type":"l2update","product_id":"BTC-USD","changes":[["buy","9098.61","0.02230000"]],"time":"2020-06-30T19:15:26.831374Z"}
{"type":"l2update","product_id":"BTC-USD","changes":[["buy","9103.29","0.00000000"]],"time":"2020-06-30T19:15:27.000050Z"}
{"type":"l2update","product_id":"BTC-USD","changes":[["buy","9111.51","0.00000000"]],"time":"2020-06-30T19:15:27.005072Z"}
{"type":"l2update","product_id":"BTC-USD","changes":[["buy","9099.18","0.00000000"]],"time":"2020-06-30T19:15:27.006146Z"}
{"type":"l2update","product_id":"BTC-USD","changes":[["buy","9120.80","2745.24850000"]],"time":"2020-06-30T19:15:27.103091Z"}
{"type":"l2update","product_id":"BTC-USD","changes":[["sell","9143.47","0.92400000"]],"time":"2020-06-30T19:15:27.403337Z"}
{"type":"heartbeat","last_trade_id":0,"product_id":"BTC-USD","sequence":180756724,"time":"2020-06-30T19:15:27.735117Z"}
{"type":"l2update","product_id":"BTC-USD","changes":[["sell","9157.98","0.00000000"]],"time":"2020-06-30T19:15:27.838335Z"}
{"type":"l2update","product_id":"BTC-USD","changes":[["sell","9156.73","0.00000000"]],"time":"2020-06-30T19:15:27.844020Z"}
{"type":"l2update","product_id":"BTC-USD","changes":[["buy","9120.80","2744.97890000"]],"time":"2020-06-30T19:15:27.961350Z"}
{"type":"l2update","product_id":"BTC-USD","changes":[["sell","9129.81","0.50000000"]],"time":"2020-06-30T19:15:28.234579Z"}
{"type":"l2update","product_id":"BTC-USD","changes":[["sell","9157.41","0.00000000"]],"time":"2020-06-30T19:15:28.655323Z"}
{"type":"heartbeat","last_trade_id":0,"product_id":"BTC-USD","sequence":180756732,"time":"2020-06-30T19:15:28.735113Z"}
{"type":"l2update","product_id":"BTC-USD","changes":[["buy","100.00","114.95500000"]],"time":"2020-06-30T19:15:29.027459Z"}
{"type":"l2update","product_id":"BTC-USD","changes":[["buy","100.00","114.94500000"]],"time":"2020-06-30T19:15:29.033680Z"}
{"type":"l2update","product_id":"BTC-USD","changes":[["buy","9111.58","0.03190000"]],"time":"2020-06-30T19:15:29.075605Z"}
{"type":"l2update","product_id":"BTC-USD","changes":[["buy","9078.78","0.00000000"]],"time":"2020-06-30T19:15:29.270334Z"}
{"type":"l2update","product_id":"BTC-USD","changes":[["sell","9158.44","0.00000000"]],"time":"2020-06-30T19:15:29.273979Z"}
{"type":"l2update","product_id":"BTC-USD","changes":[["buy","9120.80","2741.36960000"]],"time":"2020-06-30T19:15:29.652437Z"}
{"type":"heartbeat","last_trade_id":0,"product_id":"BTC-USD","sequence":180756742,"time":"2020-06-30T19:15:29.735108Z"}
{"type":"l2update","product_id":"BTC-USD","changes":[["buy","9085.45","0.05900000"]],"time":"2020-06-30T19:15:29.934102Z"}
{"type":"l2update","product_id":"BTC-USD","changes":[["sell","9143.47","0.00000000"]],"time":"2020-06-30T19:15:30.107666Z"}
{"type":"l2update","product_id":"BTC-USD","changes":[["buy","9120.80","2740.46960000"]],"time":"2020-06-30T19:15:30.214975Z"}
{"type":"l2update","product_id":"BTC-USD","changes":[["buy","9103.26","0.00000000"]],"time":"2020-06-30T19:15:30.360833Z"}
{"type":"l2update","product_id":"BTC-USD","changes":[["sell","9221.63","0.00200000"]],"time":"2020-06-30T19:15:30.512144Z"}
{"type":"heartbeat","last_trade_id":0,"product_id":"BTC-USD","sequence":180756751,"time":"2020-06-30T19:15:30.735116Z"}
{"type":"l2update","product_id":"BTC-USD","changes":[["buy","2.00","100.66000000"]],"time":"2020-06-30T19:15:30.924613Z"}
{"type":"l2update","product_id":"BTC-USD","changes":[["buy","9103.26","0.04900000"]],"time":"2020-06-30T19:15:31.055808Z"}
{"type":"l2update","product_id":"BTC-USD","changes":[["buy","9103.34","0.02230000"]],"time":"2020-06-30T19:15:31.336562Z"}
{"type":"heartbeat","last_trade_id":0,"product_id":"BTC-USD","sequence":180756757,"time":"2020-06-30T19:15:31.735109Z"}
{"type":"l2update","product_id":"BTC-USD","changes":[["sell","9157.24","0.03290000"]],"time":"2020-06-30T19:15:31.816078Z"}
{"type":"l2update","product_id":"BTC-USD","changes":[["buy","9103.70","0.00000000"]],"time":"2020-06-30T19:15:31.822258Z"}
{"type":"heartbeat","last_trade_id":0,"product_id":"BTC-USD","sequence":180756760,"time":"2020-06-30T19:15:32.735109Z"}
{"type":"l2update","product_id":"BTC-USD","changes":[["buy","9111.57","0.09970000"]],"time":"2020-06-30T19:15:32.784359Z"}
{"type":"heartbeat","last_trade_id":0,"product_id":"BTC-USD","sequence":180756762,"time":"2020-06-30T19:15:33.735118Z"}
{"type":"l2update","product_id":"BTC-USD","changes":[["sell","9142.18","1.06520000"]],"time":"2020-06-30T19:15:33.877701Z"}
{"type":"l2update","product_id":"BTC-USD","changes":[["buy","9120.80","2740.40380000"]],"time":"2020-06-30T19:15:34.487217Z"}
{"type":"heartbeat","last_trade_id":0,"product_id":"BTC-USD","sequence":180756767,"time":"2020-06-30T19:15:34.735113Z"}
{"type":"l2update","product_id":"BTC-USD","changes":[["sell","9158.30","0.03330000"]],"time":"2020-06-30T19:15:35.313842Z"}
{"type":"l2update","product_id":"BTC-USD","changes":[["buy","2.00","100.95000000"]],"time":"2020-06-30T19:15:35.348494Z"}
{"type":"heartbeat","last_trade_id":0,"product_id":"BTC-USD","sequence":180756771,"time":"2020-06-30T19:15:35.735112Z"}
{"type":"l2update","product_id":"BTC-USD","changes":[["buy","9120.80","2740.33800000"]],"time":"2020-06-30T19:15:35.865733Z"}
{"type":"l2update","product_id":"BTC-USD","changes":[["buy","9120.80","2740.27220000"]],"time":"2020-06-30T19:15:36.153789Z"}
{"type":"l2update","product_id":"BTC-USD","changes":[["buy","9120.80","2739.37220000"]],"time":"2020-06-30T19:15:36.710476Z"}
{"type":"heartbeat","last_trade_id":0,"product_id":"BTC-USD","sequence":180756780,"time":"2020-06-30T19:15:36.735115Z"}
{"type":"l2update","product_id":"BTC-USD","changes":[["buy","9120.80","2738.82420000"]],"time":"2020-06-30T19:15:36.989905Z"}
{"type":"l2update","product_id":"BTC-USD","changes":[["sell","9129.81","0.00000000"]],"time":"2020-06-30T19:15:37.409623Z"}
{"type":"l2update","product_id":"BTC-USD","changes":[["buy","9112.04","0.81530000"]],"time":"2020-06-30T19:15:37.569652Z"}
{"type":"heartbeat","last_trade_id":0,"product_id":"BTC-USD","sequence":180756786,"time":"2020-06-30T19:15:37.735114Z"}
{"type":"l2update","product_id":"BTC-USD","changes":[["buy","9120.80","2738.75840000"]],"time":"2020-06-30T19:15:37.840625Z"}
{"type":"l2update","product_id":"BTC-USD","changes":[["buy","9091.02","0.00000000"]],"time":"2020-06-30T19:15:38.041459Z"}
{"type":"l2update","product_id":"BTC-USD","changes":[["sell","9175.20","0.10000000"]],"time":"2020-06-30T19:15:38.105816Z"}
{"type":"heartbeat","last_trade_id":0,"product_id":"BTC-USD","sequence":180756792,"time":"2020-06-30T19:15:38.735114Z"}
{"type":"l2update","product_id":"BTC-USD","changes":[["buy","9088.71","3.06000000"]],"time":"2020-06-30T19:15:39.224837Z"}
{"type":"l2update","product_id":"BTC-USD","changes":[["buy","9103.61","0.00000000"]],"time":"2020-06-30T19:15:39.659421Z"}
{"type":"l2update","product_id":"BTC-USD","changes":[["buy","9112.04","0.00000000"]],"time":"2020-06-30T19:15:39.675055Z"}
{"type":"heartbeat","last_trade_id":0,"product_id":"BTC-USD","sequence":180756796,"time":"2020-06-30T19:15:39.735123Z"}
{"type":"l2update","product_id":"BTC-USD","changes":[["buy","2.00","101.24000000"]],"time":"2020-06-30T19:15:39.808463Z"}
{"type":"l2update","product_id":"BTC-USD","changes":[["buy","9120.80","2732.79780000"]],"time":"2020-06-30T19:15:40.313111Z"}
{"type":"l2update","product_id":"BTC-USD","changes":[["sell","9120.82","3006.39200000"]],"time":"2020-06-30T19:15:40.669906Z"}
{"type":"heartbeat","last_trade_id":0,"product_id":"BTC-USD","sequence":180756804,"time":"2020-06-30T19:15:40.735127Z"}
{"type":"l2update","product_id":"BTC-USD","changes":[["buy","9099.10","0.82800000"]],"time":"2020-06-30T19:15:41.488222Z"}
{"type":"heartbeat","last_trade_id":0,"product_id":"BTC-USD","sequence":180756806,"time":"2020-06-30T19:15:41.735128Z"}
{"type":"l2update","product_id":"BTC-USD","changes":[["buy","9091.10","0.00000000"]],"time":"2020-06-30T19:15:41.938154Z"}
{"type":"l2update","product_id":"BTC-USD","changes":[["buy","9112.07","0.00000000"]],"time":"2020-06-30T19:15:41.939446Z"}
{"type":"l2update","product_id":"BTC-USD","changes":[["sell","9156.37","0.06900000"]],"time":"2020-06-30T19:15:42.093057Z"}
{"type":"l2update","product_id":"BTC-USD","changes":[["buy","9111.07","0.00120000"]],"time":"2020-06-30T19:15:42.397733Z"}
{"type":"l2update","product_id":"BTC-USD","changes":[["buy","9109.32","0.00000000"]],"time":"2020-06-30T19:15:42.580454Z"}
{"type":"l2update","product_id":"BTC-USD","changes":[["buy","9111.57","0.00000000"]],"time":"2020-06-30T19:15:42.582783Z"}
{"type":"l2update","product_id":"BTC-USD","changes":[["buy","9112.13","0.00000000"]],"time":"2020-06-30T19:15:42.585367Z"}
{"type":"l2update","product_id":"BTC-USD","changes":[["buy","9109.00","17.54700000"]],"time":"2020-06-30T19:15:42.672426Z"}
{"type":"heartbeat","last_trade_id":0,"product_id":"BTC-USD","sequence":180756817,"time":"2020-06-30T19:15:42.735123Z"}
{"type":"l2update","product_id":"BTC-USD","changes":[["buy","9088.71","0.00000000"]],"time":"2020-06-30T19:15:43.140807Z"}
{"type":"l2update","product_id":"BTC-USD","changes":[["buy","9103.30","0.02230000"]],"time":"2020-06-30T19:15:43.542578Z"}
{"type":"heartbeat","last_trade_id":0,"product_id":"BTC-USD","sequence":180756820,"time":"2020-06-30T19:15:43.735124Z"}
{"type":"l2update","product_id":"BTC-USD","changes":[["buy","100.00","114.95500000"]],"time":"2020-06-30T19:15:44.040765Z"}
{"type":"l2update","product_id":"BTC-USD","changes":[["buy","100.00","114.94500000"]],"time":"2020-06-30T19:15:44.047521Z"}
{"type":"l2update","product_id":"BTC-USD","changes":[["buy","9120.80","2732.74780000"]],"time":"2020-06-30T19:15:44.088935Z"}
{"type":"l2update","product_id":"BTC-USD","changes":[["sell","9155.32","0.03290000"]],"time":"2020-06-30T19:15:44.370422Z"}
{"type":"l2update","product_id":"BTC-USD","changes":[["sell","9157.24","0.00000000"]],"time":"2020-06-30T19:15:44.527579Z"}
{"type":"l2update","product_id":"BTC-USD","changes":[["sell","9221.63","0.00000000"]],"time":"2020-06-30T19:15:44.548406Z"}
{"type":"l2update","product_id":"BTC-USD","changes":[["buy","9120.80","2732.68190000"]],"time":"2020-06-30T19:15:44.655195Z"}
{"type":"heartbeat","last_trade_id":0,"product_id":"BTC-USD","sequence":180756833,"time":"2020-06-30T19:15:44.735021Z"}
{"type":"l2update","product_id":"BTC-USD","changes":[["sell","9154.89","0.06900000"]],"time":"2020-06-30T19:15:44.933939Z"}
{"type":"l2update","product_id":"BTC-USD","changes":[["sell","9158.30","0.00000000"]],"time":"2020-06-30T19:15:45.070281Z"}
{"type":"l2update","product_id":"BTC-USD","changes":[["buy","9103.28","0.02230000"]],"time":"2020-06-30T19:15:45.209549Z"}
{"type":"l2update","product_id":"BTC-USD","changes":[["buy","9120.80","2732.63190000"]],"time":"2020-06-30T19:15:45.475733Z"}
{"type":"l2update","product_id":"BTC-USD","changes":[["buy","9111.58","0.00000000"]],"time":"2020-06-30T19:15:45.652973Z"}
{"type":"l2update","product_id":"BTC-USD","changes":[["buy","9099.10","0.00000000"]],"time":"2020-06-30T19:15:45.659009Z"}
{"type":"heartbeat","last_trade_id":0,"product_id":"BTC-USD","sequence":180756843,"time":"2020-06-30T19:15:45.735109Z"}
{"type":"l2update","product_id":"BTC-USD","changes":[["buy","2.00","101.58000000"]],"time":"2020-06-30T19:15:46.012855Z"}
{"type":"l2update","product_id":"BTC-USD","changes":[["buy","9120.80","2732.58190000"]],"time":"2020-06-30T19:15:46.320454Z"}
{"type":"l2update","product_id":"BTC-USD","changes":[["buy","9120.80","2732.51600000"]],"time":"2020-06-30T19:15:46.592278Z"}
{"type":"heartbeat","last_trade_id":0,"product_id":"BTC-USD","sequence":180756851,"time":"2020-06-30T19:15:46.735112Z"}
{"type":"l2update","product_id":"BTC-USD","changes":[["buy","9120.80","2732.45010000"]],"time":"2020-06-30T19:15:46.873307Z"}
{"type":"l2update","product_id":"BTC-USD","changes":[["buy","9098.61","0.04460000"]],"time":"2020-06-30T19:15:47.134541Z"}
{"type":"l2update","product_id":"BTC-USD","changes":[["buy","9110.69","0.00000000"]],"time":"2020-06-30T19:15:47.563303Z"}
{"type":"l2update","product_id":"BTC-USD","changes":[["buy","9120.80","2732.40010000"]],"time":"2020-06-30T19:15:47.695684Z"}
{"type":"heartbeat","last_trade_id":0,"product_id":"BTC-USD","sequence":180756860,"time":"2020-06-30T19:15:47.735121Z"}
{"type":"l2update","product_id":"BTC-USD","changes":[["buy","9120.80","2732.33420000"]],"time":"2020-06-30T19:15:48.002855Z"}
{"type":"heartbeat","last_trade_id":0,"product_id":"BTC-USD","sequence":180756863,"time":"2020-06-30T19:15:48.735111Z"}
{"type":"l2update","product_id":"BTC-USD","changes":[["buy","9120.80","2732.26830000"]],"time":"2020-06-30T19:15:48.833975Z"}
{"type":"l2update","product_id":"BTC-USD","changes":[["buy","9103.26","0.07130000"]],"time":"2020-06-30T19:15:49.106623Z"}
{"type":"heartbeat","last_trade_id":0,"product_id":"BTC-USD","sequence":180756868,"time":"2020-06-30T19:15:49.735115Z"}
{"type":"l2update","product_id":"BTC-USD","changes":[["buy","9120.80","2732.20240000"]],"time":"2020-06-30T19:15:49.930385Z"}
{"type":"l2update","product_id":"BTC-USD","changes":[["buy","2.00","101.94000000"]],"time":"2020-06-30T19:15:50.436219Z"}
{"type":"l2update","product_id":"BTC-USD","changes":[["buy","9120.80","2732.13650000"]],"time":"2020-06-30T19:15:50.522385Z"}
{"type":"heartbeat","last_trade_id":0,"product_id":"BTC-USD","sequence":180756876,"time":"2020-06-30T19:15:50.735121Z"}
{"type":"l2update","product_id":"BTC-USD","changes":[["buy","9111.05","0.54300000"]],"time":"2020-06-30T19:15:51.605988Z"}
{"type":"heartbeat","last_trade_id":0,"product_id":"BTC-USD","sequence":180756878,"time":"2020-06-30T19:15:51.735067Z"}
{"type":"l2update","product_id":"BTC-USD","changes":[["buy","9098.61","0.02230000"]],"time":"2020-06-30T19:15:51.804021Z"}
{"type":"l2update","product_id":"BTC-USD","changes":[["buy","9103.28","0.00000000"]],"time":"2020-06-30T19:15:51.811375Z"}
{"type":"l2update","product_id":"BTC-USD","changes":[["buy","9120.80","2731.84490000"]],"time":"2020-06-30T19:15:51.896456Z"}
{"type":"l2update","product_id":"BTC-USD","changes":[["buy","9111.35","0.16460000"]],"time":"2020-06-30T19:15:52.234090Z"}
{"type":"heartbeat","last_trade_id":0,"product_id":"BTC-USD","sequence":180756885,"time":"2020-06-30T19:15:52.735092Z"}
{"type":"l2update","product_id":"BTC-USD","changes":[["buy","9120.80","2731.77900000"]],"time":"2020-06-30T19:15:52.764594Z"}
{"type":"l2update","product_id":"BTC-USD","changes":[["sell","9175.20","0.00000000"]],"time":"2020-06-30T19:15:53.189504Z"}
{"type":"l2update","product_id":"BTC-USD","changes":[["sell","9142.18","0.00000000"]],"time":"2020-06-30T19:15:53.192559Z"}
{"type":"l2update","product_id":"BTC-USD","changes":[["buy","9120.80","2731.71310000"]],"time":"2020-06-30T19:15:53.612074Z"}
{"type":"heartbeat","last_trade_id":0,"product_id":"BTC-USD","sequence":180756893,"time":"2020-06-30T19:15:53.735116Z"}
{"type":"l2update","product_id":"BTC-USD","changes":[["sell","9154.89","0.00000000"]],"time":"2020-06-30T19:15:54.063626Z"}
{"type":"l2update","product_id":"BTC-USD","changes":[["sell","9157.05","0.06900000"]],"time":"2020-06-30T19:15:54.205961Z"}
{"type":"l2update","product_id":"BTC-USD","changes":[["sell","9155.93","0.03690000"]],"time":"2020-06-30T19:15:54.741847Z"}
{"type":"heartbeat","last_trade_id":0,"product_id":"BTC-USD","sequence":180756898,"time":"2020-06-30T19:15:54.735122Z"}
{"type":"l2update","product_id":"BTC-USD","changes":[["buy","2.00","102.05000000"]],"time":"2020-06-30T19:15:54.954452Z"}
{"type":"heartbeat","last_trade_id":0,"product_id":"BTC-USD","sequence":180756900,"time":"2020-06-30T19:15:55.735110Z"}
{"type":"heartbeat","last_trade_id":0,"product_id":"BTC-USD","sequence":180756900,"time":"2020-06-30T19:15:56.735115Z"}
{"type":"l2update","product_id":"BTC-USD","changes":[["buy","9120.80","2731.66310000"]],"time":"2020-06-30T19:15:56.951827Z"}
{"type":"l2update","product_id":"BTC-USD","changes":[["buy","9120.80","2730.76310000"]],"time":"2020-06-30T19:15:57.234379Z"}
{"type":"heartbeat","last_trade_id":0,"product_id":"BTC-USD","sequence":180756906,"time":"2020-06-30T19:15:57.735114Z"}
{"type":"l2update","product_id":"BTC-USD","changes":[["buy","9078.68","0.02300000"]],"time":"2020-06-30T19:15:57.817241Z"}
{"type":"l2update","product_id":"BTC-USD","changes":[["buy","9120.80","2730.56310000"]],"time":"2020-06-30T19:15:58.092911Z"}
{"type":"l2update","product_id":"BTC-USD","changes":[["buy","9111.07","0.00000000"]],"time":"2020-06-30T19:15:58.252500Z"}
{"type":"l2update","product_id":"BTC-USD","changes":[["sell","9155.23","0.06900000"]],"time":"2020-06-30T19:15:58.372032Z"}
{"type":"l2update","product_id":"BTC-USD","changes":[["sell","9155.93","0.00000000"]],"time":"2020-06-30T19:15:58.532421Z"}
{"type":"l2update","product_id":"BTC-USD","changes":[["buy","9079.28","0.07370000"]],"time":"2020-06-30T19:15:58.655472Z"}
{"type":"heartbeat","last_trade_id":0,"product_id":"BTC-USD","sequence":180756917,"time":"2020-06-30T19:15:58.735112Z"}
{"type":"l2update","product_id":"BTC-USD","changes":[["buy","8892.39","0.00000000"]],"time":"2020-06-30T19:15:58.850259Z"}
{"type":"l2update","product_id":"BTC-USD","changes":[["buy","100.00","114.95500000"]],"time":"2020-06-30T19:15:59.034977Z"}
{"type":"l2update","product_id":"BTC-USD","changes":[["buy","100.00","114.94500000"]],"time":"2020-06-30T19:15:59.042462Z"}
{"type":"l2update","product_id":"BTC-USD","changes":[["buy","8891.62","0.04673688"]],"time":"2020-06-30T19:15:59.092569Z"}
{"type":"l2update","product_id":"BTC-USD","changes":[["buy","9120.80","2730.49720000"]],"time":"2020-06-30T19:15:59.232836Z"}
{"type":"l2update","product_id":"BTC-USD","changes":[["buy","2.00","102.09000000"]],"time":"2020-06-30T19:15:59.312606Z"}
{"type":"l2update","product_id":"BTC-USD","changes":[["sell","9438.66","0.00000000"]],"time":"2020-06-30T19:15:59.355105Z"}
{"type":"l2update","product_id":"BTC-USD","changes":[["sell","9439.48","0.00747675"]],"time":"2020-06-30T19:15:59.539486Z"}
{"type":"heartbeat","last_trade_id":0,"product_id":"BTC-USD","sequence":180756931,"time":"2020-06-30T19:15:59.735112Z"}
{"type":"heartbeat","last_trade_id":0,"product_id":"BTC-USD","sequence":180756931,"time":"2020-06-30T19:16:00.735100Z"}
{"type":"l2update","product_id":"BTC-USD","changes":[["buy","9103.29","0.04900000"]],"time":"2020-06-30T19:16:01.265149Z"}
{"type":"l2update","product_id":"BTC-USD","changes":[["buy","9103.31","0.04900000"]],"time":"2020-06-30T19:16:01.553075Z"}
{"type":"l2update","product_id":"BTC-USD","changes":[["buy","9109.00","0.00000000"]],"time":"2020-06-30T19:16:01.729886Z"}
{"type":"heartbeat","last_trade_id":0,"product_id":"BTC-USD","sequence":180756936,"time":"2020-06-30T19:16:01.735099Z"}
{"type":"l2update","product_id":"BTC-USD","changes":[["buy","9111.05","0.00000000"]],"time":"2020-06-30T19:16:01.749009Z"}
{"type":"l2update","product_id":"BTC-USD","changes":[["buy","9111.98","0.00000000"]],"time":"2020-06-30T19:16:01.991098Z"}
{"type":"heartbeat","last_trade_id":0,"product_id":"BTC-USD","sequence":180756938,"time":"2020-06-30T19:16:02.735114Z"}
{"type":"l2update","product_id":"BTC-USD","changes":[["buy","9110.16","0.04180000"]],"time":"2020-06-30T19:16:02.929664Z"}
{"type":"l2update","product_id":"BTC-USD","changes":[["buy","9103.29","0.00000000"]],"time":"2020-06-30T19:16:03.340044Z"}
{"type":"l2update","product_id":"BTC-USD","changes":[["buy","9111.35","0.00000000"]],"time":"2020-06-30T19:16:03.359862Z"}
{"type":"l2update","product_id":"BTC-USD","changes":[["buy","9111.57","8.09470000"]],"time":"2020-06-30T19:16:03.514241Z"}
{"type":"heartbeat","last_trade_id":0,"product_id":"BTC-USD","sequence":180756944,"time":"2020-06-30T19:16:03.735116Z"}
{"type":"l2update","product_id":"BTC-USD","changes":[["buy","2.00","102.16000000"]],"time":"2020-06-30T19:16:03.883135Z"}
{"type":"l2update","product_id":"BTC-USD","changes":[["buy","9120.80","2730.34720000"]],"time":"2020-06-30T19:16:04.063756Z"}
{"type":"l2update","product_id":"BTC-USD","changes":[["buy","9120.80","2726.93450000"]],"time":"2020-06-30T19:16:04.408857Z"}
{"type":"l2update","product_id":"BTC-USD","changes":[["sell","9170.37","0.00100000"]],"time":"2020-06-30T19:16:04.686281Z"}
{"type":"heartbeat","last_trade_id":0,"product_id":"BTC-USD","sequence":180756954,"time":"2020-06-30T19:16:04.735117Z"}
{"type":"l2update","product_id":"BTC-USD","changes":[["sell","9155.78","0.00000000"]],"time":"2020-06-30T19:16:04.803327Z"}
{"type":"l2update","product_id":"BTC-USD","changes":[["sell","9291.19","0.00300000"]],"time":"2020-06-30T19:16:04.970825Z"}
{"type":"l2update","product_id":"BTC-USD","changes":[["buy","9087.97","0.02830000"]],"time":"2020-06-30T19:16:05.253049Z"}
{"type":"l2update","product_id":"BTC-USD","changes":[["sell","9170.37","0.00000000"]],"time":"2020-06-30T19:16:05.431364Z"}
{"type":"l2update","product_id":"BTC-USD","changes":[["buy","9103.34","0.00000000"]],"time":"2020-06-30T19:16:05.495556Z"}
{"type":"l2update","product_id":"BTC-USD","changes":[["buy","9110.16","0.00000000"]],"time":"2020-06-30T19:16:05.518680Z"}
{"type":"heartbeat","last_trade_id":0,"product_id":"BTC-USD","sequence":180756962,"time":"2020-06-30T19:16:05.735131Z"}
{"type":"l2update","product_id":"BTC-USD","changes":[["buy","9090.02","0.36870000"]],"time":"2020-06-30T19:16:05.836564Z"}
{"type":"l2update","product_id":"BTC-USD","changes":[["buy","9079.28","0.00000000"]],"time":"2020-06-30T19:16:06.034056Z"}
{"type":"l2update","product_id":"BTC-USD","changes":[["buy","9110.96","0.00000000"]],"time":"2020-06-30T19:16:06.039867Z"}
{"type":"l2update","product_id":"BTC-USD","changes":[["buy","9103.38","0.04900000"]],"time":"2020-06-30T19:16:06.381068Z"}
{"type":"heartbeat","last_trade_id":0,"product_id":"BTC-USD","sequence":180756968,"time":"2020-06-30T19:16:06.735123Z"}
{"type":"l2update","product_id":"BTC-USD","changes":[["buy","9120.80","2726.04660000"]],"time":"2020-06-30T19:16:07.246973Z"}
{"type":"l2update","product_id":"BTC-USD","changes":[["buy","9120.80","2725.99660000"]],"time":"2020-06-30T19:16:07.497250Z"}
{"type":"heartbeat","last_trade_id":0,"product_id":"BTC-USD","sequence":180756974,"time":"2020-06-30T19:16:07.735134Z"}
{"type":"l2update","product_id":"BTC-USD","changes":[["buy","2.00","102.53000000"]],"time":"2020-06-30T19:16:08.069747Z"}
{"type":"l2update","product_id":"BTC-USD","changes":[["buy","9086.59","0.01000000"]],"time":"2020-06-30T19:16:08.358652Z"}
{"type":"heartbeat","last_trade_id":0,"product_id":"BTC-USD","sequence":180756978,"time":"2020-06-30T19:16:08.735122Z"}
{"type":"l2update","product_id":"BTC-USD","changes":[["buy","9103.31","0.00000000"]],"time":"2020-06-30T19:16:08.853300Z"}
{"type":"l2update","product_id":"BTC-USD","changes":[["buy","9081.93","0.07360000"]],"time":"2020-06-30T19:16:08.879558Z"}
{"type":"l2update","product_id":"BTC-USD","changes":[["buy","9120.80","2725.93070000"]],"time":"2020-06-30T19:16:09.160117Z"}
{"type":"l2update","product_id":"BTC-USD","changes":[["buy","9078.68","0.00000000"]],"time":"2020-06-30T19:16:09.329483Z"}
{"type":"l2update","product_id":"BTC-USD","changes":[["buy","9085.45","0.00000000"]],"time":"2020-06-30T19:16:09.331961Z"}
{"type":"l2update","product_id":"BTC-USD","changes":[["sell","9155.32","0.00000000"]],"time":"2020-06-30T19:16:09.352021Z"}
{"type":"l2update","product_id":"BTC-USD","changes":[["buy","9079.47","0.03100000"]],"time":"2020-06-30T19:16:09.426988Z"}
{"type":"l2update","product_id":"BTC-USD","changes":[["buy","9086.59","0.00000000"]],"time":"2020-06-30T19:16:09.632523Z"}
{"type":"heartbeat","last_trade_id":0,"product_id":"BTC-USD","sequence":180756990,"time":"2020-06-30T19:16:09.735118Z"}
{"type":"l2update","product_id":"BTC-USD","changes":[["buy","9120.80","2725.86480000"]],"time":"2020-06-30T19:16:10.024467Z"}
{"type":"l2update","product_id":"BTC-USD","changes":[["sell","9154.70","0.03690000"]],"time":"2020-06-30T19:16:10.600278Z"}
{"type":"heartbeat","last_trade_id":0,"product_id":"BTC-USD","sequence":180756995,"time":"2020-06-30T19:16:10.735031Z"}
{"type":"l2update","product_id":"BTC-USD","changes":[["buy","9103.39","0.04900000"]],"time":"2020-06-30T19:16:10.865448Z"}
{"type":"l2update","product_id":"BTC-USD","changes":[["sell","9156.37","0.00000000"]],"time":"2020-06-30T19:16:10.990579Z"}
{"type":"l2update","product_id":"BTC-USD","changes":[["buy","9111.57","12.37370000"]],"time":"2020-06-30T19:16:11.147014Z"}
{"type":"l2update","product_id":"BTC-USD","changes":[["buy","9120.80","2725.86380000"]],"time":"2020-06-30T19:16:11.265115Z"}
{"type":"l2update","product_id":"BTC-USD","changes":[["buy","9103.26","0.02230000"]],"time":"2020-06-30T19:16:11.289535Z"}
{"type":"l2update","product_id":"BTC-USD","changes":[["buy","9079.47","0.00000000"]],"time":"2020-06-30T19:16:11.305629Z"}
{"type":"l2update","product_id":"BTC-USD","changes":[["buy","9103.39","0.00000000"]],"time":"2020-06-30T19:16:11.559160Z"}
{"type":"l2update","product_id":"BTC-USD","changes":[["buy","9103.30","0.00000000"]],"time":"2020-06-30T19:16:11.564164Z"}
{"type":"heartbeat","last_trade_id":0,"product_id":"BTC-USD","sequence":180757007,"time":"2020-06-30T19:16:11.735173Z"}
{"type":"l2update","product_id":"BTC-USD","changes":[["buy","9111.57","20.65270000"]],"time":"2020-06-30T19:16:12.002992Z"}
{"type":"l2update","product_id":"BTC-USD","changes":[["buy","9074.54","0.15180000"]],"time":"2020-06-30T19:16:12.271591Z"}
{"type":"l2update","product_id":"BTC-USD","changes":[["buy","9103.38","0.00000000"]],"time":"2020-06-30T19:16:12.434610Z"}
{"type":"l2update","product_id":"BTC-USD","changes":[["sell","9157.17","0.01490000"]],"time":"2020-06-30T19:16:12.554423Z"}
{"type":"l2update","product_id":"BTC-USD","changes":[["buy","9090.02","0.00000000"]],"time":"2020-06-30T19:16:12.729852Z"}
{"type":"heartbeat","last_trade_id":0,"product_id":"BTC-USD","sequence":180757015,"time":"2020-06-30T19:16:12.735115Z"}
{"type":"l2update","product_id":"BTC-USD","changes":[["buy","9099.98","0.02100000"]],"time":"2020-06-30T19:16:12.879010Z"}
{"type":"l2update","product_id":"BTC-USD","changes":[["buy","9103.31","0.04900000"]],"time":"2020-06-30T19:16:13.492457Z"}
{"type":"heartbeat","last_trade_id":0,"product_id":"BTC-USD","sequence":180757019,"time":"2020-06-30T19:16:13.735135Z"}
{"type":"l2update","product_id":"BTC-USD","changes":[["buy","9103.26","0.00000000"]],"time":"2020-06-30T19:16:13.934296Z"}
{"type":"l2update","product_id":"BTC-USD","changes":[["buy","100.00","114.95500000"]],"time":"2020-06-30T19:16:14.052630Z"}
{"type":"l2update","product_id":"BTC-USD","changes":[["buy","100.00","114.94500000"]],"time":"2020-06-30T19:16:14.058806Z"}
{"type":"l2update","product_id":"BTC-USD","changes":[["buy","9087.27","0.01000000"]],"time":"2020-06-30T19:16:14.295815Z"}
{"type":"heartbeat","last_trade_id":0,"product_id":"BTC-USD","sequence":180757025,"time":"2020-06-30T19:16:14.735075Z"}
{"type":"l2update","product_id":"BTC-USD","changes":[["buy","9103.39","0.04900000"]],"time":"2020-06-30T19:16:14.845571Z"}
{"type":"l2update","product_id":"BTC-USD","changes":[["sell","9154.76","0.06900000"]],"time":"2020-06-30T19:16:15.121528Z"}
{"type":"l2update","product_id":"BTC-USD","changes":[["buy","9098.61","0.00000000"]],"time":"2020-06-30T19:16:15.456046Z"}
{"type":"l2update","product_id":"BTC-USD","changes":[["sell","9291.19","0.00000000"]],"time":"2020-06-30T19:16:15.543060Z"}
{"type":"l2update","product_id":"BTC-USD","changes":[["sell","9154.70","0.00000000"]],"time":"2020-06-30T19:16:15.555219Z"}
{"type":"heartbeat","last_trade_id":0,"product_id":"BTC-USD","sequence":180757032,"time":"2020-06-30T19:16:15.735122Z"}
{"type":"l2update","product_id":"BTC-USD","changes":[["buy","9099.98","0.00000000"]],"time":"2020-06-30T19:16:16.411156Z"}
{"type":"heartbeat","last_trade_id":0,"product_id":"BTC-USD","sequence":180757033,"time":"2020-06-30T19:16:16.735110Z"}
{"type":"heartbeat","last_trade_id":0,"product_id":"BTC-USD","sequence":180757033,"time":"2020-06-30T19:16:17.735112Z"}
{"type":"l2update","product_id":"BTC-USD","changes":[["sell","9155.99","0.03290000"]],"time":"2020-06-30T19:16:17.970662Z"}
{"type":"l2update","product_id":"BTC-USD","changes":[["buy","9120.80","2725.61380000"]],"time":"2020-06-30T19:16:18.239682Z"}
{"type":"heartbeat","last_trade_id":0,"product_id":"BTC-USD","sequence":180757038,"time":"2020-06-30T19:16:18.735113Z"}
{"type":"l2update","product_id":"BTC-USD","changes":[["sell","9155.99","0.00000000"]],"time":"2020-06-30T19:16:18.791457Z"}
{"type":"l2update","product_id":"BTC-USD","changes":[["buy","9069.56","0.03770000"]],"time":"2020-06-30T19:16:19.120704Z"}
{"type":"heartbeat","last_trade_id":0,"product_id":"BTC-USD","sequence":180757041,"time":"2020-06-30T19:16:19.735031Z"}
{"type":"l2update","product_id":"BTC-USD","changes":[["buy","9120.80","2724.59020000"]],"time":"2020-06-30T19:16:19.760000Z"}
{"type":"l2update","product_id":"BTC-USD","changes":[["sell","9154.96","0.06760000"]],"time":"2020-06-30T19:16:20.024460Z"}
{"type":"l2update","product_id":"BTC-USD","changes":[["buy","9120.80","2724.54020000"]],"time":"2020-06-30T19:16:20.307592Z"}
{"type":"heartbeat","last_trade_id":0,"product_id":"BTC-USD","sequence":180757049,"time":"2020-06-30T19:16:20.735162Z"}
{"type":"l2update","product_id":"BTC-USD","changes":[["buy","9120.80","2724.47430000"]],"time":"2020-06-30T19:16:20.881279Z"}
{"type":"l2update","product_id":"BTC-USD","changes":[["sell","9155.29","0.06760000"]],"time":"2020-06-30T19:16:21.705297Z"}
{"type":"heartbeat","last_trade_id":0,"product_id":"BTC-USD","sequence":180757054,"time":"2020-06-30T19:16:21.735110Z"}
{"type":"l2update","product_id":"BTC-USD","changes":[["sell","9151.01","0.05460000"]],"time":"2020-06-30T19:16:22.268643Z"}
{"type":"heartbeat","last_trade_id":0,"product_id":"BTC-USD","sequence":180757056,"time":"2020-06-30T19:16:22.735114Z"}
{"type":"l2update","product_id":"BTC-USD","changes":[["buy","9111.57","24.71820000"]],"time":"2020-06-30T19:16:22.826682Z"}
{"type":"l2update","product_id":"BTC-USD","changes":[["buy","9111.57","16.62350000"]],"time":"2020-06-30T19:16:23.024307Z"}
{"type":"l2update","product_id":"BTC-USD","changes":[["buy","9087.27","0.00000000"]],"time":"2020-06-30T19:16:23.024780Z"}
{"type":"l2update","product_id":"BTC-USD","changes":[["buy","9075.35","0.01050000"]],"time":"2020-06-30T19:16:23.111309Z"}
{"type":"l2update","product_id":"BTC-USD","changes":[["buy","9069.56","0.00000000"]],"time":"2020-06-30T19:16:23.549513Z"}
{"type":"l2update","product_id":"BTC-USD","changes":[["buy","9120.80","2724.42430000"]],"time":"2020-06-30T19:16:23.615846Z"}
{"type":"l2update","product_id":"BTC-USD","changes":[["buy","9120.80","2724.35840000"]],"time":"2020-06-30T19:16:23.672841Z"}
{"type":"heartbeat","last_trade_id":0,"product_id":"BTC-USD","sequence":180757069,"time":"2020-06-30T19:16:23.735111Z"}
{"type":"l2update","product_id":"BTC-USD","changes":[["buy","9120.80","2722.71640000"]],"time":"2020-06-30T19:16:24.562261Z"}
{"type":"heartbeat","last_trade_id":0,"product_id":"BTC-USD","sequence":180757072,"time":"2020-06-30T19:16:24.735117Z"}
{"type":"l2update","product_id":"BTC-USD","changes":[["sell","9154.76","0.00000000"]],"time":"2020-06-30T19:16:24.994051Z"}
{"type":"l2update","product_id":"BTC-USD","changes":[["buy","9120.80","2722.65050000"]],"time":"2020-06-30T19:16:25.178631Z"}
{"type":"l2update","product_id":"BTC-USD","changes":[["sell","9151.01","0.00000000"]],"time":"2020-06-30T19:16:25.378825Z"}
{"type":"l2update","product_id":"BTC-USD","changes":[["sell","9148.74","0.05470000"]],"time":"2020-06-30T19:16:25.461755Z"}
{"type":"heartbeat","last_trade_id":0,"product_id":"BTC-USD","sequence":180757079,"time":"2020-06-30T19:16:25.735129Z"}
{"type":"l2update","product_id":"BTC-USD","changes":[["buy","9091.83","0.01560000"]],"time":"2020-06-30T19:16:26.299402Z"}
{"type":"l2update","product_id":"BTC-USD","changes":[["buy","9120.80","2722.40050000"]],"time":"2020-06-30T19:16:26.562683Z"}
{"type":"heartbeat","last_trade_id":0,"product_id":"BTC-USD","sequence":180757084,"time":"2020-06-30T19:16:26.735121Z"}
{"type":"l2update","product_id":"BTC-USD","changes":[["sell","9121.08","0.02360000"]],"time":"2020-06-30T19:16:26.892217Z"}
{"type":"heartbeat","last_trade_id":0,"product_id":"BTC-USD","sequence":180757086,"time":"2020-06-30T19:16:27.735118Z"}
{"type":"heartbeat","last_trade_id":0,"product_id":"BTC-USD","sequence":180757086,"time":"2020-06-30T19:16:28.735120Z"}
{"type":"l2update","product_id":"BTC-USD","changes":[["buy","100.00","114.95500000"]],"time":"2020-06-30T19:16:29.070896Z"}
{"type":"l2update","product_id":"BTC-USD","changes":[["buy","100.00","114.94500000"]],"time":"2020-06-30T19:16:29.078292Z"}
{"type":"l2update","product_id":"BTC-USD","changes":[["buy","9111.57","25.03620000"]],"time":"2020-06-30T19:16:29.496882Z"}
{"type":"heartbeat","last_trade_id":0,"product_id":"BTC-USD","sequence":180757091,"time":"2020-06-30T19:16:29.735120Z"}
{"type":"heartbeat","last_trade_id":0,"product_id":"BTC-USD","sequence":180757091,"time":"2020-06-30T19:16:30.735118Z"}
{"type":"l2update","product_id":"BTC-USD","changes":[["sell","9147.22","0.05470000"]],"time":"2020-06-30T19:16:31.381350Z"}
{"type":"heartbeat","last_trade_id":0,"product_id":"BTC-USD","sequence":180757093,"time":"2020-06-30T19:16:31.735124Z"}
{"type":"l2update","product_id":"BTC-USD","changes":[["buy","9103.28","0.02230000"]],"time":"2020-06-30T19:16:32.136075Z"}
{"type":"l2update","product_id":"BTC-USD","changes":[["buy","9087.97","0.00000000"]],"time":"2020-06-30T19:16:32.542292Z"}
{"type":"l2update","product_id":"BTC-USD","changes":[["buy","9111.57","20.97070000"]],"time":"2020-06-30T19:16:32.545265Z"}
{"type":"heartbeat","last_trade_id":0,"product_id":"BTC-USD","sequence":180757097,"time":"2020-06-30T19:16:32.735120Z"}
{"type":"l2update","product_id":"BTC-USD","changes":[["buy","9077.38","0.07360000"]],"time":"2020-06-30T19:16:32.974839Z"}
{"type":"l2update","product_id":"BTC-USD","changes":[["sell","9136.31","0.02010000"]],"time":"2020-06-30T19:16:33.246197Z"}
{"type":"l2update","product_id":"BTC-USD","changes":[["buy","9111.57","12.55800000"]],"time":"2020-06-30T19:16:33.424415Z"}
{"type":"l2update","product_id":"BTC-USD","changes":[["buy","9075.27","0.01050000"]],"time":"2020-06-30T19:16:33.521205Z"}
{"type":"heartbeat","last_trade_id":0,"product_id":"BTC-USD","sequence":180757104,"time":"2020-06-30T19:16:33.735054Z"}
{"type":"l2update","product_id":"BTC-USD","changes":[["buy","9075.86","0.01050000"]],"time":"2020-06-30T19:16:33.797293Z"}
{"type":"l2update","product_id":"BTC-USD","changes":[["buy","9077.38","0.00000000"]],"time":"2020-06-30T19:16:33.995552Z"}
