{"type":"l2update","product_id":"BTC-USD","changes":[["buy","9132.15","0.75000000"]],"time":"2020-06-30T19:29:58.435340Z"}
{"type":"l2update","product_id":"BTC-USD","changes":[["sell","9195.17","0.12350000"]],"time":"2020-06-30T19:29:58.657293Z"}
{"type":"heartbeat","last_trade_id":0,"product_id":"BTC-USD","sequence":180761293,"time":"2020-06-30T19:29:58.735061Z"}
{"type":"l2update","product_id":"BTC-USD","changes":[["buy","100.00","114.95500000"]],"time":"2020-06-30T19:29:59.018846Z"}
{"type":"l2update","product_id":"BTC-USD","changes":[["buy","100.00","114.94500000"]],"time":"2020-06-30T19:29:59.026278Z"}
{"type":"l2update","product_id":"BTC-USD","changes":[["sell","9178.75","0.00000000"]],"time":"2020-06-30T19:29:59.075126Z"}
{"type":"l2update","product_id":"BTC-USD","changes":[["sell","9151.23","0.00000000"]],"time":"2020-06-30T19:29:59.080375Z"}
{"type":"l2update","product_id":"BTC-USD","changes":[["buy","9131.79","0.04000000"]],"time":"2020-06-30T19:29:59.228526Z"}
{"type":"l2update","product_id":"BTC-USD","changes":[["sell","9193.25","0.02770000"]],"time":"2020-06-30T19:29:59.505291Z"}
{"type":"heartbeat","last_trade_id":0,"product_id":"BTC-USD","sequence":180761302,"time":"2020-06-30T19:29:59.735073Z"}
{"type":"l2update","product_id":"BTC-USD","changes":[["sell","9190.92","0.06880000"]],"time":"2020-06-30T19:30:00.344633Z"}
{"type":"l2update","product_id":"BTC-USD","changes":[["sell","9189.96","0.12300000"]],"time":"2020-06-30T19:30:00.634535Z"}
{"type":"heartbeat","last_trade_id":0,"product_id":"BTC-USD","sequence":180761306,"time":"2020-06-30T19:30:00.735048Z"}
{"type":"l2update","product_id":"BTC-USD","changes":[["sell","9193.25","0.00000000"]],"time":"2020-06-30T19:30:01.046362Z"}
{"type":"l2update","product_id":"BTC-USD","changes":[["sell","9164.13","1.18790000"]],"time":"2020-06-30T19:30:01.669370Z"}
{"type":"heartbeat","last_trade_id":0,"product_id":"BTC-USD","sequence":180761309,"time":"2020-06-30T19:30:01.734997Z"}
{"type":"l2update","product_id":"BTC-USD","changes":[["sell","9164.13","4.42020000"]],"time":"2020-06-30T19:30:02.036347Z"}
{"type":"l2update","product_id":"BTC-USD","changes":[["sell","9137.47","1.63700000"]],"time":"2020-06-30T19:30:02.681517Z"}
{"type":"heartbeat","last_trade_id":0,"product_id":"BTC-USD","sequence":180761313,"time":"2020-06-30T19:30:02.734951Z"}
{"type":"l2update","product_id":"BTC-USD","changes":[["buy","9130.51","0.06570000"]],"time":"2020-06-30T19:30:03.004416Z"}
{"type":"l2update","product_id":"BTC-USD","changes":[["buy","9104.90","0.00000000"]],"time":"2020-06-30T19:30:03.162079Z"}
{"type":"l2update","product_id":"BTC-USD","changes":[["buy","9095.86","0.00000000"]],"time":"2020-06-30T19:30:03.210619Z"}
{"type":"l2update","product_id":"BTC-USD","changes":[["buy","9111.09","0.01000000"]],"time":"2020-06-30T19:30:03.406867Z"}
{"type":"heartbeat","last_trade_id":0,"product_id":"BTC-USD","sequence":180761319,"time":"2020-06-30T19:30:03.735017Z"}
{"type":"l2update","product_id":"BTC-USD","changes":[["buy","9131.95","0.06570000"]],"time":"2020-06-30T19:30:03.940982Z"}
{"type":"l2update","product_id":"BTC-USD","changes":[["buy","9132.40","0.06570000"]],"time":"2020-06-30T19:30:04.022540Z"}
{"type":"heartbeat","last_trade_id":0,"product_id":"BTC-USD","sequence":180761323,"time":"2020-06-30T19:30:04.735053Z"}
{"type":"l2update","product_id":"BTC-USD","changes":[["sell","9179.64","0.05270000"]],"time":"2020-06-30T19:30:05.625523Z"}
{"type":"heartbeat","last_trade_id":0,"product_id":"BTC-USD","sequence":180761325,"time":"2020-06-30T19:30:05.734994Z"}
{"type":"l2update","product_id":"BTC-USD","changes":[["sell","9185.68","0.05310000"]],"time":"2020-06-30T19:30:06.069947Z"}
{"type":"l2update","product_id":"BTC-USD","changes":[["sell","9135.89","0.00000000"]],"time":"2020-06-30T19:30:06.100328Z"}
{"type":"l2update","product_id":"BTC-USD","changes":[["buy","9134.75","2993.24650000"]],"time":"2020-06-30T19:30:06.366635Z"}
{"type":"l2update","product_id":"BTC-USD","changes":[["sell","9139.64","0.00330000"]],"time":"2020-06-30T19:30:06.597206Z"}
{"type":"heartbeat","last_trade_id":0,"product_id":"BTC-USD","sequence":180761333,"time":"2020-06-30T19:30:06.735106Z"}
{"type":"l2update","product_id":"BTC-USD","changes":[["sell","9164.13","1.18790000"]],"time":"2020-06-30T19:30:06.808441Z"}
{"type":"l2update","product_id":"BTC-USD","changes":[["sell","9161.80","0.01100000"]],"time":"2020-06-30T19:30:06.828097Z"}
{"type":"l2update","product_id":"BTC-USD","changes":[["sell","9161.80","0.00000000"]],"time":"2020-06-30T19:30:06.872336Z"}
{"type":"l2update","product_id":"BTC-USD","changes":[["buy","9123.64","0.03060000"]],"time":"2020-06-30T19:30:07.492812Z"}
{"type":"heartbeat","last_trade_id":0,"product_id":"BTC-USD","sequence":180761338,"time":"2020-06-30T19:30:07.735031Z"}
{"type":"l2update","product_id":"BTC-USD","changes":[["sell","9181.00","0.10580000"]],"time":"2020-06-30T19:30:07.752543Z"}
{"type":"l2update","product_id":"BTC-USD","changes":[["buy","9132.74","0.00000000"]],"time":"2020-06-30T19:30:07.989483Z"}
{"type":"l2update","product_id":"BTC-USD","changes":[["buy","9102.56","0.00000000"]],"time":"2020-06-30T19:30:08.001989Z"}
{"type":"l2update","product_id":"BTC-USD","changes":[["buy","9133.29","0.00000000"]],"time":"2020-06-30T19:30:08.003830Z"}
{"type":"l2update","product_id":"BTC-USD","changes":[["buy","9134.73","6021.16390000"]],"time":"2020-06-30T19:30:08.314042Z"}
{"type":"l2update","product_id":"BTC-USD","changes":[["buy","9130.51","0.00000000"]],"time":"2020-06-30T19:30:08.490525Z"}
{"type":"l2update","product_id":"BTC-USD","changes":[["buy","9111.09","0.00000000"]],"time":"2020-06-30T19:30:08.496327Z"}
{"type":"l2update","product_id":"BTC-USD","changes":[["buy","9132.59","0.06570000"]],"time":"2020-06-30T19:30:08.584057Z"}
{"type":"heartbeat","last_trade_id":0,"product_id":"BTC-USD","sequence":180761349,"time":"2020-06-30T19:30:08.735040Z"}
{"type":"l2update","product_id":"BTC-USD","changes":[["sell","9178.50","0.03690000"]],"time":"2020-06-30T19:30:09.224883Z"}
{"type":"l2update","product_id":"BTC-USD","changes":[["sell","9177.25","0.00000000"]],"time":"2020-06-30T19:30:09.715392Z"}
{"type":"l2update","product_id":"BTC-USD","changes":[["sell","9179.64","0.00000000"]],"time":"2020-06-30T19:30:09.731029Z"}
{"type":"l2update","product_id":"BTC-USD","changes":[["sell","9217.57","0.00000000"]],"time":"2020-06-30T19:30:09.738268Z"}
{"type":"heartbeat","last_trade_id":0,"product_id":"BTC-USD","sequence":180761354,"time":"2020-06-30T19:30:09.734982Z"}
{"type":"l2update","product_id":"BTC-USD","changes":[["sell","9137.47","3.27500000"]],"time":"2020-06-30T19:30:09.821584Z"}
{"type":"l2update","product_id":"BTC-USD","changes":[["sell","9195.17","0.00000000"]],"time":"2020-06-30T19:30:10.262631Z"}
{"type":"l2update","product_id":"BTC-USD","changes":[["sell","9176.55","0.02220000"]],"time":"2020-06-30T19:30:10.603677Z"}
{"type":"heartbeat","last_trade_id":0,"product_id":"BTC-USD","sequence":180761359,"time":"2020-06-30T19:30:10.735038Z"}
{"type":"l2update","product_id":"BTC-USD","changes":[["sell","9140.43","0.00000000"]],"time":"2020-06-30T19:30:11.042192Z"}
{"type":"l2update","product_id":"BTC-USD","changes":[["buy","9131.96","0.06570000"]],"time":"2020-06-30T19:30:11.157022Z"}
{"type":"l2update","product_id":"BTC-USD","changes":[["buy","9128.91","0.16180000"]],"time":"2020-06-30T19:30:11.444089Z"}
{"type":"l2update","product_id":"BTC-USD","changes":[["buy","9132.59","0.00000000"]],"time":"2020-06-30T19:30:11.671785Z"}
{"type":"l2update","product_id":"BTC-USD","changes":[["buy","9131.95","0.00000000"]],"time":"2020-06-30T19:30:11.685103Z"}
{"type":"l2update","product_id":"BTC-USD","changes":[["buy","9134.75","2993.24550000"]],"time":"2020-06-30T19:30:11.724977Z"}
{"type":"heartbeat","last_trade_id":0,"product_id":"BTC-USD","sequence":180761369,"time":"2020-06-30T19:30:11.735027Z"}
{"type":"heartbeat","last_trade_id":0,"product_id":"BTC-USD","sequence":180761369,"time":"2020-06-30T19:30:12.735029Z"}
{"type":"l2update","product_id":"BTC-USD","changes":[["sell","9179.01","0.06880000"]],"time":"2020-06-30T19:30:13.184859Z"}
{"type":"l2update","product_id":"BTC-USD","changes":[["sell","9137.47","1.63800000"]],"time":"2020-06-30T19:30:13.596403Z"}
{"type":"l2update","product_id":"BTC-USD","changes":[["sell","9164.13","0.00000000"]],"time":"2020-06-30T19:30:13.607786Z"}
{"type":"l2update","product_id":"BTC-USD","changes":[["sell","9181.00","0.00000000"]],"time":"2020-06-30T19:30:13.612668Z"}
{"type":"heartbeat","last_trade_id":0,"product_id":"BTC-USD","sequence":180761374,"time":"2020-06-30T19:30:13.735088Z"}
{"type":"l2update","product_id":"BTC-USD","changes":[["buy","100.00","114.95500000"]],"time":"2020-06-30T19:30:14.040211Z"}
{"type":"l2update","product_id":"BTC-USD","changes":[["buy","100.00","114.94500000"]],"time":"2020-06-30T19:30:14.048298Z"}
{"type":"l2update","product_id":"BTC-USD","changes":[["buy","9132.15","0.81570000"]],"time":"2020-06-30T19:30:14.283390Z"}
{"type":"l2update","product_id":"BTC-USD","changes":[["sell","9181.79","0.10580000"]],"time":"2020-06-30T19:30:14.559508Z"}
{"type":"l2update","product_id":"BTC-USD","changes":[["buy","9123.64","0.00000000"]],"time":"2020-06-30T19:30:14.718105Z"}
{"type":"heartbeat","last_trade_id":0,"product_id":"BTC-USD","sequence":180761382,"time":"2020-06-30T19:30:14.735074Z"}
{"type":"l2update","product_id":"BTC-USD","changes":[["buy","9132.21","0.06570000"]],"time":"2020-06-30T19:30:14.859168Z"}
{"type":"l2update","product_id":"BTC-USD","changes":[["buy","9131.79","0.00000000"]],"time":"2020-06-30T19:30:15.285432Z"}
{"type":"heartbeat","last_trade_id":0,"product_id":"BTC-USD","sequence":180761385,"time":"2020-06-30T19:30:15.735070Z"}
{"type":"l2update","product_id":"BTC-USD","changes":[["buy","9132.11","0.05000000"]],"time":"2020-06-30T19:30:15.968818Z"}
{"type":"l2update","product_id":"BTC-USD","changes":[["sell","9178.06","0.02770000"]],"time":"2020-06-30T19:30:16.251063Z"}
{"type":"l2update","product_id":"BTC-USD","changes":[["buy","9131.03","0.00000000"]],"time":"2020-06-30T19:30:16.441121Z"}
{"type":"heartbeat","last_trade_id":0,"product_id":"BTC-USD","sequence":180761390,"time":"2020-06-30T19:30:16.735063Z"}
{"type":"l2update","product_id":"BTC-USD","changes":[["buy","9132.24","0.06570000"]],"time":"2020-06-30T19:30:17.107882Z"}
{"type":"l2update","product_id":"BTC-USD","changes":[["buy","9134.73","6020.00000000"]],"time":"2020-06-30T19:30:17.565221Z"}
{"type":"l2update","product_id":"BTC-USD","changes":[["buy","9128.91","0.00000000"]],"time":"2020-06-30T19:30:17.572399Z"}
{"type":"heartbeat","last_trade_id":0,"product_id":"BTC-USD","sequence":180761394,"time":"2020-06-30T19:30:17.735021Z"}
{"type":"l2update","product_id":"BTC-USD","changes":[["buy","9132.22","0.06570000"]],"time":"2020-06-30T19:30:18.247890Z"}
{"type":"l2update","product_id":"BTC-USD","changes":[["buy","9132.15","0.06570000"]],"time":"2020-06-30T19:30:18.464674Z"}
{"type":"heartbeat","last_trade_id":0,"product_id":"BTC-USD","sequence":180761397,"time":"2020-06-30T19:30:18.735066Z"}
{"type":"l2update","product_id":"BTC-USD","changes":[["buy","9132.10","0.05000000"]],"time":"2020-06-30T19:30:18.798415Z"}
{"type":"heartbeat","last_trade_id":0,"product_id":"BTC-USD","sequence":180761399,"time":"2020-06-30T19:30:19.735023Z"}
{"type":"l2update","product_id":"BTC-USD","changes":[["buy","9132.12","0.06570000"]],"time":"2020-06-30T19:30:20.493525Z"}
{"type":"l2update","product_id":"BTC-USD","changes":[["buy","9132.19","0.05000000"]],"time":"2020-06-30T19:30:20.742695Z"}
{"type":"heartbeat","last_trade_id":0,"product_id":"BTC-USD","sequence":180761403,"time":"2020-06-30T19:30:20.735070Z"}
{"type":"l2update","product_id":"BTC-USD","changes":[["buy","9131.31","0.00000000"]],"time":"2020-06-30T19:30:20.919003Z"}
{"type":"l2update","product_id":"BTC-USD","changes":[["sell","9179.41","0.01490000"]],"time":"2020-06-30T19:30:21.724010Z"}
{"type":"heartbeat","last_trade_id":0,"product_id":"BTC-USD","sequence":180761406,"time":"2020-06-30T19:30:21.735073Z"}
{"type":"l2update","product_id":"BTC-USD","changes":[["buy","9132.14","0.06570000"]],"time":"2020-06-30T19:30:21.911275Z"}
{"type":"heartbeat","last_trade_id":0,"product_id":"BTC-USD","sequence":180761408,"time":"2020-06-30T19:30:22.735063Z"}
{"type":"l2update","product_id":"BTC-USD","changes":[["buy","9132.22","0.13140000"]],"time":"2020-06-30T19:30:22.820923Z"}
{"type":"l2update","product_id":"BTC-USD","changes":[["buy","9132.10","0.00000000"]],"time":"2020-06-30T19:30:23.258624Z"}
{"type":"heartbeat","last_trade_id":0,"product_id":"BTC-USD","sequence":180761411,"time":"2020-06-30T19:30:23.734980Z"}
{"type":"l2update","product_id":"BTC-USD","changes":[["sell","9178.20","0.02220000"]],"time":"2020-06-30T19:30:24.564739Z"}
{"type":"heartbeat","last_trade_id":0,"product_id":"BTC-USD","sequence":180761413,"time":"2020-06-30T19:30:24.734987Z"}
{"type":"l2update","product_id":"BTC-USD","changes":[["buy","9052.97","7.01200000"]],"time":"2020-06-30T19:30:24.853086Z"}
{"type":"l2update","product_id":"BTC-USD","changes":[["sell","9176.55","0.00000000"]],"time":"2020-06-30T19:30:24.982604Z"}
{"type":"l2update","product_id":"BTC-USD","changes":[["sell","9179.01","0.00000000"]],"time":"2020-06-30T19:30:24.998445Z"}
{"type":"l2update","product_id":"BTC-USD","changes":[["sell","9175.18","0.00000000"]],"time":"2020-06-30T19:30:25.001848Z"}
{"type":"l2update","product_id":"BTC-USD","changes":[["buy","9011.97","8.24600000"]],"time":"2020-06-30T19:30:25.126651Z"}
{"type":"l2update","product_id":"BTC-USD","changes":[["buy","9132.14","0.00000000"]],"time":"2020-06-30T19:30:25.327001Z"}
{"type":"l2update","product_id":"BTC-USD","changes":[["buy","9132.19","0.00000000"]],"time":"2020-06-30T19:30:25.342936Z"}
{"type":"l2update","product_id":"BTC-USD","changes":[["buy","9132.22","0.06570000"]],"time":"2020-06-30T19:30:25.567572Z"}
{"type":"l2update","product_id":"BTC-USD","changes":[["buy","9132.39","0.06570000"]],"time":"2020-06-30T19:30:25.671605Z"}
{"type":"heartbeat","last_trade_id":0,"product_id":"BTC-USD","sequence":180761425,"time":"2020-06-30T19:30:25.735007Z"}
{"type":"l2update","product_id":"BTC-USD","changes":[["sell","9179.95","0.06880000"]],"time":"2020-06-30T19:30:25.965264Z"}
{"type":"l2update","product_id":"BTC-USD","changes":[["sell","9178.06","0.00000000"]],"time":"2020-06-30T19:30:26.409000Z"}
{"type":"l2update","product_id":"BTC-USD","changes":[["sell","9139.64","0.00000000"]],"time":"2020-06-30T19:30:26.413800Z"}
{"type":"l2update","product_id":"BTC-USD","changes":[["buy","9134.73","6020.02960000"]],"time":"2020-06-30T19:30:26.540500Z"}
{"type":"heartbeat","last_trade_id":0,"product_id":"BTC-USD","sequence":180761431,"time":"2020-06-30T19:30:26.735024Z"}
{"type":"l2update","product_id":"BTC-USD","changes":[["buy","9132.42","0.06570000"]],"time":"2020-06-30T19:30:26.834725Z"}
{"type":"l2update","product_id":"BTC-USD","changes":[["buy","9131.96","0.00000000"]],"time":"2020-06-30T19:30:27.025653Z"}
{"type":"l2update","product_id":"BTC-USD","changes":[["buy","9132.09","0.06570000"]],"time":"2020-06-30T19:30:27.116858Z"}
{"type":"l2update","product_id":"BTC-USD","changes":[["buy","9132.22","0.00000000"]],"time":"2020-06-30T19:30:27.326508Z"}
{"type":"l2update","product_id":"BTC-USD","changes":[["buy","9131.61","0.05000000"]],"time":"2020-06-30T19:30:27.666116Z"}
{"type":"heartbeat","last_trade_id":0,"product_id":"BTC-USD","sequence":180761439,"time":"2020-06-30T19:30:27.734955Z"}
{"type":"l2update","product_id":"BTC-USD","changes":[["buy","9102.94","0.50000000"]],"time":"2020-06-30T19:30:28.535541Z"}
{"type":"heartbeat","last_trade_id":0,"product_id":"BTC-USD","sequence":180761441,"time":"2020-06-30T19:30:28.735102Z"}
{"type":"l2update","product_id":"BTC-USD","changes":[["buy","9132.10","0.06570000"]],"time":"2020-06-30T19:30:28.796013Z"}
{"type":"l2update","product_id":"BTC-USD","changes":[["buy","100.00","114.95500000"]],"time":"2020-06-30T19:30:29.035582Z"}
{"type":"l2update","product_id":"BTC-USD","changes":[["buy","100.00","114.94500000"]],"time":"2020-06-30T19:30:29.044609Z"}
{"type":"l2update","product_id":"BTC-USD","changes":[["buy","9132.24","0.00000000"]],"time":"2020-06-30T19:30:29.218522Z"}
{"type":"heartbeat","last_trade_id":0,"product_id":"BTC-USD","sequence":180761447,"time":"2020-06-30T19:30:29.735070Z"}
{"type":"l2update","product_id":"BTC-USD","changes":[["sell","9178.46","0.02770000"]],"time":"2020-06-30T19:30:29.784466Z"}
{"type":"l2update","product_id":"BTC-USD","changes":[["sell","9181.79","0.00000000"]],"time":"2020-06-30T19:30:30.260078Z"}
{"type":"l2update","product_id":"BTC-USD","changes":[["buy","9132.27","0.06570000"]],"time":"2020-06-30T19:30:30.704766Z"}
{"type":"heartbeat","last_trade_id":0,"product_id":"BTC-USD","sequence":180761452,"time":"2020-06-30T19:30:30.735032Z"}
{"type":"l2update","product_id":"BTC-USD","changes":[["sell","9178.87","0.02770000"]],"time":"2020-06-30T19:30:31.645519Z"}
{"type":"heartbeat","last_trade_id":0,"product_id":"BTC-USD","sequence":180761454,"time":"2020-06-30T19:30:31.735074Z"}
{"type":"l2update","product_id":"BTC-USD","changes":[["sell","9189.96","0.00000000"]],"time":"2020-06-30T19:30:32.079950Z"}
{"type":"heartbeat","last_trade_id":0,"product_id":"BTC-USD","sequence":180761455,"time":"2020-06-30T19:30:32.734959Z"}
{"type":"l2update","product_id":"BTC-USD","changes":[["buy","9132.10","0.13140000"]],"time":"2020-06-30T19:30:32.863560Z"}
{"type":"l2update","product_id":"BTC-USD","changes":[["buy","9132.42","0.00000000"]],"time":"2020-06-30T19:30:33.318083Z"}
{"type":"l2update","product_id":"BTC-USD","changes":[["buy","9103.67","0.01000000"]],"time":"2020-06-30T19:30:33.427113Z"}
{"type":"heartbeat","last_trade_id":0,"product_id":"BTC-USD","sequence":180761460,"time":"2020-06-30T19:30:33.735001Z"}
{"type":"l2update","product_id":"BTC-USD","changes":[["buy","9102.94","0.00000000"]],"time":"2020-06-30T19:30:33.907240Z"}
{"type":"l2update","product_id":"BTC-USD","changes":[["buy","9130.56","3.00000000"]],"time":"2020-06-30T19:30:34.364198Z"}
{"type":"l2update","product_id":"BTC-USD","changes":[["buy","9132.10","0.06570000"]],"time":"2020-06-30T19:30:34.586449Z"}
{"type":"l2update","product_id":"BTC-USD","changes":[["buy","9134.73","6020.00000000"]],"time":"2020-06-30T19:30:34.587334Z"}
{"type":"l2update","product_id":"BTC-USD","changes":[["buy","9130.59","0.06570000"]],"time":"2020-06-30T19:30:34.656609Z"}
{"type":"heartbeat","last_trade_id":0,"product_id":"BTC-USD","sequence":180761467,"time":"2020-06-30T19:30:34.735069Z"}
{"type":"l2update","product_id":"BTC-USD","changes":[["sell","9175.35","0.00300000"]],"time":"2020-06-30T19:30:34.956370Z"}
{"type":"l2update","product_id":"BTC-USD","changes":[["sell","9171.01","0.00000000"]],"time":"2020-06-30T19:30:35.416364Z"}
{"type":"heartbeat","last_trade_id":0,"product_id":"BTC-USD","sequence":180761470,"time":"2020-06-30T19:30:35.735105Z"}
{"type":"heartbeat","last_trade_id":0,"product_id":"BTC-USD","sequence":180761470,"time":"2020-06-30T19:30:36.735022Z"}
{"type":"l2update","product_id":"BTC-USD","changes":[["sell","9179.68","0.02770000"]],"time":"2020-06-30T19:30:37.151743Z"}
{"type":"heartbeat","last_trade_id":0,"product_id":"BTC-USD","sequence":180761472,"time":"2020-06-30T19:30:37.734920Z"}
{"type":"l2update","product_id":"BTC-USD","changes":[["buy","9105.58","0.50000000"]],"time":"2020-06-30T19:30:38.072533Z"}
{"type":"heartbeat","last_trade_id":0,"product_id":"BTC-USD","sequence":180761474,"time":"2020-06-30T19:30:38.735061Z"}
{"type":"heartbeat","last_trade_id":0,"product_id":"BTC-USD","sequence":180761474,"time":"2020-06-30T19:30:39.734962Z"}
{"type":"l2update","product_id":"BTC-USD","changes":[["buy","9132.24","0.04000000"]],"time":"2020-06-30T19:30:40.272648Z"}
{"type":"l2update","product_id":"BTC-USD","changes":[["buy","9131.61","0.00000000"]],"time":"2020-06-30T19:30:40.721817Z"}
{"type":"heartbeat","last_trade_id":0,"product_id":"BTC-USD","sequence":180761477,"time":"2020-06-30T19:30:40.735038Z"}
{"type":"l2update","product_id":"BTC-USD","changes":[["sell","9134.77","2953.95600000"]],"time":"2020-06-30T19:30:40.871582Z"}
{"type":"l2update","product_id":"BTC-USD","changes":[["buy","8902.54","0.00000000"]],"time":"2020-06-30T19:30:40.950272Z"}
{"type":"l2update","product_id":"BTC-USD","changes":[["buy","8901.77","0.04548158"]],"time":"2020-06-30T19:30:41.263861Z"}
{"type":"l2update","product_id":"BTC-USD","changes":[["buy","9090.32","0.05500000"]],"time":"2020-06-30T19:30:41.419239Z"}
{"type":"l2update","product_id":"BTC-USD","changes":[["buy","9132.40","0.00000000"]],"time":"2020-06-30T19:30:41.487028Z"}
{"type":"l2update","product_id":"BTC-USD","changes":[["sell","9427.91","0.00000000"]],"time":"2020-06-30T19:30:41.669564Z"}
{"type":"heartbeat","last_trade_id":0,"product_id":"BTC-USD","sequence":180761487,"time":"2020-06-30T19:30:41.735000Z"}
{"type":"l2update","product_id":"BTC-USD","changes":[["buy","9103.67","0.00000000"]],"time":"2020-06-30T19:30:41.858153Z"}
{"type":"l2update","product_id":"BTC-USD","changes":[["sell","9428.71","0.00624858"]],"time":"2020-06-30T19:30:41.961445Z"}
{"type":"heartbeat","last_trade_id":0,"product_id":"BTC-USD","sequence":180761490,"time":"2020-06-30T19:30:42.735051Z"}
{"type":"l2update","product_id":"BTC-USD","changes":[["buy","9132.67","0.06570000"]],"time":"2020-06-30T19:30:43.125275Z"}
{"type":"l2update","product_id":"BTC-USD","changes":[["buy","9134.75","2989.22700000"]],"time":"2020-06-30T19:30:43.403157Z"}
{"type":"l2update","product_id":"BTC-USD","changes":[["buy","9131.69","0.45800000"]],"time":"2020-06-30T19:30:43.672642Z"}
{"type":"heartbeat","last_trade_id":0,"product_id":"BTC-USD","sequence":180761497,"time":"2020-06-30T19:30:43.735071Z"}
{"type":"l2update","product_id":"BTC-USD","changes":[["buy","9132.04","0.04000000"]],"time":"2020-06-30T19:30:43.966329Z"}
{"type":"l2update","product_id":"BTC-USD","changes":[["buy","100.00","114.95500000"]],"time":"2020-06-30T19:30:44.039950Z"}
{"type":"l2update","product_id":"BTC-USD","changes":[["buy","100.00","114.94500000"]],"time":"2020-06-30T19:30:44.045990Z"}
{"type":"l2update","product_id":"BTC-USD","changes":[["buy","9131.48","0.00000000"]],"time":"2020-06-30T19:30:44.110487Z"}
{"type":"l2update","product_id":"BTC-USD","changes":[["buy","9132.11","0.00000000"]],"time":"2020-06-30T19:30:44.111213Z"}
{"type":"heartbeat","last_trade_id":0,"product_id":"BTC-USD","sequence":180761504,"time":"2020-06-30T19:30:44.735066Z"}
{"type":"l2update","product_id":"BTC-USD","changes":[["buy","9132.25","0.06570000"]],"time":"2020-06-30T19:30:44.832888Z"}
{"type":"l2update","product_id":"BTC-USD","changes":[["sell","9179.41","0.08370000"]],"time":"2020-06-30T19:30:45.415228Z"}
{"type":"heartbeat","last_trade_id":0,"product_id":"BTC-USD","sequence":180761508,"time":"2020-06-30T19:30:45.735071Z"}
{"type":"l2update","product_id":"BTC-USD","changes":[["sell","9178.87","0.00000000"]],"time":"2020-06-30T19:30:45.834846Z"}
{"type":"l2update","product_id":"BTC-USD","changes":[["buy","9134.75","2984.18610000"]],"time":"2020-06-30T19:30:46.536500Z"}
{"type":"l2update","product_id":"BTC-USD","changes":[["buy","9132.15","0.00000000"]],"time":"2020-06-30T19:30:46.565837Z"}
{"type":"heartbeat","last_trade_id":0,"product_id":"BTC-USD","sequence":180761513,"time":"2020-06-30T19:30:46.735064Z"}
{"type":"l2update","product_id":"BTC-USD","changes":[["buy","9132.23","0.05000000"]],"time":"2020-06-30T19:30:46.808687Z"}
{"type":"l2update","product_id":"BTC-USD","changes":[["sell","9137.47","0.00000000"]],"time":"2020-06-30T19:30:46.987147Z"}
{"type":"l2update","product_id":"BTC-USD","changes":[["sell","9179.41","0.06880000"]],"time":"2020-06-30T19:30:46.996821Z"}
{"type":"l2update","product_id":"BTC-USD","changes":[["sell","9178.50","0.00000000"]],"time":"2020-06-30T19:30:47.002275Z"}
{"type":"l2update","product_id":"BTC-USD","changes":[["buy","9130.17","0.06570000"]],"time":"2020-06-30T19:30:47.140445Z"}
{"type":"l2update","product_id":"BTC-USD","changes":[["buy","9130.59","0.00000000"]],"time":"2020-06-30T19:30:47.225723Z"}
{"type":"l2update","product_id":"BTC-USD","changes":[["buy","9134.75","2979.13850000"]],"time":"2020-06-30T19:30:47.391240Z"}
{"type":"l2update","product_id":"BTC-USD","changes":[["buy","9132.27","0.00000000"]],"time":"2020-06-30T19:30:47.579674Z"}
{"type":"l2update","product_id":"BTC-USD","changes":[["buy","9132.24","0.00000000"]],"time":"2020-06-30T19:30:47.587593Z"}
{"type":"l2update","product_id":"BTC-USD","changes":[["buy","9131.69","0.00000000"]],"time":"2020-06-30T19:30:47.587852Z"}
{"type":"l2update","product_id":"BTC-USD","changes":[["buy","9132.21","0.00000000"]],"time":"2020-06-30T19:30:47.599829Z"}
{"type":"l2update","product_id":"BTC-USD","changes":[["sell","9177.79","0.06880000"]],"time":"2020-06-30T19:30:47.672131Z"}
{"type":"heartbeat","last_trade_id":0,"product_id":"BTC-USD","sequence":180761530,"time":"2020-06-30T19:30:47.735028Z"}
{"type":"l2update","product_id":"BTC-USD","changes":[["sell","9185.68","0.00000000"]],"time":"2020-06-30T19:30:47.832332Z"}
{"type":"l2update","product_id":"BTC-USD","changes":[["buy","9132.24","0.15570000"]],"time":"2020-06-30T19:30:47.987587Z"}
{"type":"l2update","product_id":"BTC-USD","changes":[["sell","9171.48","0.00000000"]],"time":"2020-06-30T19:30:48.143303Z"}
{"type":"l2update","product_id":"BTC-USD","changes":[["buy","9132.25","0.00000000"]],"time":"2020-06-30T19:30:48.232548Z"}
{"type":"l2update","product_id":"BTC-USD","changes":[["buy","9132.12","0.00000000"]],"time":"2020-06-30T19:30:48.243096Z"}
{"type":"l2update","product_id":"BTC-USD","changes":[["buy","9132.23","0.00000000"]],"time":"2020-06-30T19:30:48.396133Z"}
{"type":"l2update","product_id":"BTC-USD","changes":[["buy","9132.04","0.00000000"]],"time":"2020-06-30T19:30:48.399186Z"}
{"type":"heartbeat","last_trade_id":0,"product_id":"BTC-USD","sequence":180761538,"time":"2020-06-30T19:30:48.734988Z"}
{"type":"heartbeat","last_trade_id":0,"product_id":"BTC-USD","sequence":180761538,"time":"2020-06-30T19:30:49.734998Z"}
{"type":"l2update","product_id":"BTC-USD","changes":[["buy","9134.75","2974.28060000"]],"time":"2020-06-30T19:30:50.349722Z"}
{"type":"heartbeat","last_trade_id":0,"product_id":"BTC-USD","sequence":180761541,"time":"2020-06-30T19:30:50.734978Z"}
{"type":"l2update","product_id":"BTC-USD","changes":[["buy","9131.45","3.00000000"]],"time":"2020-06-30T19:30:51.190152Z"}
{"type":"l2update","product_id":"BTC-USD","changes":[["buy","9132.67","0.00000000"]],"time":"2020-06-30T19:30:51.654764Z"}
{"type":"l2update","product_id":"BTC-USD","changes":[["buy","9011.97","0.00000000"]],"time":"2020-06-30T19:30:51.662798Z"}
{"type":"l2update","product_id":"BTC-USD","changes":[["buy","9111.09","0.01000000"]],"time":"2020-06-30T19:30:51.748192Z"}
{"type":"heartbeat","last_trade_id":0,"product_id":"BTC-USD","sequence":180761547,"time":"2020-06-30T19:30:51.735107Z"}
{"type":"l2update","product_id":"BTC-USD","changes":[["buy","9107.90","1.21010000"]],"time":"2020-06-30T19:30:52.035386Z"}
{"type":"l2update","product_id":"BTC-USD","changes":[["buy","9130.56","0.00000000"]],"time":"2020-06-30T19:30:52.235614Z"}
{"type":"l2update","product_id":"BTC-USD","changes":[["buy","9131.46","0.47380000"]],"time":"2020-06-30T19:30:52.605651Z"}
{"type":"heartbeat","last_trade_id":0,"product_id":"BTC-USD","sequence":180761552,"time":"2020-06-30T19:30:52.735071Z"}
{"type":"heartbeat","last_trade_id":0,"product_id":"BTC-USD","sequence":180761552,"time":"2020-06-30T19:30:53.735069Z"}
{"type":"l2update","product_id":"BTC-USD","changes":[["sell","9139.91","1.32130000"]],"time":"2020-06-30T19:30:53.861340Z"}
{"type":"heartbeat","last_trade_id":0,"product_id":"BTC-USD","sequence":180761554,"time":"2020-06-30T19:30:54.735120Z"}
{"type":"l2update","product_id":"BTC-USD","changes":[["sell","9178.33","0.06880000"]],"time":"2020-06-30T19:30:55.200545Z"}
{"type":"l2update","product_id":"BTC-USD","changes":[["buy","9127.97","0.06570000"]],"time":"2020-06-30T19:30:55.515347Z"}
{"type":"l2update","product_id":"BTC-USD","changes":[["sell","9179.95","0.00000000"]],"time":"2020-06-30T19:30:55.646992Z"}
{"type":"l2update","product_id":"BTC-USD","changes":[["sell","9175.35","0.00000000"]],"time":"2020-06-30T19:30:55.651939Z"}
{"type":"heartbeat","last_trade_id":0,"product_id":"BTC-USD","sequence":180761560,"time":"2020-06-30T19:30:55.735073Z"}
{"type":"l2update","product_id":"BTC-USD","changes":[["buy","9111.09","0.00000000"]],"time":"2020-06-30T19:30:55.959074Z"}
{"type":"l2update","product_id":"BTC-USD","changes":[["buy","9132.09","0.00000000"]],"time":"2020-06-30T19:30:55.979819Z"}
{"type":"l2update","product_id":"BTC-USD","changes":[["buy","9132.24","0.00000000"]],"time":"2020-06-30T19:30:56.032400Z"}
{"type":"heartbeat","last_trade_id":0,"product_id":"BTC-USD","sequence":180761563,"time":"2020-06-30T19:30:56.735073Z"}
{"type":"l2update","product_id":"BTC-USD","changes":[["buy","9132.82","0.06570000"]],"time":"2020-06-30T19:30:56.833408Z"}
{"type":"l2update","product_id":"BTC-USD","changes":[["buy","9132.82","0.13140000"]],"time":"2020-06-30T19:30:57.376719Z"}
{"type":"heartbeat","last_trade_id":0,"product_id":"BTC-USD","sequence":180761567,"time":"2020-06-30T19:30:57.735122Z"}
{"type":"l2update","product_id":"BTC-USD","changes":[["buy","9132.10","0.00000000"]],"time":"2020-06-30T19:30:57.864045Z"}
{"type":"l2update","product_id":"BTC-USD","changes":[["buy","9131.31","1.63900000"]],"time":"2020-06-30T19:30:57.993306Z"}
{"type":"heartbeat","last_trade_id":0,"product_id":"BTC-USD","sequence":180761570,"time":"2020-06-30T19:30:58.735071Z"}
{"type":"l2update","product_id":"BTC-USD","changes":[["buy","100.00","114.95500000"]],"time":"2020-06-30T19:30:59.061610Z"}
{"type":"l2update","product_id":"BTC-USD","changes":[["buy","100.00","114.94500000"]],"time":"2020-06-30T19:30:59.068262Z"}
{"type":"l2update","product_id":"BTC-USD","changes":[["buy","9134.75","2972.29740000"]],"time":"2020-06-30T19:30:59.077384Z"}
{"type":"heartbeat","last_trade_id":0,"product_id":"BTC-USD","sequence":180761576,"time":"2020-06-30T19:30:59.735112Z"}
{"type":"heartbeat","last_trade_id":0,"product_id":"BTC-USD","sequence":180761576,"time":"2020-06-30T19:31:00.735067Z"}
{"type":"l2update","product_id":"BTC-USD","changes":[["buy","9132.53","0.06570000"]],"time":"2020-06-30T19:31:01.674622Z"}
{"type":"heartbeat","last_trade_id":0,"product_id":"BTC-USD","sequence":180761578,"time":"2020-06-30T19:31:01.735068Z"}
{"type":"l2update","product_id":"BTC-USD","changes":[["buy","9132.59","0.06570000"]],"time":"2020-06-30T19:31:01.970434Z"}
{"type":"l2update","product_id":"BTC-USD","changes":[["buy","9052.97","0.00000000"]],"time":"2020-06-30T19:31:02.161850Z"}
{"type":"l2update","product_id":"BTC-USD","changes":[["buy","9127.97","0.00000000"]],"time":"2020-06-30T19:31:02.162034Z"}
{"type":"l2update","product_id":"BTC-USD","changes":[["buy","9130.17","0.00000000"]],"time":"2020-06-30T19:31:02.490137Z"}
{"type":"heartbeat","last_trade_id":0,"product_id":"BTC-USD","sequence":180761583,"time":"2020-06-30T19:31:02.735072Z"}
{"type":"l2update","product_id":"BTC-USD","changes":[["buy","9132.55","0.06570000"]],"time":"2020-06-30T19:31:03.109505Z"}
{"type":"l2update","product_id":"BTC-USD","changes":[["buy","9132.52","0.11570000"]],"time":"2020-06-30T19:31:03.419972Z"}
{"type":"l2update","product_id":"BTC-USD","changes":[["buy","9107.90","0.00000000"]],"time":"2020-06-30T19:31:03.583094Z"}
{"type":"l2update","product_id":"BTC-USD","changes":[["buy","9131.45","0.00000000"]],"time":"2020-06-30T19:31:03.659262Z"}
{"type":"heartbeat","last_trade_id":0,"product_id":"BTC-USD","sequence":180761589,"time":"2020-06-30T19:31:03.735064Z"}
{"type":"l2update","product_id":"BTC-USD","changes":[["buy","9075.38","0.00000000"]],"time":"2020-06-30T19:31:04.511107Z"}
{"type":"l2update","product_id":"BTC-USD","changes":[["buy","8964.07","0.00000000"]],"time":"2020-06-30T19:31:04.515814Z"}
{"type":"l2update","product_id":"BTC-USD","changes":[["buy","9125.78","0.06570000"]],"time":"2020-06-30T19:31:04.537678Z"}
{"type":"heartbeat","last_trade_id":0,"product_id":"BTC-USD","sequence":180761593,"time":"2020-06-30T19:31:04.735072Z"}
{"type":"l2update","product_id":"BTC-USD","changes":[["buy","9132.52","0.00000000"]],"time":"2020-06-30T19:31:04.995153Z"}
{"type":"heartbeat","last_trade_id":0,"product_id":"BTC-USD","sequence":180761594,"time":"2020-06-30T19:31:05.734985Z"}
{"type":"l2update","product_id":"BTC-USD","changes":[["buy","9130.85","0.04000000"]],"time":"2020-06-30T19:31:05.864598Z"}
{"type":"l2update","product_id":"BTC-USD","changes":[["buy","9090.32","0.00000000"]],"time":"2020-06-30T19:31:06.035772Z"}
{"type":"l2update","product_id":"BTC-USD","changes":[["buy","9075.38","0.05600000"]],"time":"2020-06-30T19:31:06.085135Z"}
{"type":"l2update","product_id":"BTC-USD","changes":[["buy","8964.07","0.17800000"]],"time":"2020-06-30T19:31:06.095137Z"}
{"type":"heartbeat","last_trade_id":0,"product_id":"BTC-USD","sequence":180761601,"time":"2020-06-30T19:31:06.735150Z"}
{"type":"l2update","product_id":"BTC-USD","changes":[["buy","9132.20","0.12500000"]],"time":"2020-06-30T19:31:07.577322Z"}
{"type":"heartbeat","last_trade_id":0,"product_id":"BTC-USD","sequence":180761603,"time":"2020-06-30T19:31:07.735055Z"}
{"type":"l2update","product_id":"BTC-USD","changes":[["buy","9132.51","0.12500000"]],"time":"2020-06-30T19:31:07.878429Z"}
{"type":"l2update","product_id":"BTC-USD","changes":[["buy","9132.32","0.05000000"]],"time":"2020-06-30T19:31:08.428158Z"}
{"type":"l2update","product_id":"BTC-USD","changes":[["sell","9135.32","0.06570000"]],"time":"2020-06-30T19:31:08.700488Z"}
{"type":"heartbeat","last_trade_id":0,"product_id":"BTC-USD","sequence":180761609,"time":"2020-06-30T19:31:08.734982Z"}
{"type":"l2update","product_id":"BTC-USD","changes":[["buy","9132.39","0.00000000"]],"time":"2020-06-30T19:31:08.882253Z"}
{"type":"l2update","product_id":"BTC-USD","changes":[["sell","9178.33","0.00000000"]],"time":"2020-06-30T19:31:09.126081Z"}
{"type":"l2update","product_id":"BTC-USD","changes":[["buy","9132.48","0.12500000"]],"time":"2020-06-30T19:31:09.257529Z"}
{"type":"l2update","product_id":"BTC-USD","changes":[["buy","9132.49","0.12500000"]],"time":"2020-06-30T19:31:09.524892Z"}
{"type":"heartbeat","last_trade_id":0,"product_id":"BTC-USD","sequence":180761615,"time":"2020-06-30T19:31:09.735120Z"}
{"type":"heartbeat","last_trade_id":0,"product_id":"BTC-USD","sequence":180761615,"time":"2020-06-30T19:31:10.735120Z"}
{"type":"l2update","product_id":"BTC-USD","changes":[["buy","9132.37","0.12500000"]],"time":"2020-06-30T19:31:10.917178Z"}
{"type":"l2update","product_id":"BTC-USD","changes":[["buy","9134.75","2972.29640000"]],"time":"2020-06-30T19:31:11.072144Z"}
{"type":"l2update","product_id":"BTC-USD","changes":[["buy","9131.31","0.00000000"]],"time":"2020-06-30T19:31:11.357126Z"}
{"type":"l2update","product_id":"BTC-USD","changes":[["buy","9132.49","0.00000000"]],"time":"2020-06-30T19:31:11.379361Z"}
{"type":"l2update","product_id":"BTC-USD","changes":[["buy","9132.37","0.00000000"]],"time":"2020-06-30T19:31:11.621270Z"}
{"type":"heartbeat","last_trade_id":0,"product_id":"BTC-USD","sequence":180761623,"time":"2020-06-30T19:31:11.734987Z"}
{"type":"heartbeat","last_trade_id":0,"product_id":"BTC-USD","sequence":180761623,"time":"2020-06-30T19:31:12.735171Z"}
{"type":"l2update","product_id":"BTC-USD","changes":[["buy","9132.26","0.25000000"]],"time":"2020-06-30T19:31:13.221223Z"}
{"type":"l2update","product_id":"BTC-USD","changes":[["buy","9127.79","0.06570000"]],"time":"2020-06-30T19:31:13.494509Z"}
{"type":"l2update","product_id":"BTC-USD","changes":[["buy","9130.85","0.00000000"]],"time":"2020-06-30T19:31:13.645200Z"}
{"type":"l2update","product_id":"BTC-USD","changes":[["buy","9132.82","0.06570000"]],"time":"2020-06-30T19:31:13.651975Z"}
{"type":"l2update","product_id":"BTC-USD","changes":[["buy","9132.48","0.00000000"]],"time":"2020-06-30T19:31:13.652423Z"}
{"type":"heartbeat","last_trade_id":0,"product_id":"BTC-USD","sequence":180761630,"time":"2020-06-30T19:31:13.735117Z"}
{"type":"l2update","product_id":"BTC-USD","changes":[["buy","9132.63","0.25000000"]],"time":"2020-06-30T19:31:13.753104Z"}
{"type":"l2update","product_id":"BTC-USD","changes":[["buy","9132.51","0.00000000"]],"time":"2020-06-30T19:31:13.924766Z"}
{"type":"l2update","product_id":"BTC-USD","changes":[["buy","9125.78","0.00000000"]],"time":"2020-06-30T19:31:13.950034Z"}
{"type":"l2update","product_id":"BTC-USD","changes":[["buy","100.00","114.95500000"]],"time":"2020-06-30T19:31:14.035695Z"}
{"type":"l2update","product_id":"BTC-USD","changes":[["buy","100.00","114.94500000"]],"time":"2020-06-30T19:31:14.042994Z"}
{"type":"l2update","product_id":"BTC-USD","changes":[["buy","9133.94","0.50000000"]],"time":"2020-06-30T19:31:14.184261Z"}
{"type":"l2update","product_id":"BTC-USD","changes":[["sell","9147.51","0.02360000"]],"time":"2020-06-30T19:31:14.327391Z"}
{"type":"l2update","product_id":"BTC-USD","changes":[["sell","9144.03","0.03250000"]],"time":"2020-06-30T19:31:14.590832Z"}
{"type":"heartbeat","last_trade_id":0,"product_id":"BTC-USD","sequence":180761643,"time":"2020-06-30T19:31:14.735069Z"}
{"type":"l2update","product_id":"BTC-USD","changes":[["buy","9132.80","0.12500000"]],"time":"2020-06-30T19:31:15.447604Z"}
{"type":"heartbeat","last_trade_id":0,"product_id":"BTC-USD","sequence":180761645,"time":"2020-06-30T19:31:15.735095Z"}
{"type":"l2update","product_id":"BTC-USD","changes":[["buy","9132.26","0.00000000"]],"time":"2020-06-30T19:31:15.877642Z"}
{"type":"l2update","product_id":"BTC-USD","changes":[["buy","9132.66","0.25000000"]],"time":"2020-06-30T19:31:15.981767Z"}
{"type":"heartbeat","last_trade_id":0,"product_id":"BTC-USD","sequence":180761648,"time":"2020-06-30T19:31:16.735068Z"}
{"type":"l2update","product_id":"BTC-USD","changes":[["buy","9132.62","0.25000000"]],"time":"2020-06-30T19:31:17.383385Z"}
{"type":"l2update","product_id":"BTC-USD","changes":[["buy","9132.65","0.25000000"]],"time":"2020-06-30T19:31:17.681200Z"}
{"type":"heartbeat","last_trade_id":0,"product_id":"BTC-USD","sequence":180761652,"time":"2020-06-30T19:31:17.734981Z"}
{"type":"l2update","product_id":"BTC-USD","changes":[["buy","9132.32","0.00000000"]],"time":"2020-06-30T19:31:17.825403Z"}
{"type":"l2update","product_id":"BTC-USD","changes":[["buy","9122.77","0.06570000"]],"time":"2020-06-30T19:31:17.957674Z"}
{"type":"l2update","product_id":"BTC-USD","changes":[["buy","9134.75","2972.24640000"]],"time":"2020-06-30T19:31:18.236256Z"}
{"type":"l2update","product_id":"BTC-USD","changes":[["sell","9135.32","0.00000000"]],"time":"2020-06-30T19:31:18.438665Z"}
{"type":"l2update","product_id":"BTC-USD","changes":[["sell","9139.81","0.00000000"]],"time":"2020-06-30T19:31:18.465684Z"}
{"type":"l2update","product_id":"BTC-USD","changes":[["buy","9133.94","0.50100000"]],"time":"2020-06-30T19:31:18.560011Z"}
{"type":"heartbeat","last_trade_id":0,"product_id":"BTC-USD","sequence":180761662,"time":"2020-06-30T19:31:18.735188Z"}
{"type":"l2update","product_id":"BTC-USD","changes":[["buy","9122.82","0.03060000"]],"time":"2020-06-30T19:31:18.779496Z"}
{"type":"heartbeat","last_trade_id":0,"product_id":"BTC-USD","sequence":180761664,"time":"2020-06-30T19:31:19.735114Z"}
{"type":"l2update","product_id":"BTC-USD","changes":[["buy","9134.75","2971.40190000"]],"time":"2020-06-30T19:31:20.164120Z"}
{"type":"l2update","product_id":"BTC-USD","changes":[["buy","9133.94","0.50000000"]],"time":"2020-06-30T19:31:20.433965Z"}
{"type":"l2update","product_id":"BTC-USD","changes":[["sell","9154.89","0.04680000"]],"time":"2020-06-30T19:31:20.580849Z"}
{"type":"heartbeat","last_trade_id":0,"product_id":"BTC-USD","sequence":180761670,"time":"2020-06-30T19:31:20.735089Z"}
{"type":"l2update","product_id":"BTC-USD","changes":[["sell","9136.11","0.54600000"]],"time":"2020-06-30T19:31:21.142809Z"}
{"type":"l2update","product_id":"BTC-USD","changes":[["buy","9131.61","0.25000000"]],"time":"2020-06-30T19:31:21.704136Z"}
{"type":"heartbeat","last_trade_id":0,"product_id":"BTC-USD","sequence":180761674,"time":"2020-06-30T19:31:21.735115Z"}
{"type":"l2update","product_id":"BTC-USD","changes":[["buy","9109.98","0.01000000"]],"time":"2020-06-30T19:31:21.983589Z"}
{"type":"l2update","product_id":"BTC-USD","changes":[["buy","9132.63","0.00000000"]],"time":"2020-06-30T19:31:22.138678Z"}
{"type":"l2update","product_id":"BTC-USD","changes":[["buy","9130.99","0.05000000"]],"time":"2020-06-30T19:31:22.251386Z"}
{"type":"heartbeat","last_trade_id":0,"product_id":"BTC-USD","sequence":180761679,"time":"2020-06-30T19:31:22.735090Z"}
{"type":"l2update","product_id":"BTC-USD","changes":[["buy","9130.92","0.54500000"]],"time":"2020-06-30T19:31:22.978936Z"}
{"type":"l2update","product_id":"BTC-USD","changes":[["buy","9134.75","2971.20190000"]],"time":"2020-06-30T19:31:23.086498Z"}
{"type":"l2update","product_id":"BTC-USD","changes":[["buy","9134.75","2971.00190000"]],"time":"2020-06-30T19:31:23.363398Z"}
{"type":"l2update","product_id":"BTC-USD","changes":[["sell","9154.89","0.00000000"]],"time":"2020-06-30T19:31:23.500944Z"}
{"type":"heartbeat","last_trade_id":0,"product_id":"BTC-USD","sequence":180761688,"time":"2020-06-30T19:31:23.735114Z"}
{"type":"l2update","product_id":"BTC-USD","changes":[["sell","9139.91","0.00000000"]],"time":"2020-06-30T19:31:23.806076Z"}
{"type":"l2update","product_id":"BTC-USD","changes":[["buy","9132.04","0.12500000"]],"time":"2020-06-30T19:31:23.905927Z"}
{"type":"l2update","product_id":"BTC-USD","changes":[["buy","9131.81","0.05000000"]],"time":"2020-06-30T19:31:24.193366Z"}
{"type":"l2update","product_id":"BTC-USD","changes":[["buy","9132.20","0.00000000"]],"time":"2020-06-30T19:31:24.350795Z"}
{"type":"l2update","product_id":"BTC-USD","changes":[["buy","9132.59","0.00000000"]],"time":"2020-06-30T19:31:24.352638Z"}
{"type":"l2update","product_id":"BTC-USD","changes":[["buy","9132.62","0.00000000"]],"time":"2020-06-30T19:31:24.365660Z"}
{"type":"l2update","product_id":"BTC-USD","changes":[["sell","9144.03","0.06500000"]],"time":"2020-06-30T19:31:24.478517Z"}
{"type":"l2update","product_id":"BTC-USD","changes":[["buy","9127.79","0.00000000"]],"time":"2020-06-30T19:31:24.622055Z"}
{"type":"heartbeat","last_trade_id":0,"product_id":"BTC-USD","sequence":180761699,"time":"2020-06-30T19:31:24.735052Z"}
{"type":"l2update","product_id":"BTC-USD","changes":[["sell","9180.28","1.35390000"]],"time":"2020-06-30T19:31:25.069005Z"}
{"type":"l2update","product_id":"BTC-USD","changes":[["sell","9136.11","0.00000000"]],"time":"2020-06-30T19:31:25.526676Z"}
{"type":"heartbeat","last_trade_id":0,"product_id":"BTC-USD","sequence":180761702,"time":"2020-06-30T19:31:25.735058Z"}
{"type":"heartbeat","last_trade_id":0,"product_id":"BTC-USD","sequence":180761702,"time":"2020-06-30T19:31:26.735115Z"}
{"type":"l2update","product_id":"BTC-USD","changes":[["buy","9122.73","0.06570000"]],"time":"2020-06-30T19:31:27.614854Z"}
{"type":"heartbeat","last_trade_id":0,"product_id":"BTC-USD","sequence":180761704,"time":"2020-06-30T19:31:27.735111Z"}
{"type":"l2update","product_id":"BTC-USD","changes":[["buy","9132.09","0.75000000"]],"time":"2020-06-30T19:31:27.901602Z"}
{"type":"l2update","product_id":"BTC-USD","changes":[["buy","9109.98","0.00000000"]],"time":"2020-06-30T19:31:28.028173Z"}
{"type":"l2update","product_id":"BTC-USD","changes":[["buy","9133.94","0.00000000"]],"time":"2020-06-30T19:31:28.030592Z"}
{"type":"l2update","product_id":"BTC-USD","changes":[["buy","9122.82","0.00000000"]],"time":"2020-06-30T19:31:28.033395Z"}
{"type":"l2update","product_id":"BTC-USD","changes":[["buy","9122.77","0.00000000"]],"time":"2020-06-30T19:31:28.035770Z"}
{"type":"l2update","product_id":"BTC-USD","changes":[["buy","9133.00","0.05000000"]],"time":"2020-06-30T19:31:28.183427Z"}
{"type":"heartbeat","last_trade_id":0,"product_id":"BTC-USD","sequence":180761712,"time":"2020-06-30T19:31:28.735114Z"}
{"type":"l2update","product_id":"BTC-USD","changes":[["buy","100.00","114.95500000"]],"time":"2020-06-30T19:31:29.087841Z"}
{"type":"l2update","product_id":"BTC-USD","changes":[["buy","100.00","114.94500000"]],"time":"2020-06-30T19:31:29.094718Z"}
{"type":"l2update","product_id":"BTC-USD","changes":[["sell","9179.05","0.03690000"]],"time":"2020-06-30T19:31:29.359425Z"}
{"type":"heartbeat","last_trade_id":0,"product_id":"BTC-USD","sequence":180761717,"time":"2020-06-30T19:31:29.735128Z"}
{"type":"l2update","product_id":"BTC-USD","changes":[["sell","9144.03","0.03250000"]],"time":"2020-06-30T19:31:29.782895Z"}
{"type":"l2update","product_id":"BTC-USD","changes":[["buy","9130.43","0.54600000"]],"time":"2020-06-30T19:31:29.981313Z"}
{"type":"l2update","product_id":"BTC-USD","changes":[["buy","9133.00","0.00000000"]],"time":"2020-06-30T19:31:30.383851Z"}
{"type":"l2update","product_id":"BTC-USD","changes":[["buy","9131.85","0.25000000"]],"time":"2020-06-30T19:31:30.526898Z"}
{"type":"heartbeat","last_trade_id":0,"product_id":"BTC-USD","sequence":180761723,"time":"2020-06-30T19:31:30.735064Z"}
{"type":"l2update","product_id":"BTC-USD","changes":[["buy","9131.88","0.25000000"]],"time":"2020-06-30T19:31:30.808716Z"}
{"type":"l2update","product_id":"BTC-USD","changes":[["buy","9131.67","0.12500000"]],"time":"2020-06-30T19:31:31.640964Z"}
{"type":"heartbeat","last_trade_id":0,"product_id":"BTC-USD","sequence":180761727,"time":"2020-06-30T19:31:31.735117Z"}
{"type":"l2update","product_id":"BTC-USD","changes":[["buy","9132.04","0.00000000"]],"time":"2020-06-30T19:31:31.846246Z"}
{"type":"l2update","product_id":"BTC-USD","changes":[["buy","9134.75","2970.43900000"]],"time":"2020-06-30T19:31:32.740478Z"}
{"type":"heartbeat","last_trade_id":0,"product_id":"BTC-USD","sequence":180761731,"time":"2020-06-30T19:31:32.735130Z"}
{"type":"l2update","product_id":"BTC-USD","changes":[["sell","9178.20","0.00000000"]],"time":"2020-06-30T19:31:33.196372Z"}
{"type":"l2update","product_id":"BTC-USD","changes":[["sell","9180.28","0.00000000"]],"time":"2020-06-30T19:31:33.236177Z"}
{"type":"heartbeat","last_trade_id":0,"product_id":"BTC-USD","sequence":180761733,"time":"2020-06-30T19:31:33.735118Z"}
{"type":"l2update","product_id":"BTC-USD","changes":[["buy","9122.57","0.06570000"]],"time":"2020-06-30T19:31:34.558940Z"}
{"type":"heartbeat","last_trade_id":0,"product_id":"BTC-USD","sequence":180761735,"time":"2020-06-30T19:31:34.735122Z"}
{"type":"l2update","product_id":"BTC-USD","changes":[["buy","9132.65","0.00000000"]],"time":"2020-06-30T19:31:34.749564Z"}
{"type":"l2update","product_id":"BTC-USD","changes":[["buy","9130.43","0.00000000"]],"time":"2020-06-30T19:31:34.754014Z"}
{"type":"l2update","product_id":"BTC-USD","changes":[["buy","9122.48","0.06570000"]],"time":"2020-06-30T19:31:34.846108Z"}
{"type":"l2update","product_id":"BTC-USD","changes":[["buy","9131.00","0.33710000"]],"time":"2020-06-30T19:31:35.134251Z"}
{"type":"l2update","product_id":"BTC-USD","changes":[["buy","9132.09","0.00000000"]],"time":"2020-06-30T19:31:35.307445Z"}
{"type":"l2update","product_id":"BTC-USD","changes":[["buy","9105.58","0.00000000"]],"time":"2020-06-30T19:31:35.322704Z"}
{"type":"l2update","product_id":"BTC-USD","changes":[["buy","9134.75","2969.87610000"]],"time":"2020-06-30T19:31:35.412432Z"}
{"type":"l2update","product_id":"BTC-USD","changes":[["buy","9132.66","0.00000000"]],"time":"2020-06-30T19:31:35.604949Z"}
{"type":"heartbeat","last_trade_id":0,"product_id":"BTC-USD","sequence":180761747,"time":"2020-06-30T19:31:35.735119Z"}
{"type":"l2update","product_id":"BTC-USD","changes":[["buy","9132.35","0.02770000"]],"time":"2020-06-30T19:31:35.957509Z"}
{"type":"l2update","product_id":"BTC-USD","changes":[["buy","9122.48","0.00000000"]],"time":"2020-06-30T19:31:36.398755Z"}
{"type":"l2update","product_id":"BTC-USD","changes":[["buy","9132.82","0.00000000"]],"time":"2020-06-30T19:31:36.402475Z"}
{"type":"heartbeat","last_trade_id":0,"product_id":"BTC-USD","sequence":180761751,"time":"2020-06-30T19:31:36.735115Z"}
{"type":"l2update","product_id":"BTC-USD","changes":[["buy","9131.98","0.33710000"]],"time":"2020-06-30T19:31:36.782251Z"}
{"type":"l2update","product_id":"BTC-USD","changes":[["buy","9122.58","0.09630000"]],"time":"2020-06-30T19:31:37.096026Z"}
{"type":"heartbeat","last_trade_id":0,"product_id":"BTC-USD","sequence":180761755,"time":"2020-06-30T19:31:37.735109Z"}
{"type":"l2update","product_id":"BTC-USD","changes":[["buy","9122.68","0.06570000"]],"time":"2020-06-30T19:31:38.250186Z"}
{"type":"l2update","product_id":"BTC-USD","changes":[["sell","9269.00","0.02200000"]],"time":"2020-06-30T19:31:38.600059Z"}
{"type":"l2update","product_id":"BTC-USD","changes":[["buy","9131.61","0.00000000"]],"time":"2020-06-30T19:31:38.687460Z"}
{"type":"heartbeat","last_trade_id":0,"product_id":"BTC-USD","sequence":180761760,"time":"2020-06-30T19:31:38.735132Z"}
{"type":"l2update","product_id":"BTC-USD","changes":[["sell","9144.03","0.00000000"]],"time":"2020-06-30T19:31:39.045405Z"}
{"type":"heartbeat","last_trade_id":0,"product_id":"BTC-USD","sequence":180761761,"time":"2020-06-30T19:31:39.735114Z"}
{"type":"l2update","product_id":"BTC-USD","changes":[["buy","9132.24","0.33710000"]],"time":"2020-06-30T19:31:39.770775Z"}
{"type":"l2update","product_id":"BTC-USD","changes":[["buy","8901.77","0.00000000"]],"time":"2020-06-30T19:31:39.802455Z"}
{"type":"l2update","product_id":"BTC-USD","changes":[["sell","9179.12","0.12300000"]],"time":"2020-06-30T19:31:40.045104Z"}
{"type":"l2update","product_id":"BTC-USD","changes":[["buy","8901.01","0.04557557"]],"time":"2020-06-30T19:31:40.094289Z"}
{"type":"l2update","product_id":"BTC-USD","changes":[["sell","9179.68","0.00000000"]],"time":"2020-06-30T19:31:40.265542Z"}
{"type":"l2update","product_id":"BTC-USD","changes":[["sell","9428.71","0.00000000"]],"time":"2020-06-30T19:31:40.309388Z"}
{"type":"l2update","product_id":"BTC-USD","changes":[["sell","9429.52","0.00634058"]],"time":"2020-06-30T19:31:40.534698Z"}
{"type":"l2update","product_id":"BTC-USD","changes":[["buy","9130.87","0.04000000"]],"time":"2020-06-30T19:31:40.652475Z"}
{"type":"heartbeat","last_trade_id":0,"product_id":"BTC-USD","sequence":180761774,"time":"2020-06-30T19:31:40.735126Z"}
{"type":"l2update","product_id":"BTC-USD","changes":[["sell","9134.77","2953.95500000"]],"time":"2020-06-30T19:31:40.880995Z"}
{"type":"l2update","product_id":"BTC-USD","changes":[["buy","9131.98","0.00000000"]],"time":"2020-06-30T19:31:41.053660Z"}
{"type":"l2update","product_id":"BTC-USD","changes":[["buy","9132.24","0.00000000"]],"time":"2020-06-30T19:31:41.057210Z"}
{"type":"l2update","product_id":"BTC-USD","changes":[["buy","9131.88","0.00000000"]],"time":"2020-06-30T19:31:41.063132Z"}
{"type":"l2update","product_id":"BTC-USD","changes":[["buy","9132.29","0.05000000"]],"time":"2020-06-30T19:31:41.418220Z"}
{"type":"heartbeat","last_trade_id":0,"product_id":"BTC-USD","sequence":180761782,"time":"2020-06-30T19:31:41.735114Z"}
{"type":"l2update","product_id":"BTC-USD","changes":[["buy","9132.41","0.25000000"]],"time":"2020-06-30T19:31:42.248656Z"}
{"type":"l2update","product_id":"BTC-USD","changes":[["buy","9132.35","0.00000000"]],"time":"2020-06-30T19:31:42.665446Z"}
{"type":"heartbeat","last_trade_id":0,"product_id":"BTC-USD","sequence":180761785,"time":"2020-06-30T19:31:42.735125Z"}
{"type":"l2update","product_id":"BTC-USD","changes":[["buy","9104.68","0.50000000"]],"time":"2020-06-30T19:31:43.098053Z"}
{"type":"l2update","product_id":"BTC-USD","changes":[["buy","9113.96","2.70000000"]],"time":"2020-06-30T19:31:43.377946Z"}
{"type":"l2update","product_id":"BTC-USD","changes":[["sell","9142.87","0.02360000"]],"time":"2020-06-30T19:31:43.656712Z"}
{"type":"heartbeat","last_trade_id":0,"product_id":"BTC-USD","sequence":180761791,"time":"2020-06-30T19:31:43.735118Z"}
{"type":"l2update","product_id":"BTC-USD","changes":[["sell","9138.33","0.00670000"]],"time":"2020-06-30T19:31:43.941072Z"}
{"type":"l2update","product_id":"BTC-USD","changes":[["buy","100.00","114.95500000"]],"time":"2020-06-30T19:31:44.037243Z"}
{"type":"l2update","product_id":"BTC-USD","changes":[["buy","100.00","114.94500000"]],"time":"2020-06-30T19:31:44.044066Z"}
{"type":"l2update","product_id":"BTC-USD","changes":[["sell","9269.00","0.00000000"]],"time":"2020-06-30T19:31:44.119793Z"}
{"type":"l2update","product_id":"BTC-USD","changes":[["sell","9147.51","0.00000000"]],"time":"2020-06-30T19:31:44.136329Z"}
{"type":"l2update","product_id":"BTC-USD","changes":[["sell","9179.41","0.00000000"]],"time":"2020-06-30T19:31:44.367411Z"}
{"type":"heartbeat","last_trade_id":0,"product_id":"BTC-USD","sequence":180761799,"time":"2020-06-30T19:31:44.735119Z"}
{"type":"l2update","product_id":"BTC-USD","changes":[["buy","9134.75","2969.73110000"]],"time":"2020-06-30T19:31:45.156945Z"}
{"type":"l2update","product_id":"BTC-USD","changes":[["buy","9125.60","0.00900000"]],"time":"2020-06-30T19:31:45.474008Z"}
{"type":"heartbeat","last_trade_id":0,"product_id":"BTC-USD","sequence":180761804,"time":"2020-06-30T19:31:45.735118Z"}
{"type":"l2update","product_id":"BTC-USD","changes":[["buy","9132.80","0.00000000"]],"time":"2020-06-30T19:31:45.872942Z"}
{"type":"l2update","product_id":"BTC-USD","changes":[["buy","9130.87","0.00000000"]],"time":"2020-06-30T19:31:45.872970Z"}
{"type":"l2update","product_id":"BTC-USD","changes":[["buy","9131.81","0.00000000"]],"time":"2020-06-30T19:31:45.880962Z"}
{"type":"heartbeat","last_trade_id":0,"product_id":"BTC-USD","sequence":180761807,"time":"2020-06-30T19:31:46.735078Z"}
{"type":"l2update","product_id":"BTC-USD","changes":[["buy","9133.06","0.02540000"]],"time":"2020-06-30T19:31:46.828076Z"}
{"type":"l2update","product_id":"BTC-USD","changes":[["buy","9131.85","0.00000000"]],"time":"2020-06-30T19:31:47.265900Z"}
{"type":"l2update","product_id":"BTC-USD","changes":[["buy","9122.68","0.00000000"]],"time":"2020-06-30T19:31:47.268508Z"}
{"type":"l2update","product_id":"BTC-USD","changes":[["buy","9130.92","0.00000000"]],"time":"2020-06-30T19:31:47.268620Z"}
{"type":"l2update","product_id":"BTC-USD","changes":[["buy","9122.57","0.13140000"]],"time":"2020-06-30T19:31:47.382340Z"}
{"type":"l2update","product_id":"BTC-USD","changes":[["buy","9133.10","0.12060000"]],"time":"2020-06-30T19:31:47.704744Z"}
{"type":"heartbeat","last_trade_id":0,"product_id":"BTC-USD","sequence":180761816,"time":"2020-06-30T19:31:47.735097Z"}
{"type":"l2update","product_id":"BTC-USD","changes":[["buy","9131.46","0.00000000"]],"time":"2020-06-30T19:31:47.827098Z"}
{"type":"l2update","product_id":"BTC-USD","changes":[["buy","9113.96","0.00000000"]],"time":"2020-06-30T19:31:47.835837Z"}
{"type":"l2update","product_id":"BTC-USD","changes":[["buy","9127.81","0.82050000"]],"time":"2020-06-30T19:31:47.989302Z"}
{"type":"l2update","product_id":"BTC-USD","changes":[["buy","9132.29","0.00000000"]],"time":"2020-06-30T19:31:48.453127Z"}
{"type":"heartbeat","last_trade_id":0,"product_id":"BTC-USD","sequence":180761821,"time":"2020-06-30T19:31:48.735111Z"}
{"type":"l2update","product_id":"BTC-USD","changes":[["sell","9173.13","0.01000000"]],"time":"2020-06-30T19:31:49.095399Z"}
{"type":"l2update","product_id":"BTC-USD","changes":[["buy","9132.05","0.16400000"]],"time":"2020-06-30T19:31:49.378635Z"}
{"type":"l2update","product_id":"BTC-USD","changes":[["sell","9177.79","0.00000000"]],"time":"2020-06-30T19:31:49.539233Z"}
{"type":"heartbeat","last_trade_id":0,"product_id":"BTC-USD","sequence":180761826,"time":"2020-06-30T19:31:49.735116Z"}
{"type":"l2update","product_id":"BTC-USD","changes":[["sell","9135.36","0.06570000"]],"time":"2020-06-30T19:31:49.930780Z"}
{"type":"l2update","product_id":"BTC-USD","changes":[["sell","9179.12","0.00000000"]],"time":"2020-06-30T19:31:50.380843Z"}
{"type":"l2update","product_id":"BTC-USD","changes":[["buy","9133.68","7.65000000"]],"time":"2020-06-30T19:31:50.498479Z"}
{"type":"heartbeat","last_trade_id":0,"product_id":"BTC-USD","sequence":180761831,"time":"2020-06-30T19:31:50.735117Z"}
{"type":"l2update","product_id":"BTC-USD","changes":[["buy","9125.60","0.00000000"]],"time":"2020-06-30T19:31:50.956642Z"}
{"type":"l2update","product_id":"BTC-USD","changes":[["buy","9132.67","0.75000000"]],"time":"2020-06-30T19:31:51.035555Z"}
{"type":"l2update","product_id":"BTC-USD","changes":[["buy","9111.52","0.05180000"]],"time":"2020-06-30T19:31:51.309296Z"}
{"type":"l2update","product_id":"BTC-USD","changes":[["buy","9122.57","0.06570000"]],"time":"2020-06-30T19:31:51.449394Z"}
{"type":"l2update","product_id":"BTC-USD","changes":[["sell","9145.81","0.03250000"]],"time":"2020-06-30T19:31:51.583211Z"}
{"type":"heartbeat","last_trade_id":0,"product_id":"BTC-USD","sequence":180761839,"time":"2020-06-30T19:31:51.735119Z"}
{"type":"l2update","product_id":"BTC-USD","changes":[["buy","9134.73","6028.50600000"]],"time":"2020-06-30T19:31:52.134150Z"}
{"type":"l2update","product_id":"BTC-USD","changes":[["buy","9130.99","0.00000000"]],"time":"2020-06-30T19:31:52.549016Z"}
{"type":"l2update","product_id":"BTC-USD","changes":[["sell","9134.77","2953.29170000"]],"time":"2020-06-30T19:31:52.704880Z"}
{"type":"heartbeat","last_trade_id":0,"product_id":"BTC-USD","sequence":180761845,"time":"2020-06-30T19:31:52.735121Z"}
{"type":"l2update","product_id":"BTC-USD","changes":[["buy","9123.69","0.06570000"]],"time":"2020-06-30T19:31:53.221305Z"}
{"type":"l2update","product_id":"BTC-USD","changes":[["buy","9110.92","0.08520000"]],"time":"2020-06-30T19:31:53.492161Z"}
{"type":"l2update","product_id":"BTC-USD","changes":[["buy","9133.06","0.00000000"]],"time":"2020-06-30T19:31:53.695273Z"}
{"type":"l2update","product_id":"BTC-USD","changes":[["buy","9131.67","0.00000000"]],"time":"2020-06-30T19:31:53.696484Z"}
{"type":"l2update","product_id":"BTC-USD","changes":[["buy","9133.10","0.00000000"]],"time":"2020-06-30T19:31:53.700209Z"}
{"type":"heartbeat","last_trade_id":0,"product_id":"BTC-USD","sequence":180761852,"time":"2020-06-30T19:31:53.735117Z"}
{"type":"l2update","product_id":"BTC-USD","changes":[["sell","9139.00","0.09780000"]],"time":"2020-06-30T19:31:53.808489Z"}
{"type":"l2update","product_id":"BTC-USD","changes":[["buy","9111.52","0.00000000"]],"time":"2020-06-30T19:31:53.943777Z"}
{"type":"l2update","product_id":"BTC-USD","changes":[["sell","9140.76","0.37040000"]],"time":"2020-06-30T19:31:54.038646Z"}
{"type":"l2update","product_id":"BTC-USD","changes":[["sell","9190.92","0.00000000"]],"time":"2020-06-30T19:31:54.225977Z"}
{"type":"l2update","product_id":"BTC-USD","changes":[["sell","9134.77","2952.74570000"]],"time":"2020-06-30T19:31:54.318481Z"}
{"type":"l2update","product_id":"BTC-USD","changes":[["sell","9179.05","0.00000000"]],"time":"2020-06-30T19:31:54.471085Z"}
{"type":"l2update","product_id":"BTC-USD","changes":[["sell","9138.33","0.00000000"]],"time":"2020-06-30T19:31:54.479528Z"}
{"type":"l2update","product_id":"BTC-USD","changes":[["sell","9139.00","0.00000000"]],"time":"2020-06-30T19:31:54.493052Z"}
{"type":"l2update","product_id":"BTC-USD","changes":[["sell","9189.98","15.05280000"]],"time":"2020-06-30T19:31:54.595354Z"}
{"type":"heartbeat","last_trade_id":0,"product_id":"BTC-USD","sequence":180761866,"time":"2020-06-30T19:31:54.735122Z"}
{"type":"l2update","product_id":"BTC-USD","changes":[["buy","9110.92","0.00000000"]],"time":"2020-06-30T19:31:54.764709Z"}
{"type":"l2update","product_id":"BTC-USD","changes":[["sell","9172.87","0.01000000"]],"time":"2020-06-30T19:31:54.934504Z"}
{"type":"l2update","product_id":"BTC-USD","changes":[["sell","9140.76","0.00000000"]],"time":"2020-06-30T19:31:55.074998Z"}
{"type":"l2update","product_id":"BTC-USD","changes":[["sell","9178.46","0.00000000"]],"time":"2020-06-30T19:31:55.077288Z"}
{"type":"l2update","product_id":"BTC-USD","changes":[["sell","9167.86","1.30840000"]],"time":"2020-06-30T19:31:55.146676Z"}
{"type":"l2update","product_id":"BTC-USD","changes":[["sell","9134.77","2952.58990000"]],"time":"2020-06-30T19:31:55.720695Z"}
{"type":"heartbeat","last_trade_id":0,"product_id":"BTC-USD","sequence":180761876,"time":"2020-06-30T19:31:55.735117Z"}
{"type":"l2update","product_id":"BTC-USD","changes":[["buy","9122.58","0.00000000"]],"time":"2020-06-30T19:31:56.178907Z"}
{"type":"heartbeat","last_trade_id":0,"product_id":"BTC-USD","sequence":180761877,"time":"2020-06-30T19:31:56.735118Z"}
{"type":"l2update","product_id":"BTC-USD","changes":[["sell","9134.77","2946.57020000"]],"time":"2020-06-30T19:31:57.400113Z"}
{"type":"l2update","product_id":"BTC-USD","changes":[["buy","9122.57","0.00000000"]],"time":"2020-06-30T19:31:57.614962Z"}
{"type":"l2update","product_id":"BTC-USD","changes":[["buy","9134.73","6020.00000000"]],"time":"2020-06-30T19:31:57.622181Z"}
{"type":"heartbeat","last_trade_id":0,"product_id":"BTC-USD","sequence":180761882,"time":"2020-06-30T19:31:57.735120Z"}
{"type":"l2update","product_id":"BTC-USD","changes":[["sell","9134.77","2936.82860000"]],"time":"2020-06-30T19:31:58.259412Z"}
{"type":"l2update","product_id":"BTC-USD","changes":[["buy","9132.21","0.02220000"]],"time":"2020-06-30T19:31:58.560771Z"}
{"type":"heartbeat","last_trade_id":0,"product_id":"BTC-USD","sequence":180761887,"time":"2020-06-30T19:31:58.735118Z"}
{"type":"l2update","product_id":"BTC-USD","changes":[["sell","9145.77","0.56290000"]],"time":"2020-06-30T19:31:58.834392Z"}
{"type":"l2update","product_id":"BTC-USD","changes":[["buy","9132.41","0.00000000"]],"time":"2020-06-30T19:31:59.033483Z"}
{"type":"l2update","product_id":"BTC-USD","changes":[["sell","9142.87","0.00000000"]],"time":"2020-06-30T19:31:59.063486Z"}
{"type":"l2update","product_id":"BTC-USD","changes":[["buy","100.00","114.95500000"]],"time":"2020-06-30T19:31:59.068762Z"}
{"type":"l2update","product_id":"BTC-USD","changes":[["buy","100.00","114.94500000"]],"time":"2020-06-30T19:31:59.074651Z"}
{"type":"l2update","product_id":"BTC-USD","changes":[["sell","9173.13","0.00000000"]],"time":"2020-06-30T19:31:59.109612Z"}
{"type":"l2update","product_id":"BTC-USD","changes":[["sell","9172.68","0.01000000"]],"time":"2020-06-30T19:31:59.171997Z"}
{"type":"heartbeat","last_trade_id":0,"product_id":"BTC-USD","sequence":180761897,"time":"2020-06-30T19:31:59.735111Z"}
{"type":"l2update","product_id":"BTC-USD","changes":[["sell","9140.96","0.48660000"]],"time":"2020-06-30T19:32:00.510358Z"}
{"type":"heartbeat","last_trade_id":0,"product_id":"BTC-USD","sequence":180761899,"time":"2020-06-30T19:32:00.735119Z"}
{"type":"l2update","product_id":"BTC-USD","changes":[["sell","9169.11","2.05460000"]],"time":"2020-06-30T19:32:00.814653Z"}
{"type":"l2update","product_id":"BTC-USD","changes":[["sell","9135.36","0.00000000"]],"time":"2020-06-30T19:32:00.989504Z"}
{"type":"l2update","product_id":"BTC-USD","changes":[["sell","9145.81","0.00000000"]],"time":"2020-06-30T19:32:01.059374Z"}
{"type":"l2update","product_id":"BTC-USD","changes":[["sell","9140.74","0.24100000"]],"time":"2020-06-30T19:32:01.358838Z"}
{"type":"heartbeat","last_trade_id":0,"product_id":"BTC-USD","sequence":180761905,"time":"2020-06-30T19:32:01.735027Z"}
{"type":"l2update","product_id":"BTC-USD","changes":[["sell","9148.14","0.02360000"]],"time":"2020-06-30T19:32:01.889292Z"}
{"type":"l2update","product_id":"BTC-USD","changes":[["sell","9140.74","0.00000000"]],"time":"2020-06-30T19:32:02.330403Z"}
{"type":"heartbeat","last_trade_id":0,"product_id":"BTC-USD","sequence":180761908,"time":"2020-06-30T19:32:02.735168Z"}
{"type":"l2update","product_id":"BTC-USD","changes":[["sell","9140.93","0.12940000"]],"time":"2020-06-30T19:32:02.818170Z"}
{"type":"l2update","product_id":"BTC-USD","changes":[["sell","9150.93","0.03250000"]],"time":"2020-06-30T19:32:03.650118Z"}
{"type":"heartbeat","last_trade_id":0,"product_id":"BTC-USD","sequence":180761912,"time":"2020-06-30T19:32:03.735118Z"}
{"type":"l2update","product_id":"BTC-USD","changes":[["sell","9189.98","0.00000000"]],"time":"2020-06-30T19:32:03.854823Z"}
{"type":"l2update","product_id":"BTC-USD","changes":[["buy","9116.59","0.02840000"]],"time":"2020-06-30T19:32:04.469182Z"}
{"type":"heartbeat","last_trade_id":0,"product_id":"BTC-USD","sequence":180761915,"time":"2020-06-30T19:32:04.735120Z"}
{"type":"l2update","product_id":"BTC-USD","changes":[["buy","9127.81","0.00000000"]],"time":"2020-06-30T19:32:04.939034Z"}
{"type":"l2update","product_id":"BTC-USD","changes":[["sell","9148.36","0.02360000"]],"time":"2020-06-30T19:32:05.036353Z"}
{"type":"l2update","product_id":"BTC-USD","changes":[["sell","9140.93","0.00000000"]],"time":"2020-06-30T19:32:05.305033Z"}
{"type":"l2update","product_id":"BTC-USD","changes":[["buy","9132.77","0.06560000"]],"time":"2020-06-30T19:32:05.361620Z"}
{"type":"l2update","product_id":"BTC-USD","changes":[["buy","9130.28","0.06560000"]],"time":"2020-06-30T19:32:05.602133Z"}
{"type":"heartbeat","last_trade_id":0,"product_id":"BTC-USD","sequence":180761923,"time":"2020-06-30T19:32:05.735121Z"}
{"type":"l2update","product_id":"BTC-USD","changes":[["buy","9132.77","0.00000000"]],"time":"2020-06-30T19:32:05.847880Z"}
{"type":"l2update","product_id":"BTC-USD","changes":[["buy","9123.69","0.00000000"]],"time":"2020-06-30T19:32:05.848407Z"}
{"type":"l2update","product_id":"BTC-USD","changes":[["sell","9134.77","2936.49150000"]],"time":"2020-06-30T19:32:05.870315Z"}
{"type":"l2update","product_id":"BTC-USD","changes":[["sell","9134.77","2936.44150000"]],"time":"2020-06-30T19:32:06.162804Z"}
{"type":"l2update","product_id":"BTC-USD","changes":[["sell","9134.77","2935.69150000"]],"time":"2020-06-30T19:32:06.704142Z"}
{"type":"heartbeat","last_trade_id":0,"product_id":"BTC-USD","sequence":180761934,"time":"2020-06-30T19:32:06.735116Z"}
{"type":"l2update","product_id":"BTC-USD","changes":[["buy","9132.67","0.00000000"]],"time":"2020-06-30T19:32:06.914687Z"}
{"type":"l2update","product_id":"BTC-USD","changes":[["sell","9144.18","1.25370000"]],"time":"2020-06-30T19:32:06.977771Z"}
{"type":"l2update","product_id":"BTC-USD","changes":[["sell","9134.77","2935.15150000"]],"time":"2020-06-30T19:32:07.555872Z"}
{"type":"heartbeat","last_trade_id":0,"product_id":"BTC-USD","sequence":180761940,"time":"2020-06-30T19:32:07.735120Z"}
{"type":"l2update","product_id":"BTC-USD","changes":[["buy","9132.53","0.00000000"]],"time":"2020-06-30T19:32:08.053553Z"}
{"type":"heartbeat","last_trade_id":0,"product_id":"BTC-USD","sequence":180761941,"time":"2020-06-30T19:32:08.735117Z"}
{"type":"l2update","product_id":"BTC-USD","changes":[["buy","9130.28","0.09620000"]],"time":"2020-06-30T19:32:08.986344Z"}
{"type":"l2update","product_id":"BTC-USD","changes":[["sell","9172.21","0.01000000"]],"time":"2020-06-30T19:32:09.253022Z"}
{"type":"l2update","product_id":"BTC-USD","changes":[["buy","9132.05","0.00000000"]],"time":"2020-06-30T19:32:09.431833Z"}
{"type":"l2update","product_id":"BTC-USD","changes":[["buy","9116.59","0.00000000"]],"time":"2020-06-30T19:32:09.434201Z"}
{"type":"l2update","product_id":"BTC-USD","changes":[["sell","9140.91","4.68550000"]],"time":"2020-06-30T19:32:09.550139Z"}
{"type":"l2update","product_id":"BTC-USD","changes":[["sell","9172.68","0.00000000"]],"time":"2020-06-30T19:32:09.733247Z"}
{"type":"heartbeat","last_trade_id":0,"product_id":"BTC-USD","sequence":180761950,"time":"2020-06-30T19:32:09.735116Z"}
{"type":"l2update","product_id":"BTC-USD","changes":[["sell","9145.77","0.00000000"]],"time":"2020-06-30T19:32:09.790573Z"}
{"type":"l2update","product_id":"BTC-USD","changes":[["sell","9140.91","9.49340000"]],"time":"2020-06-30T19:32:09.909143Z"}
{"type":"l2update","product_id":"BTC-USD","changes":[["sell","9172.21","0.00000000"]],"time":"2020-06-30T19:32:09.961487Z"}
{"type":"l2update","product_id":"BTC-USD","changes":[["sell","9148.36","0.00000000"]],"time":"2020-06-30T19:32:09.962910Z"}
{"type":"heartbeat","last_trade_id":0,"product_id":"BTC-USD","sequence":180761955,"time":"2020-06-30T19:32:10.735118Z"}
{"type":"l2update","product_id":"BTC-USD","changes":[["buy","9134.75","2969.73010000"]],"time":"2020-06-30T19:32:10.869262Z"}
{"type":"heartbeat","last_trade_id":0,"product_id":"BTC-USD","sequence":180761958,"time":"2020-06-30T19:32:11.735115Z"}
{"type":"l2update","product_id":"BTC-USD","changes":[["sell","9134.77","2935.11150000"]],"time":"2020-06-30T19:32:12.376148Z"}
{"type":"heartbeat","last_trade_id":0,"product_id":"BTC-USD","sequence":180761961,"time":"2020-06-30T19:32:12.735088Z"}
{"type":"l2update","product_id":"BTC-USD","changes":[["sell","9140.91","17.39120000"]],"time":"2020-06-30T19:32:12.798743Z"}
{"type":"l2update","product_id":"BTC-USD","changes":[["buy","9131.00","0.00000000"]],"time":"2020-06-30T19:32:12.838718Z"}
{"type":"l2update","product_id":"BTC-USD","changes":[["sell","9134.77","2935.06220000"]],"time":"2020-06-30T19:32:13.042777Z"}
{"type":"l2update","product_id":"BTC-USD","changes":[["sell","9140.96","0.00000000"]],"time":"2020-06-30T19:32:13.236845Z"}
{"type":"heartbeat","last_trade_id":0,"product_id":"BTC-USD","sequence":180761968,"time":"2020-06-30T19:32:13.735101Z"}
{"type":"l2update","product_id":"BTC-USD","changes":[["buy","100.00","114.95500000"]],"time":"2020-06-30T19:32:14.048950Z"}
{"type":"l2update","product_id":"BTC-USD","changes":[["buy","100.00","114.94500000"]],"time":"2020-06-30T19:32:14.055558Z"}
{"type":"l2update","product_id":"BTC-USD","changes":[["sell","9134.77","2935.00820000"]],"time":"2020-06-30T19:32:14.182553Z"}
{"type":"l2update","product_id":"BTC-USD","changes":[["buy","9122.73","0.00000000"]],"time":"2020-06-30T19:32:14.621841Z"}
{"type":"l2update","product_id":"BTC-USD","changes":[["buy","9133.68","0.00000000"]],"time":"2020-06-30T19:32:14.624812Z"}
{"type":"l2update","product_id":"BTC-USD","changes":[["sell","9139.29","0.07100000"]],"time":"2020-06-30T19:32:14.729568Z"}
{"type":"heartbeat","last_trade_id":0,"product_id":"BTC-USD","sequence":180761978,"time":"2020-06-30T19:32:14.735113Z"}
{"type":"l2update","product_id":"BTC-USD","changes":[["sell","9140.91","9.49340000"]],"time":"2020-06-30T19:32:14.991775Z"}
{"type":"l2update","product_id":"BTC-USD","changes":[["sell","9172.87","0.00000000"]],"time":"2020-06-30T19:32:14.993751Z"}
{"type":"l2update","product_id":"BTC-USD","changes":[["buy","9128.10","0.03060000"]],"time":"2020-06-30T19:32:15.026736Z"}
{"type":"l2update","product_id":"BTC-USD","changes":[["sell","9134.77","2934.95820000"]],"time":"2020-06-30T19:32:15.556400Z"}
{"type":"heartbeat","last_trade_id":0,"product_id":"BTC-USD","sequence":180761985,"time":"2020-06-30T19:32:15.735121Z"}
{"type":"l2update","product_id":"BTC-USD","changes":[["sell","9134.77","2930.95820000"]],"time":"2020-06-30T19:32:15.837778Z"}
{"type":"l2update","product_id":"BTC-USD","changes":[["buy","9130.28","0.06560000"]],"time":"2020-06-30T19:32:16.020424Z"}
{"type":"l2update","product_id":"BTC-USD","changes":[["sell","9134.77","2930.87550000"]],"time":"2020-06-30T19:32:16.103210Z"}
{"type":"l2update","product_id":"BTC-USD","changes":[["buy","9104.68","0.00000000"]],"time":"2020-06-30T19:32:16.252371Z"}
{"type":"l2update","product_id":"BTC-USD","changes":[["sell","9134.77","2930.12550000"]],"time":"2020-06-30T19:32:16.660244Z"}
{"type":"heartbeat","last_trade_id":0,"product_id":"BTC-USD","sequence":180761996,"time":"2020-06-30T19:32:16.735117Z"}
{"type":"l2update","product_id":"BTC-USD","changes":[["sell","9134.77","2929.62550000"]],"time":"2020-06-30T19:32:16.943731Z"}
{"type":"l2update","product_id":"BTC-USD","changes":[["buy","9128.15","0.06570000"]],"time":"2020-06-30T19:32:17.715791Z"}
{"type":"heartbeat","last_trade_id":0,"product_id":"BTC-USD","sequence":180762001,"time":"2020-06-30T19:32:17.735120Z"}
{"type":"l2update","product_id":"BTC-USD","changes":[["sell","9139.31","0.25520000"]],"time":"2020-06-30T19:32:18.314328Z"}
{"type":"heartbeat","last_trade_id":0,"product_id":"BTC-USD","sequence":180762003,"time":"2020-06-30T19:32:18.735131Z"}
{"type":"l2update","product_id":"BTC-USD","changes":[["buy","9130.50","0.02220000"]],"time":"2020-06-30T19:32:18.853024Z"}
{"type":"l2update","product_id":"BTC-USD","changes":[["sell","9134.77","2929.02550000"]],"time":"2020-06-30T19:32:19.407866Z"}
{"type":"heartbeat","last_trade_id":0,"product_id":"BTC-USD","sequence":180762008,"time":"2020-06-30T19:32:19.735113Z"}
{"type":"l2update","product_id":"BTC-USD","changes":[["sell","9144.69","1.55540000"]],"time":"2020-06-30T19:32:19.751336Z"}
{"type":"l2update","product_id":"BTC-USD","changes":[["sell","9144.18","0.00000000"]],"time":"2020-06-30T19:32:20.193386Z"}
{"type":"l2update","product_id":"BTC-USD","changes":[["sell","9167.86","0.00000000"]],"time":"2020-06-30T19:32:20.208687Z"}
{"type":"l2update","product_id":"BTC-USD","changes":[["sell","9139.29","0.00000000"]],"time":"2020-06-30T19:32:20.210655Z"}
{"type":"l2update","product_id":"BTC-USD","changes":[["sell","9384.05","0.00400000"]],"time":"2020-06-30T19:32:20.335861Z"}
{"type":"l2update","product_id":"BTC-USD","changes":[["sell","9139.31","0.00000000"]],"time":"2020-06-30T19:32:20.512589Z"}
{"type":"heartbeat","last_trade_id":0,"product_id":"BTC-USD","sequence":180762016,"time":"2020-06-30T19:32:20.735112Z"}
{"type":"l2update","product_id":"BTC-USD","changes":[["buy","9130.28","0.00000000"]],"time":"2020-06-30T19:32:21.175406Z"}
{"type":"l2update","product_id":"BTC-USD","changes":[["buy","9130.64","0.02220000"]],"time":"2020-06-30T19:32:21.215355Z"}
{"type":"l2update","product_id":"BTC-USD","changes":[["buy","9128.42","0.06570000"]],"time":"2020-06-30T19:32:21.509498Z"}
{"type":"l2update","product_id":"BTC-USD","changes":[["buy","9132.55","0.00000000"]],"time":"2020-06-30T19:32:21.635854Z"}
{"type":"heartbeat","last_trade_id":0,"product_id":"BTC-USD","sequence":180762022,"time":"2020-06-30T19:32:21.735014Z"}
{"type":"l2update","product_id":"BTC-USD","changes":[["sell","9134.77","2928.27550000"]],"time":"2020-06-30T19:32:22.137741Z"}
{"type":"l2update","product_id":"BTC-USD","changes":[["buy","9130.64","0.00000000"]],"time":"2020-06-30T19:32:22.568674Z"}
{"type":"heartbeat","last_trade_id":0,"product_id":"BTC-USD","sequence":180762026,"time":"2020-06-30T19:32:22.735170Z"}
{"type":"l2update","product_id":"BTC-USD","changes":[["sell","9142.34","0.98750000"]],"time":"2020-06-30T19:32:22.928091Z"}
{"type":"l2update","product_id":"BTC-USD","changes":[["sell","9169.11","0.00000000"]],"time":"2020-06-30T19:32:23.387250Z"}
{"type":"l2update","product_id":"BTC-USD","changes":[["sell","9134.77","2928.15400000"]],"time":"2020-06-30T19:32:23.486258Z"}
{"type":"heartbeat","last_trade_id":0,"product_id":"BTC-USD","sequence":180762032,"time":"2020-06-30T19:32:23.735115Z"}
{"type":"l2update","product_id":"BTC-USD","changes":[["sell","9165.64","2.10890000"]],"time":"2020-06-30T19:32:23.750723Z"}
{"type":"l2update","product_id":"BTC-USD","changes":[["sell","9181.76","0.06880000"]],"time":"2020-06-30T19:32:24.033533Z"}
{"type":"l2update","product_id":"BTC-USD","changes":[["sell","9148.14","0.00000000"]],"time":"2020-06-30T19:32:24.203296Z"}
{"type":"heartbeat","last_trade_id":0,"product_id":"BTC-USD","sequence":180762037,"time":"2020-06-30T19:32:24.735123Z"}
{"type":"l2update","product_id":"BTC-USD","changes":[["sell","9140.87","0.56590000"]],"time":"2020-06-30T19:32:25.126126Z"}
{"type":"l2update","product_id":"BTC-USD","changes":[["sell","9384.05","0.00000000"]],"time":"2020-06-30T19:32:25.353569Z"}
{"type":"l2update","product_id":"BTC-USD","changes":[["sell","9169.57","1.25920000"]],"time":"2020-06-30T19:32:25.727148Z"}
{"type":"heartbeat","last_trade_id":0,"product_id":"BTC-USD","sequence":180762042,"time":"2020-06-30T19:32:25.735114Z"}
{"type":"l2update","product_id":"BTC-USD","changes":[["sell","9161.60","1.03310000"]],"time":"2020-06-30T19:32:25.991923Z"}
{"type":"l2update","product_id":"BTC-USD","changes":[["buy","9110.14","0.00200000"]],"time":"2020-06-30T19:32:26.267991Z"}
{"type":"l2update","product_id":"BTC-USD","changes":[["buy","9130.42","0.06570000"]],"time":"2020-06-30T19:32:26.546898Z"}
{"type":"heartbeat","last_trade_id":0,"product_id":"BTC-USD","sequence":180762048,"time":"2020-06-30T19:32:26.735118Z"}
{"type":"l2update","product_id":"BTC-USD","changes":[["buy","9130.45","0.02220000"]],"time":"2020-06-30T19:32:27.126230Z"}
{"type":"l2update","product_id":"BTC-USD","changes":[["sell","9134.77","2927.55260000"]],"time":"2020-06-30T19:32:27.387329Z"}
{"type":"l2update","product_id":"BTC-USD","changes":[["buy","9128.15","0.00000000"]],"time":"2020-06-30T19:32:27.536304Z"}
{"type":"l2update","product_id":"BTC-USD","changes":[["sell","9134.77","2927.00260000"]],"time":"2020-06-30T19:32:27.675359Z"}
{"type":"heartbeat","last_trade_id":0,"product_id":"BTC-USD","sequence":180762057,"time":"2020-06-30T19:32:27.735118Z"}
{"type":"heartbeat","last_trade_id":0,"product_id":"BTC-USD","sequence":180762057,"time":"2020-06-30T19:32:28.735121Z"}
{"type":"l2update","product_id":"BTC-USD","changes":[["buy","100.00","114.95500000"]],"time":"2020-06-30T19:32:29.042176Z"}
{"type":"l2update","product_id":"BTC-USD","changes":[["buy","100.00","114.94500000"]],"time":"2020-06-30T19:32:29.047902Z"}
{"type":"l2update","product_id":"BTC-USD","changes":[["sell","9165.64","0.00000000"]],"time":"2020-06-30T19:32:29.175079Z"}
{"type":"heartbeat","last_trade_id":0,"product_id":"BTC-USD","sequence":180762061,"time":"2020-06-30T19:32:29.735113Z"}
{"type":"l2update","product_id":"BTC-USD","changes":[["sell","9178.65","0.06890000"]],"time":"2020-06-30T19:32:29.786154Z"}
{"type":"l2update","product_id":"BTC-USD","changes":[["sell","9144.69","0.00000000"]],"time":"2020-06-30T19:32:30.208304Z"}
{"type":"heartbeat","last_trade_id":0,"product_id":"BTC-USD","sequence":180762064,"time":"2020-06-30T19:32:30.735117Z"}
{"type":"heartbeat","last_trade_id":0,"product_id":"BTC-USD","sequence":180762064,"time":"2020-06-30T19:32:31.735109Z"}
{"type":"l2update","product_id":"BTC-USD","changes":[["sell","9134.77","2926.95120000"]],"time":"2020-06-30T19:32:31.758050Z"}
{"type":"l2update","product_id":"BTC-USD","changes":[["sell","9134.77","2926.89980000"]],"time":"2020-06-30T19:32:32.579756Z"}
{"type":"heartbeat","last_trade_id":0,"product_id":"BTC-USD","sequence":180762070,"time":"2020-06-30T19:32:32.735121Z"}
{"type":"l2update","product_id":"BTC-USD","changes":[["sell","9134.77","2926.84980000"]],"time":"2020-06-30T19:32:32.856700Z"}
{"type":"l2update","product_id":"BTC-USD","changes":[["buy","9130.50","0.00000000"]],"time":"2020-06-30T19:32:32.991090Z"}
{"type":"l2update","product_id":"BTC-USD","changes":[["buy","9128.42","0.00000000"]],"time":"2020-06-30T19:32:32.995808Z"}
{"type":"l2update","product_id":"BTC-USD","changes":[["buy","9130.24","0.02220000"]],"time":"2020-06-30T19:32:33.113073Z"}
{"type":"l2update","product_id":"BTC-USD","changes":[["sell","9134.77","2926.79980000"]],"time":"2020-06-30T19:32:33.413986Z"}
{"type":"heartbeat","last_trade_id":0,"product_id":"BTC-USD","sequence":180762080,"time":"2020-06-30T19:32:33.735110Z"}
{"type":"l2update","product_id":"BTC-USD","changes":[["buy","9130.25","0.06570000"]],"time":"2020-06-30T19:32:34.199330Z"}
{"type":"l2update","product_id":"BTC-USD","changes":[["buy","9130.27","0.06570000"]],"time":"2020-06-30T19:32:34.503589Z"}
{"type":"heartbeat","last_trade_id":0,"product_id":"BTC-USD","sequence":180762084,"time":"2020-06-30T19:32:34.735114Z"}
{"type":"l2update","product_id":"BTC-USD","changes":[["sell","9134.77","2926.24980000"]],"time":"2020-06-30T19:32:35.344223Z"}
{"type":"l2update","product_id":"BTC-USD","changes":[["buy","9120.22","0.95920000"]],"time":"2020-06-30T19:32:35.618066Z"}
{"type":"heartbeat","last_trade_id":0,"product_id":"BTC-USD","sequence":180762089,"time":"2020-06-30T19:32:35.735121Z"}
{"type":"l2update","product_id":"BTC-USD","changes":[["sell","9140.27","0.05000000"]],"time":"2020-06-30T19:32:36.433138Z"}
{"type":"heartbeat","last_trade_id":0,"product_id":"BTC-USD","sequence":180762091,"time":"2020-06-30T19:32:36.735117Z"}
{"type":"l2update","product_id":"BTC-USD","changes":[["sell","9140.87","0.00000000"]],"time":"2020-06-30T19:32:36.847766Z"}
{"type":"l2update","product_id":"BTC-USD","changes":[["sell","9140.27","0.10000000"]],"time":"2020-06-30T19:32:36.991238Z"}
{"type":"l2update","product_id":"BTC-USD","changes":[["sell","9140.91","4.80790000"]],"time":"2020-06-30T19:32:37.418408Z"}
{"type":"l2update","product_id":"BTC-USD","changes":[["buy","8901.01","0.00000000"]],"time":"2020-06-30T19:32:37.483209Z"}
{"type":"l2update","product_id":"BTC-USD","changes":[["buy","9128.68","0.03060000"]],"time":"2020-06-30T19:32:37.554587Z"}
{"type":"l2update","product_id":"BTC-USD","changes":[["buy","8900.26","0.04566912"]],"time":"2020-06-30T19:32:37.686222Z"}
{"type":"heartbeat","last_trade_id":0,"product_id":"BTC-USD","sequence":180762100,"time":"2020-06-30T19:32:37.735111Z"}
{"type":"l2update","product_id":"BTC-USD","changes":[["buy","9126.43","0.06570000"]],"time":"2020-06-30T19:32:37.844605Z"}
{"type":"l2update","product_id":"BTC-USD","changes":[["sell","9429.52","0.00000000"]],"time":"2020-06-30T19:32:38.025625Z"}
{"type":"l2update","product_id":"BTC-USD","changes":[["sell","9134.77","2926.19840000"]],"time":"2020-06-30T19:32:38.120867Z"}
{"type":"l2update","product_id":"BTC-USD","changes":[["sell","9430.32","0.00643214"]],"time":"2020-06-30T19:32:38.223904Z"}
{"type":"l2update","product_id":"BTC-USD","changes":[["sell","9140.86","0.04360000"]],"time":"2020-06-30T19:32:38.393152Z"}
{"type":"heartbeat","last_trade_id":0,"product_id":"BTC-USD","sequence":180762110,"time":"2020-06-30T19:32:38.735115Z"}
{"type":"l2update","product_id":"BTC-USD","changes":[["buy","9130.24","0.00000000"]],"time":"2020-06-30T19:32:39.104224Z"}
{"type":"l2update","product_id":"BTC-USD","changes":[["sell","9161.60","2.22520000"]],"time":"2020-06-30T19:32:39.270240Z"}
{"type":"l2update","product_id":"BTC-USD","changes":[["sell","9140.27","0.05000000"]],"time":"2020-06-30T19:32:39.454540Z"}
{"type":"l2update","product_id":"BTC-USD","changes":[["sell","9140.27","0.00000000"]],"time":"2020-06-30T19:32:39.457633Z"}
{"type":"heartbeat","last_trade_id":0,"product_id":"BTC-USD","sequence":180762115,"time":"2020-06-30T19:32:39.735113Z"}
{"type":"l2update","product_id":"BTC-USD","changes":[["buy","9130.22","0.02220000"]],"time":"2020-06-30T19:32:40.649479Z"}
{"type":"heartbeat","last_trade_id":0,"product_id":"BTC-USD","sequence":180762117,"time":"2020-06-30T19:32:40.735122Z"}
{"type":"l2update","product_id":"BTC-USD","changes":[["sell","9134.77","2926.19740000"]],"time":"2020-06-30T19:32:41.468550Z"}
{"type":"l2update","product_id":"BTC-USD","changes":[["sell","9134.77","2926.15740000"]],"time":"2020-06-30T19:32:41.532414Z"}
{"type":"heartbeat","last_trade_id":0,"product_id":"BTC-USD","sequence":180762123,"time":"2020-06-30T19:32:41.735119Z"}
{"type":"l2update","product_id":"BTC-USD","changes":[["sell","9198.79","0.06880000"]],"time":"2020-06-30T19:32:41.810277Z"}
{"type":"l2update","product_id":"BTC-USD","changes":[["buy","9132.21","0.00000000"]],"time":"2020-06-30T19:32:41.992567Z"}
{"type":"l2update","product_id":"BTC-USD","changes":[["buy","9130.25","0.00000000"]],"time":"2020-06-30T19:32:42.023947Z"}
{"type":"l2update","product_id":"BTC-USD","changes":[["buy","9130.31","0.06570000"]],"time":"2020-06-30T19:32:42.086290Z"}
{"type":"l2update","product_id":"BTC-USD","changes":[["sell","9150.93","0.00000000"]],"time":"2020-06-30T19:32:42.246513Z"}
{"type":"l2update","product_id":"BTC-USD","changes":[["sell","9198.49","0.06880000"]],"time":"2020-06-30T19:32:42.365345Z"}
{"type":"l2update","product_id":"BTC-USD","changes":[["buy","9130.34","0.02220000"]],"time":"2020-06-30T19:32:42.638898Z"}
{"type":"heartbeat","last_trade_id":0,"product_id":"BTC-USD","sequence":180762134,"time":"2020-06-30T19:32:42.735119Z"}
{"type":"l2update","product_id":"BTC-USD","changes":[["sell","9198.79","0.00000000"]],"time":"2020-06-30T19:32:42.787575Z"}
{"type":"l2update","product_id":"BTC-USD","changes":[["sell","9134.77","2925.57880000"]],"time":"2020-06-30T19:32:42.927890Z"}
{"type":"l2update","product_id":"BTC-USD","changes":[["sell","9134.77","2925.00020000"]],"time":"2020-06-30T19:32:43.236503Z"}
{"type":"heartbeat","last_trade_id":0,"product_id":"BTC-USD","sequence":180762141,"time":"2020-06-30T19:32:43.735123Z"}
{"type":"l2update","product_id":"BTC-USD","changes":[["buy","100.00","114.95500000"]],"time":"2020-06-30T19:32:44.018872Z"}
{"type":"l2update","product_id":"BTC-USD","changes":[["buy","100.00","114.94500000"]],"time":"2020-06-30T19:32:44.025991Z"}
{"type":"l2update","product_id":"BTC-USD","changes":[["buy","9128.69","0.03060000"]],"time":"2020-06-30T19:32:44.065960Z"}
{"type":"l2update","product_id":"BTC-USD","changes":[["buy","9128.73","0.03060000"]],"time":"2020-06-30T19:32:44.637951Z"}
{"type":"heartbeat","last_trade_id":0,"product_id":"BTC-USD","sequence":180762148,"time":"2020-06-30T19:32:44.735115Z"}
{"type":"l2update","product_id":"BTC-USD","changes":[["sell","9197.30","0.00100000"]],"time":"2020-06-30T19:32:44.920822Z"}
{"type":"l2update","product_id":"BTC-USD","changes":[["sell","9198.49","0.00000000"]],"time":"2020-06-30T19:32:45.135423Z"}
{"type":"l2update","product_id":"BTC-USD","changes":[["sell","9178.65","0.00000000"]],"time":"2020-06-30T19:32:45.147259Z"}
{"type":"l2update","product_id":"BTC-USD","changes":[["sell","9139.31","0.43260000"]],"time":"2020-06-30T19:32:45.549080Z"}
{"type":"heartbeat","last_trade_id":0,"product_id":"BTC-USD","sequence":180762154,"time":"2020-06-30T19:32:45.735110Z"}
{"type":"l2update","product_id":"BTC-USD","changes":[["buy","9126.39","0.08790000"]],"time":"2020-06-30T19:32:45.812056Z"}
{"type":"l2update","product_id":"BTC-USD","changes":[["buy","9126.41","0.02220000"]],"time":"2020-06-30T19:32:46.369344Z"}
{"type":"l2update","product_id":"BTC-USD","changes":[["sell","9134.77","2924.29660000"]],"time":"2020-06-30T19:32:46.522269Z"}
{"type":"heartbeat","last_trade_id":0,"product_id":"BTC-USD","sequence":180762161,"time":"2020-06-30T19:32:46.735060Z"}
{"type":"l2update","product_id":"BTC-USD","changes":[["buy","9130.42","0.00000000"]],"time":"2020-06-30T19:32:46.797980Z"}
{"type":"l2update","product_id":"BTC-USD","changes":[["buy","9126.44","0.06570000"]],"time":"2020-06-30T19:32:46.984981Z"}
{"type":"l2update","product_id":"BTC-USD","changes":[["buy","9117.40","0.01000000"]],"time":"2020-06-30T19:32:47.253659Z"}
{"type":"heartbeat","last_trade_id":0,"product_id":"BTC-USD","sequence":180762166,"time":"2020-06-30T19:32:47.735114Z"}
{"type":"heartbeat","last_trade_id":0,"product_id":"BTC-USD","sequence":180762166,"time":"2020-06-30T19:32:48.735067Z"}
{"type":"heartbeat","last_trade_id":0,"product_id":"BTC-USD","sequence":180762166,"time":"2020-06-30T19:32:49.735114Z"}
{"type":"l2update","product_id":"BTC-USD","changes":[["buy","9128.81","0.06570000"]],"time":"2020-06-30T19:32:50.263552Z"}
{"type":"l2update","product_id":"BTC-USD","changes":[["buy","9126.41","0.00000000"]],"time":"2020-06-30T19:32:50.492948Z"}
{"type":"heartbeat","last_trade_id":0,"product_id":"BTC-USD","sequence":180762169,"time":"2020-06-30T19:32:50.735123Z"}
{"type":"l2update","product_id":"BTC-USD","changes":[["sell","9139.31","4.89350000"]],"time":"2020-06-30T19:32:51.114181Z"}
{"type":"l2update","product_id":"BTC-USD","changes":[["sell","9166.23","1.24000000"]],"time":"2020-06-30T19:32:51.650244Z"}
{"type":"heartbeat","last_trade_id":0,"product_id":"BTC-USD","sequence":180762173,"time":"2020-06-30T19:32:51.735059Z"}
{"type":"l2update","product_id":"BTC-USD","changes":[["sell","9142.34","0.00000000"]],"time":"2020-06-30T19:32:52.112855Z"}
{"type":"l2update","product_id":"BTC-USD","changes":[["sell","9140.86","0.00000000"]],"time":"2020-06-30T19:32:52.113073Z"}
{"type":"l2update","product_id":"BTC-USD","changes":[["sell","9139.31","0.43260000"]],"time":"2020-06-30T19:32:52.115325Z"}
{"type":"l2update","product_id":"BTC-USD","changes":[["sell","9140.91","0.00000000"]],"time":"2020-06-30T19:32:52.208283Z"}
{"type":"l2update","product_id":"BTC-USD","changes":[["sell","9148.53","0.02360000"]],"time":"2020-06-30T19:32:52.533880Z"}
{"type":"heartbeat","last_trade_id":0,"product_id":"BTC-USD","sequence":180762179,"time":"2020-06-30T19:32:52.735089Z"}
{"type":"l2update","product_id":"BTC-USD","changes":[["sell","9161.60","1.19210000"]],"time":"2020-06-30T19:32:52.962951Z"}
{"type":"heartbeat","last_trade_id":0,"product_id":"BTC-USD","sequence":180762180,"time":"2020-06-30T19:32:53.735110Z"}
{"type":"l2update","product_id":"BTC-USD","changes":[["sell","9134.77","2923.96250000"]],"time":"2020-06-30T19:32:54.027250Z"}
{"type":"l2update","product_id":"BTC-USD","changes":[["sell","9134.77","2923.92250000"]],"time":"2020-06-30T19:32:54.306543Z"}
{"type":"l2update","product_id":"BTC-USD","changes":[["buy","9128.10","0.00000000"]],"time":"2020-06-30T19:32:54.506854Z"}
{"type":"l2update","product_id":"BTC-USD","changes":[["sell","9200.35","0.03960000"]],"time":"2020-06-30T19:32:54.619869Z"}
{"type":"l2update","product_id":"BTC-USD","changes":[["buy","9117.40","0.00000000"]],"time":"2020-06-30T19:32:54.734960Z"}
{"type":"heartbeat","last_trade_id":0,"product_id":"BTC-USD","sequence":180762190,"time":"2020-06-30T19:32:54.735118Z"}
{"type":"l2update","product_id":"BTC-USD","changes":[["sell","9169.57","0.00000000"]],"time":"2020-06-30T19:32:55.077692Z"}
{"type":"l2update","product_id":"BTC-USD","changes":[["sell","9181.76","0.00000000"]],"time":"2020-06-30T19:32:55.077956Z"}
{"type":"l2update","product_id":"BTC-USD","changes":[["sell","9161.60","0.00000000"]],"time":"2020-06-30T19:32:55.085640Z"}
{"type":"l2update","product_id":"BTC-USD","changes":[["sell","9134.77","2923.87110000"]],"time":"2020-06-30T19:32:55.742265Z"}
{"type":"heartbeat","last_trade_id":0,"product_id":"BTC-USD","sequence":180762196,"time":"2020-06-30T19:32:55.735067Z"}
{"type":"l2update","product_id":"BTC-USD","changes":[["sell","9200.44","0.00100000"]],"time":"2020-06-30T19:32:56.129409Z"}
{"type":"heartbeat","last_trade_id":0,"product_id":"BTC-USD","sequence":180762198,"time":"2020-06-30T19:32:56.735116Z"}
{"type":"l2update","product_id":"BTC-USD","changes":[["sell","9197.30","0.00000000"]],"time":"2020-06-30T19:32:56.769388Z"}
{"type":"l2update","product_id":"BTC-USD","changes":[["sell","9134.77","2923.64690000"]],"time":"2020-06-30T19:32:57.311642Z"}
{"type":"l2update","product_id":"BTC-USD","changes":[["sell","9143.86","1.50000000"]],"time":"2020-06-30T19:32:57.574996Z"}
{"type":"heartbeat","last_trade_id":0,"product_id":"BTC-USD","sequence":180762204,"time":"2020-06-30T19:32:57.735118Z"}
{"type":"l2update","product_id":"BTC-USD","changes":[["buy","9126.39","0.00000000"]],"time":"2020-06-30T19:32:57.749001Z"}
{"type":"l2update","product_id":"BTC-USD","changes":[["sell","9134.77","2923.23880000"]],"time":"2020-06-30T19:32:58.184144Z"}
{"type":"heartbeat","last_trade_id":0,"product_id":"BTC-USD","sequence":180762208,"time":"2020-06-30T19:32:58.735100Z"}
{"type":"l2update","product_id":"BTC-USD","changes":[["buy","9128.69","0.00000000"]],"time":"2020-06-30T19:32:58.749168Z"}
{"type":"l2update","product_id":"BTC-USD","changes":[["buy","9130.45","0.00000000"]],"time":"2020-06-30T19:32:58.763572Z"}
{"type":"l2update","product_id":"BTC-USD","changes":[["buy","9130.22","0.00000000"]],"time":"2020-06-30T19:32:58.767778Z"}
{"type":"l2update","product_id":"BTC-USD","changes":[["buy","100.00","114.95500000"]],"time":"2020-06-30T19:32:59.035725Z"}
{"type":"l2update","product_id":"BTC-USD","changes":[["buy","100.00","114.94500000"]],"time":"2020-06-30T19:32:59.042334Z"}
{"type":"l2update","product_id":"BTC-USD","changes":[["sell","9140.48","4.35230000"]],"time":"2020-06-30T19:32:59.313804Z"}
{"type":"heartbeat","last_trade_id":0,"product_id":"BTC-USD","sequence":180762216,"time":"2020-06-30T19:32:59.735093Z"}
{"type":"l2update","product_id":"BTC-USD","changes":[["sell","9143.82","1.50000000"]],"time":"2020-06-30T19:32:59.791188Z"}
{"type":"l2update","product_id":"BTC-USD","changes":[["buy","9078.09","0.08760000"]],"time":"2020-06-30T19:33:00.148409Z"}
{"type":"l2update","product_id":"BTC-USD","changes":[["sell","9140.48","0.00000000"]],"time":"2020-06-30T19:33:00.274080Z"}
{"type":"heartbeat","last_trade_id":0,"product_id":"BTC-USD","sequence":180762221,"time":"2020-06-30T19:33:00.735113Z"}
{"type":"l2update","product_id":"BTC-USD","changes":[["sell","9143.80","1.50000000"]],"time":"2020-06-30T19:33:00.829004Z"}
{"type":"l2update","product_id":"BTC-USD","changes":[["sell","9140.48","4.27940000"]],"time":"2020-06-30T19:33:01.139942Z"}
{"type":"l2update","product_id":"BTC-USD","changes":[["sell","9200.35","0.00000000"]],"time":"2020-06-30T19:33:01.286742Z"}
{"type":"heartbeat","last_trade_id":0,"product_id":"BTC-USD","sequence":180762226,"time":"2020-06-30T19:33:01.735075Z"}
{"type":"l2update","product_id":"BTC-USD","changes":[["sell","9134.77","2922.83210000"]],"time":"2020-06-30T19:33:01.913595Z"}
{"type":"l2update","product_id":"BTC-USD","changes":[["buy","9130.27","0.00000000"]],"time":"2020-06-30T19:33:02.454006Z"}
{"type":"l2update","product_id":"BTC-USD","changes":[["buy","9128.81","0.00000000"]],"time":"2020-06-30T19:33:02.479499Z"}
{"type":"l2update","product_id":"BTC-USD","changes":[["sell","9140.48","8.34500000"]],"time":"2020-06-30T19:33:02.502618Z"}
{"type":"heartbeat","last_trade_id":0,"product_id":"BTC-USD","sequence":180762233,"time":"2020-06-30T19:33:02.735095Z"}
{"type":"l2update","product_id":"BTC-USD","changes":[["sell","9134.77","2922.10790000"]],"time":"2020-06-30T19:33:03.494220Z"}
{"type":"l2update","product_id":"BTC-USD","changes":[["sell","9134.77","2921.37630000"]],"time":"2020-06-30T19:33:03.679239Z"}
{"type":"heartbeat","last_trade_id":0,"product_id":"BTC-USD","sequence":180762239,"time":"2020-06-30T19:33:03.735122Z"}
{"type":"l2update","product_id":"BTC-USD","changes":[["sell","9140.45","0.10120000"]],"time":"2020-06-30T19:33:03.953973Z"}
{"type":"l2update","product_id":"BTC-USD","changes":[["buy","9128.68","0.00000000"]],"time":"2020-06-30T19:33:03.981051Z"}
{"type":"l2update","product_id":"BTC-USD","changes":[["sell","9200.44","0.00000000"]],"time":"2020-06-30T19:33:04.506124Z"}
{"type":"l2update","product_id":"BTC-USD","changes":[["buy","9133.76","0.06560000"]],"time":"2020-06-30T19:33:04.513378Z"}
{"type":"l2update","product_id":"BTC-USD","changes":[["sell","9143.86","0.00000000"]],"time":"2020-06-30T19:33:04.515125Z"}
{"type":"heartbeat","last_trade_id":0,"product_id":"BTC-USD","sequence":180762246,"time":"2020-06-30T19:33:04.735118Z"}
{"type":"l2update","product_id":"BTC-USD","changes":[["buy","9078.09","0.00000000"]],"time":"2020-06-30T19:33:04.988012Z"}
{"type":"l2update","product_id":"BTC-USD","changes":[["buy","9128.73","0.00000000"]],"time":"2020-06-30T19:33:05.076695Z"}
{"type":"l2update","product_id":"BTC-USD","changes":[["sell","9134.77","2921.33630000"]],"time":"2020-06-30T19:33:05.151279Z"}
{"type":"l2update","product_id":"BTC-USD","changes":[["sell","9197.93","0.09660000"]],"time":"2020-06-30T19:33:05.420376Z"}
{"type":"l2update","product_id":"BTC-USD","changes":[["buy","9120.22","0.00000000"]],"time":"2020-06-30T19:33:05.612493Z"}
{"type":"l2update","product_id":"BTC-USD","changes":[["sell","9197.90","0.00200000"]],"time":"2020-06-30T19:33:05.702499Z"}
{"type":"heartbeat","last_trade_id":0,"product_id":"BTC-USD","sequence":180762256,"time":"2020-06-30T19:33:05.735119Z"}
{"type":"l2update","product_id":"BTC-USD","changes":[["sell","9140.45","0.00000000"]],"time":"2020-06-30T19:33:05.862829Z"}
{"type":"l2update","product_id":"BTC-USD","changes":[["sell","9166.23","0.00000000"]],"time":"2020-06-30T19:33:06.157031Z"}
{"type":"heartbeat","last_trade_id":0,"product_id":"BTC-USD","sequence":180762258,"time":"2020-06-30T19:33:06.735120Z"}
{"type":"l2update","product_id":"BTC-USD","changes":[["sell","9197.15","0.03830000"]],"time":"2020-06-30T19:33:07.022929Z"}
{"type":"l2update","product_id":"BTC-USD","changes":[["sell","9140.48","4.06560000"]],"time":"2020-06-30T19:33:07.483823Z"}
{"type":"l2update","product_id":"BTC-USD","changes":[["sell","9196.72","0.09660000"]],"time":"2020-06-30T19:33:07.665044Z"}
{"type":"heartbeat","last_trade_id":0,"product_id":"BTC-USD","sequence":180762263,"time":"2020-06-30T19:33:07.735115Z"}
{"type":"l2update","product_id":"BTC-USD","changes":[["sell","9140.51","0.07660000"]],"time":"2020-06-30T19:33:08.593282Z"}
{"type":"heartbeat","last_trade_id":0,"product_id":"BTC-USD","sequence":180762265,"time":"2020-06-30T19:33:08.735037Z"}
{"type":"l2update","product_id":"BTC-USD","changes":[["buy","9081.06","0.00160000"]],"time":"2020-06-30T19:33:08.879549Z"}
{"type":"l2update","product_id":"BTC-USD","changes":[["sell","9197.15","0.00000000"]],"time":"2020-06-30T19:33:09.058491Z"}
{"type":"l2update","product_id":"BTC-USD","changes":[["sell","9141.17","0.06560000"]],"time":"2020-06-30T19:33:09.717591Z"}
{"type":"heartbeat","last_trade_id":0,"product_id":"BTC-USD","sequence":180762270,"time":"2020-06-30T19:33:09.735169Z"}
{"type":"l2update","product_id":"BTC-USD","changes":[["sell","9197.90","0.00000000"]],"time":"2020-06-30T19:33:10.160160Z"}
{"type":"l2update","product_id":"BTC-USD","changes":[["sell","9141.17","0.13120000"]],"time":"2020-06-30T19:33:10.317459Z"}
{"type":"heartbeat","last_trade_id":0,"product_id":"BTC-USD","sequence":180762273,"time":"2020-06-30T19:33:10.735120Z"}
{"type":"l2update","product_id":"BTC-USD","changes":[["sell","9139.31","0.00000000"]],"time":"2020-06-30T19:33:10.762283Z"}
{"type":"l2update","product_id":"BTC-USD","changes":[["sell","9194.95","0.09660000"]],"time":"2020-06-30T19:33:11.140189Z"}
{"type":"l2update","product_id":"BTC-USD","changes":[["sell","9141.21","0.06560000"]],"time":"2020-06-30T19:33:11.420538Z"}
{"type":"l2update","product_id":"BTC-USD","changes":[["buy","9134.75","2969.72910000"]],"time":"2020-06-30T19:33:11.674761Z"}
{"type":"l2update","product_id":"BTC-USD","changes":[["sell","9134.77","2921.31740000"]],"time":"2020-06-30T19:33:11.717175Z"}
{"type":"heartbeat","last_trade_id":0,"product_id":"BTC-USD","sequence":180762284,"time":"2020-06-30T19:33:11.735119Z"}
{"type":"l2update","product_id":"BTC-USD","changes":[["buy","9110.14","0.00000000"]],"time":"2020-06-30T19:33:12.146436Z"}
{"type":"heartbeat","last_trade_id":0,"product_id":"BTC-USD","sequence":180762285,"time":"2020-06-30T19:33:12.735120Z"}
{"type":"l2update","product_id":"BTC-USD","changes":[["sell","9134.77","2918.56740000"]],"time":"2020-06-30T19:33:12.824630Z"}
{"type":"l2update","product_id":"BTC-USD","changes":[["sell","9171.04","0.94610000"]],"time":"2020-06-30T19:33:13.110750Z"}
{"type":"l2update","product_id":"BTC-USD","changes":[["buy","9130.31","0.00000000"]],"time":"2020-06-30T19:33:13.303888Z"}
{"type":"l2update","product_id":"BTC-USD","changes":[["sell","9197.93","0.00000000"]],"time":"2020-06-30T19:33:13.543814Z"}
{"type":"heartbeat","last_trade_id":0,"product_id":"BTC-USD","sequence":180762292,"time":"2020-06-30T19:33:13.735116Z"}
{"type":"l2update","product_id":"BTC-USD","changes":[["sell","9134.77","2916.93040000"]],"time":"2020-06-30T19:33:13.927573Z"}
{"type":"l2update","product_id":"BTC-USD","changes":[["buy","100.00","114.95500000"]],"time":"2020-06-30T19:33:14.043574Z"}
{"type":"l2update","product_id":"BTC-USD","changes":[["buy","100.00","114.94500000"]],"time":"2020-06-30T19:33:14.052383Z"}
{"type":"l2update","product_id":"BTC-USD","changes":[["sell","9142.88","4.21690000"]],"time":"2020-06-30T19:33:14.259088Z"}
{"type":"l2update","product_id":"BTC-USD","changes":[["buy","9121.62","1.26200000"]],"time":"2020-06-30T19:33:14.521961Z"}
{"type":"heartbeat","last_trade_id":0,"product_id":"BTC-USD","sequence":180762302,"time":"2020-06-30T19:33:14.735031Z"}
{"type":"l2update","product_id":"BTC-USD","changes":[["sell","9167.43","0.13500000"]],"time":"2020-06-30T19:33:14.796604Z"}
{"type":"l2update","product_id":"BTC-USD","changes":[["buy","9126.44","0.00000000"]],"time":"2020-06-30T19:33:14.950747Z"}
{"type":"l2update","product_id":"BTC-USD","changes":[["sell","9141.17","0.06560000"]],"time":"2020-06-30T19:33:15.262754Z"}
{"type":"l2update","product_id":"BTC-USD","changes":[["sell","9142.88","8.33250000"]],"time":"2020-06-30T19:33:15.415588Z"}
{"type":"heartbeat","last_trade_id":0,"product_id":"BTC-USD","sequence":180762308,"time":"2020-06-30T19:33:15.735180Z"}
{"type":"l2update","product_id":"BTC-USD","changes":[["sell","9140.51","0.00000000"]],"time":"2020-06-30T19:33:15.855108Z"}
{"type":"l2update","product_id":"BTC-USD","changes":[["sell","9143.82","0.00000000"]],"time":"2020-06-30T19:33:15.857588Z"}
{"type":"heartbeat","last_trade_id":0,"product_id":"BTC-USD","sequence":180762310,"time":"2020-06-30T19:33:16.735105Z"}
{"type":"l2update","product_id":"BTC-USD","changes":[["sell","9134.77","2916.83040000"]],"time":"2020-06-30T19:33:17.263551Z"}
{"type":"l2update","product_id":"BTC-USD","changes":[["buy","9134.75","2969.62910000"]],"time":"2020-06-30T19:33:17.356387Z"}
{"type":"l2update","product_id":"BTC-USD","changes":[["sell","9134.77","2916.78660000"]],"time":"2020-06-30T19:33:17.628847Z"}
{"type":"heartbeat","last_trade_id":0,"product_id":"BTC-USD","sequence":180762319,"time":"2020-06-30T19:33:17.735110Z"}
{"type":"l2update","product_id":"BTC-USD","changes":[["buy","9123.40","0.50000000"]],"time":"2020-06-30T19:33:17.897679Z"}
{"type":"l2update","product_id":"BTC-USD","changes":[["buy","9126.43","0.00000000"]],"time":"2020-06-30T19:33:18.083785Z"}
{"type":"heartbeat","last_trade_id":0,"product_id":"BTC-USD","sequence":180762322,"time":"2020-06-30T19:33:18.735093Z"}
{"type":"l2update","product_id":"BTC-USD","changes":[["sell","9134.77","2916.69680000"]],"time":"2020-06-30T19:33:19.290337Z"}
{"type":"l2update","product_id":"BTC-USD","changes":[["sell","9141.58","0.05000000"]],"time":"2020-06-30T19:33:19.577496Z"}
{"type":"heartbeat","last_trade_id":0,"product_id":"BTC-USD","sequence":180762327,"time":"2020-06-30T19:33:19.735116Z"}
{"type":"l2update","product_id":"BTC-USD","changes":[["sell","9142.88","4.11560000"]],"time":"2020-06-30T19:33:19.989727Z"}
{"type":"l2update","product_id":"BTC-USD","changes":[["buy","9112.45","0.01000000"]],"time":"2020-06-30T19:33:20.108885Z"}
{"type":"l2update","product_id":"BTC-USD","changes":[["sell","9141.32","0.08550000"]],"time":"2020-06-30T19:33:20.706574Z"}
{"type":"heartbeat","last_trade_id":0,"product_id":"BTC-USD","sequence":180762332,"time":"2020-06-30T19:33:20.735120Z"}
{"type":"l2update","product_id":"BTC-USD","changes":[["buy","9112.34","0.54870000"]],"time":"2020-06-30T19:33:20.986458Z"}
{"type":"l2update","product_id":"BTC-USD","changes":[["sell","9141.58","0.00000000"]],"time":"2020-06-30T19:33:21.131907Z"}
{"type":"l2update","product_id":"BTC-USD","changes":[["sell","9143.80","0.00000000"]],"time":"2020-06-30T19:33:21.133595Z"}
{"type":"l2update","product_id":"BTC-USD","changes":[["sell","9194.95","0.00000000"]],"time":"2020-06-30T19:33:21.136862Z"}
{"type":"l2update","product_id":"BTC-USD","changes":[["sell","9142.88","0.00000000"]],"time":"2020-06-30T19:33:21.138274Z"}
{"type":"heartbeat","last_trade_id":0,"product_id":"BTC-USD","sequence":180762338,"time":"2020-06-30T19:33:21.735119Z"}
{"type":"l2update","product_id":"BTC-USD","changes":[["sell","9142.71","0.08550000"]],"time":"2020-06-30T19:33:21.778527Z"}
{"type":"l2update","product_id":"BTC-USD","changes":[["sell","9134.77","2916.65730000"]],"time":"2020-06-30T19:33:22.074364Z"}
{"type":"l2update","product_id":"BTC-USD","changes":[["sell","9134.77","2916.61750000"]],"time":"2020-06-30T19:33:22.348304Z"}
{"type":"l2update","product_id":"BTC-USD","changes":[["sell","9150.17","1.24230000"]],"time":"2020-06-30T19:33:22.607157Z"}
{"type":"heartbeat","last_trade_id":0,"product_id":"BTC-USD","sequence":180762348,"time":"2020-06-30T19:33:22.735121Z"}
{"type":"l2update","product_id":"BTC-USD","changes":[["sell","9134.77","2916.56750000"]],"time":"2020-06-30T19:33:22.906075Z"}
{"type":"l2update","product_id":"BTC-USD","changes":[["sell","9197.71","0.06880000"]],"time":"2020-06-30T19:33:23.457073Z"}
{"type":"heartbeat","last_trade_id":0,"product_id":"BTC-USD","sequence":180762353,"time":"2020-06-30T19:33:23.735119Z"}
{"type":"l2update","product_id":"BTC-USD","changes":[["sell","9197.43","0.00300000"]],"time":"2020-06-30T19:33:24.011199Z"}
{"type":"l2update","product_id":"BTC-USD","changes":[["sell","9134.77","2913.56750000"]],"time":"2020-06-30T19:33:24.287618Z"}
{"type":"l2update","product_id":"BTC-USD","changes":[["sell","9150.17","0.00000000"]],"time":"2020-06-30T19:33:24.434431Z"}
{"type":"l2update","product_id":"BTC-USD","changes":[["sell","9171.04","0.00000000"]],"time":"2020-06-30T19:33:24.443402Z"}
{"type":"l2update","product_id":"BTC-USD","changes":[["sell","9196.72","0.00000000"]],"time":"2020-06-30T19:33:24.445485Z"}
{"type":"l2update","product_id":"BTC-USD","changes":[["sell","9142.47","0.05000000"]],"time":"2020-06-30T19:33:24.570711Z"}
{"type":"l2update","product_id":"BTC-USD","changes":[["buy","9112.34","0.00000000"]],"time":"2020-06-30T19:33:24.715476Z"}
{"type":"heartbeat","last_trade_id":0,"product_id":"BTC-USD","sequence":180762364,"time":"2020-06-30T19:33:24.735120Z"}
{"type":"l2update","product_id":"BTC-USD","changes":[["sell","9134.77","2913.51750000"]],"time":"2020-06-30T19:33:24.833533Z"}
{"type":"l2update","product_id":"BTC-USD","changes":[["buy","9117.40","0.01000000"]],"time":"2020-06-30T19:33:25.110235Z"}
{"type":"l2update","product_id":"BTC-USD","changes":[["buy","9133.76","0.00000000"]],"time":"2020-06-30T19:33:25.255804Z"}
{"type":"l2update","product_id":"BTC-USD","changes":[["sell","9134.77","2912.97150000"]],"time":"2020-06-30T19:33:25.382372Z"}
{"type":"heartbeat","last_trade_id":0,"product_id":"BTC-USD","sequence":180762373,"time":"2020-06-30T19:33:25.735121Z"}
{"type":"l2update","product_id":"BTC-USD","changes":[["sell","9134.77","2912.23980000"]],"time":"2020-06-30T19:33:26.254855Z"}
{"type":"l2update","product_id":"BTC-USD","changes":[["sell","9197.66","0.03960000"]],"time":"2020-06-30T19:33:26.518847Z"}
{"type":"l2update","product_id":"BTC-USD","changes":[["buy","9121.62","0.00000000"]],"time":"2020-06-30T19:33:26.677961Z"}
{"type":"heartbeat","last_trade_id":0,"product_id":"BTC-USD","sequence":180762379,"time":"2020-06-30T19:33:26.735108Z"}
{"type":"l2update","product_id":"BTC-USD","changes":[["sell","9141.17","0.00000000"]],"time":"2020-06-30T19:33:26.939975Z"}
{"type":"l2update","product_id":"BTC-USD","changes":[["sell","9134.77","2912.18980000"]],"time":"2020-06-30T19:33:27.344839Z"}
{"type":"heartbeat","last_trade_id":0,"product_id":"BTC-USD","sequence":180762383,"time":"2020-06-30T19:33:27.735122Z"}
{"type":"l2update","product_id":"BTC-USD","changes":[["sell","9190.74","0.10000000"]],"time":"2020-06-30T19:33:27.908801Z"}
{"type":"l2update","product_id":"BTC-USD","changes":[["sell","9142.84","0.11560000"]],"time":"2020-06-30T19:33:28.199888Z"}
{"type":"l2update","product_id":"BTC-USD","changes":[["sell","9197.71","0.00000000"]],"time":"2020-06-30T19:33:28.348109Z"}
{"type":"heartbeat","last_trade_id":0,"product_id":"BTC-USD","sequence":180762388,"time":"2020-06-30T19:33:28.735111Z"}
{"type":"l2update","product_id":"BTC-USD","changes":[["buy","9129.42","0.02220000"]],"time":"2020-06-30T19:33:29.024220Z"}
{"type":"l2update","product_id":"BTC-USD","changes":[["buy","100.00","114.95500000"]],"time":"2020-06-30T19:33:29.065845Z"}
{"type":"l2update","product_id":"BTC-USD","changes":[["buy","100.00","114.94500000"]],"time":"2020-06-30T19:33:29.071949Z"}
{"type":"l2update","product_id":"BTC-USD","changes":[["sell","9142.53","0.11560000"]],"time":"2020-06-30T19:33:29.601364Z"}
{"type":"heartbeat","last_trade_id":0,"product_id":"BTC-USD","sequence":180762395,"time":"2020-06-30T19:33:29.735115Z"}
{"type":"l2update","product_id":"BTC-USD","changes":[["sell","9197.66","0.00000000"]],"time":"2020-06-30T19:33:30.076454Z"}
{"type":"l2update","product_id":"BTC-USD","changes":[["sell","9196.80","0.02750000"]],"time":"2020-06-30T19:33:30.164949Z"}
{"type":"l2update","product_id":"BTC-USD","changes":[["sell","9142.53","0.18120000"]],"time":"2020-06-30T19:33:30.432618Z"}
{"type":"l2update","product_id":"BTC-USD","changes":[["sell","9148.53","0.00000000"]],"time":"2020-06-30T19:33:30.609237Z"}
{"type":"l2update","product_id":"BTC-USD","changes":[["sell","9190.74","0.00000000"]],"time":"2020-06-30T19:33:30.611132Z"}
{"type":"heartbeat","last_trade_id":0,"product_id":"BTC-USD","sequence":180762402,"time":"2020-06-30T19:33:30.735120Z"}
{"type":"l2update","product_id":"BTC-USD","changes":[["sell","9140.48","0.00000000"]],"time":"2020-06-30T19:33:30.852299Z"}
{"type":"l2update","product_id":"BTC-USD","changes":[["sell","9142.84","0.00000000"]],"time":"2020-06-30T19:33:30.853701Z"}
{"type":"l2update","product_id":"BTC-USD","changes":[["sell","9134.77","2911.64730000"]],"time":"2020-06-30T19:33:31.270744Z"}
{"type":"l2update","product_id":"BTC-USD","changes":[["buy","9132.16","0.06560000"]],"time":"2020-06-30T19:33:31.563772Z"}
{"type":"heartbeat","last_trade_id":0,"product_id":"BTC-USD","sequence":180762409,"time":"2020-06-30T19:33:31.735120Z"}
{"type":"l2update","product_id":"BTC-USD","changes":[["buy","9129.42","0.00000000"]],"time":"2020-06-30T19:33:31.841799Z"}
{"type":"l2update","product_id":"BTC-USD","changes":[["sell","9146.79","0.00670000"]],"time":"2020-06-30T19:33:32.057022Z"}
{"type":"heartbeat","last_trade_id":0,"product_id":"BTC-USD","sequence":180762412,"time":"2020-06-30T19:33:32.735117Z"}
{"type":"l2update","product_id":"BTC-USD","changes":[["sell","9160.85","0.50000000"]],"time":"2020-06-30T19:33:32.791726Z"}
{"type":"l2update","product_id":"BTC-USD","changes":[["sell","9142.53","0.11560000"]],"time":"2020-06-30T19:33:33.238668Z"}
{"type":"heartbeat","last_trade_id":0,"product_id":"BTC-USD","sequence":180762415,"time":"2020-06-30T19:33:33.735117Z"}
{"type":"l2update","product_id":"BTC-USD","changes":[["buy","9112.45","0.02000000"]],"time":"2020-06-30T19:33:33.772144Z"}
{"type":"l2update","product_id":"BTC-USD","changes":[["buy","9130.34","0.00000000"]],"time":"2020-06-30T19:33:33.965424Z"}
{"type":"l2update","product_id":"BTC-USD","changes":[["buy","9132.16","0.00000000"]],"time":"2020-06-30T19:33:33.967411Z"}
{"type":"l2update","product_id":"BTC-USD","changes":[["buy","9134.32","0.06560000"]],"time":"2020-06-30T19:33:34.644028Z"}
{"type":"heartbeat","last_trade_id":0,"product_id":"BTC-USD","sequence":180762421,"time":"2020-06-30T19:33:34.735121Z"}
{"type":"l2update","product_id":"BTC-USD","changes":[["sell","9196.80","0.00000000"]],"time":"2020-06-30T19:33:35.340737Z"}
{"type":"l2update","product_id":"BTC-USD","changes":[["buy","9134.31","0.06560000"]],"time":"2020-06-30T19:33:35.469831Z"}
{"type":"heartbeat","last_trade_id":0,"product_id":"BTC-USD","sequence":180762424,"time":"2020-06-30T19:33:35.735117Z"}
{"type":"l2update","product_id":"BTC-USD","changes":[["sell","9154.52","0.02360000"]],"time":"2020-06-30T19:33:35.778679Z"}
{"type":"l2update","product_id":"BTC-USD","changes":[["sell","9134.77","2911.60480000"]],"time":"2020-06-30T19:33:36.047708Z"}
{"type":"l2update","product_id":"BTC-USD","changes":[["buy","9134.32","0.00000000"]],"time":"2020-06-30T19:33:36.514893Z"}
{"type":"l2update","product_id":"BTC-USD","changes":[["sell","9152.90","0.03250000"]],"time":"2020-06-30T19:33:36.608940Z"}
{"type":"heartbeat","last_trade_id":0,"product_id":"BTC-USD","sequence":180762432,"time":"2020-06-30T19:33:36.735118Z"}
{"type":"l2update","product_id":"BTC-USD","changes":[["buy","8900.26","0.00000000"]],"time":"2020-06-30T19:33:37.437717Z"}
{"type":"l2update","product_id":"BTC-USD","changes":[["buy","8899.50","0.04576220"]],"time":"2020-06-30T19:33:37.685792Z"}
{"type":"heartbeat","last_trade_id":0,"product_id":"BTC-USD","sequence":180762435,"time":"2020-06-30T19:33:37.735114Z"}
{"type":"l2update","product_id":"BTC-USD","changes":[["sell","9142.42","0.06560000"]],"time":"2020-06-30T19:33:37.766198Z"}
{"type":"l2update","product_id":"BTC-USD","changes":[["sell","9195.61","0.06870000"]],"time":"2020-06-30T19:33:38.056948Z"}
{"type":"l2update","product_id":"BTC-USD","changes":[["sell","9430.32","0.00000000"]],"time":"2020-06-30T19:33:38.080521Z"}
{"type":"l2update","product_id":"BTC-USD","changes":[["sell","9142.53","0.00000000"]],"time":"2020-06-30T19:33:38.208357Z"}
{"type":"l2update","product_id":"BTC-USD","changes":[["sell","9154.52","0.00000000"]],"time":"2020-06-30T19:33:38.230077Z"}
{"type":"l2update","product_id":"BTC-USD","changes":[["sell","9141.21","0.00000000"]],"time":"2020-06-30T19:33:38.239981Z"}
{"type":"l2update","product_id":"BTC-USD","changes":[["sell","9196.85","0.09400000"]],"time":"2020-06-30T19:33:38.243261Z"}
{"type":"l2update","product_id":"BTC-USD","changes":[["sell","9431.12","0.00652324"]],"time":"2020-06-30T19:33:38.305103Z"}
{"type":"l2update","product_id":"BTC-USD","changes":[["sell","9160.85","0.00000000"]],"time":"2020-06-30T19:33:38.468832Z"}
{"type":"heartbeat","last_trade_id":0,"product_id":"BTC-USD","sequence":180762448,"time":"2020-06-30T19:33:38.735121Z"}
{"type":"l2update","product_id":"BTC-USD","changes":[["sell","9142.41","0.06560000"]],"time":"2020-06-30T19:33:39.434112Z"}
{"type":"heartbeat","last_trade_id":0,"product_id":"BTC-USD","sequence":180762450,"time":"2020-06-30T19:33:39.735115Z"}
{"type":"l2update","product_id":"BTC-USD","changes":[["buy","9134.31","0.08780000"]],"time":"2020-06-30T19:33:40.542717Z"}
{"type":"heartbeat","last_trade_id":0,"product_id":"BTC-USD","sequence":180762452,"time":"2020-06-30T19:33:40.735097Z"}
{"type":"l2update","product_id":"BTC-USD","changes":[["sell","9147.13","1.50000000"]],"time":"2020-06-30T19:33:40.852759Z"}
{"type":"l2update","product_id":"BTC-USD","changes":[["sell","9134.77","2911.60380000"]],"time":"2020-06-30T19:33:41.071287Z"}
{"type":"l2update","product_id":"BTC-USD","changes":[["sell","9142.54","0.22300000"]],"time":"2020-06-30T19:33:41.117527Z"}
{"type":"l2update","product_id":"BTC-USD","changes":[["sell","9197.43","0.00000000"]],"time":"2020-06-30T19:33:41.262107Z"}
{"type":"l2update","product_id":"BTC-USD","changes":[["sell","9146.79","0.00000000"]],"time":"2020-06-30T19:33:41.267095Z"}
{"type":"l2update","product_id":"BTC-USD","changes":[["sell","9142.47","0.00000000"]],"time":"2020-06-30T19:33:41.274383Z"}
{"type":"l2update","product_id":"BTC-USD","changes":[["sell","9152.90","0.00000000"]],"time":"2020-06-30T19:33:41.543460Z"}
{"type":"l2update","product_id":"BTC-USD","changes":[["sell","9194.35","0.05950000"]],"time":"2020-06-30T19:33:41.685121Z"}
{"type":"heartbeat","last_trade_id":0,"product_id":"BTC-USD","sequence":180762465,"time":"2020-06-30T19:33:41.735009Z"}
{"type":"l2update","product_id":"BTC-USD","changes":[["sell","9194.21","0.06870000"]],"time":"2020-06-30T19:33:41.978728Z"}
{"type":"heartbeat","last_trade_id":0,"product_id":"BTC-USD","sequence":180762467,"time":"2020-06-30T19:33:42.735092Z"}
{"type":"heartbeat","last_trade_id":0,"product_id":"BTC-USD","sequence":180762467,"time":"2020-06-30T19:33:43.735158Z"}
{"type":"l2update","product_id":"BTC-USD","changes":[["buy","100.00","114.95500000"]],"time":"2020-06-30T19:33:44.017133Z"}
{"type":"l2update","product_id":"BTC-USD","changes":[["buy","100.00","114.94500000"]],"time":"2020-06-30T19:33:44.024163Z"}
{"type":"l2update","product_id":"BTC-USD","changes":[["sell","9196.14","0.00200000"]],"time":"2020-06-30T19:33:44.226661Z"}
{"type":"l2update","product_id":"BTC-USD","changes":[["sell","9196.85","0.00000000"]],"time":"2020-06-30T19:33:44.644541Z"}
{"type":"l2update","product_id":"BTC-USD","changes":[["sell","9142.71","0.00000000"]],"time":"2020-06-30T19:33:44.654158Z"}
{"type":"heartbeat","last_trade_id":0,"product_id":"BTC-USD","sequence":180762474,"time":"2020-06-30T19:33:44.735100Z"}
{"type":"heartbeat","last_trade_id":0,"product_id":"BTC-USD","sequence":180762474,"time":"2020-06-30T19:33:45.735120Z"}
{"type":"l2update","product_id":"BTC-USD","changes":[["sell","9195.10","0.03960000"]],"time":"2020-06-30T19:33:46.160429Z"}
{"type":"l2update","product_id":"BTC-USD","changes":[["sell","9142.54","0.00000000"]],"time":"2020-06-30T19:33:46.357328Z"}
{"type":"l2update","product_id":"BTC-USD","changes":[["sell","9147.13","0.00000000"]],"time":"2020-06-30T19:33:46.357582Z"}
{"type":"l2update","product_id":"BTC-USD","changes":[["sell","9195.61","0.00000000"]],"time":"2020-06-30T19:33:46.363033Z"}
