{"type":"l2update","product_id":"BTC-USD","changes":[["buy","9074.54","0.00000000"]],"time":"2020-06-30T19:16:34.239058Z"}
{"type":"heartbeat","last_trade_id":0,"product_id":"BTC-USD","sequence":180757108,"time":"2020-06-30T19:16:34.735103Z"}
{"type":"l2update","product_id":"BTC-USD","changes":[["buy","9120.80","2722.38100000"]],"time":"2020-06-30T19:16:34.922800Z"}
{"type":"l2update","product_id":"BTC-USD","changes":[["buy","9120.80","2721.31700000"]],"time":"2020-06-30T19:16:35.186795Z"}
{"type":"heartbeat","last_trade_id":0,"product_id":"BTC-USD","sequence":180757114,"time":"2020-06-30T19:16:35.735093Z"}
{"type":"l2update","product_id":"BTC-USD","changes":[["buy","9083.04","0.01000000"]],"time":"2020-06-30T19:16:36.203085Z"}
{"type":"l2update","product_id":"BTC-USD","changes":[["buy","9103.39","0.00000000"]],"time":"2020-06-30T19:16:36.637176Z"}
{"type":"heartbeat","last_trade_id":0,"product_id":"BTC-USD","sequence":180757117,"time":"2020-06-30T19:16:36.735117Z"}
{"type":"l2update","product_id":"BTC-USD","changes":[["buy","9120.80","2720.41700000"]],"time":"2020-06-30T19:16:36.767687Z"}
{"type":"l2update","product_id":"BTC-USD","changes":[["sell","9147.22","0.00000000"]],"time":"2020-06-30T19:16:37.204166Z"}
{"type":"l2update","product_id":"BTC-USD","changes":[["sell","9154.96","0.00000000"]],"time":"2020-06-30T19:16:37.206222Z"}
{"type":"l2update","product_id":"BTC-USD","changes":[["sell","9157.05","0.00000000"]],"time":"2020-06-30T19:16:37.210045Z"}
{"type":"heartbeat","last_trade_id":0,"product_id":"BTC-USD","sequence":180757123,"time":"2020-06-30T19:16:37.735103Z"}
{"type":"heartbeat","last_trade_id":0,"product_id":"BTC-USD","sequence":180757123,"time":"2020-06-30T19:16:38.735101Z"}
{"type":"heartbeat","last_trade_id":0,"product_id":"BTC-USD","sequence":180757123,"time":"2020-06-30T19:16:39.735119Z"}
{"type":"l2update","product_id":"BTC-USD","changes":[["buy","9116.02","0.01210000"]],"time":"2020-06-30T19:16:39.890839Z"}
{"type":"l2update","product_id":"BTC-USD","changes":[["buy","9120.80","2720.20860000"]],"time":"2020-06-30T19:16:40.159624Z"}
{"type":"l2update","product_id":"BTC-USD","changes":[["buy","9075.27","0.00000000"]],"time":"2020-06-30T19:16:40.335454Z"}
{"type":"l2update","product_id":"BTC-USD","changes":[["buy","9083.04","0.00000000"]],"time":"2020-06-30T19:16:40.342754Z"}
{"type":"l2update","product_id":"BTC-USD","changes":[["buy","9120.80","2719.95860000"]],"time":"2020-06-30T19:16:40.447613Z"}
{"type":"l2update","product_id":"BTC-USD","changes":[["sell","9155.23","0.00000000"]],"time":"2020-06-30T19:16:40.583079Z"}
{"type":"l2update","product_id":"BTC-USD","changes":[["sell","9145.23","3.34940000"]],"time":"2020-06-30T19:16:40.725347Z"}
{"type":"heartbeat","last_trade_id":0,"product_id":"BTC-USD","sequence":180757136,"time":"2020-06-30T19:16:40.735070Z"}
{"type":"l2update","product_id":"BTC-USD","changes":[["sell","9157.17","0.00000000"]],"time":"2020-06-30T19:16:40.910588Z"}
{"type":"l2update","product_id":"BTC-USD","changes":[["sell","9120.82","3006.39100000"]],"time":"2020-06-30T19:16:41.259464Z"}
{"type":"l2update","product_id":"BTC-USD","changes":[["buy","9116.25","0.16630000"]],"time":"2020-06-30T19:16:41.266088Z"}
{"type":"l2update","product_id":"BTC-USD","changes":[["buy","9072.78","0.01050000"]],"time":"2020-06-30T19:16:41.527215Z"}
{"type":"l2update","product_id":"BTC-USD","changes":[["buy","9116.02","0.00000000"]],"time":"2020-06-30T19:16:41.692984Z"}
{"type":"l2update","product_id":"BTC-USD","changes":[["buy","9091.83","0.00000000"]],"time":"2020-06-30T19:16:41.708580Z"}
{"type":"l2update","product_id":"BTC-USD","changes":[["buy","9111.57","8.27900000"]],"time":"2020-06-30T19:16:41.710363Z"}
{"type":"l2update","product_id":"BTC-USD","changes":[["buy","9103.31","0.00000000"]],"time":"2020-06-30T19:16:41.711187Z"}
{"type":"heartbeat","last_trade_id":0,"product_id":"BTC-USD","sequence":180757148,"time":"2020-06-30T19:16:41.735099Z"}
{"type":"heartbeat","last_trade_id":0,"product_id":"BTC-USD","sequence":180757148,"time":"2020-06-30T19:16:42.735063Z"}
{"type":"l2update","product_id":"BTC-USD","changes":[["buy","9120.80","2719.89280000"]],"time":"2020-06-30T19:16:42.938240Z"}
{"type":"l2update","product_id":"BTC-USD","changes":[["buy","9120.80","2719.80910000"]],"time":"2020-06-30T19:16:43.472892Z"}
{"type":"heartbeat","last_trade_id":0,"product_id":"BTC-USD","sequence":180757154,"time":"2020-06-30T19:16:43.735119Z"}
{"type":"l2update","product_id":"BTC-USD","changes":[["buy","9120.80","2719.75910000"]],"time":"2020-06-30T19:16:43.746327Z"}
{"type":"l2update","product_id":"BTC-USD","changes":[["sell","9136.31","0.00000000"]],"time":"2020-06-30T19:16:43.963057Z"}
{"type":"l2update","product_id":"BTC-USD","changes":[["sell","9154.29","0.06900000"]],"time":"2020-06-30T19:16:44.017663Z"}
{"type":"l2update","product_id":"BTC-USD","changes":[["buy","100.00","114.95500000"]],"time":"2020-06-30T19:16:44.048963Z"}
{"type":"l2update","product_id":"BTC-USD","changes":[["buy","100.00","114.94500000"]],"time":"2020-06-30T19:16:44.056056Z"}
{"type":"l2update","product_id":"BTC-USD","changes":[["buy","9120.80","2719.68520000"]],"time":"2020-06-30T19:16:44.305987Z"}
{"type":"heartbeat","last_trade_id":0,"product_id":"BTC-USD","sequence":180757166,"time":"2020-06-30T19:16:44.735112Z"}
{"type":"l2update","product_id":"BTC-USD","changes":[["buy","9120.80","2719.61130000"]],"time":"2020-06-30T19:16:45.381217Z"}
{"type":"heartbeat","last_trade_id":0,"product_id":"BTC-USD","sequence":180757169,"time":"2020-06-30T19:16:45.735121Z"}
{"type":"l2update","product_id":"BTC-USD","changes":[["buy","9116.94","0.00520000"]],"time":"2020-06-30T19:16:45.947652Z"}
{"type":"heartbeat","last_trade_id":0,"product_id":"BTC-USD","sequence":180757171,"time":"2020-06-30T19:16:46.735108Z"}
{"type":"l2update","product_id":"BTC-USD","changes":[["buy","9120.80","2719.31970000"]],"time":"2020-06-30T19:16:47.314815Z"}
{"type":"heartbeat","last_trade_id":0,"product_id":"BTC-USD","sequence":180757174,"time":"2020-06-30T19:16:47.735114Z"}
{"type":"l2update","product_id":"BTC-USD","changes":[["sell","9143.11","0.01000000"]],"time":"2020-06-30T19:16:47.903045Z"}
{"type":"l2update","product_id":"BTC-USD","changes":[["sell","9121.08","0.00000000"]],"time":"2020-06-30T19:16:48.330477Z"}
{"type":"heartbeat","last_trade_id":0,"product_id":"BTC-USD","sequence":180757177,"time":"2020-06-30T19:16:48.735112Z"}
{"type":"l2update","product_id":"BTC-USD","changes":[["buy","9108.81","0.02230000"]],"time":"2020-06-30T19:16:49.246565Z"}
{"type":"heartbeat","last_trade_id":0,"product_id":"BTC-USD","sequence":180757179,"time":"2020-06-30T19:16:49.735113Z"}
{"type":"l2update","product_id":"BTC-USD","changes":[["buy","9120.80","2719.30020000"]],"time":"2020-06-30T19:16:49.822114Z"}
{"type":"l2update","product_id":"BTC-USD","changes":[["buy","9118.15","0.03990000"]],"time":"2020-06-30T19:16:50.103641Z"}
{"type":"l2update","product_id":"BTC-USD","changes":[["sell","9154.29","0.00000000"]],"time":"2020-06-30T19:16:50.260402Z"}
{"type":"l2update","product_id":"BTC-USD","changes":[["buy","9108.81","0.00000000"]],"time":"2020-06-30T19:16:50.304284Z"}
{"type":"l2update","product_id":"BTC-USD","changes":[["buy","9075.35","0.00000000"]],"time":"2020-06-30T19:16:50.312287Z"}
{"type":"l2update","product_id":"BTC-USD","changes":[["buy","9116.94","0.00000000"]],"time":"2020-06-30T19:16:50.324898Z"}
{"type":"l2update","product_id":"BTC-USD","changes":[["buy","9118.15","0.09420000"]],"time":"2020-06-30T19:16:50.646464Z"}
{"type":"heartbeat","last_trade_id":0,"product_id":"BTC-USD","sequence":180757190,"time":"2020-06-30T19:16:50.735126Z"}
{"type":"l2update","product_id":"BTC-USD","changes":[["buy","9103.28","0.00000000"]],"time":"2020-06-30T19:16:51.066276Z"}
{"type":"l2update","product_id":"BTC-USD","changes":[["buy","9116.25","0.00000000"]],"time":"2020-06-30T19:16:51.074872Z"}
{"type":"heartbeat","last_trade_id":0,"product_id":"BTC-USD","sequence":180757192,"time":"2020-06-30T19:16:51.735120Z"}
{"type":"l2update","product_id":"BTC-USD","changes":[["buy","9120.80","2719.25020000"]],"time":"2020-06-30T19:16:51.785494Z"}
{"type":"l2update","product_id":"BTC-USD","changes":[["buy","9120.80","2719.18440000"]],"time":"2020-06-30T19:16:52.347760Z"}
{"type":"l2update","product_id":"BTC-USD","changes":[["buy","9120.80","2719.14450000"]],"time":"2020-06-30T19:16:52.530634Z"}
{"type":"l2update","product_id":"BTC-USD","changes":[["sell","9154.56","0.02780000"]],"time":"2020-06-30T19:16:52.620615Z"}
{"type":"heartbeat","last_trade_id":0,"product_id":"BTC-USD","sequence":180757203,"time":"2020-06-30T19:16:52.735112Z"}
{"type":"l2update","product_id":"BTC-USD","changes":[["buy","9082.56","0.01000000"]],"time":"2020-06-30T19:16:52.894675Z"}
{"type":"l2update","product_id":"BTC-USD","changes":[["buy","9072.78","0.00000000"]],"time":"2020-06-30T19:16:53.329855Z"}
{"type":"heartbeat","last_trade_id":0,"product_id":"BTC-USD","sequence":180757206,"time":"2020-06-30T19:16:53.735090Z"}
{"type":"l2update","product_id":"BTC-USD","changes":[["sell","9154.83","0.02780000"]],"time":"2020-06-30T19:16:54.038650Z"}
{"type":"heartbeat","last_trade_id":0,"product_id":"BTC-USD","sequence":180757208,"time":"2020-06-30T19:16:54.735094Z"}
{"type":"l2update","product_id":"BTC-USD","changes":[["buy","9120.80","2719.09140000"]],"time":"2020-06-30T19:16:54.865140Z"}
{"type":"l2update","product_id":"BTC-USD","changes":[["buy","9117.10","0.07190000"]],"time":"2020-06-30T19:16:55.143150Z"}
{"type":"heartbeat","last_trade_id":0,"product_id":"BTC-USD","sequence":180757213,"time":"2020-06-30T19:16:55.735116Z"}
{"type":"l2update","product_id":"BTC-USD","changes":[["buy","9118.13","0.12290000"]],"time":"2020-06-30T19:16:56.252368Z"}
{"type":"l2update","product_id":"BTC-USD","changes":[["sell","9155.37","0.03290000"]],"time":"2020-06-30T19:16:56.532034Z"}
{"type":"l2update","product_id":"BTC-USD","changes":[["buy","9075.86","0.00000000"]],"time":"2020-06-30T19:16:56.661693Z"}
{"type":"heartbeat","last_trade_id":0,"product_id":"BTC-USD","sequence":180757218,"time":"2020-06-30T19:16:56.735116Z"}
{"type":"l2update","product_id":"BTC-USD","changes":[["buy","9117.66","0.14000000"]],"time":"2020-06-30T19:16:57.073889Z"}
{"type":"l2update","product_id":"BTC-USD","changes":[["buy","9120.80","2717.45140000"]],"time":"2020-06-30T19:16:57.631299Z"}
{"type":"heartbeat","last_trade_id":0,"product_id":"BTC-USD","sequence":180757223,"time":"2020-06-30T19:16:57.735113Z"}
{"type":"l2update","product_id":"BTC-USD","changes":[["sell","9148.74","0.00000000"]],"time":"2020-06-30T19:16:58.323065Z"}
{"type":"l2update","product_id":"BTC-USD","changes":[["buy","9113.79","15.52100000"]],"time":"2020-06-30T19:16:58.722799Z"}
{"type":"heartbeat","last_trade_id":0,"product_id":"BTC-USD","sequence":180757226,"time":"2020-06-30T19:16:58.735117Z"}
{"type":"l2update","product_id":"BTC-USD","changes":[["buy","8891.62","0.00000000"]],"time":"2020-06-30T19:16:58.894153Z"}
{"type":"l2update","product_id":"BTC-USD","changes":[["buy","100.00","114.95500000"]],"time":"2020-06-30T19:16:59.118872Z"}
{"type":"l2update","product_id":"BTC-USD","changes":[["buy","100.00","114.94500000"]],"time":"2020-06-30T19:16:59.125112Z"}
{"type":"l2update","product_id":"BTC-USD","changes":[["sell","9121.93","0.03500000"]],"time":"2020-06-30T19:16:59.274989Z"}
{"type":"l2update","product_id":"BTC-USD","changes":[["buy","8890.86","0.04683127"]],"time":"2020-06-30T19:16:59.415327Z"}
{"type":"l2update","product_id":"BTC-USD","changes":[["buy","9120.80","2717.04400000"]],"time":"2020-06-30T19:16:59.551878Z"}
{"type":"heartbeat","last_trade_id":0,"product_id":"BTC-USD","sequence":180757237,"time":"2020-06-30T19:16:59.735113Z"}
{"type":"l2update","product_id":"BTC-USD","changes":[["buy","9118.37","0.50000000"]],"time":"2020-06-30T19:16:59.833555Z"}
{"type":"l2update","product_id":"BTC-USD","changes":[["sell","9439.48","0.00000000"]],"time":"2020-06-30T19:16:59.958020Z"}
{"type":"l2update","product_id":"BTC-USD","changes":[["sell","9143.11","0.00000000"]],"time":"2020-06-30T19:16:59.990231Z"}
{"type":"l2update","product_id":"BTC-USD","changes":[["buy","9114.28","1.58780000"]],"time":"2020-06-30T19:17:00.105161Z"}
{"type":"l2update","product_id":"BTC-USD","changes":[["sell","9440.29","0.00756905"]],"time":"2020-06-30T19:17:00.328472Z"}
{"type":"l2update","product_id":"BTC-USD","changes":[["buy","9118.13","0.00000000"]],"time":"2020-06-30T19:17:00.543428Z"}
{"type":"heartbeat","last_trade_id":0,"product_id":"BTC-USD","sequence":180757246,"time":"2020-06-30T19:17:00.735110Z"}
{"type":"l2update","product_id":"BTC-USD","changes":[["buy","9108.89","0.06580000"]],"time":"2020-06-30T19:17:00.746700Z"}
{"type":"l2update","product_id":"BTC-USD","changes":[["buy","9118.41","1.00000000"]],"time":"2020-06-30T19:17:00.968318Z"}
{"type":"l2update","product_id":"BTC-USD","changes":[["buy","9113.79","0.00000000"]],"time":"2020-06-30T19:17:01.184394Z"}
{"type":"l2update","product_id":"BTC-USD","changes":[["buy","9118.15","0.05430000"]],"time":"2020-06-30T19:17:01.184515Z"}
{"type":"heartbeat","last_trade_id":0,"product_id":"BTC-USD","sequence":180757252,"time":"2020-06-30T19:17:01.735125Z"}
{"type":"l2update","product_id":"BTC-USD","changes":[["sell","9122.93","0.54300000"]],"time":"2020-06-30T19:17:01.808301Z"}
{"type":"l2update","product_id":"BTC-USD","changes":[["buy","9114.28","0.00000000"]],"time":"2020-06-30T19:17:01.961646Z"}
{"type":"l2update","product_id":"BTC-USD","changes":[["sell","9123.11","0.54100000"]],"time":"2020-06-30T19:17:02.475850Z"}
{"type":"heartbeat","last_trade_id":0,"product_id":"BTC-USD","sequence":180757257,"time":"2020-06-30T19:17:02.735115Z"}
{"type":"l2update","product_id":"BTC-USD","changes":[["sell","9154.56","0.00000000"]],"time":"2020-06-30T19:17:02.927294Z"}
{"type":"l2update","product_id":"BTC-USD","changes":[["buy","9119.37","3.56460000"]],"time":"2020-06-30T19:17:03.039936Z"}
{"type":"l2update","product_id":"BTC-USD","changes":[["buy","9118.15","0.00000000"]],"time":"2020-06-30T19:17:03.547516Z"}
{"type":"l2update","product_id":"BTC-USD","changes":[["buy","9117.47","0.50000000"]],"time":"2020-06-30T19:17:03.615800Z"}
{"type":"heartbeat","last_trade_id":0,"product_id":"BTC-USD","sequence":180757263,"time":"2020-06-30T19:17:03.735113Z"}
{"type":"l2update","product_id":"BTC-USD","changes":[["buy","9120.80","2716.97820000"]],"time":"2020-06-30T19:17:03.905557Z"}
{"type":"l2update","product_id":"BTC-USD","changes":[["sell","9145.23","0.00000000"]],"time":"2020-06-30T19:17:04.140364Z"}
{"type":"heartbeat","last_trade_id":0,"product_id":"BTC-USD","sequence":180757267,"time":"2020-06-30T19:17:04.735107Z"}
{"type":"l2update","product_id":"BTC-USD","changes":[["buy","9108.78","0.06580000"]],"time":"2020-06-30T19:17:05.223633Z"}
{"type":"l2update","product_id":"BTC-USD","changes":[["sell","9144.80","0.01000000"]],"time":"2020-06-30T19:17:05.514292Z"}
{"type":"l2update","product_id":"BTC-USD","changes":[["buy","9082.56","0.00000000"]],"time":"2020-06-30T19:17:05.743964Z"}
{"type":"heartbeat","last_trade_id":0,"product_id":"BTC-USD","sequence":180757272,"time":"2020-06-30T19:17:05.735048Z"}
{"type":"l2update","product_id":"BTC-USD","changes":[["buy","9108.86","0.03060000"]],"time":"2020-06-30T19:17:06.627736Z"}
{"type":"heartbeat","last_trade_id":0,"product_id":"BTC-USD","sequence":180757274,"time":"2020-06-30T19:17:06.735117Z"}
{"type":"l2update","product_id":"BTC-USD","changes":[["buy","9108.89","0.00000000"]],"time":"2020-06-30T19:17:07.046690Z"}
{"type":"l2update","product_id":"BTC-USD","changes":[["buy","9111.50","0.02220000"]],"time":"2020-06-30T19:17:07.199549Z"}
{"type":"l2update","product_id":"BTC-USD","changes":[["buy","9120.80","2716.50720000"]],"time":"2020-06-30T19:17:07.737444Z"}
{"type":"heartbeat","last_trade_id":0,"product_id":"BTC-USD","sequence":180757280,"time":"2020-06-30T19:17:07.735116Z"}
{"type":"heartbeat","last_trade_id":0,"product_id":"BTC-USD","sequence":180757280,"time":"2020-06-30T19:17:08.735119Z"}
{"type":"l2update","product_id":"BTC-USD","changes":[["buy","9115.97","0.04930000"]],"time":"2020-06-30T19:17:09.131710Z"}
{"type":"l2update","product_id":"BTC-USD","changes":[["buy","9094.08","0.05670000"]],"time":"2020-06-30T19:17:09.402313Z"}
{"type":"l2update","product_id":"BTC-USD","changes":[["buy","9081.93","0.00000000"]],"time":"2020-06-30T19:17:09.566359Z"}
{"type":"l2update","product_id":"BTC-USD","changes":[["buy","9117.77","0.50000000"]],"time":"2020-06-30T19:17:09.691509Z"}
{"type":"heartbeat","last_trade_id":0,"product_id":"BTC-USD","sequence":180757287,"time":"2020-06-30T19:17:09.735110Z"}
{"type":"l2update","product_id":"BTC-USD","changes":[["buy","9108.86","0.00000000"]],"time":"2020-06-30T19:17:09.845385Z"}
{"type":"l2update","product_id":"BTC-USD","changes":[["sell","9141.83","0.02440000"]],"time":"2020-06-30T19:17:10.487248Z"}
{"type":"heartbeat","last_trade_id":0,"product_id":"BTC-USD","sequence":180757290,"time":"2020-06-30T19:17:10.735108Z"}
{"type":"l2update","product_id":"BTC-USD","changes":[["sell","9144.80","0.00000000"]],"time":"2020-06-30T19:17:10.919378Z"}
{"type":"l2update","product_id":"BTC-USD","changes":[["buy","9120.80","2716.50620000"]],"time":"2020-06-30T19:17:11.074041Z"}
{"type":"l2update","product_id":"BTC-USD","changes":[["buy","9118.85","0.90000000"]],"time":"2020-06-30T19:17:11.336532Z"}
{"type":"l2update","product_id":"BTC-USD","changes":[["sell","9121.03","2.18500000"]],"time":"2020-06-30T19:17:11.603086Z"}
{"type":"heartbeat","last_trade_id":0,"product_id":"BTC-USD","sequence":180757298,"time":"2020-06-30T19:17:11.735110Z"}
{"type":"l2update","product_id":"BTC-USD","changes":[["buy","9118.37","0.00000000"]],"time":"2020-06-30T19:17:11.771601Z"}
{"type":"l2update","product_id":"BTC-USD","changes":[["sell","9122.93","0.00000000"]],"time":"2020-06-30T19:17:12.041775Z"}
{"type":"l2update","product_id":"BTC-USD","changes":[["sell","9141.83","0.00000000"]],"time":"2020-06-30T19:17:12.053177Z"}
{"type":"l2update","product_id":"BTC-USD","changes":[["buy","9117.66","0.00000000"]],"time":"2020-06-30T19:17:12.562007Z"}
{"type":"l2update","product_id":"BTC-USD","changes":[["buy","9120.80","2716.45620000"]],"time":"2020-06-30T19:17:12.686052Z"}
{"type":"heartbeat","last_trade_id":0,"product_id":"BTC-USD","sequence":180757305,"time":"2020-06-30T19:17:12.735113Z"}
{"type":"l2update","product_id":"BTC-USD","changes":[["buy","9118.31","0.11450000"]],"time":"2020-06-30T19:17:12.956461Z"}
{"type":"l2update","product_id":"BTC-USD","changes":[["sell","9154.83","0.00000000"]],"time":"2020-06-30T19:17:13.108537Z"}
{"type":"l2update","product_id":"BTC-USD","changes":[["sell","9121.03","0.00000000"]],"time":"2020-06-30T19:17:13.137872Z"}
{"type":"l2update","product_id":"BTC-USD","changes":[["buy","9117.10","0.00000000"]],"time":"2020-06-30T19:17:13.197054Z"}
{"type":"heartbeat","last_trade_id":0,"product_id":"BTC-USD","sequence":180757310,"time":"2020-06-30T19:17:13.735110Z"}
{"type":"l2update","product_id":"BTC-USD","changes":[["sell","9123.13","0.16210000"]],"time":"2020-06-30T19:17:13.786407Z"}
{"type":"l2update","product_id":"BTC-USD","changes":[["buy","100.00","114.95500000"]],"time":"2020-06-30T19:17:14.021828Z"}
{"type":"l2update","product_id":"BTC-USD","changes":[["buy","100.00","114.94500000"]],"time":"2020-06-30T19:17:14.028774Z"}
{"type":"l2update","product_id":"BTC-USD","changes":[["buy","9119.69","0.12500000"]],"time":"2020-06-30T19:17:14.331037Z"}
{"type":"l2update","product_id":"BTC-USD","changes":[["buy","9102.43","0.10000000"]],"time":"2020-06-30T19:17:14.606510Z"}
{"type":"heartbeat","last_trade_id":0,"product_id":"BTC-USD","sequence":180757319,"time":"2020-06-30T19:17:14.735109Z"}
{"type":"l2update","product_id":"BTC-USD","changes":[["buy","9118.31","0.00000000"]],"time":"2020-06-30T19:17:15.141442Z"}
{"type":"l2update","product_id":"BTC-USD","changes":[["sell","9121.51","0.02500000"]],"time":"2020-06-30T19:17:15.447116Z"}
{"type":"l2update","product_id":"BTC-USD","changes":[["buy","9094.90","0.01000000"]],"time":"2020-06-30T19:17:15.730831Z"}
{"type":"heartbeat","last_trade_id":0,"product_id":"BTC-USD","sequence":180757324,"time":"2020-06-30T19:17:15.735112Z"}
{"type":"l2update","product_id":"BTC-USD","changes":[["sell","9123.11","0.00000000"]],"time":"2020-06-30T19:17:15.871078Z"}
{"type":"l2update","product_id":"BTC-USD","changes":[["buy","9120.80","2716.30620000"]],"time":"2020-06-30T19:17:16.554515Z"}
{"type":"heartbeat","last_trade_id":0,"product_id":"BTC-USD","sequence":180757328,"time":"2020-06-30T19:17:16.735068Z"}
{"type":"l2update","product_id":"BTC-USD","changes":[["buy","9081.90","0.01000000"]],"time":"2020-06-30T19:17:16.818522Z"}
{"type":"l2update","product_id":"BTC-USD","changes":[["sell","9123.13","0.00000000"]],"time":"2020-06-30T19:17:17.007768Z"}
{"type":"l2update","product_id":"BTC-USD","changes":[["buy","9094.90","0.00000000"]],"time":"2020-06-30T19:17:17.259352Z"}
{"type":"l2update","product_id":"BTC-USD","changes":[["buy","9102.43","0.00000000"]],"time":"2020-06-30T19:17:17.260558Z"}
{"type":"l2update","product_id":"BTC-USD","changes":[["buy","9072.05","0.01000000"]],"time":"2020-06-30T19:17:17.649165Z"}
{"type":"heartbeat","last_trade_id":0,"product_id":"BTC-USD","sequence":180757335,"time":"2020-06-30T19:17:17.735046Z"}
{"type":"l2update","product_id":"BTC-USD","changes":[["buy","9120.80","2716.01460000"]],"time":"2020-06-30T19:17:17.935497Z"}
{"type":"l2update","product_id":"BTC-USD","changes":[["buy","9111.57","0.00000000"]],"time":"2020-06-30T19:17:18.095610Z"}
{"type":"l2update","product_id":"BTC-USD","changes":[["buy","9081.90","0.00000000"]],"time":"2020-06-30T19:17:18.097568Z"}
{"type":"l2update","product_id":"BTC-USD","changes":[["buy","9084.37","0.01000000"]],"time":"2020-06-30T19:17:18.232257Z"}
{"type":"l2update","product_id":"BTC-USD","changes":[["buy","9111.50","0.00000000"]],"time":"2020-06-30T19:17:18.673572Z"}
{"type":"heartbeat","last_trade_id":0,"product_id":"BTC-USD","sequence":180757343,"time":"2020-06-30T19:17:18.735095Z"}
{"type":"l2update","product_id":"BTC-USD","changes":[["sell","9121.09","0.60870000"]],"time":"2020-06-30T19:17:18.746911Z"}
{"type":"l2update","product_id":"BTC-USD","changes":[["sell","9155.64","0.06900000"]],"time":"2020-06-30T19:17:19.303556Z"}
{"type":"l2update","product_id":"BTC-USD","changes":[["sell","9121.07","0.10000000"]],"time":"2020-06-30T19:17:19.563730Z"}
{"type":"l2update","product_id":"BTC-USD","changes":[["sell","9121.93","0.00000000"]],"time":"2020-06-30T19:17:19.736383Z"}
{"type":"heartbeat","last_trade_id":0,"product_id":"BTC-USD","sequence":180757350,"time":"2020-06-30T19:17:19.735112Z"}
{"type":"l2update","product_id":"BTC-USD","changes":[["sell","9121.03","0.15000000"]],"time":"2020-06-30T19:17:19.850250Z"}
{"type":"l2update","product_id":"BTC-USD","changes":[["sell","9155.29","0.00000000"]],"time":"2020-06-30T19:17:19.987435Z"}
{"type":"l2update","product_id":"BTC-USD","changes":[["sell","9121.02","0.05000000"]],"time":"2020-06-30T19:17:20.135007Z"}
{"type":"l2update","product_id":"BTC-USD","changes":[["buy","9087.14","2.99910000"]],"time":"2020-06-30T19:17:20.407698Z"}
{"type":"l2update","product_id":"BTC-USD","changes":[["buy","9117.73","0.54190000"]],"time":"2020-06-30T19:17:20.690252Z"}
{"type":"heartbeat","last_trade_id":0,"product_id":"BTC-USD","sequence":180757359,"time":"2020-06-30T19:17:20.735067Z"}
{"type":"heartbeat","last_trade_id":0,"product_id":"BTC-USD","sequence":180757359,"time":"2020-06-30T19:17:21.735091Z"}
{"type":"l2update","product_id":"BTC-USD","changes":[["buy","9119.31","0.05000000"]],"time":"2020-06-30T19:17:22.357721Z"}
{"type":"l2update","product_id":"BTC-USD","changes":[["buy","9116.61","0.59020000"]],"time":"2020-06-30T19:17:22.613233Z"}
{"type":"heartbeat","last_trade_id":0,"product_id":"BTC-USD","sequence":180757363,"time":"2020-06-30T19:17:22.735117Z"}
{"type":"l2update","product_id":"BTC-USD","changes":[["buy","9117.73","0.00000000"]],"time":"2020-06-30T19:17:22.775235Z"}
{"type":"l2update","product_id":"BTC-USD","changes":[["buy","9119.78","0.12430000"]],"time":"2020-06-30T19:17:22.903752Z"}
{"type":"l2update","product_id":"BTC-USD","changes":[["buy","9117.47","0.00000000"]],"time":"2020-06-30T19:17:23.126434Z"}
{"type":"l2update","product_id":"BTC-USD","changes":[["sell","9157.37","0.03280000"]],"time":"2020-06-30T19:17:23.449304Z"}
{"type":"heartbeat","last_trade_id":0,"product_id":"BTC-USD","sequence":180757369,"time":"2020-06-30T19:17:23.735121Z"}
{"type":"l2update","product_id":"BTC-USD","changes":[["buy","9119.66","0.05000000"]],"time":"2020-06-30T19:17:24.025209Z"}
{"type":"l2update","product_id":"BTC-USD","changes":[["buy","9108.78","0.00000000"]],"time":"2020-06-30T19:17:24.291115Z"}
{"type":"l2update","product_id":"BTC-USD","changes":[["buy","9119.73","0.05000000"]],"time":"2020-06-30T19:17:24.339603Z"}
{"type":"heartbeat","last_trade_id":0,"product_id":"BTC-USD","sequence":180757374,"time":"2020-06-30T19:17:24.735118Z"}
{"type":"l2update","product_id":"BTC-USD","changes":[["buy","9120.30","0.06580000"]],"time":"2020-06-30T19:17:24.889156Z"}
{"type":"l2update","product_id":"BTC-USD","changes":[["buy","9094.08","0.00000000"]],"time":"2020-06-30T19:17:25.347059Z"}
{"type":"heartbeat","last_trade_id":0,"product_id":"BTC-USD","sequence":180757377,"time":"2020-06-30T19:17:25.735113Z"}
{"type":"l2update","product_id":"BTC-USD","changes":[["sell","9120.82","3006.39000000"]],"time":"2020-06-30T19:17:26.094560Z"}
{"type":"l2update","product_id":"BTC-USD","changes":[["sell","9129.79","2.58370000"]],"time":"2020-06-30T19:17:26.646025Z"}
{"type":"l2update","product_id":"BTC-USD","changes":[["buy","9120.80","2716.00460000"]],"time":"2020-06-30T19:17:26.693248Z"}
{"type":"heartbeat","last_trade_id":0,"product_id":"BTC-USD","sequence":180757385,"time":"2020-06-30T19:17:26.735119Z"}
{"type":"l2update","product_id":"BTC-USD","changes":[["buy","9120.25","0.00170000"]],"time":"2020-06-30T19:17:26.917565Z"}
{"type":"l2update","product_id":"BTC-USD","changes":[["sell","9121.09","0.00000000"]],"time":"2020-06-30T19:17:26.942035Z"}
{"type":"l2update","product_id":"BTC-USD","changes":[["buy","9087.14","0.00000000"]],"time":"2020-06-30T19:17:27.128102Z"}
{"type":"l2update","product_id":"BTC-USD","changes":[["buy","9115.62","0.37100000"]],"time":"2020-06-30T19:17:27.469133Z"}
{"type":"heartbeat","last_trade_id":0,"product_id":"BTC-USD","sequence":180757391,"time":"2020-06-30T19:17:27.735116Z"}
{"type":"l2update","product_id":"BTC-USD","changes":[["buy","9119.59","0.50000000"]],"time":"2020-06-30T19:17:28.185299Z"}
{"type":"l2update","product_id":"BTC-USD","changes":[["buy","9088.73","0.01000000"]],"time":"2020-06-30T19:17:28.740171Z"}
{"type":"heartbeat","last_trade_id":0,"product_id":"BTC-USD","sequence":180757395,"time":"2020-06-30T19:17:28.735069Z"}
{"type":"l2update","product_id":"BTC-USD","changes":[["buy","100.00","114.95500000"]],"time":"2020-06-30T19:17:29.014927Z"}
{"type":"l2update","product_id":"BTC-USD","changes":[["buy","100.00","114.94500000"]],"time":"2020-06-30T19:17:29.024193Z"}
{"type":"l2update","product_id":"BTC-USD","changes":[["sell","9121.31","0.05000000"]],"time":"2020-06-30T19:17:29.288198Z"}
{"type":"l2update","product_id":"BTC-USD","changes":[["sell","9121.02","0.00000000"]],"time":"2020-06-30T19:17:29.742875Z"}
{"type":"heartbeat","last_trade_id":0,"product_id":"BTC-USD","sequence":180757401,"time":"2020-06-30T19:17:29.735097Z"}
{"type":"l2update","product_id":"BTC-USD","changes":[["buy","9120.28","0.06580000"]],"time":"2020-06-30T19:17:29.842335Z"}
{"type":"l2update","product_id":"BTC-USD","changes":[["buy","8930.31","0.00400000"]],"time":"2020-06-30T19:17:30.101837Z"}
{"type":"l2update","product_id":"BTC-USD","changes":[["buy","9084.37","0.00000000"]],"time":"2020-06-30T19:17:30.292974Z"}
{"type":"l2update","product_id":"BTC-USD","changes":[["buy","9119.66","0.00000000"]],"time":"2020-06-30T19:17:30.519346Z"}
{"type":"heartbeat","last_trade_id":0,"product_id":"BTC-USD","sequence":180757407,"time":"2020-06-30T19:17:30.735105Z"}
{"type":"l2update","product_id":"BTC-USD","changes":[["sell","9129.79","4.13530000"]],"time":"2020-06-30T19:17:31.277028Z"}
{"type":"heartbeat","last_trade_id":0,"product_id":"BTC-USD","sequence":180757409,"time":"2020-06-30T19:17:31.735120Z"}
{"type":"l2update","product_id":"BTC-USD","changes":[["buy","9114.74","0.06580000"]],"time":"2020-06-30T19:17:32.423494Z"}
{"type":"l2update","product_id":"BTC-USD","changes":[["sell","9120.82","3001.41020000"]],"time":"2020-06-30T19:17:32.686577Z"}
{"type":"heartbeat","last_trade_id":0,"product_id":"BTC-USD","sequence":180757414,"time":"2020-06-30T19:17:32.735069Z"}
{"type":"l2update","product_id":"BTC-USD","changes":[["buy","9072.05","0.00000000"]],"time":"2020-06-30T19:17:32.862665Z"}
{"type":"l2update","product_id":"BTC-USD","changes":[["buy","8930.31","0.00000000"]],"time":"2020-06-30T19:17:32.869070Z"}
{"type":"l2update","product_id":"BTC-USD","changes":[["buy","9115.97","0.00000000"]],"time":"2020-06-30T19:17:32.926026Z"}
{"type":"heartbeat","last_trade_id":0,"product_id":"BTC-USD","sequence":180757417,"time":"2020-06-30T19:17:33.735090Z"}
{"type":"l2update","product_id":"BTC-USD","changes":[["sell","9150.39","1.11270000"]],"time":"2020-06-30T19:17:33.787404Z"}
{"type":"l2update","product_id":"BTC-USD","changes":[["sell","9154.34","0.05460000"]],"time":"2020-06-30T19:17:34.518423Z"}
{"type":"heartbeat","last_trade_id":0,"product_id":"BTC-USD","sequence":180757421,"time":"2020-06-30T19:17:34.735117Z"}
{"type":"l2update","product_id":"BTC-USD","changes":[["sell","9155.64","0.00000000"]],"time":"2020-06-30T19:17:34.923355Z"}
{"type":"l2update","product_id":"BTC-USD","changes":[["sell","9121.07","0.00000000"]],"time":"2020-06-30T19:17:34.925342Z"}
{"type":"l2update","product_id":"BTC-USD","changes":[["sell","9120.82","2992.43040000"]],"time":"2020-06-30T19:17:35.126683Z"}
{"type":"l2update","product_id":"BTC-USD","changes":[["buy","9120.25","0.00000000"]],"time":"2020-06-30T19:17:35.547475Z"}
{"type":"l2update","product_id":"BTC-USD","changes":[["buy","9118.85","0.00000000"]],"time":"2020-06-30T19:17:35.557635Z"}
{"type":"l2update","product_id":"BTC-USD","changes":[["buy","9114.74","0.96580000"]],"time":"2020-06-30T19:17:35.638033Z"}
{"type":"heartbeat","last_trade_id":0,"product_id":"BTC-USD","sequence":180757430,"time":"2020-06-30T19:17:35.735114Z"}
{"type":"l2update","product_id":"BTC-USD","changes":[["buy","9117.93","0.06580000"]],"time":"2020-06-30T19:17:35.926613Z"}
{"type":"l2update","product_id":"BTC-USD","changes":[["buy","9114.74","0.06580000"]],"time":"2020-06-30T19:17:36.156758Z"}
{"type":"l2update","product_id":"BTC-USD","changes":[["buy","9116.61","0.00000000"]],"time":"2020-06-30T19:17:36.157104Z"}
{"type":"l2update","product_id":"BTC-USD","changes":[["sell","9126.20","1.62900000"]],"time":"2020-06-30T19:17:36.211632Z"}
{"type":"l2update","product_id":"BTC-USD","changes":[["sell","9150.39","0.00000000"]],"time":"2020-06-30T19:17:36.654003Z"}
{"type":"heartbeat","last_trade_id":0,"product_id":"BTC-USD","sequence":180757437,"time":"2020-06-30T19:17:36.735119Z"}
{"type":"l2update","product_id":"BTC-USD","changes":[["buy","9114.73","1.27100000"]],"time":"2020-06-30T19:17:36.782565Z"}
{"type":"l2update","product_id":"BTC-USD","changes":[["buy","9115.62","0.00000000"]],"time":"2020-06-30T19:17:36.964669Z"}
{"type":"l2update","product_id":"BTC-USD","changes":[["buy","9114.74","0.00000000"]],"time":"2020-06-30T19:17:36.969237Z"}
{"type":"l2update","product_id":"BTC-USD","changes":[["buy","9119.78","0.00000000"]],"time":"2020-06-30T19:17:36.969707Z"}
{"type":"l2update","product_id":"BTC-USD","changes":[["buy","9086.95","0.01050000"]],"time":"2020-06-30T19:17:37.394858Z"}
{"type":"heartbeat","last_trade_id":0,"product_id":"BTC-USD","sequence":180757444,"time":"2020-06-30T19:17:37.735115Z"}
{"type":"heartbeat","last_trade_id":0,"product_id":"BTC-USD","sequence":180757444,"time":"2020-06-30T19:17:38.735123Z"}
{"type":"l2update","product_id":"BTC-USD","changes":[["sell","9153.58","0.05460000"]],"time":"2020-06-30T19:17:38.940980Z"}
{"type":"heartbeat","last_trade_id":0,"product_id":"BTC-USD","sequence":180757446,"time":"2020-06-30T19:17:39.735115Z"}
{"type":"l2update","product_id":"BTC-USD","changes":[["buy","9120.24","0.06580000"]],"time":"2020-06-30T19:17:39.855955Z"}
{"type":"l2update","product_id":"BTC-USD","changes":[["buy","9119.37","0.00000000"]],"time":"2020-06-30T19:17:40.305446Z"}
{"type":"l2update","product_id":"BTC-USD","changes":[["buy","9119.31","0.00000000"]],"time":"2020-06-30T19:17:40.308088Z"}
{"type":"l2update","product_id":"BTC-USD","changes":[["sell","9120.82","2992.42940000"]],"time":"2020-06-30T19:17:40.669815Z"}
{"type":"l2update","product_id":"BTC-USD","changes":[["sell","9121.66","0.75000000"]],"time":"2020-06-30T19:17:40.721050Z"}
{"type":"heartbeat","last_trade_id":0,"product_id":"BTC-USD","sequence":180757455,"time":"2020-06-30T19:17:40.735121Z"}
{"type":"l2update","product_id":"BTC-USD","changes":[["sell","9129.79","2.58370000"]],"time":"2020-06-30T19:17:41.152234Z"}
{"type":"l2update","product_id":"BTC-USD","changes":[["sell","9122.77","0.75000000"]],"time":"2020-06-30T19:17:41.549257Z"}
{"type":"heartbeat","last_trade_id":0,"product_id":"BTC-USD","sequence":180757458,"time":"2020-06-30T19:17:41.735113Z"}
{"type":"l2update","product_id":"BTC-USD","changes":[["sell","9121.03","0.62570000"]],"time":"2020-06-30T19:17:41.849401Z"}
{"type":"l2update","product_id":"BTC-USD","changes":[["sell","9121.66","0.00000000"]],"time":"2020-06-30T19:17:41.997473Z"}
{"type":"l2update","product_id":"BTC-USD","changes":[["sell","9157.37","0.00000000"]],"time":"2020-06-30T19:17:41.998085Z"}
{"type":"heartbeat","last_trade_id":0,"product_id":"BTC-USD","sequence":180757462,"time":"2020-06-30T19:17:42.735118Z"}
{"type":"l2update","product_id":"BTC-USD","changes":[["sell","9120.82","2987.25240000"]],"time":"2020-06-30T19:17:42.777565Z"}
{"type":"l2update","product_id":"BTC-USD","changes":[["sell","9136.27","0.92470000"]],"time":"2020-06-30T19:17:43.057858Z"}
{"type":"l2update","product_id":"BTC-USD","changes":[["buy","9117.93","0.00000000"]],"time":"2020-06-30T19:17:43.226043Z"}
{"type":"l2update","product_id":"BTC-USD","changes":[["buy","9120.28","0.00000000"]],"time":"2020-06-30T19:17:43.235414Z"}
{"type":"l2update","product_id":"BTC-USD","changes":[["buy","9088.73","0.00000000"]],"time":"2020-06-30T19:17:43.243474Z"}
{"type":"l2update","product_id":"BTC-USD","changes":[["buy","9120.25","0.90000000"]],"time":"2020-06-30T19:17:43.331390Z"}
{"type":"heartbeat","last_trade_id":0,"product_id":"BTC-USD","sequence":180757472,"time":"2020-06-30T19:17:43.735114Z"}
{"type":"l2update","product_id":"BTC-USD","changes":[["buy","9086.95","0.00000000"]],"time":"2020-06-30T19:17:43.783798Z"}
{"type":"l2update","product_id":"BTC-USD","changes":[["buy","100.00","114.95500000"]],"time":"2020-06-30T19:17:44.034868Z"}
{"type":"l2update","product_id":"BTC-USD","changes":[["buy","100.00","114.94500000"]],"time":"2020-06-30T19:17:44.040900Z"}
{"type":"heartbeat","last_trade_id":0,"product_id":"BTC-USD","sequence":180757476,"time":"2020-06-30T19:17:44.735116Z"}
{"type":"l2update","product_id":"BTC-USD","changes":[["buy","9115.09","0.06580000"]],"time":"2020-06-30T19:17:45.721421Z"}
{"type":"heartbeat","last_trade_id":0,"product_id":"BTC-USD","sequence":180757478,"time":"2020-06-30T19:17:45.735118Z"}
{"type":"l2update","product_id":"BTC-USD","changes":[["buy","9088.73","0.01000000"]],"time":"2020-06-30T19:17:46.580955Z"}
{"type":"heartbeat","last_trade_id":0,"product_id":"BTC-USD","sequence":180757480,"time":"2020-06-30T19:17:46.735118Z"}
{"type":"l2update","product_id":"BTC-USD","changes":[["buy","9120.25","1.86580000"]],"time":"2020-06-30T19:17:46.875039Z"}
{"type":"l2update","product_id":"BTC-USD","changes":[["buy","9119.73","0.00000000"]],"time":"2020-06-30T19:17:47.066387Z"}
{"type":"l2update","product_id":"BTC-USD","changes":[["buy","9120.24","0.00000000"]],"time":"2020-06-30T19:17:47.066485Z"}
{"type":"l2update","product_id":"BTC-USD","changes":[["buy","9120.30","0.00000000"]],"time":"2020-06-30T19:17:47.069017Z"}
{"type":"l2update","product_id":"BTC-USD","changes":[["buy","9117.77","0.00000000"]],"time":"2020-06-30T19:17:47.313504Z"}
{"type":"heartbeat","last_trade_id":0,"product_id":"BTC-USD","sequence":180757486,"time":"2020-06-30T19:17:47.735114Z"}
{"type":"l2update","product_id":"BTC-USD","changes":[["buy","9120.25","0.90000000"]],"time":"2020-06-30T19:17:47.881277Z"}
{"type":"l2update","product_id":"BTC-USD","changes":[["buy","9118.41","0.00000000"]],"time":"2020-06-30T19:17:47.882562Z"}
{"type":"l2update","product_id":"BTC-USD","changes":[["buy","9118.25","0.04930000"]],"time":"2020-06-30T19:17:48.090977Z"}
{"type":"l2update","product_id":"BTC-USD","changes":[["buy","9088.73","0.00000000"]],"time":"2020-06-30T19:17:48.509861Z"}
{"type":"l2update","product_id":"BTC-USD","changes":[["sell","9120.82","2982.68840000"]],"time":"2020-06-30T19:17:48.666395Z"}
{"type":"heartbeat","last_trade_id":0,"product_id":"BTC-USD","sequence":180757494,"time":"2020-06-30T19:17:48.735115Z"}
{"type":"l2update","product_id":"BTC-USD","changes":[["sell","9122.98","0.25000000"]],"time":"2020-06-30T19:17:48.975552Z"}
{"type":"l2update","product_id":"BTC-USD","changes":[["sell","9121.03","0.47570000"]],"time":"2020-06-30T19:17:49.429814Z"}
{"type":"l2update","product_id":"BTC-USD","changes":[["sell","9155.51","0.06900000"]],"time":"2020-06-30T19:17:49.525477Z"}
{"type":"l2update","product_id":"BTC-USD","changes":[["sell","9153.58","0.00000000"]],"time":"2020-06-30T19:17:49.716934Z"}
{"type":"heartbeat","last_trade_id":0,"product_id":"BTC-USD","sequence":180757500,"time":"2020-06-30T19:17:49.735116Z"}
{"type":"l2update","product_id":"BTC-USD","changes":[["sell","9124.73","2.61590000"]],"time":"2020-06-30T19:17:49.841945Z"}
{"type":"l2update","product_id":"BTC-USD","changes":[["sell","9154.97","0.06900000"]],"time":"2020-06-30T19:17:50.089587Z"}
{"type":"l2update","product_id":"BTC-USD","changes":[["sell","9155.37","0.00000000"]],"time":"2020-06-30T19:17:50.539104Z"}
{"type":"l2update","product_id":"BTC-USD","changes":[["sell","9122.77","0.00000000"]],"time":"2020-06-30T19:17:50.540519Z"}
{"type":"heartbeat","last_trade_id":0,"product_id":"BTC-USD","sequence":180757506,"time":"2020-06-30T19:17:50.735113Z"}
{"type":"l2update","product_id":"BTC-USD","changes":[["sell","9155.64","0.06900000"]],"time":"2020-06-30T19:17:51.251089Z"}
{"type":"l2update","product_id":"BTC-USD","changes":[["sell","9121.51","0.00000000"]],"time":"2020-06-30T19:17:51.717979Z"}
{"type":"heartbeat","last_trade_id":0,"product_id":"BTC-USD","sequence":180757509,"time":"2020-06-30T19:17:51.735116Z"}
{"type":"l2update","product_id":"BTC-USD","changes":[["sell","9140.28","0.02210000"]],"time":"2020-06-30T19:17:52.121879Z"}
{"type":"l2update","product_id":"BTC-USD","changes":[["sell","9124.73","0.00000000"]],"time":"2020-06-30T19:17:52.540189Z"}
{"type":"heartbeat","last_trade_id":0,"product_id":"BTC-USD","sequence":180757512,"time":"2020-06-30T19:17:52.735109Z"}
{"type":"l2update","product_id":"BTC-USD","changes":[["buy","9092.16","0.01000000"]],"time":"2020-06-30T19:17:52.751989Z"}
{"type":"l2update","product_id":"BTC-USD","changes":[["buy","9120.25","0.00000000"]],"time":"2020-06-30T19:17:53.215660Z"}
{"type":"heartbeat","last_trade_id":0,"product_id":"BTC-USD","sequence":180757515,"time":"2020-06-30T19:17:53.735109Z"}
{"type":"heartbeat","last_trade_id":0,"product_id":"BTC-USD","sequence":180757515,"time":"2020-06-30T19:17:54.735112Z"}
{"type":"l2update","product_id":"BTC-USD","changes":[["sell","9148.34","0.39170000"]],"time":"2020-06-30T19:17:54.999004Z"}
{"type":"l2update","product_id":"BTC-USD","changes":[["buy","9103.20","0.02830000"]],"time":"2020-06-30T19:17:55.279318Z"}
{"type":"l2update","product_id":"BTC-USD","changes":[["sell","9154.34","0.00000000"]],"time":"2020-06-30T19:17:55.424698Z"}
{"type":"l2update","product_id":"BTC-USD","changes":[["sell","9122.98","0.00000000"]],"time":"2020-06-30T19:17:55.429420Z"}
{"type":"l2update","product_id":"BTC-USD","changes":[["sell","9154.97","0.00000000"]],"time":"2020-06-30T19:17:55.446116Z"}
{"type":"l2update","product_id":"BTC-USD","changes":[["buy","9120.25","0.90000000"]],"time":"2020-06-30T19:17:55.566076Z"}
{"type":"l2update","product_id":"BTC-USD","changes":[["buy","9119.69","0.00000000"]],"time":"2020-06-30T19:17:55.714555Z"}
{"type":"heartbeat","last_trade_id":0,"product_id":"BTC-USD","sequence":180757525,"time":"2020-06-30T19:17:55.735068Z"}
{"type":"l2update","product_id":"BTC-USD","changes":[["sell","9124.43","0.54100000"]],"time":"2020-06-30T19:17:55.853616Z"}
{"type":"l2update","product_id":"BTC-USD","changes":[["buy","9119.59","0.00000000"]],"time":"2020-06-30T19:17:56.016074Z"}
{"type":"l2update","product_id":"BTC-USD","changes":[["sell","9148.34","0.00000000"]],"time":"2020-06-30T19:17:56.307559Z"}
{"type":"l2update","product_id":"BTC-USD","changes":[["buy","7600.00","61.71120000"]],"time":"2020-06-30T19:17:56.470033Z"}
{"type":"l2update","product_id":"BTC-USD","changes":[["buy","9119.12","0.90000000"]],"time":"2020-06-30T19:17:56.736463Z"}
{"type":"heartbeat","last_trade_id":0,"product_id":"BTC-USD","sequence":180757533,"time":"2020-06-30T19:17:56.735051Z"}
{"type":"l2update","product_id":"BTC-USD","changes":[["buy","9120.25","0.00000000"]],"time":"2020-06-30T19:17:56.895842Z"}
{"type":"l2update","product_id":"BTC-USD","changes":[["buy","9103.20","0.00000000"]],"time":"2020-06-30T19:17:56.917310Z"}
{"type":"l2update","product_id":"BTC-USD","changes":[["sell","9123.11","0.54400000"]],"time":"2020-06-30T19:17:57.040599Z"}
{"type":"l2update","product_id":"BTC-USD","changes":[["buy","9092.16","0.00000000"]],"time":"2020-06-30T19:17:57.189197Z"}
{"type":"l2update","product_id":"BTC-USD","changes":[["sell","9123.46","0.25000000"]],"time":"2020-06-30T19:17:57.307626Z"}
{"type":"l2update","product_id":"BTC-USD","changes":[["sell","9136.27","0.00000000"]],"time":"2020-06-30T19:17:57.531856Z"}
{"type":"l2update","product_id":"BTC-USD","changes":[["sell","9121.03","0.00000000"]],"time":"2020-06-30T19:17:57.559104Z"}
{"type":"heartbeat","last_trade_id":0,"product_id":"BTC-USD","sequence":180757542,"time":"2020-06-30T19:17:57.735034Z"}
{"type":"l2update","product_id":"BTC-USD","changes":[["sell","9124.72","0.37100000"]],"time":"2020-06-30T19:17:57.871795Z"}
{"type":"l2update","product_id":"BTC-USD","changes":[["sell","9131.30","0.92470000"]],"time":"2020-06-30T19:17:58.166447Z"}
{"type":"l2update","product_id":"BTC-USD","changes":[["sell","9123.11","0.00000000"]],"time":"2020-06-30T19:17:58.317614Z"}
{"type":"l2update","product_id":"BTC-USD","changes":[["sell","9121.31","0.00000000"]],"time":"2020-06-30T19:17:58.324774Z"}
{"type":"l2update","product_id":"BTC-USD","changes":[["buy","9099.67","0.02830000"]],"time":"2020-06-30T19:17:58.732797Z"}
{"type":"heartbeat","last_trade_id":0,"product_id":"BTC-USD","sequence":180757550,"time":"2020-06-30T19:17:58.735092Z"}
{"type":"l2update","product_id":"BTC-USD","changes":[["buy","100.00","114.95500000"]],"time":"2020-06-30T19:17:59.016710Z"}
{"type":"l2update","product_id":"BTC-USD","changes":[["buy","100.00","114.94500000"]],"time":"2020-06-30T19:17:59.026398Z"}
{"type":"heartbeat","last_trade_id":0,"product_id":"BTC-USD","sequence":180757553,"time":"2020-06-30T19:17:59.735112Z"}
{"type":"l2update","product_id":"BTC-USD","changes":[["buy","8890.86","0.00000000"]],"time":"2020-06-30T19:18:00.172603Z"}
{"type":"l2update","product_id":"BTC-USD","changes":[["buy","8890.10","0.04692522"]],"time":"2020-06-30T19:18:00.458907Z"}
{"type":"l2update","product_id":"BTC-USD","changes":[["sell","9440.29","0.00000000"]],"time":"2020-06-30T19:18:00.677207Z"}
{"type":"heartbeat","last_trade_id":0,"product_id":"BTC-USD","sequence":180757557,"time":"2020-06-30T19:18:00.735060Z"}
{"type":"l2update","product_id":"BTC-USD","changes":[["buy","9120.15","0.06580000"]],"time":"2020-06-30T19:18:00.798690Z"}
{"type":"l2update","product_id":"BTC-USD","changes":[["sell","9441.09","0.00766091"]],"time":"2020-06-30T19:18:00.937526Z"}
{"type":"l2update","product_id":"BTC-USD","changes":[["sell","9120.82","2982.46500000"]],"time":"2020-06-30T19:18:00.969298Z"}
{"type":"l2update","product_id":"BTC-USD","changes":[["buy","9113.09","0.06580000"]],"time":"2020-06-30T19:18:01.560593Z"}
{"type":"heartbeat","last_trade_id":0,"product_id":"BTC-USD","sequence":180757566,"time":"2020-06-30T19:18:01.735105Z"}
{"type":"l2update","product_id":"BTC-USD","changes":[["buy","9113.10","0.02220000"]],"time":"2020-06-30T19:18:01.906106Z"}
{"type":"l2update","product_id":"BTC-USD","changes":[["buy","9120.15","0.00000000"]],"time":"2020-06-30T19:18:02.213600Z"}
{"type":"heartbeat","last_trade_id":0,"product_id":"BTC-USD","sequence":180757569,"time":"2020-06-30T19:18:02.735113Z"}
{"type":"l2update","product_id":"BTC-USD","changes":[["buy","9086.68","0.05500000"]],"time":"2020-06-30T19:18:02.773458Z"}
{"type":"l2update","product_id":"BTC-USD","changes":[["buy","9088.19","0.01050000"]],"time":"2020-06-30T19:18:03.042088Z"}
{"type":"l2update","product_id":"BTC-USD","changes":[["sell","9121.34","0.25020000"]],"time":"2020-06-30T19:18:03.356452Z"}
{"type":"heartbeat","last_trade_id":0,"product_id":"BTC-USD","sequence":180757575,"time":"2020-06-30T19:18:03.735114Z"}
{"type":"l2update","product_id":"BTC-USD","changes":[["sell","9126.20","0.00000000"]],"time":"2020-06-30T19:18:03.823994Z"}
{"type":"l2update","product_id":"BTC-USD","changes":[["sell","9124.43","0.00000000"]],"time":"2020-06-30T19:18:03.825146Z"}
{"type":"l2update","product_id":"BTC-USD","changes":[["buy","9120.13","0.06580000"]],"time":"2020-06-30T19:18:03.913320Z"}
{"type":"l2update","product_id":"BTC-USD","changes":[["sell","9122.97","0.54200000"]],"time":"2020-06-30T19:18:04.184986Z"}
{"type":"l2update","product_id":"BTC-USD","changes":[["sell","9123.46","0.00000000"]],"time":"2020-06-30T19:18:04.416233Z"}
{"type":"heartbeat","last_trade_id":0,"product_id":"BTC-USD","sequence":180757582,"time":"2020-06-30T19:18:04.735101Z"}
{"type":"l2update","product_id":"BTC-USD","changes":[["sell","9120.82","2982.28700000"]],"time":"2020-06-30T19:18:05.067685Z"}
{"type":"l2update","product_id":"BTC-USD","changes":[["buy","9088.19","0.00000000"]],"time":"2020-06-30T19:18:05.510608Z"}
{"type":"l2update","product_id":"BTC-USD","changes":[["buy","9086.68","0.00000000"]],"time":"2020-06-30T19:18:05.518593Z"}
{"type":"l2update","product_id":"BTC-USD","changes":[["buy","7600.00","0.00000000"]],"time":"2020-06-30T19:18:05.522950Z"}
{"type":"l2update","product_id":"BTC-USD","changes":[["buy","9084.01","0.03290000"]],"time":"2020-06-30T19:18:05.614115Z"}
{"type":"heartbeat","last_trade_id":0,"product_id":"BTC-USD","sequence":180757590,"time":"2020-06-30T19:18:05.735094Z"}
{"type":"l2update","product_id":"BTC-USD","changes":[["sell","9175.72","0.00200000"]],"time":"2020-06-30T19:18:05.933173Z"}
{"type":"l2update","product_id":"BTC-USD","changes":[["sell","9129.79","0.00000000"]],"time":"2020-06-30T19:18:06.155535Z"}
{"type":"heartbeat","last_trade_id":0,"product_id":"BTC-USD","sequence":180757593,"time":"2020-06-30T19:18:06.735122Z"}
{"type":"l2update","product_id":"BTC-USD","changes":[["sell","9125.11","0.06580000"]],"time":"2020-06-30T19:18:07.359289Z"}
{"type":"l2update","product_id":"BTC-USD","changes":[["sell","9120.82","2982.16270000"]],"time":"2020-06-30T19:18:07.639354Z"}
{"type":"heartbeat","last_trade_id":0,"product_id":"BTC-USD","sequence":180757598,"time":"2020-06-30T19:18:07.734987Z"}
{"type":"l2update","product_id":"BTC-USD","changes":[["buy","9119.12","0.00000000"]],"time":"2020-06-30T19:18:08.109319Z"}
{"type":"l2update","product_id":"BTC-USD","changes":[["sell","9125.14","0.06580000"]],"time":"2020-06-30T19:18:08.210443Z"}
{"type":"l2update","product_id":"BTC-USD","changes":[["sell","9120.82","2982.03840000"]],"time":"2020-06-30T19:18:08.470570Z"}
{"type":"l2update","product_id":"BTC-USD","changes":[["sell","9175.72","0.00000000"]],"time":"2020-06-30T19:18:08.656977Z"}
{"type":"l2update","product_id":"BTC-USD","changes":[["buy","9084.01","0.00000000"]],"time":"2020-06-30T19:18:08.663765Z"}
{"type":"l2update","product_id":"BTC-USD","changes":[["buy","9120.13","0.00000000"]],"time":"2020-06-30T19:18:08.671247Z"}
{"type":"heartbeat","last_trade_id":0,"product_id":"BTC-USD","sequence":180757607,"time":"2020-06-30T19:18:08.735129Z"}
{"type":"l2update","product_id":"BTC-USD","changes":[["sell","9122.34","0.08810000"]],"time":"2020-06-30T19:18:08.751970Z"}
{"type":"l2update","product_id":"BTC-USD","changes":[["sell","9155.51","0.00000000"]],"time":"2020-06-30T19:18:08.953880Z"}
{"type":"l2update","product_id":"BTC-USD","changes":[["sell","9121.79","0.05000000"]],"time":"2020-06-30T19:18:09.017089Z"}
{"type":"l2update","product_id":"BTC-USD","changes":[["buy","9081.95","0.03290000"]],"time":"2020-06-30T19:18:09.277863Z"}
{"type":"l2update","product_id":"BTC-USD","changes":[["buy","9120.14","0.06120000"]],"time":"2020-06-30T19:18:09.583120Z"}
{"type":"heartbeat","last_trade_id":0,"product_id":"BTC-USD","sequence":180757616,"time":"2020-06-30T19:18:09.735077Z"}
{"type":"l2update","product_id":"BTC-USD","changes":[["sell","9125.12","0.06580000"]],"time":"2020-06-30T19:18:10.128505Z"}
{"type":"l2update","product_id":"BTC-USD","changes":[["sell","9121.34","0.00000000"]],"time":"2020-06-30T19:18:10.561558Z"}
{"type":"l2update","product_id":"BTC-USD","changes":[["sell","9121.24","0.05000000"]],"time":"2020-06-30T19:18:10.675680Z"}
{"type":"l2update","product_id":"BTC-USD","changes":[["buy","9120.80","2716.00360000"]],"time":"2020-06-30T19:18:10.679392Z"}
{"type":"heartbeat","last_trade_id":0,"product_id":"BTC-USD","sequence":180757624,"time":"2020-06-30T19:18:10.735049Z"}
{"type":"l2update","product_id":"BTC-USD","changes":[["buy","9117.70","0.00120000"]],"time":"2020-06-30T19:18:11.260586Z"}
{"type":"l2update","product_id":"BTC-USD","changes":[["buy","9113.01","0.06580000"]],"time":"2020-06-30T19:18:11.532527Z"}
{"type":"l2update","product_id":"BTC-USD","changes":[["buy","9114.73","0.00000000"]],"time":"2020-06-30T19:18:11.732632Z"}
{"type":"heartbeat","last_trade_id":0,"product_id":"BTC-USD","sequence":180757629,"time":"2020-06-30T19:18:11.735096Z"}
{"type":"l2update","product_id":"BTC-USD","changes":[["buy","9120.14","0.00000000"]],"time":"2020-06-30T19:18:11.968293Z"}
{"type":"l2update","product_id":"BTC-USD","changes":[["buy","9113.04","0.06580000"]],"time":"2020-06-30T19:18:12.708758Z"}
{"type":"heartbeat","last_trade_id":0,"product_id":"BTC-USD","sequence":180757632,"time":"2020-06-30T19:18:12.735110Z"}
{"type":"l2update","product_id":"BTC-USD","changes":[["buy","9091.19","0.01000000"]],"time":"2020-06-30T19:18:12.986793Z"}
{"type":"l2update","product_id":"BTC-USD","changes":[["buy","9113.09","0.00000000"]],"time":"2020-06-30T19:18:13.191192Z"}
{"type":"l2update","product_id":"BTC-USD","changes":[["buy","9113.10","0.00000000"]],"time":"2020-06-30T19:18:13.204095Z"}
{"type":"l2update","product_id":"BTC-USD","changes":[["buy","9113.03","0.02220000"]],"time":"2020-06-30T19:18:13.300049Z"}
{"type":"l2update","product_id":"BTC-USD","changes":[["sell","9121.42","3.04370000"]],"time":"2020-06-30T19:18:13.535775Z"}
{"type":"l2update","product_id":"BTC-USD","changes":[["sell","9140.28","0.00000000"]],"time":"2020-06-30T19:18:13.732583Z"}
{"type":"heartbeat","last_trade_id":0,"product_id":"BTC-USD","sequence":180757641,"time":"2020-06-30T19:18:13.735115Z"}
{"type":"l2update","product_id":"BTC-USD","changes":[["buy","9113.07","0.06580000"]],"time":"2020-06-30T19:18:13.818857Z"}
{"type":"l2update","product_id":"BTC-USD","changes":[["buy","100.00","114.95500000"]],"time":"2020-06-30T19:18:14.038530Z"}
{"type":"l2update","product_id":"BTC-USD","changes":[["buy","100.00","114.94500000"]],"time":"2020-06-30T19:18:14.044382Z"}
{"type":"l2update","product_id":"BTC-USD","changes":[["sell","9125.09","1.64000000"]],"time":"2020-06-30T19:18:14.700273Z"}
{"type":"heartbeat","last_trade_id":0,"product_id":"BTC-USD","sequence":180757648,"time":"2020-06-30T19:18:14.735113Z"}
{"type":"l2update","product_id":"BTC-USD","changes":[["sell","9144.07","1.53380000"]],"time":"2020-06-30T19:18:14.973589Z"}
{"type":"l2update","product_id":"BTC-USD","changes":[["sell","9121.42","0.00000000"]],"time":"2020-06-30T19:18:15.129988Z"}
{"type":"l2update","product_id":"BTC-USD","changes":[["buy","9101.43","0.01000000"]],"time":"2020-06-30T19:18:15.251283Z"}
{"type":"l2update","product_id":"BTC-USD","changes":[["sell","9125.09","0.00000000"]],"time":"2020-06-30T19:18:15.427627Z"}
{"type":"l2update","product_id":"BTC-USD","changes":[["sell","9122.34","0.00000000"]],"time":"2020-06-30T19:18:15.430792Z"}
{"type":"l2update","product_id":"BTC-USD","changes":[["sell","9124.94","0.06580000"]],"time":"2020-06-30T19:18:15.531119Z"}
{"type":"l2update","product_id":"BTC-USD","changes":[["buy","9113.01","0.00000000"]],"time":"2020-06-30T19:18:15.692506Z"}
{"type":"l2update","product_id":"BTC-USD","changes":[["buy","9081.95","0.00000000"]],"time":"2020-06-30T19:18:15.703248Z"}
{"type":"heartbeat","last_trade_id":0,"product_id":"BTC-USD","sequence":180757659,"time":"2020-06-30T19:18:15.735060Z"}
{"type":"l2update","product_id":"BTC-USD","changes":[["sell","9125.11","0.00000000"]],"time":"2020-06-30T19:18:15.978651Z"}
{"type":"l2update","product_id":"BTC-USD","changes":[["sell","9121.24","0.00000000"]],"time":"2020-06-30T19:18:15.984762Z"}
{"type":"l2update","product_id":"BTC-USD","changes":[["sell","9120.82","2981.87430000"]],"time":"2020-06-30T19:18:16.075490Z"}
{"type":"l2update","product_id":"BTC-USD","changes":[["buy","9117.70","0.00000000"]],"time":"2020-06-30T19:18:16.295268Z"}
{"type":"l2update","product_id":"BTC-USD","changes":[["sell","9133.78","0.03250000"]],"time":"2020-06-30T19:18:16.345297Z"}
{"type":"l2update","product_id":"BTC-USD","changes":[["sell","9166.62","29.67900000"]],"time":"2020-06-30T19:18:16.635126Z"}
{"type":"heartbeat","last_trade_id":0,"product_id":"BTC-USD","sequence":180757669,"time":"2020-06-30T19:18:16.735118Z"}
{"type":"l2update","product_id":"BTC-USD","changes":[["sell","9120.82","2981.78260000"]],"time":"2020-06-30T19:18:16.903518Z"}
{"type":"l2update","product_id":"BTC-USD","changes":[["buy","9118.87","0.04950000"]],"time":"2020-06-30T19:18:17.205451Z"}
{"type":"l2update","product_id":"BTC-USD","changes":[["buy","9113.03","0.00000000"]],"time":"2020-06-30T19:18:17.329778Z"}
{"type":"heartbeat","last_trade_id":0,"product_id":"BTC-USD","sequence":180757675,"time":"2020-06-30T19:18:17.735108Z"}
{"type":"l2update","product_id":"BTC-USD","changes":[["buy","9087.43","0.07360000"]],"time":"2020-06-30T19:18:17.999488Z"}
{"type":"l2update","product_id":"BTC-USD","changes":[["buy","9106.72","0.01000000"]],"time":"2020-06-30T19:18:18.289540Z"}
{"type":"l2update","product_id":"BTC-USD","changes":[["buy","9118.87","0.00000000"]],"time":"2020-06-30T19:18:18.425008Z"}
{"type":"l2update","product_id":"BTC-USD","changes":[["buy","9115.52","0.02220000"]],"time":"2020-06-30T19:18:18.566422Z"}
{"type":"heartbeat","last_trade_id":0,"product_id":"BTC-USD","sequence":180757682,"time":"2020-06-30T19:18:18.735115Z"}
{"type":"heartbeat","last_trade_id":0,"product_id":"BTC-USD","sequence":180757682,"time":"2020-06-30T19:18:19.735060Z"}
{"type":"l2update","product_id":"BTC-USD","changes":[["buy","9062.97","0.08770000"]],"time":"2020-06-30T19:18:19.882002Z"}
{"type":"l2update","product_id":"BTC-USD","changes":[["buy","9115.09","0.00000000"]],"time":"2020-06-30T19:18:20.285267Z"}
{"type":"heartbeat","last_trade_id":0,"product_id":"BTC-USD","sequence":180757685,"time":"2020-06-30T19:18:20.735038Z"}
{"type":"l2update","product_id":"BTC-USD","changes":[["buy","9115.64","0.02220000"]],"time":"2020-06-30T19:18:21.019379Z"}
{"type":"l2update","product_id":"BTC-USD","changes":[["buy","9106.72","0.00000000"]],"time":"2020-06-30T19:18:21.481618Z"}
{"type":"heartbeat","last_trade_id":0,"product_id":"BTC-USD","sequence":180757688,"time":"2020-06-30T19:18:21.735049Z"}
{"type":"l2update","product_id":"BTC-USD","changes":[["buy","9115.69","0.06580000"]],"time":"2020-06-30T19:18:21.837258Z"}
{"type":"l2update","product_id":"BTC-USD","changes":[["sell","9155.69","0.01000000"]],"time":"2020-06-30T19:18:22.127087Z"}
{"type":"l2update","product_id":"BTC-USD","changes":[["buy","9087.43","0.00000000"]],"time":"2020-06-30T19:18:22.260866Z"}
{"type":"l2update","product_id":"BTC-USD","changes":[["buy","9099.67","0.00000000"]],"time":"2020-06-30T19:18:22.268586Z"}
{"type":"l2update","product_id":"BTC-USD","changes":[["buy","9092.56","0.01000000"]],"time":"2020-06-30T19:18:22.390097Z"}
{"type":"l2update","product_id":"BTC-USD","changes":[["sell","9131.30","0.00000000"]],"time":"2020-06-30T19:18:22.555002Z"}
{"type":"l2update","product_id":"BTC-USD","changes":[["sell","9121.79","0.00000000"]],"time":"2020-06-30T19:18:22.595274Z"}
{"type":"heartbeat","last_trade_id":0,"product_id":"BTC-USD","sequence":180757698,"time":"2020-06-30T19:18:22.735097Z"}
{"type":"l2update","product_id":"BTC-USD","changes":[["buy","9115.52","0.00000000"]],"time":"2020-06-30T19:18:22.845492Z"}
{"type":"l2update","product_id":"BTC-USD","changes":[["buy","9118.93","0.04950000"]],"time":"2020-06-30T19:18:22.945131Z"}
{"type":"heartbeat","last_trade_id":0,"product_id":"BTC-USD","sequence":180757701,"time":"2020-06-30T19:18:23.735072Z"}
{"type":"l2update","product_id":"BTC-USD","changes":[["buy","9115.16","0.02220000"]],"time":"2020-06-30T19:18:24.453620Z"}
{"type":"l2update","product_id":"BTC-USD","changes":[["buy","9115.19","0.06580000"]],"time":"2020-06-30T19:18:24.742027Z"}
{"type":"heartbeat","last_trade_id":0,"product_id":"BTC-USD","sequence":180757705,"time":"2020-06-30T19:18:24.735038Z"}
{"type":"l2update","product_id":"BTC-USD","changes":[["buy","9113.07","0.00000000"]],"time":"2020-06-30T19:18:24.943657Z"}
{"type":"l2update","product_id":"BTC-USD","changes":[["buy","9062.97","0.00000000"]],"time":"2020-06-30T19:18:25.217565Z"}
{"type":"l2update","product_id":"BTC-USD","changes":[["sell","9124.00","0.08850000"]],"time":"2020-06-30T19:18:25.695373Z"}
{"type":"heartbeat","last_trade_id":0,"product_id":"BTC-USD","sequence":180757709,"time":"2020-06-30T19:18:25.735096Z"}
{"type":"l2update","product_id":"BTC-USD","changes":[["sell","9166.62","0.00000000"]],"time":"2020-06-30T19:18:26.153925Z"}
{"type":"l2update","product_id":"BTC-USD","changes":[["sell","9124.00","4.17700000"]],"time":"2020-06-30T19:18:26.556045Z"}
{"type":"heartbeat","last_trade_id":0,"product_id":"BTC-USD","sequence":180757712,"time":"2020-06-30T19:18:26.735119Z"}
{"type":"l2update","product_id":"BTC-USD","changes":[["sell","9137.53","0.10000000"]],"time":"2020-06-30T19:18:26.826699Z"}
{"type":"l2update","product_id":"BTC-USD","changes":[["sell","9155.64","0.00000000"]],"time":"2020-06-30T19:18:27.038058Z"}
{"type":"heartbeat","last_trade_id":0,"product_id":"BTC-USD","sequence":180757715,"time":"2020-06-30T19:18:27.735114Z"}
{"type":"l2update","product_id":"BTC-USD","changes":[["sell","9120.82","2981.76850000"]],"time":"2020-06-30T19:18:27.914957Z"}
{"type":"heartbeat","last_trade_id":0,"product_id":"BTC-USD","sequence":180757718,"time":"2020-06-30T19:18:28.735113Z"}
{"type":"l2update","product_id":"BTC-USD","changes":[["buy","100.00","114.95500000"]],"time":"2020-06-30T19:18:29.059496Z"}
{"type":"l2update","product_id":"BTC-USD","changes":[["buy","100.00","114.94500000"]],"time":"2020-06-30T19:18:29.066958Z"}
{"type":"heartbeat","last_trade_id":0,"product_id":"BTC-USD","sequence":180757721,"time":"2020-06-30T19:18:29.735110Z"}
{"type":"l2update","product_id":"BTC-USD","changes":[["buy","9087.43","0.07360000"]],"time":"2020-06-30T19:18:29.858520Z"}
{"type":"l2update","product_id":"BTC-USD","changes":[["buy","9115.19","0.00000000"]],"time":"2020-06-30T19:18:30.076893Z"}
{"type":"l2update","product_id":"BTC-USD","changes":[["buy","9115.64","0.00000000"]],"time":"2020-06-30T19:18:30.079895Z"}
{"type":"l2update","product_id":"BTC-USD","changes":[["sell","9120.82","2981.56130000"]],"time":"2020-06-30T19:18:30.132539Z"}
{"type":"l2update","product_id":"BTC-USD","changes":[["buy","9119.20","0.54600000"]],"time":"2020-06-30T19:18:30.400371Z"}
{"type":"l2update","product_id":"BTC-USD","changes":[["buy","9087.43","0.00000000"]],"time":"2020-06-30T19:18:30.604060Z"}
{"type":"l2update","product_id":"BTC-USD","changes":[["buy","9092.56","0.00000000"]],"time":"2020-06-30T19:18:30.610374Z"}
{"type":"heartbeat","last_trade_id":0,"product_id":"BTC-USD","sequence":180757732,"time":"2020-06-30T19:18:30.735113Z"}
{"type":"l2update","product_id":"BTC-USD","changes":[["sell","9124.95","0.06580000"]],"time":"2020-06-30T19:18:30.975509Z"}
{"type":"l2update","product_id":"BTC-USD","changes":[["sell","9120.82","2980.66130000"]],"time":"2020-06-30T19:18:31.236682Z"}
{"type":"l2update","product_id":"BTC-USD","changes":[["sell","9125.14","0.00000000"]],"time":"2020-06-30T19:18:31.420821Z"}
{"type":"heartbeat","last_trade_id":0,"product_id":"BTC-USD","sequence":180757738,"time":"2020-06-30T19:18:31.735118Z"}
{"type":"l2update","product_id":"BTC-USD","changes":[["sell","9124.34","0.20000000"]],"time":"2020-06-30T19:18:32.056843Z"}
{"type":"l2update","product_id":"BTC-USD","changes":[["sell","9120.82","2980.61130000"]],"time":"2020-06-30T19:18:32.339070Z"}
{"type":"l2update","product_id":"BTC-USD","changes":[["sell","9125.12","0.00000000"]],"time":"2020-06-30T19:18:32.485159Z"}
{"type":"l2update","product_id":"BTC-USD","changes":[["sell","9124.60","0.05000000"]],"time":"2020-06-30T19:18:32.616349Z"}
{"type":"heartbeat","last_trade_id":0,"product_id":"BTC-USD","sequence":180757746,"time":"2020-06-30T19:18:32.735119Z"}
{"type":"l2update","product_id":"BTC-USD","changes":[["sell","9120.82","2980.47340000"]],"time":"2020-06-30T19:18:33.730151Z"}
{"type":"heartbeat","last_trade_id":0,"product_id":"BTC-USD","sequence":180757749,"time":"2020-06-30T19:18:33.735116Z"}
{"type":"l2update","product_id":"BTC-USD","changes":[["sell","9120.82","2980.45930000"]],"time":"2020-06-30T19:18:34.013460Z"}
{"type":"l2update","product_id":"BTC-USD","changes":[["buy","9101.43","0.00000000"]],"time":"2020-06-30T19:18:34.198066Z"}
{"type":"l2update","product_id":"BTC-USD","changes":[["buy","9119.20","0.00000000"]],"time":"2020-06-30T19:18:34.234401Z"}
{"type":"l2update","product_id":"BTC-USD","changes":[["buy","9091.19","0.00000000"]],"time":"2020-06-30T19:18:34.244785Z"}
{"type":"l2update","product_id":"BTC-USD","changes":[["sell","9120.82","2980.33500000"]],"time":"2020-06-30T19:18:34.586465Z"}
{"type":"l2update","product_id":"BTC-USD","changes":[["buy","9115.16","0.00000000"]],"time":"2020-06-30T19:18:34.721049Z"}
{"type":"heartbeat","last_trade_id":0,"product_id":"BTC-USD","sequence":180757759,"time":"2020-06-30T19:18:34.735114Z"}
{"type":"l2update","product_id":"BTC-USD","changes":[["sell","9120.82","2976.33500000"]],"time":"2020-06-30T19:18:35.392190Z"}
{"type":"heartbeat","last_trade_id":0,"product_id":"BTC-USD","sequence":180757762,"time":"2020-06-30T19:18:35.735112Z"}
{"type":"l2update","product_id":"BTC-USD","changes":[["sell","9125.44","0.16110000"]],"time":"2020-06-30T19:18:35.948595Z"}
{"type":"l2update","product_id":"BTC-USD","changes":[["buy","9118.93","0.00000000"]],"time":"2020-06-30T19:18:36.104452Z"}
{"type":"l2update","product_id":"BTC-USD","changes":[["sell","9144.07","0.00000000"]],"time":"2020-06-30T19:18:36.180579Z"}
{"type":"l2update","product_id":"BTC-USD","changes":[["sell","9124.34","0.00000000"]],"time":"2020-06-30T19:18:36.180642Z"}
{"type":"l2update","product_id":"BTC-USD","changes":[["sell","9125.41","0.25000000"]],"time":"2020-06-30T19:18:36.482625Z"}
{"type":"heartbeat","last_trade_id":0,"product_id":"BTC-USD","sequence":180757769,"time":"2020-06-30T19:18:36.735111Z"}
{"type":"l2update","product_id":"BTC-USD","changes":[["sell","9161.92","0.05460000"]],"time":"2020-06-30T19:18:37.312027Z"}
{"type":"heartbeat","last_trade_id":0,"product_id":"BTC-USD","sequence":180757771,"time":"2020-06-30T19:18:37.735114Z"}
{"type":"l2update","product_id":"BTC-USD","changes":[["sell","9124.60","0.00000000"]],"time":"2020-06-30T19:18:37.771820Z"}
{"type":"l2update","product_id":"BTC-USD","changes":[["buy","8938.22","0.00100000"]],"time":"2020-06-30T19:18:37.864114Z"}
{"type":"l2update","product_id":"BTC-USD","changes":[["sell","9120.82","2976.28500000"]],"time":"2020-06-30T19:18:38.132456Z"}
{"type":"l2update","product_id":"BTC-USD","changes":[["buy","9114.93","0.06580000"]],"time":"2020-06-30T19:18:38.409121Z"}
{"type":"heartbeat","last_trade_id":0,"product_id":"BTC-USD","sequence":180757779,"time":"2020-06-30T19:18:38.735113Z"}
{"type":"l2update","product_id":"BTC-USD","changes":[["buy","9118.25","0.00000000"]],"time":"2020-06-30T19:18:38.858060Z"}
{"type":"l2update","product_id":"BTC-USD","changes":[["buy","9118.21","1.61100000"]],"time":"2020-06-30T19:18:38.989695Z"}
{"type":"l2update","product_id":"BTC-USD","changes":[["buy","9114.93","0.00000000"]],"time":"2020-06-30T19:18:39.158864Z"}
{"type":"l2update","product_id":"BTC-USD","changes":[["buy","8933.37","0.00400000"]],"time":"2020-06-30T19:18:39.540309Z"}
{"type":"heartbeat","last_trade_id":0,"product_id":"BTC-USD","sequence":180757785,"time":"2020-06-30T19:18:39.735027Z"}
{"type":"l2update","product_id":"BTC-USD","changes":[["sell","9136.76","0.02360000"]],"time":"2020-06-30T19:18:40.401242Z"}
{"type":"l2update","product_id":"BTC-USD","changes":[["sell","9125.44","0.00000000"]],"time":"2020-06-30T19:18:40.564457Z"}
{"type":"l2update","product_id":"BTC-USD","changes":[["sell","9124.95","0.00000000"]],"time":"2020-06-30T19:18:40.572482Z"}
{"type":"l2update","product_id":"BTC-USD","changes":[["sell","9137.53","0.00000000"]],"time":"2020-06-30T19:18:40.575986Z"}
{"type":"heartbeat","last_trade_id":0,"product_id":"BTC-USD","sequence":180757790,"time":"2020-06-30T19:18:40.735172Z"}
{"type":"l2update","product_id":"BTC-USD","changes":[["buy","9103.51","0.01000000"]],"time":"2020-06-30T19:18:40.989622Z"}
{"type":"l2update","product_id":"BTC-USD","changes":[["sell","9120.82","2975.86510000"]],"time":"2020-06-30T19:18:41.258348Z"}
{"type":"l2update","product_id":"BTC-USD","changes":[["sell","9120.82","2975.86410000"]],"time":"2020-06-30T19:18:41.464109Z"}
{"type":"l2update","product_id":"BTC-USD","changes":[["sell","9120.82","2968.44020000"]],"time":"2020-06-30T19:18:41.551983Z"}
{"type":"heartbeat","last_trade_id":0,"product_id":"BTC-USD","sequence":180757801,"time":"2020-06-30T19:18:41.735069Z"}
{"type":"heartbeat","last_trade_id":0,"product_id":"BTC-USD","sequence":180757801,"time":"2020-06-30T19:18:42.735094Z"}
{"type":"l2update","product_id":"BTC-USD","changes":[["sell","9120.82","2961.64060000"]],"time":"2020-06-30T19:18:42.748221Z"}
{"type":"l2update","product_id":"BTC-USD","changes":[["buy","9118.21","0.00000000"]],"time":"2020-06-30T19:18:42.919493Z"}
{"type":"l2update","product_id":"BTC-USD","changes":[["sell","9120.82","2961.59060000"]],"time":"2020-06-30T19:18:43.017411Z"}
{"type":"l2update","product_id":"BTC-USD","changes":[["buy","8933.37","0.00000000"]],"time":"2020-06-30T19:18:43.474302Z"}
{"type":"l2update","product_id":"BTC-USD","changes":[["sell","9127.71","0.37090000"]],"time":"2020-06-30T19:18:43.590944Z"}
{"type":"heartbeat","last_trade_id":0,"product_id":"BTC-USD","sequence":180757811,"time":"2020-06-30T19:18:43.735116Z"}
{"type":"l2update","product_id":"BTC-USD","changes":[["sell","9124.94","0.00000000"]],"time":"2020-06-30T19:18:44.004422Z"}
{"type":"l2update","product_id":"BTC-USD","changes":[["sell","9155.69","0.00000000"]],"time":"2020-06-30T19:18:44.007170Z"}
{"type":"l2update","product_id":"BTC-USD","changes":[["sell","9136.76","0.00000000"]],"time":"2020-06-30T19:18:44.014446Z"}
{"type":"l2update","product_id":"BTC-USD","changes":[["buy","100.00","114.95500000"]],"time":"2020-06-30T19:18:44.024472Z"}
{"type":"l2update","product_id":"BTC-USD","changes":[["buy","100.00","114.94500000"]],"time":"2020-06-30T19:18:44.031882Z"}
{"type":"l2update","product_id":"BTC-USD","changes":[["sell","9126.04","0.16190000"]],"time":"2020-06-30T19:18:44.163471Z"}
{"type":"l2update","product_id":"BTC-USD","changes":[["sell","9122.97","0.00000000"]],"time":"2020-06-30T19:18:44.583637Z"}
{"type":"heartbeat","last_trade_id":0,"product_id":"BTC-USD","sequence":180757820,"time":"2020-06-30T19:18:44.735117Z"}
{"type":"l2update","product_id":"BTC-USD","changes":[["buy","9081.74","0.13320000"]],"time":"2020-06-30T19:18:44.782132Z"}
{"type":"l2update","product_id":"BTC-USD","changes":[["buy","9116.98","0.02220000"]],"time":"2020-06-30T19:18:45.058789Z"}
{"type":"l2update","product_id":"BTC-USD","changes":[["sell","9154.54","0.01510000"]],"time":"2020-06-30T19:18:45.326655Z"}
{"type":"l2update","product_id":"BTC-USD","changes":[["buy","9081.74","0.00000000"]],"time":"2020-06-30T19:18:45.508314Z"}
{"type":"heartbeat","last_trade_id":0,"product_id":"BTC-USD","sequence":180757827,"time":"2020-06-30T19:18:45.735111Z"}
{"type":"l2update","product_id":"BTC-USD","changes":[["sell","9126.04","0.00000000"]],"time":"2020-06-30T19:18:45.755989Z"}
{"type":"l2update","product_id":"BTC-USD","changes":[["sell","9125.28","0.95580000"]],"time":"2020-06-30T19:18:45.897093Z"}
{"type":"l2update","product_id":"BTC-USD","changes":[["sell","9127.71","0.00000000"]],"time":"2020-06-30T19:18:46.069157Z"}
{"type":"l2update","product_id":"BTC-USD","changes":[["sell","9120.82","2960.59060000"]],"time":"2020-06-30T19:18:46.482371Z"}
{"type":"heartbeat","last_trade_id":0,"product_id":"BTC-USD","sequence":180757834,"time":"2020-06-30T19:18:46.735073Z"}
{"type":"heartbeat","last_trade_id":0,"product_id":"BTC-USD","sequence":180757834,"time":"2020-06-30T19:18:47.735091Z"}
{"type":"heartbeat","last_trade_id":0,"product_id":"BTC-USD","sequence":180757834,"time":"2020-06-30T19:18:48.735127Z"}
{"type":"heartbeat","last_trade_id":0,"product_id":"BTC-USD","sequence":180757834,"time":"2020-06-30T19:18:49.735066Z"}
{"type":"l2update","product_id":"BTC-USD","changes":[["sell","9120.82","2959.69060000"]],"time":"2020-06-30T19:18:50.564742Z"}
{"type":"heartbeat","last_trade_id":0,"product_id":"BTC-USD","sequence":180757837,"time":"2020-06-30T19:18:50.735094Z"}
{"type":"l2update","product_id":"BTC-USD","changes":[["buy","9115.69","0.00000000"]],"time":"2020-06-30T19:18:51.037167Z"}
{"type":"l2update","product_id":"BTC-USD","changes":[["sell","9120.82","2954.79060000"]],"time":"2020-06-30T19:18:51.101767Z"}
{"type":"l2update","product_id":"BTC-USD","changes":[["buy","9103.54","0.07190000"]],"time":"2020-06-30T19:18:51.372059Z"}
{"type":"l2update","product_id":"BTC-USD","changes":[["buy","9102.31","0.06060000"]],"time":"2020-06-30T19:18:51.652006Z"}
{"type":"heartbeat","last_trade_id":0,"product_id":"BTC-USD","sequence":180757845,"time":"2020-06-30T19:18:51.735115Z"}
{"type":"l2update","product_id":"BTC-USD","changes":[["buy","8938.22","0.00000000"]],"time":"2020-06-30T19:18:51.805152Z"}
{"type":"l2update","product_id":"BTC-USD","changes":[["buy","9102.72","0.06060000"]],"time":"2020-06-30T19:18:51.959715Z"}
{"type":"l2update","product_id":"BTC-USD","changes":[["buy","9103.51","0.00000000"]],"time":"2020-06-30T19:18:52.370027Z"}
{"type":"heartbeat","last_trade_id":0,"product_id":"BTC-USD","sequence":180757849,"time":"2020-06-30T19:18:52.735119Z"}
{"type":"l2update","product_id":"BTC-USD","changes":[["sell","9120.82","2954.62760000"]],"time":"2020-06-30T19:18:53.321874Z"}
{"type":"l2update","product_id":"BTC-USD","changes":[["sell","9138.02","0.10000000"]],"time":"2020-06-30T19:18:53.617479Z"}
{"type":"heartbeat","last_trade_id":0,"product_id":"BTC-USD","sequence":180757854,"time":"2020-06-30T19:18:53.735094Z"}
{"type":"l2update","product_id":"BTC-USD","changes":[["sell","9120.82","2954.49630000"]],"time":"2020-06-30T19:18:54.429848Z"}
{"type":"l2update","product_id":"BTC-USD","changes":[["buy","9103.54","0.00000000"]],"time":"2020-06-30T19:18:54.599638Z"}
{"type":"l2update","product_id":"BTC-USD","changes":[["sell","9138.02","0.11950000"]],"time":"2020-06-30T19:18:54.736064Z"}
{"type":"heartbeat","last_trade_id":0,"product_id":"BTC-USD","sequence":180757860,"time":"2020-06-30T19:18:54.735045Z"}
{"type":"l2update","product_id":"BTC-USD","changes":[["sell","9152.27","1.19320000"]],"time":"2020-06-30T19:18:55.310249Z"}
{"type":"heartbeat","last_trade_id":0,"product_id":"BTC-USD","sequence":180757862,"time":"2020-06-30T19:18:55.735101Z"}
{"type":"l2update","product_id":"BTC-USD","changes":[["sell","9125.28","0.00000000"]],"time":"2020-06-30T19:18:55.768136Z"}
{"type":"l2update","product_id":"BTC-USD","changes":[["sell","9138.02","0.10000000"]],"time":"2020-06-30T19:18:55.818504Z"}
{"type":"l2update","product_id":"BTC-USD","changes":[["sell","9120.82","2947.31020000"]],"time":"2020-06-30T19:18:55.934691Z"}
{"type":"heartbeat","last_trade_id":0,"product_id":"BTC-USD","sequence":180757867,"time":"2020-06-30T19:18:56.735111Z"}
{"type":"l2update","product_id":"BTC-USD","changes":[["sell","9124.82","0.06580000"]],"time":"2020-06-30T19:18:56.821312Z"}
{"type":"l2update","product_id":"BTC-USD","changes":[["sell","9122.91","0.10950000"]],"time":"2020-06-30T19:18:57.378800Z"}
{"type":"heartbeat","last_trade_id":0,"product_id":"BTC-USD","sequence":180757871,"time":"2020-06-30T19:18:57.735112Z"}
{"type":"l2update","product_id":"BTC-USD","changes":[["sell","9160.96","0.01000000"]],"time":"2020-06-30T19:18:58.226739Z"}
{"type":"l2update","product_id":"BTC-USD","changes":[["buy","9119.23","0.06580000"]],"time":"2020-06-30T19:18:58.482350Z"}
{"type":"l2update","product_id":"BTC-USD","changes":[["sell","9122.91","0.00000000"]],"time":"2020-06-30T19:18:58.650555Z"}
{"type":"heartbeat","last_trade_id":0,"product_id":"BTC-USD","sequence":180757876,"time":"2020-06-30T19:18:58.735121Z"}
{"type":"l2update","product_id":"BTC-USD","changes":[["buy","100.00","114.95500000"]],"time":"2020-06-30T19:18:59.020159Z"}
{"type":"l2update","product_id":"BTC-USD","changes":[["buy","100.00","114.94500000"]],"time":"2020-06-30T19:18:59.027760Z"}
{"type":"l2update","product_id":"BTC-USD","changes":[["buy","9054.29","0.08770000"]],"time":"2020-06-30T19:18:59.030468Z"}
{"type":"l2update","product_id":"BTC-USD","changes":[["sell","9126.16","1.97170000"]],"time":"2020-06-30T19:18:59.585376Z"}
{"type":"heartbeat","last_trade_id":0,"product_id":"BTC-USD","sequence":180757883,"time":"2020-06-30T19:18:59.735116Z"}
{"type":"l2update","product_id":"BTC-USD","changes":[["buy","8890.10","0.00000000"]],"time":"2020-06-30T19:18:59.992056Z"}
{"type":"l2update","product_id":"BTC-USD","changes":[["sell","9124.00","4.08850000"]],"time":"2020-06-30T19:19:00.030052Z"}
{"type":"l2update","product_id":"BTC-USD","changes":[["sell","9152.27","0.00000000"]],"time":"2020-06-30T19:19:00.042551Z"}
{"type":"l2update","product_id":"BTC-USD","changes":[["sell","9120.82","2947.06020000"]],"time":"2020-06-30T19:19:00.124225Z"}
{"type":"l2update","product_id":"BTC-USD","changes":[["buy","8889.35","0.04701870"]],"time":"2020-06-30T19:19:00.393837Z"}
{"type":"l2update","product_id":"BTC-USD","changes":[["sell","9124.64","0.06580000"]],"time":"2020-06-30T19:19:00.410257Z"}
{"type":"l2update","product_id":"BTC-USD","changes":[["buy","9113.04","0.00000000"]],"time":"2020-06-30T19:19:00.552505Z"}
{"type":"heartbeat","last_trade_id":0,"product_id":"BTC-USD","sequence":180757894,"time":"2020-06-30T19:19:00.735113Z"}
{"type":"l2update","product_id":"BTC-USD","changes":[["sell","9441.09","0.00000000"]],"time":"2020-06-30T19:19:00.798436Z"}
{"type":"l2update","product_id":"BTC-USD","changes":[["sell","9160.96","0.00000000"]],"time":"2020-06-30T19:19:00.942815Z"}
{"type":"l2update","product_id":"BTC-USD","changes":[["sell","9124.00","0.00000000"]],"time":"2020-06-30T19:19:00.975642Z"}
{"type":"l2update","product_id":"BTC-USD","changes":[["sell","9125.41","0.00000000"]],"time":"2020-06-30T19:19:01.042810Z"}
{"type":"l2update","product_id":"BTC-USD","changes":[["buy","9096.68","0.01000000"]],"time":"2020-06-30T19:19:01.104671Z"}
{"type":"l2update","product_id":"BTC-USD","changes":[["sell","9441.89","0.00775230"]],"time":"2020-06-30T19:19:01.229149Z"}
{"type":"l2update","product_id":"BTC-USD","changes":[["buy","9089.81","0.01000000"]],"time":"2020-06-30T19:19:01.542562Z"}
{"type":"heartbeat","last_trade_id":0,"product_id":"BTC-USD","sequence":180757904,"time":"2020-06-30T19:19:01.735112Z"}
{"type":"heartbeat","last_trade_id":0,"product_id":"BTC-USD","sequence":180757904,"time":"2020-06-30T19:19:02.735114Z"}
{"type":"l2update","product_id":"BTC-USD","changes":[["sell","9125.26","0.06580000"]],"time":"2020-06-30T19:19:02.770202Z"}
{"type":"l2update","product_id":"BTC-USD","changes":[["sell","9125.21","0.06580000"]],"time":"2020-06-30T19:19:03.606787Z"}
{"type":"heartbeat","last_trade_id":0,"product_id":"BTC-USD","sequence":180757908,"time":"2020-06-30T19:19:03.735061Z"}
{"type":"l2update","product_id":"BTC-USD","changes":[["sell","9125.30","0.06580000"]],"time":"2020-06-30T19:19:03.883507Z"}
{"type":"l2update","product_id":"BTC-USD","changes":[["sell","9126.16","0.00000000"]],"time":"2020-06-30T19:19:04.155696Z"}
{"type":"l2update","product_id":"BTC-USD","changes":[["sell","9128.30","0.54070000"]],"time":"2020-06-30T19:19:04.163047Z"}
{"type":"l2update","product_id":"BTC-USD","changes":[["sell","9124.72","0.00000000"]],"time":"2020-06-30T19:19:04.174159Z"}
{"type":"l2update","product_id":"BTC-USD","changes":[["sell","9124.64","0.00000000"]],"time":"2020-06-30T19:19:04.209092Z"}
{"type":"l2update","product_id":"BTC-USD","changes":[["sell","9125.35","0.06580000"]],"time":"2020-06-30T19:19:04.473659Z"}
{"type":"heartbeat","last_trade_id":0,"product_id":"BTC-USD","sequence":180757917,"time":"2020-06-30T19:19:04.735100Z"}
{"type":"l2update","product_id":"BTC-USD","changes":[["sell","9125.42","0.06580000"]],"time":"2020-06-30T19:19:05.606222Z"}
{"type":"heartbeat","last_trade_id":0,"product_id":"BTC-USD","sequence":180757919,"time":"2020-06-30T19:19:05.735117Z"}
{"type":"l2update","product_id":"BTC-USD","changes":[["sell","9125.26","0.00000000"]],"time":"2020-06-30T19:19:05.952885Z"}
{"type":"l2update","product_id":"BTC-USD","changes":[["sell","9133.78","0.00000000"]],"time":"2020-06-30T19:19:05.992288Z"}
{"type":"l2update","product_id":"BTC-USD","changes":[["buy","9119.38","0.06580000"]],"time":"2020-06-30T19:19:06.149289Z"}
{"type":"l2update","product_id":"BTC-USD","changes":[["sell","9125.39","0.05000000"]],"time":"2020-06-30T19:19:06.461791Z"}
{"type":"l2update","product_id":"BTC-USD","changes":[["buy","9102.31","0.00000000"]],"time":"2020-06-30T19:19:06.619450Z"}
{"type":"l2update","product_id":"BTC-USD","changes":[["buy","9119.23","0.00000000"]],"time":"2020-06-30T19:19:06.620948Z"}
{"type":"l2update","product_id":"BTC-USD","changes":[["buy","9089.81","0.00000000"]],"time":"2020-06-30T19:19:06.631543Z"}
{"type":"heartbeat","last_trade_id":0,"product_id":"BTC-USD","sequence":180757928,"time":"2020-06-30T19:19:06.735119Z"}
{"type":"l2update","product_id":"BTC-USD","changes":[["sell","9154.54","0.00000000"]],"time":"2020-06-30T19:19:06.947885Z"}
{"type":"l2update","product_id":"BTC-USD","changes":[["sell","9122.91","0.02030000"]],"time":"2020-06-30T19:19:07.317874Z"}
{"type":"l2update","product_id":"BTC-USD","changes":[["sell","9161.92","0.00000000"]],"time":"2020-06-30T19:19:07.461221Z"}
{"type":"l2update","product_id":"BTC-USD","changes":[["sell","9125.00","0.06580000"]],"time":"2020-06-30T19:19:07.640210Z"}
{"type":"heartbeat","last_trade_id":0,"product_id":"BTC-USD","sequence":180757934,"time":"2020-06-30T19:19:07.735060Z"}
{"type":"l2update","product_id":"BTC-USD","changes":[["buy","9093.24","0.01000000"]],"time":"2020-06-30T19:19:08.490222Z"}
{"type":"heartbeat","last_trade_id":0,"product_id":"BTC-USD","sequence":180757936,"time":"2020-06-30T19:19:08.735091Z"}
{"type":"heartbeat","last_trade_id":0,"product_id":"BTC-USD","sequence":180757936,"time":"2020-06-30T19:19:09.735117Z"}
{"type":"l2update","product_id":"BTC-USD","changes":[["sell","9124.80","0.05000000"]],"time":"2020-06-30T19:19:09.792397Z"}
{"type":"l2update","product_id":"BTC-USD","changes":[["sell","9124.64","0.20000000"]],"time":"2020-06-30T19:19:09.951226Z"}
{"type":"l2update","product_id":"BTC-USD","changes":[["sell","9127.68","1.50000000"]],"time":"2020-06-30T19:19:10.183608Z"}
{"type":"l2update","product_id":"BTC-USD","changes":[["sell","9125.39","0.00000000"]],"time":"2020-06-30T19:19:10.300272Z"}
{"type":"l2update","product_id":"BTC-USD","changes":[["sell","9124.82","0.00000000"]],"time":"2020-06-30T19:19:10.301057Z"}
{"type":"l2update","product_id":"BTC-USD","changes":[["sell","9122.91","0.00000000"]],"time":"2020-06-30T19:19:10.437541Z"}
{"type":"l2update","product_id":"BTC-USD","changes":[["buy","9093.24","0.02000000"]],"time":"2020-06-30T19:19:10.484154Z"}
{"type":"heartbeat","last_trade_id":0,"product_id":"BTC-USD","sequence":180757947,"time":"2020-06-30T19:19:10.735115Z"}
{"type":"l2update","product_id":"BTC-USD","changes":[["buy","9120.80","2716.00260000"]],"time":"2020-06-30T19:19:11.072197Z"}
{"type":"l2update","product_id":"BTC-USD","changes":[["sell","9120.82","2947.02020000"]],"time":"2020-06-30T19:19:11.347924Z"}
{"type":"l2update","product_id":"BTC-USD","changes":[["sell","9124.63","0.32770000"]],"time":"2020-06-30T19:19:11.726303Z"}
{"type":"heartbeat","last_trade_id":0,"product_id":"BTC-USD","sequence":180757955,"time":"2020-06-30T19:19:11.735119Z"}
{"type":"l2update","product_id":"BTC-USD","changes":[["sell","9162.94","0.05460000"]],"time":"2020-06-30T19:19:11.889946Z"}
{"type":"heartbeat","last_trade_id":0,"product_id":"BTC-USD","sequence":180757957,"time":"2020-06-30T19:19:12.735119Z"}
{"type":"l2update","product_id":"BTC-USD","changes":[["buy","9089.48","0.03810000"]],"time":"2020-06-30T19:19:12.782154Z"}
{"type":"l2update","product_id":"BTC-USD","changes":[["buy","9089.35","0.03810000"]],"time":"2020-06-30T19:19:13.045151Z"}
{"type":"l2update","product_id":"BTC-USD","changes":[["sell","9124.09","0.05000000"]],"time":"2020-06-30T19:19:13.322097Z"}
{"type":"heartbeat","last_trade_id":0,"product_id":"BTC-USD","sequence":180757963,"time":"2020-06-30T19:19:13.735124Z"}
{"type":"l2update","product_id":"BTC-USD","changes":[["sell","9120.82","2946.12020000"]],"time":"2020-06-30T19:19:13.876594Z"}
{"type":"l2update","product_id":"BTC-USD","changes":[["buy","100.00","114.95500000"]],"time":"2020-06-30T19:19:14.020960Z"}
{"type":"l2update","product_id":"BTC-USD","changes":[["buy","100.00","114.94500000"]],"time":"2020-06-30T19:19:14.027627Z"}
{"type":"l2update","product_id":"BTC-USD","changes":[["sell","9120.82","2943.10310000"]],"time":"2020-06-30T19:19:14.141313Z"}
{"type":"l2update","product_id":"BTC-USD","changes":[["buy","9093.24","0.01000000"]],"time":"2020-06-30T19:19:14.348334Z"}
{"type":"l2update","product_id":"BTC-USD","changes":[["buy","9089.48","0.00000000"]],"time":"2020-06-30T19:19:14.351716Z"}
{"type":"l2update","product_id":"BTC-USD","changes":[["buy","9093.24","0.00000000"]],"time":"2020-06-30T19:19:14.363292Z"}
{"type":"heartbeat","last_trade_id":0,"product_id":"BTC-USD","sequence":180757975,"time":"2020-06-30T19:19:14.735112Z"}
{"type":"l2update","product_id":"BTC-USD","changes":[["buy","9120.22","1.50000000"]],"time":"2020-06-30T19:19:15.026443Z"}
{"type":"l2update","product_id":"BTC-USD","changes":[["sell","9125.15","0.06580000"]],"time":"2020-06-30T19:19:15.300609Z"}
{"type":"heartbeat","last_trade_id":0,"product_id":"BTC-USD","sequence":180757979,"time":"2020-06-30T19:19:15.735052Z"}
{"type":"l2update","product_id":"BTC-USD","changes":[["sell","9125.00","0.00000000"]],"time":"2020-06-30T19:19:15.745569Z"}
{"type":"l2update","product_id":"BTC-USD","changes":[["sell","9120.82","2943.07810000"]],"time":"2020-06-30T19:19:16.088168Z"}
{"type":"l2update","product_id":"BTC-USD","changes":[["sell","9123.77","0.56960000"]],"time":"2020-06-30T19:19:16.658529Z"}
{"type":"heartbeat","last_trade_id":0,"product_id":"BTC-USD","sequence":180757985,"time":"2020-06-30T19:19:16.735108Z"}
{"type":"l2update","product_id":"BTC-USD","changes":[["sell","9127.68","0.00000000"]],"time":"2020-06-30T19:19:17.096621Z"}
{"type":"l2update","product_id":"BTC-USD","changes":[["sell","9124.09","0.00000000"]],"time":"2020-06-30T19:19:17.161948Z"}
{"type":"heartbeat","last_trade_id":0,"product_id":"BTC-USD","sequence":180757987,"time":"2020-06-30T19:19:17.735109Z"}
{"type":"l2update","product_id":"BTC-USD","changes":[["sell","9120.82","2942.95110000"]],"time":"2020-06-30T19:19:18.063005Z"}
{"type":"l2update","product_id":"BTC-USD","changes":[["buy","9113.13","0.80840000"]],"time":"2020-06-30T19:19:18.346881Z"}
{"type":"l2update","product_id":"BTC-USD","changes":[["buy","9089.35","0.00000000"]],"time":"2020-06-30T19:19:18.520398Z"}
{"type":"heartbeat","last_trade_id":0,"product_id":"BTC-USD","sequence":180757993,"time":"2020-06-30T19:19:18.735110Z"}
{"type":"l2update","product_id":"BTC-USD","changes":[["sell","9120.82","2942.90110000"]],"time":"2020-06-30T19:19:19.486025Z"}
{"type":"heartbeat","last_trade_id":0,"product_id":"BTC-USD","sequence":180757996,"time":"2020-06-30T19:19:19.735120Z"}
{"type":"l2update","product_id":"BTC-USD","changes":[["sell","9124.82","0.14400000"]],"time":"2020-06-30T19:19:19.788858Z"}
{"type":"l2update","product_id":"BTC-USD","changes":[["sell","9124.80","0.00000000"]],"time":"2020-06-30T19:19:20.238893Z"}
{"type":"l2update","product_id":"BTC-USD","changes":[["sell","9120.82","2942.89830000"]],"time":"2020-06-30T19:19:20.328270Z"}
{"type":"l2update","product_id":"BTC-USD","changes":[["sell","9124.80","0.06580000"]],"time":"2020-06-30T19:19:20.620548Z"}
{"type":"heartbeat","last_trade_id":0,"product_id":"BTC-USD","sequence":180758004,"time":"2020-06-30T19:19:20.735116Z"}
{"type":"l2update","product_id":"BTC-USD","changes":[["sell","9124.80","0.19780000"]],"time":"2020-06-30T19:19:20.898681Z"}
{"type":"l2update","product_id":"BTC-USD","changes":[["sell","9124.64","0.00000000"]],"time":"2020-06-30T19:19:21.052214Z"}
{"type":"l2update","product_id":"BTC-USD","changes":[["sell","9138.02","0.00000000"]],"time":"2020-06-30T19:19:21.057161Z"}
{"type":"l2update","product_id":"BTC-USD","changes":[["sell","9125.35","0.00000000"]],"time":"2020-06-30T19:19:21.065791Z"}
{"type":"l2update","product_id":"BTC-USD","changes":[["sell","9125.15","0.00000000"]],"time":"2020-06-30T19:19:21.066836Z"}
{"type":"l2update","product_id":"BTC-USD","changes":[["sell","9125.19","0.06580000"]],"time":"2020-06-30T19:19:21.444774Z"}
{"type":"l2update","product_id":"BTC-USD","changes":[["sell","9120.82","2942.70830000"]],"time":"2020-06-30T19:19:21.721134Z"}
{"type":"heartbeat","last_trade_id":0,"product_id":"BTC-USD","sequence":180758015,"time":"2020-06-30T19:19:21.735114Z"}
{"type":"l2update","product_id":"BTC-USD","changes":[["sell","9124.82","0.00000000"]],"time":"2020-06-30T19:19:21.861473Z"}
{"type":"l2update","product_id":"BTC-USD","changes":[["buy","9120.22","0.00000000"]],"time":"2020-06-30T19:19:22.133491Z"}
{"type":"l2update","product_id":"BTC-USD","changes":[["sell","9125.34","0.06580000"]],"time":"2020-06-30T19:19:22.293940Z"}
{"type":"l2update","product_id":"BTC-USD","changes":[["sell","9124.63","0.00000000"]],"time":"2020-06-30T19:19:22.744820Z"}
{"type":"heartbeat","last_trade_id":0,"product_id":"BTC-USD","sequence":180758020,"time":"2020-06-30T19:19:22.735089Z"}
{"type":"l2update","product_id":"BTC-USD","changes":[["sell","9124.35","0.18630000"]],"time":"2020-06-30T19:19:23.196801Z"}
{"type":"l2update","product_id":"BTC-USD","changes":[["sell","9120.82","2942.65550000"]],"time":"2020-06-30T19:19:23.513384Z"}
{"type":"heartbeat","last_trade_id":0,"product_id":"BTC-USD","sequence":180758025,"time":"2020-06-30T19:19:23.735090Z"}
{"type":"l2update","product_id":"BTC-USD","changes":[["sell","9120.82","2942.55400000"]],"time":"2020-06-30T19:19:24.075759Z"}
{"type":"l2update","product_id":"BTC-USD","changes":[["buy","9054.29","0.00000000"]],"time":"2020-06-30T19:19:24.513412Z"}
{"type":"l2update","product_id":"BTC-USD","changes":[["sell","9124.96","0.06580000"]],"time":"2020-06-30T19:19:24.617132Z"}
{"type":"heartbeat","last_trade_id":0,"product_id":"BTC-USD","sequence":180758031,"time":"2020-06-30T19:19:24.735113Z"}
{"type":"l2update","product_id":"BTC-USD","changes":[["sell","9147.73","3.02920000"]],"time":"2020-06-30T19:19:24.901358Z"}
{"type":"l2update","product_id":"BTC-USD","changes":[["sell","9148.87","1.07260000"]],"time":"2020-06-30T19:19:25.467883Z"}
{"type":"heartbeat","last_trade_id":0,"product_id":"BTC-USD","sequence":180758035,"time":"2020-06-30T19:19:25.735112Z"}
{"type":"l2update","product_id":"BTC-USD","changes":[["sell","9152.46","3.19800000"]],"time":"2020-06-30T19:19:25.751291Z"}
{"type":"heartbeat","last_trade_id":0,"product_id":"BTC-USD","sequence":180758037,"time":"2020-06-30T19:19:26.735115Z"}
{"type":"l2update","product_id":"BTC-USD","changes":[["buy","9100.66","2.80000000"]],"time":"2020-06-30T19:19:27.185384Z"}
{"type":"l2update","product_id":"BTC-USD","changes":[["sell","9126.14","1.93230000"]],"time":"2020-06-30T19:19:27.463754Z"}
{"type":"l2update","product_id":"BTC-USD","changes":[["buy","9113.13","0.00000000"]],"time":"2020-06-30T19:19:27.621549Z"}
{"type":"heartbeat","last_trade_id":0,"product_id":"BTC-USD","sequence":180758042,"time":"2020-06-30T19:19:27.735115Z"}
{"type":"l2update","product_id":"BTC-USD","changes":[["sell","9125.34","0.00000000"]],"time":"2020-06-30T19:19:27.903670Z"}
{"type":"l2update","product_id":"BTC-USD","changes":[["sell","9125.30","0.00000000"]],"time":"2020-06-30T19:19:27.905423Z"}
{"type":"l2update","product_id":"BTC-USD","changes":[["sell","9124.66","1.50000000"]],"time":"2020-06-30T19:19:28.625694Z"}
{"type":"heartbeat","last_trade_id":0,"product_id":"BTC-USD","sequence":180758046,"time":"2020-06-30T19:19:28.735117Z"}
{"type":"l2update","product_id":"BTC-USD","changes":[["sell","9148.87","0.00000000"]],"time":"2020-06-30T19:19:28.820060Z"}
{"type":"l2update","product_id":"BTC-USD","changes":[["sell","9123.77","0.00000000"]],"time":"2020-06-30T19:19:28.829086Z"}
{"type":"l2update","product_id":"BTC-USD","changes":[["sell","9120.82","2942.42970000"]],"time":"2020-06-30T19:19:28.926609Z"}
{"type":"l2update","product_id":"BTC-USD","changes":[["buy","100.00","114.95500000"]],"time":"2020-06-30T19:19:29.028224Z"}
{"type":"l2update","product_id":"BTC-USD","changes":[["buy","100.00","114.94500000"]],"time":"2020-06-30T19:19:29.034703Z"}
{"type":"l2update","product_id":"BTC-USD","changes":[["sell","9123.73","0.20000000"]],"time":"2020-06-30T19:19:29.193046Z"}
{"type":"l2update","product_id":"BTC-USD","changes":[["sell","9125.42","0.00000000"]],"time":"2020-06-30T19:19:29.643954Z"}
{"type":"l2update","product_id":"BTC-USD","changes":[["sell","9125.19","0.00000000"]],"time":"2020-06-30T19:19:29.647960Z"}
{"type":"heartbeat","last_trade_id":0,"product_id":"BTC-USD","sequence":180758058,"time":"2020-06-30T19:19:29.735108Z"}
{"type":"l2update","product_id":"BTC-USD","changes":[["sell","9120.82","2941.57120000"]],"time":"2020-06-30T19:19:30.008287Z"}
{"type":"l2update","product_id":"BTC-USD","changes":[["buy","9119.38","0.00000000"]],"time":"2020-06-30T19:19:30.445981Z"}
{"type":"l2update","product_id":"BTC-USD","changes":[["sell","9121.68","0.02500000"]],"time":"2020-06-30T19:19:30.571323Z"}
{"type":"heartbeat","last_trade_id":0,"product_id":"BTC-USD","sequence":180758064,"time":"2020-06-30T19:19:30.735118Z"}
{"type":"l2update","product_id":"BTC-USD","changes":[["sell","9159.21","14.94000000"]],"time":"2020-06-30T19:19:30.869120Z"}
{"type":"l2update","product_id":"BTC-USD","changes":[["sell","9125.21","0.00000000"]],"time":"2020-06-30T19:19:31.023052Z"}
{"type":"l2update","product_id":"BTC-USD","changes":[["sell","9124.35","0.00000000"]],"time":"2020-06-30T19:19:31.023245Z"}
{"type":"l2update","product_id":"BTC-USD","changes":[["buy","9119.78","0.06580000"]],"time":"2020-06-30T19:19:31.145314Z"}
{"type":"l2update","product_id":"BTC-USD","changes":[["sell","9147.73","0.00000000"]],"time":"2020-06-30T19:19:31.283767Z"}
{"type":"l2update","product_id":"BTC-USD","changes":[["sell","9122.44","0.16170000"]],"time":"2020-06-30T19:19:31.707158Z"}
{"type":"heartbeat","last_trade_id":0,"product_id":"BTC-USD","sequence":180758073,"time":"2020-06-30T19:19:31.735111Z"}
{"type":"l2update","product_id":"BTC-USD","changes":[["sell","9120.82","2941.07120000"]],"time":"2020-06-30T19:19:32.268941Z"}
{"type":"l2update","product_id":"BTC-USD","changes":[["buy","9096.68","0.00000000"]],"time":"2020-06-30T19:19:32.717089Z"}
{"type":"heartbeat","last_trade_id":0,"product_id":"BTC-USD","sequence":180758077,"time":"2020-06-30T19:19:32.735067Z"}
{"type":"l2update","product_id":"BTC-USD","changes":[["buy","9087.84","0.03770000"]],"time":"2020-06-30T19:19:33.119813Z"}
{"type":"heartbeat","last_trade_id":0,"product_id":"BTC-USD","sequence":180758079,"time":"2020-06-30T19:19:33.735039Z"}
{"type":"l2update","product_id":"BTC-USD","changes":[["buy","9110.63","0.80560000"]],"time":"2020-06-30T19:19:33.938543Z"}
{"type":"l2update","product_id":"BTC-USD","changes":[["buy","9117.49","0.92230000"]],"time":"2020-06-30T19:19:34.236770Z"}
{"type":"l2update","product_id":"BTC-USD","changes":[["buy","9117.50","0.06580000"]],"time":"2020-06-30T19:19:34.507080Z"}
{"type":"heartbeat","last_trade_id":0,"product_id":"BTC-USD","sequence":180758085,"time":"2020-06-30T19:19:34.735036Z"}
{"type":"l2update","product_id":"BTC-USD","changes":[["sell","9138.02","0.09680000"]],"time":"2020-06-30T19:19:34.777906Z"}
{"type":"l2update","product_id":"BTC-USD","changes":[["buy","9100.66","0.00000000"]],"time":"2020-06-30T19:19:34.936932Z"}
{"type":"l2update","product_id":"BTC-USD","changes":[["buy","9087.15","0.05500000"]],"time":"2020-06-30T19:19:35.074800Z"}
{"type":"l2update","product_id":"BTC-USD","changes":[["sell","9124.06","0.54500000"]],"time":"2020-06-30T19:19:35.618965Z"}
{"type":"heartbeat","last_trade_id":0,"product_id":"BTC-USD","sequence":180758092,"time":"2020-06-30T19:19:35.735047Z"}
{"type":"l2update","product_id":"BTC-USD","changes":[["sell","9152.46","0.00000000"]],"time":"2020-06-30T19:19:36.057132Z"}
{"type":"l2update","product_id":"BTC-USD","changes":[["sell","9122.44","0.00000000"]],"time":"2020-06-30T19:19:36.061940Z"}
{"type":"heartbeat","last_trade_id":0,"product_id":"BTC-USD","sequence":180758094,"time":"2020-06-30T19:19:36.735095Z"}
{"type":"l2update","product_id":"BTC-USD","changes":[["buy","9108.53","0.80540000"]],"time":"2020-06-30T19:19:36.769599Z"}
{"type":"l2update","product_id":"BTC-USD","changes":[["buy","8938.24","0.00100000"]],"time":"2020-06-30T19:19:37.594123Z"}
{"type":"heartbeat","last_trade_id":0,"product_id":"BTC-USD","sequence":180758098,"time":"2020-06-30T19:19:37.735067Z"}
{"type":"l2update","product_id":"BTC-USD","changes":[["buy","9117.50","0.00000000"]],"time":"2020-06-30T19:19:38.058886Z"}
{"type":"l2update","product_id":"BTC-USD","changes":[["buy","9097.76","0.01000000"]],"time":"2020-06-30T19:19:38.157836Z"}
{"type":"l2update","product_id":"BTC-USD","changes":[["buy","9086.92","0.01050000"]],"time":"2020-06-30T19:19:38.433005Z"}
{"type":"l2update","product_id":"BTC-USD","changes":[["buy","9119.78","0.00000000"]],"time":"2020-06-30T19:19:38.582208Z"}
{"type":"heartbeat","last_trade_id":0,"product_id":"BTC-USD","sequence":180758104,"time":"2020-06-30T19:19:38.735093Z"}
{"type":"l2update","product_id":"BTC-USD","changes":[["buy","9097.76","0.02000000"]],"time":"2020-06-30T19:19:38.997126Z"}
{"type":"l2update","product_id":"BTC-USD","changes":[["buy","9081.06","0.01050000"]],"time":"2020-06-30T19:19:39.577025Z"}
{"type":"heartbeat","last_trade_id":0,"product_id":"BTC-USD","sequence":180758108,"time":"2020-06-30T19:19:39.735121Z"}
{"type":"l2update","product_id":"BTC-USD","changes":[["sell","9134.51","0.21900000"]],"time":"2020-06-30T19:19:39.874119Z"}
{"type":"l2update","product_id":"BTC-USD","changes":[["buy","9097.76","0.01000000"]],"time":"2020-06-30T19:19:39.994031Z"}
{"type":"l2update","product_id":"BTC-USD","changes":[["buy","9097.76","0.00000000"]],"time":"2020-06-30T19:19:40.004205Z"}
{"type":"l2update","product_id":"BTC-USD","changes":[["buy","9087.15","0.00000000"]],"time":"2020-06-30T19:19:40.006225Z"}
{"type":"l2update","product_id":"BTC-USD","changes":[["buy","9087.84","0.00000000"]],"time":"2020-06-30T19:19:40.006374Z"}
{"type":"l2update","product_id":"BTC-USD","changes":[["sell","9124.42","0.32220000"]],"time":"2020-06-30T19:19:40.176053Z"}
{"type":"l2update","product_id":"BTC-USD","changes":[["sell","9124.96","0.00000000"]],"time":"2020-06-30T19:19:40.300162Z"}
{"type":"heartbeat","last_trade_id":0,"product_id":"BTC-USD","sequence":180758117,"time":"2020-06-30T19:19:40.735114Z"}
{"type":"l2update","product_id":"BTC-USD","changes":[["sell","9120.82","2941.07020000"]],"time":"2020-06-30T19:19:41.669084Z"}
{"type":"heartbeat","last_trade_id":0,"product_id":"BTC-USD","sequence":180758120,"time":"2020-06-30T19:19:41.735112Z"}
{"type":"l2update","product_id":"BTC-USD","changes":[["sell","9121.69","1.13150000"]],"time":"2020-06-30T19:19:41.943674Z"}
{"type":"l2update","product_id":"BTC-USD","changes":[["sell","9134.51","0.00000000"]],"time":"2020-06-30T19:19:42.133020Z"}
{"type":"l2update","product_id":"BTC-USD","changes":[["sell","9124.66","0.00000000"]],"time":"2020-06-30T19:19:42.146699Z"}
{"type":"l2update","product_id":"BTC-USD","changes":[["sell","9158.53","0.01000000"]],"time":"2020-06-30T19:19:42.213034Z"}
{"type":"l2update","product_id":"BTC-USD","changes":[["buy","9116.21","0.00120000"]],"time":"2020-06-30T19:19:42.556001Z"}
{"type":"l2update","product_id":"BTC-USD","changes":[["sell","9126.14","0.00000000"]],"time":"2020-06-30T19:19:42.650109Z"}
{"type":"l2update","product_id":"BTC-USD","changes":[["sell","9124.80","0.06580000"]],"time":"2020-06-30T19:19:42.658728Z"}
{"type":"heartbeat","last_trade_id":0,"product_id":"BTC-USD","sequence":180758130,"time":"2020-06-30T19:19:42.735109Z"}
{"type":"l2update","product_id":"BTC-USD","changes":[["buy","9102.72","0.00000000"]],"time":"2020-06-30T19:19:42.980588Z"}
{"type":"heartbeat","last_trade_id":0,"product_id":"BTC-USD","sequence":180758131,"time":"2020-06-30T19:19:43.735089Z"}
{"type":"l2update","product_id":"BTC-USD","changes":[["buy","100.00","114.95500000"]],"time":"2020-06-30T19:19:44.063400Z"}
{"type":"l2update","product_id":"BTC-USD","changes":[["buy","100.00","114.94500000"]],"time":"2020-06-30T19:19:44.070550Z"}
{"type":"heartbeat","last_trade_id":0,"product_id":"BTC-USD","sequence":180758134,"time":"2020-06-30T19:19:44.735017Z"}
{"type":"l2update","product_id":"BTC-USD","changes":[["buy","9118.19","0.21340000"]],"time":"2020-06-30T19:19:45.368524Z"}
{"type":"l2update","product_id":"BTC-USD","changes":[["buy","9099.13","0.01000000"]],"time":"2020-06-30T19:19:45.653057Z"}
{"type":"heartbeat","last_trade_id":0,"product_id":"BTC-USD","sequence":180758138,"time":"2020-06-30T19:19:45.735170Z"}
{"type":"l2update","product_id":"BTC-USD","changes":[["sell","9121.69","2.39820000"]],"time":"2020-06-30T19:19:46.071292Z"}
{"type":"l2update","product_id":"BTC-USD","changes":[["buy","9098.45","0.01000000"]],"time":"2020-06-30T19:19:46.362543Z"}
{"type":"l2update","product_id":"BTC-USD","changes":[["sell","9162.94","0.00000000"]],"time":"2020-06-30T19:19:46.541634Z"}
{"type":"l2update","product_id":"BTC-USD","changes":[["sell","9124.06","0.00000000"]],"time":"2020-06-30T19:19:46.543022Z"}
{"type":"l2update","product_id":"BTC-USD","changes":[["sell","9121.68","0.00000000"]],"time":"2020-06-30T19:19:46.553407Z"}
{"type":"l2update","product_id":"BTC-USD","changes":[["sell","9138.02","0.00000000"]],"time":"2020-06-30T19:19:46.582821Z"}
{"type":"heartbeat","last_trade_id":0,"product_id":"BTC-USD","sequence":180758146,"time":"2020-06-30T19:19:46.735121Z"}
{"type":"l2update","product_id":"BTC-USD","changes":[["sell","9120.82","2940.93570000"]],"time":"2020-06-30T19:19:46.990772Z"}
{"type":"l2update","product_id":"BTC-USD","changes":[["sell","9121.69","2.77630000"]],"time":"2020-06-30T19:19:47.260927Z"}
{"type":"l2update","product_id":"BTC-USD","changes":[["sell","9121.69","1.64480000"]],"time":"2020-06-30T19:19:47.676827Z"}
{"type":"heartbeat","last_trade_id":0,"product_id":"BTC-USD","sequence":180758152,"time":"2020-06-30T19:19:47.735113Z"}
{"type":"heartbeat","last_trade_id":0,"product_id":"BTC-USD","sequence":180758152,"time":"2020-06-30T19:19:48.735059Z"}
{"type":"l2update","product_id":"BTC-USD","changes":[["sell","9124.62","0.06580000"]],"time":"2020-06-30T19:19:48.999290Z"}
{"type":"l2update","product_id":"BTC-USD","changes":[["buy","8938.24","0.00000000"]],"time":"2020-06-30T19:19:49.111329Z"}
{"type":"l2update","product_id":"BTC-USD","changes":[["buy","9099.13","0.00000000"]],"time":"2020-06-30T19:19:49.135524Z"}
{"type":"heartbeat","last_trade_id":0,"product_id":"BTC-USD","sequence":180758156,"time":"2020-06-30T19:19:49.735098Z"}
{"type":"l2update","product_id":"BTC-USD","changes":[["sell","9120.82","2936.14580000"]],"time":"2020-06-30T19:19:50.150137Z"}
{"type":"l2update","product_id":"BTC-USD","changes":[["sell","9125.93","0.32220000"]],"time":"2020-06-30T19:19:50.474448Z"}
{"type":"l2update","product_id":"BTC-USD","changes":[["buy","9108.53","0.00000000"]],"time":"2020-06-30T19:19:50.577712Z"}
{"type":"l2update","product_id":"BTC-USD","changes":[["buy","9098.45","0.00000000"]],"time":"2020-06-30T19:19:50.583823Z"}
{"type":"heartbeat","last_trade_id":0,"product_id":"BTC-USD","sequence":180758163,"time":"2020-06-30T19:19:50.735127Z"}
{"type":"l2update","product_id":"BTC-USD","changes":[["sell","9121.69","1.26670000"]],"time":"2020-06-30T19:19:50.905031Z"}
{"type":"l2update","product_id":"BTC-USD","changes":[["buy","9116.41","5.00000000"]],"time":"2020-06-30T19:19:51.061754Z"}
{"type":"l2update","product_id":"BTC-USD","changes":[["sell","9120.82","2931.38690000"]],"time":"2020-06-30T19:19:51.636185Z"}
{"type":"heartbeat","last_trade_id":0,"product_id":"BTC-USD","sequence":180758169,"time":"2020-06-30T19:19:51.735116Z"}
{"type":"l2update","product_id":"BTC-USD","changes":[["buy","9118.19","0.00000000"]],"time":"2020-06-30T19:19:51.821664Z"}
{"type":"l2update","product_id":"BTC-USD","changes":[["sell","9120.82","2926.59700000"]],"time":"2020-06-30T19:19:51.933821Z"}
{"type":"heartbeat","last_trade_id":0,"product_id":"BTC-USD","sequence":180758173,"time":"2020-06-30T19:19:52.735121Z"}
{"type":"l2update","product_id":"BTC-USD","changes":[["buy","9115.15","0.06580000"]],"time":"2020-06-30T19:19:52.810184Z"}
{"type":"l2update","product_id":"BTC-USD","changes":[["sell","9120.82","2918.89770000"]],"time":"2020-06-30T19:19:53.369614Z"}
{"type":"l2update","product_id":"BTC-USD","changes":[["sell","9120.82","2910.90760000"]],"time":"2020-06-30T19:19:53.672072Z"}
{"type":"heartbeat","last_trade_id":0,"product_id":"BTC-USD","sequence":180758181,"time":"2020-06-30T19:19:53.735116Z"}
{"type":"l2update","product_id":"BTC-USD","changes":[["buy","9101.45","0.06840000"]],"time":"2020-06-30T19:19:53.953718Z"}
{"type":"l2update","product_id":"BTC-USD","changes":[["sell","9120.82","2910.78290000"]],"time":"2020-06-30T19:19:54.596442Z"}
{"type":"heartbeat","last_trade_id":0,"product_id":"BTC-USD","sequence":180758186,"time":"2020-06-30T19:19:54.735120Z"}
{"type":"l2update","product_id":"BTC-USD","changes":[["sell","9123.28","0.06300000"]],"time":"2020-06-30T19:19:54.858431Z"}
{"type":"l2update","product_id":"BTC-USD","changes":[["sell","9125.93","0.00000000"]],"time":"2020-06-30T19:19:55.297465Z"}
{"type":"l2update","product_id":"BTC-USD","changes":[["sell","9123.15","0.00300000"]],"time":"2020-06-30T19:19:55.700651Z"}
{"type":"heartbeat","last_trade_id":0,"product_id":"BTC-USD","sequence":180758191,"time":"2020-06-30T19:19:55.735120Z"}
{"type":"l2update","product_id":"BTC-USD","changes":[["sell","9124.80","0.00000000"]],"time":"2020-06-30T19:19:56.144491Z"}
{"type":"l2update","product_id":"BTC-USD","changes":[["sell","9124.62","0.00000000"]],"time":"2020-06-30T19:19:56.147262Z"}
{"type":"l2update","product_id":"BTC-USD","changes":[["sell","9159.21","0.00000000"]],"time":"2020-06-30T19:19:56.156330Z"}
{"type":"l2update","product_id":"BTC-USD","changes":[["sell","9120.82","2910.65860000"]],"time":"2020-06-30T19:19:56.524495Z"}
{"type":"heartbeat","last_trade_id":0,"product_id":"BTC-USD","sequence":180758197,"time":"2020-06-30T19:19:56.735118Z"}
{"type":"l2update","product_id":"BTC-USD","changes":[["buy","9081.06","0.00000000"]],"time":"2020-06-30T19:19:56.976931Z"}
{"type":"l2update","product_id":"BTC-USD","changes":[["sell","9120.82","2910.53430000"]],"time":"2020-06-30T19:19:57.092674Z"}
{"type":"l2update","product_id":"BTC-USD","changes":[["buy","9109.68","0.50210000"]],"time":"2020-06-30T19:19:57.369352Z"}
{"type":"heartbeat","last_trade_id":0,"product_id":"BTC-USD","sequence":180758203,"time":"2020-06-30T19:19:57.735108Z"}
{"type":"l2update","product_id":"BTC-USD","changes":[["buy","9120.32","0.40000000"]],"time":"2020-06-30T19:19:57.981246Z"}
{"type":"l2update","product_id":"BTC-USD","changes":[["buy","9099.84","0.02470000"]],"time":"2020-06-30T19:19:58.143884Z"}
{"type":"heartbeat","last_trade_id":0,"product_id":"BTC-USD","sequence":180758207,"time":"2020-06-30T19:19:58.735109Z"}
{"type":"l2update","product_id":"BTC-USD","changes":[["buy","9099.43","0.02630000"]],"time":"2020-06-30T19:19:58.830178Z"}
{"type":"l2update","product_id":"BTC-USD","changes":[["buy","8889.35","0.00000000"]],"time":"2020-06-30T19:19:58.967538Z"}
{"type":"l2update","product_id":"BTC-USD","changes":[["buy","100.00","114.95500000"]],"time":"2020-06-30T19:19:59.071625Z"}
{"type":"l2update","product_id":"BTC-USD","changes":[["buy","100.00","114.94500000"]],"time":"2020-06-30T19:19:59.078716Z"}
{"type":"l2update","product_id":"BTC-USD","changes":[["buy","9101.45","0.11790000"]],"time":"2020-06-30T19:19:59.101697Z"}
{"type":"l2update","product_id":"BTC-USD","changes":[["buy","8888.60","0.04711175"]],"time":"2020-06-30T19:19:59.350244Z"}
{"type":"l2update","product_id":"BTC-USD","changes":[["buy","9119.58","0.43670000"]],"time":"2020-06-30T19:19:59.372054Z"}
{"type":"heartbeat","last_trade_id":0,"product_id":"BTC-USD","sequence":180758219,"time":"2020-06-30T19:19:59.735096Z"}
{"type":"l2update","product_id":"BTC-USD","changes":[["sell","9441.89","0.00000000"]],"time":"2020-06-30T19:19:59.827990Z"}
{"type":"l2update","product_id":"BTC-USD","changes":[["sell","9442.69","0.00784327"]],"time":"2020-06-30T19:20:00.207240Z"}
{"type":"l2update","product_id":"BTC-USD","changes":[["sell","9120.82","2909.67780000"]],"time":"2020-06-30T19:20:00.353001Z"}
{"type":"heartbeat","last_trade_id":0,"product_id":"BTC-USD","sequence":180758225,"time":"2020-06-30T19:20:00.735113Z"}
{"type":"l2update","product_id":"BTC-USD","changes":[["buy","9116.21","0.00000000"]],"time":"2020-06-30T19:20:00.787769Z"}
{"type":"l2update","product_id":"BTC-USD","changes":[["sell","9123.54","0.09840000"]],"time":"2020-06-30T19:20:01.158211Z"}
{"type":"l2update","product_id":"BTC-USD","changes":[["sell","9120.82","2908.67780000"]],"time":"2020-06-30T19:20:01.428413Z"}
{"type":"l2update","product_id":"BTC-USD","changes":[["sell","9124.42","0.00000000"]],"time":"2020-06-30T19:20:01.632630Z"}
{"type":"l2update","product_id":"BTC-USD","changes":[["buy","9120.32","0.00000000"]],"time":"2020-06-30T19:20:01.672004Z"}
{"type":"l2update","product_id":"BTC-USD","changes":[["buy","9075.38","0.00000000"]],"time":"2020-06-30T19:20:01.684357Z"}
{"type":"l2update","product_id":"BTC-USD","changes":[["buy","8964.07","0.00000000"]],"time":"2020-06-30T19:20:01.688195Z"}
{"type":"heartbeat","last_trade_id":0,"product_id":"BTC-USD","sequence":180758235,"time":"2020-06-30T19:20:01.735111Z"}
{"type":"l2update","product_id":"BTC-USD","changes":[["sell","9124.97","0.06580000"]],"time":"2020-06-30T19:20:02.731210Z"}
{"type":"heartbeat","last_trade_id":0,"product_id":"BTC-USD","sequence":180758237,"time":"2020-06-30T19:20:02.735114Z"}
{"type":"l2update","product_id":"BTC-USD","changes":[["sell","9120.82","2901.72780000"]],"time":"2020-06-30T19:20:03.001032Z"}
{"type":"l2update","product_id":"BTC-USD","changes":[["buy","9102.77","0.05090000"]],"time":"2020-06-30T19:20:03.394237Z"}
{"type":"l2update","product_id":"BTC-USD","changes":[["buy","9116.41","0.00000000"]],"time":"2020-06-30T19:20:03.696713Z"}
{"type":"heartbeat","last_trade_id":0,"product_id":"BTC-USD","sequence":180758243,"time":"2020-06-30T19:20:03.735118Z"}
{"type":"l2update","product_id":"BTC-USD","changes":[["buy","9119.58","0.00000000"]],"time":"2020-06-30T19:20:03.911474Z"}
{"type":"l2update","product_id":"BTC-USD","changes":[["sell","9120.82","2901.60350000"]],"time":"2020-06-30T19:20:04.161114Z"}
{"type":"l2update","product_id":"BTC-USD","changes":[["sell","9124.64","0.12290000"]],"time":"2020-06-30T19:20:04.427972Z"}
{"type":"l2update","product_id":"BTC-USD","changes":[["buy","9075.38","0.05600000"]],"time":"2020-06-30T19:20:04.524187Z"}
{"type":"l2update","product_id":"BTC-USD","changes":[["buy","8964.07","0.17800000"]],"time":"2020-06-30T19:20:04.534268Z"}
{"type":"heartbeat","last_trade_id":0,"product_id":"BTC-USD","sequence":180758253,"time":"2020-06-30T19:20:04.735112Z"}
{"type":"l2update","product_id":"BTC-USD","changes":[["sell","9157.28","0.01000000"]],"time":"2020-06-30T19:20:04.920138Z"}
{"type":"l2update","product_id":"BTC-USD","changes":[["sell","9158.53","0.00000000"]],"time":"2020-06-30T19:20:04.933532Z"}
{"type":"l2update","product_id":"BTC-USD","changes":[["sell","9128.30","0.00000000"]],"time":"2020-06-30T19:20:05.135516Z"}
{"type":"l2update","product_id":"BTC-USD","changes":[["buy","9063.85","0.00160000"]],"time":"2020-06-30T19:20:05.208454Z"}
{"type":"l2update","product_id":"BTC-USD","changes":[["buy","9120.55","0.21340000"]],"time":"2020-06-30T19:20:05.438762Z"}
{"type":"l2update","product_id":"BTC-USD","changes":[["buy","9099.43","0.00000000"]],"time":"2020-06-30T19:20:05.675753Z"}
{"type":"heartbeat","last_trade_id":0,"product_id":"BTC-USD","sequence":180758262,"time":"2020-06-30T19:20:05.735117Z"}
{"type":"heartbeat","last_trade_id":0,"product_id":"BTC-USD","sequence":180758262,"time":"2020-06-30T19:20:06.735113Z"}
{"type":"l2update","product_id":"BTC-USD","changes":[["buy","9101.59","0.02830000"]],"time":"2020-06-30T19:20:07.122166Z"}
{"type":"l2update","product_id":"BTC-USD","changes":[["sell","9124.59","0.05710000"]],"time":"2020-06-30T19:20:07.404788Z"}
{"type":"l2update","product_id":"BTC-USD","changes":[["buy","9109.68","0.00000000"]],"time":"2020-06-30T19:20:07.564357Z"}
{"type":"l2update","product_id":"BTC-USD","changes":[["buy","9110.63","0.00000000"]],"time":"2020-06-30T19:20:07.572130Z"}
{"type":"l2update","product_id":"BTC-USD","changes":[["sell","9157.28","0.00000000"]],"time":"2020-06-30T19:20:07.617908Z"}
{"type":"l2update","product_id":"BTC-USD","changes":[["sell","9120.82","2893.87590000"]],"time":"2020-06-30T19:20:07.671282Z"}
{"type":"heartbeat","last_trade_id":0,"product_id":"BTC-USD","sequence":180758272,"time":"2020-06-30T19:20:07.735068Z"}
{"type":"l2update","product_id":"BTC-USD","changes":[["buy","9101.45","0.04950000"]],"time":"2020-06-30T19:20:08.131267Z"}
{"type":"l2update","product_id":"BTC-USD","changes":[["sell","9120.82","2886.29820000"]],"time":"2020-06-30T19:20:08.232311Z"}
{"type":"heartbeat","last_trade_id":0,"product_id":"BTC-USD","sequence":180758276,"time":"2020-06-30T19:20:08.735112Z"}
{"type":"l2update","product_id":"BTC-USD","changes":[["sell","9172.69","0.05310000"]],"time":"2020-06-30T19:20:08.798124Z"}
{"type":"l2update","product_id":"BTC-USD","changes":[["sell","9172.40","0.01490000"]],"time":"2020-06-30T19:20:09.063302Z"}
{"type":"l2update","product_id":"BTC-USD","changes":[["sell","9124.64","0.00000000"]],"time":"2020-06-30T19:20:09.534861Z"}
{"type":"l2update","product_id":"BTC-USD","changes":[["sell","9125.00","0.03130000"]],"time":"2020-06-30T19:20:09.703708Z"}
{"type":"heartbeat","last_trade_id":0,"product_id":"BTC-USD","sequence":180758283,"time":"2020-06-30T19:20:09.735115Z"}
{"type":"l2update","product_id":"BTC-USD","changes":[["sell","9124.97","0.00000000"]],"time":"2020-06-30T19:20:09.878058Z"}
{"type":"l2update","product_id":"BTC-USD","changes":[["buy","9112.93","0.02220000"]],"time":"2020-06-30T19:20:10.267021Z"}
{"type":"l2update","product_id":"BTC-USD","changes":[["buy","9117.49","0.00000000"]],"time":"2020-06-30T19:20:10.688982Z"}
{"type":"heartbeat","last_trade_id":0,"product_id":"BTC-USD","sequence":180758287,"time":"2020-06-30T19:20:10.735071Z"}
{"type":"l2update","product_id":"BTC-USD","changes":[["buy","9120.80","2716.00160000"]],"time":"2020-06-30T19:20:10.880744Z"}
{"type":"l2update","product_id":"BTC-USD","changes":[["sell","9120.82","2886.18220000"]],"time":"2020-06-30T19:20:11.069277Z"}
{"type":"l2update","product_id":"BTC-USD","changes":[["sell","9120.82","2886.06340000"]],"time":"2020-06-30T19:20:11.330748Z"}
{"type":"l2update","product_id":"BTC-USD","changes":[["buy","9086.92","0.00000000"]],"time":"2020-06-30T19:20:11.524513Z"}
{"type":"l2update","product_id":"BTC-USD","changes":[["buy","9101.59","0.00000000"]],"time":"2020-06-30T19:20:11.526931Z"}
{"type":"l2update","product_id":"BTC-USD","changes":[["sell","9120.82","2885.94460000"]],"time":"2020-06-30T19:20:11.605582Z"}
{"type":"heartbeat","last_trade_id":0,"product_id":"BTC-USD","sequence":180758301,"time":"2020-06-30T19:20:11.735099Z"}
{"type":"l2update","product_id":"BTC-USD","changes":[["buy","9115.15","0.00000000"]],"time":"2020-06-30T19:20:11.766035Z"}
{"type":"l2update","product_id":"BTC-USD","changes":[["buy","9115.61","0.03060000"]],"time":"2020-06-30T19:20:12.731092Z"}
{"type":"heartbeat","last_trade_id":0,"product_id":"BTC-USD","sequence":180758304,"time":"2020-06-30T19:20:12.735113Z"}
{"type":"l2update","product_id":"BTC-USD","changes":[["sell","9120.82","2885.82880000"]],"time":"2020-06-30T19:20:13.000132Z"}
{"type":"l2update","product_id":"BTC-USD","changes":[["sell","9173.21","0.12320000"]],"time":"2020-06-30T19:20:13.542550Z"}
{"type":"l2update","product_id":"BTC-USD","changes":[["sell","9123.54","0.00000000"]],"time":"2020-06-30T19:20:13.719961Z"}
{"type":"heartbeat","last_trade_id":0,"product_id":"BTC-USD","sequence":180758310,"time":"2020-06-30T19:20:13.735116Z"}
{"type":"l2update","product_id":"BTC-USD","changes":[["sell","9172.91","0.06890000"]],"time":"2020-06-30T19:20:13.819259Z"}
{"type":"l2update","product_id":"BTC-USD","changes":[["buy","100.00","114.95500000"]],"time":"2020-06-30T19:20:14.029548Z"}
{"type":"l2update","product_id":"BTC-USD","changes":[["buy","100.00","114.94500000"]],"time":"2020-06-30T19:20:14.037743Z"}
{"type":"l2update","product_id":"BTC-USD","changes":[["sell","9127.56","0.06570000"]],"time":"2020-06-30T19:20:14.635703Z"}
{"type":"heartbeat","last_trade_id":0,"product_id":"BTC-USD","sequence":180758317,"time":"2020-06-30T19:20:14.735071Z"}
{"type":"l2update","product_id":"BTC-USD","changes":[["sell","9172.69","0.00000000"]],"time":"2020-06-30T19:20:15.111609Z"}
{"type":"l2update","product_id":"BTC-USD","changes":[["sell","9126.05","0.00100000"]],"time":"2020-06-30T19:20:15.467904Z"}
{"type":"heartbeat","last_trade_id":0,"product_id":"BTC-USD","sequence":180758320,"time":"2020-06-30T19:20:15.735092Z"}
{"type":"l2update","product_id":"BTC-USD","changes":[["buy","9117.70","0.02220000"]],"time":"2020-06-30T19:20:15.786617Z"}
{"type":"l2update","product_id":"BTC-USD","changes":[["buy","9116.98","0.00000000"]],"time":"2020-06-30T19:20:16.230134Z"}
{"type":"l2update","product_id":"BTC-USD","changes":[["buy","9063.85","0.00000000"]],"time":"2020-06-30T19:20:16.235080Z"}
{"type":"l2update","product_id":"BTC-USD","changes":[["sell","9120.82","2885.72220000"]],"time":"2020-06-30T19:20:16.603367Z"}
{"type":"heartbeat","last_trade_id":0,"product_id":"BTC-USD","sequence":180758327,"time":"2020-06-30T19:20:16.735109Z"}
{"type":"l2update","product_id":"BTC-USD","changes":[["sell","9126.26","0.05000000"]],"time":"2020-06-30T19:20:17.696832Z"}
{"type":"heartbeat","last_trade_id":0,"product_id":"BTC-USD","sequence":180758329,"time":"2020-06-30T19:20:17.735111Z"}
{"type":"l2update","product_id":"BTC-USD","changes":[["sell","9120.82","2885.60340000"]],"time":"2020-06-30T19:20:17.974202Z"}
{"type":"l2update","product_id":"BTC-USD","changes":[["sell","9126.05","0.00000000"]],"time":"2020-06-30T19:20:18.148769Z"}
{"type":"heartbeat","last_trade_id":0,"product_id":"BTC-USD","sequence":180758333,"time":"2020-06-30T19:20:18.735068Z"}
{"type":"heartbeat","last_trade_id":0,"product_id":"BTC-USD","sequence":180758333,"time":"2020-06-30T19:20:19.735050Z"}
{"type":"l2update","product_id":"BTC-USD","changes":[["buy","9102.36","0.03700000"]],"time":"2020-06-30T19:20:20.494428Z"}
{"type":"heartbeat","last_trade_id":0,"product_id":"BTC-USD","sequence":180758335,"time":"2020-06-30T19:20:20.735048Z"}
{"type":"l2update","product_id":"BTC-USD","changes":[["sell","9120.82","2884.76040000"]],"time":"2020-06-30T19:20:20.766344Z"}
{"type":"l2update","product_id":"BTC-USD","changes":[["buy","9099.84","0.00000000"]],"time":"2020-06-30T19:20:20.973283Z"}
{"type":"heartbeat","last_trade_id":0,"product_id":"BTC-USD","sequence":180758339,"time":"2020-06-30T19:20:21.735093Z"}
{"type":"l2update","product_id":"BTC-USD","changes":[["buy","8925.20","0.00100000"]],"time":"2020-06-30T19:20:21.895198Z"}
{"type":"l2update","product_id":"BTC-USD","changes":[["sell","9127.77","0.53570000"]],"time":"2020-06-30T19:20:22.208967Z"}
{"type":"l2update","product_id":"BTC-USD","changes":[["sell","9173.21","0.00000000"]],"time":"2020-06-30T19:20:22.404689Z"}
{"type":"heartbeat","last_trade_id":0,"product_id":"BTC-USD","sequence":180758344,"time":"2020-06-30T19:20:22.735089Z"}
{"type":"l2update","product_id":"BTC-USD","changes":[["sell","9120.82","2867.57910000"]],"time":"2020-06-30T19:20:22.988325Z"}
{"type":"l2update","product_id":"BTC-USD","changes":[["buy","9115.61","0.00000000"]],"time":"2020-06-30T19:20:23.226652Z"}
{"type":"l2update","product_id":"BTC-USD","changes":[["sell","9120.82","2857.94690000"]],"time":"2020-06-30T19:20:23.531214Z"}
{"type":"heartbeat","last_trade_id":0,"product_id":"BTC-USD","sequence":180758351,"time":"2020-06-30T19:20:23.735097Z"}
{"type":"l2update","product_id":"BTC-USD","changes":[["sell","9156.01","0.01000000"]],"time":"2020-06-30T19:20:23.816012Z"}
{"type":"l2update","product_id":"BTC-USD","changes":[["buy","9112.93","0.00000000"]],"time":"2020-06-30T19:20:23.976328Z"}
{"type":"l2update","product_id":"BTC-USD","changes":[["sell","9120.82","2857.61810000"]],"time":"2020-06-30T19:20:24.076455Z"}
{"type":"l2update","product_id":"BTC-USD","changes":[["sell","9123.15","0.00000000"]],"time":"2020-06-30T19:20:24.355094Z"}
{"type":"l2update","product_id":"BTC-USD","changes":[["buy","9094.88","0.02300000"]],"time":"2020-06-30T19:20:24.377901Z"}
{"type":"l2update","product_id":"BTC-USD","changes":[["buy","9117.70","0.00000000"]],"time":"2020-06-30T19:20:24.509435Z"}
{"type":"heartbeat","last_trade_id":0,"product_id":"BTC-USD","sequence":180758361,"time":"2020-06-30T19:20:24.735123Z"}
{"type":"l2update","product_id":"BTC-USD","changes":[["sell","9120.82","2857.58700000"]],"time":"2020-06-30T19:20:25.467391Z"}
{"type":"heartbeat","last_trade_id":0,"product_id":"BTC-USD","sequence":180758364,"time":"2020-06-30T19:20:25.735123Z"}
{"type":"l2update","product_id":"BTC-USD","changes":[["buy","9094.88","0.00000000"]],"time":"2020-06-30T19:20:26.140735Z"}
{"type":"l2update","product_id":"BTC-USD","changes":[["sell","9120.82","2856.81350000"]],"time":"2020-06-30T19:20:26.273385Z"}
{"type":"heartbeat","last_trade_id":0,"product_id":"BTC-USD","sequence":180758368,"time":"2020-06-30T19:20:26.735122Z"}
{"type":"l2update","product_id":"BTC-USD","changes":[["sell","9132.89","0.05000000"]],"time":"2020-06-30T19:20:26.812906Z"}
{"type":"l2update","product_id":"BTC-USD","changes":[["sell","9167.12","0.05450000"]],"time":"2020-06-30T19:20:27.116807Z"}
{"type":"l2update","product_id":"BTC-USD","changes":[["sell","9127.77","0.00000000"]],"time":"2020-06-30T19:20:27.245621Z"}
{"type":"l2update","product_id":"BTC-USD","changes":[["sell","9123.73","0.00000000"]],"time":"2020-06-30T19:20:27.266531Z"}
{"type":"l2update","product_id":"BTC-USD","changes":[["sell","9156.01","0.00000000"]],"time":"2020-06-30T19:20:27.298400Z"}
{"type":"heartbeat","last_trade_id":0,"product_id":"BTC-USD","sequence":180758375,"time":"2020-06-30T19:20:27.735112Z"}
{"type":"l2update","product_id":"BTC-USD","changes":[["sell","9157.13","2.10000000"]],"time":"2020-06-30T19:20:27.943063Z"}
{"type":"l2update","product_id":"BTC-USD","changes":[["sell","9120.82","2855.31350000"]],"time":"2020-06-30T19:20:28.200835Z"}
{"type":"l2update","product_id":"BTC-USD","changes":[["sell","9167.12","0.00000000"]],"time":"2020-06-30T19:20:28.406520Z"}
{"type":"l2update","product_id":"BTC-USD","changes":[["sell","9120.82","2847.32550000"]],"time":"2020-06-30T19:20:28.486890Z"}
{"type":"heartbeat","last_trade_id":0,"product_id":"BTC-USD","sequence":180758384,"time":"2020-06-30T19:20:28.735117Z"}
{"type":"l2update","product_id":"BTC-USD","changes":[["sell","9120.82","2847.25980000"]],"time":"2020-06-30T19:20:28.760090Z"}
{"type":"l2update","product_id":"BTC-USD","changes":[["buy","9102.36","0.00000000"]],"time":"2020-06-30T19:20:28.919571Z"}
{"type":"l2update","product_id":"BTC-USD","changes":[["buy","8925.20","0.00000000"]],"time":"2020-06-30T19:20:28.927807Z"}
{"type":"l2update","product_id":"BTC-USD","changes":[["buy","100.00","114.95500000"]],"time":"2020-06-30T19:20:29.058210Z"}
{"type":"l2update","product_id":"BTC-USD","changes":[["buy","100.00","114.94500000"]],"time":"2020-06-30T19:20:29.067196Z"}
{"type":"heartbeat","last_trade_id":0,"product_id":"BTC-USD","sequence":180758392,"time":"2020-06-30T19:20:29.735113Z"}
{"type":"l2update","product_id":"BTC-USD","changes":[["sell","9135.68","0.06570000"]],"time":"2020-06-30T19:20:29.897672Z"}
{"type":"l2update","product_id":"BTC-USD","changes":[["sell","9120.82","2846.25980000"]],"time":"2020-06-30T19:20:30.180526Z"}
{"type":"l2update","product_id":"BTC-USD","changes":[["sell","9172.40","0.00000000"]],"time":"2020-06-30T19:20:30.347101Z"}
{"type":"l2update","product_id":"BTC-USD","changes":[["sell","9126.26","0.00000000"]],"time":"2020-06-30T19:20:30.348260Z"}
{"type":"l2update","product_id":"BTC-USD","changes":[["sell","9172.91","0.00000000"]],"time":"2020-06-30T19:20:30.354357Z"}
{"type":"heartbeat","last_trade_id":0,"product_id":"BTC-USD","sequence":180758400,"time":"2020-06-30T19:20:30.735110Z"}
{"type":"l2update","product_id":"BTC-USD","changes":[["sell","9131.96","4.00000000"]],"time":"2020-06-30T19:20:31.014482Z"}
{"type":"heartbeat","last_trade_id":0,"product_id":"BTC-USD","sequence":180758402,"time":"2020-06-30T19:20:31.735143Z"}
{"type":"l2update","product_id":"BTC-USD","changes":[["sell","9120.82","2846.14100000"]],"time":"2020-06-30T19:20:32.670791Z"}
{"type":"heartbeat","last_trade_id":0,"product_id":"BTC-USD","sequence":180758405,"time":"2020-06-30T19:20:32.735076Z"}
{"type":"l2update","product_id":"BTC-USD","changes":[["sell","9141.44","0.03250000"]],"time":"2020-06-30T19:20:32.941789Z"}
{"type":"l2update","product_id":"BTC-USD","changes":[["sell","9120.82","2844.15100000"]],"time":"2020-06-30T19:20:33.223514Z"}
{"type":"l2update","product_id":"BTC-USD","changes":[["sell","9120.82","2840.15100000"]],"time":"2020-06-30T19:20:33.502868Z"}
{"type":"heartbeat","last_trade_id":0,"product_id":"BTC-USD","sequence":180758413,"time":"2020-06-30T19:20:33.735098Z"}
{"type":"l2update","product_id":"BTC-USD","changes":[["buy","9120.55","0.00000000"]],"time":"2020-06-30T19:20:33.914814Z"}
{"type":"l2update","product_id":"BTC-USD","changes":[["sell","9120.82","2840.12880000"]],"time":"2020-06-30T19:20:34.037285Z"}
{"type":"l2update","product_id":"BTC-USD","changes":[["sell","9149.88","0.10000000"]],"time":"2020-06-30T19:20:34.596077Z"}
{"type":"heartbeat","last_trade_id":0,"product_id":"BTC-USD","sequence":180758419,"time":"2020-06-30T19:20:34.735116Z"}
{"type":"l2update","product_id":"BTC-USD","changes":[["sell","9124.59","0.00000000"]],"time":"2020-06-30T19:20:35.063663Z"}
{"type":"l2update","product_id":"BTC-USD","changes":[["sell","9132.89","0.00000000"]],"time":"2020-06-30T19:20:35.066042Z"}
{"type":"l2update","product_id":"BTC-USD","changes":[["sell","9157.13","0.00000000"]],"time":"2020-06-30T19:20:35.099679Z"}
{"type":"l2update","product_id":"BTC-USD","changes":[["buy","9109.41","0.03080000"]],"time":"2020-06-30T19:20:35.420052Z"}
{"type":"l2update","product_id":"BTC-USD","changes":[["sell","9120.82","2839.75830000"]],"time":"2020-06-30T19:20:35.700225Z"}
{"type":"heartbeat","last_trade_id":0,"product_id":"BTC-USD","sequence":180758427,"time":"2020-06-30T19:20:35.735117Z"}
{"type":"l2update","product_id":"BTC-USD","changes":[["sell","9120.82","2839.69260000"]],"time":"2020-06-30T19:20:36.017006Z"}
{"type":"l2update","product_id":"BTC-USD","changes":[["buy","9109.41","0.00000000"]],"time":"2020-06-30T19:20:36.141046Z"}
{"type":"l2update","product_id":"BTC-USD","changes":[["sell","9183.53","0.02400000"]],"time":"2020-06-30T19:20:36.293954Z"}
{"type":"l2update","product_id":"BTC-USD","changes":[["sell","9125.00","0.00000000"]],"time":"2020-06-30T19:20:36.713198Z"}
{"type":"heartbeat","last_trade_id":0,"product_id":"BTC-USD","sequence":180758434,"time":"2020-06-30T19:20:36.735115Z"}
{"type":"l2update","product_id":"BTC-USD","changes":[["sell","9120.82","2839.62690000"]],"time":"2020-06-30T19:20:36.887198Z"}
{"type":"heartbeat","last_trade_id":0,"product_id":"BTC-USD","sequence":180758437,"time":"2020-06-30T19:20:37.735118Z"}
{"type":"l2update","product_id":"BTC-USD","changes":[["sell","9141.62","1.03060000"]],"time":"2020-06-30T19:20:38.588563Z"}
{"type":"heartbeat","last_trade_id":0,"product_id":"BTC-USD","sequence":180758439,"time":"2020-06-30T19:20:38.735024Z"}
{"type":"l2update","product_id":"BTC-USD","changes":[["sell","9123.28","0.00000000"]],"time":"2020-06-30T19:20:39.001363Z"}
{"type":"heartbeat","last_trade_id":0,"product_id":"BTC-USD","sequence":180758440,"time":"2020-06-30T19:20:39.735107Z"}
{"type":"l2update","product_id":"BTC-USD","changes":[["sell","9183.40","0.12310000"]],"time":"2020-06-30T19:20:40.295578Z"}
{"type":"l2update","product_id":"BTC-USD","changes":[["sell","9183.78","0.05180000"]],"time":"2020-06-30T19:20:40.554331Z"}
{"type":"heartbeat","last_trade_id":0,"product_id":"BTC-USD","sequence":180758444,"time":"2020-06-30T19:20:40.735116Z"}
{"type":"l2update","product_id":"BTC-USD","changes":[["sell","9120.82","2839.57690000"]],"time":"2020-06-30T19:20:40.837303Z"}
{"type":"l2update","product_id":"BTC-USD","changes":[["sell","9120.82","2839.57590000"]],"time":"2020-06-30T19:20:40.863890Z"}
{"type":"heartbeat","last_trade_id":0,"product_id":"BTC-USD","sequence":180758450,"time":"2020-06-30T19:20:41.735118Z"}
{"type":"heartbeat","last_trade_id":0,"product_id":"BTC-USD","sequence":180758450,"time":"2020-06-30T19:20:42.735110Z"}
{"type":"l2update","product_id":"BTC-USD","changes":[["buy","9108.99","0.02280000"]],"time":"2020-06-30T19:20:43.081045Z"}
{"type":"l2update","product_id":"BTC-USD","changes":[["sell","9120.82","2839.51020000"]],"time":"2020-06-30T19:20:43.702189Z"}
{"type":"heartbeat","last_trade_id":0,"product_id":"BTC-USD","sequence":180758455,"time":"2020-06-30T19:20:43.735109Z"}
{"type":"l2update","product_id":"BTC-USD","changes":[["buy","100.00","114.95500000"]],"time":"2020-06-30T19:20:44.092360Z"}
{"type":"l2update","product_id":"BTC-USD","changes":[["buy","100.00","114.94500000"]],"time":"2020-06-30T19:20:44.099603Z"}
{"type":"l2update","product_id":"BTC-USD","changes":[["sell","9187.76","0.00100000"]],"time":"2020-06-30T19:20:44.276420Z"}
{"type":"l2update","product_id":"BTC-USD","changes":[["sell","9187.47","0.09100000"]],"time":"2020-06-30T19:20:44.561850Z"}
{"type":"l2update","product_id":"BTC-USD","changes":[["sell","9183.40","0.00000000"]],"time":"2020-06-30T19:20:44.697393Z"}
{"type":"heartbeat","last_trade_id":0,"product_id":"BTC-USD","sequence":180758463,"time":"2020-06-30T19:20:44.735119Z"}
{"type":"l2update","product_id":"BTC-USD","changes":[["sell","9187.17","0.03930000"]],"time":"2020-06-30T19:20:44.843393Z"}
{"type":"l2update","product_id":"BTC-USD","changes":[["sell","9183.78","0.00000000"]],"time":"2020-06-30T19:20:45.004023Z"}
{"type":"l2update","product_id":"BTC-USD","changes":[["sell","9127.56","0.00000000"]],"time":"2020-06-30T19:20:45.007845Z"}
{"type":"l2update","product_id":"BTC-USD","changes":[["buy","8775.12","0.00100000"]],"time":"2020-06-30T19:20:45.420854Z"}
{"type":"l2update","product_id":"BTC-USD","changes":[["buy","9108.99","0.10570000"]],"time":"2020-06-30T19:20:45.694629Z"}
{"type":"heartbeat","last_trade_id":0,"product_id":"BTC-USD","sequence":180758471,"time":"2020-06-30T19:20:45.735110Z"}
{"type":"l2update","product_id":"BTC-USD","changes":[["buy","9108.58","0.03690000"]],"time":"2020-06-30T19:20:46.246945Z"}
{"type":"l2update","product_id":"BTC-USD","changes":[["buy","9108.58","0.07310000"]],"time":"2020-06-30T19:20:46.537059Z"}
{"type":"l2update","product_id":"BTC-USD","changes":[["buy","9101.45","0.00000000"]],"time":"2020-06-30T19:20:46.673741Z"}
{"type":"heartbeat","last_trade_id":0,"product_id":"BTC-USD","sequence":180758476,"time":"2020-06-30T19:20:46.735123Z"}
{"type":"l2update","product_id":"BTC-USD","changes":[["sell","9132.83","0.05000000"]],"time":"2020-06-30T19:20:46.812827Z"}
{"type":"l2update","product_id":"BTC-USD","changes":[["sell","9120.82","2834.51020000"]],"time":"2020-06-30T19:20:47.379356Z"}
{"type":"l2update","product_id":"BTC-USD","changes":[["buy","9107.76","0.06990000"]],"time":"2020-06-30T19:20:47.660093Z"}
{"type":"heartbeat","last_trade_id":0,"product_id":"BTC-USD","sequence":180758483,"time":"2020-06-30T19:20:47.735074Z"}
{"type":"l2update","product_id":"BTC-USD","changes":[["sell","9132.79","2.29960000"]],"time":"2020-06-30T19:20:48.007163Z"}
{"type":"l2update","product_id":"BTC-USD","changes":[["sell","9185.19","0.12310000"]],"time":"2020-06-30T19:20:48.219397Z"}
{"type":"l2update","product_id":"BTC-USD","changes":[["sell","9141.44","0.00000000"]],"time":"2020-06-30T19:20:48.396418Z"}
{"type":"l2update","product_id":"BTC-USD","changes":[["sell","9187.47","0.00000000"]],"time":"2020-06-30T19:20:48.400726Z"}
{"type":"l2update","product_id":"BTC-USD","changes":[["sell","9132.83","0.00000000"]],"time":"2020-06-30T19:20:48.403641Z"}
{"type":"heartbeat","last_trade_id":0,"product_id":"BTC-USD","sequence":180758490,"time":"2020-06-30T19:20:48.735099Z"}
{"type":"l2update","product_id":"BTC-USD","changes":[["sell","9120.82","2833.61020000"]],"time":"2020-06-30T19:20:49.332791Z"}
{"type":"l2update","product_id":"BTC-USD","changes":[["buy","9107.35","0.07100000"]],"time":"2020-06-30T19:20:49.620427Z"}
{"type":"heartbeat","last_trade_id":0,"product_id":"BTC-USD","sequence":180758495,"time":"2020-06-30T19:20:49.735119Z"}
{"type":"l2update","product_id":"BTC-USD","changes":[["buy","9108.99","0.08290000"]],"time":"2020-06-30T19:20:49.768291Z"}
{"type":"l2update","product_id":"BTC-USD","changes":[["sell","9186.15","0.06880000"]],"time":"2020-06-30T19:20:49.922362Z"}
{"type":"l2update","product_id":"BTC-USD","changes":[["sell","9135.68","0.00000000"]],"time":"2020-06-30T19:20:50.438781Z"}
{"type":"l2update","product_id":"BTC-USD","changes":[["sell","9120.82","2833.54450000"]],"time":"2020-06-30T19:20:50.723869Z"}
{"type":"heartbeat","last_trade_id":0,"product_id":"BTC-USD","sequence":180758502,"time":"2020-06-30T19:20:50.735114Z"}
{"type":"l2update","product_id":"BTC-USD","changes":[["sell","9133.98","0.54200000"]],"time":"2020-06-30T19:20:51.035957Z"}
{"type":"heartbeat","last_trade_id":0,"product_id":"BTC-USD","sequence":180758504,"time":"2020-06-30T19:20:51.735110Z"}
{"type":"l2update","product_id":"BTC-USD","changes":[["sell","9134.26","0.54600000"]],"time":"2020-06-30T19:20:51.893288Z"}
{"type":"l2update","product_id":"BTC-USD","changes":[["sell","9187.76","0.00000000"]],"time":"2020-06-30T19:20:52.088047Z"}
{"type":"l2update","product_id":"BTC-USD","changes":[["sell","9131.96","0.00000000"]],"time":"2020-06-30T19:20:52.100242Z"}
{"type":"heartbeat","last_trade_id":0,"product_id":"BTC-USD","sequence":180758508,"time":"2020-06-30T19:20:52.735029Z"}
{"type":"l2update","product_id":"BTC-USD","changes":[["buy","9103.61","0.50000000"]],"time":"2020-06-30T19:20:53.267813Z"}
{"type":"heartbeat","last_trade_id":0,"product_id":"BTC-USD","sequence":180758510,"time":"2020-06-30T19:20:53.735121Z"}
{"type":"l2update","product_id":"BTC-USD","changes":[["buy","9108.58","0.03690000"]],"time":"2020-06-30T19:20:53.863421Z"}
{"type":"l2update","product_id":"BTC-USD","changes":[["sell","9187.30","0.02780000"]],"time":"2020-06-30T19:20:54.111571Z"}
{"type":"l2update","product_id":"BTC-USD","changes":[["sell","9187.17","0.04030000"]],"time":"2020-06-30T19:20:54.381244Z"}
{"type":"l2update","product_id":"BTC-USD","changes":[["sell","9132.79","0.00000000"]],"time":"2020-06-30T19:20:54.543884Z"}
{"type":"heartbeat","last_trade_id":0,"product_id":"BTC-USD","sequence":180758516,"time":"2020-06-30T19:20:54.735040Z"}
{"type":"l2update","product_id":"BTC-USD","changes":[["buy","9106.01","0.02200000"]],"time":"2020-06-30T19:20:55.536188Z"}
{"type":"heartbeat","last_trade_id":0,"product_id":"BTC-USD","sequence":180758518,"time":"2020-06-30T19:20:55.735115Z"}
{"type":"l2update","product_id":"BTC-USD","changes":[["buy","9107.35","0.00000000"]],"time":"2020-06-30T19:20:55.974813Z"}
{"type":"l2update","product_id":"BTC-USD","changes":[["buy","9093.92","0.02300000"]],"time":"2020-06-30T19:20:56.084940Z"}
{"type":"l2update","product_id":"BTC-USD","changes":[["buy","9094.30","0.03890000"]],"time":"2020-06-30T19:20:56.379152Z"}
{"type":"l2update","product_id":"BTC-USD","changes":[["buy","9103.61","0.00000000"]],"time":"2020-06-30T19:20:56.513279Z"}
{"type":"l2update","product_id":"BTC-USD","changes":[["buy","9101.87","0.07360000"]],"time":"2020-06-30T19:20:56.662388Z"}
{"type":"heartbeat","last_trade_id":0,"product_id":"BTC-USD","sequence":180758526,"time":"2020-06-30T19:20:56.735113Z"}
{"type":"l2update","product_id":"BTC-USD","changes":[["sell","9148.99","0.02360000"]],"time":"2020-06-30T19:20:57.743458Z"}
{"type":"heartbeat","last_trade_id":0,"product_id":"BTC-USD","sequence":180758528,"time":"2020-06-30T19:20:57.735116Z"}
{"type":"l2update","product_id":"BTC-USD","changes":[["buy","9104.44","1.26090000"]],"time":"2020-06-30T19:20:58.016794Z"}
{"type":"l2update","product_id":"BTC-USD","changes":[["sell","9134.26","0.00000000"]],"time":"2020-06-30T19:20:58.159716Z"}
{"type":"l2update","product_id":"BTC-USD","changes":[["sell","9185.19","0.00000000"]],"time":"2020-06-30T19:20:58.162404Z"}
{"type":"l2update","product_id":"BTC-USD","changes":[["sell","9141.62","0.00000000"]],"time":"2020-06-30T19:20:58.177460Z"}
{"type":"l2update","product_id":"BTC-USD","changes":[["sell","9158.42","1.06330000"]],"time":"2020-06-30T19:20:58.278581Z"}
{"type":"l2update","product_id":"BTC-USD","changes":[["buy","9108.99","0.00000000"]],"time":"2020-06-30T19:20:58.455407Z"}
{"type":"l2update","product_id":"BTC-USD","changes":[["buy","9093.92","0.00000000"]],"time":"2020-06-30T19:20:58.455720Z"}
{"type":"l2update","product_id":"BTC-USD","changes":[["sell","9120.82","2833.49450000"]],"time":"2020-06-30T19:20:58.563251Z"}
{"type":"l2update","product_id":"BTC-USD","changes":[["sell","9149.88","0.00000000"]],"time":"2020-06-30T19:20:58.723182Z"}
{"type":"heartbeat","last_trade_id":0,"product_id":"BTC-USD","sequence":180758541,"time":"2020-06-30T19:20:58.735117Z"}
{"type":"l2update","product_id":"BTC-USD","changes":[["buy","100.00","114.95500000"]],"time":"2020-06-30T19:20:59.059953Z"}
{"type":"l2update","product_id":"BTC-USD","changes":[["buy","100.00","114.94500000"]],"time":"2020-06-30T19:20:59.066225Z"}
{"type":"l2update","product_id":"BTC-USD","changes":[["sell","9120.82","2833.42880000"]],"time":"2020-06-30T19:20:59.110989Z"}
{"type":"l2update","product_id":"BTC-USD","changes":[["buy","8775.12","0.00000000"]],"time":"2020-06-30T19:20:59.537473Z"}
{"type":"l2update","product_id":"BTC-USD","changes":[["sell","9120.82","2833.37880000"]],"time":"2020-06-30T19:20:59.672752Z"}
{"type":"heartbeat","last_trade_id":0,"product_id":"BTC-USD","sequence":180758551,"time":"2020-06-30T19:20:59.735118Z"}
{"type":"l2update","product_id":"BTC-USD","changes":[["buy","9102.77","0.00000000"]],"time":"2020-06-30T19:21:00.124643Z"}
{"type":"l2update","product_id":"BTC-USD","changes":[["buy","8888.60","0.00000000"]],"time":"2020-06-30T19:21:00.519680Z"}
{"type":"l2update","product_id":"BTC-USD","changes":[["sell","9185.80","0.01490000"]],"time":"2020-06-30T19:21:00.536255Z"}
{"type":"heartbeat","last_trade_id":0,"product_id":"BTC-USD","sequence":180758555,"time":"2020-06-30T19:21:00.735110Z"}
{"type":"l2update","product_id":"BTC-USD","changes":[["sell","9187.17","0.00100000"]],"time":"2020-06-30T19:21:00.802517Z"}
{"type":"l2update","product_id":"BTC-USD","changes":[["sell","9187.30","0.00000000"]],"time":"2020-06-30T19:21:00.815715Z"}
{"type":"l2update","product_id":"BTC-USD","changes":[["buy","8887.85","0.04720437"]],"time":"2020-06-30T19:21:01.030034Z"}
{"type":"l2update","product_id":"BTC-USD","changes":[["sell","9442.69","0.00000000"]],"time":"2020-06-30T19:21:01.384029Z"}
{"type":"l2update","product_id":"BTC-USD","changes":[["sell","9443.49","0.00793381"]],"time":"2020-06-30T19:21:01.648526Z"}
{"type":"l2update","product_id":"BTC-USD","changes":[["sell","9135.04","1.63900000"]],"time":"2020-06-30T19:21:01.686524Z"}
{"type":"heartbeat","last_trade_id":0,"product_id":"BTC-USD","sequence":180758564,"time":"2020-06-30T19:21:01.735060Z"}
{"type":"l2update","product_id":"BTC-USD","changes":[["sell","9153.10","0.50000000"]],"time":"2020-06-30T19:21:01.985647Z"}
{"type":"l2update","product_id":"BTC-USD","changes":[["buy","9096.77","0.07370000"]],"time":"2020-06-30T19:21:02.263243Z"}
{"type":"l2update","product_id":"BTC-USD","changes":[["sell","9148.99","0.00000000"]],"time":"2020-06-30T19:21:02.509803Z"}
{"type":"heartbeat","last_trade_id":0,"product_id":"BTC-USD","sequence":180758569,"time":"2020-06-30T19:21:02.735113Z"}
{"type":"l2update","product_id":"BTC-USD","changes":[["sell","9120.82","2832.47880000"]],"time":"2020-06-30T19:21:02.883050Z"}
{"type":"l2update","product_id":"BTC-USD","changes":[["sell","9120.82","2832.41310000"]],"time":"2020-06-30T19:21:03.163193Z"}
{"type":"l2update","product_id":"BTC-USD","changes":[["sell","9120.82","2832.04260000"]],"time":"2020-06-30T19:21:03.447866Z"}
{"type":"l2update","product_id":"BTC-USD","changes":[["buy","9102.31","0.02430000"]],"time":"2020-06-30T19:21:03.696875Z"}
{"type":"heartbeat","last_trade_id":0,"product_id":"BTC-USD","sequence":180758580,"time":"2020-06-30T19:21:03.735118Z"}
{"type":"l2update","product_id":"BTC-USD","changes":[["sell","9184.77","0.00100000"]],"time":"2020-06-30T19:21:04.109649Z"}
{"type":"l2update","product_id":"BTC-USD","changes":[["buy","9102.72","0.04730000"]],"time":"2020-06-30T19:21:04.423829Z"}
{"type":"heartbeat","last_trade_id":0,"product_id":"BTC-USD","sequence":180758584,"time":"2020-06-30T19:21:04.735115Z"}
{"type":"heartbeat","last_trade_id":0,"product_id":"BTC-USD","sequence":180758584,"time":"2020-06-30T19:21:05.735117Z"}
{"type":"l2update","product_id":"BTC-USD","changes":[["buy","9102.31","0.07430000"]],"time":"2020-06-30T19:21:05.895767Z"}
{"type":"l2update","product_id":"BTC-USD","changes":[["buy","9108.58","0.00000000"]],"time":"2020-06-30T19:21:06.340368Z"}
{"type":"l2update","product_id":"BTC-USD","changes":[["buy","9106.01","0.00000000"]],"time":"2020-06-30T19:21:06.355569Z"}
{"type":"heartbeat","last_trade_id":0,"product_id":"BTC-USD","sequence":180758588,"time":"2020-06-30T19:21:06.735091Z"}
{"type":"l2update","product_id":"BTC-USD","changes":[["sell","9133.71","0.05000000"]],"time":"2020-06-30T19:21:06.752013Z"}
{"type":"l2update","product_id":"BTC-USD","changes":[["sell","9183.53","0.00000000"]],"time":"2020-06-30T19:21:07.222470Z"}
{"type":"l2update","product_id":"BTC-USD","changes":[["sell","9120.82","2831.97690000"]],"time":"2020-06-30T19:21:07.299696Z"}
{"type":"heartbeat","last_trade_id":0,"product_id":"BTC-USD","sequence":180758594,"time":"2020-06-30T19:21:07.735096Z"}
{"type":"l2update","product_id":"BTC-USD","changes":[["buy","9102.72","0.09910000"]],"time":"2020-06-30T19:21:08.163115Z"}
{"type":"l2update","product_id":"BTC-USD","changes":[["buy","9101.87","0.00000000"]],"time":"2020-06-30T19:21:08.365891Z"}
{"type":"l2update","product_id":"BTC-USD","changes":[["sell","9120.82","2831.91120000"]],"time":"2020-06-30T19:21:08.444558Z"}
{"type":"heartbeat","last_trade_id":0,"product_id":"BTC-USD","sequence":180758600,"time":"2020-06-30T19:21:08.735114Z"}
{"type":"l2update","product_id":"BTC-USD","changes":[["sell","9120.82","2831.84550000"]],"time":"2020-06-30T19:21:09.031841Z"}
{"type":"l2update","product_id":"BTC-USD","changes":[["sell","9186.03","0.05270000"]],"time":"2020-06-30T19:21:09.309350Z"}
{"type":"l2update","product_id":"BTC-USD","changes":[["sell","9185.80","0.00000000"]],"time":"2020-06-30T19:21:09.533889Z"}
{"type":"heartbeat","last_trade_id":0,"product_id":"BTC-USD","sequence":180758606,"time":"2020-06-30T19:21:09.735116Z"}
{"type":"l2update","product_id":"BTC-USD","changes":[["sell","9120.82","2831.77980000"]],"time":"2020-06-30T19:21:10.709332Z"}
{"type":"heartbeat","last_trade_id":0,"product_id":"BTC-USD","sequence":180758609,"time":"2020-06-30T19:21:10.735117Z"}
{"type":"l2update","product_id":"BTC-USD","changes":[["sell","9120.82","2831.71410000"]],"time":"2020-06-30T19:21:11.259790Z"}
{"type":"l2update","product_id":"BTC-USD","changes":[["buy","9120.80","2716.00060000"]],"time":"2020-06-30T19:21:11.470322Z"}
{"type":"heartbeat","last_trade_id":0,"product_id":"BTC-USD","sequence":180758615,"time":"2020-06-30T19:21:11.735097Z"}
{"type":"l2update","product_id":"BTC-USD","changes":[["sell","9120.82","2831.64840000"]],"time":"2020-06-30T19:21:12.526805Z"}
{"type":"heartbeat","last_trade_id":0,"product_id":"BTC-USD","sequence":180758618,"time":"2020-06-30T19:21:12.735098Z"}
{"type":"l2update","product_id":"BTC-USD","changes":[["buy","9107.76","0.00000000"]],"time":"2020-06-30T19:21:12.748804Z"}
{"type":"l2update","product_id":"BTC-USD","changes":[["buy","9104.44","0.00000000"]],"time":"2020-06-30T19:21:12.759746Z"}
{"type":"l2update","product_id":"BTC-USD","changes":[["buy","9094.30","0.00000000"]],"time":"2020-06-30T19:21:12.762540Z"}
{"type":"l2update","product_id":"BTC-USD","changes":[["buy","9094.12","0.01050000"]],"time":"2020-06-30T19:21:13.698183Z"}
{"type":"heartbeat","last_trade_id":0,"product_id":"BTC-USD","sequence":180758623,"time":"2020-06-30T19:21:13.735115Z"}
{"type":"l2update","product_id":"BTC-USD","changes":[["sell","9181.81","0.06880000"]],"time":"2020-06-30T19:21:13.978868Z"}
{"type":"l2update","product_id":"BTC-USD","changes":[["buy","100.00","114.95500000"]],"time":"2020-06-30T19:21:14.050126Z"}
{"type":"l2update","product_id":"BTC-USD","changes":[["buy","100.00","114.94500000"]],"time":"2020-06-30T19:21:14.057702Z"}
{"type":"l2update","product_id":"BTC-USD","changes":[["sell","9158.42","0.00000000"]],"time":"2020-06-30T19:21:14.509669Z"}
{"type":"l2update","product_id":"BTC-USD","changes":[["sell","9185.15","0.01490000"]],"time":"2020-06-30T19:21:14.555827Z"}
{"type":"heartbeat","last_trade_id":0,"product_id":"BTC-USD","sequence":180758631,"time":"2020-06-30T19:21:14.735117Z"}
{"type":"l2update","product_id":"BTC-USD","changes":[["sell","9184.74","0.09640000"]],"time":"2020-06-30T19:21:14.805943Z"}
{"type":"l2update","product_id":"BTC-USD","changes":[["sell","9186.15","0.00000000"]],"time":"2020-06-30T19:21:14.992568Z"}
{"type":"l2update","product_id":"BTC-USD","changes":[["sell","9135.04","0.00000000"]],"time":"2020-06-30T19:21:15.002454Z"}
{"type":"l2update","product_id":"BTC-USD","changes":[["sell","9133.98","0.00000000"]],"time":"2020-06-30T19:21:15.007128Z"}
{"type":"l2update","product_id":"BTC-USD","changes":[["sell","9120.82","2830.75610000"]],"time":"2020-06-30T19:21:15.726319Z"}
{"type":"heartbeat","last_trade_id":0,"product_id":"BTC-USD","sequence":180758639,"time":"2020-06-30T19:21:15.735114Z"}
{"type":"heartbeat","last_trade_id":0,"product_id":"BTC-USD","sequence":180758639,"time":"2020-06-30T19:21:16.735117Z"}
{"type":"l2update","product_id":"BTC-USD","changes":[["sell","9120.82","2830.69040000"]],"time":"2020-06-30T19:21:17.129001Z"}
{"type":"l2update","product_id":"BTC-USD","changes":[["sell","9120.82","2830.64040000"]],"time":"2020-06-30T19:21:17.409379Z"}
{"type":"l2update","product_id":"BTC-USD","changes":[["buy","9094.12","0.00000000"]],"time":"2020-06-30T19:21:17.603535Z"}
{"type":"l2update","product_id":"BTC-USD","changes":[["sell","9120.82","2829.78770000"]],"time":"2020-06-30T19:21:17.679341Z"}
{"type":"heartbeat","last_trade_id":0,"product_id":"BTC-USD","sequence":180758649,"time":"2020-06-30T19:21:17.735130Z"}
{"type":"l2update","product_id":"BTC-USD","changes":[["sell","9180.62","0.06880000"]],"time":"2020-06-30T19:21:17.956812Z"}
{"type":"l2update","product_id":"BTC-USD","changes":[["buy","9102.31","0.02430000"]],"time":"2020-06-30T19:21:18.102899Z"}
{"type":"l2update","product_id":"BTC-USD","changes":[["buy","9102.72","0.04730000"]],"time":"2020-06-30T19:21:18.129354Z"}
{"type":"l2update","product_id":"BTC-USD","changes":[["sell","9185.15","0.00000000"]],"time":"2020-06-30T19:21:18.394587Z"}
{"type":"l2update","product_id":"BTC-USD","changes":[["sell","9187.17","0.00000000"]],"time":"2020-06-30T19:21:18.399715Z"}
{"type":"heartbeat","last_trade_id":0,"product_id":"BTC-USD","sequence":180758655,"time":"2020-06-30T19:21:18.735118Z"}
{"type":"l2update","product_id":"BTC-USD","changes":[["sell","9184.07","0.05180000"]],"time":"2020-06-30T19:21:18.845356Z"}
{"type":"l2update","product_id":"BTC-USD","changes":[["sell","9120.82","2829.73770000"]],"time":"2020-06-30T19:21:19.121728Z"}
{"type":"heartbeat","last_trade_id":0,"product_id":"BTC-USD","sequence":180758660,"time":"2020-06-30T19:21:19.735116Z"}
{"type":"l2update","product_id":"BTC-USD","changes":[["sell","9120.82","2829.67200000"]],"time":"2020-06-30T19:21:19.976425Z"}
{"type":"heartbeat","last_trade_id":0,"product_id":"BTC-USD","sequence":180758663,"time":"2020-06-30T19:21:20.735110Z"}
{"type":"l2update","product_id":"BTC-USD","changes":[["sell","9184.71","0.06880000"]],"time":"2020-06-30T19:21:21.681747Z"}
{"type":"heartbeat","last_trade_id":0,"product_id":"BTC-USD","sequence":180758665,"time":"2020-06-30T19:21:21.735116Z"}
{"type":"l2update","product_id":"BTC-USD","changes":[["sell","9186.03","0.00000000"]],"time":"2020-06-30T19:21:22.123968Z"}
{"type":"l2update","product_id":"BTC-USD","changes":[["sell","9184.74","0.00000000"]],"time":"2020-06-30T19:21:22.136016Z"}
{"type":"l2update","product_id":"BTC-USD","changes":[["sell","9140.84","1.27790000"]],"time":"2020-06-30T19:21:22.273087Z"}
{"type":"l2update","product_id":"BTC-USD","changes":[["sell","9184.07","0.00000000"]],"time":"2020-06-30T19:21:22.708819Z"}
{"type":"heartbeat","last_trade_id":0,"product_id":"BTC-USD","sequence":180758670,"time":"2020-06-30T19:21:22.735021Z"}
{"type":"l2update","product_id":"BTC-USD","changes":[["sell","9133.80","0.05000000"]],"time":"2020-06-30T19:21:22.816038Z"}
{"type":"l2update","product_id":"BTC-USD","changes":[["sell","9120.82","2829.67100000"]],"time":"2020-06-30T19:21:23.618356Z"}
{"type":"heartbeat","last_trade_id":0,"product_id":"BTC-USD","sequence":180758675,"time":"2020-06-30T19:21:23.735098Z"}
{"type":"l2update","product_id":"BTC-USD","changes":[["sell","9120.82","2828.85180000"]],"time":"2020-06-30T19:21:23.898973Z"}
{"type":"heartbeat","last_trade_id":0,"product_id":"BTC-USD","sequence":180758678,"time":"2020-06-30T19:21:24.735117Z"}
{"type":"l2update","product_id":"BTC-USD","changes":[["sell","9132.24","0.03280000"]],"time":"2020-06-30T19:21:25.056758Z"}
{"type":"l2update","product_id":"BTC-USD","changes":[["sell","9133.26","0.05000000"]],"time":"2020-06-30T19:21:25.305634Z"}
{"type":"l2update","product_id":"BTC-USD","changes":[["sell","9140.84","0.00000000"]],"time":"2020-06-30T19:21:25.479195Z"}
{"type":"l2update","product_id":"BTC-USD","changes":[["sell","9133.71","0.00000000"]],"time":"2020-06-30T19:21:25.486610Z"}
{"type":"l2update","product_id":"BTC-USD","changes":[["sell","9132.78","0.05000000"]],"time":"2020-06-30T19:21:25.583256Z"}
{"type":"heartbeat","last_trade_id":0,"product_id":"BTC-USD","sequence":180758686,"time":"2020-06-30T19:21:25.735113Z"}
{"type":"l2update","product_id":"BTC-USD","changes":[["sell","9120.82","2828.35180000"]],"time":"2020-06-30T19:21:25.850708Z"}
{"type":"l2update","product_id":"BTC-USD","changes":[["sell","9120.82","2827.53260000"]],"time":"2020-06-30T19:21:26.115047Z"}
{"type":"l2update","product_id":"BTC-USD","changes":[["buy","9091.60","0.01050000"]],"time":"2020-06-30T19:21:26.391374Z"}
{"type":"l2update","product_id":"BTC-USD","changes":[["sell","9120.82","2825.89460000"]],"time":"2020-06-30T19:21:26.680453Z"}
{"type":"heartbeat","last_trade_id":0,"product_id":"BTC-USD","sequence":180758697,"time":"2020-06-30T19:21:26.735117Z"}
{"type":"heartbeat","last_trade_id":0,"product_id":"BTC-USD","sequence":180758697,"time":"2020-06-30T19:21:27.735119Z"}
{"type":"l2update","product_id":"BTC-USD","changes":[["sell","9120.82","2825.84910000"]],"time":"2020-06-30T19:21:27.790214Z"}
{"type":"l2update","product_id":"BTC-USD","changes":[["sell","9120.82","2825.81850000"]],"time":"2020-06-30T19:21:28.037143Z"}
{"type":"heartbeat","last_trade_id":0,"product_id":"BTC-USD","sequence":180758703,"time":"2020-06-30T19:21:28.735115Z"}
{"type":"l2update","product_id":"BTC-USD","changes":[["sell","9120.82","2825.76850000"]],"time":"2020-06-30T19:21:28.852793Z"}
{"type":"l2update","product_id":"BTC-USD","changes":[["buy","100.00","114.95500000"]],"time":"2020-06-30T19:21:29.076617Z"}
{"type":"l2update","product_id":"BTC-USD","changes":[["buy","100.00","114.94500000"]],"time":"2020-06-30T19:21:29.082781Z"}
{"type":"l2update","product_id":"BTC-USD","changes":[["sell","9133.56","0.20000000"]],"time":"2020-06-30T19:21:29.693902Z"}
{"type":"heartbeat","last_trade_id":0,"product_id":"BTC-USD","sequence":180758711,"time":"2020-06-30T19:21:29.735116Z"}
{"type":"l2update","product_id":"BTC-USD","changes":[["sell","9120.82","2825.75810000"]],"time":"2020-06-30T19:21:29.955579Z"}
{"type":"l2update","product_id":"BTC-USD","changes":[["sell","9153.10","0.00000000"]],"time":"2020-06-30T19:21:30.171278Z"}
{"type":"l2update","product_id":"BTC-USD","changes":[["buy","9096.77","0.00000000"]],"time":"2020-06-30T19:21:30.378504Z"}
{"type":"l2update","product_id":"BTC-USD","changes":[["buy","9102.31","0.00000000"]],"time":"2020-06-30T19:21:30.380713Z"}
{"type":"l2update","product_id":"BTC-USD","changes":[["sell","9133.76","0.03280000"]],"time":"2020-06-30T19:21:30.536702Z"}
{"type":"l2update","product_id":"BTC-USD","changes":[["sell","9180.62","0.00000000"]],"time":"2020-06-30T19:21:30.737028Z"}
{"type":"l2update","product_id":"BTC-USD","changes":[["sell","9133.56","0.00000000"]],"time":"2020-06-30T19:21:30.742269Z"}
{"type":"heartbeat","last_trade_id":0,"product_id":"BTC-USD","sequence":180758721,"time":"2020-06-30T19:21:30.735120Z"}
{"type":"l2update","product_id":"BTC-USD","changes":[["sell","9132.24","0.00000000"]],"time":"2020-06-30T19:21:30.764239Z"}
{"type":"l2update","product_id":"BTC-USD","changes":[["sell","9133.22","0.20000000"]],"time":"2020-06-30T19:21:30.805832Z"}
{"type":"l2update","product_id":"BTC-USD","changes":[["sell","9133.76","0.00000000"]],"time":"2020-06-30T19:21:30.989124Z"}
{"type":"l2update","product_id":"BTC-USD","changes":[["sell","9152.48","1.18910000"]],"time":"2020-06-30T19:21:31.357907Z"}
{"type":"l2update","product_id":"BTC-USD","changes":[["sell","9155.74","1.22070000"]],"time":"2020-06-30T19:21:31.648251Z"}
{"type":"heartbeat","last_trade_id":0,"product_id":"BTC-USD","sequence":180758729,"time":"2020-06-30T19:21:31.735118Z"}
{"type":"l2update","product_id":"BTC-USD","changes":[["sell","9133.26","0.00000000"]],"time":"2020-06-30T19:21:31.797155Z"}
{"type":"l2update","product_id":"BTC-USD","changes":[["buy","9100.03","0.07360000"]],"time":"2020-06-30T19:21:31.912083Z"}
{"type":"l2update","product_id":"BTC-USD","changes":[["sell","9184.89","0.02220000"]],"time":"2020-06-30T19:21:32.745539Z"}
{"type":"heartbeat","last_trade_id":0,"product_id":"BTC-USD","sequence":180758734,"time":"2020-06-30T19:21:32.735066Z"}
{"type":"l2update","product_id":"BTC-USD","changes":[["sell","9184.15","0.06880000"]],"time":"2020-06-30T19:21:33.564070Z"}
{"type":"heartbeat","last_trade_id":0,"product_id":"BTC-USD","sequence":180758736,"time":"2020-06-30T19:21:33.735116Z"}
{"type":"l2update","product_id":"BTC-USD","changes":[["sell","9132.78","0.00000000"]],"time":"2020-06-30T19:21:33.761721Z"}
{"type":"l2update","product_id":"BTC-USD","changes":[["sell","9120.82","2825.09910000"]],"time":"2020-06-30T19:21:33.839198Z"}
{"type":"heartbeat","last_trade_id":0,"product_id":"BTC-USD","sequence":180758740,"time":"2020-06-30T19:21:34.735117Z"}
{"type":"l2update","product_id":"BTC-USD","changes":[["sell","9182.70","0.12320000"]],"time":"2020-06-30T19:21:35.232380Z"}
{"type":"l2update","product_id":"BTC-USD","changes":[["sell","9184.77","0.00000000"]],"time":"2020-06-30T19:21:35.717681Z"}
{"type":"l2update","product_id":"BTC-USD","changes":[["sell","9152.48","0.00000000"]],"time":"2020-06-30T19:21:35.727969Z"}
{"type":"heartbeat","last_trade_id":0,"product_id":"BTC-USD","sequence":180758744,"time":"2020-06-30T19:21:35.735115Z"}
{"type":"l2update","product_id":"BTC-USD","changes":[["sell","9184.15","0.00000000"]],"time":"2020-06-30T19:21:35.755225Z"}
{"type":"l2update","product_id":"BTC-USD","changes":[["buy","9097.58","0.05510000"]],"time":"2020-06-30T19:21:35.795928Z"}
{"type":"l2update","product_id":"BTC-USD","changes":[["sell","9120.82","2825.03340000"]],"time":"2020-06-30T19:21:36.112105Z"}
{"type":"l2update","product_id":"BTC-USD","changes":[["sell","9184.01","0.02220000"]],"time":"2020-06-30T19:21:36.366894Z"}
{"type":"l2update","product_id":"BTC-USD","changes":[["sell","9134.93","0.01890000"]],"time":"2020-06-30T19:21:36.670237Z"}
{"type":"heartbeat","last_trade_id":0,"product_id":"BTC-USD","sequence":180758754,"time":"2020-06-30T19:21:36.735121Z"}
{"type":"l2update","product_id":"BTC-USD","changes":[["sell","9133.22","0.00000000"]],"time":"2020-06-30T19:21:36.786955Z"}
{"type":"l2update","product_id":"BTC-USD","changes":[["sell","9162.99","1.96070000"]],"time":"2020-06-30T19:21:36.935107Z"}
{"type":"l2update","product_id":"BTC-USD","changes":[["sell","9184.71","0.00000000"]],"time":"2020-06-30T19:21:37.110507Z"}
{"type":"l2update","product_id":"BTC-USD","changes":[["sell","9155.74","0.00000000"]],"time":"2020-06-30T19:21:37.404252Z"}
{"type":"l2update","product_id":"BTC-USD","changes":[["sell","9133.80","0.00000000"]],"time":"2020-06-30T19:21:37.406378Z"}
{"type":"l2update","product_id":"BTC-USD","changes":[["sell","9120.82","2824.96770000"]],"time":"2020-06-30T19:21:37.491816Z"}
{"type":"l2update","product_id":"BTC-USD","changes":[["sell","9187.17","0.00100000"]],"time":"2020-06-30T19:21:37.741103Z"}
{"type":"heartbeat","last_trade_id":0,"product_id":"BTC-USD","sequence":180758765,"time":"2020-06-30T19:21:37.735070Z"}
{"type":"l2update","product_id":"BTC-USD","changes":[["sell","9121.69","0.00000000"]],"time":"2020-06-30T19:21:38.200497Z"}
{"type":"l2update","product_id":"BTC-USD","changes":[["sell","9182.70","0.00000000"]],"time":"2020-06-30T19:21:38.203022Z"}
{"type":"l2update","product_id":"BTC-USD","changes":[["sell","9186.34","0.12320000"]],"time":"2020-06-30T19:21:38.305243Z"}
{"type":"heartbeat","last_trade_id":0,"product_id":"BTC-USD","sequence":180758769,"time":"2020-06-30T19:21:38.735088Z"}
{"type":"heartbeat","last_trade_id":0,"product_id":"BTC-USD","sequence":180758769,"time":"2020-06-30T19:21:39.735112Z"}
{"type":"l2update","product_id":"BTC-USD","changes":[["sell","9149.88","0.10000000"]],"time":"2020-06-30T19:21:39.755283Z"}
{"type":"l2update","product_id":"BTC-USD","changes":[["sell","9120.82","2824.90200000"]],"time":"2020-06-30T19:21:40.648389Z"}
{"type":"heartbeat","last_trade_id":0,"product_id":"BTC-USD","sequence":180758774,"time":"2020-06-30T19:21:40.735114Z"}
{"type":"l2update","product_id":"BTC-USD","changes":[["buy","9093.55","0.01050000"]],"time":"2020-06-30T19:21:40.918946Z"}
{"type":"l2update","product_id":"BTC-USD","changes":[["buy","9091.60","0.00000000"]],"time":"2020-06-30T19:21:41.058178Z"}
{"type":"l2update","product_id":"BTC-USD","changes":[["sell","9120.82","2824.90100000"]],"time":"2020-06-30T19:21:41.465712Z"}
{"type":"heartbeat","last_trade_id":0,"product_id":"BTC-USD","sequence":180758780,"time":"2020-06-30T19:21:41.735116Z"}
{"type":"l2update","product_id":"BTC-USD","changes":[["buy","9111.67","0.01000000"]],"time":"2020-06-30T19:21:41.766358Z"}
{"type":"l2update","product_id":"BTC-USD","changes":[["buy","9094.47","0.01050000"]],"time":"2020-06-30T19:21:42.321164Z"}
{"type":"l2update","product_id":"BTC-USD","changes":[["sell","9120.82","2822.85600000"]],"time":"2020-06-30T19:21:42.621537Z"}
{"type":"heartbeat","last_trade_id":0,"product_id":"BTC-USD","sequence":180758787,"time":"2020-06-30T19:21:42.735114Z"}
{"type":"l2update","product_id":"BTC-USD","changes":[["sell","9120.82","2822.83380000"]],"time":"2020-06-30T19:21:43.222147Z"}
{"type":"l2update","product_id":"BTC-USD","changes":[["sell","9120.82","2822.81160000"]],"time":"2020-06-30T19:21:43.466080Z"}
{"type":"l2update","product_id":"BTC-USD","changes":[["buy","9097.58","0.00000000"]],"time":"2020-06-30T19:21:43.663077Z"}
{"type":"heartbeat","last_trade_id":0,"product_id":"BTC-USD","sequence":180758794,"time":"2020-06-30T19:21:43.735116Z"}
{"type":"l2update","product_id":"BTC-USD","changes":[["buy","100.00","114.95500000"]],"time":"2020-06-30T19:21:44.026879Z"}
{"type":"l2update","product_id":"BTC-USD","changes":[["buy","100.00","114.94500000"]],"time":"2020-06-30T19:21:44.034109Z"}
{"type":"l2update","product_id":"BTC-USD","changes":[["sell","9120.82","2817.94670000"]],"time":"2020-06-30T19:21:44.292582Z"}
{"type":"l2update","product_id":"BTC-USD","changes":[["buy","9102.72","0.00000000"]],"time":"2020-06-30T19:21:44.711552Z"}
{"type":"heartbeat","last_trade_id":0,"product_id":"BTC-USD","sequence":180758801,"time":"2020-06-30T19:21:44.735115Z"}
{"type":"heartbeat","last_trade_id":0,"product_id":"BTC-USD","sequence":180758801,"time":"2020-06-30T19:21:45.734972Z"}
{"type":"heartbeat","last_trade_id":0,"product_id":"BTC-USD","sequence":180758801,"time":"2020-06-30T19:21:46.735101Z"}
{"type":"l2update","product_id":"BTC-USD","changes":[["sell","9132.34","0.08940000"]],"time":"2020-06-30T19:21:46.920545Z"}
{"type":"l2update","product_id":"BTC-USD","changes":[["buy","9094.88","0.06410000"]],"time":"2020-06-30T19:21:47.463894Z"}
{"type":"heartbeat","last_trade_id":0,"product_id":"BTC-USD","sequence":180758805,"time":"2020-06-30T19:21:47.735122Z"}
{"type":"l2update","product_id":"BTC-USD","changes":[["buy","9104.83","0.03290000"]],"time":"2020-06-30T19:21:48.291229Z"}
{"type":"l2update","product_id":"BTC-USD","changes":[["buy","9100.03","0.00000000"]],"time":"2020-06-30T19:21:48.517142Z"}
{"type":"heartbeat","last_trade_id":0,"product_id":"BTC-USD","sequence":180758808,"time":"2020-06-30T19:21:48.735130Z"}
{"type":"heartbeat","last_trade_id":0,"product_id":"BTC-USD","sequence":180758808,"time":"2020-06-30T19:21:49.735118Z"}
{"type":"l2update","product_id":"BTC-USD","changes":[["sell","9120.82","2811.04670000"]],"time":"2020-06-30T19:21:49.789157Z"}
{"type":"l2update","product_id":"BTC-USD","changes":[["sell","9141.16","0.02360000"]],"time":"2020-06-30T19:21:50.081563Z"}
{"type":"l2update","product_id":"BTC-USD","changes":[["sell","9120.82","2810.49570000"]],"time":"2020-06-30T19:21:50.339642Z"}
{"type":"l2update","product_id":"BTC-USD","changes":[["sell","9184.89","0.00000000"]],"time":"2020-06-30T19:21:50.577078Z"}
{"type":"l2update","product_id":"BTC-USD","changes":[["sell","9120.82","2810.47350000"]],"time":"2020-06-30T19:21:50.623746Z"}
{"type":"heartbeat","last_trade_id":0,"product_id":"BTC-USD","sequence":180758820,"time":"2020-06-30T19:21:50.735116Z"}
{"type":"l2update","product_id":"BTC-USD","changes":[["sell","9133.55","0.05000000"]],"time":"2020-06-30T19:21:51.180925Z"}
{"type":"l2update","product_id":"BTC-USD","changes":[["sell","9132.34","0.00000000"]],"time":"2020-06-30T19:21:51.380707Z"}
{"type":"l2update","product_id":"BTC-USD","changes":[["sell","9133.28","0.20000000"]],"time":"2020-06-30T19:21:51.478469Z"}
{"type":"heartbeat","last_trade_id":0,"product_id":"BTC-USD","sequence":180758825,"time":"2020-06-30T19:21:51.735068Z"}
{"type":"l2update","product_id":"BTC-USD","changes":[["sell","9133.55","0.00000000"]],"time":"2020-06-30T19:21:51.901252Z"}
{"type":"l2update","product_id":"BTC-USD","changes":[["sell","9162.99","0.00000000"]],"time":"2020-06-30T19:21:51.902542Z"}
{"type":"l2update","product_id":"BTC-USD","changes":[["sell","9134.04","0.05000000"]],"time":"2020-06-30T19:21:52.022416Z"}
{"type":"l2update","product_id":"BTC-USD","changes":[["sell","9187.17","0.00000000"]],"time":"2020-06-30T19:21:52.468083Z"}
{"type":"l2update","product_id":"BTC-USD","changes":[["sell","9120.82","2810.37310000"]],"time":"2020-06-30T19:21:52.627838Z"}
{"type":"heartbeat","last_trade_id":0,"product_id":"BTC-USD","sequence":180758833,"time":"2020-06-30T19:21:52.735098Z"}
{"type":"l2update","product_id":"BTC-USD","changes":[["buy","9111.67","0.00000000"]],"time":"2020-06-30T19:21:52.779665Z"}
{"type":"l2update","product_id":"BTC-USD","changes":[["sell","9120.82","2810.27270000"]],"time":"2020-06-30T19:21:52.881056Z"}
{"type":"l2update","product_id":"BTC-USD","changes":[["sell","9133.45","0.17900000"]],"time":"2020-06-30T19:21:53.148370Z"}
{"type":"l2update","product_id":"BTC-USD","changes":[["buy","9093.55","0.00000000"]],"time":"2020-06-30T19:21:53.312192Z"}
{"type":"l2update","product_id":"BTC-USD","changes":[["sell","9183.75","0.05270000"]],"time":"2020-06-30T19:21:53.411134Z"}
{"type":"l2update","product_id":"BTC-USD","changes":[["sell","9141.16","0.00000000"]],"time":"2020-06-30T19:21:53.572826Z"}
{"type":"l2update","product_id":"BTC-USD","changes":[["buy","9033.37","0.00200000"]],"time":"2020-06-30T19:21:53.697731Z"}
{"type":"heartbeat","last_trade_id":0,"product_id":"BTC-USD","sequence":180758845,"time":"2020-06-30T19:21:53.735101Z"}
{"type":"l2update","product_id":"BTC-USD","changes":[["sell","9186.68","0.02220000"]],"time":"2020-06-30T19:21:53.969219Z"}
{"type":"l2update","product_id":"BTC-USD","changes":[["sell","9132.99","0.12420000"]],"time":"2020-06-30T19:21:54.510510Z"}
{"type":"heartbeat","last_trade_id":0,"product_id":"BTC-USD","sequence":180758849,"time":"2020-06-30T19:21:54.735118Z"}
{"type":"l2update","product_id":"BTC-USD","changes":[["sell","9185.29","0.01490000"]],"time":"2020-06-30T19:21:54.800174Z"}
{"type":"heartbeat","last_trade_id":0,"product_id":"BTC-USD","sequence":180758851,"time":"2020-06-30T19:21:55.735107Z"}
{"type":"l2update","product_id":"BTC-USD","changes":[["sell","9183.76","0.09610000"]],"time":"2020-06-30T19:21:55.934619Z"}
{"type":"l2update","product_id":"BTC-USD","changes":[["sell","9120.82","2810.25050000"]],"time":"2020-06-30T19:21:56.173567Z"}
{"type":"heartbeat","last_trade_id":0,"product_id":"BTC-USD","sequence":180758856,"time":"2020-06-30T19:21:56.735070Z"}
{"type":"l2update","product_id":"BTC-USD","changes":[["sell","9134.44","0.02500000"]],"time":"2020-06-30T19:21:56.746956Z"}
{"type":"l2update","product_id":"BTC-USD","changes":[["sell","9120.82","2809.43130000"]],"time":"2020-06-30T19:21:57.037434Z"}
{"type":"heartbeat","last_trade_id":0,"product_id":"BTC-USD","sequence":180758861,"time":"2020-06-30T19:21:57.735093Z"}
{"type":"heartbeat","last_trade_id":0,"product_id":"BTC-USD","sequence":180758861,"time":"2020-06-30T19:21:58.735117Z"}
{"type":"l2update","product_id":"BTC-USD","changes":[["buy","100.00","114.95500000"]],"time":"2020-06-30T19:21:59.093679Z"}
{"type":"l2update","product_id":"BTC-USD","changes":[["buy","100.00","114.94500000"]],"time":"2020-06-30T19:21:59.100598Z"}
{"type":"l2update","product_id":"BTC-USD","changes":[["sell","9185.53","0.05270000"]],"time":"2020-06-30T19:21:59.318525Z"}
{"type":"l2update","product_id":"BTC-USD","changes":[["sell","9120.82","2809.06080000"]],"time":"2020-06-30T19:21:59.602936Z"}
{"type":"heartbeat","last_trade_id":0,"product_id":"BTC-USD","sequence":180758869,"time":"2020-06-30T19:21:59.735109Z"}
{"type":"l2update","product_id":"BTC-USD","changes":[["buy","8887.85","0.00000000"]],"time":"2020-06-30T19:21:59.848778Z"}
{"type":"l2update","product_id":"BTC-USD","changes":[["sell","9186.58","0.10580000"]],"time":"2020-06-30T19:21:59.892936Z"}
{"type":"l2update","product_id":"BTC-USD","changes":[["buy","8887.10","0.04729655"]],"time":"2020-06-30T19:22:00.147110Z"}
{"type":"l2update","product_id":"BTC-USD","changes":[["sell","9133.45","0.00000000"]],"time":"2020-06-30T19:22:00.347685Z"}
{"type":"l2update","product_id":"BTC-USD","changes":[["sell","9132.99","0.00000000"]],"time":"2020-06-30T19:22:00.381488Z"}
{"type":"l2update","product_id":"BTC-USD","changes":[["sell","9443.49","0.00000000"]],"time":"2020-06-30T19:22:00.450869Z"}
{"type":"l2update","product_id":"BTC-USD","changes":[["buy","9095.97","0.07360000"]],"time":"2020-06-30T19:22:00.462982Z"}
{"type":"l2update","product_id":"BTC-USD","changes":[["sell","9186.78","0.06880000"]],"time":"2020-06-30T19:22:00.739315Z"}
{"type":"heartbeat","last_trade_id":0,"product_id":"BTC-USD","sequence":180758881,"time":"2020-06-30T19:22:00.735096Z"}
{"type":"l2update","product_id":"BTC-USD","changes":[["sell","9444.28","0.00802392"]],"time":"2020-06-30T19:22:00.874705Z"}
{"type":"l2update","product_id":"BTC-USD","changes":[["sell","9120.82","2807.42380000"]],"time":"2020-06-30T19:22:01.019268Z"}
{"type":"l2update","product_id":"BTC-USD","changes":[["sell","9181.81","0.00000000"]],"time":"2020-06-30T19:22:01.174609Z"}
{"type":"l2update","product_id":"BTC-USD","changes":[["sell","9186.68","0.00000000"]],"time":"2020-06-30T19:22:01.180414Z"}
{"type":"l2update","product_id":"BTC-USD","changes":[["buy","9033.37","0.00000000"]],"time":"2020-06-30T19:22:01.479041Z"}
{"type":"l2update","product_id":"BTC-USD","changes":[["buy","9095.97","0.00000000"]],"time":"2020-06-30T19:22:01.537334Z"}
{"type":"heartbeat","last_trade_id":0,"product_id":"BTC-USD","sequence":180758890,"time":"2020-06-30T19:22:01.735118Z"}
{"type":"l2update","product_id":"BTC-USD","changes":[["sell","9120.82","2806.61330000"]],"time":"2020-06-30T19:22:01.752973Z"}
{"type":"l2update","product_id":"BTC-USD","changes":[["buy","9097.11","0.07360000"]],"time":"2020-06-30T19:22:01.756248Z"}
{"type":"l2update","product_id":"BTC-USD","changes":[["buy","9103.13","0.54490000"]],"time":"2020-06-30T19:22:02.058319Z"}
{"type":"l2update","product_id":"BTC-USD","changes":[["buy","9089.83","0.01050000"]],"time":"2020-06-30T19:22:02.403137Z"}
{"type":"heartbeat","last_trade_id":0,"product_id":"BTC-USD","sequence":180758899,"time":"2020-06-30T19:22:02.734993Z"}
{"type":"l2update","product_id":"BTC-USD","changes":[["buy","9097.65","0.01050000"]],"time":"2020-06-30T19:22:02.962789Z"}
{"type":"heartbeat","last_trade_id":0,"product_id":"BTC-USD","sequence":180758901,"time":"2020-06-30T19:22:03.735134Z"}
{"type":"l2update","product_id":"BTC-USD","changes":[["sell","9135.57","4.49790000"]],"time":"2020-06-30T19:22:03.812154Z"}
{"type":"l2update","product_id":"BTC-USD","changes":[["sell","9186.03","0.01490000"]],"time":"2020-06-30T19:22:04.094151Z"}
{"type":"l2update","product_id":"BTC-USD","changes":[["sell","9183.75","0.00000000"]],"time":"2020-06-30T19:22:04.262244Z"}
{"type":"heartbeat","last_trade_id":0,"product_id":"BTC-USD","sequence":180758906,"time":"2020-06-30T19:22:04.735058Z"}
{"type":"l2update","product_id":"BTC-USD","changes":[["buy","9087.07","0.03900000"]],"time":"2020-06-30T19:22:05.579283Z"}
{"type":"heartbeat","last_trade_id":0,"product_id":"BTC-USD","sequence":180758908,"time":"2020-06-30T19:22:05.735096Z"}
{"type":"l2update","product_id":"BTC-USD","changes":[["buy","9094.47","0.00000000"]],"time":"2020-06-30T19:22:06.010251Z"}
{"type":"l2update","product_id":"BTC-USD","changes":[["buy","8938.19","0.00100000"]],"time":"2020-06-30T19:22:06.397338Z"}
{"type":"l2update","product_id":"BTC-USD","changes":[["sell","9120.82","2806.01290000"]],"time":"2020-06-30T19:22:06.727439Z"}
{"type":"heartbeat","last_trade_id":0,"product_id":"BTC-USD","sequence":180758914,"time":"2020-06-30T19:22:06.735115Z"}
{"type":"l2update","product_id":"BTC-USD","changes":[["sell","9132.34","0.34310000"]],"time":"2020-06-30T19:22:06.986749Z"}
{"type":"l2update","product_id":"BTC-USD","changes":[["sell","9149.88","0.00000000"]],"time":"2020-06-30T19:22:07.196100Z"}
{"type":"l2update","product_id":"BTC-USD","changes":[["sell","9186.03","0.00000000"]],"time":"2020-06-30T19:22:07.207300Z"}
{"type":"l2update","product_id":"BTC-USD","changes":[["sell","9185.29","0.00000000"]],"time":"2020-06-30T19:22:07.210151Z"}
{"type":"l2update","product_id":"BTC-USD","changes":[["buy","9100.63","0.07360000"]],"time":"2020-06-30T19:22:07.589051Z"}
{"type":"heartbeat","last_trade_id":0,"product_id":"BTC-USD","sequence":180758921,"time":"2020-06-30T19:22:07.735112Z"}
{"type":"l2update","product_id":"BTC-USD","changes":[["buy","9120.34","0.02220000"]],"time":"2020-06-30T19:22:07.852347Z"}
{"type":"l2update","product_id":"BTC-USD","changes":[["sell","9120.82","2805.99070000"]],"time":"2020-06-30T19:22:08.420161Z"}
{"type":"heartbeat","last_trade_id":0,"product_id":"BTC-USD","sequence":180758926,"time":"2020-06-30T19:22:08.735118Z"}
{"type":"l2update","product_id":"BTC-USD","changes":[["buy","9120.53","0.01070000"]],"time":"2020-06-30T19:22:08.972711Z"}
{"type":"l2update","product_id":"BTC-USD","changes":[["buy","8938.19","0.00000000"]],"time":"2020-06-30T19:22:09.211471Z"}
{"type":"heartbeat","last_trade_id":0,"product_id":"BTC-USD","sequence":180758929,"time":"2020-06-30T19:22:09.735116Z"}
{"type":"l2update","product_id":"BTC-USD","changes":[["sell","9120.82","2805.92500000"]],"time":"2020-06-30T19:22:10.103903Z"}
{"type":"l2update","product_id":"BTC-USD","changes":[["buy","9097.11","0.00000000"]],"time":"2020-06-30T19:22:10.527614Z"}
{"type":"heartbeat","last_trade_id":0,"product_id":"BTC-USD","sequence":180758933,"time":"2020-06-30T19:22:10.735115Z"}
{"type":"l2update","product_id":"BTC-USD","changes":[["buy","9120.80","2715.99960000"]],"time":"2020-06-30T19:22:11.458554Z"}
{"type":"l2update","product_id":"BTC-USD","changes":[["sell","9149.88","0.10000000"]],"time":"2020-06-30T19:22:11.485299Z"}
{"type":"heartbeat","last_trade_id":0,"product_id":"BTC-USD","sequence":180758938,"time":"2020-06-30T19:22:11.735114Z"}
{"type":"l2update","product_id":"BTC-USD","changes":[["buy","9103.54","0.07830000"]],"time":"2020-06-30T19:22:11.830390Z"}
{"type":"l2update","product_id":"BTC-USD","changes":[["sell","9186.58","0.00000000"]],"time":"2020-06-30T19:22:11.992451Z"}
{"type":"l2update","product_id":"BTC-USD","changes":[["sell","9134.44","0.00000000"]],"time":"2020-06-30T19:22:11.994050Z"}
{"type":"l2update","product_id":"BTC-USD","changes":[["buy","9120.53","0.00000000"]],"time":"2020-06-30T19:22:12.260156Z"}
{"type":"l2update","product_id":"BTC-USD","changes":[["sell","9162.99","1.96070000"]],"time":"2020-06-30T19:22:12.421714Z"}
{"type":"heartbeat","last_trade_id":0,"product_id":"BTC-USD","sequence":180758945,"time":"2020-06-30T19:22:12.735120Z"}
{"type":"l2update","product_id":"BTC-USD","changes":[["buy","9102.31","0.02430000"]],"time":"2020-06-30T19:22:12.977337Z"}
{"type":"l2update","product_id":"BTC-USD","changes":[["sell","9185.31","0.02220000"]],"time":"2020-06-30T19:22:13.256986Z"}
{"type":"l2update","product_id":"BTC-USD","changes":[["buy","9089.83","0.00000000"]],"time":"2020-06-30T19:22:13.434116Z"}
{"type":"l2update","product_id":"BTC-USD","changes":[["sell","9134.04","0.00000000"]],"time":"2020-06-30T19:22:13.505031Z"}
{"type":"l2update","product_id":"BTC-USD","changes":[["sell","9135.57","0.00000000"]],"time":"2020-06-30T19:22:13.507242Z"}
{"type":"heartbeat","last_trade_id":0,"product_id":"BTC-USD","sequence":180758952,"time":"2020-06-30T19:22:13.735115Z"}
{"type":"l2update","product_id":"BTC-USD","changes":[["buy","100.00","114.95500000"]],"time":"2020-06-30T19:22:14.018774Z"}
{"type":"l2update","product_id":"BTC-USD","changes":[["buy","100.00","114.94500000"]],"time":"2020-06-30T19:22:14.025313Z"}
{"type":"heartbeat","last_trade_id":0,"product_id":"BTC-USD","sequence":180758955,"time":"2020-06-30T19:22:14.735111Z"}
{"type":"l2update","product_id":"BTC-USD","changes":[["buy","9097.11","0.03890000"]],"time":"2020-06-30T19:22:15.384996Z"}
{"type":"heartbeat","last_trade_id":0,"product_id":"BTC-USD","sequence":180758957,"time":"2020-06-30T19:22:15.735065Z"}
{"type":"l2update","product_id":"BTC-USD","changes":[["sell","9154.62","1.06050000"]],"time":"2020-06-30T19:22:16.716781Z"}
{"type":"heartbeat","last_trade_id":0,"product_id":"BTC-USD","sequence":180758959,"time":"2020-06-30T19:22:16.735094Z"}
{"type":"l2update","product_id":"BTC-USD","changes":[["sell","9184.01","0.00000000"]],"time":"2020-06-30T19:22:17.146585Z"}
{"type":"heartbeat","last_trade_id":0,"product_id":"BTC-USD","sequence":180758960,"time":"2020-06-30T19:22:17.735118Z"}
{"type":"heartbeat","last_trade_id":0,"product_id":"BTC-USD","sequence":180758960,"time":"2020-06-30T19:22:18.735120Z"}
{"type":"l2update","product_id":"BTC-USD","changes":[["sell","9148.55","0.08270000"]],"time":"2020-06-30T19:22:19.638680Z"}
{"type":"heartbeat","last_trade_id":0,"product_id":"BTC-USD","sequence":180758962,"time":"2020-06-30T19:22:19.735028Z"}
{"type":"l2update","product_id":"BTC-USD","changes":[["sell","9120.82","2805.85930000"]],"time":"2020-06-30T19:22:19.919679Z"}
{"type":"l2update","product_id":"BTC-USD","changes":[["sell","9132.34","0.00000000"]],"time":"2020-06-30T19:22:20.076720Z"}
{"type":"l2update","product_id":"BTC-USD","changes":[["sell","9120.82","2805.82870000"]],"time":"2020-06-30T19:22:20.223217Z"}
{"type":"l2update","product_id":"BTC-USD","changes":[["buy","9103.13","0.00000000"]],"time":"2020-06-30T19:22:20.364406Z"}
{"type":"l2update","product_id":"BTC-USD","changes":[["buy","9097.65","0.00000000"]],"time":"2020-06-30T19:22:20.650835Z"}
{"type":"heartbeat","last_trade_id":0,"product_id":"BTC-USD","sequence":180758971,"time":"2020-06-30T19:22:20.735163Z"}
{"type":"l2update","product_id":"BTC-USD","changes":[["sell","9144.39","0.03250000"]],"time":"2020-06-30T19:22:21.099132Z"}
{"type":"l2update","product_id":"BTC-USD","changes":[["sell","9135.39","0.05000000"]],"time":"2020-06-30T19:22:21.387166Z"}
{"type":"l2update","product_id":"BTC-USD","changes":[["sell","9154.62","0.00000000"]],"time":"2020-06-30T19:22:21.550175Z"}
{"type":"l2update","product_id":"BTC-USD","changes":[["sell","9185.53","0.00000000"]],"time":"2020-06-30T19:22:21.554100Z"}
{"type":"l2update","product_id":"BTC-USD","changes":[["sell","9134.67","0.23290000"]],"time":"2020-06-30T19:22:21.643151Z"}
{"type":"heartbeat","last_trade_id":0,"product_id":"BTC-USD","sequence":180758979,"time":"2020-06-30T19:22:21.735117Z"}
{"type":"l2update","product_id":"BTC-USD","changes":[["sell","9149.88","0.00000000"]],"time":"2020-06-30T19:22:21.812434Z"}
{"type":"l2update","product_id":"BTC-USD","changes":[["sell","9162.99","0.00000000"]],"time":"2020-06-30T19:22:21.824462Z"}
{"type":"l2update","product_id":"BTC-USD","changes":[["sell","9148.55","0.00000000"]],"time":"2020-06-30T19:22:21.825480Z"}
{"type":"l2update","product_id":"BTC-USD","changes":[["sell","9120.82","2804.98450000"]],"time":"2020-06-30T19:22:21.920565Z"}
{"type":"l2update","product_id":"BTC-USD","changes":[["buy","9104.92","0.02300000"]],"time":"2020-06-30T19:22:22.197288Z"}
{"type":"l2update","product_id":"BTC-USD","changes":[["buy","9103.54","0.00000000"]],"time":"2020-06-30T19:22:22.339366Z"}
{"type":"l2update","product_id":"BTC-USD","changes":[["sell","9120.82","2804.91880000"]],"time":"2020-06-30T19:22:22.503747Z"}
{"type":"l2update","product_id":"BTC-USD","changes":[["buy","9120.34","0.00000000"]],"time":"2020-06-30T19:22:22.622765Z"}
{"type":"heartbeat","last_trade_id":0,"product_id":"BTC-USD","sequence":180758992,"time":"2020-06-30T19:22:22.735111Z"}
{"type":"l2update","product_id":"BTC-USD","changes":[["sell","9184.81","0.01000000"]],"time":"2020-06-30T19:22:22.783997Z"}
{"type":"l2update","product_id":"BTC-USD","changes":[["sell","9133.28","0.00000000"]],"time":"2020-06-30T19:22:23.198878Z"}
{"type":"l2update","product_id":"BTC-USD","changes":[["sell","9186.78","0.00000000"]],"time":"2020-06-30T19:22:23.201752Z"}
{"type":"l2update","product_id":"BTC-USD","changes":[["sell","9120.82","2804.88820000"]],"time":"2020-06-30T19:22:23.676016Z"}
{"type":"heartbeat","last_trade_id":0,"product_id":"BTC-USD","sequence":180758999,"time":"2020-06-30T19:22:23.735117Z"}
{"type":"l2update","product_id":"BTC-USD","changes":[["buy","9094.88","0.00000000"]],"time":"2020-06-30T19:22:24.114135Z"}
{"type":"l2update","product_id":"BTC-USD","changes":[["sell","9171.53","0.05450000"]],"time":"2020-06-30T19:22:24.246737Z"}
{"type":"l2update","product_id":"BTC-USD","changes":[["sell","9134.67","0.00000000"]],"time":"2020-06-30T19:22:24.730175Z"}
{"type":"l2update","product_id":"BTC-USD","changes":[["sell","9144.39","0.00000000"]],"time":"2020-06-30T19:22:24.730261Z"}
{"type":"heartbeat","last_trade_id":0,"product_id":"BTC-USD","sequence":180759004,"time":"2020-06-30T19:22:24.735117Z"}
{"type":"l2update","product_id":"BTC-USD","changes":[["sell","9120.82","2804.06900000"]],"time":"2020-06-30T19:22:24.809560Z"}
{"type":"l2update","product_id":"BTC-USD","changes":[["buy","9095.75","0.02300000"]],"time":"2020-06-30T19:22:25.410339Z"}
{"type":"heartbeat","last_trade_id":0,"product_id":"BTC-USD","sequence":180759009,"time":"2020-06-30T19:22:25.735111Z"}
{"type":"heartbeat","last_trade_id":0,"product_id":"BTC-USD","sequence":180759009,"time":"2020-06-30T19:22:26.735114Z"}
{"type":"l2update","product_id":"BTC-USD","changes":[["sell","9149.88","0.01090000"]],"time":"2020-06-30T19:22:27.060646Z"}
{"type":"l2update","product_id":"BTC-USD","changes":[["sell","9120.82","2804.00330000"]],"time":"2020-06-30T19:22:27.327422Z"}
{"type":"l2update","product_id":"BTC-USD","changes":[["sell","9183.76","0.00000000"]],"time":"2020-06-30T19:22:27.526550Z"}
{"type":"heartbeat","last_trade_id":0,"product_id":"BTC-USD","sequence":180759015,"time":"2020-06-30T19:22:27.735070Z"}
{"type":"l2update","product_id":"BTC-USD","changes":[["buy","9100.63","0.00000000"]],"time":"2020-06-30T19:22:27.750677Z"}
{"type":"l2update","product_id":"BTC-USD","changes":[["buy","9087.07","0.00000000"]],"time":"2020-06-30T19:22:27.763074Z"}
{"type":"l2update","product_id":"BTC-USD","changes":[["buy","9100.52","0.01050000"]],"time":"2020-06-30T19:22:27.877734Z"}
{"type":"l2update","product_id":"BTC-USD","changes":[["sell","9167.74","0.05450000"]],"time":"2020-06-30T19:22:28.161793Z"}
{"type":"l2update","product_id":"BTC-USD","changes":[["buy","9095.75","0.00000000"]],"time":"2020-06-30T19:22:28.305529Z"}
{"type":"heartbeat","last_trade_id":0,"product_id":"BTC-USD","sequence":180759022,"time":"2020-06-30T19:22:28.735093Z"}
{"type":"l2update","product_id":"BTC-USD","changes":[["sell","9120.82","2803.93760000"]],"time":"2020-06-30T19:22:28.782980Z"}
{"type":"l2update","product_id":"BTC-USD","changes":[["buy","100.00","114.95500000"]],"time":"2020-06-30T19:22:29.042643Z"}
{"type":"l2update","product_id":"BTC-USD","changes":[["buy","100.00","114.94500000"]],"time":"2020-06-30T19:22:29.049877Z"}
{"type":"l2update","product_id":"BTC-USD","changes":[["buy","9097.11","0.00000000"]],"time":"2020-06-30T19:22:29.199495Z"}
{"type":"l2update","product_id":"BTC-USD","changes":[["sell","9384.60","0.00400000"]],"time":"2020-06-30T19:22:29.355723Z"}
{"type":"l2update","product_id":"BTC-USD","changes":[["sell","9184.81","0.00000000"]],"time":"2020-06-30T19:22:29.546195Z"}
{"type":"l2update","product_id":"BTC-USD","changes":[["sell","9167.05","0.01670000"]],"time":"2020-06-30T19:22:29.630766Z"}
{"type":"heartbeat","last_trade_id":0,"product_id":"BTC-USD","sequence":180759034,"time":"2020-06-30T19:22:29.735115Z"}
{"type":"heartbeat","last_trade_id":0,"product_id":"BTC-USD","sequence":180759034,"time":"2020-06-30T19:22:30.735114Z"}
{"type":"l2update","product_id":"BTC-USD","changes":[["sell","9135.33","0.05000000"]],"time":"2020-06-30T19:22:31.153956Z"}
{"type":"l2update","product_id":"BTC-USD","changes":[["sell","9135.24","0.01650000"]],"time":"2020-06-30T19:22:31.427213Z"}
{"type":"l2update","product_id":"BTC-USD","changes":[["sell","9171.53","0.00000000"]],"time":"2020-06-30T19:22:31.590215Z"}
{"type":"l2update","product_id":"BTC-USD","changes":[["sell","9135.53","1.50000000"]],"time":"2020-06-30T19:22:31.705336Z"}
{"type":"heartbeat","last_trade_id":0,"product_id":"BTC-USD","sequence":180759041,"time":"2020-06-30T19:22:31.735060Z"}
{"type":"l2update","product_id":"BTC-USD","changes":[["sell","9149.88","0.00000000"]],"time":"2020-06-30T19:22:31.873511Z"}
{"type":"heartbeat","last_trade_id":0,"product_id":"BTC-USD","sequence":180759042,"time":"2020-06-30T19:22:32.735120Z"}
{"type":"l2update","product_id":"BTC-USD","changes":[["sell","9142.18","0.02360000"]],"time":"2020-06-30T19:22:33.066173Z"}
{"type":"l2update","product_id":"BTC-USD","changes":[["sell","9135.53","0.00000000"]],"time":"2020-06-30T19:22:33.518094Z"}
{"type":"heartbeat","last_trade_id":0,"product_id":"BTC-USD","sequence":180759045,"time":"2020-06-30T19:22:33.735100Z"}
{"type":"l2update","product_id":"BTC-USD","changes":[["sell","9135.56","0.12340000"]],"time":"2020-06-30T19:22:34.259208Z"}
{"type":"l2update","product_id":"BTC-USD","changes":[["sell","9135.56","0.18910000"]],"time":"2020-06-30T19:22:34.552815Z"}
{"type":"heartbeat","last_trade_id":0,"product_id":"BTC-USD","sequence":180759049,"time":"2020-06-30T19:22:34.735090Z"}
{"type":"l2update","product_id":"BTC-USD","changes":[["sell","9142.18","0.00000000"]],"time":"2020-06-30T19:22:35.017132Z"}
{"type":"l2update","product_id":"BTC-USD","changes":[["sell","9120.82","2803.87190000"]],"time":"2020-06-30T19:22:35.076182Z"}
{"type":"l2update","product_id":"BTC-USD","changes":[["buy","9096.69","0.07370000"]],"time":"2020-06-30T19:22:35.355650Z"}
{"type":"heartbeat","last_trade_id":0,"product_id":"BTC-USD","sequence":180759055,"time":"2020-06-30T19:22:35.735076Z"}
{"type":"l2update","product_id":"BTC-USD","changes":[["buy","9102.07","0.01050000"]],"time":"2020-06-30T19:22:36.186533Z"}
{"type":"heartbeat","last_trade_id":0,"product_id":"BTC-USD","sequence":180759057,"time":"2020-06-30T19:22:36.735051Z"}
{"type":"heartbeat","last_trade_id":0,"product_id":"BTC-USD","sequence":180759057,"time":"2020-06-30T19:22:37.735096Z"}
{"type":"heartbeat","last_trade_id":0,"product_id":"BTC-USD","sequence":180759057,"time":"2020-06-30T19:22:38.734954Z"}
{"type":"heartbeat","last_trade_id":0,"product_id":"BTC-USD","sequence":180759057,"time":"2020-06-30T19:22:39.747409Z"}
{"type":"l2update","product_id":"BTC-USD","changes":[["sell","9120.82","2803.05270000"]],"time":"2020-06-30T19:22:40.069272Z"}
{"type":"heartbeat","last_trade_id":0,"product_id":"BTC-USD","sequence":180759060,"time":"2020-06-30T19:22:40.735119Z"}
{"type":"l2update","product_id":"BTC-USD","changes":[["buy","8887.10","0.00000000"]],"time":"2020-06-30T19:22:40.953202Z"}
{"type":"l2update","product_id":"BTC-USD","changes":[["sell","9135.57","4.52290000"]],"time":"2020-06-30T19:22:41.164892Z"}
{"type":"l2update","product_id":"BTC-USD","changes":[["sell","9120.82","2803.05170000"]],"time":"2020-06-30T19:22:41.470347Z"}
{"type":"l2update","product_id":"BTC-USD","changes":[["buy","8908.03","0.04470836"]],"time":"2020-06-30T19:22:41.509684Z"}
{"type":"l2update","product_id":"BTC-USD","changes":[["sell","9120.82","2803.00170000"]],"time":"2020-06-30T19:22:41.588158Z"}
{"type":"heartbeat","last_trade_id":0,"product_id":"BTC-USD","sequence":180759071,"time":"2020-06-30T19:22:41.735119Z"}
{"type":"l2update","product_id":"BTC-USD","changes":[["sell","9444.28","0.00000000"]],"time":"2020-06-30T19:22:42.188160Z"}
{"type":"l2update","product_id":"BTC-USD","changes":[["sell","9120.82","2802.96170000"]],"time":"2020-06-30T19:22:42.229508Z"}
{"type":"l2update","product_id":"BTC-USD","changes":[["sell","9422.09","0.00549145"]],"time":"2020-06-30T19:22:42.563580Z"}
{"type":"heartbeat","last_trade_id":0,"product_id":"BTC-USD","sequence":180759077,"time":"2020-06-30T19:22:42.735111Z"}
{"type":"l2update","product_id":"BTC-USD","changes":[["sell","9120.89","0.00000000"]],"time":"2020-06-30T19:22:43.129151Z"}
{"type":"l2update","product_id":"BTC-USD","changes":[["sell","9120.88","0.00000000"]],"time":"2020-06-30T19:22:43.132685Z"}
{"type":"l2update","product_id":"BTC-USD","changes":[["sell","9120.87","0.00000000"]],"time":"2020-06-30T19:22:43.136225Z"}
{"type":"l2update","product_id":"BTC-USD","changes":[["sell","9120.86","0.00000000"]],"time":"2020-06-30T19:22:43.139749Z"}
{"type":"l2update","product_id":"BTC-USD","changes":[["sell","9120.85","0.00000000"]],"time":"2020-06-30T19:22:43.143247Z"}
{"type":"l2update","product_id":"BTC-USD","changes":[["sell","9120.84","0.00000000"]],"time":"2020-06-30T19:22:43.146832Z"}
{"type":"l2update","product_id":"BTC-USD","changes":[["sell","9120.83","0.00000000"]],"time":"2020-06-30T19:22:43.228785Z"}
{"type":"l2update","product_id":"BTC-USD","changes":[["sell","9120.82","0.00000000"]],"time":"2020-06-30T19:22:43.232559Z"}
{"type":"l2update","product_id":"BTC-USD","changes":[["buy","9120.73","0.00000000"]],"time":"2020-06-30T19:22:43.236369Z"}
{"type":"l2update","product_id":"BTC-USD","changes":[["buy","9120.74","0.00000000"]],"time":"2020-06-30T19:22:43.240398Z"}
{"type":"l2update","product_id":"BTC-USD","changes":[["buy","9120.75","0.00000000"]],"time":"2020-06-30T19:22:43.244083Z"}
{"type":"l2update","product_id":"BTC-USD","changes":[["buy","9120.76","0.00000000"]],"time":"2020-06-30T19:22:43.247688Z"}
{"type":"l2update","product_id":"BTC-USD","changes":[["buy","9120.77","0.00000000"]],"time":"2020-06-30T19:22:43.251275Z"}
{"type":"l2update","product_id":"BTC-USD","changes":[["buy","9120.78","0.00000000"]],"time":"2020-06-30T19:22:43.254886Z"}
{"type":"l2update","product_id":"BTC-USD","changes":[["buy","9120.79","0.00000000"]],"time":"2020-06-30T19:22:43.258728Z"}
{"type":"l2update","product_id":"BTC-USD","changes":[["buy","9120.80","0.00000000"]],"time":"2020-06-30T19:22:43.262361Z"}
{"type":"l2update","product_id":"BTC-USD","changes":[["sell","9126.36","0.00000000"]],"time":"2020-06-30T19:22:43.427049Z"}
{"type":"l2update","product_id":"BTC-USD","changes":[["sell","9134.93","0.00000000"]],"time":"2020-06-30T19:22:43.427049Z"}
{"type":"l2update","product_id":"BTC-USD","changes":[["sell","9135.24","0.00000000"]],"time":"2020-06-30T19:22:43.427049Z"}
{"type":"l2update","product_id":"BTC-USD","changes":[["sell","9135.33","0.00000000"]],"time":"2020-06-30T19:22:43.427049Z"}
{"type":"l2update","product_id":"BTC-USD","changes":[["sell","9135.39","0.00000000"]],"time":"2020-06-30T19:22:43.427049Z"}
{"type":"l2update","product_id":"BTC-USD","changes":[["sell","9135.56","0.12910000"]],"time":"2020-06-30T19:22:43.427049Z"}
{"type":"l2update","product_id":"BTC-USD","changes":[["buy","9134.75","3010.00000000"]],"time":"2020-06-30T19:22:43.622284Z"}
{"type":"l2update","product_id":"BTC-USD","changes":[["buy","9104.99","1.24450000"]],"time":"2020-06-30T19:22:43.692325Z"}
{"type":"heartbeat","last_trade_id":0,"product_id":"BTC-USD","sequence":180759110,"time":"2020-06-30T19:22:43.735072Z"}
{"type":"l2update","product_id":"BTC-USD","changes":[["buy","9134.74","4771.00000000"]],"time":"2020-06-30T19:22:43.828984Z"}
{"type":"l2update","product_id":"BTC-USD","changes":[["buy","9127.95","0.32870000"]],"time":"2020-06-30T19:22:43.988076Z"}
{"type":"l2update","product_id":"BTC-USD","changes":[["buy","100.00","114.95500000"]],"time":"2020-06-30T19:22:44.019551Z"}
{"type":"l2update","product_id":"BTC-USD","changes":[["buy","9134.73","6020.00000000"]],"time":"2020-06-30T19:22:44.022899Z"}
{"type":"l2update","product_id":"BTC-USD","changes":[["buy","100.00","114.94500000"]],"time":"2020-06-30T19:22:44.026612Z"}
{"type":"l2update","product_id":"BTC-USD","changes":[["buy","9102.31","0.00000000"]],"time":"2020-06-30T19:22:44.124032Z"}
{"type":"l2update","product_id":"BTC-USD","changes":[["buy","9134.72","6989.00000000"]],"time":"2020-06-30T19:22:44.236585Z"}
{"type":"l2update","product_id":"BTC-USD","changes":[["sell","9183.35","0.02220000"]],"time":"2020-06-30T19:22:44.268789Z"}
{"type":"l2update","product_id":"BTC-USD","changes":[["buy","9134.71","7781.00000000"]],"time":"2020-06-30T19:22:44.423511Z"}
{"type":"l2update","product_id":"BTC-USD","changes":[["buy","9104.83","0.00000000"]],"time":"2020-06-30T19:22:44.442450Z"}
{"type":"l2update","product_id":"BTC-USD","changes":[["buy","9134.70","8450.00000000"]],"time":"2020-06-30T19:22:44.622702Z"}
{"type":"l2update","product_id":"BTC-USD","changes":[["sell","9185.31","0.00000000"]],"time":"2020-06-30T19:22:44.714717Z"}
{"type":"heartbeat","last_trade_id":0,"product_id":"BTC-USD","sequence":180759130,"time":"2020-06-30T19:22:44.735100Z"}
{"type":"l2update","product_id":"BTC-USD","changes":[["sell","9183.30","0.02220000"]],"time":"2020-06-30T19:22:44.817247Z"}
{"type":"l2update","product_id":"BTC-USD","changes":[["buy","9134.69","9030.00000000"]],"time":"2020-06-30T19:22:44.820425Z"}
{"type":"l2update","product_id":"BTC-USD","changes":[["buy","9134.68","9542.00000000"]],"time":"2020-06-30T19:22:45.017967Z"}
{"type":"l2update","product_id":"BTC-USD","changes":[["sell","9134.77","3010.00000000"]],"time":"2020-06-30T19:22:45.221006Z"}
{"type":"l2update","product_id":"BTC-USD","changes":[["sell","9134.78","4771.00000000"]],"time":"2020-06-30T19:22:45.421656Z"}
{"type":"l2update","product_id":"BTC-USD","changes":[["sell","9134.79","6020.00000000"]],"time":"2020-06-30T19:22:45.621263Z"}
{"type":"heartbeat","last_trade_id":0,"product_id":"BTC-USD","sequence":180759142,"time":"2020-06-30T19:22:45.735119Z"}
{"type":"l2update","product_id":"BTC-USD","changes":[["sell","9134.80","6989.00000000"]],"time":"2020-06-30T19:22:45.818226Z"}
{"type":"l2update","product_id":"BTC-USD","changes":[["buy","9100.66","0.02300000"]],"time":"2020-06-30T19:22:45.982270Z"}
{"type":"l2update","product_id":"BTC-USD","changes":[["sell","9134.81","7781.00000000"]],"time":"2020-06-30T19:22:46.023582Z"}
{"type":"l2update","product_id":"BTC-USD","changes":[["sell","9134.82","8450.00000000"]],"time":"2020-06-30T19:22:46.217374Z"}
{"type":"l2update","product_id":"BTC-USD","changes":[["buy","9100.84","0.02300000"]],"time":"2020-06-30T19:22:46.257686Z"}
{"type":"l2update","product_id":"BTC-USD","changes":[["sell","9134.83","9030.00000000"]],"time":"2020-06-30T19:22:46.418007Z"}
{"type":"l2update","product_id":"BTC-USD","changes":[["sell","9134.84","9542.00000000"]],"time":"2020-06-30T19:22:46.651562Z"}
{"type":"heartbeat","last_trade_id":0,"product_id":"BTC-USD","sequence":180759156,"time":"2020-06-30T19:22:46.735130Z"}
{"type":"l2update","product_id":"BTC-USD","changes":[["buy","9103.91","0.02300000"]],"time":"2020-06-30T19:22:47.385863Z"}
{"type":"heartbeat","last_trade_id":0,"product_id":"BTC-USD","sequence":180759158,"time":"2020-06-30T19:22:47.735120Z"}
{"type":"l2update","product_id":"BTC-USD","changes":[["buy","9100.52","0.00000000"]],"time":"2020-06-30T19:22:47.801313Z"}
{"type":"l2update","product_id":"BTC-USD","changes":[["buy","9104.99","0.00000000"]],"time":"2020-06-30T19:22:47.813868Z"}
{"type":"heartbeat","last_trade_id":0,"product_id":"BTC-USD","sequence":180759160,"time":"2020-06-30T19:22:48.735117Z"}
{"type":"l2update","product_id":"BTC-USD","changes":[["sell","9183.05","0.02220000"]],"time":"2020-06-30T19:22:49.356216Z"}
{"type":"l2update","product_id":"BTC-USD","changes":[["sell","9134.77","3009.95000000"]],"time":"2020-06-30T19:22:49.643840Z"}
{"type":"heartbeat","last_trade_id":0,"product_id":"BTC-USD","sequence":180759165,"time":"2020-06-30T19:22:49.735117Z"}
{"type":"l2update","product_id":"BTC-USD","changes":[["sell","9135.56","0.06570000"]],"time":"2020-06-30T19:22:49.791414Z"}
{"type":"l2update","product_id":"BTC-USD","changes":[["sell","9384.60","0.00000000"]],"time":"2020-06-30T19:22:49.794199Z"}
{"type":"l2update","product_id":"BTC-USD","changes":[["sell","9183.35","0.00000000"]],"time":"2020-06-30T19:22:49.794961Z"}
{"type":"l2update","product_id":"BTC-USD","changes":[["buy","9096.69","0.00000000"]],"time":"2020-06-30T19:22:50.064303Z"}
{"type":"heartbeat","last_trade_id":0,"product_id":"BTC-USD","sequence":180759169,"time":"2020-06-30T19:22:50.735113Z"}
{"type":"l2update","product_id":"BTC-USD","changes":[["sell","9134.77","3009.90000000"]],"time":"2020-06-30T19:22:51.653070Z"}
{"type":"heartbeat","last_trade_id":0,"product_id":"BTC-USD","sequence":180759172,"time":"2020-06-30T19:22:51.735123Z"}
{"type":"l2update","product_id":"BTC-USD","changes":[["buy","9134.73","6025.21870000"]],"time":"2020-06-30T19:22:51.934114Z"}
{"type":"l2update","product_id":"BTC-USD","changes":[["buy","9103.91","0.00000000"]],"time":"2020-06-30T19:22:52.085224Z"}
{"type":"l2update","product_id":"BTC-USD","changes":[["buy","9127.95","0.00000000"]],"time":"2020-06-30T19:22:52.150525Z"}
{"type":"l2update","product_id":"BTC-USD","changes":[["buy","9107.60","2.60000000"]],"time":"2020-06-30T19:22:52.310110Z"}
{"type":"l2update","product_id":"BTC-USD","changes":[["buy","9127.87","0.02220000"]],"time":"2020-06-30T19:22:52.574570Z"}
{"type":"heartbeat","last_trade_id":0,"product_id":"BTC-USD","sequence":180759180,"time":"2020-06-30T19:22:52.735116Z"}
{"type":"l2update","product_id":"BTC-USD","changes":[["sell","9134.77","3009.85000000"]],"time":"2020-06-30T19:22:53.134778Z"}
{"type":"l2update","product_id":"BTC-USD","changes":[["buy","9100.66","0.00000000"]],"time":"2020-06-30T19:22:53.554326Z"}
{"type":"heartbeat","last_trade_id":0,"product_id":"BTC-USD","sequence":180759184,"time":"2020-06-30T19:22:53.735116Z"}
{"type":"l2update","product_id":"BTC-USD","changes":[["buy","9127.81","0.02220000"]],"time":"2020-06-30T19:22:53.953399Z"}
{"type":"heartbeat","last_trade_id":0,"product_id":"BTC-USD","sequence":180759186,"time":"2020-06-30T19:22:54.735093Z"}
{"type":"l2update","product_id":"BTC-USD","changes":[["buy","9127.83","0.06570000"]],"time":"2020-06-30T19:22:55.659177Z"}
{"type":"heartbeat","last_trade_id":0,"product_id":"BTC-USD","sequence":180759188,"time":"2020-06-30T19:22:55.735091Z"}
{"type":"l2update","product_id":"BTC-USD","changes":[["sell","9136.40","0.04000000"]],"time":"2020-06-30T19:22:55.951118Z"}
{"type":"l2update","product_id":"BTC-USD","changes":[["sell","9136.40","4.09790000"]],"time":"2020-06-30T19:22:56.544450Z"}
{"type":"heartbeat","last_trade_id":0,"product_id":"BTC-USD","sequence":180759192,"time":"2020-06-30T19:22:56.735112Z"}
{"type":"l2update","product_id":"BTC-USD","changes":[["sell","9186.34","0.00000000"]],"time":"2020-06-30T19:22:56.992130Z"}
{"type":"l2update","product_id":"BTC-USD","changes":[["buy","9132.33","2.90000000"]],"time":"2020-06-30T19:22:57.092040Z"}
{"type":"l2update","product_id":"BTC-USD","changes":[["buy","9104.92","0.00000000"]],"time":"2020-06-30T19:22:57.515479Z"}
{"type":"heartbeat","last_trade_id":0,"product_id":"BTC-USD","sequence":180759196,"time":"2020-06-30T19:22:57.735111Z"}
{"type":"l2update","product_id":"BTC-USD","changes":[["buy","9113.11","0.04460000"]],"time":"2020-06-30T19:22:58.300571Z"}
{"type":"l2update","product_id":"BTC-USD","changes":[["sell","9182.46","0.02220000"]],"time":"2020-06-30T19:22:58.569203Z"}
{"type":"heartbeat","last_trade_id":0,"product_id":"BTC-USD","sequence":180759200,"time":"2020-06-30T19:22:58.735113Z"}
{"type":"l2update","product_id":"BTC-USD","changes":[["sell","9135.57","0.00000000"]],"time":"2020-06-30T19:22:58.848013Z"}
{"type":"l2update","product_id":"BTC-USD","changes":[["buy","9113.11","0.00000000"]],"time":"2020-06-30T19:22:58.858838Z"}
{"type":"l2update","product_id":"BTC-USD","changes":[["buy","9131.86","0.82070000"]],"time":"2020-06-30T19:22:58.873114Z"}
{"type":"l2update","product_id":"BTC-USD","changes":[["buy","9127.87","0.00000000"]],"time":"2020-06-30T19:22:58.881364Z"}
{"type":"l2update","product_id":"BTC-USD","changes":[["buy","100.00","114.95500000"]],"time":"2020-06-30T19:22:59.015479Z"}
{"type":"l2update","product_id":"BTC-USD","changes":[["buy","100.00","114.94500000"]],"time":"2020-06-30T19:22:59.025181Z"}
{"type":"heartbeat","last_trade_id":0,"product_id":"BTC-USD","sequence":180759208,"time":"2020-06-30T19:22:59.735116Z"}
{"type":"l2update","product_id":"BTC-USD","changes":[["buy","9129.71","0.02220000"]],"time":"2020-06-30T19:23:00.576994Z"}
{"type":"heartbeat","last_trade_id":0,"product_id":"BTC-USD","sequence":180759210,"time":"2020-06-30T19:23:00.735110Z"}
{"type":"l2update","product_id":"BTC-USD","changes":[["buy","9128.07","0.09620000"]],"time":"2020-06-30T19:23:01.209497Z"}
{"type":"l2update","product_id":"BTC-USD","changes":[["buy","9128.09","0.06570000"]],"time":"2020-06-30T19:23:01.547280Z"}
{"type":"l2update","product_id":"BTC-USD","changes":[["buy","9100.84","0.00000000"]],"time":"2020-06-30T19:23:01.711137Z"}
{"type":"heartbeat","last_trade_id":0,"product_id":"BTC-USD","sequence":180759215,"time":"2020-06-30T19:23:01.735116Z"}
{"type":"l2update","product_id":"BTC-USD","changes":[["buy","9107.60","0.00000000"]],"time":"2020-06-30T19:23:01.806960Z"}
{"type":"l2update","product_id":"BTC-USD","changes":[["buy","9124.53","0.02220000"]],"time":"2020-06-30T19:23:02.094907Z"}
{"type":"l2update","product_id":"BTC-USD","changes":[["sell","9138.83","4.00000000"]],"time":"2020-06-30T19:23:02.294498Z"}
{"type":"l2update","product_id":"BTC-USD","changes":[["sell","9138.83","0.00000000"]],"time":"2020-06-30T19:23:02.658036Z"}
{"type":"heartbeat","last_trade_id":0,"product_id":"BTC-USD","sequence":180759221,"time":"2020-06-30T19:23:02.735115Z"}
{"type":"l2update","product_id":"BTC-USD","changes":[["sell","9134.77","3009.10000000"]],"time":"2020-06-30T19:23:03.463219Z"}
{"type":"heartbeat","last_trade_id":0,"product_id":"BTC-USD","sequence":180759224,"time":"2020-06-30T19:23:03.735116Z"}
{"type":"l2update","product_id":"BTC-USD","changes":[["buy","9131.49","0.04000000"]],"time":"2020-06-30T19:23:03.828693Z"}
{"type":"l2update","product_id":"BTC-USD","changes":[["buy","9132.33","0.00000000"]],"time":"2020-06-30T19:23:03.940010Z"}
{"type":"l2update","product_id":"BTC-USD","changes":[["buy","9128.07","0.00000000"]],"time":"2020-06-30T19:23:03.952232Z"}
{"type":"l2update","product_id":"BTC-USD","changes":[["sell","9134.77","3009.05000000"]],"time":"2020-06-30T19:23:04.096535Z"}
{"type":"l2update","product_id":"BTC-USD","changes":[["buy","9124.53","0.00000000"]],"time":"2020-06-30T19:23:04.284484Z"}
{"type":"heartbeat","last_trade_id":0,"product_id":"BTC-USD","sequence":180759232,"time":"2020-06-30T19:23:04.735115Z"}
{"type":"l2update","product_id":"BTC-USD","changes":[["buy","9134.73","6020.00000000"]],"time":"2020-06-30T19:23:04.884908Z"}
{"type":"l2update","product_id":"BTC-USD","changes":[["buy","9127.79","0.03060000"]],"time":"2020-06-30T19:23:05.240311Z"}
{"type":"heartbeat","last_trade_id":0,"product_id":"BTC-USD","sequence":180759235,"time":"2020-06-30T19:23:05.735109Z"}
{"type":"l2update","product_id":"BTC-USD","changes":[["sell","9163.75","1.23680000"]],"time":"2020-06-30T19:23:06.089999Z"}
{"type":"l2update","product_id":"BTC-USD","changes":[["sell","9134.77","3006.05000000"]],"time":"2020-06-30T19:23:06.408820Z"}
{"type":"l2update","product_id":"BTC-USD","changes":[["sell","9167.74","0.00000000"]],"time":"2020-06-30T19:23:06.536265Z"}
{"type":"l2update","product_id":"BTC-USD","changes":[["sell","9135.56","0.00000000"]],"time":"2020-06-30T19:23:06.536998Z"}
{"type":"l2update","product_id":"BTC-USD","changes":[["sell","9136.40","0.04000000"]],"time":"2020-06-30T19:23:06.550645Z"}
