[270, {"a": [["11683.60000", "0.33817624", "1596666863.491235"]], "c": "1486522579"}, "book-100", "XBT/USD"]
[270, {"a": [["11706.90000", "1.95751842", "1596666863.494238"]], "c": "1486522579"}, "book-100", "XBT/USD"]
[270, {"a": [["11676.20000", "0.00000000", "1596666863.527840"], ["11721.70000", "2.47549182", "1596666772.357495", "r"]], "c": "1486522579"}, "book-100", "XBT/USD"]
[270, {"a": [["11689.40000", "1.41963548", "1596666863.528017"]], "c": "1486522579"}, "book-100", "XBT/USD"]
[270, {"b": [["11666.50000", "0.00000000", "1596666863.542869"], ["11616.00000", "0.17085000", "1596666842.228991", "r"]], "c": "1486522579"}, "book-100", "XBT/USD"]
[270, {"b": [["11660.90000", "0.00000000", "1596666863.733365"], ["11615.60000", "0.20000000", "1596666623.308321", "r"]], "c": "1486522579"}, "book-100", "XBT/USD"]
[270, {"a": [["11677.70000", "0.64965000", "1596666863.797332"]], "c": "1486522579"}, "book-100", "XBT/USD"]
[270, {"a": [["11675.50000", "0.25000000", "1596666863.921329"]], "c": "4273494910"}, "book-100", "XBT/USD"]
[270, {"b": [["11671.50000", "1.27199594", "1596666863.921520"]], "c": "4198346198"}, "book-100", "XBT/USD"]
[270, {"b": [["11666.50000", "9.99987003", "1596666863.980793"]], "c": "4198346198"}, "book-100", "XBT/USD"]
[270, {"b": [["11666.50000", "0.00000000", "1596666864.111164"], ["11615.60000", "0.20000000", "1596666623.308321", "r"]], "c": "4198346198"}, "book-100", "XBT/USD"]
[270, {"a": [["11675.90000", "0.00000000", "1596666864.151118"], ["11720.80000", "0.75800000", "1596666850.512768", "r"]], "c": "3377714266"}, "book-100", "XBT/USD"]
[270, {"a": [["11676.50000", "0.85669337", "1596666864.212091"]], "c": "3377714266"}, "book-100", "XBT/USD"]
[270, {"b": [["11668.90000", "1.14250258", "1596666864.212213"]], "c": "4127786792"}, "book-100", "XBT/USD"]
[271, [["11671.50000", "0.02188534", "1596666864.214616", "s", "l", ""]], "trade", "XBT/USD"]
[270, {"b": [["11671.50000", "1.25011060", "1596666864.214616"]], "c": "2456968506"}, "book-100", "XBT/USD"]
[270, {"a": [["11674.30000", "0.25825132", "1596666864.251554"]], "c": "2511656815"}, "book-100", "XBT/USD"]
[270, {"b": [["11671.50000", "1.08911060", "1596666864.346809"]], "c": "3992899580"}, "book-100", "XBT/USD"]
[270, {"a": [["11672.20000", "0.64252002", "1596666864.360127"]], "c": "3845044419"}, "book-100", "XBT/USD"]
[270, {"b": [["11666.50000", "9.99987003", "1596666864.382626"]], "c": "3845044419"}, "book-100", "XBT/USD"]
[270, {"b": [["11670.10000", "0.00000000", "1596666864.448012"], ["11615.60000", "0.20000000", "1596666623.308321", "r"]], "c": "1537087070"}, "book-100", "XBT/USD"]
[270, {"a": [["11695.60000", "0.00000000", "1596666864.470412"], ["11719.60000", "2.98021891", "1596666782.974175", "r"]], "c": "1537087070"}, "book-100", "XBT/USD"]
[270, {"a": [["11683.60000", "0.77717624", "1596666864.508907"]], "c": "1537087070"}, "book-100", "XBT/USD"]
[270, {"b": [["11669.00000", "0.25825335", "1596666864.551556"]], "c": "2591087108"}, "book-100", "XBT/USD"]
[270, {"a": [["11693.20000", "0.00000000", "1596666864.555697"], ["11719.70000", "3.50602221", "1596666789.365232", "r"]], "c": "2591087108"}, "book-100", "XBT/USD"]
[270, {"b": [["11662.30000", "0.87370000", "1596666864.634392"]], "c": "2591087108"}, "book-100", "XBT/USD"]
[270, {"a": [["11673.90000", "0.78050000", "1596666864.634496"]], "c": "2161461327"}, "book-100", "XBT/USD"]
[270, {"a": [["11676.20000", "1.70800000", "1596666864.759430"]], "c": "2161461327"}, "book-100", "XBT/USD"]
[270, {"a": [["11674.00000", "0.00000000", "1596666864.774134"], ["11719.60000", "2.98021891", "1596666782.974175", "r"]], "c": "1751771698"}, "book-100", "XBT/USD"]
[270, {"a": [["11673.80000", "0.02763280", "1596666864.775974"]], "c": "889442241"}, "book-100", "XBT/USD"]
[270, {"a": [["11707.00000", "0.02826783", "1596666864.801368"]], "c": "889442241"}, "book-100", "XBT/USD"]
[270, {"a": [["11687.00000", "7.96987627", "1596666864.861920"]], "c": "889442241"}, "book-100", "XBT/USD"]
[270, {"a": [["11689.30000", "0.72257220", "1596666864.862575"]], "c": "889442241"}, "book-100", "XBT/USD"]
[270, {"a": [["11695.10000", "1.20712886", "1596666864.865717"]], "c": "889442241"}, "book-100", "XBT/USD"]
[270, {"b": [["11642.40000", "8.61422305", "1596666864.866783"]], "c": "889442241"}, "book-100", "XBT/USD"]
[270, {"b": [["11659.80000", "0.72440035", "1596666864.869563"]], "c": "889442241"}, "book-100", "XBT/USD"]
[270, {"b": [["11662.10000", "0.10346535", "1596666864.871732"]], "c": "889442241"}, "book-100", "XBT/USD"]
[270, {"b": [["11654.00000", "1.21138603", "1596666864.872919"]], "c": "889442241"}, "book-100", "XBT/USD"]
[270, {"b": [["11625.10000", "0.00856780", "1596666864.899828"]], "c": "889442241"}, "book-100", "XBT/USD"]
[270, {"b": [["11624.00000", "8.74847055", "1596666864.905820"]], "c": "889442241"}, "book-100", "XBT/USD"]
[270, {"a": [["11692.80000", "0.74847055", "1596666864.910612"]], "c": "889442241"}, "book-100", "XBT/USD"]
[270, {"a": [["11691.90000", "0.00000000", "1596666864.916964"], ["11715.30000", "6.10000000", "1596666635.445451", "r"]], "c": "889442241"}, "book-100", "XBT/USD"]
[270, {"b": [["11668.00000", "1.80600000", "1596666865.101834"]], "c": "2242200574"}, "book-100", "XBT/USD"]
[270, {"a": [["11682.60000", "0.67355841", "1596666865.282415"]], "c": "2242200574"}, "book-100", "XBT/USD"]
[270, {"b": [["11641.20000", "0.00000000", "1596666865.313211"], ["11618.30000", "1.51500000", "1596666850.975183", "r"]], "c": "2242200574"}, "book-100", "XBT/USD"]
[270, {"b": [["11666.50000", "0.00000000", "1596666865.537196"], ["11617.50000", "2.49761864", "1596666811.445738", "r"]], "c": "2242200574"}, "book-100", "XBT/USD"]
[270, {"b": [["11671.50000", "0.72774583", "1596666865.782950"]], "c": "593529996"}, "book-100", "XBT/USD"]
[270, {"b": [["11668.00000", "1.70600000", "1596666865.904513"]], "c": "2139676915"}, "book-100", "XBT/USD"]
[270, {"b": [["11668.90000", "0.64250258", "1596666866.188593"]], "c": "3095234145"}, "book-100", "XBT/USD"]
[270, {"b": [["11670.10000", "0.10000000", "1596666866.221943"]], "c": "4163893054"}, "book-100", "XBT/USD"]
[270, {"a": [["11675.50000", "0.00000000", "1596666866.226289"], ["11715.30000", "6.10000000", "1596666635.445451", "r"]], "c": "4163893054"}, "book-100", "XBT/USD"]
[270, {"b": [["11666.70000", "0.22500000", "1596666866.261386"]], "c": "4163893054"}, "book-100", "XBT/USD"]
[270, {"b": [["11666.50000", "9.99987003", "1596666866.270924"]], "c": "4163893054"}, "book-100", "XBT/USD"]
[270, {"a": [["11674.40000", "0.00000000", "1596666866.312494"], ["11717.80000", "1.99812614", "1596666759.535617", "r"]], "c": "3170898637"}, "book-100", "XBT/USD"]
[270, {"b": [["11670.70000", "0.00000000", "1596666866.313284"], ["11618.30000", "1.51500000", "1596666850.975183", "r"]], "c": "610911764"}, "book-100", "XBT/USD"]
[270, {"a": [["11674.30000", "0.00000000", "1596666866.330542"], ["11718.00000", "0.17085000", "1596666865.758675", "r"]], "c": "2100610492"}, "book-100", "XBT/USD"]
[270, {"b": [["11666.80000", "0.50000000", "1596666866.345795"]], "c": "2100610492"}, "book-100", "XBT/USD"]
[270, {"b": [["11666.50000", "0.00000000", "1596666866.404156"], ["11618.30000", "1.51500000", "1596666850.975183", "r"]], "c": "2100610492"}, "book-100", "XBT/USD"]
[270, {"b": [["11666.20000", "16.22500000", "1596666866.419736"]], "c": "2100610492"}, "book-100", "XBT/USD"]
[270, {"b": [["11666.20000", "15.22500000", "1596666866.420259"]], "c": "2100610492"}, "book-100", "XBT/USD"]
[270, {"a": [["11674.10000", "1.07767866", "1596666866.429013"]], "c": "1970607186"}, "book-100", "XBT/USD"]
[270, {"a": [["11673.80000", "0.28589625", "1596666866.434474"]], "c": "1587460761"}, "book-100", "XBT/USD"]
[270, {"a": [["11671.60000", "0.96135951", "1596666866.440302"]], "c": "160312255"}, "book-100", "XBT/USD"]
[270, {"a": [["11674.10000", "0.25000000", "1596666866.467455"]], "c": "2192001292"}, "book-100", "XBT/USD"]
[270, {"b": [["11668.00000", "0.00000000", "1596666866.476835"], ["11617.50000", "2.49761864", "1596666811.445738", "r"]], "c": "2727094807"}, "book-100", "XBT/USD"]
[270, {"b": [["11660.70000", "2.27402124", "1596666866.534404"]], "c": "2727094807"}, "book-100", "XBT/USD"]
[270, {"a": [["11682.70000", "0.08250000", "1596666866.546014"]], "c": "2727094807"}, "book-100", "XBT/USD"]
[270, {"b": [["11658.90000", "1.22527000", "1596666866.548931"]], "c": "2727094807"}, "book-100", "XBT/USD"]
[270, {"a": [["11674.10000", "1.17527000", "1596666866.549882"]], "c": "1414845304"}, "book-100", "XBT/USD"]
[270, {"b": [["11667.70000", "0.00000000", "1596666866.551993"], ["11617.50000", "2.49761864", "1596666811.445738", "r"]], "c": "2776678412"}, "book-100", "XBT/USD"]
[270, {"a": [["11682.70000", "0.00000000", "1596666866.554602"], ["11718.40000", "0.48360000", "1596666846.374528", "r"]], "c": "2776678412"}, "book-100", "XBT/USD"]
[270, {"b": [["11662.30000", "0.00000000", "1596666866.554938"], ["11617.40000", "0.75800000", "1596666775.482846", "r"]], "c": "2776678412"}, "book-100", "XBT/USD"]
[270, {"b": [["11669.80000", "0.00000000", "1596666866.558838"], ["11616.00000", "0.17085000", "1596666842.228991", "r"]], "c": "2969242118"}, "book-100", "XBT/USD"]
[270, {"a": [["11687.00000", "7.11320841", "1596666866.561781"]], "c": "2969242118"}, "book-100", "XBT/USD"]
[270, {"b": [["11669.00000", "0.00000000", "1596666866.624702"], ["11615.60000", "0.20000000", "1596666623.308321", "r"]], "c": "2263670281"}, "book-100", "XBT/USD"]
[270, {"a": [["11671.60000", "1.60392435", "1596666866.634964"]], "c": "2969070550"}, "book-100", "XBT/USD"]
[270, {"b": [["11654.80000", "4.18491666", "1596666866.638361"]], "c": "2969070550"}, "book-100", "XBT/USD"]
[270, {"a": [["11673.90000", "0.00000000", "1596666866.639636"], ["11718.50000", "24.30000000", "1596666641.380470", "r"]], "c": "2361788259"}, "book-100", "XBT/USD"]
[270, {"b": [["11664.00000", "0.00000000", "1596666866.708230"], ["11614.80000", "3.08717099", "1596666746.879208", "r"]], "c": "2361788259"}, "book-100", "XBT/USD"]
[270, {"a": [["11672.30000", "0.81975491", "1596666866.719564"]], "c": "2340998559"}, "book-100", "XBT/USD"]
[270, {"b": [["11668.00000", "0.25827429", "1596666866.725297"]], "c": "510839399"}, "book-100", "XBT/USD"]
[270, {"b": [["11666.40000", "0.00000000", "1596666866.769775"], ["11614.80000", "3.08717099", "1596666746.879208", "r"]], "c": "510839399"}, "book-100", "XBT/USD"]
[270, {"b": [["11665.00000", "0.08250000", "1596666866.774704"]], "c": "510839399"}, "book-100", "XBT/USD"]
[270, {"a": [["11681.10000", "0.08250000", "1596666866.775162"]], "c": "510839399"}, "book-100", "XBT/USD"]
[270, {"a": [["11676.00000", "0.00000000", "1596666866.780157"], ["11718.40000", "0.48360000", "1596666846.374528", "r"]], "c": "2544655510"}, "book-100", "XBT/USD"]
[270, {"a": [["11672.10000", "0.78050000", "1596666866.804252"]], "c": "1555089370"}, "book-100", "XBT/USD"]
[270, {"a": [["11673.80000", "1.14270704", "1596666866.835519"]], "c": "1964407108"}, "book-100", "XBT/USD"]
[270, {"a": [["11673.80000", "1.11507424", "1596666866.962235"]], "c": "2907479893"}, "book-100", "XBT/USD"]
[270, {"a": [["11673.70000", "0.02763303", "1596666866.965075"]], "c": "2793562337"}, "book-100", "XBT/USD"]
[270, {"a": [["11680.30000", "2.85734812", "1596666866.971083"]], "c": "2793562337"}, "book-100", "XBT/USD"]
[270, {"b": [["11664.30000", "0.04250000", "1596666867.091972"]], "c": "2793562337"}, "book-100", "XBT/USD"]
[270, {"b": [["11656.70000", "0.43800000", "1596666867.096950"]], "c": "2793562337"}, "book-100", "XBT/USD"]
[270, {"b": [["11625.00000", "0.25000000", "1596666867.101148"]], "c": "2793562337"}, "book-100", "XBT/USD"]
[270, {"a": [["11677.60000", "0.15000000", "1596666867.104718"]], "c": "2793562337"}, "book-100", "XBT/USD"]
[271, [["11671.50000", "0.02332600", "1596666867.110662", "s", "l", ""]], "trade", "XBT/USD"]
[270, {"b": [["11671.50000", "0.70441983", "1596666867.110662"]], "c": "4236678225"}, "book-100", "XBT/USD"]
[270, {"b": [["11655.60000", "0.85675312", "1596666867.119450"]], "c": "4236678225"}, "book-100", "XBT/USD"]
[270, {"a": [["11678.30000", "1.50000000", "1596666867.123166"]], "c": "4236678225"}, "book-100", "XBT/USD"]
[270, {"a": [["11674.00000", "0.04250000", "1596666867.134928"]], "c": "2723291556"}, "book-100", "XBT/USD"]
[271, [["11671.50000", "0.01500000", "1596666867.182869", "s", "m", ""]], "trade", "XBT/USD"]
[270, {"b": [["11671.50000", "0.68941983", "1596666867.182869"]], "c": "2233957958"}, "book-100", "XBT/USD"]
[270, {"a": [["11671.60000", "3.35392435", "1596666867.244309"]], "c": "1971573398"}, "book-100", "XBT/USD"]
[270, {"a": [["11671.60000", "1.60392435", "1596666867.312652"]], "c": "2233957958"}, "book-100", "XBT/USD"]
[270, {"a": [["11674.10000", "0.92527000", "1596666867.329053"]], "c": "743218131"}, "book-100", "XBT/USD"]
[270, {"a": [["11677.40000", "0.15000000", "1596666867.403750"]], "c": "743218131"}, "book-100", "XBT/USD"]
[270, {"b": [["11654.10000", "0.38000000", "1596666867.463128"]], "c": "743218131"}, "book-100", "XBT/USD"]
[270, {"b": [["11658.00000", "0.00000000", "1596666867.464854"], ["11617.50000", "2.49761864", "1596666811.445738", "r"]], "c": "743218131"}, "book-100", "XBT/USD"]
[270, {"a": [["11685.60000", "6.39756039", "1596666867.474396"]], "c": "743218131"}, "book-100", "XBT/USD"]
[270, {"a": [["11710.30000", "2.24640816", "1596666867.529055"]], "c": "743218131"}, "book-100", "XBT/USD"]
[270, {"a": [["11688.30000", "0.00000000", "1596666867.531052"], ["11711.10000", "0.75800000", "1596666806.349295", "r"]], "c": "743218131"}, "book-100", "XBT/USD"]
[270, {"a": [["11695.60000", "0.00300000", "1596666867.549789"]], "c": "743218131"}, "book-100", "XBT/USD"]
[270, {"b": [["11667.50000", "0.00000000", "1596666867.552977"], ["11617.40000", "0.75800000", "1596666775.482846", "r"]], "c": "4115016065"}, "book-100", "XBT/USD"]
[270, {"a": [["11677.30000", "2.14487677", "1596666867.591060"]], "c": "4115016065"}, "book-100", "XBT/USD"]
[270, {"a": [["11673.60000", "0.25000000", "1596666867.609146"]], "c": "3970353214"}, "book-100", "XBT/USD"]
[270, {"a": [["11684.20000", "1.88760000", "1596666867.675614"]], "c": "3970353214"}, "book-100", "XBT/USD"]
[270, {"b": [["11634.60000", "0.00900000", "1596666867.710971"]], "c": "3970353214"}, "book-100", "XBT/USD"]
[270, {"b": [["11666.10000", "0.00000000", "1596666867.742846"], ["11617.40000", "0.75800000", "1596666775.482846", "r"]], "c": "3970353214"}, "book-100", "XBT/USD"]
[270, {"a": [["11677.20000", "0.15000000", "1596666867.868393"]], "c": "3970353214"}, "book-100", "XBT/USD"]
[270, {"b": [["11661.90000", "0.00000000", "1596666867.945926"], ["11616.00000", "0.17085000", "1596666842.228991", "r"]], "c": "3970353214"}, "book-100", "XBT/USD"]
[270, {"b": [["11643.70000", "0.00446617", "1596666867.949083"]], "c": "3970353214"}, "book-100", "XBT/USD"]
[270, {"a": [["11688.60000", "0.00438186", "1596666867.949945"]], "c": "3970353214"}, "book-100", "XBT/USD"]
[270, {"b": [["11622.20000", "0.36606647", "1596666868.116057"]], "c": "3970353214"}, "book-100", "XBT/USD"]
[270, {"b": [["11671.50000", "0.50274583", "1596666868.191393"]], "c": "1475967943"}, "book-100", "XBT/USD"]
[270, {"b": [["11643.70000", "0.00000000", "1596666868.212006"], ["11617.40000", "0.75800000", "1596666775.482846", "r"]], "c": "1475967943"}, "book-100", "XBT/USD"]
[270, {"b": [["11658.90000", "2.12573413", "1596666868.240726"]], "c": "1475967943"}, "book-100", "XBT/USD"]
[270, {"b": [["11670.10000", "0.31257000", "1596666868.252171"]], "c": "2068348357"}, "book-100", "XBT/USD"]
[270, {"b": [["11635.20000", "0.00000000", "1596666868.260636"], ["11616.00000", "0.17085000", "1596666842.228991", "r"]], "c": "2068348357"}, "book-100", "XBT/USD"]
[271, [["11671.50000", "0.00274583", "1596666868.327213", "s", "l", ""], ["11671.50000", "0.02058017", "1596666868.330041", "s", "l", ""]], "trade", "XBT/USD"]
[270, {"b": [["11671.50000", "0.50000000", "1596666868.327213"], ["11671.50000", "0.47941983", "1596666868.330041"]], "c": "806549926"}, "book-100", "XBT/USD"]
[270, {"a": [["11695.70000", "0.00000000", "1596666868.356963"], ["11710.30000", "2.24640816", "1596666867.529055", "r"]], "c": "806549926"}, "book-100", "XBT/USD"]
[270, {"b": [["11652.10000", "0.00000000", "1596666868.386966"], ["11615.60000", "0.20000000", "1596666623.308321", "r"]], "c": "806549926"}, "book-100", "XBT/USD"]
[270, {"a": [["11678.10000", "0.00000000", "1596666868.387051"], ["11710.40000", "1.16811308", "1596666772.597033", "r"]], "c": "806549926"}, "book-100", "XBT/USD"]
[270, {"a": [["11689.60000", "0.00000000", "1596666868.544626"], ["11710.60000", "2.80039129", "1596666770.582883", "r"]], "c": "806549926"}, "book-100", "XBT/USD"]
[270, {"a": [["11673.80000", "0.85681079", "1596666868.545704"]], "c": "1140985545"}, "book-100", "XBT/USD"]
[270, {"b": [["11640.40000", "2.06000000", "1596666868.558499"]], "c": "1140985545"}, "book-100", "XBT/USD"]
[270, {"b": [["11653.10000", "0.03100000", "1596666868.558739"]], "c": "1140985545"}, "book-100", "XBT/USD"]
[270, {"b": [["11631.70000", "6.05366049", "1596666868.559113"]], "c": "1140985545"}, "book-100", "XBT/USD"]
[270, {"a": [["11679.10000", "0.01000000", "1596666868.560618"]], "c": "1140985545"}, "book-100", "XBT/USD"]
[270, {"b": [["11627.30000", "0.00000000", "1596666868.587559"], ["11617.40000", "0.75800000", "1596666775.482846", "r"]], "c": "1140985545"}, "book-100", "XBT/USD"]
[270, {"b": [["11670.00000", "0.00000000", "1596666868.587795"], ["11616.00000", "0.17085000", "1596666842.228991", "r"]], "c": "3349358760"}, "book-100", "XBT/USD"]
[270, {"a": [["11673.50000", "0.25828153", "1596666868.602291"]], "c": "3075285936"}, "book-100", "XBT/USD"]
[270, {"a": [["11692.20000", "6.47414196", "1596666868.641739"]], "c": "3075285936"}, "book-100", "XBT/USD"]
[270, {"a": [["11691.10000", "0.00000000", "1596666868.660345"], ["11710.30000", "2.24640816", "1596666867.529055", "r"]], "c": "3075285936"}, "book-100", "XBT/USD"]
[270, {"b": [["11636.80000", "0.02875597", "1596666868.869460"]], "c": "3075285936"}, "book-100", "XBT/USD"]
[270, {"a": [["11682.60000", "0.00000000", "1596666868.912614"], ["11710.40000", "1.16811308", "1596666772.597033", "r"]], "c": "3075285936"}, "book-100", "XBT/USD"]
[270, {"a": [["11689.40000", "0.00000000", "1596666868.914681"], ["11710.60000", "2.80039129", "1596666770.582883", "r"]], "c": "3075285936"}, "book-100", "XBT/USD"]
[270, {"a": [["11683.60000", "0.43900000", "1596666868.915061"]], "c": "3075285936"}, "book-100", "XBT/USD"]
[270, {"b": [["11662.00000", "0.71148546", "1596666868.915288"]], "c": "3075285936"}, "book-100", "XBT/USD"]
[270, {"a": [["11677.20000", "0.00000000", "1596666868.915537"], ["11710.70000", "3.52183532", "1596666711.393054", "r"]], "c": "3075285936"}, "book-100", "XBT/USD"]
[270, {"a": [["11687.00000", "6.40324491", "1596666868.924248"]], "c": "3075285936"}, "book-100", "XBT/USD"]
[270, {"a": [["11679.10000", "0.00000000", "1596666868.967770"], ["11711.10000", "0.75800000", "1596666806.349295", "r"]], "c": "3075285936"}, "book-100", "XBT/USD"]
[270, {"b": [["11665.40000", "0.00000000", "1596666868.972128"], ["11616.00000", "0.17085000", "1596666842.228991", "r"]], "c": "3075285936"}, "book-100", "XBT/USD"]
[270, {"a": [["11676.80000", "0.15000000", "1596666868.995839"]], "c": "3075285936"}, "book-100", "XBT/USD"]
[270, {"a": [["11687.40000", "0.89826833", "1596666869.019874"]], "c": "3075285936"}, "book-100", "XBT/USD"]
[270, {"a": [["11677.90000", "0.01000000", "1596666869.020085"]], "c": "3075285936"}, "book-100", "XBT/USD"]
[270, {"a": [["11684.50000", "0.00000000", "1596666869.082598"], ["11710.60000", "2.80039129", "1596666770.582883", "r"]], "c": "3075285936"}, "book-100", "XBT/USD"]
[270, {"a": [["11679.80000", "0.49882932", "1596666869.096184"]], "c": "3075285936"}, "book-100", "XBT/USD"]
[270, {"a": [["11694.60000", "0.00000000", "1596666869.141510"], ["11710.60000", "2.80039129", "1596666770.582883", "r"]], "c": "3075285936"}, "book-100", "XBT/USD"]
[270, {"b": [["11667.30000", "1.69900000", "1596666869.142616"]], "c": "2205858340"}, "book-100", "XBT/USD"]
[270, {"a": [["11680.10000", "0.00000000", "1596666869.159940"], ["11710.70000", "3.52183532", "1596666711.393054", "r"]], "c": "2205858340"}, "book-100", "XBT/USD"]
[270, {"b": [["11658.90000", "1.20046413", "1596666869.161682"]], "c": "2205858340"}, "book-100", "XBT/USD"]
[270, {"a": [["11671.60000", "2.33773435", "1596666869.165609"]], "c": "3055394891"}, "book-100", "XBT/USD"]
[270, {"b": [["11642.30000", "0.00000000", "1596666869.173178"], ["11616.00000", "0.17085000", "1596666842.228991", "r"]], "c": "3055394891"}, "book-100", "XBT/USD"]
[270, {"b": [["11668.40000", "0.64259391", "1596666869.203273"]], "c": "2751880809"}, "book-100", "XBT/USD"]
[270, {"a": [["11693.40000", "8.86080403", "1596666869.475272"]], "c": "2751880809"}, "book-100", "XBT/USD"]
[270, {"a": [["11674.20000", "0.00000000", "1596666869.552065"], ["11711.10000", "0.75800000", "1596666806.349295", "r"]], "c": "2751880809"}, "book-100", "XBT/USD"]
[270, {"b": [["11662.00000", "0.00000000", "1596666869.611719"], ["11616.00000", "0.17085000", "1596666842.228991", "r"]], "c": "2751880809"}, "book-100", "XBT/USD"]
[270, {"b": [["11664.20000", "0.85676324", "1596666869.645793"]], "c": "2751880809"}, "book-100", "XBT/USD"]
[270, {"a": [["11677.90000", "0.00000000", "1596666869.674986"], ["11711.50000", "1.99898326", "1596666797.632161", "r"]], "c": "2751880809"}, "book-100", "XBT/USD"]
[270, {"b": [["11668.00000", "0.00000000", "1596666869.677305"], ["11615.60000", "0.20000000", "1596666623.308321", "r"]], "c": "4122140320"}, "book-100", "XBT/USD"]
[270, {"a": [["11673.00000", "4.27400000", "1596666869.754449"]], "c": "2793660597"}, "book-100", "XBT/USD"]
[270, {"a": [["11679.10000", "0.01000000", "1596666869.936649"]], "c": "2793660597"}, "book-100", "XBT/USD"]
[270, {"b": [["11662.60000", "1.50000000", "1596666869.989393"]], "c": "2793660597"}, "book-100", "XBT/USD"]
[270, {"a": [["11699.50000", "0.92500000", "1596666870.168882"]], "c": "2793660597"}, "book-100", "XBT/USD"]
[270, {"a": [["11681.60000", "0.11091640", "1596666870.192482"]], "c": "2793660597"}, "book-100", "XBT/USD"]
[270, {"b": [["11658.20000", "0.24966696", "1596666870.217236"]], "c": "2793660597"}, "book-100", "XBT/USD"]
[270, {"a": [["11675.00000", "0.11442094", "1596666870.233102"]], "c": "2793660597"}, "book-100", "XBT/USD"]
[270, {"a": [["11689.70000", "3.52825287", "1596666870.233202"]], "c": "2793660597"}, "book-100", "XBT/USD"]
[270, {"a": [["11677.30000", "2.04866583", "1596666870.244766"]], "c": "2793660597"}, "book-100", "XBT/USD"]
[270, {"a": [["11679.10000", "0.00000000", "1596666870.284019"], ["11710.40000", "1.16811308", "1596666772.597033", "r"]], "c": "2793660597"}, "book-100", "XBT/USD"]
[270, {"a": [["11677.90000", "0.01000000", "1596666870.338632"]], "c": "2793660597"}, "book-100", "XBT/USD"]
[270, {"b": [["11659.80000", "0.00000000", "1596666870.373276"], ["11616.00000", "0.17085000", "1596666842.228991", "r"]], "c": "2793660597"}, "book-100", "XBT/USD"]
[270, {"b": [["11658.60000", "0.00000000", "1596666870.379402"], ["11615.60000", "0.20000000", "1596666623.308321", "r"]], "c": "2793660597"}, "book-100", "XBT/USD"]
[270, {"b": [["11667.30000", "0.00000000", "1596666870.380285"], ["11614.80000", "3.08717099", "1596666746.879208", "r"]], "c": "919871482"}, "book-100", "XBT/USD"]
[270, {"b": [["11668.70000", "0.00000000", "1596666870.390591"], ["11613.60000", "3.55198121", "1596666780.634357", "r"]], "c": "4003551133"}, "book-100", "XBT/USD"]
[270, {"b": [["11666.40000", "0.09621094", "1596666870.391286"]], "c": "2609951156"}, "book-100", "XBT/USD"]
[270, {"b": [["11662.10000", "0.00000000", "1596666870.391471"], ["11613.60000", "3.55198121", "1596666780.634357", "r"]], "c": "2609951156"}, "book-100", "XBT/USD"]
[270, {"b": [["11668.50000", "0.25826785", "1596666870.391829"]], "c": "2037475617"}, "book-100", "XBT/USD"]
[270, {"b": [["11659.70000", "0.00000000", "1596666870.394465"], ["11613.60000", "3.55198121", "1596666780.634357", "r"]], "c": "2037475617"}, "book-100", "XBT/USD"]
[270, {"b": [["11659.40000", "0.00000000", "1596666870.405361"], ["11613.00000", "0.17085000", "1596666803.224745", "r"]], "c": "2037475617"}, "book-100", "XBT/USD"]
[270, {"b": [["11666.80000", "0.00000000", "1596666870.413308"], ["11612.30000", "7.00000000", "1596666617.080387", "r"]], "c": "850493505"}, "book-100", "XBT/USD"]
[270, {"a": [["11695.50000", "0.00000000", "1596666870.434898"], ["11710.40000", "1.16811308", "1596666772.597033", "r"]], "c": "850493505"}, "book-100", "XBT/USD"]
[270, {"a": [["11684.00000", "1.40940716", "1596666870.435595"]], "c": "850493505"}, "book-100", "XBT/USD"]
[270, {"b": [["11658.40000", "0.00000000", "1596666870.438312"], ["11611.90000", "1.06000000", "1596666780.430510", "r"]], "c": "850493505"}, "book-100", "XBT/USD"]
[270, {"b": [["11662.40000", "0.33879098", "1596666870.440232"]], "c": "850493505"}, "book-100", "XBT/USD"]
[270, {"a": [["11686.30000", "1.92001206", "1596666870.441590"]], "c": "850493505"}, "book-100", "XBT/USD"]
[270, {"a": [["11693.30000", "0.56545556", "1596666870.443521"]], "c": "850493505"}, "book-100", "XBT/USD"]
[270, {"b": [["11659.00000", "0.50000000", "1596666870.447070"]], "c": "850493505"}, "book-100", "XBT/USD"]
[270, {"a": [["11680.60000", "0.33826310", "1596666870.451298"]], "c": "850493505"}, "book-100", "XBT/USD"]
[270, {"b": [["11659.10000", "0.71166243", "1596666870.451369"]], "c": "850493505"}, "book-100", "XBT/USD"]
[271, [["11671.50000", "0.02332600", "1596666870.496494", "s", "l", ""]], "trade", "XBT/USD"]
[270, {"b": [["11671.50000", "0.45609383", "1596666870.496495"]], "c": "4071225403"}, "book-100", "XBT/USD"]
[270, {"b": [["11654.00000", "1.70940291", "1596666870.576392"]], "c": "4071225403"}, "book-100", "XBT/USD"]
[270, {"b": [["11656.70000", "1.86161791", "1596666870.607814"]], "c": "4071225403"}, "book-100", "XBT/USD"]
[270, {"b": [["11665.90000", "0.50000000", "1596666870.610863"]], "c": "4071225403"}, "book-100", "XBT/USD"]
[270, {"a": [["11690.60000", "0.49645773", "1596666870.656612"]], "c": "4071225403"}, "book-100", "XBT/USD"]
[270, {"a": [["11692.20000", "8.47680583", "1596666870.697873"]], "c": "4071225403"}, "book-100", "XBT/USD"]
[270, {"b": [["11659.00000", "0.60349286", "1596666870.701270"]], "c": "4071225403"}, "book-100", "XBT/USD"]
[270, {"b": [["11653.70000", "0.34966872", "1596666870.741722"]], "c": "4071225403"}, "book-100", "XBT/USD"]
[270, {"a": [["11690.90000", "0.89799940", "1596666870.763843"]], "c": "4071225403"}, "book-100", "XBT/USD"]
[270, {"a": [["11673.60000", "0.00000000", "1596666870.816297"], ["11710.10000", "0.89650546", "1596666771.484931", "r"]], "c": "2473043387"}, "book-100", "XBT/USD"]
[270, {"b": [["11665.90000", "0.00000000", "1596666870.821678"], ["11613.60000", "3.55198121", "1596666780.634357", "r"]], "c": "2473043387"}, "book-100", "XBT/USD"]
[270, {"b": [["11653.60000", "0.90087365", "1596666870.853782"]], "c": "2473043387"}, "book-100", "XBT/USD"]
[270, {"a": [["11677.90000", "0.00000000", "1596666870.869556"], ["11710.30000", "2.24640816", "1596666867.529055", "r"]], "c": "2473043387"}, "book-100", "XBT/USD"]
[270, {"b": [["11670.10000", "0.10000000", "1596666870.899260"]], "c": "3218514873"}, "book-100", "XBT/USD"]
[270, {"a": [["11676.80000", "0.00000000", "1596666870.903453"], ["11710.40000", "1.16811308", "1596666772.597033", "r"]], "c": "3218514873"}, "book-100", "XBT/USD"]
[270, {"a": [["11679.10000", "0.01000000", "1596666870.923988"]], "c": "3218514873"}, "book-100", "XBT/USD"]
[270, {"b": [["11671.50000", "0.00000000", "1596666870.941376"], ["11613.60000", "3.55198121", "1596666780.634357", "r"]], "c": "1634042425"}, "book-100", "XBT/USD"]
[270, {"a": [["11671.60000", "2.53914020", "1596666870.942359"]], "c": "792108527"}, "book-100", "XBT/USD"]
[270, {"b": [["11654.50000", "3.53857552", "1596666870.943082"]], "c": "792108527"}, "book-100", "XBT/USD"]
[270, {"a": [["11672.50000", "0.25000000", "1596666870.961930"]], "c": "73409212"}, "book-100", "XBT/USD"]
[270, {"b": [["11665.40000", "0.50000000", "1596666870.962647"]], "c": "73409212"}, "book-100", "XBT/USD"]
[270, {"a": [["11675.80000", "0.15000000", "1596666870.968309"]], "c": "73409212"}, "book-100", "XBT/USD"]
[270, {"a": [["11671.60000", "2.83773435", "1596666870.968591"]], "c": "2125407204"}, "book-100", "XBT/USD"]
[270, {"a": [["11681.00000", "8.20000000", "1596666870.971109"]], "c": "2125407204"}, "book-100", "XBT/USD"]
[270, {"b": [["11659.00000", "0.10349286", "1596666870.973254"]], "c": "2125407204"}, "book-100", "XBT/USD"]
[270, {"b": [["11649.60000", "0.50000000", "1596666870.982953"]], "c": "2125407204"}, "book-100", "XBT/USD"]
[270, {"b": [["11668.90000", "0.00000000", "1596666870.992372"], ["11615.60000", "0.20000000", "1596666623.308321", "r"]], "c": "856637719"}, "book-100", "XBT/USD"]
[270, {"b": [["11668.40000", "0.00000000", "1596666870.992751"], ["11614.80000", "3.08717099", "1596666746.879208", "r"]], "c": "3590800290"}, "book-100", "XBT/USD"]
[270, {"a": [["11671.60000", "2.63632850", "1596666870.999684"]], "c": "2131652058"}, "book-100", "XBT/USD"]
[270, {"a": [["11671.60000", "2.56132850", "1596666871.000008"]], "c": "2088324104"}, "book-100", "XBT/USD"]
[270, {"a": [["11670.20000", "0.50000000", "1596666871.001168"]], "c": "1831313154"}, "book-100", "XBT/USD"]
[270, {"a": [["11680.00000", "0.49627419", "1596666871.008368"]], "c": "1831313154"}, "book-100", "XBT/USD"]
[270, {"a": [["11679.90000", "0.21182219", "1596666871.016146"]], "c": "1831313154"}, "book-100", "XBT/USD"]
[270, {"a": [["11679.90000", "0.00000000", "1596666871.021100"], ["11709.70000", "7.20507863", "1596666814.449677", "r"]], "c": "1831313154"}, "book-100", "XBT/USD"]
[270, {"a": [["11671.60000", "2.26273435", "1596666871.021742"]], "c": "64147372"}, "book-100", "XBT/USD"]
[270, {"a": [["11680.00000", "0.00000000", "1596666871.023697"], ["11709.90000", "3.52186457", "1596666773.954225", "r"]], "c": "64147372"}, "book-100", "XBT/USD"]
[270, {"b": [["11666.30000", "0.00000000", "1596666871.024277"], ["11613.60000", "3.55198121", "1596666780.634357", "r"]], "c": "4117226658"}, "book-100", "XBT/USD"]
[270, {"b": [["11664.70000", "0.00000000", "1596666871.024578"], ["11613.00000", "0.17085000", "1596666803.224745", "r"]], "c": "4117226658"}, "book-100", "XBT/USD"]
[270, {"b": [["11667.60000", "0.00000000", "1596666871.024823"], ["11612.30000", "7.00000000", "1596666617.080387", "r"]], "c": "824571344"}, "book-100", "XBT/USD"]
[270, {"a": [["11672.70000", "0.00000000", "1596666871.026595"], ["11710.10000", "0.89650546", "1596666771.484931", "r"]], "c": "3604647170"}, "book-100", "XBT/USD"]
[270, {"a": [["11671.60000", "1.92773435", "1596666871.029578"]], "c": "3038641053"}, "book-100", "XBT/USD"]
[270, {"b": [["11669.40000", "0.20397000", "1596666871.037248"]], "c": "3850356374"}, "book-100", "XBT/USD"]
[270, {"a": [["11674.10000", "1.02627000", "1596666871.043603"]], "c": "3850356374"}, "book-100", "XBT/USD"]
[270, {"b": [["11657.40000", "3.23546850", "1596666871.050293"]], "c": "3850356374"}, "book-100", "XBT/USD"]
[270, {"a": [["11670.20000", "0.61890617", "1596666871.059869"]], "c": "2855166769"}, "book-100", "XBT/USD"]
[270, {"b": [["11651.30000", "0.00000000", "1596666871.064333"], ["11613.00000", "0.17085000", "1596666803.224745", "r"]], "c": "2855166769"}, "book-100", "XBT/USD"]
[270, {"a": [["11675.80000", "0.00000000", "1596666871.066596"], ["11710.30000", "2.24640816", "1596666867.529055", "r"]], "c": "2855166769"}, "book-100", "XBT/USD"]
[270, {"b": [["11645.80000", "0.98380000", "1596666871.067164"]], "c": "2855166769"}, "book-100", "XBT/USD"]
[270, {"a": [["11672.20000", "0.00000000", "1596666871.067531"], ["11710.40000", "1.16811308", "1596666772.597033", "r"]], "c": "1330398366"}, "book-100", "XBT/USD"]
[270, {"a": [["11673.50000", "0.00000000", "1596666871.069134"], ["11710.60000", "2.80039129", "1596666770.582883", "r"]], "c": "3292935075"}, "book-100", "XBT/USD"]
[270, {"a": [["11686.50000", "0.00000000", "1596666871.070711"], ["11710.70000", "3.52183532", "1596666711.393054", "r"]], "c": "3292935075"}, "book-100", "XBT/USD"]
[270, {"a": [["11679.10000", "0.00000000", "1596666871.074592"], ["11711.10000", "0.75800000", "1596666806.349295", "r"]], "c": "3292935075"}, "book-100", "XBT/USD"]
[270, {"b": [["11659.10000", "0.00000000", "1596666871.079585"], ["11613.00000", "0.17085000", "1596666803.224745", "r"]], "c": "3292935075"}, "book-100", "XBT/USD"]
[270, {"b": [["11662.40000", "0.00000000", "1596666871.080453"], ["11612.30000", "7.00000000", "1596666617.080387", "r"]], "c": "3292935075"}, "book-100", "XBT/USD"]
[270, {"b": [["11665.40000", "0.00000000", "1596666871.089449"], ["11611.90000", "1.06000000", "1596666780.430510", "r"]], "c": "685371538"}, "book-100", "XBT/USD"]
[270, {"b": [["11658.20000", "0.00000000", "1596666871.096480"], ["11610.00000", "0.17085000", "1596666865.604704", "r"]], "c": "685371538"}, "book-100", "XBT/USD"]
[270, {"b": [["11668.50000", "0.00000000", "1596666871.097191"], ["11609.80000", "21.20000000", "1596666704.766154", "r"]], "c": "3069444181"}, "book-100", "XBT/USD"]
[270, {"b": [["11658.90000", "0.30000000", "1596666871.102749"]], "c": "3069444181"}, "book-100", "XBT/USD"]
[270, {"a": [["11672.10000", "0.00000000", "1596666871.110306"], ["11711.50000", "1.99898326", "1596666797.632161", "r"]], "c": "1115481468"}, "book-100", "XBT/USD"]
[270, {"b": [["11655.80000", "0.00000000", "1596666871.116883"], ["11609.30000", "2.01627299", "1596666817.684177", "r"]], "c": "1115481468"}, "book-100", "XBT/USD"]
[270, {"b": [["11664.00000", "1.70500000", "1596666871.119885"]], "c": "1115481468"}, "book-100", "XBT/USD"]
[270, {"a": [["11677.90000", "0.01000000", "1596666871.124468"]], "c": "1115481468"}, "book-100", "XBT/USD"]
[270, {"a": [["11670.70000", "0.10300000", "1596666871.128983"]], "c": "5904694"}, "book-100", "XBT/USD"]
[270, {"b": [["11659.00000", "0.00000000", "1596666871.133092"], ["11609.30000", "2.01627299", "1596666817.684177", "r"]], "c": "5904694"}, "book-100", "XBT/USD"]
[270, {"a": [["11686.90000", "0.00000000", "1596666871.136670"], ["11711.10000", "0.75800000", "1596666806.349295", "r"]], "c": "5904694"}, "book-100", "XBT/USD"]
[270, {"b": [["11669.40000", "0.00000000", "1596666871.144380"], ["11607.70000", "8.40000000", "1596666861.504830", "r"]], "c": "2762201129"}, "book-100", "XBT/USD"]
[270, {"a": [["11673.50000", "0.15000000", "1596666871.145397"]], "c": "8200422"}, "book-100", "XBT/USD"]
[270, {"a": [["11672.20000", "1.70400000", "1596666871.147003"]], "c": "1637949101"}, "book-100", "XBT/USD"]
[270, {"a": [["11683.40000", "0.00000000", "1596666871.148354"], ["11710.70000", "3.52183532", "1596666711.393054", "r"]], "c": "1637949101"}, "book-100", "XBT/USD"]
[270, {"b": [["11656.20000", "0.00000000", "1596666871.155391"], ["11607.00000", "0.17085000", "1596666870.943401", "r"]], "c": "1637949101"}, "book-100", "XBT/USD"]
[270, {"a": [["11671.60000", "2.42773435", "1596666871.163770"]], "c": "1404008779"}, "book-100", "XBT/USD"]
[270, {"a": [["11671.50000", "0.25832347", "1596666871.167519"]], "c": "531974082"}, "book-100", "XBT/USD"]
[270, {"b": [["11667.90000", "0.00000000", "1596666871.180125"], ["11606.40000", "2.24640816", "1596666867.000402", "r"]], "c": "1053942620"}, "book-100", "XBT/USD"]
[270, {"b": [["11670.10000", "0.00000000", "1596666871.190752"], ["11602.70000", "0.01285176", "1596666867.951046", "r"]], "c": "1827054238"}, "book-100", "XBT/USD"]
[270, {"b": [["11654.00000", "0.49801688", "1596666871.195050"]], "c": "1827054238"}, "book-100", "XBT/USD"]
[270, {"b": [["11653.90000", "2.04666093", "1596666871.203186"]], "c": "1827054238"}, "book-100", "XBT/USD"]
[270, {"b": [["11660.70000", "0.00000000", "1596666871.208968"], ["11602.60000", "1.48021868", "1596666784.125874", "r"]], "c": "1827054238"}, "book-100", "XBT/USD"]
[270, {"b": [["11664.80000", "0.30000000", "1596666871.209711"]], "c": "97767539"}, "book-100", "XBT/USD"]
[270, {"b": [["11666.70000", "0.00000000", "1596666871.216280"], ["11602.20000", "6.32634371", "1596666815.593602", "r"]], "c": "3416352735"}, "book-100", "XBT/USD"]
[270, {"b": [["11653.90000", "0.24975908", "1596666871.222266"]], "c": "3416352735"}, "book-100", "XBT/USD"]
[270, {"a": [["11671.60000", "1.87637484", "1596666871.224633"]], "c": "4275908191"}, "book-100", "XBT/USD"]
[270, {"b": [["11656.70000", "0.43800000", "1596666871.228025"]], "c": "4275908191"}, "book-100", "XBT/USD"]
[270, {"a": [["11672.50000", "0.00000000", "1596666871.229111"], ["11710.70000", "3.52183532", "1596666711.393054", "r"]], "c": "3449104087"}, "book-100", "XBT/USD"]
[270, {"a": [["11671.60000", "1.37637484", "1596666871.229336"]], "c": "2179479492"}, "book-100", "XBT/USD"]
[270, {"a": [["11684.00000", "0.71014580", "1596666871.233737"]], "c": "2179479492"}, "book-100", "XBT/USD"]
[270, {"b": [["11662.50000", "0.00000000", "1596666871.244804"], ["11602.10000", "11.25550194", "1596666780.609892", "r"]], "c": "2179479492"}, "book-100", "XBT/USD"]
[270, {"a": [["11670.20000", "0.11890617", "1596666871.248150"]], "c": "1397992302"}, "book-100", "XBT/USD"]
[270, {"a": [["11670.20000", "0.00000000", "1596666871.249122"], ["11711.10000", "0.75800000", "1596666806.349295", "r"]], "c": "3176939821"}, "book-100", "XBT/USD"]
[270, {"a": [["11673.50000", "0.00000000", "1596666871.256272"], ["11711.50000", "1.99898326", "1596666797.632161", "r"]], "c": "1127534759"}, "book-100", "XBT/USD"]
[270, {"b": [["11661.80000", "0.50000000", "1596666871.256447"]], "c": "1127534759"}, "book-100", "XBT/USD"]
[270, {"a": [["11673.20000", "2.92349703", "1596666871.256881"]], "c": "3981338404"}, "book-100", "XBT/USD"]
[270, {"a": [["11682.80000", "0.00000000", "1596666871.258772"], ["11711.50000", "1.99898326", "1596666797.632161", "r"]], "c": "3981338404"}, "book-100", "XBT/USD"]
[270, {"a": [["11692.80000", "0.00000000", "1596666871.263097"], ["11712.00000", "0.17085000", "1596666871.114258", "r"]], "c": "3981338404"}, "book-100", "XBT/USD"]
[270, {"b": [["11624.00000", "8.00000000", "1596666871.264490"]], "c": "3981338404"}, "book-100", "XBT/USD"]
[270, {"a": [["11670.60000", "0.24000000", "1596666871.272362"]], "c": "3394947680"}, "book-100", "XBT/USD"]
[270, {"b": [["11664.00000", "0.00000000", "1596666871.272978"], ["11602.10000", "11.25550194", "1596666780.609892", "r"]], "c": "3181270995"}, "book-100", "XBT/USD"]
[270, {"a": [["11690.80000", "0.74849269", "1596666871.274807"]], "c": "3181270995"}, "book-100", "XBT/USD"]
[270, {"b": [["11622.70000", "0.74849269", "1596666871.276083"]], "c": "3181270995"}, "book-100", "XBT/USD"]
[270, {"a": [["11677.90000", "0.00000000", "1596666871.279081"], ["11711.50000", "1.99898326", "1596666797.632161", "r"]], "c": "3181270995"}, "book-100", "XBT/USD"]
[270, {"b": [["11653.10000", "0.00000000", "1596666871.279539"], ["11602.10000", "11.25550194", "1596666780.609892", "r"]], "c": "3181270995"}, "book-100", "XBT/USD"]
[270, {"a": [["11672.10000", "0.60250000", "1596666871.286105"]], "c": "4279054277"}, "book-100", "XBT/USD"]
[270, {"b": [["11662.60000", "0.00000000", "1596666871.288389"], ["11601.10000", "3.00166376", "1596666779.976375", "r"]], "c": "2535475953"}, "book-100", "XBT/USD"]
[270, {"b": [["11661.60000", "0.00000000", "1596666871.293541"], ["11600.50000", "3.54195852", "1596666820.729492", "r"]], "c": "3373137123"}, "book-100", "XBT/USD"]
[270, {"b": [["11664.30000", "0.00000000", "1596666871.295286"], ["11600.40000", "0.90458128", "1596666816.038277", "r"]], "c": "2094409101"}, "book-100", "XBT/USD"]
[270, {"a": [["11671.70000", "0.00000000", "1596666871.296264"], ["11711.50000", "1.99898326", "1596666797.632161", "r"]], "c": "1830631483"}, "book-100", "XBT/USD"]
[270, {"a": [["11677.40000", "0.84945852", "1596666871.301803"]], "c": "1830631483"}, "book-100", "XBT/USD"]
[270, {"a": [["11674.00000", "0.00000000", "1596666871.302837"], ["11712.00000", "0.17085000", "1596666871.114258", "r"]], "c": "1830631483"}, "book-100", "XBT/USD"]
[270, {"b": [["11661.70000", "0.85691535", "1596666871.303747"]], "c": "3469287144"}, "book-100", "XBT/USD"]
[270, {"a": [["11670.20000", "0.64271920", "1596666871.304360"]], "c": "2628599806"}, "book-100", "XBT/USD"]
[270, {"a": [["11670.90000", "0.64268651", "1596666871.308247"]], "c": "1199709586"}, "book-100", "XBT/USD"]
[270, {"a": [["11666.80000", "0.50000000", "1596666871.308535"]], "c": "3287076756"}, "book-100", "XBT/USD"]
[270, {"b": [["11652.10000", "0.85706932", "1596666871.310073"]], "c": "3287076756"}, "book-100", "XBT/USD"]
[270, {"b": [["11656.30000", "0.00000000", "1596666871.311001"], ["11600.50000", "3.54195852", "1596666820.729492", "r"]], "c": "3287076756"}, "book-100", "XBT/USD"]
[270, {"b": [["11655.70000", "0.04218686", "1596666871.311459"]], "c": "3287076756"}, "book-100", "XBT/USD"]
[270, {"a": [["11666.50000", "0.11890617", "1596666871.312165"]], "c": "3439737403"}, "book-100", "XBT/USD"]
[270, {"b": [["11659.90000", "0.85714254", "1596666871.316432"]], "c": "3439737403"}, "book-100", "XBT/USD"]
[270, {"b": [["11660.90000", "0.85706932", "1596666871.316731"]], "c": "3439737403"}, "book-100", "XBT/USD"]
[270, {"a": [["11672.80000", "0.85706932", "1596666871.317903"]], "c": "3439737403"}, "book-100", "XBT/USD"]
[270, {"b": [["11653.70000", "1.25053464", "1596666871.325743"]], "c": "3439737403"}, "book-100", "XBT/USD"]
[270, {"b": [["11646.10000", "0.03100000", "1596666871.347140"]], "c": "3439737403"}, "book-100", "XBT/USD"]
[270, {"a": [["11677.70000", "0.94965000", "1596666871.347368"]], "c": "3439737403"}, "book-100", "XBT/USD"]
[270, {"a": [["11672.10000", "0.61250000", "1596666871.347580"]], "c": "1365049818"}, "book-100", "XBT/USD"]
[270, {"b": [["11666.40000", "0.29421094", "1596666871.349254"]], "c": "313381162"}, "book-100", "XBT/USD"]
[270, {"b": [["11656.10000", "0.73381000", "1596666871.357290"]], "c": "313381162"}, "book-100", "XBT/USD"]
[270, {"a": [["11673.70000", "0.17763303", "1596666871.364589"]], "c": "313381162"}, "book-100", "XBT/USD"]
[270, {"a": [["11671.60000", "4.62637484", "1596666871.366650"]], "c": "1135653263"}, "book-100", "XBT/USD"]
[270, {"b": [["11654.00000", "2.46757050", "1596666871.377923"]], "c": "1135653263"}, "book-100", "XBT/USD"]
[270, {"a": [["11666.50000", "0.61890617", "1596666871.379198"]], "c": "1969307877"}, "book-100", "XBT/USD"]
[270, {"b": [["11660.10000", "0.00000000", "1596666871.380366"], ["11602.60000", "1.48021868", "1596666784.125874", "r"]], "c": "1969307877"}, "book-100", "XBT/USD"]
[270, {"b": [["11656.70000", "0.00000000", "1596666871.383544"], ["11602.20000", "6.32634371", "1596666815.593602", "r"]], "c": "1969307877"}, "book-100", "XBT/USD"]
[270, {"a": [["11673.10000", "0.02763445", "1596666871.385487"]], "c": "1969307877"}, "book-100", "XBT/USD"]
[270, {"a": [["11673.70000", "0.15000000", "1596666871.386303"]], "c": "1969307877"}, "book-100", "XBT/USD"]
[270, {"a": [["11670.40000", "0.25000000", "1596666871.388700"]], "c": "2087437024"}, "book-100", "XBT/USD"]
[270, {"b": [["11661.80000", "0.00000000", "1596666871.392405"], ["11602.10000", "11.25550194", "1596666780.609892", "r"]], "c": "2728241651"}, "book-100", "XBT/USD"]
[270, {"a": [["11671.00000", "0.08570229", "1596666871.403220"]], "c": "2646182270"}, "book-100", "XBT/USD"]
[270, {"a": [["11676.20000", "0.00000000", "1596666871.406006"], ["11710.10000", "0.89650546", "1596666771.484931", "r"]], "c": "2646182270"}, "book-100", "XBT/USD"]
[270, {"b": [["11656.70000", "0.72459300", "1596666871.409703"]], "c": "2646182270"}, "book-100", "XBT/USD"]
[270, {"a": [["11670.20000", "0.00000000", "1596666871.409902"], ["11710.30000", "2.24640816", "1596666867.529055", "r"]], "c": "954726659"}, "book-100", "XBT/USD"]
[270, {"a": [["11670.90000", "0.00000000", "1596666871.410762"], ["11710.40000", "1.16811308", "1596666772.597033", "r"]], "c": "3243611390"}, "book-100", "XBT/USD"]
[270, {"a": [["11677.30000", "0.15000000", "1596666871.410893"]], "c": "3243611390"}, "book-100", "XBT/USD"]
[270, {"a": [["11671.60000", "3.98381000", "1596666871.413386"]], "c": "1848611950"}, "book-100", "XBT/USD"]
[270, {"b": [["11655.00000", "0.85691535", "1596666871.416731"]], "c": "1848611950"}, "book-100", "XBT/USD"]
[270, {"b": [["11652.10000", "0.00000000", "1596666871.423409"], ["11602.20000", "6.32634371", "1596666815.593602", "r"]], "c": "1848611950"}, "book-100", "XBT/USD"]
[270, {"b": [["11631.70000", "6.49166049", "1596666871.424707"]], "c": "1848611950"}, "book-100", "XBT/USD"]
[270, {"b": [["11655.80000", "0.10352128", "1596666871.449645"]], "c": "1848611950"}, "book-100", "XBT/USD"]
[270, {"b": [["11652.20000", "0.77861000", "1596666871.453432"]], "c": "1848611950"}, "book-100", "XBT/USD"]
[270, {"a": [["11673.70000", "0.00000000", "1596666871.455499"], ["11710.60000", "2.80039129", "1596666770.582883", "r"]], "c": "1848611950"}, "book-100", "XBT/USD"]
[270, {"b": [["11647.70000", "1.21204124", "1596666871.455914"]], "c": "1848611950"}, "book-100", "XBT/USD"]
[270, {"b": [["11660.70000", "1.50000000", "1596666871.461831"]], "c": "1848611950"}, "book-100", "XBT/USD"]
[270, {"b": [["11661.60000", "0.04250000", "1596666871.502717"]], "c": "1019269426"}, "book-100", "XBT/USD"]
[270, {"a": [["11670.80000", "0.04250000", "1596666871.504166"]], "c": "3194654743"}, "book-100", "XBT/USD"]
[270, {"a": [["11686.30000", "1.42001206", "1596666871.508686"]], "c": "3194654743"}, "book-100", "XBT/USD"]
[270, {"b": [["11652.20000", "0.00000000", "1596666871.513580"], ["11607.00000", "0.17085000", "1596666870.943401", "r"]], "c": "3194654743"}, "book-100", "XBT/USD"]
[270, {"a": [["11676.00000", "0.50000000", "1596666871.516572"]], "c": "3194654743"}, "book-100", "XBT/USD"]
[270, {"a": [["11666.50000", "0.78390617", "1596666871.516995"]], "c": "3074047593"}, "book-100", "XBT/USD"]
[270, {"a": [["11677.70000", "0.30000000", "1596666871.519214"]], "c": "3074047593"}, "book-100", "XBT/USD"]
[270, {"a": [["11666.80000", "1.26931000", "1596666871.519846"]], "c": "2788734010"}, "book-100", "XBT/USD"]
[270, {"a": [["11673.50000", "0.15000000", "1596666871.521406"]], "c": "2788734010"}, "book-100", "XBT/USD"]
[270, {"a": [["11670.30000", "0.60250000", "1596666871.527862"]], "c": "3553314136"}, "book-100", "XBT/USD"]
[270, {"a": [["11689.30000", "0.00000000", "1596666871.535390"], ["11710.10000", "0.89650546", "1596666771.484931", "r"]], "c": "3553314136"}, "book-100", "XBT/USD"]
[270, {"a": [["11695.10000", "0.00000000", "1596666871.540675"], ["11710.30000", "2.24640816", "1596666867.529055", "r"]], "c": "3553314136"}, "book-100", "XBT/USD"]
[270, {"a": [["11685.90000", "0.00000000", "1596666871.542287"], ["11710.40000", "1.16811308", "1596666772.597033", "r"]], "c": "3553314136"}, "book-100", "XBT/USD"]
[270, {"b": [["11630.10000", "9.60000000", "1596666871.549799"]], "c": "3553314136"}, "book-100", "XBT/USD"]
[270, {"b": [["11646.10000", "0.00000000", "1596666871.557524"], ["11606.40000", "2.24640816", "1596666867.000402", "r"]], "c": "3553314136"}, "book-100", "XBT/USD"]
[270, {"a": [["11672.10000", "0.60250000", "1596666871.558623"]], "c": "3553314136"}, "book-100", "XBT/USD"]
[270, {"a": [["11672.10000", "0.00000000", "1596666871.572443"], ["11710.60000", "2.80039129", "1596666770.582883", "r"]], "c": "3553314136"}, "book-100", "XBT/USD"]
[270, {"a": [["11688.60000", "0.00000000", "1596666871.589474"], ["11710.70000", "3.52183532", "1596666711.393054", "r"]], "c": "3553314136"}, "book-100", "XBT/USD"]
[270, {"b": [["11645.10000", "0.03100000", "1596666871.615379"]], "c": "3553314136"}, "book-100", "XBT/USD"]
[270, {"b": [["11656.70000", "0.00000000", "1596666871.653561"], ["11606.40000", "2.24640816", "1596666867.000402", "r"]], "c": "3553314136"}, "book-100", "XBT/USD"]
[270, {"a": [["11688.90000", "0.00000000", "1596666871.656393"], ["11711.10000", "0.75800000", "1596666806.349295", "r"]], "c": "3553314136"}, "book-100", "XBT/USD"]
[270, {"a": [["11680.30000", "0.85734812", "1596666871.660159"]], "c": "3553314136"}, "book-100", "XBT/USD"]
[270, {"a": [["11670.60000", "0.00000000", "1596666871.668167"], ["11711.50000", "1.99898326", "1596666797.632161", "r"]], "c": "2650471728"}, "book-100", "XBT/USD"]
[270, {"a": [["11666.80000", "0.76931000", "1596666871.732340"]], "c": "3529374067"}, "book-100", "XBT/USD"]
[270, {"a": [["11679.80000", "0.00000000", "1596666871.736165"], ["11712.00000", "0.17085000", "1596666871.114258", "r"]], "c": "3529374067"}, "book-100", "XBT/USD"]
[270, {"a": [["11670.60000", "0.33079602", "1596666871.799324"]], "c": "2291657699"}, "book-100", "XBT/USD"]
[270, {"b": [["11666.40000", "0.19800000", "1596666871.804421"]], "c": "2044456407"}, "book-100", "XBT/USD"]
[270, {"a": [["11672.20000", "0.00000000", "1596666871.806036"], ["11712.00000", "0.17085000", "1596666871.114258", "r"]], "c": "2044456407"}, "book-100", "XBT/USD"]
[270, {"b": [["11622.00000", "0.00000000", "1596666871.807115"], ["11602.60000", "1.48021868", "1596666784.125874", "r"]], "c": "2044456407"}, "book-100", "XBT/USD"]
[270, {"a": [["11670.60000", "0.54519650", "1596666871.807547"]], "c": "1042496244"}, "book-100", "XBT/USD"]
[270, {"a": [["11677.80000", "0.65715455", "1596666871.807849"]], "c": "1042496244"}, "book-100", "XBT/USD"]
[270, {"b": [["11657.40000", "0.00000000", "1596666871.808113"], ["11602.20000", "6.32634371", "1596666815.593602", "r"]], "c": "1042496244"}, "book-100", "XBT/USD"]
[270, {"b": [["11656.10000", "0.00000000", "1596666871.809609"], ["11602.10000", "11.25550194", "1596666780.609892", "r"]], "c": "1042496244"}, "book-100", "XBT/USD"]
[270, {"a": [["11668.80000", "0.24000000", "1596666871.836195"]], "c": "736237767"}, "book-100", "XBT/USD"]
[270, {"a": [["11673.50000", "0.00000000", "1596666871.872433"], ["11711.50000", "1.99898326", "1596666797.632161", "r"]], "c": "736237767"}, "book-100", "XBT/USD"]
[270, {"a": [["11675.90000", "0.45988882", "1596666871.937014"]], "c": "736237767"}, "book-100", "XBT/USD"]
[270, {"b": [["11619.00000", "7.00000000", "1596666871.953314"]], "c": "736237767"}, "book-100", "XBT/USD"]
[270, {"a": [["11678.30000", "0.00000000", "1596666871.970929"], ["11711.50000", "1.99898326", "1596666797.632161", "r"]], "c": "736237767"}, "book-100", "XBT/USD"]
[270, {"a": [["11686.30000", "1.66907869", "1596666871.975422"]], "c": "736237767"}, "book-100", "XBT/USD"]
[270, {"a": [["11686.30000", "2.39183638", "1596666871.982395"]], "c": "736237767"}, "book-100", "XBT/USD"]
[270, {"b": [["11653.40000", "7.81857028", "1596666871.983440"]], "c": "736237767"}, "book-100", "XBT/USD"]
[270, {"a": [["11692.20000", "9.68423410", "1596666871.983939"]], "c": "736237767"}, "book-100", "XBT/USD"]
[270, {"b": [["11664.60000", "4.27800000", "1596666872.035388"]], "c": "492896327"}, "book-100", "XBT/USD"]
[270, {"a": [["11670.50000", "0.60250000", "1596666872.037745"]], "c": "1765915503"}, "book-100", "XBT/USD"]
[270, {"a": [["11670.30000", "0.00000000", "1596666872.082221"], ["11711.50000", "1.99898326", "1596666797.632161", "r"]], "c": "194690104"}, "book-100", "XBT/USD"]
[270, {"a": [["11687.00000", "6.30000000", "1596666872.144615"]], "c": "194690104"}, "book-100", "XBT/USD"]
[270, {"a": [["11671.50000", "0.26832347", "1596666872.144968"]], "c": "937771354"}, "book-100", "XBT/USD"]
[270, {"a": [["11670.60000", "1.41668938", "1596666872.149958"]], "c": "880514325"}, "book-100", "XBT/USD"]
[270, {"a": [["11671.60000", "0.73381000", "1596666872.152563"]], "c": "880514325"}, "book-100", "XBT/USD"]
[270, {"a": [["11684.20000", "0.00000000", "1596666872.153247"], ["11712.00000", "0.17085000", "1596666871.114258", "r"]], "c": "880514325"}, "book-100", "XBT/USD"]
[270, {"b": [["11663.00000", "0.50000000", "1596666872.154725"]], "c": "1310926867"}, "book-100", "XBT/USD"]
[270, {"a": [["11692.40000", "0.00000000", "1596666872.155351"], ["11714.80000", "1.99881632", "1596666809.038669", "r"]], "c": "1310926867"}, "book-100", "XBT/USD"]
[270, {"a": [["11666.50000", "1.28390617", "1596666872.170994"]], "c": "4035675347"}, "book-100", "XBT/USD"]
[270, {"a": [["11674.30000", "1.50000000", "1596666872.171952"]], "c": "4035675347"}, "book-100", "XBT/USD"]
[270, {"a": [["11678.20000", "1.96990000", "1596666872.172557"]], "c": "4035675347"}, "book-100", "XBT/USD"]
[270, {"a": [["11670.20000", "0.44762365", "1596666872.177602"]], "c": "1415909070"}, "book-100", "XBT/USD"]
[270, {"a": [["11670.60000", "1.91435754", "1596666872.183171"]], "c": "567642916"}, "book-100", "XBT/USD"]
[270, {"a": [["11672.30000", "0.00000000", "1596666872.192376"], ["11711.50000", "1.99898326", "1596666797.632161", "r"]], "c": "567642916"}, "book-100", "XBT/USD"]
[270, {"a": [["11693.30000", "0.00000000", "1596666872.284489"], ["11712.00000", "0.17085000", "1596666871.114258", "r"]], "c": "567642916"}, "book-100", "XBT/USD"]
[270, {"a": [["11708.70000", "0.00000000", "1596666872.340941"], ["11714.80000", "1.99881632", "1596666809.038669", "r"]], "c": "567642916"}, "book-100", "XBT/USD"]
[270, {"a": [["11673.00000", "4.42400000", "1596666872.361640"]], "c": "567642916"}, "book-100", "XBT/USD"]
[270, {"b": [["11654.20000", "0.10300000", "1596666872.418260"]], "c": "567642916"}, "book-100", "XBT/USD"]
[270, {"b": [["11648.50000", "0.38000000", "1596666872.490446"]], "c": "567642916"}, "book-100", "XBT/USD"]
[270, {"a": [["11670.20000", "0.00000000", "1596666872.493645"], ["11715.30000", "6.10000000", "1596666635.445451", "r"]], "c": "2108851417"}, "book-100", "XBT/USD"]
[270, {"a": [["11686.90000", "0.47808065", "1596666872.496618"]], "c": "2108851417"}, "book-100", "XBT/USD"]
[270, {"b": [["11654.10000", "0.00000000", "1596666872.501860"], ["11606.40000", "2.24640816", "1596666867.000402", "r"]], "c": "2108851417"}, "book-100", "XBT/USD"]
[270, {"a": [["11680.00000", "0.38000000", "1596666872.549077"]], "c": "2108851417"}, "book-100", "XBT/USD"]
[270, {"b": [["11655.70000", "0.00000000", "1596666872.579049"], ["11602.60000", "1.48021868", "1596666784.125874", "r"]], "c": "2108851417"}, "book-100", "XBT/USD"]
[270, {"a": [["11673.10000", "0.00000000", "1596666872.601315"], ["11714.80000", "1.99881632", "1596666809.038669", "r"]], "c": "2108851417"}, "book-100", "XBT/USD"]
[270, {"a": [["11680.30000", "0.00000000", "1596666872.660767"], ["11715.30000", "6.10000000", "1596666635.445451", "r"]], "c": "2108851417"}, "book-100", "XBT/USD"]
[270, {"b": [["11655.90000", "0.03666590", "1596666872.771115"]], "c": "2108851417"}, "book-100", "XBT/USD"]
[270, {"b": [["11616.00000", "0.00000000", "1596666872.774656"], ["11602.60000", "1.48021868", "1596666784.125874", "r"]], "c": "2108851417"}, "book-100", "XBT/USD"]
[270, {"b": [["11659.60000", "0.09700000", "1596666872.779377"]], "c": "2108851417"}, "book-100", "XBT/USD"]
[270, {"b": [["11655.30000", "0.00000000", "1596666872.795085"], ["11602.60000", "1.48021868", "1596666784.125874", "r"]], "c": "2108851417"}, "book-100", "XBT/USD"]
[270, {"a": [["11670.70000", "0.90846697", "1596666872.837065"]], "c": "2176894818"}, "book-100", "XBT/USD"]
[270, {"a": [["11666.50000", "1.78240965", "1596666872.950757"]], "c": "2537012362"}, "book-100", "XBT/USD"]
[270, {"b": [["11645.10000", "0.00000000", "1596666873.014921"], ["11602.20000", "6.32634371", "1596666815.593602", "r"]], "c": "2537012362"}, "book-100", "XBT/USD"]
[270, {"a": [["11671.50000", "0.25832347", "1596666873.052522"]], "c": "884458243"}, "book-100", "XBT/USD"]
[270, {"a": [["11686.90000", "0.00000000", "1596666873.075076"], ["11717.80000", "1.99812614", "1596666759.535617", "r"]], "c": "884458243"}, "book-100", "XBT/USD"]
[270, {"b": [["11648.60000", "4.00000000", "1596666873.090999"]], "c": "884458243"}, "book-100", "XBT/USD"]
[270, {"b": [["11646.10000", "0.03100000", "1596666873.095800"]], "c": "884458243"}, "book-100", "XBT/USD"]
[270, {"a": [["11684.10000", "0.10327054", "1596666873.246937"]], "c": "884458243"}, "book-100", "XBT/USD"]
[270, {"a": [["11672.60000", "0.01000000", "1596666873.252858"]], "c": "884458243"}, "book-100", "XBT/USD"]
[270, {"a": [["11673.10000", "0.01216515", "1596666873.306911"]], "c": "884458243"}, "book-100", "XBT/USD"]
[270, {"a": [["11675.00000", "0.01821000", "1596666873.327182"]], "c": "884458243"}, "book-100", "XBT/USD"]
[270, {"a": [["11670.30000", "0.25836336", "1596666873.345660"]], "c": "3660434389"}, "book-100", "XBT/USD"]
[270, {"b": [["11653.40000", "0.72479819", "1596666873.396253"]], "c": "3660434389"}, "book-100", "XBT/USD"]
[270, {"b": [["11654.50000", "0.00000000", "1596666873.399543"], ["11602.60000", "1.48021868", "1596666784.125874", "r"]], "c": "3660434389"}, "book-100", "XBT/USD"]
[270, {"b": [["11651.80000", "0.00000000", "1596666873.401737"], ["11602.20000", "6.32634371", "1596666815.593602", "r"]], "c": "3660434389"}, "book-100", "XBT/USD"]
[270, {"a": [["11671.50000", "0.00000000", "1596666873.409267"], ["11712.00000", "0.17085000", "1596666871.114258", "r"]], "c": "3660434389"}, "book-100", "XBT/USD"]
[270, {"b": [["11653.00000", "0.00000000", "1596666873.413073"], ["11602.10000", "11.25550194", "1596666780.609892", "r"]], "c": "3660434389"}, "book-100", "XBT/USD"]
[270, {"b": [["11651.60000", "0.00000000", "1596666873.431585"], ["11601.10000", "3.00166376", "1596666779.976375", "r"]], "c": "3660434389"}, "book-100", "XBT/USD"]
[270, {"a": [["11672.60000", "0.00000000", "1596666873.462524"], ["11714.80000", "1.99881632", "1596666809.038669", "r"]], "c": "3660434389"}, "book-100", "XBT/USD"]
[270, {"b": [["11646.10000", "0.00000000", "1596666873.462596"], ["11600.50000", "3.54195852", "1596666820.729492", "r"]], "c": "3660434389"}, "book-100", "XBT/USD"]
[270, {"b": [["11645.10000", "0.03100000", "1596666873.515976"]], "c": "3660434389"}, "book-100", "XBT/USD"]
[270, {"a": [["11689.90000", "0.44858590", "1596666873.554367"]], "c": "3660434389"}, "book-100", "XBT/USD"]
[270, {"a": [["11685.60000", "6.01756039", "1596666873.650668"]], "c": "3660434389"}, "book-100", "XBT/USD"]
[270, {"b": [["11630.10000", "8.60000000", "1596666873.959071"]], "c": "3660434389"}, "book-100", "XBT/USD"]
[270, {"b": [["11664.20000", "0.00000000", "1596666873.974227"], ["11600.50000", "3.54195852", "1596666820.729492", "r"]], "c": "2524320109"}, "book-100", "XBT/USD"]
[270, {"a": [["11667.70000", "0.64285690", "1596666874.055633"]], "c": "2017548402"}, "book-100", "XBT/USD"]
[270, {"b": [["11662.90000", "0.64285690", "1596666874.055745"]], "c": "2161867278"}, "book-100", "XBT/USD"]
[270, {"a": [["11666.90000", "0.64285690", "1596666874.055864"]], "c": "2120242142"}, "book-100", "XBT/USD"]
[270, {"a": [["11669.10000", "0.64285690", "1596666874.055983"]], "c": "870836506"}, "book-100", "XBT/USD"]
[270, {"b": [["11648.10000", "2.86648346", "1596666874.057073"]], "c": "870836506"}, "book-100", "XBT/USD"]
[270, {"b": [["11654.00000", "1.96955362", "1596666874.189796"]], "c": "870836506"}, "book-100", "XBT/USD"]
[270, {"b": [["11624.30000", "0.00000000", "1596666874.201126"], ["11600.50000", "3.54195852", "1596666820.729492", "r"]], "c": "870836506"}, "book-100", "XBT/USD"]
[270, {"b": [["11618.50000", "13.92203968", "1596666874.206167"]], "c": "870836506"}, "book-100", "XBT/USD"]
[270, {"b": [["11646.90000", "2.01010823", "1596666874.230980"]], "c": "870836506"}, "book-100", "XBT/USD"]
[270, {"b": [["11644.70000", "0.95428925", "1596666874.234212"]], "c": "870836506"}, "book-100", "XBT/USD"]
[270, {"a": [["11671.50000", "0.01000000", "1596666874.343084"]], "c": "870836506"}, "book-100", "XBT/USD"]
[270, {"a": [["11670.00000", "0.85716050", "1596666874.385085"]], "c": "362776927"}, "book-100", "XBT/USD"]
[270, {"a": [["11673.00000", "4.27400000", "1596666874.415017"]], "c": "362776927"}, "book-100", "XBT/USD"]
[270, {"b": [["11650.50000", "0.49816650", "1596666874.512572"]], "c": "362776927"}, "book-100", "XBT/USD"]
[270, {"b": [["11647.90000", "1.79767599", "1596666874.685729"]], "c": "362776927"}, "book-100", "XBT/USD"]
[270, {"b": [["11653.70000", "2.67439906", "1596666874.689557"]], "c": "362776927"}, "book-100", "XBT/USD"]
[270, {"b": [["11656.00000", "0.71179173", "1596666874.693119"]], "c": "362776927"}, "book-100", "XBT/USD"]
[270, {"b": [["11659.40000", "0.33884960", "1596666874.694707"]], "c": "362776927"}, "book-100", "XBT/USD"]
[270, {"a": [["11674.00000", "0.02763402", "1596666874.762752"]], "c": "362776927"}, "book-100", "XBT/USD"]
[270, {"a": [["11673.10000", "0.00000000", "1596666874.763941"], ["11710.60000", "2.80039129", "1596666770.582883", "r"]], "c": "362776927"}, "book-100", "XBT/USD"]
[270, {"a": [["11672.90000", "0.15000000", "1596666874.815437"]], "c": "362776927"}, "book-100", "XBT/USD"]
[270, {"b": [["11654.00000", "3.96955362", "1596666874.847026"]], "c": "362776927"}, "book-100", "XBT/USD"]
[270, {"b": [["11656.10000", "0.01333990", "1596666874.908421"]], "c": "362776927"}, "book-100", "XBT/USD"]
[270, {"b": [["11655.90000", "0.00000000", "1596666874.912447"], ["11607.00000", "0.17085000", "1596666870.943401", "r"]], "c": "362776927"}, "book-100", "XBT/USD"]
[270, {"a": [["11669.10000", "0.00000000", "1596666875.034923"], ["11710.60000", "2.80039129", "1596666770.582883", "r"]], "c": "3911341182"}, "book-100", "XBT/USD"]
[270, {"a": [["11670.70000", "0.10300000", "1596666875.135928"]], "c": "3911341182"}, "book-100", "XBT/USD"]
[270, {"a": [["11672.90000", "0.00000000", "1596666875.163710"], ["11710.70000", "3.52183532", "1596666711.393054", "r"]], "c": "3911341182"}, "book-100", "XBT/USD"]
[270, {"b": [["11645.10000", "0.00000000", "1596666875.190956"], ["11606.40000", "2.24640816", "1596666867.000402", "r"]], "c": "3911341182"}, "book-100", "XBT/USD"]
[270, {"a": [["11671.50000", "0.00000000", "1596666875.191033"], ["11711.10000", "0.75800000", "1596666806.349295", "r"]], "c": "3911341182"}, "book-100", "XBT/USD"]
[270, {"b": [["11646.10000", "0.03100000", "1596666875.239953"]], "c": "3911341182"}, "book-100", "XBT/USD"]
[270, {"a": [["11672.60000", "0.01000000", "1596666875.242318"]], "c": "3911341182"}, "book-100", "XBT/USD"]
[270, {"a": [["11672.00000", "0.15000000", "1596666875.246103"]], "c": "3911341182"}, "book-100", "XBT/USD"]
[270, {"a": [["11679.10000", "2.00000000", "1596666875.370029"]], "c": "3911341182"}, "book-100", "XBT/USD"]
[270, {"b": [["11666.40000", "0.00000000", "1596666875.396961"], ["11606.40000", "2.24640816", "1596666867.000402", "r"]], "c": "3605320173"}, "book-100", "XBT/USD"]
[270, {"b": [["11666.20000", "15.00000000", "1596666875.397450"]], "c": "367743579"}, "book-100", "XBT/USD"]
[270, {"a": [["11672.00000", "0.00000000", "1596666875.402883"], ["11710.60000", "2.80039129", "1596666770.582883", "r"]], "c": "367743579"}, "book-100", "XBT/USD"]
[270, {"a": [["11668.90000", "0.82465163", "1596666875.406025"]], "c": "604439118"}, "book-100", "XBT/USD"]
[270, {"a": [["11670.30000", "0.00000000", "1596666875.420498"], ["11710.60000", "2.80039129", "1596666770.582883", "r"]], "c": "3254477802"}, "book-100", "XBT/USD"]
[270, {"b": [["11646.10000", "0.00000000", "1596666875.447236"], ["11602.60000", "1.48021868", "1596666784.125874", "r"]], "c": "3254477802"}, "book-100", "XBT/USD"]
[270, {"a": [["11672.60000", "0.00000000", "1596666875.447810"], ["11710.70000", "3.52183532", "1596666711.393054", "r"]], "c": "3254477802"}, "book-100", "XBT/USD"]
[270, {"a": [["11666.50000", "1.66350348", "1596666875.448960"]], "c": "310884158"}, "book-100", "XBT/USD"]
[270, {"a": [["11666.50000", "1.16350348", "1596666875.450848"]], "c": "2761875480"}, "book-100", "XBT/USD"]
[270, {"a": [["11666.50000", "0.99850348", "1596666875.490582"]], "c": "2521588410"}, "book-100", "XBT/USD"]
[270, {"a": [["11670.40000", "0.26000000", "1596666875.498144"]], "c": "1410687575"}, "book-100", "XBT/USD"]
[270, {"b": [["11644.10000", "0.03100000", "1596666875.498440"]], "c": "1410687575"}, "book-100", "XBT/USD"]
[270, {"a": [["11666.30000", "0.11890617", "1596666875.507476"]], "c": "1057709714"}, "book-100", "XBT/USD"]
[270, {"a": [["11668.80000", "0.49837328", "1596666875.518236"]], "c": "812572435"}, "book-100", "XBT/USD"]
[270, {"a": [["11671.90000", "0.15000000", "1596666875.556440"]], "c": "812572435"}, "book-100", "XBT/USD"]
[270, {"b": [["11665.50000", "0.19789000", "1596666875.567925"]], "c": "2435653247"}, "book-100", "XBT/USD"]
[270, {"a": [["11666.80000", "0.00000000", "1596666875.592652"], ["11710.60000", "2.80039129", "1596666770.582883", "r"]], "c": "2355637601"}, "book-100", "XBT/USD"]
[270, {"a": [["11668.80000", "0.25837328", "1596666875.636291"]], "c": "3529237264"}, "book-100", "XBT/USD"]
[270, {"a": [["11666.50000", "0.50000000", "1596666875.734697"]], "c": "2618255043"}, "book-100", "XBT/USD"]
[270, {"b": [["11665.00000", "0.28039000", "1596666875.759620"]], "c": "4044619070"}, "book-100", "XBT/USD"]
[270, {"a": [["11667.50000", "0.24000000", "1596666875.805140"]], "c": "3713418181"}, "book-100", "XBT/USD"]
[270, {"b": [["11663.30000", "1.70000000", "1596666875.911132"]], "c": "3026507628"}, "book-100", "XBT/USD"]
[270, {"a": [["11666.30000", "0.55901369", "1596666875.972577"]], "c": "4017360855"}, "book-100", "XBT/USD"]
[270, {"b": [["11655.60000", "0.90148759", "1596666875.972672"]], "c": "4017360855"}, "book-100", "XBT/USD"]
[270, {"a": [["11677.10000", "0.04473447", "1596666875.972839"]], "c": "4017360855"}, "book-100", "XBT/USD"]
[270, {"a": [["11668.90000", "0.00000000", "1596666876.010701"], ["11710.40000", "1.16811308", "1596666772.597033", "r"]], "c": "658726855"}, "book-100", "XBT/USD"]
[270, {"b": [["11665.70000", "0.19789000", "1596666876.034904"]], "c": "474321828"}, "book-100", "XBT/USD"]
[270, {"b": [["11666.10000", "0.19789000", "1596666876.037303"]], "c": "3534667954"}, "book-100", "XBT/USD"]
[270, {"a": [["11671.90000", "0.00000000", "1596666876.040447"], ["11710.60000", "2.80039129", "1596666770.582883", "r"]], "c": "3534667954"}, "book-100", "XBT/USD"]
[270, {"a": [["11666.50000", "0.00000000", "1596666876.041702"], ["11710.70000", "3.52183532", "1596666711.393054", "r"]], "c": "668081826"}, "book-100", "XBT/USD"]
[270, {"b": [["11652.10000", "3.53933470", "1596666876.282798"]], "c": "668081826"}, "book-100", "XBT/USD"]
[270, {"b": [["11646.20000", "3.54112774", "1596666876.284784"]], "c": "668081826"}, "book-100", "XBT/USD"]
[270, {"a": [["11669.10000", "0.82481837", "1596666876.290403"]], "c": "18832184"}, "book-100", "XBT/USD"]
[270, {"a": [["11678.30000", "0.13419792", "1596666876.451616"]], "c": "18832184"}, "book-100", "XBT/USD"]
[270, {"b": [["11655.00000", "0.99111327", "1596666876.451985"]], "c": "18832184"}, "book-100", "XBT/USD"]
[270, {"b": [["11666.10000", "0.00000000", "1596666876.492810"], ["11610.00000", "0.17085000", "1596666865.604704", "r"]], "c": "3488876590"}, "book-100", "XBT/USD"]
[270, {"a": [["11675.90000", "0.00000000", "1596666876.606672"], ["11710.60000", "2.80039129", "1596666770.582883", "r"]], "c": "3488876590"}, "book-100", "XBT/USD"]
[270, {"a": [["11671.50000", "1.70000000", "1596666876.725261"]], "c": "3488876590"}, "book-100", "XBT/USD"]
[270, {"a": [["11668.80000", "0.00000000", "1596666876.777587"], ["11710.60000", "2.80039129", "1596666770.582883", "r"]], "c": "2404377237"}, "book-100", "XBT/USD"]
[270, {"a": [["11671.90000", "0.15000000", "1596666876.799868"]], "c": "2404377237"}, "book-100", "XBT/USD"]
[270, {"b": [["11665.50000", "0.00000000", "1596666876.804626"], ["11609.80000", "21.20000000", "1596666704.766154", "r"]], "c": "3291438340"}, "book-100", "XBT/USD"]
[270, {"a": [["11669.00000", "0.25836845", "1596666876.805697"]], "c": "3677153074"}, "book-100", "XBT/USD"]
[270, {"a": [["11681.10000", "0.00000000", "1596666876.847937"], ["11710.40000", "1.16811308", "1596666772.597033", "r"]], "c": "3677153074"}, "book-100", "XBT/USD"]
[270, {"b": [["11665.00000", "0.19789000", "1596666876.848159"]], "c": "2291644139"}, "book-100", "XBT/USD"]
[270, {"b": [["11656.10000", "0.00000000", "1596666876.963213"], ["11609.30000", "2.01627299", "1596666817.684177", "r"]], "c": "2291644139"}, "book-100", "XBT/USD"]
[270, {"b": [["11654.90000", "0.04218975", "1596666876.965416"]], "c": "2291644139"}, "book-100", "XBT/USD"]
[270, {"b": [["11665.60000", "0.58766000", "1596666876.993916"]], "c": "1296611800"}, "book-100", "XBT/USD"]
[270, {"a": [["11706.00000", "0.17085000", "1596666877.024455"]], "c": "1296611800"}, "book-100", "XBT/USD"]
[270, {"a": [["11671.90000", "0.00000000", "1596666877.037414"], ["11710.40000", "1.16811308", "1596666772.597033", "r"]], "c": "1296611800"}, "book-100", "XBT/USD"]
[270, {"a": [["11666.30000", "0.11890617", "1596666877.051535"]], "c": "295748356"}, "book-100", "XBT/USD"]
[270, {"b": [["11655.80000", "0.00000000", "1596666877.095965"], ["11609.30000", "2.01627299", "1596666817.684177", "r"]], "c": "295748356"}, "book-100", "XBT/USD"]
[270, {"b": [["11653.40000", "0.00000000", "1596666877.096841"], ["11607.70000", "8.40000000", "1596666861.504830", "r"]], "c": "295748356"}, "book-100", "XBT/USD"]
[270, {"a": [["11676.40000", "0.08250000", "1596666877.102627"]], "c": "295748356"}, "book-100", "XBT/USD"]
[270, {"b": [["11661.00000", "0.08250000", "1596666877.102723"]], "c": "295748356"}, "book-100", "XBT/USD"]
[270, {"a": [["11671.50000", "0.00000000", "1596666877.105618"], ["11710.40000", "1.16811308", "1596666772.597033", "r"]], "c": "295748356"}, "book-100", "XBT/USD"]
[270, {"b": [["11665.70000", "0.00000000", "1596666877.118761"], ["11607.70000", "8.40000000", "1596666861.504830", "r"]], "c": "4057537245"}, "book-100", "XBT/USD"]
[270, {"a": [["11672.40000", "0.15000000", "1596666877.122540"]], "c": "4057537245"}, "book-100", "XBT/USD"]
[270, {"a": [["11666.30000", "0.36390617", "1596666877.145122"]], "c": "2149164443"}, "book-100", "XBT/USD"]
[270, {"b": [["11649.30000", "7.09567075", "1596666877.154213"]], "c": "2149164443"}, "book-100", "XBT/USD"]
[270, {"b": [["11659.40000", "0.00000000", "1596666877.154586"], ["11607.70000", "8.40000000", "1596666861.504830", "r"]], "c": "2149164443"}, "book-100", "XBT/USD"]
[270, {"b": [["11653.80000", "0.04219373", "1596666877.191879"]], "c": "2149164443"}, "book-100", "XBT/USD"]
[270, {"a": [["11666.50000", "0.64287016", "1596666877.200125"]], "c": "4041552357"}, "book-100", "XBT/USD"]
[270, {"b": [["11654.90000", "0.00000000", "1596666877.205712"], ["11607.70000", "8.40000000", "1596666861.504830", "r"]], "c": "4041552357"}, "book-100", "XBT/USD"]
[270, {"b": [["11666.20000", "15.19766000", "1596666877.207082"]], "c": "980435483"}, "book-100", "XBT/USD"]
[270, {"a": [["11672.40000", "0.00000000", "1596666877.210239"], ["11710.30000", "2.24640816", "1596666867.529055", "r"]], "c": "980435483"}, "book-100", "XBT/USD"]
[270, {"b": [["11648.20000", "3.20779913", "1596666877.264930"]], "c": "980435483"}, "book-100", "XBT/USD"]
[270, {"a": [["11669.00000", "0.00000000", "1596666877.293922"], ["11710.40000", "1.16811308", "1596666772.597033", "r"]], "c": "846739746"}, "book-100", "XBT/USD"]
[270, {"a": [["11669.90000", "0.25835542", "1596666877.300662"]], "c": "1304964585"}, "book-100", "XBT/USD"]
[270, {"b": [["11657.30000", "3.00055440", "1596666877.344111"]], "c": "1304964585"}, "book-100", "XBT/USD"]
[270, {"b": [["11657.40000", "0.10344645", "1596666877.405111"]], "c": "1304964585"}, "book-100", "XBT/USD"]
[270, {"b": [["11655.10000", "0.72426803", "1596666877.408932"]], "c": "1304964585"}, "book-100", "XBT/USD"]
[270, {"b": [["11656.00000", "0.00000000", "1596666877.478430"], ["11610.00000", "0.17085000", "1596666865.604704", "r"]], "c": "1304964585"}, "book-100", "XBT/USD"]
[270, {"b": [["11654.00000", "2.00000000", "1596666877.479756"]], "c": "1304964585"}, "book-100", "XBT/USD"]
[270, {"b": [["11653.70000", "1.25053464", "1596666877.516562"]], "c": "1304964585"}, "book-100", "XBT/USD"]
[270, {"b": [["11660.60000", "0.33881473", "1596666877.533676"]], "c": "1304964585"}, "book-100", "XBT/USD"]
[270, {"b": [["11664.60000", "0.00000000", "1596666877.597518"], ["11610.00000", "0.17085000", "1596666865.604704", "r"]], "c": "1222341576"}, "book-100", "XBT/USD"]
[270, {"b": [["11665.80000", "4.27900000", "1596666877.608474"]], "c": "79893850"}, "book-100", "XBT/USD"]
[270, {"a": [["11679.10000", "0.00000000", "1596666877.634713"], ["11710.40000", "1.16811308", "1596666772.597033", "r"]], "c": "79893850"}, "book-100", "XBT/USD"]
[270, {"b": [["11622.70000", "0.00000000", "1596666877.676712"], ["11610.00000", "0.17085000", "1596666865.604704", "r"]], "c": "79893850"}, "book-100", "XBT/USD"]
[270, {"a": [["11705.20000", "2.24677915", "1596666877.678669"]], "c": "79893850"}, "book-100", "XBT/USD"]
[270, {"a": [["11710.30000", "0.00000000", "1596666877.679503"], ["11710.40000", "1.16811308", "1596666772.597033", "r"]], "c": "79893850"}, "book-100", "XBT/USD"]
[270, {"a": [["11687.70000", "0.74858735", "1596666877.679689"]], "c": "79893850"}, "book-100", "XBT/USD"]
[270, {"b": [["11621.30000", "0.74858735", "1596666877.679873"]], "c": "79893850"}, "book-100", "XBT/USD"]
[270, {"a": [["11706.00000", "0.00000000", "1596666877.686298"], ["11710.40000", "1.16811308", "1596666772.597033", "r"]], "c": "79893850"}, "book-100", "XBT/USD"]
[270, {"a": [["11690.80000", "0.00000000", "1596666877.699027"], ["11710.60000", "2.80039129", "1596666770.582883", "r"]], "c": "79893850"}, "book-100", "XBT/USD"]
[270, {"b": [["11654.90000", "1.42371782", "1596666877.786873"]], "c": "79893850"}, "book-100", "XBT/USD"]
[270, {"b": [["11657.20000", "1.56836800", "1596666877.788360"]], "c": "79893850"}, "book-100", "XBT/USD"]
[270, {"b": [["11660.70000", "1.51491251", "1596666877.796833"]], "c": "79893850"}, "book-100", "XBT/USD"]
[270, {"a": [["11671.30000", "0.01491251", "1596666877.796958"]], "c": "79893850"}, "book-100", "XBT/USD"]
[270, {"a": [["11673.60000", "0.07456347", "1596666877.865694"]], "c": "79893850"}, "book-100", "XBT/USD"]
[270, {"b": [["11659.80000", "0.07456347", "1596666877.867934"]], "c": "79893850"}, "book-100", "XBT/USD"]
[270, {"a": [["11672.20000", "0.15000000", "1596666877.914504"]], "c": "79893850"}, "book-100", "XBT/USD"]
[270, {"b": [["11659.20000", "0.17895232", "1596666877.923114"]], "c": "79893850"}, "book-100", "XBT/USD"]
[270, {"a": [["11676.00000", "0.67894991", "1596666877.983083"]], "c": "79893850"}, "book-100", "XBT/USD"]
[270, {"b": [["11648.30000", "0.00428624", "1596666877.983316"]], "c": "79893850"}, "book-100", "XBT/USD"]
[270, {"a": [["11685.50000", "0.00438186", "1596666877.984657"]], "c": "79893850"}, "book-100", "XBT/USD"]
[270, {"b": [["11663.00000", "0.00000000", "1596666878.025089"], ["11613.60000", "3.55198121", "1596666780.634357", "r"]], "c": "1666075750"}, "book-100", "XBT/USD"]
[270, {"b": [["11650.50000", "0.00000000", "1596666878.040239"], ["11613.00000", "0.17085000", "1596666803.224745", "r"]], "c": "1666075750"}, "book-100", "XBT/USD"]
[270, {"a": [["11677.40000", "0.15000000", "1596666878.053427"]], "c": "1666075750"}, "book-100", "XBT/USD"]
[270, {"a": [["11673.60000", "0.00000000", "1596666878.058830"], ["11709.90000", "3.52186457", "1596666773.954225", "r"]], "c": "1666075750"}, "book-100", "XBT/USD"]
[270, {"b": [["11646.90000", "0.00000000", "1596666878.062967"], ["11612.30000", "7.00000000", "1596666617.080387", "r"]], "c": "1666075750"}, "book-100", "XBT/USD"]
[270, {"b": [["11653.90000", "0.00000000", "1596666878.066755"], ["11611.90000", "1.06000000", "1596666780.430510", "r"]], "c": "1666075750"}, "book-100", "XBT/USD"]
[270, {"b": [["11653.70000", "0.34966872", "1596666878.068758"]], "c": "1666075750"}, "book-100", "XBT/USD"]
[270, {"b": [["11644.10000", "0.00000000", "1596666878.080540"], ["11610.00000", "0.17085000", "1596666865.604704", "r"]], "c": "1666075750"}, "book-100", "XBT/USD"]
[270, {"a": [["11670.40000", "0.25000000", "1596666878.080606"]], "c": "3230519384"}, "book-100", "XBT/USD"]
[270, {"a": [["11672.20000", "0.00000000", "1596666878.104488"], ["11710.10000", "0.89650546", "1596666771.484931", "r"]], "c": "3230519384"}, "book-100", "XBT/USD"]
[270, {"a": [["11679.70000", "0.69938843", "1596666878.121994"]], "c": "3230519384"}, "book-100", "XBT/USD"]
[270, {"b": [["11646.10000", "0.03100000", "1596666878.131720"]], "c": "3230519384"}, "book-100", "XBT/USD"]
[270, {"a": [["11672.60000", "0.01000000", "1596666878.131840"]], "c": "3230519384"}, "book-100", "XBT/USD"]
[270, {"b": [["11666.20000", "15.57813572", "1596666878.137835"]], "c": "2574039076"}, "book-100", "XBT/USD"]
[270, {"b": [["11663.50000", "0.50000000", "1596666878.166354"]], "c": "378702911"}, "book-100", "XBT/USD"]
[270, {"b": [["11655.80000", "0.24969732", "1596666878.198313"]], "c": "378702911"}, "book-100", "XBT/USD"]
[270, {"a": [["11672.60000", "0.16000000", "1596666878.204521"]], "c": "378702911"}, "book-100", "XBT/USD"]
[270, {"a": [["11674.40000", "0.07456196", "1596666878.229809"]], "c": "378702911"}, "book-100", "XBT/USD"]
[270, {"a": [["11672.60000", "0.01000000", "1596666878.298896"]], "c": "378702911"}, "book-100", "XBT/USD"]
[270, {"a": [["11677.80000", "0.00000000", "1596666878.310046"], ["11709.70000", "7.20507863", "1596666814.449677", "r"]], "c": "378702911"}, "book-100", "XBT/USD"]
[270, {"a": [["11671.60000", "0.00000000", "1596666878.330604"], ["11709.90000", "3.52186457", "1596666773.954225", "r"]], "c": "378702911"}, "book-100", "XBT/USD"]
[270, {"a": [["11672.60000", "0.00000000", "1596666878.354151"], ["11710.10000", "0.89650546", "1596666771.484931", "r"]], "c": "378702911"}, "book-100", "XBT/USD"]
[270, {"b": [["11646.10000", "0.00000000", "1596666878.354744"], ["11612.30000", "7.00000000", "1596666617.080387", "r"]], "c": "378702911"}, "book-100", "XBT/USD"]
[270, {"a": [["11672.10000", "0.15000000", "1596666878.392335"]], "c": "378702911"}, "book-100", "XBT/USD"]
[270, {"a": [["11671.50000", "0.01000000", "1596666878.403290"]], "c": "378702911"}, "book-100", "XBT/USD"]
[270, {"b": [["11645.10000", "0.03100000", "1596666878.404197"]], "c": "378702911"}, "book-100", "XBT/USD"]
[270, {"b": [["11652.20000", "0.49799117", "1596666878.405228"]], "c": "378702911"}, "book-100", "XBT/USD"]
[270, {"b": [["11664.20000", "0.09621094", "1596666878.408719"]], "c": "1478174991"}, "book-100", "XBT/USD"]
[270, {"b": [["11649.20000", "2.00965371", "1596666878.429023"]], "c": "1478174991"}, "book-100", "XBT/USD"]
[270, {"b": [["11655.30000", "0.90053727", "1596666878.470034"]], "c": "1478174991"}, "book-100", "XBT/USD"]
[270, {"b": [["11648.10000", "2.00936632", "1596666878.517036"]], "c": "1478174991"}, "book-100", "XBT/USD"]
[270, {"a": [["11672.80000", "0.95328026", "1596666878.517769"]], "c": "1478174991"}, "book-100", "XBT/USD"]
[270, {"a": [["11678.50000", "0.66302820", "1596666878.580335"]], "c": "1478174991"}, "book-100", "XBT/USD"]
[270, {"a": [["11671.50000", "0.00000000", "1596666878.580414"], ["11709.70000", "7.20507863", "1596666814.449677", "r"]], "c": "1478174991"}, "book-100", "XBT/USD"]
[270, {"a": [["11672.00000", "0.01000000", "1596666878.635454"]], "c": "1478174991"}, "book-100", "XBT/USD"]
[270, {"a": [["11669.10000", "0.00000000", "1596666878.995593"], ["11709.70000", "7.20507863", "1596666814.449677", "r"]], "c": "2470869785"}, "book-100", "XBT/USD"]
[271, [["11666.20000", "0.02332600", "1596666879.037980", "s", "l", ""]], "trade", "XBT/USD"]
[270, {"b": [["11666.20000", "15.55480972", "1596666879.037980"]], "c": "587512581"}, "book-100", "XBT/USD"]
[270, {"a": [["11672.10000", "0.00000000", "1596666879.115845"], ["11709.90000", "3.52186457", "1596666773.954225", "r"]], "c": "587512581"}, "book-100", "XBT/USD"]
[270, {"a": [["11672.00000", "0.00000000", "1596666879.175044"], ["11710.10000", "0.89650546", "1596666771.484931", "r"]], "c": "587512581"}, "book-100", "XBT/USD"]
[270, {"b": [["11663.80000", "1.70200000", "1596666879.176718"]], "c": "1652408652"}, "book-100", "XBT/USD"]
[270, {"a": [["11672.00000", "1.71300000", "1596666879.193444"]], "c": "1652408652"}, "book-100", "XBT/USD"]
[270, {"b": [["11663.30000", "0.00000000", "1596666879.251315"], ["11617.40000", "0.75800000", "1596666775.482846", "r"]], "c": "2900535965"}, "book-100", "XBT/USD"]
[270, {"a": [["11672.60000", "0.01000000", "1596666879.383348"]], "c": "2900535965"}, "book-100", "XBT/USD"]
[270, {"a": [["11672.80000", "1.10328026", "1596666879.402501"]], "c": "2900535965"}, "book-100", "XBT/USD"]
[270, {"b": [["11648.30000", "0.00000000", "1596666879.592507"], ["11615.60000", "0.20000000", "1596666623.308321", "r"]], "c": "2900535965"}, "book-100", "XBT/USD"]
[270, {"a": [["11676.00000", "0.17894991", "1596666879.614978"]], "c": "2900535965"}, "book-100", "XBT/USD"]
[270, {"a": [["11681.50000", "0.50000000", "1596666879.618119"]], "c": "2900535965"}, "book-100", "XBT/USD"]
[270, {"a": [["11668.20000", "0.81744262", "1596666879.662314"]], "c": "1895157641"}, "book-100", "XBT/USD"]
[270, {"a": [["11672.80000", "0.95328026", "1596666879.695092"]], "c": "1895157641"}, "book-100", "XBT/USD"]
[270, {"a": [["11672.60000", "0.00000000", "1596666879.713633"], ["11708.60000", "5.02595511", "1596666850.305826", "r"]], "c": "1895157641"}, "book-100", "XBT/USD"]
[270, {"a": [["11671.90000", "0.01000000", "1596666879.766276"]], "c": "1895157641"}, "book-100", "XBT/USD"]
[270, {"a": [["11685.50000", "0.00000000", "1596666879.778521"], ["11708.60000", "5.02595511", "1596666850.305826", "r"]], "c": "1895157641"}, "book-100", "XBT/USD"]
[271, [["11666.20000", "0.00519661", "1596666879.850856", "s", "l", ""]], "trade", "XBT/USD"]
[270, {"b": [["11666.20000", "15.54961311", "1596666879.850856"]], "c": "643629478"}, "book-100", "XBT/USD"]
[270, {"a": [["11667.50000", "0.00000000", "1596666879.872796"], ["11709.70000", "7.20507863", "1596666814.449677", "r"]], "c": "1919815801"}, "book-100", "XBT/USD"]
[270, {"a": [["11683.60000", "0.00000000", "1596666879.873854"], ["11709.90000", "3.52186457", "1596666773.954225", "r"]], "c": "1919815801"}, "book-100", "XBT/USD"]
[270, {"a": [["11672.10000", "0.15000000", "1596666879.901685"]], "c": "1919815801"}, "book-100", "XBT/USD"]
[270, {"a": [["11676.00000", "0.61794991", "1596666879.924623"]], "c": "1919815801"}, "book-100", "XBT/USD"]
[270, {"b": [["11631.70000", "6.05366049", "1596666879.992308"]], "c": "1919815801"}, "book-100", "XBT/USD"]
[270, {"b": [["11653.90000", "0.43800000", "1596666880.045081"]], "c": "1919815801"}, "book-100", "XBT/USD"]
[270, {"a": [["11668.60000", "0.24000000", "1596666880.047905"]], "c": "1319699390"}, "book-100", "XBT/USD"]
[270, {"b": [["11660.70000", "1.50000000", "1596666880.081835"]], "c": "1319699390"}, "book-100", "XBT/USD"]
[270, {"b": [["11659.20000", "0.00000000", "1596666880.082143"], ["11615.60000", "0.20000000", "1596666623.308321", "r"]], "c": "1319699390"}, "book-100", "XBT/USD"]
[270, {"b": [["11659.80000", "0.00000000", "1596666880.087091"], ["11614.80000", "3.08717099", "1596666746.879208", "r"]], "c": "1319699390"}, "book-100", "XBT/USD"]
[270, {"b": [["11666.20000", "15.35195311", "1596666880.089064"]], "c": "1225820735"}, "book-100", "XBT/USD"]
[270, {"b": [["11661.60000", "0.00000000", "1596666880.127354"], ["11613.60000", "3.55198121", "1596666780.634357", "r"]], "c": "1225820735"}, "book-100", "XBT/USD"]
[270, {"a": [["11670.80000", "0.00000000", "1596666880.141017"], ["11709.70000", "7.20507863", "1596666814.449677", "r"]], "c": "1225820735"}, "book-100", "XBT/USD"]
[270, {"a": [["11672.10000", "0.00000000", "1596666880.164916"], ["11709.90000", "3.52186457", "1596666773.954225", "r"]], "c": "1225820735"}, "book-100", "XBT/USD"]
[270, {"b": [["11663.80000", "0.00000000", "1596666880.198475"], ["11613.00000", "0.17085000", "1596666803.224745", "r"]], "c": "966435074"}, "book-100", "XBT/USD"]
[270, {"b": [["11662.80000", "0.64281769", "1596666880.201181"]], "c": "12734412"}, "book-100", "XBT/USD"]
[270, {"b": [["11657.50000", "0.72196464", "1596666880.276142"]], "c": "12734412"}, "book-100", "XBT/USD"]
[270, {"b": [["11659.80000", "0.01491372", "1596666880.276360"]], "c": "12734412"}, "book-100", "XBT/USD"]
[270, {"b": [["11657.80000", "0.07456860", "1596666880.276536"]], "c": "12734412"}, "book-100", "XBT/USD"]
[270, {"a": [["11676.40000", "0.52069688", "1596666880.347078"]], "c": "12734412"}, "book-100", "XBT/USD"]
[270, {"a": [["11689.60000", "0.63691783", "1596666880.347152"]], "c": "12734412"}, "book-100", "XBT/USD"]
[270, {"b": [["11666.20000", "14.97147739", "1596666880.399584"]], "c": "2462050904"}, "book-100", "XBT/USD"]
[270, {"a": [["11669.80000", "0.04250000", "1596666880.405979"]], "c": "478452758"}, "book-100", "XBT/USD"]
[270, {"b": [["11660.00000", "0.04250000", "1596666880.406172"]], "c": "478452758"}, "book-100", "XBT/USD"]
[270, {"a": [["11674.40000", "0.00000000", "1596666880.431434"], ["11709.70000", "7.20507863", "1596666814.449677", "r"]], "c": "478452758"}, "book-100", "XBT/USD"]
[270, {"a": [["11671.30000", "0.00000000", "1596666880.433970"], ["11709.90000", "3.52186457", "1596666773.954225", "r"]], "c": "478452758"}, "book-100", "XBT/USD"]
[270, {"a": [["11669.90000", "0.00000000", "1596666880.464122"], ["11710.10000", "0.89650546", "1596666771.484931", "r"]], "c": "1117612465"}, "book-100", "XBT/USD"]
[270, {"a": [["11669.70000", "0.25835658", "1596666880.560947"]], "c": "1132580874"}, "book-100", "XBT/USD"]
[270, {"a": [["11678.10000", "0.01491342", "1596666880.661867"]], "c": "1132580874"}, "book-100", "XBT/USD"]
[270, {"a": [["11680.00000", "0.45456708", "1596666880.662336"]], "c": "1132580874"}, "book-100", "XBT/USD"]
[270, {"b": [["11660.90000", "1.74277932", "1596666880.779264"]], "c": "1132580874"}, "book-100", "XBT/USD"]
[271, [["11666.20000", "0.00521607", "1596666880.989771", "s", "l", ""]], "trade", "XBT/USD"]
[270, {"b": [["11666.20000", "14.96626132", "1596666880.989771"]], "c": "3545077342"}, "book-100", "XBT/USD"]
[270, {"a": [["11670.40000", "0.00000000", "1596666881.080538"], ["11709.90000", "3.52186457", "1596666773.954225", "r"]], "c": "3483496330"}, "book-100", "XBT/USD"]
[271, [["11666.20000", "0.02332600", "1596666881.081921", "s", "l", ""]], "trade", "XBT/USD"]
[270, {"b": [["11666.20000", "14.94293532", "1596666881.081921"]], "c": "759481455"}, "book-100", "XBT/USD"]
[270, {"b": [["11663.50000", "0.00000000", "1596666881.087471"], ["11615.60000", "0.20000000", "1596666623.308321", "r"]], "c": "976097971"}, "book-100", "XBT/USD"]
[270, {"b": [["11654.80000", "3.32810587", "1596666881.126962"]], "c": "976097971"}, "book-100", "XBT/USD"]
[270, {"a": [["11666.50000", "0.00000000", "1596666881.127625"], ["11710.10000", "0.89650546", "1596666771.484931", "r"]], "c": "2693413052"}, "book-100", "XBT/USD"]
[270, {"b": [["11666.20000", "15.32341104", "1596666881.166777"]], "c": "3407037611"}, "book-100", "XBT/USD"]
[270, {"b": [["11656.60000", "7.10000000", "1596666881.175054"]], "c": "3407037611"}, "book-100", "XBT/USD"]
[270, {"a": [["11677.70000", "0.00000000", "1596666881.176100"], ["11710.40000", "1.16811308", "1596666772.597033", "r"]], "c": "3407037611"}, "book-100", "XBT/USD"]
[270, {"a": [["11672.00000", "0.00000000", "1596666881.182224"], ["11710.60000", "2.80039129", "1596666770.582883", "r"]], "c": "3407037611"}, "book-100", "XBT/USD"]
[270, {"a": [["11677.70000", "2.00000000", "1596666881.186534"]], "c": "3407037611"}, "book-100", "XBT/USD"]
[270, {"a": [["11669.70000", "0.00000000", "1596666881.187713"], ["11710.60000", "2.80039129", "1596666770.582883", "r"]], "c": "2932686789"}, "book-100", "XBT/USD"]
[270, {"a": [["11676.60000", "0.88138000", "1596666881.196269"]], "c": "2932686789"}, "book-100", "XBT/USD"]
[270, {"a": [["11674.10000", "0.10100000", "1596666881.199079"]], "c": "2932686789"}, "book-100", "XBT/USD"]
[270, {"a": [["11674.30000", "0.00000000", "1596666881.212985"], ["11710.60000", "2.80039129", "1596666770.582883", "r"]], "c": "2932686789"}, "book-100", "XBT/USD"]
[270, {"b": [["11665.20000", "0.50000000", "1596666881.220696"]], "c": "2018130370"}, "book-100", "XBT/USD"]
[270, {"a": [["11672.60000", "0.25000000", "1596666881.222318"]], "c": "2018130370"}, "book-100", "XBT/USD"]
[270, {"a": [["11671.90000", "0.00000000", "1596666881.236128"], ["11710.60000", "2.80039129", "1596666770.582883", "r"]], "c": "2018130370"}, "book-100", "XBT/USD"]
[270, {"b": [["11662.00000", "9.99987003", "1596666881.237130"]], "c": "2018130370"}, "book-100", "XBT/USD"]
[270, {"a": [["11670.40000", "0.25834135", "1596666881.253158"]], "c": "801769302"}, "book-100", "XBT/USD"]
[270, {"a": [["11676.40000", "2.93806952", "1596666881.271161"]], "c": "801769302"}, "book-100", "XBT/USD"]
[270, {"a": [["11681.60000", "0.00000000", "1596666881.341296"], ["11710.60000", "2.80039129", "1596666770.582883", "r"]], "c": "801769302"}, "book-100", "XBT/USD"]
[270, {"b": [["11662.80000", "0.00000000", "1596666881.341585"], ["11617.50000", "2.49761864", "1596666811.445738", "r"]], "c": "2299811518"}, "book-100", "XBT/USD"]
[270, {"a": [["11666.90000", "0.00000000", "1596666881.342420"], ["11710.70000", "3.52183532", "1596666711.393054", "r"]], "c": "2819069869"}, "book-100", "XBT/USD"]
[270, {"a": [["11668.60000", "0.00000000", "1596666881.342624"], ["11711.10000", "0.75800000", "1596666806.349295", "r"]], "c": "2969993637"}, "book-100", "XBT/USD"]
[270, {"a": [["11667.70000", "0.00000000", "1596666881.343626"], ["11711.50000", "1.99898326", "1596666797.632161", "r"]], "c": "3615301365"}, "book-100", "XBT/USD"]
[270, {"b": [["11662.90000", "0.00000000", "1596666881.345100"], ["11617.40000", "0.75800000", "1596666775.482846", "r"]], "c": "1464258714"}, "book-100", "XBT/USD"]
[270, {"b": [["11662.00000", "10.09987003", "1596666881.346755"]], "c": "4258026596"}, "book-100", "XBT/USD"]
[270, {"b": [["11662.00000", "0.10000000", "1596666881.348268"]], "c": "1729078207"}, "book-100", "XBT/USD"]
[270, {"a": [["11670.70000", "0.00000000", "1596666881.348342"], ["11712.00000", "0.17085000", "1596666871.114258", "r"]], "c": "3929101019"}, "book-100", "XBT/USD"]
[270, {"a": [["11668.20000", "0.00000000", "1596666881.348528"], ["11714.80000", "1.99881632", "1596666809.038669", "r"]], "c": "3603996025"}, "book-100", "XBT/USD"]
[270, {"a": [["11672.60000", "0.26000000", "1596666881.349610"]], "c": "145316540"}, "book-100", "XBT/USD"]
[270, {"a": [["11678.30000", "0.00000000", "1596666881.350689"], ["11715.30000", "6.10000000", "1596666635.445451", "r"]], "c": "145316540"}, "book-100", "XBT/USD"]
[270, {"a": [["11678.50000", "0.00000000", "1596666881.351104"], ["11717.80000", "1.99812614", "1596666759.535617", "r"]], "c": "145316540"}, "book-100", "XBT/USD"]
[270, {"a": [["11670.00000", "0.00000000", "1596666881.361900"], ["11718.00000", "0.17085000", "1596666865.758675", "r"]], "c": "478396787"}, "book-100", "XBT/USD"]
[270, {"a": [["11677.60000", "1.65000000", "1596666881.363360"]], "c": "478396787"}, "book-100", "XBT/USD"]
[270, {"b": [["11665.20000", "0.00000000", "1596666881.397619"], ["11615.60000", "0.20000000", "1596666623.308321", "r"]], "c": "3921458779"}, "book-100", "XBT/USD"]
[270, {"a": [["11676.00000", "0.43900000", "1596666881.399979"]], "c": "3921458779"}, "book-100", "XBT/USD"]
[270, {"a": [["11672.60000", "0.01000000", "1596666881.404408"]], "c": "715294615"}, "book-100", "XBT/USD"]
[270, {"b": [["11660.80000", "3.19647445", "1596666881.424701"]], "c": "715294615"}, "book-100", "XBT/USD"]
[270, {"a": [["11673.20000", "0.00000000", "1596666881.424821"], ["11718.40000", "0.48360000", "1596666846.374528", "r"]], "c": "3486276638"}, "book-100", "XBT/USD"]
[270, {"a": [["11681.00000", "0.00000000", "1596666881.435035"], ["11718.50000", "24.30000000", "1596666641.380470", "r"]], "c": "3486276638"}, "book-100", "XBT/USD"]
[270, {"a": [["11674.60000", "0.09621094", "1596666881.486851"]], "c": "3486276638"}, "book-100", "XBT/USD"]
[270, {"a": [["11678.10000", "0.00000000", "1596666881.494026"], ["11718.50000", "24.30000000", "1596666641.380470", "r"]], "c": "3486276638"}, "book-100", "XBT/USD"]
[270, {"a": [["11666.30000", "0.11890617", "1596666881.496009"]], "c": "1002041924"}, "book-100", "XBT/USD"]
[270, {"a": [["11670.40000", "0.00000000", "1596666881.498098"], ["11719.60000", "2.98021891", "1596666782.974175", "r"]], "c": "1497491486"}, "book-100", "XBT/USD"]
[270, {"b": [["11662.50000", "9.99987003", "1596666881.499250"]], "c": "1129267257"}, "book-100", "XBT/USD"]
[270, {"a": [["11677.60000", "0.15000000", "1596666881.512443"]], "c": "1129267257"}, "book-100", "XBT/USD"]
[270, {"b": [["11666.20000", "17.02341104", "1596666881.523564"]], "c": "2266488112"}, "book-100", "XBT/USD"]
[270, {"a": [["11672.80000", "0.85706932", "1596666881.524329"]], "c": "1327485714"}, "book-100", "XBT/USD"]
[270, {"a": [["11675.20000", "1.70800000", "1596666881.529680"]], "c": "1327485714"}, "book-100", "XBT/USD"]
[270, {"b": [["11645.10000", "0.00000000", "1596666881.539127"], ["11617.40000", "0.75800000", "1596666775.482846", "r"]], "c": "1327485714"}, "book-100", "XBT/USD"]
[270, {"b": [["11666.20000", "17.52341104", "1596666881.549858"]], "c": "272243385"}, "book-100", "XBT/USD"]
[270, {"b": [["11666.20000", "18.02341104", "1596666881.558587"]], "c": "2364683241"}, "book-100", "XBT/USD"]
[270, {"a": [["11673.70000", "0.25000000", "1596666881.562094"]], "c": "4264531322"}, "book-100", "XBT/USD"]
[270, {"b": [["11657.30000", "0.00000000", "1596666881.565294"], ["11615.60000", "0.20000000", "1596666623.308321", "r"]], "c": "4264531322"}, "book-100", "XBT/USD"]
[270, {"a": [["11677.30000", "0.32892643", "1596666881.568121"]], "c": "4264531322"}, "book-100", "XBT/USD"]
[270, {"a": [["11680.00000", "0.38000000", "1596666881.572863"]], "c": "4264531322"}, "book-100", "XBT/USD"]
[270, {"a": [["11681.00000", "0.66038881", "1596666881.579029"]], "c": "4264531322"}, "book-100", "XBT/USD"]
[270, {"a": [["11681.10000", "0.13417094", "1596666881.581132"]], "c": "4264531322"}, "book-100", "XBT/USD"]
[270, {"a": [["11677.10000", "0.00000000", "1596666881.582272"], ["11718.00000", "0.17085000", "1596666865.758675", "r"]], "c": "4264531322"}, "book-100", "XBT/USD"]
[270, {"b": [["11646.10000", "0.03100000", "1596666881.592600"]], "c": "4264531322"}, "book-100", "XBT/USD"]
[270, {"a": [["11669.50000", "0.85454216", "1596666881.594759"]], "c": "274870100"}, "book-100", "XBT/USD"]
[270, {"b": [["11621.30000", "0.00000000", "1596666881.598859"], ["11615.60000", "0.20000000", "1596666623.308321", "r"]], "c": "274870100"}, "book-100", "XBT/USD"]
[270, {"b": [["11657.20000", "0.85664954", "1596666881.630156"]], "c": "274870100"}, "book-100", "XBT/USD"]
[270, {"a": [["11680.40000", "0.11078149", "1596666881.631482"]], "c": "274870100"}, "book-100", "XBT/USD"]
[270, {"b": [["11660.60000", "0.00000000", "1596666881.640406"], ["11614.80000", "3.08717099", "1596666746.879208", "r"]], "c": "274870100"}, "book-100", "XBT/USD"]
[270, {"b": [["11644.70000", "0.05287327", "1596666881.642051"]], "c": "274870100"}, "book-100", "XBT/USD"]
[270, {"b": [["11647.70000", "0.00000000", "1596666881.646907"], ["11613.60000", "3.55198121", "1596666780.634357", "r"]], "c": "274870100"}, "book-100", "XBT/USD"]
[270, {"a": [["11679.60000", "1.59800000", "1596666881.660298"]], "c": "274870100"}, "book-100", "XBT/USD"]
[270, {"a": [["11708.70000", "0.30000000", "1596666881.676760"]], "c": "274870100"}, "book-100", "XBT/USD"]
[270, {"b": [["11664.50000", "0.78268000", "1596666881.696204"]], "c": "4184042682"}, "book-100", "XBT/USD"]
[270, {"a": [["11676.60000", "0.00000000", "1596666881.723314"], ["11715.30000", "6.10000000", "1596666635.445451", "r"]], "c": "4184042682"}, "book-100", "XBT/USD"]
[270, {"a": [["11679.00000", "0.88199000", "1596666881.725290"]], "c": "4184042682"}, "book-100", "XBT/USD"]
[270, {"b": [["11664.50000", "0.88268000", "1596666881.725604"]], "c": "4249538863"}, "book-100", "XBT/USD"]
[270, {"a": [["11679.70000", "2.64010575", "1596666881.742756"]], "c": "4249538863"}, "book-100", "XBT/USD"]
[270, {"a": [["11672.50000", "0.25831408", "1596666881.746686"]], "c": "2018178286"}, "book-100", "XBT/USD"]
[270, {"b": [["11660.00000", "0.00000000", "1596666881.756573"], ["11613.60000", "3.55198121", "1596666780.634357", "r"]], "c": "2018178286"}, "book-100", "XBT/USD"]
[270, {"a": [["11669.80000", "0.00000000", "1596666881.758893"], ["11714.80000", "1.99881632", "1596666809.038669", "r"]], "c": "3764625872"}, "book-100", "XBT/USD"]
[270, {"a": [["11680.50000", "0.01491094", "1596666881.779956"]], "c": "3764625872"}, "book-100", "XBT/USD"]
[270, {"a": [["11680.30000", "0.04472282", "1596666881.794838"]], "c": "3764625872"}, "book-100", "XBT/USD"]
[270, {"a": [["11681.10000", "0.00000000", "1596666881.797808"], ["11712.00000", "0.17085000", "1596666871.114258", "r"]], "c": "3764625872"}, "book-100", "XBT/USD"]
[270, {"a": [["11672.60000", "0.00000000", "1596666881.798531"], ["11714.80000", "1.99881632", "1596666809.038669", "r"]], "c": "737287541"}, "book-100", "XBT/USD"]
[270, {"a": [["11677.30000", "0.15000000", "1596666881.818279"]], "c": "737287541"}, "book-100", "XBT/USD"]
[270, {"a": [["11681.00000", "0.00000000", "1596666881.834748"], ["11715.30000", "6.10000000", "1596666635.445451", "r"]], "c": "737287541"}, "book-100", "XBT/USD"]
[270, {"a": [["11672.40000", "0.01000000", "1596666881.848139"]], "c": "1638433677"}, "book-100", "XBT/USD"]
[270, {"a": [["11673.70000", "0.00000000", "1596666881.850773"], ["11715.30000", "6.10000000", "1596666635.445451", "r"]], "c": "1184136164"}, "book-100", "XBT/USD"]
[270, {"a": [["11705.20000", "0.00000000", "1596666881.855477"], ["11717.80000", "1.99812614", "1596666759.535617", "r"]], "c": "1184136164"}, "book-100", "XBT/USD"]
[270, {"a": [["11681.80000", "0.07455260", "1596666881.862993"]], "c": "1184136164"}, "book-100", "XBT/USD"]
[270, {"b": [["11666.20000", "17.52341104", "1596666881.876716"]], "c": "3663483572"}, "book-100", "XBT/USD"]
[270, {"a": [["11676.40000", "2.49987264", "1596666881.952525"]], "c": "3663483572"}, "book-100", "XBT/USD"]
[270, {"a": [["11679.70000", "1.94071732", "1596666881.953839"]], "c": "3663483572"}, "book-100", "XBT/USD"]
[270, {"b": [["11650.60000", "1.21102986", "1596666881.956037"]], "c": "3663483572"}, "book-100", "XBT/USD"]
[270, {"a": [["11672.40000", "0.05250000", "1596666881.963734"]], "c": "2679144036"}, "book-100", "XBT/USD"]
[270, {"b": [["11662.60000", "0.04250000", "1596666881.963858"]], "c": "1749356914"}, "book-100", "XBT/USD"]
[270, {"a": [["11687.70000", "0.00000000", "1596666881.978673"], ["11717.80000", "1.99812614", "1596666759.535617", "r"]], "c": "1749356914"}, "book-100", "XBT/USD"]
[270, {"a": [["11671.90000", "0.25000000", "1596666881.993219"]], "c": "332005767"}, "book-100", "XBT/USD"]
[270, {"a": [["11679.30000", "0.17892071", "1596666882.004085"]], "c": "332005767"}, "book-100", "XBT/USD"]
[270, {"b": [["11665.30000", "0.50000000", "1596666882.017116"]], "c": "908505124"}, "book-100", "XBT/USD"]
[270, {"a": [["11682.40000", "1.15301370", "1596666882.021669"]], "c": "908505124"}, "book-100", "XBT/USD"]
[270, {"a": [["11681.70000", "0.13416532", "1596666882.033897"]], "c": "908505124"}, "book-100", "XBT/USD"]
[270, {"a": [["11681.50000", "1.21121607", "1596666882.083839"]], "c": "908505124"}, "book-100", "XBT/USD"]
[270, {"a": [["11682.40000", "1.85232189", "1596666882.097772"]], "c": "908505124"}, "book-100", "XBT/USD"]
[270, {"a": [["11677.60000", "0.59606651", "1596666882.139032"]], "c": "908505124"}, "book-100", "XBT/USD"]
[270, {"a": [["11678.20000", "0.00000000", "1596666882.161248"], ["11714.80000", "1.99881632", "1596666809.038669", "r"]], "c": "908505124"}, "book-100", "XBT/USD"]
[270, {"b": [["11661.90000", "0.33877696", "1596666882.176894"]], "c": "908505124"}, "book-100", "XBT/USD"]
[270, {"a": [["11684.30000", "1.96990000", "1596666882.218364"]], "c": "908505124"}, "book-100", "XBT/USD"]
[270, {"b": [["11619.00000", "7.17085000", "1596666882.357144"]], "c": "908505124"}, "book-100", "XBT/USD"]
[270, {"b": [["11657.60000", "1.00000000", "1596666882.367678"]], "c": "908505124"}, "book-100", "XBT/USD"]
[270, {"b": [["11658.50000", "0.71163909", "1596666882.388054"]], "c": "908505124"}, "book-100", "XBT/USD"]
[270, {"b": [["11648.50000", "1.28106298", "1596666882.392622"]], "c": "908505124"}, "book-100", "XBT/USD"]
[270, {"a": [["11671.90000", "0.00000000", "1596666882.421876"], ["11714.80000", "1.99881632", "1596666809.038669", "r"]], "c": "136178670"}, "book-100", "XBT/USD"]
[270, {"a": [["11709.00000", "0.17085000", "1596666882.556393"]], "c": "136178670"}, "book-100", "XBT/USD"]
[270, {"b": [["11648.20000", "0.00000000", "1596666882.583537"], ["11618.30000", "1.51500000", "1596666850.975183", "r"]], "c": "136178670"}, "book-100", "XBT/USD"]
[270, {"a": [["11680.60000", "0.00000000", "1596666882.585982"], ["11714.80000", "1.99881632", "1596666809.038669", "r"]], "c": "136178670"}, "book-100", "XBT/USD"]
[270, {"a": [["11684.00000", "0.00000000", "1596666882.586590"], ["11715.30000", "6.10000000", "1596666635.445451", "r"]], "c": "136178670"}, "book-100", "XBT/USD"]
[270, {"b": [["11649.30000", "0.00000000", "1596666882.589550"], ["11617.50000", "2.49761864", "1596666811.445738", "r"]], "c": "136178670"}, "book-100", "XBT/USD"]
[270, {"a": [["11680.40000", "0.00000000", "1596666882.602116"], ["11717.80000", "1.99812614", "1596666759.535617", "r"]], "c": "136178670"}, "book-100", "XBT/USD"]
[270, {"b": [["11655.30000", "0.00000000", "1596666882.602343"], ["11617.40000", "0.75800000", "1596666775.482846", "r"]], "c": "136178670"}, "book-100", "XBT/USD"]
[270, {"a": [["11672.70000", "0.25000000", "1596666882.605706"]], "c": "353789842"}, "book-100", "XBT/USD"]
[270, {"b": [["11652.20000", "0.00000000", "1596666882.607473"], ["11615.60000", "0.20000000", "1596666623.308321", "r"]], "c": "353789842"}, "book-100", "XBT/USD"]
[270, {"b": [["11646.20000", "0.00000000", "1596666882.607650"], ["11614.80000", "3.08717099", "1596666746.879208", "r"]], "c": "353789842"}, "book-100", "XBT/USD"]
[270, {"b": [["11652.10000", "0.00000000", "1596666882.617841"], ["11613.60000", "3.55198121", "1596666780.634357", "r"]], "c": "353789842"}, "book-100", "XBT/USD"]
[270, {"b": [["11649.20000", "0.00000000", "1596666882.622743"], ["11613.00000", "0.17085000", "1596666803.224745", "r"]], "c": "353789842"}, "book-100", "XBT/USD"]
[270, {"b": [["11655.80000", "0.00000000", "1596666882.634714"], ["11612.30000", "7.00000000", "1596666617.080387", "r"]], "c": "353789842"}, "book-100", "XBT/USD"]
[270, {"b": [["11658.50000", "0.00000000", "1596666882.636595"], ["11611.90000", "1.06000000", "1596666780.430510", "r"]], "c": "353789842"}, "book-100", "XBT/USD"]
[270, {"b": [["11655.10000", "0.00000000", "1596666882.640121"], ["11610.00000", "0.17085000", "1596666865.604704", "r"]], "c": "353789842"}, "book-100", "XBT/USD"]
[270, {"b": [["11661.90000", "0.00000000", "1596666882.643083"], ["11609.80000", "21.20000000", "1596666704.766154", "r"]], "c": "353789842"}, "book-100", "XBT/USD"]
[270, {"b": [["11654.90000", "0.00000000", "1596666882.646943"], ["11609.30000", "2.01627299", "1596666817.684177", "r"]], "c": "353789842"}, "book-100", "XBT/USD"]
[270, {"b": [["11647.90000", "0.00000000", "1596666882.649851"], ["11607.70000", "8.40000000", "1596666861.504830", "r"]], "c": "353789842"}, "book-100", "XBT/USD"]
[270, {"b": [["11657.40000", "0.00000000", "1596666882.697785"], ["11607.00000", "0.17085000", "1596666870.943401", "r"]], "c": "353789842"}, "book-100", "XBT/USD"]
[270, {"a": [["11675.20000", "0.00000000", "1596666882.839408"], ["11717.80000", "1.99812614", "1596666759.535617", "r"]], "c": "353789842"}, "book-100", "XBT/USD"]
[270, {"a": [["11676.40000", "0.08250000", "1596666882.839573"]], "c": "353789842"}, "book-100", "XBT/USD"]
[270, {"b": [["11658.30000", "0.72421786", "1596666882.841291"]], "c": "353789842"}, "book-100", "XBT/USD"]
[270, {"b": [["11660.60000", "0.10343929", "1596666882.867103"]], "c": "353789842"}, "book-100", "XBT/USD"]
[270, {"b": [["11651.70000", "3.20735937", "1596666882.962561"]], "c": "353789842"}, "book-100", "XBT/USD"]
[270, {"a": [["11682.50000", "0.11078149", "1596666882.980722"]], "c": "353789842"}, "book-100", "XBT/USD"]
[270, {"b": [["11651.70000", "5.21658189", "1596666883.045173"]], "c": "353789842"}, "book-100", "XBT/USD"]
[270, {"b": [["11657.90000", "0.24965234", "1596666883.069663"]], "c": "353789842"}, "book-100", "XBT/USD"]
[270, {"b": [["11655.60000", "0.85675312", "1596666883.071532"]], "c": "353789842"}, "book-100", "XBT/USD"]
[270, {"a": [["11682.40000", "1.15301370", "1596666883.087420"]], "c": "353789842"}, "book-100", "XBT/USD"]
[270, {"b": [["11657.70000", "0.90035188", "1596666883.119817"]], "c": "353789842"}, "book-100", "XBT/USD"]
[270, {"b": [["11655.30000", "3.53896968", "1596666883.136132"]], "c": "353789842"}, "book-100", "XBT/USD"]
[271, [["11666.20000", "0.02332600", "1596666883.144420", "s", "l", ""]], "trade", "XBT/USD"]
[270, {"b": [["11666.20000", "17.50008504", "1596666883.144420"]], "c": "1266975576"}, "book-100", "XBT/USD"]
[270, {"a": [["11674.80000", "1.70300000", "1596666883.160538"]], "c": "1266975576"}, "book-100", "XBT/USD"]
[270, {"a": [["11669.60000", "0.64271602", "1596666883.206304"]], "c": "3610040810"}, "book-100", "XBT/USD"]
[270, {"a": [["11683.20000", "0.85699787", "1596666883.206420"]], "c": "3610040810"}, "book-100", "XBT/USD"]
[270, {"a": [["11669.80000", "0.64278639", "1596666883.206933"]], "c": "2137080494"}, "book-100", "XBT/USD"]
[270, {"b": [["11665.60000", "1.23037602", "1596666883.208309"]], "c": "3297401886"}, "book-100", "XBT/USD"]
[270, {"a": [["11683.70000", "0.85695469", "1596666883.208398"]], "c": "3297401886"}, "book-100", "XBT/USD"]
[270, {"b": [["11664.20000", "0.73899733", "1596666883.208499"]], "c": "3759917039"}, "book-100", "XBT/USD"]
[270, {"b": [["11665.30000", "1.14268312", "1596666883.208833"]], "c": "811043245"}, "book-100", "XBT/USD"]
[270, {"b": [["11664.50000", "0.78268000", "1596666883.214852"]], "c": "1800532502"}, "book-100", "XBT/USD"]
[270, {"b": [["11654.90000", "0.49789162", "1596666883.224199"]], "c": "1800532502"}, "book-100", "XBT/USD"]
[270, {"b": [["11657.10000", "0.04472228", "1596666883.270969"]], "c": "1800532502"}, "book-100", "XBT/USD"]
[270, {"b": [["11660.60000", "0.00000000", "1596666883.283440"], ["11613.00000", "0.17085000", "1596666803.224745", "r"]], "c": "1800532502"}, "book-100", "XBT/USD"]
[270, {"b": [["11658.30000", "0.00000000", "1596666883.322979"], ["11612.30000", "7.00000000", "1596666617.080387", "r"]], "c": "1800532502"}, "book-100", "XBT/USD"]
[270, {"a": [["11690.60000", "0.00000000", "1596666883.362769"], ["11711.10000", "0.75800000", "1596666806.349295", "r"]], "c": "1800532502"}, "book-100", "XBT/USD"]
[270, {"a": [["11709.00000", "0.00000000", "1596666883.369976"], ["11711.50000", "1.99898326", "1596666797.632161", "r"]], "c": "1800532502"}, "book-100", "XBT/USD"]
[270, {"b": [["11650.00000", "8.09270076", "1596666883.375864"]], "c": "1800532502"}, "book-100", "XBT/USD"]
[270, {"a": [["11680.50000", "0.35314843", "1596666883.377164"]], "c": "1800532502"}, "book-100", "XBT/USD"]
[270, {"b": [["11653.10000", "0.38000000", "1596666883.476703"]], "c": "1800532502"}, "book-100", "XBT/USD"]
[270, {"a": [["11684.60000", "0.38000000", "1596666883.478569"]], "c": "1800532502"}, "book-100", "XBT/USD"]
[270, {"a": [["11672.70000", "0.00000000", "1596666883.529022"], ["11711.50000", "1.99898326", "1596666797.632161", "r"]], "c": "1423683339"}, "book-100", "XBT/USD"]
[270, {"b": [["11665.30000", "0.64268312", "1596666883.539040"]], "c": "442036515"}, "book-100", "XBT/USD"]
[270, {"b": [["11655.00000", "0.85691535", "1596666883.540487"]], "c": "442036515"}, "book-100", "XBT/USD"]
[270, {"b": [["11666.20000", "17.90008504", "1596666883.577310"]], "c": "3458863943"}, "book-100", "XBT/USD"]
[270, {"a": [["11688.00000", "0.49648161", "1596666883.654025"]], "c": "3458863943"}, "book-100", "XBT/USD"]
[270, {"a": [["11680.00000", "0.00000000", "1596666883.657060"], ["11711.50000", "1.99898326", "1596666797.632161", "r"]], "c": "3458863943"}, "book-100", "XBT/USD"]
[270, {"a": [["11682.50000", "0.00000000", "1596666883.657820"], ["11714.80000", "1.99881632", "1596666809.038669", "r"]], "c": "3458863943"}, "book-100", "XBT/USD"]
[270, {"b": [["11657.50000", "0.82543143", "1596666883.665967"]], "c": "3458863943"}, "book-100", "XBT/USD"]
[270, {"b": [["11655.20000", "0.72441048", "1596666883.671983"]], "c": "3458863943"}, "book-100", "XBT/USD"]
[270, {"b": [["11656.50000", "0.13417180", "1596666883.740445"]], "c": "3458863943"}, "book-100", "XBT/USD"]
[270, {"b": [["11664.60000", "0.50000000", "1596666883.742242"]], "c": "4240623218"}, "book-100", "XBT/USD"]
[270, {"a": [["11671.70000", "0.25000000", "1596666883.742404"]], "c": "2831522262"}, "book-100", "XBT/USD"]
[270, {"a": [["11708.50000", "0.00000000", "1596666883.768250"], ["11714.80000", "1.99881632", "1596666809.038669", "r"]], "c": "2831522262"}, "book-100", "XBT/USD"]
[270, {"a": [["11693.60000", "0.00000000", "1596666883.768929"], ["11715.30000", "6.10000000", "1596666635.445451", "r"]], "c": "2831522262"}, "book-100", "XBT/USD"]
[270, {"a": [["11697.10000", "0.00000000", "1596666883.775889"], ["11717.80000", "1.99812614", "1596666759.535617", "r"]], "c": "2831522262"}, "book-100", "XBT/USD"]
[270, {"a": [["11708.60000", "3.52225560", "1596666883.789196"]], "c": "2831522262"}, "book-100", "XBT/USD"]
[270, {"a": [["11672.50000", "0.00000000", "1596666883.819764"], ["11718.00000", "0.17085000", "1596666865.758675", "r"]], "c": "1893658259"}, "book-100", "XBT/USD"]
[270, {"a": [["11672.40000", "0.04250000", "1596666883.870398"]], "c": "2259704129"}, "book-100", "XBT/USD"]
[270, {"a": [["11680.30000", "0.15550431", "1596666883.895080"]], "c": "2259704129"}, "book-100", "XBT/USD"]
[270, {"a": [["11672.60000", "0.01000000", "1596666883.921645"]], "c": "4174887268"}, "book-100", "XBT/USD"]
[270, {"a": [["11671.60000", "0.25832208", "1596666883.935167"]], "c": "100571602"}, "book-100", "XBT/USD"]
[270, {"a": [["11676.40000", "2.90964388", "1596666883.943547"]], "c": "100571602"}, "book-100", "XBT/USD"]
[270, {"a": [["11679.60000", "0.09800000", "1596666883.971574"]], "c": "100571602"}, "book-100", "XBT/USD"]
[270, {"b": [["11660.70000", "0.00000000", "1596666883.971884"], ["11614.80000", "3.08717099", "1596666746.879208", "r"]], "c": "100571602"}, "book-100", "XBT/USD"]
[270, {"a": [["11693.70000", "0.57244248", "1596666884.018725"]], "c": "100571602"}, "book-100", "XBT/USD"]
[270, {"a": [["11679.70000", "0.00000000", "1596666884.091089"], ["11715.30000", "6.10000000", "1596666635.445451", "r"]], "c": "100571602"}, "book-100", "XBT/USD"]
[270, {"a": [["11702.80000", "2.67052797", "1596666884.109130"]], "c": "100571602"}, "book-100", "XBT/USD"]
[270, {"a": [["11675.80000", "1.50000000", "1596666884.121448"]], "c": "100571602"}, "book-100", "XBT/USD"]
[270, {"b": [["11662.20000", "1.50000000", "1596666884.123075"]], "c": "100571602"}, "book-100", "XBT/USD"]
[270, {"a": [["11683.70000", "0.00000000", "1596666884.123884"], ["11715.30000", "6.10000000", "1596666635.445451", "r"]], "c": "100571602"}, "book-100", "XBT/USD"]
[270, {"b": [["11666.20000", "16.20008504", "1596666884.128130"]], "c": "1781390552"}, "book-100", "XBT/USD"]
[270, {"b": [["11648.50000", "0.90106298", "1596666884.460310"]], "c": "1781390552"}, "book-100", "XBT/USD"]
[270, {"b": [["11665.60000", "0.84037602", "1596666884.555607"]], "c": "1811429989"}, "book-100", "XBT/USD"]
[270, {"b": [["11622.20000", "0.00000000", "1596666884.580239"], ["11614.80000", "3.08717099", "1596666746.879208", "r"]], "c": "1811429989"}, "book-100", "XBT/USD"]
[270, {"b": [["11622.90000", "0.74859951", "1596666884.661654"]], "c": "1811429989"}, "book-100", "XBT/USD"]
[270, {"a": [["11687.40000", "1.64686784", "1596666884.661777"]], "c": "1811429989"}, "book-100", "XBT/USD"]
[270, {"b": [["11662.50000", "0.00000000", "1596666884.673038"], ["11614.80000", "3.08717099", "1596666746.879208", "r"]], "c": "1811429989"}, "book-100", "XBT/USD"]
[270, {"a": [["11671.40000", "0.10300000", "1596666884.752618"]], "c": "391139393"}, "book-100", "XBT/USD"]
[270, {"b": [["11664.50000", "0.00000000", "1596666884.872322"], ["11613.60000", "3.55198121", "1596666780.634357", "r"]], "c": "3558400575"}, "book-100", "XBT/USD"]
[270, {"a": [["11676.20000", "0.77093000", "1596666884.873397"]], "c": "3558400575"}, "book-100", "XBT/USD"]
[270, {"b": [["11662.00000", "10.09987003", "1596666884.894448"]], "c": "3558400575"}, "book-100", "XBT/USD"]
[270, {"a": [["11669.40000", "0.20500000", "1596666885.135709"]], "c": "2718546474"}, "book-100", "XBT/USD"]
[270, {"a": [["11669.50000", "0.00000000", "1596666885.143464"], ["11711.50000", "1.99898326", "1596666797.632161", "r"]], "c": "2554800333"}, "book-100", "XBT/USD"]
[270, {"b": [["11662.00000", "0.10000000", "1596666885.290249"]], "c": "2554800333"}, "book-100", "XBT/USD"]
[270, {"a": [["11670.60000", "2.77006920", "1596666885.367106"]], "c": "85437989"}, "book-100", "XBT/USD"]
[270, {"a": [["11689.70000", "0.00000000", "1596666885.424386"], ["11714.80000", "1.99881632", "1596666809.038669", "r"]], "c": "85437989"}, "book-100", "XBT/USD"]
[270, {"a": [["11674.80000", "0.00000000", "1596666885.533396"], ["11715.30000", "6.10000000", "1596666635.445451", "r"]], "c": "85437989"}, "book-100", "XBT/USD"]
[270, {"a": [["11674.60000", "1.79721094", "1596666885.539838"]], "c": "85437989"}, "book-100", "XBT/USD"]
[271, [["11666.20000", "0.02332600", "1596666885.567126", "s", "l", ""]], "trade", "XBT/USD"]
[270, {"b": [["11666.20000", "16.17675904", "1596666885.567126"]], "c": "2571396819"}, "book-100", "XBT/USD"]
[270, {"a": [["11689.60000", "0.00000000", "1596666885.659056"], ["11717.80000", "1.99812614", "1596666759.535617", "r"]], "c": "2571396819"}, "book-100", "XBT/USD"]
[270, {"a": [["11705.70000", "0.00000000", "1596666885.659654"], ["11718.00000", "0.17085000", "1596666865.758675", "r"]], "c": "2571396819"}, "book-100", "XBT/USD"]
[270, {"a": [["11687.40000", "0.74859951", "1596666885.661725"]], "c": "2571396819"}, "book-100", "XBT/USD"]
[270, {"a": [["11690.90000", "0.00000000", "1596666885.668150"], ["11718.40000", "0.48360000", "1596666846.374528", "r"]], "c": "2571396819"}, "book-100", "XBT/USD"]
[270, {"b": [["11661.50000", "11.03585440", "1596666885.705333"]], "c": "2571396819"}, "book-100", "XBT/USD"]
[270, {"a": [["11692.10000", "0.61106020", "1596666885.846076"]], "c": "2571396819"}, "book-100", "XBT/USD"]
[270, {"b": [["11661.50000", "1.03598437", "1596666885.846142"]], "c": "2571396819"}, "book-100", "XBT/USD"]
[270, {"a": [["11700.20000", "0.89705684", "1596666885.896079"]], "c": "2571396819"}, "book-100", "XBT/USD"]
[270, {"a": [["11688.50000", "0.89795478", "1596666885.896508"]], "c": "2571396819"}, "book-100", "XBT/USD"]
[270, {"a": [["11685.00000", "0.99822374", "1596666885.897175"]], "c": "2571396819"}, "book-100", "XBT/USD"]
[270, {"a": [["11680.50000", "0.01491094", "1596666885.960251"]], "c": "2571396819"}, "book-100", "XBT/USD"]
[270, {"b": [["11657.50000", "0.28243143", "1596666885.974150"]], "c": "2571396819"}, "book-100", "XBT/USD"]
[270, {"a": [["11699.50000", "0.00000000", "1596666885.995101"], ["11717.80000", "1.99812614", "1596666759.535617", "r"]], "c": "2571396819"}, "book-100", "XBT/USD"]
[270, {"a": [["11671.60000", "0.00000000", "1596666885.998446"], ["11718.00000", "0.17085000", "1596666865.758675", "r"]], "c": "1794947811"}, "book-100", "XBT/USD"]
[270, {"a": [["11708.60000", "0.00000000", "1596666886.075533"], ["11718.40000", "0.48360000", "1596666846.374528", "r"]], "c": "1794947811"}, "book-100", "XBT/USD"]
[270, {"b": [["11652.00000", "0.76200000", "1596666886.085237"]], "c": "1794947811"}, "book-100", "XBT/USD"]
[270, {"a": [["11674.60000", "0.09621094", "1596666886.100566"]], "c": "1794947811"}, "book-100", "XBT/USD"]
[270, {"a": [["11671.30000", "0.25832185", "1596666886.100792"]], "c": "697382190"}, "book-100", "XBT/USD"]
[270, {"a": [["11680.30000", "0.04472282", "1596666886.126110"]], "c": "697382190"}, "book-100", "XBT/USD"]
[270, {"a": [["11668.40000", "0.64273283", "1596666886.126945"]], "c": "3813325834"}, "book-100", "XBT/USD"]
[270, {"a": [["11669.40000", "0.00000000", "1596666886.145533"], ["11718.00000", "0.17085000", "1596666865.758675", "r"]], "c": "4011076279"}, "book-100", "XBT/USD"]
[270, {"b": [["11650.70000", "0.00438367", "1596666886.159857"]], "c": "4011076279"}, "book-100", "XBT/USD"]
[270, {"a": [["11687.90000", "0.00438186", "1596666886.161236"]], "c": "4011076279"}, "book-100", "XBT/USD"]
[270, {"b": [["11662.50000", "9.99987003", "1596666886.247338"]], "c": "4011076279"}, "book-100", "XBT/USD"]
[270, {"a": [["11679.10000", "0.11078149", "1596666886.347885"]], "c": "4011076279"}, "book-100", "XBT/USD"]
[270, {"a": [["11674.80000", "1.70000000", "1596666886.362465"]], "c": "4011076279"}, "book-100", "XBT/USD"]
[270, {"b": [["11661.70000", "1.19568670", "1596666886.596211"]], "c": "4011076279"}, "book-100", "XBT/USD"]
[270, {"b": [["11658.30000", "0.71162732", "1596666886.598845"]], "c": "4011076279"}, "book-100", "XBT/USD"]
[270, {"b": [["11650.20000", "1.79726051", "1596666886.599775"]], "c": "4011076279"}, "book-100", "XBT/USD"]
[270, {"b": [["11656.00000", "1.42353548", "1596666886.602438"]], "c": "4011076279"}, "book-100", "XBT/USD"]
[270, {"a": [["11682.70000", "0.71014104", "1596666886.604678"]], "c": "4011076279"}, "book-100", "XBT/USD"]
[270, {"a": [["11679.30000", "0.51718155", "1596666886.640625"]], "c": "4011076279"}, "book-100", "XBT/USD"]
[271, [["11666.20000", "0.02332600", "1596666887.263214", "s", "l", ""]], "trade", "XBT/USD"]
[270, {"b": [["11666.20000", "16.15343304", "1596666887.263214"]], "c": "1575062981"}, "book-100", "XBT/USD"]
[270, {"b": [["11659.80000", "0.00000000", "1596666887.356052"], ["11618.30000", "1.51500000", "1596666850.975183", "r"]], "c": "1575062981"}, "book-100", "XBT/USD"]
[270, {"b": [["11657.50000", "0.10346679", "1596666887.357283"]], "c": "1575062981"}, "book-100", "XBT/USD"]
[270, {"b": [["11657.80000", "0.00000000", "1596666887.357358"], ["11617.50000", "2.49761864", "1596666811.445738", "r"]], "c": "1575062981"}, "book-100", "XBT/USD"]
[270, {"b": [["11661.00000", "0.00000000", "1596666887.489348"], ["11617.40000", "0.75800000", "1596666775.482846", "r"]], "c": "1575062981"}, "book-100", "XBT/USD"]
[270, {"a": [["11676.40000", "2.82714388", "1596666887.489771"]], "c": "1575062981"}, "book-100", "XBT/USD"]
[270, {"b": [["11665.40000", "0.09621094", "1596666887.636538"]], "c": "3708116715"}, "book-100", "XBT/USD"]
[270, {"b": [["11664.20000", "0.64278639", "1596666887.673583"]], "c": "2466781616"}, "book-100", "XBT/USD"]
[270, {"b": [["11622.00000", "0.17085000", "1596666887.732661"]], "c": "2466781616"}, "book-100", "XBT/USD"]
[270, {"a": [["11687.90000", "0.00000000", "1596666887.763543"], ["11714.80000", "1.99881632", "1596666809.038669", "r"]], "c": "2466781616"}, "book-100", "XBT/USD"]
[270, {"b": [["11665.70000", "1.25000000", "1596666887.807136"]], "c": "590304588"}, "book-100", "XBT/USD"]
[270, {"b": [["11662.60000", "0.12500000", "1596666887.853183"]], "c": "590304588"}, "book-100", "XBT/USD"]
[270, {"a": [["11679.30000", "0.17892071", "1596666887.884844"]], "c": "590304588"}, "book-100", "XBT/USD"]
[270, {"a": [["11712.00000", "0.17085000", "1596666887.891015"]], "c": "590304588"}, "book-100", "XBT/USD"]
[270, {"b": [["11661.70000", "0.85691535", "1596666887.893142"]], "c": "590304588"}, "book-100", "XBT/USD"]
[270, {"a": [["11701.30000", "0.08250000", "1596666887.893247"]], "c": "590304588"}, "book-100", "XBT/USD"]
[270, {"b": [["11658.30000", "0.00000000", "1596666887.899732"], ["11618.30000", "1.51500000", "1596666850.975183", "r"]], "c": "590304588"}, "book-100", "XBT/USD"]
[270, {"b": [["11655.20000", "0.00000000", "1596666887.920826"], ["11617.50000", "2.49761864", "1596666811.445738", "r"]], "c": "590304588"}, "book-100", "XBT/USD"]
[270, {"b": [["11657.50000", "0.00000000", "1596666887.920917"], ["11617.40000", "0.75800000", "1596666775.482846", "r"]], "c": "590304588"}, "book-100", "XBT/USD"]
[270, {"b": [["11650.70000", "0.00000000", "1596666887.952928"], ["11615.60000", "0.20000000", "1596666623.308321", "r"]], "c": "590304588"}, "book-100", "XBT/USD"]
[270, {"a": [["11687.40000", "4.27754672", "1596666888.091817"]], "c": "590304588"}, "book-100", "XBT/USD"]
[270, {"a": [["11702.50000", "3.52439373", "1596666888.099480"]], "c": "590304588"}, "book-100", "XBT/USD"]
[270, {"b": [["11648.80000", "3.54064089", "1596666888.100685"]], "c": "590304588"}, "book-100", "XBT/USD"]
[270, {"b": [["11656.90000", "0.72437808", "1596666888.105210"]], "c": "590304588"}, "book-100", "XBT/USD"]
[270, {"b": [["11659.30000", "0.10346128", "1596666888.108539"]], "c": "590304588"}, "book-100", "XBT/USD"]
[270, {"a": [["11671.30000", "0.00000000", "1596666888.168607"], ["11711.50000", "1.99898326", "1596666797.632161", "r"]], "c": "2301179816"}, "book-100", "XBT/USD"]
[270, {"b": [["11659.30000", "0.81502756", "1596666888.273056"]], "c": "2301179816"}, "book-100", "XBT/USD"]
[270, {"b": [["11662.70000", "0.33874231", "1596666888.273720"]], "c": "2301179816"}, "book-100", "XBT/USD"]
[270, {"b": [["11662.50000", "0.00000000", "1596666888.274665"], ["11618.30000", "1.51500000", "1596666850.975183", "r"]], "c": "2301179816"}, "book-100", "XBT/USD"]
[270, {"a": [["11670.90000", "0.25833237", "1596666888.277816"]], "c": "2692132082"}, "book-100", "XBT/USD"]
[270, {"b": [["11648.60000", "0.00000000", "1596666888.340925"], ["11617.50000", "2.49761864", "1596666811.445738", "r"]], "c": "2692132082"}, "book-100", "XBT/USD"]
[270, {"a": [["11671.70000", "0.00000000", "1596666888.538103"], ["11711.50000", "1.99898326", "1596666797.632161", "r"]], "c": "854584685"}, "book-100", "XBT/USD"]
[270, {"a": [["11679.30000", "0.51718155", "1596666888.549055"]], "c": "854584685"}, "book-100", "XBT/USD"]
[270, {"a": [["11681.50000", "7.21121607", "1596666888.567088"]], "c": "854584685"}, "book-100", "XBT/USD"]
[270, {"b": [["11648.90000", "4.00000000", "1596666888.571654"]], "c": "854584685"}, "book-100", "XBT/USD"]
[270, {"b": [["11664.60000", "0.00000000", "1596666888.577759"], ["11617.50000", "2.49761864", "1596666811.445738", "r"]], "c": "3837158954"}, "book-100", "XBT/USD"]
[270, {"b": [["11662.60000", "0.08250000", "1596666888.666348"]], "c": "3837158954"}, "book-100", "XBT/USD"]
[270, {"a": [["11672.40000", "0.00000000", "1596666888.668116"], ["11712.00000", "0.17085000", "1596666887.891015", "r"]], "c": "1553745094"}, "book-100", "XBT/USD"]
[270, {"b": [["11665.80000", "5.98400000", "1596666888.677167"]], "c": "1409993595"}, "book-100", "XBT/USD"]
[270, {"a": [["11670.60000", "3.02006920", "1596666888.677753"]], "c": "2010586522"}, "book-100", "XBT/USD"]
[270, {"a": [["11674.00000", "1.73163402", "1596666888.689457"]], "c": "2010586522"}, "book-100", "XBT/USD"]
[270, {"a": [["11702.50000", "9.91072811", "1596666888.698590"]], "c": "2010586522"}, "book-100", "XBT/USD"]
[270, {"a": [["11690.90000", "3.19633553", "1596666888.703619"]], "c": "2010586522"}, "book-100", "XBT/USD"]
[270, {"a": [["11666.30000", "0.12095825", "1596666888.731996"]], "c": "2824739973"}, "book-100", "XBT/USD"]
[270, {"a": [["11708.00000", "0.00000000", "1596666888.752917"], ["11712.00000", "0.17085000", "1596666887.891015", "r"]], "c": "2824739973"}, "book-100", "XBT/USD"]
[270, {"a": [["11686.30000", "2.14276975", "1596666888.757436"]], "c": "2824739973"}, "book-100", "XBT/USD"]
[270, {"a": [["11693.40000", "7.07010194", "1596666888.763357"]], "c": "2824739973"}, "book-100", "XBT/USD"]
[270, {"a": [["11684.10000", "0.00000000", "1596666888.772323"], ["11714.80000", "1.99881632", "1596666809.038669", "r"]], "c": "2824739973"}, "book-100", "XBT/USD"]
[270, {"a": [["11686.30000", "1.42001206", "1596666888.774372"]], "c": "2824739973"}, "book-100", "XBT/USD"]
[270, {"a": [["11700.10000", "0.00000000", "1596666888.774933"], ["11715.30000", "6.10000000", "1596666635.445451", "r"]], "c": "2824739973"}, "book-100", "XBT/USD"]
[270, {"a": [["11689.90000", "0.10000000", "1596666888.778593"]], "c": "2824739973"}, "book-100", "XBT/USD"]
[270, {"a": [["11679.10000", "0.00000000", "1596666888.780144"], ["11717.80000", "1.99812614", "1596666759.535617", "r"]], "c": "2824739973"}, "book-100", "XBT/USD"]
[270, {"a": [["11695.90000", "0.00000000", "1596666888.785562"], ["11718.00000", "0.17085000", "1596666865.758675", "r"]], "c": "2824739973"}, "book-100", "XBT/USD"]
[270, {"a": [["11714.80000", "0.00000000", "1596666888.786246"], ["11718.40000", "0.48360000", "1596666846.374528", "r"]], "c": "2824739973"}, "book-100", "XBT/USD"]
[270, {"b": [["11662.70000", "0.00000000", "1596666888.798704"], ["11617.40000", "0.75800000", "1596666775.482846", "r"]], "c": "2824739973"}, "book-100", "XBT/USD"]
[270, {"a": [["11674.00000", "0.02763402", "1596666888.809568"]], "c": "2824739973"}, "book-100", "XBT/USD"]
[270, {"a": [["11668.30000", "0.18000000", "1596666888.821774"]], "c": "102083570"}, "book-100", "XBT/USD"]
[270, {"a": [["11695.80000", "0.00000000", "1596666888.830548"], ["11718.40000", "0.48360000", "1596666846.374528", "r"]], "c": "102083570"}, "book-100", "XBT/USD"]
[270, {"a": [["11681.80000", "0.00000000", "1596666888.881921"], ["11718.50000", "24.30000000", "1596666641.380470", "r"]], "c": "102083570"}, "book-100", "XBT/USD"]
[270, {"a": [["11680.50000", "0.00000000", "1596666888.882269"], ["11719.60000", "2.98021891", "1596666782.974175", "r"]], "c": "102083570"}, "book-100", "XBT/USD"]
[270, {"b": [["11661.80000", "0.04250000", "1596666888.903903"]], "c": "102083570"}, "book-100", "XBT/USD"]
[270, {"a": [["11680.30000", "0.00000000", "1596666888.925556"], ["11719.70000", "3.50602221", "1596666789.365232", "r"]], "c": "102083570"}, "book-100", "XBT/USD"]
[270, {"a": [["11671.30000", "0.04250000", "1596666888.938539"]], "c": "3748205055"}, "book-100", "XBT/USD"]
[270, {"a": [["11679.10000", "0.11078149", "1596666888.982268"]], "c": "3748205055"}, "book-100", "XBT/USD"]
[270, {"a": [["11688.50000", "1.24654129", "1596666889.003221"]], "c": "3748205055"}, "book-100", "XBT/USD"]
[270, {"a": [["11685.00000", "1.24728869", "1596666889.003355"]], "c": "3748205055"}, "book-100", "XBT/USD"]
[270, {"a": [["11692.90000", "0.99253037", "1596666889.050049"]], "c": "3748205055"}, "book-100", "XBT/USD"]
[270, {"a": [["11679.30000", "0.33826084", "1596666889.059867"]], "c": "3748205055"}, "book-100", "XBT/USD"]
[270, {"a": [["11708.20000", "1.99935679", "1596666889.096786"]], "c": "3748205055"}, "book-100", "XBT/USD"]
[270, {"a": [["11696.50000", "2.00135674", "1596666889.096876"]], "c": "3748205055"}, "book-100", "XBT/USD"]
[270, {"b": [["11623.10000", "0.74859575", "1596666889.101882"]], "c": "3748205055"}, "book-100", "XBT/USD"]
[270, {"a": [["11687.40000", "3.52894721", "1596666889.102127"]], "c": "3748205055"}, "book-100", "XBT/USD"]
[270, {"b": [["11622.90000", "0.00000000", "1596666889.102840"], ["11617.50000", "2.49761864", "1596666811.445738", "r"]], "c": "3748205055"}, "book-100", "XBT/USD"]
[270, {"a": [["11705.10000", "2.24680437", "1596666889.104909"]], "c": "3748205055"}, "book-100", "XBT/USD"]
[270, {"a": [["11687.60000", "0.74859575", "1596666889.106505"]], "c": "3748205055"}, "book-100", "XBT/USD"]
[270, {"a": [["11674.80000", "0.00000000", "1596666889.112748"], ["11715.30000", "6.10000000", "1596666635.445451", "r"]], "c": "3748205055"}, "book-100", "XBT/USD"]
[270, {"b": [["11663.50000", "0.50000000", "1596666889.113523"]], "c": "3748205055"}, "book-100", "XBT/USD"]
[270, {"a": [["11693.40000", "0.00000000", "1596666889.115755"], ["11717.80000", "1.99812614", "1596666759.535617", "r"]], "c": "3748205055"}, "book-100", "XBT/USD"]
[270, {"a": [["11686.30000", "0.00000000", "1596666889.120476"], ["11718.00000", "0.17085000", "1596666865.758675", "r"]], "c": "3748205055"}, "book-100", "XBT/USD"]
[270, {"b": [["11662.00000", "10.09987003", "1596666889.132137"]], "c": "3748205055"}, "book-100", "XBT/USD"]
[270, {"a": [["11677.90000", "0.04472746", "1596666889.132219"]], "c": "3748205055"}, "book-100", "XBT/USD"]
[270, {"a": [["11681.70000", "0.00000000", "1596666889.132629"], ["11718.00000", "0.17085000", "1596666865.758675", "r"]], "c": "3748205055"}, "book-100", "XBT/USD"]
[270, {"a": [["11693.20000", "0.89759385", "1596666889.133439"]], "c": "3748205055"}, "book-100", "XBT/USD"]
[270, {"a": [["11684.70000", "0.72265466", "1596666889.273973"]], "c": "3748205055"}, "book-100", "XBT/USD"]
[270, {"a": [["11713.90000", "2.30673040", "1596666889.279950"]], "c": "3748205055"}, "book-100", "XBT/USD"]
[270, {"b": [["11661.80000", "0.38126845", "1596666889.306925"]], "c": "3748205055"}, "book-100", "XBT/USD"]
[270, {"a": [["11679.70000", "0.13418238", "1596666889.315091"]], "c": "3748205055"}, "book-100", "XBT/USD"]
[271, [["11666.20000", "0.02332600", "1596666889.334461", "s", "l", ""]], "trade", "XBT/USD"]
[270, {"b": [["11666.20000", "16.13010704", "1596666889.334461"]], "c": "1024360279"}, "book-100", "XBT/USD"]
[270, {"a": [["11682.40000", "1.25627040", "1596666889.637920"]], "c": "1024360279"}, "book-100", "XBT/USD"]
[270, {"b": [["11662.00000", "0.10000000", "1596666890.004186"]], "c": "1024360279"}, "book-100", "XBT/USD"]
[270, {"b": [["11661.50000", "11.03585440", "1596666890.358314"]], "c": "1024360279"}, "book-100", "XBT/USD"]
[270, {"a": [["11670.50000", "0.86083543", "1596666890.639867"]], "c": "672912784"}, "book-100", "XBT/USD"]
[270, {"a": [["11670.90000", "0.00000000", "1596666890.779910"], ["11713.90000", "2.30673040", "1596666889.279950", "r"]], "c": "3883751264"}, "book-100", "XBT/USD"]
[270, {"a": [["11705.30000", "0.00000000", "1596666891.133141"], ["11715.30000", "6.10000000", "1596666635.445451", "r"]], "c": "3883751264"}, "book-100", "XBT/USD"]
[270, {"a": [["11673.90000", "1.71300000", "1596666891.166711"]], "c": "3883751264"}, "book-100", "XBT/USD"]
[270, {"a": [["11670.50000", "0.60250000", "1596666891.562402"]], "c": "4066966951"}, "book-100", "XBT/USD"]
[270, {"b": [["11666.20000", "15.73010704", "1596666891.578343"]], "c": "297253837"}, "book-100", "XBT/USD"]
[270, {"b": [["11661.50000", "1.03598437", "1596666891.710514"]], "c": "297253837"}, "book-100", "XBT/USD"]
[270, {"a": [["11670.90000", "0.25832648", "1596666891.945799"]], "c": "3048811058"}, "book-100", "XBT/USD"]
[270, {"b": [["11662.00000", "10.09987003", "1596666892.089069"]], "c": "3048811058"}, "book-100", "XBT/USD"]
[270, {"b": [["11663.50000", "0.00000000", "1596666892.133813"], ["11617.50000", "2.49761864", "1596666811.445738", "r"]], "c": "3048811058"}, "book-100", "XBT/USD"]
[270, {"a": [["11670.60000", "2.77006920", "1596666892.139839"]], "c": "509911183"}, "book-100", "XBT/USD"]
[270, {"a": [["11673.90000", "0.00000000", "1596666892.142840"], ["11713.90000", "2.30673040", "1596666889.279950", "r"]], "c": "509911183"}, "book-100", "XBT/USD"]
[270, {"b": [["11665.50000", "0.50000000", "1596666892.273794"]], "c": "1530778013"}, "book-100", "XBT/USD"]
[270, {"b": [["11662.00000", "0.10000000", "1596666892.285287"]], "c": "1530778013"}, "book-100", "XBT/USD"]
[270, {"a": [["11670.90000", "0.00000000", "1596666892.300470"], ["11715.30000", "6.10000000", "1596666635.445451", "r"]], "c": "4281548898"}, "book-100", "XBT/USD"]
[270, {"a": [["11671.30000", "0.30081731", "1596666892.322330"]], "c": "316965241"}, "book-100", "XBT/USD"]
[270, {"a": [["11672.80000", "1.10706932", "1596666892.367958"]], "c": "316965241"}, "book-100", "XBT/USD"]
[270, {"a": [["11668.40000", "0.00000000", "1596666892.369119"], ["11717.80000", "1.99812614", "1596666759.535617", "r"]], "c": "3202788446"}, "book-100", "XBT/USD"]
[270, {"a": [["11683.90000", "1.56250179", "1596666892.425529"]], "c": "3202788446"}, "book-100", "XBT/USD"]
[270, {"b": [["11666.20000", "16.13010704", "1596666892.445240"]], "c": "1564076596"}, "book-100", "XBT/USD"]
[270, {"b": [["11662.50000", "9.99987003", "1596666892.550513"]], "c": "1564076596"}, "book-100", "XBT/USD"]
[270, {"a": [["11670.60000", "1.91435754", "1596666892.579204"]], "c": "3228134620"}, "book-100", "XBT/USD"]
[270, {"a": [["11668.30000", "0.00000000", "1596666892.630596"], ["11718.00000", "0.17085000", "1596666865.758675", "r"]], "c": "3430399401"}, "book-100", "XBT/USD"]
[270, {"b": [["11661.80000", "0.04250000", "1596666892.692135"]], "c": "3430399401"}, "book-100", "XBT/USD"]
[270, {"b": [["11656.00000", "0.00000000", "1596666892.735048"], ["11618.30000", "1.51500000", "1596666850.975183", "r"]], "c": "3430399401"}, "book-100", "XBT/USD"]
[270, {"a": [["11671.70000", "0.84755556", "1596666892.813198"]], "c": "1171213065"}, "book-100", "XBT/USD"]
[270, {"a": [["11683.90000", "0.70560000", "1596666892.849030"]], "c": "1171213065"}, "book-100", "XBT/USD"]
[270, {"a": [["11671.30000", "0.04250000", "1596666892.897169"]], "c": "3779527964"}, "book-100", "XBT/USD"]
[270, {"a": [["11672.50000", "0.25830648", "1596666892.913410"]], "c": "3251450655"}, "book-100", "XBT/USD"]
[270, {"a": [["11672.60000", "0.00000000", "1596666892.976496"], ["11717.80000", "1.99812614", "1596666759.535617", "r"]], "c": "3251450655"}, "book-100", "XBT/USD"]
[270, {"b": [["11655.00000", "0.00000000", "1596666892.983666"], ["11617.50000", "2.49761864", "1596666811.445738", "r"]], "c": "3251450655"}, "book-100", "XBT/USD"]
[270, {"b": [["11663.40000", "0.87716000", "1596666893.015048"]], "c": "3251450655"}, "book-100", "XBT/USD"]
[270, {"b": [["11657.10000", "0.00000000", "1596666893.086295"], ["11617.50000", "2.49761864", "1596666811.445738", "r"]], "c": "3251450655"}, "book-100", "XBT/USD"]
[270, {"b": [["11665.50000", "0.00000000", "1596666893.093688"], ["11617.40000", "0.75800000", "1596666775.482846", "r"]], "c": "2224308749"}, "book-100", "XBT/USD"]
[270, {"b": [["11656.50000", "0.00000000", "1596666893.157464"], ["11616.00000", "0.17085000", "1596666893.083885", "r"]], "c": "2224308749"}, "book-100", "XBT/USD"]
[270, {"a": [["11675.80000", "0.00000000", "1596666893.179492"], ["11718.00000", "0.17085000", "1596666865.758675", "r"]], "c": "2224308749"}, "book-100", "XBT/USD"]
[270, {"a": [["11672.40000", "0.01000000", "1596666893.192152"]], "c": "1252183097"}, "book-100", "XBT/USD"]
[270, {"a": [["11686.30000", "1.42013170", "1596666893.252600"]], "c": "1252183097"}, "book-100", "XBT/USD"]
[270, {"a": [["11715.00000", "0.17085000", "1596666893.351638"]], "c": "1252183097"}, "book-100", "XBT/USD"]
[270, {"a": [["11677.70000", "3.50000000", "1596666893.358351"]], "c": "1252183097"}, "book-100", "XBT/USD"]
[270, {"b": [["11665.60000", "1.34037602", "1596666893.368276"]], "c": "572693608"}, "book-100", "XBT/USD"]
[270, {"b": [["11663.40000", "1.21595048", "1596666893.386584"]], "c": "572693608"}, "book-100", "XBT/USD"]
[270, {"a": [["11679.30000", "0.00000000", "1596666893.387713"], ["11715.30000", "6.10000000", "1596666635.445451", "r"]], "c": "572693608"}, "book-100", "XBT/USD"]
[270, {"a": [["11671.40000", "0.00000000", "1596666893.401097"], ["11717.80000", "1.99812614", "1596666759.535617", "r"]], "c": "3060718911"}, "book-100", "XBT/USD"]
[270, {"b": [["11666.20000", "16.38840853", "1596666893.408605"]], "c": "1236081275"}, "book-100", "XBT/USD"]
[270, {"a": [["11692.10000", "2.40224218", "1596666893.426408"]], "c": "1236081275"}, "book-100", "XBT/USD"]
[270, {"b": [["11657.70000", "2.32396761", "1596666893.450253"]], "c": "1236081275"}, "book-100", "XBT/USD"]
[270, {"a": [["11676.20000", "0.00000000", "1596666893.601496"], ["11718.00000", "0.17085000", "1596666865.758675", "r"]], "c": "1236081275"}, "book-100", "XBT/USD"]
[270, {"b": [["11665.60000", "0.84037602", "1596666893.689857"]], "c": "2926914409"}, "book-100", "XBT/USD"]
[270, {"a": [["11672.80000", "0.85706932", "1596666893.691976"]], "c": "2926914409"}, "book-100", "XBT/USD"]
[270, {"a": [["11680.40000", "0.33829739", "1596666893.842438"]], "c": "2926914409"}, "book-100", "XBT/USD"]
[270, {"b": [["11664.60000", "0.50000000", "1596666893.846078"]], "c": "2016190510"}, "book-100", "XBT/USD"]
[270, {"a": [["11671.80000", "0.25000000", "1596666893.856361"]], "c": "2413081262"}, "book-100", "XBT/USD"]
[270, {"a": [["11712.00000", "0.00000000", "1596666894.006975"], ["11717.80000", "1.99812614", "1596666759.535617", "r"]], "c": "2413081262"}, "book-100", "XBT/USD"]
[270, {"a": [["11697.00000", "0.91100000", "1596666894.167143"]], "c": "2413081262"}, "book-100", "XBT/USD"]
[270, {"a": [["11706.10000", "3.18000000", "1596666894.352703"]], "c": "2413081262"}, "book-100", "XBT/USD"]
[270, {"a": [["11677.60000", "0.15000000", "1596666894.498421"]], "c": "2413081262"}, "book-100", "XBT/USD"]
[270, {"a": [["11677.60000", "0.62648186", "1596666894.683264"]], "c": "2413081262"}, "book-100", "XBT/USD"]
[271, [["11666.20000", "0.02332600", "1596666894.858608", "s", "l", ""]], "trade", "XBT/USD"]
[270, {"b": [["11666.20000", "16.36508253", "1596666894.858608"]], "c": "1318576639"}, "book-100", "XBT/USD"]
[270, {"a": [["11677.70000", "2.00000000", "1596666894.970614"]], "c": "1318576639"}, "book-100", "XBT/USD"]
[270, {"b": [["11662.20000", "0.00000000", "1596666894.972876"], ["11616.00000", "0.17085000", "1596666893.083885", "r"]], "c": "1318576639"}, "book-100", "XBT/USD"]
[270, {"a": [["11672.50000", "0.00000000", "1596666894.989630"], ["11715.30000", "6.10000000", "1596666635.445451", "r"]], "c": "1318576639"}, "book-100", "XBT/USD"]
[270, {"a": [["11672.40000", "0.00000000", "1596666895.041614"], ["11717.80000", "1.99812614", "1596666759.535617", "r"]], "c": "2250425017"}, "book-100", "XBT/USD"]
[270, {"a": [["11671.60000", "0.25831354", "1596666895.089125"]], "c": "3901040173"}, "book-100", "XBT/USD"]
[270, {"a": [["11672.60000", "0.01000000", "1596666895.091110"]], "c": "3901040173"}, "book-100", "XBT/USD"]
[270, {"b": [["11659.30000", "0.10346128", "1596666895.116638"]], "c": "3901040173"}, "book-100", "XBT/USD"]
[270, {"a": [["11680.40000", "0.00000000", "1596666895.118382"], ["11715.30000", "6.10000000", "1596666635.445451", "r"]], "c": "3901040173"}, "book-100", "XBT/USD"]
[270, {"b": [["11659.30000", "0.00000000", "1596666895.120009"], ["11615.60000", "0.20000000", "1596666623.308321", "r"]], "c": "3901040173"}, "book-100", "XBT/USD"]
[270, {"a": [["11686.30000", "0.00000000", "1596666895.120284"], ["11717.80000", "1.99812614", "1596666759.535617", "r"]], "c": "3901040173"}, "book-100", "XBT/USD"]
[270, {"a": [["11676.80000", "1.50000000", "1596666895.121972"]], "c": "3901040173"}, "book-100", "XBT/USD"]
[270, {"b": [["11661.70000", "2.35691535", "1596666895.122067"]], "c": "3901040173"}, "book-100", "XBT/USD"]
[270, {"b": [["11657.70000", "0.90035188", "1596666895.125032"]], "c": "3901040173"}, "book-100", "XBT/USD"]
[270, {"a": [["11682.70000", "0.00000000", "1596666895.125531"], ["11717.80000", "1.99812614", "1596666759.535617", "r"]], "c": "3901040173"}, "book-100", "XBT/USD"]
[270, {"b": [["11663.40000", "0.87716000", "1596666895.126837"]], "c": "3901040173"}, "book-100", "XBT/USD"]
[270, {"a": [["11706.10000", "0.00000000", "1596666895.128004"], ["11718.00000", "0.17085000", "1596666865.758675", "r"]], "c": "3901040173"}, "book-100", "XBT/USD"]
[270, {"a": [["11679.10000", "0.00000000", "1596666895.152340"], ["11718.40000", "0.48360000", "1596666846.374528", "r"]], "c": "3901040173"}, "book-100", "XBT/USD"]
[270, {"b": [["11663.90000", "0.85684986", "1596666895.202116"]], "c": "3901040173"}, "book-100", "XBT/USD"]
[270, {"a": [["11671.30000", "0.68517634", "1596666895.203281"]], "c": "3361072845"}, "book-100", "XBT/USD"]
[270, {"a": [["11682.40000", "0.55696221", "1596666895.206340"]], "c": "3361072845"}, "book-100", "XBT/USD"]
[270, {"b": [["11656.90000", "0.82786938", "1596666895.257293"]], "c": "3361072845"}, "book-100", "XBT/USD"]
[270, {"a": [["11679.70000", "0.83357273", "1596666895.271092"]], "c": "3361072845"}, "book-100", "XBT/USD"]
[270, {"a": [["11702.60000", "7.06311509", "1596666895.330579"]], "c": "3361072845"}, "book-100", "XBT/USD"]
[270, {"a": [["11690.90000", "10.26651924", "1596666895.331491"]], "c": "3361072845"}, "book-100", "XBT/USD"]
[270, {"a": [["11677.90000", "0.15550895", "1596666895.370698"]], "c": "3361072845"}, "book-100", "XBT/USD"]
[270, {"b": [["11654.60000", "1.42399440", "1596666895.431132"]], "c": "3361072845"}, "book-100", "XBT/USD"]
[270, {"a": [["11684.00000", "1.42041126", "1596666895.431806"]], "c": "3361072845"}, "book-100", "XBT/USD"]
[270, {"a": [["11678.20000", "0.33836112", "1596666895.432686"]], "c": "3361072845"}, "book-100", "XBT/USD"]
[270, {"a": [["11681.60000", "0.71035154", "1596666895.432900"]], "c": "3361072845"}, "book-100", "XBT/USD"]
[270, {"b": [["11660.30000", "0.33888055", "1596666895.436362"]], "c": "3361072845"}, "book-100", "XBT/USD"]
[270, {"b": [["11622.90000", "0.74859283", "1596666895.466910"]], "c": "3361072845"}, "book-100", "XBT/USD"]
[270, {"b": [["11623.10000", "0.00000000", "1596666895.491930"], ["11617.50000", "2.49761864", "1596666811.445738", "r"]], "c": "3361072845"}, "book-100", "XBT/USD"]
[270, {"b": [["11660.30000", "0.00000000", "1596666895.624657"], ["11617.40000", "0.75800000", "1596666775.482846", "r"]], "c": "3361072845"}, "book-100", "XBT/USD"]
[270, {"b": [["11657.00000", "0.71185061", "1596666895.663736"]], "c": "3361072845"}, "book-100", "XBT/USD"]
[270, {"b": [["11654.60000", "0.00000000", "1596666895.666041"], ["11617.40000", "0.75800000", "1596666775.482846", "r"]], "c": "3361072845"}, "book-100", "XBT/USD"]
[270, {"b": [["11657.00000", "0.00000000", "1596666895.850358"], ["11616.00000", "0.17085000", "1596666893.083885", "r"]], "c": "3361072845"}, "book-100", "XBT/USD"]
[271, [["11666.20000", "0.02332600", "1596666896.856278", "s", "l", ""]], "trade", "XBT/USD"]
[270, {"b": [["11666.20000", "16.34175653", "1596666896.856278"]], "c": "2372424220"}, "book-100", "XBT/USD"]
[270, {"a": [["11676.40000", "3.50095388", "1596666897.059598"]], "c": "2372424220"}, "book-100", "XBT/USD"]
[270, {"b": [["11661.80000", "0.00000000", "1596666897.188147"], ["11615.60000", "0.20000000", "1596666623.308321", "r"]], "c": "2372424220"}, "book-100", "XBT/USD"]
[270, {"a": [["11671.30000", "0.64267634", "1596666897.188451"]], "c": "1318839605"}, "book-100", "XBT/USD"]
[270, {"a": [["11677.60000", "0.47648186", "1596666897.200093"]], "c": "1318839605"}, "book-100", "XBT/USD"]
[270, {"b": [["11662.50000", "0.00000000", "1596666897.300710"], ["11614.80000", "3.08717099", "1596666746.879208", "r"]], "c": "1318839605"}, "book-100", "XBT/USD"]
[270, {"a": [["11671.50000", "0.10300000", "1596666897.377128"]], "c": "2063310789"}, "book-100", "XBT/USD"]
[270, {"b": [["11653.80000", "0.00000000", "1596666897.427095"], ["11613.60000", "3.55198121", "1596666780.634357", "r"]], "c": "2063310789"}, "book-100", "XBT/USD"]
[270, {"b": [["11653.80000", "0.01805722", "1596666897.428019"]], "c": "2063310789"}, "book-100", "XBT/USD"]
[270, {"b": [["11662.10000", "0.04250000", "1596666897.435300"]], "c": "2063310789"}, "book-100", "XBT/USD"]
[270, {"a": [["11672.50000", "0.04250000", "1596666897.437092"]], "c": "2063310789"}, "book-100", "XBT/USD"]
[270, {"b": [["11662.00000", "10.09987003", "1596666897.440485"]], "c": "2063310789"}, "book-100", "XBT/USD"]
[270, {"b": [["11650.40000", "0.00429094", "1596666897.554191"]], "c": "2063310789"}, "book-100", "XBT/USD"]
[270, {"a": [["11686.90000", "0.00438186", "1596666897.554949"]], "c": "2063310789"}, "book-100", "XBT/USD"]
[270, {"a": [["11671.60000", "0.00000000", "1596666897.656808"], ["11711.50000", "1.99898326", "1596666797.632161", "r"]], "c": "1323122707"}, "book-100", "XBT/USD"]
[270, {"a": [["11678.20000", "0.00000000", "1596666897.682858"], ["11713.90000", "2.30673040", "1596666889.279950", "r"]], "c": "1323122707"}, "book-100", "XBT/USD"]
[270, {"a": [["11677.90000", "0.04472746", "1596666897.695887"]], "c": "1323122707"}, "book-100", "XBT/USD"]
[270, {"a": [["11677.40000", "0.00000000", "1596666897.735926"], ["11715.00000", "0.17085000", "1596666893.351638", "r"]], "c": "1323122707"}, "book-100", "XBT/USD"]
[270, {"a": [["11677.30000", "0.00000000", "1596666897.736367"], ["11715.30000", "6.10000000", "1596666635.445451", "r"]], "c": "1323122707"}, "book-100", "XBT/USD"]
[270, {"a": [["11671.60000", "0.25831242", "1596666897.757036"]], "c": "2197263029"}, "book-100", "XBT/USD"]
[270, {"a": [["11679.10000", "0.11078149", "1596666897.869369"]], "c": "2197263029"}, "book-100", "XBT/USD"]
[270, {"a": [["11669.50000", "0.16500000", "1596666897.880059"]], "c": "1936863869"}, "book-100", "XBT/USD"]
[270, {"b": [["11650.40000", "0.00000000", "1596666898.424475"], ["11615.60000", "0.20000000", "1596666623.308321", "r"]], "c": "1936863869"}, "book-100", "XBT/USD"]
[270, {"b": [["11662.00000", "0.10000000", "1596666898.482282"]], "c": "1936863869"}, "book-100", "XBT/USD"]
[270, {"b": [["11649.00000", "0.00443204", "1596666898.608956"]], "c": "1936863869"}, "book-100", "XBT/USD"]
[271, [["11666.20000", "0.02332600", "1596666898.878845", "s", "l", ""]], "trade", "XBT/USD"]
[270, {"b": [["11666.20000", "16.31843053", "1596666898.878846"]], "c": "3776795707"}, "book-100", "XBT/USD"]
[270, {"b": [["11658.70000", "0.71162689", "1596666898.940185"]], "c": "3776795707"}, "book-100", "XBT/USD"]
[270, {"b": [["11656.40000", "1.42353461", "1596666898.941070"]], "c": "3776795707"}, "book-100", "XBT/USD"]
[270, {"b": [["11665.80000", "4.27900000", "1596666898.954496"]], "c": "3918257030"}, "book-100", "XBT/USD"]
[270, {"b": [["11662.10000", "0.38127115", "1596666898.960208"]], "c": "3918257030"}, "book-100", "XBT/USD"]
[270, {"a": [["11679.30000", "0.33827225", "1596666899.001257"]], "c": "3918257030"}, "book-100", "XBT/USD"]
[270, {"b": [["11662.00000", "0.00000000", "1596666899.232218"], ["11617.40000", "0.75800000", "1596666775.482846", "r"]], "c": "3918257030"}, "book-100", "XBT/USD"]
[270, {"a": [["11671.30000", "0.00000000", "1596666899.341473"], ["11711.50000", "1.99898326", "1596666797.632161", "r"]], "c": "1676593704"}, "book-100", "XBT/USD"]
[270, {"b": [["11664.60000", "0.00000000", "1596666899.391515"], ["11616.00000", "0.17085000", "1596666893.083885", "r"]], "c": "3048685935"}, "book-100", "XBT/USD"]
[270, {"a": [["11671.80000", "0.00000000", "1596666899.399409"], ["11712.00000", "0.17085000", "1596666898.841793", "r"]], "c": "3048685935"}, "book-100", "XBT/USD"]
[270, {"a": [["11668.70000", "0.64270486", "1596666899.399566"]], "c": "2853151015"}, "book-100", "XBT/USD"]
[270, {"b": [["11663.10000", "0.50000000", "1596666899.535577"]], "c": "2853151015"}, "book-100", "XBT/USD"]
[270, {"a": [["11670.30000", "0.25000000", "1596666899.545053"]], "c": "3884296202"}, "book-100", "XBT/USD"]
[270, {"b": [["11649.00000", "0.00000000", "1596666899.566427"], ["11616.00000", "0.17085000", "1596666893.083885", "r"]], "c": "3884296202"}, "book-100", "XBT/USD"]
[270, {"a": [["11669.50000", "0.00000000", "1596666899.595313"], ["11711.50000", "1.99898326", "1596666797.632161", "r"]], "c": "2428669812"}, "book-100", "XBT/USD"]
[270, {"b": [["11657.30000", "2.98502405", "1596666899.621754"]], "c": "2428669812"}, "book-100", "XBT/USD"]
[270, {"a": [["11702.80000", "4.67052797", "1596666899.663524"]], "c": "2428669812"}, "book-100", "XBT/USD"]
[270, {"a": [["11669.80000", "0.00000000", "1596666899.687263"], ["11712.00000", "0.17085000", "1596666898.841793", "r"]], "c": "711625665"}, "book-100", "XBT/USD"]
[270, {"b": [["11665.60000", "0.19766000", "1596666899.687448"]], "c": "9730307"}, "book-100", "XBT/USD"]
[270, {"b": [["11660.80000", "0.00000000", "1596666899.761064"], ["11616.00000", "0.17085000", "1596666893.083885", "r"]], "c": "9730307"}, "book-100", "XBT/USD"]
[270, {"a": [["11671.70000", "0.00000000", "1596666899.770585"], ["11713.90000", "2.30673040", "1596666889.279950", "r"]], "c": "2757048702"}, "book-100", "XBT/USD"]
[270, {"a": [["11671.60000", "0.00000000", "1596666899.833751"], ["11715.00000", "0.17085000", "1596666893.351638", "r"]], "c": "712229534"}, "book-100", "XBT/USD"]
[270, {"b": [["11653.80000", "0.06025095", "1596666899.904167"]], "c": "712229534"}, "book-100", "XBT/USD"]
[270, {"b": [["11653.80000", "0.04219373", "1596666899.905994"]], "c": "712229534"}, "book-100", "XBT/USD"]
[270, {"a": [["11670.90000", "0.25833323", "1596666899.928665"]], "c": "1283466728"}, "book-100", "XBT/USD"]
[270, {"a": [["11670.90000", "1.07331323", "1596666900.030015"]], "c": "770639461"}, "book-100", "XBT/USD"]
[270, {"b": [["11662.60000", "0.00000000", "1596666900.042631"], ["11615.60000", "0.20000000", "1596666623.308321", "r"]], "c": "770639461"}, "book-100", "XBT/USD"]
[270, {"a": [["11701.30000", "0.00000000", "1596666900.044481"], ["11715.00000", "0.17085000", "1596666893.351638", "r"]], "c": "770639461"}, "book-100", "XBT/USD"]
[270, {"b": [["11663.40000", "0.00000000", "1596666900.068109"], ["11614.80000", "3.08717099", "1596666746.879208", "r"]], "c": "770639461"}, "book-100", "XBT/USD"]
[270, {"a": [["11673.80000", "1.80750079", "1596666900.074578"]], "c": "770639461"}, "book-100", "XBT/USD"]
[270, {"b": [["11622.00000", "0.00000000", "1596666900.230446"], ["11613.60000", "3.55198121", "1596666780.634357", "r"]], "c": "770639461"}, "book-100", "XBT/USD"]
[270, {"a": [["11701.50000", "0.08250000", "1596666900.363162"]], "c": "770639461"}, "book-100", "XBT/USD"]
[270, {"b": [["11662.20000", "0.08250000", "1596666900.422831"]], "c": "770639461"}, "book-100", "XBT/USD"]
[270, {"b": [["11666.20000", "15.91843053", "1596666900.445342"]], "c": "440574571"}, "book-100", "XBT/USD"]
[270, {"b": [["11666.20000", "16.13409053", "1596666900.472753"]], "c": "206384180"}, "book-100", "XBT/USD"]
[270, {"a": [["11684.30000", "0.00000000", "1596666900.631092"], ["11715.00000", "0.17085000", "1596666893.351638", "r"]], "c": "206384180"}, "book-100", "XBT/USD"]
[270, {"b": [["11662.10000", "0.04250000", "1596666900.643587"]], "c": "206384180"}, "book-100", "XBT/USD"]
[270, {"a": [["11680.20000", "1.96990000", "1596666900.688289"]], "c": "206384180"}, "book-100", "XBT/USD"]
[270, {"b": [["11664.40000", "1.70500000", "1596666900.797699"]], "c": "3683116555"}, "book-100", "XBT/USD"]
[270, {"a": [["11672.60000", "1.71200000", "1596666900.809321"]], "c": "3683116555"}, "book-100", "XBT/USD"]
[270, {"b": [["11666.20000", "16.13666053", "1596666900.852475"]], "c": "1297763675"}, "book-100", "XBT/USD"]
[270, {"a": [["11673.50000", "0.15000000", "1596666900.861802"]], "c": "1297763675"}, "book-100", "XBT/USD"]
[270, {"a": [["11670.90000", "0.25833323", "1596666900.863363"]], "c": "3727875557"}, "book-100", "XBT/USD"]
[270, {"a": [["11669.70000", "0.81786710", "1596666901.105366"]], "c": "154323927"}, "book-100", "XBT/USD"]
[270, {"a": [["11683.20000", "0.00000000", "1596666901.121046"], ["11712.00000", "0.17085000", "1596666898.841793", "r"]], "c": "154323927"}, "book-100", "XBT/USD"]
[270, {"b": [["11631.70000", "0.00000000", "1596666901.169382"], ["11614.80000", "3.08717099", "1596666746.879208", "r"]], "c": "154323927"}, "book-100", "XBT/USD"]
[270, {"a": [["11674.60000", "0.24621094", "1596666901.237001"]], "c": "154323927"}, "book-100", "XBT/USD"]
[270, {"a": [["11673.50000", "0.00000000", "1596666901.240976"], ["11713.90000", "2.30673040", "1596666889.279950", "r"]], "c": "154323927"}, "book-100", "XBT/USD"]
[270, {"a": [["11692.20000", "3.21009214", "1596666901.248776"]], "c": "154323927"}, "book-100", "XBT/USD"]
[270, {"b": [["11661.20000", "0.33879730", "1596666901.323524"]], "c": "154323927"}, "book-100", "XBT/USD"]
[270, {"b": [["11631.00000", "6.05433707", "1596666901.333331"]], "c": "154323927"}, "book-100", "XBT/USD"]
[270, {"a": [["11690.80000", "6.47425272", "1596666901.424543"]], "c": "154323927"}, "book-100", "XBT/USD"]
[270, {"a": [["11674.80000", "0.15000000", "1596666901.455786"]], "c": "154323927"}, "book-100", "XBT/USD"]
[270, {"a": [["11673.30000", "0.15000000", "1596666901.713508"]], "c": "154323927"}, "book-100", "XBT/USD"]
[270, {"a": [["11673.30000", "0.00000000", "1596666901.804402"], ["11711.50000", "1.99898326", "1596666797.632161", "r"]], "c": "154323927"}, "book-100", "XBT/USD"]
[270, {"a": [["11672.60000", "0.01000000", "1596666901.872928"]], "c": "154323927"}, "book-100", "XBT/USD"]
[270, {"a": [["11687.60000", "0.00000000", "1596666901.977753"], ["11712.00000", "0.17085000", "1596666898.841793", "r"]], "c": "154323927"}, "book-100", "XBT/USD"]
[270, {"b": [["11622.90000", "0.00000000", "1596666901.978515"], ["11615.60000", "0.20000000", "1596666623.308321", "r"]], "c": "154323927"}, "book-100", "XBT/USD"]
[270, {"a": [["11687.50000", "0.74857264", "1596666901.989028"]], "c": "154323927"}, "book-100", "XBT/USD"]
[270, {"b": [["11622.70000", "0.74857264", "1596666901.989176"]], "c": "154323927"}, "book-100", "XBT/USD"]
[270, {"a": [["11677.60000", "0.00000000", "1596666902.078443"], ["11712.00000", "0.17085000", "1596666898.841793", "r"]], "c": "154323927"}, "book-100", "XBT/USD"]
[270, {"a": [["11674.40000", "0.15000000", "1596666902.087235"]], "c": "154323927"}, "book-100", "XBT/USD"]
[270, {"a": [["11667.50000", "0.64277827", "1596666902.201077"]], "c": "3079612446"}, "book-100", "XBT/USD"]
[270, {"a": [["11670.60000", "2.77139018", "1596666902.202542"]], "c": "766703360"}, "book-100", "XBT/USD"]
[270, {"b": [["11650.30000", "9.15703770", "1596666902.202693"]], "c": "766703360"}, "book-100", "XBT/USD"]
[270, {"a": [["11673.80000", "1.95750079", "1596666902.239167"]], "c": "766703360"}, "book-100", "XBT/USD"]
[270, {"a": [["11670.90000", "0.00000000", "1596666902.299827"], ["11711.50000", "1.99898326", "1596666797.632161", "r"]], "c": "4154568227"}, "book-100", "XBT/USD"]
[270, {"a": [["11677.60000", "0.52799512", "1596666902.344718"]], "c": "4154568227"}, "book-100", "XBT/USD"]
[270, {"a": [["11673.80000", "1.80750079", "1596666902.378151"]], "c": "4154568227"}, "book-100", "XBT/USD"]
[270, {"a": [["11670.40000", "0.25834045", "1596666902.398801"]], "c": "420749181"}, "book-100", "XBT/USD"]
[270, {"a": [["11673.70000", "0.15000000", "1596666902.505537"]], "c": "420749181"}, "book-100", "XBT/USD"]
[270, {"a": [["11666.30000", "0.11890617", "1596666902.771985"]], "c": "2739535612"}, "book-100", "XBT/USD"]
[270, {"a": [["11673.70000", "0.00000000", "1596666902.818899"], ["11710.70000", "3.52183532", "1596666711.393054", "r"]], "c": "2739535612"}, "book-100", "XBT/USD"]
[270, {"b": [["11657.90000", "0.00000000", "1596666902.951460"], ["11615.60000", "0.20000000", "1596666623.308321", "r"]], "c": "2739535612"}, "book-100", "XBT/USD"]
[270, {"b": [["11658.70000", "0.00000000", "1596666902.982879"], ["11614.80000", "3.08717099", "1596666746.879208", "r"]], "c": "2739535612"}, "book-100", "XBT/USD"]
[270, {"a": [["11673.80000", "1.95750079", "1596666903.027175"]], "c": "2739535612"}, "book-100", "XBT/USD"]
[270, {"b": [["11655.80000", "0.24969732", "1596666903.156021"]], "c": "2739535612"}, "book-100", "XBT/USD"]
[270, {"b": [["11649.00000", "0.00434534", "1596666903.166182"]], "c": "2739535612"}, "book-100", "XBT/USD"]
[270, {"a": [["11687.50000", "0.00000000", "1596666903.183838"], ["11711.10000", "0.75800000", "1596666806.349295", "r"]], "c": "2739535612"}, "book-100", "XBT/USD"]
[270, {"b": [["11657.80000", "0.71168183", "1596666903.407020"]], "c": "2739535612"}, "book-100", "XBT/USD"]
[270, {"a": [["11687.40000", "4.27752184", "1596666903.413885"]], "c": "2739535612"}, "book-100", "XBT/USD"]
[270, {"b": [["11622.70000", "0.00000000", "1596666903.421297"], ["11616.00000", "0.17085000", "1596666893.083885", "r"]], "c": "2739535612"}, "book-100", "XBT/USD"]
[270, {"b": [["11622.80000", "0.74857463", "1596666903.428062"]], "c": "2739535612"}, "book-100", "XBT/USD"]
[270, {"b": [["11649.00000", "0.00000000", "1596666903.445271"], ["11616.00000", "0.17085000", "1596666893.083885", "r"]], "c": "2739535612"}, "book-100", "XBT/USD"]
[270, {"b": [["11648.60000", "0.00431919", "1596666903.629594"]], "c": "2739535612"}, "book-100", "XBT/USD"]
[270, {"b": [["11648.60000", "0.00000000", "1596666903.816952"], ["11616.00000", "0.17085000", "1596666893.083885", "r"]], "c": "2739535612"}, "book-100", "XBT/USD"]
[270, {"b": [["11653.90000", "0.00000000", "1596666903.865264"], ["11615.60000", "0.20000000", "1596666623.308321", "r"]], "c": "2739535612"}, "book-100", "XBT/USD"]
[270, {"b": [["11658.80000", "0.43800000", "1596666903.905677"]], "c": "2739535612"}, "book-100", "XBT/USD"]
[270, {"b": [["11662.10000", "0.00000000", "1596666903.941931"], ["11615.60000", "0.20000000", "1596666623.308321", "r"]], "c": "2739535612"}, "book-100", "XBT/USD"]
[270, {"a": [["11672.50000", "0.00000000", "1596666903.942270"], ["11711.50000", "1.99898326", "1596666797.632161", "r"]], "c": "2739535612"}, "book-100", "XBT/USD"]
[270, {"a": [["11673.80000", "1.80750079", "1596666904.209478"]], "c": "2739535612"}, "book-100", "XBT/USD"]
[270, {"a": [["11673.80000", "1.95750079", "1596666904.307835"]], "c": "2739535612"}, "book-100", "XBT/USD"]
[270, {"b": [["11661.60000", "0.04250000", "1596666904.339419"]], "c": "2739535612"}, "book-100", "XBT/USD"]
[270, {"a": [["11670.90000", "0.04250000", "1596666904.340030"]], "c": "1371947912"}, "book-100", "XBT/USD"]
[270, {"a": [["11709.00000", "0.17085000", "1596666904.504022"]], "c": "1371947912"}, "book-100", "XBT/USD"]
[270, {"a": [["11670.50000", "0.86083543", "1596666904.572981"]], "c": "3003202228"}, "book-100", "XBT/USD"]
[270, {"a": [["11669.60000", "0.00000000", "1596666904.706651"], ["11711.10000", "0.75800000", "1596666806.349295", "r"]], "c": "1805616074"}, "book-100", "XBT/USD"]
[270, {"a": [["11667.80000", "0.64277990", "1596666904.761331"]], "c": "1344006619"}, "book-100", "XBT/USD"]
[270, {"a": [["11673.80000", "1.80750079", "1596666904.831955"]], "c": "1344006619"}, "book-100", "XBT/USD"]
[270, {"a": [["11670.40000", "0.00000000", "1596666904.847948"], ["11711.10000", "0.75800000", "1596666806.349295", "r"]], "c": "86789164"}, "book-100", "XBT/USD"]
[270, {"a": [["11672.70000", "0.15000000", "1596666904.916026"]], "c": "86789164"}, "book-100", "XBT/USD"]
[270, {"a": [["11677.90000", "0.00000000", "1596666904.925376"], ["11711.10000", "0.75800000", "1596666806.349295", "r"]], "c": "86789164"}, "book-100", "XBT/USD"]
[270, {"a": [["11705.10000", "0.00000000", "1596666904.959814"], ["11711.50000", "1.99898326", "1596666797.632161", "r"]], "c": "86789164"}, "book-100", "XBT/USD"]
[270, {"a": [["11668.70000", "0.00000000", "1596666904.991234"], ["11712.00000", "0.17085000", "1596666898.841793", "r"]], "c": "4251428229"}, "book-100", "XBT/USD"]
[270, {"b": [["11665.30000", "0.00000000", "1596666905.003889"], ["11615.60000", "0.20000000", "1596666623.308321", "r"]], "c": "3907420603"}, "book-100", "XBT/USD"]
[270, {"a": [["11666.30000", "0.32890617", "1596666905.187998"]], "c": "4204033897"}, "book-100", "XBT/USD"]
[270, {"a": [["11672.70000", "0.00000000", "1596666905.222660"], ["11713.90000", "2.30673040", "1596666889.279950", "r"]], "c": "4204033897"}, "book-100", "XBT/USD"]
[270, {"b": [["11664.40000", "0.00000000", "1596666905.225692"], ["11614.80000", "3.08717099", "1596666746.879208", "r"]], "c": "1888703463"}, "book-100", "XBT/USD"]
[270, {"a": [["11679.70000", "0.69939035", "1596666905.230277"]], "c": "1888703463"}, "book-100", "XBT/USD"]
[270, {"a": [["11672.10000", "0.15000000", "1596666905.307700"]], "c": "1888703463"}, "book-100", "XBT/USD"]
[270, {"a": [["11673.00000", "6.38671750", "1596666905.392095"]], "c": "1888703463"}, "book-100", "XBT/USD"]
[270, {"a": [["11676.40000", "0.67381000", "1596666905.542052"]], "c": "1888703463"}, "book-100", "XBT/USD"]
[270, {"a": [["11678.10000", "0.30000000", "1596666905.545450"]], "c": "1888703463"}, "book-100", "XBT/USD"]
[270, {"b": [["11665.00000", "0.00000000", "1596666905.868810"], ["11613.60000", "3.55198121", "1596666780.634357", "r"]], "c": "4092665076"}, "book-100", "XBT/USD"]
[270, {"a": [["11676.80000", "0.00000000", "1596666905.972947"], ["11712.00000", "0.17085000", "1596666898.841793", "r"]], "c": "4092665076"}, "book-100", "XBT/USD"]
[270, {"b": [["11661.70000", "0.85691535", "1596666905.973031"]], "c": "4092665076"}, "book-100", "XBT/USD"]
[270, {"a": [["11667.80000", "0.00000000", "1596666905.996705"], ["11713.90000", "2.30673040", "1596666889.279950", "r"]], "c": "300380785"}, "book-100", "XBT/USD"]
[270, {"a": [["11672.60000", "0.10621094", "1596666906.101299"]], "c": "300380785"}, "book-100", "XBT/USD"]
[270, {"a": [["11674.60000", "0.15000000", "1596666906.113484"]], "c": "300380785"}, "book-100", "XBT/USD"]
[270, {"a": [["11674.80000", "1.65000000", "1596666906.129324"]], "c": "300380785"}, "book-100", "XBT/USD"]
[270, {"b": [["11660.70000", "1.50000000", "1596666906.131868"]], "c": "300380785"}, "book-100", "XBT/USD"]
[270, {"b": [["11657.60000", "0.00000000", "1596666906.132191"], ["11613.60000", "3.55198121", "1596666780.634357", "r"]], "c": "300380785"}, "book-100", "XBT/USD"]
[270, {"a": [["11669.70000", "0.00000000", "1596666906.232036"], ["11715.00000", "0.17085000", "1596666893.351638", "r"]], "c": "1978185036"}, "book-100", "XBT/USD"]
[270, {"a": [["11672.10000", "0.00000000", "1596666906.253992"], ["11715.30000", "6.10000000", "1596666635.445451", "r"]], "c": "3935461027"}, "book-100", "XBT/USD"]
[270, {"a": [["11669.80000", "0.82060287", "1596666906.457259"]], "c": "1882472302"}, "book-100", "XBT/USD"]
[270, {"a": [["11672.10000", "0.15000000", "1596666906.479336"]], "c": "937552652"}, "book-100", "XBT/USD"]
[270, {"a": [["11708.70000", "0.00000000", "1596666906.524657"], ["11715.00000", "0.17085000", "1596666893.351638", "r"]], "c": "937552652"}, "book-100", "XBT/USD"]
[270, {"a": [["11670.50000", "0.60250000", "1596666906.653206"]], "c": "2410779534"}, "book-100", "XBT/USD"]
[270, {"a": [["11669.80000", "0.00000000", "1596666906.675666"], ["11715.30000", "6.10000000", "1596666635.445451", "r"]], "c": "3640912938"}, "book-100", "XBT/USD"]
[270, {"a": [["11672.10000", "0.00000000", "1596666906.708590"], ["11717.80000", "1.99812614", "1596666759.535617", "r"]], "c": "1182336965"}, "book-100", "XBT/USD"]
[270, {"a": [["11670.20000", "0.25834821", "1596666906.748968"]], "c": "3079574366"}, "book-100", "XBT/USD"]
[270, {"b": [["11656.60000", "0.00000000", "1596666906.810333"], ["11613.00000", "0.17085000", "1596666803.224745", "r"]], "c": "3079574366"}, "book-100", "XBT/USD"]
[270, {"a": [["11668.20000", "0.35990000", "1596666906.893132"]], "c": "2082636064"}, "book-100", "XBT/USD"]
[270, {"a": [["11670.80000", "0.80683888", "1596666906.911136"]], "c": "907892041"}, "book-100", "XBT/USD"]
[270, {"a": [["11679.20000", "0.00000000", "1596666907.156427"], ["11715.00000", "0.17085000", "1596666893.351638", "r"]], "c": "907892041"}, "book-100", "XBT/USD"]
[270, {"b": [["11660.90000", "0.85706932", "1596666907.161680"]], "c": "907892041"}, "book-100", "XBT/USD"]
[270, {"b": [["11658.40000", "0.78675000", "1596666907.164250"]], "c": "907892041"}, "book-100", "XBT/USD"]
[270, {"a": [["11686.90000", "0.00000000", "1596666907.191479"], ["11715.30000", "6.10000000", "1596666635.445451", "r"]], "c": "907892041"}, "book-100", "XBT/USD"]
[270, {"a": [["11666.30000", "0.82890617", "1596666907.193511"]], "c": "3302631200"}, "book-100", "XBT/USD"]
[270, {"a": [["11670.10000", "0.85713744", "1596666907.218316"]], "c": "3588801772"}, "book-100", "XBT/USD"]
[270, {"a": [["11666.50000", "0.64282025", "1596666907.218456"]], "c": "736331594"}, "book-100", "XBT/USD"]
[270, {"a": [["11666.60000", "0.64284935", "1596666907.218575"]], "c": "21184792"}, "book-100", "XBT/USD"]
[270, {"b": [["11650.10000", "0.85709366", "1596666907.219125"]], "c": "21184792"}, "book-100", "XBT/USD"]
[271, [["11666.30000", "0.11890617", "1596666907.224212", "b", "l", ""], ["11666.30000", "0.21000000", "1596666907.238708", "b", "l", ""], ["11666.30000", "0.50000000", "1596666907.240362", "b", "l", ""], ["11666.50000", "0.64282025", "1596666907.241759", "b", "l", ""], ["11666.60000", "0.64284935", "1596666907.243263", "b", "l", ""], ["11667.50000", "0.64277827", "1596666907.244876", "b", "l", ""], ["11668.20000", "0.35990000", "1596666907.246389", "b", "l", ""], ["11670.10000", "0.85713744", "1596666907.248497", "b", "l", ""], ["11670.20000", "0.25834821", "1596666907.250190", "b", "l", ""], ["11670.30000", "0.25000000", "1596666907.251626", "b", "l", ""], ["11670.50000", "0.51726031", "1596666907.253425", "b", "l", ""]], "trade", "XBT/USD"]
[270, {"a": [["11666.30000", "0.71000000", "1596666907.224212"], ["11666.30000", "0.50000000", "1596666907.238708"], ["11666.30000", "0.00000000", "1596666907.240363"], ["11713.90000", "2.30673040", "1596666889.279950", "r"], ["11666.50000", "0.00000000", "1596666907.241759"], ["11715.00000", "0.17085000", "1596666893.351638", "r"], ["11666.60000", "0.00000000", "1596666907.243263"], ["11715.30000", "6.10000000", "1596666635.445451", "r"], ["11667.50000", "0.00000000", "1596666907.244876"], ["11717.80000", "1.99812614", "1596666759.535617", "r"], ["11668.20000", "0.00000000", "1596666907.246389"], ["11718.00000", "0.17085000", "1596666865.758675", "r"], ["11670.10000", "0.00000000", "1596666907.248497"], ["11718.40000", "0.48360000", "1596666846.374528", "r"], ["11670.20000", "0.00000000", "1596666907.250191"], ["11718.50000", "24.30000000", "1596666641.380470", "r"], ["11670.30000", "0.00000000", "1596666907.251627"], ["11719.60000", "2.98021891", "1596666782.974175", "r"], ["11670.50000", "0.08523969", "1596666907.253426"]], "c": "2593044753"}, "book-100", "XBT/USD"]
[270, {"b": [["11657.70000", "0.00000000", "1596666907.263473"], ["11613.60000", "3.55198121", "1596666780.634357", "r"]], "c": "2593044753"}, "book-100", "XBT/USD"]
[270, {"b": [["11661.20000", "0.00000000", "1596666907.281508"], ["11613.00000", "0.17085000", "1596666803.224745", "r"]], "c": "2593044753"}, "book-100", "XBT/USD"]
[270, {"b": [["11666.20000", "15.63666053", "1596666907.311838"]], "c": "3700069683"}, "book-100", "XBT/USD"]
[270, {"b": [["11666.30000", "5.20000000", "1596666907.321426"]], "c": "3460178591"}, "book-100", "XBT/USD"]
[270, {"a": [["11679.70000", "0.00000000", "1596666907.327911"], ["11719.70000", "3.50602221", "1596666789.365232", "r"]], "c": "3460178591"}, "book-100", "XBT/USD"]
[270, {"a": [["11671.50000", "0.00000000", "1596666907.329061"], ["11720.80000", "0.75800000", "1596666850.512768", "r"]], "c": "603962797"}, "book-100", "XBT/USD"]
[270, {"b": [["11662.80000", "0.09800000", "1596666907.330257"]], "c": "603962797"}, "book-100", "XBT/USD"]
[270, {"b": [["11666.30000", "0.00000000", "1596666907.386994"], ["11613.60000", "3.55198121", "1596666780.634357", "r"]], "c": "2778105779"}, "book-100", "XBT/USD"]
[270, {"a": [["11670.90000", "0.00000000", "1596666907.387281"], ["11721.00000", "0.97885000", "1596666860.230720", "r"]], "c": "1407386946"}, "book-100", "XBT/USD"]
[270, {"b": [["11661.60000", "0.00000000", "1596666907.389598"], ["11613.00000", "0.17085000", "1596666803.224745", "r"]], "c": "1407386946"}, "book-100", "XBT/USD"]
[270, {"b": [["11663.10000", "0.00000000", "1596666907.391759"], ["11612.30000", "7.00000000", "1596666617.080387", "r"]], "c": "875563497"}, "book-100", "XBT/USD"]
[270, {"a": [["11677.30000", "0.69946101", "1596666907.408782"]], "c": "875563497"}, "book-100", "XBT/USD"]
[270, {"a": [["11676.00000", "0.00000000", "1596666907.453824"], ["11721.00000", "0.97885000", "1596666860.230720", "r"]], "c": "875563497"}, "book-100", "XBT/USD"]
[270, {"b": [["11653.10000", "0.00000000", "1596666907.465177"], ["11611.90000", "1.06000000", "1596666780.430510", "r"]], "c": "875563497"}, "book-100", "XBT/USD"]
[270, {"b": [["11649.30000", "0.38000000", "1596666907.474193"]], "c": "875563497"}, "book-100", "XBT/USD"]
[270, {"a": [["11680.80000", "0.38000000", "1596666907.478921"]], "c": "875563497"}, "book-100", "XBT/USD"]
[270, {"a": [["11668.40000", "0.35990000", "1596666907.509279"]], "c": "3059533635"}, "book-100", "XBT/USD"]
[270, {"b": [["11666.20000", "15.25618481", "1596666907.509875"]], "c": "277291749"}, "book-100", "XBT/USD"]
[270, {"a": [["11682.60000", "0.43900000", "1596666907.531107"]], "c": "277291749"}, "book-100", "XBT/USD"]
[270, {"a": [["11670.40000", "0.04250000", "1596666907.641109"]], "c": "373748796"}, "book-100", "XBT/USD"]
[270, {"b": [["11663.00000", "0.75000000", "1596666907.641321"]], "c": "1760797883"}, "book-100", "XBT/USD"]
[270, {"b": [["11660.00000", "0.04250000", "1596666907.641396"]], "c": "1760797883"}, "book-100", "XBT/USD"]
[270, {"a": [["11670.80000", "0.00000000", "1596666907.756357"], ["11719.60000", "2.98021891", "1596666782.974175", "r"]], "c": "2452655757"}, "book-100", "XBT/USD"]
[270, {"a": [["11670.40000", "0.60554049", "1596666907.827338"]], "c": "2665729118"}, "book-100", "XBT/USD"]
[270, {"a": [["11671.60000", "1.70300000", "1596666907.897684"]], "c": "3282728535"}, "book-100", "XBT/USD"]
[270, {"b": [["11663.90000", "0.00000000", "1596666907.912765"], ["11613.00000", "0.17085000", "1596666803.224745", "r"]], "c": "3254112048"}, "book-100", "XBT/USD"]
[270, {"b": [["11650.10000", "0.00000000", "1596666907.913040"], ["11612.30000", "7.00000000", "1596666617.080387", "r"]], "c": "3254112048"}, "book-100", "XBT/USD"]
[270, {"a": [["11670.40000", "0.73531063", "1596666907.940424"]], "c": "2748392398"}, "book-100", "XBT/USD"]
[270, {"b": [["11654.90000", "1.39845790", "1596666907.941915"]], "c": "2748392398"}, "book-100", "XBT/USD"]
[270, {"b": [["11663.40000", "1.70600000", "1596666907.944525"]], "c": "846416860"}, "book-100", "XBT/USD"]
[270, {"a": [["11669.40000", "0.80933525", "1596666908.001326"]], "c": "3699760593"}, "book-100", "XBT/USD"]
[270, {"a": [["11702.40000", "10.19786497", "1596666908.136328"]], "c": "3699760593"}, "book-100", "XBT/USD"]
[271, [["11666.20000", "0.02332600", "1596666908.183671", "s", "l", ""]], "trade", "XBT/USD"]
[270, {"b": [["11666.20000", "15.23285881", "1596666908.183671"]], "c": "1224808479"}, "book-100", "XBT/USD"]
[270, {"b": [["11665.60000", "0.00000000", "1596666908.194788"], ["11612.30000", "7.00000000", "1596666617.080387", "r"]], "c": "3995388747"}, "book-100", "XBT/USD"]
[270, {"b": [["11660.20000", "0.33879780", "1596666908.200459"]], "c": "3995388747"}, "book-100", "XBT/USD"]
[270, {"a": [["11707.90000", "0.00000000", "1596666908.301999"], ["11718.40000", "0.48360000", "1596666846.374528", "r"]], "c": "3995388747"}, "book-100", "XBT/USD"]
[270, {"a": [["11670.40000", "0.60554049", "1596666908.343079"]], "c": "3427293764"}, "book-100", "XBT/USD"]
[270, {"a": [["11684.60000", "0.00000000", "1596666908.458432"], ["11718.50000", "24.30000000", "1596666641.380470", "r"]], "c": "3427293764"}, "book-100", "XBT/USD"]
[270, {"a": [["11674.00000", "0.00000000", "1596666908.505200"], ["11719.60000", "2.98021891", "1596666782.974175", "r"]], "c": "3427293764"}, "book-100", "XBT/USD"]
[270, {"a": [["11668.30000", "0.00236093", "1596666908.506736"]], "c": "3653693703"}, "book-100", "XBT/USD"]
[270, {"b": [["11663.80000", "0.09621094", "1596666909.311515"]], "c": "1528334125"}, "book-100", "XBT/USD"]
[270, {"b": [["11665.40000", "0.00000000", "1596666909.622112"], ["11613.00000", "0.17085000", "1596666803.224745", "r"]], "c": "3018048263"}, "book-100", "XBT/USD"]
[270, {"a": [["11686.90000", "0.74857071", "1596666909.651772"]], "c": "3018048263"}, "book-100", "XBT/USD"]
[270, {"b": [["11623.90000", "0.74857071", "1596666909.652790"]], "c": "3018048263"}, "book-100", "XBT/USD"]
[270, {"a": [["11687.40000", "3.52894721", "1596666909.653517"]], "c": "3018048263"}, "book-100", "XBT/USD"]
[270, {"b": [["11622.80000", "0.00000000", "1596666909.684841"], ["11613.00000", "0.17085000", "1596666803.224745", "r"]], "c": "3018048263"}, "book-100", "XBT/USD"]
[271, [["11666.20000", "0.02332600", "1596666910.155691", "s", "l", ""]], "trade", "XBT/USD"]
[270, {"b": [["11666.20000", "15.20953281", "1596666910.155691"]], "c": "2301440883"}, "book-100", "XBT/USD"]
[270, {"a": [["11682.20000", "0.85713744", "1596666910.208249"]], "c": "2301440883"}, "book-100", "XBT/USD"]
[270, {"a": [["11668.40000", "1.00275308", "1596666910.208374"]], "c": "1215083622"}, "book-100", "XBT/USD"]
[270, {"a": [["11680.20000", "2.82701228", "1596666910.209770"]], "c": "1215083622"}, "book-100", "XBT/USD"]
[270, {"b": [["11666.20000", "15.85238589", "1596666910.209865"]], "c": "3959863888"}, "book-100", "XBT/USD"]
[270, {"a": [["11670.90000", "0.01491298", "1596666910.238727"]], "c": "3703646825"}, "book-100", "XBT/USD"]
[270, {"a": [["11671.90000", "0.07456488", "1596666910.299964"]], "c": "3209513137"}, "book-100", "XBT/USD"]
[270, {"a": [["11669.20000", "0.64283421", "1596666910.344105"]], "c": "965825981"}, "book-100", "XBT/USD"]
[270, {"b": [["11660.30000", "0.07456692", "1596666910.345056"]], "c": "965825981"}, "book-100", "XBT/USD"]
[270, {"a": [["11673.40000", "0.17896061", "1596666910.355445"]], "c": "965825981"}, "book-100", "XBT/USD"]
[270, {"b": [["11646.90000", "0.00455610", "1596666910.382557"]], "c": "965825981"}, "book-100", "XBT/USD"]
[270, {"b": [["11662.20000", "0.00000000", "1596666910.424217"], ["11613.60000", "3.55198121", "1596666780.634357", "r"]], "c": "965825981"}, "book-100", "XBT/USD"]
[270, {"a": [["11701.50000", "0.00000000", "1596666910.424881"], ["11715.00000", "0.17085000", "1596666893.351638", "r"]], "c": "965825981"}, "book-100", "XBT/USD"]
[270, {"b": [["11660.70000", "1.51491298", "1596666910.434124"]], "c": "965825981"}, "book-100", "XBT/USD"]
[270, {"b": [["11658.50000", "0.17896096", "1596666910.464551"]], "c": "965825981"}, "book-100", "XBT/USD"]
[270, {"a": [["11704.50000", "2.24671246", "1596666910.642316"]], "c": "965825981"}, "book-100", "XBT/USD"]
[270, {"b": [["11661.00000", "0.08250000", "1596666910.671873"]], "c": "965825981"}, "book-100", "XBT/USD"]
[270, {"a": [["11676.30000", "0.08250000", "1596666910.674051"]], "c": "965825981"}, "book-100", "XBT/USD"]
[270, {"a": [["11668.30000", "0.00000000", "1596666910.772661"], ["11713.90000", "2.30673040", "1596666889.279950", "r"]], "c": "2414625954"}, "book-100", "XBT/USD"]
[270, {"a": [["11674.00000", "0.02763402", "1596666910.773076"]], "c": "2414625954"}, "book-100", "XBT/USD"]
[270, {"b": [["11665.50000", "0.64285308", "1596666911.033650"]], "c": "611795919"}, "book-100", "XBT/USD"]
[270, {"a": [["11670.30000", "0.25835060", "1596666911.295504"]], "c": "3178545557"}, "book-100", "XBT/USD"]
[270, {"b": [["11640.00000", "7.14000000", "1596666911.496830"]], "c": "3178545557"}, "book-100", "XBT/USD"]
[270, {"a": [["11671.40000", "0.09700000", "1596666912.169462"]], "c": "3210474561"}, "book-100", "XBT/USD"]
[270, {"b": [["11666.20000", "15.20953281", "1596666912.209460"]], "c": "1883573206"}, "book-100", "XBT/USD"]
[270, {"a": [["11682.20000", "0.00000000", "1596666912.212856"], ["11711.50000", "1.99898326", "1596666797.632161", "r"]], "c": "1883573206"}, "book-100", "XBT/USD"]
[270, {"b": [["11663.80000", "0.00000000", "1596666912.239183"], ["11615.60000", "0.20000000", "1596666623.308321", "r"]], "c": "4070276604"}, "book-100", "XBT/USD"]
[270, {"b": [["11663.00000", "0.00000000", "1596666912.239247"], ["11614.80000", "3.08717099", "1596666746.879208", "r"]], "c": "333374016"}, "book-100", "XBT/USD"]
[270, {"b": [["11665.70000", "0.00000000", "1596666912.240621"], ["11613.60000", "3.55198121", "1596666780.634357", "r"]], "c": "1396478206"}, "book-100", "XBT/USD"]
[270, {"b": [["11650.30000", "8.30000000", "1596666912.258366"]], "c": "1396478206"}, "book-100", "XBT/USD"]
[270, {"a": [["11670.70000", "0.09621094", "1596666912.258664"]], "c": "1783081030"}, "book-100", "XBT/USD"]
[270, {"a": [["11680.20000", "1.96990000", "1596666912.267724"]], "c": "1783081030"}, "book-100", "XBT/USD"]
[270, {"b": [["11665.50000", "0.00000000", "1596666912.269024"], ["11613.00000", "0.17085000", "1596666803.224745", "r"]], "c": "85620879"}, "book-100", "XBT/USD"]
[270, {"b": [["11662.00000", "0.09621094", "1596666912.270484"]], "c": "774497341"}, "book-100", "XBT/USD"]
[270, {"b": [["11666.20000", "14.95123132", "1596666912.272973"]], "c": "2186162424"}, "book-100", "XBT/USD"]
[270, {"b": [["11662.80000", "0.00000000", "1596666912.280192"], ["11613.00000", "0.17085000", "1596666803.224745", "r"]], "c": "1559610157"}, "book-100", "XBT/USD"]
[270, {"b": [["11666.20000", "14.73557132", "1596666912.282123"]], "c": "659257195"}, "book-100", "XBT/USD"]
[270, {"b": [["11656.40000", "0.00000000", "1596666912.301142"], ["11612.30000", "7.00000000", "1596666617.080387", "r"]], "c": "659257195"}, "book-100", "XBT/USD"]
[270, {"b": [["11657.80000", "0.00000000", "1596666912.304481"], ["11611.90000", "1.06000000", "1596666780.430510", "r"]], "c": "659257195"}, "book-100", "XBT/USD"]
[270, {"b": [["11656.90000", "0.72437808", "1596666912.306816"]], "c": "659257195"}, "book-100", "XBT/USD"]
[270, {"b": [["11656.90000", "0.00000000", "1596666912.307129"], ["11610.00000", "0.17085000", "1596666865.604704", "r"]], "c": "659257195"}, "book-100", "XBT/USD"]
[270, {"a": [["11670.40000", "0.56304049", "1596666912.307674"]], "c": "3419716634"}, "book-100", "XBT/USD"]
[270, {"b": [["11653.70000", "0.00000000", "1596666912.310949"], ["11609.80000", "21.20000000", "1596666704.766154", "r"]], "c": "3419716634"}, "book-100", "XBT/USD"]
[270, {"a": [["11677.70000", "0.00000000", "1596666912.311021"], ["11711.50000", "1.99898326", "1596666797.632161", "r"]], "c": "3419716634"}, "book-100", "XBT/USD"]
[270, {"b": [["11654.90000", "0.90056628", "1596666912.312415"]], "c": "3419716634"}, "book-100", "XBT/USD"]
[270, {"a": [["11669.20000", "0.00000000", "1596666912.318486"], ["11712.00000", "0.17085000", "1596666898.841793", "r"]], "c": "4103672996"}, "book-100", "XBT/USD"]
[270, {"b": [["11660.30000", "0.00000000", "1596666912.330589"], ["11609.30000", "2.01627299", "1596666817.684177", "r"]], "c": "4103672996"}, "book-100", "XBT/USD"]
[270, {"b": [["11660.70000", "1.50000000", "1596666912.331276"]], "c": "4103672996"}, "book-100", "XBT/USD"]
[270, {"b": [["11653.60000", "0.00000000", "1596666912.331922"], ["11607.70000", "8.40000000", "1596666861.504830", "r"]], "c": "4103672996"}, "book-100", "XBT/USD"]
[270, {"a": [["11670.40000", "0.00000000", "1596666912.338566"], ["11713.90000", "2.30673040", "1596666889.279950", "r"]], "c": "1827384451"}, "book-100", "XBT/USD"]
[270, {"b": [["11659.60000", "0.00000000", "1596666912.340182"], ["11607.00000", "0.17085000", "1596666870.943401", "r"]], "c": "1827384451"}, "book-100", "XBT/USD"]
[270, {"a": [["11667.70000", "0.09900000", "1596666912.342737"]], "c": "191952967"}, "book-100", "XBT/USD"]
[270, {"a": [["11672.60000", "0.09621094", "1596666912.359293"]], "c": "191952967"}, "book-100", "XBT/USD"]
[270, {"b": [["11660.00000", "0.00000000", "1596666912.359685"], ["11606.90000", "2.24671246", "1596666910.541859", "r"]], "c": "191952967"}, "book-100", "XBT/USD"]
[270, {"b": [["11646.10000", "0.00000000", "1596666912.360563"], ["11605.40000", "0.37412106", "1596666891.055682", "r"]], "c": "191952967"}, "book-100", "XBT/USD"]
[270, {"b": [["11655.30000", "0.00000000", "1596666912.360695"], ["11604.00000", "0.17085000", "1596666898.609631", "r"]], "c": "191952967"}, "book-100", "XBT/USD"]
[270, {"b": [["11665.80000", "0.00000000", "1596666912.361488"], ["11602.60000", "1.48021868", "1596666784.125874", "r"]], "c": "1406632045"}, "book-100", "XBT/USD"]
[270, {"b": [["11660.20000", "0.00000000", "1596666912.361975"], ["11602.20000", "6.32634371", "1596666815.593602", "r"]], "c": "1406632045"}, "book-100", "XBT/USD"]
[270, {"b": [["11663.40000", "0.00000000", "1596666912.363894"], ["11602.10000", "11.25550194", "1596666780.609892", "r"]], "c": "2595073560"}, "book-100", "XBT/USD"]
[270, {"a": [["11672.60000", "0.00000000", "1596666912.364147"], ["11713.90000", "2.30673040", "1596666889.279950", "r"]], "c": "2595073560"}, "book-100", "XBT/USD"]
[270, {"b": [["11655.80000", "0.00000000", "1596666912.364512"], ["11601.10000", "3.00166376", "1596666779.976375", "r"]], "c": "2595073560"}, "book-100", "XBT/USD"]
[270, {"b": [["11665.50000", "0.17729000", "1596666912.366398"]], "c": "1726911984"}, "book-100", "XBT/USD"]
[270, {"b": [["11659.10000", "0.75000000", "1596666912.377300"]], "c": "1726911984"}, "book-100", "XBT/USD"]
[270, {"a": [["11680.20000", "0.00000000", "1596666912.386341"], ["11715.00000", "0.17085000", "1596666893.351638", "r"]], "c": "1726911984"}, "book-100", "XBT/USD"]
[270, {"b": [["11653.80000", "3.11128122", "1596666912.388745"]], "c": "1726911984"}, "book-100", "XBT/USD"]
[270, {"b": [["11654.90000", "0.00000000", "1596666912.404093"], ["11602.10000", "11.25550194", "1596666780.609892", "r"]], "c": "1726911984"}, "book-100", "XBT/USD"]
[270, {"b": [["11645.10000", "0.03100000", "1596666912.409434"]], "c": "1726911984"}, "book-100", "XBT/USD"]
[270, {"a": [["11671.50000", "0.01000000", "1596666912.409581"]], "c": "1726911984"}, "book-100", "XBT/USD"]
[270, {"b": [["11651.70000", "2.00922252", "1596666912.410866"]], "c": "1726911984"}, "book-100", "XBT/USD"]
[270, {"b": [["11651.10000", "0.00000000", "1596666912.412490"], ["11602.10000", "11.25550194", "1596666780.609892", "r"]], "c": "1726911984"}, "book-100", "XBT/USD"]
[270, {"a": [["11679.60000", "0.00000000", "1596666912.416169"], ["11715.00000", "0.17085000", "1596666893.351638", "r"]], "c": "1726911984"}, "book-100", "XBT/USD"]
[270, {"a": [["11671.00000", "0.00000000", "1596666912.421815"], ["11715.30000", "6.10000000", "1596666635.445451", "r"]], "c": "1851165530"}, "book-100", "XBT/USD"]
[270, {"b": [["11651.70000", "0.00000000", "1596666912.434898"], ["11601.10000", "3.00166376", "1596666779.976375", "r"]], "c": "1851165530"}, "book-100", "XBT/USD"]
[270, {"a": [["11673.00000", "16.38671750", "1596666912.439355"]], "c": "1851165530"}, "book-100", "XBT/USD"]
[270, {"b": [["11664.20000", "0.00000000", "1596666912.442526"], ["11601.00000", "0.17085000", "1596666876.878632", "r"]], "c": "2534678172"}, "book-100", "XBT/USD"]
[270, {"b": [["11653.80000", "3.06908749", "1596666912.445084"]], "c": "2534678172"}, "book-100", "XBT/USD"]
[270, {"b": [["11653.70000", "0.04219410", "1596666912.448148"]], "c": "2534678172"}, "book-100", "XBT/USD"]
[270, {"b": [["11658.50000", "0.00000000", "1596666912.450417"], ["11601.00000", "0.17085000", "1596666876.878632", "r"]], "c": "2534678172"}, "book-100", "XBT/USD"]
[270, {"a": [["11675.70000", "1.96990000", "1596666912.461079"]], "c": "2534678172"}, "book-100", "XBT/USD"]
[270, {"a": [["11677.60000", "0.00000000", "1596666912.489202"], ["11715.30000", "6.10000000", "1596666635.445451", "r"]], "c": "2534678172"}, "book-100", "XBT/USD"]
[270, {"b": [["11658.60000", "0.04250000", "1596666912.504060"]], "c": "2534678172"}, "book-100", "XBT/USD"]
[270, {"a": [["11667.60000", "0.04250000", "1596666912.505869"]], "c": "1841140455"}, "book-100", "XBT/USD"]
[270, {"b": [["11648.10000", "0.00000000", "1596666912.507194"], ["11601.00000", "0.17085000", "1596666876.878632", "r"]], "c": "1841140455"}, "book-100", "XBT/USD"]
[270, {"b": [["11646.80000", "0.00000000", "1596666912.529009"], ["11600.50000", "3.54195852", "1596666820.729492", "r"]], "c": "1841140455"}, "book-100", "XBT/USD"]
[270, {"b": [["11657.30000", "0.00000000", "1596666912.533540"], ["11600.40000", "0.90458128", "1596666816.038277", "r"]], "c": "1841140455"}, "book-100", "XBT/USD"]
[270, {"a": [["11669.70000", "1.97050358", "1596666912.536264"]], "c": "841608753"}, "book-100", "XBT/USD"]
[270, {"a": [["11677.30000", "0.00000000", "1596666912.537162"], ["11715.00000", "0.17085000", "1596666893.351638", "r"]], "c": "841608753"}, "book-100", "XBT/USD"]
[270, {"a": [["11673.00000", "6.38671750", "1596666912.548799"]], "c": "841608753"}, "book-100", "XBT/USD"]
[270, {"a": [["11679.00000", "0.00000000", "1596666912.552481"], ["11715.30000", "6.10000000", "1596666635.445451", "r"]], "c": "841608753"}, "book-100", "XBT/USD"]
[270, {"b": [["11660.70000", "0.00000000", "1596666912.560639"], ["11600.10000", "0.05000000", "1596666747.910313", "r"]], "c": "841608753"}, "book-100", "XBT/USD"]
[270, {"a": [["11670.10000", "0.83872000", "1596666912.561288"]], "c": "3619882974"}, "book-100", "XBT/USD"]
[270, {"a": [["11671.50000", "0.00000000", "1596666912.587858"], ["11715.30000", "6.10000000", "1596666635.445451", "r"]], "c": "3619882974"}, "book-100", "XBT/USD"]
[270, {"b": [["11645.10000", "0.00000000", "1596666912.588778"], ["11600.00000", "0.02931034", "1596666720.289823", "r"]], "c": "3619882974"}, "book-100", "XBT/USD"]
[270, {"b": [["11664.80000", "0.00000000", "1596666912.595617"], ["11599.60000", "3.04585670", "1596666779.021471", "r"]], "c": "441616490"}, "book-100", "XBT/USD"]
[270, {"a": [["11669.40000", "0.00000000", "1596666912.597681"], ["11717.80000", "1.99812614", "1596666759.535617", "r"]], "c": "222462685"}, "book-100", "XBT/USD"]
[270, {"b": [["11650.00000", "7.09644035", "1596666912.599330"]], "c": "222462685"}, "book-100", "XBT/USD"]
[270, {"b": [["11658.40000", "0.00000000", "1596666912.602776"], ["11598.80000", "10.88860000", "1596666792.969132", "r"]], "c": "222462685"}, "book-100", "XBT/USD"]
[270, {"a": [["11679.30000", "0.00000000", "1596666912.603985"], ["11718.00000", "0.17085000", "1596666865.758675", "r"]], "c": "222462685"}, "book-100", "XBT/USD"]
[270, {"a": [["11673.90000", "0.69956287", "1596666912.605902"]], "c": "222462685"}, "book-100", "XBT/USD"]
[270, {"a": [["11679.10000", "0.00000000", "1596666912.607665"], ["11718.00000", "0.17085000", "1596666865.758675", "r"]], "c": "222462685"}, "book-100", "XBT/USD"]
[270, {"b": [["11650.20000", "0.00000000", "1596666912.611610"], ["11598.00000", "0.17085000", "1596666904.022538", "r"]], "c": "222462685"}, "book-100", "XBT/USD"]
[270, {"a": [["11692.20000", "1.20742827", "1596666912.614023"]], "c": "222462685"}, "book-100", "XBT/USD"]
[270, {"a": [["11692.20000", "0.00000000", "1596666912.621186"], ["11718.40000", "0.48360000", "1596666846.374528", "r"]], "c": "222462685"}, "book-100", "XBT/USD"]
[270, {"b": [["11650.60000", "0.00000000", "1596666912.621245"], ["11597.60000", "19.10000000", "1596666887.863569", "r"]], "c": "222462685"}, "book-100", "XBT/USD"]
[270, {"b": [["11646.80000", "0.34984638", "1596666912.621783"]], "c": "222462685"}, "book-100", "XBT/USD"]
[270, {"b": [["11650.30000", "8.54981520", "1596666912.624766"]], "c": "222462685"}, "book-100", "XBT/USD"]
[270, {"b": [["11644.10000", "0.03100000", "1596666912.639545"]], "c": "222462685"}, "book-100", "XBT/USD"]
[270, {"a": [["11670.10000", "0.84872000", "1596666912.639620"]], "c": "2555838476"}, "book-100", "XBT/USD"]
[270, {"b": [["11648.90000", "0.00000000", "1596666912.648770"], ["11598.00000", "0.17085000", "1596666904.022538", "r"]], "c": "2555838476"}, "book-100", "XBT/USD"]
[270, {"b": [["11647.30000", "0.49823715", "1596666912.654186"]], "c": "2555838476"}, "book-100", "XBT/USD"]
[270, {"b": [["11647.80000", "0.90111523", "1596666912.654784"]], "c": "2555838476"}, "book-100", "XBT/USD"]
[270, {"a": [["11667.60000", "0.50513918", "1596666912.659965"]], "c": "959747949"}, "book-100", "XBT/USD"]
[270, {"b": [["11647.70000", "3.54067171", "1596666912.662220"]], "c": "959747949"}, "book-100", "XBT/USD"]
[270, {"a": [["11672.70000", "0.55156860", "1596666912.675455"]], "c": "959747949"}, "book-100", "XBT/USD"]
[270, {"a": [["11673.00000", "4.27400000", "1596666912.676390"]], "c": "959747949"}, "book-100", "XBT/USD"]
[270, {"b": [["11652.30000", "0.10352500", "1596666912.682472"]], "c": "959747949"}, "book-100", "XBT/USD"]
[270, {"b": [["11650.00000", "7.82125841", "1596666912.683479"]], "c": "959747949"}, "book-100", "XBT/USD"]
[270, {"a": [["11676.90000", "0.00000000", "1596666912.708202"], ["11718.40000", "0.48360000", "1596666846.374528", "r"]], "c": "959747949"}, "book-100", "XBT/USD"]
[270, {"b": [["11657.80000", "1.50000000", "1596666912.709613"]], "c": "959747949"}, "book-100", "XBT/USD"]
[270, {"b": [["11661.50000", "0.57230000", "1596666912.729816"]], "c": "3760909459"}, "book-100", "XBT/USD"]
[270, {"a": [["11668.40000", "0.64285308", "1596666912.751282"]], "c": "3404487013"}, "book-100", "XBT/USD"]
[270, {"b": [["11642.50000", "0.99688513", "1596666912.754111"]], "c": "3404487013"}, "book-100", "XBT/USD"]
[270, {"a": [["11669.60000", "0.46204702", "1596666912.764633"]], "c": "2694428249"}, "book-100", "XBT/USD"]
[270, {"b": [["11653.90000", "0.47292060", "1596666912.765030"]], "c": "2694428249"}, "book-100", "XBT/USD"]
[270, {"a": [["11682.40000", "0.10325670", "1596666912.765482"]], "c": "2694428249"}, "book-100", "XBT/USD"]
[270, {"b": [["11639.20000", "2.01137929", "1596666912.767938"]], "c": "2694428249"}, "book-100", "XBT/USD"]
[270, {"b": [["11645.00000", "2.01037749", "1596666912.768751"]], "c": "2694428249"}, "book-100", "XBT/USD"]
[270, {"b": [["11661.20000", "4.28600000", "1596666912.807488"]], "c": "449669287"}, "book-100", "XBT/USD"]
[270, {"b": [["11665.50000", "0.00000000", "1596666912.827624"], ["11602.10000", "11.25550194", "1596666780.609892", "r"]], "c": "145830258"}, "book-100", "XBT/USD"]
[270, {"a": [["11677.70000", "0.11078149", "1596666912.827688"]], "c": "145830258"}, "book-100", "XBT/USD"]
[270, {"a": [["11689.10000", "1.20742921", "1596666912.854645"]], "c": "145830258"}, "book-100", "XBT/USD"]
[270, {"b": [["11645.10000", "1.21199137", "1596666912.862731"]], "c": "145830258"}, "book-100", "XBT/USD"]
[270, {"b": [["11643.10000", "0.57493027", "1596666912.864689"]], "c": "145830258"}, "book-100", "XBT/USD"]
[270, {"b": [["11662.00000", "0.00000000", "1596666912.875065"], ["11602.20000", "6.32634371", "1596666815.593602", "r"]], "c": "3049036711"}, "book-100", "XBT/USD"]
[270, {"a": [["11681.50000", "6.50000000", "1596666912.883921"]], "c": "3049036711"}, "book-100", "XBT/USD"]
[270, {"b": [["11650.70000", "4.00000000", "1596666912.893556"]], "c": "3049036711"}, "book-100", "XBT/USD"]
[270, {"a": [["11668.50000", "0.79810990", "1596666912.896155"]], "c": "1944754561"}, "book-100", "XBT/USD"]
[270, {"a": [["11688.00000", "0.00000000", "1596666912.904341"], ["11715.30000", "6.10000000", "1596666635.445451", "r"]], "c": "1944754561"}, "book-100", "XBT/USD"]
[270, {"b": [["11651.30000", "0.90084454", "1596666912.906937"]], "c": "1944754561"}, "book-100", "XBT/USD"]
[270, {"a": [["11692.10000", "0.61106020", "1596666912.908628"]], "c": "1944754561"}, "book-100", "XBT/USD"]
[270, {"a": [["11706.90000", "0.00000000", "1596666912.911357"], ["11717.80000", "1.99812614", "1596666759.535617", "r"]], "c": "1944754561"}, "book-100", "XBT/USD"]
[270, {"b": [["11636.20000", "0.90201354", "1596666912.913762"]], "c": "1944754561"}, "book-100", "XBT/USD"]
[270, {"b": [["11659.10000", "0.00000000", "1596666912.918683"], ["11604.00000", "0.17085000", "1596666898.609631", "r"]], "c": "1653902023"}, "book-100", "XBT/USD"]
[270, {"a": [["11667.00000", "0.35990000", "1596666912.927513"]], "c": "4046047221"}, "book-100", "XBT/USD"]
[270, {"a": [["11666.30000", "0.50000000", "1596666912.982709"]], "c": "71744482"}, "book-100", "XBT/USD"]
[270, {"b": [["11661.70000", "0.00000000", "1596666913.015791"], ["11602.60000", "1.48021868", "1596666784.125874", "r"]], "c": "3459985530"}, "book-100", "XBT/USD"]
[270, {"a": [["11676.50000", "0.00000000", "1596666913.016553"], ["11715.30000", "6.10000000", "1596666635.445451", "r"]], "c": "3459985530"}, "book-100", "XBT/USD"]
[270, {"a": [["11688.90000", "2.00282712", "1596666913.065632"]], "c": "3459985530"}, "book-100", "XBT/USD"]
[270, {"b": [["11660.80000", "0.75000000", "1596666913.077440"]], "c": "4161890171"}, "book-100", "XBT/USD"]
[270, {"b": [["11648.90000", "0.30000000", "1596666913.096624"]], "c": "4161890171"}, "book-100", "XBT/USD"]
[270, {"a": [["11676.40000", "0.00000000", "1596666913.103870"], ["11715.30000", "6.10000000", "1596666635.445451", "r"]], "c": "4161890171"}, "book-100", "XBT/USD"]
[270, {"a": [["11667.60000", "1.49579918", "1596666913.106403"]], "c": "3833343840"}, "book-100", "XBT/USD"]
[270, {"a": [["11674.10000", "0.78551326", "1596666913.137502"]], "c": "3833343840"}, "book-100", "XBT/USD"]
[270, {"a": [["11667.60000", "1.03316000", "1596666913.156401"]], "c": "1659433404"}, "book-100", "XBT/USD"]
[270, {"b": [["11651.20000", "0.85720737", "1596666913.161784"]], "c": "1659433404"}, "book-100", "XBT/USD"]
[270, {"b": [["11655.50000", "0.85743819", "1596666913.161886"]], "c": "1659433404"}, "book-100", "XBT/USD"]
[270, {"a": [["11667.30000", "0.64298213", "1596666913.162094"]], "c": "2185165294"}, "book-100", "XBT/USD"]
[270, {"a": [["11667.40000", "0.64298213", "1596666913.162254"]], "c": "3714751398"}, "book-100", "XBT/USD"]
[270, {"a": [["11667.50000", "0.85743819", "1596666913.163130"]], "c": "3978460294"}, "book-100", "XBT/USD"]
[270, {"b": [["11647.20000", "0.85743819", "1596666913.164011"]], "c": "3978460294"}, "book-100", "XBT/USD"]
[270, {"a": [["11667.60000", "1.89059819", "1596666913.164138"]], "c": "1724950489"}, "book-100", "XBT/USD"]
[270, {"a": [["11670.70000", "0.95341831", "1596666913.164360"]], "c": "1724950489"}, "book-100", "XBT/USD"]
[270, {"b": [["11649.00000", "0.85730951", "1596666913.164459"]], "c": "1724950489"}, "book-100", "XBT/USD"]
[270, {"b": [["11650.40000", "0.85725214", "1596666913.166082"]], "c": "1724950489"}, "book-100", "XBT/USD"]
[270, {"b": [["11619.00000", "7.00000000", "1596666913.171017"]], "c": "1724950489"}, "book-100", "XBT/USD"]
[270, {"b": [["11640.40000", "0.00000000", "1596666913.173978"], ["11609.30000", "2.01627299", "1596666817.684177", "r"]], "c": "1724950489"}, "book-100", "XBT/USD"]
[270, {"a": [["11668.40000", "0.00000000", "1596666913.199508"], ["11713.90000", "2.30673040", "1596666889.279950", "r"]], "c": "4165326042"}, "book-100", "XBT/USD"]
[270, {"b": [["11660.90000", "0.00000000", "1596666913.200448"], ["11607.70000", "8.40000000", "1596666861.504830", "r"]], "c": "2215202126"}, "book-100", "XBT/USD"]
[270, {"a": [["11675.80000", "7.20000000", "1596666913.211513"]], "c": "2215202126"}, "book-100", "XBT/USD"]
[270, {"b": [["11656.60000", "0.33893100", "1596666913.215328"]], "c": "2215202126"}, "book-100", "XBT/USD"]
[270, {"b": [["11650.90000", "1.42420661", "1596666913.215399"]], "c": "2215202126"}, "book-100", "XBT/USD"]
[270, {"a": [["11677.30000", "0.33833018", "1596666913.219468"]], "c": "2215202126"}, "book-100", "XBT/USD"]
[270, {"b": [["11653.20000", "0.71196276", "1596666913.219678"]], "c": "2215202126"}, "book-100", "XBT/USD"]
[270, {"a": [["11669.60000", "0.00000000", "1596666913.233243"], ["11712.00000", "0.17085000", "1596666898.841793", "r"]], "c": "1415065104"}, "book-100", "XBT/USD"]
[270, {"a": [["11688.90000", "3.79419758", "1596666913.244785"]], "c": "1415065104"}, "book-100", "XBT/USD"]
[270, {"a": [["11667.30000", "0.00000000", "1596666913.245471"], ["11713.90000", "2.30673040", "1596666889.279950", "r"]], "c": "3041495799"}, "book-100", "XBT/USD"]
[270, {"b": [["11645.10000", "3.01009960", "1596666913.252065"]], "c": "3041495799"}, "book-100", "XBT/USD"]
[270, {"a": [["11685.40000", "0.49661266", "1596666913.272221"]], "c": "3041495799"}, "book-100", "XBT/USD"]
[270, {"a": [["11674.70000", "0.46285621", "1596666913.273909"]], "c": "3041495799"}, "book-100", "XBT/USD"]
[270, {"b": [["11616.00000", "0.00000000", "1596666913.362085"], ["11609.80000", "21.20000000", "1596666704.766154", "r"]], "c": "3041495799"}, "book-100", "XBT/USD"]
[270, {"a": [["11692.10000", "0.00000000", "1596666913.362682"], ["11712.00000", "0.17085000", "1596666898.841793", "r"]], "c": "3041495799"}, "book-100", "XBT/USD"]
[270, {"a": [["11670.30000", "0.00000000", "1596666913.373389"], ["11713.90000", "2.30673040", "1596666889.279950", "r"]], "c": "2466870176"}, "book-100", "XBT/USD"]
[270, {"a": [["11670.10000", "0.83872000", "1596666913.434267"]], "c": "4140470205"}, "book-100", "XBT/USD"]
[270, {"a": [["11666.30000", "0.93277220", "1596666913.472818"]], "c": "76485204"}, "book-100", "XBT/USD"]
[270, {"a": [["11667.40000", "0.90138874", "1596666913.474257"]], "c": "2332516483"}, "book-100", "XBT/USD"]
[270, {"a": [["11670.50000", "0.09523969", "1596666913.493778"]], "c": "1554532411"}, "book-100", "XBT/USD"]
[270, {"b": [["11645.20000", "0.43800000", "1596666913.538263"]], "c": "1554532411"}, "book-100", "XBT/USD"]
[270, {"b": [["11650.50000", "0.09800000", "1596666913.543644"]], "c": "1554532411"}, "book-100", "XBT/USD"]
[270, {"a": [["11685.50000", "0.52462342", "1596666913.551023"]], "c": "1554532411"}, "book-100", "XBT/USD"]
[270, {"b": [["11645.00000", "5.21877069", "1596666913.556818"]], "c": "1554532411"}, "book-100", "XBT/USD"]
[270, {"b": [["11646.90000", "0.00000000", "1596666913.598826"], ["11610.00000", "0.17085000", "1596666865.604704", "r"]], "c": "1554532411"}, "book-100", "XBT/USD"]
[270, {"a": [["11681.40000", "0.00438186", "1596666913.602763"]], "c": "1554532411"}, "book-100", "XBT/USD"]
[270, {"b": [["11661.20000", "0.00000000", "1596666913.626020"], ["11609.80000", "21.20000000", "1596666704.766154", "r"]], "c": "2751438633"}, "book-100", "XBT/USD"]
[270, {"a": [["11668.50000", "0.00000000", "1596666913.811240"], ["11712.00000", "0.17085000", "1596666898.841793", "r"]], "c": "1497805017"}, "book-100", "XBT/USD"]
[270, {"a": [["11667.70000", "0.00000000", "1596666913.905273"], ["11713.90000", "2.30673040", "1596666889.279950", "r"]], "c": "2329955400"}, "book-100", "XBT/USD"]
[270, {"a": [["11701.20000", "19.60000000", "1596666913.915921"]], "c": "2329955400"}, "book-100", "XBT/USD"]
[270, {"b": [["11647.20000", "0.00000000", "1596666913.935713"], ["11609.30000", "2.01627299", "1596666817.684177", "r"]], "c": "2329955400"}, "book-100", "XBT/USD"]
[270, {"a": [["11668.40000", "0.80309074", "1596666914.081774"]], "c": "4251738403"}, "book-100", "XBT/USD"]
[270, {"a": [["11700.60000", "1.95840740", "1596666914.131479"]], "c": "4251738403"}, "book-100", "XBT/USD"]
[270, {"b": [["11658.80000", "0.00000000", "1596666914.140154"], ["11607.70000", "8.40000000", "1596666861.504830", "r"]], "c": "1389564798"}, "book-100", "XBT/USD"]
[270, {"b": [["11658.10000", "0.09900000", "1596666914.152722"]], "c": "1628996434"}, "book-100", "XBT/USD"]
[270, {"a": [["11667.40000", "0.25840661", "1596666914.163443"]], "c": "209747487"}, "book-100", "XBT/USD"]
[270, {"b": [["11662.70000", "4.27800000", "1596666914.164614"]], "c": "496310416"}, "book-100", "XBT/USD"]
[270, {"b": [["11652.00000", "0.00000000", "1596666914.168219"], ["11609.30000", "2.01627299", "1596666817.684177", "r"]], "c": "496310416"}, "book-100", "XBT/USD"]
[270, {"b": [["11648.10000", "0.82500000", "1596666914.171014"]], "c": "496310416"}, "book-100", "XBT/USD"]
[270, {"a": [["11692.20000", "0.72500000", "1596666914.174012"]], "c": "496310416"}, "book-100", "XBT/USD"]
[270, {"a": [["11697.00000", "0.00000000", "1596666914.181435"], ["11711.10000", "0.75800000", "1596666806.349295", "r"]], "c": "496310416"}, "book-100", "XBT/USD"]
[270, {"b": [["11660.80000", "0.00000000", "1596666914.234885"], ["11609.30000", "2.01627299", "1596666817.684177", "r"]], "c": "1320666192"}, "book-100", "XBT/USD"]
[270, {"a": [["11668.40000", "0.00000000", "1596666914.392386"], ["11711.50000", "1.99898326", "1596666797.632161", "r"]], "c": "960227643"}, "book-100", "XBT/USD"]
[270, {"a": [["11685.50000", "0.00000000", "1596666914.418415"], ["11712.00000", "0.17085000", "1596666898.841793", "r"]], "c": "960227643"}, "book-100", "XBT/USD"]
[270, {"a": [["11672.70000", "0.00000000", "1596666914.420049"], ["11713.90000", "2.30673040", "1596666889.279950", "r"]], "c": "960227643"}, "book-100", "XBT/USD"]
[270, {"b": [["11661.70000", "0.75000000", "1596666914.439945"]], "c": "2040175031"}, "book-100", "XBT/USD"]
[270, {"b": [["11653.70000", "0.00000000", "1596666914.590130"], ["11609.30000", "2.01627299", "1596666817.684177", "r"]], "c": "2040175031"}, "book-100", "XBT/USD"]
[270, {"b": [["11653.90000", "0.49097782", "1596666914.590573"]], "c": "2040175031"}, "book-100", "XBT/USD"]
[270, {"a": [["11672.70000", "0.50098793", "1596666914.605045"]], "c": "2040175031"}, "book-100", "XBT/USD"]
[270, {"a": [["11685.50000", "0.57455939", "1596666914.609744"]], "c": "2040175031"}, "book-100", "XBT/USD"]
[270, {"a": [["11667.30000", "0.81350727", "1596666914.625490"]], "c": "717417042"}, "book-100", "XBT/USD"]
[271, [["11666.20000", "0.02332600", "1596666914.686007", "s", "l", ""]], "trade", "XBT/USD"]
[270, {"b": [["11666.20000", "14.71224532", "1596666914.686007"]], "c": "2485176796"}, "book-100", "XBT/USD"]
[270, {"a": [["11668.70000", "0.09700000", "1596666914.756503"]], "c": "2640354826"}, "book-100", "XBT/USD"]
[270, {"b": [["11645.80000", "0.00000000", "1596666914.790842"], ["11607.70000", "8.40000000", "1596666861.504830", "r"]], "c": "2640354826"}, "book-100", "XBT/USD"]
