[270, {"a": [["11646.90000", "0.00000000", "1596666698.661190"], ["11706.00000", "0.17085000", "1596666669.832774", "r"]], "c": "4131924453"}, "book-100", "XBT/USD"]
[270, {"a": [["11659.60000", "0.10348648", "1596666698.681813"]], "c": "4131924453"}, "book-100", "XBT/USD"]
[270, {"a": [["11661.90000", "0.72426246", "1596666698.686038"]], "c": "4131924453"}, "book-100", "XBT/USD"]
[270, {"a": [["11664.20000", "3.53657250", "1596666698.751976"]], "c": "4131924453"}, "book-100", "XBT/USD"]
[270, {"a": [["11664.20000", "4.03412406", "1596666698.767277"]], "c": "4131924453"}, "book-100", "XBT/USD"]
[270, {"b": [["11640.00000", "1.57942622", "1596666698.790302"]], "c": "3435430246"}, "book-100", "XBT/USD"]
[270, {"b": [["11639.60000", "0.10000000", "1596666698.800300"]], "c": "38027548"}, "book-100", "XBT/USD"]
[270, {"a": [["11648.10000", "0.00000000", "1596666698.805125"], ["11704.20000", "1.06000000", "1596666647.223134", "r"]], "c": "1047363772"}, "book-100", "XBT/USD"]
[270, {"a": [["11648.70000", "1.50000000", "1596666698.816706"]], "c": "716383003"}, "book-100", "XBT/USD"]
[270, {"a": [["11648.00000", "0.00000000", "1596666698.852017"], ["11704.20000", "1.06000000", "1596666647.223134", "r"]], "c": "1533875763"}, "book-100", "XBT/USD"]
[270, {"a": [["11657.00000", "8.91147292", "1596666698.870770"]], "c": "1533875763"}, "book-100", "XBT/USD"]
[270, {"a": [["11645.20000", "0.00000000", "1596666698.872442"], ["11705.90000", "4.41315145", "1596666428.485819", "r"]], "c": "2542761552"}, "book-100", "XBT/USD"]
[270, {"a": [["11665.40000", "1.24946098", "1596666698.899262"]], "c": "2542761552"}, "book-100", "XBT/USD"]
[270, {"b": [["11640.00000", "2.06992622", "1596666698.912540"]], "c": "1278313610"}, "book-100", "XBT/USD"]
[270, {"b": [["11629.20000", "0.00000000", "1596666698.971062"], ["11589.00000", "0.17085000", "1596666680.844319", "r"]], "c": "1278313610"}, "book-100", "XBT/USD"]
[270, {"a": [["11653.70000", "0.00000000", "1596666699.006171"], ["11706.00000", "0.17085000", "1596666669.832774", "r"]], "c": "1278313610"}, "book-100", "XBT/USD"]
[270, {"b": [["11637.10000", "0.00000000", "1596666699.026024"], ["11588.60000", "0.75800000", "1596666599.475365", "r"]], "c": "1278313610"}, "book-100", "XBT/USD"]
[270, {"b": [["11640.00000", "6.36192622", "1596666699.048471"]], "c": "1035943715"}, "book-100", "XBT/USD"]
[270, {"a": [["11646.80000", "4.54487819", "1596666699.052438"]], "c": "1573375349"}, "book-100", "XBT/USD"]
[270, {"a": [["11657.10000", "0.00000000", "1596666699.061432"], ["11706.10000", "3.50960038", "1596666142.533745", "r"]], "c": "1573375349"}, "book-100", "XBT/USD"]
[270, {"b": [["11638.50000", "0.15000000", "1596666699.086081"]], "c": "20758814"}, "book-100", "XBT/USD"]
[270, {"a": [["11647.50000", "0.45120003", "1596666699.129891"]], "c": "4171714658"}, "book-100", "XBT/USD"]
[270, {"a": [["11650.30000", "1.49441436", "1596666699.213126"]], "c": "4171714658"}, "book-100", "XBT/USD"]
[270, {"a": [["11647.90000", "0.71417128", "1596666699.218144"]], "c": "840432129"}, "book-100", "XBT/USD"]
[270, {"a": [["11703.00000", "0.00000000", "1596666699.282726"], ["11706.10000", "3.50960038", "1596666142.533745", "r"]], "c": "840432129"}, "book-100", "XBT/USD"]
[270, {"b": [["11639.50000", "0.23000000", "1596666699.302672"]], "c": "4045252049"}, "book-100", "XBT/USD"]
[270, {"a": [["11662.70000", "0.00000000", "1596666699.320368"], ["11709.00000", "0.17085000", "1596666698.599816", "r"]], "c": "4045252049"}, "book-100", "XBT/USD"]
[270, {"a": [["11662.60000", "0.00000000", "1596666699.331204"], ["11709.60000", "4.27000068", "1596666650.408245", "r"]], "c": "4045252049"}, "book-100", "XBT/USD"]
[270, {"a": [["11662.40000", "0.00000000", "1596666699.336814"], ["11709.70000", "7.20507863", "1596666620.257365", "r"]], "c": "4045252049"}, "book-100", "XBT/USD"]
[270, {"b": [["11640.00000", "5.87142622", "1596666699.414326"]], "c": "1896443429"}, "book-100", "XBT/USD"]
[270, {"a": [["11706.00000", "0.00000000", "1596666699.443326"], ["11711.00000", "3.52207482", "1596666594.088624", "r"]], "c": "1896443429"}, "book-100", "XBT/USD"]
[270, {"a": [["11676.60000", "0.00000000", "1596666699.561466"], ["11711.10000", "2.97327583", "1596666596.503005", "r"]], "c": "1896443429"}, "book-100", "XBT/USD"]
[270, {"a": [["11649.40000", "1.71000000", "1596666699.802182"]], "c": "2685978949"}, "book-100", "XBT/USD"]
[270, {"a": [["11655.10000", "0.85899436", "1596666699.831754"]], "c": "2685978949"}, "book-100", "XBT/USD"]
[270, {"b": [["11640.00000", "6.51553838", "1596666699.857094"]], "c": "1589295908"}, "book-100", "XBT/USD"]
[270, {"a": [["11650.60000", "0.85872032", "1596666699.858543"]], "c": "1589295908"}, "book-100", "XBT/USD"]
[270, {"b": [["11639.90000", "0.64411216", "1596666699.887213"]], "c": "696851154"}, "book-100", "XBT/USD"]
[270, {"a": [["11658.90000", "0.85881622", "1596666699.901804"]], "c": "696851154"}, "book-100", "XBT/USD"]
[270, {"b": [["11639.80000", "0.64411216", "1596666699.908672"]], "c": "4294256392"}, "book-100", "XBT/USD"]
[270, {"a": [["11650.20000", "0.97665861", "1596666699.922399"]], "c": "4294256392"}, "book-100", "XBT/USD"]
[270, {"b": [["11637.30000", "0.85886294", "1596666699.940916"]], "c": "4294256392"}, "book-100", "XBT/USD"]
[270, {"a": [["11659.20000", "0.95490000", "1596666699.945826"]], "c": "4294256392"}, "book-100", "XBT/USD"]
[270, {"a": [["11648.20000", "0.64404024", "1596666699.946940"]], "c": "2870860355"}, "book-100", "XBT/USD"]
[270, {"a": [["11657.20000", "0.85886294", "1596666699.947651"]], "c": "2870860355"}, "book-100", "XBT/USD"]
[270, {"b": [["11638.20000", "0.85877308", "1596666699.948357"]], "c": "2637187889"}, "book-100", "XBT/USD"]
[270, {"b": [["11624.10000", "1.04540000", "1596666699.950073"]], "c": "2637187889"}, "book-100", "XBT/USD"]
[270, {"a": [["11649.00000", "0.64392991", "1596666699.951815"]], "c": "2637187889"}, "book-100", "XBT/USD"]
[270, {"a": [["11655.40000", "0.00000000", "1596666699.952808"], ["11705.90000", "4.41315145", "1596666428.485819", "r"]], "c": "2637187889"}, "book-100", "XBT/USD"]
[270, {"a": [["11649.40000", "0.00000000", "1596666699.953142"], ["11706.10000", "3.50960038", "1596666142.533745", "r"]], "c": "2637187889"}, "book-100", "XBT/USD"]
[270, {"a": [["11660.90000", "0.85867306", "1596666699.956048"]], "c": "2637187889"}, "book-100", "XBT/USD"]
[270, {"a": [["11676.90000", "1.98818681", "1596666699.997837"]], "c": "2637187889"}, "book-100", "XBT/USD"]
[270, {"b": [["11640.00000", "6.81553838", "1596666700.016825"]], "c": "2946076250"}, "book-100", "XBT/USD"]
[270, {"b": [["11618.30000", "0.00000000", "1596666700.019077"], ["11590.20000", "0.90571082", "1596666644.915161", "r"]], "c": "2946076250"}, "book-100", "XBT/USD"]
[270, {"b": [["11640.00000", "7.30603838", "1596666700.019673"]], "c": "3802613829"}, "book-100", "XBT/USD"]
[270, {"a": [["11680.60000", "0.66743977", "1596666700.051068"]], "c": "3802613829"}, "book-100", "XBT/USD"]
[270, {"a": [["11658.40000", "0.69745456", "1596666700.059243"]], "c": "3802613829"}, "book-100", "XBT/USD"]
[270, {"a": [["11658.00000", "0.70004396", "1596666700.087704"]], "c": "3802613829"}, "book-100", "XBT/USD"]
[270, {"a": [["11701.70000", "3.00242295", "1596666700.111068"]], "c": "3802613829"}, "book-100", "XBT/USD"]
[270, {"a": [["11648.20000", "0.00000000", "1596666700.172893"], ["11702.50000", "23.57900000", "1596666155.599282", "r"]], "c": "1958162888"}, "book-100", "XBT/USD"]
[270, {"a": [["11646.80000", "4.28600000", "1596666700.189070"]], "c": "147399357"}, "book-100", "XBT/USD"]
[270, {"a": [["11660.70000", "0.00000000", "1596666700.190438"], ["11704.10000", "8.30000000", "1596666665.290916", "r"]], "c": "147399357"}, "book-100", "XBT/USD"]
[270, {"a": [["11665.00000", "2.29920000", "1596666700.194612"]], "c": "147399357"}, "book-100", "XBT/USD"]
[270, {"a": [["11660.30000", "0.00000000", "1596666700.224809"], ["11704.20000", "1.06000000", "1596666647.223134", "r"]], "c": "147399357"}, "book-100", "XBT/USD"]
[270, {"a": [["11663.20000", "0.00000000", "1596666700.229824"], ["11705.90000", "4.41315145", "1596666428.485819", "r"]], "c": "147399357"}, "book-100", "XBT/USD"]
[270, {"a": [["11663.40000", "6.10000000", "1596666700.231163"]], "c": "147399357"}, "book-100", "XBT/USD"]
[270, {"a": [["11650.60000", "0.00000000", "1596666700.235433"], ["11706.10000", "3.50960038", "1596666142.533745", "r"]], "c": "147399357"}, "book-100", "XBT/USD"]
[270, {"a": [["11669.60000", "2.00661056", "1596666700.272966"]], "c": "147399357"}, "book-100", "XBT/USD"]
[270, {"a": [["11675.00000", "0.01821000", "1596666700.341634"]], "c": "147399357"}, "book-100", "XBT/USD"]
[270, {"a": [["11650.30000", "0.10300000", "1596666700.427712"]], "c": "147399357"}, "book-100", "XBT/USD"]
[270, {"a": [["11647.40000", "0.25885147", "1596666700.494484"]], "c": "2252600533"}, "book-100", "XBT/USD"]
[270, {"a": [["11663.40000", "6.34955565", "1596666700.512737"]], "c": "2252600533"}, "book-100", "XBT/USD"]
[270, {"a": [["11671.60000", "0.57357475", "1596666700.514251"]], "c": "2252600533"}, "book-100", "XBT/USD"]
[270, {"a": [["11668.80000", "1.74673122", "1596666700.567166"]], "c": "2252600533"}, "book-100", "XBT/USD"]
[270, {"b": [["11638.90000", "0.04250000", "1596666700.594246"]], "c": "3602188305"}, "book-100", "XBT/USD"]
[270, {"b": [["11640.00000", "9.01603838", "1596666700.604974"]], "c": "1599376680"}, "book-100", "XBT/USD"]
[270, {"b": [["11639.00000", "0.00000000", "1596666700.609022"], ["11590.10000", "1.51500000", "1596666649.220608", "r"]], "c": "993224254"}, "book-100", "XBT/USD"]
[270, {"a": [["11650.10000", "2.58328628", "1596666700.614319"]], "c": "993224254"}, "book-100", "XBT/USD"]
[270, {"a": [["11655.00000", "1.32403857", "1596666700.648764"]], "c": "993224254"}, "book-100", "XBT/USD"]
[270, {"a": [["11647.50000", "0.00000000", "1596666700.754428"], ["11704.10000", "8.30000000", "1596666665.290916", "r"]], "c": "2351050416"}, "book-100", "XBT/USD"]
[270, {"a": [["11650.10000", "0.87728628", "1596666700.790890"]], "c": "2351050416"}, "book-100", "XBT/USD"]
[270, {"a": [["11655.60000", "0.50000000", "1596666700.887041"]], "c": "2351050416"}, "book-100", "XBT/USD"]
[270, {"a": [["11667.20000", "0.00000000", "1596666700.935588"], ["11704.10000", "8.30000000", "1596666665.290916", "r"]], "c": "2351050416"}, "book-100", "XBT/USD"]
[270, {"a": [["11676.70000", "0.00000000", "1596666700.948650"], ["11704.20000", "1.06000000", "1596666647.223134", "r"]], "c": "2351050416"}, "book-100", "XBT/USD"]
[270, {"a": [["11665.50000", "0.00000000", "1596666700.959172"], ["11705.90000", "4.41315145", "1596666428.485819", "r"]], "c": "2351050416"}, "book-100", "XBT/USD"]
[270, {"a": [["11665.60000", "0.00000000", "1596666700.961495"], ["11706.10000", "3.50960038", "1596666142.533745", "r"]], "c": "2351050416"}, "book-100", "XBT/USD"]
[270, {"a": [["11659.60000", "0.00000000", "1596666700.968460"], ["11709.00000", "0.17085000", "1596666698.599816", "r"]], "c": "2351050416"}, "book-100", "XBT/USD"]
[270, {"a": [["11661.90000", "0.00000000", "1596666700.970377"], ["11709.60000", "4.27000068", "1596666650.408245", "r"]], "c": "2351050416"}, "book-100", "XBT/USD"]
[270, {"a": [["11650.00000", "0.00000000", "1596666701.005949"], ["11709.70000", "7.20507863", "1596666620.257365", "r"]], "c": "2351050416"}, "book-100", "XBT/USD"]
[270, {"b": [["11630.00000", "0.00000000", "1596666701.017687"], ["11590.00000", "1.97724585", "1596666646.997760", "r"]], "c": "2351050416"}, "book-100", "XBT/USD"]
[270, {"a": [["11645.60000", "0.47601549", "1596666701.042309"]], "c": "2230597460"}, "book-100", "XBT/USD"]
[270, {"b": [["11630.50000", "2.00000000", "1596666701.050962"]], "c": "2230597460"}, "book-100", "XBT/USD"]
[270, {"a": [["11674.50000", "0.00000000", "1596666701.060544"], ["11709.70000", "7.20507863", "1596666620.257365", "r"]], "c": "2230597460"}, "book-100", "XBT/USD"]
[270, {"a": [["11693.70000", "1.16987239", "1596666701.085240"]], "c": "2230597460"}, "book-100", "XBT/USD"]
[270, {"a": [["11658.80000", "0.33892527", "1596666701.103235"]], "c": "2230597460"}, "book-100", "XBT/USD"]
[270, {"a": [["11670.30000", "1.79453383", "1596666701.111742"]], "c": "2230597460"}, "book-100", "XBT/USD"]
[270, {"a": [["11662.10000", "0.71154166", "1596666701.111905"]], "c": "2230597460"}, "book-100", "XBT/USD"]
[270, {"a": [["11664.50000", "1.42279052", "1596666701.114164"]], "c": "2230597460"}, "book-100", "XBT/USD"]
[270, {"a": [["11692.10000", "0.96780000", "1596666701.114582"]], "c": "2230597460"}, "book-100", "XBT/USD"]
[270, {"a": [["11675.70000", "2.00556220", "1596666701.139628"]], "c": "2230597460"}, "book-100", "XBT/USD"]
[270, {"a": [["11672.60000", "0.00000000", "1596666701.176790"], ["11704.10000", "8.30000000", "1596666665.290916", "r"]], "c": "2230597460"}, "book-100", "XBT/USD"]
[270, {"b": [["11591.20000", "1.42910979", "1596666701.223131"]], "c": "2230597460"}, "book-100", "XBT/USD"]
[270, {"a": [["11672.20000", "0.99442109", "1596666701.245637"]], "c": "2230597460"}, "book-100", "XBT/USD"]
[270, {"a": [["11664.10000", "0.72412585", "1596666701.333067"]], "c": "2230597460"}, "book-100", "XBT/USD"]
[270, {"a": [["11653.80000", "0.50899698", "1596666701.355500"]], "c": "2230597460"}, "book-100", "XBT/USD"]
[270, {"a": [["11670.80000", "1.96620664", "1596666701.409323"]], "c": "2230597460"}, "book-100", "XBT/USD"]
[270, {"b": [["11630.30000", "0.38000000", "1596666701.544900"]], "c": "2230597460"}, "book-100", "XBT/USD"]
[270, {"a": [["11664.50000", "0.00000000", "1596666701.606899"], ["11701.40000", "23.40000000", "1596666447.014661", "r"]], "c": "2230597460"}, "book-100", "XBT/USD"]
[270, {"b": [["11631.60000", "0.04481104", "1596666701.655926"]], "c": "2230597460"}, "book-100", "XBT/USD"]
[270, {"b": [["11639.60000", "0.00000000", "1596666701.680091"], ["11590.20000", "0.90571082", "1596666644.915161", "r"]], "c": "4077521881"}, "book-100", "XBT/USD"]
[270, {"b": [["11596.40000", "0.00000000", "1596666701.687748"], ["11590.10000", "1.51500000", "1596666649.220608", "r"]], "c": "4077521881"}, "book-100", "XBT/USD"]
[270, {"b": [["11640.00000", "9.10194866", "1596666701.704372"]], "c": "725367692"}, "book-100", "XBT/USD"]
[270, {"b": [["11638.90000", "0.00000000", "1596666701.780662"], ["11590.00000", "1.97724585", "1596666646.997760", "r"]], "c": "2246273151"}, "book-100", "XBT/USD"]
[270, {"a": [["11647.70000", "0.00000000", "1596666701.781223"], ["11701.70000", "3.00242295", "1596666700.111068", "r"]], "c": "2044047107"}, "book-100", "XBT/USD"]
[270, {"a": [["11656.80000", "1.80691024", "1596666702.037333"]], "c": "2044047107"}, "book-100", "XBT/USD"]
[270, {"a": [["11662.10000", "0.00000000", "1596666702.130917"], ["11702.50000", "23.57900000", "1596666155.599282", "r"]], "c": "2044047107"}, "book-100", "XBT/USD"]
[270, {"a": [["11661.80000", "0.10346695", "1596666702.144191"]], "c": "2044047107"}, "book-100", "XBT/USD"]
[270, {"b": [["11599.60000", "6.54923673", "1596666702.173018"]], "c": "2044047107"}, "book-100", "XBT/USD"]
[270, {"a": [["11658.80000", "0.00000000", "1596666702.173636"], ["11702.50000", "23.57900000", "1596666155.599282", "r"]], "c": "2044047107"}, "book-100", "XBT/USD"]
[270, {"a": [["11650.50000", "1.70500000", "1596666702.206354"]], "c": "2044047107"}, "book-100", "XBT/USD"]
[270, {"a": [["11651.70000", "0.64385786", "1596666702.214329"]], "c": "2044047107"}, "book-100", "XBT/USD"]
[270, {"a": [["11664.30000", "0.85847714", "1596666702.217573"]], "c": "2044047107"}, "book-100", "XBT/USD"]
[270, {"a": [["11692.10000", "4.49523792", "1596666702.300008"]], "c": "2044047107"}, "book-100", "XBT/USD"]
[270, {"b": [["11631.20000", "0.13442982", "1596666702.343215"]], "c": "2044047107"}, "book-100", "XBT/USD"]
[270, {"a": [["11676.20000", "0.00000000", "1596666702.352537"], ["11701.40000", "23.40000000", "1596666447.014661", "r"]], "c": "2044047107"}, "book-100", "XBT/USD"]
[270, {"a": [["11659.00000", "1.56070000", "1596666702.354270"]], "c": "2044047107"}, "book-100", "XBT/USD"]
[270, {"b": [["11597.40000", "0.00000000", "1596666702.354883"], ["11590.10000", "1.51500000", "1596666649.220608", "r"]], "c": "2044047107"}, "book-100", "XBT/USD"]
[270, {"b": [["11599.90000", "0.75026761", "1596666702.361090"]], "c": "2044047107"}, "book-100", "XBT/USD"]
[270, {"a": [["11662.20000", "0.75026761", "1596666702.363812"]], "c": "2044047107"}, "book-100", "XBT/USD"]
[270, {"a": [["11646.10000", "0.00000000", "1596666702.391558"], ["11701.40000", "23.40000000", "1596666447.014661", "r"]], "c": "2492477924"}, "book-100", "XBT/USD"]
[270, {"a": [["11679.70000", "2.25182221", "1596666702.421163"]], "c": "2492477924"}, "book-100", "XBT/USD"]
[270, {"b": [["11639.10000", "0.00000000", "1596666702.429794"], ["11590.10000", "1.51500000", "1596666649.220608", "r"]], "c": "564607287"}, "book-100", "XBT/USD"]
[270, {"b": [["11608.00000", "0.50000000", "1596666702.436475"]], "c": "564607287"}, "book-100", "XBT/USD"]
[270, {"b": [["11624.60000", "0.00000000", "1596666702.467594"], ["11590.10000", "1.51500000", "1596666649.220608", "r"]], "c": "564607287"}, "book-100", "XBT/USD"]
[270, {"a": [["11646.00000", "0.00000000", "1596666702.523916"], ["11701.40000", "23.40000000", "1596666447.014661", "r"]], "c": "3319576255"}, "book-100", "XBT/USD"]
[270, {"a": [["11658.00000", "0.00000000", "1596666702.563072"], ["11701.70000", "3.00242295", "1596666700.111068", "r"]], "c": "3319576255"}, "book-100", "XBT/USD"]
[270, {"a": [["11646.70000", "0.00860916", "1596666702.564066"]], "c": "2838231719"}, "book-100", "XBT/USD"]
[270, {"b": [["11640.00000", "7.39194866", "1596666702.577728"]], "c": "4116572291"}, "book-100", "XBT/USD"]
[270, {"a": [["11646.60000", "0.41352978", "1596666702.587550"]], "c": "1397283843"}, "book-100", "XBT/USD"]
[270, {"b": [["11639.50000", "0.48000000", "1596666702.590786"]], "c": "220422161"}, "book-100", "XBT/USD"]
[271, [["11640.10000", "0.35001634", "1596666702.603834", "b", "m", ""], ["11640.10000", "0.17818366", "1596666702.614583", "b", "m", ""], ["11643.10000", "0.01100000", "1596666702.616659", "b", "m", ""], ["11645.60000", "0.06016638", "1596666702.618656", "b", "m", ""]], "trade", "XBT/USD"]
[270, {"a": [["11640.10000", "0.17818366", "1596666702.603834"], ["11640.10000", "0.00000000", "1596666702.614583"], ["11701.40000", "23.40000000", "1596666447.014661", "r"], ["11643.10000", "0.00000000", "1596666702.616659"], ["11701.70000", "3.00242295", "1596666700.111068", "r"], ["11645.60000", "0.41584911", "1596666702.618657"]], "c": "295032474"}, "book-100", "XBT/USD"]
[270, {"a": [["11650.50000", "0.00000000", "1596666702.627695"], ["11702.50000", "23.57900000", "1596666155.599282", "r"]], "c": "295032474"}, "book-100", "XBT/USD"]
[270, {"a": [["11660.40000", "0.69997139", "1596666702.632524"]], "c": "295032474"}, "book-100", "XBT/USD"]
[270, {"b": [["11640.00000", "8.39194866", "1596666702.640835"]], "c": "1188548473"}, "book-100", "XBT/USD"]
[270, {"a": [["11652.50000", "0.09621094", "1596666702.657216"]], "c": "1188548473"}, "book-100", "XBT/USD"]
[270, {"b": [["11640.00000", "7.89194866", "1596666702.678410"]], "c": "28686445"}, "book-100", "XBT/USD"]
[270, {"a": [["11655.00000", "0.00000000", "1596666702.678512"], ["11701.70000", "3.00242295", "1596666700.111068", "r"]], "c": "28686445"}, "book-100", "XBT/USD"]
[270, {"a": [["11663.70000", "1.42288811", "1596666702.679780"]], "c": "28686445"}, "book-100", "XBT/USD"]
[270, {"b": [["11640.10000", "5.30000000", "1596666702.681723"]], "c": "2761587461"}, "book-100", "XBT/USD"]
[270, {"a": [["11661.40000", "0.71158437", "1596666702.691134"]], "c": "2761587461"}, "book-100", "XBT/USD"]
[270, {"a": [["11658.00000", "0.33894853", "1596666702.693845"]], "c": "2761587461"}, "book-100", "XBT/USD"]
[270, {"a": [["11656.80000", "0.04481024", "1596666702.694536"]], "c": "2761587461"}, "book-100", "XBT/USD"]
[270, {"b": [["11640.00000", "7.49194866", "1596666702.703774"]], "c": "3548552972"}, "book-100", "XBT/USD"]
[270, {"b": [["11633.80000", "0.00000000", "1596666702.716769"], ["11590.10000", "1.51500000", "1596666649.220608", "r"]], "c": "3548552972"}, "book-100", "XBT/USD"]
[270, {"b": [["11637.60000", "0.00000000", "1596666702.719726"], ["11590.00000", "1.97724585", "1596666646.997760", "r"]], "c": "2773086904"}, "book-100", "XBT/USD"]
[270, {"a": [["11647.40000", "0.00000000", "1596666702.731779"], ["11701.10000", "0.01796445", "1596665962.941606", "r"]], "c": "489405675"}, "book-100", "XBT/USD"]
[270, {"a": [["11647.90000", "0.21974360", "1596666702.733942"]], "c": "664575831"}, "book-100", "XBT/USD"]
[270, {"b": [["11639.50000", "0.23000000", "1596666702.749339"]], "c": "718375131"}, "book-100", "XBT/USD"]
[270, {"a": [["11646.60000", "0.00000000", "1596666702.754203"], ["11701.40000", "23.40000000", "1596666447.014661", "r"]], "c": "55151289"}, "book-100", "XBT/USD"]
[270, {"a": [["11659.40000", "0.13443042", "1596666702.760774"]], "c": "55151289"}, "book-100", "XBT/USD"]
[270, {"a": [["11646.70000", "0.00000000", "1596666702.770746"], ["11701.40000", "23.40000000", "1596666447.014661", "r"]], "c": "2760527913"}, "book-100", "XBT/USD"]
[270, {"a": [["11662.80000", "1.76210000", "1596666702.774303"]], "c": "2760527913"}, "book-100", "XBT/USD"]
[270, {"a": [["11646.50000", "0.00860931", "1596666702.775635"]], "c": "1395888886"}, "book-100", "XBT/USD"]
[270, {"b": [["11640.10000", "0.00000000", "1596666702.781408"], ["11589.90000", "6.90000000", "1596666166.290818", "r"]], "c": "3589777078"}, "book-100", "XBT/USD"]
[270, {"a": [["11648.70000", "0.00000000", "1596666702.796218"], ["11701.10000", "0.01796445", "1596665962.941606", "r"]], "c": "1050273525"}, "book-100", "XBT/USD"]
[270, {"a": [["11648.60000", "2.00000000", "1596666702.812482"]], "c": "3671105521"}, "book-100", "XBT/USD"]
[270, {"a": [["11648.60000", "2.25883473", "1596666702.830226"]], "c": "2729183595"}, "book-100", "XBT/USD"]
[270, {"b": [["11606.30000", "0.00000000", "1596666702.842199"], ["11589.40000", "0.90410776", "1596666642.290517", "r"]], "c": "2729183595"}, "book-100", "XBT/USD"]
[270, {"b": [["11640.20000", "0.08588962", "1596666702.843565"]], "c": "2610617094"}, "book-100", "XBT/USD"]
[270, {"b": [["11605.80000", "0.00000000", "1596666702.845339"], ["11589.40000", "0.90410776", "1596666642.290517", "r"]], "c": "2610617094"}, "book-100", "XBT/USD"]
[270, {"b": [["11639.40000", "0.09621094", "1596666702.849486"]], "c": "4157244750"}, "book-100", "XBT/USD"]
[270, {"b": [["11619.50000", "0.00000000", "1596666702.852058"], ["11589.40000", "0.90410776", "1596666642.290517", "r"]], "c": "4157244750"}, "book-100", "XBT/USD"]
[270, {"b": [["11640.00000", "7.00144866", "1596666702.863066"]], "c": "3282818318"}, "book-100", "XBT/USD"]
[270, {"b": [["11623.80000", "0.00000000", "1596666702.883264"], ["11589.00000", "0.17085000", "1596666680.844319", "r"]], "c": "3282818318"}, "book-100", "XBT/USD"]
[270, {"b": [["11618.00000", "0.00000000", "1596666702.884936"], ["11588.60000", "0.75800000", "1596666599.475365", "r"]], "c": "3282818318"}, "book-100", "XBT/USD"]
[270, {"b": [["11606.20000", "0.00000000", "1596666702.887464"], ["11586.50000", "2.02039265", "1596666642.016032", "r"]], "c": "3282818318"}, "book-100", "XBT/USD"]
[270, {"a": [["11649.00000", "1.05745969", "1596666702.893765"]], "c": "47638490"}, "book-100", "XBT/USD"]
[270, {"b": [["11641.90000", "0.25000000", "1596666702.903826"]], "c": "2238738852"}, "book-100", "XBT/USD"]
[270, {"a": [["11645.60000", "0.00000000", "1596666702.941162"], ["11701.10000", "0.01796445", "1596665962.941606", "r"]], "c": "2802987887"}, "book-100", "XBT/USD"]
[270, {"a": [["11648.60000", "0.25883473", "1596666702.942222"]], "c": "1245010596"}, "book-100", "XBT/USD"]
[270, {"b": [["11599.40000", "0.00000000", "1596666702.950605"], ["11586.50000", "2.02039265", "1596666642.016032", "r"]], "c": "1245010596"}, "book-100", "XBT/USD"]
[270, {"a": [["11650.00000", "1.50000000", "1596666702.953214"]], "c": "1148398082"}, "book-100", "XBT/USD"]
[270, {"b": [["11607.40000", "0.00000000", "1596666702.958210"], ["11586.20000", "3.00500211", "1596666626.428727", "r"]], "c": "1148398082"}, "book-100", "XBT/USD"]
[270, {"b": [["11603.60000", "0.75800000", "1596666702.965229"]], "c": "1148398082"}, "book-100", "XBT/USD"]
[270, {"a": [["11662.20000", "1.44573761", "1596666702.985298"]], "c": "1148398082"}, "book-100", "XBT/USD"]
[270, {"a": [["11653.00000", "1.34763223", "1596666702.992458"]], "c": "1148398082"}, "book-100", "XBT/USD"]
[270, {"a": [["11646.70000", "0.00860916", "1596666703.025104"]], "c": "3807615768"}, "book-100", "XBT/USD"]
[270, {"b": [["11639.90000", "0.00000000", "1596666703.026362"], ["11586.20000", "3.00500211", "1596666626.428727", "r"]], "c": "250677577"}, "book-100", "XBT/USD"]
[270, {"b": [["11628.60000", "0.00000000", "1596666703.026654"], ["11586.10000", "3.56041667", "1596666642.875530", "r"]], "c": "250677577"}, "book-100", "XBT/USD"]
[270, {"a": [["11646.50000", "0.00000000", "1596666703.026925"], ["11699.90000", "0.10000000", "1596666079.896762", "r"]], "c": "3745079879"}, "book-100", "XBT/USD"]
[270, {"b": [["11640.00000", "6.35733650", "1596666703.027009"]], "c": "4006655136"}, "book-100", "XBT/USD"]
[270, {"b": [["11639.80000", "0.00000000", "1596666703.027623"], ["11586.00000", "2.83070444", "1596666641.836792", "r"]], "c": "3592098217"}, "book-100", "XBT/USD"]
[270, {"a": [["11649.00000", "0.64392991", "1596666703.036829"]], "c": "2541585860"}, "book-100", "XBT/USD"]
[270, {"a": [["11653.80000", "0.99930789", "1596666703.045785"]], "c": "2541585860"}, "book-100", "XBT/USD"]
[270, {"b": [["11609.70000", "0.00000000", "1596666703.046493"], ["11585.50000", "0.00509766", "1596666166.036585", "r"]], "c": "2541585860"}, "book-100", "XBT/USD"]
[270, {"a": [["11646.80000", "0.00000000", "1596666703.052748"], ["11700.00000", "0.52000000", "1596666697.653648", "r"]], "c": "986295563"}, "book-100", "XBT/USD"]
[270, {"a": [["11648.80000", "4.28200000", "1596666703.056084"]], "c": "917716337"}, "book-100", "XBT/USD"]
[270, {"b": [["11640.00000", "6.30191028", "1596666703.069475"]], "c": "3101576791"}, "book-100", "XBT/USD"]
[270, {"a": [["11693.30000", "0.48410000", "1596666703.085185"]], "c": "3101576791"}, "book-100", "XBT/USD"]
[270, {"b": [["11628.50000", "0.00000000", "1596666703.099569"], ["11585.00000", "7.70000000", "1596666429.743667", "r"]], "c": "3101576791"}, "book-100", "XBT/USD"]
[270, {"b": [["11641.90000", "1.16774000", "1596666703.108543"]], "c": "4071809274"}, "book-100", "XBT/USD"]
[270, {"a": [["11647.90000", "0.00000000", "1596666703.115288"], ["11699.90000", "0.10000000", "1596666079.896762", "r"]], "c": "1099733806"}, "book-100", "XBT/USD"]
[270, {"b": [["11590.90000", "2.50315283", "1596666703.117862"]], "c": "1099733806"}, "book-100", "XBT/USD"]
[270, {"b": [["11614.00000", "1.49890447", "1596666703.120920"]], "c": "1099733806"}, "book-100", "XBT/USD"]
[270, {"b": [["11641.90000", "0.91774000", "1596666703.122504"]], "c": "3824021177"}, "book-100", "XBT/USD"]
[270, {"b": [["11623.20000", "0.99847870", "1596666703.125091"]], "c": "3824021177"}, "book-100", "XBT/USD"]
[270, {"b": [["11629.00000", "0.49899035", "1596666703.136839"]], "c": "3824021177"}, "book-100", "XBT/USD"]
[270, {"a": [["11658.00000", "0.00000000", "1596666703.156484"], ["11700.00000", "0.52000000", "1596666697.653648", "r"]], "c": "3824021177"}, "book-100", "XBT/USD"]
[270, {"b": [["11640.00000", "5.93291028", "1596666703.184136"]], "c": "387537113"}, "book-100", "XBT/USD"]
[270, {"a": [["11649.90000", "0.41352978", "1596666703.188652"]], "c": "3250455019"}, "book-100", "XBT/USD"]
[270, {"b": [["11640.00000", "1.64091028", "1596666703.195820"]], "c": "988234398"}, "book-100", "XBT/USD"]
[270, {"a": [["11647.00000", "0.41184710", "1596666703.203329"]], "c": "3630504886"}, "book-100", "XBT/USD"]
[270, {"a": [["11670.00000", "7.08344277", "1596666703.209635"]], "c": "3630504886"}, "book-100", "XBT/USD"]
[270, {"b": [["11602.50000", "0.00000000", "1596666703.216428"], ["11586.10000", "3.56041667", "1596666642.875530", "r"]], "c": "3630504886"}, "book-100", "XBT/USD"]
[271, [["11641.90000", "0.04523000", "1596666703.229655", "s", "m", ""]], "trade", "XBT/USD"]
[270, {"b": [["11641.90000", "0.87251000", "1596666703.229655"]], "c": "2964423232"}, "book-100", "XBT/USD"]
[270, {"b": [["11624.70000", "0.00000000", "1596666703.234797"], ["11586.00000", "2.83070444", "1596666641.836792", "r"]], "c": "2964423232"}, "book-100", "XBT/USD"]
[270, {"b": [["11625.60000", "0.04229608", "1596666703.235119"]], "c": "2964423232"}, "book-100", "XBT/USD"]
[270, {"b": [["11586.10000", "0.00000000", "1596666703.240365"], ["11586.00000", "2.83070444", "1596666641.836792", "r"]], "c": "2964423232"}, "book-100", "XBT/USD"]
[270, {"a": [["11676.60000", "2.47000000", "1596666703.257786"]], "c": "2964423232"}, "book-100", "XBT/USD"]
[270, {"a": [["11646.70000", "0.00000000", "1596666703.277643"], ["11698.00000", "6.50000000", "1596665849.372318", "r"]], "c": "1007516843"}, "book-100", "XBT/USD"]
[270, {"b": [["11643.10000", "0.25000000", "1596666703.280518"]], "c": "2014106984"}, "book-100", "XBT/USD"]
[270, {"b": [["11610.40000", "2.01684202", "1596666703.299947"]], "c": "2014106984"}, "book-100", "XBT/USD"]
[270, {"b": [["11604.60000", "2.01785004", "1596666703.305755"]], "c": "2014106984"}, "book-100", "XBT/USD"]
[270, {"b": [["11597.80000", "0.00000000", "1596666703.342887"], ["11586.50000", "2.02039265", "1596666642.016032", "r"]], "c": "2014106984"}, "book-100", "XBT/USD"]
[270, {"b": [["11607.20000", "0.00000000", "1596666703.342951"], ["11586.20000", "3.00500211", "1596666626.428727", "r"]], "c": "2014106984"}, "book-100", "XBT/USD"]
[270, {"a": [["11648.50000", "0.00860783", "1596666703.348510"]], "c": "2243344671"}, "book-100", "XBT/USD"]
[270, {"b": [["11589.40000", "0.00000000", "1596666703.351534"], ["11586.00000", "2.83070444", "1596666641.836792", "r"]], "c": "2243344671"}, "book-100", "XBT/USD"]
[270, {"b": [["11603.70000", "0.00000000", "1596666703.360419"], ["11585.50000", "0.00509766", "1596666166.036585", "r"]], "c": "2243344671"}, "book-100", "XBT/USD"]
[270, {"b": [["11590.00000", "0.00000000", "1596666703.365892"], ["11585.00000", "7.70000000", "1596666429.743667", "r"]], "c": "2243344671"}, "book-100", "XBT/USD"]
[270, {"b": [["11612.00000", "0.00000000", "1596666703.366066"], ["11583.80000", "2.33213693", "1596666587.499785", "r"]], "c": "2243344671"}, "book-100", "XBT/USD"]
[270, {"b": [["11605.00000", "0.00000000", "1596666703.367264"], ["11583.60000", "2.29920000", "1596666614.296152", "r"]], "c": "2243344671"}, "book-100", "XBT/USD"]
[270, {"b": [["11617.60000", "0.00000000", "1596666703.368484"], ["11583.00000", "0.01000000", "1596666661.045375", "r"]], "c": "2243344671"}, "book-100", "XBT/USD"]
[270, {"b": [["11614.30000", "0.00000000", "1596666703.369642"], ["11582.70000", "0.00199361", "1596666580.634885", "r"]], "c": "2243344671"}, "book-100", "XBT/USD"]
[270, {"a": [["11670.20000", "3.20200103", "1596666703.372880"]], "c": "2243344671"}, "book-100", "XBT/USD"]
[270, {"b": [["11619.80000", "0.00000000", "1596666703.374924"], ["11582.40000", "2.25182221", "1596666702.380025", "r"]], "c": "2243344671"}, "book-100", "XBT/USD"]
[270, {"b": [["11605.50000", "0.00000000", "1596666703.380480"], ["11582.20000", "1.44500000", "1596666339.973800", "r"]], "c": "2243344671"}, "book-100", "XBT/USD"]
[270, {"b": [["11642.00000", "0.05541670", "1596666703.383501"]], "c": "4113816955"}, "book-100", "XBT/USD"]
[270, {"b": [["11640.10000", "0.54430000", "1596666703.403381"]], "c": "1083970850"}, "book-100", "XBT/USD"]
[270, {"b": [["11641.90000", "1.30151000", "1596666703.405186"]], "c": "1980001651"}, "book-100", "XBT/USD"]
[270, {"b": [["11643.10000", "0.00000000", "1596666703.408468"], ["11582.40000", "2.25182221", "1596666702.380025", "r"]], "c": "1256922535"}, "book-100", "XBT/USD"]
[270, {"b": [["11622.40000", "0.00000000", "1596666703.416048"], ["11582.20000", "1.44500000", "1596666339.973800", "r"]], "c": "1256922535"}, "book-100", "XBT/USD"]
[270, {"b": [["11590.20000", "0.00000000", "1596666703.419919"], ["11581.60000", "0.90627075", "1596666584.885878", "r"]], "c": "1256922535"}, "book-100", "XBT/USD"]
[270, {"b": [["11637.00000", "0.00000000", "1596666703.424443"], ["11581.10000", "1.18130561", "1596666582.765292", "r"]], "c": "1256922535"}, "book-100", "XBT/USD"]
[270, {"b": [["11604.30000", "0.00000000", "1596666703.436704"], ["11580.00000", "0.01000000", "1596666585.490563", "r"]], "c": "1256922535"}, "book-100", "XBT/USD"]
[270, {"b": [["11595.50000", "7.80858966", "1596666703.441148"]], "c": "1256922535"}, "book-100", "XBT/USD"]
[270, {"b": [["11608.70000", "0.00000000", "1596666703.457240"], ["11579.60000", "3.56210278", "1596666663.294117", "r"]], "c": "1256922535"}, "book-100", "XBT/USD"]
[270, {"a": [["11659.90000", "0.00000000", "1596666703.472259"], ["11695.10000", "0.35368913", "1596666684.533099", "r"]], "c": "1256922535"}, "book-100", "XBT/USD"]
[270, {"b": [["11631.70000", "0.00000000", "1596666703.518044"], ["11579.50000", "8.70000000", "1596666702.354626", "r"]], "c": "1256922535"}, "book-100", "XBT/USD"]
[270, {"b": [["11642.00000", "0.55166576", "1596666703.519595"]], "c": "2628462487"}, "book-100", "XBT/USD"]
[270, {"a": [["11648.50000", "0.00000000", "1596666703.527829"], ["11698.00000", "6.50000000", "1596665849.372318", "r"]], "c": "1379367268"}, "book-100", "XBT/USD"]
[270, {"a": [["11646.90000", "0.00860902", "1596666703.532582"]], "c": "2624075351"}, "book-100", "XBT/USD"]
[270, {"b": [["11640.10000", "0.64230000", "1596666703.532768"]], "c": "1101226078"}, "book-100", "XBT/USD"]
[270, {"b": [["11592.20000", "0.00000000", "1596666703.541583"], ["11579.10000", "2.02151457", "1596666684.587330", "r"]], "c": "1101226078"}, "book-100", "XBT/USD"]
[270, {"b": [["11613.50000", "0.00000000", "1596666703.541651"], ["11579.00000", "0.03000000", "1596666635.087422", "r"]], "c": "1101226078"}, "book-100", "XBT/USD"]
[270, {"b": [["11605.40000", "0.00000000", "1596666703.547975"], ["11577.30000", "19.70000000", "1596666640.677200", "r"]], "c": "1101226078"}, "book-100", "XBT/USD"]
[270, {"b": [["11611.20000", "0.00000000", "1596666703.552284"], ["11576.90000", "0.00539672", "1596666693.890226", "r"]], "c": "1101226078"}, "book-100", "XBT/USD"]
[270, {"a": [["11660.50000", "0.00300000", "1596666703.552510"]], "c": "1101226078"}, "book-100", "XBT/USD"]
[270, {"b": [["11581.60000", "2.92812805", "1596666703.553394"]], "c": "1101226078"}, "book-100", "XBT/USD"]
[270, {"b": [["11641.60000", "0.25000000", "1596666703.568950"]], "c": "1835298842"}, "book-100", "XBT/USD"]
[270, {"a": [["11654.20000", "0.21696687", "1596666703.589771"]], "c": "1835298842"}, "book-100", "XBT/USD"]
[270, {"a": [["11649.90000", "0.00000000", "1596666703.590246"], ["11693.70000", "1.16987239", "1596666701.085240", "r"]], "c": "1067626359"}, "book-100", "XBT/USD"]
[270, {"b": [["11640.00000", "1.38591028", "1596666703.590563"]], "c": "818794729"}, "book-100", "XBT/USD"]
[270, {"b": [["11625.00000", "3.21445096", "1596666703.605941"]], "c": "818794729"}, "book-100", "XBT/USD"]
[270, {"b": [["11612.10000", "0.25065814", "1596666703.618597"]], "c": "818794729"}, "book-100", "XBT/USD"]
[270, {"a": [["11648.70000", "0.75551922", "1596666703.621055"]], "c": "710398900"}, "book-100", "XBT/USD"]
[270, {"b": [["11608.60000", "0.35102720", "1596666703.621135"]], "c": "710398900"}, "book-100", "XBT/USD"]
[270, {"b": [["11599.70000", "0.00900000", "1596666703.651555"]], "c": "710398900"}, "book-100", "XBT/USD"]
[270, {"a": [["11648.70000", "0.00000000", "1596666703.673745"], ["11693.70000", "1.16987239", "1596666701.085240", "r"]], "c": "818794729"}, "book-100", "XBT/USD"]
[270, {"b": [["11592.70000", "3.55768345", "1596666703.677696"]], "c": "818794729"}, "book-100", "XBT/USD"]
[270, {"b": [["11641.60000", "0.00000000", "1596666703.705727"], ["11579.60000", "3.56210278", "1596666663.294117", "r"]], "c": "3415589797"}, "book-100", "XBT/USD"]
[270, {"a": [["11648.50000", "0.75551922", "1596666703.719825"]], "c": "2928908925"}, "book-100", "XBT/USD"]
[270, {"b": [["11635.10000", "8.24495263", "1596666703.729665"]], "c": "2928908925"}, "book-100", "XBT/USD"]
[270, {"a": [["11650.20000", "1.39018839", "1596666703.736481"]], "c": "436153933"}, "book-100", "XBT/USD"]
[270, {"b": [["11611.50000", "1.21523269", "1596666703.739507"]], "c": "436153933"}, "book-100", "XBT/USD"]
[270, {"b": [["11599.90000", "2.26822828", "1596666703.739993"]], "c": "436153933"}, "book-100", "XBT/USD"]
[270, {"b": [["11619.60000", "0.10379364", "1596666703.744029"]], "c": "436153933"}, "book-100", "XBT/USD"]
[270, {"b": [["11617.30000", "0.72669930", "1596666703.745455"]], "c": "436153933"}, "book-100", "XBT/USD"]
[270, {"a": [["11648.50000", "0.00000000", "1596666703.765649"], ["11693.70000", "1.16987239", "1596666701.085240", "r"]], "c": "488944554"}, "book-100", "XBT/USD"]
[270, {"b": [["11638.50000", "0.00000000", "1596666703.781114"], ["11581.10000", "1.18130561", "1596666582.765292", "r"]], "c": "86695792"}, "book-100", "XBT/USD"]
[270, {"a": [["11653.80000", "0.49031091", "1596666703.783178"]], "c": "86695792"}, "book-100", "XBT/USD"]
[270, {"b": [["11642.10000", "4.28800000", "1596666703.816251"]], "c": "1429374336"}, "book-100", "XBT/USD"]
[270, {"a": [["11653.00000", "0.00000000", "1596666703.821298"], ["11695.10000", "0.35368913", "1596666684.533099", "r"]], "c": "1429374336"}, "book-100", "XBT/USD"]
[270, {"b": [["11644.00000", "0.40000000", "1596666703.825488"]], "c": "2690759623"}, "book-100", "XBT/USD"]
[270, {"a": [["11650.30000", "0.00000000", "1596666703.830003"], ["11698.00000", "6.50000000", "1596665849.372318", "r"]], "c": "387854336"}, "book-100", "XBT/USD"]
[270, {"b": [["11637.00000", "9.99987003", "1596666703.841049"]], "c": "387854336"}, "book-100", "XBT/USD"]
[270, {"a": [["11648.60000", "0.00000000", "1596666703.881576"], ["11699.50000", "2.48018651", "1596666596.614575", "r"]], "c": "3957773051"}, "book-100", "XBT/USD"]
[270, {"b": [["11642.90000", "0.25000000", "1596666703.883251"]], "c": "836638547"}, "book-100", "XBT/USD"]
[270, {"a": [["11658.70000", "0.39700000", "1596666703.904167"]], "c": "836638547"}, "book-100", "XBT/USD"]
[270, {"a": [["11649.90000", "0.25880551", "1596666703.916446"]], "c": "3239052688"}, "book-100", "XBT/USD"]
[270, {"a": [["11655.00000", "0.55974758", "1596666703.972747"]], "c": "3239052688"}, "book-100", "XBT/USD"]
[270, {"b": [["11593.90000", "0.00000000", "1596666703.975123"], ["11582.40000", "2.25182221", "1596666702.380025", "r"]], "c": "3239052688"}, "book-100", "XBT/USD"]
[270, {"b": [["11637.00000", "0.00000000", "1596666703.990073"], ["11582.20000", "1.44500000", "1596666339.973800", "r"]], "c": "3239052688"}, "book-100", "XBT/USD"]
[270, {"a": [["11674.60000", "0.67600000", "1596666704.000548"]], "c": "3239052688"}, "book-100", "XBT/USD"]
[270, {"a": [["11665.70000", "0.00000000", "1596666704.000602"], ["11695.10000", "0.35368913", "1596666684.533099", "r"]], "c": "3239052688"}, "book-100", "XBT/USD"]
[270, {"b": [["11642.00000", "0.05541670", "1596666704.024200"]], "c": "4135696369"}, "book-100", "XBT/USD"]
[270, {"a": [["11656.70000", "1.36531999", "1596666704.033047"]], "c": "4135696369"}, "book-100", "XBT/USD"]
[270, {"b": [["11642.00000", "0.00000000", "1596666704.065602"], ["11581.60000", "2.92812805", "1596666703.553394", "r"]], "c": "2227457036"}, "book-100", "XBT/USD"]
[270, {"a": [["11658.40000", "0.00000000", "1596666704.066120"], ["11695.10000", "0.35368913", "1596666684.533099", "r"]], "c": "2227457036"}, "book-100", "XBT/USD"]
[270, {"b": [["11642.20000", "0.49687207", "1596666704.088757"]], "c": "2906156946"}, "book-100", "XBT/USD"]
[270, {"b": [["11641.90000", "0.87251000", "1596666704.099608"]], "c": "1367197654"}, "book-100", "XBT/USD"]
[270, {"a": [["11676.60000", "0.00000000", "1596666704.159215"], ["11698.00000", "6.50000000", "1596665849.372318", "r"]], "c": "1367197654"}, "book-100", "XBT/USD"]
[270, {"a": [["11649.00000", "0.00000000", "1596666704.167761"], ["11699.50000", "2.48018651", "1596666596.614575", "r"]], "c": "4022746177"}, "book-100", "XBT/USD"]
[270, {"b": [["11631.50000", "0.00000000", "1596666704.168748"], ["11581.60000", "2.92812805", "1596666703.553394", "r"]], "c": "4022746177"}, "book-100", "XBT/USD"]
[270, {"a": [["11663.60000", "0.38000000", "1596666704.207367"]], "c": "4022746177"}, "book-100", "XBT/USD"]
[270, {"b": [["11613.40000", "0.49800000", "1596666704.211952"]], "c": "4022746177"}, "book-100", "XBT/USD"]
[270, {"b": [["11613.40000", "6.93332340", "1596666704.212807"]], "c": "4022746177"}, "book-100", "XBT/USD"]
[270, {"b": [["11608.30000", "0.90427148", "1596666704.217769"]], "c": "4022746177"}, "book-100", "XBT/USD"]
[270, {"b": [["11592.00000", "0.00000000", "1596666704.223883"], ["11582.20000", "1.44500000", "1596666339.973800", "r"]], "c": "4022746177"}, "book-100", "XBT/USD"]
[270, {"b": [["11630.50000", "0.00000000", "1596666704.226641"], ["11581.60000", "2.92812805", "1596666703.553394", "r"]], "c": "4022746177"}, "book-100", "XBT/USD"]
[270, {"b": [["11607.70000", "11.95308605", "1596666704.240198"]], "c": "4022746177"}, "book-100", "XBT/USD"]
[270, {"a": [["11672.90000", "0.89926707", "1596666704.246093"]], "c": "4022746177"}, "book-100", "XBT/USD"]
[270, {"b": [["11596.80000", "0.90516820", "1596666704.261148"]], "c": "4022746177"}, "book-100", "XBT/USD"]
[270, {"a": [["11656.80000", "0.00000000", "1596666704.280687"], ["11698.00000", "6.50000000", "1596665849.372318", "r"]], "c": "4022746177"}, "book-100", "XBT/USD"]
[270, {"b": [["11611.80000", "0.90399891", "1596666704.289030"]], "c": "4022746177"}, "book-100", "XBT/USD"]
[270, {"a": [["11650.00000", "0.00000000", "1596666704.313723"], ["11699.50000", "2.48018651", "1596666596.614575", "r"]], "c": "2134129639"}, "book-100", "XBT/USD"]
[270, {"a": [["11658.80000", "0.71346870", "1596666704.317658"]], "c": "2134129639"}, "book-100", "XBT/USD"]
[270, {"a": [["11665.80000", "0.00000000", "1596666704.329030"], ["11699.50000", "2.48018651", "1596666596.614575", "r"]], "c": "2134129639"}, "book-100", "XBT/USD"]
[270, {"b": [["11643.20000", "0.42900000", "1596666704.334992"]], "c": "3679606713"}, "book-100", "XBT/USD"]
[270, {"a": [["11659.40000", "0.00000000", "1596666704.348152"], ["11699.90000", "0.10000000", "1596666079.896762", "r"]], "c": "3679606713"}, "book-100", "XBT/USD"]
[270, {"a": [["11650.20000", "0.97665861", "1596666704.350591"]], "c": "4064877941"}, "book-100", "XBT/USD"]
[270, {"b": [["11617.10000", "0.05297882", "1596666704.350961"]], "c": "4064877941"}, "book-100", "XBT/USD"]
[270, {"a": [["11664.70000", "0.89989923", "1596666704.352053"]], "c": "4064877941"}, "book-100", "XBT/USD"]
[270, {"b": [["11637.50000", "0.00000000", "1596666704.352254"], ["11582.40000", "2.25182221", "1596666702.380025", "r"]], "c": "4064877941"}, "book-100", "XBT/USD"]
[270, {"b": [["11589.00000", "0.00000000", "1596666704.374329"], ["11582.20000", "1.44500000", "1596666339.973800", "r"]], "c": "4064877941"}, "book-100", "XBT/USD"]
[270, {"a": [["11655.00000", "0.00000000", "1596666704.386510"], ["11699.90000", "0.10000000", "1596666079.896762", "r"]], "c": "4064877941"}, "book-100", "XBT/USD"]
[270, {"a": [["11652.60000", "0.01100000", "1596666704.398071"]], "c": "4070609906"}, "book-100", "XBT/USD"]
[270, {"a": [["11661.40000", "0.00000000", "1596666704.436597"], ["11699.90000", "0.10000000", "1596666079.896762", "r"]], "c": "4070609906"}, "book-100", "XBT/USD"]
[270, {"a": [["11658.50000", "0.04480568", "1596666704.497618"]], "c": "4070609906"}, "book-100", "XBT/USD"]
[270, {"a": [["11651.20000", "0.41352978", "1596666704.513636"]], "c": "3478521138"}, "book-100", "XBT/USD"]
[270, {"b": [["11616.00000", "0.17085000", "1596666704.529492"]], "c": "3478521138"}, "book-100", "XBT/USD"]
[270, {"b": [["11644.10000", "0.30000000", "1596666704.539105"]], "c": "2502655900"}, "book-100", "XBT/USD"]
[270, {"b": [["11642.30000", "1.36785273", "1596666704.549820"]], "c": "1183607380"}, "book-100", "XBT/USD"]
[270, {"a": [["11658.80000", "0.00000000", "1596666704.563624"], ["11699.50000", "2.48018651", "1596666596.614575", "r"]], "c": "1183607380"}, "book-100", "XBT/USD"]
[270, {"a": [["11660.90000", "0.99308794", "1596666704.570593"]], "c": "1183607380"}, "book-100", "XBT/USD"]
[270, {"b": [["11640.90000", "3.31484204", "1596666704.573051"]], "c": "1954675428"}, "book-100", "XBT/USD"]
[270, {"b": [["11644.10000", "0.35540671", "1596666704.574043"]], "c": "1072108887"}, "book-100", "XBT/USD"]
[270, {"b": [["11642.90000", "0.00000000", "1596666704.602510"], ["11583.00000", "0.01000000", "1596666661.045375", "r"]], "c": "2230379346"}, "book-100", "XBT/USD"]
[270, {"b": [["11640.30000", "1.70200000", "1596666704.619334"]], "c": "521413002"}, "book-100", "XBT/USD"]
[270, {"a": [["11657.00000", "10.62647292", "1596666704.629602"]], "c": "521413002"}, "book-100", "XBT/USD"]
[270, {"a": [["11652.50000", "0.00000000", "1596666704.655574"], ["11699.90000", "0.10000000", "1596666079.896762", "r"]], "c": "3480179941"}, "book-100", "XBT/USD"]
[270, {"a": [["11662.20000", "0.75026761", "1596666704.734848"]], "c": "3480179941"}, "book-100", "XBT/USD"]
[270, {"b": [["11644.00000", "0.65000000", "1596666704.740520"]], "c": "3881409808"}, "book-100", "XBT/USD"]
[270, {"a": [["11649.90000", "0.00000000", "1596666704.751359"], ["11700.00000", "0.52000000", "1596666697.653648", "r"]], "c": "3916789380"}, "book-100", "XBT/USD"]
[270, {"b": [["11622.50000", "0.00000000", "1596666704.758884"], ["11583.00000", "0.01000000", "1596666661.045375", "r"]], "c": "3916789380"}, "book-100", "XBT/USD"]
[270, {"b": [["11630.10000", "9.48900000", "1596666704.760924"]], "c": "3916789380"}, "book-100", "XBT/USD"]
[270, {"b": [["11609.80000", "21.20000000", "1596666704.766154"]], "c": "3916789380"}, "book-100", "XBT/USD"]
[270, {"a": [["11674.60000", "0.00000000", "1596666704.769892"], ["11701.10000", "0.01796445", "1596665962.941606", "r"]], "c": "3916789380"}, "book-100", "XBT/USD"]
[270, {"a": [["11651.60000", "1.50000000", "1596666704.771076"]], "c": "2764912366"}, "book-100", "XBT/USD"]
[270, {"a": [["11661.40000", "0.66383256", "1596666704.822567"]], "c": "2764912366"}, "book-100", "XBT/USD"]
[270, {"b": [["11604.70000", "0.00436760", "1596666705.057058"]], "c": "2764912366"}, "book-100", "XBT/USD"]
[270, {"a": [["11679.80000", "0.00438186", "1596666705.058238"]], "c": "2764912366"}, "book-100", "XBT/USD"]
[270, {"a": [["11651.20000", "0.00000000", "1596666705.087775"], ["11699.90000", "0.10000000", "1596666079.896762", "r"]], "c": "3229710130"}, "book-100", "XBT/USD"]
[270, {"b": [["11644.00000", "0.40000000", "1596666705.090599"]], "c": "3904356039"}, "book-100", "XBT/USD"]
[270, {"b": [["11642.70000", "0.09600000", "1596666705.093250"]], "c": "1359953718"}, "book-100", "XBT/USD"]
[270, {"b": [["11642.20000", "1.49687207", "1596666705.096278"]], "c": "3702343627"}, "book-100", "XBT/USD"]
[270, {"a": [["11655.30000", "0.00000000", "1596666705.124088"], ["11700.00000", "0.52000000", "1596666697.653648", "r"]], "c": "3702343627"}, "book-100", "XBT/USD"]
[270, {"a": [["11670.20000", "3.64100103", "1596666705.170814"]], "c": "3702343627"}, "book-100", "XBT/USD"]
[270, {"b": [["11640.00000", "0.38591028", "1596666705.172709"]], "c": "3702343627"}, "book-100", "XBT/USD"]
[270, {"b": [["11627.10000", "0.03000000", "1596666705.189831"]], "c": "3702343627"}, "book-100", "XBT/USD"]
[270, {"b": [["11637.40000", "0.00000000", "1596666705.191651"], ["11585.00000", "7.70000000", "1596666429.743667", "r"]], "c": "3702343627"}, "book-100", "XBT/USD"]
[270, {"a": [["11651.10000", "0.25878111", "1596666705.191983"]], "c": "309615970"}, "book-100", "XBT/USD"]
[270, {"b": [["11640.30000", "0.00000000", "1596666705.194843"], ["11583.80000", "2.33213693", "1596666587.499785", "r"]], "c": "1994544277"}, "book-100", "XBT/USD"]
[270, {"a": [["11652.90000", "0.64376305", "1596666705.208551"]], "c": "1994544277"}, "book-100", "XBT/USD"]
[270, {"b": [["11645.30000", "0.64380900", "1596666705.210264"]], "c": "1895106447"}, "book-100", "XBT/USD"]
[270, {"b": [["11645.40000", "0.64380900", "1596666705.211414"]], "c": "3169854718"}, "book-100", "XBT/USD"]
[270, {"b": [["11641.80000", "0.85846608", "1596666705.213950"]], "c": "3169854718"}, "book-100", "XBT/USD"]
[270, {"b": [["11641.90000", "1.73086073", "1596666705.214616"]], "c": "172500626"}, "book-100", "XBT/USD"]
[270, {"b": [["11644.20000", "0.64384956", "1596666705.216601"]], "c": "3160909385"}, "book-100", "XBT/USD"]
[270, {"a": [["11651.60000", "1.91352978", "1596666705.233755"]], "c": "4138841127"}, "book-100", "XBT/USD"]
[270, {"b": [["11632.10000", "0.00000000", "1596666705.372529"], ["11586.00000", "2.83070444", "1596666641.836792", "r"]], "c": "4138841127"}, "book-100", "XBT/USD"]
[270, {"b": [["11645.30000", "5.94380900", "1596666705.372639"]], "c": "2997687411"}, "book-100", "XBT/USD"]
[270, {"a": [["11651.60000", "0.41352978", "1596666705.373293"]], "c": "492757975"}, "book-100", "XBT/USD"]
[270, {"b": [["11633.50000", "0.00000000", "1596666705.378057"], ["11585.50000", "0.00509766", "1596666166.036585", "r"]], "c": "492757975"}, "book-100", "XBT/USD"]
[270, {"a": [["11656.70000", "0.00000000", "1596666705.379849"], ["11699.90000", "0.10000000", "1596666079.896762", "r"]], "c": "492757975"}, "book-100", "XBT/USD"]
[270, {"a": [["11660.70000", "2.91767140", "1596666705.380958"]], "c": "492757975"}, "book-100", "XBT/USD"]
[270, {"a": [["11657.00000", "3.88349435", "1596666705.381658"]], "c": "492757975"}, "book-100", "XBT/USD"]
[270, {"b": [["11644.50000", "0.25000000", "1596666705.381804"]], "c": "849823271"}, "book-100", "XBT/USD"]
[270, {"a": [["11647.00000", "0.00000000", "1596666705.382763"], ["11699.90000", "0.10000000", "1596666079.896762", "r"]], "c": "4287813160"}, "book-100", "XBT/USD"]
[270, {"b": [["11598.80000", "0.10603336", "1596666705.382897"]], "c": "4287813160"}, "book-100", "XBT/USD"]
[270, {"a": [["11676.90000", "0.00000000", "1596666705.386190"], ["11700.00000", "0.52000000", "1596666697.653648", "r"]], "c": "4287813160"}, "book-100", "XBT/USD"]
[270, {"b": [["11598.80000", "0.00000000", "1596666705.386802"], ["11585.50000", "0.00509766", "1596666166.036585", "r"]], "c": "4287813160"}, "book-100", "XBT/USD"]
[270, {"b": [["11632.50000", "0.00000000", "1596666705.401104"], ["11585.00000", "7.70000000", "1596666429.743667", "r"]], "c": "4287813160"}, "book-100", "XBT/USD"]
[270, {"b": [["11645.10000", "0.92120000", "1596666705.406690"]], "c": "738765853"}, "book-100", "XBT/USD"]
[270, {"b": [["11642.10000", "0.00000000", "1596666705.419592"], ["11585.00000", "7.70000000", "1596666429.743667", "r"]], "c": "738765853"}, "book-100", "XBT/USD"]
[270, {"a": [["11680.60000", "0.00000000", "1596666705.423450"], ["11701.10000", "0.01796445", "1596665962.941606", "r"]], "c": "738765853"}, "book-100", "XBT/USD"]
[270, {"b": [["11644.20000", "4.92284956", "1596666705.431334"]], "c": "2730464657"}, "book-100", "XBT/USD"]
[270, {"b": [["11645.30000", "0.64380900", "1596666705.441823"]], "c": "961187890"}, "book-100", "XBT/USD"]
[270, {"b": [["11644.10000", "0.30000000", "1596666705.443109"]], "c": "3226494334"}, "book-100", "XBT/USD"]
[270, {"a": [["11656.80000", "1.30492111", "1596666705.453571"]], "c": "3226494334"}, "book-100", "XBT/USD"]
[270, {"a": [["11662.20000", "6.88358237", "1596666705.460064"]], "c": "3226494334"}, "book-100", "XBT/USD"]
[270, {"b": [["11600.60000", "0.00000000", "1596666705.469501"], ["11583.80000", "2.33213693", "1596666587.499785", "r"]], "c": "3226494334"}, "book-100", "XBT/USD"]
[270, {"a": [["11646.90000", "0.00000000", "1596666705.519412"], ["11701.10000", "0.01796445", "1596665962.941606", "r"]], "c": "2878088818"}, "book-100", "XBT/USD"]
[270, {"a": [["11657.00000", "1.71500000", "1596666705.525828"]], "c": "2878088818"}, "book-100", "XBT/USD"]
[270, {"a": [["11653.50000", "1.50000000", "1596666705.527443"]], "c": "2878088818"}, "book-100", "XBT/USD"]
[270, {"a": [["11650.20000", "0.33272870", "1596666705.621259"]], "c": "994724324"}, "book-100", "XBT/USD"]
[270, {"a": [["11651.60000", "0.00000000", "1596666705.662710"], ["11701.10000", "0.01796445", "1596665962.941606", "r"]], "c": "571808952"}, "book-100", "XBT/USD"]
[270, {"a": [["11648.80000", "0.00000000", "1596666705.664525"], ["11701.40000", "23.40000000", "1596666447.014661", "r"]], "c": "685156729"}, "book-100", "XBT/USD"]
[270, {"b": [["11644.50000", "0.00000000", "1596666705.671860"], ["11583.60000", "2.29920000", "1596666614.296152", "r"]], "c": "336119442"}, "book-100", "XBT/USD"]
[270, {"b": [["11639.40000", "0.00000000", "1596666705.675753"], ["11583.00000", "0.01000000", "1596666661.045375", "r"]], "c": "336119442"}, "book-100", "XBT/USD"]
[270, {"a": [["11652.60000", "0.00000000", "1596666705.676439"], ["11701.70000", "3.00242295", "1596666700.111068", "r"]], "c": "2499875379"}, "book-100", "XBT/USD"]
[270, {"b": [["11627.10000", "0.00000000", "1596666705.676860"], ["11582.70000", "0.00199361", "1596666580.634885", "r"]], "c": "2499875379"}, "book-100", "XBT/USD"]
[270, {"a": [["11663.40000", "6.10000000", "1596666705.716025"]], "c": "2499875379"}, "book-100", "XBT/USD"]
[270, {"b": [["11630.10000", "9.51900000", "1596666705.727551"]], "c": "2499875379"}, "book-100", "XBT/USD"]
[270, {"a": [["11656.60000", "0.01100000", "1596666705.727817"]], "c": "2499875379"}, "book-100", "XBT/USD"]
[270, {"a": [["11648.70000", "0.00860769", "1596666705.732639"]], "c": "2445706229"}, "book-100", "XBT/USD"]
[270, {"b": [["11604.70000", "0.00000000", "1596666705.747584"], ["11582.40000", "2.25182221", "1596666702.380025", "r"]], "c": "2445706229"}, "book-100", "XBT/USD"]
[270, {"a": [["11679.80000", "0.00000000", "1596666705.747813"], ["11701.40000", "23.40000000", "1596666447.014661", "r"]], "c": "2445706229"}, "book-100", "XBT/USD"]
[270, {"a": [["11683.10000", "0.66743977", "1596666705.799890"]], "c": "2445706229"}, "book-100", "XBT/USD"]
[270, {"a": [["11652.70000", "0.41352978", "1596666705.800856"]], "c": "3719158064"}, "book-100", "XBT/USD"]
[270, {"b": [["11645.70000", "0.25000000", "1596666705.816035"]], "c": "1178729152"}, "book-100", "XBT/USD"]
[270, {"b": [["11586.50000", "0.00000000", "1596666705.825931"], ["11582.40000", "2.25182221", "1596666702.380025", "r"]], "c": "1178729152"}, "book-100", "XBT/USD"]
[270, {"b": [["11646.20000", "0.09621094", "1596666705.839592"]], "c": "1024285378"}, "book-100", "XBT/USD"]
[270, {"a": [["11656.20000", "0.09621094", "1596666705.850504"]], "c": "1024285378"}, "book-100", "XBT/USD"]
[270, {"a": [["11650.70000", "0.41328859", "1596666705.852052"]], "c": "3288440177"}, "book-100", "XBT/USD"]
[270, {"a": [["11694.10000", "20.00000000", "1596666705.854859"]], "c": "3288440177"}, "book-100", "XBT/USD"]
[270, {"b": [["11613.10000", "0.10590960", "1596666705.855196"]], "c": "3288440177"}, "book-100", "XBT/USD"]
[270, {"b": [["11604.00000", "0.74774670", "1596666705.857871"]], "c": "3288440177"}, "book-100", "XBT/USD"]
[270, {"b": [["11597.00000", "0.90351378", "1596666705.861620"]], "c": "3288440177"}, "book-100", "XBT/USD"]
[270, {"a": [["11658.50000", "0.00000000", "1596666705.872933"], ["11699.50000", "2.48018651", "1596666596.614575", "r"]], "c": "3288440177"}, "book-100", "XBT/USD"]
[270, {"a": [["11660.90000", "0.85867306", "1596666705.873210"]], "c": "3288440177"}, "book-100", "XBT/USD"]
[270, {"a": [["11648.70000", "0.00000000", "1596666705.880093"], ["11699.90000", "0.10000000", "1596666079.896762", "r"]], "c": "401783050"}, "book-100", "XBT/USD"]
[270, {"b": [["11645.30000", "0.00000000", "1596666705.883396"], ["11583.00000", "0.01000000", "1596666661.045375", "r"]], "c": "869940564"}, "book-100", "XBT/USD"]
[270, {"b": [["11644.00000", "0.00000000", "1596666705.884033"], ["11582.70000", "0.00199361", "1596666580.634885", "r"]], "c": "747008137"}, "book-100", "XBT/USD"]
[270, {"b": [["11644.20000", "4.27900000", "1596666705.887442"]], "c": "3811573087"}, "book-100", "XBT/USD"]
[270, {"b": [["11604.90000", "0.90453641", "1596666705.889566"]], "c": "3811573087"}, "book-100", "XBT/USD"]
[270, {"a": [["11660.40000", "0.00000000", "1596666705.893310"], ["11700.00000", "0.52000000", "1596666697.653648", "r"]], "c": "3811573087"}, "book-100", "XBT/USD"]
[270, {"a": [["11656.90000", "0.00000000", "1596666705.909115"], ["11701.10000", "0.01796445", "1596665962.941606", "r"]], "c": "3811573087"}, "book-100", "XBT/USD"]
[270, {"b": [["11643.30000", "0.04250000", "1596666705.927682"]], "c": "3912925251"}, "book-100", "XBT/USD"]
[270, {"a": [["11650.00000", "0.00860672", "1596666705.928508"]], "c": "2003737956"}, "book-100", "XBT/USD"]
[270, {"a": [["11667.40000", "0.91830000", "1596666705.931921"]], "c": "2003737956"}, "book-100", "XBT/USD"]
[270, {"a": [["11658.90000", "1.35558999", "1596666705.948785"]], "c": "2003737956"}, "book-100", "XBT/USD"]
[270, {"a": [["11664.20000", "3.53657250", "1596666705.952067"]], "c": "2003737956"}, "book-100", "XBT/USD"]
[270, {"a": [["11663.70000", "2.12275809", "1596666705.958107"]], "c": "2003737956"}, "book-100", "XBT/USD"]
[270, {"a": [["11657.00000", "0.00000000", "1596666705.965753"], ["11700.00000", "0.52000000", "1596666697.653648", "r"]], "c": "2003737956"}, "book-100", "XBT/USD"]
[270, {"a": [["11665.40000", "0.90011352", "1596666705.972783"]], "c": "2003737956"}, "book-100", "XBT/USD"]
[270, {"a": [["11651.10000", "0.00000000", "1596666705.996001"], ["11701.10000", "0.01796445", "1596665962.941606", "r"]], "c": "783723132"}, "book-100", "XBT/USD"]
[270, {"a": [["11673.30000", "0.00000000", "1596666705.997619"], ["11701.40000", "23.40000000", "1596666447.014661", "r"]], "c": "783723132"}, "book-100", "XBT/USD"]
[270, {"a": [["11650.20000", "0.00000000", "1596666706.000318"], ["11701.70000", "3.00242295", "1596666700.111068", "r"]], "c": "2160101973"}, "book-100", "XBT/USD"]
[270, {"a": [["11663.70000", "0.69986998", "1596666706.024265"]], "c": "2160101973"}, "book-100", "XBT/USD"]
[270, {"a": [["11661.80000", "0.00000000", "1596666706.032407"], ["11702.50000", "23.57900000", "1596666155.599282", "r"]], "c": "2160101973"}, "book-100", "XBT/USD"]
[270, {"a": [["11664.70000", "0.00000000", "1596666706.033589"], ["11704.10000", "8.30000000", "1596666665.290916", "r"]], "c": "2160101973"}, "book-100", "XBT/USD"]
[270, {"a": [["11680.80000", "0.00000000", "1596666706.033644"], ["11704.20000", "1.06000000", "1596666647.223134", "r"]], "c": "2160101973"}, "book-100", "XBT/USD"]
[270, {"a": [["11664.10000", "0.00000000", "1596666706.044947"], ["11705.90000", "4.41315145", "1596666428.485819", "r"]], "c": "2160101973"}, "book-100", "XBT/USD"]
[270, {"a": [["11664.20000", "0.00000000", "1596666706.046809"], ["11706.10000", "3.50960038", "1596666142.533745", "r"]], "c": "2160101973"}, "book-100", "XBT/USD"]
[270, {"a": [["11665.40000", "0.00000000", "1596666706.052512"], ["11709.00000", "0.17085000", "1596666698.599816", "r"]], "c": "2160101973"}, "book-100", "XBT/USD"]
[270, {"a": [["11650.10000", "0.00000000", "1596666706.080751"], ["11709.60000", "4.27000068", "1596666650.408245", "r"]], "c": "2926382374"}, "book-100", "XBT/USD"]
[270, {"b": [["11596.30000", "19.40000000", "1596666706.107317"]], "c": "2926382374"}, "book-100", "XBT/USD"]
[270, {"a": [["11673.20000", "0.00000000", "1596666706.107398"], ["11709.70000", "7.20507863", "1596666620.257365", "r"]], "c": "2926382374"}, "book-100", "XBT/USD"]
[270, {"a": [["11662.50000", "0.00000000", "1596666706.109234"], ["11711.00000", "3.52207482", "1596666594.088624", "r"]], "c": "2926382374"}, "book-100", "XBT/USD"]
[270, {"a": [["11651.60000", "0.25875307", "1596666706.109381"]], "c": "4222543945"}, "book-100", "XBT/USD"]
[270, {"b": [["11594.30000", "2.01919334", "1596666706.140722"]], "c": "4222543945"}, "book-100", "XBT/USD"]
[270, {"a": [["11709.00000", "0.00000000", "1596666706.154846"], ["11711.00000", "3.52207482", "1596666594.088624", "r"]], "c": "4222543945"}, "book-100", "XBT/USD"]
[270, {"a": [["11668.30000", "0.24944244", "1596666706.156603"]], "c": "4222543945"}, "book-100", "XBT/USD"]
[270, {"a": [["11662.50000", "0.13438983", "1596666706.156945"]], "c": "4222543945"}, "book-100", "XBT/USD"]
[270, {"b": [["11625.60000", "0.00000000", "1596666706.158760"], ["11583.60000", "2.29920000", "1596666614.296152", "r"]], "c": "4222543945"}, "book-100", "XBT/USD"]
[270, {"a": [["11660.40000", "0.04479661", "1596666706.159317"]], "c": "4222543945"}, "book-100", "XBT/USD"]
[270, {"b": [["11617.10000", "0.00000000", "1596666706.159498"], ["11583.00000", "0.01000000", "1596666661.045375", "r"]], "c": "4222543945"}, "book-100", "XBT/USD"]
[270, {"b": [["11643.20000", "0.00000000", "1596666706.175764"], ["11582.70000", "0.00199361", "1596666580.634885", "r"]], "c": "1371130258"}, "book-100", "XBT/USD"]
[270, {"b": [["11599.60000", "0.00000000", "1596666706.193235"], ["11582.40000", "2.25182221", "1596666702.380025", "r"]], "c": "1371130258"}, "book-100", "XBT/USD"]
[270, {"b": [["11630.40000", "0.00375137", "1596666706.225141"]], "c": "1371130258"}, "book-100", "XBT/USD"]
[270, {"b": [["11645.50000", "0.05540005", "1596666706.233020"]], "c": "2211453001"}, "book-100", "XBT/USD"]
[270, {"a": [["11650.60000", "0.00860628", "1596666706.236272"]], "c": "4086473952"}, "book-100", "XBT/USD"]
[270, {"a": [["11650.00000", "0.00000000", "1596666706.236335"], ["11706.10000", "3.50960038", "1596666142.533745", "r"]], "c": "972424095"}, "book-100", "XBT/USD"]
[270, {"b": [["11644.20000", "0.00000000", "1596666706.238224"], ["11582.70000", "0.00199361", "1596666580.634885", "r"]], "c": "2130734918"}, "book-100", "XBT/USD"]
[270, {"a": [["11651.50000", "4.28900000", "1596666706.256875"]], "c": "145772850"}, "book-100", "XBT/USD"]
[270, {"b": [["11616.40000", "2.77000000", "1596666706.263674"]], "c": "145772850"}, "book-100", "XBT/USD"]
[270, {"b": [["11645.50000", "4.34340005", "1596666706.265800"]], "c": "217988553"}, "book-100", "XBT/USD"]
[270, {"a": [["11668.90000", "7.59728413", "1596666706.283870"]], "c": "217988553"}, "book-100", "XBT/USD"]
[270, {"a": [["11684.50000", "10.19791134", "1596666706.297441"]], "c": "217988553"}, "book-100", "XBT/USD"]
[270, {"a": [["11655.60000", "0.00000000", "1596666706.341728"], ["11705.90000", "4.41315145", "1596666428.485819", "r"]], "c": "217988553"}, "book-100", "XBT/USD"]
[270, {"a": [["11661.60000", "0.50000000", "1596666706.344387"]], "c": "217988553"}, "book-100", "XBT/USD"]
[270, {"a": [["11701.50000", "2.00069507", "1596666706.346367"]], "c": "217988553"}, "book-100", "XBT/USD"]
[270, {"b": [["11605.60000", "6.54669730", "1596666706.356653"]], "c": "217988553"}, "book-100", "XBT/USD"]
[270, {"b": [["11624.10000", "0.00000000", "1596666706.372871"], ["11583.00000", "0.01000000", "1596666661.045375", "r"]], "c": "217988553"}, "book-100", "XBT/USD"]
[270, {"a": [["11659.20000", "0.00000000", "1596666706.373084"], ["11704.20000", "1.06000000", "1596666647.223134", "r"]], "c": "217988553"}, "book-100", "XBT/USD"]
[270, {"b": [["11630.00000", "1.00930000", "1596666706.375662"]], "c": "217988553"}, "book-100", "XBT/USD"]
[270, {"a": [["11665.00000", "3.30840000", "1596666706.378215"]], "c": "217988553"}, "book-100", "XBT/USD"]
[270, {"b": [["11644.70000", "0.42900000", "1596666706.423958"]], "c": "2457794016"}, "book-100", "XBT/USD"]
[270, {"a": [["11668.70000", "6.49772840", "1596666706.440951"]], "c": "2457794016"}, "book-100", "XBT/USD"]
[270, {"a": [["11671.20000", "0.34913265", "1596666706.481781"]], "c": "2457794016"}, "book-100", "XBT/USD"]
[270, {"a": [["11651.40000", "2.00000000", "1596666706.498517"]], "c": "1435933254"}, "book-100", "XBT/USD"]
[270, {"a": [["11656.30000", "0.33826614", "1596666706.501202"]], "c": "1435933254"}, "book-100", "XBT/USD"]
[270, {"a": [["11650.50000", "0.12079848", "1596666706.514942"]], "c": "1196013889"}, "book-100", "XBT/USD"]
[270, {"a": [["11657.00000", "0.87052737", "1596666706.536252"]], "c": "1196013889"}, "book-100", "XBT/USD"]
[270, {"a": [["11665.00000", "3.41178967", "1596666706.555621"]], "c": "1196013889"}, "book-100", "XBT/USD"]
[270, {"a": [["11667.40000", "1.64187885", "1596666706.555961"]], "c": "1196013889"}, "book-100", "XBT/USD"]
[270, {"a": [["11650.60000", "0.00000000", "1596666706.655428"], ["11701.50000", "2.00069507", "1596666706.346367", "r"]], "c": "1578397744"}, "book-100", "XBT/USD"]
[270, {"a": [["11650.40000", "0.00860643", "1596666706.655873"]], "c": "3236799467"}, "book-100", "XBT/USD"]
[270, {"a": [["11670.80000", "2.86563552", "1596666706.659014"]], "c": "3236799467"}, "book-100", "XBT/USD"]
[270, {"a": [["11667.30000", "0.89969870", "1596666706.659902"]], "c": "3236799467"}, "book-100", "XBT/USD"]
[270, {"b": [["11645.50000", "4.28800000", "1596666706.667963"]], "c": "2168853915"}, "book-100", "XBT/USD"]
[270, {"a": [["11685.20000", "1.96108754", "1596666706.732356"]], "c": "2168853915"}, "book-100", "XBT/USD"]
[270, {"a": [["11667.70000", "1.42222783", "1596666706.735538"]], "c": "2168853915"}, "book-100", "XBT/USD"]
[270, {"a": [["11665.30000", "0.71126022", "1596666706.750417"]], "c": "2168853915"}, "book-100", "XBT/USD"]
[270, {"b": [["11599.80000", "1.97552545", "1596666706.751723"]], "c": "2168853915"}, "book-100", "XBT/USD"]
[270, {"b": [["11619.40000", "0.71406990", "1596666706.753445"]], "c": "2168853915"}, "book-100", "XBT/USD"]
[270, {"b": [["11611.30000", "1.80343361", "1596666706.758254"]], "c": "2168853915"}, "book-100", "XBT/USD"]
[270, {"b": [["11622.80000", "0.33993382", "1596666706.758340"]], "c": "2168853915"}, "book-100", "XBT/USD"]
[270, {"a": [["11662.00000", "0.33879118", "1596666706.770541"]], "c": "2168853915"}, "book-100", "XBT/USD"]
[270, {"b": [["11630.40000", "0.00000000", "1596666706.773743"], ["11586.00000", "2.83070444", "1596666641.836792", "r"]], "c": "2168853915"}, "book-100", "XBT/USD"]
[270, {"a": [["11672.70000", "0.00000000", "1596666706.830518"], ["11699.50000", "2.48018651", "1596666596.614575", "r"]], "c": "2168853915"}, "book-100", "XBT/USD"]
[270, {"a": [["11650.50000", "0.00000000", "1596666706.950696"], ["11699.90000", "0.10000000", "1596666079.896762", "r"]], "c": "2367864170"}, "book-100", "XBT/USD"]
[270, {"a": [["11650.30000", "0.12086400", "1596666706.954707"]], "c": "291191023"}, "book-100", "XBT/USD"]
[270, {"a": [["11679.90000", "0.00000000", "1596666706.967798"], ["11699.90000", "0.10000000", "1596666079.896762", "r"]], "c": "291191023"}, "book-100", "XBT/USD"]
[270, {"a": [["11690.30000", "0.75800000", "1596666706.971928"]], "c": "291191023"}, "book-100", "XBT/USD"]
[270, {"b": [["11646.30000", "0.05539624", "1596666706.988199"]], "c": "897742736"}, "book-100", "XBT/USD"]
[270, {"a": [["11656.80000", "0.00000000", "1596666707.000151"], ["11699.90000", "0.10000000", "1596666079.896762", "r"]], "c": "897742736"}, "book-100", "XBT/USD"]
[270, {"b": [["11642.80000", "0.08250000", "1596666707.075108"]], "c": "2987404851"}, "book-100", "XBT/USD"]
[270, {"b": [["11617.10000", "1.42842256", "1596666707.079485"]], "c": "2987404851"}, "book-100", "XBT/USD"]
[270, {"b": [["11631.70000", "0.04227390", "1596666707.080559"]], "c": "2987404851"}, "book-100", "XBT/USD"]
[270, {"a": [["11658.80000", "0.08250000", "1596666707.115108"]], "c": "2987404851"}, "book-100", "XBT/USD"]
[270, {"a": [["11650.40000", "0.00000000", "1596666707.146967"], ["11699.90000", "0.10000000", "1596666079.896762", "r"]], "c": "861870291"}, "book-100", "XBT/USD"]
[270, {"a": [["11650.20000", "0.00860658", "1596666707.153657"]], "c": "1031618504"}, "book-100", "XBT/USD"]
[270, {"a": [["11652.70000", "0.00000000", "1596666707.156711"], ["11699.90000", "0.10000000", "1596666079.896762", "r"]], "c": "4240743771"}, "book-100", "XBT/USD"]
[270, {"b": [["11645.70000", "0.00000000", "1596666707.186380"], ["11589.90000", "6.90000000", "1596666166.290818", "r"]], "c": "3096022525"}, "book-100", "XBT/USD"]
[270, {"a": [["11662.00000", "0.00000000", "1596666707.215096"], ["11700.00000", "0.52000000", "1596666697.653648", "r"]], "c": "3096022525"}, "book-100", "XBT/USD"]
[270, {"b": [["11646.50000", "0.25000000", "1596666707.330903"]], "c": "1374376064"}, "book-100", "XBT/USD"]
[270, {"a": [["11653.60000", "0.41352978", "1596666707.331182"]], "c": "1374376064"}, "book-100", "XBT/USD"]
[270, {"a": [["11656.10000", "1.38190843", "1596666707.387768"]], "c": "1374376064"}, "book-100", "XBT/USD"]
[270, {"a": [["11670.80000", "0.89942888", "1596666707.451997"]], "c": "1374376064"}, "book-100", "XBT/USD"]
[270, {"b": [["11616.40000", "0.00000000", "1596666707.452451"], ["11589.90000", "6.90000000", "1596666166.290818", "r"]], "c": "1374376064"}, "book-100", "XBT/USD"]
[270, {"a": [["11656.10000", "0.00000000", "1596666707.502990"], ["11699.90000", "0.10000000", "1596666079.896762", "r"]], "c": "1374376064"}, "book-100", "XBT/USD"]
[270, {"a": [["11660.50000", "0.00000000", "1596666707.591016"], ["11700.00000", "0.52000000", "1596666697.653648", "r"]], "c": "1374376064"}, "book-100", "XBT/USD"]
[270, {"a": [["11650.20000", "0.00000000", "1596666707.598933"], ["11701.10000", "0.01796445", "1596665962.941606", "r"]], "c": "34281744"}, "book-100", "XBT/USD"]
[270, {"a": [["11677.20000", "0.84300000", "1596666707.648571"]], "c": "34281744"}, "book-100", "XBT/USD"]
[270, {"a": [["11661.40000", "1.00264117", "1596666707.682463"]], "c": "34281744"}, "book-100", "XBT/USD"]
[270, {"a": [["11675.60000", "2.06270941", "1596666707.690685"]], "c": "34281744"}, "book-100", "XBT/USD"]
[270, {"b": [["11633.50000", "2.00000000", "1596666707.777473"]], "c": "34281744"}, "book-100", "XBT/USD"]
[270, {"a": [["11668.80000", "1.20983714", "1596666707.782219"]], "c": "34281744"}, "book-100", "XBT/USD"]
[270, {"b": [["11599.90000", "1.51796067", "1596666707.840672"]], "c": "34281744"}, "book-100", "XBT/USD"]
[270, {"a": [["11650.30000", "0.00000000", "1596666707.869954"], ["11700.00000", "0.52000000", "1596666697.653648", "r"]], "c": "2993083378"}, "book-100", "XBT/USD"]
[270, {"a": [["11651.60000", "0.00000000", "1596666707.898805"], ["11701.10000", "0.01796445", "1596665962.941606", "r"]], "c": "2662531235"}, "book-100", "XBT/USD"]
[270, {"a": [["11656.00000", "1.26255584", "1596666707.907598"]], "c": "2662531235"}, "book-100", "XBT/USD"]
[270, {"a": [["11652.70000", "0.25874403", "1596666707.970838"]], "c": "374361111"}, "book-100", "XBT/USD"]
[270, {"a": [["11662.20000", "6.13331476", "1596666707.971878"]], "c": "374361111"}, "book-100", "XBT/USD"]
[270, {"b": [["11599.50000", "2.00125593", "1596666708.111995"]], "c": "374361111"}, "book-100", "XBT/USD"]
[270, {"a": [["11650.60000", "0.12107286", "1596666708.168741"]], "c": "3591610975"}, "book-100", "XBT/USD"]
[270, {"a": [["11653.70000", "0.64372717", "1596666708.200446"]], "c": "3591610975"}, "book-100", "XBT/USD"]
[270, {"b": [["11647.20000", "0.64372717", "1596666708.202229"]], "c": "1969252214"}, "book-100", "XBT/USD"]
[270, {"b": [["11646.50000", "0.89372717", "1596666708.204444"]], "c": "3835034593"}, "book-100", "XBT/USD"]
[270, {"b": [["11608.90000", "0.70560000", "1596666708.206358"]], "c": "3835034593"}, "book-100", "XBT/USD"]
[270, {"a": [["11682.70000", "2.48000000", "1596666708.262695"]], "c": "3835034593"}, "book-100", "XBT/USD"]
[270, {"a": [["11650.20000", "0.00586966", "1596666708.349503"]], "c": "505244982"}, "book-100", "XBT/USD"]
[270, {"a": [["11674.90000", "3.53333592", "1596666708.393222"]], "c": "505244982"}, "book-100", "XBT/USD"]
[270, {"a": [["11668.20000", "3.53466318", "1596666708.437803"]], "c": "505244982"}, "book-100", "XBT/USD"]
[270, {"b": [["11608.00000", "0.00000000", "1596666708.442116"], ["11590.90000", "2.50315283", "1596666703.117862", "r"]], "c": "505244982"}, "book-100", "XBT/USD"]
[270, {"a": [["11653.70000", "0.00000000", "1596666708.445591"], ["11694.10000", "20.00000000", "1596666705.854859", "r"]], "c": "505244982"}, "book-100", "XBT/USD"]
[270, {"a": [["11674.00000", "4.43049922", "1596666708.447383"]], "c": "505244982"}, "book-100", "XBT/USD"]
[270, {"b": [["11603.20000", "3.55446402", "1596666708.458533"]], "c": "505244982"}, "book-100", "XBT/USD"]
[270, {"a": [["11667.70000", "0.00000000", "1596666708.472400"], ["11695.10000", "0.35368913", "1596666684.533099", "r"]], "c": "505244982"}, "book-100", "XBT/USD"]
[270, {"a": [["11665.30000", "0.00000000", "1596666708.477090"], ["11696.80000", "1.98460791", "1596666708.392556", "r"]], "c": "505244982"}, "book-100", "XBT/USD"]
[270, {"b": [["11646.50000", "0.64372717", "1596666708.508686"]], "c": "2665228180"}, "book-100", "XBT/USD"]
[270, {"a": [["11657.00000", "3.70575122", "1596666708.508986"]], "c": "2665228180"}, "book-100", "XBT/USD"]
[270, {"a": [["11653.60000", "0.00000000", "1596666708.533702"], ["11698.00000", "6.50000000", "1596665849.372318", "r"]], "c": "2665228180"}, "book-100", "XBT/USD"]
[270, {"a": [["11650.60000", "0.00000000", "1596666708.583828"], ["11699.50000", "2.48018651", "1596666596.614575", "r"]], "c": "4004003688"}, "book-100", "XBT/USD"]
[270, {"b": [["11644.20000", "1.71200000", "1596666708.595403"]], "c": "2206528666"}, "book-100", "XBT/USD"]
[270, {"a": [["11652.60000", "1.70500000", "1596666708.604721"]], "c": "4039081956"}, "book-100", "XBT/USD"]
[270, {"b": [["11646.30000", "0.00000000", "1596666708.649400"], ["11591.20000", "1.42910979", "1596666701.223131", "r"]], "c": "3033434079"}, "book-100", "XBT/USD"]
[270, {"a": [["11660.70000", "0.00000000", "1596666708.662555"], ["11699.50000", "2.48018651", "1596666596.614575", "r"]], "c": "3033434079"}, "book-100", "XBT/USD"]
[270, {"a": [["11652.90000", "1.05729283", "1596666708.670223"]], "c": "2734347149"}, "book-100", "XBT/USD"]
[270, {"b": [["11645.80000", "0.25000000", "1596666708.720127"]], "c": "1508649178"}, "book-100", "XBT/USD"]
[270, {"a": [["11663.60000", "1.09136389", "1596666708.777861"]], "c": "1508649178"}, "book-100", "XBT/USD"]
[270, {"b": [["11631.60000", "0.00000000", "1596666708.778014"], ["11591.20000", "1.42910979", "1596666701.223131", "r"]], "c": "1508649178"}, "book-100", "XBT/USD"]
[270, {"a": [["11666.00000", "1.42243508", "1596666708.780659"]], "c": "1508649178"}, "book-100", "XBT/USD"]
[270, {"b": [["11646.20000", "0.00000000", "1596666708.788885"], ["11590.90000", "2.50315283", "1596666703.117862", "r"]], "c": "1522019392"}, "book-100", "XBT/USD"]
[270, {"a": [["11656.20000", "0.00000000", "1596666708.801637"], ["11699.50000", "2.48018651", "1596666596.614575", "r"]], "c": "1522019392"}, "book-100", "XBT/USD"]
[270, {"a": [["11668.30000", "0.00000000", "1596666708.829824"], ["11699.90000", "0.10000000", "1596666079.896762", "r"]], "c": "1522019392"}, "book-100", "XBT/USD"]
[270, {"b": [["11631.30000", "0.04227536", "1596666708.907629"]], "c": "1522019392"}, "book-100", "XBT/USD"]
[270, {"b": [["11631.70000", "0.00000000", "1596666708.909373"], ["11590.90000", "2.50315283", "1596666703.117862", "r"]], "c": "1522019392"}, "book-100", "XBT/USD"]
[270, {"b": [["11634.60000", "0.04480106", "1596666708.961103"]], "c": "1522019392"}, "book-100", "XBT/USD"]
[270, {"b": [["11601.40000", "13.94256021", "1596666708.975741"]], "c": "1522019392"}, "book-100", "XBT/USD"]
[270, {"b": [["11600.60000", "0.75008810", "1596666708.992105"]], "c": "1522019392"}, "book-100", "XBT/USD"]
[270, {"b": [["11633.60000", "0.00000000", "1596666708.996752"], ["11592.70000", "3.55768345", "1596666703.677696", "r"]], "c": "1522019392"}, "book-100", "XBT/USD"]
[270, {"a": [["11667.90000", "0.75008810", "1596666709.009269"]], "c": "1522019392"}, "book-100", "XBT/USD"]
[270, {"a": [["11679.70000", "0.00000000", "1596666709.021078"], ["11699.90000", "0.10000000", "1596666079.896762", "r"]], "c": "1522019392"}, "book-100", "XBT/USD"]
[270, {"a": [["11656.00000", "0.00000000", "1596666709.028747"], ["11700.00000", "0.52000000", "1596666697.653648", "r"]], "c": "1522019392"}, "book-100", "XBT/USD"]
[270, {"b": [["11643.30000", "0.00000000", "1596666709.031542"], ["11591.20000", "1.06000000", "1596666709.000103", "r"]], "c": "823933887"}, "book-100", "XBT/USD"]
[270, {"a": [["11682.40000", "0.89857854", "1596666709.036856"]], "c": "823933887"}, "book-100", "XBT/USD"]
[270, {"b": [["11644.20000", "0.00000000", "1596666709.039975"], ["11590.90000", "2.50315283", "1596666703.117862", "r"]], "c": "3575064950"}, "book-100", "XBT/USD"]
[270, {"b": [["11647.20000", "0.86780717", "1596666709.158806"]], "c": "3989250979"}, "book-100", "XBT/USD"]
[270, {"a": [["11664.60000", "0.67223000", "1596666709.229466"]], "c": "3989250979"}, "book-100", "XBT/USD"]
[270, {"b": [["11644.80000", "0.04250000", "1596666709.286441"]], "c": "2947915421"}, "book-100", "XBT/USD"]
[270, {"b": [["11631.20000", "0.00000000", "1596666709.453355"], ["11590.90000", "2.50315283", "1596666703.117862", "r"]], "c": "2947915421"}, "book-100", "XBT/USD"]
[270, {"b": [["11615.40000", "7.11679957", "1596666709.453629"]], "c": "2947915421"}, "book-100", "XBT/USD"]
[270, {"b": [["11627.00000", "7.10969930", "1596666709.468249"]], "c": "2947915421"}, "book-100", "XBT/USD"]
[270, {"a": [["11655.00000", "1.37457180", "1596666709.472523"]], "c": "2947915421"}, "book-100", "XBT/USD"]
[270, {"a": [["11655.00000", "0.00000000", "1596666709.528539"], ["11699.50000", "2.48018651", "1596666596.614575", "r"]], "c": "2947915421"}, "book-100", "XBT/USD"]
[270, {"b": [["11630.40000", "0.04227863", "1596666709.586089"]], "c": "2947915421"}, "book-100", "XBT/USD"]
[270, {"b": [["11631.30000", "0.00000000", "1596666709.586936"], ["11592.70000", "3.55768345", "1596666703.677696", "r"]], "c": "2947915421"}, "book-100", "XBT/USD"]
[270, {"a": [["11651.40000", "0.00000000", "1596666709.605657"], ["11699.90000", "0.10000000", "1596666079.896762", "r"]], "c": "471724875"}, "book-100", "XBT/USD"]
[270, {"a": [["11652.90000", "0.64376305", "1596666709.624924"]], "c": "1553918420"}, "book-100", "XBT/USD"]
[270, {"a": [["11685.10000", "6.39584557", "1596666709.627131"]], "c": "1553918420"}, "book-100", "XBT/USD"]
[270, {"b": [["11644.70000", "0.00000000", "1596666709.636847"], ["11591.20000", "1.06000000", "1596666709.000103", "r"]], "c": "1962676869"}, "book-100", "XBT/USD"]
[270, {"b": [["11645.80000", "0.00000000", "1596666709.636938"], ["11590.90000", "2.50315283", "1596666703.117862", "r"]], "c": "2287414871"}, "book-100", "XBT/USD"]
[270, {"b": [["11634.10000", "0.13440245", "1596666709.677649"]], "c": "2287414871"}, "book-100", "XBT/USD"]
[270, {"a": [["11651.50000", "0.00000000", "1596666709.685138"], ["11699.90000", "0.10000000", "1596666079.896762", "r"]], "c": "2025179244"}, "book-100", "XBT/USD"]
[270, {"a": [["11653.70000", "0.41352978", "1596666709.853931"]], "c": "4187261181"}, "book-100", "XBT/USD"]
[270, {"b": [["11646.60000", "0.25000000", "1596666709.862789"]], "c": "2239525458"}, "book-100", "XBT/USD"]
[270, {"b": [["11646.20000", "0.42900000", "1596666709.869943"]], "c": "476158067"}, "book-100", "XBT/USD"]
[270, {"b": [["11595.00000", "0.00000000", "1596666709.902068"], ["11592.70000", "3.55768345", "1596666703.677696", "r"]], "c": "476158067"}, "book-100", "XBT/USD"]
[270, {"a": [["11652.70000", "0.00000000", "1596666710.042647"], ["11699.90000", "0.10000000", "1596666079.896762", "r"]], "c": "894267038"}, "book-100", "XBT/USD"]
[270, {"b": [["11619.00000", "7.17085000", "1596666710.064885"]], "c": "894267038"}, "book-100", "XBT/USD"]
[270, {"a": [["11651.60000", "0.25875904", "1596666710.140631"]], "c": "4075568994"}, "book-100", "XBT/USD"]
[270, {"a": [["11668.70000", "0.30000000", "1596666710.575914"]], "c": "4075568994"}, "book-100", "XBT/USD"]
[270, {"a": [["11654.90000", "1.37286500", "1596666710.589274"]], "c": "4075568994"}, "book-100", "XBT/USD"]
[270, {"b": [["11635.20000", "0.00000000", "1596666710.630372"], ["11591.20000", "1.06000000", "1596666709.000103", "r"]], "c": "4075568994"}, "book-100", "XBT/USD"]
[270, {"b": [["11605.60000", "0.00000000", "1596666710.656627"], ["11590.90000", "2.50315283", "1596666703.117862", "r"]], "c": "4075568994"}, "book-100", "XBT/USD"]
[270, {"b": [["11624.70000", "0.05294960", "1596666710.690469"]], "c": "4075568994"}, "book-100", "XBT/USD"]
[270, {"a": [["11669.90000", "6.19544473", "1596666710.742400"]], "c": "4075568994"}, "book-100", "XBT/USD"]
[270, {"b": [["11609.90000", "6.54427258", "1596666710.823845"]], "c": "4075568994"}, "book-100", "XBT/USD"]
[270, {"a": [["11673.90000", "0.49932740", "1596666710.979056"]], "c": "4075568994"}, "book-100", "XBT/USD"]
[270, {"a": [["11660.80000", "0.57579554", "1596666710.983873"]], "c": "4075568994"}, "book-100", "XBT/USD"]
[270, {"a": [["11686.60000", "0.00000000", "1596666711.030886"], ["11695.10000", "0.35368913", "1596666684.533099", "r"]], "c": "4075568994"}, "book-100", "XBT/USD"]
[270, {"b": [["11608.30000", "0.00000000", "1596666711.034288"], ["11591.20000", "1.06000000", "1596666709.000103", "r"]], "c": "4075568994"}, "book-100", "XBT/USD"]
[270, {"b": [["11607.70000", "8.40000000", "1596666711.038925"]], "c": "4075568994"}, "book-100", "XBT/USD"]
[270, {"a": [["11674.90000", "0.00000000", "1596666711.050806"], ["11696.80000", "1.98460791", "1596666708.392556", "r"]], "c": "4075568994"}, "book-100", "XBT/USD"]
[270, {"a": [["11674.80000", "0.00000000", "1596666711.051094"], ["11698.00000", "6.50000000", "1596665849.372318", "r"]], "c": "4075568994"}, "book-100", "XBT/USD"]
[270, {"a": [["11661.40000", "0.66383256", "1596666711.052651"]], "c": "4075568994"}, "book-100", "XBT/USD"]
[270, {"a": [["11666.00000", "0.00000000", "1596666711.055200"], ["11699.50000", "2.48018651", "1596666596.614575", "r"]], "c": "4075568994"}, "book-100", "XBT/USD"]
[270, {"a": [["11665.00000", "3.30840000", "1596666711.056068"]], "c": "4075568994"}, "book-100", "XBT/USD"]
[270, {"b": [["11617.30000", "0.00000000", "1596666711.056498"], ["11590.90000", "2.50315283", "1596666703.117862", "r"]], "c": "4075568994"}, "book-100", "XBT/USD"]
[270, {"b": [["11611.50000", "0.00000000", "1596666711.056573"], ["11590.10000", "1.51500000", "1596666649.220608", "r"]], "c": "4075568994"}, "book-100", "XBT/USD"]
[270, {"b": [["11619.60000", "0.00000000", "1596666711.056785"], ["11589.90000", "6.90000000", "1596666166.290818", "r"]], "c": "4075568994"}, "book-100", "XBT/USD"]
[270, {"a": [["11668.80000", "0.00000000", "1596666711.057513"], ["11699.90000", "0.10000000", "1596666079.896762", "r"]], "c": "4075568994"}, "book-100", "XBT/USD"]
[270, {"a": [["11663.60000", "0.38000000", "1596666711.058129"]], "c": "4075568994"}, "book-100", "XBT/USD"]
[270, {"b": [["11611.80000", "0.00000000", "1596666711.059094"], ["11588.60000", "0.75800000", "1596666599.475365", "r"]], "c": "4075568994"}, "book-100", "XBT/USD"]
[270, {"b": [["11617.10000", "0.00000000", "1596666711.061900"], ["11586.20000", "3.00500211", "1596666626.428727", "r"]], "c": "4075568994"}, "book-100", "XBT/USD"]
[270, {"a": [["11652.80000", "4.39200000", "1596666711.063406"]], "c": "3080233604"}, "book-100", "XBT/USD"]
[270, {"b": [["11611.30000", "0.00000000", "1596666711.068391"], ["11586.00000", "2.83070444", "1596666641.836792", "r"]], "c": "3080233604"}, "book-100", "XBT/USD"]
[270, {"b": [["11608.60000", "0.00000000", "1596666711.070014"], ["11585.50000", "0.00509766", "1596666166.036585", "r"]], "c": "3080233604"}, "book-100", "XBT/USD"]
[270, {"b": [["11619.40000", "0.00000000", "1596666711.071267"], ["11585.10000", "4.31588851", "1596666707.782876", "r"]], "c": "3080233604"}, "book-100", "XBT/USD"]
[270, {"b": [["11623.20000", "0.00000000", "1596666711.073465"], ["11585.00000", "7.70000000", "1596666429.743667", "r"]], "c": "3080233604"}, "book-100", "XBT/USD"]
[270, {"b": [["11612.10000", "0.00000000", "1596666711.074049"], ["11583.80000", "2.33213693", "1596666587.499785", "r"]], "c": "3080233604"}, "book-100", "XBT/USD"]
[270, {"b": [["11604.00000", "0.17085000", "1596666711.074347"]], "c": "3080233604"}, "book-100", "XBT/USD"]
[270, {"b": [["11622.80000", "0.00000000", "1596666711.077699"], ["11583.60000", "2.29920000", "1596666614.296152", "r"]], "c": "3080233604"}, "book-100", "XBT/USD"]
[270, {"a": [["11674.00000", "3.53290705", "1596666711.085046"]], "c": "3080233604"}, "book-100", "XBT/USD"]
[270, {"b": [["11629.00000", "0.00000000", "1596666711.085254"], ["11583.00000", "0.01000000", "1596666661.045375", "r"]], "c": "3080233604"}, "book-100", "XBT/USD"]
[270, {"b": [["11644.20000", "1.70500000", "1596666711.096215"]], "c": "2073381595"}, "book-100", "XBT/USD"]
[270, {"b": [["11610.40000", "0.00000000", "1596666711.103448"], ["11583.00000", "0.01000000", "1596666661.045375", "r"]], "c": "2073381595"}, "book-100", "XBT/USD"]
[270, {"a": [["11669.60000", "0.00000000", "1596666711.104043"], ["11700.00000", "0.52000000", "1596666697.653648", "r"]], "c": "2073381595"}, "book-100", "XBT/USD"]
[270, {"b": [["11625.00000", "0.00000000", "1596666711.141230"], ["11582.70000", "0.00199361", "1596666580.634885", "r"]], "c": "2073381595"}, "book-100", "XBT/USD"]
[270, {"b": [["11615.10000", "1.21527387", "1596666711.197259"]], "c": "2073381595"}, "book-100", "XBT/USD"]
[270, {"a": [["11675.70000", "3.21452847", "1596666711.198970"]], "c": "2073381595"}, "book-100", "XBT/USD"]
[270, {"b": [["11623.20000", "0.10379718", "1596666711.202185"]], "c": "2073381595"}, "book-100", "XBT/USD"]
[270, {"b": [["11620.90000", "0.72672404", "1596666711.205971"]], "c": "2073381595"}, "book-100", "XBT/USD"]
[270, {"a": [["11667.50000", "0.13163902", "1596666711.206665"]], "c": "2073381595"}, "book-100", "XBT/USD"]
[270, {"a": [["11650.40000", "0.64378789", "1596666711.209431"]], "c": "1564074462"}, "book-100", "XBT/USD"]
[270, {"a": [["11687.40000", "1.50711433", "1596666711.311980"]], "c": "1564074462"}, "book-100", "XBT/USD"]
[270, {"a": [["11674.20000", "0.00000000", "1596666711.312563"], ["11699.90000", "0.10000000", "1596666079.896762", "r"]], "c": "1564074462"}, "book-100", "XBT/USD"]
[270, {"b": [["11621.90000", "2.76000000", "1596666711.318597"]], "c": "1564074462"}, "book-100", "XBT/USD"]
[270, {"b": [["11612.20000", "3.55170914", "1596666711.396580"]], "c": "1564074462"}, "book-100", "XBT/USD"]
[270, {"a": [["11687.40000", "5.03597078", "1596666711.409367"]], "c": "1564074462"}, "book-100", "XBT/USD"]
[270, {"b": [["11626.90000", "0.99826961", "1596666711.419845"]], "c": "1564074462"}, "book-100", "XBT/USD"]
[270, {"b": [["11604.60000", "0.00000000", "1596666711.447322"], ["11585.10000", "4.31588851", "1596666707.782876", "r"]], "c": "1564074462"}, "book-100", "XBT/USD"]
[270, {"b": [["11632.70000", "1.35803488", "1596666711.447997"]], "c": "1564074462"}, "book-100", "XBT/USD"]
[270, {"b": [["11614.80000", "5.10280192", "1596666711.486730"]], "c": "1564074462"}, "book-100", "XBT/USD"]
[270, {"a": [["11675.70000", "5.21964595", "1596666711.489059"]], "c": "1564074462"}, "book-100", "XBT/USD"]
[270, {"b": [["11612.80000", "0.90396407", "1596666711.602467"]], "c": "1564074462"}, "book-100", "XBT/USD"]
[270, {"b": [["11616.20000", "0.90369949", "1596666711.624562"]], "c": "1564074462"}, "book-100", "XBT/USD"]
[270, {"b": [["11607.10000", "2.01696808", "1596666711.721534"]], "c": "1564074462"}, "book-100", "XBT/USD"]
[270, {"b": [["11613.70000", "0.25062361", "1596666711.777692"]], "c": "1564074462"}, "book-100", "XBT/USD"]
[270, {"b": [["11610.30000", "0.35097580", "1596666711.778590"]], "c": "1564074462"}, "book-100", "XBT/USD"]
[270, {"a": [["11683.10000", "1.56432524", "1596666711.787884"]], "c": "1564074462"}, "book-100", "XBT/USD"]
[270, {"b": [["11605.70000", "0.57683164", "1596666711.788286"]], "c": "1564074462"}, "book-100", "XBT/USD"]
[270, {"a": [["11667.90000", "0.99954751", "1596666711.797768"]], "c": "1564074462"}, "book-100", "XBT/USD"]
[270, {"a": [["11653.50000", "0.00000000", "1596666711.801481"], ["11700.00000", "0.52000000", "1596666697.653648", "r"]], "c": "2279390267"}, "book-100", "XBT/USD"]
[270, {"a": [["11652.60000", "0.00000000", "1596666711.826295"], ["11701.10000", "0.01796445", "1596665962.941606", "r"]], "c": "2119801083"}, "book-100", "XBT/USD"]
[270, {"a": [["11652.90000", "2.34576305", "1596666711.837949"]], "c": "1755789474"}, "book-100", "XBT/USD"]
[270, {"a": [["11651.60000", "1.75875904", "1596666711.960215"]], "c": "1643881219"}, "book-100", "XBT/USD"]
[270, {"b": [["11642.30000", "0.00000000", "1596666712.019883"], ["11589.90000", "6.90000000", "1596666166.290818", "r"]], "c": "1643881219"}, "book-100", "XBT/USD"]
[270, {"a": [["11652.90000", "0.64376305", "1596666712.063526"]], "c": "2492338935"}, "book-100", "XBT/USD"]
[270, {"a": [["11660.80000", "0.00000000", "1596666712.187104"], ["11701.40000", "23.40000000", "1596666447.014661", "r"]], "c": "2492338935"}, "book-100", "XBT/USD"]
[270, {"a": [["11673.90000", "0.00000000", "1596666712.187854"], ["11701.50000", "2.00069507", "1596666706.346367", "r"]], "c": "2492338935"}, "book-100", "XBT/USD"]
[270, {"b": [["11642.40000", "1.27743411", "1596666712.220937"]], "c": "2492338935"}, "book-100", "XBT/USD"]
[270, {"a": [["11653.10000", "0.00000000", "1596666712.244878"], ["11702.50000", "23.57900000", "1596666155.599282", "r"]], "c": "2023412601"}, "book-100", "XBT/USD"]
[270, {"b": [["11623.20000", "0.00000000", "1596666712.289102"], ["11589.90000", "6.90000000", "1596666166.290818", "r"]], "c": "2023412601"}, "book-100", "XBT/USD"]
[270, {"a": [["11667.50000", "0.02823595", "1596666712.289323"]], "c": "2023412601"}, "book-100", "XBT/USD"]
[270, {"a": [["11659.80000", "0.70560000", "1596666712.309457"]], "c": "2023412601"}, "book-100", "XBT/USD"]
[270, {"b": [["11644.80000", "0.00000000", "1596666712.312007"], ["11588.60000", "0.75800000", "1596666599.475365", "r"]], "c": "2043360578"}, "book-100", "XBT/USD"]
[270, {"a": [["11651.60000", "1.50000000", "1596666712.404224"]], "c": "2501078302"}, "book-100", "XBT/USD"]
[270, {"a": [["11652.70000", "0.25874424", "1596666712.417583"]], "c": "3639817595"}, "book-100", "XBT/USD"]
[270, {"b": [["11613.40000", "6.43532340", "1596666712.418761"]], "c": "3639817595"}, "book-100", "XBT/USD"]
[270, {"b": [["11645.20000", "0.04250000", "1596666712.528913"]], "c": "4075776212"}, "book-100", "XBT/USD"]
[270, {"a": [["11654.80000", "0.04051069", "1596666712.530067"]], "c": "4075776212"}, "book-100", "XBT/USD"]
[270, {"a": [["11665.10000", "0.10342435", "1596666712.552148"]], "c": "4075776212"}, "book-100", "XBT/USD"]
[270, {"b": [["11623.30000", "0.10379628", "1596666712.581467"]], "c": "4075776212"}, "book-100", "XBT/USD"]
[270, {"a": [["11652.80000", "0.10500000", "1596666712.656304"]], "c": "371489648"}, "book-100", "XBT/USD"]
[270, {"a": [["11651.60000", "5.78500000", "1596666712.662087"]], "c": "3264488279"}, "book-100", "XBT/USD"]
[270, {"a": [["11661.70000", "0.33879704", "1596666712.782833"]], "c": "3264488279"}, "book-100", "XBT/USD"]
[270, {"a": [["11665.10000", "0.81469077", "1596666712.782933"]], "c": "3264488279"}, "book-100", "XBT/USD"]
[270, {"b": [["11617.90000", "1.42831216", "1596666712.787711"]], "c": "3264488279"}, "book-100", "XBT/USD"]
[270, {"a": [["11667.40000", "3.06413127", "1596666712.801200"]], "c": "3264488279"}, "book-100", "XBT/USD"]
[270, {"b": [["11623.60000", "0.33990756", "1596666712.802567"]], "c": "3264488279"}, "book-100", "XBT/USD"]
[270, {"b": [["11612.20000", "5.35498779", "1596666712.803477"]], "c": "3264488279"}, "book-100", "XBT/USD"]
[270, {"b": [["11620.30000", "0.71400858", "1596666712.804539"]], "c": "3264488279"}, "book-100", "XBT/USD"]
[271, [["11647.20000", "0.04977000", "1596666712.875495", "s", "m", ""]], "trade", "XBT/USD"]
[270, {"b": [["11647.20000", "0.81803717", "1596666712.875495"]], "c": "124026370"}, "book-100", "XBT/USD"]
[270, {"b": [["11647.50000", "0.09621094", "1596666712.883516"]], "c": "2046916472"}, "book-100", "XBT/USD"]
[270, {"a": [["11656.00000", "0.09621094", "1596666712.907117"]], "c": "2046916472"}, "book-100", "XBT/USD"]
[270, {"b": [["11647.50000", "0.32030094", "1596666712.947349"]], "c": "1255244144"}, "book-100", "XBT/USD"]
[270, {"b": [["11647.50000", "1.26204094", "1596666713.086516"]], "c": "225276189"}, "book-100", "XBT/USD"]
[270, {"b": [["11638.00000", "0.00000000", "1596666713.087260"], ["11592.70000", "3.55768345", "1596666703.677696", "r"]], "c": "225276189"}, "book-100", "XBT/USD"]
[270, {"a": [["11658.10000", "2.00000000", "1596666713.159680"]], "c": "225276189"}, "book-100", "XBT/USD"]
[270, {"a": [["11660.40000", "0.00000000", "1596666713.182857"], ["11699.50000", "2.48018651", "1596666596.614575", "r"]], "c": "225276189"}, "book-100", "XBT/USD"]
[270, {"a": [["11662.50000", "0.00000000", "1596666713.214893"], ["11699.90000", "0.10000000", "1596666079.896762", "r"]], "c": "225276189"}, "book-100", "XBT/USD"]
[270, {"a": [["11659.90000", "1.69000000", "1596666713.270824"]], "c": "225276189"}, "book-100", "XBT/USD"]
[270, {"a": [["11667.90000", "0.24945941", "1596666713.325372"]], "c": "225276189"}, "book-100", "XBT/USD"]
[270, {"a": [["11687.80000", "2.25118865", "1596666713.331398"]], "c": "225276189"}, "book-100", "XBT/USD"]
[270, {"b": [["11600.60000", "0.00000000", "1596666713.332844"], ["11591.20000", "1.06000000", "1596666709.000103", "r"]], "c": "225276189"}, "book-100", "XBT/USD"]
[270, {"b": [["11600.00000", "0.77936686", "1596666713.357391"]], "c": "225276189"}, "book-100", "XBT/USD"]
[270, {"a": [["11670.30000", "2.54459035", "1596666713.361993"]], "c": "225276189"}, "book-100", "XBT/USD"]
[270, {"a": [["11660.90000", "0.99307308", "1596666713.395082"]], "c": "225276189"}, "book-100", "XBT/USD"]
[270, {"a": [["11659.10000", "0.04480001", "1596666713.395290"]], "c": "225276189"}, "book-100", "XBT/USD"]
[270, {"b": [["11644.20000", "0.00000000", "1596666713.465807"], ["11590.90000", "2.50315283", "1596666703.117862", "r"]], "c": "4258892241"}, "book-100", "XBT/USD"]
[270, {"b": [["11646.60000", "0.00000000", "1596666713.479246"], ["11590.10000", "1.51500000", "1596666649.220608", "r"]], "c": "210677477"}, "book-100", "XBT/USD"]
[270, {"a": [["11653.70000", "0.00000000", "1596666713.482280"], ["11698.00000", "6.50000000", "1596665849.372318", "r"]], "c": "2080471855"}, "book-100", "XBT/USD"]
[270, {"a": [["11675.70000", "4.01067968", "1596666713.549341"]], "c": "2080471855"}, "book-100", "XBT/USD"]
[270, {"b": [["11618.20000", "0.49800000", "1596666713.589654"]], "c": "2080471855"}, "book-100", "XBT/USD"]
[270, {"a": [["11650.30000", "0.01830392", "1596666713.601592"]], "c": "41802879"}, "book-100", "XBT/USD"]
[270, {"a": [["11664.60000", "0.00000000", "1596666713.606613"], ["11698.00000", "6.50000000", "1596665849.372318", "r"]], "c": "41802879"}, "book-100", "XBT/USD"]
[270, {"b": [["11645.70000", "0.25000000", "1596666713.642858"]], "c": "433511206"}, "book-100", "XBT/USD"]
[270, {"a": [["11653.00000", "0.41352978", "1596666713.667903"]], "c": "2772796335"}, "book-100", "XBT/USD"]
[270, {"b": [["11642.40000", "0.00000000", "1596666713.668024"], ["11590.90000", "2.50315283", "1596666703.117862", "r"]], "c": "2772796335"}, "book-100", "XBT/USD"]
[270, {"a": [["11672.50000", "1.20929771", "1596666713.793647"]], "c": "2772796335"}, "book-100", "XBT/USD"]
[270, {"b": [["11635.40000", "3.93488323", "1596666714.024697"]], "c": "2772796335"}, "book-100", "XBT/USD"]
[270, {"a": [["11675.70000", "2.00556220", "1596666714.053610"]], "c": "2772796335"}, "book-100", "XBT/USD"]
[270, {"b": [["11641.00000", "1.33317123", "1596666714.082143"]], "c": "2772796335"}, "book-100", "XBT/USD"]
[270, {"a": [["11672.30000", "2.00570155", "1596666714.314843"]], "c": "2772796335"}, "book-100", "XBT/USD"]
[270, {"b": [["11616.10000", "0.00000000", "1596666714.468133"], ["11590.90000", "2.50315283", "1596666703.117862", "r"]], "c": "2772796335"}, "book-100", "XBT/USD"]
[270, {"a": [["11650.20000", "0.00000000", "1596666714.533293"], ["11695.10000", "0.35368913", "1596666684.533099", "r"]], "c": "303649582"}, "book-100", "XBT/USD"]
[270, {"b": [["11628.80000", "3.21335315", "1596666714.543782"]], "c": "303649582"}, "book-100", "XBT/USD"]
[270, {"b": [["11641.00000", "0.00000000", "1596666714.585510"], ["11590.90000", "2.50315283", "1596666703.117862", "r"]], "c": "303649582"}, "book-100", "XBT/USD"]
[270, {"a": [["11659.90000", "0.00000000", "1596666714.657037"], ["11696.80000", "1.98460791", "1596666708.392556", "r"]], "c": "303649582"}, "book-100", "XBT/USD"]
[270, {"b": [["11641.10000", "1.35373608", "1596666714.670927"]], "c": "303649582"}, "book-100", "XBT/USD"]
[270, {"a": [["11650.30000", "0.00000000", "1596666714.684807"], ["11698.00000", "6.50000000", "1596665849.372318", "r"]], "c": "515395063"}, "book-100", "XBT/USD"]
[270, {"a": [["11650.30000", "0.00586961", "1596666714.701169"]], "c": "4084086308"}, "book-100", "XBT/USD"]
[270, {"b": [["11643.60000", "0.01493485", "1596666714.778809"]], "c": "4084086308"}, "book-100", "XBT/USD"]
[270, {"a": [["11655.60000", "0.07467434", "1596666714.835017"]], "c": "4084086308"}, "book-100", "XBT/USD"]
[270, {"b": [["11638.50000", "0.07467434", "1596666714.835334"]], "c": "4084086308"}, "book-100", "XBT/USD"]
[270, {"b": [["11621.90000", "0.00000000", "1596666714.853454"], ["11592.70000", "3.55768345", "1596666703.677696", "r"]], "c": "4084086308"}, "book-100", "XBT/USD"]
[270, {"b": [["11634.90000", "0.17921850", "1596666714.895118"]], "c": "4084086308"}, "book-100", "XBT/USD"]
[270, {"a": [["11657.10000", "0.17921993", "1596666714.951039"]], "c": "4084086308"}, "book-100", "XBT/USD"]
[270, {"a": [["11650.40000", "0.00000000", "1596666715.008310"], ["11695.10000", "0.35368913", "1596666684.533099", "r"]], "c": "2109739689"}, "book-100", "XBT/USD"]
[270, {"a": [["11655.00000", "0.01493485", "1596666715.017631"]], "c": "2109739689"}, "book-100", "XBT/USD"]
[270, {"a": [["11654.50000", "0.64373378", "1596666715.064427"]], "c": "2109739689"}, "book-100", "XBT/USD"]
[270, {"b": [["11641.10000", "0.00000000", "1596666715.112282"], ["11592.70000", "3.55768345", "1596666703.677696", "r"]], "c": "2109739689"}, "book-100", "XBT/USD"]
[270, {"b": [["11645.70000", "0.00000000", "1596666715.144848"], ["11591.20000", "1.06000000", "1596666709.000103", "r"]], "c": "1619372935"}, "book-100", "XBT/USD"]
[270, {"b": [["11641.20000", "1.33613722", "1596666715.197999"]], "c": "1619372935"}, "book-100", "XBT/USD"]
[270, {"a": [["11653.00000", "0.00000000", "1596666715.213922"], ["11694.10000", "20.00000000", "1596666705.854859", "r"]], "c": "252545351"}, "book-100", "XBT/USD"]
[270, {"a": [["11684.10000", "7.07489469", "1596666715.237470"]], "c": "252545351"}, "book-100", "XBT/USD"]
[270, {"b": [["11643.60000", "0.00000000", "1596666715.253889"], ["11591.20000", "1.06000000", "1596666709.000103", "r"]], "c": "278180262"}, "book-100", "XBT/USD"]
[270, {"b": [["11646.60000", "0.25000000", "1596666715.291543"]], "c": "303072228"}, "book-100", "XBT/USD"]
[270, {"a": [["11653.60000", "0.41352978", "1596666715.356599"]], "c": "1141528311"}, "book-100", "XBT/USD"]
[270, {"b": [["11613.00000", "0.17085000", "1596666715.414024"]], "c": "1141528311"}, "book-100", "XBT/USD"]
[270, {"a": [["11659.70000", "0.47921527", "1596666715.568726"]], "c": "1141528311"}, "book-100", "XBT/USD"]
[270, {"a": [["11673.90000", "0.59585541", "1596666715.570314"]], "c": "1141528311"}, "book-100", "XBT/USD"]
[270, {"a": [["11667.80000", "0.00438186", "1596666715.596404"]], "c": "1141528311"}, "book-100", "XBT/USD"]
[270, {"b": [["11641.20000", "0.00000000", "1596666715.617119"], ["11592.70000", "3.55768345", "1596666703.677696", "r"]], "c": "1141528311"}, "book-100", "XBT/USD"]
[270, {"a": [["11652.70000", "0.00000000", "1596666715.676284"], ["11692.30000", "8.50000000", "1596666502.813701", "r"]], "c": "1772324001"}, "book-100", "XBT/USD"]
[270, {"b": [["11592.80000", "0.01287675", "1596666715.683151"]], "c": "1772324001"}, "book-100", "XBT/USD"]
[270, {"b": [["11630.40000", "0.04676795", "1596666715.683281"]], "c": "1772324001"}, "book-100", "XBT/USD"]
[270, {"b": [["11645.20000", "0.00000000", "1596666715.694819"], ["11592.70000", "3.55768345", "1596666703.677696", "r"]], "c": "3563293606"}, "book-100", "XBT/USD"]
[270, {"b": [["11641.30000", "1.39721442", "1596666715.717070"]], "c": "3563293606"}, "book-100", "XBT/USD"]
[270, {"a": [["11680.30000", "0.05295093", "1596666715.724456"]], "c": "3563293606"}, "book-100", "XBT/USD"]
[270, {"a": [["11651.60000", "6.04375199", "1596666715.774706"]], "c": "3519592177"}, "book-100", "XBT/USD"]
[270, {"a": [["11654.80000", "0.00000000", "1596666715.777473"], ["11692.30000", "8.50000000", "1596666502.813701", "r"]], "c": "3519592177"}, "book-100", "XBT/USD"]
[270, {"b": [["11636.60000", "0.00000000", "1596666715.959272"], ["11592.70000", "3.55768345", "1596666703.677696", "r"]], "c": "3519592177"}, "book-100", "XBT/USD"]
[270, {"b": [["11634.60000", "0.00000000", "1596666716.082005"], ["11591.20000", "1.06000000", "1596666709.000103", "r"]], "c": "3519592177"}, "book-100", "XBT/USD"]
[270, {"b": [["11641.30000", "0.00000000", "1596666716.131053"], ["11590.90000", "2.50315283", "1596666703.117862", "r"]], "c": "3519592177"}, "book-100", "XBT/USD"]
[270, {"b": [["11630.40000", "0.04227863", "1596666716.133762"]], "c": "3519592177"}, "book-100", "XBT/USD"]
[270, {"a": [["11682.70000", "0.00000000", "1596666716.271179"], ["11692.70000", "1.75400000", "1596666164.005133", "r"]], "c": "3519592177"}, "book-100", "XBT/USD"]
[270, {"b": [["11636.30000", "0.04480126", "1596666716.361700"]], "c": "3519592177"}, "book-100", "XBT/USD"]
[270, {"b": [["11623.60000", "0.00000000", "1596666716.363573"], ["11590.90000", "2.50315283", "1596666703.117862", "r"]], "c": "3519592177"}, "book-100", "XBT/USD"]
[270, {"b": [["11603.20000", "0.00000000", "1596666716.366795"], ["11590.10000", "1.51500000", "1596666649.220608", "r"]], "c": "3519592177"}, "book-100", "XBT/USD"]
[270, {"a": [["11673.90000", "0.00000000", "1596666716.372421"], ["11693.30000", "0.48410000", "1596666703.085185", "r"]], "c": "3519592177"}, "book-100", "XBT/USD"]
[270, {"b": [["11617.90000", "0.00000000", "1596666716.372944"], ["11589.90000", "6.90000000", "1596666166.290818", "r"]], "c": "3519592177"}, "book-100", "XBT/USD"]
[270, {"b": [["11604.90000", "0.00000000", "1596666716.470813"], ["11588.60000", "0.75800000", "1596666599.475365", "r"]], "c": "3519592177"}, "book-100", "XBT/USD"]
[270, {"a": [["11669.90000", "6.75275622", "1596666716.558372"]], "c": "3519592177"}, "book-100", "XBT/USD"]
[270, {"b": [["11640.00000", "0.30000000", "1596666716.715198"]], "c": "3519592177"}, "book-100", "XBT/USD"]
[270, {"b": [["11634.10000", "0.00000000", "1596666716.775703"], ["11586.20000", "3.00500211", "1596666626.428727", "r"]], "c": "3519592177"}, "book-100", "XBT/USD"]
[270, {"b": [["11635.80000", "0.13440451", "1596666716.995817"]], "c": "3519592177"}, "book-100", "XBT/USD"]
[270, {"b": [["11644.20000", "0.04250000", "1596666717.122867"]], "c": "546204355"}, "book-100", "XBT/USD"]
[270, {"a": [["11653.50000", "0.04051069", "1596666717.124785"]], "c": "3298910545"}, "book-100", "XBT/USD"]
[270, {"b": [["11642.00000", "1.30852700", "1596666717.181890"]], "c": "3298910545"}, "book-100", "XBT/USD"]
[270, {"b": [["11635.40000", "3.76167323", "1596666717.188147"]], "c": "3298910545"}, "book-100", "XBT/USD"]
[270, {"b": [["11606.80000", "3.55330063", "1596666717.199867"]], "c": "3298910545"}, "book-100", "XBT/USD"]
[270, {"b": [["11608.60000", "0.90430740", "1596666717.268867"]], "c": "3298910545"}, "book-100", "XBT/USD"]
[270, {"b": [["11626.60000", "0.33981985", "1596666717.287552"]], "c": "3298910545"}, "book-100", "XBT/USD"]
[270, {"b": [["11620.90000", "2.15466747", "1596666717.293289"]], "c": "3298910545"}, "book-100", "XBT/USD"]
[270, {"b": [["11620.30000", "0.00000000", "1596666717.305551"], ["11591.20000", "1.06000000", "1596666709.000103", "r"]], "c": "3298910545"}, "book-100", "XBT/USD"]
[270, {"a": [["11660.90000", "1.10150658", "1596666717.569041"]], "c": "3298910545"}, "book-100", "XBT/USD"]
[270, {"a": [["11683.10000", "0.89688547", "1596666717.606671"]], "c": "3298910545"}, "book-100", "XBT/USD"]
[270, {"a": [["11684.50000", "10.86189696", "1596666717.659862"]], "c": "3298910545"}, "book-100", "XBT/USD"]
[270, {"a": [["11653.60000", "0.00000000", "1596666717.702183"], ["11693.30000", "0.48410000", "1596666703.085185", "r"]], "c": "2461774914"}, "book-100", "XBT/USD"]
[270, {"b": [["11623.20000", "0.71383044", "1596666717.738599"]], "c": "2461774914"}, "book-100", "XBT/USD"]
[270, {"a": [["11669.90000", "6.19544473", "1596666717.831660"]], "c": "2461774914"}, "book-100", "XBT/USD"]
[270, {"a": [["11659.70000", "0.00000000", "1596666717.832302"], ["11693.70000", "1.16987239", "1596666701.085240", "r"]], "c": "2461774914"}, "book-100", "XBT/USD"]
[270, {"b": [["11640.20000", "0.00000000", "1596666717.854165"], ["11591.20000", "1.06000000", "1596666709.000103", "r"]], "c": "2461774914"}, "book-100", "XBT/USD"]
[270, {"a": [["11654.10000", "0.41352978", "1596666717.854713"]], "c": "3839258898"}, "book-100", "XBT/USD"]
[270, {"b": [["11621.90000", "2.74000000", "1596666718.096842"]], "c": "3839258898"}, "book-100", "XBT/USD"]
[270, {"b": [["11625.00000", "0.25000000", "1596666718.166274"]], "c": "3839258898"}, "book-100", "XBT/USD"]
[270, {"b": [["11646.60000", "0.00000000", "1596666718.166664"], ["11592.70000", "3.55768345", "1596666703.677696", "r"]], "c": "4152550318"}, "book-100", "XBT/USD"]
[270, {"a": [["11650.70000", "0.00000000", "1596666718.202705"], ["11693.70000", "1.16987239", "1596666701.085240", "r"]], "c": "2225396156"}, "book-100", "XBT/USD"]
[270, {"a": [["11657.50000", "1.10000000", "1596666718.311889"]], "c": "2225396156"}, "book-100", "XBT/USD"]
[270, {"b": [["11647.10000", "0.25000000", "1596666718.317867"]], "c": "1667546322"}, "book-100", "XBT/USD"]
[270, {"a": [["11651.50000", "0.00586901", "1596666718.332120"]], "c": "359708481"}, "book-100", "XBT/USD"]
[270, {"a": [["11650.30000", "0.00000000", "1596666718.332290"], ["11693.30000", "0.48410000", "1596666703.085185", "r"]], "c": "3635388959"}, "book-100", "XBT/USD"]
[270, {"a": [["11652.10000", "0.42669541", "1596666718.426232"]], "c": "3504628656"}, "book-100", "XBT/USD"]
[270, {"a": [["11651.60000", "5.78500000", "1596666718.838975"]], "c": "3727090302"}, "book-100", "XBT/USD"]
[270, {"a": [["11652.00000", "0.25874995", "1596666718.937866"]], "c": "387110230"}, "book-100", "XBT/USD"]
[270, {"a": [["11651.40000", "0.58139158", "1596666719.290887"]], "c": "2276290892"}, "book-100", "XBT/USD"]
[270, {"a": [["11658.70000", "0.09700000", "1596666719.368500"]], "c": "2276290892"}, "book-100", "XBT/USD"]
[270, {"a": [["11652.00000", "0.00000000", "1596666719.412770"], ["11692.30000", "8.50000000", "1596666502.813701", "r"]], "c": "381202084"}, "book-100", "XBT/USD"]
[270, {"a": [["11651.50000", "0.00000000", "1596666719.420051"], ["11692.70000", "1.75400000", "1596666164.005133", "r"]], "c": "3089504015"}, "book-100", "XBT/USD"]
[270, {"a": [["11651.30000", "0.00586911", "1596666719.432942"]], "c": "1181918072"}, "book-100", "XBT/USD"]
[270, {"a": [["11652.70000", "0.25873269", "1596666719.433332"]], "c": "3917385266"}, "book-100", "XBT/USD"]
[270, {"b": [["11592.80000", "0.00000000", "1596666719.512166"], ["11592.70000", "3.55768345", "1596666703.677696", "r"]], "c": "3917385266"}, "book-100", "XBT/USD"]
[270, {"a": [["11661.40000", "0.00000000", "1596666719.584527"], ["11692.30000", "8.50000000", "1596666502.813701", "r"]], "c": "3917385266"}, "book-100", "XBT/USD"]
[270, {"a": [["11688.70000", "0.30000000", "1596666720.227548"]], "c": "3917385266"}, "book-100", "XBT/USD"]
[270, {"a": [["11663.20000", "0.68700326", "1596666720.241482"]], "c": "3917385266"}, "book-100", "XBT/USD"]
[270, {"b": [["11647.10000", "0.00000000", "1596666720.245381"], ["11591.20000", "1.06000000", "1596666709.000103", "r"]], "c": "4217361831"}, "book-100", "XBT/USD"]
[270, {"b": [["11599.20000", "0.75006327", "1596666720.247531"]], "c": "4217361831"}, "book-100", "XBT/USD"]
[270, {"a": [["11654.10000", "0.00000000", "1596666720.249955"], ["11692.10000", "4.49523792", "1596666702.300008", "r"]], "c": "4217361831"}, "book-100", "XBT/USD"]
[270, {"a": [["11671.40000", "0.75006327", "1596666720.253810"]], "c": "4217361831"}, "book-100", "XBT/USD"]
[270, {"a": [["11653.90000", "0.00000000", "1596666720.284628"], ["11692.10000", "4.49523792", "1596666702.300008", "r"]], "c": "4217361831"}, "book-100", "XBT/USD"]
[270, {"b": [["11600.00000", "0.02931034", "1596666720.289823"]], "c": "4217361831"}, "book-100", "XBT/USD"]
[270, {"a": [["11668.10000", "0.85827547", "1596666720.339254"]], "c": "4217361831"}, "book-100", "XBT/USD"]
[270, {"a": [["11670.30000", "1.79453383", "1596666720.362496"]], "c": "4217361831"}, "book-100", "XBT/USD"]
[270, {"b": [["11646.20000", "0.67900000", "1596666720.481427"]], "c": "538610092"}, "book-100", "XBT/USD"]
[270, {"a": [["11651.40000", "0.00000000", "1596666720.574839"], ["11692.10000", "4.49523792", "1596666702.300008", "r"]], "c": "1488243291"}, "book-100", "XBT/USD"]
[270, {"b": [["11607.00000", "0.17085000", "1596666720.750083"]], "c": "1488243291"}, "book-100", "XBT/USD"]
[270, {"a": [["11665.00000", "4.04806000", "1596666720.823222"]], "c": "1488243291"}, "book-100", "XBT/USD"]
[270, {"a": [["11653.30000", "0.41352978", "1596666720.848828"]], "c": "1865425824"}, "book-100", "XBT/USD"]
[270, {"a": [["11651.20000", "0.40260116", "1596666720.891598"]], "c": "274488212"}, "book-100", "XBT/USD"]
[270, {"b": [["11598.60000", "2.29920000", "1596666720.945552"]], "c": "274488212"}, "book-100", "XBT/USD"]
[270, {"a": [["11651.30000", "0.00000000", "1596666721.066926"], ["11691.90000", "0.89806591", "1596666649.630348", "r"]], "c": "844828945"}, "book-100", "XBT/USD"]
[270, {"a": [["11651.20000", "0.00000000", "1596666721.146771"], ["11692.10000", "4.49523792", "1596666702.300008", "r"]], "c": "4234895756"}, "book-100", "XBT/USD"]
[270, {"a": [["11651.10000", "0.00586921", "1596666721.148954"]], "c": "3578281070"}, "book-100", "XBT/USD"]
[270, {"a": [["11660.90000", "0.99307308", "1596666721.170818"]], "c": "3578281070"}, "book-100", "XBT/USD"]
[270, {"b": [["11605.70000", "0.00000000", "1596666721.173028"], ["11592.90000", "0.80800000", "1596666471.264849", "r"]], "c": "3578281070"}, "book-100", "XBT/USD"]
[270, {"b": [["11623.20000", "0.00000000", "1596666721.175064"], ["11592.70000", "3.55768345", "1596666703.677696", "r"]], "c": "3578281070"}, "book-100", "XBT/USD"]
[270, {"b": [["11626.60000", "0.00000000", "1596666721.176372"], ["11591.20000", "1.06000000", "1596666709.000103", "r"]], "c": "3578281070"}, "book-100", "XBT/USD"]
[270, {"b": [["11612.20000", "3.55170914", "1596666721.178840"]], "c": "3578281070"}, "book-100", "XBT/USD"]
[270, {"b": [["11610.30000", "0.00000000", "1596666721.190104"], ["11590.90000", "2.50315283", "1596666703.117862", "r"]], "c": "3578281070"}, "book-100", "XBT/USD"]
[270, {"b": [["11592.70000", "0.00000000", "1596666721.190464"], ["11590.10000", "1.51500000", "1596666649.220608", "r"]], "c": "3578281070"}, "book-100", "XBT/USD"]
[270, {"b": [["11596.80000", "0.00000000", "1596666721.190533"], ["11589.90000", "6.90000000", "1596666166.290818", "r"]], "c": "3578281070"}, "book-100", "XBT/USD"]
[270, {"a": [["11661.70000", "0.00000000", "1596666721.190907"], ["11692.10000", "4.49523792", "1596666702.300008", "r"]], "c": "3578281070"}, "book-100", "XBT/USD"]
[270, {"b": [["11597.00000", "0.00000000", "1596666721.193637"], ["11588.60000", "0.75800000", "1596666599.475365", "r"]], "c": "3578281070"}, "book-100", "XBT/USD"]
[270, {"b": [["11645.40000", "0.00000000", "1596666721.202147"], ["11586.20000", "3.00500211", "1596666626.428727", "r"]], "c": "655011537"}, "book-100", "XBT/USD"]
[270, {"b": [["11613.70000", "0.00000000", "1596666721.207708"], ["11586.00000", "2.83070444", "1596666641.836792", "r"]], "c": "655011537"}, "book-100", "XBT/USD"]
[270, {"b": [["11627.00000", "0.00000000", "1596666721.210695"], ["11585.50000", "0.00509766", "1596666166.036585", "r"]], "c": "655011537"}, "book-100", "XBT/USD"]
[270, {"b": [["11646.20000", "0.25000000", "1596666721.245033"]], "c": "3606126317"}, "book-100", "XBT/USD"]
[270, {"a": [["11653.30000", "0.00000000", "1596666721.285137"], ["11692.30000", "8.50000000", "1596666502.813701", "r"]], "c": "2317554950"}, "book-100", "XBT/USD"]
[270, {"b": [["11646.20000", "0.00000000", "1596666721.285867"], ["11585.00000", "7.70000000", "1596666429.743667", "r"]], "c": "2614446067"}, "book-100", "XBT/USD"]
[270, {"b": [["11609.20000", "0.57663829", "1596666721.392843"]], "c": "2614446067"}, "book-100", "XBT/USD"]
[270, {"b": [["11624.50000", "0.71375662", "1596666721.410657"]], "c": "2614446067"}, "book-100", "XBT/USD"]
[270, {"a": [["11662.90000", "0.33876504", "1596666721.411557"]], "c": "2614446067"}, "book-100", "XBT/USD"]
[270, {"b": [["11616.40000", "1.80264185", "1596666721.421307"]], "c": "2614446067"}, "book-100", "XBT/USD"]
[270, {"b": [["11627.90000", "0.33978472", "1596666721.435619"]], "c": "2614446067"}, "book-100", "XBT/USD"]
[270, {"b": [["11597.60000", "3.55614984", "1596666721.465658"]], "c": "2614446067"}, "book-100", "XBT/USD"]
[270, {"b": [["11647.10000", "0.42900000", "1596666721.490934"]], "c": "3473939790"}, "book-100", "XBT/USD"]
[270, {"b": [["11592.20000", "2.33146098", "1596666721.550957"]], "c": "3473939790"}, "book-100", "XBT/USD"]
[270, {"b": [["11615.90000", "0.25056769", "1596666721.568588"]], "c": "3473939790"}, "book-100", "XBT/USD"]
[270, {"b": [["11612.40000", "0.35090050", "1596666721.568700"]], "c": "3473939790"}, "book-100", "XBT/USD"]
[270, {"b": [["11600.90000", "1.93791004", "1596666721.568795"]], "c": "3473939790"}, "book-100", "XBT/USD"]
[270, {"b": [["11647.10000", "0.67900000", "1596666721.671120"]], "c": "131975324"}, "book-100", "XBT/USD"]
[270, {"a": [["11654.20000", "0.63049665", "1596666721.674184"]], "c": "1547640625"}, "book-100", "XBT/USD"]
[270, {"a": [["11652.10000", "0.00000000", "1596666721.689117"], ["11692.30000", "8.50000000", "1596666502.813701", "r"]], "c": "827967717"}, "book-100", "XBT/USD"]
[270, {"b": [["11601.70000", "0.90487256", "1596666721.764427"]], "c": "827967717"}, "book-100", "XBT/USD"]
[270, {"b": [["11618.20000", "0.00000000", "1596666721.789329"], ["11592.20000", "2.33146098", "1596666721.550957", "r"]], "c": "827967717"}, "book-100", "XBT/USD"]
[270, {"b": [["11642.80000", "0.00000000", "1596666721.802232"], ["11591.20000", "1.06000000", "1596666709.000103", "r"]], "c": "2871262218"}, "book-100", "XBT/USD"]
[270, {"a": [["11658.80000", "0.00000000", "1596666721.803738"], ["11692.70000", "1.75400000", "1596666164.005133", "r"]], "c": "2871262218"}, "book-100", "XBT/USD"]
[270, {"b": [["11638.50000", "0.00000000", "1596666721.923934"], ["11590.90000", "2.50315283", "1596666703.117862", "r"]], "c": "2871262218"}, "book-100", "XBT/USD"]
[270, {"a": [["11652.50000", "0.42783965", "1596666721.961108"]], "c": "3307268308"}, "book-100", "XBT/USD"]
[270, {"b": [["11634.90000", "0.00000000", "1596666721.999417"], ["11590.10000", "1.51500000", "1596666649.220608", "r"]], "c": "3307268308"}, "book-100", "XBT/USD"]
[270, {"b": [["11633.50000", "0.00000000", "1596666722.023837"], ["11589.90000", "6.90000000", "1596666166.290818", "r"]], "c": "3307268308"}, "book-100", "XBT/USD"]
[270, {"b": [["11644.20000", "0.12500000", "1596666722.039829"]], "c": "4208455155"}, "book-100", "XBT/USD"]
[270, {"a": [["11683.30000", "0.08250000", "1596666722.043917"]], "c": "4208455155"}, "book-100", "XBT/USD"]
[270, {"a": [["11652.70000", "0.00000000", "1596666722.108076"], ["11692.30000", "8.50000000", "1596666502.813701", "r"]], "c": "2333702810"}, "book-100", "XBT/USD"]
[270, {"a": [["11652.40000", "0.25873469", "1596666722.200497"]], "c": "2029577366"}, "book-100", "XBT/USD"]
[270, {"b": [["11632.70000", "0.49888594", "1596666722.200733"]], "c": "2029577366"}, "book-100", "XBT/USD"]
[270, {"a": [["11662.90000", "0.00000000", "1596666722.312823"], ["11692.30000", "8.50000000", "1596666502.813701", "r"]], "c": "2029577366"}, "book-100", "XBT/USD"]
[270, {"b": [["11627.90000", "0.00000000", "1596666722.376751"], ["11588.60000", "0.75800000", "1596666599.475365", "r"]], "c": "2029577366"}, "book-100", "XBT/USD"]
[270, {"b": [["11626.40000", "0.33982856", "1596666722.697861"]], "c": "2029577366"}, "book-100", "XBT/USD"]
[270, {"a": [["11661.30000", "0.33881152", "1596666722.702176"]], "c": "2029577366"}, "book-100", "XBT/USD"]
[270, {"b": [["11630.40000", "0.04677025", "1596666722.714236"]], "c": "2029577366"}, "book-100", "XBT/USD"]
[270, {"b": [["11592.30000", "0.01287631", "1596666722.714513"]], "c": "2029577366"}, "book-100", "XBT/USD"]
[270, {"b": [["11616.90000", "0.49800000", "1596666722.959152"]], "c": "2029577366"}, "book-100", "XBT/USD"]
[270, {"b": [["11645.40000", "1.70900000", "1596666723.077657"]], "c": "3700245448"}, "book-100", "XBT/USD"]
[270, {"a": [["11653.80000", "2.20231091", "1596666723.093071"]], "c": "2747369455"}, "book-100", "XBT/USD"]
[270, {"b": [["11648.40000", "0.64370427", "1596666723.217968"]], "c": "2482176332"}, "book-100", "XBT/USD"]
[270, {"b": [["11644.70000", "0.85826664", "1596666723.237580"]], "c": "3698134317"}, "book-100", "XBT/USD"]
[270, {"b": [["11598.00000", "0.53460245", "1596666723.277921"]], "c": "3698134317"}, "book-100", "XBT/USD"]
[270, {"b": [["11648.40000", "0.86710427", "1596666723.301770"]], "c": "4074628618"}, "book-100", "XBT/USD"]
[270, {"a": [["11651.10000", "0.00000000", "1596666723.351232"], ["11692.30000", "8.50000000", "1596666502.813701", "r"]], "c": "306432228"}, "book-100", "XBT/USD"]
[270, {"a": [["11653.70000", "0.02477214", "1596666723.368777"]], "c": "2467369242"}, "book-100", "XBT/USD"]
[270, {"b": [["11648.50000", "0.19500000", "1596666723.385421"]], "c": "2858523749"}, "book-100", "XBT/USD"]
[270, {"b": [["11636.30000", "0.00000000", "1596666723.395702"], ["11592.30000", "0.01287631", "1596666722.714513", "r"]], "c": "2858523749"}, "book-100", "XBT/USD"]
[270, {"a": [["11651.60000", "1.50000000", "1596666723.529426"]], "c": "1420572869"}, "book-100", "XBT/USD"]
[270, {"b": [["11647.50000", "0.32030094", "1596666723.571117"]], "c": "1425058479"}, "book-100", "XBT/USD"]
[270, {"b": [["11637.40000", "0.04479924", "1596666723.578494"]], "c": "1425058479"}, "book-100", "XBT/USD"]
[270, {"b": [["11642.00000", "0.00000000", "1596666723.593305"], ["11592.30000", "0.01287631", "1596666722.714513", "r"]], "c": "1425058479"}, "book-100", "XBT/USD"]
[270, {"a": [["11651.50000", "0.55969327", "1596666723.836459"]], "c": "1936351963"}, "book-100", "XBT/USD"]
[270, {"a": [["11652.80000", "4.38800000", "1596666723.854722"]], "c": "850227362"}, "book-100", "XBT/USD"]
[270, {"a": [["11657.10000", "0.00000000", "1596666723.947476"], ["11692.10000", "4.49523792", "1596666702.300008", "r"]], "c": "850227362"}, "book-100", "XBT/USD"]
[270, {"a": [["11687.20000", "2.00000000", "1596666724.003775"]], "c": "850227362"}, "book-100", "XBT/USD"]
[270, {"b": [["11635.80000", "0.00000000", "1596666724.086682"], ["11592.20000", "2.33146098", "1596666721.550957", "r"]], "c": "850227362"}, "book-100", "XBT/USD"]
[270, {"a": [["11652.40000", "0.00000000", "1596666724.151088"], ["11692.10000", "4.49523792", "1596666702.300008", "r"]], "c": "3925843969"}, "book-100", "XBT/USD"]
[270, {"a": [["11652.80000", "4.64672629", "1596666724.180925"]], "c": "3389439096"}, "book-100", "XBT/USD"]
[270, {"a": [["11687.80000", "0.00000000", "1596666724.259534"], ["11692.30000", "8.50000000", "1596666502.813701", "r"]], "c": "3389439096"}, "book-100", "XBT/USD"]
[270, {"a": [["11689.10000", "2.25111754", "1596666724.261076"]], "c": "3389439096"}, "book-100", "XBT/USD"]
[270, {"b": [["11636.80000", "0.13439749", "1596666724.287068"]], "c": "3389439096"}, "book-100", "XBT/USD"]
[270, {"b": [["11636.90000", "1.00000000", "1596666724.327130"]], "c": "3389439096"}, "book-100", "XBT/USD"]
[270, {"b": [["11636.90000", "0.00000000", "1596666724.333608"], ["11592.20000", "2.33146098", "1596666721.550957", "r"]], "c": "3389439096"}, "book-100", "XBT/USD"]
[270, {"b": [["11643.80000", "0.43900000", "1596666724.340348"]], "c": "3389439096"}, "book-100", "XBT/USD"]
[270, {"b": [["11642.80000", "1.31472655", "1596666724.408168"]], "c": "3389439096"}, "book-100", "XBT/USD"]
[270, {"a": [["11673.90000", "0.64494001", "1596666724.423498"]], "c": "3389439096"}, "book-100", "XBT/USD"]
[270, {"a": [["11662.10000", "0.43001321", "1596666724.424325"]], "c": "3389439096"}, "book-100", "XBT/USD"]
[270, {"b": [["11643.80000", "1.43900000", "1596666724.561895"]], "c": "3389439096"}, "book-100", "XBT/USD"]
[270, {"b": [["11641.30000", "1.70700000", "1596666724.708932"]], "c": "3389439096"}, "book-100", "XBT/USD"]
[270, {"a": [["11670.20000", "3.20200103", "1596666724.852487"]], "c": "3389439096"}, "book-100", "XBT/USD"]
[270, {"a": [["11661.00000", "0.43900000", "1596666724.898570"]], "c": "3389439096"}, "book-100", "XBT/USD"]
[270, {"b": [["11645.40000", "0.00000000", "1596666725.212354"], ["11592.90000", "0.80800000", "1596666471.264849", "r"]], "c": "818117154"}, "book-100", "XBT/USD"]
[270, {"a": [["11662.10000", "0.00000000", "1596666725.213020"], ["11691.60000", "2.80491857", "1596666648.819519", "r"]], "c": "818117154"}, "book-100", "XBT/USD"]
[270, {"a": [["11653.80000", "0.49031091", "1596666725.297739"]], "c": "178466918"}, "book-100", "XBT/USD"]
[270, {"a": [["11658.80000", "0.46262138", "1596666725.402213"]], "c": "178466918"}, "book-100", "XBT/USD"]
[270, {"b": [["11634.90000", "1.99460000", "1596666725.445088"]], "c": "178466918"}, "book-100", "XBT/USD"]
[270, {"a": [["11662.40000", "0.63643000", "1596666725.556851"]], "c": "178466918"}, "book-100", "XBT/USD"]
[270, {"b": [["11635.00000", "2.00000000", "1596666725.594608"]], "c": "178466918"}, "book-100", "XBT/USD"]
[270, {"a": [["11652.40000", "0.02477490", "1596666725.753834"]], "c": "1010151507"}, "book-100", "XBT/USD"]
[270, {"a": [["11653.70000", "0.00000000", "1596666725.757328"], ["11690.30000", "0.75800000", "1596666706.971928", "r"]], "c": "1979456688"}, "book-100", "XBT/USD"]
[270, {"a": [["11652.80000", "4.38800000", "1596666726.265110"]], "c": "986017689"}, "book-100", "XBT/USD"]
[270, {"b": [["11599.30000", "0.75003705", "1596666726.304546"]], "c": "986017689"}, "book-100", "XBT/USD"]
[270, {"a": [["11671.60000", "1.32361180", "1596666726.310962"]], "c": "986017689"}, "book-100", "XBT/USD"]
[270, {"b": [["11599.20000", "0.00000000", "1596666726.313520"], ["11594.30000", "2.01919334", "1596666706.140722", "r"]], "c": "986017689"}, "book-100", "XBT/USD"]
[270, {"a": [["11652.70000", "0.25872880", "1596666726.359788"]], "c": "3329260334"}, "book-100", "XBT/USD"]
[270, {"a": [["11655.60000", "0.00000000", "1596666726.484021"], ["11690.30000", "0.75800000", "1596666706.971928", "r"]], "c": "3329260334"}, "book-100", "XBT/USD"]
[270, {"a": [["11671.40000", "0.00000000", "1596666726.509170"], ["11691.30000", "2.00311243", "1596666619.337977", "r"]], "c": "3329260334"}, "book-100", "XBT/USD"]
[270, {"b": [["11613.40000", "0.00000000", "1596666726.529168"], ["11594.10000", "0.48610000", "1596666616.025674", "r"]], "c": "3329260334"}, "book-100", "XBT/USD"]
[270, {"b": [["11607.10000", "0.00000000", "1596666726.547960"], ["11592.90000", "0.80800000", "1596666471.264849", "r"]], "c": "3329260334"}, "book-100", "XBT/USD"]
[270, {"b": [["11599.50000", "0.00000000", "1596666726.552025"], ["11592.30000", "0.01287631", "1596666722.714513", "r"]], "c": "3329260334"}, "book-100", "XBT/USD"]
[270, {"b": [["11632.70000", "0.00000000", "1596666726.568576"], ["11592.20000", "2.33146098", "1596666721.550957", "r"]], "c": "3329260334"}, "book-100", "XBT/USD"]
[270, {"b": [["11615.90000", "0.00000000", "1596666726.576181"], ["11591.20000", "1.06000000", "1596666709.000103", "r"]], "c": "3329260334"}, "book-100", "XBT/USD"]
[270, {"b": [["11623.30000", "0.00000000", "1596666726.577358"], ["11590.90000", "2.50315283", "1596666703.117862", "r"]], "c": "3329260334"}, "book-100", "XBT/USD"]
[270, {"b": [["11614.00000", "0.00000000", "1596666726.578676"], ["11590.10000", "1.51500000", "1596666649.220608", "r"]], "c": "3329260334"}, "book-100", "XBT/USD"]
[270, {"b": [["11620.90000", "1.42794343", "1596666726.580973"]], "c": "3329260334"}, "book-100", "XBT/USD"]
[270, {"b": [["11599.90000", "0.00000000", "1596666726.585028"], ["11589.90000", "6.90000000", "1596666166.290818", "r"]], "c": "3329260334"}, "book-100", "XBT/USD"]
[270, {"b": [["11612.20000", "0.00000000", "1596666726.621126"], ["11588.60000", "0.75800000", "1596666599.475365", "r"]], "c": "3329260334"}, "book-100", "XBT/USD"]
[270, {"b": [["11616.20000", "0.00000000", "1596666726.622452"], ["11586.20000", "3.00500211", "1596666626.428727", "r"]], "c": "3329260334"}, "book-100", "XBT/USD"]
[270, {"b": [["11612.40000", "0.00000000", "1596666726.623175"], ["11586.00000", "2.83070444", "1596666641.836792", "r"]], "c": "3329260334"}, "book-100", "XBT/USD"]
[270, {"b": [["11612.80000", "0.00000000", "1596666726.632660"], ["11585.50000", "0.00509766", "1596666166.036585", "r"]], "c": "3329260334"}, "book-100", "XBT/USD"]
[270, {"a": [["11665.10000", "0.10342435", "1596666726.669450"]], "c": "3329260334"}, "book-100", "XBT/USD"]
[270, {"b": [["11626.40000", "0.00000000", "1596666726.674605"], ["11585.00000", "7.70000000", "1596666429.743667", "r"]], "c": "3329260334"}, "book-100", "XBT/USD"]
[270, {"b": [["11599.80000", "0.00000000", "1596666726.677481"], ["11583.00000", "0.01000000", "1596666661.045375", "r"]], "c": "3329260334"}, "book-100", "XBT/USD"]
[270, {"a": [["11661.30000", "0.00000000", "1596666726.678864"], ["11691.60000", "2.80491857", "1596666648.819519", "r"]], "c": "3329260334"}, "book-100", "XBT/USD"]
[270, {"b": [["11620.90000", "0.00000000", "1596666726.716235"], ["11582.70000", "0.00199361", "1596666580.634885", "r"]], "c": "3329260334"}, "book-100", "XBT/USD"]
[270, {"b": [["11622.50000", "0.72669112", "1596666726.816205"]], "c": "3329260334"}, "book-100", "XBT/USD"]
[270, {"b": [["11624.80000", "0.10379248", "1596666726.818119"]], "c": "3329260334"}, "book-100", "XBT/USD"]
[270, {"b": [["11605.10000", "1.51794256", "1596666726.820981"]], "c": "3329260334"}, "book-100", "XBT/USD"]
[270, {"a": [["11652.40000", "0.00000000", "1596666726.827106"], ["11691.90000", "0.89806591", "1596666649.630348", "r"]], "c": "517388467"}, "book-100", "XBT/USD"]
[270, {"a": [["11662.10000", "0.05313798", "1596666726.828122"]], "c": "517388467"}, "book-100", "XBT/USD"]
[270, {"b": [["11618.70000", "6.43310331", "1596666726.862981"]], "c": "517388467"}, "book-100", "XBT/USD"]
[270, {"b": [["11613.80000", "0.35085820", "1596666726.891327"]], "c": "517388467"}, "book-100", "XBT/USD"]
[270, {"b": [["11607.70000", "10.39986603", "1596666726.902834"]], "c": "517388467"}, "book-100", "XBT/USD"]
[270, {"b": [["11634.30000", "0.49882341", "1596666726.908374"]], "c": "517388467"}, "book-100", "XBT/USD"]
[270, {"b": [["11619.20000", "1.49841501", "1596666726.908448"]], "c": "517388467"}, "book-100", "XBT/USD"]
[270, {"a": [["11667.20000", "0.00438186", "1596666726.918810"]], "c": "517388467"}, "book-100", "XBT/USD"]
[270, {"b": [["11610.90000", "2.01635862", "1596666726.924449"]], "c": "517388467"}, "book-100", "XBT/USD"]
[270, {"b": [["11613.90000", "3.55115881", "1596666726.956638"]], "c": "517388467"}, "book-100", "XBT/USD"]
[270, {"a": [["11652.80000", "4.28300000", "1596666726.980246"]], "c": "191877776"}, "book-100", "XBT/USD"]
[270, {"b": [["11614.50000", "0.90387533", "1596666726.991971"]], "c": "191877776"}, "book-100", "XBT/USD"]
[270, {"b": [["11618.00000", "0.90360303", "1596666726.996062"]], "c": "191877776"}, "book-100", "XBT/USD"]
[270, {"a": [["11662.10000", "0.00000000", "1596666727.125059"], ["11691.60000", "2.80491857", "1596666648.819519", "r"]], "c": "191877776"}, "book-100", "XBT/USD"]
[270, {"b": [["11604.90000", "1.97465727", "1596666727.127462"]], "c": "191877776"}, "book-100", "XBT/USD"]
[270, {"a": [["11666.30000", "0.71119925", "1596666727.139293"]], "c": "191877776"}, "book-100", "XBT/USD"]
[270, {"a": [["11651.40000", "0.02477703", "1596666727.156950"]], "c": "659176430"}, "book-100", "XBT/USD"]
[270, {"b": [["11622.20000", "1.42779574", "1596666727.158026"]], "c": "659176430"}, "book-100", "XBT/USD"]
[270, {"a": [["11662.90000", "0.33876504", "1596666727.158478"]], "c": "659176430"}, "book-100", "XBT/USD"]
[270, {"b": [["11617.20000", "0.25053965", "1596666727.159995"]], "c": "659176430"}, "book-100", "XBT/USD"]
[270, {"a": [["11667.80000", "0.00000000", "1596666727.160766"], ["11690.30000", "0.75800000", "1596666706.971928", "r"]], "c": "659176430"}, "book-100", "XBT/USD"]
[270, {"b": [["11631.20000", "7.10791062", "1596666727.162610"]], "c": "659176430"}, "book-100", "XBT/USD"]
[270, {"b": [["11627.90000", "0.33978472", "1596666727.162918"]], "c": "659176430"}, "book-100", "XBT/USD"]
[270, {"a": [["11658.20000", "1.70800000", "1596666727.164913"]], "c": "659176430"}, "book-100", "XBT/USD"]
[270, {"a": [["11655.10000", "0.95499436", "1596666727.253360"]], "c": "659176430"}, "book-100", "XBT/USD"]
[270, {"a": [["11667.20000", "0.00000000", "1596666727.353531"], ["11690.30000", "0.75800000", "1596666706.971928", "r"]], "c": "659176430"}, "book-100", "XBT/USD"]
[270, {"a": [["11652.70000", "0.00000000", "1596666727.510738"], ["11691.30000", "2.00311243", "1596666619.337977", "r"]], "c": "3312605475"}, "book-100", "XBT/USD"]
[270, {"a": [["11653.40000", "0.25872265", "1596666727.541637"]], "c": "2831249296"}, "book-100", "XBT/USD"]
[270, {"a": [["11655.00000", "0.00000000", "1596666727.586246"], ["11691.30000", "2.00311243", "1596666619.337977", "r"]], "c": "2831249296"}, "book-100", "XBT/USD"]
[270, {"a": [["11651.40000", "0.00000000", "1596666727.621456"], ["11691.60000", "2.80491857", "1596666648.819519", "r"]], "c": "4263279224"}, "book-100", "XBT/USD"]
[270, {"b": [["11644.20000", "0.08250000", "1596666728.010350"]], "c": "1385380701"}, "book-100", "XBT/USD"]
[270, {"a": [["11653.50000", "0.00000000", "1596666728.012003"], ["11691.90000", "0.89806591", "1596666649.630348", "r"]], "c": "4202138975"}, "book-100", "XBT/USD"]
[270, {"a": [["11651.40000", "0.05313798", "1596666728.138609"]], "c": "502656370"}, "book-100", "XBT/USD"]
[270, {"a": [["11654.40000", "0.04051069", "1596666728.266325"]], "c": "502656370"}, "book-100", "XBT/USD"]
[270, {"a": [["11673.90000", "0.00000000", "1596666728.304224"], ["11691.60000", "2.80491857", "1596666648.819519", "r"]], "c": "502656370"}, "book-100", "XBT/USD"]
[270, {"a": [["11658.80000", "0.00000000", "1596666728.307474"], ["11691.90000", "0.89806591", "1596666649.630348", "r"]], "c": "502656370"}, "book-100", "XBT/USD"]
[270, {"b": [["11645.20000", "0.04250000", "1596666728.391360"]], "c": "286716437"}, "book-100", "XBT/USD"]
[270, {"a": [["11671.60000", "0.57357475", "1596666728.391571"]], "c": "286716437"}, "book-100", "XBT/USD"]
[270, {"b": [["11646.50000", "0.00000000", "1596666728.406757"], ["11595.50000", "7.80858966", "1596666703.441148", "r"]], "c": "2701213658"}, "book-100", "XBT/USD"]
[270, {"b": [["11648.20000", "0.64370408", "1596666728.482089"]], "c": "992716236"}, "book-100", "XBT/USD"]
[270, {"b": [["11645.50000", "0.00000000", "1596666728.494314"], ["11595.50000", "7.80858966", "1596666703.441148", "r"]], "c": "4130443983"}, "book-100", "XBT/USD"]
[270, {"b": [["11645.20000", "4.33150000", "1596666728.753342"]], "c": "359311638"}, "book-100", "XBT/USD"]
[270, {"b": [["11599.30000", "0.00000000", "1596666729.099070"], ["11594.30000", "2.01919334", "1596666706.140722", "r"]], "c": "359311638"}, "book-100", "XBT/USD"]
[270, {"a": [["11654.50000", "0.00000000", "1596666729.234999"], ["11692.10000", "4.49523792", "1596666702.300008", "r"]], "c": "359311638"}, "book-100", "XBT/USD"]
[270, {"b": [["11635.10000", "7.38592874", "1596666730.197730"]], "c": "359311638"}, "book-100", "XBT/USD"]
[270, {"a": [["11689.10000", "0.00000000", "1596666730.341808"], ["11692.30000", "8.50000000", "1596666502.813701", "r"]], "c": "359311638"}, "book-100", "XBT/USD"]
[270, {"a": [["11651.40000", "0.00000000", "1596666730.413094"], ["11692.70000", "1.75400000", "1596666164.005133", "r"]], "c": "858955680"}, "book-100", "XBT/USD"]
[270, {"b": [["11647.20000", "0.22408000", "1596666730.414319"]], "c": "1974688990"}, "book-100", "XBT/USD"]
[270, {"b": [["11630.40000", "0.04227863", "1596666730.554593"]], "c": "1974688990"}, "book-100", "XBT/USD"]
[270, {"a": [["11667.20000", "0.00438186", "1596666730.554965"]], "c": "1974688990"}, "book-100", "XBT/USD"]
[270, {"a": [["11651.40000", "0.02769246", "1596666730.598525"]], "c": "3001377451"}, "book-100", "XBT/USD"]
[270, {"b": [["11637.60000", "0.00258000", "1596666731.095635"]], "c": "3001377451"}, "book-100", "XBT/USD"]
[270, {"b": [["11637.40000", "0.00000000", "1596666731.102071"], ["11594.30000", "2.01919334", "1596666706.140722", "r"]], "c": "3001377451"}, "book-100", "XBT/USD"]
[270, {"b": [["11630.10000", "8.63000000", "1596666731.112184"]], "c": "3001377451"}, "book-100", "XBT/USD"]
[270, {"b": [["11632.60000", "0.73300000", "1596666731.117990"]], "c": "3001377451"}, "book-100", "XBT/USD"]
[270, {"a": [["11677.20000", "0.00000000", "1596666731.118103"], ["11692.30000", "8.50000000", "1596666502.813701", "r"]], "c": "3001377451"}, "book-100", "XBT/USD"]
[270, {"b": [["11648.20000", "0.00000000", "1596666731.127515"], ["11594.30000", "2.01919334", "1596666706.140722", "r"]], "c": "1920572161"}, "book-100", "XBT/USD"]
[270, {"b": [["11645.00000", "0.85824923", "1596666731.217258"]], "c": "2648326134"}, "book-100", "XBT/USD"]
[270, {"b": [["11649.30000", "0.64365129", "1596666731.217487"]], "c": "3271680731"}, "book-100", "XBT/USD"]
[270, {"a": [["11654.20000", "1.27414794", "1596666731.217947"]], "c": "3693271958"}, "book-100", "XBT/USD"]
[270, {"b": [["11649.40000", "0.64368692", "1596666731.218059"]], "c": "2041116327"}, "book-100", "XBT/USD"]
[270, {"a": [["11654.90000", "0.00000000", "1596666731.251522"], ["11692.70000", "1.75400000", "1596666164.005133", "r"]], "c": "2041116327"}, "book-100", "XBT/USD"]
[270, {"a": [["11662.90000", "0.00000000", "1596666731.317073"], ["11693.30000", "0.48410000", "1596666703.085185", "r"]], "c": "2041116327"}, "book-100", "XBT/USD"]
[270, {"b": [["11627.90000", "0.00000000", "1596666731.317516"], ["11596.30000", "19.40000000", "1596666706.107317", "r"]], "c": "2041116327"}, "book-100", "XBT/USD"]
[270, {"b": [["11648.50000", "0.00000000", "1596666731.318061"], ["11595.50000", "7.80858966", "1596666703.441148", "r"]], "c": "1937673187"}, "book-100", "XBT/USD"]
[270, {"a": [["11666.30000", "0.00000000", "1596666731.326732"], ["11693.70000", "1.16987239", "1596666701.085240", "r"]], "c": "1937673187"}, "book-100", "XBT/USD"]
[270, {"b": [["11643.80000", "0.43900000", "1596666731.354134"]], "c": "1937673187"}, "book-100", "XBT/USD"]
[270, {"b": [["11636.80000", "0.00000000", "1596666731.420389"], ["11594.30000", "2.01919334", "1596666706.140722", "r"]], "c": "1937673187"}, "book-100", "XBT/USD"]
[270, {"b": [["11634.30000", "0.87882341", "1596666731.468394"]], "c": "1937673187"}, "book-100", "XBT/USD"]
[270, {"b": [["11602.80000", "0.75800000", "1596666731.483110"]], "c": "1937673187"}, "book-100", "XBT/USD"]
[270, {"a": [["11651.40000", "0.08083044", "1596666731.565089"]], "c": "3910621066"}, "book-100", "XBT/USD"]
[270, {"a": [["11651.40000", "0.05313798", "1596666731.567750"]], "c": "2641520210"}, "book-100", "XBT/USD"]
[270, {"b": [["11616.90000", "0.00000000", "1596666731.588728"], ["11594.30000", "2.01919334", "1596666706.140722", "r"]], "c": "2641520210"}, "book-100", "XBT/USD"]
[270, {"a": [["11656.90000", "1.29856134", "1596666731.995746"]], "c": "2641520210"}, "book-100", "XBT/USD"]
[270, {"b": [["11647.80000", "0.86781000", "1596666732.573686"]], "c": "632324257"}, "book-100", "XBT/USD"]
[270, {"a": [["11658.80000", "0.46856291", "1596666732.576511"]], "c": "632324257"}, "book-100", "XBT/USD"]
[270, {"b": [["11627.70000", "0.33983065", "1596666732.578997"]], "c": "632324257"}, "book-100", "XBT/USD"]
[270, {"a": [["11673.90000", "0.60661297", "1596666732.585102"]], "c": "632324257"}, "book-100", "XBT/USD"]
[270, {"a": [["11664.70000", "0.71138071", "1596666732.594916"]], "c": "632324257"}, "book-100", "XBT/USD"]
[270, {"a": [["11683.30000", "0.00000000", "1596666732.732864"], ["11692.30000", "8.50000000", "1596666502.813701", "r"]], "c": "632324257"}, "book-100", "XBT/USD"]
[270, {"b": [["11644.20000", "0.00000000", "1596666732.750377"], ["11595.50000", "7.80858966", "1596666703.441148", "r"]], "c": "632324257"}, "book-100", "XBT/USD"]
[270, {"a": [["11671.70000", "0.75002868", "1596666732.751148"]], "c": "632324257"}, "book-100", "XBT/USD"]
[270, {"b": [["11599.70000", "0.75902868", "1596666732.754942"]], "c": "632324257"}, "book-100", "XBT/USD"]
[270, {"b": [["11618.20000", "0.49800000", "1596666732.771988"]], "c": "632324257"}, "book-100", "XBT/USD"]
[270, {"a": [["11653.40000", "0.00000000", "1596666732.779206"], ["11692.30000", "8.50000000", "1596666502.813701", "r"]], "c": "3996326498"}, "book-100", "XBT/USD"]
[270, {"a": [["11653.70000", "0.25872095", "1596666732.880004"]], "c": "3013880391"}, "book-100", "XBT/USD"]
[270, {"a": [["11658.80000", "0.00000000", "1596666732.954667"], ["11692.30000", "8.50000000", "1596666502.813701", "r"]], "c": "3013880391"}, "book-100", "XBT/USD"]
[270, {"a": [["11673.90000", "0.00000000", "1596666732.955913"], ["11692.70000", "1.75400000", "1596666164.005133", "r"]], "c": "3013880391"}, "book-100", "XBT/USD"]
[270, {"b": [["11645.20000", "4.41400000", "1596666733.018997"]], "c": "1572613549"}, "book-100", "XBT/USD"]
[270, {"b": [["11630.30000", "0.00000000", "1596666733.061273"], ["11595.50000", "7.80858966", "1596666703.441148", "r"]], "c": "1572613549"}, "book-100", "XBT/USD"]
[270, {"b": [["11630.40000", "0.00000000", "1596666733.388717"], ["11594.30000", "2.01919334", "1596666706.140722", "r"]], "c": "1572613549"}, "book-100", "XBT/USD"]
[270, {"a": [["11662.40000", "0.00000000", "1596666733.393372"], ["11693.30000", "0.48410000", "1596666703.085185", "r"]], "c": "1572613549"}, "book-100", "XBT/USD"]
[270, {"a": [["11661.40000", "0.33884858", "1596666733.393678"]], "c": "1572613549"}, "book-100", "XBT/USD"]
[270, {"a": [["11683.50000", "0.08250000", "1596666733.403233"]], "c": "1572613549"}, "book-100", "XBT/USD"]
[270, {"b": [["11645.20000", "0.12500000", "1596666733.473216"]], "c": "1913874646"}, "book-100", "XBT/USD"]
[270, {"b": [["11647.20000", "4.51308000", "1596666733.486777"]], "c": "453928578"}, "book-100", "XBT/USD"]
[270, {"b": [["11635.10000", "7.42819029", "1596666733.729592"]], "c": "453928578"}, "book-100", "XBT/USD"]
[270, {"b": [["11635.20000", "0.02682839", "1596666733.853968"]], "c": "453928578"}, "book-100", "XBT/USD"]
[270, {"b": [["11635.10000", "7.38592874", "1596666733.854893"]], "c": "453928578"}, "book-100", "XBT/USD"]
[270, {"a": [["11654.20000", "0.63049665", "1596666734.031700"]], "c": "1673260496"}, "book-100", "XBT/USD"]
[270, {"a": [["11652.10000", "0.64368160", "1596666734.089526"]], "c": "2855475098"}, "book-100", "XBT/USD"]
[270, {"b": [["11647.20000", "0.22408000", "1596666734.173175"]], "c": "1149981933"}, "book-100", "XBT/USD"]
[270, {"a": [["11667.20000", "0.00000000", "1596666734.300196"], ["11692.30000", "8.50000000", "1596666502.813701", "r"]], "c": "1149981933"}, "book-100", "XBT/USD"]
[270, {"b": [["11645.20000", "4.40400000", "1596666734.384966"]], "c": "2878515790"}, "book-100", "XBT/USD"]
[270, {"a": [["11652.90000", "0.00000000", "1596666734.611625"], ["11692.70000", "1.75400000", "1596666164.005133", "r"]], "c": "1062206779"}, "book-100", "XBT/USD"]
[270, {"b": [["11649.30000", "0.00000000", "1596666734.620445"], ["11594.30000", "2.01919334", "1596666706.140722", "r"]], "c": "3108658305"}, "book-100", "XBT/USD"]
[270, {"b": [["11635.10000", "7.30000000", "1596666734.679746"]], "c": "3108658305"}, "book-100", "XBT/USD"]
[270, {"b": [["11645.20000", "0.12500000", "1596666734.697139"]], "c": "1830223575"}, "book-100", "XBT/USD"]
[270, {"b": [["11634.60000", "0.02682840", "1596666734.827331"]], "c": "1830223575"}, "book-100", "XBT/USD"]
[270, {"b": [["11635.20000", "0.00000000", "1596666734.865424"], ["11594.30000", "2.01919334", "1596666706.140722", "r"]], "c": "1830223575"}, "book-100", "XBT/USD"]
[270, {"a": [["11689.00000", "2.25106635", "1596666734.869450"]], "c": "1830223575"}, "book-100", "XBT/USD"]
[270, {"b": [["11624.50000", "0.00000000", "1596666734.949157"], ["11594.10000", "0.48610000", "1596666616.025674", "r"]], "c": "1830223575"}, "book-100", "XBT/USD"]
[270, {"b": [["11627.70000", "0.00000000", "1596666734.951946"], ["11592.90000", "0.80800000", "1596666471.264849", "r"]], "c": "1830223575"}, "book-100", "XBT/USD"]
[270, {"a": [["11661.40000", "0.00000000", "1596666734.954987"], ["11692.70000", "1.75400000", "1596666164.005133", "r"]], "c": "1830223575"}, "book-100", "XBT/USD"]
[270, {"b": [["11641.30000", "0.00000000", "1596666734.976293"], ["11592.20000", "2.33146098", "1596666721.550957", "r"]], "c": "1830223575"}, "book-100", "XBT/USD"]
[270, {"b": [["11644.60000", "1.70900000", "1596666734.987519"]], "c": "1830223575"}, "book-100", "XBT/USD"]
[270, {"a": [["11652.80000", "5.98500000", "1596666734.999754"]], "c": "3867917778"}, "book-100", "XBT/USD"]
[270, {"a": [["11658.20000", "0.00000000", "1596666735.002088"], ["11693.30000", "0.48410000", "1596666703.085185", "r"]], "c": "3867917778"}, "book-100", "XBT/USD"]
[270, {"a": [["11662.80000", "2.10090791", "1596666735.258205"]], "c": "3867917778"}, "book-100", "XBT/USD"]
[270, {"a": [["11652.80000", "4.28300000", "1596666735.321412"]], "c": "1830223575"}, "book-100", "XBT/USD"]
[270, {"b": [["11628.90000", "0.33979558", "1596666735.370044"]], "c": "1830223575"}, "book-100", "XBT/USD"]
[271, [["11651.40000", "0.03200000", "1596666735.371935", "b", "m", ""]], "trade", "XBT/USD"]
[270, {"a": [["11651.40000", "0.02113798", "1596666735.371935"]], "c": "1278275391"}, "book-100", "XBT/USD"]
[270, {"b": [["11649.50000", "0.00588309", "1596666735.419790"]], "c": "3535384445"}, "book-100", "XBT/USD"]
[270, {"a": [["11651.40000", "0.00000000", "1596666735.515557"], ["11693.70000", "1.16987239", "1596666701.085240", "r"]], "c": "3894208436"}, "book-100", "XBT/USD"]
[270, {"a": [["11651.40000", "0.04907605", "1596666735.517068"]], "c": "3857470765"}, "book-100", "XBT/USD"]
[270, {"b": [["11595.50000", "7.80000000", "1596666735.579667"]], "c": "3857470765"}, "book-100", "XBT/USD"]
[270, {"b": [["11625.50000", "1.21377941", "1596666735.595805"]], "c": "3857470765"}, "book-100", "XBT/USD"]
[270, {"b": [["11647.80000", "0.00000000", "1596666735.631559"], ["11594.10000", "0.48610000", "1596666616.025674", "r"]], "c": "3905129811"}, "book-100", "XBT/USD"]
[270, {"b": [["11645.20000", "1.12500000", "1596666735.711202"]], "c": "2830857892"}, "book-100", "XBT/USD"]
[270, {"a": [["11662.10000", "0.91093000", "1596666735.730762"]], "c": "2830857892"}, "book-100", "XBT/USD"]
[270, {"a": [["11653.70000", "0.00000000", "1596666735.845802"], ["11693.30000", "0.48410000", "1596666703.085185", "r"]], "c": "1969090291"}, "book-100", "XBT/USD"]
[270, {"b": [["11645.30000", "4.28200000", "1596666735.925329"]], "c": "1668446602"}, "book-100", "XBT/USD"]
[270, {"a": [["11652.70000", "0.25872845", "1596666735.941639"]], "c": "841431966"}, "book-100", "XBT/USD"]
[270, {"b": [["11647.00000", "0.64371384", "1596666736.205316"]], "c": "1078020555"}, "book-100", "XBT/USD"]
[270, {"a": [["11651.60000", "0.00000000", "1596666736.283451"], ["11693.30000", "0.48410000", "1596666703.085185", "r"]], "c": "321167423"}, "book-100", "XBT/USD"]
[270, {"a": [["11658.80000", "0.45379787", "1596666736.338214"]], "c": "321167423"}, "book-100", "XBT/USD"]
[270, {"a": [["11673.90000", "0.62133456", "1596666736.338288"]], "c": "321167423"}, "book-100", "XBT/USD"]
[270, {"b": [["11645.30000", "0.00000000", "1596666736.366141"], ["11594.30000", "2.01919334", "1596666706.140722", "r"]], "c": "2017133578"}, "book-100", "XBT/USD"]
[270, {"a": [["11652.80000", "0.00000000", "1596666736.391009"], ["11692.70000", "1.75400000", "1596666164.005133", "r"]], "c": "441813533"}, "book-100", "XBT/USD"]
[270, {"a": [["11650.90000", "0.64371384", "1596666736.587232"]], "c": "2339937950"}, "book-100", "XBT/USD"]
[270, {"b": [["11642.20000", "0.49687207", "1596666736.589124"]], "c": "2339937950"}, "book-100", "XBT/USD"]
[270, {"a": [["11652.10000", "0.00000000", "1596666736.627589"], ["11692.70000", "1.75400000", "1596666164.005133", "r"]], "c": "2225231770"}, "book-100", "XBT/USD"]
[270, {"a": [["11650.90000", "0.00000000", "1596666736.643903"], ["11693.30000", "0.48410000", "1596666703.085185", "r"]], "c": "2023156713"}, "book-100", "XBT/USD"]
[270, {"a": [["11651.40000", "0.00000000", "1596666736.715951"], ["11693.70000", "1.16987239", "1596666701.085240", "r"]], "c": "3902856973"}, "book-100", "XBT/USD"]
[270, {"a": [["11650.80000", "0.04067366", "1596666736.719566"]], "c": "2004816430"}, "book-100", "XBT/USD"]
[270, {"a": [["11651.50000", "0.00000000", "1596666736.853264"], ["11693.70000", "1.16987239", "1596666701.085240", "r"]], "c": "3082766087"}, "book-100", "XBT/USD"]
[270, {"a": [["11652.50000", "0.00000000", "1596666736.960494"], ["11694.10000", "20.00000000", "1596666705.854859", "r"]], "c": "3122446314"}, "book-100", "XBT/USD"]
[270, {"a": [["11651.40000", "0.04907605", "1596666736.971512"]], "c": "3736610100"}, "book-100", "XBT/USD"]
[270, {"a": [["11650.80000", "0.00000000", "1596666736.977429"], ["11694.10000", "20.00000000", "1596666705.854859", "r"]], "c": "1394363555"}, "book-100", "XBT/USD"]
[270, {"a": [["11655.00000", "0.53990000", "1596666737.007847"]], "c": "3368340099"}, "book-100", "XBT/USD"]
[270, {"a": [["11657.50000", "0.00000000", "1596666737.025972"], ["11694.10000", "20.00000000", "1596666705.854859", "r"]], "c": "3368340099"}, "book-100", "XBT/USD"]
[270, {"a": [["11661.00000", "0.00000000", "1596666737.133179"], ["11695.10000", "0.35368913", "1596666684.533099", "r"]], "c": "3368340099"}, "book-100", "XBT/USD"]
[270, {"a": [["11652.70000", "0.00000000", "1596666737.136096"], ["11696.80000", "1.98460791", "1596666708.392556", "r"]], "c": "382067638"}, "book-100", "XBT/USD"]
[270, {"a": [["11650.70000", "0.44977469", "1596666737.172504"]], "c": "1247955918"}, "book-100", "XBT/USD"]
[270, {"a": [["11674.80000", "0.43900000", "1596666737.178455"]], "c": "1247955918"}, "book-100", "XBT/USD"]
[270, {"a": [["11652.70000", "0.43209377", "1596666737.193889"]], "c": "1227088267"}, "book-100", "XBT/USD"]
[270, {"a": [["11651.60000", "0.05313798", "1596666737.220589"]], "c": "905747899"}, "book-100", "XBT/USD"]
[270, {"a": [["11651.40000", "0.00000000", "1596666737.224180"], ["11693.70000", "1.16987239", "1596666701.085240", "r"]], "c": "1143149355"}, "book-100", "XBT/USD"]
[270, {"a": [["11653.70000", "0.25871544", "1596666737.231941"]], "c": "2838094126"}, "book-100", "XBT/USD"]
[270, {"a": [["11651.60000", "0.00000000", "1596666737.480477"], ["11693.70000", "1.16987239", "1596666701.085240", "r"]], "c": "3117174908"}, "book-100", "XBT/USD"]
[270, {"a": [["11650.60000", "0.04067436", "1596666737.480617"]], "c": "154122649"}, "book-100", "XBT/USD"]
[270, {"a": [["11668.10000", "0.86265733", "1596666737.516556"]], "c": "154122649"}, "book-100", "XBT/USD"]
[270, {"a": [["11653.60000", "4.28500000", "1596666737.528501"]], "c": "3299766892"}, "book-100", "XBT/USD"]
[270, {"b": [["11647.60000", "4.27900000", "1596666737.530510"]], "c": "4074846249"}, "book-100", "XBT/USD"]
[270, {"a": [["11663.40000", "0.00000000", "1596666737.694646"], ["11693.30000", "0.48410000", "1596666703.085185", "r"]], "c": "4074846249"}, "book-100", "XBT/USD"]
[270, {"b": [["11642.80000", "0.00000000", "1596666737.710115"], ["11594.30000", "2.01919334", "1596666706.140722", "r"]], "c": "4074846249"}, "book-100", "XBT/USD"]
[270, {"a": [["11664.70000", "0.00000000", "1596666737.878696"], ["11693.70000", "1.16987239", "1596666701.085240", "r"]], "c": "4074846249"}, "book-100", "XBT/USD"]
[270, {"b": [["11624.10000", "0.00430487", "1596666737.881593"]], "c": "4074846249"}, "book-100", "XBT/USD"]
[270, {"a": [["11650.60000", "0.00000000", "1596666737.898514"], ["11694.10000", "20.00000000", "1596666705.854859", "r"]], "c": "565326000"}, "book-100", "XBT/USD"]
[270, {"a": [["11650.60000", "0.04067433", "1596666737.899826"]], "c": "572522749"}, "book-100", "XBT/USD"]
[270, {"a": [["11658.80000", "0.00000000", "1596666737.984746"], ["11694.10000", "20.00000000", "1596666705.854859", "r"]], "c": "572522749"}, "book-100", "XBT/USD"]
[270, {"b": [["11642.90000", "1.30704162", "1596666738.078462"]], "c": "572522749"}, "book-100", "XBT/USD"]
[270, {"a": [["11658.80000", "0.46841785", "1596666738.177823"]], "c": "572522749"}, "book-100", "XBT/USD"]
[270, {"a": [["11665.20000", "0.71135022", "1596666738.177936"]], "c": "572522749"}, "book-100", "XBT/USD"]
[270, {"b": [["11624.10000", "0.00000000", "1596666738.223265"], ["11595.50000", "7.80000000", "1596666735.579667", "r"]], "c": "572522749"}, "book-100", "XBT/USD"]
[270, {"b": [["11642.90000", "0.00000000", "1596666738.225331"], ["11594.30000", "2.01919334", "1596666706.140722", "r"]], "c": "572522749"}, "book-100", "XBT/USD"]
[270, {"a": [["11684.50000", "10.19791134", "1596666738.231876"]], "c": "572522749"}, "book-100", "XBT/USD"]
[270, {"a": [["11686.90000", "0.66398562", "1596666738.284283"]], "c": "572522749"}, "book-100", "XBT/USD"]
[270, {"b": [["11643.00000", "1.39334619", "1596666738.579606"]], "c": "572522749"}, "book-100", "XBT/USD"]
[270, {"b": [["11648.50000", "0.25500000", "1596666738.847321"]], "c": "908970742"}, "book-100", "XBT/USD"]
[270, {"b": [["11643.00000", "0.00000000", "1596666738.865431"], ["11595.50000", "7.80000000", "1596666735.579667", "r"]], "c": "908970742"}, "book-100", "XBT/USD"]
[271, [["11649.50000", "0.00588309", "1596666738.914673", "s", "m", ""], ["11649.40000", "0.02766675", "1596666738.921748", "s", "m", ""]], "trade", "XBT/USD"]
[270, {"b": [["11649.50000", "0.00000000", "1596666738.914673"], ["11594.30000", "2.01919334", "1596666706.140722", "r"], ["11649.40000", "0.61602017", "1596666738.921749"]], "c": "948969615"}, "book-100", "XBT/USD"]
[270, {"a": [["11650.60000", "0.00000000", "1596666738.926407"], ["11693.30000", "0.48410000", "1596666703.085185", "r"]], "c": "1537090297"}, "book-100", "XBT/USD"]
[270, {"b": [["11649.50000", "0.25500000", "1596666738.940347"]], "c": "3698931225"}, "book-100", "XBT/USD"]
[270, {"a": [["11651.10000", "0.64373459", "1596666738.980961"]], "c": "1248405231"}, "book-100", "XBT/USD"]
[270, {"a": [["11653.40000", "0.64371004", "1596666738.981338"]], "c": "3988165582"}, "book-100", "XBT/USD"]
[270, {"b": [["11649.50000", "4.65500000", "1596666739.005694"]], "c": "3342449083"}, "book-100", "XBT/USD"]
[270, {"b": [["11648.50000", "0.00000000", "1596666739.033857"], ["11594.30000", "2.01919334", "1596666706.140722", "r"]], "c": "3543430064"}, "book-100", "XBT/USD"]
[271, [["11649.50000", "0.25500000", "1596666739.060203", "s", "l", ""], ["11649.50000", "0.24437167", "1596666739.063507", "s", "l", ""], ["11649.50000", "0.00062833", "1596666739.065134", "s", "l", ""]], "trade", "XBT/USD"]
[270, {"b": [["11649.50000", "4.40000000", "1596666739.060203"], ["11649.50000", "4.15562833", "1596666739.063507"], ["11649.50000", "4.15500000", "1596666739.065134"]], "c": "1835062839"}, "book-100", "XBT/USD"]
[270, {"a": [["11653.60000", "0.00000000", "1596666739.080652"], ["11692.70000", "1.75400000", "1596666164.005133", "r"]], "c": "2984006901"}, "book-100", "XBT/USD"]
[270, {"a": [["11650.60000", "0.02769491", "1596666739.086112"]], "c": "330035779"}, "book-100", "XBT/USD"]
[270, {"b": [["11635.50000", "1.39659444", "1596666739.109531"]], "c": "330035779"}, "book-100", "XBT/USD"]
[270, {"b": [["11649.50000", "0.00000000", "1596666739.111641"], ["11594.30000", "2.01919334", "1596666706.140722", "r"]], "c": "661970368"}, "book-100", "XBT/USD"]
[270, {"a": [["11655.00000", "4.81890000", "1596666739.123787"]], "c": "661970368"}, "book-100", "XBT/USD"]
[270, {"b": [["11603.10000", "0.00858405", "1596666739.130412"]], "c": "661970368"}, "book-100", "XBT/USD"]
[270, {"b": [["11599.70000", "0.00900000", "1596666739.190302"]], "c": "661970368"}, "book-100", "XBT/USD"]
[270, {"a": [["11671.70000", "0.00000000", "1596666739.216855"], ["11692.70000", "1.75400000", "1596666164.005133", "r"]], "c": "661970368"}, "book-100", "XBT/USD"]
[270, {"a": [["11670.20000", "3.95202531", "1596666739.227395"]], "c": "661970368"}, "book-100", "XBT/USD"]
[270, {"b": [["11601.20000", "0.75002428", "1596666739.235455"]], "c": "661970368"}, "book-100", "XBT/USD"]
[270, {"b": [["11628.90000", "0.00000000", "1596666739.239123"], ["11595.50000", "7.80000000", "1596666735.579667", "r"]], "c": "661970368"}, "book-100", "XBT/USD"]
[270, {"b": [["11647.20000", "0.00000000", "1596666739.244493"], ["11594.30000", "2.01919334", "1596666706.140722", "r"]], "c": "1470679406"}, "book-100", "XBT/USD"]
[270, {"a": [["11653.70000", "0.00000000", "1596666739.302939"], ["11693.30000", "0.48410000", "1596666703.085185", "r"]], "c": "3969257326"}, "book-100", "XBT/USD"]
[270, {"a": [["11662.80000", "1.76210000", "1596666739.367803"]], "c": "3969257326"}, "book-100", "XBT/USD"]
[270, {"a": [["11653.30000", "0.25872383", "1596666739.400957"]], "c": "3875326791"}, "book-100", "XBT/USD"]
[270, {"b": [["11635.50000", "0.00000000", "1596666739.418940"], ["11594.10000", "0.48610000", "1596666616.025674", "r"]], "c": "3875326791"}, "book-100", "XBT/USD"]
[270, {"b": [["11649.40000", "0.83936017", "1596666739.610943"]], "c": "3065350421"}, "book-100", "XBT/USD"]
[270, {"b": [["11642.00000", "1.28640336", "1596666739.698975"]], "c": "3065350421"}, "book-100", "XBT/USD"]
[270, {"b": [["11628.00000", "0.33982188", "1596666739.761044"]], "c": "3065350421"}, "book-100", "XBT/USD"]
[270, {"a": [["11662.10000", "0.00000000", "1596666739.806323"], ["11693.30000", "0.48410000", "1596666703.085185", "r"]], "c": "3065350421"}, "book-100", "XBT/USD"]
[270, {"b": [["11644.90000", "1.71300000", "1596666739.851549"]], "c": "681832281"}, "book-100", "XBT/USD"]
[270, {"a": [["11653.10000", "1.71500000", "1596666739.872208"]], "c": "625552737"}, "book-100", "XBT/USD"]
[270, {"a": [["11661.60000", "0.83884277", "1596666740.096353"]], "c": "625552737"}, "book-100", "XBT/USD"]
[270, {"b": [["11642.00000", "0.00000000", "1596666740.106979"], ["11595.50000", "7.80000000", "1596666735.579667", "r"]], "c": "625552737"}, "book-100", "XBT/USD"]
[270, {"b": [["11644.60000", "0.00000000", "1596666740.107612"], ["11594.30000", "2.01919334", "1596666706.140722", "r"]], "c": "625552737"}, "book-100", "XBT/USD"]
[270, {"a": [["11653.10000", "0.00000000", "1596666740.230054"], ["11693.30000", "0.48410000", "1596666703.085185", "r"]], "c": "681832281"}, "book-100", "XBT/USD"]
[270, {"a": [["11660.70000", "1.67000000", "1596666740.268283"]], "c": "681832281"}, "book-100", "XBT/USD"]
[270, {"b": [["11635.50000", "1.39598609", "1596666740.282309"]], "c": "681832281"}, "book-100", "XBT/USD"]
[270, {"a": [["11674.00000", "3.53590705", "1596666740.346319"]], "c": "681832281"}, "book-100", "XBT/USD"]
[270, {"b": [["11643.10000", "0.01493411", "1596666740.410674"]], "c": "681832281"}, "book-100", "XBT/USD"]
[270, {"a": [["11657.20000", "0.87379705", "1596666740.411603"]], "c": "681832281"}, "book-100", "XBT/USD"]
[270, {"b": [["11635.50000", "0.00000000", "1596666740.462735"], ["11595.50000", "7.80000000", "1596666735.579667", "r"]], "c": "681832281"}, "book-100", "XBT/USD"]
[270, {"a": [["11656.90000", "1.37323234", "1596666740.471880"]], "c": "681832281"}, "book-100", "XBT/USD"]
[270, {"b": [["11642.40000", "0.07467100", "1596666740.472245"]], "c": "681832281"}, "book-100", "XBT/USD"]
[270, {"b": [["11637.30000", "1.03807280", "1596666740.530129"]], "c": "681832281"}, "book-100", "XBT/USD"]
[270, {"a": [["11658.40000", "0.17920986", "1596666740.531719"]], "c": "681832281"}, "book-100", "XBT/USD"]
[270, {"a": [["11673.90000", "0.00000000", "1596666740.567477"], ["11692.70000", "1.75400000", "1596666164.005133", "r"]], "c": "681832281"}, "book-100", "XBT/USD"]
[270, {"b": [["11644.90000", "0.00000000", "1596666740.600674"], ["11595.50000", "7.80000000", "1596666735.579667", "r"]], "c": "3065350421"}, "book-100", "XBT/USD"]
[270, {"b": [["11645.50000", "1.71300000", "1596666740.601438"]], "c": "3581361804"}, "book-100", "XBT/USD"]
[270, {"a": [["11653.70000", "1.71300000", "1596666740.610168"]], "c": "353320523"}, "book-100", "XBT/USD"]
[270, {"b": [["11647.10000", "0.42900000", "1596666740.667046"]], "c": "1747171641"}, "book-100", "XBT/USD"]
[270, {"a": [["11654.20000", "0.21696687", "1596666740.667816"]], "c": "3474276934"}, "book-100", "XBT/USD"]
[270, {"b": [["11645.20000", "0.12500000", "1596666740.712632"]], "c": "3682333044"}, "book-100", "XBT/USD"]
[270, {"a": [["11673.90000", "0.59627640", "1596666740.759967"]], "c": "3682333044"}, "book-100", "XBT/USD"]
[270, {"a": [["11653.10000", "0.41352978", "1596666740.814758"]], "c": "779129351"}, "book-100", "XBT/USD"]
[270, {"b": [["11645.90000", "0.25000000", "1596666740.821396"]], "c": "3759254305"}, "book-100", "XBT/USD"]
[270, {"b": [["11635.50000", "1.39236700", "1596666740.930311"]], "c": "3759254305"}, "book-100", "XBT/USD"]
[270, {"b": [["11618.20000", "0.00000000", "1596666740.980101"], ["11597.60000", "3.55614984", "1596666721.465658", "r"]], "c": "3759254305"}, "book-100", "XBT/USD"]
[270, {"a": [["11652.70000", "0.00000000", "1596666741.068228"], ["11692.10000", "4.49523792", "1596666702.300008", "r"]], "c": "496450208"}, "book-100", "XBT/USD"]
[270, {"a": [["11673.90000", "0.00000000", "1596666741.174102"], ["11692.30000", "8.50000000", "1596666502.813701", "r"]], "c": "496450208"}, "book-100", "XBT/USD"]
[270, {"a": [["11656.60000", "0.00000000", "1596666741.266456"], ["11692.70000", "1.75400000", "1596666164.005133", "r"]], "c": "496450208"}, "book-100", "XBT/USD"]
[270, {"a": [["11656.10000", "0.01000000", "1596666741.324075"]], "c": "496450208"}, "book-100", "XBT/USD"]
[270, {"a": [["11652.30000", "0.41436798", "1596666741.349517"]], "c": "262626887"}, "book-100", "XBT/USD"]
[270, {"b": [["11634.60000", "0.00000000", "1596666741.462184"], ["11596.30000", "19.40000000", "1596666706.107317", "r"]], "c": "262626887"}, "book-100", "XBT/USD"]
[270, {"b": [["11635.20000", "0.02682839", "1596666741.462643"]], "c": "262626887"}, "book-100", "XBT/USD"]
[270, {"a": [["11653.30000", "0.00000000", "1596666741.473525"], ["11692.30000", "8.50000000", "1596666502.813701", "r"]], "c": "1973219409"}, "book-100", "XBT/USD"]
[270, {"a": [["11655.00000", "0.53990000", "1596666741.502503"]], "c": "1973219409"}, "book-100", "XBT/USD"]
[270, {"a": [["11653.10000", "4.70352978", "1596666741.514898"]], "c": "809063015"}, "book-100", "XBT/USD"]
[270, {"a": [["11653.00000", "0.25872388", "1596666741.574009"]], "c": "2194994156"}, "book-100", "XBT/USD"]
[270, {"b": [["11630.20000", "0.00442926", "1596666741.603202"]], "c": "2194994156"}, "book-100", "XBT/USD"]
[270, {"a": [["11651.10000", "0.00000000", "1596666741.679476"], ["11692.30000", "8.50000000", "1596666502.813701", "r"]], "c": "2256348676"}, "book-100", "XBT/USD"]
[270, {"b": [["11647.00000", "0.00000000", "1596666741.680405"], ["11597.60000", "3.55614984", "1596666721.465658", "r"]], "c": "1102221695"}, "book-100", "XBT/USD"]
[270, {"b": [["11649.30000", "0.64368823", "1596666741.746341"]], "c": "2867074836"}, "book-100", "XBT/USD"]
[270, {"a": [["11653.80000", "1.13399914", "1596666741.747137"]], "c": "890865133"}, "book-100", "XBT/USD"]
[270, {"a": [["11653.80000", "0.49031091", "1596666741.841367"]], "c": "2867074836"}, "book-100", "XBT/USD"]
[270, {"a": [["11653.70000", "0.00000000", "1596666741.921973"], ["11692.70000", "1.75400000", "1596666164.005133", "r"]], "c": "707778620"}, "book-100", "XBT/USD"]
[270, {"a": [["11668.10000", "0.85827547", "1596666741.941162"]], "c": "707778620"}, "book-100", "XBT/USD"]
[270, {"b": [["11618.20000", "0.49800000", "1596666742.155446"]], "c": "707778620"}, "book-100", "XBT/USD"]
[270, {"b": [["11635.50000", "0.00000000", "1596666742.568303"], ["11598.00000", "0.53460245", "1596666723.277921", "r"]], "c": "707778620"}, "book-100", "XBT/USD"]
[270, {"b": [["11649.50000", "0.30100000", "1596666742.603489"]], "c": "298772692"}, "book-100", "XBT/USD"]
[270, {"a": [["11660.70000", "0.00000000", "1596666742.605049"], ["11693.30000", "0.48410000", "1596666703.085185", "r"]], "c": "298772692"}, "book-100", "XBT/USD"]
[270, {"b": [["11649.50000", "3.75100000", "1596666742.668749"]], "c": "1079098861"}, "book-100", "XBT/USD"]
[270, {"b": [["11649.50000", "0.30100000", "1596666742.732528"]], "c": "298772692"}, "book-100", "XBT/USD"]
[270, {"a": [["11653.10000", "0.41352978", "1596666742.743623"]], "c": "1219969110"}, "book-100", "XBT/USD"]
[270, {"b": [["11630.20000", "0.00000000", "1596666742.745944"], ["11598.00000", "0.53460245", "1596666723.277921", "r"]], "c": "1219969110"}, "book-100", "XBT/USD"]
[270, {"a": [["11654.30000", "1.70700000", "1596666743.012858"]], "c": "1105035440"}, "book-100", "XBT/USD"]
[270, {"a": [["11683.50000", "0.00000000", "1596666743.089662"], ["11693.30000", "0.48410000", "1596666703.085185", "r"]], "c": "1105035440"}, "book-100", "XBT/USD"]
[270, {"b": [["11642.00000", "1.36809892", "1596666743.110212"]], "c": "1105035440"}, "book-100", "XBT/USD"]
[270, {"a": [["11683.60000", "0.08250000", "1596666743.215077"]], "c": "1105035440"}, "book-100", "XBT/USD"]
[270, {"b": [["11645.90000", "0.00000000", "1596666743.343933"], ["11598.00000", "0.53460245", "1596666723.277921", "r"]], "c": "1760270599"}, "book-100", "XBT/USD"]
[270, {"a": [["11653.10000", "0.00000000", "1596666743.344005"], ["11693.30000", "0.48410000", "1596666703.085185", "r"]], "c": "3824942961"}, "book-100", "XBT/USD"]
[270, {"a": [["11654.00000", "0.41352978", "1596666743.480187"]], "c": "131087335"}, "book-100", "XBT/USD"]
[270, {"b": [["11646.80000", "0.25000000", "1596666743.498603"]], "c": "803547477"}, "book-100", "XBT/USD"]
[270, {"b": [["11647.50000", "0.22409000", "1596666743.611316"]], "c": "1270210077"}, "book-100", "XBT/USD"]
[270, {"b": [["11646.10000", "0.09621094", "1596666743.625432"]], "c": "4228929506"}, "book-100", "XBT/USD"]
[270, {"b": [["11642.00000", "0.00000000", "1596666743.626031"], ["11598.60000", "2.29920000", "1596666720.945552", "r"]], "c": "4228929506"}, "book-100", "XBT/USD"]
[270, {"a": [["11654.60000", "0.09621094", "1596666743.635829"]], "c": "4228929506"}, "book-100", "XBT/USD"]
[270, {"a": [["11653.00000", "0.00000000", "1596666743.647199"], ["11692.70000", "1.75400000", "1596666164.005133", "r"]], "c": "819239326"}, "book-100", "XBT/USD"]
[270, {"b": [["11635.20000", "1.42190323", "1596666743.682984"]], "c": "819239326"}, "book-100", "XBT/USD"]
[270, {"a": [["11653.30000", "0.25871720", "1596666743.746358"]], "c": "1376410323"}, "book-100", "XBT/USD"]
[270, {"a": [["11656.00000", "0.00000000", "1596666743.765008"], ["11692.70000", "1.75400000", "1596666164.005133", "r"]], "c": "1376410323"}, "book-100", "XBT/USD"]
[270, {"b": [["11647.50000", "0.00000000", "1596666743.845673"], ["11598.00000", "0.53460245", "1596666723.277921", "r"]], "c": "458445288"}, "book-100", "XBT/USD"]
[270, {"a": [["11667.50000", "0.00000000", "1596666743.906649"], ["11693.30000", "0.48410000", "1596666703.085185", "r"]], "c": "458445288"}, "book-100", "XBT/USD"]
[270, {"a": [["11653.40000", "4.93271004", "1596666743.956528"]], "c": "59823318"}, "book-100", "XBT/USD"]
[270, {"a": [["11679.30000", "0.02824126", "1596666744.150526"]], "c": "59823318"}, "book-100", "XBT/USD"]
[270, {"b": [["11635.20000", "0.02682839", "1596666744.202757"]], "c": "59823318"}, "book-100", "XBT/USD"]
[270, {"a": [["11652.50000", "0.64368823", "1596666744.203599"]], "c": "1400672881"}, "book-100", "XBT/USD"]
[270, {"a": [["11670.10000", "0.57238797", "1596666744.550440"]], "c": "1400672881"}, "book-100", "XBT/USD"]
[270, {"a": [["11650.00000", "0.41258798", "1596666744.633137"]], "c": "3818068319"}, "book-100", "XBT/USD"]
[270, {"a": [["11660.90000", "1.10570184", "1596666744.636854"]], "c": "3818068319"}, "book-100", "XBT/USD"]
[270, {"a": [["11670.10000", "0.00000000", "1596666744.737214"], ["11692.10000", "4.49523792", "1596666702.300008", "r"]], "c": "3818068319"}, "book-100", "XBT/USD"]
[270, {"b": [["11649.50000", "0.51241000", "1596666744.748099"]], "c": "4052064854"}, "book-100", "XBT/USD"]
[270, {"a": [["11650.60000", "0.00000000", "1596666744.765436"], ["11692.30000", "8.50000000", "1596666502.813701", "r"]], "c": "2976263190"}, "book-100", "XBT/USD"]
[270, {"a": [["11649.90000", "0.02769658", "1596666744.768272"]], "c": "4045417419"}, "book-100", "XBT/USD"]
[270, {"b": [["11642.00000", "1.27243026", "1596666744.787435"]], "c": "4045417419"}, "book-100", "XBT/USD"]
[271, [["11649.90000", "0.02769658", "1596666744.805901", "b", "l", ""], ["11650.00000", "0.02910222", "1596666744.808913", "b", "l", ""]], "trade", "XBT/USD"]
[270, {"a": [["11649.90000", "0.00000000", "1596666744.805901"], ["11692.30000", "8.50000000", "1596666502.813701", "r"], ["11650.00000", "0.38348576", "1596666744.808913"]], "c": "1653925955"}, "book-100", "XBT/USD"]
[270, {"a": [["11660.30000", "0.96651000", "1596666744.826523"]], "c": "1653925955"}, "book-100", "XBT/USD"]
[270, {"b": [["11649.50000", "2.11241000", "1596666744.881455"]], "c": "2632731919"}, "book-100", "XBT/USD"]
[270, {"a": [["11670.10000", "0.57718411", "1596666744.939495"]], "c": "2632731919"}, "book-100", "XBT/USD"]
[270, {"b": [["11649.50000", "0.51241000", "1596666744.943258"]], "c": "1653925955"}, "book-100", "XBT/USD"]
[270, {"a": [["11662.10000", "0.05313798", "1596666744.963907"]], "c": "1653925955"}, "book-100", "XBT/USD"]
[270, {"a": [["11669.90000", "0.00000000", "1596666745.000188"], ["11691.90000", "0.89806591", "1596666649.630348", "r"]]}, {"b": [["11609.90000", "0.00000000", "1596666745.000218"], ["11598.00000", "0.53460245", "1596666723.277921", "r"]], "c": "1653925955"}, "book-100", "XBT/USD"]
[270, {"a": [["11658.40000", "0.00000000", "1596666745.047765"], ["11692.10000", "4.49523792", "1596666702.300008", "r"]], "c": "1653925955"}, "book-100", "XBT/USD"]
[270, {"a": [["11659.20000", "0.43900000", "1596666745.059062"]], "c": "1653925955"}, "book-100", "XBT/USD"]
[270, {"a": [["11674.80000", "0.00000000", "1596666745.102285"], ["11692.10000", "4.49523792", "1596666702.300008", "r"]], "c": "1653925955"}, "book-100", "XBT/USD"]
[270, {"a": [["11670.10000", "0.00000000", "1596666745.336860"], ["11692.30000", "8.50000000", "1596666502.813701", "r"]], "c": "1653925955"}, "book-100", "XBT/USD"]
[270, {"b": [["11613.80000", "0.00000000", "1596666745.338283"], ["11597.60000", "3.55614984", "1596666721.465658", "r"]], "c": "1653925955"}, "book-100", "XBT/USD"]
[270, {"b": [["11600.90000", "1.03470000", "1596666745.340027"]], "c": "1653925955"}, "book-100", "XBT/USD"]
[270, {"b": [["11617.20000", "0.00000000", "1596666745.342783"], ["11596.30000", "19.40000000", "1596666706.107317", "r"]], "c": "1653925955"}, "book-100", "XBT/USD"]
[270, {"a": [["11650.70000", "0.00000000", "1596666745.347078"], ["11692.70000", "1.75400000", "1596666164.005133", "r"]], "c": "3166624070"}, "book-100", "XBT/USD"]
[270, {"b": [["11609.20000", "0.00000000", "1596666745.368786"], ["11595.50000", "7.80000000", "1596666735.579667", "r"]], "c": "3166624070"}, "book-100", "XBT/USD"]
[270, {"b": [["11642.00000", "0.00000000", "1596666745.381170"], ["11594.30000", "2.01919334", "1596666706.140722", "r"]], "c": "3166624070"}, "book-100", "XBT/USD"]
[270, {"a": [["11649.90000", "0.44901691", "1596666745.663595"]], "c": "709909016"}, "book-100", "XBT/USD"]
[270, {"b": [["11601.20000", "0.00000000", "1596666745.695700"], ["11594.10000", "0.48610000", "1596666616.025674", "r"]], "c": "709909016"}, "book-100", "XBT/USD"]
[270, {"a": [["11689.00000", "0.00000000", "1596666745.701801"], ["11692.70000", "1.75400000", "1596666164.005133", "r"]], "c": "709909016"}, "book-100", "XBT/USD"]
[270, {"b": [["11604.20000", "0.75004199", "1596666745.705220"]], "c": "709909016"}, "book-100", "XBT/USD"]
[270, {"a": [["11670.20000", "3.20200103", "1596666745.712519"]], "c": "709909016"}, "book-100", "XBT/USD"]
[270, {"a": [["11668.10000", "1.60831746", "1596666745.719041"]], "c": "709909016"}, "book-100", "XBT/USD"]
[270, {"a": [["11685.60000", "2.25114506", "1596666745.726882"]], "c": "709909016"}, "book-100", "XBT/USD"]
[270, {"b": [["11634.50000", "0.45122805", "1596666745.765374"]], "c": "709909016"}, "book-100", "XBT/USD"]
[270, {"b": [["11637.90000", "0.25008981", "1596666745.768260"]], "c": "709909016"}, "book-100", "XBT/USD"]
[270, {"b": [["11609.00000", "1.17834825", "1596666745.769456"]], "c": "709909016"}, "book-100", "XBT/USD"]
[270, {"b": [["11622.90000", "0.90148523", "1596666745.775092"]], "c": "709909016"}, "book-100", "XBT/USD"]
[270, {"b": [["11629.80000", "0.57560718", "1596666745.779926"]], "c": "709909016"}, "book-100", "XBT/USD"]
[270, {"b": [["11642.30000", "1.30755302", "1596666745.822086"]], "c": "709909016"}, "book-100", "XBT/USD"]
[270, {"a": [["11653.30000", "0.00000000", "1596666745.824974"], ["11692.70000", "1.75400000", "1596666164.005133", "r"]], "c": "1169483259"}, "book-100", "XBT/USD"]
[270, {"a": [["11653.30000", "0.25871917", "1596666745.927128"]], "c": "2403260158"}, "book-100", "XBT/USD"]
[270, {"b": [["11630.10000", "8.60000000", "1596666745.984410"]], "c": "2403260158"}, "book-100", "XBT/USD"]
[270, {"a": [["11658.10000", "3.10000000", "1596666746.012168"]], "c": "2403260158"}, "book-100", "XBT/USD"]
[270, {"b": [["11629.10000", "0.03100000", "1596666746.037678"]], "c": "2403260158"}, "book-100", "XBT/USD"]
[270, {"b": [["11606.80000", "0.00000000", "1596666746.269521"], ["11598.60000", "2.29920000", "1596666720.945552", "r"]], "c": "2403260158"}, "book-100", "XBT/USD"]
[270, {"b": [["11613.90000", "0.00000000", "1596666746.300655"], ["11598.00000", "0.53460245", "1596666723.277921", "r"]], "c": "2403260158"}, "book-100", "XBT/USD"]
[270, {"b": [["11608.60000", "0.00000000", "1596666746.515660"], ["11596.30000", "19.40000000", "1596666706.107317", "r"]], "c": "2403260158"}, "book-100", "XBT/USD"]
[270, {"b": [["11601.70000", "0.00000000", "1596666746.517380"], ["11595.50000", "7.80000000", "1596666735.579667", "r"]], "c": "2403260158"}, "book-100", "XBT/USD"]
[270, {"b": [["11614.50000", "0.00000000", "1596666746.525635"], ["11594.30000", "2.01919334", "1596666706.140722", "r"]], "c": "2403260158"}, "book-100", "XBT/USD"]
[270, {"b": [["11618.00000", "0.00000000", "1596666746.527707"], ["11594.10000", "0.48610000", "1596666616.025674", "r"]], "c": "2403260158"}, "book-100", "XBT/USD"]
[270, {"b": [["11646.10000", "0.00000000", "1596666746.697787"], ["11592.90000", "0.80800000", "1596666471.264849", "r"]], "c": "85667852"}, "book-100", "XBT/USD"]
[270, {"b": [["11629.10000", "0.00000000", "1596666746.761203"], ["11592.20000", "2.33146098", "1596666721.550957", "r"]], "c": "85667852"}, "book-100", "XBT/USD"]
[270, {"b": [["11615.40000", "0.00000000", "1596666746.770100"], ["11591.20000", "1.06000000", "1596666709.000103", "r"]], "c": "85667852"}, "book-100", "XBT/USD"]
[270, {"b": [["11634.50000", "0.10100000", "1596666746.779714"]], "c": "85667852"}, "book-100", "XBT/USD"]
[270, {"b": [["11637.90000", "0.00000000", "1596666746.783764"], ["11590.90000", "2.50315283", "1596666703.117862", "r"]], "c": "85667852"}, "book-100", "XBT/USD"]
[270, {"b": [["11628.80000", "0.00000000", "1596666746.797545"], ["11590.10000", "1.51500000", "1596666649.220608", "r"]], "c": "85667852"}, "book-100", "XBT/USD"]
[270, {"b": [["11626.90000", "0.00000000", "1596666746.798748"], ["11589.90000", "6.90000000", "1596666166.290818", "r"]], "c": "85667852"}, "book-100", "XBT/USD"]
[270, {"b": [["11622.20000", "0.00000000", "1596666746.808179"], ["11586.70000", "2.25114506", "1596666745.719494", "r"]], "c": "85667852"}, "book-100", "XBT/USD"]
[270, {"b": [["11615.10000", "0.00000000", "1596666746.810726"], ["11586.20000", "3.00500211", "1596666626.428727", "r"]], "c": "85667852"}, "book-100", "XBT/USD"]
[270, {"a": [["11661.60000", "0.50000000", "1596666746.810985"]], "c": "85667852"}, "book-100", "XBT/USD"]
[270, {"a": [["11665.20000", "0.00000000", "1596666746.811624"], ["11692.70000", "1.75400000", "1596666164.005133", "r"]], "c": "85667852"}, "book-100", "XBT/USD"]
[270, {"b": [["11628.00000", "0.00000000", "1596666746.813287"], ["11585.90000", "1.48215236", "1596666745.788273", "r"]], "c": "85667852"}, "book-100", "XBT/USD"]
[270, {"a": [["11660.90000", "0.99307308", "1596666746.814787"]], "c": "85667852"}, "book-100", "XBT/USD"]
[270, {"b": [["11630.10000", "8.63100000", "1596666746.820866"]], "c": "85667852"}, "book-100", "XBT/USD"]
[270, {"b": [["11625.50000", "0.50000000", "1596666746.821165"]], "c": "85667852"}, "book-100", "XBT/USD"]
[270, {"b": [["11587.00000", "3.55934204", "1596666746.867590"]], "c": "85667852"}, "book-100", "XBT/USD"]
[270, {"b": [["11621.70000", "3.54871458", "1596666746.869643"]], "c": "85667852"}, "book-100", "XBT/USD"]
[270, {"b": [["11598.60000", "5.85498227", "1596666746.869996"]], "c": "85667852"}, "book-100", "XBT/USD"]
[270, {"b": [["11631.00000", "3.54587707", "1596666746.870707"]], "c": "85667852"}, "book-100", "XBT/USD"]
[270, {"b": [["11636.80000", "3.54410974", "1596666746.873551"]], "c": "85667852"}, "book-100", "XBT/USD"]
[270, {"b": [["11610.10000", "3.55226020", "1596666746.875501"]], "c": "85667852"}, "book-100", "XBT/USD"]
[270, {"b": [["11614.80000", "3.08717099", "1596666746.879208"]], "c": "85667852"}, "book-100", "XBT/USD"]
[270, {"b": [["11624.60000", "0.90303269", "1596666746.929117"]], "c": "85667852"}, "book-100", "XBT/USD"]
[270, {"b": [["11631.50000", "0.90249700", "1596666746.931097"]], "c": "85667852"}, "book-100", "XBT/USD"]
[270, {"b": [["11610.70000", "0.90411378", "1596666746.933205"]], "c": "85667852"}, "book-100", "XBT/USD"]
[270, {"b": [["11639.70000", "0.90186120", "1596666746.940938"]], "c": "85667852"}, "book-100", "XBT/USD"]
[270, {"b": [["11636.20000", "0.90213247", "1596666746.948858"]], "c": "85667852"}, "book-100", "XBT/USD"]
[270, {"b": [["11618.90000", "1.21484579", "1596666747.061376"]], "c": "85667852"}, "book-100", "XBT/USD"]
[270, {"a": [["11663.80000", "0.11262765", "1596666747.085251"]], "c": "85667852"}, "book-100", "XBT/USD"]
[270, {"a": [["11658.10000", "2.00000000", "1596666747.104830"]], "c": "85667852"}, "book-100", "XBT/USD"]
[270, {"b": [["11618.80000", "2.01488151", "1596666747.148048"]], "c": "85667852"}, "book-100", "XBT/USD"]
[270, {"a": [["11654.60000", "0.00000000", "1596666747.257063"], ["11692.70000", "1.75400000", "1596666164.005133", "r"]], "c": "85667852"}, "book-100", "XBT/USD"]
[270, {"b": [["11630.70000", "0.99791582", "1596666747.320136"]], "c": "85667852"}, "book-100", "XBT/USD"]
[270, {"b": [["11624.80000", "0.00000000", "1596666747.373458"], ["11595.50000", "7.80000000", "1596666735.579667", "r"]], "c": "85667852"}, "book-100", "XBT/USD"]
[270, {"b": [["11622.50000", "0.00000000", "1596666747.373520"], ["11594.30000", "2.01919334", "1596666706.140722", "r"]], "c": "85667852"}, "book-100", "XBT/USD"]
[270, {"b": [["11605.10000", "0.00000000", "1596666747.378476"], ["11594.10000", "0.48610000", "1596666616.025674", "r"]], "c": "85667852"}, "book-100", "XBT/USD"]
[270, {"b": [["11618.90000", "0.00000000", "1596666747.379826"], ["11592.90000", "0.80800000", "1596666471.264849", "r"]], "c": "85667852"}, "book-100", "XBT/USD"]
[270, {"a": [["11663.80000", "0.00000000", "1596666747.385606"], ["11693.30000", "0.48410000", "1596666703.085185", "r"]], "c": "85667852"}, "book-100", "XBT/USD"]
[270, {"b": [["11649.50000", "0.91241000", "1596666747.457589"]], "c": "2558972506"}, "book-100", "XBT/USD"]
[270, {"a": [["11661.10000", "0.11262868", "1596666747.606369"]], "c": "2558972506"}, "book-100", "XBT/USD"]
[270, {"b": [["11637.30000", "0.85886294", "1596666747.617147"]], "c": "2558972506"}, "book-100", "XBT/USD"]
[270, {"b": [["11607.90000", "2.32806266", "1596666747.643836"]], "c": "2558972506"}, "book-100", "XBT/USD"]
[270, {"b": [["11636.90000", "0.72570655", "1596666747.645058"]], "c": "2558972506"}, "book-100", "XBT/USD"]
[270, {"b": [["11639.20000", "0.10365188", "1596666747.645423"]], "c": "2558972506"}, "book-100", "XBT/USD"]
[270, {"b": [["11619.50000", "1.51588313", "1596666747.651029"]], "c": "2558972506"}, "book-100", "XBT/USD"]
[270, {"b": [["11631.10000", "1.21357152", "1596666747.652965"]], "c": "2558972506"}, "book-100", "XBT/USD"]
[270, {"b": [["11634.70000", "0.35021613", "1596666747.712903"]], "c": "2558972506"}, "book-100", "XBT/USD"]
[270, {"b": [["11638.10000", "0.25008129", "1596666747.715791"]], "c": "2558972506"}, "book-100", "XBT/USD"]
[270, {"a": [["11649.80000", "0.12137434", "1596666747.739681"]], "c": "4093473265"}, "book-100", "XBT/USD"]
[270, {"b": [["11610.90000", "0.00000000", "1596666747.743848"], ["11598.60000", "5.85498227", "1596666746.869996", "r"]], "c": "4093473265"}, "book-100", "XBT/USD"]
[270, {"b": [["11618.80000", "0.00000000", "1596666747.745227"], ["11598.00000", "0.53460245", "1596666723.277921", "r"]], "c": "4093473265"}, "book-100", "XBT/USD"]
[270, {"a": [["11654.00000", "0.00000000", "1596666747.779969"], ["11692.70000", "1.75400000", "1596666164.005133", "r"]], "c": "2990471003"}, "book-100", "XBT/USD"]
[270, {"b": [["11646.80000", "0.00000000", "1596666747.788147"], ["11596.30000", "19.40000000", "1596666706.107317", "r"]], "c": "3172783258"}, "book-100", "XBT/USD"]
[270, {"b": [["11600.10000", "0.05000000", "1596666747.910313"]], "c": "3172783258"}, "book-100", "XBT/USD"]
[270, {"b": [["11645.80000", "0.25000000", "1596666747.938977"]], "c": "373323166"}, "book-100", "XBT/USD"]
[270, {"a": [["11652.90000", "0.41352978", "1596666747.941828"]], "c": "340160934"}, "book-100", "XBT/USD"]
[270, {"a": [["11686.90000", "0.00000000", "1596666747.963088"], ["11692.70000", "1.75400000", "1596666164.005133", "r"]], "c": "340160934"}, "book-100", "XBT/USD"]
[270, {"b": [["11603.00000", "0.00000000", "1596666747.982639"], ["11596.30000", "19.40000000", "1596666706.107317", "r"]], "c": "340160934"}, "book-100", "XBT/USD"]
[270, {"a": [["11653.30000", "0.00000000", "1596666747.996434"], ["11693.30000", "0.48410000", "1596666703.085185", "r"]], "c": "1626448177"}, "book-100", "XBT/USD"]
[270, {"a": [["11691.00000", "0.55961699", "1596666748.037839"]], "c": "1626448177"}, "book-100", "XBT/USD"]
[270, {"b": [["11617.00000", "1.11290000", "1596666748.063667"]], "c": "1626448177"}, "book-100", "XBT/USD"]
[270, {"a": [["11653.30000", "0.25872002", "1596666748.096037"]], "c": "3478369482"}, "book-100", "XBT/USD"]
[270, {"a": [["11666.10000", "0.05313798", "1596666748.105927"]], "c": "3478369482"}, "book-100", "XBT/USD"]
[270, {"a": [["11662.10000", "0.00000000", "1596666748.110768"], ["11692.30000", "8.50000000", "1596666502.813701", "r"]], "c": "3478369482"}, "book-100", "XBT/USD"]
[270, {"b": [["11625.40000", "2.01373762", "1596666748.155899"]], "c": "3478369482"}, "book-100", "XBT/USD"]
[270, {"b": [["11602.30000", "2.01774694", "1596666748.156295"]], "c": "3478369482"}, "book-100", "XBT/USD"]
[270, {"b": [["11613.80000", "2.01574896", "1596666748.158110"]], "c": "3478369482"}, "book-100", "XBT/USD"]
[270, {"b": [["11631.20000", "9.12064407", "1596666748.160345"]], "c": "3478369482"}, "book-100", "XBT/USD"]
[271, [["11649.50000", "0.02300088", "1596666748.199665", "s", "m", ""]], "trade", "XBT/USD"]
[270, {"b": [["11649.50000", "0.88940912", "1596666748.199665"]], "c": "152297514"}, "book-100", "XBT/USD"]
[270, {"b": [["11610.80000", "5.95478606", "1596666748.215457"]], "c": "152297514"}, "book-100", "XBT/USD"]
[270, {"a": [["11653.40000", "4.28900000", "1596666748.281046"]], "c": "234475702"}, "book-100", "XBT/USD"]
[270, {"b": [["11649.40000", "0.22334000", "1596666748.281640"]], "c": "806232624"}, "book-100", "XBT/USD"]
[270, {"a": [["11672.10000", "6.23733107", "1596666748.293537"]], "c": "806232624"}, "book-100", "XBT/USD"]
[270, {"a": [["11661.70000", "0.33878848", "1596666748.308983"]], "c": "806232624"}, "book-100", "XBT/USD"]
[270, {"b": [["11622.90000", "2.32914686", "1596666748.312661"]], "c": "806232624"}, "book-100", "XBT/USD"]
[270, {"b": [["11625.20000", "0.71368959", "1596666748.316521"]], "c": "806232624"}, "book-100", "XBT/USD"]
[270, {"b": [["11628.50000", "0.33975574", "1596666748.320345"]], "c": "806232624"}, "book-100", "XBT/USD"]
[270, {"a": [["11665.00000", "4.75931454", "1596666748.334362"]], "c": "806232624"}, "book-100", "XBT/USD"]
[270, {"b": [["11634.80000", "0.85833759", "1596666748.342203"]], "c": "806232624"}, "book-100", "XBT/USD"]
[270, {"a": [["11650.80000", "0.64375319", "1596666748.353793"]], "c": "1838231563"}, "book-100", "XBT/USD"]
[270, {"b": [["11647.60000", "0.00000000", "1596666748.382208"], ["11601.00000", "0.17085000", "1596666692.102814", "r"]], "c": "2573644649"}, "book-100", "XBT/USD"]
[270, {"b": [["11613.90000", "0.02884034", "1596666748.382350"]], "c": "2573644649"}, "book-100", "XBT/USD"]
[270, {"a": [["11660.30000", "0.00000000", "1596666748.409668"], ["11691.90000", "0.89806591", "1596666649.630348", "r"]], "c": "2573644649"}, "book-100", "XBT/USD"]
[270, {"b": [["11634.60000", "0.02682840", "1596666748.492587"]], "c": "2573644649"}, "book-100", "XBT/USD"]
[270, {"b": [["11634.80000", "0.00000000", "1596666748.493513"], ["11601.40000", "13.94256021", "1596666708.975741", "r"]], "c": "2573644649"}, "book-100", "XBT/USD"]
[270, {"b": [["11649.30000", "0.00000000", "1596666748.493574"], ["11601.00000", "0.17085000", "1596666692.102814", "r"]], "c": "3135150278"}, "book-100", "XBT/USD"]
[270, {"b": [["11635.20000", "0.00000000", "1596666748.494524"], ["11600.90000", "1.03470000", "1596666745.340027", "r"]], "c": "3135150278"}, "book-100", "XBT/USD"]
[270, {"a": [["11649.90000", "0.00000000", "1596666748.639492"], ["11692.10000", "4.49523792", "1596666702.300008", "r"]], "c": "3533779648"}, "book-100", "XBT/USD"]
[270, {"a": [["11672.00000", "0.59872878", "1596666748.792278"]], "c": "3533779648"}, "book-100", "XBT/USD"]
[270, {"b": [["11645.90000", "4.28100000", "1596666748.814922"]], "c": "1062325360"}, "book-100", "XBT/USD"]
[270, {"b": [["11630.20000", "0.00441992", "1596666748.837766"]], "c": "1062325360"}, "book-100", "XBT/USD"]
[270, {"a": [["11667.20000", "0.00438186", "1596666748.839243"]], "c": "1062325360"}, "book-100", "XBT/USD"]
[270, {"a": [["11649.80000", "0.00000000", "1596666748.908627"], ["11691.90000", "0.89806591", "1596666649.630348", "r"]], "c": "267271160"}, "book-100", "XBT/USD"]
[270, {"a": [["11649.80000", "0.25000000", "1596666748.952659"]], "c": "2695395412"}, "book-100", "XBT/USD"]
[270, {"a": [["11649.70000", "0.47175810", "1596666748.970989"]], "c": "3867408582"}, "book-100", "XBT/USD"]
[270, {"a": [["11649.90000", "0.12134020", "1596666749.067069"]], "c": "1053132344"}, "book-100", "XBT/USD"]
[270, {"b": [["11622.90000", "0.90148523", "1596666749.245939"]], "c": "1053132344"}, "book-100", "XBT/USD"]
[270, {"b": [["11604.90000", "0.00000000", "1596666749.246597"], ["11601.00000", "0.17085000", "1596666692.102814", "r"]], "c": "1053132344"}, "book-100", "XBT/USD"]
[270, {"b": [["11628.50000", "0.00000000", "1596666749.250310"], ["11600.90000", "1.03470000", "1596666745.340027", "r"]], "c": "1053132344"}, "book-100", "XBT/USD"]
[270, {"a": [["11649.60000", "0.23000000", "1596666749.253731"]], "c": "1028598236"}, "book-100", "XBT/USD"]
[270, {"a": [["11654.30000", "0.00000000", "1596666749.270900"], ["11691.00000", "0.55961699", "1596666748.037839", "r"]], "c": "1028598236"}, "book-100", "XBT/USD"]
[270, {"a": [["11649.90000", "0.00000000", "1596666749.328866"], ["11691.30000", "2.00311243", "1596666619.337977", "r"]], "c": "206124978"}, "book-100", "XBT/USD"]
[270, {"b": [["11625.20000", "0.00000000", "1596666749.371426"], ["11600.10000", "0.05000000", "1596666747.910313", "r"]], "c": "206124978"}, "book-100", "XBT/USD"]
[270, {"a": [["11649.80000", "0.00000000", "1596666749.476734"], ["11691.60000", "2.80491857", "1596666648.819519", "r"]], "c": "2354071302"}, "book-100", "XBT/USD"]
[270, {"a": [["11649.60000", "0.35131357", "1596666749.532923"]], "c": "3682718383"}, "book-100", "XBT/USD"]
[270, {"b": [["11616.40000", "0.00000000", "1596666749.677066"], ["11600.00000", "0.02931034", "1596666720.289823", "r"]], "c": "3682718383"}, "book-100", "XBT/USD"]
[270, {"a": [["11685.60000", "0.00000000", "1596666749.682585"], ["11691.90000", "0.89806591", "1596666649.630348", "r"]], "c": "3682718383"}, "book-100", "XBT/USD"]
[270, {"b": [["11649.40000", "0.00000000", "1596666749.720144"], ["11599.70000", "0.00900000", "1596666739.190302", "r"]], "c": "2143999364"}, "book-100", "XBT/USD"]
[270, {"b": [["11635.90000", "1.42606660", "1596666749.720839"]], "c": "2143999364"}, "book-100", "XBT/USD"]
[270, {"b": [["11649.50000", "0.67799912", "1596666749.722199"]], "c": "3519742458"}, "book-100", "XBT/USD"]
[270, {"b": [["11618.50000", "1.97227936", "1596666749.725325"]], "c": "3519742458"}, "book-100", "XBT/USD"]
[270, {"b": [["11641.60000", "0.33937342", "1596666749.728904"]], "c": "3519742458"}, "book-100", "XBT/USD"]
[270, {"b": [["11604.20000", "0.00000000", "1596666749.787632"], ["11600.10000", "0.05000000", "1596666747.910313", "r"]], "c": "3519742458"}, "book-100", "XBT/USD"]
[270, {"b": [["11606.90000", "2.82522050", "1596666749.873906"]], "c": "3519742458"}, "book-100", "XBT/USD"]
[270, {"b": [["11638.20000", "1.57166547", "1596666749.889149"]], "c": "3519742458"}, "book-100", "XBT/USD"]
[270, {"b": [["11649.30000", "0.21917000", "1596666750.021049"]], "c": "1062648143"}, "book-100", "XBT/USD"]
[270, {"b": [["11630.10000", "10.43145769", "1596666750.060899"]], "c": "1062648143"}, "book-100", "XBT/USD"]
[270, {"a": [["11653.30000", "0.00000000", "1596666750.176703"], ["11692.10000", "4.49523792", "1596666702.300008", "r"]], "c": "1607766000"}, "book-100", "XBT/USD"]
[270, {"a": [["11649.60000", "0.23000000", "1596666750.196801"]], "c": "134552153"}, "book-100", "XBT/USD"]
[270, {"a": [["11657.20000", "0.85886294", "1596666750.210802"]], "c": "134552153"}, "book-100", "XBT/USD"]
[270, {"a": [["11654.50000", "1.71500000", "1596666750.222812"]], "c": "134552153"}, "book-100", "XBT/USD"]
[270, {"b": [["11645.50000", "0.00000000", "1596666750.223389"], ["11600.90000", "1.03470000", "1596666745.340027", "r"]], "c": "1522768273"}, "book-100", "XBT/USD"]
[270, {"a": [["11652.40000", "0.25873390", "1596666750.272443"]], "c": "3465439987"}, "book-100", "XBT/USD"]
[270, {"b": [["11646.30000", "1.71100000", "1596666750.275984"]], "c": "2082483195"}, "book-100", "XBT/USD"]
[270, {"a": [["11668.10000", "0.75004199", "1596666750.289323"]], "c": "2082483195"}, "book-100", "XBT/USD"]
[270, {"b": [["11618.20000", "0.00000000", "1596666750.373321"], ["11600.90000", "1.03470000", "1596666745.340027", "r"]], "c": "2082483195"}, "book-100", "XBT/USD"]
[270, {"a": [["11652.50000", "0.00000000", "1596666750.571948"], ["11691.90000", "0.89806591", "1596666649.630348", "r"]], "c": "2471086420"}, "book-100", "XBT/USD"]
[270, {"a": [["11668.10000", "0.00000000", "1596666750.604313"], ["11692.10000", "4.49523792", "1596666702.300008", "r"]], "c": "2471086420"}, "book-100", "XBT/USD"]
[270, {"a": [["11650.30000", "0.64376130", "1596666750.640245"]], "c": "3584368818"}, "book-100", "XBT/USD"]
[270, {"a": [["11654.70000", "0.85834840", "1596666750.640381"]], "c": "3584368818"}, "book-100", "XBT/USD"]
[270, {"b": [["11649.00000", "0.64374879", "1596666750.641988"]], "c": "3493709576"}, "book-100", "XBT/USD"]
[270, {"b": [["11646.80000", "0.64375319", "1596666750.643143"]], "c": "2465554453"}, "book-100", "XBT/USD"]
[270, {"b": [["11634.60000", "0.00000000", "1596666750.708580"], ["11601.00000", "0.17085000", "1596666692.102814", "r"]], "c": "2465554453"}, "book-100", "XBT/USD"]
[270, {"b": [["11635.20000", "0.02739939", "1596666750.718657"]], "c": "2465554453"}, "book-100", "XBT/USD"]
[270, {"a": [["11656.90000", "0.07467100", "1596666750.762266"]], "c": "2465554453"}, "book-100", "XBT/USD"]
[270, {"b": [["11643.80000", "0.00000000", "1596666750.841537"], ["11601.00000", "0.17085000", "1596666692.102814", "r"]], "c": "2465554453"}, "book-100", "XBT/USD"]
[270, {"b": [["11635.20000", "0.00000000", "1596666750.844986"], ["11600.90000", "1.03470000", "1596666745.340027", "r"]], "c": "2465554453"}, "book-100", "XBT/USD"]
[270, {"b": [["11635.50000", "0.02682839", "1596666750.851808"]], "c": "2465554453"}, "book-100", "XBT/USD"]
[270, {"b": [["11639.40000", "0.43900000", "1596666750.868759"]], "c": "2465554453"}, "book-100", "XBT/USD"]
[270, {"a": [["11656.80000", "1.34258313", "1596666750.979290"]], "c": "2465554453"}, "book-100", "XBT/USD"]
[270, {"b": [["11649.40000", "0.21916000", "1596666751.022642"]], "c": "1148928589"}, "book-100", "XBT/USD"]
[270, {"b": [["11631.40000", "3.21254778", "1596666751.211647"]], "c": "1148928589"}, "book-100", "XBT/USD"]
[270, {"a": [["11656.80000", "0.00000000", "1596666751.292009"], ["11691.60000", "2.80491857", "1596666648.819519", "r"]], "c": "1148928589"}, "book-100", "XBT/USD"]
[270, {"a": [["11658.10000", "3.10000000", "1596666751.326786"]], "c": "1148928589"}, "book-100", "XBT/USD"]
[270, {"b": [["11620.30000", "7.11349884", "1596666751.347805"]], "c": "1148928589"}, "book-100", "XBT/USD"]
[270, {"a": [["11656.70000", "1.28803383", "1596666751.490493"]], "c": "1148928589"}, "book-100", "XBT/USD"]
[270, {"b": [["11618.90000", "0.49800000", "1596666751.560807"]], "c": "1148928589"}, "book-100", "XBT/USD"]
[270, {"b": [["11630.20000", "0.00000000", "1596666751.689580"], ["11602.30000", "2.01774694", "1596666748.156295", "r"]], "c": "1148928589"}, "book-100", "XBT/USD"]
[270, {"a": [["11667.20000", "0.00000000", "1596666751.690178"], ["11691.60000", "2.80491857", "1596666648.819519", "r"]], "c": "1148928589"}, "book-100", "XBT/USD"]
[270, {"b": [["11641.60000", "0.00000000", "1596666751.767785"], ["11602.20000", "2.01681621", "1596666634.588713", "r"]], "c": "1148928589"}, "book-100", "XBT/USD"]
[270, {"b": [["11638.20000", "0.85877308", "1596666751.770470"]], "c": "1148928589"}, "book-100", "XBT/USD"]
[270, {"a": [["11654.00000", "1.50000000", "1596666751.896208"]], "c": "1148928589"}, "book-100", "XBT/USD"]
[270, {"b": [["11645.20000", "0.22100000", "1596666752.028363"]], "c": "1148928589"}, "book-100", "XBT/USD"]
[271, [["11649.60000", "0.23000000", "1596666752.032125", "b", "l", ""], ["11649.70000", "0.47175810", "1596666752.035130", "b", "l", ""], ["11650.00000", "0.38332906", "1596666752.036551", "b", "l", ""], ["11650.30000", "0.20230073", "1596666752.038043", "b", "l", ""]], "trade", "XBT/USD"]
[270, {"a": [["11649.60000", "0.00000000", "1596666752.032125"], ["11691.60000", "2.80491857", "1596666648.819519", "r"], ["11649.70000", "0.00000000", "1596666752.035131"], ["11691.90000", "0.89806591", "1596666649.630348", "r"], ["11650.00000", "0.00015670", "1596666752.036551"], ["11650.00000", "0.00000000", "1596666752.037824"], ["11692.10000", "4.49523792", "1596666702.300008", "r"], ["11650.30000", "0.44146057", "1596666752.038043"]], "c": "2555209578"}, "book-100", "XBT/USD"]
[270, {"a": [["11650.30000", "0.00000000", "1596666752.094340"], ["11692.30000", "8.50000000", "1596666502.813701", "r"]], "c": "1966759430"}, "book-100", "XBT/USD"]
[270, {"a": [["11652.90000", "0.00000000", "1596666752.128176"], ["11692.70000", "1.75400000", "1596666164.005133", "r"]], "c": "4162570828"}, "book-100", "XBT/USD"]
[270, {"b": [["11638.10000", "0.29487739", "1596666752.144378"]], "c": "4162570828"}, "book-100", "XBT/USD"]
[270, {"a": [["11656.90000", "0.00000000", "1596666752.176064"], ["11693.30000", "0.48410000", "1596666703.085185", "r"]], "c": "4162570828"}, "book-100", "XBT/USD"]
[270, {"a": [["11653.30000", "0.75551922", "1596666752.182682"]], "c": "2548241615"}, "book-100", "XBT/USD"]
[270, {"b": [["11634.50000", "0.00000000", "1596666752.188102"], ["11602.10000", "7.70000000", "1596666410.902600", "r"]], "c": "2548241615"}, "book-100", "XBT/USD"]
[270, {"a": [["11652.40000", "0.00000000", "1596666752.215109"], ["11693.30000", "0.48410000", "1596666703.085185", "r"]], "c": "3484179585"}, "book-100", "XBT/USD"]
[270, {"a": [["11662.60000", "0.83923000", "1596666752.235408"]], "c": "3484179585"}, "book-100", "XBT/USD"]
[270, {"a": [["11650.80000", "0.00000000", "1596666752.288755"], ["11693.30000", "0.48410000", "1596666703.085185", "r"]], "c": "399972311"}, "book-100", "XBT/USD"]
[270, {"a": [["11656.10000", "0.00000000", "1596666752.289897"], ["11693.70000", "1.16987239", "1596666701.085240", "r"]], "c": "399972311"}, "book-100", "XBT/USD"]
[270, {"a": [["11654.30000", "0.41352978", "1596666752.302722"]], "c": "2624360843"}, "book-100", "XBT/USD"]
[270, {"a": [["11650.70000", "0.12138811", "1596666752.322935"]], "c": "1840244660"}, "book-100", "XBT/USD"]
[270, {"a": [["11656.60000", "0.01000000", "1596666752.341806"]], "c": "1840244660"}, "book-100", "XBT/USD"]
[270, {"b": [["11645.20000", "0.13850000", "1596666752.418543"]], "c": "1840244660"}, "book-100", "XBT/USD"]
[270, {"b": [["11637.30000", "0.00000000", "1596666752.596941"], ["11601.40000", "13.94256021", "1596666708.975741", "r"]], "c": "1840244660"}, "book-100", "XBT/USD"]
[270, {"b": [["11649.60000", "2.20000000", "1596666752.607591"]], "c": "1449909391"}, "book-100", "XBT/USD"]
[270, {"a": [["11656.70000", "0.00000000", "1596666752.615366"], ["11692.70000", "1.75400000", "1596666164.005133", "r"]], "c": "1449909391"}, "book-100", "XBT/USD"]
[270, {"b": [["11645.80000", "0.00000000", "1596666752.620634"], ["11601.40000", "13.94256021", "1596666708.975741", "r"]], "c": "1449909391"}, "book-100", "XBT/USD"]
[270, {"a": [["11653.20000", "0.25872529", "1596666752.622778"]], "c": "819887354"}, "book-100", "XBT/USD"]
[270, {"b": [["11646.30000", "0.00000000", "1596666752.649732"], ["11601.00000", "0.17085000", "1596666692.102814", "r"]], "c": "1396028650"}, "book-100", "XBT/USD"]
[270, {"a": [["11664.00000", "5.70000000", "1596666752.653475"]], "c": "1396028650"}, "book-100", "XBT/USD"]
[270, {"a": [["11654.50000", "0.00000000", "1596666752.657619"], ["11692.30000", "8.50000000", "1596666502.813701", "r"]], "c": "1396028650"}, "book-100", "XBT/USD"]
[270, {"a": [["11653.30000", "0.00000000", "1596666752.670504"], ["11692.70000", "1.75400000", "1596666164.005133", "r"]], "c": "235037119"}, "book-100", "XBT/USD"]
[270, {"a": [["11656.60000", "0.00000000", "1596666752.682793"], ["11693.30000", "0.48410000", "1596666703.085185", "r"]], "c": "235037119"}, "book-100", "XBT/USD"]
[270, {"b": [["11649.60000", "0.00000000", "1596666752.683016"], ["11600.90000", "1.03470000", "1596666745.340027", "r"]], "c": "2967934596"}, "book-100", "XBT/USD"]
[270, {"a": [["11650.70000", "0.00000000", "1596666752.732237"], ["11693.70000", "1.16987239", "1596666701.085240", "r"]], "c": "1887802960"}, "book-100", "XBT/USD"]
[270, {"a": [["11651.60000", "0.12136553", "1596666752.732419"]], "c": "1255821895"}, "book-100", "XBT/USD"]
[270, {"b": [["11606.20000", "0.75003603", "1596666752.736623"]], "c": "1255821895"}, "book-100", "XBT/USD"]
[270, {"a": [["11656.90000", "0.01000000", "1596666752.737682"]], "c": "1255821895"}, "book-100", "XBT/USD"]
[270, {"a": [["11666.20000", "0.85003603", "1596666752.740851"]], "c": "1255821895"}, "book-100", "XBT/USD"]
[270, {"b": [["11645.90000", "0.00000000", "1596666752.766682"], ["11600.90000", "1.03470000", "1596666745.340027", "r"]], "c": "2907514731"}, "book-100", "XBT/USD"]
[270, {"b": [["11637.50000", "0.13438685", "1596666752.772575"]], "c": "2907514731"}, "book-100", "XBT/USD"]
[270, {"b": [["11646.80000", "0.89375319", "1596666752.825656"]], "c": "377380982"}, "book-100", "XBT/USD"]
[270, {"a": [["11662.10000", "1.36609684", "1596666752.869627"]], "c": "377380982"}, "book-100", "XBT/USD"]
[270, {"a": [["11649.60000", "0.42140041", "1596666753.107437"]], "c": "1592415007"}, "book-100", "XBT/USD"]
[270, {"a": [["11683.60000", "0.00000000", "1596666753.341847"], ["11692.30000", "8.50000000", "1596666502.813701", "r"]], "c": "1592415007"}, "book-100", "XBT/USD"]
[270, {"b": [["11648.40000", "0.64370427", "1596666753.419154"]], "c": "3026648727"}, "book-100", "XBT/USD"]
[270, {"b": [["11647.20000", "4.28600000", "1596666753.421413"]], "c": "3121152869"}, "book-100", "XBT/USD"]
[270, {"b": [["11645.30000", "0.08250000", "1596666753.468740"]], "c": "1706634348"}, "book-100", "XBT/USD"]
[270, {"a": [["11660.80000", "0.08250000", "1596666753.469694"]], "c": "1706634348"}, "book-100", "XBT/USD"]
[270, {"b": [["11649.50000", "0.89924912", "1596666753.528150"]], "c": "559036476"}, "book-100", "XBT/USD"]
[271, [["11649.50000", "0.07809993", "1596666753.563700", "s", "m", ""]], "trade", "XBT/USD"]
[270, {"b": [["11649.50000", "0.82114919", "1596666753.563700"]], "c": "3652716796"}, "book-100", "XBT/USD"]
[270, {"a": [["11651.60000", "0.00000000", "1596666753.624389"], ["11692.30000", "8.50000000", "1596666502.813701", "r"]], "c": "3081575605"}, "book-100", "XBT/USD"]
[270, {"a": [["11651.70000", "0.00000000", "1596666753.630743"], ["11692.70000", "1.75400000", "1596666164.005133", "r"]], "c": "3737628664"}, "book-100", "XBT/USD"]
[270, {"a": [["11653.30000", "0.75551922", "1596666753.684229"]], "c": "2698172161"}, "book-100", "XBT/USD"]
[270, {"a": [["11650.90000", "0.64373805", "1596666753.690597"]], "c": "1889671252"}, "book-100", "XBT/USD"]
[270, {"a": [["11651.30000", "0.64373547", "1596666753.690782"]], "c": "520594709"}, "book-100", "XBT/USD"]
[270, {"a": [["11653.00000", "0.64374206", "1596666753.691110"]], "c": "3127199526"}, "book-100", "XBT/USD"]
[270, {"b": [["11649.50000", "1.46489125", "1596666753.691252"]], "c": "3604649312"}, "book-100", "XBT/USD"]
[270, {"a": [["11653.30000", "0.00000000", "1596666753.740823"], ["11691.90000", "0.89806591", "1596666649.630348", "r"]], "c": "1351649097"}, "book-100", "XBT/USD"]
[270, {"b": [["11608.90000", "0.00000000", "1596666753.837390"], ["11601.40000", "13.94256021", "1596666708.975741", "r"]], "c": "1351649097"}, "book-100", "XBT/USD"]
[270, {"b": [["11617.30000", "0.70560000", "1596666753.909677"]], "c": "1351649097"}, "book-100", "XBT/USD"]
[270, {"b": [["11642.40000", "0.00000000", "1596666754.114102"], ["11601.40000", "13.94256021", "1596666708.975741", "r"]], "c": "1351649097"}, "book-100", "XBT/USD"]
[270, {"a": [["11654.60000", "0.09621094", "1596666754.358412"]], "c": "1351649097"}, "book-100", "XBT/USD"]
[270, {"a": [["11665.00000", "4.04806000", "1596666754.370385"]], "c": "1351649097"}, "book-100", "XBT/USD"]
[270, {"b": [["11646.10000", "0.09621094", "1596666754.404187"]], "c": "3163311901"}, "book-100", "XBT/USD"]
[270, {"a": [["11652.30000", "0.00000000", "1596666754.417312"], ["11691.90000", "0.89806591", "1596666649.630348", "r"]], "c": "4205884695"}, "book-100", "XBT/USD"]
[270, {"b": [["11646.80000", "0.64375319", "1596666754.431267"]], "c": "1351603693"}, "book-100", "XBT/USD"]
[270, {"a": [["11661.70000", "0.00000000", "1596666754.537204"], ["11692.10000", "4.49523792", "1596666702.300008", "r"]], "c": "1351603693"}, "book-100", "XBT/USD"]
[270, {"b": [["11647.10000", "0.00000000", "1596666754.539210"], ["11601.40000", "13.94256021", "1596666708.975741", "r"]], "c": "3184925216"}, "book-100", "XBT/USD"]
[270, {"a": [["11649.60000", "0.00000000", "1596666754.587281"], ["11692.30000", "8.50000000", "1596666502.813701", "r"]], "c": "660658161"}, "book-100", "XBT/USD"]
[270, {"b": [["11643.10000", "0.00000000", "1596666754.606034"], ["11601.00000", "0.17085000", "1596666692.102814", "r"]], "c": "660658161"}, "book-100", "XBT/USD"]
[270, {"b": [["11647.80000", "0.25000000", "1596666754.633302"]], "c": "4253669940"}, "book-100", "XBT/USD"]
[270, {"a": [["11650.90000", "0.00000000", "1596666754.675863"], ["11692.70000", "1.75400000", "1596666164.005133", "r"]], "c": "4258757833"}, "book-100", "XBT/USD"]
[270, {"a": [["11653.20000", "0.00000000", "1596666754.722776"], ["11693.30000", "0.48410000", "1596666703.085185", "r"]], "c": "1407418378"}, "book-100", "XBT/USD"]
[270, {"b": [["11648.20000", "0.42900000", "1596666754.803529"]], "c": "917501734"}, "book-100", "XBT/USD"]
[270, {"b": [["11642.40000", "0.33937298", "1596666754.814260"]], "c": "917501734"}, "book-100", "XBT/USD"]
