{"type":"received","side":"buy","product_id":"BTC-USD","time":"2020-06-30T19:17:18.232257Z","sequence":180757341,"order_id":"07af6f81-6d5c-42f2-8cbc-3ab06374eafc","order_type":"limit","size":"0.01","price":"9084.37","client_oid":""}
{"type":"open","side":"buy","product_id":"BTC-USD","time":"2020-06-30T19:17:18.232257Z","sequence":180757342,"price":"9084.37","order_id":"07af6f81-6d5c-42f2-8cbc-3ab06374eafc","remaining_size":"0.01"}
{"type":"done","side":"buy","product_id":"BTC-USD","time":"2020-06-30T19:17:18.673572Z","sequence":180757343,"order_id":"4b66e3df-9a94-452c-8b72-69732f8020aa","reason":"canceled","price":"9111.5","remaining_size":"0.0222"}
{"type":"heartbeat","last_trade_id":0,"product_id":"BTC-USD","sequence":180757343,"time":"2020-06-30T19:17:18.735095Z"}
{"type":"received","side":"sell","product_id":"BTC-USD","time":"2020-06-30T19:17:18.746911Z","sequence":180757344,"order_id":"33b39cb0-d6c0-4df4-9aa1-edefc646f6ee","order_type":"limit","size":"0.6087","price":"9121.09","client_oid":""}
{"type":"open","side":"sell","product_id":"BTC-USD","time":"2020-06-30T19:17:18.746911Z","sequence":180757345,"price":"9121.09","order_id":"33b39cb0-d6c0-4df4-9aa1-edefc646f6ee","remaining_size":"0.6087"}
{"type":"received","side":"sell","product_id":"BTC-USD","time":"2020-06-30T19:17:19.303556Z","sequence":180757346,"order_id":"a2f2f5ef-0af9-449b-8378-2fc541b74043","order_type":"limit","size":"0.069","price":"9155.64","client_oid":""}
{"type":"open","side":"sell","product_id":"BTC-USD","time":"2020-06-30T19:17:19.303556Z","sequence":180757347,"price":"9155.64","order_id":"a2f2f5ef-0af9-449b-8378-2fc541b74043","remaining_size":"0.069"}
{"type":"received","side":"sell","product_id":"BTC-USD","time":"2020-06-30T19:17:19.563730Z","sequence":180757348,"order_id":"8ab6da45-2080-42a2-98b9-28d0d317a595","order_type":"limit","size":"0.1","price":"9121.07","client_oid":""}
{"type":"open","side":"sell","product_id":"BTC-USD","time":"2020-06-30T19:17:19.563730Z","sequence":180757349,"price":"9121.07","order_id":"8ab6da45-2080-42a2-98b9-28d0d317a595","remaining_size":"0.1"}
{"type":"done","side":"sell","product_id":"BTC-USD","time":"2020-06-30T19:17:19.736383Z","sequence":180757350,"order_id":"816f25d3-e270-4578-aed1-bbd85baf6243","reason":"canceled","price":"9121.93","remaining_size":"0.035"}
{"type":"heartbeat","last_trade_id":0,"product_id":"BTC-USD","sequence":180757350,"time":"2020-06-30T19:17:19.735112Z"}
{"type":"received","side":"sell","product_id":"BTC-USD","time":"2020-06-30T19:17:19.850250Z","sequence":180757351,"order_id":"a4507b82-b700-4380-831b-315e1f3ad00f","order_type":"limit","size":"0.15","price":"9121.03","client_oid":""}
{"type":"open","side":"sell","product_id":"BTC-USD","time":"2020-06-30T19:17:19.850250Z","sequence":180757352,"price":"9121.03","order_id":"a4507b82-b700-4380-831b-315e1f3ad00f","remaining_size":"0.15"}
{"type":"done","side":"sell","product_id":"BTC-USD","time":"2020-06-30T19:17:19.987435Z","sequence":180757353,"order_id":"d5acdab5-c124-4046-8b3b-17cfcce45607","reason":"canceled","price":"9155.29","remaining_size":"0.0676"}
{"type":"received","side":"sell","product_id":"BTC-USD","time":"2020-06-30T19:17:20.135007Z","sequence":180757354,"order_id":"7884dabb-2682-41e7-89ed-8ffcc72014f2","order_type":"limit","size":"0.05","price":"9121.02","client_oid":""}
{"type":"open","side":"sell","product_id":"BTC-USD","time":"2020-06-30T19:17:20.135007Z","sequence":180757355,"price":"9121.02","order_id":"7884dabb-2682-41e7-89ed-8ffcc72014f2","remaining_size":"0.05"}
{"type":"received","side":"buy","product_id":"BTC-USD","time":"2020-06-30T19:17:20.407698Z","sequence":180757356,"order_id":"3d993838-b8e9-4fcb-aeeb-5c8c9173bae4","order_type":"limit","size":"2.9991","price":"9087.14","client_oid":""}
{"type":"open","side":"buy","product_id":"BTC-USD","time":"2020-06-30T19:17:20.407698Z","sequence":180757357,"price":"9087.14","order_id":"3d993838-b8e9-4fcb-aeeb-5c8c9173bae4","remaining_size":"2.9991"}
{"type":"received","side":"buy","product_id":"BTC-USD","time":"2020-06-30T19:17:20.690252Z","sequence":180757358,"order_id":"b49037c2-28ad-46bd-b6d6-835aa1602449","order_type":"limit","size":"0.5419","price":"9117.73","client_oid":""}
{"type":"open","side":"buy","product_id":"BTC-USD","time":"2020-06-30T19:17:20.690252Z","sequence":180757359,"price":"9117.73","order_id":"b49037c2-28ad-46bd-b6d6-835aa1602449","remaining_size":"0.5419"}
{"type":"heartbeat","last_trade_id":0,"product_id":"BTC-USD","sequence":180757359,"time":"2020-06-30T19:17:20.735067Z"}
{"type":"heartbeat","last_trade_id":0,"product_id":"BTC-USD","sequence":180757359,"time":"2020-06-30T19:17:21.735091Z"}
{"type":"received","side":"buy","product_id":"BTC-USD","time":"2020-06-30T19:17:22.357721Z","sequence":180757360,"order_id":"d9d4ac39-3ab9-4c47-b2a7-5072f1480999","order_type":"limit","size":"0.05","price":"9119.31","client_oid":""}
{"type":"open","side":"buy","product_id":"BTC-USD","time":"2020-06-30T19:17:22.357721Z","sequence":180757361,"price":"9119.31","order_id":"d9d4ac39-3ab9-4c47-b2a7-5072f1480999","remaining_size":"0.05"}
{"type":"received","side":"buy","product_id":"BTC-USD","time":"2020-06-30T19:17:22.613233Z","sequence":180757362,"order_id":"a84fa2dc-2d07-442c-a539-4c66203c9709","order_type":"limit","size":"0.5902","price":"9116.61","client_oid":""}
{"type":"open","side":"buy","product_id":"BTC-USD","time":"2020-06-30T19:17:22.613233Z","sequence":180757363,"price":"9116.61","order_id":"a84fa2dc-2d07-442c-a539-4c66203c9709","remaining_size":"0.5902"}
{"type":"heartbeat","last_trade_id":0,"product_id":"BTC-USD","sequence":180757363,"time":"2020-06-30T19:17:22.735117Z"}
{"type":"done","side":"buy","product_id":"BTC-USD","time":"2020-06-30T19:17:22.775235Z","sequence":180757364,"order_id":"b49037c2-28ad-46bd-b6d6-835aa1602449","reason":"canceled","price":"9117.73","remaining_size":"0.5419"}
{"type":"received","side":"buy","product_id":"BTC-USD","time":"2020-06-30T19:17:22.903752Z","sequence":180757365,"order_id":"5d91f6d8-164b-422f-89b6-8a1c46c5452e","order_type":"limit","size":"0.1243","price":"9119.78","client_oid":""}
{"type":"open","side":"buy","product_id":"BTC-USD","time":"2020-06-30T19:17:22.903752Z","sequence":180757366,"price":"9119.78","order_id":"5d91f6d8-164b-422f-89b6-8a1c46c5452e","remaining_size":"0.1243"}
{"type":"done","side":"buy","product_id":"BTC-USD","time":"2020-06-30T19:17:23.126434Z","sequence":180757367,"order_id":"9423a7a9-c9ba-4b61-9c96-62cf490d25df","reason":"canceled","price":"9117.47","remaining_size":"0.5"}
{"type":"received","side":"sell","product_id":"BTC-USD","time":"2020-06-30T19:17:23.449304Z","sequence":180757368,"order_id":"9e6eaa5a-2f2d-4bd7-b400-2e7e2bc94039","order_type":"limit","size":"0.0328","price":"9157.37","client_oid":""}
{"type":"open","side":"sell","product_id":"BTC-USD","time":"2020-06-30T19:17:23.449304Z","sequence":180757369,"price":"9157.37","order_id":"9e6eaa5a-2f2d-4bd7-b400-2e7e2bc94039","remaining_size":"0.0328"}
{"type":"heartbeat","last_trade_id":0,"product_id":"BTC-USD","sequence":180757369,"time":"2020-06-30T19:17:23.735121Z"}
{"type":"received","side":"buy","product_id":"BTC-USD","time":"2020-06-30T19:17:24.025209Z","sequence":180757370,"order_id":"c0dfca1f-0068-4837-9414-c87ae87aaa31","order_type":"limit","size":"0.05","price":"9119.66","client_oid":""}
{"type":"open","side":"buy","product_id":"BTC-USD","time":"2020-06-30T19:17:24.025209Z","sequence":180757371,"price":"9119.66","order_id":"c0dfca1f-0068-4837-9414-c87ae87aaa31","remaining_size":"0.05"}
{"type":"done","side":"buy","product_id":"BTC-USD","time":"2020-06-30T19:17:24.291115Z","sequence":180757372,"order_id":"e629f6f7-6f85-46d5-bf11-8caf5e19dabf","reason":"canceled","price":"9108.78","remaining_size":"0.0658"}
{"type":"received","side":"buy","product_id":"BTC-USD","time":"2020-06-30T19:17:24.339603Z","sequence":180757373,"order_id":"2302c71d-b09c-4448-bfea-cf2a8f7d65fd","order_type":"limit","size":"0.05","price":"9119.73","client_oid":""}
{"type":"open","side":"buy","product_id":"BTC-USD","time":"2020-06-30T19:17:24.339603Z","sequence":180757374,"price":"9119.73","order_id":"2302c71d-b09c-4448-bfea-cf2a8f7d65fd","remaining_size":"0.05"}
{"type":"heartbeat","last_trade_id":0,"product_id":"BTC-USD","sequence":180757374,"time":"2020-06-30T19:17:24.735118Z"}
{"type":"received","side":"buy","product_id":"BTC-USD","time":"2020-06-30T19:17:24.889156Z","sequence":180757375,"order_id":"0e860e23-7ea1-4be4-acc5-bf3fc9335955","order_type":"limit","size":"0.0658","price":"9120.3","client_oid":""}
{"type":"open","side":"buy","product_id":"BTC-USD","time":"2020-06-30T19:17:24.889156Z","sequence":180757376,"price":"9120.3","order_id":"0e860e23-7ea1-4be4-acc5-bf3fc9335955","remaining_size":"0.0658"}
{"type":"done","side":"buy","product_id":"BTC-USD","time":"2020-06-30T19:17:25.347059Z","sequence":180757377,"order_id":"55466822-82d3-4de3-bd5f-5b1e024096a9","reason":"canceled","price":"9094.08","remaining_size":"0.0567"}
{"type":"heartbeat","last_trade_id":0,"product_id":"BTC-USD","sequence":180757377,"time":"2020-06-30T19:17:25.735113Z"}
{"type":"received","side":"buy","product_id":"BTC-USD","time":"2020-06-30T19:17:26.094560Z","sequence":180757378,"order_id":"1420c9d9-52f5-48bc-80f6-e58a5dacef81","order_type":"limit","size":"0.001","price":"9121.02","client_oid":""}
{"type":"match","side":"sell","product_id":"BTC-USD","time":"2020-06-30T19:17:26.094560Z","sequence":180757379,"trade_id":14587663,"maker_order_id":"36fe0734-4801-466d-b093-cccd411db09a","taker_order_id":"1420c9d9-52f5-48bc-80f6-e58a5dacef81","size":"0.001","price":"9120.82"}
{"type":"done","side":"buy","product_id":"BTC-USD","time":"2020-06-30T19:17:26.094560Z","sequence":180757380,"order_id":"1420c9d9-52f5-48bc-80f6-e58a5dacef81","reason":"filled","price":"9121.02","remaining_size":"0"}
{"type":"received","side":"sell","product_id":"BTC-USD","time":"2020-06-30T19:17:26.646025Z","sequence":180757381,"order_id":"df6ae444-084e-4eb3-9f3b-bbb4a4a522a1","order_type":"limit","size":"2.5837","price":"9129.79","client_oid":""}
{"type":"open","side":"sell","product_id":"BTC-USD","time":"2020-06-30T19:17:26.646025Z","sequence":180757382,"price":"9129.79","order_id":"df6ae444-084e-4eb3-9f3b-bbb4a4a522a1","remaining_size":"2.5837"}
{"type":"received","side":"sell","product_id":"BTC-USD","time":"2020-06-30T19:17:26.693248Z","sequence":180757383,"order_id":"0fb0e0d4-5501-4bd1-a68b-5fbaf695fac6","order_type":"market","size":"0.01","client_oid":""}
{"type":"match","side":"buy","product_id":"BTC-USD","time":"2020-06-30T19:17:26.693248Z","sequence":180757384,"trade_id":14587664,"maker_order_id":"91b59a7c-6a07-4039-9536-21daf3cb3282","taker_order_id":"0fb0e0d4-5501-4bd1-a68b-5fbaf695fac6","size":"0.01","price":"9120.8"}
{"type":"done","side":"sell","product_id":"BTC-USD","time":"2020-06-30T19:17:26.693248Z","sequence":180757385,"order_id":"0fb0e0d4-5501-4bd1-a68b-5fbaf695fac6","reason":"filled","remaining_size":"0"}
{"type":"heartbeat","last_trade_id":0,"product_id":"BTC-USD","sequence":180757385,"time":"2020-06-30T19:17:26.735119Z"}
{"type":"received","side":"buy","product_id":"BTC-USD","time":"2020-06-30T19:17:26.917565Z","sequence":180757386,"order_id":"d6909703-6e28-4dcd-b145-6533357e41a6","order_type":"limit","size":"0.0017","price":"9120.25","client_oid":""}
{"type":"open","side":"buy","product_id":"BTC-USD","time":"2020-06-30T19:17:26.917565Z","sequence":180757387,"price":"9120.25","order_id":"d6909703-6e28-4dcd-b145-6533357e41a6","remaining_size":"0.0017"}
{"type":"done","side":"sell","product_id":"BTC-USD","time":"2020-06-30T19:17:26.942035Z","sequence":180757388,"order_id":"33b39cb0-d6c0-4df4-9aa1-edefc646f6ee","reason":"canceled","price":"9121.09","remaining_size":"0.6087"}
{"type":"done","side":"buy","product_id":"BTC-USD","time":"2020-06-30T19:17:27.128102Z","sequence":180757389,"order_id":"3d993838-b8e9-4fcb-aeeb-5c8c9173bae4","reason":"canceled","price":"9087.14","remaining_size":"2.9991"}
{"type":"received","side":"buy","product_id":"BTC-USD","time":"2020-06-30T19:17:27.469133Z","sequence":180757390,"order_id":"92133e7f-fcf9-41e2-a237-90875aa0510a","order_type":"limit","size":"0.371","price":"9115.62","client_oid":""}
{"type":"open","side":"buy","product_id":"BTC-USD","time":"2020-06-30T19:17:27.469133Z","sequence":180757391,"price":"9115.62","order_id":"92133e7f-fcf9-41e2-a237-90875aa0510a","remaining_size":"0.371"}
{"type":"heartbeat","last_trade_id":0,"product_id":"BTC-USD","sequence":180757391,"time":"2020-06-30T19:17:27.735116Z"}
{"type":"received","side":"buy","product_id":"BTC-USD","time":"2020-06-30T19:17:28.185299Z","sequence":180757392,"order_id":"c2f8406b-2490-42eb-a77d-50775923b7ec","order_type":"limit","size":"0.5","price":"9119.59","client_oid":""}
{"type":"open","side":"buy","product_id":"BTC-USD","time":"2020-06-30T19:17:28.185299Z","sequence":180757393,"price":"9119.59","order_id":"c2f8406b-2490-42eb-a77d-50775923b7ec","remaining_size":"0.5"}
{"type":"received","side":"buy","product_id":"BTC-USD","time":"2020-06-30T19:17:28.740171Z","sequence":180757394,"order_id":"e5922720-e2c3-41a6-b2cc-afbd787b181b","order_type":"limit","size":"0.01","price":"9088.73","client_oid":""}
{"type":"open","side":"buy","product_id":"BTC-USD","time":"2020-06-30T19:17:28.740171Z","sequence":180757395,"price":"9088.73","order_id":"e5922720-e2c3-41a6-b2cc-afbd787b181b","remaining_size":"0.01"}
{"type":"heartbeat","last_trade_id":0,"product_id":"BTC-USD","sequence":180757395,"time":"2020-06-30T19:17:28.735069Z"}
{"type":"received","side":"buy","product_id":"BTC-USD","time":"2020-06-30T19:17:29.014927Z","sequence":180757396,"order_id":"4c1b62b9-a399-4578-86f1-157439ffe3cd","order_type":"limit","size":"0.01","price":"100","client_oid":"7f21e174-1f53-49d4-895b-26b327eca526"}
{"type":"open","side":"buy","product_id":"BTC-USD","time":"2020-06-30T19:17:29.014927Z","sequence":180757397,"price":"100","order_id":"4c1b62b9-a399-4578-86f1-157439ffe3cd","remaining_size":"0.01"}
{"type":"done","side":"buy","product_id":"BTC-USD","time":"2020-06-30T19:17:29.024193Z","sequence":180757398,"order_id":"4c1b62b9-a399-4578-86f1-157439ffe3cd","reason":"canceled","price":"100","remaining_size":"0.01"}
{"type":"received","side":"sell","product_id":"BTC-USD","time":"2020-06-30T19:17:29.288198Z","sequence":180757399,"order_id":"51f4d44c-d6ab-4197-8d39-f51a4b4a38b2","order_type":"limit","size":"0.05","price":"9121.31","client_oid":""}
{"type":"open","side":"sell","product_id":"BTC-USD","time":"2020-06-30T19:17:29.288198Z","sequence":180757400,"price":"9121.31","order_id":"51f4d44c-d6ab-4197-8d39-f51a4b4a38b2","remaining_size":"0.05"}
{"type":"done","side":"sell","product_id":"BTC-USD","time":"2020-06-30T19:17:29.742875Z","sequence":180757401,"order_id":"7884dabb-2682-41e7-89ed-8ffcc72014f2","reason":"canceled","price":"9121.02","remaining_size":"0.05"}
{"type":"heartbeat","last_trade_id":0,"product_id":"BTC-USD","sequence":180757401,"time":"2020-06-30T19:17:29.735097Z"}
{"type":"received","side":"buy","product_id":"BTC-USD","time":"2020-06-30T19:17:29.842335Z","sequence":180757402,"order_id":"589c816b-b5a4-46af-aae4-ff3a490fd3be","order_type":"limit","size":"0.0658","price":"9120.28","client_oid":""}
{"type":"open","side":"buy","product_id":"BTC-USD","time":"2020-06-30T19:17:29.842335Z","sequence":180757403,"price":"9120.28","order_id":"589c816b-b5a4-46af-aae4-ff3a490fd3be","remaining_size":"0.0658"}
{"type":"received","side":"buy","product_id":"BTC-USD","time":"2020-06-30T19:17:30.101837Z","sequence":180757404,"order_id":"242cd79b-ec82-4554-9285-9572b655e577","order_type":"limit","size":"0.004","price":"8930.31","client_oid":""}
{"type":"open","side":"buy","product_id":"BTC-USD","time":"2020-06-30T19:17:30.101837Z","sequence":180757405,"price":"8930.31","order_id":"242cd79b-ec82-4554-9285-9572b655e577","remaining_size":"0.004"}
{"type":"done","side":"buy","product_id":"BTC-USD","time":"2020-06-30T19:17:30.292974Z","sequence":180757406,"order_id":"07af6f81-6d5c-42f2-8cbc-3ab06374eafc","reason":"canceled","price":"9084.37","remaining_size":"0.01"}
{"type":"done","side":"buy","product_id":"BTC-USD","time":"2020-06-30T19:17:30.519346Z","sequence":180757407,"order_id":"c0dfca1f-0068-4837-9414-c87ae87aaa31","reason":"canceled","price":"9119.66","remaining_size":"0.05"}
{"type":"heartbeat","last_trade_id":0,"product_id":"BTC-USD","sequence":180757407,"time":"2020-06-30T19:17:30.735105Z"}
{"type":"received","side":"sell","product_id":"BTC-USD","time":"2020-06-30T19:17:31.277028Z","sequence":180757408,"order_id":"75109e77-1b95-4461-8d41-fc6bc14a70bf","order_type":"limit","size":"1.5516","price":"9129.79","client_oid":""}
{"type":"open","side":"sell","product_id":"BTC-USD","time":"2020-06-30T19:17:31.277028Z","sequence":180757409,"price":"9129.79","order_id":"75109e77-1b95-4461-8d41-fc6bc14a70bf","remaining_size":"1.5516"}
{"type":"heartbeat","last_trade_id":0,"product_id":"BTC-USD","sequence":180757409,"time":"2020-06-30T19:17:31.735120Z"}
{"type":"received","side":"buy","product_id":"BTC-USD","time":"2020-06-30T19:17:32.423494Z","sequence":180757410,"order_id":"a1a3fbdb-cce8-44f5-8617-13d27f86486f","order_type":"limit","size":"0.0658","price":"9114.74","client_oid":""}
{"type":"open","side":"buy","product_id":"BTC-USD","time":"2020-06-30T19:17:32.423494Z","sequence":180757411,"price":"9114.74","order_id":"a1a3fbdb-cce8-44f5-8617-13d27f86486f","remaining_size":"0.0658"}
{"type":"received","side":"buy","product_id":"BTC-USD","time":"2020-06-30T19:17:32.686577Z","sequence":180757412,"order_id":"e0ee4256-3989-4e0d-95e9-47306eb15425","order_type":"limit","size":"4.9798","price":"9121.02","client_oid":""}
{"type":"match","side":"sell","product_id":"BTC-USD","time":"2020-06-30T19:17:32.686577Z","sequence":180757413,"trade_id":14587665,"maker_order_id":"36fe0734-4801-466d-b093-cccd411db09a","taker_order_id":"e0ee4256-3989-4e0d-95e9-47306eb15425","size":"4.9798","price":"9120.82"}
{"type":"done","side":"buy","product_id":"BTC-USD","time":"2020-06-30T19:17:32.686577Z","sequence":180757414,"order_id":"e0ee4256-3989-4e0d-95e9-47306eb15425","reason":"filled","price":"9121.02","remaining_size":"0"}
{"type":"heartbeat","last_trade_id":0,"product_id":"BTC-USD","sequence":180757414,"time":"2020-06-30T19:17:32.735069Z"}
{"type":"done","side":"buy","product_id":"BTC-USD","time":"2020-06-30T19:17:32.862665Z","sequence":180757415,"order_id":"b4b0aadf-eda5-40df-b938-13f6775c4035","reason":"canceled","price":"9072.05","remaining_size":"0.01"}
{"type":"done","side":"buy","product_id":"BTC-USD","time":"2020-06-30T19:17:32.869070Z","sequence":180757416,"order_id":"242cd79b-ec82-4554-9285-9572b655e577","reason":"canceled","price":"8930.31","remaining_size":"0.004"}
{"type":"done","side":"buy","product_id":"BTC-USD","time":"2020-06-30T19:17:32.926026Z","sequence":180757417,"order_id":"7f0ef5d8-52e3-49dd-9f41-45e95ce31716","reason":"canceled","price":"9115.97","remaining_size":"0.0493"}
{"type":"heartbeat","last_trade_id":0,"product_id":"BTC-USD","sequence":180757417,"time":"2020-06-30T19:17:33.735090Z"}
{"type":"received","side":"sell","product_id":"BTC-USD","time":"2020-06-30T19:17:33.787404Z","sequence":180757418,"order_id":"5cb6befa-bb15-4170-827a-c9c7e7bba4ac","order_type":"limit","size":"1.1127","price":"9150.39","client_oid":""}
{"type":"open","side":"sell","product_id":"BTC-USD","time":"2020-06-30T19:17:33.787404Z","sequence":180757419,"price":"9150.39","order_id":"5cb6befa-bb15-4170-827a-c9c7e7bba4ac","remaining_size":"1.1127"}
{"type":"received","side":"sell","product_id":"BTC-USD","time":"2020-06-30T19:17:34.518423Z","sequence":180757420,"order_id":"17866525-73d1-442e-a124-b33095ab8977","order_type":"limit","size":"0.0546","price":"9154.34","client_oid":""}
{"type":"open","side":"sell","product_id":"BTC-USD","time":"2020-06-30T19:17:34.518423Z","sequence":180757421,"price":"9154.34","order_id":"17866525-73d1-442e-a124-b33095ab8977","remaining_size":"0.0546"}
{"type":"heartbeat","last_trade_id":0,"product_id":"BTC-USD","sequence":180757421,"time":"2020-06-30T19:17:34.735117Z"}
{"type":"done","side":"sell","product_id":"BTC-USD","time":"2020-06-30T19:17:34.923355Z","sequence":180757422,"order_id":"a2f2f5ef-0af9-449b-8378-2fc541b74043","reason":"canceled","price":"9155.64","remaining_size":"0.069"}
{"type":"done","side":"sell","product_id":"BTC-USD","time":"2020-06-30T19:17:34.925342Z","sequence":180757423,"order_id":"8ab6da45-2080-42a2-98b9-28d0d317a595","reason":"canceled","price":"9121.07","remaining_size":"0.1"}
{"type":"received","side":"buy","product_id":"BTC-USD","time":"2020-06-30T19:17:35.126683Z","sequence":180757424,"order_id":"af19a96b-fb49-4728-8533-e39851616d58","order_type":"limit","size":"8.9798","price":"9121.02","client_oid":""}
{"type":"match","side":"sell","product_id":"BTC-USD","time":"2020-06-30T19:17:35.126683Z","sequence":180757425,"trade_id":14587666,"maker_order_id":"36fe0734-4801-466d-b093-cccd411db09a","taker_order_id":"af19a96b-fb49-4728-8533-e39851616d58","size":"8.9798","price":"9120.82"}
{"type":"done","side":"buy","product_id":"BTC-USD","time":"2020-06-30T19:17:35.126683Z","sequence":180757426,"order_id":"af19a96b-fb49-4728-8533-e39851616d58","reason":"filled","price":"9121.02","remaining_size":"0"}
{"type":"done","side":"buy","product_id":"BTC-USD","time":"2020-06-30T19:17:35.547475Z","sequence":180757427,"order_id":"d6909703-6e28-4dcd-b145-6533357e41a6","reason":"canceled","price":"9120.25","remaining_size":"0.0017"}
{"type":"done","side":"buy","product_id":"BTC-USD","time":"2020-06-30T19:17:35.557635Z","sequence":180757428,"order_id":"60328261-934c-414b-89d0-85358c9b14f9","reason":"canceled","price":"9118.85","remaining_size":"0.9"}
{"type":"received","side":"buy","product_id":"BTC-USD","time":"2020-06-30T19:17:35.638033Z","sequence":180757429,"order_id":"48d2809b-dc6c-4b1b-b1aa-8d1286560e3c","order_type":"limit","size":"0.9","price":"9114.74","client_oid":""}
{"type":"open","side":"buy","product_id":"BTC-USD","time":"2020-06-30T19:17:35.638033Z","sequence":180757430,"price":"9114.74","order_id":"48d2809b-dc6c-4b1b-b1aa-8d1286560e3c","remaining_size":"0.9"}
{"type":"heartbeat","last_trade_id":0,"product_id":"BTC-USD","sequence":180757430,"time":"2020-06-30T19:17:35.735114Z"}
{"type":"received","side":"buy","product_id":"BTC-USD","time":"2020-06-30T19:17:35.926613Z","sequence":180757431,"order_id":"29becaa1-4cab-4b67-aafb-47bfb90a01a0","order_type":"limit","size":"0.0658","price":"9117.93","client_oid":""}
{"type":"open","side":"buy","product_id":"BTC-USD","time":"2020-06-30T19:17:35.926613Z","sequence":180757432,"price":"9117.93","order_id":"29becaa1-4cab-4b67-aafb-47bfb90a01a0","remaining_size":"0.0658"}
{"type":"done","side":"buy","product_id":"BTC-USD","time":"2020-06-30T19:17:36.156758Z","sequence":180757433,"order_id":"48d2809b-dc6c-4b1b-b1aa-8d1286560e3c","reason":"canceled","price":"9114.74","remaining_size":"0.9"}
{"type":"done","side":"buy","product_id":"BTC-USD","time":"2020-06-30T19:17:36.157104Z","sequence":180757434,"order_id":"a84fa2dc-2d07-442c-a539-4c66203c9709","reason":"canceled","price":"9116.61","remaining_size":"0.5902"}
{"type":"received","side":"sell","product_id":"BTC-USD","time":"2020-06-30T19:17:36.211632Z","sequence":180757435,"order_id":"5362ccd4-3e80-4619-b85e-26a9e0575b32","order_type":"limit","size":"1.629","price":"9126.2","client_oid":""}
{"type":"open","side":"sell","product_id":"BTC-USD","time":"2020-06-30T19:17:36.211632Z","sequence":180757436,"price":"9126.2","order_id":"5362ccd4-3e80-4619-b85e-26a9e0575b32","remaining_size":"1.629"}
{"type":"done","side":"sell","product_id":"BTC-USD","time":"2020-06-30T19:17:36.654003Z","sequence":180757437,"order_id":"5cb6befa-bb15-4170-827a-c9c7e7bba4ac","reason":"canceled","price":"9150.39","remaining_size":"1.1127"}
{"type":"heartbeat","last_trade_id":0,"product_id":"BTC-USD","sequence":180757437,"time":"2020-06-30T19:17:36.735119Z"}
{"type":"received","side":"buy","product_id":"BTC-USD","time":"2020-06-30T19:17:36.782565Z","sequence":180757438,"order_id":"5bfc708e-e38e-49c8-b3ba-a8184c9be9ea","order_type":"limit","size":"1.271","price":"9114.73","client_oid":""}
{"type":"open","side":"buy","product_id":"BTC-USD","time":"2020-06-30T19:17:36.782565Z","sequence":180757439,"price":"9114.73","order_id":"5bfc708e-e38e-49c8-b3ba-a8184c9be9ea","remaining_size":"1.271"}
{"type":"done","side":"buy","product_id":"BTC-USD","time":"2020-06-30T19:17:36.964669Z","sequence":180757440,"order_id":"92133e7f-fcf9-41e2-a237-90875aa0510a","reason":"canceled","price":"9115.62","remaining_size":"0.371"}
{"type":"done","side":"buy","product_id":"BTC-USD","time":"2020-06-30T19:17:36.969237Z","sequence":180757441,"order_id":"a1a3fbdb-cce8-44f5-8617-13d27f86486f","reason":"canceled","price":"9114.74","remaining_size":"0.0658"}
{"type":"done","side":"buy","product_id":"BTC-USD","time":"2020-06-30T19:17:36.969707Z","sequence":180757442,"order_id":"5d91f6d8-164b-422f-89b6-8a1c46c5452e","reason":"canceled","price":"9119.78","remaining_size":"0.1243"}
{"type":"received","side":"buy","product_id":"BTC-USD","time":"2020-06-30T19:17:37.394858Z","sequence":180757443,"order_id":"c2dd6265-3ede-44a0-a583-decf8c8a9b01","order_type":"limit","size":"0.0105","price":"9086.95","client_oid":""}
{"type":"open","side":"buy","product_id":"BTC-USD","time":"2020-06-30T19:17:37.394858Z","sequence":180757444,"price":"9086.95","order_id":"c2dd6265-3ede-44a0-a583-decf8c8a9b01","remaining_size":"0.0105"}
{"type":"heartbeat","last_trade_id":0,"product_id":"BTC-USD","sequence":180757444,"time":"2020-06-30T19:17:37.735115Z"}
{"type":"heartbeat","last_trade_id":0,"product_id":"BTC-USD","sequence":180757444,"time":"2020-06-30T19:17:38.735123Z"}
{"type":"received","side":"sell","product_id":"BTC-USD","time":"2020-06-30T19:17:38.940980Z","sequence":180757445,"order_id":"fa5b9e59-1460-4c77-b67d-189262b1f721","order_type":"limit","size":"0.0546","price":"9153.58","client_oid":""}
{"type":"open","side":"sell","product_id":"BTC-USD","time":"2020-06-30T19:17:38.940980Z","sequence":180757446,"price":"9153.58","order_id":"fa5b9e59-1460-4c77-b67d-189262b1f721","remaining_size":"0.0546"}
{"type":"heartbeat","last_trade_id":0,"product_id":"BTC-USD","sequence":180757446,"time":"2020-06-30T19:17:39.735115Z"}
{"type":"received","side":"buy","product_id":"BTC-USD","time":"2020-06-30T19:17:39.855955Z","sequence":180757447,"order_id":"1443c3b4-be4c-4baa-bb6c-fb720cba0110","order_type":"limit","size":"0.0658","price":"9120.24","client_oid":""}
{"type":"open","side":"buy","product_id":"BTC-USD","time":"2020-06-30T19:17:39.855955Z","sequence":180757448,"price":"9120.24","order_id":"1443c3b4-be4c-4baa-bb6c-fb720cba0110","remaining_size":"0.0658"}
{"type":"done","side":"buy","product_id":"BTC-USD","time":"2020-06-30T19:17:40.305446Z","sequence":180757449,"order_id":"8206509a-e0b6-4a34-b6bb-595331803cfe","reason":"canceled","price":"9119.37","remaining_size":"3.5646"}
{"type":"done","side":"buy","product_id":"BTC-USD","time":"2020-06-30T19:17:40.308088Z","sequence":180757450,"order_id":"d9d4ac39-3ab9-4c47-b2a7-5072f1480999","reason":"canceled","price":"9119.31","remaining_size":"0.05"}
{"type":"received","side":"buy","product_id":"BTC-USD","time":"2020-06-30T19:17:40.669815Z","sequence":180757451,"order_id":"bfe24d20-60e7-444c-8aa8-c18d104ff4ea","order_type":"market","size":"0.001","funds":"9.12082","client_oid":""}
{"type":"match","side":"sell","product_id":"BTC-USD","time":"2020-06-30T19:17:40.669815Z","sequence":180757452,"trade_id":14587667,"maker_order_id":"36fe0734-4801-466d-b093-cccd411db09a","taker_order_id":"bfe24d20-60e7-444c-8aa8-c18d104ff4ea","size":"0.001","price":"9120.82"}
{"type":"done","side":"buy","product_id":"BTC-USD","time":"2020-06-30T19:17:40.669815Z","sequence":180757453,"order_id":"bfe24d20-60e7-444c-8aa8-c18d104ff4ea","reason":"filled","remaining_size":"0"}
{"type":"received","side":"sell","product_id":"BTC-USD","time":"2020-06-30T19:17:40.721050Z","sequence":180757454,"order_id":"5d4cc2b5-dad0-4663-9762-c83f98fb8a6b","order_type":"limit","size":"0.75","price":"9121.66","client_oid":""}
{"type":"open","side":"sell","product_id":"BTC-USD","time":"2020-06-30T19:17:40.721050Z","sequence":180757455,"price":"9121.66","order_id":"5d4cc2b5-dad0-4663-9762-c83f98fb8a6b","remaining_size":"0.75"}
{"type":"heartbeat","last_trade_id":0,"product_id":"BTC-USD","sequence":180757455,"time":"2020-06-30T19:17:40.735121Z"}
{"type":"done","side":"sell","product_id":"BTC-USD","time":"2020-06-30T19:17:41.152234Z","sequence":180757456,"order_id":"75109e77-1b95-4461-8d41-fc6bc14a70bf","reason":"canceled","price":"9129.79","remaining_size":"1.5516"}
{"type":"received","side":"sell","product_id":"BTC-USD","time":"2020-06-30T19:17:41.549257Z","sequence":180757457,"order_id":"4eecd3bf-87c6-483e-8a2e-e9514c5032a5","order_type":"limit","size":"0.75","price":"9122.77","client_oid":""}
{"type":"open","side":"sell","product_id":"BTC-USD","time":"2020-06-30T19:17:41.549257Z","sequence":180757458,"price":"9122.77","order_id":"4eecd3bf-87c6-483e-8a2e-e9514c5032a5","remaining_size":"0.75"}
{"type":"heartbeat","last_trade_id":0,"product_id":"BTC-USD","sequence":180757458,"time":"2020-06-30T19:17:41.735113Z"}
{"type":"received","side":"sell","product_id":"BTC-USD","time":"2020-06-30T19:17:41.849401Z","sequence":180757459,"order_id":"ccd599e0-7e28-4e4a-9c8e-9aef2cc600a3","order_type":"limit","size":"0.4757","price":"9121.03","client_oid":""}
{"type":"open","side":"sell","product_id":"BTC-USD","time":"2020-06-30T19:17:41.849401Z","sequence":180757460,"price":"9121.03","order_id":"ccd599e0-7e28-4e4a-9c8e-9aef2cc600a3","remaining_size":"0.4757"}
{"type":"done","side":"sell","product_id":"BTC-USD","time":"2020-06-30T19:17:41.997473Z","sequence":180757461,"order_id":"5d4cc2b5-dad0-4663-9762-c83f98fb8a6b","reason":"canceled","price":"9121.66","remaining_size":"0.75"}
{"type":"done","side":"sell","product_id":"BTC-USD","time":"2020-06-30T19:17:41.998085Z","sequence":180757462,"order_id":"9e6eaa5a-2f2d-4bd7-b400-2e7e2bc94039","reason":"canceled","price":"9157.37","remaining_size":"0.0328"}
{"type":"heartbeat","last_trade_id":0,"product_id":"BTC-USD","sequence":180757462,"time":"2020-06-30T19:17:42.735118Z"}
{"type":"received","side":"buy","product_id":"BTC-USD","time":"2020-06-30T19:17:42.777565Z","sequence":180757463,"order_id":"da6061e8-d48a-46d0-8d23-835674b19808","order_type":"limit","size":"5.177","price":"9121.02","client_oid":""}
{"type":"match","side":"sell","product_id":"BTC-USD","time":"2020-06-30T19:17:42.777565Z","sequence":180757464,"trade_id":14587668,"maker_order_id":"36fe0734-4801-466d-b093-cccd411db09a","taker_order_id":"da6061e8-d48a-46d0-8d23-835674b19808","size":"5.177","price":"9120.82"}
{"type":"done","side":"buy","product_id":"BTC-USD","time":"2020-06-30T19:17:42.777565Z","sequence":180757465,"order_id":"da6061e8-d48a-46d0-8d23-835674b19808","reason":"filled","price":"9121.02","remaining_size":"0"}
{"type":"received","side":"sell","product_id":"BTC-USD","time":"2020-06-30T19:17:43.057858Z","sequence":180757466,"order_id":"90d437c9-b784-4ac2-b4ff-6d22e30bafd5","order_type":"limit","size":"0.9247","price":"9136.27","client_oid":""}
{"type":"open","side":"sell","product_id":"BTC-USD","time":"2020-06-30T19:17:43.057858Z","sequence":180757467,"price":"9136.27","order_id":"90d437c9-b784-4ac2-b4ff-6d22e30bafd5","remaining_size":"0.9247"}
{"type":"done","side":"buy","product_id":"BTC-USD","time":"2020-06-30T19:17:43.226043Z","sequence":180757468,"order_id":"29becaa1-4cab-4b67-aafb-47bfb90a01a0","reason":"canceled","price":"9117.93","remaining_size":"0.0658"}
{"type":"done","side":"buy","product_id":"BTC-USD","time":"2020-06-30T19:17:43.235414Z","sequence":180757469,"order_id":"589c816b-b5a4-46af-aae4-ff3a490fd3be","reason":"canceled","price":"9120.28","remaining_size":"0.0658"}
{"type":"done","side":"buy","product_id":"BTC-USD","time":"2020-06-30T19:17:43.243474Z","sequence":180757470,"order_id":"e5922720-e2c3-41a6-b2cc-afbd787b181b","reason":"canceled","price":"9088.73","remaining_size":"0.01"}
{"type":"received","side":"buy","product_id":"BTC-USD","time":"2020-06-30T19:17:43.331390Z","sequence":180757471,"order_id":"d30632a7-5086-4d2f-a673-4f40a5743bc7","order_type":"limit","size":"0.9","price":"9120.25","client_oid":""}
{"type":"open","side":"buy","product_id":"BTC-USD","time":"2020-06-30T19:17:43.331390Z","sequence":180757472,"price":"9120.25","order_id":"d30632a7-5086-4d2f-a673-4f40a5743bc7","remaining_size":"0.9"}
{"type":"heartbeat","last_trade_id":0,"product_id":"BTC-USD","sequence":180757472,"time":"2020-06-30T19:17:43.735114Z"}
{"type":"done","side":"buy","product_id":"BTC-USD","time":"2020-06-30T19:17:43.783798Z","sequence":180757473,"order_id":"c2dd6265-3ede-44a0-a583-decf8c8a9b01","reason":"canceled","price":"9086.95","remaining_size":"0.0105"}
{"type":"received","side":"buy","product_id":"BTC-USD","time":"2020-06-30T19:17:44.034868Z","sequence":180757474,"order_id":"4610f524-c5cf-4252-a840-dd730b15847a","order_type":"limit","size":"0.01","price":"100","client_oid":"14cff7ab-1962-49b0-b9cb-ec8b4c8c6e0d"}
{"type":"open","side":"buy","product_id":"BTC-USD","time":"2020-06-30T19:17:44.034868Z","sequence":180757475,"price":"100","order_id":"4610f524-c5cf-4252-a840-dd730b15847a","remaining_size":"0.01"}
{"type":"done","side":"buy","product_id":"BTC-USD","time":"2020-06-30T19:17:44.040900Z","sequence":180757476,"order_id":"4610f524-c5cf-4252-a840-dd730b15847a","reason":"canceled","price":"100","remaining_size":"0.01"}
{"type":"heartbeat","last_trade_id":0,"product_id":"BTC-USD","sequence":180757476,"time":"2020-06-30T19:17:44.735116Z"}
{"type":"received","side":"buy","product_id":"BTC-USD","time":"2020-06-30T19:17:45.721421Z","sequence":180757477,"order_id":"7902584c-4989-4c89-ba52-c6465afe652f","order_type":"limit","size":"0.0658","price":"9115.09","client_oid":""}
{"type":"open","side":"buy","product_id":"BTC-USD","time":"2020-06-30T19:17:45.721421Z","sequence":180757478,"price":"9115.09","order_id":"7902584c-4989-4c89-ba52-c6465afe652f","remaining_size":"0.0658"}
{"type":"heartbeat","last_trade_id":0,"product_id":"BTC-USD","sequence":180757478,"time":"2020-06-30T19:17:45.735118Z"}
{"type":"received","side":"buy","product_id":"BTC-USD","time":"2020-06-30T19:17:46.580955Z","sequence":180757479,"order_id":"312918b2-5c60-44c0-bd97-ea7aecfbe383","order_type":"limit","size":"0.01","price":"9088.73","client_oid":""}
{"type":"open","side":"buy","product_id":"BTC-USD","time":"2020-06-30T19:17:46.580955Z","sequence":180757480,"price":"9088.73","order_id":"312918b2-5c60-44c0-bd97-ea7aecfbe383","remaining_size":"0.01"}
{"type":"heartbeat","last_trade_id":0,"product_id":"BTC-USD","sequence":180757480,"time":"2020-06-30T19:17:46.735118Z"}
{"type":"received","side":"buy","product_id":"BTC-USD","time":"2020-06-30T19:17:46.875039Z","sequence":180757481,"order_id":"cbc7299d-8c19-466a-8f44-8b734e63aa6f","order_type":"limit","size":"0.9658","price":"9120.25","client_oid":""}
{"type":"open","side":"buy","product_id":"BTC-USD","time":"2020-06-30T19:17:46.875039Z","sequence":180757482,"price":"9120.25","order_id":"cbc7299d-8c19-466a-8f44-8b734e63aa6f","remaining_size":"0.9658"}
{"type":"done","side":"buy","product_id":"BTC-USD","time":"2020-06-30T19:17:47.066387Z","sequence":180757483,"order_id":"2302c71d-b09c-4448-bfea-cf2a8f7d65fd","reason":"canceled","price":"9119.73","remaining_size":"0.05"}
{"type":"done","side":"buy","product_id":"BTC-USD","time":"2020-06-30T19:17:47.066485Z","sequence":180757484,"order_id":"1443c3b4-be4c-4baa-bb6c-fb720cba0110","reason":"canceled","price":"9120.24","remaining_size":"0.0658"}
{"type":"done","side":"buy","product_id":"BTC-USD","time":"2020-06-30T19:17:47.069017Z","sequence":180757485,"order_id":"0e860e23-7ea1-4be4-acc5-bf3fc9335955","reason":"canceled","price":"9120.3","remaining_size":"0.0658"}
{"type":"done","side":"buy","product_id":"BTC-USD","time":"2020-06-30T19:17:47.313504Z","sequence":180757486,"order_id":"4a8589eb-32f2-45d1-95e7-3dcadc3c0f0a","reason":"canceled","price":"9117.77","remaining_size":"0.5"}
{"type":"heartbeat","last_trade_id":0,"product_id":"BTC-USD","sequence":180757486,"time":"2020-06-30T19:17:47.735114Z"}
{"type":"done","side":"buy","product_id":"BTC-USD","time":"2020-06-30T19:17:47.881277Z","sequence":180757487,"order_id":"cbc7299d-8c19-466a-8f44-8b734e63aa6f","reason":"canceled","price":"9120.25","remaining_size":"0.9658"}
{"type":"done","side":"buy","product_id":"BTC-USD","time":"2020-06-30T19:17:47.882562Z","sequence":180757488,"order_id":"7a281102-3084-4d80-84ee-b2ee2448138d","reason":"canceled","price":"9118.41","remaining_size":"1"}
{"type":"received","side":"buy","product_id":"BTC-USD","time":"2020-06-30T19:17:48.090977Z","sequence":180757489,"order_id":"a5d34e00-f67e-4caf-aca1-d8eaea53dc27","order_type":"limit","size":"0.0493","price":"9118.25","client_oid":""}
{"type":"open","side":"buy","product_id":"BTC-USD","time":"2020-06-30T19:17:48.090977Z","sequence":180757490,"price":"9118.25","order_id":"a5d34e00-f67e-4caf-aca1-d8eaea53dc27","remaining_size":"0.0493"}
{"type":"done","side":"buy","product_id":"BTC-USD","time":"2020-06-30T19:17:48.509861Z","sequence":180757491,"order_id":"312918b2-5c60-44c0-bd97-ea7aecfbe383","reason":"canceled","price":"9088.73","remaining_size":"0.01"}
{"type":"received","side":"buy","product_id":"BTC-USD","time":"2020-06-30T19:17:48.666395Z","sequence":180757492,"order_id":"6250d29e-6d14-49ff-8413-feffcacf4d76","order_type":"limit","size":"4.564","price":"9121.02","client_oid":""}
{"type":"match","side":"sell","product_id":"BTC-USD","time":"2020-06-30T19:17:48.666395Z","sequence":180757493,"trade_id":14587669,"maker_order_id":"36fe0734-4801-466d-b093-cccd411db09a","taker_order_id":"6250d29e-6d14-49ff-8413-feffcacf4d76","size":"4.564","price":"9120.82"}
{"type":"done","side":"buy","product_id":"BTC-USD","time":"2020-06-30T19:17:48.666395Z","sequence":180757494,"order_id":"6250d29e-6d14-49ff-8413-feffcacf4d76","reason":"filled","price":"9121.02","remaining_size":"0"}
{"type":"heartbeat","last_trade_id":0,"product_id":"BTC-USD","sequence":180757494,"time":"2020-06-30T19:17:48.735115Z"}
{"type":"received","side":"sell","product_id":"BTC-USD","time":"2020-06-30T19:17:48.975552Z","sequence":180757495,"order_id":"33a6df93-51e4-4cc6-8ffb-3613ccfe3983","order_type":"limit","size":"0.25","price":"9122.98","client_oid":""}
{"type":"open","side":"sell","product_id":"BTC-USD","time":"2020-06-30T19:17:48.975552Z","sequence":180757496,"price":"9122.98","order_id":"33a6df93-51e4-4cc6-8ffb-3613ccfe3983","remaining_size":"0.25"}
{"type":"done","side":"sell","product_id":"BTC-USD","time":"2020-06-30T19:17:49.429814Z","sequence":180757497,"order_id":"a4507b82-b700-4380-831b-315e1f3ad00f","reason":"canceled","price":"9121.03","remaining_size":"0.15"}
{"type":"received","side":"sell","product_id":"BTC-USD","time":"2020-06-30T19:17:49.525477Z","sequence":180757498,"order_id":"bb7074a8-63c6-40b7-87c5-969079c2b747","order_type":"limit","size":"0.069","price":"9155.51","client_oid":""}
{"type":"open","side":"sell","product_id":"BTC-USD","time":"2020-06-30T19:17:49.525477Z","sequence":180757499,"price":"9155.51","order_id":"bb7074a8-63c6-40b7-87c5-969079c2b747","remaining_size":"0.069"}
{"type":"done","side":"sell","product_id":"BTC-USD","time":"2020-06-30T19:17:49.716934Z","sequence":180757500,"order_id":"fa5b9e59-1460-4c77-b67d-189262b1f721","reason":"canceled","price":"9153.58","remaining_size":"0.0546"}
{"type":"heartbeat","last_trade_id":0,"product_id":"BTC-USD","sequence":180757500,"time":"2020-06-30T19:17:49.735116Z"}
{"type":"received","side":"sell","product_id":"BTC-USD","time":"2020-06-30T19:17:49.841945Z","sequence":180757501,"order_id":"187856a5-381c-4b31-b105-f5cde6445fc5","order_type":"limit","size":"2.6159","price":"9124.73","client_oid":""}
{"type":"open","side":"sell","product_id":"BTC-USD","time":"2020-06-30T19:17:49.841945Z","sequence":180757502,"price":"9124.73","order_id":"187856a5-381c-4b31-b105-f5cde6445fc5","remaining_size":"2.6159"}
{"type":"received","side":"sell","product_id":"BTC-USD","time":"2020-06-30T19:17:50.089587Z","sequence":180757503,"order_id":"9c5b9422-12ed-4f74-be51-98dd73a3a89f","order_type":"limit","size":"0.069","price":"9154.97","client_oid":""}
{"type":"open","side":"sell","product_id":"BTC-USD","time":"2020-06-30T19:17:50.089587Z","sequence":180757504,"price":"9154.97","order_id":"9c5b9422-12ed-4f74-be51-98dd73a3a89f","remaining_size":"0.069"}
{"type":"done","side":"sell","product_id":"BTC-USD","time":"2020-06-30T19:17:50.539104Z","sequence":180757505,"order_id":"94c9febc-5835-4932-b98f-0797c55afe21","reason":"canceled","price":"9155.37","remaining_size":"0.0329"}
{"type":"done","side":"sell","product_id":"BTC-USD","time":"2020-06-30T19:17:50.540519Z","sequence":180757506,"order_id":"4eecd3bf-87c6-483e-8a2e-e9514c5032a5","reason":"canceled","price":"9122.77","remaining_size":"0.75"}
{"type":"heartbeat","last_trade_id":0,"product_id":"BTC-USD","sequence":180757506,"time":"2020-06-30T19:17:50.735113Z"}
{"type":"received","side":"sell","product_id":"BTC-USD","time":"2020-06-30T19:17:51.251089Z","sequence":180757507,"order_id":"4712c6f5-74b5-4031-a053-021d02c89ade","order_type":"limit","size":"0.069","price":"9155.64","client_oid":""}
{"type":"open","side":"sell","product_id":"BTC-USD","time":"2020-06-30T19:17:51.251089Z","sequence":180757508,"price":"9155.64","order_id":"4712c6f5-74b5-4031-a053-021d02c89ade","remaining_size":"0.069"}
{"type":"done","side":"sell","product_id":"BTC-USD","time":"2020-06-30T19:17:51.717979Z","sequence":180757509,"order_id":"00c6e3cf-549f-44a6-b47f-f9214be883aa","reason":"canceled","price":"9121.51","remaining_size":"0.025"}
{"type":"heartbeat","last_trade_id":0,"product_id":"BTC-USD","sequence":180757509,"time":"2020-06-30T19:17:51.735116Z"}
{"type":"received","side":"sell","product_id":"BTC-USD","time":"2020-06-30T19:17:52.121879Z","sequence":180757510,"order_id":"124566eb-b746-4c54-9a71-6a4c2f628448","order_type":"limit","size":"0.0221","price":"9140.28","client_oid":""}
{"type":"open","side":"sell","product_id":"BTC-USD","time":"2020-06-30T19:17:52.121879Z","sequence":180757511,"price":"9140.28","order_id":"124566eb-b746-4c54-9a71-6a4c2f628448","remaining_size":"0.0221"}
{"type":"done","side":"sell","product_id":"BTC-USD","time":"2020-06-30T19:17:52.540189Z","sequence":180757512,"order_id":"187856a5-381c-4b31-b105-f5cde6445fc5","reason":"canceled","price":"9124.73","remaining_size":"2.6159"}
{"type":"heartbeat","last_trade_id":0,"product_id":"BTC-USD","sequence":180757512,"time":"2020-06-30T19:17:52.735109Z"}
{"type":"received","side":"buy","product_id":"BTC-USD","time":"2020-06-30T19:17:52.751989Z","sequence":180757513,"order_id":"a841d296-82b9-4304-a7d5-d8feff9012c7","order_type":"limit","size":"0.01","price":"9092.16","client_oid":""}
{"type":"open","side":"buy","product_id":"BTC-USD","time":"2020-06-30T19:17:52.751989Z","sequence":180757514,"price":"9092.16","order_id":"a841d296-82b9-4304-a7d5-d8feff9012c7","remaining_size":"0.01"}
{"type":"done","side":"buy","product_id":"BTC-USD","time":"2020-06-30T19:17:53.215660Z","sequence":180757515,"order_id":"d30632a7-5086-4d2f-a673-4f40a5743bc7","reason":"canceled","price":"9120.25","remaining_size":"0.9"}
{"type":"heartbeat","last_trade_id":0,"product_id":"BTC-USD","sequence":180757515,"time":"2020-06-30T19:17:53.735109Z"}
{"type":"heartbeat","last_trade_id":0,"product_id":"BTC-USD","sequence":180757515,"time":"2020-06-30T19:17:54.735112Z"}
{"type":"received","side":"sell","product_id":"BTC-USD","time":"2020-06-30T19:17:54.999004Z","sequence":180757516,"order_id":"41fbf6f8-47d9-49d6-818e-5c32380a6a56","order_type":"limit","size":"0.3917","price":"9148.34","client_oid":""}
{"type":"open","side":"sell","product_id":"BTC-USD","time":"2020-06-30T19:17:54.999004Z","sequence":180757517,"price":"9148.34","order_id":"41fbf6f8-47d9-49d6-818e-5c32380a6a56","remaining_size":"0.3917"}
{"type":"received","side":"buy","product_id":"BTC-USD","time":"2020-06-30T19:17:55.279318Z","sequence":180757518,"order_id":"efefa43a-553f-40ee-bc1e-28acd44d2c59","order_type":"limit","size":"0.0283","price":"9103.2","client_oid":""}
{"type":"open","side":"buy","product_id":"BTC-USD","time":"2020-06-30T19:17:55.279318Z","sequence":180757519,"price":"9103.2","order_id":"efefa43a-553f-40ee-bc1e-28acd44d2c59","remaining_size":"0.0283"}
{"type":"done","side":"sell","product_id":"BTC-USD","time":"2020-06-30T19:17:55.424698Z","sequence":180757520,"order_id":"17866525-73d1-442e-a124-b33095ab8977","reason":"canceled","price":"9154.34","remaining_size":"0.0546"}
{"type":"done","side":"sell","product_id":"BTC-USD","time":"2020-06-30T19:17:55.429420Z","sequence":180757521,"order_id":"33a6df93-51e4-4cc6-8ffb-3613ccfe3983","reason":"canceled","price":"9122.98","remaining_size":"0.25"}
{"type":"done","side":"sell","product_id":"BTC-USD","time":"2020-06-30T19:17:55.446116Z","sequence":180757522,"order_id":"9c5b9422-12ed-4f74-be51-98dd73a3a89f","reason":"canceled","price":"9154.97","remaining_size":"0.069"}
{"type":"received","side":"buy","product_id":"BTC-USD","time":"2020-06-30T19:17:55.566076Z","sequence":180757523,"order_id":"866b8604-e0bf-49df-8a00-3626fb76cf9d","order_type":"limit","size":"0.9","price":"9120.25","client_oid":""}
{"type":"open","side":"buy","product_id":"BTC-USD","time":"2020-06-30T19:17:55.566076Z","sequence":180757524,"price":"9120.25","order_id":"866b8604-e0bf-49df-8a00-3626fb76cf9d","remaining_size":"0.9"}
{"type":"done","side":"buy","product_id":"BTC-USD","time":"2020-06-30T19:17:55.714555Z","sequence":180757525,"order_id":"61fbcd9c-9d45-4028-9f7a-e0bf0c1db536","reason":"canceled","price":"9119.69","remaining_size":"0.125"}
{"type":"heartbeat","last_trade_id":0,"product_id":"BTC-USD","sequence":180757525,"time":"2020-06-30T19:17:55.735068Z"}
{"type":"received","side":"sell","product_id":"BTC-USD","time":"2020-06-30T19:17:55.853616Z","sequence":180757526,"order_id":"123872c2-41b2-4542-9fc7-1883e50a27f2","order_type":"limit","size":"0.541","price":"9124.43","client_oid":""}
{"type":"open","side":"sell","product_id":"BTC-USD","time":"2020-06-30T19:17:55.853616Z","sequence":180757527,"price":"9124.43","order_id":"123872c2-41b2-4542-9fc7-1883e50a27f2","remaining_size":"0.541"}
{"type":"done","side":"buy","product_id":"BTC-USD","time":"2020-06-30T19:17:56.016074Z","sequence":180757528,"order_id":"c2f8406b-2490-42eb-a77d-50775923b7ec","reason":"canceled","price":"9119.59","remaining_size":"0.5"}
{"type":"done","side":"sell","product_id":"BTC-USD","time":"2020-06-30T19:17:56.307559Z","sequence":180757529,"order_id":"41fbf6f8-47d9-49d6-818e-5c32380a6a56","reason":"canceled","price":"9148.34","remaining_size":"0.3917"}
{"type":"received","side":"buy","product_id":"BTC-USD","time":"2020-06-30T19:17:56.470033Z","sequence":180757530,"order_id":"0fe5637d-8c7f-4ee3-af40-79927d5bf436","order_type":"limit","size":"61.7112","price":"7600","client_oid":""}
{"type":"open","side":"buy","product_id":"BTC-USD","time":"2020-06-30T19:17:56.470033Z","sequence":180757531,"price":"7600","order_id":"0fe5637d-8c7f-4ee3-af40-79927d5bf436","remaining_size":"61.7112"}
{"type":"received","side":"buy","product_id":"BTC-USD","time":"2020-06-30T19:17:56.736463Z","sequence":180757532,"order_id":"e5c972dd-9c74-4139-9276-b2dec2ad6fab","order_type":"limit","size":"0.9","price":"9119.12","client_oid":""}
{"type":"open","side":"buy","product_id":"BTC-USD","time":"2020-06-30T19:17:56.736463Z","sequence":180757533,"price":"9119.12","order_id":"e5c972dd-9c74-4139-9276-b2dec2ad6fab","remaining_size":"0.9"}
{"type":"heartbeat","last_trade_id":0,"product_id":"BTC-USD","sequence":180757533,"time":"2020-06-30T19:17:56.735051Z"}
{"type":"done","side":"buy","product_id":"BTC-USD","time":"2020-06-30T19:17:56.895842Z","sequence":180757534,"order_id":"866b8604-e0bf-49df-8a00-3626fb76cf9d","reason":"canceled","price":"9120.25","remaining_size":"0.9"}
{"type":"done","side":"buy","product_id":"BTC-USD","time":"2020-06-30T19:17:56.917310Z","sequence":180757535,"order_id":"efefa43a-553f-40ee-bc1e-28acd44d2c59","reason":"canceled","price":"9103.2","remaining_size":"0.0283"}
{"type":"received","side":"sell","product_id":"BTC-USD","time":"2020-06-30T19:17:57.040599Z","sequence":180757536,"order_id":"bb830f8f-a737-418f-943c-d56e57adad42","order_type":"limit","size":"0.544","price":"9123.11","client_oid":""}
{"type":"open","side":"sell","product_id":"BTC-USD","time":"2020-06-30T19:17:57.040599Z","sequence":180757537,"price":"9123.11","order_id":"bb830f8f-a737-418f-943c-d56e57adad42","remaining_size":"0.544"}
{"type":"done","side":"buy","product_id":"BTC-USD","time":"2020-06-30T19:17:57.189197Z","sequence":180757538,"order_id":"a841d296-82b9-4304-a7d5-d8feff9012c7","reason":"canceled","price":"9092.16","remaining_size":"0.01"}
{"type":"received","side":"sell","product_id":"BTC-USD","time":"2020-06-30T19:17:57.307626Z","sequence":180757539,"order_id":"5fac26e2-4e57-4c82-b33a-3a3698508af3","order_type":"limit","size":"0.25","price":"9123.46","client_oid":""}
{"type":"open","side":"sell","product_id":"BTC-USD","time":"2020-06-30T19:17:57.307626Z","sequence":180757540,"price":"9123.46","order_id":"5fac26e2-4e57-4c82-b33a-3a3698508af3","remaining_size":"0.25"}
{"type":"done","side":"sell","product_id":"BTC-USD","time":"2020-06-30T19:17:57.531856Z","sequence":180757541,"order_id":"90d437c9-b784-4ac2-b4ff-6d22e30bafd5","reason":"canceled","price":"9136.27","remaining_size":"0.9247"}
{"type":"done","side":"sell","product_id":"BTC-USD","time":"2020-06-30T19:17:57.559104Z","sequence":180757542,"order_id":"ccd599e0-7e28-4e4a-9c8e-9aef2cc600a3","reason":"canceled","price":"9121.03","remaining_size":"0.4757"}
{"type":"heartbeat","last_trade_id":0,"product_id":"BTC-USD","sequence":180757542,"time":"2020-06-30T19:17:57.735034Z"}
{"type":"received","side":"sell","product_id":"BTC-USD","time":"2020-06-30T19:17:57.871795Z","sequence":180757543,"order_id":"71318ebf-abcf-4ff0-b9aa-803cd867980d","order_type":"limit","size":"0.371","price":"9124.72","client_oid":""}
{"type":"open","side":"sell","product_id":"BTC-USD","time":"2020-06-30T19:17:57.871795Z","sequence":180757544,"price":"9124.72","order_id":"71318ebf-abcf-4ff0-b9aa-803cd867980d","remaining_size":"0.371"}
{"type":"received","side":"sell","product_id":"BTC-USD","time":"2020-06-30T19:17:58.166447Z","sequence":180757545,"order_id":"d62c58a2-94a7-47e3-aa33-d4b32f3372f3","order_type":"limit","size":"0.9247","price":"9131.3","client_oid":""}
{"type":"open","side":"sell","product_id":"BTC-USD","time":"2020-06-30T19:17:58.166447Z","sequence":180757546,"price":"9131.3","order_id":"d62c58a2-94a7-47e3-aa33-d4b32f3372f3","remaining_size":"0.9247"}
{"type":"done","side":"sell","product_id":"BTC-USD","time":"2020-06-30T19:17:58.317614Z","sequence":180757547,"order_id":"bb830f8f-a737-418f-943c-d56e57adad42","reason":"canceled","price":"9123.11","remaining_size":"0.544"}
{"type":"done","side":"sell","product_id":"BTC-USD","time":"2020-06-30T19:17:58.324774Z","sequence":180757548,"order_id":"51f4d44c-d6ab-4197-8d39-f51a4b4a38b2","reason":"canceled","price":"9121.31","remaining_size":"0.05"}
{"type":"received","side":"buy","product_id":"BTC-USD","time":"2020-06-30T19:17:58.732797Z","sequence":180757549,"order_id":"f8bc6949-fdec-4c92-afa7-a31d36cb77d2","order_type":"limit","size":"0.0283","price":"9099.67","client_oid":""}
{"type":"open","side":"buy","product_id":"BTC-USD","time":"2020-06-30T19:17:58.732797Z","sequence":180757550,"price":"9099.67","order_id":"f8bc6949-fdec-4c92-afa7-a31d36cb77d2","remaining_size":"0.0283"}
{"type":"heartbeat","last_trade_id":0,"product_id":"BTC-USD","sequence":180757550,"time":"2020-06-30T19:17:58.735092Z"}
{"type":"received","side":"buy","product_id":"BTC-USD","time":"2020-06-30T19:17:59.016710Z","sequence":180757551,"order_id":"d1df44f2-2a2d-4463-82ba-c82eb7cb54b7","order_type":"limit","size":"0.01","price":"100","client_oid":"32c034de-43b9-454e-832c-48ed31f30386"}
{"type":"open","side":"buy","product_id":"BTC-USD","time":"2020-06-30T19:17:59.016710Z","sequence":180757552,"price":"100","order_id":"d1df44f2-2a2d-4463-82ba-c82eb7cb54b7","remaining_size":"0.01"}
{"type":"done","side":"buy","product_id":"BTC-USD","time":"2020-06-30T19:17:59.026398Z","sequence":180757553,"order_id":"d1df44f2-2a2d-4463-82ba-c82eb7cb54b7","reason":"canceled","price":"100","remaining_size":"0.01"}
{"type":"heartbeat","last_trade_id":0,"product_id":"BTC-USD","sequence":180757553,"time":"2020-06-30T19:17:59.735112Z"}
{"type":"done","side":"buy","product_id":"BTC-USD","time":"2020-06-30T19:18:00.172603Z","sequence":180757554,"order_id":"d4fe4324-78ae-4550-9509-defa9edc8c99","reason":"canceled","price":"8890.86","remaining_size":"0.04683127"}
{"type":"received","side":"buy","product_id":"BTC-USD","time":"2020-06-30T19:18:00.458907Z","sequence":180757555,"order_id":"a0193aa2-a6f7-4982-85d2-9ac18dcd6100","order_type":"limit","size":"0.04692522","price":"8890.1","client_oid":""}
{"type":"open","side":"buy","product_id":"BTC-USD","time":"2020-06-30T19:18:00.458907Z","sequence":180757556,"price":"8890.1","order_id":"a0193aa2-a6f7-4982-85d2-9ac18dcd6100","remaining_size":"0.04692522"}
{"type":"done","side":"sell","product_id":"BTC-USD","time":"2020-06-30T19:18:00.677207Z","sequence":180757557,"order_id":"3eff7076-9cb0-454b-9de5-e7f5ec6c306a","reason":"canceled","price":"9440.29","remaining_size":"0.00756905"}
{"type":"heartbeat","last_trade_id":0,"product_id":"BTC-USD","sequence":180757557,"time":"2020-06-30T19:18:00.735060Z"}
{"type":"received","side":"buy","product_id":"BTC-USD","time":"2020-06-30T19:18:00.798690Z","sequence":180757558,"order_id":"135ad241-2d6d-4a7f-b0d8-ead27951b9b9","order_type":"limit","size":"0.0658","price":"9120.15","client_oid":""}
{"type":"open","side":"buy","product_id":"BTC-USD","time":"2020-06-30T19:18:00.798690Z","sequence":180757559,"price":"9120.15","order_id":"135ad241-2d6d-4a7f-b0d8-ead27951b9b9","remaining_size":"0.0658"}
{"type":"received","side":"sell","product_id":"BTC-USD","time":"2020-06-30T19:18:00.937526Z","sequence":180757560,"order_id":"92864363-17b9-4d43-a530-217a8c105b3d","order_type":"limit","size":"0.00766091","price":"9441.09","client_oid":""}
{"type":"open","side":"sell","product_id":"BTC-USD","time":"2020-06-30T19:18:00.937526Z","sequence":180757561,"price":"9441.09","order_id":"92864363-17b9-4d43-a530-217a8c105b3d","remaining_size":"0.00766091"}
{"type":"received","side":"buy","product_id":"BTC-USD","time":"2020-06-30T19:18:00.969298Z","sequence":180757562,"order_id":"44406ff3-00ee-4e08-92b1-110f36239c29","order_type":"limit","size":"0.2234","price":"9121.33","client_oid":""}
{"type":"match","side":"sell","product_id":"BTC-USD","time":"2020-06-30T19:18:00.969298Z","sequence":180757563,"trade_id":14587670,"maker_order_id":"36fe0734-4801-466d-b093-cccd411db09a","taker_order_id":"44406ff3-00ee-4e08-92b1-110f36239c29","size":"0.2234","price":"9120.82"}
{"type":"done","side":"buy","product_id":"BTC-USD","time":"2020-06-30T19:18:00.969298Z","sequence":180757564,"order_id":"44406ff3-00ee-4e08-92b1-110f36239c29","reason":"filled","price":"9121.33","remaining_size":"0"}
{"type":"received","side":"buy","product_id":"BTC-USD","time":"2020-06-30T19:18:01.560593Z","sequence":180757565,"order_id":"02cce035-ba71-4635-9971-f30bcf6d91b7","order_type":"limit","size":"0.0658","price":"9113.09","client_oid":""}
{"type":"open","side":"buy","product_id":"BTC-USD","time":"2020-06-30T19:18:01.560593Z","sequence":180757566,"price":"9113.09","order_id":"02cce035-ba71-4635-9971-f30bcf6d91b7","remaining_size":"0.0658"}
{"type":"heartbeat","last_trade_id":0,"product_id":"BTC-USD","sequence":180757566,"time":"2020-06-30T19:18:01.735105Z"}
{"type":"received","side":"buy","product_id":"BTC-USD","time":"2020-06-30T19:18:01.906106Z","sequence":180757567,"order_id":"283a307b-7836-4e11-b899-7f3f1bc48422","order_type":"limit","size":"0.0222","price":"9113.1","client_oid":""}
{"type":"open","side":"buy","product_id":"BTC-USD","time":"2020-06-30T19:18:01.906106Z","sequence":180757568,"price":"9113.1","order_id":"283a307b-7836-4e11-b899-7f3f1bc48422","remaining_size":"0.0222"}
{"type":"done","side":"buy","product_id":"BTC-USD","time":"2020-06-30T19:18:02.213600Z","sequence":180757569,"order_id":"135ad241-2d6d-4a7f-b0d8-ead27951b9b9","reason":"canceled","price":"9120.15","remaining_size":"0.0658"}
{"type":"heartbeat","last_trade_id":0,"product_id":"BTC-USD","sequence":180757569,"time":"2020-06-30T19:18:02.735113Z"}
{"type":"received","side":"buy","product_id":"BTC-USD","time":"2020-06-30T19:18:02.773458Z","sequence":180757570,"order_id":"300dd4c6-7799-42db-9efd-b37fb41356c1","order_type":"limit","size":"0.055","price":"9086.68","client_oid":""}
{"type":"open","side":"buy","product_id":"BTC-USD","time":"2020-06-30T19:18:02.773458Z","sequence":180757571,"price":"9086.68","order_id":"300dd4c6-7799-42db-9efd-b37fb41356c1","remaining_size":"0.055"}
{"type":"received","side":"buy","product_id":"BTC-USD","time":"2020-06-30T19:18:03.042088Z","sequence":180757572,"order_id":"3b0f9c4d-e6dd-462f-a5c5-570b98c80600","order_type":"limit","size":"0.0105","price":"9088.19","client_oid":""}
{"type":"open","side":"buy","product_id":"BTC-USD","time":"2020-06-30T19:18:03.042088Z","sequence":180757573,"price":"9088.19","order_id":"3b0f9c4d-e6dd-462f-a5c5-570b98c80600","remaining_size":"0.0105"}
{"type":"received","side":"sell","product_id":"BTC-USD","time":"2020-06-30T19:18:03.356452Z","sequence":180757574,"order_id":"279afeb8-364f-4f7d-b44e-1b7421c84afe","order_type":"limit","size":"0.2502","price":"9121.34","client_oid":""}
{"type":"open","side":"sell","product_id":"BTC-USD","time":"2020-06-30T19:18:03.356452Z","sequence":180757575,"price":"9121.34","order_id":"279afeb8-364f-4f7d-b44e-1b7421c84afe","remaining_size":"0.2502"}
{"type":"heartbeat","last_trade_id":0,"product_id":"BTC-USD","sequence":180757575,"time":"2020-06-30T19:18:03.735114Z"}
{"type":"done","side":"sell","product_id":"BTC-USD","time":"2020-06-30T19:18:03.823994Z","sequence":180757576,"order_id":"5362ccd4-3e80-4619-b85e-26a9e0575b32","reason":"canceled","price":"9126.2","remaining_size":"1.629"}
{"type":"done","side":"sell","product_id":"BTC-USD","time":"2020-06-30T19:18:03.825146Z","sequence":180757577,"order_id":"123872c2-41b2-4542-9fc7-1883e50a27f2","reason":"canceled","price":"9124.43","remaining_size":"0.541"}
{"type":"received","side":"buy","product_id":"BTC-USD","time":"2020-06-30T19:18:03.913320Z","sequence":180757578,"order_id":"d28c8b6d-79f4-42a2-ab95-ffc011c96666","order_type":"limit","size":"0.0658","price":"9120.13","client_oid":""}
{"type":"open","side":"buy","product_id":"BTC-USD","time":"2020-06-30T19:18:03.913320Z","sequence":180757579,"price":"9120.13","order_id":"d28c8b6d-79f4-42a2-ab95-ffc011c96666","remaining_size":"0.0658"}
{"type":"received","side":"sell","product_id":"BTC-USD","time":"2020-06-30T19:18:04.184986Z","sequence":180757580,"order_id":"b43cf272-d287-4c71-9e7e-3e9bbb63df1c","order_type":"limit","size":"0.542","price":"9122.97","client_oid":""}
{"type":"open","side":"sell","product_id":"BTC-USD","time":"2020-06-30T19:18:04.184986Z","sequence":180757581,"price":"9122.97","order_id":"b43cf272-d287-4c71-9e7e-3e9bbb63df1c","remaining_size":"0.542"}
{"type":"done","side":"sell","product_id":"BTC-USD","time":"2020-06-30T19:18:04.416233Z","sequence":180757582,"order_id":"5fac26e2-4e57-4c82-b33a-3a3698508af3","reason":"canceled","price":"9123.46","remaining_size":"0.25"}
{"type":"heartbeat","last_trade_id":0,"product_id":"BTC-USD","sequence":180757582,"time":"2020-06-30T19:18:04.735101Z"}
{"type":"received","side":"buy","product_id":"BTC-USD","time":"2020-06-30T19:18:05.067685Z","sequence":180757583,"order_id":"71260540-6c4f-4f83-b25a-38b4efb8b4ff","order_type":"limit","size":"0.178","price":"9121.07","client_oid":""}
{"type":"match","side":"sell","product_id":"BTC-USD","time":"2020-06-30T19:18:05.067685Z","sequence":180757584,"trade_id":14587671,"maker_order_id":"36fe0734-4801-466d-b093-cccd411db09a","taker_order_id":"71260540-6c4f-4f83-b25a-38b4efb8b4ff","size":"0.178","price":"9120.82"}
{"type":"done","side":"buy","product_id":"BTC-USD","time":"2020-06-30T19:18:05.067685Z","sequence":180757585,"order_id":"71260540-6c4f-4f83-b25a-38b4efb8b4ff","reason":"filled","price":"9121.07","remaining_size":"0"}
{"type":"done","side":"buy","product_id":"BTC-USD","time":"2020-06-30T19:18:05.510608Z","sequence":180757586,"order_id":"3b0f9c4d-e6dd-462f-a5c5-570b98c80600","reason":"canceled","price":"9088.19","remaining_size":"0.0105"}
{"type":"done","side":"buy","product_id":"BTC-USD","time":"2020-06-30T19:18:05.518593Z","sequence":180757587,"order_id":"300dd4c6-7799-42db-9efd-b37fb41356c1","reason":"canceled","price":"9086.68","remaining_size":"0.055"}
{"type":"done","side":"buy","product_id":"BTC-USD","time":"2020-06-30T19:18:05.522950Z","sequence":180757588,"order_id":"0fe5637d-8c7f-4ee3-af40-79927d5bf436","reason":"canceled","price":"7600","remaining_size":"61.7112"}
{"type":"received","side":"buy","product_id":"BTC-USD","time":"2020-06-30T19:18:05.614115Z","sequence":180757589,"order_id":"4d8b77f7-086e-4f61-83af-5174ce3ca1bb","order_type":"limit","size":"0.0329","price":"9084.01","client_oid":""}
{"type":"open","side":"buy","product_id":"BTC-USD","time":"2020-06-30T19:18:05.614115Z","sequence":180757590,"price":"9084.01","order_id":"4d8b77f7-086e-4f61-83af-5174ce3ca1bb","remaining_size":"0.0329"}
{"type":"heartbeat","last_trade_id":0,"product_id":"BTC-USD","sequence":180757590,"time":"2020-06-30T19:18:05.735094Z"}
{"type":"received","side":"sell","product_id":"BTC-USD","time":"2020-06-30T19:18:05.933173Z","sequence":180757591,"order_id":"3495cfa9-e25a-46fe-985e-d8a8a2d321c5","order_type":"limit","size":"0.002","price":"9175.72","client_oid":""}
{"type":"open","side":"sell","product_id":"BTC-USD","time":"2020-06-30T19:18:05.933173Z","sequence":180757592,"price":"9175.72","order_id":"3495cfa9-e25a-46fe-985e-d8a8a2d321c5","remaining_size":"0.002"}
{"type":"done","side":"sell","product_id":"BTC-USD","time":"2020-06-30T19:18:06.155535Z","sequence":180757593,"order_id":"df6ae444-084e-4eb3-9f3b-bbb4a4a522a1","reason":"canceled","price":"9129.79","remaining_size":"2.5837"}
{"type":"heartbeat","last_trade_id":0,"product_id":"BTC-USD","sequence":180757593,"time":"2020-06-30T19:18:06.735122Z"}
{"type":"received","side":"sell","product_id":"BTC-USD","time":"2020-06-30T19:18:07.359289Z","sequence":180757594,"order_id":"7fa761ac-0280-497d-b0bb-ebc632553e79","order_type":"limit","size":"0.0658","price":"9125.11","client_oid":""}
{"type":"open","side":"sell","product_id":"BTC-USD","time":"2020-06-30T19:18:07.359289Z","sequence":180757595,"price":"9125.11","order_id":"7fa761ac-0280-497d-b0bb-ebc632553e79","remaining_size":"0.0658"}
{"type":"received","side":"buy","product_id":"BTC-USD","time":"2020-06-30T19:18:07.639354Z","sequence":180757596,"order_id":"e325eb65-e10c-41f0-b7a2-aed8a846c0ef","order_type":"limit","size":"0.1243","price":"9121.1","client_oid":""}
{"type":"match","side":"sell","product_id":"BTC-USD","time":"2020-06-30T19:18:07.639354Z","sequence":180757597,"trade_id":14587672,"maker_order_id":"36fe0734-4801-466d-b093-cccd411db09a","taker_order_id":"e325eb65-e10c-41f0-b7a2-aed8a846c0ef","size":"0.1243","price":"9120.82"}
{"type":"done","side":"buy","product_id":"BTC-USD","time":"2020-06-30T19:18:07.639354Z","sequence":180757598,"order_id":"e325eb65-e10c-41f0-b7a2-aed8a846c0ef","reason":"filled","price":"9121.1","remaining_size":"0"}
{"type":"heartbeat","last_trade_id":0,"product_id":"BTC-USD","sequence":180757598,"time":"2020-06-30T19:18:07.734987Z"}
{"type":"done","side":"buy","product_id":"BTC-USD","time":"2020-06-30T19:18:08.109319Z","sequence":180757599,"order_id":"e5c972dd-9c74-4139-9276-b2dec2ad6fab","reason":"canceled","price":"9119.12","remaining_size":"0.9"}
{"type":"received","side":"sell","product_id":"BTC-USD","time":"2020-06-30T19:18:08.210443Z","sequence":180757600,"order_id":"3b9b94bc-90b1-41c2-8269-152183b5d168","order_type":"limit","size":"0.0658","price":"9125.14","client_oid":""}
{"type":"open","side":"sell","product_id":"BTC-USD","time":"2020-06-30T19:18:08.210443Z","sequence":180757601,"price":"9125.14","order_id":"3b9b94bc-90b1-41c2-8269-152183b5d168","remaining_size":"0.0658"}
{"type":"received","side":"buy","product_id":"BTC-USD","time":"2020-06-30T19:18:08.470570Z","sequence":180757602,"order_id":"fff09723-f38a-48a2-8524-996387161305","order_type":"limit","size":"0.1243","price":"9121.37","client_oid":""}
{"type":"match","side":"sell","product_id":"BTC-USD","time":"2020-06-30T19:18:08.470570Z","sequence":180757603,"trade_id":14587673,"maker_order_id":"36fe0734-4801-466d-b093-cccd411db09a","taker_order_id":"fff09723-f38a-48a2-8524-996387161305","size":"0.1243","price":"9120.82"}
{"type":"done","side":"buy","product_id":"BTC-USD","time":"2020-06-30T19:18:08.470570Z","sequence":180757604,"order_id":"fff09723-f38a-48a2-8524-996387161305","reason":"filled","price":"9121.37","remaining_size":"0"}
{"type":"done","side":"sell","product_id":"BTC-USD","time":"2020-06-30T19:18:08.656977Z","sequence":180757605,"order_id":"3495cfa9-e25a-46fe-985e-d8a8a2d321c5","reason":"canceled","price":"9175.72","remaining_size":"0.002"}
{"type":"done","side":"buy","product_id":"BTC-USD","time":"2020-06-30T19:18:08.663765Z","sequence":180757606,"order_id":"4d8b77f7-086e-4f61-83af-5174ce3ca1bb","reason":"canceled","price":"9084.01","remaining_size":"0.0329"}
{"type":"done","side":"buy","product_id":"BTC-USD","time":"2020-06-30T19:18:08.671247Z","sequence":180757607,"order_id":"d28c8b6d-79f4-42a2-ab95-ffc011c96666","reason":"canceled","price":"9120.13","remaining_size":"0.0658"}
{"type":"heartbeat","last_trade_id":0,"product_id":"BTC-USD","sequence":180757607,"time":"2020-06-30T19:18:08.735129Z"}
{"type":"received","side":"sell","product_id":"BTC-USD","time":"2020-06-30T19:18:08.751970Z","sequence":180757608,"order_id":"d663a60d-f2a3-40b6-98d6-f9a5e41f8b7a","order_type":"limit","size":"0.0881","price":"9122.34","client_oid":""}
{"type":"open","side":"sell","product_id":"BTC-USD","time":"2020-06-30T19:18:08.751970Z","sequence":180757609,"price":"9122.34","order_id":"d663a60d-f2a3-40b6-98d6-f9a5e41f8b7a","remaining_size":"0.0881"}
{"type":"done","side":"sell","product_id":"BTC-USD","time":"2020-06-30T19:18:08.953880Z","sequence":180757610,"order_id":"bb7074a8-63c6-40b7-87c5-969079c2b747","reason":"canceled","price":"9155.51","remaining_size":"0.069"}
{"type":"received","side":"sell","product_id":"BTC-USD","time":"2020-06-30T19:18:09.017089Z","sequence":180757611,"order_id":"11d34603-b7cd-457f-a176-753521ea93d4","order_type":"limit","size":"0.05","price":"9121.79","client_oid":""}
{"type":"open","side":"sell","product_id":"BTC-USD","time":"2020-06-30T19:18:09.017089Z","sequence":180757612,"price":"9121.79","order_id":"11d34603-b7cd-457f-a176-753521ea93d4","remaining_size":"0.05"}
{"type":"received","side":"buy","product_id":"BTC-USD","time":"2020-06-30T19:18:09.277863Z","sequence":180757613,"order_id":"b1e2e627-003a-4056-8631-e9a90455ce77","order_type":"limit","size":"0.0329","price":"9081.95","client_oid":""}
{"type":"open","side":"buy","product_id":"BTC-USD","time":"2020-06-30T19:18:09.277863Z","sequence":180757614,"price":"9081.95","order_id":"b1e2e627-003a-4056-8631-e9a90455ce77","remaining_size":"0.0329"}
{"type":"received","side":"buy","product_id":"BTC-USD","time":"2020-06-30T19:18:09.583120Z","sequence":180757615,"order_id":"7078a3ec-cd09-4801-b423-193c7e92c6c6","order_type":"limit","size":"0.0612","price":"9120.14","client_oid":""}
{"type":"open","side":"buy","product_id":"BTC-USD","time":"2020-06-30T19:18:09.583120Z","sequence":180757616,"price":"9120.14","order_id":"7078a3ec-cd09-4801-b423-193c7e92c6c6","remaining_size":"0.0612"}
{"type":"heartbeat","last_trade_id":0,"product_id":"BTC-USD","sequence":180757616,"time":"2020-06-30T19:18:09.735077Z"}
{"type":"received","side":"sell","product_id":"BTC-USD","time":"2020-06-30T19:18:10.128505Z","sequence":180757617,"order_id":"731bd5e3-8115-463c-b3df-a3362564fd41","order_type":"limit","size":"0.0658","price":"9125.12","client_oid":""}
{"type":"open","side":"sell","product_id":"BTC-USD","time":"2020-06-30T19:18:10.128505Z","sequence":180757618,"price":"9125.12","order_id":"731bd5e3-8115-463c-b3df-a3362564fd41","remaining_size":"0.0658"}
{"type":"done","side":"sell","product_id":"BTC-USD","time":"2020-06-30T19:18:10.561558Z","sequence":180757619,"order_id":"279afeb8-364f-4f7d-b44e-1b7421c84afe","reason":"canceled","price":"9121.34","remaining_size":"0.2502"}
{"type":"received","side":"sell","product_id":"BTC-USD","time":"2020-06-30T19:18:10.675680Z","sequence":180757620,"order_id":"60835661-fff6-4c38-997f-f6f4dc7be810","order_type":"limit","size":"0.05","price":"9121.24","client_oid":""}
{"type":"open","side":"sell","product_id":"BTC-USD","time":"2020-06-30T19:18:10.675680Z","sequence":180757621,"price":"9121.24","order_id":"60835661-fff6-4c38-997f-f6f4dc7be810","remaining_size":"0.05"}
{"type":"received","side":"sell","product_id":"BTC-USD","time":"2020-06-30T19:18:10.679392Z","sequence":180757622,"order_id":"9a23ed04-927b-4a4c-83da-7a7708260b0e","order_type":"market","size":"0.001","funds":"9.1208","client_oid":""}
{"type":"match","side":"buy","product_id":"BTC-USD","time":"2020-06-30T19:18:10.679392Z","sequence":180757623,"trade_id":14587674,"maker_order_id":"91b59a7c-6a07-4039-9536-21daf3cb3282","taker_order_id":"9a23ed04-927b-4a4c-83da-7a7708260b0e","size":"0.001","price":"9120.8"}
{"type":"done","side":"sell","product_id":"BTC-USD","time":"2020-06-30T19:18:10.679392Z","sequence":180757624,"order_id":"9a23ed04-927b-4a4c-83da-7a7708260b0e","reason":"filled","remaining_size":"0"}
{"type":"heartbeat","last_trade_id":0,"product_id":"BTC-USD","sequence":180757624,"time":"2020-06-30T19:18:10.735049Z"}
{"type":"received","side":"buy","product_id":"BTC-USD","time":"2020-06-30T19:18:11.260586Z","sequence":180757625,"order_id":"d52a3a15-a295-4dd1-8434-e90b15c36752","order_type":"limit","size":"0.0012","price":"9117.7","client_oid":""}
{"type":"open","side":"buy","product_id":"BTC-USD","time":"2020-06-30T19:18:11.260586Z","sequence":180757626,"price":"9117.7","order_id":"d52a3a15-a295-4dd1-8434-e90b15c36752","remaining_size":"0.0012"}
{"type":"received","side":"buy","product_id":"BTC-USD","time":"2020-06-30T19:18:11.532527Z","sequence":180757627,"order_id":"609c544e-cabe-4ee5-bf69-8d0add8ca0e3","order_type":"limit","size":"0.0658","price":"9113.01","client_oid":""}
{"type":"open","side":"buy","product_id":"BTC-USD","time":"2020-06-30T19:18:11.532527Z","sequence":180757628,"price":"9113.01","order_id":"609c544e-cabe-4ee5-bf69-8d0add8ca0e3","remaining_size":"0.0658"}
{"type":"done","side":"buy","product_id":"BTC-USD","time":"2020-06-30T19:18:11.732632Z","sequence":180757629,"order_id":"5bfc708e-e38e-49c8-b3ba-a8184c9be9ea","reason":"canceled","price":"9114.73","remaining_size":"1.271"}
{"type":"heartbeat","last_trade_id":0,"product_id":"BTC-USD","sequence":180757629,"time":"2020-06-30T19:18:11.735096Z"}
{"type":"done","side":"buy","product_id":"BTC-USD","time":"2020-06-30T19:18:11.968293Z","sequence":180757630,"order_id":"7078a3ec-cd09-4801-b423-193c7e92c6c6","reason":"canceled","price":"9120.14","remaining_size":"0.0612"}
{"type":"received","side":"buy","product_id":"BTC-USD","time":"2020-06-30T19:18:12.708758Z","sequence":180757631,"order_id":"68c9f054-bf3e-4750-91bb-8de2bf827788","order_type":"limit","size":"0.0658","price":"9113.04","client_oid":""}
{"type":"open","side":"buy","product_id":"BTC-USD","time":"2020-06-30T19:18:12.708758Z","sequence":180757632,"price":"9113.04","order_id":"68c9f054-bf3e-4750-91bb-8de2bf827788","remaining_size":"0.0658"}
{"type":"heartbeat","last_trade_id":0,"product_id":"BTC-USD","sequence":180757632,"time":"2020-06-30T19:18:12.735110Z"}
{"type":"received","side":"buy","product_id":"BTC-USD","time":"2020-06-30T19:18:12.986793Z","sequence":180757633,"order_id":"84f54a05-6efb-4dee-8285-e44afb4317db","order_type":"limit","size":"0.01","price":"9091.19","client_oid":""}
{"type":"open","side":"buy","product_id":"BTC-USD","time":"2020-06-30T19:18:12.986793Z","sequence":180757634,"price":"9091.19","order_id":"84f54a05-6efb-4dee-8285-e44afb4317db","remaining_size":"0.01"}
{"type":"done","side":"buy","product_id":"BTC-USD","time":"2020-06-30T19:18:13.191192Z","sequence":180757635,"order_id":"02cce035-ba71-4635-9971-f30bcf6d91b7","reason":"canceled","price":"9113.09","remaining_size":"0.0658"}
{"type":"done","side":"buy","product_id":"BTC-USD","time":"2020-06-30T19:18:13.204095Z","sequence":180757636,"order_id":"283a307b-7836-4e11-b899-7f3f1bc48422","reason":"canceled","price":"9113.1","remaining_size":"0.0222"}
{"type":"received","side":"buy","product_id":"BTC-USD","time":"2020-06-30T19:18:13.300049Z","sequence":180757637,"order_id":"7ceacc06-63cc-421b-960a-e1eb881a3249","order_type":"limit","size":"0.0222","price":"9113.03","client_oid":""}
{"type":"open","side":"buy","product_id":"BTC-USD","time":"2020-06-30T19:18:13.300049Z","sequence":180757638,"price":"9113.03","order_id":"7ceacc06-63cc-421b-960a-e1eb881a3249","remaining_size":"0.0222"}
{"type":"received","side":"sell","product_id":"BTC-USD","time":"2020-06-30T19:18:13.535775Z","sequence":180757639,"order_id":"eb8fd669-34e2-4ee2-a601-efdb55fab298","order_type":"limit","size":"3.0437","price":"9121.42","client_oid":""}
{"type":"open","side":"sell","product_id":"BTC-USD","time":"2020-06-30T19:18:13.535775Z","sequence":180757640,"price":"9121.42","order_id":"eb8fd669-34e2-4ee2-a601-efdb55fab298","remaining_size":"3.0437"}
{"type":"done","side":"sell","product_id":"BTC-USD","time":"2020-06-30T19:18:13.732583Z","sequence":180757641,"order_id":"124566eb-b746-4c54-9a71-6a4c2f628448","reason":"canceled","price":"9140.28","remaining_size":"0.0221"}
{"type":"heartbeat","last_trade_id":0,"product_id":"BTC-USD","sequence":180757641,"time":"2020-06-30T19:18:13.735115Z"}
{"type":"received","side":"buy","product_id":"BTC-USD","time":"2020-06-30T19:18:13.818857Z","sequence":180757642,"order_id":"466afa94-d16a-45f0-a789-225feb7285c6","order_type":"limit","size":"0.0658","price":"9113.07","client_oid":""}
{"type":"open","side":"buy","product_id":"BTC-USD","time":"2020-06-30T19:18:13.818857Z","sequence":180757643,"price":"9113.07","order_id":"466afa94-d16a-45f0-a789-225feb7285c6","remaining_size":"0.0658"}
{"type":"received","side":"buy","product_id":"BTC-USD","time":"2020-06-30T19:18:14.038530Z","sequence":180757644,"order_id":"6a0f05b6-adcb-4379-865a-c072c74467ad","order_type":"limit","size":"0.01","price":"100","client_oid":"fde592fd-9bf5-4dd4-8440-c900926920b8"}
{"type":"open","side":"buy","product_id":"BTC-USD","time":"2020-06-30T19:18:14.038530Z","sequence":180757645,"price":"100","order_id":"6a0f05b6-adcb-4379-865a-c072c74467ad","remaining_size":"0.01"}
{"type":"done","side":"buy","product_id":"BTC-USD","time":"2020-06-30T19:18:14.044382Z","sequence":180757646,"order_id":"6a0f05b6-adcb-4379-865a-c072c74467ad","reason":"canceled","price":"100","remaining_size":"0.01"}
{"type":"received","side":"sell","product_id":"BTC-USD","time":"2020-06-30T19:18:14.700273Z","sequence":180757647,"order_id":"0645caba-acdd-4016-8970-b2b1e77cc4c3","order_type":"limit","size":"1.64","price":"9125.09","client_oid":""}
{"type":"open","side":"sell","product_id":"BTC-USD","time":"2020-06-30T19:18:14.700273Z","sequence":180757648,"price":"9125.09","order_id":"0645caba-acdd-4016-8970-b2b1e77cc4c3","remaining_size":"1.64"}
{"type":"heartbeat","last_trade_id":0,"product_id":"BTC-USD","sequence":180757648,"time":"2020-06-30T19:18:14.735113Z"}
{"type":"received","side":"sell","product_id":"BTC-USD","time":"2020-06-30T19:18:14.973589Z","sequence":180757649,"order_id":"13ce76a2-cce1-436c-b2ed-3118e87fbf2e","order_type":"limit","size":"1.5338","price":"9144.07","client_oid":""}
{"type":"open","side":"sell","product_id":"BTC-USD","time":"2020-06-30T19:18:14.973589Z","sequence":180757650,"price":"9144.07","order_id":"13ce76a2-cce1-436c-b2ed-3118e87fbf2e","remaining_size":"1.5338"}
{"type":"done","side":"sell","product_id":"BTC-USD","time":"2020-06-30T19:18:15.129988Z","sequence":180757651,"order_id":"eb8fd669-34e2-4ee2-a601-efdb55fab298","reason":"canceled","price":"9121.42","remaining_size":"3.0437"}
{"type":"received","side":"buy","product_id":"BTC-USD","time":"2020-06-30T19:18:15.251283Z","sequence":180757652,"order_id":"41c41d3f-961a-449d-b106-322ed770de62","order_type":"limit","size":"0.01","price":"9101.43","client_oid":""}
{"type":"open","side":"buy","product_id":"BTC-USD","time":"2020-06-30T19:18:15.251283Z","sequence":180757653,"price":"9101.43","order_id":"41c41d3f-961a-449d-b106-322ed770de62","remaining_size":"0.01"}
{"type":"done","side":"sell","product_id":"BTC-USD","time":"2020-06-30T19:18:15.427627Z","sequence":180757654,"order_id":"0645caba-acdd-4016-8970-b2b1e77cc4c3","reason":"canceled","price":"9125.09","remaining_size":"1.64"}
{"type":"done","side":"sell","product_id":"BTC-USD","time":"2020-06-30T19:18:15.430792Z","sequence":180757655,"order_id":"d663a60d-f2a3-40b6-98d6-f9a5e41f8b7a","reason":"canceled","price":"9122.34","remaining_size":"0.0881"}
{"type":"received","side":"sell","product_id":"BTC-USD","time":"2020-06-30T19:18:15.531119Z","sequence":180757656,"order_id":"4cd236f8-3729-43b6-ad4d-5cb82b8de4f4","order_type":"limit","size":"0.0658","price":"9124.94","client_oid":""}
{"type":"open","side":"sell","product_id":"BTC-USD","time":"2020-06-30T19:18:15.531119Z","sequence":180757657,"price":"9124.94","order_id":"4cd236f8-3729-43b6-ad4d-5cb82b8de4f4","remaining_size":"0.0658"}
{"type":"done","side":"buy","product_id":"BTC-USD","time":"2020-06-30T19:18:15.692506Z","sequence":180757658,"order_id":"609c544e-cabe-4ee5-bf69-8d0add8ca0e3","reason":"canceled","price":"9113.01","remaining_size":"0.0658"}
{"type":"done","side":"buy","product_id":"BTC-USD","time":"2020-06-30T19:18:15.703248Z","sequence":180757659,"order_id":"b1e2e627-003a-4056-8631-e9a90455ce77","reason":"canceled","price":"9081.95","remaining_size":"0.0329"}
{"type":"heartbeat","last_trade_id":0,"product_id":"BTC-USD","sequence":180757659,"time":"2020-06-30T19:18:15.735060Z"}
{"type":"done","side":"sell","product_id":"BTC-USD","time":"2020-06-30T19:18:15.978651Z","sequence":180757660,"order_id":"7fa761ac-0280-497d-b0bb-ebc632553e79","reason":"canceled","price":"9125.11","remaining_size":"0.0658"}
{"type":"done","side":"sell","product_id":"BTC-USD","time":"2020-06-30T19:18:15.984762Z","sequence":180757661,"order_id":"60835661-fff6-4c38-997f-f6f4dc7be810","reason":"canceled","price":"9121.24","remaining_size":"0.05"}
{"type":"received","side":"buy","product_id":"BTC-USD","time":"2020-06-30T19:18:16.075490Z","sequence":180757662,"order_id":"dd0322f5-1f16-4040-a522-606a7028de44","order_type":"limit","size":"0.1641","price":"9121.3","client_oid":""}
{"type":"match","side":"sell","product_id":"BTC-USD","time":"2020-06-30T19:18:16.075490Z","sequence":180757663,"trade_id":14587675,"maker_order_id":"36fe0734-4801-466d-b093-cccd411db09a","taker_order_id":"dd0322f5-1f16-4040-a522-606a7028de44","size":"0.1641","price":"9120.82"}
{"type":"done","side":"buy","product_id":"BTC-USD","time":"2020-06-30T19:18:16.075490Z","sequence":180757664,"order_id":"dd0322f5-1f16-4040-a522-606a7028de44","reason":"filled","price":"9121.3","remaining_size":"0"}
{"type":"done","side":"buy","product_id":"BTC-USD","time":"2020-06-30T19:18:16.295268Z","sequence":180757665,"order_id":"d52a3a15-a295-4dd1-8434-e90b15c36752","reason":"canceled","price":"9117.7","remaining_size":"0.0012"}
{"type":"received","side":"sell","product_id":"BTC-USD","time":"2020-06-30T19:18:16.345297Z","sequence":180757666,"order_id":"31cc69bf-b5fe-4fe2-b4b9-35e0b3d5c1df","order_type":"limit","size":"0.0325","price":"9133.78","client_oid":""}
{"type":"open","side":"sell","product_id":"BTC-USD","time":"2020-06-30T19:18:16.345297Z","sequence":180757667,"price":"9133.78","order_id":"31cc69bf-b5fe-4fe2-b4b9-35e0b3d5c1df","remaining_size":"0.0325"}
{"type":"received","side":"sell","product_id":"BTC-USD","time":"2020-06-30T19:18:16.635126Z","sequence":180757668,"order_id":"c7e45cea-f7fa-48c5-bc10-efe6a0366b46","order_type":"limit","size":"29.679","price":"9166.62","client_oid":""}
{"type":"open","side":"sell","product_id":"BTC-USD","time":"2020-06-30T19:18:16.635126Z","sequence":180757669,"price":"9166.62","order_id":"c7e45cea-f7fa-48c5-bc10-efe6a0366b46","remaining_size":"29.679"}
{"type":"heartbeat","last_trade_id":0,"product_id":"BTC-USD","sequence":180757669,"time":"2020-06-30T19:18:16.735118Z"}
{"type":"received","side":"buy","product_id":"BTC-USD","time":"2020-06-30T19:18:16.903518Z","sequence":180757670,"order_id":"531b4390-c814-4a31-92b7-70b30cea334a","order_type":"limit","size":"0.0917","price":"9122.29","client_oid":""}
{"type":"match","side":"sell","product_id":"BTC-USD","time":"2020-06-30T19:18:16.903518Z","sequence":180757671,"trade_id":14587676,"maker_order_id":"36fe0734-4801-466d-b093-cccd411db09a","taker_order_id":"531b4390-c814-4a31-92b7-70b30cea334a","size":"0.0917","price":"9120.82"}
{"type":"done","side":"buy","product_id":"BTC-USD","time":"2020-06-30T19:18:16.903518Z","sequence":180757672,"order_id":"531b4390-c814-4a31-92b7-70b30cea334a","reason":"filled","price":"9122.29","remaining_size":"0"}
{"type":"received","side":"buy","product_id":"BTC-USD","time":"2020-06-30T19:18:17.205451Z","sequence":180757673,"order_id":"65d6cfe5-dc2a-4a5d-bf64-09da334a6fc0","order_type":"limit","size":"0.0495","price":"9118.87","client_oid":""}
{"type":"open","side":"buy","product_id":"BTC-USD","time":"2020-06-30T19:18:17.205451Z","sequence":180757674,"price":"9118.87","order_id":"65d6cfe5-dc2a-4a5d-bf64-09da334a6fc0","remaining_size":"0.0495"}
{"type":"done","side":"buy","product_id":"BTC-USD","time":"2020-06-30T19:18:17.329778Z","sequence":180757675,"order_id":"7ceacc06-63cc-421b-960a-e1eb881a3249","reason":"canceled","price":"9113.03","remaining_size":"0.0222"}
{"type":"heartbeat","last_trade_id":0,"product_id":"BTC-USD","sequence":180757675,"time":"2020-06-30T19:18:17.735108Z"}
{"type":"received","side":"buy","product_id":"BTC-USD","time":"2020-06-30T19:18:17.999488Z","sequence":180757676,"order_id":"904fba81-10ef-45d2-94b8-d9eb852e3b81","order_type":"limit","size":"0.0736","price":"9087.43","client_oid":""}
{"type":"open","side":"buy","product_id":"BTC-USD","time":"2020-06-30T19:18:17.999488Z","sequence":180757677,"price":"9087.43","order_id":"904fba81-10ef-45d2-94b8-d9eb852e3b81","remaining_size":"0.0736"}
{"type":"received","side":"buy","product_id":"BTC-USD","time":"2020-06-30T19:18:18.289540Z","sequence":180757678,"order_id":"665fbab9-9b1c-4a72-b828-280e23dca87d","order_type":"limit","size":"0.01","price":"9106.72","client_oid":""}
{"type":"open","side":"buy","product_id":"BTC-USD","time":"2020-06-30T19:18:18.289540Z","sequence":180757679,"price":"9106.72","order_id":"665fbab9-9b1c-4a72-b828-280e23dca87d","remaining_size":"0.01"}
{"type":"done","side":"buy","product_id":"BTC-USD","time":"2020-06-30T19:18:18.425008Z","sequence":180757680,"order_id":"65d6cfe5-dc2a-4a5d-bf64-09da334a6fc0","reason":"canceled","price":"9118.87","remaining_size":"0.0495"}
{"type":"received","side":"buy","product_id":"BTC-USD","time":"2020-06-30T19:18:18.566422Z","sequence":180757681,"order_id":"5afe4b91-7438-45bd-80a8-f2684d535f62","order_type":"limit","size":"0.0222","price":"9115.52","client_oid":""}
{"type":"open","side":"buy","product_id":"BTC-USD","time":"2020-06-30T19:18:18.566422Z","sequence":180757682,"price":"9115.52","order_id":"5afe4b91-7438-45bd-80a8-f2684d535f62","remaining_size":"0.0222"}
{"type":"heartbeat","last_trade_id":0,"product_id":"BTC-USD","sequence":180757682,"time":"2020-06-30T19:18:18.735115Z"}
{"type":"heartbeat","last_trade_id":0,"product_id":"BTC-USD","sequence":180757682,"time":"2020-06-30T19:18:19.735060Z"}
{"type":"received","side":"buy","product_id":"BTC-USD","time":"2020-06-30T19:18:19.882002Z","sequence":180757683,"order_id":"6c1f6200-9b33-45b2-b33c-28de25ed1c37","order_type":"limit","size":"0.0877","price":"9062.97","client_oid":""}
{"type":"open","side":"buy","product_id":"BTC-USD","time":"2020-06-30T19:18:19.882002Z","sequence":180757684,"price":"9062.97","order_id":"6c1f6200-9b33-45b2-b33c-28de25ed1c37","remaining_size":"0.0877"}
{"type":"done","side":"buy","product_id":"BTC-USD","time":"2020-06-30T19:18:20.285267Z","sequence":180757685,"order_id":"7902584c-4989-4c89-ba52-c6465afe652f","reason":"canceled","price":"9115.09","remaining_size":"0.0658"}
{"type":"heartbeat","last_trade_id":0,"product_id":"BTC-USD","sequence":180757685,"time":"2020-06-30T19:18:20.735038Z"}
{"type":"received","side":"buy","product_id":"BTC-USD","time":"2020-06-30T19:18:21.019379Z","sequence":180757686,"order_id":"f04080a2-683d-4274-aa0c-574738c5125e","order_type":"limit","size":"0.0222","price":"9115.64","client_oid":""}
{"type":"open","side":"buy","product_id":"BTC-USD","time":"2020-06-30T19:18:21.019379Z","sequence":180757687,"price":"9115.64","order_id":"f04080a2-683d-4274-aa0c-574738c5125e","remaining_size":"0.0222"}
{"type":"done","side":"buy","product_id":"BTC-USD","time":"2020-06-30T19:18:21.481618Z","sequence":180757688,"order_id":"665fbab9-9b1c-4a72-b828-280e23dca87d","reason":"canceled","price":"9106.72","remaining_size":"0.01"}
{"type":"heartbeat","last_trade_id":0,"product_id":"BTC-USD","sequence":180757688,"time":"2020-06-30T19:18:21.735049Z"}
{"type":"received","side":"buy","product_id":"BTC-USD","time":"2020-06-30T19:18:21.837258Z","sequence":180757689,"order_id":"d7b27d81-8e96-4078-a2a0-1e75f767d9ea","order_type":"limit","size":"0.0658","price":"9115.69","client_oid":""}
{"type":"open","side":"buy","product_id":"BTC-USD","time":"2020-06-30T19:18:21.837258Z","sequence":180757690,"price":"9115.69","order_id":"d7b27d81-8e96-4078-a2a0-1e75f767d9ea","remaining_size":"0.0658"}
{"type":"received","side":"sell","product_id":"BTC-USD","time":"2020-06-30T19:18:22.127087Z","sequence":180757691,"order_id":"e34223e8-5259-49b7-a624-febbd6e57de3","order_type":"limit","size":"0.01","price":"9155.69","client_oid":""}
{"type":"open","side":"sell","product_id":"BTC-USD","time":"2020-06-30T19:18:22.127087Z","sequence":180757692,"price":"9155.69","order_id":"e34223e8-5259-49b7-a624-febbd6e57de3","remaining_size":"0.01"}
{"type":"done","side":"buy","product_id":"BTC-USD","time":"2020-06-30T19:18:22.260866Z","sequence":180757693,"order_id":"904fba81-10ef-45d2-94b8-d9eb852e3b81","reason":"canceled","price":"9087.43","remaining_size":"0.0736"}
{"type":"done","side":"buy","product_id":"BTC-USD","time":"2020-06-30T19:18:22.268586Z","sequence":180757694,"order_id":"f8bc6949-fdec-4c92-afa7-a31d36cb77d2","reason":"canceled","price":"9099.67","remaining_size":"0.0283"}
{"type":"received","side":"buy","product_id":"BTC-USD","time":"2020-06-30T19:18:22.390097Z","sequence":180757695,"order_id":"05a4d7e3-2fd0-4ba3-b9fe-a5a815343c9f","order_type":"limit","size":"0.01","price":"9092.56","client_oid":""}
{"type":"open","side":"buy","product_id":"BTC-USD","time":"2020-06-30T19:18:22.390097Z","sequence":180757696,"price":"9092.56","order_id":"05a4d7e3-2fd0-4ba3-b9fe-a5a815343c9f","remaining_size":"0.01"}
{"type":"done","side":"sell","product_id":"BTC-USD","time":"2020-06-30T19:18:22.555002Z","sequence":180757697,"order_id":"d62c58a2-94a7-47e3-aa33-d4b32f3372f3","reason":"canceled","price":"9131.3","remaining_size":"0.9247"}
{"type":"done","side":"sell","product_id":"BTC-USD","time":"2020-06-30T19:18:22.595274Z","sequence":180757698,"order_id":"11d34603-b7cd-457f-a176-753521ea93d4","reason":"canceled","price":"9121.79","remaining_size":"0.05"}
{"type":"heartbeat","last_trade_id":0,"product_id":"BTC-USD","sequence":180757698,"time":"2020-06-30T19:18:22.735097Z"}
{"type":"done","side":"buy","product_id":"BTC-USD","time":"2020-06-30T19:18:22.845492Z","sequence":180757699,"order_id":"5afe4b91-7438-45bd-80a8-f2684d535f62","reason":"canceled","price":"9115.52","remaining_size":"0.0222"}
{"type":"received","side":"buy","product_id":"BTC-USD","time":"2020-06-30T19:18:22.945131Z","sequence":180757700,"order_id":"19457460-6d8b-4386-b690-675c8f66ee19","order_type":"limit","size":"0.0495","price":"9118.93","client_oid":""}
{"type":"open","side":"buy","product_id":"BTC-USD","time":"2020-06-30T19:18:22.945131Z","sequence":180757701,"price":"9118.93","order_id":"19457460-6d8b-4386-b690-675c8f66ee19","remaining_size":"0.0495"}
{"type":"heartbeat","last_trade_id":0,"product_id":"BTC-USD","sequence":180757701,"time":"2020-06-30T19:18:23.735072Z"}
{"type":"received","side":"buy","product_id":"BTC-USD","time":"2020-06-30T19:18:24.453620Z","sequence":180757702,"order_id":"d949aaf1-fa3a-42d9-b787-563b15e149d3","order_type":"limit","size":"0.0222","price":"9115.16","client_oid":""}
{"type":"open","side":"buy","product_id":"BTC-USD","time":"2020-06-30T19:18:24.453620Z","sequence":180757703,"price":"9115.16","order_id":"d949aaf1-fa3a-42d9-b787-563b15e149d3","remaining_size":"0.0222"}
{"type":"received","side":"buy","product_id":"BTC-USD","time":"2020-06-30T19:18:24.742027Z","sequence":180757704,"order_id":"a46d7aa7-659f-4e23-a216-33925e9d9c04","order_type":"limit","size":"0.0658","price":"9115.19","client_oid":""}
{"type":"open","side":"buy","product_id":"BTC-USD","time":"2020-06-30T19:18:24.742027Z","sequence":180757705,"price":"9115.19","order_id":"a46d7aa7-659f-4e23-a216-33925e9d9c04","remaining_size":"0.0658"}
{"type":"heartbeat","last_trade_id":0,"product_id":"BTC-USD","sequence":180757705,"time":"2020-06-30T19:18:24.735038Z"}
{"type":"done","side":"buy","product_id":"BTC-USD","time":"2020-06-30T19:18:24.943657Z","sequence":180757706,"order_id":"466afa94-d16a-45f0-a789-225feb7285c6","reason":"canceled","price":"9113.07","remaining_size":"0.0658"}
{"type":"done","side":"buy","product_id":"BTC-USD","time":"2020-06-30T19:18:25.217565Z","sequence":180757707,"order_id":"6c1f6200-9b33-45b2-b33c-28de25ed1c37","reason":"canceled","price":"9062.97","remaining_size":"0.0877"}
{"type":"received","side":"sell","product_id":"BTC-USD","time":"2020-06-30T19:18:25.695373Z","sequence":180757708,"order_id":"e41e3d71-e882-4f64-a804-2d039a7d508f","order_type":"limit","size":"0.0885","price":"9124","client_oid":""}
{"type":"open","side":"sell","product_id":"BTC-USD","time":"2020-06-30T19:18:25.695373Z","sequence":180757709,"price":"9124","order_id":"e41e3d71-e882-4f64-a804-2d039a7d508f","remaining_size":"0.0885"}
{"type":"heartbeat","last_trade_id":0,"product_id":"BTC-USD","sequence":180757709,"time":"2020-06-30T19:18:25.735096Z"}
{"type":"done","side":"sell","product_id":"BTC-USD","time":"2020-06-30T19:18:26.153925Z","sequence":180757710,"order_id":"c7e45cea-f7fa-48c5-bc10-efe6a0366b46","reason":"canceled","price":"9166.62","remaining_size":"29.679"}
{"type":"received","side":"sell","product_id":"BTC-USD","time":"2020-06-30T19:18:26.556045Z","sequence":180757711,"order_id":"c24d7a5d-003d-436f-9b54-3a6be6e1d2ac","order_type":"limit","size":"4.0885","price":"9124","client_oid":""}
{"type":"open","side":"sell","product_id":"BTC-USD","time":"2020-06-30T19:18:26.556045Z","sequence":180757712,"price":"9124","order_id":"c24d7a5d-003d-436f-9b54-3a6be6e1d2ac","remaining_size":"4.0885"}
{"type":"heartbeat","last_trade_id":0,"product_id":"BTC-USD","sequence":180757712,"time":"2020-06-30T19:18:26.735119Z"}
{"type":"received","side":"sell","product_id":"BTC-USD","time":"2020-06-30T19:18:26.826699Z","sequence":180757713,"order_id":"23ccf206-8785-4887-b8a6-2014ec47c10b","order_type":"limit","size":"0.1","price":"9137.53","client_oid":""}
{"type":"open","side":"sell","product_id":"BTC-USD","time":"2020-06-30T19:18:26.826699Z","sequence":180757714,"price":"9137.53","order_id":"23ccf206-8785-4887-b8a6-2014ec47c10b","remaining_size":"0.1"}
{"type":"done","side":"sell","product_id":"BTC-USD","time":"2020-06-30T19:18:27.038058Z","sequence":180757715,"order_id":"4712c6f5-74b5-4031-a053-021d02c89ade","reason":"canceled","price":"9155.64","remaining_size":"0.069"}
{"type":"heartbeat","last_trade_id":0,"product_id":"BTC-USD","sequence":180757715,"time":"2020-06-30T19:18:27.735114Z"}
{"type":"received","side":"buy","product_id":"BTC-USD","time":"2020-06-30T19:18:27.914957Z","sequence":180757716,"order_id":"00c838a6-d500-45eb-ac0a-a5c03e896041","order_type":"limit","size":"0.0141","price":"9121.8","client_oid":""}
{"type":"match","side":"sell","product_id":"BTC-USD","time":"2020-06-30T19:18:27.914957Z","sequence":180757717,"trade_id":14587677,"maker_order_id":"36fe0734-4801-466d-b093-cccd411db09a","taker_order_id":"00c838a6-d500-45eb-ac0a-a5c03e896041","size":"0.0141","price":"9120.82"}
{"type":"done","side":"buy","product_id":"BTC-USD","time":"2020-06-30T19:18:27.914957Z","sequence":180757718,"order_id":"00c838a6-d500-45eb-ac0a-a5c03e896041","reason":"filled","price":"9121.8","remaining_size":"0"}
{"type":"heartbeat","last_trade_id":0,"product_id":"BTC-USD","sequence":180757718,"time":"2020-06-30T19:18:28.735113Z"}
{"type":"received","side":"buy","product_id":"BTC-USD","time":"2020-06-30T19:18:29.059496Z","sequence":180757719,"order_id":"b728b68a-6892-4be7-adf4-4ada978c838a","order_type":"limit","size":"0.01","price":"100","client_oid":"0f891f75-8dec-474a-ad72-a79f70a9c33d"}
{"type":"open","side":"buy","product_id":"BTC-USD","time":"2020-06-30T19:18:29.059496Z","sequence":180757720,"price":"100","order_id":"b728b68a-6892-4be7-adf4-4ada978c838a","remaining_size":"0.01"}
{"type":"done","side":"buy","product_id":"BTC-USD","time":"2020-06-30T19:18:29.066958Z","sequence":180757721,"order_id":"b728b68a-6892-4be7-adf4-4ada978c838a","reason":"canceled","price":"100","remaining_size":"0.01"}
{"type":"heartbeat","last_trade_id":0,"product_id":"BTC-USD","sequence":180757721,"time":"2020-06-30T19:18:29.735110Z"}
{"type":"received","side":"buy","product_id":"BTC-USD","time":"2020-06-30T19:18:29.858520Z","sequence":180757722,"order_id":"9e7c7c12-d455-4a8e-b85f-7d68f70d485d","order_type":"limit","size":"0.0736","price":"9087.43","client_oid":""}
{"type":"open","side":"buy","product_id":"BTC-USD","time":"2020-06-30T19:18:29.858520Z","sequence":180757723,"price":"9087.43","order_id":"9e7c7c12-d455-4a8e-b85f-7d68f70d485d","remaining_size":"0.0736"}
{"type":"done","side":"buy","product_id":"BTC-USD","time":"2020-06-30T19:18:30.076893Z","sequence":180757724,"order_id":"a46d7aa7-659f-4e23-a216-33925e9d9c04","reason":"canceled","price":"9115.19","remaining_size":"0.0658"}
{"type":"done","side":"buy","product_id":"BTC-USD","time":"2020-06-30T19:18:30.079895Z","sequence":180757725,"order_id":"f04080a2-683d-4274-aa0c-574738c5125e","reason":"canceled","price":"9115.64","remaining_size":"0.0222"}
{"type":"received","side":"buy","product_id":"BTC-USD","time":"2020-06-30T19:18:30.132539Z","sequence":180757726,"order_id":"7250fca8-dfe8-4c7e-8bf3-695cebdbb1ea","order_type":"limit","size":"0.2072","price":"9122.19","client_oid":""}
{"type":"match","side":"sell","product_id":"BTC-USD","time":"2020-06-30T19:18:30.132539Z","sequence":180757727,"trade_id":14587678,"maker_order_id":"36fe0734-4801-466d-b093-cccd411db09a","taker_order_id":"7250fca8-dfe8-4c7e-8bf3-695cebdbb1ea","size":"0.2072","price":"9120.82"}
{"type":"done","side":"buy","product_id":"BTC-USD","time":"2020-06-30T19:18:30.132539Z","sequence":180757728,"order_id":"7250fca8-dfe8-4c7e-8bf3-695cebdbb1ea","reason":"filled","price":"9122.19","remaining_size":"0"}
{"type":"received","side":"buy","product_id":"BTC-USD","time":"2020-06-30T19:18:30.400371Z","sequence":180757729,"order_id":"eb564999-2199-4dd2-abcc-2027471ed825","order_type":"limit","size":"0.546","price":"9119.2","client_oid":""}
{"type":"open","side":"buy","product_id":"BTC-USD","time":"2020-06-30T19:18:30.400371Z","sequence":180757730,"price":"9119.2","order_id":"eb564999-2199-4dd2-abcc-2027471ed825","remaining_size":"0.546"}
{"type":"done","side":"buy","product_id":"BTC-USD","time":"2020-06-30T19:18:30.604060Z","sequence":180757731,"order_id":"9e7c7c12-d455-4a8e-b85f-7d68f70d485d","reason":"canceled","price":"9087.43","remaining_size":"0.0736"}
{"type":"done","side":"buy","product_id":"BTC-USD","time":"2020-06-30T19:18:30.610374Z","sequence":180757732,"order_id":"05a4d7e3-2fd0-4ba3-b9fe-a5a815343c9f","reason":"canceled","price":"9092.56","remaining_size":"0.01"}
{"type":"heartbeat","last_trade_id":0,"product_id":"BTC-USD","sequence":180757732,"time":"2020-06-30T19:18:30.735113Z"}
{"type":"received","side":"sell","product_id":"BTC-USD","time":"2020-06-30T19:18:30.975509Z","sequence":180757733,"order_id":"cb348166-de31-4172-91ad-c3dd0bab39e3","order_type":"limit","size":"0.0658","price":"9124.95","client_oid":""}
{"type":"open","side":"sell","product_id":"BTC-USD","time":"2020-06-30T19:18:30.975509Z","sequence":180757734,"price":"9124.95","order_id":"cb348166-de31-4172-91ad-c3dd0bab39e3","remaining_size":"0.0658"}
{"type":"received","side":"buy","product_id":"BTC-USD","time":"2020-06-30T19:18:31.236682Z","sequence":180757735,"order_id":"833a61cc-5792-46b0-abfe-84d671f5a13f","order_type":"limit","size":"0.9","price":"9122.85","client_oid":""}
{"type":"match","side":"sell","product_id":"BTC-USD","time":"2020-06-30T19:18:31.236682Z","sequence":180757736,"trade_id":14587679,"maker_order_id":"36fe0734-4801-466d-b093-cccd411db09a","taker_order_id":"833a61cc-5792-46b0-abfe-84d671f5a13f","size":"0.9","price":"9120.82"}
{"type":"done","side":"buy","product_id":"BTC-USD","time":"2020-06-30T19:18:31.236682Z","sequence":180757737,"order_id":"833a61cc-5792-46b0-abfe-84d671f5a13f","reason":"filled","price":"9122.85","remaining_size":"0"}
{"type":"done","side":"sell","product_id":"BTC-USD","time":"2020-06-30T19:18:31.420821Z","sequence":180757738,"order_id":"3b9b94bc-90b1-41c2-8269-152183b5d168","reason":"canceled","price":"9125.14","remaining_size":"0.0658"}
{"type":"heartbeat","last_trade_id":0,"product_id":"BTC-USD","sequence":180757738,"time":"2020-06-30T19:18:31.735118Z"}
{"type":"received","side":"sell","product_id":"BTC-USD","time":"2020-06-30T19:18:32.056843Z","sequence":180757739,"order_id":"88c97491-d0ce-4dfb-89ff-c994b8d311d9","order_type":"limit","size":"0.2","price":"9124.34","client_oid":""}
{"type":"open","side":"sell","product_id":"BTC-USD","time":"2020-06-30T19:18:32.056843Z","sequence":180757740,"price":"9124.34","order_id":"88c97491-d0ce-4dfb-89ff-c994b8d311d9","remaining_size":"0.2"}
{"type":"received","side":"buy","product_id":"BTC-USD","time":"2020-06-30T19:18:32.339070Z","sequence":180757741,"order_id":"f95a0fc4-e98c-4b18-97cd-3638a3bae93b","order_type":"limit","size":"0.05","price":"9122.83","client_oid":""}
{"type":"match","side":"sell","product_id":"BTC-USD","time":"2020-06-30T19:18:32.339070Z","sequence":180757742,"trade_id":14587680,"maker_order_id":"36fe0734-4801-466d-b093-cccd411db09a","taker_order_id":"f95a0fc4-e98c-4b18-97cd-3638a3bae93b","size":"0.05","price":"9120.82"}
{"type":"done","side":"buy","product_id":"BTC-USD","time":"2020-06-30T19:18:32.339070Z","sequence":180757743,"order_id":"f95a0fc4-e98c-4b18-97cd-3638a3bae93b","reason":"filled","price":"9122.83","remaining_size":"0"}
{"type":"done","side":"sell","product_id":"BTC-USD","time":"2020-06-30T19:18:32.485159Z","sequence":180757744,"order_id":"731bd5e3-8115-463c-b3df-a3362564fd41","reason":"canceled","price":"9125.12","remaining_size":"0.0658"}
{"type":"received","side":"sell","product_id":"BTC-USD","time":"2020-06-30T19:18:32.616349Z","sequence":180757745,"order_id":"863d4307-c17c-4450-ab75-48864589cf0d","order_type":"limit","size":"0.05","price":"9124.6","client_oid":""}
{"type":"open","side":"sell","product_id":"BTC-USD","time":"2020-06-30T19:18:32.616349Z","sequence":180757746,"price":"9124.6","order_id":"863d4307-c17c-4450-ab75-48864589cf0d","remaining_size":"0.05"}
{"type":"heartbeat","last_trade_id":0,"product_id":"BTC-USD","sequence":180757746,"time":"2020-06-30T19:18:32.735119Z"}
{"type":"received","side":"buy","product_id":"BTC-USD","time":"2020-06-30T19:18:33.730151Z","sequence":180757747,"order_id":"0c2ac004-0ea3-4ea1-8782-0936c291c61d","order_type":"limit","size":"0.1379","price":"9121.88","client_oid":""}
{"type":"match","side":"sell","product_id":"BTC-USD","time":"2020-06-30T19:18:33.730151Z","sequence":180757748,"trade_id":14587681,"maker_order_id":"36fe0734-4801-466d-b093-cccd411db09a","taker_order_id":"0c2ac004-0ea3-4ea1-8782-0936c291c61d","size":"0.1379","price":"9120.82"}
{"type":"done","side":"buy","product_id":"BTC-USD","time":"2020-06-30T19:18:33.730151Z","sequence":180757749,"order_id":"0c2ac004-0ea3-4ea1-8782-0936c291c61d","reason":"filled","price":"9121.88","remaining_size":"0"}
{"type":"heartbeat","last_trade_id":0,"product_id":"BTC-USD","sequence":180757749,"time":"2020-06-30T19:18:33.735116Z"}
{"type":"received","side":"buy","product_id":"BTC-USD","time":"2020-06-30T19:18:34.013460Z","sequence":180757750,"order_id":"092a6fb1-3910-435a-9188-bc07cec02e0a","order_type":"limit","size":"0.0141","price":"9122.74","client_oid":""}
{"type":"match","side":"sell","product_id":"BTC-USD","time":"2020-06-30T19:18:34.013460Z","sequence":180757751,"trade_id":14587682,"maker_order_id":"36fe0734-4801-466d-b093-cccd411db09a","taker_order_id":"092a6fb1-3910-435a-9188-bc07cec02e0a","size":"0.0141","price":"9120.82"}
{"type":"done","side":"buy","product_id":"BTC-USD","time":"2020-06-30T19:18:34.013460Z","sequence":180757752,"order_id":"092a6fb1-3910-435a-9188-bc07cec02e0a","reason":"filled","price":"9122.74","remaining_size":"0"}
{"type":"done","side":"buy","product_id":"BTC-USD","time":"2020-06-30T19:18:34.198066Z","sequence":180757753,"order_id":"41c41d3f-961a-449d-b106-322ed770de62","reason":"canceled","price":"9101.43","remaining_size":"0.01"}
{"type":"done","side":"buy","product_id":"BTC-USD","time":"2020-06-30T19:18:34.234401Z","sequence":180757754,"order_id":"eb564999-2199-4dd2-abcc-2027471ed825","reason":"canceled","price":"9119.2","remaining_size":"0.546"}
{"type":"done","side":"buy","product_id":"BTC-USD","time":"2020-06-30T19:18:34.244785Z","sequence":180757755,"order_id":"84f54a05-6efb-4dee-8285-e44afb4317db","reason":"canceled","price":"9091.19","remaining_size":"0.01"}
{"type":"received","side":"buy","product_id":"BTC-USD","time":"2020-06-30T19:18:34.586465Z","sequence":180757756,"order_id":"5bc67c90-f44c-4072-8d8c-bb935924182d","order_type":"limit","size":"0.1243","price":"9122.3","client_oid":""}
{"type":"match","side":"sell","product_id":"BTC-USD","time":"2020-06-30T19:18:34.586465Z","sequence":180757757,"trade_id":14587683,"maker_order_id":"36fe0734-4801-466d-b093-cccd411db09a","taker_order_id":"5bc67c90-f44c-4072-8d8c-bb935924182d","size":"0.1243","price":"9120.82"}
{"type":"done","side":"buy","product_id":"BTC-USD","time":"2020-06-30T19:18:34.586465Z","sequence":180757758,"order_id":"5bc67c90-f44c-4072-8d8c-bb935924182d","reason":"filled","price":"9122.3","remaining_size":"0"}
{"type":"done","side":"buy","product_id":"BTC-USD","time":"2020-06-30T19:18:34.721049Z","sequence":180757759,"order_id":"d949aaf1-fa3a-42d9-b787-563b15e149d3","reason":"canceled","price":"9115.16","remaining_size":"0.0222"}
{"type":"heartbeat","last_trade_id":0,"product_id":"BTC-USD","sequence":180757759,"time":"2020-06-30T19:18:34.735114Z"}
{"type":"received","side":"buy","product_id":"BTC-USD","time":"2020-06-30T19:18:35.392190Z","sequence":180757760,"order_id":"a9e3a86c-c81b-4a8e-8779-45f2962179fd","order_type":"limit","size":"4","price":"9123.43","client_oid":""}
{"type":"match","side":"sell","product_id":"BTC-USD","time":"2020-06-30T19:18:35.392190Z","sequence":180757761,"trade_id":14587684,"maker_order_id":"36fe0734-4801-466d-b093-cccd411db09a","taker_order_id":"a9e3a86c-c81b-4a8e-8779-45f2962179fd","size":"4","price":"9120.82"}
{"type":"done","side":"buy","product_id":"BTC-USD","time":"2020-06-30T19:18:35.392190Z","sequence":180757762,"order_id":"a9e3a86c-c81b-4a8e-8779-45f2962179fd","reason":"filled","price":"9123.43","remaining_size":"0"}
{"type":"heartbeat","last_trade_id":0,"product_id":"BTC-USD","sequence":180757762,"time":"2020-06-30T19:18:35.735112Z"}
{"type":"received","side":"sell","product_id":"BTC-USD","time":"2020-06-30T19:18:35.948595Z","sequence":180757763,"order_id":"9dde4708-1311-4e5f-8528-b7e25466ea2b","order_type":"limit","size":"0.1611","price":"9125.44","client_oid":""}
{"type":"open","side":"sell","product_id":"BTC-USD","time":"2020-06-30T19:18:35.948595Z","sequence":180757764,"price":"9125.44","order_id":"9dde4708-1311-4e5f-8528-b7e25466ea2b","remaining_size":"0.1611"}
{"type":"done","side":"buy","product_id":"BTC-USD","time":"2020-06-30T19:18:36.104452Z","sequence":180757765,"order_id":"19457460-6d8b-4386-b690-675c8f66ee19","reason":"canceled","price":"9118.93","remaining_size":"0.0495"}
{"type":"done","side":"sell","product_id":"BTC-USD","time":"2020-06-30T19:18:36.180579Z","sequence":180757766,"order_id":"13ce76a2-cce1-436c-b2ed-3118e87fbf2e","reason":"canceled","price":"9144.07","remaining_size":"1.5338"}
{"type":"done","side":"sell","product_id":"BTC-USD","time":"2020-06-30T19:18:36.180642Z","sequence":180757767,"order_id":"88c97491-d0ce-4dfb-89ff-c994b8d311d9","reason":"canceled","price":"9124.34","remaining_size":"0.2"}
{"type":"received","side":"sell","product_id":"BTC-USD","time":"2020-06-30T19:18:36.482625Z","sequence":180757768,"order_id":"1715322c-f462-4402-9e41-48d067fd57b5","order_type":"limit","size":"0.25","price":"9125.41","client_oid":""}
{"type":"open","side":"sell","product_id":"BTC-USD","time":"2020-06-30T19:18:36.482625Z","sequence":180757769,"price":"9125.41","order_id":"1715322c-f462-4402-9e41-48d067fd57b5","remaining_size":"0.25"}
{"type":"heartbeat","last_trade_id":0,"product_id":"BTC-USD","sequence":180757769,"time":"2020-06-30T19:18:36.735111Z"}
{"type":"received","side":"sell","product_id":"BTC-USD","time":"2020-06-30T19:18:37.312027Z","sequence":180757770,"order_id":"42f530ea-f122-4c8b-a8cd-e4c4a1bdce66","order_type":"limit","size":"0.0546","price":"9161.92","client_oid":""}
{"type":"open","side":"sell","product_id":"BTC-USD","time":"2020-06-30T19:18:37.312027Z","sequence":180757771,"price":"9161.92","order_id":"42f530ea-f122-4c8b-a8cd-e4c4a1bdce66","remaining_size":"0.0546"}
{"type":"heartbeat","last_trade_id":0,"product_id":"BTC-USD","sequence":180757771,"time":"2020-06-30T19:18:37.735114Z"}
{"type":"done","side":"sell","product_id":"BTC-USD","time":"2020-06-30T19:18:37.771820Z","sequence":180757772,"order_id":"863d4307-c17c-4450-ab75-48864589cf0d","reason":"canceled","price":"9124.6","remaining_size":"0.05"}
{"type":"received","side":"buy","product_id":"BTC-USD","time":"2020-06-30T19:18:37.864114Z","sequence":180757773,"order_id":"40b86517-89ee-4fa4-8cf5-74bb0335aa12","order_type":"limit","size":"0.001","price":"8938.22","client_oid":""}
{"type":"open","side":"buy","product_id":"BTC-USD","time":"2020-06-30T19:18:37.864114Z","sequence":180757774,"price":"8938.22","order_id":"40b86517-89ee-4fa4-8cf5-74bb0335aa12","remaining_size":"0.001"}
{"type":"received","side":"buy","product_id":"BTC-USD","time":"2020-06-30T19:18:38.132456Z","sequence":180757775,"order_id":"d03bacdd-ceb7-4a3d-9bda-fdbb72e6f71c","order_type":"limit","size":"0.05","price":"9122.97","client_oid":""}
{"type":"match","side":"sell","product_id":"BTC-USD","time":"2020-06-30T19:18:38.132456Z","sequence":180757776,"trade_id":14587685,"maker_order_id":"36fe0734-4801-466d-b093-cccd411db09a","taker_order_id":"d03bacdd-ceb7-4a3d-9bda-fdbb72e6f71c","size":"0.05","price":"9120.82"}
{"type":"done","side":"buy","product_id":"BTC-USD","time":"2020-06-30T19:18:38.132456Z","sequence":180757777,"order_id":"d03bacdd-ceb7-4a3d-9bda-fdbb72e6f71c","reason":"filled","price":"9122.97","remaining_size":"0"}
{"type":"received","side":"buy","product_id":"BTC-USD","time":"2020-06-30T19:18:38.409121Z","sequence":180757778,"order_id":"705152a1-f7bf-4935-b9c7-4015b0c66e6a","order_type":"limit","size":"0.0658","price":"9114.93","client_oid":""}
{"type":"open","side":"buy","product_id":"BTC-USD","time":"2020-06-30T19:18:38.409121Z","sequence":180757779,"price":"9114.93","order_id":"705152a1-f7bf-4935-b9c7-4015b0c66e6a","remaining_size":"0.0658"}
{"type":"heartbeat","last_trade_id":0,"product_id":"BTC-USD","sequence":180757779,"time":"2020-06-30T19:18:38.735113Z"}
{"type":"done","side":"buy","product_id":"BTC-USD","time":"2020-06-30T19:18:38.858060Z","sequence":180757780,"order_id":"a5d34e00-f67e-4caf-aca1-d8eaea53dc27","reason":"canceled","price":"9118.25","remaining_size":"0.0493"}
{"type":"received","side":"buy","product_id":"BTC-USD","time":"2020-06-30T19:18:38.989695Z","sequence":180757781,"order_id":"0808b5c1-0f94-4d65-978d-e9e9487308fa","order_type":"limit","size":"1.611","price":"9118.21","client_oid":""}
{"type":"open","side":"buy","product_id":"BTC-USD","time":"2020-06-30T19:18:38.989695Z","sequence":180757782,"price":"9118.21","order_id":"0808b5c1-0f94-4d65-978d-e9e9487308fa","remaining_size":"1.611"}
{"type":"done","side":"buy","product_id":"BTC-USD","time":"2020-06-30T19:18:39.158864Z","sequence":180757783,"order_id":"705152a1-f7bf-4935-b9c7-4015b0c66e6a","reason":"canceled","price":"9114.93","remaining_size":"0.0658"}
{"type":"received","side":"buy","product_id":"BTC-USD","time":"2020-06-30T19:18:39.540309Z","sequence":180757784,"order_id":"340265f0-716b-43aa-bd42-26472b90fd18","order_type":"limit","size":"0.004","price":"8933.37","client_oid":""}
{"type":"open","side":"buy","product_id":"BTC-USD","time":"2020-06-30T19:18:39.540309Z","sequence":180757785,"price":"8933.37","order_id":"340265f0-716b-43aa-bd42-26472b90fd18","remaining_size":"0.004"}
{"type":"heartbeat","last_trade_id":0,"product_id":"BTC-USD","sequence":180757785,"time":"2020-06-30T19:18:39.735027Z"}
{"type":"received","side":"sell","product_id":"BTC-USD","time":"2020-06-30T19:18:40.401242Z","sequence":180757786,"order_id":"ea6b7b3f-1285-447e-b774-d39cd20cd181","order_type":"limit","size":"0.0236","price":"9136.76","client_oid":""}
{"type":"open","side":"sell","product_id":"BTC-USD","time":"2020-06-30T19:18:40.401242Z","sequence":180757787,"price":"9136.76","order_id":"ea6b7b3f-1285-447e-b774-d39cd20cd181","remaining_size":"0.0236"}
{"type":"done","side":"sell","product_id":"BTC-USD","time":"2020-06-30T19:18:40.564457Z","sequence":180757788,"order_id":"9dde4708-1311-4e5f-8528-b7e25466ea2b","reason":"canceled","price":"9125.44","remaining_size":"0.1611"}
{"type":"done","side":"sell","product_id":"BTC-USD","time":"2020-06-30T19:18:40.572482Z","sequence":180757789,"order_id":"cb348166-de31-4172-91ad-c3dd0bab39e3","reason":"canceled","price":"9124.95","remaining_size":"0.0658"}
{"type":"done","side":"sell","product_id":"BTC-USD","time":"2020-06-30T19:18:40.575986Z","sequence":180757790,"order_id":"23ccf206-8785-4887-b8a6-2014ec47c10b","reason":"canceled","price":"9137.53","remaining_size":"0.1"}
{"type":"heartbeat","last_trade_id":0,"product_id":"BTC-USD","sequence":180757790,"time":"2020-06-30T19:18:40.735172Z"}
{"type":"received","side":"buy","product_id":"BTC-USD","time":"2020-06-30T19:18:40.989622Z","sequence":180757791,"order_id":"b80b0f1a-f906-4333-b78d-7e9ce23c8a56","order_type":"limit","size":"0.01","price":"9103.51","client_oid":""}
{"type":"open","side":"buy","product_id":"BTC-USD","time":"2020-06-30T19:18:40.989622Z","sequence":180757792,"price":"9103.51","order_id":"b80b0f1a-f906-4333-b78d-7e9ce23c8a56","remaining_size":"0.01"}
{"type":"received","side":"buy","product_id":"BTC-USD","time":"2020-06-30T19:18:41.258348Z","sequence":180757793,"order_id":"cb94e799-df00-44c8-95a0-6dfed2345695","order_type":"limit","size":"0.4199","price":"9122.75","client_oid":""}
{"type":"match","side":"sell","product_id":"BTC-USD","time":"2020-06-30T19:18:41.258348Z","sequence":180757794,"trade_id":14587686,"maker_order_id":"36fe0734-4801-466d-b093-cccd411db09a","taker_order_id":"cb94e799-df00-44c8-95a0-6dfed2345695","size":"0.4199","price":"9120.82"}
{"type":"done","side":"buy","product_id":"BTC-USD","time":"2020-06-30T19:18:41.258348Z","sequence":180757795,"order_id":"cb94e799-df00-44c8-95a0-6dfed2345695","reason":"filled","price":"9122.75","remaining_size":"0"}
{"type":"received","side":"buy","product_id":"BTC-USD","time":"2020-06-30T19:18:41.464109Z","sequence":180757796,"order_id":"af9f5c78-e035-40ad-b48d-395a68ba2b5d","order_type":"market","size":"0.001","funds":"9.12082","client_oid":""}
{"type":"match","side":"sell","product_id":"BTC-USD","time":"2020-06-30T19:18:41.464109Z","sequence":180757797,"trade_id":14587687,"maker_order_id":"36fe0734-4801-466d-b093-cccd411db09a","taker_order_id":"af9f5c78-e035-40ad-b48d-395a68ba2b5d","size":"0.001","price":"9120.82"}
{"type":"done","side":"buy","product_id":"BTC-USD","time":"2020-06-30T19:18:41.464109Z","sequence":180757798,"order_id":"af9f5c78-e035-40ad-b48d-395a68ba2b5d","reason":"filled","remaining_size":"0"}
{"type":"received","side":"buy","product_id":"BTC-USD","time":"2020-06-30T19:18:41.551983Z","sequence":180757799,"order_id":"dece5177-16ec-4580-90fc-8f2843ed37eb","order_type":"limit","size":"7.4239","price":"9123.91","client_oid":""}
{"type":"match","side":"sell","product_id":"BTC-USD","time":"2020-06-30T19:18:41.551983Z","sequence":180757800,"trade_id":14587688,"maker_order_id":"36fe0734-4801-466d-b093-cccd411db09a","taker_order_id":"dece5177-16ec-4580-90fc-8f2843ed37eb","size":"7.4239","price":"9120.82"}
{"type":"done","side":"buy","product_id":"BTC-USD","time":"2020-06-30T19:18:41.551983Z","sequence":180757801,"order_id":"dece5177-16ec-4580-90fc-8f2843ed37eb","reason":"filled","price":"9123.91","remaining_size":"0"}
{"type":"heartbeat","last_trade_id":0,"product_id":"BTC-USD","sequence":180757801,"time":"2020-06-30T19:18:41.735069Z"}
{"type":"heartbeat","last_trade_id":0,"product_id":"BTC-USD","sequence":180757801,"time":"2020-06-30T19:18:42.735094Z"}
{"type":"received","side":"buy","product_id":"BTC-USD","time":"2020-06-30T19:18:42.748221Z","sequence":180757802,"order_id":"c0e818c6-c310-4479-a224-55494de007b0","order_type":"limit","size":"6.7996","price":"9123.91","client_oid":""}
{"type":"match","side":"sell","product_id":"BTC-USD","time":"2020-06-30T19:18:42.748221Z","sequence":180757803,"trade_id":14587689,"maker_order_id":"36fe0734-4801-466d-b093-cccd411db09a","taker_order_id":"c0e818c6-c310-4479-a224-55494de007b0","size":"6.7996","price":"9120.82"}
{"type":"done","side":"buy","product_id":"BTC-USD","time":"2020-06-30T19:18:42.748221Z","sequence":180757804,"order_id":"c0e818c6-c310-4479-a224-55494de007b0","reason":"filled","price":"9123.91","remaining_size":"0"}
{"type":"done","side":"buy","product_id":"BTC-USD","time":"2020-06-30T19:18:42.919493Z","sequence":180757805,"order_id":"0808b5c1-0f94-4d65-978d-e9e9487308fa","reason":"canceled","price":"9118.21","remaining_size":"1.611"}
{"type":"received","side":"buy","product_id":"BTC-USD","time":"2020-06-30T19:18:43.017411Z","sequence":180757806,"order_id":"54dbcb7c-c319-49a8-86ab-dd1e0513fa0a","order_type":"limit","size":"0.05","price":"9123.52","client_oid":""}
{"type":"match","side":"sell","product_id":"BTC-USD","time":"2020-06-30T19:18:43.017411Z","sequence":180757807,"trade_id":14587690,"maker_order_id":"36fe0734-4801-466d-b093-cccd411db09a","taker_order_id":"54dbcb7c-c319-49a8-86ab-dd1e0513fa0a","size":"0.05","price":"9120.82"}
{"type":"done","side":"buy","product_id":"BTC-USD","time":"2020-06-30T19:18:43.017411Z","sequence":180757808,"order_id":"54dbcb7c-c319-49a8-86ab-dd1e0513fa0a","reason":"filled","price":"9123.52","remaining_size":"0"}
{"type":"done","side":"buy","product_id":"BTC-USD","time":"2020-06-30T19:18:43.474302Z","sequence":180757809,"order_id":"340265f0-716b-43aa-bd42-26472b90fd18","reason":"canceled","price":"8933.37","remaining_size":"0.004"}
{"type":"received","side":"sell","product_id":"BTC-USD","time":"2020-06-30T19:18:43.590944Z","sequence":180757810,"order_id":"1c5f9c77-6a45-4b02-84f8-040edd393c30","order_type":"limit","size":"0.3709","price":"9127.71","client_oid":""}
{"type":"open","side":"sell","product_id":"BTC-USD","time":"2020-06-30T19:18:43.590944Z","sequence":180757811,"price":"9127.71","order_id":"1c5f9c77-6a45-4b02-84f8-040edd393c30","remaining_size":"0.3709"}
{"type":"heartbeat","last_trade_id":0,"product_id":"BTC-USD","sequence":180757811,"time":"2020-06-30T19:18:43.735116Z"}
{"type":"done","side":"sell","product_id":"BTC-USD","time":"2020-06-30T19:18:44.004422Z","sequence":180757812,"order_id":"4cd236f8-3729-43b6-ad4d-5cb82b8de4f4","reason":"canceled","price":"9124.94","remaining_size":"0.0658"}
{"type":"done","side":"sell","product_id":"BTC-USD","time":"2020-06-30T19:18:44.007170Z","sequence":180757813,"order_id":"e34223e8-5259-49b7-a624-febbd6e57de3","reason":"canceled","price":"9155.69","remaining_size":"0.01"}
{"type":"done","side":"sell","product_id":"BTC-USD","time":"2020-06-30T19:18:44.014446Z","sequence":180757814,"order_id":"ea6b7b3f-1285-447e-b774-d39cd20cd181","reason":"canceled","price":"9136.76","remaining_size":"0.0236"}
{"type":"received","side":"buy","product_id":"BTC-USD","time":"2020-06-30T19:18:44.024472Z","sequence":180757815,"order_id":"76b3e6be-7225-48be-a590-57972f9a87dc","order_type":"limit","size":"0.01","price":"100","client_oid":"051589b0-19e0-4257-92b4-9bb779d162a3"}
{"type":"open","side":"buy","product_id":"BTC-USD","time":"2020-06-30T19:18:44.024472Z","sequence":180757816,"price":"100","order_id":"76b3e6be-7225-48be-a590-57972f9a87dc","remaining_size":"0.01"}
{"type":"done","side":"buy","product_id":"BTC-USD","time":"2020-06-30T19:18:44.031882Z","sequence":180757817,"order_id":"76b3e6be-7225-48be-a590-57972f9a87dc","reason":"canceled","price":"100","remaining_size":"0.01"}
{"type":"received","side":"sell","product_id":"BTC-USD","time":"2020-06-30T19:18:44.163471Z","sequence":180757818,"order_id":"32e9c1d0-1328-4ff4-b168-efbe1462758d","order_type":"limit","size":"0.1619","price":"9126.04","client_oid":""}
{"type":"open","side":"sell","product_id":"BTC-USD","time":"2020-06-30T19:18:44.163471Z","sequence":180757819,"price":"9126.04","order_id":"32e9c1d0-1328-4ff4-b168-efbe1462758d","remaining_size":"0.1619"}
{"type":"done","side":"sell","product_id":"BTC-USD","time":"2020-06-30T19:18:44.583637Z","sequence":180757820,"order_id":"b43cf272-d287-4c71-9e7e-3e9bbb63df1c","reason":"canceled","price":"9122.97","remaining_size":"0.542"}
{"type":"heartbeat","last_trade_id":0,"product_id":"BTC-USD","sequence":180757820,"time":"2020-06-30T19:18:44.735117Z"}
{"type":"received","side":"buy","product_id":"BTC-USD","time":"2020-06-30T19:18:44.782132Z","sequence":180757821,"order_id":"7d115466-33df-4d8e-a8d7-da077b634ac5","order_type":"limit","size":"0.1332","price":"9081.74","client_oid":""}
{"type":"open","side":"buy","product_id":"BTC-USD","time":"2020-06-30T19:18:44.782132Z","sequence":180757822,"price":"9081.74","order_id":"7d115466-33df-4d8e-a8d7-da077b634ac5","remaining_size":"0.1332"}
{"type":"received","side":"buy","product_id":"BTC-USD","time":"2020-06-30T19:18:45.058789Z","sequence":180757823,"order_id":"0a4a113f-3823-4db4-b18f-732258ee6167","order_type":"limit","size":"0.0222","price":"9116.98","client_oid":""}
{"type":"open","side":"buy","product_id":"BTC-USD","time":"2020-06-30T19:18:45.058789Z","sequence":180757824,"price":"9116.98","order_id":"0a4a113f-3823-4db4-b18f-732258ee6167","remaining_size":"0.0222"}
{"type":"received","side":"sell","product_id":"BTC-USD","time":"2020-06-30T19:18:45.326655Z","sequence":180757825,"order_id":"a5230680-be01-4d6a-85b1-a49e282cf559","order_type":"limit","size":"0.0151","price":"9154.54","client_oid":""}
{"type":"open","side":"sell","product_id":"BTC-USD","time":"2020-06-30T19:18:45.326655Z","sequence":180757826,"price":"9154.54","order_id":"a5230680-be01-4d6a-85b1-a49e282cf559","remaining_size":"0.0151"}
{"type":"done","side":"buy","product_id":"BTC-USD","time":"2020-06-30T19:18:45.508314Z","sequence":180757827,"order_id":"7d115466-33df-4d8e-a8d7-da077b634ac5","reason":"canceled","price":"9081.74","remaining_size":"0.1332"}
{"type":"heartbeat","last_trade_id":0,"product_id":"BTC-USD","sequence":180757827,"time":"2020-06-30T19:18:45.735111Z"}
{"type":"done","side":"sell","product_id":"BTC-USD","time":"2020-06-30T19:18:45.755989Z","sequence":180757828,"order_id":"32e9c1d0-1328-4ff4-b168-efbe1462758d","reason":"canceled","price":"9126.04","remaining_size":"0.1619"}
{"type":"received","side":"sell","product_id":"BTC-USD","time":"2020-06-30T19:18:45.897093Z","sequence":180757829,"order_id":"a618c1eb-d75f-432b-a81b-6e178d6b9f20","order_type":"limit","size":"0.9558","price":"9125.28","client_oid":""}
{"type":"open","side":"sell","product_id":"BTC-USD","time":"2020-06-30T19:18:45.897093Z","sequence":180757830,"price":"9125.28","order_id":"a618c1eb-d75f-432b-a81b-6e178d6b9f20","remaining_size":"0.9558"}
{"type":"done","side":"sell","product_id":"BTC-USD","time":"2020-06-30T19:18:46.069157Z","sequence":180757831,"order_id":"1c5f9c77-6a45-4b02-84f8-040edd393c30","reason":"canceled","price":"9127.71","remaining_size":"0.3709"}
{"type":"received","side":"buy","product_id":"BTC-USD","time":"2020-06-30T19:18:46.482371Z","sequence":180757832,"order_id":"95859387-203c-45d3-8554-21401aa23803","order_type":"limit","size":"1","price":"9124.77","client_oid":""}
{"type":"match","side":"sell","product_id":"BTC-USD","time":"2020-06-30T19:18:46.482371Z","sequence":180757833,"trade_id":14587691,"maker_order_id":"36fe0734-4801-466d-b093-cccd411db09a","taker_order_id":"95859387-203c-45d3-8554-21401aa23803","size":"1","price":"9120.82"}
{"type":"done","side":"buy","product_id":"BTC-USD","time":"2020-06-30T19:18:46.482371Z","sequence":180757834,"order_id":"95859387-203c-45d3-8554-21401aa23803","reason":"filled","price":"9124.77","remaining_size":"0"}
{"type":"heartbeat","last_trade_id":0,"product_id":"BTC-USD","sequence":180757834,"time":"2020-06-30T19:18:46.735073Z"}
{"type":"heartbeat","last_trade_id":0,"product_id":"BTC-USD","sequence":180757834,"time":"2020-06-30T19:18:47.735091Z"}
{"type":"heartbeat","last_trade_id":0,"product_id":"BTC-USD","sequence":180757834,"time":"2020-06-30T19:18:48.735127Z"}
{"type":"heartbeat","last_trade_id":0,"product_id":"BTC-USD","sequence":180757834,"time":"2020-06-30T19:18:49.735066Z"}
{"type":"received","side":"buy","product_id":"BTC-USD","time":"2020-06-30T19:18:50.564742Z","sequence":180757835,"order_id":"7126ab24-592c-44ba-8844-b830205ac5a8","order_type":"limit","size":"0.9","price":"9124.35","client_oid":""}
{"type":"match","side":"sell","product_id":"BTC-USD","time":"2020-06-30T19:18:50.564742Z","sequence":180757836,"trade_id":14587692,"maker_order_id":"36fe0734-4801-466d-b093-cccd411db09a","taker_order_id":"7126ab24-592c-44ba-8844-b830205ac5a8","size":"0.9","price":"9120.82"}
{"type":"done","side":"buy","product_id":"BTC-USD","time":"2020-06-30T19:18:50.564742Z","sequence":180757837,"order_id":"7126ab24-592c-44ba-8844-b830205ac5a8","reason":"filled","price":"9124.35","remaining_size":"0"}
{"type":"heartbeat","last_trade_id":0,"product_id":"BTC-USD","sequence":180757837,"time":"2020-06-30T19:18:50.735094Z"}
{"type":"done","side":"buy","product_id":"BTC-USD","time":"2020-06-30T19:18:51.037167Z","sequence":180757838,"order_id":"d7b27d81-8e96-4078-a2a0-1e75f767d9ea","reason":"canceled","price":"9115.69","remaining_size":"0.0658"}
{"type":"received","side":"buy","product_id":"BTC-USD","time":"2020-06-30T19:18:51.101767Z","sequence":180757839,"order_id":"348bd23a-13fe-418b-8bcc-e1d3700c41df","order_type":"limit","size":"4.9","price":"9124.72","client_oid":""}
{"type":"match","side":"sell","product_id":"BTC-USD","time":"2020-06-30T19:18:51.101767Z","sequence":180757840,"trade_id":14587693,"maker_order_id":"36fe0734-4801-466d-b093-cccd411db09a","taker_order_id":"348bd23a-13fe-418b-8bcc-e1d3700c41df","size":"4.9","price":"9120.82"}
{"type":"done","side":"buy","product_id":"BTC-USD","time":"2020-06-30T19:18:51.101767Z","sequence":180757841,"order_id":"348bd23a-13fe-418b-8bcc-e1d3700c41df","reason":"filled","price":"9124.72","remaining_size":"0"}
{"type":"received","side":"buy","product_id":"BTC-USD","time":"2020-06-30T19:18:51.372059Z","sequence":180757842,"order_id":"14b7b6aa-6def-498d-9d7c-dcdce9caee99","order_type":"limit","size":"0.0719","price":"9103.54","client_oid":""}
{"type":"open","side":"buy","product_id":"BTC-USD","time":"2020-06-30T19:18:51.372059Z","sequence":180757843,"price":"9103.54","order_id":"14b7b6aa-6def-498d-9d7c-dcdce9caee99","remaining_size":"0.0719"}
{"type":"received","side":"buy","product_id":"BTC-USD","time":"2020-06-30T19:18:51.652006Z","sequence":180757844,"order_id":"22a429da-a842-47ef-9e42-a1aae985aa33","order_type":"limit","size":"0.0606","price":"9102.31","client_oid":""}
{"type":"open","side":"buy","product_id":"BTC-USD","time":"2020-06-30T19:18:51.652006Z","sequence":180757845,"price":"9102.31","order_id":"22a429da-a842-47ef-9e42-a1aae985aa33","remaining_size":"0.0606"}
{"type":"heartbeat","last_trade_id":0,"product_id":"BTC-USD","sequence":180757845,"time":"2020-06-30T19:18:51.735115Z"}
{"type":"done","side":"buy","product_id":"BTC-USD","time":"2020-06-30T19:18:51.805152Z","sequence":180757846,"order_id":"40b86517-89ee-4fa4-8cf5-74bb0335aa12","reason":"canceled","price":"8938.22","remaining_size":"0.001"}
{"type":"received","side":"buy","product_id":"BTC-USD","time":"2020-06-30T19:18:51.959715Z","sequence":180757847,"order_id":"71f343eb-1f20-4a42-852a-dd0f23f7723d","order_type":"limit","size":"0.0606","price":"9102.72","client_oid":""}
{"type":"open","side":"buy","product_id":"BTC-USD","time":"2020-06-30T19:18:51.959715Z","sequence":180757848,"price":"9102.72","order_id":"71f343eb-1f20-4a42-852a-dd0f23f7723d","remaining_size":"0.0606"}
{"type":"done","side":"buy","product_id":"BTC-USD","time":"2020-06-30T19:18:52.370027Z","sequence":180757849,"order_id":"b80b0f1a-f906-4333-b78d-7e9ce23c8a56","reason":"canceled","price":"9103.51","remaining_size":"0.01"}
{"type":"heartbeat","last_trade_id":0,"product_id":"BTC-USD","sequence":180757849,"time":"2020-06-30T19:18:52.735119Z"}
{"type":"received","side":"buy","product_id":"BTC-USD","time":"2020-06-30T19:18:53.321874Z","sequence":180757850,"order_id":"f02f8dcc-fe9c-43d0-9bc5-b04735aa9a25","order_type":"limit","size":"0.163","price":"9122.04","client_oid":""}
{"type":"match","side":"sell","product_id":"BTC-USD","time":"2020-06-30T19:18:53.321874Z","sequence":180757851,"trade_id":14587694,"maker_order_id":"36fe0734-4801-466d-b093-cccd411db09a","taker_order_id":"f02f8dcc-fe9c-43d0-9bc5-b04735aa9a25","size":"0.163","price":"9120.82"}
{"type":"done","side":"buy","product_id":"BTC-USD","time":"2020-06-30T19:18:53.321874Z","sequence":180757852,"order_id":"f02f8dcc-fe9c-43d0-9bc5-b04735aa9a25","reason":"filled","price":"9122.04","remaining_size":"0"}
{"type":"received","side":"sell","product_id":"BTC-USD","time":"2020-06-30T19:18:53.617479Z","sequence":180757853,"order_id":"6233b210-3471-479a-8173-9fd136d98347","order_type":"limit","size":"0.1","price":"9138.02","client_oid":""}
{"type":"open","side":"sell","product_id":"BTC-USD","time":"2020-06-30T19:18:53.617479Z","sequence":180757854,"price":"9138.02","order_id":"6233b210-3471-479a-8173-9fd136d98347","remaining_size":"0.1"}
{"type":"heartbeat","last_trade_id":0,"product_id":"BTC-USD","sequence":180757854,"time":"2020-06-30T19:18:53.735094Z"}
{"type":"received","side":"buy","product_id":"BTC-USD","time":"2020-06-30T19:18:54.429848Z","sequence":180757855,"order_id":"7766cefb-0af6-4834-a242-5ec1e2501032","order_type":"limit","size":"0.1313","price":"9122.54","client_oid":""}
{"type":"match","side":"sell","product_id":"BTC-USD","time":"2020-06-30T19:18:54.429848Z","sequence":180757856,"trade_id":14587695,"maker_order_id":"36fe0734-4801-466d-b093-cccd411db09a","taker_order_id":"7766cefb-0af6-4834-a242-5ec1e2501032","size":"0.1313","price":"9120.82"}
{"type":"done","side":"buy","product_id":"BTC-USD","time":"2020-06-30T19:18:54.429848Z","sequence":180757857,"order_id":"7766cefb-0af6-4834-a242-5ec1e2501032","reason":"filled","price":"9122.54","remaining_size":"0"}
{"type":"done","side":"buy","product_id":"BTC-USD","time":"2020-06-30T19:18:54.599638Z","sequence":180757858,"order_id":"14b7b6aa-6def-498d-9d7c-dcdce9caee99","reason":"canceled","price":"9103.54","remaining_size":"0.0719"}
{"type":"received","side":"sell","product_id":"BTC-USD","time":"2020-06-30T19:18:54.736064Z","sequence":180757859,"order_id":"c9022366-680e-4ba1-82fc-3f3347820045","order_type":"limit","size":"0.0195","price":"9138.02","client_oid":""}
{"type":"open","side":"sell","product_id":"BTC-USD","time":"2020-06-30T19:18:54.736064Z","sequence":180757860,"price":"9138.02","order_id":"c9022366-680e-4ba1-82fc-3f3347820045","remaining_size":"0.0195"}
{"type":"heartbeat","last_trade_id":0,"product_id":"BTC-USD","sequence":180757860,"time":"2020-06-30T19:18:54.735045Z"}
{"type":"received","side":"sell","product_id":"BTC-USD","time":"2020-06-30T19:18:55.310249Z","sequence":180757861,"order_id":"7f34c367-aebe-4b80-8777-0e9a6f001849","order_type":"limit","size":"1.1932","price":"9152.27","client_oid":""}
{"type":"open","side":"sell","product_id":"BTC-USD","time":"2020-06-30T19:18:55.310249Z","sequence":180757862,"price":"9152.27","order_id":"7f34c367-aebe-4b80-8777-0e9a6f001849","remaining_size":"1.1932"}
{"type":"heartbeat","last_trade_id":0,"product_id":"BTC-USD","sequence":180757862,"time":"2020-06-30T19:18:55.735101Z"}
{"type":"done","side":"sell","product_id":"BTC-USD","time":"2020-06-30T19:18:55.768136Z","sequence":180757863,"order_id":"a618c1eb-d75f-432b-a81b-6e178d6b9f20","reason":"canceled","price":"9125.28","remaining_size":"0.9558"}
{"type":"done","side":"sell","product_id":"BTC-USD","time":"2020-06-30T19:18:55.818504Z","sequence":180757864,"order_id":"c9022366-680e-4ba1-82fc-3f3347820045","reason":"canceled","price":"9138.02","remaining_size":"0.0195"}
{"type":"received","side":"buy","product_id":"BTC-USD","time":"2020-06-30T19:18:55.934691Z","sequence":180757865,"order_id":"3a0570d9-6298-4dc7-949f-39c8b7798de6","order_type":"limit","size":"7.1861","price":"9122.9","client_oid":""}
{"type":"match","side":"sell","product_id":"BTC-USD","time":"2020-06-30T19:18:55.934691Z","sequence":180757866,"trade_id":14587696,"maker_order_id":"36fe0734-4801-466d-b093-cccd411db09a","taker_order_id":"3a0570d9-6298-4dc7-949f-39c8b7798de6","size":"7.1861","price":"9120.82"}
{"type":"done","side":"buy","product_id":"BTC-USD","time":"2020-06-30T19:18:55.934691Z","sequence":180757867,"order_id":"3a0570d9-6298-4dc7-949f-39c8b7798de6","reason":"filled","price":"9122.9","remaining_size":"0"}
{"type":"heartbeat","last_trade_id":0,"product_id":"BTC-USD","sequence":180757867,"time":"2020-06-30T19:18:56.735111Z"}
{"type":"received","side":"sell","product_id":"BTC-USD","time":"2020-06-30T19:18:56.821312Z","sequence":180757868,"order_id":"e6b758f6-5565-4429-8e91-5ebafe9602ba","order_type":"limit","size":"0.0658","price":"9124.82","client_oid":""}
{"type":"open","side":"sell","product_id":"BTC-USD","time":"2020-06-30T19:18:56.821312Z","sequence":180757869,"price":"9124.82","order_id":"e6b758f6-5565-4429-8e91-5ebafe9602ba","remaining_size":"0.0658"}
{"type":"received","side":"sell","product_id":"BTC-USD","time":"2020-06-30T19:18:57.378800Z","sequence":180757870,"order_id":"52e8da20-9005-49d5-a08b-f0463687ba09","order_type":"limit","size":"0.1095","price":"9122.91","client_oid":""}
{"type":"open","side":"sell","product_id":"BTC-USD","time":"2020-06-30T19:18:57.378800Z","sequence":180757871,"price":"9122.91","order_id":"52e8da20-9005-49d5-a08b-f0463687ba09","remaining_size":"0.1095"}
{"type":"heartbeat","last_trade_id":0,"product_id":"BTC-USD","sequence":180757871,"time":"2020-06-30T19:18:57.735112Z"}
{"type":"received","side":"sell","product_id":"BTC-USD","time":"2020-06-30T19:18:58.226739Z","sequence":180757872,"order_id":"05451b7a-205c-4263-af11-e1a2939ba2d7","order_type":"limit","size":"0.01","price":"9160.96","client_oid":""}
{"type":"open","side":"sell","product_id":"BTC-USD","time":"2020-06-30T19:18:58.226739Z","sequence":180757873,"price":"9160.96","order_id":"05451b7a-205c-4263-af11-e1a2939ba2d7","remaining_size":"0.01"}
{"type":"received","side":"buy","product_id":"BTC-USD","time":"2020-06-30T19:18:58.482350Z","sequence":180757874,"order_id":"5e70d10b-d32b-4823-84d4-8cd0adf29a17","order_type":"limit","size":"0.0658","price":"9119.23","client_oid":""}
{"type":"open","side":"buy","product_id":"BTC-USD","time":"2020-06-30T19:18:58.482350Z","sequence":180757875,"price":"9119.23","order_id":"5e70d10b-d32b-4823-84d4-8cd0adf29a17","remaining_size":"0.0658"}
{"type":"done","side":"sell","product_id":"BTC-USD","time":"2020-06-30T19:18:58.650555Z","sequence":180757876,"order_id":"52e8da20-9005-49d5-a08b-f0463687ba09","reason":"canceled","price":"9122.91","remaining_size":"0.1095"}
{"type":"heartbeat","last_trade_id":0,"product_id":"BTC-USD","sequence":180757876,"time":"2020-06-30T19:18:58.735121Z"}
{"type":"received","side":"buy","product_id":"BTC-USD","time":"2020-06-30T19:18:59.020159Z","sequence":180757877,"order_id":"72fbac36-4c7e-4750-996a-fb963bca9e18","order_type":"limit","size":"0.01","price":"100","client_oid":"c7c51d5b-2cfb-4b86-ab8a-afb8244698ac"}
{"type":"open","side":"buy","product_id":"BTC-USD","time":"2020-06-30T19:18:59.020159Z","sequence":180757878,"price":"100","order_id":"72fbac36-4c7e-4750-996a-fb963bca9e18","remaining_size":"0.01"}
{"type":"done","side":"buy","product_id":"BTC-USD","time":"2020-06-30T19:18:59.027760Z","sequence":180757879,"order_id":"72fbac36-4c7e-4750-996a-fb963bca9e18","reason":"canceled","price":"100","remaining_size":"0.01"}
{"type":"received","side":"buy","product_id":"BTC-USD","time":"2020-06-30T19:18:59.030468Z","sequence":180757880,"order_id":"f176c0f9-1de3-4caf-90b6-4620f48cb2fd","order_type":"limit","size":"0.0877","price":"9054.29","client_oid":""}
{"type":"open","side":"buy","product_id":"BTC-USD","time":"2020-06-30T19:18:59.030468Z","sequence":180757881,"price":"9054.29","order_id":"f176c0f9-1de3-4caf-90b6-4620f48cb2fd","remaining_size":"0.0877"}
{"type":"received","side":"sell","product_id":"BTC-USD","time":"2020-06-30T19:18:59.585376Z","sequence":180757882,"order_id":"e57ecc6f-d19f-4386-a6ba-da42952a74ba","order_type":"limit","size":"1.9717","price":"9126.16","client_oid":""}
{"type":"open","side":"sell","product_id":"BTC-USD","time":"2020-06-30T19:18:59.585376Z","sequence":180757883,"price":"9126.16","order_id":"e57ecc6f-d19f-4386-a6ba-da42952a74ba","remaining_size":"1.9717"}
{"type":"heartbeat","last_trade_id":0,"product_id":"BTC-USD","sequence":180757883,"time":"2020-06-30T19:18:59.735116Z"}
{"type":"done","side":"buy","product_id":"BTC-USD","time":"2020-06-30T19:18:59.992056Z","sequence":180757884,"order_id":"a0193aa2-a6f7-4982-85d2-9ac18dcd6100","reason":"canceled","price":"8890.1","remaining_size":"0.04692522"}
{"type":"done","side":"sell","product_id":"BTC-USD","time":"2020-06-30T19:19:00.030052Z","sequence":180757885,"order_id":"e41e3d71-e882-4f64-a804-2d039a7d508f","reason":"canceled","price":"9124","remaining_size":"0.0885"}
{"type":"done","side":"sell","product_id":"BTC-USD","time":"2020-06-30T19:19:00.042551Z","sequence":180757886,"order_id":"7f34c367-aebe-4b80-8777-0e9a6f001849","reason":"canceled","price":"9152.27","remaining_size":"1.1932"}
{"type":"received","side":"buy","product_id":"BTC-USD","time":"2020-06-30T19:19:00.124225Z","sequence":180757887,"order_id":"137b459e-ea16-4ec7-95d0-e36e45fb68b9","order_type":"limit","size":"0.25","price":"9122.24","client_oid":""}
{"type":"match","side":"sell","product_id":"BTC-USD","time":"2020-06-30T19:19:00.124225Z","sequence":180757888,"trade_id":14587697,"maker_order_id":"36fe0734-4801-466d-b093-cccd411db09a","taker_order_id":"137b459e-ea16-4ec7-95d0-e36e45fb68b9","size":"0.25","price":"9120.82"}
{"type":"done","side":"buy","product_id":"BTC-USD","time":"2020-06-30T19:19:00.124225Z","sequence":180757889,"order_id":"137b459e-ea16-4ec7-95d0-e36e45fb68b9","reason":"filled","price":"9122.24","remaining_size":"0"}
{"type":"received","side":"buy","product_id":"BTC-USD","time":"2020-06-30T19:19:00.393837Z","sequence":180757890,"order_id":"18d16032-2bf5-459e-a970-1bd824afe351","order_type":"limit","size":"0.0470187","price":"8889.35","client_oid":""}
{"type":"open","side":"buy","product_id":"BTC-USD","time":"2020-06-30T19:19:00.393837Z","sequence":180757891,"price":"8889.35","order_id":"18d16032-2bf5-459e-a970-1bd824afe351","remaining_size":"0.0470187"}
{"type":"received","side":"sell","product_id":"BTC-USD","time":"2020-06-30T19:19:00.410257Z","sequence":180757892,"order_id":"f2fffb12-7fcf-4ee7-98f1-fd366b38744b","order_type":"limit","size":"0.0658","price":"9124.64","client_oid":""}
{"type":"open","side":"sell","product_id":"BTC-USD","time":"2020-06-30T19:19:00.410257Z","sequence":180757893,"price":"9124.64","order_id":"f2fffb12-7fcf-4ee7-98f1-fd366b38744b","remaining_size":"0.0658"}
{"type":"done","side":"buy","product_id":"BTC-USD","time":"2020-06-30T19:19:00.552505Z","sequence":180757894,"order_id":"68c9f054-bf3e-4750-91bb-8de2bf827788","reason":"canceled","price":"9113.04","remaining_size":"0.0658"}
{"type":"heartbeat","last_trade_id":0,"product_id":"BTC-USD","sequence":180757894,"time":"2020-06-30T19:19:00.735113Z"}
{"type":"done","side":"sell","product_id":"BTC-USD","time":"2020-06-30T19:19:00.798436Z","sequence":180757895,"order_id":"92864363-17b9-4d43-a530-217a8c105b3d","reason":"canceled","price":"9441.09","remaining_size":"0.00766091"}
{"type":"done","side":"sell","product_id":"BTC-USD","time":"2020-06-30T19:19:00.942815Z","sequence":180757896,"order_id":"05451b7a-205c-4263-af11-e1a2939ba2d7","reason":"canceled","price":"9160.96","remaining_size":"0.01"}
{"type":"done","side":"sell","product_id":"BTC-USD","time":"2020-06-30T19:19:00.975642Z","sequence":180757897,"order_id":"c24d7a5d-003d-436f-9b54-3a6be6e1d2ac","reason":"canceled","price":"9124","remaining_size":"4.0885"}
{"type":"done","side":"sell","product_id":"BTC-USD","time":"2020-06-30T19:19:01.042810Z","sequence":180757898,"order_id":"1715322c-f462-4402-9e41-48d067fd57b5","reason":"canceled","price":"9125.41","remaining_size":"0.25"}
{"type":"received","side":"buy","product_id":"BTC-USD","time":"2020-06-30T19:19:01.104671Z","sequence":180757899,"order_id":"587b0bfc-d2f7-4a09-865e-f7800ffb86b7","order_type":"limit","size":"0.01","price":"9096.68","client_oid":""}
{"type":"open","side":"buy","product_id":"BTC-USD","time":"2020-06-30T19:19:01.104671Z","sequence":180757900,"price":"9096.68","order_id":"587b0bfc-d2f7-4a09-865e-f7800ffb86b7","remaining_size":"0.01"}
{"type":"received","side":"sell","product_id":"BTC-USD","time":"2020-06-30T19:19:01.229149Z","sequence":180757901,"order_id":"bbb02623-9772-4a57-910c-c5a5f17311bc","order_type":"limit","size":"0.0077523","price":"9441.89","client_oid":""}
{"type":"open","side":"sell","product_id":"BTC-USD","time":"2020-06-30T19:19:01.229149Z","sequence":180757902,"price":"9441.89","order_id":"bbb02623-9772-4a57-910c-c5a5f17311bc","remaining_size":"0.0077523"}
{"type":"received","side":"buy","product_id":"BTC-USD","time":"2020-06-30T19:19:01.542562Z","sequence":180757903,"order_id":"bfddb5e8-50bf-4b68-aff2-749c75a0b05c","order_type":"limit","size":"0.01","price":"9089.81","client_oid":""}
{"type":"open","side":"buy","product_id":"BTC-USD","time":"2020-06-30T19:19:01.542562Z","sequence":180757904,"price":"9089.81","order_id":"bfddb5e8-50bf-4b68-aff2-749c75a0b05c","remaining_size":"0.01"}
{"type":"heartbeat","last_trade_id":0,"product_id":"BTC-USD","sequence":180757904,"time":"2020-06-30T19:19:01.735112Z"}
{"type":"heartbeat","last_trade_id":0,"product_id":"BTC-USD","sequence":180757904,"time":"2020-06-30T19:19:02.735114Z"}
{"type":"received","side":"sell","product_id":"BTC-USD","time":"2020-06-30T19:19:02.770202Z","sequence":180757905,"order_id":"40565483-eedf-4f91-b9ca-330937f074ea","order_type":"limit","size":"0.0658","price":"9125.26","client_oid":""}
{"type":"open","side":"sell","product_id":"BTC-USD","time":"2020-06-30T19:19:02.770202Z","sequence":180757906,"price":"9125.26","order_id":"40565483-eedf-4f91-b9ca-330937f074ea","remaining_size":"0.0658"}
{"type":"received","side":"sell","product_id":"BTC-USD","time":"2020-06-30T19:19:03.606787Z","sequence":180757907,"order_id":"ee7069f7-d604-442c-9619-ce953ada6fd9","order_type":"limit","size":"0.0658","price":"9125.21","client_oid":""}
{"type":"open","side":"sell","product_id":"BTC-USD","time":"2020-06-30T19:19:03.606787Z","sequence":180757908,"price":"9125.21","order_id":"ee7069f7-d604-442c-9619-ce953ada6fd9","remaining_size":"0.0658"}
{"type":"heartbeat","last_trade_id":0,"product_id":"BTC-USD","sequence":180757908,"time":"2020-06-30T19:19:03.735061Z"}
{"type":"received","side":"sell","product_id":"BTC-USD","time":"2020-06-30T19:19:03.883507Z","sequence":180757909,"order_id":"b8f5e878-886b-4ea3-9000-a1ca48bc0e69","order_type":"limit","size":"0.0658","price":"9125.3","client_oid":""}
{"type":"open","side":"sell","product_id":"BTC-USD","time":"2020-06-30T19:19:03.883507Z","sequence":180757910,"price":"9125.3","order_id":"b8f5e878-886b-4ea3-9000-a1ca48bc0e69","remaining_size":"0.0658"}
{"type":"done","side":"sell","product_id":"BTC-USD","time":"2020-06-30T19:19:04.155696Z","sequence":180757911,"order_id":"e57ecc6f-d19f-4386-a6ba-da42952a74ba","reason":"canceled","price":"9126.16","remaining_size":"1.9717"}
{"type":"received","side":"sell","product_id":"BTC-USD","time":"2020-06-30T19:19:04.163047Z","sequence":180757912,"order_id":"f141ce69-5484-4ef1-9f03-8b2bf63a5338","order_type":"limit","size":"0.5407","price":"9128.3","client_oid":""}
{"type":"open","side":"sell","product_id":"BTC-USD","time":"2020-06-30T19:19:04.163047Z","sequence":180757913,"price":"9128.3","order_id":"f141ce69-5484-4ef1-9f03-8b2bf63a5338","remaining_size":"0.5407"}
{"type":"done","side":"sell","product_id":"BTC-USD","time":"2020-06-30T19:19:04.174159Z","sequence":180757914,"order_id":"71318ebf-abcf-4ff0-b9aa-803cd867980d","reason":"canceled","price":"9124.72","remaining_size":"0.371"}
{"type":"done","side":"sell","product_id":"BTC-USD","time":"2020-06-30T19:19:04.209092Z","sequence":180757915,"order_id":"f2fffb12-7fcf-4ee7-98f1-fd366b38744b","reason":"canceled","price":"9124.64","remaining_size":"0.0658"}
{"type":"received","side":"sell","product_id":"BTC-USD","time":"2020-06-30T19:19:04.473659Z","sequence":180757916,"order_id":"4ec60379-36a4-44f8-931c-6e19a3f748e8","order_type":"limit","size":"0.0658","price":"9125.35","client_oid":""}
{"type":"open","side":"sell","product_id":"BTC-USD","time":"2020-06-30T19:19:04.473659Z","sequence":180757917,"price":"9125.35","order_id":"4ec60379-36a4-44f8-931c-6e19a3f748e8","remaining_size":"0.0658"}
{"type":"heartbeat","last_trade_id":0,"product_id":"BTC-USD","sequence":180757917,"time":"2020-06-30T19:19:04.735100Z"}
{"type":"received","side":"sell","product_id":"BTC-USD","time":"2020-06-30T19:19:05.606222Z","sequence":180757918,"order_id":"8ee1cf15-9667-411f-b591-c94c080934a7","order_type":"limit","size":"0.0658","price":"9125.42","client_oid":""}
{"type":"open","side":"sell","product_id":"BTC-USD","time":"2020-06-30T19:19:05.606222Z","sequence":180757919,"price":"9125.42","order_id":"8ee1cf15-9667-411f-b591-c94c080934a7","remaining_size":"0.0658"}
{"type":"heartbeat","last_trade_id":0,"product_id":"BTC-USD","sequence":180757919,"time":"2020-06-30T19:19:05.735117Z"}
{"type":"done","side":"sell","product_id":"BTC-USD","time":"2020-06-30T19:19:05.952885Z","sequence":180757920,"order_id":"40565483-eedf-4f91-b9ca-330937f074ea","reason":"canceled","price":"9125.26","remaining_size":"0.0658"}
{"type":"done","side":"sell","product_id":"BTC-USD","time":"2020-06-30T19:19:05.992288Z","sequence":180757921,"order_id":"31cc69bf-b5fe-4fe2-b4b9-35e0b3d5c1df","reason":"canceled","price":"9133.78","remaining_size":"0.0325"}
{"type":"received","side":"buy","product_id":"BTC-USD","time":"2020-06-30T19:19:06.149289Z","sequence":180757922,"order_id":"a6b838b6-9335-4db9-ba0c-24973a976608","order_type":"limit","size":"0.0658","price":"9119.38","client_oid":""}
{"type":"open","side":"buy","product_id":"BTC-USD","time":"2020-06-30T19:19:06.149289Z","sequence":180757923,"price":"9119.38","order_id":"a6b838b6-9335-4db9-ba0c-24973a976608","remaining_size":"0.0658"}
{"type":"received","side":"sell","product_id":"BTC-USD","time":"2020-06-30T19:19:06.461791Z","sequence":180757924,"order_id":"16084047-7ae5-404e-96f7-8d90806f4cd8","order_type":"limit","size":"0.05","price":"9125.39","client_oid":""}
{"type":"open","side":"sell","product_id":"BTC-USD","time":"2020-06-30T19:19:06.461791Z","sequence":180757925,"price":"9125.39","order_id":"16084047-7ae5-404e-96f7-8d90806f4cd8","remaining_size":"0.05"}
{"type":"done","side":"buy","product_id":"BTC-USD","time":"2020-06-30T19:19:06.619450Z","sequence":180757926,"order_id":"22a429da-a842-47ef-9e42-a1aae985aa33","reason":"canceled","price":"9102.31","remaining_size":"0.0606"}
{"type":"done","side":"buy","product_id":"BTC-USD","time":"2020-06-30T19:19:06.620948Z","sequence":180757927,"order_id":"5e70d10b-d32b-4823-84d4-8cd0adf29a17","reason":"canceled","price":"9119.23","remaining_size":"0.0658"}
{"type":"done","side":"buy","product_id":"BTC-USD","time":"2020-06-30T19:19:06.631543Z","sequence":180757928,"order_id":"bfddb5e8-50bf-4b68-aff2-749c75a0b05c","reason":"canceled","price":"9089.81","remaining_size":"0.01"}
{"type":"heartbeat","last_trade_id":0,"product_id":"BTC-USD","sequence":180757928,"time":"2020-06-30T19:19:06.735119Z"}
{"type":"done","side":"sell","product_id":"BTC-USD","time":"2020-06-30T19:19:06.947885Z","sequence":180757929,"order_id":"a5230680-be01-4d6a-85b1-a49e282cf559","reason":"canceled","price":"9154.54","remaining_size":"0.0151"}
{"type":"received","side":"sell","product_id":"BTC-USD","time":"2020-06-30T19:19:07.317874Z","sequence":180757930,"order_id":"2fbcf9de-e8d6-4ca0-bfaf-49e756ae9e27","order_type":"limit","size":"0.0203","price":"9122.91","client_oid":""}
{"type":"open","side":"sell","product_id":"BTC-USD","time":"2020-06-30T19:19:07.317874Z","sequence":180757931,"price":"9122.91","order_id":"2fbcf9de-e8d6-4ca0-bfaf-49e756ae9e27","remaining_size":"0.0203"}
{"type":"done","side":"sell","product_id":"BTC-USD","time":"2020-06-30T19:19:07.461221Z","sequence":180757932,"order_id":"42f530ea-f122-4c8b-a8cd-e4c4a1bdce66","reason":"canceled","price":"9161.92","remaining_size":"0.0546"}
{"type":"received","side":"sell","product_id":"BTC-USD","time":"2020-06-30T19:19:07.640210Z","sequence":180757933,"order_id":"326a88a4-74dd-471b-a4f4-c305ee73979d","order_type":"limit","size":"0.0658","price":"9125","client_oid":""}
{"type":"open","side":"sell","product_id":"BTC-USD","time":"2020-06-30T19:19:07.640210Z","sequence":180757934,"price":"9125","order_id":"326a88a4-74dd-471b-a4f4-c305ee73979d","remaining_size":"0.0658"}
{"type":"heartbeat","last_trade_id":0,"product_id":"BTC-USD","sequence":180757934,"time":"2020-06-30T19:19:07.735060Z"}
{"type":"received","side":"buy","product_id":"BTC-USD","time":"2020-06-30T19:19:08.490222Z","sequence":180757935,"order_id":"1037dd98-ee9f-4e8d-b819-8d883e277873","order_type":"limit","size":"0.01","price":"9093.24","client_oid":""}
{"type":"open","side":"buy","product_id":"BTC-USD","time":"2020-06-30T19:19:08.490222Z","sequence":180757936,"price":"9093.24","order_id":"1037dd98-ee9f-4e8d-b819-8d883e277873","remaining_size":"0.01"}
{"type":"heartbeat","last_trade_id":0,"product_id":"BTC-USD","sequence":180757936,"time":"2020-06-30T19:19:08.735091Z"}
{"type":"heartbeat","last_trade_id":0,"product_id":"BTC-USD","sequence":180757936,"time":"2020-06-30T19:19:09.735117Z"}
{"type":"received","side":"sell","product_id":"BTC-USD","time":"2020-06-30T19:19:09.792397Z","sequence":180757937,"order_id":"8adf8faf-2b1f-4802-8a32-c096eae97613","order_type":"limit","size":"0.05","price":"9124.8","client_oid":""}
{"type":"open","side":"sell","product_id":"BTC-USD","time":"2020-06-30T19:19:09.792397Z","sequence":180757938,"price":"9124.8","order_id":"8adf8faf-2b1f-4802-8a32-c096eae97613","remaining_size":"0.05"}
{"type":"received","side":"sell","product_id":"BTC-USD","time":"2020-06-30T19:19:09.951226Z","sequence":180757939,"order_id":"298b32b7-cf57-436e-aba2-63b243e17dcc","order_type":"limit","size":"0.2","price":"9124.64","client_oid":""}
{"type":"open","side":"sell","product_id":"BTC-USD","time":"2020-06-30T19:19:09.951226Z","sequence":180757940,"price":"9124.64","order_id":"298b32b7-cf57-436e-aba2-63b243e17dcc","remaining_size":"0.2"}
{"type":"received","side":"sell","product_id":"BTC-USD","time":"2020-06-30T19:19:10.183608Z","sequence":180757941,"order_id":"f8ccbfaf-2c6b-4299-aa13-c518daf79546","order_type":"limit","size":"1.5","price":"9127.68","client_oid":""}
{"type":"open","side":"sell","product_id":"BTC-USD","time":"2020-06-30T19:19:10.183608Z","sequence":180757942,"price":"9127.68","order_id":"f8ccbfaf-2c6b-4299-aa13-c518daf79546","remaining_size":"1.5"}
{"type":"done","side":"sell","product_id":"BTC-USD","time":"2020-06-30T19:19:10.300272Z","sequence":180757943,"order_id":"16084047-7ae5-404e-96f7-8d90806f4cd8","reason":"canceled","price":"9125.39","remaining_size":"0.05"}
{"type":"done","side":"sell","product_id":"BTC-USD","time":"2020-06-30T19:19:10.301057Z","sequence":180757944,"order_id":"e6b758f6-5565-4429-8e91-5ebafe9602ba","reason":"canceled","price":"9124.82","remaining_size":"0.0658"}
{"type":"done","side":"sell","product_id":"BTC-USD","time":"2020-06-30T19:19:10.437541Z","sequence":180757945,"order_id":"2fbcf9de-e8d6-4ca0-bfaf-49e756ae9e27","reason":"canceled","price":"9122.91","remaining_size":"0.0203"}
{"type":"received","side":"buy","product_id":"BTC-USD","time":"2020-06-30T19:19:10.484154Z","sequence":180757946,"order_id":"48e5973f-32e5-4c5e-9da5-f9dc56e646bf","order_type":"limit","size":"0.01","price":"9093.24","client_oid":""}
{"type":"open","side":"buy","product_id":"BTC-USD","time":"2020-06-30T19:19:10.484154Z","sequence":180757947,"price":"9093.24","order_id":"48e5973f-32e5-4c5e-9da5-f9dc56e646bf","remaining_size":"0.01"}
{"type":"heartbeat","last_trade_id":0,"product_id":"BTC-USD","sequence":180757947,"time":"2020-06-30T19:19:10.735115Z"}
{"type":"received","side":"sell","product_id":"BTC-USD","time":"2020-06-30T19:19:11.072197Z","sequence":180757948,"order_id":"0826317f-c802-4229-a6c3-0b277e306bac","order_type":"market","size":"0.001","funds":"9.1208","client_oid":""}
{"type":"match","side":"buy","product_id":"BTC-USD","time":"2020-06-30T19:19:11.072197Z","sequence":180757949,"trade_id":14587698,"maker_order_id":"91b59a7c-6a07-4039-9536-21daf3cb3282","taker_order_id":"0826317f-c802-4229-a6c3-0b277e306bac","size":"0.001","price":"9120.8"}
{"type":"done","side":"sell","product_id":"BTC-USD","time":"2020-06-30T19:19:11.072197Z","sequence":180757950,"order_id":"0826317f-c802-4229-a6c3-0b277e306bac","reason":"filled","remaining_size":"0"}
{"type":"received","side":"buy","product_id":"BTC-USD","time":"2020-06-30T19:19:11.347924Z","sequence":180757951,"order_id":"7cd54fed-17d4-4551-b9da-05da7914c260","order_type":"limit","size":"0.04","price":"9122.61","client_oid":""}
{"type":"match","side":"sell","product_id":"BTC-USD","time":"2020-06-30T19:19:11.347924Z","sequence":180757952,"trade_id":14587699,"maker_order_id":"36fe0734-4801-466d-b093-cccd411db09a","taker_order_id":"7cd54fed-17d4-4551-b9da-05da7914c260","size":"0.04","price":"9120.82"}
{"type":"done","side":"buy","product_id":"BTC-USD","time":"2020-06-30T19:19:11.347924Z","sequence":180757953,"order_id":"7cd54fed-17d4-4551-b9da-05da7914c260","reason":"filled","price":"9122.61","remaining_size":"0"}
{"type":"received","side":"sell","product_id":"BTC-USD","time":"2020-06-30T19:19:11.726303Z","sequence":180757954,"order_id":"bc29394c-2634-44f0-9cd7-f2c9bacfa97f","order_type":"limit","size":"0.3277","price":"9124.63","client_oid":""}
{"type":"open","side":"sell","product_id":"BTC-USD","time":"2020-06-30T19:19:11.726303Z","sequence":180757955,"price":"9124.63","order_id":"bc29394c-2634-44f0-9cd7-f2c9bacfa97f","remaining_size":"0.3277"}
{"type":"heartbeat","last_trade_id":0,"product_id":"BTC-USD","sequence":180757955,"time":"2020-06-30T19:19:11.735119Z"}
{"type":"received","side":"sell","product_id":"BTC-USD","time":"2020-06-30T19:19:11.889946Z","sequence":180757956,"order_id":"3ee911bb-228b-456a-930b-e64cd3a096ee","order_type":"limit","size":"0.0546","price":"9162.94","client_oid":""}
{"type":"open","side":"sell","product_id":"BTC-USD","time":"2020-06-30T19:19:11.889946Z","sequence":180757957,"price":"9162.94","order_id":"3ee911bb-228b-456a-930b-e64cd3a096ee","remaining_size":"0.0546"}
{"type":"heartbeat","last_trade_id":0,"product_id":"BTC-USD","sequence":180757957,"time":"2020-06-30T19:19:12.735119Z"}
{"type":"received","side":"buy","product_id":"BTC-USD","time":"2020-06-30T19:19:12.782154Z","sequence":180757958,"order_id":"940295b9-eed7-437d-b394-b5abff21152c","order_type":"limit","size":"0.0381","price":"9089.48","client_oid":""}
{"type":"open","side":"buy","product_id":"BTC-USD","time":"2020-06-30T19:19:12.782154Z","sequence":180757959,"price":"9089.48","order_id":"940295b9-eed7-437d-b394-b5abff21152c","remaining_size":"0.0381"}
{"type":"received","side":"buy","product_id":"BTC-USD","time":"2020-06-30T19:19:13.045151Z","sequence":180757960,"order_id":"57a52560-70cf-4be2-a052-f99a2d04eaa7","order_type":"limit","size":"0.0381","price":"9089.35","client_oid":""}
{"type":"open","side":"buy","product_id":"BTC-USD","time":"2020-06-30T19:19:13.045151Z","sequence":180757961,"price":"9089.35","order_id":"57a52560-70cf-4be2-a052-f99a2d04eaa7","remaining_size":"0.0381"}
{"type":"received","side":"sell","product_id":"BTC-USD","time":"2020-06-30T19:19:13.322097Z","sequence":180757962,"order_id":"28e5ce98-ff59-4454-9ccd-69a9364c067c","order_type":"limit","size":"0.05","price":"9124.09","client_oid":""}
{"type":"open","side":"sell","product_id":"BTC-USD","time":"2020-06-30T19:19:13.322097Z","sequence":180757963,"price":"9124.09","order_id":"28e5ce98-ff59-4454-9ccd-69a9364c067c","remaining_size":"0.05"}
{"type":"heartbeat","last_trade_id":0,"product_id":"BTC-USD","sequence":180757963,"time":"2020-06-30T19:19:13.735124Z"}
{"type":"received","side":"buy","product_id":"BTC-USD","time":"2020-06-30T19:19:13.876594Z","sequence":180757964,"order_id":"9ca2512e-d89b-478e-af30-e1ddeb990e30","order_type":"limit","size":"0.9","price":"9122.95","client_oid":""}
{"type":"match","side":"sell","product_id":"BTC-USD","time":"2020-06-30T19:19:13.876594Z","sequence":180757965,"trade_id":14587700,"maker_order_id":"36fe0734-4801-466d-b093-cccd411db09a","taker_order_id":"9ca2512e-d89b-478e-af30-e1ddeb990e30","size":"0.9","price":"9120.82"}
{"type":"done","side":"buy","product_id":"BTC-USD","time":"2020-06-30T19:19:13.876594Z","sequence":180757966,"order_id":"9ca2512e-d89b-478e-af30-e1ddeb990e30","reason":"filled","price":"9122.95","remaining_size":"0"}
{"type":"received","side":"buy","product_id":"BTC-USD","time":"2020-06-30T19:19:14.020960Z","sequence":180757967,"order_id":"09ca7fd1-956d-4293-97bd-50aaf39bfdc3","order_type":"limit","size":"0.01","price":"100","client_oid":"2cb10389-8a12-4eb3-abea-50dd7a7ac9bd"}
{"type":"open","side":"buy","product_id":"BTC-USD","time":"2020-06-30T19:19:14.020960Z","sequence":180757968,"price":"100","order_id":"09ca7fd1-956d-4293-97bd-50aaf39bfdc3","remaining_size":"0.01"}
{"type":"done","side":"buy","product_id":"BTC-USD","time":"2020-06-30T19:19:14.027627Z","sequence":180757969,"order_id":"09ca7fd1-956d-4293-97bd-50aaf39bfdc3","reason":"canceled","price":"100","remaining_size":"0.01"}
{"type":"received","side":"buy","product_id":"BTC-USD","time":"2020-06-30T19:19:14.141313Z","sequence":180757970,"order_id":"2fbe1730-f4f5-47d0-93e8-dc4b1cf78dc7","order_type":"limit","size":"3.0171","price":"9123.32","client_oid":""}
{"type":"match","side":"sell","product_id":"BTC-USD","time":"2020-06-30T19:19:14.141313Z","sequence":180757971,"trade_id":14587701,"maker_order_id":"36fe0734-4801-466d-b093-cccd411db09a","taker_order_id":"2fbe1730-f4f5-47d0-93e8-dc4b1cf78dc7","size":"3.0171","price":"9120.82"}
{"type":"done","side":"buy","product_id":"BTC-USD","time":"2020-06-30T19:19:14.141313Z","sequence":180757972,"order_id":"2fbe1730-f4f5-47d0-93e8-dc4b1cf78dc7","reason":"filled","price":"9123.32","remaining_size":"0"}
{"type":"done","side":"buy","product_id":"BTC-USD","time":"2020-06-30T19:19:14.348334Z","sequence":180757973,"order_id":"48e5973f-32e5-4c5e-9da5-f9dc56e646bf","reason":"canceled","price":"9093.24","remaining_size":"0.01"}
{"type":"done","side":"buy","product_id":"BTC-USD","time":"2020-06-30T19:19:14.351716Z","sequence":180757974,"order_id":"940295b9-eed7-437d-b394-b5abff21152c","reason":"canceled","price":"9089.48","remaining_size":"0.0381"}
{"type":"done","side":"buy","product_id":"BTC-USD","time":"2020-06-30T19:19:14.363292Z","sequence":180757975,"order_id":"1037dd98-ee9f-4e8d-b819-8d883e277873","reason":"canceled","price":"9093.24","remaining_size":"0.01"}
{"type":"heartbeat","last_trade_id":0,"product_id":"BTC-USD","sequence":180757975,"time":"2020-06-30T19:19:14.735112Z"}
{"type":"received","side":"buy","product_id":"BTC-USD","time":"2020-06-30T19:19:15.026443Z","sequence":180757976,"order_id":"29b7560d-2746-4705-aae3-b2ce6462dd4c","order_type":"limit","size":"1.5","price":"9120.22","client_oid":""}
{"type":"open","side":"buy","product_id":"BTC-USD","time":"2020-06-30T19:19:15.026443Z","sequence":180757977,"price":"9120.22","order_id":"29b7560d-2746-4705-aae3-b2ce6462dd4c","remaining_size":"1.5"}
{"type":"received","side":"sell","product_id":"BTC-USD","time":"2020-06-30T19:19:15.300609Z","sequence":180757978,"order_id":"d573b402-2bb7-4876-9906-3b74ec02a41b","order_type":"limit","size":"0.0658","price":"9125.15","client_oid":""}
{"type":"open","side":"sell","product_id":"BTC-USD","time":"2020-06-30T19:19:15.300609Z","sequence":180757979,"price":"9125.15","order_id":"d573b402-2bb7-4876-9906-3b74ec02a41b","remaining_size":"0.0658"}
{"type":"heartbeat","last_trade_id":0,"product_id":"BTC-USD","sequence":180757979,"time":"2020-06-30T19:19:15.735052Z"}
{"type":"done","side":"sell","product_id":"BTC-USD","time":"2020-06-30T19:19:15.745569Z","sequence":180757980,"order_id":"326a88a4-74dd-471b-a4f4-c305ee73979d","reason":"canceled","price":"9125","remaining_size":"0.0658"}
{"type":"received","side":"buy","product_id":"BTC-USD","time":"2020-06-30T19:19:16.088168Z","sequence":180757981,"order_id":"7dc5588c-8989-471e-bf13-e6c1cd164a2c","order_type":"limit","size":"0.025","price":"9121.34","client_oid":""}
{"type":"match","side":"sell","product_id":"BTC-USD","time":"2020-06-30T19:19:16.088168Z","sequence":180757982,"trade_id":14587702,"maker_order_id":"36fe0734-4801-466d-b093-cccd411db09a","taker_order_id":"7dc5588c-8989-471e-bf13-e6c1cd164a2c","size":"0.025","price":"9120.82"}
{"type":"done","side":"buy","product_id":"BTC-USD","time":"2020-06-30T19:19:16.088168Z","sequence":180757983,"order_id":"7dc5588c-8989-471e-bf13-e6c1cd164a2c","reason":"filled","price":"9121.34","remaining_size":"0"}
{"type":"received","side":"sell","product_id":"BTC-USD","time":"2020-06-30T19:19:16.658529Z","sequence":180757984,"order_id":"3e4c8e31-8ff7-40df-876d-1fc7e310eab3","order_type":"limit","size":"0.5696","price":"9123.77","client_oid":""}
{"type":"open","side":"sell","product_id":"BTC-USD","time":"2020-06-30T19:19:16.658529Z","sequence":180757985,"price":"9123.77","order_id":"3e4c8e31-8ff7-40df-876d-1fc7e310eab3","remaining_size":"0.5696"}
{"type":"heartbeat","last_trade_id":0,"product_id":"BTC-USD","sequence":180757985,"time":"2020-06-30T19:19:16.735108Z"}
{"type":"done","side":"sell","product_id":"BTC-USD","time":"2020-06-30T19:19:17.096621Z","sequence":180757986,"order_id":"f8ccbfaf-2c6b-4299-aa13-c518daf79546","reason":"canceled","price":"9127.68","remaining_size":"1.5"}
{"type":"done","side":"sell","product_id":"BTC-USD","time":"2020-06-30T19:19:17.161948Z","sequence":180757987,"order_id":"28e5ce98-ff59-4454-9ccd-69a9364c067c","reason":"canceled","price":"9124.09","remaining_size":"0.05"}
{"type":"heartbeat","last_trade_id":0,"product_id":"BTC-USD","sequence":180757987,"time":"2020-06-30T19:19:17.735109Z"}
{"type":"received","side":"buy","product_id":"BTC-USD","time":"2020-06-30T19:19:18.063005Z","sequence":180757988,"order_id":"6ea59548-0908-451a-a9a8-13a34d24f78a","order_type":"limit","size":"0.127","price":"9123.3","client_oid":""}
{"type":"match","side":"sell","product_id":"BTC-USD","time":"2020-06-30T19:19:18.063005Z","sequence":180757989,"trade_id":14587703,"maker_order_id":"36fe0734-4801-466d-b093-cccd411db09a","taker_order_id":"6ea59548-0908-451a-a9a8-13a34d24f78a","size":"0.127","price":"9120.82"}
{"type":"done","side":"buy","product_id":"BTC-USD","time":"2020-06-30T19:19:18.063005Z","sequence":180757990,"order_id":"6ea59548-0908-451a-a9a8-13a34d24f78a","reason":"filled","price":"9123.3","remaining_size":"0"}
{"type":"received","side":"buy","product_id":"BTC-USD","time":"2020-06-30T19:19:18.346881Z","sequence":180757991,"order_id":"4d32f012-9565-4522-9c4f-abd7b975c195","order_type":"limit","size":"0.8084","price":"9113.13","client_oid":""}
{"type":"open","side":"buy","product_id":"BTC-USD","time":"2020-06-30T19:19:18.346881Z","sequence":180757992,"price":"9113.13","order_id":"4d32f012-9565-4522-9c4f-abd7b975c195","remaining_size":"0.8084"}
{"type":"done","side":"buy","product_id":"BTC-USD","time":"2020-06-30T19:19:18.520398Z","sequence":180757993,"order_id":"57a52560-70cf-4be2-a052-f99a2d04eaa7","reason":"canceled","price":"9089.35","remaining_size":"0.0381"}
{"type":"heartbeat","last_trade_id":0,"product_id":"BTC-USD","sequence":180757993,"time":"2020-06-30T19:19:18.735110Z"}
{"type":"received","side":"buy","product_id":"BTC-USD","time":"2020-06-30T19:19:19.486025Z","sequence":180757994,"order_id":"ff35a4cb-4f7a-4a4e-b6a0-f9279aa95265","order_type":"limit","size":"0.05","price":"9121.49","client_oid":""}
{"type":"match","side":"sell","product_id":"BTC-USD","time":"2020-06-30T19:19:19.486025Z","sequence":180757995,"trade_id":14587704,"maker_order_id":"36fe0734-4801-466d-b093-cccd411db09a","taker_order_id":"ff35a4cb-4f7a-4a4e-b6a0-f9279aa95265","size":"0.05","price":"9120.82"}
{"type":"done","side":"buy","product_id":"BTC-USD","time":"2020-06-30T19:19:19.486025Z","sequence":180757996,"order_id":"ff35a4cb-4f7a-4a4e-b6a0-f9279aa95265","reason":"filled","price":"9121.49","remaining_size":"0"}
{"type":"heartbeat","last_trade_id":0,"product_id":"BTC-USD","sequence":180757996,"time":"2020-06-30T19:19:19.735120Z"}
{"type":"received","side":"sell","product_id":"BTC-USD","time":"2020-06-30T19:19:19.788858Z","sequence":180757997,"order_id":"4c83bfc1-7a95-4e76-b22d-12cdbe25b6b0","order_type":"limit","size":"0.144","price":"9124.82","client_oid":""}
{"type":"open","side":"sell","product_id":"BTC-USD","time":"2020-06-30T19:19:19.788858Z","sequence":180757998,"price":"9124.82","order_id":"4c83bfc1-7a95-4e76-b22d-12cdbe25b6b0","remaining_size":"0.144"}
{"type":"done","side":"sell","product_id":"BTC-USD","time":"2020-06-30T19:19:20.238893Z","sequence":180757999,"order_id":"8adf8faf-2b1f-4802-8a32-c096eae97613","reason":"canceled","price":"9124.8","remaining_size":"0.05"}
{"type":"received","side":"buy","product_id":"BTC-USD","time":"2020-06-30T19:19:20.328270Z","sequence":180758000,"order_id":"713b3899-28e7-4065-b0c7-08ec27a090ff","order_type":"limit","size":"0.0028","price":"9123.21","client_oid":""}
{"type":"match","side":"sell","product_id":"BTC-USD","time":"2020-06-30T19:19:20.328270Z","sequence":180758001,"trade_id":14587705,"maker_order_id":"36fe0734-4801-466d-b093-cccd411db09a","taker_order_id":"713b3899-28e7-4065-b0c7-08ec27a090ff","size":"0.0028","price":"9120.82"}
{"type":"done","side":"buy","product_id":"BTC-USD","time":"2020-06-30T19:19:20.328270Z","sequence":180758002,"order_id":"713b3899-28e7-4065-b0c7-08ec27a090ff","reason":"filled","price":"9123.21","remaining_size":"0"}
{"type":"received","side":"sell","product_id":"BTC-USD","time":"2020-06-30T19:19:20.620548Z","sequence":180758003,"order_id":"25e342a0-12fc-4a67-b471-98f267177227","order_type":"limit","size":"0.0658","price":"9124.8","client_oid":""}
{"type":"open","side":"sell","product_id":"BTC-USD","time":"2020-06-30T19:19:20.620548Z","sequence":180758004,"price":"9124.8","order_id":"25e342a0-12fc-4a67-b471-98f267177227","remaining_size":"0.0658"}
{"type":"heartbeat","last_trade_id":0,"product_id":"BTC-USD","sequence":180758004,"time":"2020-06-30T19:19:20.735116Z"}
{"type":"received","side":"sell","product_id":"BTC-USD","time":"2020-06-30T19:19:20.898681Z","sequence":180758005,"order_id":"e99fba60-8748-40c0-af5e-05c542153c81","order_type":"limit","size":"0.132","price":"9124.8","client_oid":""}
{"type":"open","side":"sell","product_id":"BTC-USD","time":"2020-06-30T19:19:20.898681Z","sequence":180758006,"price":"9124.8","order_id":"e99fba60-8748-40c0-af5e-05c542153c81","remaining_size":"0.132"}
{"type":"done","side":"sell","product_id":"BTC-USD","time":"2020-06-30T19:19:21.052214Z","sequence":180758007,"order_id":"298b32b7-cf57-436e-aba2-63b243e17dcc","reason":"canceled","price":"9124.64","remaining_size":"0.2"}
{"type":"done","side":"sell","product_id":"BTC-USD","time":"2020-06-30T19:19:21.057161Z","sequence":180758008,"order_id":"6233b210-3471-479a-8173-9fd136d98347","reason":"canceled","price":"9138.02","remaining_size":"0.1"}
{"type":"done","side":"sell","product_id":"BTC-USD","time":"2020-06-30T19:19:21.065791Z","sequence":180758009,"order_id":"4ec60379-36a4-44f8-931c-6e19a3f748e8","reason":"canceled","price":"9125.35","remaining_size":"0.0658"}
{"type":"done","side":"sell","product_id":"BTC-USD","time":"2020-06-30T19:19:21.066836Z","sequence":180758010,"order_id":"d573b402-2bb7-4876-9906-3b74ec02a41b","reason":"canceled","price":"9125.15","remaining_size":"0.0658"}
{"type":"received","side":"sell","product_id":"BTC-USD","time":"2020-06-30T19:19:21.444774Z","sequence":180758011,"order_id":"fbfe1ea2-350d-4598-815a-d7df195ec7f0","order_type":"limit","size":"0.0658","price":"9125.19","client_oid":""}
{"type":"open","side":"sell","product_id":"BTC-USD","time":"2020-06-30T19:19:21.444774Z","sequence":180758012,"price":"9125.19","order_id":"fbfe1ea2-350d-4598-815a-d7df195ec7f0","remaining_size":"0.0658"}
{"type":"received","side":"buy","product_id":"BTC-USD","time":"2020-06-30T19:19:21.721134Z","sequence":180758013,"order_id":"8028734b-fed5-4ec8-97a9-a6674ba3c087","order_type":"limit","size":"0.19","price":"9124.34","client_oid":""}
{"type":"match","side":"sell","product_id":"BTC-USD","time":"2020-06-30T19:19:21.721134Z","sequence":180758014,"trade_id":14587706,"maker_order_id":"36fe0734-4801-466d-b093-cccd411db09a","taker_order_id":"8028734b-fed5-4ec8-97a9-a6674ba3c087","size":"0.19","price":"9120.82"}
{"type":"done","side":"buy","product_id":"BTC-USD","time":"2020-06-30T19:19:21.721134Z","sequence":180758015,"order_id":"8028734b-fed5-4ec8-97a9-a6674ba3c087","reason":"filled","price":"9124.34","remaining_size":"0"}
{"type":"heartbeat","last_trade_id":0,"product_id":"BTC-USD","sequence":180758015,"time":"2020-06-30T19:19:21.735114Z"}
{"type":"done","side":"sell","product_id":"BTC-USD","time":"2020-06-30T19:19:21.861473Z","sequence":180758016,"order_id":"4c83bfc1-7a95-4e76-b22d-12cdbe25b6b0","reason":"canceled","price":"9124.82","remaining_size":"0.144"}
{"type":"done","side":"buy","product_id":"BTC-USD","time":"2020-06-30T19:19:22.133491Z","sequence":180758017,"order_id":"29b7560d-2746-4705-aae3-b2ce6462dd4c","reason":"canceled","price":"9120.22","remaining_size":"1.5"}
{"type":"received","side":"sell","product_id":"BTC-USD","time":"2020-06-30T19:19:22.293940Z","sequence":180758018,"order_id":"3c325a61-91bd-47a8-8d7f-06747d523580","order_type":"limit","size":"0.0658","price":"9125.34","client_oid":""}
{"type":"open","side":"sell","product_id":"BTC-USD","time":"2020-06-30T19:19:22.293940Z","sequence":180758019,"price":"9125.34","order_id":"3c325a61-91bd-47a8-8d7f-06747d523580","remaining_size":"0.0658"}
{"type":"done","side":"sell","product_id":"BTC-USD","time":"2020-06-30T19:19:22.744820Z","sequence":180758020,"order_id":"bc29394c-2634-44f0-9cd7-f2c9bacfa97f","reason":"canceled","price":"9124.63","remaining_size":"0.3277"}
{"type":"heartbeat","last_trade_id":0,"product_id":"BTC-USD","sequence":180758020,"time":"2020-06-30T19:19:22.735089Z"}
{"type":"received","side":"sell","product_id":"BTC-USD","time":"2020-06-30T19:19:23.196801Z","sequence":180758021,"order_id":"1eefd4fa-e60c-4cfe-80b8-6528119f06b9","order_type":"limit","size":"0.1863","price":"9124.35","client_oid":""}
{"type":"open","side":"sell","product_id":"BTC-USD","time":"2020-06-30T19:19:23.196801Z","sequence":180758022,"price":"9124.35","order_id":"1eefd4fa-e60c-4cfe-80b8-6528119f06b9","remaining_size":"0.1863"}
{"type":"received","side":"buy","product_id":"BTC-USD","time":"2020-06-30T19:19:23.513384Z","sequence":180758023,"order_id":"e8612ff8-c02e-429b-b0a7-b7b42a8cbb12","order_type":"limit","size":"0.0528","price":"9124.34","client_oid":""}
{"type":"match","side":"sell","product_id":"BTC-USD","time":"2020-06-30T19:19:23.513384Z","sequence":180758024,"trade_id":14587707,"maker_order_id":"36fe0734-4801-466d-b093-cccd411db09a","taker_order_id":"e8612ff8-c02e-429b-b0a7-b7b42a8cbb12","size":"0.0528","price":"9120.82"}
{"type":"done","side":"buy","product_id":"BTC-USD","time":"2020-06-30T19:19:23.513384Z","sequence":180758025,"order_id":"e8612ff8-c02e-429b-b0a7-b7b42a8cbb12","reason":"filled","price":"9124.34","remaining_size":"0"}
{"type":"heartbeat","last_trade_id":0,"product_id":"BTC-USD","sequence":180758025,"time":"2020-06-30T19:19:23.735090Z"}
{"type":"received","side":"buy","product_id":"BTC-USD","time":"2020-06-30T19:19:24.075759Z","sequence":180758026,"order_id":"f332a409-7a56-44ce-b7f7-7176b2ae4fd9","order_type":"limit","size":"0.1015","price":"9124.34","client_oid":""}
{"type":"match","side":"sell","product_id":"BTC-USD","time":"2020-06-30T19:19:24.075759Z","sequence":180758027,"trade_id":14587708,"maker_order_id":"36fe0734-4801-466d-b093-cccd411db09a","taker_order_id":"f332a409-7a56-44ce-b7f7-7176b2ae4fd9","size":"0.1015","price":"9120.82"}
{"type":"done","side":"buy","product_id":"BTC-USD","time":"2020-06-30T19:19:24.075759Z","sequence":180758028,"order_id":"f332a409-7a56-44ce-b7f7-7176b2ae4fd9","reason":"filled","price":"9124.34","remaining_size":"0"}
{"type":"done","side":"buy","product_id":"BTC-USD","time":"2020-06-30T19:19:24.513412Z","sequence":180758029,"order_id":"f176c0f9-1de3-4caf-90b6-4620f48cb2fd","reason":"canceled","price":"9054.29","remaining_size":"0.0877"}
{"type":"received","side":"sell","product_id":"BTC-USD","time":"2020-06-30T19:19:24.617132Z","sequence":180758030,"order_id":"6b055937-68a7-42f8-9746-523c807854b3","order_type":"limit","size":"0.0658","price":"9124.96","client_oid":""}
{"type":"open","side":"sell","product_id":"BTC-USD","time":"2020-06-30T19:19:24.617132Z","sequence":180758031,"price":"9124.96","order_id":"6b055937-68a7-42f8-9746-523c807854b3","remaining_size":"0.0658"}
{"type":"heartbeat","last_trade_id":0,"product_id":"BTC-USD","sequence":180758031,"time":"2020-06-30T19:19:24.735113Z"}
{"type":"received","side":"sell","product_id":"BTC-USD","time":"2020-06-30T19:19:24.901358Z","sequence":180758032,"order_id":"e67f5d9a-2cc8-43fb-88d8-def46673fa59","order_type":"limit","size":"3.0292","price":"9147.73","client_oid":""}
{"type":"open","side":"sell","product_id":"BTC-USD","time":"2020-06-30T19:19:24.901358Z","sequence":180758033,"price":"9147.73","order_id":"e67f5d9a-2cc8-43fb-88d8-def46673fa59","remaining_size":"3.0292"}
{"type":"received","side":"sell","product_id":"BTC-USD","time":"2020-06-30T19:19:25.467883Z","sequence":180758034,"order_id":"1ad58021-9bae-46ee-bb52-3d33593ee6cf","order_type":"limit","size":"1.0726","price":"9148.87","client_oid":""}
{"type":"open","side":"sell","product_id":"BTC-USD","time":"2020-06-30T19:19:25.467883Z","sequence":180758035,"price":"9148.87","order_id":"1ad58021-9bae-46ee-bb52-3d33593ee6cf","remaining_size":"1.0726"}
{"type":"heartbeat","last_trade_id":0,"product_id":"BTC-USD","sequence":180758035,"time":"2020-06-30T19:19:25.735112Z"}
{"type":"received","side":"sell","product_id":"BTC-USD","time":"2020-06-30T19:19:25.751291Z","sequence":180758036,"order_id":"c4436d22-8e7d-47b5-b0b8-d369119773eb","order_type":"limit","size":"3.198","price":"9152.46","client_oid":""}
{"type":"open","side":"sell","product_id":"BTC-USD","time":"2020-06-30T19:19:25.751291Z","sequence":180758037,"price":"9152.46","order_id":"c4436d22-8e7d-47b5-b0b8-d369119773eb","remaining_size":"3.198"}
{"type":"heartbeat","last_trade_id":0,"product_id":"BTC-USD","sequence":180758037,"time":"2020-06-30T19:19:26.735115Z"}
{"type":"received","side":"buy","product_id":"BTC-USD","time":"2020-06-30T19:19:27.185384Z","sequence":180758038,"order_id":"af6d20ec-0c3d-421d-92b0-9e51ae5c045a","order_type":"limit","size":"2.8","price":"9100.66","client_oid":""}
{"type":"open","side":"buy","product_id":"BTC-USD","time":"2020-06-30T19:19:27.185384Z","sequence":180758039,"price":"9100.66","order_id":"af6d20ec-0c3d-421d-92b0-9e51ae5c045a","remaining_size":"2.8"}
{"type":"received","side":"sell","product_id":"BTC-USD","time":"2020-06-30T19:19:27.463754Z","sequence":180758040,"order_id":"d9130a83-92a9-442b-b1fb-c67268d65a1b","order_type":"limit","size":"1.9323","price":"9126.14","client_oid":""}
{"type":"open","side":"sell","product_id":"BTC-USD","time":"2020-06-30T19:19:27.463754Z","sequence":180758041,"price":"9126.14","order_id":"d9130a83-92a9-442b-b1fb-c67268d65a1b","remaining_size":"1.9323"}
{"type":"done","side":"buy","product_id":"BTC-USD","time":"2020-06-30T19:19:27.621549Z","sequence":180758042,"order_id":"4d32f012-9565-4522-9c4f-abd7b975c195","reason":"canceled","price":"9113.13","remaining_size":"0.8084"}
{"type":"heartbeat","last_trade_id":0,"product_id":"BTC-USD","sequence":180758042,"time":"2020-06-30T19:19:27.735115Z"}
{"type":"done","side":"sell","product_id":"BTC-USD","time":"2020-06-30T19:19:27.903670Z","sequence":180758043,"order_id":"3c325a61-91bd-47a8-8d7f-06747d523580","reason":"canceled","price":"9125.34","remaining_size":"0.0658"}
{"type":"done","side":"sell","product_id":"BTC-USD","time":"2020-06-30T19:19:27.905423Z","sequence":180758044,"order_id":"b8f5e878-886b-4ea3-9000-a1ca48bc0e69","reason":"canceled","price":"9125.3","remaining_size":"0.0658"}
{"type":"received","side":"sell","product_id":"BTC-USD","time":"2020-06-30T19:19:28.625694Z","sequence":180758045,"order_id":"00e14007-8b9f-4c83-9328-d82cca05493c","order_type":"limit","size":"1.5","price":"9124.66","client_oid":""}
{"type":"open","side":"sell","product_id":"BTC-USD","time":"2020-06-30T19:19:28.625694Z","sequence":180758046,"price":"9124.66","order_id":"00e14007-8b9f-4c83-9328-d82cca05493c","remaining_size":"1.5"}
{"type":"heartbeat","last_trade_id":0,"product_id":"BTC-USD","sequence":180758046,"time":"2020-06-30T19:19:28.735117Z"}
{"type":"done","side":"sell","product_id":"BTC-USD","time":"2020-06-30T19:19:28.820060Z","sequence":180758047,"order_id":"1ad58021-9bae-46ee-bb52-3d33593ee6cf","reason":"canceled","price":"9148.87","remaining_size":"1.0726"}
{"type":"done","side":"sell","product_id":"BTC-USD","time":"2020-06-30T19:19:28.829086Z","sequence":180758048,"order_id":"3e4c8e31-8ff7-40df-876d-1fc7e310eab3","reason":"canceled","price":"9123.77","remaining_size":"0.5696"}
{"type":"received","side":"buy","product_id":"BTC-USD","time":"2020-06-30T19:19:28.926609Z","sequence":180758049,"order_id":"0ddf143f-27ff-4ad8-84a7-b4c2ee119fbf","order_type":"limit","size":"0.1243","price":"9122.05","client_oid":""}
{"type":"match","side":"sell","product_id":"BTC-USD","time":"2020-06-30T19:19:28.926609Z","sequence":180758050,"trade_id":14587709,"maker_order_id":"36fe0734-4801-466d-b093-cccd411db09a","taker_order_id":"0ddf143f-27ff-4ad8-84a7-b4c2ee119fbf","size":"0.1243","price":"9120.82"}
{"type":"done","side":"buy","product_id":"BTC-USD","time":"2020-06-30T19:19:28.926609Z","sequence":180758051,"order_id":"0ddf143f-27ff-4ad8-84a7-b4c2ee119fbf","reason":"filled","price":"9122.05","remaining_size":"0"}
{"type":"received","side":"buy","product_id":"BTC-USD","time":"2020-06-30T19:19:29.028224Z","sequence":180758052,"order_id":"63625e30-0b47-41c0-851c-c0cbf06b026a","order_type":"limit","size":"0.01","price":"100","client_oid":"bc114d2e-9196-4354-9a29-b9974b23209b"}
{"type":"open","side":"buy","product_id":"BTC-USD","time":"2020-06-30T19:19:29.028224Z","sequence":180758053,"price":"100","order_id":"63625e30-0b47-41c0-851c-c0cbf06b026a","remaining_size":"0.01"}
{"type":"done","side":"buy","product_id":"BTC-USD","time":"2020-06-30T19:19:29.034703Z","sequence":180758054,"order_id":"63625e30-0b47-41c0-851c-c0cbf06b026a","reason":"canceled","price":"100","remaining_size":"0.01"}
{"type":"received","side":"sell","product_id":"BTC-USD","time":"2020-06-30T19:19:29.193046Z","sequence":180758055,"order_id":"a5cef692-1a6d-43fc-800e-dbafbefce8df","order_type":"limit","size":"0.2","price":"9123.73","client_oid":""}
{"type":"open","side":"sell","product_id":"BTC-USD","time":"2020-06-30T19:19:29.193046Z","sequence":180758056,"price":"9123.73","order_id":"a5cef692-1a6d-43fc-800e-dbafbefce8df","remaining_size":"0.2"}
{"type":"done","side":"sell","product_id":"BTC-USD","time":"2020-06-30T19:19:29.643954Z","sequence":180758057,"order_id":"8ee1cf15-9667-411f-b591-c94c080934a7","reason":"canceled","price":"9125.42","remaining_size":"0.0658"}
{"type":"done","side":"sell","product_id":"BTC-USD","time":"2020-06-30T19:19:29.647960Z","sequence":180758058,"order_id":"fbfe1ea2-350d-4598-815a-d7df195ec7f0","reason":"canceled","price":"9125.19","remaining_size":"0.0658"}
{"type":"heartbeat","last_trade_id":0,"product_id":"BTC-USD","sequence":180758058,"time":"2020-06-30T19:19:29.735108Z"}
{"type":"received","side":"buy","product_id":"BTC-USD","time":"2020-06-30T19:19:30.008287Z","sequence":180758059,"order_id":"d70879d8-0c46-410c-9f43-e9e1fc17bdfd","order_type":"limit","size":"0.8585","price":"9121.25","client_oid":""}
{"type":"match","side":"sell","product_id":"BTC-USD","time":"2020-06-30T19:19:30.008287Z","sequence":180758060,"trade_id":14587710,"maker_order_id":"36fe0734-4801-466d-b093-cccd411db09a","taker_order_id":"d70879d8-0c46-410c-9f43-e9e1fc17bdfd","size":"0.8585","price":"9120.82"}
{"type":"done","side":"buy","product_id":"BTC-USD","time":"2020-06-30T19:19:30.008287Z","sequence":180758061,"order_id":"d70879d8-0c46-410c-9f43-e9e1fc17bdfd","reason":"filled","price":"9121.25","remaining_size":"0"}
{"type":"done","side":"buy","product_id":"BTC-USD","time":"2020-06-30T19:19:30.445981Z","sequence":180758062,"order_id":"a6b838b6-9335-4db9-ba0c-24973a976608","reason":"canceled","price":"9119.38","remaining_size":"0.0658"}
{"type":"received","side":"sell","product_id":"BTC-USD","time":"2020-06-30T19:19:30.571323Z","sequence":180758063,"order_id":"85f3a96f-71ae-46e3-b3e3-5b36c0736fad","order_type":"limit","size":"0.025","price":"9121.68","client_oid":""}
{"type":"open","side":"sell","product_id":"BTC-USD","time":"2020-06-30T19:19:30.571323Z","sequence":180758064,"price":"9121.68","order_id":"85f3a96f-71ae-46e3-b3e3-5b36c0736fad","remaining_size":"0.025"}
{"type":"heartbeat","last_trade_id":0,"product_id":"BTC-USD","sequence":180758064,"time":"2020-06-30T19:19:30.735118Z"}
{"type":"received","side":"sell","product_id":"BTC-USD","time":"2020-06-30T19:19:30.869120Z","sequence":180758065,"order_id":"53aba182-19a5-4ef3-a26b-df49198a6361","order_type":"limit","size":"14.94","price":"9159.21","client_oid":""}
{"type":"open","side":"sell","product_id":"BTC-USD","time":"2020-06-30T19:19:30.869120Z","sequence":180758066,"price":"9159.21","order_id":"53aba182-19a5-4ef3-a26b-df49198a6361","remaining_size":"14.94"}
{"type":"done","side":"sell","product_id":"BTC-USD","time":"2020-06-30T19:19:31.023052Z","sequence":180758067,"order_id":"ee7069f7-d604-442c-9619-ce953ada6fd9","reason":"canceled","price":"9125.21","remaining_size":"0.0658"}
{"type":"done","side":"sell","product_id":"BTC-USD","time":"2020-06-30T19:19:31.023245Z","sequence":180758068,"order_id":"1eefd4fa-e60c-4cfe-80b8-6528119f06b9","reason":"canceled","price":"9124.35","remaining_size":"0.1863"}
{"type":"received","side":"buy","product_id":"BTC-USD","time":"2020-06-30T19:19:31.145314Z","sequence":180758069,"order_id":"c37c985c-1014-4627-af5f-7701432d1c5e","order_type":"limit","size":"0.0658","price":"9119.78","client_oid":""}
{"type":"open","side":"buy","product_id":"BTC-USD","time":"2020-06-30T19:19:31.145314Z","sequence":180758070,"price":"9119.78","order_id":"c37c985c-1014-4627-af5f-7701432d1c5e","remaining_size":"0.0658"}
{"type":"done","side":"sell","product_id":"BTC-USD","time":"2020-06-30T19:19:31.283767Z","sequence":180758071,"order_id":"e67f5d9a-2cc8-43fb-88d8-def46673fa59","reason":"canceled","price":"9147.73","remaining_size":"3.0292"}
{"type":"received","side":"sell","product_id":"BTC-USD","time":"2020-06-30T19:19:31.707158Z","sequence":180758072,"order_id":"90a0cee4-eab5-4e5a-bf10-20f7394d0a21","order_type":"limit","size":"0.1617","price":"9122.44","client_oid":""}
{"type":"open","side":"sell","product_id":"BTC-USD","time":"2020-06-30T19:19:31.707158Z","sequence":180758073,"price":"9122.44","order_id":"90a0cee4-eab5-4e5a-bf10-20f7394d0a21","remaining_size":"0.1617"}
{"type":"heartbeat","last_trade_id":0,"product_id":"BTC-USD","sequence":180758073,"time":"2020-06-30T19:19:31.735111Z"}
{"type":"received","side":"buy","product_id":"BTC-USD","time":"2020-06-30T19:19:32.268941Z","sequence":180758074,"order_id":"f7b6f754-380d-44ac-967f-e5fa2a89836e","order_type":"limit","size":"0.5","price":"9121.3","client_oid":""}
{"type":"match","side":"sell","product_id":"BTC-USD","time":"2020-06-30T19:19:32.268941Z","sequence":180758075,"trade_id":14587711,"maker_order_id":"36fe0734-4801-466d-b093-cccd411db09a","taker_order_id":"f7b6f754-380d-44ac-967f-e5fa2a89836e","size":"0.5","price":"9120.82"}
{"type":"done","side":"buy","product_id":"BTC-USD","time":"2020-06-30T19:19:32.268941Z","sequence":180758076,"order_id":"f7b6f754-380d-44ac-967f-e5fa2a89836e","reason":"filled","price":"9121.3","remaining_size":"0"}
{"type":"done","side":"buy","product_id":"BTC-USD","time":"2020-06-30T19:19:32.717089Z","sequence":180758077,"order_id":"587b0bfc-d2f7-4a09-865e-f7800ffb86b7","reason":"canceled","price":"9096.68","remaining_size":"0.01"}
{"type":"heartbeat","last_trade_id":0,"product_id":"BTC-USD","sequence":180758077,"time":"2020-06-30T19:19:32.735067Z"}
{"type":"received","side":"buy","product_id":"BTC-USD","time":"2020-06-30T19:19:33.119813Z","sequence":180758078,"order_id":"4d5b0407-15c2-499b-a5a1-c8980b779a25","order_type":"limit","size":"0.0377","price":"9087.84","client_oid":""}
{"type":"open","side":"buy","product_id":"BTC-USD","time":"2020-06-30T19:19:33.119813Z","sequence":180758079,"price":"9087.84","order_id":"4d5b0407-15c2-499b-a5a1-c8980b779a25","remaining_size":"0.0377"}
{"type":"heartbeat","last_trade_id":0,"product_id":"BTC-USD","sequence":180758079,"time":"2020-06-30T19:19:33.735039Z"}
{"type":"received","side":"buy","product_id":"BTC-USD","time":"2020-06-30T19:19:33.938543Z","sequence":180758080,"order_id":"c2d307c5-4ef3-45d0-b743-7e0f8f4ade65","order_type":"limit","size":"0.8056","price":"9110.63","client_oid":""}
{"type":"open","side":"buy","product_id":"BTC-USD","time":"2020-06-30T19:19:33.938543Z","sequence":180758081,"price":"9110.63","order_id":"c2d307c5-4ef3-45d0-b743-7e0f8f4ade65","remaining_size":"0.8056"}
{"type":"received","side":"buy","product_id":"BTC-USD","time":"2020-06-30T19:19:34.236770Z","sequence":180758082,"order_id":"b2fa2702-ed04-4545-9dff-b2b255c88d96","order_type":"limit","size":"0.9223","price":"9117.49","client_oid":""}
{"type":"open","side":"buy","product_id":"BTC-USD","time":"2020-06-30T19:19:34.236770Z","sequence":180758083,"price":"9117.49","order_id":"b2fa2702-ed04-4545-9dff-b2b255c88d96","remaining_size":"0.9223"}
{"type":"received","side":"buy","product_id":"BTC-USD","time":"2020-06-30T19:19:34.507080Z","sequence":180758084,"order_id":"b42fc9f9-b318-4c37-93d6-8b8cbfc00f37","order_type":"limit","size":"0.0658","price":"9117.5","client_oid":""}
{"type":"open","side":"buy","product_id":"BTC-USD","time":"2020-06-30T19:19:34.507080Z","sequence":180758085,"price":"9117.5","order_id":"b42fc9f9-b318-4c37-93d6-8b8cbfc00f37","remaining_size":"0.0658"}
{"type":"heartbeat","last_trade_id":0,"product_id":"BTC-USD","sequence":180758085,"time":"2020-06-30T19:19:34.735036Z"}
{"type":"received","side":"sell","product_id":"BTC-USD","time":"2020-06-30T19:19:34.777906Z","sequence":180758086,"order_id":"c30b281f-90d0-4985-97b2-0f434715b710","order_type":"limit","size":"0.0968","price":"9138.02","client_oid":""}
{"type":"open","side":"sell","product_id":"BTC-USD","time":"2020-06-30T19:19:34.777906Z","sequence":180758087,"price":"9138.02","order_id":"c30b281f-90d0-4985-97b2-0f434715b710","remaining_size":"0.0968"}
{"type":"done","side":"buy","product_id":"BTC-USD","time":"2020-06-30T19:19:34.936932Z","sequence":180758088,"order_id":"af6d20ec-0c3d-421d-92b0-9e51ae5c045a","reason":"canceled","price":"9100.66","remaining_size":"2.8"}
{"type":"received","side":"buy","product_id":"BTC-USD","time":"2020-06-30T19:19:35.074800Z","sequence":180758089,"order_id":"7b7b3435-db8c-446e-bd06-c2f522fff083","order_type":"limit","size":"0.055","price":"9087.15","client_oid":""}
{"type":"open","side":"buy","product_id":"BTC-USD","time":"2020-06-30T19:19:35.074800Z","sequence":180758090,"price":"9087.15","order_id":"7b7b3435-db8c-446e-bd06-c2f522fff083","remaining_size":"0.055"}
{"type":"received","side":"sell","product_id":"BTC-USD","time":"2020-06-30T19:19:35.618965Z","sequence":180758091,"order_id":"b1f02093-e42c-4e36-a58f-2a4d399cccdf","order_type":"limit","size":"0.545","price":"9124.06","client_oid":""}
{"type":"open","side":"sell","product_id":"BTC-USD","time":"2020-06-30T19:19:35.618965Z","sequence":180758092,"price":"9124.06","order_id":"b1f02093-e42c-4e36-a58f-2a4d399cccdf","remaining_size":"0.545"}
{"type":"heartbeat","last_trade_id":0,"product_id":"BTC-USD","sequence":180758092,"time":"2020-06-30T19:19:35.735047Z"}
{"type":"done","side":"sell","product_id":"BTC-USD","time":"2020-06-30T19:19:36.057132Z","sequence":180758093,"order_id":"c4436d22-8e7d-47b5-b0b8-d369119773eb","reason":"canceled","price":"9152.46","remaining_size":"3.198"}
{"type":"done","side":"sell","product_id":"BTC-USD","time":"2020-06-30T19:19:36.061940Z","sequence":180758094,"order_id":"90a0cee4-eab5-4e5a-bf10-20f7394d0a21","reason":"canceled","price":"9122.44","remaining_size":"0.1617"}
{"type":"heartbeat","last_trade_id":0,"product_id":"BTC-USD","sequence":180758094,"time":"2020-06-30T19:19:36.735095Z"}
{"type":"received","side":"buy","product_id":"BTC-USD","time":"2020-06-30T19:19:36.769599Z","sequence":180758095,"order_id":"9bef0277-d484-4f3d-959c-812288fa9b27","order_type":"limit","size":"0.8054","price":"9108.53","client_oid":""}
{"type":"open","side":"buy","product_id":"BTC-USD","time":"2020-06-30T19:19:36.769599Z","sequence":180758096,"price":"9108.53","order_id":"9bef0277-d484-4f3d-959c-812288fa9b27","remaining_size":"0.8054"}
{"type":"received","side":"buy","product_id":"BTC-USD","time":"2020-06-30T19:19:37.594123Z","sequence":180758097,"order_id":"179d0063-7c32-41dd-8709-0ca7c3cd6c96","order_type":"limit","size":"0.001","price":"8938.24","client_oid":""}
{"type":"open","side":"buy","product_id":"BTC-USD","time":"2020-06-30T19:19:37.594123Z","sequence":180758098,"price":"8938.24","order_id":"179d0063-7c32-41dd-8709-0ca7c3cd6c96","remaining_size":"0.001"}
{"type":"heartbeat","last_trade_id":0,"product_id":"BTC-USD","sequence":180758098,"time":"2020-06-30T19:19:37.735067Z"}
{"type":"done","side":"buy","product_id":"BTC-USD","time":"2020-06-30T19:19:38.058886Z","sequence":180758099,"order_id":"b42fc9f9-b318-4c37-93d6-8b8cbfc00f37","reason":"canceled","price":"9117.5","remaining_size":"0.0658"}
{"type":"received","side":"buy","product_id":"BTC-USD","time":"2020-06-30T19:19:38.157836Z","sequence":180758100,"order_id":"df356a14-168e-4712-9d6f-20e0e3359c90","order_type":"limit","size":"0.01","price":"9097.76","client_oid":""}
{"type":"open","side":"buy","product_id":"BTC-USD","time":"2020-06-30T19:19:38.157836Z","sequence":180758101,"price":"9097.76","order_id":"df356a14-168e-4712-9d6f-20e0e3359c90","remaining_size":"0.01"}
{"type":"received","side":"buy","product_id":"BTC-USD","time":"2020-06-30T19:19:38.433005Z","sequence":180758102,"order_id":"f88edc07-c013-4af1-81d1-1d55b62b1b77","order_type":"limit","size":"0.0105","price":"9086.92","client_oid":""}
{"type":"open","side":"buy","product_id":"BTC-USD","time":"2020-06-30T19:19:38.433005Z","sequence":180758103,"price":"9086.92","order_id":"f88edc07-c013-4af1-81d1-1d55b62b1b77","remaining_size":"0.0105"}
{"type":"done","side":"buy","product_id":"BTC-USD","time":"2020-06-30T19:19:38.582208Z","sequence":180758104,"order_id":"c37c985c-1014-4627-af5f-7701432d1c5e","reason":"canceled","price":"9119.78","remaining_size":"0.0658"}
{"type":"heartbeat","last_trade_id":0,"product_id":"BTC-USD","sequence":180758104,"time":"2020-06-30T19:19:38.735093Z"}
{"type":"received","side":"buy","product_id":"BTC-USD","time":"2020-06-30T19:19:38.997126Z","sequence":180758105,"order_id":"3801483a-4ffc-4492-91f1-59582ea8903d","order_type":"limit","size":"0.01","price":"9097.76","client_oid":""}
{"type":"open","side":"buy","product_id":"BTC-USD","time":"2020-06-30T19:19:38.997126Z","sequence":180758106,"price":"9097.76","order_id":"3801483a-4ffc-4492-91f1-59582ea8903d","remaining_size":"0.01"}
{"type":"received","side":"buy","product_id":"BTC-USD","time":"2020-06-30T19:19:39.577025Z","sequence":180758107,"order_id":"de8cffb3-fecb-4d4b-a1a2-2e500bcddfaf","order_type":"limit","size":"0.0105","price":"9081.06","client_oid":""}
{"type":"open","side":"buy","product_id":"BTC-USD","time":"2020-06-30T19:19:39.577025Z","sequence":180758108,"price":"9081.06","order_id":"de8cffb3-fecb-4d4b-a1a2-2e500bcddfaf","remaining_size":"0.0105"}
{"type":"heartbeat","last_trade_id":0,"product_id":"BTC-USD","sequence":180758108,"time":"2020-06-30T19:19:39.735121Z"}
{"type":"received","side":"sell","product_id":"BTC-USD","time":"2020-06-30T19:19:39.874119Z","sequence":180758109,"order_id":"7fa94ca5-a532-474f-b1bf-f35e17b7ea42","order_type":"limit","size":"0.219","price":"9134.51","client_oid":""}
{"type":"open","side":"sell","product_id":"BTC-USD","time":"2020-06-30T19:19:39.874119Z","sequence":180758110,"price":"9134.51","order_id":"7fa94ca5-a532-474f-b1bf-f35e17b7ea42","remaining_size":"0.219"}
{"type":"done","side":"buy","product_id":"BTC-USD","time":"2020-06-30T19:19:39.994031Z","sequence":180758111,"order_id":"df356a14-168e-4712-9d6f-20e0e3359c90","reason":"canceled","price":"9097.76","remaining_size":"0.01"}
{"type":"done","side":"buy","product_id":"BTC-USD","time":"2020-06-30T19:19:40.004205Z","sequence":180758112,"order_id":"3801483a-4ffc-4492-91f1-59582ea8903d","reason":"canceled","price":"9097.76","remaining_size":"0.01"}
{"type":"done","side":"buy","product_id":"BTC-USD","time":"2020-06-30T19:19:40.006225Z","sequence":180758113,"order_id":"7b7b3435-db8c-446e-bd06-c2f522fff083","reason":"canceled","price":"9087.15","remaining_size":"0.055"}
{"type":"done","side":"buy","product_id":"BTC-USD","time":"2020-06-30T19:19:40.006374Z","sequence":180758114,"order_id":"4d5b0407-15c2-499b-a5a1-c8980b779a25","reason":"canceled","price":"9087.84","remaining_size":"0.0377"}
{"type":"received","side":"sell","product_id":"BTC-USD","time":"2020-06-30T19:19:40.176053Z","sequence":180758115,"order_id":"1fd2d33f-c1fd-4e5b-bed8-dec4a5df5019","order_type":"limit","size":"0.3222","price":"9124.42","client_oid":""}
{"type":"open","side":"sell","product_id":"BTC-USD","time":"2020-06-30T19:19:40.176053Z","sequence":180758116,"price":"9124.42","order_id":"1fd2d33f-c1fd-4e5b-bed8-dec4a5df5019","remaining_size":"0.3222"}
{"type":"done","side":"sell","product_id":"BTC-USD","time":"2020-06-30T19:19:40.300162Z","sequence":180758117,"order_id":"6b055937-68a7-42f8-9746-523c807854b3","reason":"canceled","price":"9124.96","remaining_size":"0.0658"}
{"type":"heartbeat","last_trade_id":0,"product_id":"BTC-USD","sequence":180758117,"time":"2020-06-30T19:19:40.735114Z"}
{"type":"received","side":"buy","product_id":"BTC-USD","time":"2020-06-30T19:19:41.669084Z","sequence":180758118,"order_id":"01972dba-e77a-4bed-989e-b49ec13b0265","order_type":"market","size":"0.001","funds":"9.12082","client_oid":""}
{"type":"match","side":"sell","product_id":"BTC-USD","time":"2020-06-30T19:19:41.669084Z","sequence":180758119,"trade_id":14587712,"maker_order_id":"36fe0734-4801-466d-b093-cccd411db09a","taker_order_id":"01972dba-e77a-4bed-989e-b49ec13b0265","size":"0.001","price":"9120.82"}
{"type":"done","side":"buy","product_id":"BTC-USD","time":"2020-06-30T19:19:41.669084Z","sequence":180758120,"order_id":"01972dba-e77a-4bed-989e-b49ec13b0265","reason":"filled","remaining_size":"0"}
{"type":"heartbeat","last_trade_id":0,"product_id":"BTC-USD","sequence":180758120,"time":"2020-06-30T19:19:41.735112Z"}
{"type":"received","side":"sell","product_id":"BTC-USD","time":"2020-06-30T19:19:41.943674Z","sequence":180758121,"order_id":"cd79dc17-a13f-4027-a899-945fcb2f1465","order_type":"limit","size":"1.1315","price":"9121.69","client_oid":""}
{"type":"open","side":"sell","product_id":"BTC-USD","time":"2020-06-30T19:19:41.943674Z","sequence":180758122,"price":"9121.69","order_id":"cd79dc17-a13f-4027-a899-945fcb2f1465","remaining_size":"1.1315"}
{"type":"done","side":"sell","product_id":"BTC-USD","time":"2020-06-30T19:19:42.133020Z","sequence":180758123,"order_id":"7fa94ca5-a532-474f-b1bf-f35e17b7ea42","reason":"canceled","price":"9134.51","remaining_size":"0.219"}
{"type":"done","side":"sell","product_id":"BTC-USD","time":"2020-06-30T19:19:42.146699Z","sequence":180758124,"order_id":"00e14007-8b9f-4c83-9328-d82cca05493c","reason":"canceled","price":"9124.66","remaining_size":"1.5"}
{"type":"received","side":"sell","product_id":"BTC-USD","time":"2020-06-30T19:19:42.213034Z","sequence":180758125,"order_id":"a9b7fbc3-079f-4369-9abd-61099178b979","order_type":"limit","size":"0.01","price":"9158.53","client_oid":""}
{"type":"open","side":"sell","product_id":"BTC-USD","time":"2020-06-30T19:19:42.213034Z","sequence":180758126,"price":"9158.53","order_id":"a9b7fbc3-079f-4369-9abd-61099178b979","remaining_size":"0.01"}
{"type":"received","side":"buy","product_id":"BTC-USD","time":"2020-06-30T19:19:42.556001Z","sequence":180758127,"order_id":"c57497ef-b880-4b37-a502-270461cfc694","order_type":"limit","size":"0.0012","price":"9116.21","client_oid":""}
{"type":"open","side":"buy","product_id":"BTC-USD","time":"2020-06-30T19:19:42.556001Z","sequence":180758128,"price":"9116.21","order_id":"c57497ef-b880-4b37-a502-270461cfc694","remaining_size":"0.0012"}
{"type":"done","side":"sell","product_id":"BTC-USD","time":"2020-06-30T19:19:42.650109Z","sequence":180758129,"order_id":"d9130a83-92a9-442b-b1fb-c67268d65a1b","reason":"canceled","price":"9126.14","remaining_size":"1.9323"}
{"type":"done","side":"sell","product_id":"BTC-USD","time":"2020-06-30T19:19:42.658728Z","sequence":180758130,"order_id":"e99fba60-8748-40c0-af5e-05c542153c81","reason":"canceled","price":"9124.8","remaining_size":"0.132"}
{"type":"heartbeat","last_trade_id":0,"product_id":"BTC-USD","sequence":180758130,"time":"2020-06-30T19:19:42.735109Z"}
{"type":"done","side":"buy","product_id":"BTC-USD","time":"2020-06-30T19:19:42.980588Z","sequence":180758131,"order_id":"71f343eb-1f20-4a42-852a-dd0f23f7723d","reason":"canceled","price":"9102.72","remaining_size":"0.0606"}
{"type":"heartbeat","last_trade_id":0,"product_id":"BTC-USD","sequence":180758131,"time":"2020-06-30T19:19:43.735089Z"}
{"type":"received","side":"buy","product_id":"BTC-USD","time":"2020-06-30T19:19:44.063400Z","sequence":180758132,"order_id":"3ed491ba-5300-4bf1-b416-58f4fca867af","order_type":"limit","size":"0.01","price":"100","client_oid":"b8c86199-5cc9-47c5-8e3c-5556cf1f885a"}
{"type":"open","side":"buy","product_id":"BTC-USD","time":"2020-06-30T19:19:44.063400Z","sequence":180758133,"price":"100","order_id":"3ed491ba-5300-4bf1-b416-58f4fca867af","remaining_size":"0.01"}
{"type":"done","side":"buy","product_id":"BTC-USD","time":"2020-06-30T19:19:44.070550Z","sequence":180758134,"order_id":"3ed491ba-5300-4bf1-b416-58f4fca867af","reason":"canceled","price":"100","remaining_size":"0.01"}
{"type":"heartbeat","last_trade_id":0,"product_id":"BTC-USD","sequence":180758134,"time":"2020-06-30T19:19:44.735017Z"}
{"type":"received","side":"buy","product_id":"BTC-USD","time":"2020-06-30T19:19:45.368524Z","sequence":180758135,"order_id":"4d556e33-e43b-4774-8299-188aadc58159","order_type":"limit","size":"0.2134","price":"9118.19","client_oid":""}
{"type":"open","side":"buy","product_id":"BTC-USD","time":"2020-06-30T19:19:45.368524Z","sequence":180758136,"price":"9118.19","order_id":"4d556e33-e43b-4774-8299-188aadc58159","remaining_size":"0.2134"}
{"type":"received","side":"buy","product_id":"BTC-USD","time":"2020-06-30T19:19:45.653057Z","sequence":180758137,"order_id":"6b64ebc7-fc28-417c-a182-43fdc369a3f7","order_type":"limit","size":"0.01","price":"9099.13","client_oid":""}
{"type":"open","side":"buy","product_id":"BTC-USD","time":"2020-06-30T19:19:45.653057Z","sequence":180758138,"price":"9099.13","order_id":"6b64ebc7-fc28-417c-a182-43fdc369a3f7","remaining_size":"0.01"}
{"type":"heartbeat","last_trade_id":0,"product_id":"BTC-USD","sequence":180758138,"time":"2020-06-30T19:19:45.735170Z"}
{"type":"received","side":"sell","product_id":"BTC-USD","time":"2020-06-30T19:19:46.071292Z","sequence":180758139,"order_id":"56302310-1ec9-4d4c-ac4f-4040eb15b3c0","order_type":"limit","size":"1.2667","price":"9121.69","client_oid":""}
{"type":"open","side":"sell","product_id":"BTC-USD","time":"2020-06-30T19:19:46.071292Z","sequence":180758140,"price":"9121.69","order_id":"56302310-1ec9-4d4c-ac4f-4040eb15b3c0","remaining_size":"1.2667"}
{"type":"received","side":"buy","product_id":"BTC-USD","time":"2020-06-30T19:19:46.362543Z","sequence":180758141,"order_id":"5e67c7a1-08fe-4eae-bc01-77fedc12c4a2","order_type":"limit","size":"0.01","price":"9098.45","client_oid":""}
{"type":"open","side":"buy","product_id":"BTC-USD","time":"2020-06-30T19:19:46.362543Z","sequence":180758142,"price":"9098.45","order_id":"5e67c7a1-08fe-4eae-bc01-77fedc12c4a2","remaining_size":"0.01"}
{"type":"done","side":"sell","product_id":"BTC-USD","time":"2020-06-30T19:19:46.541634Z","sequence":180758143,"order_id":"3ee911bb-228b-456a-930b-e64cd3a096ee","reason":"canceled","price":"9162.94","remaining_size":"0.0546"}
{"type":"done","side":"sell","product_id":"BTC-USD","time":"2020-06-30T19:19:46.543022Z","sequence":180758144,"order_id":"b1f02093-e42c-4e36-a58f-2a4d399cccdf","reason":"canceled","price":"9124.06","remaining_size":"0.545"}
{"type":"done","side":"sell","product_id":"BTC-USD","time":"2020-06-30T19:19:46.553407Z","sequence":180758145,"order_id":"85f3a96f-71ae-46e3-b3e3-5b36c0736fad","reason":"canceled","price":"9121.68","remaining_size":"0.025"}
{"type":"done","side":"sell","product_id":"BTC-USD","time":"2020-06-30T19:19:46.582821Z","sequence":180758146,"order_id":"c30b281f-90d0-4985-97b2-0f434715b710","reason":"canceled","price":"9138.02","remaining_size":"0.0968"}
{"type":"heartbeat","last_trade_id":0,"product_id":"BTC-USD","sequence":180758146,"time":"2020-06-30T19:19:46.735121Z"}
{"type":"received","side":"buy","product_id":"BTC-USD","time":"2020-06-30T19:19:46.990772Z","sequence":180758147,"order_id":"d7d8e8c9-fd99-4501-8da3-a68dd3178c4c","order_type":"limit","size":"0.1345","price":"9121.68","client_oid":""}
{"type":"match","side":"sell","product_id":"BTC-USD","time":"2020-06-30T19:19:46.990772Z","sequence":180758148,"trade_id":14587713,"maker_order_id":"36fe0734-4801-466d-b093-cccd411db09a","taker_order_id":"d7d8e8c9-fd99-4501-8da3-a68dd3178c4c","size":"0.1345","price":"9120.82"}
{"type":"done","side":"buy","product_id":"BTC-USD","time":"2020-06-30T19:19:46.990772Z","sequence":180758149,"order_id":"d7d8e8c9-fd99-4501-8da3-a68dd3178c4c","reason":"filled","price":"9121.68","remaining_size":"0"}
