{"type":"received","side":"sell","product_id":"BTC-USD","time":"2020-06-30T19:19:47.260927Z","sequence":180758150,"order_id":"24155393-2a52-4614-91fe-e224f30dd058","order_type":"limit","size":"0.3781","price":"9121.69","client_oid":""}
{"type":"open","side":"sell","product_id":"BTC-USD","time":"2020-06-30T19:19:47.260927Z","sequence":180758151,"price":"9121.69","order_id":"24155393-2a52-4614-91fe-e224f30dd058","remaining_size":"0.3781"}
{"type":"done","side":"sell","product_id":"BTC-USD","time":"2020-06-30T19:19:47.676827Z","sequence":180758152,"order_id":"cd79dc17-a13f-4027-a899-945fcb2f1465","reason":"canceled","price":"9121.69","remaining_size":"1.1315"}
{"type":"heartbeat","last_trade_id":0,"product_id":"BTC-USD","sequence":180758152,"time":"2020-06-30T19:19:47.735113Z"}
{"type":"heartbeat","last_trade_id":0,"product_id":"BTC-USD","sequence":180758152,"time":"2020-06-30T19:19:48.735059Z"}
{"type":"received","side":"sell","product_id":"BTC-USD","time":"2020-06-30T19:19:48.999290Z","sequence":180758153,"order_id":"e11a36af-bc12-4da2-a511-f0d24a8f4112","order_type":"limit","size":"0.0658","price":"9124.62","client_oid":""}
{"type":"open","side":"sell","product_id":"BTC-USD","time":"2020-06-30T19:19:48.999290Z","sequence":180758154,"price":"9124.62","order_id":"e11a36af-bc12-4da2-a511-f0d24a8f4112","remaining_size":"0.0658"}
{"type":"done","side":"buy","product_id":"BTC-USD","time":"2020-06-30T19:19:49.111329Z","sequence":180758155,"order_id":"179d0063-7c32-41dd-8709-0ca7c3cd6c96","reason":"canceled","price":"8938.24","remaining_size":"0.001"}
{"type":"done","side":"buy","product_id":"BTC-USD","time":"2020-06-30T19:19:49.135524Z","sequence":180758156,"order_id":"6b64ebc7-fc28-417c-a182-43fdc369a3f7","reason":"canceled","price":"9099.13","remaining_size":"0.01"}
{"type":"heartbeat","last_trade_id":0,"product_id":"BTC-USD","sequence":180758156,"time":"2020-06-30T19:19:49.735098Z"}
{"type":"received","side":"buy","product_id":"BTC-USD","time":"2020-06-30T19:19:50.150137Z","sequence":180758157,"order_id":"161c1902-0a34-48b6-9252-910b8e02e331","order_type":"limit","size":"4.7899","price":"9121.68","client_oid":""}
{"type":"match","side":"sell","product_id":"BTC-USD","time":"2020-06-30T19:19:50.150137Z","sequence":180758158,"trade_id":14587714,"maker_order_id":"36fe0734-4801-466d-b093-cccd411db09a","taker_order_id":"161c1902-0a34-48b6-9252-910b8e02e331","size":"4.7899","price":"9120.82"}
{"type":"done","side":"buy","product_id":"BTC-USD","time":"2020-06-30T19:19:50.150137Z","sequence":180758159,"order_id":"161c1902-0a34-48b6-9252-910b8e02e331","reason":"filled","price":"9121.68","remaining_size":"0"}
{"type":"received","side":"sell","product_id":"BTC-USD","time":"2020-06-30T19:19:50.474448Z","sequence":180758160,"order_id":"7f54b831-265c-4f74-93e3-d7173ff1167d","order_type":"limit","size":"0.3222","price":"9125.93","client_oid":""}
{"type":"open","side":"sell","product_id":"BTC-USD","time":"2020-06-30T19:19:50.474448Z","sequence":180758161,"price":"9125.93","order_id":"7f54b831-265c-4f74-93e3-d7173ff1167d","remaining_size":"0.3222"}
{"type":"done","side":"buy","product_id":"BTC-USD","time":"2020-06-30T19:19:50.577712Z","sequence":180758162,"order_id":"9bef0277-d484-4f3d-959c-812288fa9b27","reason":"canceled","price":"9108.53","remaining_size":"0.8054"}
{"type":"done","side":"buy","product_id":"BTC-USD","time":"2020-06-30T19:19:50.583823Z","sequence":180758163,"order_id":"5e67c7a1-08fe-4eae-bc01-77fedc12c4a2","reason":"canceled","price":"9098.45","remaining_size":"0.01"}
{"type":"heartbeat","last_trade_id":0,"product_id":"BTC-USD","sequence":180758163,"time":"2020-06-30T19:19:50.735127Z"}
{"type":"done","side":"sell","product_id":"BTC-USD","time":"2020-06-30T19:19:50.905031Z","sequence":180758164,"order_id":"24155393-2a52-4614-91fe-e224f30dd058","reason":"canceled","price":"9121.69","remaining_size":"0.3781"}
{"type":"received","side":"buy","product_id":"BTC-USD","time":"2020-06-30T19:19:51.061754Z","sequence":180758165,"order_id":"e3e40391-9ca7-4784-b03f-36a72fdaac5f","order_type":"limit","size":"5","price":"9116.41","client_oid":""}
{"type":"open","side":"buy","product_id":"BTC-USD","time":"2020-06-30T19:19:51.061754Z","sequence":180758166,"price":"9116.41","order_id":"e3e40391-9ca7-4784-b03f-36a72fdaac5f","remaining_size":"5"}
{"type":"received","side":"buy","product_id":"BTC-USD","time":"2020-06-30T19:19:51.636185Z","sequence":180758167,"order_id":"b0649af1-12de-48da-a7f8-85f0a20a9986","order_type":"limit","size":"4.7589","price":"9121.68","client_oid":""}
{"type":"match","side":"sell","product_id":"BTC-USD","time":"2020-06-30T19:19:51.636185Z","sequence":180758168,"trade_id":14587715,"maker_order_id":"36fe0734-4801-466d-b093-cccd411db09a","taker_order_id":"b0649af1-12de-48da-a7f8-85f0a20a9986","size":"4.7589","price":"9120.82"}
{"type":"done","side":"buy","product_id":"BTC-USD","time":"2020-06-30T19:19:51.636185Z","sequence":180758169,"order_id":"b0649af1-12de-48da-a7f8-85f0a20a9986","reason":"filled","price":"9121.68","remaining_size":"0"}
{"type":"heartbeat","last_trade_id":0,"product_id":"BTC-USD","sequence":180758169,"time":"2020-06-30T19:19:51.735116Z"}
{"type":"done","side":"buy","product_id":"BTC-USD","time":"2020-06-30T19:19:51.821664Z","sequence":180758170,"order_id":"4d556e33-e43b-4774-8299-188aadc58159","reason":"canceled","price":"9118.19","remaining_size":"0.2134"}
{"type":"received","side":"buy","product_id":"BTC-USD","time":"2020-06-30T19:19:51.933821Z","sequence":180758171,"order_id":"070f3baf-eff1-4a7c-8372-02afb38f1a2c","order_type":"limit","size":"4.7899","price":"9121.68","client_oid":""}
{"type":"match","side":"sell","product_id":"BTC-USD","time":"2020-06-30T19:19:51.933821Z","sequence":180758172,"trade_id":14587716,"maker_order_id":"36fe0734-4801-466d-b093-cccd411db09a","taker_order_id":"070f3baf-eff1-4a7c-8372-02afb38f1a2c","size":"4.7899","price":"9120.82"}
{"type":"done","side":"buy","product_id":"BTC-USD","time":"2020-06-30T19:19:51.933821Z","sequence":180758173,"order_id":"070f3baf-eff1-4a7c-8372-02afb38f1a2c","reason":"filled","price":"9121.68","remaining_size":"0"}
{"type":"heartbeat","last_trade_id":0,"product_id":"BTC-USD","sequence":180758173,"time":"2020-06-30T19:19:52.735121Z"}
{"type":"received","side":"buy","product_id":"BTC-USD","time":"2020-06-30T19:19:52.810184Z","sequence":180758174,"order_id":"b229e2b7-8656-4fae-8a30-5c1d4daec297","order_type":"limit","size":"0.0658","price":"9115.15","client_oid":""}
{"type":"open","side":"buy","product_id":"BTC-USD","time":"2020-06-30T19:19:52.810184Z","sequence":180758175,"price":"9115.15","order_id":"b229e2b7-8656-4fae-8a30-5c1d4daec297","remaining_size":"0.0658"}
{"type":"received","side":"buy","product_id":"BTC-USD","time":"2020-06-30T19:19:53.369614Z","sequence":180758176,"order_id":"c6e86bb2-0364-4c6d-bab3-54de0a7ef1da","order_type":"limit","size":"7.6993","price":"9121.71","client_oid":""}
{"type":"match","side":"sell","product_id":"BTC-USD","time":"2020-06-30T19:19:53.369614Z","sequence":180758177,"trade_id":14587717,"maker_order_id":"36fe0734-4801-466d-b093-cccd411db09a","taker_order_id":"c6e86bb2-0364-4c6d-bab3-54de0a7ef1da","size":"7.6993","price":"9120.82"}
{"type":"done","side":"buy","product_id":"BTC-USD","time":"2020-06-30T19:19:53.369614Z","sequence":180758178,"order_id":"c6e86bb2-0364-4c6d-bab3-54de0a7ef1da","reason":"filled","price":"9121.71","remaining_size":"0"}
{"type":"received","side":"buy","product_id":"BTC-USD","time":"2020-06-30T19:19:53.672072Z","sequence":180758179,"order_id":"4cd67047-552f-43d5-aee5-744aa7ad1bc7","order_type":"limit","size":"7.9901","price":"9121.71","client_oid":""}
{"type":"match","side":"sell","product_id":"BTC-USD","time":"2020-06-30T19:19:53.672072Z","sequence":180758180,"trade_id":14587718,"maker_order_id":"36fe0734-4801-466d-b093-cccd411db09a","taker_order_id":"4cd67047-552f-43d5-aee5-744aa7ad1bc7","size":"7.9901","price":"9120.82"}
{"type":"done","side":"buy","product_id":"BTC-USD","time":"2020-06-30T19:19:53.672072Z","sequence":180758181,"order_id":"4cd67047-552f-43d5-aee5-744aa7ad1bc7","reason":"filled","price":"9121.71","remaining_size":"0"}
{"type":"heartbeat","last_trade_id":0,"product_id":"BTC-USD","sequence":180758181,"time":"2020-06-30T19:19:53.735116Z"}
{"type":"received","side":"buy","product_id":"BTC-USD","time":"2020-06-30T19:19:53.953718Z","sequence":180758182,"order_id":"790e0c94-a3e0-4c23-9f13-e53d5f5266c6","order_type":"limit","size":"0.0684","price":"9101.45","client_oid":""}
{"type":"open","side":"buy","product_id":"BTC-USD","time":"2020-06-30T19:19:53.953718Z","sequence":180758183,"price":"9101.45","order_id":"790e0c94-a3e0-4c23-9f13-e53d5f5266c6","remaining_size":"0.0684"}
{"type":"received","side":"buy","product_id":"BTC-USD","time":"2020-06-30T19:19:54.596442Z","sequence":180758184,"order_id":"b4885290-3b3d-4409-a534-f59e38a81866","order_type":"limit","size":"0.1247","price":"9122.8","client_oid":""}
{"type":"match","side":"sell","product_id":"BTC-USD","time":"2020-06-30T19:19:54.596442Z","sequence":180758185,"trade_id":14587719,"maker_order_id":"36fe0734-4801-466d-b093-cccd411db09a","taker_order_id":"b4885290-3b3d-4409-a534-f59e38a81866","size":"0.1247","price":"9120.82"}
{"type":"done","side":"buy","product_id":"BTC-USD","time":"2020-06-30T19:19:54.596442Z","sequence":180758186,"order_id":"b4885290-3b3d-4409-a534-f59e38a81866","reason":"filled","price":"9122.8","remaining_size":"0"}
{"type":"heartbeat","last_trade_id":0,"product_id":"BTC-USD","sequence":180758186,"time":"2020-06-30T19:19:54.735120Z"}
{"type":"received","side":"sell","product_id":"BTC-USD","time":"2020-06-30T19:19:54.858431Z","sequence":180758187,"order_id":"5f52c02b-917b-4a15-893b-9d7f6f3b3f37","order_type":"limit","size":"0.063","price":"9123.28","client_oid":""}
{"type":"open","side":"sell","product_id":"BTC-USD","time":"2020-06-30T19:19:54.858431Z","sequence":180758188,"price":"9123.28","order_id":"5f52c02b-917b-4a15-893b-9d7f6f3b3f37","remaining_size":"0.063"}
{"type":"done","side":"sell","product_id":"BTC-USD","time":"2020-06-30T19:19:55.297465Z","sequence":180758189,"order_id":"7f54b831-265c-4f74-93e3-d7173ff1167d","reason":"canceled","price":"9125.93","remaining_size":"0.3222"}
{"type":"received","side":"sell","product_id":"BTC-USD","time":"2020-06-30T19:19:55.700651Z","sequence":180758190,"order_id":"2a787514-ac28-42e8-b6d6-18f9aade9a50","order_type":"limit","size":"0.003","price":"9123.15","client_oid":""}
{"type":"open","side":"sell","product_id":"BTC-USD","time":"2020-06-30T19:19:55.700651Z","sequence":180758191,"price":"9123.15","order_id":"2a787514-ac28-42e8-b6d6-18f9aade9a50","remaining_size":"0.003"}
{"type":"heartbeat","last_trade_id":0,"product_id":"BTC-USD","sequence":180758191,"time":"2020-06-30T19:19:55.735120Z"}
{"type":"done","side":"sell","product_id":"BTC-USD","time":"2020-06-30T19:19:56.144491Z","sequence":180758192,"order_id":"25e342a0-12fc-4a67-b471-98f267177227","reason":"canceled","price":"9124.8","remaining_size":"0.0658"}
{"type":"done","side":"sell","product_id":"BTC-USD","time":"2020-06-30T19:19:56.147262Z","sequence":180758193,"order_id":"e11a36af-bc12-4da2-a511-f0d24a8f4112","reason":"canceled","price":"9124.62","remaining_size":"0.0658"}
{"type":"done","side":"sell","product_id":"BTC-USD","time":"2020-06-30T19:19:56.156330Z","sequence":180758194,"order_id":"53aba182-19a5-4ef3-a26b-df49198a6361","reason":"canceled","price":"9159.21","remaining_size":"14.94"}
{"type":"received","side":"buy","product_id":"BTC-USD","time":"2020-06-30T19:19:56.524495Z","sequence":180758195,"order_id":"8d06f3fc-68a0-4116-9adb-5d4f2637d404","order_type":"limit","size":"0.1243","price":"9122.47","client_oid":""}
{"type":"match","side":"sell","product_id":"BTC-USD","time":"2020-06-30T19:19:56.524495Z","sequence":180758196,"trade_id":14587720,"maker_order_id":"36fe0734-4801-466d-b093-cccd411db09a","taker_order_id":"8d06f3fc-68a0-4116-9adb-5d4f2637d404","size":"0.1243","price":"9120.82"}
{"type":"done","side":"buy","product_id":"BTC-USD","time":"2020-06-30T19:19:56.524495Z","sequence":180758197,"order_id":"8d06f3fc-68a0-4116-9adb-5d4f2637d404","reason":"filled","price":"9122.47","remaining_size":"0"}
{"type":"heartbeat","last_trade_id":0,"product_id":"BTC-USD","sequence":180758197,"time":"2020-06-30T19:19:56.735118Z"}
{"type":"done","side":"buy","product_id":"BTC-USD","time":"2020-06-30T19:19:56.976931Z","sequence":180758198,"order_id":"de8cffb3-fecb-4d4b-a1a2-2e500bcddfaf","reason":"canceled","price":"9081.06","remaining_size":"0.0105"}
{"type":"received","side":"buy","product_id":"BTC-USD","time":"2020-06-30T19:19:57.092674Z","sequence":180758199,"order_id":"fe34657e-fc4c-498a-bf72-75765a759778","order_type":"limit","size":"0.1243","price":"9122.44","client_oid":""}
{"type":"match","side":"sell","product_id":"BTC-USD","time":"2020-06-30T19:19:57.092674Z","sequence":180758200,"trade_id":14587721,"maker_order_id":"36fe0734-4801-466d-b093-cccd411db09a","taker_order_id":"fe34657e-fc4c-498a-bf72-75765a759778","size":"0.1243","price":"9120.82"}
{"type":"done","side":"buy","product_id":"BTC-USD","time":"2020-06-30T19:19:57.092674Z","sequence":180758201,"order_id":"fe34657e-fc4c-498a-bf72-75765a759778","reason":"filled","price":"9122.44","remaining_size":"0"}
{"type":"received","side":"buy","product_id":"BTC-USD","time":"2020-06-30T19:19:57.369352Z","sequence":180758202,"order_id":"e705a6b7-69b9-4355-bc77-a1ee94964c6e","order_type":"limit","size":"0.5021","price":"9109.68","client_oid":""}
{"type":"open","side":"buy","product_id":"BTC-USD","time":"2020-06-30T19:19:57.369352Z","sequence":180758203,"price":"9109.68","order_id":"e705a6b7-69b9-4355-bc77-a1ee94964c6e","remaining_size":"0.5021"}
{"type":"heartbeat","last_trade_id":0,"product_id":"BTC-USD","sequence":180758203,"time":"2020-06-30T19:19:57.735108Z"}
{"type":"received","side":"buy","product_id":"BTC-USD","time":"2020-06-30T19:19:57.981246Z","sequence":180758204,"order_id":"86d500af-9d16-4dec-b630-9e50191a26ea","order_type":"limit","size":"0.4","price":"9120.32","client_oid":""}
{"type":"open","side":"buy","product_id":"BTC-USD","time":"2020-06-30T19:19:57.981246Z","sequence":180758205,"price":"9120.32","order_id":"86d500af-9d16-4dec-b630-9e50191a26ea","remaining_size":"0.4"}
{"type":"received","side":"buy","product_id":"BTC-USD","time":"2020-06-30T19:19:58.143884Z","sequence":180758206,"order_id":"3380a023-cc0f-4034-a8f4-8cc740432d83","order_type":"limit","size":"0.0247","price":"9099.84","client_oid":""}
{"type":"open","side":"buy","product_id":"BTC-USD","time":"2020-06-30T19:19:58.143884Z","sequence":180758207,"price":"9099.84","order_id":"3380a023-cc0f-4034-a8f4-8cc740432d83","remaining_size":"0.0247"}
{"type":"heartbeat","last_trade_id":0,"product_id":"BTC-USD","sequence":180758207,"time":"2020-06-30T19:19:58.735109Z"}
{"type":"received","side":"buy","product_id":"BTC-USD","time":"2020-06-30T19:19:58.830178Z","sequence":180758208,"order_id":"c3162a48-4c52-4fe8-ba47-9ba5873f7be3","order_type":"limit","size":"0.0263","price":"9099.43","client_oid":""}
{"type":"open","side":"buy","product_id":"BTC-USD","time":"2020-06-30T19:19:58.830178Z","sequence":180758209,"price":"9099.43","order_id":"c3162a48-4c52-4fe8-ba47-9ba5873f7be3","remaining_size":"0.0263"}
{"type":"done","side":"buy","product_id":"BTC-USD","time":"2020-06-30T19:19:58.967538Z","sequence":180758210,"order_id":"18d16032-2bf5-459e-a970-1bd824afe351","reason":"canceled","price":"8889.35","remaining_size":"0.0470187"}
{"type":"received","side":"buy","product_id":"BTC-USD","time":"2020-06-30T19:19:59.071625Z","sequence":180758211,"order_id":"ae4597af-be7a-432c-b3f0-b7b3a2fc38bb","order_type":"limit","size":"0.01","price":"100","client_oid":"25589693-605b-460f-b4a5-66b5cda521b9"}
{"type":"open","side":"buy","product_id":"BTC-USD","time":"2020-06-30T19:19:59.071625Z","sequence":180758212,"price":"100","order_id":"ae4597af-be7a-432c-b3f0-b7b3a2fc38bb","remaining_size":"0.01"}
{"type":"done","side":"buy","product_id":"BTC-USD","time":"2020-06-30T19:19:59.078716Z","sequence":180758213,"order_id":"ae4597af-be7a-432c-b3f0-b7b3a2fc38bb","reason":"canceled","price":"100","remaining_size":"0.01"}
{"type":"received","side":"buy","product_id":"BTC-USD","time":"2020-06-30T19:19:59.101697Z","sequence":180758214,"order_id":"03b126ec-123f-4b6c-8966-1d77e9df3c95","order_type":"limit","size":"0.0495","price":"9101.45","client_oid":""}
{"type":"open","side":"buy","product_id":"BTC-USD","time":"2020-06-30T19:19:59.101697Z","sequence":180758215,"price":"9101.45","order_id":"03b126ec-123f-4b6c-8966-1d77e9df3c95","remaining_size":"0.0495"}
{"type":"received","side":"buy","product_id":"BTC-USD","time":"2020-06-30T19:19:59.350244Z","sequence":180758216,"order_id":"ec910220-2a26-43d1-b9cf-a39d3b51e169","order_type":"limit","size":"0.04711175","price":"8888.6","client_oid":""}
{"type":"open","side":"buy","product_id":"BTC-USD","time":"2020-06-30T19:19:59.350244Z","sequence":180758217,"price":"8888.6","order_id":"ec910220-2a26-43d1-b9cf-a39d3b51e169","remaining_size":"0.04711175"}
{"type":"received","side":"buy","product_id":"BTC-USD","time":"2020-06-30T19:19:59.372054Z","sequence":180758218,"order_id":"1fbfae28-1c5a-4d27-88c0-8f9871985e0c","order_type":"limit","size":"0.4367","price":"9119.58","client_oid":""}
{"type":"open","side":"buy","product_id":"BTC-USD","time":"2020-06-30T19:19:59.372054Z","sequence":180758219,"price":"9119.58","order_id":"1fbfae28-1c5a-4d27-88c0-8f9871985e0c","remaining_size":"0.4367"}
{"type":"heartbeat","last_trade_id":0,"product_id":"BTC-USD","sequence":180758219,"time":"2020-06-30T19:19:59.735096Z"}
{"type":"done","side":"sell","product_id":"BTC-USD","time":"2020-06-30T19:19:59.827990Z","sequence":180758220,"order_id":"bbb02623-9772-4a57-910c-c5a5f17311bc","reason":"canceled","price":"9441.89","remaining_size":"0.0077523"}
{"type":"received","side":"sell","product_id":"BTC-USD","time":"2020-06-30T19:20:00.207240Z","sequence":180758221,"order_id":"3ed4daf0-ceb6-4236-8ce7-7c80b0f10728","order_type":"limit","size":"0.00784327","price":"9442.69","client_oid":""}
{"type":"open","side":"sell","product_id":"BTC-USD","time":"2020-06-30T19:20:00.207240Z","sequence":180758222,"price":"9442.69","order_id":"3ed4daf0-ceb6-4236-8ce7-7c80b0f10728","remaining_size":"0.00784327"}
{"type":"received","side":"buy","product_id":"BTC-USD","time":"2020-06-30T19:20:00.353001Z","sequence":180758223,"order_id":"207ad67e-2c04-4acd-a5d3-dde24ba83eae","order_type":"limit","size":"0.8565","price":"9121.72","client_oid":""}
{"type":"match","side":"sell","product_id":"BTC-USD","time":"2020-06-30T19:20:00.353001Z","sequence":180758224,"trade_id":14587722,"maker_order_id":"36fe0734-4801-466d-b093-cccd411db09a","taker_order_id":"207ad67e-2c04-4acd-a5d3-dde24ba83eae","size":"0.8565","price":"9120.82"}
{"type":"done","side":"buy","product_id":"BTC-USD","time":"2020-06-30T19:20:00.353001Z","sequence":180758225,"order_id":"207ad67e-2c04-4acd-a5d3-dde24ba83eae","reason":"filled","price":"9121.72","remaining_size":"0"}
{"type":"heartbeat","last_trade_id":0,"product_id":"BTC-USD","sequence":180758225,"time":"2020-06-30T19:20:00.735113Z"}
{"type":"done","side":"buy","product_id":"BTC-USD","time":"2020-06-30T19:20:00.787769Z","sequence":180758226,"order_id":"c57497ef-b880-4b37-a502-270461cfc694","reason":"canceled","price":"9116.21","remaining_size":"0.0012"}
{"type":"received","side":"sell","product_id":"BTC-USD","time":"2020-06-30T19:20:01.158211Z","sequence":180758227,"order_id":"7abc7002-f433-4b56-875f-dc4749d4864f","order_type":"limit","size":"0.0984","price":"9123.54","client_oid":""}
{"type":"open","side":"sell","product_id":"BTC-USD","time":"2020-06-30T19:20:01.158211Z","sequence":180758228,"price":"9123.54","order_id":"7abc7002-f433-4b56-875f-dc4749d4864f","remaining_size":"0.0984"}
{"type":"received","side":"buy","product_id":"BTC-USD","time":"2020-06-30T19:20:01.428413Z","sequence":180758229,"order_id":"05889c3d-4934-4116-a0cd-5fc52e2afc89","order_type":"limit","size":"1","price":"9122.06","client_oid":""}
{"type":"match","side":"sell","product_id":"BTC-USD","time":"2020-06-30T19:20:01.428413Z","sequence":180758230,"trade_id":14587723,"maker_order_id":"36fe0734-4801-466d-b093-cccd411db09a","taker_order_id":"05889c3d-4934-4116-a0cd-5fc52e2afc89","size":"1","price":"9120.82"}
{"type":"done","side":"buy","product_id":"BTC-USD","time":"2020-06-30T19:20:01.428413Z","sequence":180758231,"order_id":"05889c3d-4934-4116-a0cd-5fc52e2afc89","reason":"filled","price":"9122.06","remaining_size":"0"}
{"type":"done","side":"sell","product_id":"BTC-USD","time":"2020-06-30T19:20:01.632630Z","sequence":180758232,"order_id":"1fd2d33f-c1fd-4e5b-bed8-dec4a5df5019","reason":"canceled","price":"9124.42","remaining_size":"0.3222"}
{"type":"done","side":"buy","product_id":"BTC-USD","time":"2020-06-30T19:20:01.672004Z","sequence":180758233,"order_id":"86d500af-9d16-4dec-b630-9e50191a26ea","reason":"canceled","price":"9120.32","remaining_size":"0.4"}
{"type":"done","side":"buy","product_id":"BTC-USD","time":"2020-06-30T19:20:01.684357Z","sequence":180758234,"order_id":"45d7538d-3a7a-41be-a3ae-759d7f0b9798","reason":"canceled","price":"9075.38","remaining_size":"0.056"}
{"type":"done","side":"buy","product_id":"BTC-USD","time":"2020-06-30T19:20:01.688195Z","sequence":180758235,"order_id":"51e49eb3-1648-4073-beee-9a18b44c223f","reason":"canceled","price":"8964.07","remaining_size":"0.178"}
{"type":"heartbeat","last_trade_id":0,"product_id":"BTC-USD","sequence":180758235,"time":"2020-06-30T19:20:01.735111Z"}
{"type":"received","side":"sell","product_id":"BTC-USD","time":"2020-06-30T19:20:02.731210Z","sequence":180758236,"order_id":"c8e48cb4-af76-42ae-9994-72788526e36e","order_type":"limit","size":"0.0658","price":"9124.97","client_oid":""}
{"type":"open","side":"sell","product_id":"BTC-USD","time":"2020-06-30T19:20:02.731210Z","sequence":180758237,"price":"9124.97","order_id":"c8e48cb4-af76-42ae-9994-72788526e36e","remaining_size":"0.0658"}
{"type":"heartbeat","last_trade_id":0,"product_id":"BTC-USD","sequence":180758237,"time":"2020-06-30T19:20:02.735114Z"}
{"type":"received","side":"buy","product_id":"BTC-USD","time":"2020-06-30T19:20:03.001032Z","sequence":180758238,"order_id":"d98147e1-fb81-41d9-be0a-dd3ad6ba98b1","order_type":"limit","size":"6.95","price":"9123.51","client_oid":""}
{"type":"match","side":"sell","product_id":"BTC-USD","time":"2020-06-30T19:20:03.001032Z","sequence":180758239,"trade_id":14587724,"maker_order_id":"36fe0734-4801-466d-b093-cccd411db09a","taker_order_id":"d98147e1-fb81-41d9-be0a-dd3ad6ba98b1","size":"6.95","price":"9120.82"}
{"type":"done","side":"buy","product_id":"BTC-USD","time":"2020-06-30T19:20:03.001032Z","sequence":180758240,"order_id":"d98147e1-fb81-41d9-be0a-dd3ad6ba98b1","reason":"filled","price":"9123.51","remaining_size":"0"}
{"type":"received","side":"buy","product_id":"BTC-USD","time":"2020-06-30T19:20:03.394237Z","sequence":180758241,"order_id":"b55256b7-987d-4d27-905d-5932e090e1c8","order_type":"limit","size":"0.0509","price":"9102.77","client_oid":""}
