{"type":"subscriptions","channels":[{"name":"heartbeat","product_ids":["BTC-USD"]},{"name":"full","product_ids":["BTC-USD"]}]}
{"type":"heartbeat","last_trade_id":0,"product_id":"BTC-USD","sequence":180754924,"time":"2020-06-30T19:10:21.735070Z"}
{"type":"received","side":"buy","product_id":"BTC-USD","time":"2020-06-30T19:10:22.381718Z","sequence":180754925,"order_id":"e37f7609-a026-4717-873e-ca2360fc83ff","order_type":"limit","size":"0.001","price":"9110","client_oid":""}
{"type":"open","side":"buy","product_id":"BTC-USD","time":"2020-06-30T19:10:22.381718Z","sequence":180754926,"price":"9110","order_id":"e37f7609-a026-4717-873e-ca2360fc83ff","remaining_size":"0.001"}
{"type":"heartbeat","last_trade_id":0,"product_id":"BTC-USD","sequence":180754926,"time":"2020-06-30T19:10:22.735092Z"}
{"type":"done","side":"buy","product_id":"BTC-USD","time":"2020-06-30T19:10:22.833144Z","sequence":180754927,"order_id":"56d7a89b-9e62-4af9-80cd-7014f16c50f9","reason":"canceled","price":"9077.66","remaining_size":"0.0257"}
{"type":"done","side":"buy","product_id":"BTC-USD","time":"2020-06-30T19:10:22.837265Z","sequence":180754928,"order_id":"aa451d6e-9738-48ec-8ad6-d907e34a4359","reason":"canceled","price":"9107.72","remaining_size":"0.025"}
{"type":"done","side":"buy","product_id":"BTC-USD","time":"2020-06-30T19:10:22.837345Z","sequence":180754929,"order_id":"755776f4-3ad8-4409-8bfc-f52bbe2ba934","reason":"canceled","price":"9084.81","remaining_size":"0.0371"}
{"type":"received","side":"sell","product_id":"BTC-USD","time":"2020-06-30T19:10:23.252314Z","sequence":180754930,"order_id":"091bb901-31d9-4515-8835-119d013c1508","order_type":"limit","size":"1.0158","price":"9137.48","client_oid":""}
{"type":"open","side":"sell","product_id":"BTC-USD","time":"2020-06-30T19:10:23.252314Z","sequence":180754931,"price":"9137.48","order_id":"091bb901-31d9-4515-8835-119d013c1508","remaining_size":"1.0158"}
{"type":"heartbeat","last_trade_id":0,"product_id":"BTC-USD","sequence":180754931,"time":"2020-06-30T19:10:23.735107Z"}
{"type":"received","side":"buy","product_id":"BTC-USD","time":"2020-06-30T19:10:24.322117Z","sequence":180754932,"order_id":"9254f43d-0a76-4008-a5c8-595becb3b02d","order_type":"limit","size":"0.1565","price":"9085.4","client_oid":""}
{"type":"open","side":"buy","product_id":"BTC-USD","time":"2020-06-30T19:10:24.322117Z","sequence":180754933,"price":"9085.4","order_id":"9254f43d-0a76-4008-a5c8-595becb3b02d","remaining_size":"0.1565"}
{"type":"received","side":"sell","product_id":"BTC-USD","time":"2020-06-30T19:10:24.602001Z","sequence":180754934,"order_id":"47888661-47cc-4af6-a26e-ea359b236b1b","order_type":"limit","size":"0.0659","price":"9109.25","client_oid":""}
{"type":"match","side":"buy","product_id":"BTC-USD","time":"2020-06-30T19:10:24.602001Z","sequence":180754935,"trade_id":14587419,"maker_order_id":"91b59a7c-6a07-4039-9536-21daf3cb3282","taker_order_id":"47888661-47cc-4af6-a26e-ea359b236b1b","size":"0.0659","price":"9120.8"}
{"type":"done","side":"sell","product_id":"BTC-USD","time":"2020-06-30T19:10:24.602001Z","sequence":180754936,"order_id":"47888661-47cc-4af6-a26e-ea359b236b1b","reason":"filled","price":"9109.25","remaining_size":"0"}
{"type":"heartbeat","last_trade_id":0,"product_id":"BTC-USD","sequence":180754936,"time":"2020-06-30T19:10:24.735115Z"}
{"type":"done","side":"buy","product_id":"BTC-USD","time":"2020-06-30T19:10:24.779046Z","sequence":180754937,"order_id":"7b5f118b-3b37-479a-93dc-d1fcb9b4b5df","reason":"canceled","price":"9110.09","remaining_size":"4.9555"}
{"type":"done","side":"sell","product_id":"BTC-USD","time":"2020-06-30T19:10:25.046980Z","sequence":180754938,"order_id":"091bb901-31d9-4515-8835-119d013c1508","reason":"canceled","price":"9137.48","remaining_size":"1.0158"}
{"type":"received","side":"sell","product_id":"BTC-USD","time":"2020-06-30T19:10:25.282011Z","sequence":180754939,"order_id":"6e18daea-f790-42b7-848d-d356bb5793f9","order_type":"limit","size":"0.05","price":"9109.29","client_oid":""}
{"type":"match","side":"buy","product_id":"BTC-USD","time":"2020-06-30T19:10:25.282011Z","sequence":180754940,"trade_id":14587420,"maker_order_id":"91b59a7c-6a07-4039-9536-21daf3cb3282","taker_order_id":"6e18daea-f790-42b7-848d-d356bb5793f9","size":"0.05","price":"9120.8"}
{"type":"done","side":"sell","product_id":"BTC-USD","time":"2020-06-30T19:10:25.282011Z","sequence":180754941,"order_id":"6e18daea-f790-42b7-848d-d356bb5793f9","reason":"filled","price":"9109.29","remaining_size":"0"}
{"type":"received","side":"buy","product_id":"BTC-USD","time":"2020-06-30T19:10:25.546819Z","sequence":180754942,"order_id":"10d2ad8d-8948-4a50-9b04-413ad483cdfa","order_type":"limit","size":"0.0692","price":"9079.24","client_oid":""}
{"type":"open","side":"buy","product_id":"BTC-USD","time":"2020-06-30T19:10:25.546819Z","sequence":180754943,"price":"9079.24","order_id":"10d2ad8d-8948-4a50-9b04-413ad483cdfa","remaining_size":"0.0692"}
{"type":"done","side":"sell","product_id":"BTC-USD","time":"2020-06-30T19:10:25.727819Z","sequence":180754944,"order_id":"b7c65cbb-d8e2-4933-8131-a74e90384aa2","reason":"canceled","price":"9164.12","remaining_size":"0.069"}
{"type":"heartbeat","last_trade_id":0,"product_id":"BTC-USD","sequence":180754944,"time":"2020-06-30T19:10:25.735119Z"}
{"type":"done","side":"buy","product_id":"BTC-USD","time":"2020-06-30T19:10:25.756751Z","sequence":180754945,"order_id":"59c50d00-104b-4d69-b858-72e1919b3bf1","reason":"canceled","price":"9095.58","remaining_size":"0.0102"}
{"type":"received","side":"sell","product_id":"BTC-USD","time":"2020-06-30T19:10:25.839564Z","sequence":180754946,"order_id":"281196c7-0be0-46a2-942b-78891eb2783d","order_type":"limit","size":"0.149","price":"9109.61","client_oid":""}
{"type":"match","side":"buy","product_id":"BTC-USD","time":"2020-06-30T19:10:25.839564Z","sequence":180754947,"trade_id":14587421,"maker_order_id":"91b59a7c-6a07-4039-9536-21daf3cb3282","taker_order_id":"281196c7-0be0-46a2-942b-78891eb2783d","size":"0.149","price":"9120.8"}
{"type":"done","side":"sell","product_id":"BTC-USD","time":"2020-06-30T19:10:25.839564Z","sequence":180754948,"order_id":"281196c7-0be0-46a2-942b-78891eb2783d","reason":"filled","price":"9109.61","remaining_size":"0"}
{"type":"done","side":"sell","product_id":"BTC-USD","time":"2020-06-30T19:10:26.307894Z","sequence":180754949,"order_id":"47b9cbd1-d91a-48ef-863c-95a85946465b","reason":"canceled","price":"9145.01","remaining_size":"0.0547"}
{"type":"heartbeat","last_trade_id":0,"product_id":"BTC-USD","sequence":180754949,"time":"2020-06-30T19:10:26.735115Z"}
{"type":"received","side":"sell","product_id":"BTC-USD","time":"2020-06-30T19:10:27.280188Z","sequence":180754950,"order_id":"f15097ae-f448-4caa-98a3-cb29795f85ed","order_type":"limit","size":"0.0352","price":"9161.71","client_oid":""}
{"type":"open","side":"sell","product_id":"BTC-USD","time":"2020-06-30T19:10:27.280188Z","sequence":180754951,"price":"9161.71","order_id":"f15097ae-f448-4caa-98a3-cb29795f85ed","remaining_size":"0.0352"}
{"type":"done","side":"sell","product_id":"BTC-USD","time":"2020-06-30T19:10:27.726889Z","sequence":180754952,"order_id":"7b7bba99-a845-4cb0-a2fe-fc0bd22cba45","reason":"canceled","price":"9121.12","remaining_size":"0.0659"}
{"type":"heartbeat","last_trade_id":0,"product_id":"BTC-USD","sequence":180754952,"time":"2020-06-30T19:10:27.735118Z"}
{"type":"received","side":"sell","product_id":"BTC-USD","time":"2020-06-30T19:10:27.826621Z","sequence":180754953,"order_id":"ecb1243e-9a02-4d80-9390-d5c22438c44c","order_type":"limit","size":"0.0547","price":"9142.68","client_oid":""}
{"type":"open","side":"sell","product_id":"BTC-USD","time":"2020-06-30T19:10:27.826621Z","sequence":180754954,"price":"9142.68","order_id":"ecb1243e-9a02-4d80-9390-d5c22438c44c","remaining_size":"0.0547"}
{"type":"received","side":"buy","product_id":"BTC-USD","time":"2020-06-30T19:10:28.118774Z","sequence":180754955,"order_id":"000c5c40-96d7-443e-8bc8-de07689d6752","order_type":"limit","size":"0.0331","price":"9075.47","client_oid":""}
{"type":"open","side":"buy","product_id":"BTC-USD","time":"2020-06-30T19:10:28.118774Z","sequence":180754956,"price":"9075.47","order_id":"000c5c40-96d7-443e-8bc8-de07689d6752","remaining_size":"0.0331"}
{"type":"done","side":"sell","product_id":"BTC-USD","time":"2020-06-30T19:10:28.261442Z","sequence":180754957,"order_id":"a17bb2de-18aa-4ac6-9546-dd8d214a017c","reason":"canceled","price":"9170.47","remaining_size":"0.0765"}
{"type":"received","side":"sell","product_id":"BTC-USD","time":"2020-06-30T19:10:28.392867Z","sequence":180754958,"order_id":"e4c9735f-b000-4c5f-9be9-20abda7dfb6a","order_type":"limit","size":"0.2867","price":"9108.98","client_oid":""}
{"type":"match","side":"buy","product_id":"BTC-USD","time":"2020-06-30T19:10:28.392867Z","sequence":180754959,"trade_id":14587422,"maker_order_id":"91b59a7c-6a07-4039-9536-21daf3cb3282","taker_order_id":"e4c9735f-b000-4c5f-9be9-20abda7dfb6a","size":"0.2867","price":"9120.8"}
{"type":"done","side":"sell","product_id":"BTC-USD","time":"2020-06-30T19:10:28.392867Z","sequence":180754960,"order_id":"e4c9735f-b000-4c5f-9be9-20abda7dfb6a","reason":"filled","price":"9108.98","remaining_size":"0"}
{"type":"done","side":"buy","product_id":"BTC-USD","time":"2020-06-30T19:10:28.571021Z","sequence":180754961,"order_id":"e37f7609-a026-4717-873e-ca2360fc83ff","reason":"canceled","price":"9110","remaining_size":"0.001"}
{"type":"done","side":"buy","product_id":"BTC-USD","time":"2020-06-30T19:10:28.574873Z","sequence":180754962,"order_id":"425cb0a2-4f0c-4e4e-8c6f-1d9911fffea2","reason":"canceled","price":"9110.09","remaining_size":"2.9218"}
{"type":"done","side":"buy","product_id":"BTC-USD","time":"2020-06-30T19:10:28.577774Z","sequence":180754963,"order_id":"511af1ae-b4e3-44a3-89c9-f0bb529d6255","reason":"canceled","price":"9106.64","remaining_size":"0.75"}
{"type":"received","side":"sell","product_id":"BTC-USD","time":"2020-06-30T19:10:28.676726Z","sequence":180754964,"order_id":"790d316c-c040-4cd9-bf5e-a880546fd955","order_type":"limit","size":"0.0659","price":"9108.72","client_oid":""}
{"type":"match","side":"buy","product_id":"BTC-USD","time":"2020-06-30T19:10:28.676726Z","sequence":180754965,"trade_id":14587423,"maker_order_id":"91b59a7c-6a07-4039-9536-21daf3cb3282","taker_order_id":"790d316c-c040-4cd9-bf5e-a880546fd955","size":"0.0659","price":"9120.8"}
{"type":"done","side":"sell","product_id":"BTC-USD","time":"2020-06-30T19:10:28.676726Z","sequence":180754966,"order_id":"790d316c-c040-4cd9-bf5e-a880546fd955","reason":"filled","price":"9108.72","remaining_size":"0"}
{"type":"heartbeat","last_trade_id":0,"product_id":"BTC-USD","sequence":180754966,"time":"2020-06-30T19:10:28.735118Z"}
{"type":"received","side":"buy","product_id":"BTC-USD","time":"2020-06-30T19:10:28.994427Z","sequence":180754967,"order_id":"7b1669b2-f0a9-4f59-9247-5365609115ec","order_type":"limit","size":"0.0692","price":"9076.31","client_oid":""}
{"type":"open","side":"buy","product_id":"BTC-USD","time":"2020-06-30T19:10:28.994427Z","sequence":180754968,"price":"9076.31","order_id":"7b1669b2-f0a9-4f59-9247-5365609115ec","remaining_size":"0.0692"}
{"type":"received","side":"buy","product_id":"BTC-USD","time":"2020-06-30T19:10:29.090940Z","sequence":180754969,"order_id":"c2fb7df9-6d61-4ca3-9c88-8bedc6a9670f","order_type":"limit","size":"0.01","price":"100","client_oid":"59774e88-c7f5-4c0b-af7d-4f330040bc52"}
{"type":"open","side":"buy","product_id":"BTC-USD","time":"2020-06-30T19:10:29.090940Z","sequence":180754970,"price":"100","order_id":"c2fb7df9-6d61-4ca3-9c88-8bedc6a9670f","remaining_size":"0.01"}
{"type":"done","side":"buy","product_id":"BTC-USD","time":"2020-06-30T19:10:29.097959Z","sequence":180754971,"order_id":"c2fb7df9-6d61-4ca3-9c88-8bedc6a9670f","reason":"canceled","price":"100","remaining_size":"0.01"}
{"type":"done","side":"buy","product_id":"BTC-USD","time":"2020-06-30T19:10:29.425063Z","sequence":180754972,"order_id":"9254f43d-0a76-4008-a5c8-595becb3b02d","reason":"canceled","price":"9085.4","remaining_size":"0.1565"}
{"type":"done","side":"buy","product_id":"BTC-USD","time":"2020-06-30T19:10:29.426088Z","sequence":180754973,"order_id":"000c5c40-96d7-443e-8bc8-de07689d6752","reason":"canceled","price":"9075.47","remaining_size":"0.0331"}
{"type":"heartbeat","last_trade_id":0,"product_id":"BTC-USD","sequence":180754973,"time":"2020-06-30T19:10:29.735094Z"}
{"type":"received","side":"sell","product_id":"BTC-USD","time":"2020-06-30T19:10:29.919477Z","sequence":180754974,"order_id":"6b8eb102-c29f-4569-a2fd-3aff08439d24","order_type":"limit","size":"0.7632","price":"9131.21","client_oid":""}
{"type":"open","side":"sell","product_id":"BTC-USD","time":"2020-06-30T19:10:29.919477Z","sequence":180754975,"price":"9131.21","order_id":"6b8eb102-c29f-4569-a2fd-3aff08439d24","remaining_size":"0.7632"}
{"type":"heartbeat","last_trade_id":0,"product_id":"BTC-USD","sequence":180754975,"time":"2020-06-30T19:10:30.735122Z"}
{"type":"received","side":"buy","product_id":"BTC-USD","time":"2020-06-30T19:10:30.775988Z","sequence":180754976,"order_id":"51f470e4-3607-479a-83cc-b178fc711939","order_type":"limit","size":"0.0692","price":"9080.54","client_oid":""}
{"type":"open","side":"buy","product_id":"BTC-USD","time":"2020-06-30T19:10:30.775988Z","sequence":180754977,"price":"9080.54","order_id":"51f470e4-3607-479a-83cc-b178fc711939","remaining_size":"0.0692"}
{"type":"done","side":"buy","product_id":"BTC-USD","time":"2020-06-30T19:10:31.257477Z","sequence":180754978,"order_id":"08ea8283-22f8-43b2-a346-5bd8bf4898c9","reason":"canceled","price":"9110.1","remaining_size":"0.9"}
{"type":"done","side":"buy","product_id":"BTC-USD","time":"2020-06-30T19:10:31.261537Z","sequence":180754979,"order_id":"7b1669b2-f0a9-4f59-9247-5365609115ec","reason":"canceled","price":"9076.31","remaining_size":"0.0692"}
{"type":"done","side":"buy","product_id":"BTC-USD","time":"2020-06-30T19:10:31.294384Z","sequence":180754980,"order_id":"01953974-2ea7-444d-9075-712f14d851f4","reason":"canceled","price":"9089.23","remaining_size":"0.1047"}
{"type":"received","side":"sell","product_id":"BTC-USD","time":"2020-06-30T19:10:31.344615Z","sequence":180754981,"order_id":"13f49490-005a-4a4d-b0a0-5e8097686668","order_type":"limit","size":"3.8867","price":"9108.51","client_oid":""}
{"type":"match","side":"buy","product_id":"BTC-USD","time":"2020-06-30T19:10:31.344615Z","sequence":180754982,"trade_id":14587424,"maker_order_id":"91b59a7c-6a07-4039-9536-21daf3cb3282","taker_order_id":"13f49490-005a-4a4d-b0a0-5e8097686668","size":"3.8867","price":"9120.8"}
{"type":"done","side":"sell","product_id":"BTC-USD","time":"2020-06-30T19:10:31.344615Z","sequence":180754983,"order_id":"13f49490-005a-4a4d-b0a0-5e8097686668","reason":"filled","price":"9108.51","remaining_size":"0"}
{"type":"received","side":"sell","product_id":"BTC-USD","time":"2020-06-30T19:10:31.614624Z","sequence":180754984,"order_id":"882c7d26-666b-4604-adeb-41ded8552855","order_type":"limit","size":"6.0861","price":"9108.51","client_oid":""}
{"type":"match","side":"buy","product_id":"BTC-USD","time":"2020-06-30T19:10:31.614624Z","sequence":180754985,"trade_id":14587425,"maker_order_id":"91b59a7c-6a07-4039-9536-21daf3cb3282","taker_order_id":"882c7d26-666b-4604-adeb-41ded8552855","size":"6.0861","price":"9120.8"}
{"type":"done","side":"sell","product_id":"BTC-USD","time":"2020-06-30T19:10:31.614624Z","sequence":180754986,"order_id":"882c7d26-666b-4604-adeb-41ded8552855","reason":"filled","price":"9108.51","remaining_size":"0"}
{"type":"heartbeat","last_trade_id":0,"product_id":"BTC-USD","sequence":180754986,"time":"2020-06-30T19:10:31.735121Z"}
{"type":"done","side":"sell","product_id":"BTC-USD","time":"2020-06-30T19:10:31.933635Z","sequence":180754987,"order_id":"132b0220-26d5-47e7-97a8-2c1667096bc8","reason":"canceled","price":"9167.19","remaining_size":"0.0962"}
{"type":"received","side":"sell","product_id":"BTC-USD","time":"2020-06-30T19:10:32.427539Z","sequence":180754988,"order_id":"53097ba8-efe9-44f7-8d25-f6d3b807c156","order_type":"limit","size":"0.1","price":"9160.56","client_oid":""}
{"type":"open","side":"sell","product_id":"BTC-USD","time":"2020-06-30T19:10:32.427539Z","sequence":180754989,"price":"9160.56","order_id":"53097ba8-efe9-44f7-8d25-f6d3b807c156","remaining_size":"0.1"}
{"type":"done","side":"buy","product_id":"BTC-USD","time":"2020-06-30T19:10:32.442947Z","sequence":180754990,"order_id":"10d2ad8d-8948-4a50-9b04-413ad483cdfa","reason":"canceled","price":"9079.24","remaining_size":"0.0692"}
{"type":"received","side":"sell","product_id":"BTC-USD","time":"2020-06-30T19:10:32.699106Z","sequence":180754991,"order_id":"deb23fdf-a9e8-4172-809d-941b02f543e6","order_type":"limit","size":"1.5","price":"9108.44","client_oid":""}
{"type":"match","side":"buy","product_id":"BTC-USD","time":"2020-06-30T19:10:32.699106Z","sequence":180754992,"trade_id":14587426,"maker_order_id":"91b59a7c-6a07-4039-9536-21daf3cb3282","taker_order_id":"deb23fdf-a9e8-4172-809d-941b02f543e6","size":"1.5","price":"9120.8"}
{"type":"done","side":"sell","product_id":"BTC-USD","time":"2020-06-30T19:10:32.699106Z","sequence":180754993,"order_id":"deb23fdf-a9e8-4172-809d-941b02f543e6","reason":"filled","price":"9108.44","remaining_size":"0"}
{"type":"heartbeat","last_trade_id":0,"product_id":"BTC-USD","sequence":180754993,"time":"2020-06-30T19:10:32.735109Z"}
{"type":"done","side":"sell","product_id":"BTC-USD","time":"2020-06-30T19:10:32.938483Z","sequence":180754994,"order_id":"53097ba8-efe9-44f7-8d25-f6d3b807c156","reason":"canceled","price":"9160.56","remaining_size":"0.1"}
{"type":"heartbeat","last_trade_id":0,"product_id":"BTC-USD","sequence":180754994,"time":"2020-06-30T19:10:33.735108Z"}
{"type":"received","side":"buy","product_id":"BTC-USD","time":"2020-06-30T19:10:33.782364Z","sequence":180754995,"order_id":"8f2f876f-6a50-4d3c-9c8c-34d8dd712352","order_type":"limit","size":"0.015","price":"9107.06","client_oid":""}
{"type":"open","side":"buy","product_id":"BTC-USD","time":"2020-06-30T19:10:33.782364Z","sequence":180754996,"price":"9107.06","order_id":"8f2f876f-6a50-4d3c-9c8c-34d8dd712352","remaining_size":"0.015"}
{"type":"received","side":"sell","product_id":"BTC-USD","time":"2020-06-30T19:10:34.071409Z","sequence":180754997,"order_id":"c93549ec-4585-459c-ba0e-0fccd31f61c3","order_type":"limit","size":"0.3873","price":"9112.95","client_oid":""}
{"type":"match","side":"buy","product_id":"BTC-USD","time":"2020-06-30T19:10:34.071409Z","sequence":180754998,"trade_id":14587427,"maker_order_id":"91b59a7c-6a07-4039-9536-21daf3cb3282","taker_order_id":"c93549ec-4585-459c-ba0e-0fccd31f61c3","size":"0.3873","price":"9120.8"}
{"type":"done","side":"sell","product_id":"BTC-USD","time":"2020-06-30T19:10:34.071409Z","sequence":180754999,"order_id":"c93549ec-4585-459c-ba0e-0fccd31f61c3","reason":"filled","price":"9112.95","remaining_size":"0"}
{"type":"received","side":"buy","product_id":"BTC-USD","time":"2020-06-30T19:10:34.658106Z","sequence":180755000,"order_id":"ccddf108-ac97-4b57-9b4e-f8b8eaa99fba","order_type":"limit","size":"0.0235","price":"9077.02","client_oid":""}
{"type":"open","side":"buy","product_id":"BTC-USD","time":"2020-06-30T19:10:34.658106Z","sequence":180755001,"price":"9077.02","order_id":"ccddf108-ac97-4b57-9b4e-f8b8eaa99fba","remaining_size":"0.0235"}
{"type":"heartbeat","last_trade_id":0,"product_id":"BTC-USD","sequence":180755001,"time":"2020-06-30T19:10:34.735082Z"}
{"type":"heartbeat","last_trade_id":0,"product_id":"BTC-USD","sequence":180755001,"time":"2020-06-30T19:10:35.735068Z"}
{"type":"received","side":"buy","product_id":"BTC-USD","time":"2020-06-30T19:10:35.806899Z","sequence":180755002,"order_id":"c807f27a-e07f-447e-b3d7-26aa0665c25b","order_type":"limit","size":"0.25","price":"9106.15","client_oid":""}
{"type":"open","side":"buy","product_id":"BTC-USD","time":"2020-06-30T19:10:35.806899Z","sequence":180755003,"price":"9106.15","order_id":"c807f27a-e07f-447e-b3d7-26aa0665c25b","remaining_size":"0.25"}
{"type":"received","side":"buy","product_id":"BTC-USD","time":"2020-06-30T19:10:36.071893Z","sequence":180755004,"order_id":"79ac9525-dc1a-4d9e-abe7-82eecae9b822","order_type":"limit","size":"0.0692","price":"9079.64","client_oid":""}
{"type":"open","side":"buy","product_id":"BTC-USD","time":"2020-06-30T19:10:36.071893Z","sequence":180755005,"price":"9079.64","order_id":"79ac9525-dc1a-4d9e-abe7-82eecae9b822","remaining_size":"0.0692"}
{"type":"done","side":"buy","product_id":"BTC-USD","time":"2020-06-30T19:10:36.271365Z","sequence":180755006,"order_id":"2c5a75d1-07a7-474f-a570-20c08dbe6ade","reason":"canceled","price":"9105.99","remaining_size":"1.0976"}
{"type":"received","side":"sell","product_id":"BTC-USD","time":"2020-06-30T19:10:36.347327Z","sequence":180755007,"order_id":"e5140f0e-20c9-4271-b231-e62f819f4e24","order_type":"limit","size":"0.0469","price":"9136.14","client_oid":""}
{"type":"open","side":"sell","product_id":"BTC-USD","time":"2020-06-30T19:10:36.347327Z","sequence":180755008,"price":"9136.14","order_id":"e5140f0e-20c9-4271-b231-e62f819f4e24","remaining_size":"0.0469"}
{"type":"heartbeat","last_trade_id":0,"product_id":"BTC-USD","sequence":180755008,"time":"2020-06-30T19:10:36.735072Z"}
{"type":"received","side":"buy","product_id":"BTC-USD","time":"2020-06-30T19:10:36.921070Z","sequence":180755009,"order_id":"19c9feb4-7091-4fe6-b773-9be03dd894dc","order_type":"limit","size":"0.0692","price":"9073.36","client_oid":""}
{"type":"open","side":"buy","product_id":"BTC-USD","time":"2020-06-30T19:10:36.921070Z","sequence":180755010,"price":"9073.36","order_id":"19c9feb4-7091-4fe6-b773-9be03dd894dc","remaining_size":"0.0692"}
{"type":"received","side":"sell","product_id":"BTC-USD","time":"2020-06-30T19:10:37.529104Z","sequence":180755011,"order_id":"3d4c5705-9b5a-42fc-a834-9350a075c87f","order_type":"limit","size":"0.0531","price":"9160.27","client_oid":""}
{"type":"open","side":"sell","product_id":"BTC-USD","time":"2020-06-30T19:10:37.529104Z","sequence":180755012,"price":"9160.27","order_id":"3d4c5705-9b5a-42fc-a834-9350a075c87f","remaining_size":"0.0531"}
{"type":"heartbeat","last_trade_id":0,"product_id":"BTC-USD","sequence":180755012,"time":"2020-06-30T19:10:37.735111Z"}
{"type":"received","side":"buy","product_id":"BTC-USD","time":"2020-06-30T19:10:37.749867Z","sequence":180755013,"order_id":"5e9ad1e8-e871-4ca1-b2eb-06c599ea8af9","order_type":"limit","size":"0.0692","price":"9075.42","client_oid":""}
{"type":"open","side":"buy","product_id":"BTC-USD","time":"2020-06-30T19:10:37.749867Z","sequence":180755014,"price":"9075.42","order_id":"5e9ad1e8-e871-4ca1-b2eb-06c599ea8af9","remaining_size":"0.0692"}
{"type":"done","side":"buy","product_id":"BTC-USD","time":"2020-06-30T19:10:37.963009Z","sequence":180755015,"order_id":"1faa0846-a912-4f69-a13d-6a1b617ea964","reason":"canceled","price":"9082.54","remaining_size":"0.0395"}
{"type":"heartbeat","last_trade_id":0,"product_id":"BTC-USD","sequence":180755015,"time":"2020-06-30T19:10:38.735121Z"}
{"type":"heartbeat","last_trade_id":0,"product_id":"BTC-USD","sequence":180755015,"time":"2020-06-30T19:10:39.735121Z"}
{"type":"received","side":"buy","product_id":"BTC-USD","time":"2020-06-30T19:10:39.985551Z","sequence":180755016,"order_id":"e29fadb9-ef26-4b04-8474-3ffd325dc58a","order_type":"limit","size":"0.0777","price":"9084.17","client_oid":""}
{"type":"open","side":"buy","product_id":"BTC-USD","time":"2020-06-30T19:10:39.985551Z","sequence":180755017,"price":"9084.17","order_id":"e29fadb9-ef26-4b04-8474-3ffd325dc58a","remaining_size":"0.0777"}
{"type":"received","side":"sell","product_id":"BTC-USD","time":"2020-06-30T19:10:40.264902Z","sequence":180755018,"order_id":"c82155f5-4f7f-4372-9466-6863b7b9d8c2","order_type":"limit","size":"2","price":"9109.71","client_oid":""}
{"type":"match","side":"buy","product_id":"BTC-USD","time":"2020-06-30T19:10:40.264902Z","sequence":180755019,"trade_id":14587428,"maker_order_id":"91b59a7c-6a07-4039-9536-21daf3cb3282","taker_order_id":"c82155f5-4f7f-4372-9466-6863b7b9d8c2","size":"2","price":"9120.8"}
{"type":"done","side":"sell","product_id":"BTC-USD","time":"2020-06-30T19:10:40.264902Z","sequence":180755020,"order_id":"c82155f5-4f7f-4372-9466-6863b7b9d8c2","reason":"filled","price":"9109.71","remaining_size":"0"}
{"type":"received","side":"buy","product_id":"BTC-USD","time":"2020-06-30T19:10:40.524143Z","sequence":180755021,"order_id":"93459b48-facb-4a43-98ae-7d06b9b0324b","order_type":"limit","size":"0.0276","price":"9083.35","client_oid":""}
{"type":"open","side":"buy","product_id":"BTC-USD","time":"2020-06-30T19:10:40.524143Z","sequence":180755022,"price":"9083.35","order_id":"93459b48-facb-4a43-98ae-7d06b9b0324b","remaining_size":"0.0276"}
{"type":"done","side":"sell","product_id":"BTC-USD","time":"2020-06-30T19:10:40.700324Z","sequence":180755023,"order_id":"6b8eb102-c29f-4569-a2fd-3aff08439d24","reason":"canceled","price":"9131.21","remaining_size":"0.7632"}
{"type":"done","side":"buy","product_id":"BTC-USD","time":"2020-06-30T19:10:40.732615Z","sequence":180755024,"order_id":"5e9ad1e8-e871-4ca1-b2eb-06c599ea8af9","reason":"canceled","price":"9075.42","remaining_size":"0.0692"}
{"type":"heartbeat","last_trade_id":0,"product_id":"BTC-USD","sequence":180755024,"time":"2020-06-30T19:10:40.735074Z"}
{"type":"received","side":"buy","product_id":"BTC-USD","time":"2020-06-30T19:10:40.805340Z","sequence":180755025,"order_id":"edaa94a9-3d4d-465a-b48e-b3b9adefe9b1","order_type":"limit","size":"0.1064","price":"9081.7","client_oid":""}
{"type":"open","side":"buy","product_id":"BTC-USD","time":"2020-06-30T19:10:40.805340Z","sequence":180755026,"price":"9081.7","order_id":"edaa94a9-3d4d-465a-b48e-b3b9adefe9b1","remaining_size":"0.1064"}
{"type":"done","side":"buy","product_id":"BTC-USD","time":"2020-06-30T19:10:40.806564Z","sequence":180755027,"order_id":"8f2f876f-6a50-4d3c-9c8c-34d8dd712352","reason":"canceled","price":"9107.06","remaining_size":"0.015"}
{"type":"received","side":"buy","product_id":"BTC-USD","time":"2020-06-30T19:10:41.065112Z","sequence":180755028,"order_id":"60df62ed-f328-4dca-a233-a4286b8b4b27","order_type":"market","size":"0.001","funds":"9.12082","client_oid":""}
{"type":"match","side":"sell","product_id":"BTC-USD","time":"2020-06-30T19:10:41.065112Z","sequence":180755029,"trade_id":14587429,"maker_order_id":"36fe0734-4801-466d-b093-cccd411db09a","taker_order_id":"60df62ed-f328-4dca-a233-a4286b8b4b27","size":"0.001","price":"9120.82"}
{"type":"done","side":"buy","product_id":"BTC-USD","time":"2020-06-30T19:10:41.065112Z","sequence":180755030,"order_id":"60df62ed-f328-4dca-a233-a4286b8b4b27","reason":"filled","remaining_size":"0"}
{"type":"received","side":"sell","product_id":"BTC-USD","time":"2020-06-30T19:10:41.086812Z","sequence":180755031,"order_id":"3b622352-77bd-4273-bea5-0249614fe6ef","order_type":"limit","size":"1.5","price":"9108.44","client_oid":""}
{"type":"match","side":"buy","product_id":"BTC-USD","time":"2020-06-30T19:10:41.086812Z","sequence":180755032,"trade_id":14587430,"maker_order_id":"91b59a7c-6a07-4039-9536-21daf3cb3282","taker_order_id":"3b622352-77bd-4273-bea5-0249614fe6ef","size":"1.5","price":"9120.8"}
{"type":"done","side":"sell","product_id":"BTC-USD","time":"2020-06-30T19:10:41.086812Z","sequence":180755033,"order_id":"3b622352-77bd-4273-bea5-0249614fe6ef","reason":"filled","price":"9108.44","remaining_size":"0"}
{"type":"received","side":"buy","product_id":"BTC-USD","time":"2020-06-30T19:10:41.361459Z","sequence":180755034,"order_id":"d27193a2-a145-4dce-ac3f-c2677274ecf3","order_type":"limit","size":"0.0395","price":"9073.7","client_oid":""}
{"type":"open","side":"buy","product_id":"BTC-USD","time":"2020-06-30T19:10:41.361459Z","sequence":180755035,"price":"9073.7","order_id":"d27193a2-a145-4dce-ac3f-c2677274ecf3","remaining_size":"0.0395"}
{"type":"received","side":"buy","product_id":"BTC-USD","time":"2020-06-30T19:10:41.639607Z","sequence":180755036,"order_id":"c69cd951-63c1-4529-bcb1-b6c87565ffd1","order_type":"limit","size":"0.01","price":"9081.12","client_oid":""}
{"type":"open","side":"buy","product_id":"BTC-USD","time":"2020-06-30T19:10:41.639607Z","sequence":180755037,"price":"9081.12","order_id":"c69cd951-63c1-4529-bcb1-b6c87565ffd1","remaining_size":"0.01"}
{"type":"heartbeat","last_trade_id":0,"product_id":"BTC-USD","sequence":180755037,"time":"2020-06-30T19:10:41.735094Z"}
{"type":"done","side":"buy","product_id":"BTC-USD","time":"2020-06-30T19:10:42.066149Z","sequence":180755038,"order_id":"79ac9525-dc1a-4d9e-abe7-82eecae9b822","reason":"canceled","price":"9079.64","remaining_size":"0.0692"}
{"type":"received","side":"buy","product_id":"BTC-USD","time":"2020-06-30T19:10:42.248407Z","sequence":180755039,"order_id":"a9e836cc-311d-4b94-80b9-cefa14c43058","order_type":"limit","size":"0.0692","price":"9075.61","client_oid":""}
{"type":"open","side":"buy","product_id":"BTC-USD","time":"2020-06-30T19:10:42.248407Z","sequence":180755040,"price":"9075.61","order_id":"a9e836cc-311d-4b94-80b9-cefa14c43058","remaining_size":"0.0692"}
{"type":"received","side":"buy","product_id":"BTC-USD","time":"2020-06-30T19:10:42.540444Z","sequence":180755041,"order_id":"9059dda6-4dae-4f32-9940-14ba8f904b0d","order_type":"limit","size":"0.75","price":"9104.8","client_oid":""}
{"type":"open","side":"buy","product_id":"BTC-USD","time":"2020-06-30T19:10:42.540444Z","sequence":180755042,"price":"9104.8","order_id":"9059dda6-4dae-4f32-9940-14ba8f904b0d","remaining_size":"0.75"}
{"type":"done","side":"buy","product_id":"BTC-USD","time":"2020-06-30T19:10:42.675489Z","sequence":180755043,"order_id":"fe5e7e7f-fda2-4d76-b975-16f069d4fd5e","reason":"canceled","price":"9084.37","remaining_size":"0.0439"}
{"type":"heartbeat","last_trade_id":0,"product_id":"BTC-USD","sequence":180755043,"time":"2020-06-30T19:10:42.735118Z"}
{"type":"done","side":"buy","product_id":"BTC-USD","time":"2020-06-30T19:10:43.005349Z","sequence":180755044,"order_id":"d27193a2-a145-4dce-ac3f-c2677274ecf3","reason":"canceled","price":"9073.7","remaining_size":"0.0395"}
{"type":"heartbeat","last_trade_id":0,"product_id":"BTC-USD","sequence":180755044,"time":"2020-06-30T19:10:43.735118Z"}
{"type":"received","side":"sell","product_id":"BTC-USD","time":"2020-06-30T19:10:43.971768Z","sequence":180755045,"order_id":"71aa22dc-8a7a-426b-9ac0-5a53d46b970e","order_type":"limit","size":"0.1062","price":"9107.09","client_oid":""}
{"type":"match","side":"buy","product_id":"BTC-USD","time":"2020-06-30T19:10:43.971768Z","sequence":180755046,"trade_id":14587431,"maker_order_id":"91b59a7c-6a07-4039-9536-21daf3cb3282","taker_order_id":"71aa22dc-8a7a-426b-9ac0-5a53d46b970e","size":"0.1062","price":"9120.8"}
{"type":"done","side":"sell","product_id":"BTC-USD","time":"2020-06-30T19:10:43.971768Z","sequence":180755047,"order_id":"71aa22dc-8a7a-426b-9ac0-5a53d46b970e","reason":"filled","price":"9107.09","remaining_size":"0"}
{"type":"received","side":"buy","product_id":"BTC-USD","time":"2020-06-30T19:10:44.041557Z","sequence":180755048,"order_id":"5671d4bb-1959-4f60-8cad-041bf8905c84","order_type":"limit","size":"0.01","price":"100","client_oid":"f8026b14-9440-4548-94cd-3ef5c75205ca"}
{"type":"open","side":"buy","product_id":"BTC-USD","time":"2020-06-30T19:10:44.041557Z","sequence":180755049,"price":"100","order_id":"5671d4bb-1959-4f60-8cad-041bf8905c84","remaining_size":"0.01"}
{"type":"done","side":"buy","product_id":"BTC-USD","time":"2020-06-30T19:10:44.049095Z","sequence":180755050,"order_id":"5671d4bb-1959-4f60-8cad-041bf8905c84","reason":"canceled","price":"100","remaining_size":"0.01"}
{"type":"done","side":"sell","product_id":"BTC-USD","time":"2020-06-30T19:10:44.411176Z","sequence":180755051,"order_id":"f15097ae-f448-4caa-98a3-cb29795f85ed","reason":"canceled","price":"9161.71","remaining_size":"0.0352"}
{"type":"received","side":"buy","product_id":"BTC-USD","time":"2020-06-30T19:10:44.566797Z","sequence":180755052,"order_id":"9170732e-3a01-48b7-8ece-46dca9df1010","order_type":"limit","size":"3.1201","price":"9080","client_oid":""}
{"type":"open","side":"buy","product_id":"BTC-USD","time":"2020-06-30T19:10:44.566797Z","sequence":180755053,"price":"9080","order_id":"9170732e-3a01-48b7-8ece-46dca9df1010","remaining_size":"3.1201"}
{"type":"heartbeat","last_trade_id":0,"product_id":"BTC-USD","sequence":180755053,"time":"2020-06-30T19:10:44.735125Z"}
{"type":"received","side":"buy","product_id":"BTC-USD","time":"2020-06-30T19:10:45.701440Z","sequence":180755054,"order_id":"ddcd4301-4de5-4b32-b170-9050563c8ca8","order_type":"limit","size":"0.0235","price":"9081.15","client_oid":""}
{"type":"open","side":"buy","product_id":"BTC-USD","time":"2020-06-30T19:10:45.701440Z","sequence":180755055,"price":"9081.15","order_id":"ddcd4301-4de5-4b32-b170-9050563c8ca8","remaining_size":"0.0235"}
{"type":"heartbeat","last_trade_id":0,"product_id":"BTC-USD","sequence":180755055,"time":"2020-06-30T19:10:45.735119Z"}
{"type":"done","side":"buy","product_id":"BTC-USD","time":"2020-06-30T19:10:46.187585Z","sequence":180755056,"order_id":"c807f27a-e07f-447e-b3d7-26aa0665c25b","reason":"canceled","price":"9106.15","remaining_size":"0.25"}
{"type":"received","side":"buy","product_id":"BTC-USD","time":"2020-06-30T19:10:46.417362Z","sequence":180755057,"order_id":"3f175cef-d228-479c-960b-44408fa127f7","order_type":"limit","size":"0.0692","price":"9077.81","client_oid":""}
{"type":"open","side":"buy","product_id":"BTC-USD","time":"2020-06-30T19:10:46.417362Z","sequence":180755058,"price":"9077.81","order_id":"3f175cef-d228-479c-960b-44408fa127f7","remaining_size":"0.0692"}
{"type":"received","side":"sell","product_id":"BTC-USD","time":"2020-06-30T19:10:46.556729Z","sequence":180755059,"order_id":"95c6aaae-ffb0-4ccf-b415-ccc83304dfca","order_type":"limit","size":"0.0325","price":"9117.18","client_oid":""}
{"type":"match","side":"buy","product_id":"BTC-USD","time":"2020-06-30T19:10:46.556729Z","sequence":180755060,"trade_id":14587432,"maker_order_id":"91b59a7c-6a07-4039-9536-21daf3cb3282","taker_order_id":"95c6aaae-ffb0-4ccf-b415-ccc83304dfca","size":"0.0325","price":"9120.8"}
{"type":"done","side":"sell","product_id":"BTC-USD","time":"2020-06-30T19:10:46.556729Z","sequence":180755061,"order_id":"95c6aaae-ffb0-4ccf-b415-ccc83304dfca","reason":"filled","price":"9117.18","remaining_size":"0"}
{"type":"heartbeat","last_trade_id":0,"product_id":"BTC-USD","sequence":180755061,"time":"2020-06-30T19:10:46.735120Z"}
{"type":"received","side":"sell","product_id":"BTC-USD","time":"2020-06-30T19:10:47.116824Z","sequence":180755062,"order_id":"5fce12cd-4c04-4397-8f27-cb98842326a1","order_type":"limit","size":"1.0699","price":"9137.65","client_oid":""}
{"type":"open","side":"sell","product_id":"BTC-USD","time":"2020-06-30T19:10:47.116824Z","sequence":180755063,"price":"9137.65","order_id":"5fce12cd-4c04-4397-8f27-cb98842326a1","remaining_size":"1.0699"}
{"type":"received","side":"buy","product_id":"BTC-USD","time":"2020-06-30T19:10:47.429852Z","sequence":180755064,"order_id":"7f42d227-f1c1-417e-866a-1ad689818f32","order_type":"limit","size":"0.0235","price":"9075.46","client_oid":""}
{"type":"open","side":"buy","product_id":"BTC-USD","time":"2020-06-30T19:10:47.429852Z","sequence":180755065,"price":"9075.46","order_id":"7f42d227-f1c1-417e-866a-1ad689818f32","remaining_size":"0.0235"}
{"type":"done","side":"sell","product_id":"BTC-USD","time":"2020-06-30T19:10:47.534261Z","sequence":180755066,"order_id":"10c62d0b-4d9a-4c8f-8c4e-1c442701e63a","reason":"canceled","price":"9227.57","remaining_size":"0.001"}
{"type":"heartbeat","last_trade_id":0,"product_id":"BTC-USD","sequence":180755066,"time":"2020-06-30T19:10:47.735089Z"}
{"type":"received","side":"buy","product_id":"BTC-USD","time":"2020-06-30T19:10:47.976363Z","sequence":180755067,"order_id":"89002509-d03b-4464-b9c8-3c366c6c03a4","order_type":"limit","size":"0.0788","price":"9084.17","client_oid":""}
{"type":"open","side":"buy","product_id":"BTC-USD","time":"2020-06-30T19:10:47.976363Z","sequence":180755068,"price":"9084.17","order_id":"89002509-d03b-4464-b9c8-3c366c6c03a4","remaining_size":"0.0788"}
{"type":"received","side":"buy","product_id":"BTC-USD","time":"2020-06-30T19:10:48.251971Z","sequence":180755069,"order_id":"e9bd2446-5833-4ef7-bcbe-eb20542bce5f","order_type":"limit","size":"1.75","price":"9105.38","client_oid":""}
{"type":"open","side":"buy","product_id":"BTC-USD","time":"2020-06-30T19:10:48.251971Z","sequence":180755070,"price":"9105.38","order_id":"e9bd2446-5833-4ef7-bcbe-eb20542bce5f","remaining_size":"1.75"}
{"type":"done","side":"buy","product_id":"BTC-USD","time":"2020-06-30T19:10:48.697551Z","sequence":180755071,"order_id":"89002509-d03b-4464-b9c8-3c366c6c03a4","reason":"canceled","price":"9084.17","remaining_size":"0.0788"}
{"type":"heartbeat","last_trade_id":0,"product_id":"BTC-USD","sequence":180755071,"time":"2020-06-30T19:10:48.735126Z"}
{"type":"received","side":"sell","product_id":"BTC-USD","time":"2020-06-30T19:10:49.412240Z","sequence":180755072,"order_id":"a3296fc4-a57f-4462-b585-ae004041cd8f","order_type":"limit","size":"0.045","price":"9135.32","client_oid":""}
{"type":"open","side":"sell","product_id":"BTC-USD","time":"2020-06-30T19:10:49.412240Z","sequence":180755073,"price":"9135.32","order_id":"a3296fc4-a57f-4462-b585-ae004041cd8f","remaining_size":"0.045"}
{"type":"heartbeat","last_trade_id":0,"product_id":"BTC-USD","sequence":180755073,"time":"2020-06-30T19:10:49.735111Z"}
{"type":"received","side":"sell","product_id":"BTC-USD","time":"2020-06-30T19:10:50.274895Z","sequence":180755074,"order_id":"9711997a-9141-4bcf-96cd-6476779492d3","order_type":"limit","size":"0.0216","price":"9107.47","client_oid":""}
{"type":"match","side":"buy","product_id":"BTC-USD","time":"2020-06-30T19:10:50.274895Z","sequence":180755075,"trade_id":14587433,"maker_order_id":"91b59a7c-6a07-4039-9536-21daf3cb3282","taker_order_id":"9711997a-9141-4bcf-96cd-6476779492d3","size":"0.0216","price":"9120.8"}
{"type":"done","side":"sell","product_id":"BTC-USD","time":"2020-06-30T19:10:50.274895Z","sequence":180755076,"order_id":"9711997a-9141-4bcf-96cd-6476779492d3","reason":"filled","price":"9107.47","remaining_size":"0"}
{"type":"received","side":"buy","product_id":"BTC-USD","time":"2020-06-30T19:10:50.559904Z","sequence":180755077,"order_id":"31af8aa6-32a6-4878-982b-664527887794","order_type":"limit","size":"0.548","price":"9105.36","client_oid":""}
{"type":"open","side":"buy","product_id":"BTC-USD","time":"2020-06-30T19:10:50.559904Z","sequence":180755078,"price":"9105.36","order_id":"31af8aa6-32a6-4878-982b-664527887794","remaining_size":"0.548"}
{"type":"heartbeat","last_trade_id":0,"product_id":"BTC-USD","sequence":180755078,"time":"2020-06-30T19:10:50.735095Z"}
{"type":"done","side":"buy","product_id":"BTC-USD","time":"2020-06-30T19:10:51.006793Z","sequence":180755079,"order_id":"e29fadb9-ef26-4b04-8474-3ffd325dc58a","reason":"canceled","price":"9084.17","remaining_size":"0.0777"}
{"type":"done","side":"buy","product_id":"BTC-USD","time":"2020-06-30T19:10:51.008200Z","sequence":180755080,"order_id":"edaa94a9-3d4d-465a-b48e-b3b9adefe9b1","reason":"canceled","price":"9081.7","remaining_size":"0.1064"}
{"type":"heartbeat","last_trade_id":0,"product_id":"BTC-USD","sequence":180755080,"time":"2020-06-30T19:10:51.735114Z"}
{"type":"received","side":"buy","product_id":"BTC-USD","time":"2020-06-30T19:10:52.573038Z","sequence":180755081,"order_id":"82d015e7-a7be-4fa7-aba0-5f8216662c08","order_type":"limit","size":"0.8066","price":"9098.05","client_oid":""}
{"type":"open","side":"buy","product_id":"BTC-USD","time":"2020-06-30T19:10:52.573038Z","sequence":180755082,"price":"9098.05","order_id":"82d015e7-a7be-4fa7-aba0-5f8216662c08","remaining_size":"0.8066"}
{"type":"heartbeat","last_trade_id":0,"product_id":"BTC-USD","sequence":180755082,"time":"2020-06-30T19:10:52.735141Z"}
{"type":"done","side":"buy","product_id":"BTC-USD","time":"2020-06-30T19:10:52.987560Z","sequence":180755083,"order_id":"93459b48-facb-4a43-98ae-7d06b9b0324b","reason":"canceled","price":"9083.35","remaining_size":"0.0276"}
{"type":"heartbeat","last_trade_id":0,"product_id":"BTC-USD","sequence":180755083,"time":"2020-06-30T19:10:53.735110Z"}
{"type":"received","side":"sell","product_id":"BTC-USD","time":"2020-06-30T19:10:53.761490Z","sequence":180755084,"order_id":"2f3996c4-6d5c-48d4-b289-2cc7015e24fb","order_type":"limit","size":"0.069","price":"9160.01","client_oid":""}
{"type":"open","side":"sell","product_id":"BTC-USD","time":"2020-06-30T19:10:53.761490Z","sequence":180755085,"price":"9160.01","order_id":"2f3996c4-6d5c-48d4-b289-2cc7015e24fb","remaining_size":"0.069"}
{"type":"received","side":"buy","product_id":"BTC-USD","time":"2020-06-30T19:10:54.623411Z","sequence":180755086,"order_id":"9e273528-143d-46ec-a164-12ddad5a342f","order_type":"limit","size":"4.2169","price":"9107.06","client_oid":""}
{"type":"open","side":"buy","product_id":"BTC-USD","time":"2020-06-30T19:10:54.623411Z","sequence":180755087,"price":"9107.06","order_id":"9e273528-143d-46ec-a164-12ddad5a342f","remaining_size":"4.2169"}
{"type":"heartbeat","last_trade_id":0,"product_id":"BTC-USD","sequence":180755087,"time":"2020-06-30T19:10:54.735122Z"}
{"type":"done","side":"buy","product_id":"BTC-USD","time":"2020-06-30T19:10:55.062105Z","sequence":180755088,"order_id":"82d015e7-a7be-4fa7-aba0-5f8216662c08","reason":"canceled","price":"9098.05","remaining_size":"0.8066"}
{"type":"received","side":"sell","product_id":"BTC-USD","time":"2020-06-30T19:10:55.200688Z","sequence":180755089,"order_id":"aff2c3a7-ebc5-4edf-9680-86b0e4635bdc","order_type":"limit","size":"0.069","price":"9159.26","client_oid":""}
{"type":"open","side":"sell","product_id":"BTC-USD","time":"2020-06-30T19:10:55.200688Z","sequence":180755090,"price":"9159.26","order_id":"aff2c3a7-ebc5-4edf-9680-86b0e4635bdc","remaining_size":"0.069"}
{"type":"received","side":"buy","product_id":"BTC-USD","time":"2020-06-30T19:10:55.741559Z","sequence":180755091,"order_id":"eec24ff4-ed3b-45c6-9e68-8dfcc34d283a","order_type":"limit","size":"0.9","price":"9103.23","client_oid":""}
{"type":"open","side":"buy","product_id":"BTC-USD","time":"2020-06-30T19:10:55.741559Z","sequence":180755092,"price":"9103.23","order_id":"eec24ff4-ed3b-45c6-9e68-8dfcc34d283a","remaining_size":"0.9"}
{"type":"heartbeat","last_trade_id":0,"product_id":"BTC-USD","sequence":180755092,"time":"2020-06-30T19:10:55.735119Z"}
{"type":"done","side":"buy","product_id":"BTC-USD","time":"2020-06-30T19:10:56.190503Z","sequence":180755093,"order_id":"31af8aa6-32a6-4878-982b-664527887794","reason":"canceled","price":"9105.36","remaining_size":"0.548"}
{"type":"done","side":"buy","product_id":"BTC-USD","time":"2020-06-30T19:10:56.196396Z","sequence":180755094,"order_id":"7f42d227-f1c1-417e-866a-1ad689818f32","reason":"canceled","price":"9075.46","remaining_size":"0.0235"}
{"type":"done","side":"buy","product_id":"BTC-USD","time":"2020-06-30T19:10:56.203067Z","sequence":180755095,"order_id":"e9bd2446-5833-4ef7-bcbe-eb20542bce5f","reason":"canceled","price":"9105.38","remaining_size":"1.75"}
{"type":"received","side":"buy","product_id":"BTC-USD","time":"2020-06-30T19:10:56.273878Z","sequence":180755096,"order_id":"7f9e9d4d-3d88-436b-84a4-7c5a60f5a562","order_type":"limit","size":"0.25","price":"18240","client_oid":""}
{"type":"match","side":"sell","product_id":"BTC-USD","time":"2020-06-30T19:10:56.273878Z","sequence":180755097,"trade_id":14587434,"maker_order_id":"36fe0734-4801-466d-b093-cccd411db09a","taker_order_id":"7f9e9d4d-3d88-436b-84a4-7c5a60f5a562","size":"0.25","price":"9120.82"}
{"type":"done","side":"buy","product_id":"BTC-USD","time":"2020-06-30T19:10:56.273878Z","sequence":180755098,"order_id":"7f9e9d4d-3d88-436b-84a4-7c5a60f5a562","reason":"filled","price":"18240","remaining_size":"0"}
{"type":"received","side":"buy","product_id":"BTC-USD","time":"2020-06-30T19:10:56.567504Z","sequence":180755099,"order_id":"08278a03-0512-43e4-8ea7-6fa18c0c4d30","order_type":"limit","size":"0.0692","price":"9075.31","client_oid":""}
{"type":"open","side":"buy","product_id":"BTC-USD","time":"2020-06-30T19:10:56.567504Z","sequence":180755100,"price":"9075.31","order_id":"08278a03-0512-43e4-8ea7-6fa18c0c4d30","remaining_size":"0.0692"}
{"type":"heartbeat","last_trade_id":0,"product_id":"BTC-USD","sequence":180755100,"time":"2020-06-30T19:10:56.735032Z"}
{"type":"received","side":"buy","product_id":"BTC-USD","time":"2020-06-30T19:10:56.897490Z","sequence":180755101,"order_id":"513265f1-3d3e-476d-b7f7-cff48692e2ad","order_type":"limit","size":"0.01","price":"9083.58","client_oid":""}
{"type":"open","side":"buy","product_id":"BTC-USD","time":"2020-06-30T19:10:56.897490Z","sequence":180755102,"price":"9083.58","order_id":"513265f1-3d3e-476d-b7f7-cff48692e2ad","remaining_size":"0.01"}
{"type":"done","side":"buy","product_id":"BTC-USD","time":"2020-06-30T19:10:57.106648Z","sequence":180755103,"order_id":"ddcd4301-4de5-4b32-b170-9050563c8ca8","reason":"canceled","price":"9081.15","remaining_size":"0.0235"}
{"type":"received","side":"sell","product_id":"BTC-USD","time":"2020-06-30T19:10:57.168103Z","sequence":180755104,"order_id":"cd9954c8-d578-415b-8aa2-44384b16f639","order_type":"limit","size":"1.643","price":"9108.18","client_oid":""}
{"type":"match","side":"buy","product_id":"BTC-USD","time":"2020-06-30T19:10:57.168103Z","sequence":180755105,"trade_id":14587435,"maker_order_id":"91b59a7c-6a07-4039-9536-21daf3cb3282","taker_order_id":"cd9954c8-d578-415b-8aa2-44384b16f639","size":"1.643","price":"9120.8"}
{"type":"done","side":"sell","product_id":"BTC-USD","time":"2020-06-30T19:10:57.168103Z","sequence":180755106,"order_id":"cd9954c8-d578-415b-8aa2-44384b16f639","reason":"filled","price":"9108.18","remaining_size":"0"}
{"type":"received","side":"buy","product_id":"BTC-USD","time":"2020-06-30T19:10:57.445699Z","sequence":180755107,"order_id":"61819a02-1e76-4b24-a338-a0971b7ca90f","order_type":"limit","size":"0.01","price":"9086.05","client_oid":""}
{"type":"open","side":"buy","product_id":"BTC-USD","time":"2020-06-30T19:10:57.445699Z","sequence":180755108,"price":"9086.05","order_id":"61819a02-1e76-4b24-a338-a0971b7ca90f","remaining_size":"0.01"}
{"type":"received","side":"sell","product_id":"BTC-USD","time":"2020-06-30T19:10:57.742154Z","sequence":180755109,"order_id":"8400a26d-9434-4887-bd08-f852ac6c6e88","order_type":"limit","size":"0.0616","price":"9153.3","client_oid":""}
{"type":"open","side":"sell","product_id":"BTC-USD","time":"2020-06-30T19:10:57.742154Z","sequence":180755110,"price":"9153.3","order_id":"8400a26d-9434-4887-bd08-f852ac6c6e88","remaining_size":"0.0616"}
{"type":"heartbeat","last_trade_id":0,"product_id":"BTC-USD","sequence":180755110,"time":"2020-06-30T19:10:57.735103Z"}
{"type":"done","side":"sell","product_id":"BTC-USD","time":"2020-06-30T19:10:57.759858Z","sequence":180755111,"order_id":"e5140f0e-20c9-4271-b231-e62f819f4e24","reason":"canceled","price":"9136.14","remaining_size":"0.0469"}
{"type":"received","side":"buy","product_id":"BTC-USD","time":"2020-06-30T19:10:58.002843Z","sequence":180755112,"order_id":"04702502-8db9-4dd1-a964-c02eae8adfdd","order_type":"limit","size":"0.0368","price":"9077.41","client_oid":""}
{"type":"open","side":"buy","product_id":"BTC-USD","time":"2020-06-30T19:10:58.002843Z","sequence":180755113,"price":"9077.41","order_id":"04702502-8db9-4dd1-a964-c02eae8adfdd","remaining_size":"0.0368"}
{"type":"done","side":"sell","product_id":"BTC-USD","time":"2020-06-30T19:10:58.180971Z","sequence":180755114,"order_id":"ecb1243e-9a02-4d80-9390-d5c22438c44c","reason":"canceled","price":"9142.68","remaining_size":"0.0547"}
{"type":"heartbeat","last_trade_id":0,"product_id":"BTC-USD","sequence":180755114,"time":"2020-06-30T19:10:58.735112Z"}
{"type":"done","side":"buy","product_id":"BTC-USD","time":"2020-06-30T19:10:59.000541Z","sequence":180755115,"order_id":"4b2ea96d-7179-4b0c-95e6-d94dda29f68b","reason":"canceled","price":"8896.47","remaining_size":"0.04613699"}
{"type":"received","side":"buy","product_id":"BTC-USD","time":"2020-06-30T19:10:59.080840Z","sequence":180755116,"order_id":"2c8002ac-e3a1-434c-a063-88bb96d94e4a","order_type":"limit","size":"0.01","price":"100","client_oid":"ebc07103-a193-4aaa-9e23-5993dbf42a27"}
{"type":"open","side":"buy","product_id":"BTC-USD","time":"2020-06-30T19:10:59.080840Z","sequence":180755117,"price":"100","order_id":"2c8002ac-e3a1-434c-a063-88bb96d94e4a","remaining_size":"0.01"}
{"type":"done","side":"buy","product_id":"BTC-USD","time":"2020-06-30T19:10:59.087293Z","sequence":180755118,"order_id":"2c8002ac-e3a1-434c-a063-88bb96d94e4a","reason":"canceled","price":"100","remaining_size":"0.01"}
{"type":"received","side":"buy","product_id":"BTC-USD","time":"2020-06-30T19:10:59.113413Z","sequence":180755119,"order_id":"a98319ed-473d-49bd-ac06-1d9bfa087039","order_type":"limit","size":"0.0395","price":"9072.38","client_oid":""}
{"type":"open","side":"buy","product_id":"BTC-USD","time":"2020-06-30T19:10:59.113413Z","sequence":180755120,"price":"9072.38","order_id":"a98319ed-473d-49bd-ac06-1d9bfa087039","remaining_size":"0.0395"}
{"type":"received","side":"buy","product_id":"BTC-USD","time":"2020-06-30T19:10:59.215670Z","sequence":180755121,"order_id":"e790b7fa-354c-48f6-bff7-3f77d0b031d0","order_type":"limit","size":"0.04623953","price":"8895.64","client_oid":""}
{"type":"open","side":"buy","product_id":"BTC-USD","time":"2020-06-30T19:10:59.215670Z","sequence":180755122,"price":"8895.64","order_id":"e790b7fa-354c-48f6-bff7-3f77d0b031d0","remaining_size":"0.04623953"}
{"type":"received","side":"buy","product_id":"BTC-USD","time":"2020-06-30T19:10:59.386464Z","sequence":180755123,"order_id":"4c330e27-d76a-411c-af39-3d29eb2f7cf8","order_type":"limit","size":"0.0692","price":"9072.93","client_oid":""}
{"type":"open","side":"buy","product_id":"BTC-USD","time":"2020-06-30T19:10:59.386464Z","sequence":180755124,"price":"9072.93","order_id":"4c330e27-d76a-411c-af39-3d29eb2f7cf8","remaining_size":"0.0692"}
{"type":"done","side":"sell","product_id":"BTC-USD","time":"2020-06-30T19:10:59.430554Z","sequence":180755125,"order_id":"f2f880b9-811b-4f53-b97a-889a3e8a531a","reason":"canceled","price":"9434.33","remaining_size":"0.00688998"}
{"type":"done","side":"buy","product_id":"BTC-USD","time":"2020-06-30T19:10:59.588796Z","sequence":180755126,"order_id":"a98319ed-473d-49bd-ac06-1d9bfa087039","reason":"canceled","price":"9072.38","remaining_size":"0.0395"}
{"type":"done","side":"buy","product_id":"BTC-USD","time":"2020-06-30T19:10:59.594853Z","sequence":180755127,"order_id":"08278a03-0512-43e4-8ea7-6fa18c0c4d30","reason":"canceled","price":"9075.31","remaining_size":"0.0692"}
{"type":"received","side":"sell","product_id":"BTC-USD","time":"2020-06-30T19:10:59.652285Z","sequence":180755128,"order_id":"6a7fe453-7199-4584-ac02-d22747a1736b","order_type":"limit","size":"0.00699029","price":"9435.21","client_oid":""}
{"type":"open","side":"sell","product_id":"BTC-USD","time":"2020-06-30T19:10:59.652285Z","sequence":180755129,"price":"9435.21","order_id":"6a7fe453-7199-4584-ac02-d22747a1736b","remaining_size":"0.00699029"}
{"type":"done","side":"buy","product_id":"BTC-USD","time":"2020-06-30T19:10:59.691165Z","sequence":180755130,"order_id":"9170732e-3a01-48b7-8ece-46dca9df1010","reason":"canceled","price":"9080","remaining_size":"3.1201"}
{"type":"heartbeat","last_trade_id":0,"product_id":"BTC-USD","sequence":180755130,"time":"2020-06-30T19:10:59.735121Z"}
{"type":"received","side":"sell","product_id":"BTC-USD","time":"2020-06-30T19:11:00.253142Z","sequence":180755131,"order_id":"a3b00cb7-775b-4741-8857-d91bd326f4e9","order_type":"limit","size":"0.069","price":"9159.17","client_oid":""}
{"type":"open","side":"sell","product_id":"BTC-USD","time":"2020-06-30T19:11:00.253142Z","sequence":180755132,"price":"9159.17","order_id":"a3b00cb7-775b-4741-8857-d91bd326f4e9","remaining_size":"0.069"}
{"type":"received","side":"sell","product_id":"BTC-USD","time":"2020-06-30T19:11:00.508097Z","sequence":180755133,"order_id":"2dd3c125-61ba-4552-ad57-d4f32badb1a3","order_type":"limit","size":"0.25","price":"4560","client_oid":""}
{"type":"match","side":"buy","product_id":"BTC-USD","time":"2020-06-30T19:11:00.508097Z","sequence":180755134,"trade_id":14587436,"maker_order_id":"91b59a7c-6a07-4039-9536-21daf3cb3282","taker_order_id":"2dd3c125-61ba-4552-ad57-d4f32badb1a3","size":"0.25","price":"9120.8"}
{"type":"done","side":"sell","product_id":"BTC-USD","time":"2020-06-30T19:11:00.508097Z","sequence":180755135,"order_id":"2dd3c125-61ba-4552-ad57-d4f32badb1a3","reason":"filled","price":"4560","remaining_size":"0"}
{"type":"done","side":"sell","product_id":"BTC-USD","time":"2020-06-30T19:11:00.705015Z","sequence":180755136,"order_id":"8400a26d-9434-4887-bd08-f852ac6c6e88","reason":"canceled","price":"9153.3","remaining_size":"0.0616"}
{"type":"done","side":"sell","product_id":"BTC-USD","time":"2020-06-30T19:11:00.709310Z","sequence":180755137,"order_id":"a3296fc4-a57f-4462-b585-ae004041cd8f","reason":"canceled","price":"9135.32","remaining_size":"0.045"}
{"type":"heartbeat","last_trade_id":0,"product_id":"BTC-USD","sequence":180755137,"time":"2020-06-30T19:11:00.735124Z"}
{"type":"heartbeat","last_trade_id":0,"product_id":"BTC-USD","sequence":180755137,"time":"2020-06-30T19:11:01.735115Z"}
{"type":"received","side":"buy","product_id":"BTC-USD","time":"2020-06-30T19:11:02.707085Z","sequence":180755138,"order_id":"a5cad29d-d7e2-4e33-9527-2ff9ad520307","order_type":"limit","size":"0.0692","price":"9078.98","client_oid":""}
{"type":"open","side":"buy","product_id":"BTC-USD","time":"2020-06-30T19:11:02.707085Z","sequence":180755139,"price":"9078.98","order_id":"a5cad29d-d7e2-4e33-9527-2ff9ad520307","remaining_size":"0.0692"}
{"type":"heartbeat","last_trade_id":0,"product_id":"BTC-USD","sequence":180755139,"time":"2020-06-30T19:11:02.735112Z"}
{"type":"done","side":"buy","product_id":"BTC-USD","time":"2020-06-30T19:11:03.102343Z","sequence":180755140,"order_id":"513265f1-3d3e-476d-b7f7-cff48692e2ad","reason":"canceled","price":"9083.58","remaining_size":"0.01"}
{"type":"received","side":"sell","product_id":"BTC-USD","time":"2020-06-30T19:11:03.214113Z","sequence":180755141,"order_id":"40a85277-469a-44bf-9d24-51136bf47df7","order_type":"limit","size":"0.002","price":"9170.81","client_oid":""}
{"type":"open","side":"sell","product_id":"BTC-USD","time":"2020-06-30T19:11:03.214113Z","sequence":180755142,"price":"9170.81","order_id":"40a85277-469a-44bf-9d24-51136bf47df7","remaining_size":"0.002"}
{"type":"received","side":"sell","product_id":"BTC-USD","time":"2020-06-30T19:11:03.701089Z","sequence":180755143,"order_id":"4fc00af0-3cf0-4f80-8ac3-ce638fe19c6e","order_type":"limit","size":"0.05","price":"9106.87","client_oid":""}
{"type":"match","side":"buy","product_id":"BTC-USD","time":"2020-06-30T19:11:03.701089Z","sequence":180755144,"trade_id":14587437,"maker_order_id":"91b59a7c-6a07-4039-9536-21daf3cb3282","taker_order_id":"4fc00af0-3cf0-4f80-8ac3-ce638fe19c6e","size":"0.05","price":"9120.8"}
{"type":"done","side":"sell","product_id":"BTC-USD","time":"2020-06-30T19:11:03.701089Z","sequence":180755145,"order_id":"4fc00af0-3cf0-4f80-8ac3-ce638fe19c6e","reason":"filled","price":"9106.87","remaining_size":"0"}
{"type":"heartbeat","last_trade_id":0,"product_id":"BTC-USD","sequence":180755145,"time":"2020-06-30T19:11:03.735116Z"}
{"type":"done","side":"sell","product_id":"BTC-USD","time":"2020-06-30T19:11:03.779590Z","sequence":180755146,"order_id":"2f3996c4-6d5c-48d4-b289-2cc7015e24fb","reason":"canceled","price":"9160.01","remaining_size":"0.069"}
{"type":"received","side":"buy","product_id":"BTC-USD","time":"2020-06-30T19:11:04.237729Z","sequence":180755147,"order_id":"fdfc8b6a-a0ce-4a5e-87c2-6aaf2837e518","order_type":"limit","size":"0.0692","price":"9073.15","client_oid":""}
{"type":"open","side":"buy","product_id":"BTC-USD","time":"2020-06-30T19:11:04.237729Z","sequence":180755148,"price":"9073.15","order_id":"fdfc8b6a-a0ce-4a5e-87c2-6aaf2837e518","remaining_size":"0.0692"}
{"type":"received","side":"sell","product_id":"BTC-USD","time":"2020-06-30T19:11:04.537931Z","sequence":180755149,"order_id":"9797d3f4-c902-4d39-92e4-63d41547d233","order_type":"limit","size":"0.0659","price":"9106.63","client_oid":""}
{"type":"match","side":"buy","product_id":"BTC-USD","time":"2020-06-30T19:11:04.537931Z","sequence":180755150,"trade_id":14587438,"maker_order_id":"91b59a7c-6a07-4039-9536-21daf3cb3282","taker_order_id":"9797d3f4-c902-4d39-92e4-63d41547d233","size":"0.0659","price":"9120.8"}
{"type":"done","side":"sell","product_id":"BTC-USD","time":"2020-06-30T19:11:04.537931Z","sequence":180755151,"order_id":"9797d3f4-c902-4d39-92e4-63d41547d233","reason":"filled","price":"9106.63","remaining_size":"0"}
{"type":"done","side":"buy","product_id":"BTC-USD","time":"2020-06-30T19:11:04.688158Z","sequence":180755152,"order_id":"61819a02-1e76-4b24-a338-a0971b7ca90f","reason":"canceled","price":"9086.05","remaining_size":"0.01"}
{"type":"received","side":"buy","product_id":"BTC-USD","time":"2020-06-30T19:11:04.740338Z","sequence":180755153,"order_id":"38cbb6c2-c778-4de0-810a-86bc21c90038","order_type":"limit","size":"0.25","price":"18240","client_oid":""}
{"type":"match","side":"sell","product_id":"BTC-USD","time":"2020-06-30T19:11:04.740338Z","sequence":180755154,"trade_id":14587439,"maker_order_id":"36fe0734-4801-466d-b093-cccd411db09a","taker_order_id":"38cbb6c2-c778-4de0-810a-86bc21c90038","size":"0.25","price":"9120.82"}
{"type":"done","side":"buy","product_id":"BTC-USD","time":"2020-06-30T19:11:04.740338Z","sequence":180755155,"order_id":"38cbb6c2-c778-4de0-810a-86bc21c90038","reason":"filled","price":"18240","remaining_size":"0"}
{"type":"heartbeat","last_trade_id":0,"product_id":"BTC-USD","sequence":180755155,"time":"2020-06-30T19:11:04.735116Z"}
{"type":"done","side":"sell","product_id":"BTC-USD","time":"2020-06-30T19:11:04.970237Z","sequence":180755156,"order_id":"a3b00cb7-775b-4741-8857-d91bd326f4e9","reason":"canceled","price":"9159.17","remaining_size":"0.069"}
{"type":"received","side":"buy","product_id":"BTC-USD","time":"2020-06-30T19:11:05.076867Z","sequence":180755157,"order_id":"960a9aa2-29ce-447a-83b8-4b86e959604e","order_type":"limit","size":"0.0235","price":"9074.53","client_oid":""}
{"type":"open","side":"buy","product_id":"BTC-USD","time":"2020-06-30T19:11:05.076867Z","sequence":180755158,"price":"9074.53","order_id":"960a9aa2-29ce-447a-83b8-4b86e959604e","remaining_size":"0.0235"}
{"type":"received","side":"sell","product_id":"BTC-USD","time":"2020-06-30T19:11:05.355046Z","sequence":180755159,"order_id":"120309a6-8449-41a6-ad38-c6f19c19ee58","order_type":"limit","size":"1.3689","price":"9108.86","client_oid":""}
{"type":"match","side":"buy","product_id":"BTC-USD","time":"2020-06-30T19:11:05.355046Z","sequence":180755160,"trade_id":14587440,"maker_order_id":"91b59a7c-6a07-4039-9536-21daf3cb3282","taker_order_id":"120309a6-8449-41a6-ad38-c6f19c19ee58","size":"1.3689","price":"9120.8"}
{"type":"done","side":"sell","product_id":"BTC-USD","time":"2020-06-30T19:11:05.355046Z","sequence":180755161,"order_id":"120309a6-8449-41a6-ad38-c6f19c19ee58","reason":"filled","price":"9108.86","remaining_size":"0"}
{"type":"received","side":"buy","product_id":"BTC-USD","time":"2020-06-30T19:11:05.627038Z","sequence":180755162,"order_id":"5eabc5e9-ba53-443e-b0be-6d1e48a2d832","order_type":"limit","size":"0.0967","price":"9075.63","client_oid":""}
{"type":"open","side":"buy","product_id":"BTC-USD","time":"2020-06-30T19:11:05.627038Z","sequence":180755163,"price":"9075.63","order_id":"5eabc5e9-ba53-443e-b0be-6d1e48a2d832","remaining_size":"0.0967"}
{"type":"heartbeat","last_trade_id":0,"product_id":"BTC-USD","sequence":180755163,"time":"2020-06-30T19:11:05.735117Z"}
{"type":"done","side":"buy","product_id":"BTC-USD","time":"2020-06-30T19:11:06.133029Z","sequence":180755164,"order_id":"9059dda6-4dae-4f32-9940-14ba8f904b0d","reason":"canceled","price":"9104.8","remaining_size":"0.75"}
{"type":"done","side":"buy","product_id":"BTC-USD","time":"2020-06-30T19:11:06.142747Z","sequence":180755165,"order_id":"04702502-8db9-4dd1-a964-c02eae8adfdd","reason":"canceled","price":"9077.41","remaining_size":"0.0368"}
{"type":"received","side":"buy","product_id":"BTC-USD","time":"2020-06-30T19:11:06.210842Z","sequence":180755166,"order_id":"48c19729-3fe1-4302-a641-20074f05e75a","order_type":"limit","size":"1.296","price":"9102.84","client_oid":""}
{"type":"open","side":"buy","product_id":"BTC-USD","time":"2020-06-30T19:11:06.210842Z","sequence":180755167,"price":"9102.84","order_id":"48c19729-3fe1-4302-a641-20074f05e75a","remaining_size":"1.296"}
{"type":"done","side":"buy","product_id":"BTC-USD","time":"2020-06-30T19:11:06.633046Z","sequence":180755168,"order_id":"4c330e27-d76a-411c-af39-3d29eb2f7cf8","reason":"canceled","price":"9072.93","remaining_size":"0.0692"}
{"type":"heartbeat","last_trade_id":0,"product_id":"BTC-USD","sequence":180755168,"time":"2020-06-30T19:11:06.735110Z"}
{"type":"heartbeat","last_trade_id":0,"product_id":"BTC-USD","sequence":180755168,"time":"2020-06-30T19:11:07.735054Z"}
{"type":"received","side":"sell","product_id":"BTC-USD","time":"2020-06-30T19:11:07.928850Z","sequence":180755169,"order_id":"0bc0af4e-e709-439a-a451-905430a8ec92","order_type":"limit","size":"0.8186","price":"9111.4","client_oid":""}
{"type":"match","side":"buy","product_id":"BTC-USD","time":"2020-06-30T19:11:07.928850Z","sequence":180755170,"trade_id":14587441,"maker_order_id":"91b59a7c-6a07-4039-9536-21daf3cb3282","taker_order_id":"0bc0af4e-e709-439a-a451-905430a8ec92","size":"0.8186","price":"9120.8"}
{"type":"done","side":"sell","product_id":"BTC-USD","time":"2020-06-30T19:11:07.928850Z","sequence":180755171,"order_id":"0bc0af4e-e709-439a-a451-905430a8ec92","reason":"filled","price":"9111.4","remaining_size":"0"}
{"type":"heartbeat","last_trade_id":0,"product_id":"BTC-USD","sequence":180755171,"time":"2020-06-30T19:11:08.735114Z"}
{"type":"received","side":"buy","product_id":"BTC-USD","time":"2020-06-30T19:11:09.004676Z","sequence":180755172,"order_id":"97574299-7ed2-4d5e-82cd-48abf49b1e06","order_type":"limit","size":"0.0692","price":"9072.54","client_oid":""}
{"type":"open","side":"buy","product_id":"BTC-USD","time":"2020-06-30T19:11:09.004676Z","sequence":180755173,"price":"9072.54","order_id":"97574299-7ed2-4d5e-82cd-48abf49b1e06","remaining_size":"0.0692"}
{"type":"received","side":"sell","product_id":"BTC-USD","time":"2020-06-30T19:11:09.028744Z","sequence":180755174,"order_id":"fa213ae1-9c44-47dd-b801-894401cf5d75","order_type":"limit","size":"0.25","price":"4560","client_oid":""}
{"type":"match","side":"buy","product_id":"BTC-USD","time":"2020-06-30T19:11:09.028744Z","sequence":180755175,"trade_id":14587442,"maker_order_id":"91b59a7c-6a07-4039-9536-21daf3cb3282","taker_order_id":"fa213ae1-9c44-47dd-b801-894401cf5d75","size":"0.25","price":"9120.8"}
{"type":"done","side":"sell","product_id":"BTC-USD","time":"2020-06-30T19:11:09.028744Z","sequence":180755176,"order_id":"fa213ae1-9c44-47dd-b801-894401cf5d75","reason":"filled","price":"4560","remaining_size":"0"}
{"type":"done","side":"buy","product_id":"BTC-USD","time":"2020-06-30T19:11:09.432742Z","sequence":180755177,"order_id":"a9e836cc-311d-4b94-80b9-cefa14c43058","reason":"canceled","price":"9075.61","remaining_size":"0.0692"}
{"type":"received","side":"buy","product_id":"BTC-USD","time":"2020-06-30T19:11:09.551144Z","sequence":180755178,"order_id":"160b1d3c-b694-44ba-8098-17aa824172bf","order_type":"limit","size":"0.003","price":"8906.87","client_oid":""}
{"type":"open","side":"buy","product_id":"BTC-USD","time":"2020-06-30T19:11:09.551144Z","sequence":180755179,"price":"8906.87","order_id":"160b1d3c-b694-44ba-8098-17aa824172bf","remaining_size":"0.003"}
{"type":"heartbeat","last_trade_id":0,"product_id":"BTC-USD","sequence":180755179,"time":"2020-06-30T19:11:09.735121Z"}
{"type":"received","side":"sell","product_id":"BTC-USD","time":"2020-06-30T19:11:09.817004Z","sequence":180755180,"order_id":"5e9ae696-1731-486c-8dc9-affdae966a6d","order_type":"limit","size":"0.001","price":"9160.07","client_oid":""}
{"type":"open","side":"sell","product_id":"BTC-USD","time":"2020-06-30T19:11:09.817004Z","sequence":180755181,"price":"9160.07","order_id":"5e9ae696-1731-486c-8dc9-affdae966a6d","remaining_size":"0.001"}
{"type":"done","side":"buy","product_id":"BTC-USD","time":"2020-06-30T19:11:10.016038Z","sequence":180755182,"order_id":"5eabc5e9-ba53-443e-b0be-6d1e48a2d832","reason":"canceled","price":"9075.63","remaining_size":"0.0967"}
{"type":"received","side":"buy","product_id":"BTC-USD","time":"2020-06-30T19:11:10.101412Z","sequence":180755183,"order_id":"1dfebde3-f4d9-483e-ac61-b04f376f4479","order_type":"limit","size":"0.0967","price":"9075.15","client_oid":""}
{"type":"open","side":"buy","product_id":"BTC-USD","time":"2020-06-30T19:11:10.101412Z","sequence":180755184,"price":"9075.15","order_id":"1dfebde3-f4d9-483e-ac61-b04f376f4479","remaining_size":"0.0967"}
{"type":"received","side":"sell","product_id":"BTC-USD","time":"2020-06-30T19:11:10.384836Z","sequence":180755185,"order_id":"8998b82d-9b99-4275-94fa-5d0cd4476e64","order_type":"limit","size":"0.069","price":"9158.32","client_oid":""}
{"type":"open","side":"sell","product_id":"BTC-USD","time":"2020-06-30T19:11:10.384836Z","sequence":180755186,"price":"9158.32","order_id":"8998b82d-9b99-4275-94fa-5d0cd4476e64","remaining_size":"0.069"}
{"type":"done","side":"buy","product_id":"BTC-USD","time":"2020-06-30T19:11:10.535371Z","sequence":180755187,"order_id":"160b1d3c-b694-44ba-8098-17aa824172bf","reason":"canceled","price":"8906.87","remaining_size":"0.003"}
{"type":"heartbeat","last_trade_id":0,"product_id":"BTC-USD","sequence":180755187,"time":"2020-06-30T19:11:10.735120Z"}
{"type":"received","side":"sell","product_id":"BTC-USD","time":"2020-06-30T19:11:10.926110Z","sequence":180755188,"order_id":"690af1ec-ac84-45d5-8d7a-3bfbf0ef2133","order_type":"limit","size":"0.069","price":"9158.3","client_oid":""}
{"type":"open","side":"sell","product_id":"BTC-USD","time":"2020-06-30T19:11:10.926110Z","sequence":180755189,"price":"9158.3","order_id":"690af1ec-ac84-45d5-8d7a-3bfbf0ef2133","remaining_size":"0.069"}
{"type":"received","side":"sell","product_id":"BTC-USD","time":"2020-06-30T19:11:11.087014Z","sequence":180755190,"order_id":"916fd07e-ccb5-481a-81d2-545ec1bae364","order_type":"market","size":"0.001","funds":"9.1208","client_oid":""}
{"type":"match","side":"buy","product_id":"BTC-USD","time":"2020-06-30T19:11:11.087014Z","sequence":180755191,"trade_id":14587443,"maker_order_id":"91b59a7c-6a07-4039-9536-21daf3cb3282","taker_order_id":"916fd07e-ccb5-481a-81d2-545ec1bae364","size":"0.001","price":"9120.8"}
{"type":"done","side":"sell","product_id":"BTC-USD","time":"2020-06-30T19:11:11.087014Z","sequence":180755192,"order_id":"916fd07e-ccb5-481a-81d2-545ec1bae364","reason":"filled","remaining_size":"0"}
{"type":"done","side":"sell","product_id":"BTC-USD","time":"2020-06-30T19:11:11.372337Z","sequence":180755193,"order_id":"40a85277-469a-44bf-9d24-51136bf47df7","reason":"canceled","price":"9170.81","remaining_size":"0.002"}
{"type":"received","side":"buy","product_id":"BTC-USD","time":"2020-06-30T19:11:11.504339Z","sequence":180755194,"order_id":"7cf2e5b4-2af3-49fe-8409-da1d949ebe5e","order_type":"limit","size":"0.05","price":"9105.08","client_oid":""}
{"type":"open","side":"buy","product_id":"BTC-USD","time":"2020-06-30T19:11:11.504339Z","sequence":180755195,"price":"9105.08","order_id":"7cf2e5b4-2af3-49fe-8409-da1d949ebe5e","remaining_size":"0.05"}
{"type":"heartbeat","last_trade_id":0,"product_id":"BTC-USD","sequence":180755195,"time":"2020-06-30T19:11:11.735119Z"}
{"type":"received","side":"buy","product_id":"BTC-USD","time":"2020-06-30T19:11:12.078992Z","sequence":180755196,"order_id":"d7a84894-769d-47b1-b560-27b21aa0ce1d","order_type":"limit","size":"0.05","price":"9105.59","client_oid":""}
{"type":"open","side":"buy","product_id":"BTC-USD","time":"2020-06-30T19:11:12.078992Z","sequence":180755197,"price":"9105.59","order_id":"d7a84894-769d-47b1-b560-27b21aa0ce1d","remaining_size":"0.05"}
{"type":"received","side":"sell","product_id":"BTC-USD","time":"2020-06-30T19:11:12.327349Z","sequence":180755198,"order_id":"b26e158f-0327-4856-96db-50a3c3c5080a","order_type":"limit","size":"0.06","price":"9106.39","client_oid":""}
{"type":"match","side":"buy","product_id":"BTC-USD","time":"2020-06-30T19:11:12.327349Z","sequence":180755199,"trade_id":14587444,"maker_order_id":"91b59a7c-6a07-4039-9536-21daf3cb3282","taker_order_id":"b26e158f-0327-4856-96db-50a3c3c5080a","size":"0.06","price":"9120.8"}
{"type":"done","side":"sell","product_id":"BTC-USD","time":"2020-06-30T19:11:12.327349Z","sequence":180755200,"order_id":"b26e158f-0327-4856-96db-50a3c3c5080a","reason":"filled","price":"9106.39","remaining_size":"0"}
{"type":"done","side":"buy","product_id":"BTC-USD","time":"2020-06-30T19:11:12.526986Z","sequence":180755201,"order_id":"9e273528-143d-46ec-a164-12ddad5a342f","reason":"canceled","price":"9107.06","remaining_size":"4.2169"}
{"type":"heartbeat","last_trade_id":0,"product_id":"BTC-USD","sequence":180755201,"time":"2020-06-30T19:11:12.735117Z"}
{"type":"done","side":"sell","product_id":"BTC-USD","time":"2020-06-30T19:11:12.793837Z","sequence":180755202,"order_id":"8998b82d-9b99-4275-94fa-5d0cd4476e64","reason":"canceled","price":"9158.32","remaining_size":"0.069"}
{"type":"received","side":"sell","product_id":"BTC-USD","time":"2020-06-30T19:11:12.924171Z","sequence":180755203,"order_id":"fbbae574-8a05-4dde-9565-8b11c47ac99c","order_type":"limit","size":"0.2489","price":"9106.39","client_oid":""}
{"type":"match","side":"buy","product_id":"BTC-USD","time":"2020-06-30T19:11:12.924171Z","sequence":180755204,"trade_id":14587445,"maker_order_id":"91b59a7c-6a07-4039-9536-21daf3cb3282","taker_order_id":"fbbae574-8a05-4dde-9565-8b11c47ac99c","size":"0.2489","price":"9120.8"}
{"type":"done","side":"sell","product_id":"BTC-USD","time":"2020-06-30T19:11:12.924171Z","sequence":180755205,"order_id":"fbbae574-8a05-4dde-9565-8b11c47ac99c","reason":"filled","price":"9106.39","remaining_size":"0"}
{"type":"received","side":"sell","product_id":"BTC-USD","time":"2020-06-30T19:11:13.200185Z","sequence":180755206,"order_id":"327f4836-854c-4f28-8d25-1373d48d114a","order_type":"limit","size":"0.069","price":"9158.2","client_oid":""}
{"type":"open","side":"sell","product_id":"BTC-USD","time":"2020-06-30T19:11:13.200185Z","sequence":180755207,"price":"9158.2","order_id":"327f4836-854c-4f28-8d25-1373d48d114a","remaining_size":"0.069"}
{"type":"received","side":"buy","product_id":"BTC-USD","time":"2020-06-30T19:11:13.464361Z","sequence":180755208,"order_id":"389d2309-b9f3-4500-883c-40b3c353d073","order_type":"limit","size":"0.0187","price":"9084.17","client_oid":""}
{"type":"open","side":"buy","product_id":"BTC-USD","time":"2020-06-30T19:11:13.464361Z","sequence":180755209,"price":"9084.17","order_id":"389d2309-b9f3-4500-883c-40b3c353d073","remaining_size":"0.0187"}
{"type":"heartbeat","last_trade_id":0,"product_id":"BTC-USD","sequence":180755209,"time":"2020-06-30T19:11:13.735106Z"}
{"type":"done","side":"buy","product_id":"BTC-USD","time":"2020-06-30T19:11:13.881698Z","sequence":180755210,"order_id":"960a9aa2-29ce-447a-83b8-4b86e959604e","reason":"canceled","price":"9074.53","remaining_size":"0.0235"}
{"type":"received","side":"buy","product_id":"BTC-USD","time":"2020-06-30T19:11:14.021656Z","sequence":180755211,"order_id":"51469c62-1151-4156-b6cb-a1a8a92c263d","order_type":"limit","size":"0.0974","price":"9084.58","client_oid":""}
{"type":"open","side":"buy","product_id":"BTC-USD","time":"2020-06-30T19:11:14.021656Z","sequence":180755212,"price":"9084.58","order_id":"51469c62-1151-4156-b6cb-a1a8a92c263d","remaining_size":"0.0974"}
{"type":"received","side":"buy","product_id":"BTC-USD","time":"2020-06-30T19:11:14.032039Z","sequence":180755213,"order_id":"a86bd9cc-4cc0-4a88-ae40-0c41f3bd4371","order_type":"limit","size":"0.01","price":"100","client_oid":"3293acad-adb5-4f70-9c9d-b16166a48b0c"}
{"type":"open","side":"buy","product_id":"BTC-USD","time":"2020-06-30T19:11:14.032039Z","sequence":180755214,"price":"100","order_id":"a86bd9cc-4cc0-4a88-ae40-0c41f3bd4371","remaining_size":"0.01"}
{"type":"done","side":"buy","product_id":"BTC-USD","time":"2020-06-30T19:11:14.039537Z","sequence":180755215,"order_id":"a86bd9cc-4cc0-4a88-ae40-0c41f3bd4371","reason":"canceled","price":"100","remaining_size":"0.01"}
{"type":"received","side":"sell","product_id":"BTC-USD","time":"2020-06-30T19:11:14.587798Z","sequence":180755216,"order_id":"433bbd1e-e967-4414-af5a-9f1fd75cd74c","order_type":"limit","size":"0.1513","price":"9106.38","client_oid":""}
{"type":"match","side":"buy","product_id":"BTC-USD","time":"2020-06-30T19:11:14.587798Z","sequence":180755217,"trade_id":14587446,"maker_order_id":"91b59a7c-6a07-4039-9536-21daf3cb3282","taker_order_id":"433bbd1e-e967-4414-af5a-9f1fd75cd74c","size":"0.1513","price":"9120.8"}
{"type":"done","side":"sell","product_id":"BTC-USD","time":"2020-06-30T19:11:14.587798Z","sequence":180755218,"order_id":"433bbd1e-e967-4414-af5a-9f1fd75cd74c","reason":"filled","price":"9106.38","remaining_size":"0"}
{"type":"heartbeat","last_trade_id":0,"product_id":"BTC-USD","sequence":180755218,"time":"2020-06-30T19:11:14.735117Z"}
{"type":"done","side":"sell","product_id":"BTC-USD","time":"2020-06-30T19:11:15.031303Z","sequence":180755219,"order_id":"aff2c3a7-ebc5-4edf-9680-86b0e4635bdc","reason":"canceled","price":"9159.26","remaining_size":"0.069"}
{"type":"done","side":"sell","product_id":"BTC-USD","time":"2020-06-30T19:11:15.032185Z","sequence":180755220,"order_id":"3d4c5705-9b5a-42fc-a834-9350a075c87f","reason":"canceled","price":"9160.27","remaining_size":"0.0531"}
{"type":"received","side":"buy","product_id":"BTC-USD","time":"2020-06-30T19:11:15.171323Z","sequence":180755221,"order_id":"a3b156a6-5814-414d-82be-f64b51045ab1","order_type":"limit","size":"0.0967","price":"9075.5","client_oid":""}
{"type":"open","side":"buy","product_id":"BTC-USD","time":"2020-06-30T19:11:15.171323Z","sequence":180755222,"price":"9075.5","order_id":"a3b156a6-5814-414d-82be-f64b51045ab1","remaining_size":"0.0967"}
{"type":"received","side":"sell","product_id":"BTC-USD","time":"2020-06-30T19:11:15.457932Z","sequence":180755223,"order_id":"a73bc850-313b-4cef-aff9-b18cf2d434e9","order_type":"limit","size":"0.06","price":"9106.31","client_oid":""}
{"type":"match","side":"buy","product_id":"BTC-USD","time":"2020-06-30T19:11:15.457932Z","sequence":180755224,"trade_id":14587447,"maker_order_id":"91b59a7c-6a07-4039-9536-21daf3cb3282","taker_order_id":"a73bc850-313b-4cef-aff9-b18cf2d434e9","size":"0.06","price":"9120.8"}
{"type":"done","side":"sell","product_id":"BTC-USD","time":"2020-06-30T19:11:15.457932Z","sequence":180755225,"order_id":"a73bc850-313b-4cef-aff9-b18cf2d434e9","reason":"filled","price":"9106.31","remaining_size":"0"}
{"type":"done","side":"buy","product_id":"BTC-USD","time":"2020-06-30T19:11:15.586369Z","sequence":180755226,"order_id":"d7a84894-769d-47b1-b560-27b21aa0ce1d","reason":"canceled","price":"9105.59","remaining_size":"0.05"}
{"type":"done","side":"buy","product_id":"BTC-USD","time":"2020-06-30T19:11:15.593022Z","sequence":180755227,"order_id":"ccddf108-ac97-4b57-9b4e-f8b8eaa99fba","reason":"canceled","price":"9077.02","remaining_size":"0.0235"}
{"type":"done","side":"buy","product_id":"BTC-USD","time":"2020-06-30T19:11:15.598114Z","sequence":180755228,"order_id":"273fe885-981a-4706-935d-9c534605a9a4","reason":"canceled","price":"9102.76","remaining_size":"5"}
{"type":"done","side":"buy","product_id":"BTC-USD","time":"2020-06-30T19:11:15.611533Z","sequence":180755229,"order_id":"7cf2e5b4-2af3-49fe-8409-da1d949ebe5e","reason":"canceled","price":"9105.08","remaining_size":"0.05"}
{"type":"received","side":"buy","product_id":"BTC-USD","time":"2020-06-30T19:11:15.711865Z","sequence":180755230,"order_id":"8a462752-7607-41b7-88ca-bc5ae399105d","order_type":"limit","size":"0.1357","price":"9106.21","client_oid":""}
{"type":"open","side":"buy","product_id":"BTC-USD","time":"2020-06-30T19:11:15.711865Z","sequence":180755231,"price":"9106.21","order_id":"8a462752-7607-41b7-88ca-bc5ae399105d","remaining_size":"0.1357"}
{"type":"heartbeat","last_trade_id":0,"product_id":"BTC-USD","sequence":180755231,"time":"2020-06-30T19:11:15.735111Z"}
{"type":"done","side":"buy","product_id":"BTC-USD","time":"2020-06-30T19:11:16.163026Z","sequence":180755232,"order_id":"a3b156a6-5814-414d-82be-f64b51045ab1","reason":"canceled","price":"9075.5","remaining_size":"0.0967"}
{"type":"done","side":"buy","product_id":"BTC-USD","time":"2020-06-30T19:11:16.168459Z","sequence":180755233,"order_id":"a5cad29d-d7e2-4e33-9527-2ff9ad520307","reason":"canceled","price":"9078.98","remaining_size":"0.0692"}
{"type":"heartbeat","last_trade_id":0,"product_id":"BTC-USD","sequence":180755233,"time":"2020-06-30T19:11:16.735025Z"}
{"type":"received","side":"buy","product_id":"BTC-USD","time":"2020-06-30T19:11:17.388227Z","sequence":180755234,"order_id":"c59654b7-665b-44ed-a670-584d8cff7216","order_type":"limit","size":"0.1038","price":"9106.26","client_oid":""}
{"type":"open","side":"buy","product_id":"BTC-USD","time":"2020-06-30T19:11:17.388227Z","sequence":180755235,"price":"9106.26","order_id":"c59654b7-665b-44ed-a670-584d8cff7216","remaining_size":"0.1038"}
{"type":"heartbeat","last_trade_id":0,"product_id":"BTC-USD","sequence":180755235,"time":"2020-06-30T19:11:17.735164Z"}
{"type":"received","side":"sell","product_id":"BTC-USD","time":"2020-06-30T19:11:18.256737Z","sequence":180755236,"order_id":"cdb910ab-bd59-47ce-a7ef-29f676bceb81","order_type":"limit","size":"0.0236","price":"9115.35","client_oid":""}
{"type":"match","side":"buy","product_id":"BTC-USD","time":"2020-06-30T19:11:18.256737Z","sequence":180755237,"trade_id":14587448,"maker_order_id":"91b59a7c-6a07-4039-9536-21daf3cb3282","taker_order_id":"cdb910ab-bd59-47ce-a7ef-29f676bceb81","size":"0.0236","price":"9120.8"}
{"type":"done","side":"sell","product_id":"BTC-USD","time":"2020-06-30T19:11:18.256737Z","sequence":180755238,"order_id":"cdb910ab-bd59-47ce-a7ef-29f676bceb81","reason":"filled","price":"9115.35","remaining_size":"0"}
{"type":"received","side":"sell","product_id":"BTC-USD","time":"2020-06-30T19:11:18.513162Z","sequence":180755239,"order_id":"16c909c4-31a8-4ce3-83f6-b33d48ce23ff","order_type":"limit","size":"4.1727","price":"9106.9","client_oid":""}
{"type":"match","side":"buy","product_id":"BTC-USD","time":"2020-06-30T19:11:18.513162Z","sequence":180755240,"trade_id":14587449,"maker_order_id":"91b59a7c-6a07-4039-9536-21daf3cb3282","taker_order_id":"16c909c4-31a8-4ce3-83f6-b33d48ce23ff","size":"4.1727","price":"9120.8"}
{"type":"done","side":"sell","product_id":"BTC-USD","time":"2020-06-30T19:11:18.513162Z","sequence":180755241,"order_id":"16c909c4-31a8-4ce3-83f6-b33d48ce23ff","reason":"filled","price":"9106.9","remaining_size":"0"}
{"type":"heartbeat","last_trade_id":0,"product_id":"BTC-USD","sequence":180755241,"time":"2020-06-30T19:11:18.735082Z"}
{"type":"received","side":"buy","product_id":"BTC-USD","time":"2020-06-30T19:11:18.793416Z","sequence":180755242,"order_id":"67f4f64e-4b82-4bbe-871d-7b393e0166a7","order_type":"limit","size":"0.0879","price":"9043.1","client_oid":""}
{"type":"open","side":"buy","product_id":"BTC-USD","time":"2020-06-30T19:11:18.793416Z","sequence":180755243,"price":"9043.1","order_id":"67f4f64e-4b82-4bbe-871d-7b393e0166a7","remaining_size":"0.0879"}
{"type":"received","side":"buy","product_id":"BTC-USD","time":"2020-06-30T19:11:19.074403Z","sequence":180755244,"order_id":"293fb458-90fa-4098-a1cc-a03ca5809410","order_type":"limit","size":"0.1284","price":"9105.47","client_oid":""}
{"type":"open","side":"buy","product_id":"BTC-USD","time":"2020-06-30T19:11:19.074403Z","sequence":180755245,"price":"9105.47","order_id":"293fb458-90fa-4098-a1cc-a03ca5809410","remaining_size":"0.1284"}
{"type":"done","side":"buy","product_id":"BTC-USD","time":"2020-06-30T19:11:19.226160Z","sequence":180755246,"order_id":"eec24ff4-ed3b-45c6-9e68-8dfcc34d283a","reason":"canceled","price":"9103.23","remaining_size":"0.9"}
{"type":"done","side":"buy","product_id":"BTC-USD","time":"2020-06-30T19:11:19.229293Z","sequence":180755247,"order_id":"51f470e4-3607-479a-83cc-b178fc711939","reason":"canceled","price":"9080.54","remaining_size":"0.0692"}
{"type":"heartbeat","last_trade_id":0,"product_id":"BTC-USD","sequence":180755247,"time":"2020-06-30T19:11:19.735097Z"}
{"type":"received","side":"buy","product_id":"BTC-USD","time":"2020-06-30T19:11:19.913837Z","sequence":180755248,"order_id":"e7d49d28-1d9f-4c79-86c7-09d2e5372778","order_type":"limit","size":"0.25","price":"18240","client_oid":""}
{"type":"match","side":"sell","product_id":"BTC-USD","time":"2020-06-30T19:11:19.913837Z","sequence":180755249,"trade_id":14587450,"maker_order_id":"36fe0734-4801-466d-b093-cccd411db09a","taker_order_id":"e7d49d28-1d9f-4c79-86c7-09d2e5372778","size":"0.25","price":"9120.82"}
{"type":"done","side":"buy","product_id":"BTC-USD","time":"2020-06-30T19:11:19.913837Z","sequence":180755250,"order_id":"e7d49d28-1d9f-4c79-86c7-09d2e5372778","reason":"filled","price":"18240","remaining_size":"0"}
{"type":"heartbeat","last_trade_id":0,"product_id":"BTC-USD","sequence":180755250,"time":"2020-06-30T19:11:20.735112Z"}
{"type":"received","side":"buy","product_id":"BTC-USD","time":"2020-06-30T19:11:20.747735Z","sequence":180755251,"order_id":"5c936923-7bc2-4480-94df-23a2ea29f19c","order_type":"limit","size":"0.0659","price":"9105.49","client_oid":""}
{"type":"open","side":"buy","product_id":"BTC-USD","time":"2020-06-30T19:11:20.747735Z","sequence":180755252,"price":"9105.49","order_id":"5c936923-7bc2-4480-94df-23a2ea29f19c","remaining_size":"0.0659"}
{"type":"received","side":"buy","product_id":"BTC-USD","time":"2020-06-30T19:11:21.002790Z","sequence":180755253,"order_id":"eed23b0b-1d2f-4459-ba08-27bfe4d35ecd","order_type":"limit","size":"0.1705","price":"9106.44","client_oid":""}
{"type":"open","side":"buy","product_id":"BTC-USD","time":"2020-06-30T19:11:21.002790Z","sequence":180755254,"price":"9106.44","order_id":"eed23b0b-1d2f-4459-ba08-27bfe4d35ecd","remaining_size":"0.1705"}
{"type":"done","side":"buy","product_id":"BTC-USD","time":"2020-06-30T19:11:21.176043Z","sequence":180755255,"order_id":"3f175cef-d228-479c-960b-44408fa127f7","reason":"canceled","price":"9077.81","remaining_size":"0.0692"}
{"type":"received","side":"buy","product_id":"BTC-USD","time":"2020-06-30T19:11:21.284005Z","sequence":180755256,"order_id":"e672e32e-e9c6-4e9b-ad84-c592f11242b8","order_type":"limit","size":"4.7996","price":"9106.44","client_oid":""}
{"type":"open","side":"buy","product_id":"BTC-USD","time":"2020-06-30T19:11:21.284005Z","sequence":180755257,"price":"9106.44","order_id":"e672e32e-e9c6-4e9b-ad84-c592f11242b8","remaining_size":"4.7996"}
{"type":"received","side":"sell","product_id":"BTC-USD","time":"2020-06-30T19:11:21.511701Z","sequence":180755258,"order_id":"fc009401-37a0-492c-b1c5-cdb24b8a5039","order_type":"limit","size":"0.25","price":"4560","client_oid":""}
{"type":"match","side":"buy","product_id":"BTC-USD","time":"2020-06-30T19:11:21.511701Z","sequence":180755259,"trade_id":14587451,"maker_order_id":"91b59a7c-6a07-4039-9536-21daf3cb3282","taker_order_id":"fc009401-37a0-492c-b1c5-cdb24b8a5039","size":"0.25","price":"9120.8"}
{"type":"done","side":"sell","product_id":"BTC-USD","time":"2020-06-30T19:11:21.511701Z","sequence":180755260,"order_id":"fc009401-37a0-492c-b1c5-cdb24b8a5039","reason":"filled","price":"4560","remaining_size":"0"}
{"type":"done","side":"buy","product_id":"BTC-USD","time":"2020-06-30T19:11:21.724742Z","sequence":180755261,"order_id":"67f4f64e-4b82-4bbe-871d-7b393e0166a7","reason":"canceled","price":"9043.1","remaining_size":"0.0879"}
{"type":"heartbeat","last_trade_id":0,"product_id":"BTC-USD","sequence":180755261,"time":"2020-06-30T19:11:21.735109Z"}
{"type":"received","side":"sell","product_id":"BTC-USD","time":"2020-06-30T19:11:22.169314Z","sequence":180755262,"order_id":"13a14f0b-547c-4473-aed1-32f3d8e05a63","order_type":"limit","size":"1.0819","price":"9138.33","client_oid":""}
{"type":"open","side":"sell","product_id":"BTC-USD","time":"2020-06-30T19:11:22.169314Z","sequence":180755263,"price":"9138.33","order_id":"13a14f0b-547c-4473-aed1-32f3d8e05a63","remaining_size":"1.0819"}
{"type":"received","side":"buy","product_id":"BTC-USD","time":"2020-06-30T19:11:22.441215Z","sequence":180755264,"order_id":"108ece61-c435-4021-9add-474ef56d6a28","order_type":"limit","size":"0.0235","price":"9076.36","client_oid":""}
{"type":"open","side":"buy","product_id":"BTC-USD","time":"2020-06-30T19:11:22.441215Z","sequence":180755265,"price":"9076.36","order_id":"108ece61-c435-4021-9add-474ef56d6a28","remaining_size":"0.0235"}
{"type":"heartbeat","last_trade_id":0,"product_id":"BTC-USD","sequence":180755265,"time":"2020-06-30T19:11:22.735076Z"}
{"type":"received","side":"buy","product_id":"BTC-USD","time":"2020-06-30T19:11:23.136051Z","sequence":180755266,"order_id":"51ace2be-dc08-49ba-b613-6be75f926530","order_type":"limit","size":"0.25","price":"18240","client_oid":""}
{"type":"match","side":"sell","product_id":"BTC-USD","time":"2020-06-30T19:11:23.136051Z","sequence":180755267,"trade_id":14587452,"maker_order_id":"36fe0734-4801-466d-b093-cccd411db09a","taker_order_id":"51ace2be-dc08-49ba-b613-6be75f926530","size":"0.25","price":"9120.82"}
{"type":"done","side":"buy","product_id":"BTC-USD","time":"2020-06-30T19:11:23.136051Z","sequence":180755268,"order_id":"51ace2be-dc08-49ba-b613-6be75f926530","reason":"filled","price":"18240","remaining_size":"0"}
{"type":"received","side":"sell","product_id":"BTC-USD","time":"2020-06-30T19:11:23.299287Z","sequence":180755269,"order_id":"9ac3c8b4-6841-43a4-b600-7d55c791b865","order_type":"limit","size":"1.0849","price":"9133.28","client_oid":""}
{"type":"open","side":"sell","product_id":"BTC-USD","time":"2020-06-30T19:11:23.299287Z","sequence":180755270,"price":"9133.28","order_id":"9ac3c8b4-6841-43a4-b600-7d55c791b865","remaining_size":"1.0849"}
{"type":"received","side":"buy","product_id":"BTC-USD","time":"2020-06-30T19:11:23.579401Z","sequence":180755271,"order_id":"d6710bc5-0c00-4dbb-84af-d0932635fa86","order_type":"limit","size":"0.0788","price":"9085.81","client_oid":""}
{"type":"open","side":"buy","product_id":"BTC-USD","time":"2020-06-30T19:11:23.579401Z","sequence":180755272,"price":"9085.81","order_id":"d6710bc5-0c00-4dbb-84af-d0932635fa86","remaining_size":"0.0788"}
{"type":"done","side":"sell","product_id":"BTC-USD","time":"2020-06-30T19:11:23.739820Z","sequence":180755273,"order_id":"13a14f0b-547c-4473-aed1-32f3d8e05a63","reason":"canceled","price":"9138.33","remaining_size":"1.0819"}
{"type":"heartbeat","last_trade_id":0,"product_id":"BTC-USD","sequence":180755273,"time":"2020-06-30T19:11:23.735097Z"}
{"type":"done","side":"buy","product_id":"BTC-USD","time":"2020-06-30T19:11:24.026118Z","sequence":180755274,"order_id":"eed23b0b-1d2f-4459-ba08-27bfe4d35ecd","reason":"canceled","price":"9106.44","remaining_size":"0.1705"}
{"type":"done","side":"buy","product_id":"BTC-USD","time":"2020-06-30T19:11:24.029512Z","sequence":180755275,"order_id":"c69cd951-63c1-4529-bcb1-b6c87565ffd1","reason":"canceled","price":"9081.12","remaining_size":"0.01"}
{"type":"done","side":"buy","product_id":"BTC-USD","time":"2020-06-30T19:11:24.049676Z","sequence":180755276,"order_id":"fdfc8b6a-a0ce-4a5e-87c2-6aaf2837e518","reason":"canceled","price":"9073.15","remaining_size":"0.0692"}
{"type":"received","side":"buy","product_id":"BTC-USD","time":"2020-06-30T19:11:24.680862Z","sequence":180755277,"order_id":"40e0df06-b50a-4ecb-b777-bdc1951e0eb2","order_type":"limit","size":"0.0692","price":"9080.87","client_oid":""}
{"type":"open","side":"buy","product_id":"BTC-USD","time":"2020-06-30T19:11:24.680862Z","sequence":180755278,"price":"9080.87","order_id":"40e0df06-b50a-4ecb-b777-bdc1951e0eb2","remaining_size":"0.0692"}
{"type":"heartbeat","last_trade_id":0,"product_id":"BTC-USD","sequence":180755278,"time":"2020-06-30T19:11:24.735116Z"}
{"type":"received","side":"sell","product_id":"BTC-USD","time":"2020-06-30T19:11:24.814671Z","sequence":180755279,"order_id":"bc892328-3652-4fe7-8746-fc0d1e6aaac1","order_type":"limit","size":"0.25","price":"4560","client_oid":""}
{"type":"match","side":"buy","product_id":"BTC-USD","time":"2020-06-30T19:11:24.814671Z","sequence":180755280,"trade_id":14587453,"maker_order_id":"91b59a7c-6a07-4039-9536-21daf3cb3282","taker_order_id":"bc892328-3652-4fe7-8746-fc0d1e6aaac1","size":"0.25","price":"9120.8"}
{"type":"done","side":"sell","product_id":"BTC-USD","time":"2020-06-30T19:11:24.814671Z","sequence":180755281,"order_id":"bc892328-3652-4fe7-8746-fc0d1e6aaac1","reason":"filled","price":"4560","remaining_size":"0"}
{"type":"received","side":"buy","product_id":"BTC-USD","time":"2020-06-30T19:11:24.962638Z","sequence":180755282,"order_id":"30806573-f649-4924-9d19-5a7a7b5f6f02","order_type":"limit","size":"0.0967","price":"9081.28","client_oid":""}
{"type":"open","side":"buy","product_id":"BTC-USD","time":"2020-06-30T19:11:24.962638Z","sequence":180755283,"price":"9081.28","order_id":"30806573-f649-4924-9d19-5a7a7b5f6f02","remaining_size":"0.0967"}
{"type":"done","side":"buy","product_id":"BTC-USD","time":"2020-06-30T19:11:25.384098Z","sequence":180755284,"order_id":"389d2309-b9f3-4500-883c-40b3c353d073","reason":"canceled","price":"9084.17","remaining_size":"0.0187"}
{"type":"received","side":"sell","product_id":"BTC-USD","time":"2020-06-30T19:11:25.522376Z","sequence":180755285,"order_id":"1f6a34bc-e486-40a5-9042-80b167e984ce","order_type":"limit","size":"0.069","price":"9158.17","client_oid":""}
{"type":"open","side":"sell","product_id":"BTC-USD","time":"2020-06-30T19:11:25.522376Z","sequence":180755286,"price":"9158.17","order_id":"1f6a34bc-e486-40a5-9042-80b167e984ce","remaining_size":"0.069"}
{"type":"heartbeat","last_trade_id":0,"product_id":"BTC-USD","sequence":180755286,"time":"2020-06-30T19:11:25.735116Z"}
{"type":"received","side":"buy","product_id":"BTC-USD","time":"2020-06-30T19:11:25.779954Z","sequence":180755287,"order_id":"6c3f551a-e610-46e9-bf4f-9ad14744637a","order_type":"limit","size":"0.0692","price":"9072.2","client_oid":""}
{"type":"open","side":"buy","product_id":"BTC-USD","time":"2020-06-30T19:11:25.779954Z","sequence":180755288,"price":"9072.2","order_id":"6c3f551a-e610-46e9-bf4f-9ad14744637a","remaining_size":"0.0692"}
{"type":"done","side":"sell","product_id":"BTC-USD","time":"2020-06-30T19:11:25.937417Z","sequence":180755289,"order_id":"9ac3c8b4-6841-43a4-b600-7d55c791b865","reason":"canceled","price":"9133.28","remaining_size":"1.0849"}
{"type":"received","side":"sell","product_id":"BTC-USD","time":"2020-06-30T19:11:26.061457Z","sequence":180755290,"order_id":"7eac6f03-10b2-4a91-943d-776e6005b2f0","order_type":"limit","size":"0.069","price":"9157.87","client_oid":""}
{"type":"open","side":"sell","product_id":"BTC-USD","time":"2020-06-30T19:11:26.061457Z","sequence":180755291,"price":"9157.87","order_id":"7eac6f03-10b2-4a91-943d-776e6005b2f0","remaining_size":"0.069"}
{"type":"received","side":"buy","product_id":"BTC-USD","time":"2020-06-30T19:11:26.351961Z","sequence":180755292,"order_id":"190c0f8e-4a0a-4a5e-bffa-aacb88954193","order_type":"limit","size":"0.0692","price":"9073.3","client_oid":""}
{"type":"open","side":"buy","product_id":"BTC-USD","time":"2020-06-30T19:11:26.351961Z","sequence":180755293,"price":"9073.3","order_id":"190c0f8e-4a0a-4a5e-bffa-aacb88954193","remaining_size":"0.0692"}
{"type":"received","side":"sell","product_id":"BTC-USD","time":"2020-06-30T19:11:26.608493Z","sequence":180755294,"order_id":"64c11e55-aad0-4e9e-b636-1e9d6be8a5f7","order_type":"limit","size":"0.069","price":"9157.58","client_oid":""}
{"type":"open","side":"sell","product_id":"BTC-USD","time":"2020-06-30T19:11:26.608493Z","sequence":180755295,"price":"9157.58","order_id":"64c11e55-aad0-4e9e-b636-1e9d6be8a5f7","remaining_size":"0.069"}
{"type":"received","side":"buy","product_id":"BTC-USD","time":"2020-06-30T19:11:26.629346Z","sequence":180755296,"order_id":"93333195-60e5-47ff-bbc6-87819bf2cd3c","order_type":"limit","size":"0.25","price":"18240","client_oid":""}
{"type":"match","side":"sell","product_id":"BTC-USD","time":"2020-06-30T19:11:26.629346Z","sequence":180755297,"trade_id":14587454,"maker_order_id":"36fe0734-4801-466d-b093-cccd411db09a","taker_order_id":"93333195-60e5-47ff-bbc6-87819bf2cd3c","size":"0.25","price":"9120.82"}
{"type":"done","side":"buy","product_id":"BTC-USD","time":"2020-06-30T19:11:26.629346Z","sequence":180755298,"order_id":"93333195-60e5-47ff-bbc6-87819bf2cd3c","reason":"filled","price":"18240","remaining_size":"0"}
{"type":"heartbeat","last_trade_id":0,"product_id":"BTC-USD","sequence":180755298,"time":"2020-06-30T19:11:26.735131Z"}
{"type":"done","side":"sell","product_id":"BTC-USD","time":"2020-06-30T19:11:27.056209Z","sequence":180755299,"order_id":"690af1ec-ac84-45d5-8d7a-3bfbf0ef2133","reason":"canceled","price":"9158.3","remaining_size":"0.069"}
{"type":"received","side":"sell","product_id":"BTC-USD","time":"2020-06-30T19:11:27.738735Z","sequence":180755300,"order_id":"e4495d4a-1d8e-408d-9fff-4f18d51e89a4","order_type":"limit","size":"0.069","price":"9157.53","client_oid":""}
{"type":"open","side":"sell","product_id":"BTC-USD","time":"2020-06-30T19:11:27.738735Z","sequence":180755301,"price":"9157.53","order_id":"e4495d4a-1d8e-408d-9fff-4f18d51e89a4","remaining_size":"0.069"}
{"type":"heartbeat","last_trade_id":0,"product_id":"BTC-USD","sequence":180755301,"time":"2020-06-30T19:11:27.735074Z"}
{"type":"done","side":"sell","product_id":"BTC-USD","time":"2020-06-30T19:11:27.927950Z","sequence":180755302,"order_id":"5fce12cd-4c04-4397-8f27-cb98842326a1","reason":"canceled","price":"9137.65","remaining_size":"1.0699"}
{"type":"received","side":"sell","product_id":"BTC-USD","time":"2020-06-30T19:11:28.695417Z","sequence":180755303,"order_id":"3e641321-60b2-442b-976e-6a404712792d","order_type":"limit","size":"0.25","price":"4560","client_oid":""}
{"type":"match","side":"buy","product_id":"BTC-USD","time":"2020-06-30T19:11:28.695417Z","sequence":180755304,"trade_id":14587455,"maker_order_id":"91b59a7c-6a07-4039-9536-21daf3cb3282","taker_order_id":"3e641321-60b2-442b-976e-6a404712792d","size":"0.25","price":"9120.8"}
{"type":"done","side":"sell","product_id":"BTC-USD","time":"2020-06-30T19:11:28.695417Z","sequence":180755305,"order_id":"3e641321-60b2-442b-976e-6a404712792d","reason":"filled","price":"4560","remaining_size":"0"}
{"type":"heartbeat","last_trade_id":0,"product_id":"BTC-USD","sequence":180755305,"time":"2020-06-30T19:11:28.735048Z"}
{"type":"received","side":"sell","product_id":"BTC-USD","time":"2020-06-30T19:11:28.864834Z","sequence":180755306,"order_id":"49044cfa-7625-4d96-a120-f5e95189b60e","order_type":"limit","size":"0.07","price":"9157.48","client_oid":""}
{"type":"open","side":"sell","product_id":"BTC-USD","time":"2020-06-30T19:11:28.864834Z","sequence":180755307,"price":"9157.48","order_id":"49044cfa-7625-4d96-a120-f5e95189b60e","remaining_size":"0.07"}
{"type":"received","side":"buy","product_id":"BTC-USD","time":"2020-06-30T19:11:29.030896Z","sequence":180755308,"order_id":"70f1a4c8-a6d9-4ee3-ae7b-77da26612e0e","order_type":"limit","size":"0.01","price":"100","client_oid":"d24418b3-f025-4ea2-8d7d-6300938f374a"}
{"type":"open","side":"buy","product_id":"BTC-USD","time":"2020-06-30T19:11:29.030896Z","sequence":180755309,"price":"100","order_id":"70f1a4c8-a6d9-4ee3-ae7b-77da26612e0e","remaining_size":"0.01"}
{"type":"done","side":"buy","product_id":"BTC-USD","time":"2020-06-30T19:11:29.037894Z","sequence":180755310,"order_id":"70f1a4c8-a6d9-4ee3-ae7b-77da26612e0e","reason":"canceled","price":"100","remaining_size":"0.01"}
{"type":"done","side":"sell","product_id":"BTC-USD","time":"2020-06-30T19:11:29.324946Z","sequence":180755311,"order_id":"64c11e55-aad0-4e9e-b636-1e9d6be8a5f7","reason":"canceled","price":"9157.58","remaining_size":"0.069"}
{"type":"received","side":"sell","product_id":"BTC-USD","time":"2020-06-30T19:11:29.430872Z","sequence":180755312,"order_id":"be79451c-3443-469b-acf5-f9440fc91a37","order_type":"limit","size":"0.069","price":"9157.46","client_oid":""}
{"type":"open","side":"sell","product_id":"BTC-USD","time":"2020-06-30T19:11:29.430872Z","sequence":180755313,"price":"9157.46","order_id":"be79451c-3443-469b-acf5-f9440fc91a37","remaining_size":"0.069"}
{"type":"heartbeat","last_trade_id":0,"product_id":"BTC-USD","sequence":180755313,"time":"2020-06-30T19:11:29.735049Z"}
{"type":"received","side":"buy","product_id":"BTC-USD","time":"2020-06-30T19:11:29.978284Z","sequence":180755314,"order_id":"6dcecd8b-fed6-4a48-afe5-15d6a0cf8eb3","order_type":"limit","size":"0.05","price":"9106.19","client_oid":""}
{"type":"open","side":"buy","product_id":"BTC-USD","time":"2020-06-30T19:11:29.978284Z","sequence":180755315,"price":"9106.19","order_id":"6dcecd8b-fed6-4a48-afe5-15d6a0cf8eb3","remaining_size":"0.05"}
{"type":"received","side":"buy","product_id":"BTC-USD","time":"2020-06-30T19:11:30.108579Z","sequence":180755316,"order_id":"9b202cc2-5ac1-4e3b-ae94-e5e16fe46e17","order_type":"limit","size":"0.25","price":"9212.03","client_oid":""}
{"type":"match","side":"sell","product_id":"BTC-USD","time":"2020-06-30T19:11:30.108579Z","sequence":180755317,"trade_id":14587456,"maker_order_id":"36fe0734-4801-466d-b093-cccd411db09a","taker_order_id":"9b202cc2-5ac1-4e3b-ae94-e5e16fe46e17","size":"0.25","price":"9120.82"}
{"type":"done","side":"buy","product_id":"BTC-USD","time":"2020-06-30T19:11:30.108579Z","sequence":180755318,"order_id":"9b202cc2-5ac1-4e3b-ae94-e5e16fe46e17","reason":"filled","price":"9212.03","remaining_size":"0"}
{"type":"received","side":"buy","product_id":"BTC-USD","time":"2020-06-30T19:11:30.261557Z","sequence":180755319,"order_id":"6a29d676-c866-4d0c-b839-72b08b93a2e1","order_type":"limit","size":"0.1087","price":"9072.26","client_oid":""}
{"type":"open","side":"buy","product_id":"BTC-USD","time":"2020-06-30T19:11:30.261557Z","sequence":180755320,"price":"9072.26","order_id":"6a29d676-c866-4d0c-b839-72b08b93a2e1","remaining_size":"0.1087"}
{"type":"done","side":"buy","product_id":"BTC-USD","time":"2020-06-30T19:11:30.475334Z","sequence":180755321,"order_id":"6c3f551a-e610-46e9-bf4f-9ad14744637a","reason":"canceled","price":"9072.2","remaining_size":"0.0692"}
{"type":"heartbeat","last_trade_id":0,"product_id":"BTC-USD","sequence":180755321,"time":"2020-06-30T19:11:30.735036Z"}
{"type":"received","side":"sell","product_id":"BTC-USD","time":"2020-06-30T19:11:31.100093Z","sequence":180755322,"order_id":"086e77a4-67d7-44f5-b79d-a270574372cf","order_type":"limit","size":"0.069","price":"9158.19","client_oid":""}
{"type":"open","side":"sell","product_id":"BTC-USD","time":"2020-06-30T19:11:31.100093Z","sequence":180755323,"price":"9158.19","order_id":"086e77a4-67d7-44f5-b79d-a270574372cf","remaining_size":"0.069"}
{"type":"received","side":"buy","product_id":"BTC-USD","time":"2020-06-30T19:11:31.420421Z","sequence":180755324,"order_id":"41162654-2bd2-4eb0-8123-867d2bafa2c7","order_type":"limit","size":"0.0692","price":"9075.13","client_oid":""}
{"type":"open","side":"buy","product_id":"BTC-USD","time":"2020-06-30T19:11:31.420421Z","sequence":180755325,"price":"9075.13","order_id":"41162654-2bd2-4eb0-8123-867d2bafa2c7","remaining_size":"0.0692"}
{"type":"done","side":"sell","product_id":"BTC-USD","time":"2020-06-30T19:11:31.546115Z","sequence":180755326,"order_id":"e4495d4a-1d8e-408d-9fff-4f18d51e89a4","reason":"canceled","price":"9157.53","remaining_size":"0.069"}
{"type":"heartbeat","last_trade_id":0,"product_id":"BTC-USD","sequence":180755326,"time":"2020-06-30T19:11:31.735055Z"}
{"type":"received","side":"buy","product_id":"BTC-USD","time":"2020-06-30T19:11:32.217022Z","sequence":180755327,"order_id":"74fb9eee-15e1-4993-8206-34f57e837bb5","order_type":"limit","size":"0.01","price":"9086.05","client_oid":""}
{"type":"open","side":"buy","product_id":"BTC-USD","time":"2020-06-30T19:11:32.217022Z","sequence":180755328,"price":"9086.05","order_id":"74fb9eee-15e1-4993-8206-34f57e837bb5","remaining_size":"0.01"}
{"type":"done","side":"buy","product_id":"BTC-USD","time":"2020-06-30T19:11:32.445614Z","sequence":180755329,"order_id":"30806573-f649-4924-9d19-5a7a7b5f6f02","reason":"canceled","price":"9081.28","remaining_size":"0.0967"}
{"type":"done","side":"buy","product_id":"BTC-USD","time":"2020-06-30T19:11:32.448854Z","sequence":180755330,"order_id":"1dfebde3-f4d9-483e-ac61-b04f376f4479","reason":"canceled","price":"9075.15","remaining_size":"0.0967"}
{"type":"done","side":"buy","product_id":"BTC-USD","time":"2020-06-30T19:11:32.450487Z","sequence":180755331,"order_id":"97574299-7ed2-4d5e-82cd-48abf49b1e06","reason":"canceled","price":"9072.54","remaining_size":"0.0692"}
{"type":"heartbeat","last_trade_id":0,"product_id":"BTC-USD","sequence":180755331,"time":"2020-06-30T19:11:32.735177Z"}
{"type":"received","side":"sell","product_id":"BTC-USD","time":"2020-06-30T19:11:33.334895Z","sequence":180755332,"order_id":"ad34ff66-4429-4a9c-a087-0ae03121bceb","order_type":"limit","size":"0.069","price":"9157.28","client_oid":""}
{"type":"open","side":"sell","product_id":"BTC-USD","time":"2020-06-30T19:11:33.334895Z","sequence":180755333,"price":"9157.28","order_id":"ad34ff66-4429-4a9c-a087-0ae03121bceb","remaining_size":"0.069"}
{"type":"heartbeat","last_trade_id":0,"product_id":"BTC-USD","sequence":180755333,"time":"2020-06-30T19:11:33.735096Z"}
{"type":"received","side":"sell","product_id":"BTC-USD","time":"2020-06-30T19:11:33.883694Z","sequence":180755334,"order_id":"42c688af-a91b-44bd-bb4b-fcab7522e175","order_type":"limit","size":"1.0725","price":"9132.09","client_oid":""}
{"type":"open","side":"sell","product_id":"BTC-USD","time":"2020-06-30T19:11:33.883694Z","sequence":180755335,"price":"9132.09","order_id":"42c688af-a91b-44bd-bb4b-fcab7522e175","remaining_size":"1.0725"}
{"type":"done","side":"sell","product_id":"BTC-USD","time":"2020-06-30T19:11:34.333445Z","sequence":180755336,"order_id":"5e9ae696-1731-486c-8dc9-affdae966a6d","reason":"canceled","price":"9160.07","remaining_size":"0.001"}
{"type":"done","side":"sell","product_id":"BTC-USD","time":"2020-06-30T19:11:34.353973Z","sequence":180755337,"order_id":"49044cfa-7625-4d96-a120-f5e95189b60e","reason":"canceled","price":"9157.48","remaining_size":"0.07"}
{"type":"done","side":"sell","product_id":"BTC-USD","time":"2020-06-30T19:11:34.368876Z","sequence":180755338,"order_id":"086e77a4-67d7-44f5-b79d-a270574372cf","reason":"canceled","price":"9158.19","remaining_size":"0.069"}
{"type":"heartbeat","last_trade_id":0,"product_id":"BTC-USD","sequence":180755338,"time":"2020-06-30T19:11:34.735111Z"}
{"type":"received","side":"buy","product_id":"BTC-USD","time":"2020-06-30T19:11:34.952282Z","sequence":180755339,"order_id":"6b953d5b-95f1-4060-abde-2b75be41b484","order_type":"limit","size":"0.25","price":"9212.03","client_oid":""}
{"type":"match","side":"sell","product_id":"BTC-USD","time":"2020-06-30T19:11:34.952282Z","sequence":180755340,"trade_id":14587457,"maker_order_id":"36fe0734-4801-466d-b093-cccd411db09a","taker_order_id":"6b953d5b-95f1-4060-abde-2b75be41b484","size":"0.25","price":"9120.82"}
{"type":"done","side":"buy","product_id":"BTC-USD","time":"2020-06-30T19:11:34.952282Z","sequence":180755341,"order_id":"6b953d5b-95f1-4060-abde-2b75be41b484","reason":"filled","price":"9212.03","remaining_size":"0"}
{"type":"received","side":"buy","product_id":"BTC-USD","time":"2020-06-30T19:11:35.091195Z","sequence":180755342,"order_id":"ed74b5fe-9b91-4712-a728-c27de8f0b878","order_type":"limit","size":"0.0967","price":"9081.32","client_oid":""}
{"type":"open","side":"buy","product_id":"BTC-USD","time":"2020-06-30T19:11:35.091195Z","sequence":180755343,"price":"9081.32","order_id":"ed74b5fe-9b91-4712-a728-c27de8f0b878","remaining_size":"0.0967"}
{"type":"received","side":"buy","product_id":"BTC-USD","time":"2020-06-30T19:11:35.354126Z","sequence":180755344,"order_id":"383ae691-f768-4639-afea-e4457f614d60","order_type":"limit","size":"0.75","price":"9105.31","client_oid":""}
{"type":"open","side":"buy","product_id":"BTC-USD","time":"2020-06-30T19:11:35.354126Z","sequence":180755345,"price":"9105.31","order_id":"383ae691-f768-4639-afea-e4457f614d60","remaining_size":"0.75"}
{"type":"received","side":"sell","product_id":"BTC-USD","time":"2020-06-30T19:11:35.626526Z","sequence":180755346,"order_id":"07c87942-40d6-4aed-9623-3233f39e32bc","order_type":"limit","size":"1.1518","price":"9137.03","client_oid":""}
{"type":"open","side":"sell","product_id":"BTC-USD","time":"2020-06-30T19:11:35.626526Z","sequence":180755347,"price":"9137.03","order_id":"07c87942-40d6-4aed-9623-3233f39e32bc","remaining_size":"1.1518"}
{"type":"heartbeat","last_trade_id":0,"product_id":"BTC-USD","sequence":180755347,"time":"2020-06-30T19:11:35.735052Z"}
{"type":"done","side":"buy","product_id":"BTC-USD","time":"2020-06-30T19:11:35.799147Z","sequence":180755348,"order_id":"190c0f8e-4a0a-4a5e-bffa-aacb88954193","reason":"canceled","price":"9073.3","remaining_size":"0.0692"}
{"type":"done","side":"buy","product_id":"BTC-USD","time":"2020-06-30T19:11:35.803121Z","sequence":180755349,"order_id":"51469c62-1151-4156-b6cb-a1a8a92c263d","reason":"canceled","price":"9084.58","remaining_size":"0.0974"}
{"type":"received","side":"buy","product_id":"BTC-USD","time":"2020-06-30T19:11:35.896996Z","sequence":180755350,"order_id":"16358797-6cd8-4e6e-ba45-b4fae3b715b7","order_type":"limit","size":"0.0879","price":"9051.56","client_oid":""}
{"type":"open","side":"buy","product_id":"BTC-USD","time":"2020-06-30T19:11:35.896996Z","sequence":180755351,"price":"9051.56","order_id":"16358797-6cd8-4e6e-ba45-b4fae3b715b7","remaining_size":"0.0879"}
{"type":"done","side":"buy","product_id":"BTC-USD","time":"2020-06-30T19:11:36.342600Z","sequence":180755352,"order_id":"19c9feb4-7091-4fe6-b773-9be03dd894dc","reason":"canceled","price":"9073.36","remaining_size":"0.0692"}
{"type":"done","side":"buy","product_id":"BTC-USD","time":"2020-06-30T19:11:36.344084Z","sequence":180755353,"order_id":"293fb458-90fa-4098-a1cc-a03ca5809410","reason":"canceled","price":"9105.47","remaining_size":"0.1284"}
{"type":"received","side":"sell","product_id":"BTC-USD","time":"2020-06-30T19:11:36.724932Z","sequence":180755354,"order_id":"4abb6c92-4e3b-423d-989d-884ac92bb57b","order_type":"limit","size":"2.365","price":"9115.28","client_oid":""}
{"type":"match","side":"buy","product_id":"BTC-USD","time":"2020-06-30T19:11:36.724932Z","sequence":180755355,"trade_id":14587458,"maker_order_id":"91b59a7c-6a07-4039-9536-21daf3cb3282","taker_order_id":"4abb6c92-4e3b-423d-989d-884ac92bb57b","size":"2.365","price":"9120.8"}
{"type":"done","side":"sell","product_id":"BTC-USD","time":"2020-06-30T19:11:36.724932Z","sequence":180755356,"order_id":"4abb6c92-4e3b-423d-989d-884ac92bb57b","reason":"filled","price":"9115.28","remaining_size":"0"}
{"type":"heartbeat","last_trade_id":0,"product_id":"BTC-USD","sequence":180755356,"time":"2020-06-30T19:11:36.735078Z"}
{"type":"received","side":"sell","product_id":"BTC-USD","time":"2020-06-30T19:11:36.999216Z","sequence":180755357,"order_id":"5d105483-4267-4231-9094-f40f4b1d752b","order_type":"limit","size":"0.0676","price":"9157.93","client_oid":""}
{"type":"open","side":"sell","product_id":"BTC-USD","time":"2020-06-30T19:11:36.999216Z","sequence":180755358,"price":"9157.93","order_id":"5d105483-4267-4231-9094-f40f4b1d752b","remaining_size":"0.0676"}
{"type":"done","side":"sell","product_id":"BTC-USD","time":"2020-06-30T19:11:37.144585Z","sequence":180755359,"order_id":"be79451c-3443-469b-acf5-f9440fc91a37","reason":"canceled","price":"9157.46","remaining_size":"0.069"}
{"type":"received","side":"buy","product_id":"BTC-USD","time":"2020-06-30T19:11:37.268356Z","sequence":180755360,"order_id":"da27d1db-3c49-4932-a626-019a2d6f1b99","order_type":"limit","size":"0.05","price":"9106","client_oid":""}
{"type":"open","side":"buy","product_id":"BTC-USD","time":"2020-06-30T19:11:37.268356Z","sequence":180755361,"price":"9106","order_id":"da27d1db-3c49-4932-a626-019a2d6f1b99","remaining_size":"0.05"}
{"type":"heartbeat","last_trade_id":0,"product_id":"BTC-USD","sequence":180755361,"time":"2020-06-30T19:11:37.735127Z"}
{"type":"received","side":"sell","product_id":"BTC-USD","time":"2020-06-30T19:11:38.126708Z","sequence":180755362,"order_id":"95dab599-a951-454a-8a6f-33108c8224ea","order_type":"limit","size":"1.0008","price":"9137.05","client_oid":""}
{"type":"open","side":"sell","product_id":"BTC-USD","time":"2020-06-30T19:11:38.126708Z","sequence":180755363,"price":"9137.05","order_id":"95dab599-a951-454a-8a6f-33108c8224ea","remaining_size":"1.0008"}
{"type":"done","side":"sell","product_id":"BTC-USD","time":"2020-06-30T19:11:38.585846Z","sequence":180755364,"order_id":"7eac6f03-10b2-4a91-943d-776e6005b2f0","reason":"canceled","price":"9157.87","remaining_size":"0.069"}
{"type":"done","side":"sell","product_id":"BTC-USD","time":"2020-06-30T19:11:38.600782Z","sequence":180755365,"order_id":"1f6a34bc-e486-40a5-9042-80b167e984ce","reason":"canceled","price":"9158.17","remaining_size":"0.069"}
{"type":"done","side":"sell","product_id":"BTC-USD","time":"2020-06-30T19:11:38.611186Z","sequence":180755366,"order_id":"ad34ff66-4429-4a9c-a087-0ae03121bceb","reason":"canceled","price":"9157.28","remaining_size":"0.069"}
{"type":"heartbeat","last_trade_id":0,"product_id":"BTC-USD","sequence":180755366,"time":"2020-06-30T19:11:38.735041Z"}
{"type":"heartbeat","last_trade_id":0,"product_id":"BTC-USD","sequence":180755366,"time":"2020-06-30T19:11:39.735108Z"}
{"type":"received","side":"buy","product_id":"BTC-USD","time":"2020-06-30T19:11:40.353746Z","sequence":180755367,"order_id":"765d004e-5ebd-46c8-a8f8-e32f766aa270","order_type":"limit","size":"0.0692","price":"9070.69","client_oid":""}
{"type":"open","side":"buy","product_id":"BTC-USD","time":"2020-06-30T19:11:40.353746Z","sequence":180755368,"price":"9070.69","order_id":"765d004e-5ebd-46c8-a8f8-e32f766aa270","remaining_size":"0.0692"}
{"type":"heartbeat","last_trade_id":0,"product_id":"BTC-USD","sequence":180755368,"time":"2020-06-30T19:11:40.735074Z"}
{"type":"done","side":"buy","product_id":"BTC-USD","time":"2020-06-30T19:11:40.794351Z","sequence":180755369,"order_id":"8a462752-7607-41b7-88ca-bc5ae399105d","reason":"canceled","price":"9106.21","remaining_size":"0.1357"}
{"type":"done","side":"buy","product_id":"BTC-USD","time":"2020-06-30T19:11:40.794576Z","sequence":180755370,"order_id":"5c936923-7bc2-4480-94df-23a2ea29f19c","reason":"canceled","price":"9105.49","remaining_size":"0.0659"}
{"type":"done","side":"buy","product_id":"BTC-USD","time":"2020-06-30T19:11:40.796701Z","sequence":180755371,"order_id":"40e0df06-b50a-4ecb-b777-bdc1951e0eb2","reason":"canceled","price":"9080.87","remaining_size":"0.0692"}
{"type":"done","side":"buy","product_id":"BTC-USD","time":"2020-06-30T19:11:40.801583Z","sequence":180755372,"order_id":"74fb9eee-15e1-4993-8206-34f57e837bb5","reason":"canceled","price":"9086.05","remaining_size":"0.01"}
{"type":"received","side":"buy","product_id":"BTC-USD","time":"2020-06-30T19:11:41.676936Z","sequence":180755373,"order_id":"66867cfc-f2c3-4967-befd-3248c6066bd4","order_type":"market","size":"0.001","funds":"9.12082","client_oid":""}
{"type":"match","side":"sell","product_id":"BTC-USD","time":"2020-06-30T19:11:41.676936Z","sequence":180755374,"trade_id":14587459,"maker_order_id":"36fe0734-4801-466d-b093-cccd411db09a","taker_order_id":"66867cfc-f2c3-4967-befd-3248c6066bd4","size":"0.001","price":"9120.82"}
{"type":"done","side":"buy","product_id":"BTC-USD","time":"2020-06-30T19:11:41.676936Z","sequence":180755375,"order_id":"66867cfc-f2c3-4967-befd-3248c6066bd4","reason":"filled","remaining_size":"0"}
{"type":"heartbeat","last_trade_id":0,"product_id":"BTC-USD","sequence":180755375,"time":"2020-06-30T19:11:41.735023Z"}
{"type":"received","side":"buy","product_id":"BTC-USD","time":"2020-06-30T19:11:41.837071Z","sequence":180755376,"order_id":"e30844ec-df48-4841-8ca5-702b895cbe81","order_type":"limit","size":"0.0692","price":"9073.58","client_oid":""}
{"type":"open","side":"buy","product_id":"BTC-USD","time":"2020-06-30T19:11:41.837071Z","sequence":180755377,"price":"9073.58","order_id":"e30844ec-df48-4841-8ca5-702b895cbe81","remaining_size":"0.0692"}
{"type":"done","side":"buy","product_id":"BTC-USD","time":"2020-06-30T19:11:42.234868Z","sequence":180755378,"order_id":"e672e32e-e9c6-4e9b-ad84-c592f11242b8","reason":"canceled","price":"9106.44","remaining_size":"4.7996"}
{"type":"received","side":"buy","product_id":"BTC-USD","time":"2020-06-30T19:11:42.362172Z","sequence":180755379,"order_id":"58c97195-ebb4-4802-9448-546790ba6eab","order_type":"limit","size":"0.0692","price":"9074.68","client_oid":""}
{"type":"open","side":"buy","product_id":"BTC-USD","time":"2020-06-30T19:11:42.362172Z","sequence":180755380,"price":"9074.68","order_id":"58c97195-ebb4-4802-9448-546790ba6eab","remaining_size":"0.0692"}
{"type":"received","side":"buy","product_id":"BTC-USD","time":"2020-06-30T19:11:42.652903Z","sequence":180755381,"order_id":"730d1e66-937d-42b1-945d-c6cd76a00302","order_type":"limit","size":"0.01","price":"9081.12","client_oid":""}
{"type":"open","side":"buy","product_id":"BTC-USD","time":"2020-06-30T19:11:42.652903Z","sequence":180755382,"price":"9081.12","order_id":"730d1e66-937d-42b1-945d-c6cd76a00302","remaining_size":"0.01"}
{"type":"heartbeat","last_trade_id":0,"product_id":"BTC-USD","sequence":180755382,"time":"2020-06-30T19:11:42.735136Z"}
{"type":"done","side":"buy","product_id":"BTC-USD","time":"2020-06-30T19:11:43.103584Z","sequence":180755383,"order_id":"6dcecd8b-fed6-4a48-afe5-15d6a0cf8eb3","reason":"canceled","price":"9106.19","remaining_size":"0.05"}
{"type":"received","side":"sell","product_id":"BTC-USD","time":"2020-06-30T19:11:43.210376Z","sequence":180755384,"order_id":"d4a676ea-4eca-476e-beba-8286402eda88","order_type":"limit","size":"4.1202","price":"9144.65","client_oid":""}
{"type":"open","side":"sell","product_id":"BTC-USD","time":"2020-06-30T19:11:43.210376Z","sequence":180755385,"price":"9144.65","order_id":"d4a676ea-4eca-476e-beba-8286402eda88","remaining_size":"4.1202"}
{"type":"received","side":"buy","product_id":"BTC-USD","time":"2020-06-30T19:11:43.484354Z","sequence":180755386,"order_id":"f977f72f-f762-4ce7-b411-a9a1928b17d9","order_type":"limit","size":"1.596","price":"9105.54","client_oid":""}
{"type":"open","side":"buy","product_id":"BTC-USD","time":"2020-06-30T19:11:43.484354Z","sequence":180755387,"price":"9105.54","order_id":"f977f72f-f762-4ce7-b411-a9a1928b17d9","remaining_size":"1.596"}
{"type":"heartbeat","last_trade_id":0,"product_id":"BTC-USD","sequence":180755387,"time":"2020-06-30T19:11:43.735043Z"}
{"type":"received","side":"sell","product_id":"BTC-USD","time":"2020-06-30T19:11:43.820337Z","sequence":180755388,"order_id":"d5f4da76-1858-4070-9460-8e81bfb8cba6","order_type":"limit","size":"0.0659","price":"9113","client_oid":""}
{"type":"match","side":"buy","product_id":"BTC-USD","time":"2020-06-30T19:11:43.820337Z","sequence":180755389,"trade_id":14587460,"maker_order_id":"91b59a7c-6a07-4039-9536-21daf3cb3282","taker_order_id":"d5f4da76-1858-4070-9460-8e81bfb8cba6","size":"0.0659","price":"9120.8"}
{"type":"done","side":"sell","product_id":"BTC-USD","time":"2020-06-30T19:11:43.820337Z","sequence":180755390,"order_id":"d5f4da76-1858-4070-9460-8e81bfb8cba6","reason":"filled","price":"9113","remaining_size":"0"}
{"type":"received","side":"buy","product_id":"BTC-USD","time":"2020-06-30T19:11:44.027763Z","sequence":180755391,"order_id":"2db7c980-f8db-492a-ad2d-61dfe566b099","order_type":"limit","size":"0.01","price":"100","client_oid":"a9bae61c-8777-4f1d-ace7-da7d0db98cc6"}
{"type":"open","side":"buy","product_id":"BTC-USD","time":"2020-06-30T19:11:44.027763Z","sequence":180755392,"price":"100","order_id":"2db7c980-f8db-492a-ad2d-61dfe566b099","remaining_size":"0.01"}
{"type":"done","side":"buy","product_id":"BTC-USD","time":"2020-06-30T19:11:44.034834Z","sequence":180755393,"order_id":"2db7c980-f8db-492a-ad2d-61dfe566b099","reason":"canceled","price":"100","remaining_size":"0.01"}
{"type":"received","side":"buy","product_id":"BTC-USD","time":"2020-06-30T19:11:44.358975Z","sequence":180755394,"order_id":"0262bdb8-b739-4acf-b64d-380dba8ff71c","order_type":"limit","size":"0.0263","price":"9092.85","client_oid":""}
{"type":"open","side":"buy","product_id":"BTC-USD","time":"2020-06-30T19:11:44.358975Z","sequence":180755395,"price":"9092.85","order_id":"0262bdb8-b739-4acf-b64d-380dba8ff71c","remaining_size":"0.0263"}
{"type":"heartbeat","last_trade_id":0,"product_id":"BTC-USD","sequence":180755395,"time":"2020-06-30T19:11:44.735038Z"}
{"type":"received","side":"sell","product_id":"BTC-USD","time":"2020-06-30T19:11:45.201406Z","sequence":180755396,"order_id":"dec1f399-3373-42b3-ae2b-ac6fa89876bb","order_type":"limit","size":"2","price":"9114.65","client_oid":""}
{"type":"match","side":"buy","product_id":"BTC-USD","time":"2020-06-30T19:11:45.201406Z","sequence":180755397,"trade_id":14587461,"maker_order_id":"91b59a7c-6a07-4039-9536-21daf3cb3282","taker_order_id":"dec1f399-3373-42b3-ae2b-ac6fa89876bb","size":"2","price":"9120.8"}
{"type":"done","side":"sell","product_id":"BTC-USD","time":"2020-06-30T19:11:45.201406Z","sequence":180755398,"order_id":"dec1f399-3373-42b3-ae2b-ac6fa89876bb","reason":"filled","price":"9114.65","remaining_size":"0"}
{"type":"heartbeat","last_trade_id":0,"product_id":"BTC-USD","sequence":180755398,"time":"2020-06-30T19:11:45.735018Z"}
{"type":"received","side":"buy","product_id":"BTC-USD","time":"2020-06-30T19:11:45.773089Z","sequence":180755399,"order_id":"8b87b348-30e8-474b-931b-3779e7630d20","order_type":"limit","size":"0.0279","price":"9072.69","client_oid":""}
{"type":"open","side":"buy","product_id":"BTC-USD","time":"2020-06-30T19:11:45.773089Z","sequence":180755400,"price":"9072.69","order_id":"8b87b348-30e8-474b-931b-3779e7630d20","remaining_size":"0.0279"}
{"type":"done","side":"buy","product_id":"BTC-USD","time":"2020-06-30T19:11:46.213390Z","sequence":180755401,"order_id":"f977f72f-f762-4ce7-b411-a9a1928b17d9","reason":"canceled","price":"9105.54","remaining_size":"1.596"}
{"type":"received","side":"sell","product_id":"BTC-USD","time":"2020-06-30T19:11:46.609863Z","sequence":180755402,"order_id":"60625ed0-0ca7-4fd0-ba38-e9a7e72a1175","order_type":"limit","size":"0.544","price":"9115.29","client_oid":""}
{"type":"match","side":"buy","product_id":"BTC-USD","time":"2020-06-30T19:11:46.609863Z","sequence":180755403,"trade_id":14587462,"maker_order_id":"91b59a7c-6a07-4039-9536-21daf3cb3282","taker_order_id":"60625ed0-0ca7-4fd0-ba38-e9a7e72a1175","size":"0.544","price":"9120.8"}
{"type":"done","side":"sell","product_id":"BTC-USD","time":"2020-06-30T19:11:46.609863Z","sequence":180755404,"order_id":"60625ed0-0ca7-4fd0-ba38-e9a7e72a1175","reason":"filled","price":"9115.29","remaining_size":"0"}
{"type":"heartbeat","last_trade_id":0,"product_id":"BTC-USD","sequence":180755404,"time":"2020-06-30T19:11:46.734985Z"}
{"type":"received","side":"buy","product_id":"BTC-USD","time":"2020-06-30T19:11:46.957464Z","sequence":180755405,"order_id":"be6e2a1f-2bc5-49a7-9a34-ad622883e02e","order_type":"limit","size":"0.004","price":"8930.72","client_oid":""}
{"type":"open","side":"buy","product_id":"BTC-USD","time":"2020-06-30T19:11:46.957464Z","sequence":180755406,"price":"8930.72","order_id":"be6e2a1f-2bc5-49a7-9a34-ad622883e02e","remaining_size":"0.004"}
{"type":"done","side":"sell","product_id":"BTC-USD","time":"2020-06-30T19:11:47.032312Z","sequence":180755407,"order_id":"d4a676ea-4eca-476e-beba-8286402eda88","reason":"canceled","price":"9144.65","remaining_size":"4.1202"}
{"type":"done","side":"sell","product_id":"BTC-USD","time":"2020-06-30T19:11:47.042797Z","sequence":180755408,"order_id":"42c688af-a91b-44bd-bb4b-fcab7522e175","reason":"canceled","price":"9132.09","remaining_size":"1.0725"}
{"type":"received","side":"buy","product_id":"BTC-USD","time":"2020-06-30T19:11:47.213823Z","sequence":180755409,"order_id":"6180a1b0-d668-4821-a838-511c99d91858","order_type":"limit","size":"0.0967","price":"9075.69","client_oid":""}
{"type":"open","side":"buy","product_id":"BTC-USD","time":"2020-06-30T19:11:47.213823Z","sequence":180755410,"price":"9075.69","order_id":"6180a1b0-d668-4821-a838-511c99d91858","remaining_size":"0.0967"}
{"type":"done","side":"buy","product_id":"BTC-USD","time":"2020-06-30T19:11:47.361936Z","sequence":180755411,"order_id":"16358797-6cd8-4e6e-ba45-b4fae3b715b7","reason":"canceled","price":"9051.56","remaining_size":"0.0879"}
{"type":"received","side":"sell","product_id":"BTC-USD","time":"2020-06-30T19:11:47.505576Z","sequence":180755412,"order_id":"6f03d0a5-c12f-46a3-be15-0b1c1535184d","order_type":"limit","size":"0.003","price":"9283.64","client_oid":""}
{"type":"open","side":"sell","product_id":"BTC-USD","time":"2020-06-30T19:11:47.505576Z","sequence":180755413,"price":"9283.64","order_id":"6f03d0a5-c12f-46a3-be15-0b1c1535184d","remaining_size":"0.003"}
{"type":"done","side":"buy","product_id":"BTC-USD","time":"2020-06-30T19:11:47.629669Z","sequence":180755414,"order_id":"383ae691-f768-4639-afea-e4457f614d60","reason":"canceled","price":"9105.31","remaining_size":"0.75"}
{"type":"heartbeat","last_trade_id":0,"product_id":"BTC-USD","sequence":180755414,"time":"2020-06-30T19:11:47.735062Z"}
{"type":"received","side":"buy","product_id":"BTC-USD","time":"2020-06-30T19:11:48.053817Z","sequence":180755415,"order_id":"70ba6732-e349-40e3-b9cf-dd423dc36d60","order_type":"limit","size":"9.4692","price":"9110.07","client_oid":""}
{"type":"open","side":"buy","product_id":"BTC-USD","time":"2020-06-30T19:11:48.053817Z","sequence":180755416,"price":"9110.07","order_id":"70ba6732-e349-40e3-b9cf-dd423dc36d60","remaining_size":"9.4692"}
{"type":"done","side":"buy","product_id":"BTC-USD","time":"2020-06-30T19:11:48.496305Z","sequence":180755417,"order_id":"765d004e-5ebd-46c8-a8f8-e32f766aa270","reason":"canceled","price":"9070.69","remaining_size":"0.0692"}
{"type":"heartbeat","last_trade_id":0,"product_id":"BTC-USD","sequence":180755417,"time":"2020-06-30T19:11:48.734983Z"}
{"type":"received","side":"buy","product_id":"BTC-USD","time":"2020-06-30T19:11:49.228458Z","sequence":180755418,"order_id":"4db661fb-3b44-45c6-8b29-0c3d68ea6539","order_type":"limit","size":"0.25","price":"4560","client_oid":""}
{"type":"open","side":"buy","product_id":"BTC-USD","time":"2020-06-30T19:11:49.228458Z","sequence":180755419,"price":"4560","order_id":"4db661fb-3b44-45c6-8b29-0c3d68ea6539","remaining_size":"0.25"}
{"type":"received","side":"buy","product_id":"BTC-USD","time":"2020-06-30T19:11:49.269944Z","sequence":180755420,"order_id":"8884ccb0-65f2-4b7c-aacb-e365cc1a5d82","order_type":"limit","size":"0.039","price":"9073.48","client_oid":""}
{"type":"open","side":"buy","product_id":"BTC-USD","time":"2020-06-30T19:11:49.269944Z","sequence":180755421,"price":"9073.48","order_id":"8884ccb0-65f2-4b7c-aacb-e365cc1a5d82","remaining_size":"0.039"}
{"type":"done","side":"buy","product_id":"BTC-USD","time":"2020-06-30T19:11:49.459625Z","sequence":180755422,"order_id":"c59654b7-665b-44ed-a670-584d8cff7216","reason":"canceled","price":"9106.26","remaining_size":"0.1038"}
{"type":"done","side":"buy","product_id":"BTC-USD","time":"2020-06-30T19:11:49.469535Z","sequence":180755423,"order_id":"d6710bc5-0c00-4dbb-84af-d0932635fa86","reason":"canceled","price":"9085.81","remaining_size":"0.0788"}
{"type":"done","side":"buy","product_id":"BTC-USD","time":"2020-06-30T19:11:49.472695Z","sequence":180755424,"order_id":"58c97195-ebb4-4802-9448-546790ba6eab","reason":"canceled","price":"9074.68","remaining_size":"0.0692"}
{"type":"done","side":"buy","product_id":"BTC-USD","time":"2020-06-30T19:11:49.735908Z","sequence":180755425,"order_id":"4db661fb-3b44-45c6-8b29-0c3d68ea6539","reason":"canceled","price":"4560","remaining_size":"0.25"}
{"type":"heartbeat","last_trade_id":0,"product_id":"BTC-USD","sequence":180755425,"time":"2020-06-30T19:11:49.735059Z"}
{"type":"received","side":"buy","product_id":"BTC-USD","time":"2020-06-30T19:11:50.101851Z","sequence":180755426,"order_id":"8251294c-27c6-4188-aa73-99d111f48014","order_type":"limit","size":"0.0279","price":"9081.45","client_oid":""}
{"type":"open","side":"buy","product_id":"BTC-USD","time":"2020-06-30T19:11:50.101851Z","sequence":180755427,"price":"9081.45","order_id":"8251294c-27c6-4188-aa73-99d111f48014","remaining_size":"0.0279"}
{"type":"received","side":"buy","product_id":"BTC-USD","time":"2020-06-30T19:11:50.392452Z","sequence":180755428,"order_id":"96aef06e-ac96-471c-81ae-10dc0731a5f4","order_type":"limit","size":"0.0967","price":"9071.82","client_oid":""}
{"type":"open","side":"buy","product_id":"BTC-USD","time":"2020-06-30T19:11:50.392452Z","sequence":180755429,"price":"9071.82","order_id":"96aef06e-ac96-471c-81ae-10dc0731a5f4","remaining_size":"0.0967"}
{"type":"done","side":"buy","product_id":"BTC-USD","time":"2020-06-30T19:11:50.588284Z","sequence":180755430,"order_id":"be6e2a1f-2bc5-49a7-9a34-ad622883e02e","reason":"canceled","price":"8930.72","remaining_size":"0.004"}
{"type":"heartbeat","last_trade_id":0,"product_id":"BTC-USD","sequence":180755430,"time":"2020-06-30T19:11:50.735074Z"}
{"type":"done","side":"buy","product_id":"BTC-USD","time":"2020-06-30T19:11:50.824767Z","sequence":180755431,"order_id":"108ece61-c435-4021-9add-474ef56d6a28","reason":"canceled","price":"9076.36","remaining_size":"0.0235"}
{"type":"received","side":"buy","product_id":"BTC-USD","time":"2020-06-30T19:11:51.238652Z","sequence":180755432,"order_id":"1ea9354d-c3e9-4c5d-a2e6-875eb98a2c7c","order_type":"limit","size":"0.0737","price":"9079.19","client_oid":""}
{"type":"open","side":"buy","product_id":"BTC-USD","time":"2020-06-30T19:11:51.238652Z","sequence":180755433,"price":"9079.19","order_id":"1ea9354d-c3e9-4c5d-a2e6-875eb98a2c7c","remaining_size":"0.0737"}
{"type":"received","side":"buy","product_id":"BTC-USD","time":"2020-06-30T19:11:51.310266Z","sequence":180755434,"order_id":"7e27ac79-c46c-4eb5-b5d1-136d673b53a9","order_type":"limit","size":"0.25","price":"4560","client_oid":""}
{"type":"open","side":"buy","product_id":"BTC-USD","time":"2020-06-30T19:11:51.310266Z","sequence":180755435,"price":"4560","order_id":"7e27ac79-c46c-4eb5-b5d1-136d673b53a9","remaining_size":"0.25"}
{"type":"done","side":"buy","product_id":"BTC-USD","time":"2020-06-30T19:11:51.398086Z","sequence":180755436,"order_id":"7e27ac79-c46c-4eb5-b5d1-136d673b53a9","reason":"canceled","price":"4560","remaining_size":"0.25"}
{"type":"received","side":"buy","product_id":"BTC-USD","time":"2020-06-30T19:11:51.500936Z","sequence":180755437,"order_id":"8a7013fa-126b-4111-aa71-5a5588cdca57","order_type":"limit","size":"0.0165","price":"9090.34","client_oid":""}
{"type":"open","side":"buy","product_id":"BTC-USD","time":"2020-06-30T19:11:51.500936Z","sequence":180755438,"price":"9090.34","order_id":"8a7013fa-126b-4111-aa71-5a5588cdca57","remaining_size":"0.0165"}
{"type":"heartbeat","last_trade_id":0,"product_id":"BTC-USD","sequence":180755438,"time":"2020-06-30T19:11:51.735069Z"}
{"type":"heartbeat","last_trade_id":0,"product_id":"BTC-USD","sequence":180755438,"time":"2020-06-30T19:11:52.735030Z"}
{"type":"received","side":"buy","product_id":"BTC-USD","time":"2020-06-30T19:11:53.154342Z","sequence":180755439,"order_id":"ddf6e9c9-a6d9-4682-a5d6-13b47f7138fe","order_type":"limit","size":"0.9","price":"9109.07","client_oid":""}
{"type":"open","side":"buy","product_id":"BTC-USD","time":"2020-06-30T19:11:53.154342Z","sequence":180755440,"price":"9109.07","order_id":"ddf6e9c9-a6d9-4682-a5d6-13b47f7138fe","remaining_size":"0.9"}
{"type":"done","side":"buy","product_id":"BTC-USD","time":"2020-06-30T19:11:53.368390Z","sequence":180755441,"order_id":"8884ccb0-65f2-4b7c-aacb-e365cc1a5d82","reason":"canceled","price":"9073.48","remaining_size":"0.039"}
{"type":"done","side":"buy","product_id":"BTC-USD","time":"2020-06-30T19:11:53.369060Z","sequence":180755442,"order_id":"41162654-2bd2-4eb0-8123-867d2bafa2c7","reason":"canceled","price":"9075.13","remaining_size":"0.0692"}
{"type":"done","side":"buy","product_id":"BTC-USD","time":"2020-06-30T19:11:53.375533Z","sequence":180755443,"order_id":"e30844ec-df48-4841-8ca5-702b895cbe81","reason":"canceled","price":"9073.58","remaining_size":"0.0692"}
{"type":"received","side":"buy","product_id":"BTC-USD","time":"2020-06-30T19:11:53.428041Z","sequence":180755444,"order_id":"18202f4a-9909-4360-bc19-4367dcdcf040","order_type":"limit","size":"1","price":"9109.2","client_oid":""}
{"type":"open","side":"buy","product_id":"BTC-USD","time":"2020-06-30T19:11:53.428041Z","sequence":180755445,"price":"9109.2","order_id":"18202f4a-9909-4360-bc19-4367dcdcf040","remaining_size":"1"}
{"type":"received","side":"sell","product_id":"BTC-USD","time":"2020-06-30T19:11:53.471415Z","sequence":180755446,"order_id":"e5258209-928d-4087-9138-63298795a746","order_type":"limit","size":"0.25","price":"18240","client_oid":""}
{"type":"open","side":"sell","product_id":"BTC-USD","time":"2020-06-30T19:11:53.471415Z","sequence":180755447,"price":"18240","order_id":"e5258209-928d-4087-9138-63298795a746","remaining_size":"0.25"}
{"type":"done","side":"buy","product_id":"BTC-USD","time":"2020-06-30T19:11:53.617857Z","sequence":180755448,"order_id":"0262bdb8-b739-4acf-b64d-380dba8ff71c","reason":"canceled","price":"9092.85","remaining_size":"0.0263"}
{"type":"heartbeat","last_trade_id":0,"product_id":"BTC-USD","sequence":180755448,"time":"2020-06-30T19:11:53.735070Z"}
{"type":"done","side":"sell","product_id":"BTC-USD","time":"2020-06-30T19:11:53.963202Z","sequence":180755449,"order_id":"e5258209-928d-4087-9138-63298795a746","reason":"canceled","price":"18240","remaining_size":"0.25"}
{"type":"heartbeat","last_trade_id":0,"product_id":"BTC-USD","sequence":180755449,"time":"2020-06-30T19:11:54.735073Z"}
{"type":"received","side":"sell","product_id":"BTC-USD","time":"2020-06-30T19:11:54.877363Z","sequence":180755450,"order_id":"771c1bb0-bb55-449d-bfa7-4e6f3148eb7a","order_type":"limit","size":"0.0659","price":"9112.62","client_oid":""}
{"type":"match","side":"buy","product_id":"BTC-USD","time":"2020-06-30T19:11:54.877363Z","sequence":180755451,"trade_id":14587463,"maker_order_id":"91b59a7c-6a07-4039-9536-21daf3cb3282","taker_order_id":"771c1bb0-bb55-449d-bfa7-4e6f3148eb7a","size":"0.0659","price":"9120.8"}
{"type":"done","side":"sell","product_id":"BTC-USD","time":"2020-06-30T19:11:54.877363Z","sequence":180755452,"order_id":"771c1bb0-bb55-449d-bfa7-4e6f3148eb7a","reason":"filled","price":"9112.62","remaining_size":"0"}
{"type":"received","side":"buy","product_id":"BTC-USD","time":"2020-06-30T19:11:55.162350Z","sequence":180755453,"order_id":"5f26e095-4094-4dbd-94f4-ec35eb294830","order_type":"limit","size":"0.0967","price":"9081.27","client_oid":""}
{"type":"open","side":"buy","product_id":"BTC-USD","time":"2020-06-30T19:11:55.162350Z","sequence":180755454,"price":"9081.27","order_id":"5f26e095-4094-4dbd-94f4-ec35eb294830","remaining_size":"0.0967"}
{"type":"received","side":"sell","product_id":"BTC-USD","time":"2020-06-30T19:11:55.563758Z","sequence":180755455,"order_id":"f4b49976-0b39-4e65-89b1-9305865c78b1","order_type":"limit","size":"0.25","price":"18240","client_oid":""}
{"type":"open","side":"sell","product_id":"BTC-USD","time":"2020-06-30T19:11:55.563758Z","sequence":180755456,"price":"18240","order_id":"f4b49976-0b39-4e65-89b1-9305865c78b1","remaining_size":"0.25"}
{"type":"done","side":"buy","product_id":"BTC-USD","time":"2020-06-30T19:11:55.625427Z","sequence":180755457,"order_id":"6a29d676-c866-4d0c-b839-72b08b93a2e1","reason":"canceled","price":"9072.26","remaining_size":"0.1087"}
{"type":"done","side":"buy","product_id":"BTC-USD","time":"2020-06-30T19:11:55.626271Z","sequence":180755458,"order_id":"8b87b348-30e8-474b-931b-3779e7630d20","reason":"canceled","price":"9072.69","remaining_size":"0.0279"}
{"type":"done","side":"sell","product_id":"BTC-USD","time":"2020-06-30T19:11:55.642836Z","sequence":180755459,"order_id":"f4b49976-0b39-4e65-89b1-9305865c78b1","reason":"canceled","price":"18240","remaining_size":"0.25"}
{"type":"heartbeat","last_trade_id":0,"product_id":"BTC-USD","sequence":180755459,"time":"2020-06-30T19:11:55.735087Z"}
{"type":"received","side":"buy","product_id":"BTC-USD","time":"2020-06-30T19:11:55.752108Z","sequence":180755460,"order_id":"509f2b6c-0e23-4dd9-837f-7b5c380f27c2","order_type":"limit","size":"1.5","price":"9107.19","client_oid":""}
{"type":"open","side":"buy","product_id":"BTC-USD","time":"2020-06-30T19:11:55.752108Z","sequence":180755461,"price":"9107.19","order_id":"509f2b6c-0e23-4dd9-837f-7b5c380f27c2","remaining_size":"1.5"}
{"type":"done","side":"buy","product_id":"BTC-USD","time":"2020-06-30T19:11:55.928385Z","sequence":180755462,"order_id":"8a7013fa-126b-4111-aa71-5a5588cdca57","reason":"canceled","price":"9090.34","remaining_size":"0.0165"}
{"type":"received","side":"sell","product_id":"BTC-USD","time":"2020-06-30T19:11:56.021752Z","sequence":180755463,"order_id":"3e6699c2-5efb-46de-b750-819170c68222","order_type":"limit","size":"1.691","price":"9110.91","client_oid":""}
{"type":"match","side":"buy","product_id":"BTC-USD","time":"2020-06-30T19:11:56.021752Z","sequence":180755464,"trade_id":14587464,"maker_order_id":"91b59a7c-6a07-4039-9536-21daf3cb3282","taker_order_id":"3e6699c2-5efb-46de-b750-819170c68222","size":"1.691","price":"9120.8"}
{"type":"done","side":"sell","product_id":"BTC-USD","time":"2020-06-30T19:11:56.021752Z","sequence":180755465,"order_id":"3e6699c2-5efb-46de-b750-819170c68222","reason":"filled","price":"9110.91","remaining_size":"0"}
{"type":"done","side":"sell","product_id":"BTC-USD","time":"2020-06-30T19:11:56.469711Z","sequence":180755466,"order_id":"5d105483-4267-4231-9094-f40f4b1d752b","reason":"canceled","price":"9157.93","remaining_size":"0.0676"}
{"type":"done","side":"sell","product_id":"BTC-USD","time":"2020-06-30T19:11:56.471187Z","sequence":180755467,"order_id":"6f03d0a5-c12f-46a3-be15-0b1c1535184d","reason":"canceled","price":"9283.64","remaining_size":"0.003"}
{"type":"received","side":"buy","product_id":"BTC-USD","time":"2020-06-30T19:11:56.558710Z","sequence":180755468,"order_id":"88847cd2-703a-44fd-81e0-3d5655a63c0e","order_type":"limit","size":"0.1333","price":"9071.02","client_oid":""}
{"type":"open","side":"buy","product_id":"BTC-USD","time":"2020-06-30T19:11:56.558710Z","sequence":180755469,"price":"9071.02","order_id":"88847cd2-703a-44fd-81e0-3d5655a63c0e","remaining_size":"0.1333"}
{"type":"received","side":"buy","product_id":"BTC-USD","time":"2020-06-30T19:11:56.714823Z","sequence":180755470,"order_id":"d3500635-9111-4f03-8c80-f3a99181622f","order_type":"limit","size":"5.9645","price":"9110.07","client_oid":""}
{"type":"open","side":"buy","product_id":"BTC-USD","time":"2020-06-30T19:11:56.714823Z","sequence":180755471,"price":"9110.07","order_id":"d3500635-9111-4f03-8c80-f3a99181622f","remaining_size":"5.9645"}
{"type":"heartbeat","last_trade_id":0,"product_id":"BTC-USD","sequence":180755471,"time":"2020-06-30T19:11:56.735073Z"}
{"type":"received","side":"sell","product_id":"BTC-USD","time":"2020-06-30T19:11:57.113082Z","sequence":180755472,"order_id":"f6ecc11f-b999-4cbd-94af-770970617d4c","order_type":"limit","size":"0.0278","price":"9157.39","client_oid":""}
{"type":"open","side":"sell","product_id":"BTC-USD","time":"2020-06-30T19:11:57.113082Z","sequence":180755473,"price":"9157.39","order_id":"f6ecc11f-b999-4cbd-94af-770970617d4c","remaining_size":"0.0278"}
{"type":"done","side":"sell","product_id":"BTC-USD","time":"2020-06-30T19:11:57.327004Z","sequence":180755474,"order_id":"327f4836-854c-4f28-8d25-1373d48d114a","reason":"canceled","price":"9158.2","remaining_size":"0.069"}
{"type":"received","side":"sell","product_id":"BTC-USD","time":"2020-06-30T19:11:57.379082Z","sequence":180755475,"order_id":"8d31b703-b1e7-4c4d-8942-a5a38dafd35b","order_type":"limit","size":"0.2466","price":"9132.88","client_oid":""}
{"type":"open","side":"sell","product_id":"BTC-USD","time":"2020-06-30T19:11:57.379082Z","sequence":180755476,"price":"9132.88","order_id":"8d31b703-b1e7-4c4d-8942-a5a38dafd35b","remaining_size":"0.2466"}
{"type":"received","side":"buy","product_id":"BTC-USD","time":"2020-06-30T19:11:57.659567Z","sequence":180755477,"order_id":"aed32383-6b0a-439a-b6ae-7e566c163c22","order_type":"limit","size":"0.063","price":"9076.7","client_oid":""}
{"type":"open","side":"buy","product_id":"BTC-USD","time":"2020-06-30T19:11:57.659567Z","sequence":180755478,"price":"9076.7","order_id":"aed32383-6b0a-439a-b6ae-7e566c163c22","remaining_size":"0.063"}
{"type":"heartbeat","last_trade_id":0,"product_id":"BTC-USD","sequence":180755478,"time":"2020-06-30T19:11:57.735063Z"}
{"type":"received","side":"sell","product_id":"BTC-USD","time":"2020-06-30T19:11:57.939354Z","sequence":180755479,"order_id":"4f644635-5202-459d-a8d7-295e0b9d8172","order_type":"limit","size":"1.2505","price":"9130.16","client_oid":""}
{"type":"open","side":"sell","product_id":"BTC-USD","time":"2020-06-30T19:11:57.939354Z","sequence":180755480,"price":"9130.16","order_id":"4f644635-5202-459d-a8d7-295e0b9d8172","remaining_size":"1.2505"}
{"type":"received","side":"buy","product_id":"BTC-USD","time":"2020-06-30T19:11:58.505143Z","sequence":180755481,"order_id":"06e8a9fd-e81b-4ac1-af55-31cbdf41f10b","order_type":"limit","size":"0.0551","price":"9070.67","client_oid":""}
{"type":"open","side":"buy","product_id":"BTC-USD","time":"2020-06-30T19:11:58.505143Z","sequence":180755482,"price":"9070.67","order_id":"06e8a9fd-e81b-4ac1-af55-31cbdf41f10b","remaining_size":"0.0551"}
{"type":"heartbeat","last_trade_id":0,"product_id":"BTC-USD","sequence":180755482,"time":"2020-06-30T19:11:58.735071Z"}
{"type":"received","side":"buy","product_id":"BTC-USD","time":"2020-06-30T19:11:58.785534Z","sequence":180755483,"order_id":"3e3452d1-117b-4538-b98d-8b4a6e24aa26","order_type":"limit","size":"0.0659","price":"9107.79","client_oid":""}
{"type":"open","side":"buy","product_id":"BTC-USD","time":"2020-06-30T19:11:58.785534Z","sequence":180755484,"price":"9107.79","order_id":"3e3452d1-117b-4538-b98d-8b4a6e24aa26","remaining_size":"0.0659"}
{"type":"done","side":"buy","product_id":"BTC-USD","time":"2020-06-30T19:11:58.825795Z","sequence":180755485,"order_id":"e790b7fa-354c-48f6-bff7-3f77d0b031d0","reason":"canceled","price":"8895.64","remaining_size":"0.04623953"}
{"type":"done","side":"buy","product_id":"BTC-USD","time":"2020-06-30T19:11:58.962172Z","sequence":180755486,"order_id":"70ba6732-e349-40e3-b9cf-dd423dc36d60","reason":"canceled","price":"9110.07","remaining_size":"9.4692"}
{"type":"received","side":"buy","product_id":"BTC-USD","time":"2020-06-30T19:11:59.045206Z","sequence":180755487,"order_id":"44124a07-1968-4159-81ea-510de5c72017","order_type":"limit","size":"0.01","price":"100","client_oid":"7e56a406-b5fe-40d6-b150-c960f75f81e6"}
{"type":"open","side":"buy","product_id":"BTC-USD","time":"2020-06-30T19:11:59.045206Z","sequence":180755488,"price":"100","order_id":"44124a07-1968-4159-81ea-510de5c72017","remaining_size":"0.01"}
{"type":"done","side":"buy","product_id":"BTC-USD","time":"2020-06-30T19:11:59.051353Z","sequence":180755489,"order_id":"44124a07-1968-4159-81ea-510de5c72017","reason":"canceled","price":"100","remaining_size":"0.01"}
{"type":"received","side":"buy","product_id":"BTC-USD","time":"2020-06-30T19:11:59.110941Z","sequence":180755490,"order_id":"2129da63-d170-4bed-a8bc-52db9a261cf2","order_type":"limit","size":"0.04634155","price":"8894.82","client_oid":""}
{"type":"open","side":"buy","product_id":"BTC-USD","time":"2020-06-30T19:11:59.110941Z","sequence":180755491,"price":"8894.82","order_id":"2129da63-d170-4bed-a8bc-52db9a261cf2","remaining_size":"0.04634155"}
{"type":"done","side":"sell","product_id":"BTC-USD","time":"2020-06-30T19:11:59.372374Z","sequence":180755492,"order_id":"6a7fe453-7199-4584-ac02-d22747a1736b","reason":"canceled","price":"9435.21","remaining_size":"0.00699029"}
{"type":"heartbeat","last_trade_id":0,"product_id":"BTC-USD","sequence":180755492,"time":"2020-06-30T19:11:59.735073Z"}
{"type":"received","side":"buy","product_id":"BTC-USD","time":"2020-06-30T19:11:59.889122Z","sequence":180755493,"order_id":"02a1c224-c548-4b28-8e0d-08e8e0dd0d39","order_type":"limit","size":"0.0293","price":"9089.1","client_oid":""}
{"type":"open","side":"buy","product_id":"BTC-USD","time":"2020-06-30T19:11:59.889122Z","sequence":180755494,"price":"9089.1","order_id":"02a1c224-c548-4b28-8e0d-08e8e0dd0d39","remaining_size":"0.0293"}
{"type":"received","side":"sell","product_id":"BTC-USD","time":"2020-06-30T19:11:59.924091Z","sequence":180755495,"order_id":"31cdeae0-dc8e-4e9f-a855-60668a893061","order_type":"limit","size":"0.00709009","price":"9436.09","client_oid":""}
{"type":"open","side":"sell","product_id":"BTC-USD","time":"2020-06-30T19:11:59.924091Z","sequence":180755496,"price":"9436.09","order_id":"31cdeae0-dc8e-4e9f-a855-60668a893061","remaining_size":"0.00709009"}
{"type":"received","side":"sell","product_id":"BTC-USD","time":"2020-06-30T19:12:00.163131Z","sequence":180755497,"order_id":"3982fbba-50eb-438c-b5d4-8410823a8b18","order_type":"limit","size":"1.5336","price":"9130.16","client_oid":""}
{"type":"open","side":"sell","product_id":"BTC-USD","time":"2020-06-30T19:12:00.163131Z","sequence":180755498,"price":"9130.16","order_id":"3982fbba-50eb-438c-b5d4-8410823a8b18","remaining_size":"1.5336"}
{"type":"done","side":"buy","product_id":"BTC-USD","time":"2020-06-30T19:12:00.326010Z","sequence":180755499,"order_id":"06e8a9fd-e81b-4ac1-af55-31cbdf41f10b","reason":"canceled","price":"9070.67","remaining_size":"0.0551"}
{"type":"done","side":"buy","product_id":"BTC-USD","time":"2020-06-30T19:12:00.328338Z","sequence":180755500,"order_id":"ddf6e9c9-a6d9-4682-a5d6-13b47f7138fe","reason":"canceled","price":"9109.07","remaining_size":"0.9"}
{"type":"done","side":"buy","product_id":"BTC-USD","time":"2020-06-30T19:12:00.341601Z","sequence":180755501,"order_id":"18202f4a-9909-4360-bc19-4367dcdcf040","reason":"canceled","price":"9109.2","remaining_size":"1"}
{"type":"done","side":"buy","product_id":"BTC-USD","time":"2020-06-30T19:12:00.346275Z","sequence":180755502,"order_id":"6180a1b0-d668-4821-a838-511c99d91858","reason":"canceled","price":"9075.69","remaining_size":"0.0967"}
{"type":"heartbeat","last_trade_id":0,"product_id":"BTC-USD","sequence":180755502,"time":"2020-06-30T19:12:00.735067Z"}
{"type":"received","side":"buy","product_id":"BTC-USD","time":"2020-06-30T19:12:01.031086Z","sequence":180755503,"order_id":"81963809-5797-4940-842b-24965837a910","order_type":"limit","size":"0.001","price":"8938.29","client_oid":""}
{"type":"open","side":"buy","product_id":"BTC-USD","time":"2020-06-30T19:12:01.031086Z","sequence":180755504,"price":"8938.29","order_id":"81963809-5797-4940-842b-24965837a910","remaining_size":"0.001"}
{"type":"done","side":"buy","product_id":"BTC-USD","time":"2020-06-30T19:12:01.507984Z","sequence":180755505,"order_id":"3e3452d1-117b-4538-b98d-8b4a6e24aa26","reason":"canceled","price":"9107.79","remaining_size":"0.0659"}
{"type":"received","side":"buy","product_id":"BTC-USD","time":"2020-06-30T19:12:01.607456Z","sequence":180755506,"order_id":"fc162a26-95c0-4c60-ac98-1ed88f8d73c3","order_type":"limit","size":"0.0223","price":"9096.94","client_oid":""}
{"type":"open","side":"buy","product_id":"BTC-USD","time":"2020-06-30T19:12:01.607456Z","sequence":180755507,"price":"9096.94","order_id":"fc162a26-95c0-4c60-ac98-1ed88f8d73c3","remaining_size":"0.0223"}
{"type":"heartbeat","last_trade_id":0,"product_id":"BTC-USD","sequence":180755507,"time":"2020-06-30T19:12:01.735119Z"}
{"type":"received","side":"sell","product_id":"BTC-USD","time":"2020-06-30T19:12:01.901623Z","sequence":180755508,"order_id":"3c2dbcc5-a692-4795-a764-624bcf11fd93","order_type":"limit","size":"0.3293","price":"9112.84","client_oid":""}
{"type":"match","side":"buy","product_id":"BTC-USD","time":"2020-06-30T19:12:01.901623Z","sequence":180755509,"trade_id":14587465,"maker_order_id":"91b59a7c-6a07-4039-9536-21daf3cb3282","taker_order_id":"3c2dbcc5-a692-4795-a764-624bcf11fd93","size":"0.3293","price":"9120.8"}
{"type":"done","side":"sell","product_id":"BTC-USD","time":"2020-06-30T19:12:01.901623Z","sequence":180755510,"order_id":"3c2dbcc5-a692-4795-a764-624bcf11fd93","reason":"filled","price":"9112.84","remaining_size":"0"}
{"type":"done","side":"buy","product_id":"BTC-USD","time":"2020-06-30T19:12:02.033946Z","sequence":180755511,"order_id":"aed32383-6b0a-439a-b6ae-7e566c163c22","reason":"canceled","price":"9076.7","remaining_size":"0.063"}
{"type":"done","side":"buy","product_id":"BTC-USD","time":"2020-06-30T19:12:02.041696Z","sequence":180755512,"order_id":"730d1e66-937d-42b1-945d-c6cd76a00302","reason":"canceled","price":"9081.12","remaining_size":"0.01"}
{"type":"received","side":"buy","product_id":"BTC-USD","time":"2020-06-30T19:12:02.405446Z","sequence":180755513,"order_id":"e5e5285f-2509-4f09-a974-bc8404db0e2c","order_type":"limit","size":"0.035","price":"9104.34","client_oid":""}
{"type":"open","side":"buy","product_id":"BTC-USD","time":"2020-06-30T19:12:02.405446Z","sequence":180755514,"price":"9104.34","order_id":"e5e5285f-2509-4f09-a974-bc8404db0e2c","remaining_size":"0.035"}
{"type":"heartbeat","last_trade_id":0,"product_id":"BTC-USD","sequence":180755514,"time":"2020-06-30T19:12:02.735114Z"}
{"type":"received","side":"sell","product_id":"BTC-USD","time":"2020-06-30T19:12:02.942924Z","sequence":180755515,"order_id":"eeb58d42-e833-47a4-8f83-ee99ddb434ed","order_type":"limit","size":"0.069","price":"9156.85","client_oid":""}
{"type":"open","side":"sell","product_id":"BTC-USD","time":"2020-06-30T19:12:02.942924Z","sequence":180755516,"price":"9156.85","order_id":"eeb58d42-e833-47a4-8f83-ee99ddb434ed","remaining_size":"0.069"}
{"type":"received","side":"sell","product_id":"BTC-USD","time":"2020-06-30T19:12:03.220986Z","sequence":180755517,"order_id":"6ba5bea6-847d-4312-9597-dabd6ef2388c","order_type":"limit","size":"0.069","price":"9156.58","client_oid":""}
{"type":"open","side":"sell","product_id":"BTC-USD","time":"2020-06-30T19:12:03.220986Z","sequence":180755518,"price":"9156.58","order_id":"6ba5bea6-847d-4312-9597-dabd6ef2388c","remaining_size":"0.069"}
{"type":"done","side":"sell","product_id":"BTC-USD","time":"2020-06-30T19:12:03.638597Z","sequence":180755519,"order_id":"f6ecc11f-b999-4cbd-94af-770970617d4c","reason":"canceled","price":"9157.39","remaining_size":"0.0278"}
{"type":"done","side":"sell","product_id":"BTC-USD","time":"2020-06-30T19:12:03.701580Z","sequence":180755520,"order_id":"3982fbba-50eb-438c-b5d4-8410823a8b18","reason":"canceled","price":"9130.16","remaining_size":"1.5336"}
{"type":"heartbeat","last_trade_id":0,"product_id":"BTC-USD","sequence":180755520,"time":"2020-06-30T19:12:03.735118Z"}
{"type":"received","side":"sell","product_id":"BTC-USD","time":"2020-06-30T19:12:04.412214Z","sequence":180755521,"order_id":"575289e0-3bc6-4fcf-bdd4-1ce39ef5ee3b","order_type":"limit","size":"0.0546","price":"9152.59","client_oid":""}
{"type":"open","side":"sell","product_id":"BTC-USD","time":"2020-06-30T19:12:04.412214Z","sequence":180755522,"price":"9152.59","order_id":"575289e0-3bc6-4fcf-bdd4-1ce39ef5ee3b","remaining_size":"0.0546"}
{"type":"received","side":"buy","product_id":"BTC-USD","time":"2020-06-30T19:12:04.663682Z","sequence":180755523,"order_id":"3cc220c9-63e4-4de9-bae0-90ab7e9e9a80","order_type":"limit","size":"0.0395","price":"9079.57","client_oid":""}
{"type":"open","side":"buy","product_id":"BTC-USD","time":"2020-06-30T19:12:04.663682Z","sequence":180755524,"price":"9079.57","order_id":"3cc220c9-63e4-4de9-bae0-90ab7e9e9a80","remaining_size":"0.0395"}
{"type":"heartbeat","last_trade_id":0,"product_id":"BTC-USD","sequence":180755524,"time":"2020-06-30T19:12:04.735134Z"}
{"type":"done","side":"sell","product_id":"BTC-USD","time":"2020-06-30T19:12:04.841506Z","sequence":180755525,"order_id":"4f644635-5202-459d-a8d7-295e0b9d8172","reason":"canceled","price":"9130.16","remaining_size":"1.2505"}
{"type":"received","side":"sell","product_id":"BTC-USD","time":"2020-06-30T19:12:04.949092Z","sequence":180755526,"order_id":"3ee65cad-ec4b-48c9-9a36-52d537dea44c","order_type":"limit","size":"0.0546","price":"9151.21","client_oid":""}
{"type":"open","side":"sell","product_id":"BTC-USD","time":"2020-06-30T19:12:04.949092Z","sequence":180755527,"price":"9151.21","order_id":"3ee65cad-ec4b-48c9-9a36-52d537dea44c","remaining_size":"0.0546"}
{"type":"done","side":"buy","product_id":"BTC-USD","time":"2020-06-30T19:12:05.108897Z","sequence":180755528,"order_id":"88847cd2-703a-44fd-81e0-3d5655a63c0e","reason":"canceled","price":"9071.02","remaining_size":"0.1333"}
{"type":"received","side":"buy","product_id":"BTC-USD","time":"2020-06-30T19:12:05.273902Z","sequence":180755529,"order_id":"7133d0f5-23b5-4f7a-a56c-cc2daa43994c","order_type":"limit","size":"0.1899","price":"9105.37","client_oid":""}
{"type":"open","side":"buy","product_id":"BTC-USD","time":"2020-06-30T19:12:05.273902Z","sequence":180755530,"price":"9105.37","order_id":"7133d0f5-23b5-4f7a-a56c-cc2daa43994c","remaining_size":"0.1899"}
{"type":"done","side":"buy","product_id":"BTC-USD","time":"2020-06-30T19:12:05.486665Z","sequence":180755531,"order_id":"e5e5285f-2509-4f09-a974-bc8404db0e2c","reason":"canceled","price":"9104.34","remaining_size":"0.035"}
{"type":"heartbeat","last_trade_id":0,"product_id":"BTC-USD","sequence":180755531,"time":"2020-06-30T19:12:05.735116Z"}
{"type":"received","side":"sell","product_id":"BTC-USD","time":"2020-06-30T19:12:06.090621Z","sequence":180755532,"order_id":"0323134e-9e57-45cd-a266-be01cea51a63","order_type":"limit","size":"0.0659","price":"9112.62","client_oid":""}
{"type":"match","side":"buy","product_id":"BTC-USD","time":"2020-06-30T19:12:06.090621Z","sequence":180755533,"trade_id":14587466,"maker_order_id":"91b59a7c-6a07-4039-9536-21daf3cb3282","taker_order_id":"0323134e-9e57-45cd-a266-be01cea51a63","size":"0.0659","price":"9120.8"}
{"type":"done","side":"sell","product_id":"BTC-USD","time":"2020-06-30T19:12:06.090621Z","sequence":180755534,"order_id":"0323134e-9e57-45cd-a266-be01cea51a63","reason":"filled","price":"9112.62","remaining_size":"0"}
{"type":"done","side":"sell","product_id":"BTC-USD","time":"2020-06-30T19:12:06.327956Z","sequence":180755535,"order_id":"07c87942-40d6-4aed-9623-3233f39e32bc","reason":"canceled","price":"9137.03","remaining_size":"1.1518"}
{"type":"received","side":"sell","product_id":"BTC-USD","time":"2020-06-30T19:12:06.640961Z","sequence":180755536,"order_id":"2b9e6380-625f-450b-a5fc-bd9a5c2e75ab","order_type":"limit","size":"1.2189","price":"9128.9","client_oid":""}
{"type":"open","side":"sell","product_id":"BTC-USD","time":"2020-06-30T19:12:06.640961Z","sequence":180755537,"price":"9128.9","order_id":"2b9e6380-625f-450b-a5fc-bd9a5c2e75ab","remaining_size":"1.2189"}
{"type":"heartbeat","last_trade_id":0,"product_id":"BTC-USD","sequence":180755537,"time":"2020-06-30T19:12:06.735118Z"}
{"type":"done","side":"sell","product_id":"BTC-USD","time":"2020-06-30T19:12:07.074173Z","sequence":180755538,"order_id":"95dab599-a951-454a-8a6f-33108c8224ea","reason":"canceled","price":"9137.05","remaining_size":"1.0008"}
{"type":"done","side":"sell","product_id":"BTC-USD","time":"2020-06-30T19:12:07.079529Z","sequence":180755539,"order_id":"3ee65cad-ec4b-48c9-9a36-52d537dea44c","reason":"canceled","price":"9151.21","remaining_size":"0.0546"}
{"type":"received","side":"sell","product_id":"BTC-USD","time":"2020-06-30T19:12:07.469138Z","sequence":180755540,"order_id":"46ecdab5-f662-4262-9276-847c46b98620","order_type":"limit","size":"1.643","price":"9106.13","client_oid":""}
{"type":"match","side":"buy","product_id":"BTC-USD","time":"2020-06-30T19:12:07.469138Z","sequence":180755541,"trade_id":14587467,"maker_order_id":"91b59a7c-6a07-4039-9536-21daf3cb3282","taker_order_id":"46ecdab5-f662-4262-9276-847c46b98620","size":"1.643","price":"9120.8"}
{"type":"done","side":"sell","product_id":"BTC-USD","time":"2020-06-30T19:12:07.469138Z","sequence":180755542,"order_id":"46ecdab5-f662-4262-9276-847c46b98620","reason":"filled","price":"9106.13","remaining_size":"0"}
{"type":"heartbeat","last_trade_id":0,"product_id":"BTC-USD","sequence":180755542,"time":"2020-06-30T19:12:07.734986Z"}
{"type":"received","side":"sell","product_id":"BTC-USD","time":"2020-06-30T19:12:07.751287Z","sequence":180755543,"order_id":"c58fe32a-a3b4-4d2d-a126-63a3217cca09","order_type":"limit","size":"0.5145","price":"9126.17","client_oid":""}
{"type":"open","side":"sell","product_id":"BTC-USD","time":"2020-06-30T19:12:07.751287Z","sequence":180755544,"price":"9126.17","order_id":"c58fe32a-a3b4-4d2d-a126-63a3217cca09","remaining_size":"0.5145"}
{"type":"done","side":"sell","product_id":"BTC-USD","time":"2020-06-30T19:12:08.196114Z","sequence":180755545,"order_id":"8d31b703-b1e7-4c4d-8942-a5a38dafd35b","reason":"canceled","price":"9132.88","remaining_size":"0.2466"}
{"type":"received","side":"sell","product_id":"BTC-USD","time":"2020-06-30T19:12:08.580927Z","sequence":180755546,"order_id":"60ada362-10a4-4da3-8e78-da2af9209b05","order_type":"limit","size":"0.0547","price":"9144.97","client_oid":""}
{"type":"open","side":"sell","product_id":"BTC-USD","time":"2020-06-30T19:12:08.580927Z","sequence":180755547,"price":"9144.97","order_id":"60ada362-10a4-4da3-8e78-da2af9209b05","remaining_size":"0.0547"}
{"type":"heartbeat","last_trade_id":0,"product_id":"BTC-USD","sequence":180755547,"time":"2020-06-30T19:12:08.735163Z"}
{"type":"received","side":"buy","product_id":"BTC-USD","time":"2020-06-30T19:12:09.566306Z","sequence":180755548,"order_id":"44822686-30e0-4c76-9344-6cb9864ad2a1","order_type":"limit","size":"0.033","price":"9072.43","client_oid":""}
{"type":"open","side":"buy","product_id":"BTC-USD","time":"2020-06-30T19:12:09.566306Z","sequence":180755549,"price":"9072.43","order_id":"44822686-30e0-4c76-9344-6cb9864ad2a1","remaining_size":"0.033"}
{"type":"heartbeat","last_trade_id":0,"product_id":"BTC-USD","sequence":180755549,"time":"2020-06-30T19:12:09.735122Z"}
{"type":"done","side":"buy","product_id":"BTC-USD","time":"2020-06-30T19:12:09.977164Z","sequence":180755550,"order_id":"fc162a26-95c0-4c60-ac98-1ed88f8d73c3","reason":"canceled","price":"9096.94","remaining_size":"0.0223"}
{"type":"received","side":"buy","product_id":"BTC-USD","time":"2020-06-30T19:12:10.111408Z","sequence":180755551,"order_id":"bdef139a-5128-4cd2-ae19-0ae7460956e3","order_type":"limit","size":"0.0395","price":"9073.63","client_oid":""}
{"type":"open","side":"buy","product_id":"BTC-USD","time":"2020-06-30T19:12:10.111408Z","sequence":180755552,"price":"9073.63","order_id":"bdef139a-5128-4cd2-ae19-0ae7460956e3","remaining_size":"0.0395"}
{"type":"received","side":"sell","product_id":"BTC-USD","time":"2020-06-30T19:12:10.445517Z","sequence":180755553,"order_id":"e60a9628-ba77-45b5-a6a8-ff39c22fcbba","order_type":"limit","size":"0.1","price":"9177.67","client_oid":""}
{"type":"open","side":"sell","product_id":"BTC-USD","time":"2020-06-30T19:12:10.445517Z","sequence":180755554,"price":"9177.67","order_id":"e60a9628-ba77-45b5-a6a8-ff39c22fcbba","remaining_size":"0.1"}
{"type":"done","side":"buy","product_id":"BTC-USD","time":"2020-06-30T19:12:10.563708Z","sequence":180755555,"order_id":"48c19729-3fe1-4302-a641-20074f05e75a","reason":"canceled","price":"9102.84","remaining_size":"1.296"}
{"type":"received","side":"sell","product_id":"BTC-USD","time":"2020-06-30T19:12:10.671382Z","sequence":180755556,"order_id":"7f7f4483-526c-4f95-b794-8cf1fbbc1fd2","order_type":"market","size":"0.001","funds":"9.1208","client_oid":""}
{"type":"match","side":"buy","product_id":"BTC-USD","time":"2020-06-30T19:12:10.671382Z","sequence":180755557,"trade_id":14587468,"maker_order_id":"91b59a7c-6a07-4039-9536-21daf3cb3282","taker_order_id":"7f7f4483-526c-4f95-b794-8cf1fbbc1fd2","size":"0.001","price":"9120.8"}
{"type":"done","side":"sell","product_id":"BTC-USD","time":"2020-06-30T19:12:10.671382Z","sequence":180755558,"order_id":"7f7f4483-526c-4f95-b794-8cf1fbbc1fd2","reason":"filled","remaining_size":"0"}
{"type":"heartbeat","last_trade_id":0,"product_id":"BTC-USD","sequence":180755558,"time":"2020-06-30T19:12:10.735113Z"}
{"type":"received","side":"buy","product_id":"BTC-USD","time":"2020-06-30T19:12:10.993246Z","sequence":180755559,"order_id":"647a1189-591c-4274-bbcf-405ccb96f822","order_type":"limit","size":"0.543","price":"9102.22","client_oid":""}
{"type":"open","side":"buy","product_id":"BTC-USD","time":"2020-06-30T19:12:10.993246Z","sequence":180755560,"price":"9102.22","order_id":"647a1189-591c-4274-bbcf-405ccb96f822","remaining_size":"0.543"}
{"type":"received","side":"sell","product_id":"BTC-USD","time":"2020-06-30T19:12:11.274724Z","sequence":180755561,"order_id":"302db60c-e545-4d40-8973-3f0f3275d2e9","order_type":"limit","size":"0.0547","price":"9140.44","client_oid":""}
{"type":"open","side":"sell","product_id":"BTC-USD","time":"2020-06-30T19:12:11.274724Z","sequence":180755562,"price":"9140.44","order_id":"302db60c-e545-4d40-8973-3f0f3275d2e9","remaining_size":"0.0547"}
{"type":"done","side":"buy","product_id":"BTC-USD","time":"2020-06-30T19:12:11.453048Z","sequence":180755563,"order_id":"5f26e095-4094-4dbd-94f4-ec35eb294830","reason":"canceled","price":"9081.27","remaining_size":"0.0967"}
{"type":"heartbeat","last_trade_id":0,"product_id":"BTC-USD","sequence":180755563,"time":"2020-06-30T19:12:11.735120Z"}
{"type":"received","side":"sell","product_id":"BTC-USD","time":"2020-06-30T19:12:11.886633Z","sequence":180755564,"order_id":"d3bb600e-7c64-49db-bda8-1e6f3aa58798","order_type":"limit","size":"0.5145","price":"9126.17","client_oid":""}
{"type":"open","side":"sell","product_id":"BTC-USD","time":"2020-06-30T19:12:11.886633Z","sequence":180755565,"price":"9126.17","order_id":"d3bb600e-7c64-49db-bda8-1e6f3aa58798","remaining_size":"0.5145"}
{"type":"received","side":"buy","product_id":"BTC-USD","time":"2020-06-30T19:12:12.165354Z","sequence":180755566,"order_id":"9d1bc32e-62f5-4c3d-a4d0-c3b591e9dbf9","order_type":"limit","size":"0.0395","price":"9077.08","client_oid":""}
{"type":"open","side":"buy","product_id":"BTC-USD","time":"2020-06-30T19:12:12.165354Z","sequence":180755567,"price":"9077.08","order_id":"9d1bc32e-62f5-4c3d-a4d0-c3b591e9dbf9","remaining_size":"0.0395"}
{"type":"done","side":"sell","product_id":"BTC-USD","time":"2020-06-30T19:12:12.377626Z","sequence":180755568,"order_id":"575289e0-3bc6-4fcf-bdd4-1ce39ef5ee3b","reason":"canceled","price":"9152.59","remaining_size":"0.0546"}
{"type":"done","side":"buy","product_id":"BTC-USD","time":"2020-06-30T19:12:12.662341Z","sequence":180755569,"order_id":"da27d1db-3c49-4932-a626-019a2d6f1b99","reason":"canceled","price":"9106","remaining_size":"0.05"}
{"type":"done","side":"buy","product_id":"BTC-USD","time":"2020-06-30T19:12:12.698272Z","sequence":180755570,"order_id":"3cc220c9-63e4-4de9-bae0-90ab7e9e9a80","reason":"canceled","price":"9079.57","remaining_size":"0.0395"}
{"type":"done","side":"buy","product_id":"BTC-USD","time":"2020-06-30T19:12:12.707716Z","sequence":180755571,"order_id":"647a1189-591c-4274-bbcf-405ccb96f822","reason":"canceled","price":"9102.22","remaining_size":"0.543"}
{"type":"heartbeat","last_trade_id":0,"product_id":"BTC-USD","sequence":180755571,"time":"2020-06-30T19:12:12.735115Z"}
{"type":"received","side":"buy","product_id":"BTC-USD","time":"2020-06-30T19:12:13.267657Z","sequence":180755572,"order_id":"07b51d73-f1f5-4441-9090-1381f696761b","order_type":"limit","size":"0.0279","price":"9078.86","client_oid":""}
{"type":"open","side":"buy","product_id":"BTC-USD","time":"2020-06-30T19:12:13.267657Z","sequence":180755573,"price":"9078.86","order_id":"07b51d73-f1f5-4441-9090-1381f696761b","remaining_size":"0.0279"}
{"type":"done","side":"buy","product_id":"BTC-USD","time":"2020-06-30T19:12:13.457809Z","sequence":180755574,"order_id":"d3500635-9111-4f03-8c80-f3a99181622f","reason":"canceled","price":"9110.07","remaining_size":"5.9645"}
{"type":"done","side":"buy","product_id":"BTC-USD","time":"2020-06-30T19:12:13.464745Z","sequence":180755575,"order_id":"81963809-5797-4940-842b-24965837a910","reason":"canceled","price":"8938.29","remaining_size":"0.001"}
{"type":"heartbeat","last_trade_id":0,"product_id":"BTC-USD","sequence":180755575,"time":"2020-06-30T19:12:13.735123Z"}
{"type":"received","side":"buy","product_id":"BTC-USD","time":"2020-06-30T19:12:13.818583Z","sequence":180755576,"order_id":"c71d1280-d7b0-44d7-960c-f0981016187b","order_type":"limit","size":"0.094","price":"9073.4","client_oid":""}
{"type":"open","side":"buy","product_id":"BTC-USD","time":"2020-06-30T19:12:13.818583Z","sequence":180755577,"price":"9073.4","order_id":"c71d1280-d7b0-44d7-960c-f0981016187b","remaining_size":"0.094"}
{"type":"received","side":"buy","product_id":"BTC-USD","time":"2020-06-30T19:12:14.040993Z","sequence":180755578,"order_id":"a14b83a9-1679-4640-b248-328c201f566b","order_type":"limit","size":"0.01","price":"100","client_oid":"57c66f19-519a-4b77-b945-a0c27a467490"}
{"type":"open","side":"buy","product_id":"BTC-USD","time":"2020-06-30T19:12:14.040993Z","sequence":180755579,"price":"100","order_id":"a14b83a9-1679-4640-b248-328c201f566b","remaining_size":"0.01"}
{"type":"done","side":"buy","product_id":"BTC-USD","time":"2020-06-30T19:12:14.048263Z","sequence":180755580,"order_id":"a14b83a9-1679-4640-b248-328c201f566b","reason":"canceled","price":"100","remaining_size":"0.01"}
{"type":"received","side":"buy","product_id":"BTC-USD","time":"2020-06-30T19:12:14.099544Z","sequence":180755581,"order_id":"0f205457-da87-4901-bd7b-eefb5b9094bd","order_type":"limit","size":"0.0693","price":"9074.08","client_oid":""}
{"type":"open","side":"buy","product_id":"BTC-USD","time":"2020-06-30T19:12:14.099544Z","sequence":180755582,"price":"9074.08","order_id":"0f205457-da87-4901-bd7b-eefb5b9094bd","remaining_size":"0.0693"}
{"type":"received","side":"buy","product_id":"BTC-USD","time":"2020-06-30T19:12:14.655224Z","sequence":180755583,"order_id":"ad98878a-e51d-4316-a555-a1dd0ee2d6ab","order_type":"limit","size":"0.0693","price":"9075.31","client_oid":""}
{"type":"open","side":"buy","product_id":"BTC-USD","time":"2020-06-30T19:12:14.655224Z","sequence":180755584,"price":"9075.31","order_id":"ad98878a-e51d-4316-a555-a1dd0ee2d6ab","remaining_size":"0.0693"}
{"type":"heartbeat","last_trade_id":0,"product_id":"BTC-USD","sequence":180755584,"time":"2020-06-30T19:12:14.735120Z"}
{"type":"received","side":"buy","product_id":"BTC-USD","time":"2020-06-30T19:12:14.979584Z","sequence":180755585,"order_id":"3a4f898f-e4ef-4e08-9cae-2aa6d42fb493","order_type":"limit","size":"0.0277","price":"9082.94","client_oid":""}
{"type":"open","side":"buy","product_id":"BTC-USD","time":"2020-06-30T19:12:14.979584Z","sequence":180755586,"price":"9082.94","order_id":"3a4f898f-e4ef-4e08-9cae-2aa6d42fb493","remaining_size":"0.0277"}
{"type":"done","side":"buy","product_id":"BTC-USD","time":"2020-06-30T19:12:15.113411Z","sequence":180755587,"order_id":"02a1c224-c548-4b28-8e0d-08e8e0dd0d39","reason":"canceled","price":"9089.1","remaining_size":"0.0293"}
{"type":"heartbeat","last_trade_id":0,"product_id":"BTC-USD","sequence":180755587,"time":"2020-06-30T19:12:15.735123Z"}
{"type":"received","side":"buy","product_id":"BTC-USD","time":"2020-06-30T19:12:15.777720Z","sequence":180755588,"order_id":"cce23ef2-41f9-45ad-876e-77aee2e927ae","order_type":"limit","size":"0.0693","price":"9077.64","client_oid":""}
{"type":"open","side":"buy","product_id":"BTC-USD","time":"2020-06-30T19:12:15.777720Z","sequence":180755589,"price":"9077.64","order_id":"cce23ef2-41f9-45ad-876e-77aee2e927ae","remaining_size":"0.0693"}
{"type":"received","side":"buy","product_id":"BTC-USD","time":"2020-06-30T19:12:16.306950Z","sequence":180755590,"order_id":"c775469d-24ab-4d01-8a43-12afe02255e4","order_type":"limit","size":"0.023","price":"9075.32","client_oid":""}
{"type":"open","side":"buy","product_id":"BTC-USD","time":"2020-06-30T19:12:16.306950Z","sequence":180755591,"price":"9075.32","order_id":"c775469d-24ab-4d01-8a43-12afe02255e4","remaining_size":"0.023"}
{"type":"heartbeat","last_trade_id":0,"product_id":"BTC-USD","sequence":180755591,"time":"2020-06-30T19:12:16.735118Z"}
{"type":"received","side":"buy","product_id":"BTC-USD","time":"2020-06-30T19:12:17.507622Z","sequence":180755592,"order_id":"79c99f68-05eb-433d-b1b8-d45ed44d7a35","order_type":"limit","size":"0.02","price":"9071.88","client_oid":""}
{"type":"open","side":"buy","product_id":"BTC-USD","time":"2020-06-30T19:12:17.507622Z","sequence":180755593,"price":"9071.88","order_id":"79c99f68-05eb-433d-b1b8-d45ed44d7a35","remaining_size":"0.02"}
{"type":"heartbeat","last_trade_id":0,"product_id":"BTC-USD","sequence":180755593,"time":"2020-06-30T19:12:17.735115Z"}
{"type":"received","side":"buy","product_id":"BTC-USD","time":"2020-06-30T19:12:17.774166Z","sequence":180755594,"order_id":"d46e777c-3b50-4630-b52d-9d9dc2fdd6f1","order_type":"limit","size":"0.0395","price":"9073.43","client_oid":""}
{"type":"open","side":"buy","product_id":"BTC-USD","time":"2020-06-30T19:12:17.774166Z","sequence":180755595,"price":"9073.43","order_id":"d46e777c-3b50-4630-b52d-9d9dc2fdd6f1","remaining_size":"0.0395"}
{"type":"done","side":"buy","product_id":"BTC-USD","time":"2020-06-30T19:12:18.209016Z","sequence":180755596,"order_id":"7133d0f5-23b5-4f7a-a56c-cc2daa43994c","reason":"canceled","price":"9105.37","remaining_size":"0.1899"}
{"type":"received","side":"buy","product_id":"BTC-USD","time":"2020-06-30T19:12:18.615434Z","sequence":180755597,"order_id":"38e0735c-672d-4c95-8e06-f3afe7e68f6d","order_type":"limit","size":"0.0235","price":"9074.96","client_oid":""}
{"type":"open","side":"buy","product_id":"BTC-USD","time":"2020-06-30T19:12:18.615434Z","sequence":180755598,"price":"9074.96","order_id":"38e0735c-672d-4c95-8e06-f3afe7e68f6d","remaining_size":"0.0235"}
{"type":"heartbeat","last_trade_id":0,"product_id":"BTC-USD","sequence":180755598,"time":"2020-06-30T19:12:18.735127Z"}
{"type":"received","side":"buy","product_id":"BTC-USD","time":"2020-06-30T19:12:18.889767Z","sequence":180755599,"order_id":"9fa42e3c-8ef2-4e45-8da2-1cf582e4c34c","order_type":"limit","size":"0.01","price":"9077.41","client_oid":""}
{"type":"open","side":"buy","product_id":"BTC-USD","time":"2020-06-30T19:12:18.889767Z","sequence":180755600,"price":"9077.41","order_id":"9fa42e3c-8ef2-4e45-8da2-1cf582e4c34c","remaining_size":"0.01"}
{"type":"done","side":"buy","product_id":"BTC-USD","time":"2020-06-30T19:12:19.068159Z","sequence":180755601,"order_id":"9d1bc32e-62f5-4c3d-a4d0-c3b591e9dbf9","reason":"canceled","price":"9077.08","remaining_size":"0.0395"}
{"type":"received","side":"buy","product_id":"BTC-USD","time":"2020-06-30T19:12:19.440234Z","sequence":180755602,"order_id":"9686b054-a574-4c81-aac3-8d8a65f3f376","order_type":"limit","size":"0.025","price":"9102.85","client_oid":""}
{"type":"open","side":"buy","product_id":"BTC-USD","time":"2020-06-30T19:12:19.440234Z","sequence":180755603,"price":"9102.85","order_id":"9686b054-a574-4c81-aac3-8d8a65f3f376","remaining_size":"0.025"}
{"type":"received","side":"sell","product_id":"BTC-USD","time":"2020-06-30T19:12:19.708250Z","sequence":180755604,"order_id":"734cf2ac-1a6c-4f6f-bf4f-ab813ca6c284","order_type":"limit","size":"0.0547","price":"9146.15","client_oid":""}
{"type":"open","side":"sell","product_id":"BTC-USD","time":"2020-06-30T19:12:19.708250Z","sequence":180755605,"price":"9146.15","order_id":"734cf2ac-1a6c-4f6f-bf4f-ab813ca6c284","remaining_size":"0.0547"}
{"type":"heartbeat","last_trade_id":0,"product_id":"BTC-USD","sequence":180755605,"time":"2020-06-30T19:12:19.735120Z"}
{"type":"done","side":"sell","product_id":"BTC-USD","time":"2020-06-30T19:12:19.914637Z","sequence":180755606,"order_id":"eeb58d42-e833-47a4-8f83-ee99ddb434ed","reason":"canceled","price":"9156.85","remaining_size":"0.069"}
{"type":"heartbeat","last_trade_id":0,"product_id":"BTC-USD","sequence":180755606,"time":"2020-06-30T19:12:20.735124Z"}
{"type":"done","side":"buy","product_id":"BTC-USD","time":"2020-06-30T19:12:20.937686Z","sequence":180755607,"order_id":"c71d1280-d7b0-44d7-960c-f0981016187b","reason":"canceled","price":"9073.4","remaining_size":"0.094"}
{"type":"received","side":"buy","product_id":"BTC-USD","time":"2020-06-30T19:12:21.085475Z","sequence":180755608,"order_id":"e53703f9-67ce-49f0-a7ef-94fc688a9289","order_type":"limit","size":"0.0223","price":"9085.45","client_oid":""}
{"type":"open","side":"buy","product_id":"BTC-USD","time":"2020-06-30T19:12:21.085475Z","sequence":180755609,"price":"9085.45","order_id":"e53703f9-67ce-49f0-a7ef-94fc688a9289","remaining_size":"0.0223"}
{"type":"done","side":"buy","product_id":"BTC-USD","time":"2020-06-30T19:12:21.532468Z","sequence":180755610,"order_id":"ad98878a-e51d-4316-a555-a1dd0ee2d6ab","reason":"canceled","price":"9075.31","remaining_size":"0.0693"}
{"type":"done","side":"buy","product_id":"BTC-USD","time":"2020-06-30T19:12:21.532748Z","sequence":180755611,"order_id":"3a4f898f-e4ef-4e08-9cae-2aa6d42fb493","reason":"canceled","price":"9082.94","remaining_size":"0.0277"}
{"type":"done","side":"buy","product_id":"BTC-USD","time":"2020-06-30T19:12:21.548080Z","sequence":180755612,"order_id":"0f205457-da87-4901-bd7b-eefb5b9094bd","reason":"canceled","price":"9074.08","remaining_size":"0.0693"}
{"type":"heartbeat","last_trade_id":0,"product_id":"BTC-USD","sequence":180755612,"time":"2020-06-30T19:12:21.735115Z"}
{"type":"received","side":"sell","product_id":"BTC-USD","time":"2020-06-30T19:12:21.951229Z","sequence":180755613,"order_id":"2e108d98-ae63-4ee3-a1ce-7d094a1bb75f","order_type":"limit","size":"0.05","price":"9105.81","client_oid":""}
{"type":"match","side":"buy","product_id":"BTC-USD","time":"2020-06-30T19:12:21.951229Z","sequence":180755614,"trade_id":14587469,"maker_order_id":"91b59a7c-6a07-4039-9536-21daf3cb3282","taker_order_id":"2e108d98-ae63-4ee3-a1ce-7d094a1bb75f","size":"0.05","price":"9120.8"}
{"type":"done","side":"sell","product_id":"BTC-USD","time":"2020-06-30T19:12:21.951229Z","sequence":180755615,"order_id":"2e108d98-ae63-4ee3-a1ce-7d094a1bb75f","reason":"filled","price":"9105.81","remaining_size":"0"}
{"type":"received","side":"buy","product_id":"BTC-USD","time":"2020-06-30T19:12:22.504634Z","sequence":180755616,"order_id":"cc06e600-caeb-44df-b180-88e2b988d5a2","order_type":"limit","size":"0.0999","price":"9084.62","client_oid":""}
{"type":"open","side":"buy","product_id":"BTC-USD","time":"2020-06-30T19:12:22.504634Z","sequence":180755617,"price":"9084.62","order_id":"cc06e600-caeb-44df-b180-88e2b988d5a2","remaining_size":"0.0999"}
{"type":"heartbeat","last_trade_id":0,"product_id":"BTC-USD","sequence":180755617,"time":"2020-06-30T19:12:22.735131Z"}
{"type":"done","side":"buy","product_id":"BTC-USD","time":"2020-06-30T19:12:23.012828Z","sequence":180755618,"order_id":"9fa42e3c-8ef2-4e45-8da2-1cf582e4c34c","reason":"canceled","price":"9077.41","remaining_size":"0.01"}
{"type":"done","side":"buy","product_id":"BTC-USD","time":"2020-06-30T19:12:23.023132Z","sequence":180755619,"order_id":"c775469d-24ab-4d01-8a43-12afe02255e4","reason":"canceled","price":"9075.32","remaining_size":"0.023"}
{"type":"done","side":"sell","product_id":"BTC-USD","time":"2020-06-30T19:12:23.526667Z","sequence":180755620,"order_id":"6ba5bea6-847d-4312-9597-dabd6ef2388c","reason":"canceled","price":"9156.58","remaining_size":"0.069"}
{"type":"done","side":"sell","product_id":"BTC-USD","time":"2020-06-30T19:12:23.557228Z","sequence":180755621,"order_id":"302db60c-e545-4d40-8973-3f0f3275d2e9","reason":"canceled","price":"9140.44","remaining_size":"0.0547"}
{"type":"heartbeat","last_trade_id":0,"product_id":"BTC-USD","sequence":180755621,"time":"2020-06-30T19:12:23.735117Z"}
{"type":"received","side":"sell","product_id":"BTC-USD","time":"2020-06-30T19:12:24.463568Z","sequence":180755622,"order_id":"20ca9b23-d69f-469f-923b-ced7d48e5d07","order_type":"limit","size":"1.0861","price":"9130.65","client_oid":""}
{"type":"open","side":"sell","product_id":"BTC-USD","time":"2020-06-30T19:12:24.463568Z","sequence":180755623,"price":"9130.65","order_id":"20ca9b23-d69f-469f-923b-ced7d48e5d07","remaining_size":"1.0861"}
{"type":"heartbeat","last_trade_id":0,"product_id":"BTC-USD","sequence":180755623,"time":"2020-06-30T19:12:24.735122Z"}
{"type":"received","side":"sell","product_id":"BTC-USD","time":"2020-06-30T19:12:25.394485Z","sequence":180755624,"order_id":"bcc1f6b2-e794-4e1d-aa03-f8e5ff2dc6b1","order_type":"limit","size":"0.6139","price":"9105.67","client_oid":""}
{"type":"match","side":"buy","product_id":"BTC-USD","time":"2020-06-30T19:12:25.394485Z","sequence":180755625,"trade_id":14587470,"maker_order_id":"91b59a7c-6a07-4039-9536-21daf3cb3282","taker_order_id":"bcc1f6b2-e794-4e1d-aa03-f8e5ff2dc6b1","size":"0.6139","price":"9120.8"}
{"type":"done","side":"sell","product_id":"BTC-USD","time":"2020-06-30T19:12:25.394485Z","sequence":180755626,"order_id":"bcc1f6b2-e794-4e1d-aa03-f8e5ff2dc6b1","reason":"filled","price":"9105.67","remaining_size":"0"}
{"type":"heartbeat","last_trade_id":0,"product_id":"BTC-USD","sequence":180755626,"time":"2020-06-30T19:12:25.735031Z"}
{"type":"received","side":"sell","product_id":"BTC-USD","time":"2020-06-30T19:12:26.108072Z","sequence":180755627,"order_id":"2d98a71d-8595-463e-b219-d8a949ecc7f4","order_type":"limit","size":"0.002","price":"9203.18","client_oid":""}
{"type":"open","side":"sell","product_id":"BTC-USD","time":"2020-06-30T19:12:26.108072Z","sequence":180755628,"price":"9203.18","order_id":"2d98a71d-8595-463e-b219-d8a949ecc7f4","remaining_size":"0.002"}
{"type":"heartbeat","last_trade_id":0,"product_id":"BTC-USD","sequence":180755628,"time":"2020-06-30T19:12:26.735084Z"}
{"type":"received","side":"buy","product_id":"BTC-USD","time":"2020-06-30T19:12:27.151821Z","sequence":180755629,"order_id":"690c910c-b6b2-42cf-a2aa-d04824d77c19","order_type":"limit","size":"0.0692","price":"9076.79","client_oid":""}
{"type":"open","side":"buy","product_id":"BTC-USD","time":"2020-06-30T19:12:27.151821Z","sequence":180755630,"price":"9076.79","order_id":"690c910c-b6b2-42cf-a2aa-d04824d77c19","remaining_size":"0.0692"}
{"type":"done","side":"buy","product_id":"BTC-USD","time":"2020-06-30T19:12:27.622996Z","sequence":180755631,"order_id":"bdef139a-5128-4cd2-ae19-0ae7460956e3","reason":"canceled","price":"9073.63","remaining_size":"0.0395"}
{"type":"done","side":"buy","product_id":"BTC-USD","time":"2020-06-30T19:12:27.635325Z","sequence":180755632,"order_id":"38e0735c-672d-4c95-8e06-f3afe7e68f6d","reason":"canceled","price":"9074.96","remaining_size":"0.0235"}
{"type":"heartbeat","last_trade_id":0,"product_id":"BTC-USD","sequence":180755632,"time":"2020-06-30T19:12:27.735170Z"}
{"type":"received","side":"buy","product_id":"BTC-USD","time":"2020-06-30T19:12:28.059411Z","sequence":180755633,"order_id":"fe5630f6-ee9f-4a7d-af95-b399875f6987","order_type":"limit","size":"0.0692","price":"9076.76","client_oid":""}
{"type":"open","side":"buy","product_id":"BTC-USD","time":"2020-06-30T19:12:28.059411Z","sequence":180755634,"price":"9076.76","order_id":"fe5630f6-ee9f-4a7d-af95-b399875f6987","remaining_size":"0.0692"}
{"type":"done","side":"buy","product_id":"BTC-USD","time":"2020-06-30T19:12:28.234829Z","sequence":180755635,"order_id":"07b51d73-f1f5-4441-9090-1381f696761b","reason":"canceled","price":"9078.86","remaining_size":"0.0279"}
{"type":"done","side":"buy","product_id":"BTC-USD","time":"2020-06-30T19:12:28.240031Z","sequence":180755636,"order_id":"9686b054-a574-4c81-aac3-8d8a65f3f376","reason":"canceled","price":"9102.85","remaining_size":"0.025"}
{"type":"received","side":"sell","product_id":"BTC-USD","time":"2020-06-30T19:12:28.336679Z","sequence":180755637,"order_id":"71f794b4-572d-4d9e-9fe7-b4e600bf945e","order_type":"limit","size":"1.3826","price":"9128.82","client_oid":""}
{"type":"open","side":"sell","product_id":"BTC-USD","time":"2020-06-30T19:12:28.336679Z","sequence":180755638,"price":"9128.82","order_id":"71f794b4-572d-4d9e-9fe7-b4e600bf945e","remaining_size":"1.3826"}
{"type":"received","side":"buy","product_id":"BTC-USD","time":"2020-06-30T19:12:28.611785Z","sequence":180755639,"order_id":"1457870c-8020-4ae2-8567-af17c63e562f","order_type":"limit","size":"0.0391","price":"9082.16","client_oid":""}
{"type":"open","side":"buy","product_id":"BTC-USD","time":"2020-06-30T19:12:28.611785Z","sequence":180755640,"price":"9082.16","order_id":"1457870c-8020-4ae2-8567-af17c63e562f","remaining_size":"0.0391"}
{"type":"heartbeat","last_trade_id":0,"product_id":"BTC-USD","sequence":180755640,"time":"2020-06-30T19:12:28.735118Z"}
{"type":"received","side":"buy","product_id":"BTC-USD","time":"2020-06-30T19:12:29.022313Z","sequence":180755641,"order_id":"8b7393b5-f4ad-42cb-bf61-e250c08cfe13","order_type":"limit","size":"0.01","price":"100","client_oid":"1cf2be26-0d07-4891-8952-a083626ad616"}
{"type":"open","side":"buy","product_id":"BTC-USD","time":"2020-06-30T19:12:29.022313Z","sequence":180755642,"price":"100","order_id":"8b7393b5-f4ad-42cb-bf61-e250c08cfe13","remaining_size":"0.01"}
{"type":"done","side":"buy","product_id":"BTC-USD","time":"2020-06-30T19:12:29.028479Z","sequence":180755643,"order_id":"8b7393b5-f4ad-42cb-bf61-e250c08cfe13","reason":"canceled","price":"100","remaining_size":"0.01"}
{"type":"received","side":"buy","product_id":"BTC-USD","time":"2020-06-30T19:12:29.161043Z","sequence":180755644,"order_id":"9b6e4cc2-16e3-4b8f-b6e8-e635672ed14c","order_type":"limit","size":"0.0192","price":"9083.39","client_oid":""}
{"type":"open","side":"buy","product_id":"BTC-USD","time":"2020-06-30T19:12:29.161043Z","sequence":180755645,"price":"9083.39","order_id":"9b6e4cc2-16e3-4b8f-b6e8-e635672ed14c","remaining_size":"0.0192"}
{"type":"received","side":"buy","product_id":"BTC-USD","time":"2020-06-30T19:12:29.486837Z","sequence":180755646,"order_id":"f0e3a190-c09c-4d0a-8c49-cedf9cd362eb","order_type":"limit","size":"0.0396","price":"9105","client_oid":""}
{"type":"open","side":"buy","product_id":"BTC-USD","time":"2020-06-30T19:12:29.486837Z","sequence":180755647,"price":"9105","order_id":"f0e3a190-c09c-4d0a-8c49-cedf9cd362eb","remaining_size":"0.0396"}
{"type":"done","side":"buy","product_id":"BTC-USD","time":"2020-06-30T19:12:29.602250Z","sequence":180755648,"order_id":"fe5630f6-ee9f-4a7d-af95-b399875f6987","reason":"canceled","price":"9076.76","remaining_size":"0.0692"}
{"type":"received","side":"sell","product_id":"BTC-USD","time":"2020-06-30T19:12:29.725763Z","sequence":180755649,"order_id":"509a40d1-3e91-4912-90cc-892bff5ef84f","order_type":"limit","size":"0.0149","price":"9154.9","client_oid":""}
{"type":"open","side":"sell","product_id":"BTC-USD","time":"2020-06-30T19:12:29.725763Z","sequence":180755650,"price":"9154.9","order_id":"509a40d1-3e91-4912-90cc-892bff5ef84f","remaining_size":"0.0149"}
{"type":"heartbeat","last_trade_id":0,"product_id":"BTC-USD","sequence":180755650,"time":"2020-06-30T19:12:29.735125Z"}
{"type":"done","side":"sell","product_id":"BTC-USD","time":"2020-06-30T19:12:30.200512Z","sequence":180755651,"order_id":"20ca9b23-d69f-469f-923b-ced7d48e5d07","reason":"canceled","price":"9130.65","remaining_size":"1.0861"}
{"type":"received","side":"buy","product_id":"BTC-USD","time":"2020-06-30T19:12:30.325875Z","sequence":180755652,"order_id":"616ffe4b-663d-40ff-9290-7656252d24f7","order_type":"limit","size":"0.0395","price":"9074.32","client_oid":""}
{"type":"open","side":"buy","product_id":"BTC-USD","time":"2020-06-30T19:12:30.325875Z","sequence":180755653,"price":"9074.32","order_id":"616ffe4b-663d-40ff-9290-7656252d24f7","remaining_size":"0.0395"}
{"type":"heartbeat","last_trade_id":0,"product_id":"BTC-USD","sequence":180755653,"time":"2020-06-30T19:12:30.735112Z"}
{"type":"done","side":"buy","product_id":"BTC-USD","time":"2020-06-30T19:12:30.775829Z","sequence":180755654,"order_id":"e53703f9-67ce-49f0-a7ef-94fc688a9289","reason":"canceled","price":"9085.45","remaining_size":"0.0223"}
{"type":"heartbeat","last_trade_id":0,"product_id":"BTC-USD","sequence":180755654,"time":"2020-06-30T19:12:31.735114Z"}
{"type":"received","side":"buy","product_id":"BTC-USD","time":"2020-06-30T19:12:32.288133Z","sequence":180755655,"order_id":"7a64ded0-d0ff-41ae-ade7-792944911c9a","order_type":"limit","size":"0.01","price":"9095.58","client_oid":""}
{"type":"open","side":"buy","product_id":"BTC-USD","time":"2020-06-30T19:12:32.288133Z","sequence":180755656,"price":"9095.58","order_id":"7a64ded0-d0ff-41ae-ade7-792944911c9a","remaining_size":"0.01"}
{"type":"done","side":"buy","product_id":"BTC-USD","time":"2020-06-30T19:12:32.720718Z","sequence":180755657,"order_id":"616ffe4b-663d-40ff-9290-7656252d24f7","reason":"canceled","price":"9074.32","remaining_size":"0.0395"}
{"type":"done","side":"buy","product_id":"BTC-USD","time":"2020-06-30T19:12:32.732570Z","sequence":180755658,"order_id":"f0e3a190-c09c-4d0a-8c49-cedf9cd362eb","reason":"canceled","price":"9105","remaining_size":"0.0396"}
{"type":"done","side":"buy","product_id":"BTC-USD","time":"2020-06-30T19:12:32.739103Z","sequence":180755659,"order_id":"44822686-30e0-4c76-9344-6cb9864ad2a1","reason":"canceled","price":"9072.43","remaining_size":"0.033"}
{"type":"heartbeat","last_trade_id":0,"product_id":"BTC-USD","sequence":180755659,"time":"2020-06-30T19:12:32.735118Z"}
{"type":"received","side":"buy","product_id":"BTC-USD","time":"2020-06-30T19:12:32.846519Z","sequence":180755660,"order_id":"99ff855a-5bdb-48a8-91e0-cfad6f4a820b","order_type":"limit","size":"0.0279","price":"9078.72","client_oid":""}
{"type":"open","side":"buy","product_id":"BTC-USD","time":"2020-06-30T19:12:32.846519Z","sequence":180755661,"price":"9078.72","order_id":"99ff855a-5bdb-48a8-91e0-cfad6f4a820b","remaining_size":"0.0279"}
{"type":"received","side":"buy","product_id":"BTC-USD","time":"2020-06-30T19:12:33.127143Z","sequence":180755662,"order_id":"e81dda53-b31b-4a6b-8bd4-517387febfff","order_type":"limit","size":"0.044","price":"9072.7","client_oid":""}
{"type":"open","side":"buy","product_id":"BTC-USD","time":"2020-06-30T19:12:33.127143Z","sequence":180755663,"price":"9072.7","order_id":"e81dda53-b31b-4a6b-8bd4-517387febfff","remaining_size":"0.044"}
{"type":"done","side":"buy","product_id":"BTC-USD","time":"2020-06-30T19:12:33.596318Z","sequence":180755664,"order_id":"509f2b6c-0e23-4dd9-837f-7b5c380f27c2","reason":"canceled","price":"9107.19","remaining_size":"1.5"}
{"type":"done","side":"buy","product_id":"BTC-USD","time":"2020-06-30T19:12:33.598750Z","sequence":180755665,"order_id":"cce23ef2-41f9-45ad-876e-77aee2e927ae","reason":"canceled","price":"9077.64","remaining_size":"0.0693"}
{"type":"heartbeat","last_trade_id":0,"product_id":"BTC-USD","sequence":180755665,"time":"2020-06-30T19:12:33.735116Z"}
{"type":"heartbeat","last_trade_id":0,"product_id":"BTC-USD","sequence":180755665,"time":"2020-06-30T19:12:34.735119Z"}
{"type":"received","side":"buy","product_id":"BTC-USD","time":"2020-06-30T19:12:35.163833Z","sequence":180755666,"order_id":"75c31ca3-3a05-48bb-9b3a-d759b2a703c9","order_type":"limit","size":"0.0395","price":"9077.09","client_oid":""}
{"type":"open","side":"buy","product_id":"BTC-USD","time":"2020-06-30T19:12:35.163833Z","sequence":180755667,"price":"9077.09","order_id":"75c31ca3-3a05-48bb-9b3a-d759b2a703c9","remaining_size":"0.0395"}
{"type":"done","side":"buy","product_id":"BTC-USD","time":"2020-06-30T19:12:35.384535Z","sequence":180755668,"order_id":"e81dda53-b31b-4a6b-8bd4-517387febfff","reason":"canceled","price":"9072.7","remaining_size":"0.044"}
{"type":"done","side":"buy","product_id":"BTC-USD","time":"2020-06-30T19:12:35.395744Z","sequence":180755669,"order_id":"690c910c-b6b2-42cf-a2aa-d04824d77c19","reason":"canceled","price":"9076.79","remaining_size":"0.0692"}
{"type":"heartbeat","last_trade_id":0,"product_id":"BTC-USD","sequence":180755669,"time":"2020-06-30T19:12:35.735114Z"}
{"type":"done","side":"buy","product_id":"BTC-USD","time":"2020-06-30T19:12:36.324102Z","sequence":180755670,"order_id":"1457870c-8020-4ae2-8567-af17c63e562f","reason":"canceled","price":"9082.16","remaining_size":"0.0391"}
{"type":"done","side":"buy","product_id":"BTC-USD","time":"2020-06-30T19:12:36.326729Z","sequence":180755671,"order_id":"79c99f68-05eb-433d-b1b8-d45ed44d7a35","reason":"canceled","price":"9071.88","remaining_size":"0.02"}
{"type":"received","side":"buy","product_id":"BTC-USD","time":"2020-06-30T19:12:36.334115Z","sequence":180755672,"order_id":"53bb6d82-6c31-49e5-a438-65572e6c18ef","order_type":"limit","size":"0.04","price":"9104.04","client_oid":""}
{"type":"open","side":"buy","product_id":"BTC-USD","time":"2020-06-30T19:12:36.334115Z","sequence":180755673,"price":"9104.04","order_id":"53bb6d82-6c31-49e5-a438-65572e6c18ef","remaining_size":"0.04"}
{"type":"done","side":"buy","product_id":"BTC-USD","time":"2020-06-30T19:12:36.338215Z","sequence":180755674,"order_id":"d46e777c-3b50-4630-b52d-9d9dc2fdd6f1","reason":"canceled","price":"9073.43","remaining_size":"0.0395"}
{"type":"done","side":"buy","product_id":"BTC-USD","time":"2020-06-30T19:12:36.346717Z","sequence":180755675,"order_id":"75c31ca3-3a05-48bb-9b3a-d759b2a703c9","reason":"canceled","price":"9077.09","remaining_size":"0.0395"}
{"type":"heartbeat","last_trade_id":0,"product_id":"BTC-USD","sequence":180755675,"time":"2020-06-30T19:12:36.735110Z"}
{"type":"done","side":"buy","product_id":"BTC-USD","time":"2020-06-30T19:12:36.794360Z","sequence":180755676,"order_id":"8251294c-27c6-4188-aa73-99d111f48014","reason":"canceled","price":"9081.45","remaining_size":"0.0279"}
{"type":"done","side":"buy","product_id":"BTC-USD","time":"2020-06-30T19:12:36.801314Z","sequence":180755677,"order_id":"7a64ded0-d0ff-41ae-ade7-792944911c9a","reason":"canceled","price":"9095.58","remaining_size":"0.01"}
{"type":"done","side":"buy","product_id":"BTC-USD","time":"2020-06-30T19:12:36.801656Z","sequence":180755678,"order_id":"96aef06e-ac96-471c-81ae-10dc0731a5f4","reason":"canceled","price":"9071.82","remaining_size":"0.0967"}
{"type":"done","side":"buy","product_id":"BTC-USD","time":"2020-06-30T19:12:36.808041Z","sequence":180755679,"order_id":"99ff855a-5bdb-48a8-91e0-cfad6f4a820b","reason":"canceled","price":"9078.72","remaining_size":"0.0279"}
{"type":"received","side":"buy","product_id":"BTC-USD","time":"2020-06-30T19:12:37.483118Z","sequence":180755680,"order_id":"bbd7fb66-ec8f-46bb-bd0a-8255480b6a1a","order_type":"limit","size":"0.0235","price":"9070.48","client_oid":""}
{"type":"open","side":"buy","product_id":"BTC-USD","time":"2020-06-30T19:12:37.483118Z","sequence":180755681,"price":"9070.48","order_id":"bbd7fb66-ec8f-46bb-bd0a-8255480b6a1a","remaining_size":"0.0235"}
{"type":"heartbeat","last_trade_id":0,"product_id":"BTC-USD","sequence":180755681,"time":"2020-06-30T19:12:37.735114Z"}
{"type":"received","side":"buy","product_id":"BTC-USD","time":"2020-06-30T19:12:37.748047Z","sequence":180755682,"order_id":"6fcd8f9f-be7d-4005-a21c-c2bdc641689a","order_type":"limit","size":"0.8159","price":"9100.22","client_oid":""}
{"type":"open","side":"buy","product_id":"BTC-USD","time":"2020-06-30T19:12:37.748047Z","sequence":180755683,"price":"9100.22","order_id":"6fcd8f9f-be7d-4005-a21c-c2bdc641689a","remaining_size":"0.8159"}
{"type":"done","side":"buy","product_id":"BTC-USD","time":"2020-06-30T19:12:37.898404Z","sequence":180755684,"order_id":"1ea9354d-c3e9-4c5d-a2e6-875eb98a2c7c","reason":"canceled","price":"9079.19","remaining_size":"0.0737"}
{"type":"received","side":"buy","product_id":"BTC-USD","time":"2020-06-30T19:12:38.308125Z","sequence":180755685,"order_id":"fefc2265-4f87-490a-b10d-bad5ed7045eb","order_type":"limit","size":"0.0967","price":"9072.52","client_oid":""}
{"type":"open","side":"buy","product_id":"BTC-USD","time":"2020-06-30T19:12:38.308125Z","sequence":180755686,"price":"9072.52","order_id":"fefc2265-4f87-490a-b10d-bad5ed7045eb","remaining_size":"0.0967"}
{"type":"done","side":"buy","product_id":"BTC-USD","time":"2020-06-30T19:12:38.729778Z","sequence":180755687,"order_id":"9b6e4cc2-16e3-4b8f-b6e8-e635672ed14c","reason":"canceled","price":"9083.39","remaining_size":"0.0192"}
{"type":"heartbeat","last_trade_id":0,"product_id":"BTC-USD","sequence":180755687,"time":"2020-06-30T19:12:38.735119Z"}
{"type":"heartbeat","last_trade_id":0,"product_id":"BTC-USD","sequence":180755687,"time":"2020-06-30T19:12:39.735117Z"}
{"type":"received","side":"buy","product_id":"BTC-USD","time":"2020-06-30T19:12:39.976104Z","sequence":180755688,"order_id":"b1f668c8-bfe1-45b8-b8e0-df3ddddaef40","order_type":"limit","size":"0.002","price":"8987.61","client_oid":""}
{"type":"open","side":"buy","product_id":"BTC-USD","time":"2020-06-30T19:12:39.976104Z","sequence":180755689,"price":"8987.61","order_id":"b1f668c8-bfe1-45b8-b8e0-df3ddddaef40","remaining_size":"0.002"}
{"type":"done","side":"buy","product_id":"BTC-USD","time":"2020-06-30T19:12:40.396016Z","sequence":180755690,"order_id":"fefc2265-4f87-490a-b10d-bad5ed7045eb","reason":"canceled","price":"9072.52","remaining_size":"0.0967"}
{"type":"received","side":"sell","product_id":"BTC-USD","time":"2020-06-30T19:12:40.538853Z","sequence":180755691,"order_id":"4d07ead6-26bf-4b8a-8197-d8a0fceed7cf","order_type":"limit","size":"0.0383","price":"9161.21","client_oid":""}
{"type":"open","side":"sell","product_id":"BTC-USD","time":"2020-06-30T19:12:40.538853Z","sequence":180755692,"price":"9161.21","order_id":"4d07ead6-26bf-4b8a-8197-d8a0fceed7cf","remaining_size":"0.0383"}
{"type":"heartbeat","last_trade_id":0,"product_id":"BTC-USD","sequence":180755692,"time":"2020-06-30T19:12:40.735118Z"}
{"type":"received","side":"buy","product_id":"BTC-USD","time":"2020-06-30T19:12:40.798993Z","sequence":180755693,"order_id":"4ff73e45-486d-451b-9c80-d20f074a6718","order_type":"limit","size":"0.132","price":"9104.61","client_oid":""}
{"type":"open","side":"buy","product_id":"BTC-USD","time":"2020-06-30T19:12:40.798993Z","sequence":180755694,"price":"9104.61","order_id":"4ff73e45-486d-451b-9c80-d20f074a6718","remaining_size":"0.132"}
{"type":"done","side":"sell","product_id":"BTC-USD","time":"2020-06-30T19:12:40.971658Z","sequence":180755695,"order_id":"60ada362-10a4-4da3-8e78-da2af9209b05","reason":"canceled","price":"9144.97","remaining_size":"0.0547"}
{"type":"done","side":"buy","product_id":"BTC-USD","time":"2020-06-30T19:12:41.041245Z","sequence":180755696,"order_id":"cc06e600-caeb-44df-b180-88e2b988d5a2","reason":"canceled","price":"9084.62","remaining_size":"0.0999"}
{"type":"received","side":"buy","product_id":"BTC-USD","time":"2020-06-30T19:12:41.660553Z","sequence":180755697,"order_id":"6e96f68a-a3ce-4bff-8d2c-b137937e1fc9","order_type":"market","size":"0.001","funds":"9.12082","client_oid":""}
{"type":"match","side":"sell","product_id":"BTC-USD","time":"2020-06-30T19:12:41.660553Z","sequence":180755698,"trade_id":14587471,"maker_order_id":"36fe0734-4801-466d-b093-cccd411db09a","taker_order_id":"6e96f68a-a3ce-4bff-8d2c-b137937e1fc9","size":"0.001","price":"9120.82"}
{"type":"done","side":"buy","product_id":"BTC-USD","time":"2020-06-30T19:12:41.660553Z","sequence":180755699,"order_id":"6e96f68a-a3ce-4bff-8d2c-b137937e1fc9","reason":"filled","remaining_size":"0"}
{"type":"received","side":"sell","product_id":"BTC-USD","time":"2020-06-30T19:12:41.671465Z","sequence":180755700,"order_id":"d56966c2-d322-465f-b9d4-ec049075d7e4","order_type":"limit","size":"0.0659","price":"9104.94","client_oid":""}
{"type":"match","side":"buy","product_id":"BTC-USD","time":"2020-06-30T19:12:41.671465Z","sequence":180755701,"trade_id":14587472,"maker_order_id":"91b59a7c-6a07-4039-9536-21daf3cb3282","taker_order_id":"d56966c2-d322-465f-b9d4-ec049075d7e4","size":"0.0659","price":"9120.8"}
{"type":"done","side":"sell","product_id":"BTC-USD","time":"2020-06-30T19:12:41.671465Z","sequence":180755702,"order_id":"d56966c2-d322-465f-b9d4-ec049075d7e4","reason":"filled","price":"9104.94","remaining_size":"0"}
{"type":"heartbeat","last_trade_id":0,"product_id":"BTC-USD","sequence":180755702,"time":"2020-06-30T19:12:41.735114Z"}
{"type":"received","side":"buy","product_id":"BTC-USD","time":"2020-06-30T19:12:41.957060Z","sequence":180755703,"order_id":"1a64c913-01dd-4ef1-bffc-d5ece08a93dc","order_type":"limit","size":"0.133","price":"9104.61","client_oid":""}
{"type":"open","side":"buy","product_id":"BTC-USD","time":"2020-06-30T19:12:41.957060Z","sequence":180755704,"price":"9104.61","order_id":"1a64c913-01dd-4ef1-bffc-d5ece08a93dc","remaining_size":"0.133"}
{"type":"done","side":"sell","product_id":"BTC-USD","time":"2020-06-30T19:12:42.138456Z","sequence":180755705,"order_id":"509a40d1-3e91-4912-90cc-892bff5ef84f","reason":"canceled","price":"9154.9","remaining_size":"0.0149"}
{"type":"received","side":"buy","product_id":"BTC-USD","time":"2020-06-30T19:12:42.504629Z","sequence":180755706,"order_id":"c76defa4-3cb4-4608-9dd3-b2942ef47008","order_type":"limit","size":"0.0661","price":"9079.69","client_oid":""}
{"type":"open","side":"buy","product_id":"BTC-USD","time":"2020-06-30T19:12:42.504629Z","sequence":180755707,"price":"9079.69","order_id":"c76defa4-3cb4-4608-9dd3-b2942ef47008","remaining_size":"0.0661"}
{"type":"heartbeat","last_trade_id":0,"product_id":"BTC-USD","sequence":180755707,"time":"2020-06-30T19:12:42.735110Z"}
{"type":"received","side":"sell","product_id":"BTC-USD","time":"2020-06-30T19:12:42.779376Z","sequence":180755708,"order_id":"baf95f26-e300-42c4-a7e3-462a0b02bbbb","order_type":"limit","size":"0.0527","price":"9160.24","client_oid":""}
{"type":"open","side":"sell","product_id":"BTC-USD","time":"2020-06-30T19:12:42.779376Z","sequence":180755709,"price":"9160.24","order_id":"baf95f26-e300-42c4-a7e3-462a0b02bbbb","remaining_size":"0.0527"}
{"type":"done","side":"buy","product_id":"BTC-USD","time":"2020-06-30T19:12:42.918125Z","sequence":180755710,"order_id":"53bb6d82-6c31-49e5-a438-65572e6c18ef","reason":"canceled","price":"9104.04","remaining_size":"0.04"}
{"type":"done","side":"buy","product_id":"BTC-USD","time":"2020-06-30T19:12:42.931710Z","sequence":180755711,"order_id":"b1f668c8-bfe1-45b8-b8e0-df3ddddaef40","reason":"canceled","price":"8987.61","remaining_size":"0.002"}
{"type":"received","side":"sell","product_id":"BTC-USD","time":"2020-06-30T19:12:43.042781Z","sequence":180755712,"order_id":"8e89d5de-2c98-440f-b803-d9dac0b83672","order_type":"limit","size":"1.632","price":"9116.33","client_oid":""}
{"type":"match","side":"buy","product_id":"BTC-USD","time":"2020-06-30T19:12:43.042781Z","sequence":180755713,"trade_id":14587473,"maker_order_id":"91b59a7c-6a07-4039-9536-21daf3cb3282","taker_order_id":"8e89d5de-2c98-440f-b803-d9dac0b83672","size":"1.632","price":"9120.8"}
{"type":"done","side":"sell","product_id":"BTC-USD","time":"2020-06-30T19:12:43.042781Z","sequence":180755714,"order_id":"8e89d5de-2c98-440f-b803-d9dac0b83672","reason":"filled","price":"9116.33","remaining_size":"0"}
{"type":"done","side":"sell","product_id":"BTC-USD","time":"2020-06-30T19:12:43.250173Z","sequence":180755715,"order_id":"734cf2ac-1a6c-4f6f-bf4f-ab813ca6c284","reason":"canceled","price":"9146.15","remaining_size":"0.0547"}
{"type":"received","side":"sell","product_id":"BTC-USD","time":"2020-06-30T19:12:43.602392Z","sequence":180755716,"order_id":"542ccd79-1897-42c9-be65-1b6e681de573","order_type":"limit","size":"14.669","price":"9103.68","client_oid":""}
{"type":"match","side":"buy","product_id":"BTC-USD","time":"2020-06-30T19:12:43.602392Z","sequence":180755717,"trade_id":14587474,"maker_order_id":"91b59a7c-6a07-4039-9536-21daf3cb3282","taker_order_id":"542ccd79-1897-42c9-be65-1b6e681de573","size":"14.669","price":"9120.8"}
{"type":"done","side":"sell","product_id":"BTC-USD","time":"2020-06-30T19:12:43.602392Z","sequence":180755718,"order_id":"542ccd79-1897-42c9-be65-1b6e681de573","reason":"filled","price":"9103.68","remaining_size":"0"}
{"type":"heartbeat","last_trade_id":0,"product_id":"BTC-USD","sequence":180755718,"time":"2020-06-30T19:12:43.735119Z"}
{"type":"received","side":"sell","product_id":"BTC-USD","time":"2020-06-30T19:12:43.870263Z","sequence":180755719,"order_id":"7fd3a374-21c6-49a5-8787-e83e302c2e3c","order_type":"limit","size":"1.2309","price":"9128.98","client_oid":""}
{"type":"open","side":"sell","product_id":"BTC-USD","time":"2020-06-30T19:12:43.870263Z","sequence":180755720,"price":"9128.98","order_id":"7fd3a374-21c6-49a5-8787-e83e302c2e3c","remaining_size":"1.2309"}
{"type":"received","side":"buy","product_id":"BTC-USD","time":"2020-06-30T19:12:44.059782Z","sequence":180755721,"order_id":"196e71c0-9c86-4486-a940-f1413845ae9f","order_type":"limit","size":"0.01","price":"100","client_oid":"f66af257-c457-4564-9a82-aeaa06272781"}
{"type":"open","side":"buy","product_id":"BTC-USD","time":"2020-06-30T19:12:44.059782Z","sequence":180755722,"price":"100","order_id":"196e71c0-9c86-4486-a940-f1413845ae9f","remaining_size":"0.01"}
{"type":"done","side":"buy","product_id":"BTC-USD","time":"2020-06-30T19:12:44.066515Z","sequence":180755723,"order_id":"196e71c0-9c86-4486-a940-f1413845ae9f","reason":"canceled","price":"100","remaining_size":"0.01"}
{"type":"received","side":"sell","product_id":"BTC-USD","time":"2020-06-30T19:12:44.159170Z","sequence":180755724,"order_id":"1b9e3173-b5b5-424a-9647-5db8b3ea8ded","order_type":"limit","size":"0.0659","price":"9103.6","client_oid":""}
{"type":"match","side":"buy","product_id":"BTC-USD","time":"2020-06-30T19:12:44.159170Z","sequence":180755725,"trade_id":14587475,"maker_order_id":"91b59a7c-6a07-4039-9536-21daf3cb3282","taker_order_id":"1b9e3173-b5b5-424a-9647-5db8b3ea8ded","size":"0.0659","price":"9120.8"}
{"type":"done","side":"sell","product_id":"BTC-USD","time":"2020-06-30T19:12:44.159170Z","sequence":180755726,"order_id":"1b9e3173-b5b5-424a-9647-5db8b3ea8ded","reason":"filled","price":"9103.6","remaining_size":"0"}
{"type":"received","side":"sell","product_id":"BTC-USD","time":"2020-06-30T19:12:44.437290Z","sequence":180755727,"order_id":"a997d59f-a453-4d51-9a33-2f184d5ab54a","order_type":"limit","size":"0.0659","price":"9103.54","client_oid":""}
{"type":"match","side":"buy","product_id":"BTC-USD","time":"2020-06-30T19:12:44.437290Z","sequence":180755728,"trade_id":14587476,"maker_order_id":"91b59a7c-6a07-4039-9536-21daf3cb3282","taker_order_id":"a997d59f-a453-4d51-9a33-2f184d5ab54a","size":"0.0659","price":"9120.8"}
{"type":"done","side":"sell","product_id":"BTC-USD","time":"2020-06-30T19:12:44.437290Z","sequence":180755729,"order_id":"a997d59f-a453-4d51-9a33-2f184d5ab54a","reason":"filled","price":"9103.54","remaining_size":"0"}
{"type":"received","side":"sell","product_id":"BTC-USD","time":"2020-06-30T19:12:44.704867Z","sequence":180755730,"order_id":"f3239839-cc35-4f5d-9baf-992f356229c9","order_type":"limit","size":"0.05","price":"9103.48","client_oid":""}
{"type":"match","side":"buy","product_id":"BTC-USD","time":"2020-06-30T19:12:44.704867Z","sequence":180755731,"trade_id":14587477,"maker_order_id":"91b59a7c-6a07-4039-9536-21daf3cb3282","taker_order_id":"f3239839-cc35-4f5d-9baf-992f356229c9","size":"0.05","price":"9120.8"}
{"type":"done","side":"sell","product_id":"BTC-USD","time":"2020-06-30T19:12:44.704867Z","sequence":180755732,"order_id":"f3239839-cc35-4f5d-9baf-992f356229c9","reason":"filled","price":"9103.48","remaining_size":"0"}
{"type":"heartbeat","last_trade_id":0,"product_id":"BTC-USD","sequence":180755732,"time":"2020-06-30T19:12:44.735118Z"}
{"type":"received","side":"buy","product_id":"BTC-USD","time":"2020-06-30T19:12:45.267604Z","sequence":180755733,"order_id":"e969f413-878c-4898-a0a1-fcf947f37138","order_type":"limit","size":"0.0693","price":"9077.25","client_oid":""}
