{"type":"done","side":"buy","product_id":"BTC-USD","time":"2020-06-30T19:14:58.599951Z","sequence":180756538,"order_id":"c20df563-781d-4fab-be58-dd824f58978b","reason":"canceled","price":"8893.18","remaining_size":"0.04654411"}
{"type":"heartbeat","last_trade_id":0,"product_id":"BTC-USD","sequence":180756538,"time":"2020-06-30T19:14:58.735115Z"}
{"type":"received","side":"sell","product_id":"BTC-USD","time":"2020-06-30T19:14:58.766931Z","sequence":180756539,"order_id":"1a446af2-3b78-4aa6-ab40-06cfa13d912f","order_type":"limit","size":"0.05","price":"9113.39","client_oid":""}
{"type":"match","side":"buy","product_id":"BTC-USD","time":"2020-06-30T19:14:58.766931Z","sequence":180756540,"trade_id":14587575,"maker_order_id":"91b59a7c-6a07-4039-9536-21daf3cb3282","taker_order_id":"1a446af2-3b78-4aa6-ab40-06cfa13d912f","size":"0.05","price":"9120.8"}
{"type":"done","side":"sell","product_id":"BTC-USD","time":"2020-06-30T19:14:58.766931Z","sequence":180756541,"order_id":"1a446af2-3b78-4aa6-ab40-06cfa13d912f","reason":"filled","price":"9113.39","remaining_size":"0"}
{"type":"received","side":"buy","product_id":"BTC-USD","time":"2020-06-30T19:14:58.836383Z","sequence":180756542,"order_id":"ca03a0b3-dc33-418c-8b0e-69c28ed2ef4b","order_type":"limit","size":"0.04664204","price":"8892.39","client_oid":""}
{"type":"open","side":"buy","product_id":"BTC-USD","time":"2020-06-30T19:14:58.836383Z","sequence":180756543,"price":"8892.39","order_id":"ca03a0b3-dc33-418c-8b0e-69c28ed2ef4b","remaining_size":"0.04664204"}
{"type":"received","side":"sell","product_id":"BTC-USD","time":"2020-06-30T19:14:59.030484Z","sequence":180756544,"order_id":"6152b000-cb37-4934-adbe-803a5dc65c2f","order_type":"limit","size":"0.114","price":"9112.11","client_oid":""}
{"type":"match","side":"buy","product_id":"BTC-USD","time":"2020-06-30T19:14:59.030484Z","sequence":180756545,"trade_id":14587576,"maker_order_id":"91b59a7c-6a07-4039-9536-21daf3cb3282","taker_order_id":"6152b000-cb37-4934-adbe-803a5dc65c2f","size":"0.114","price":"9120.8"}
{"type":"done","side":"sell","product_id":"BTC-USD","time":"2020-06-30T19:14:59.030484Z","sequence":180756546,"order_id":"6152b000-cb37-4934-adbe-803a5dc65c2f","reason":"filled","price":"9112.11","remaining_size":"0"}
{"type":"done","side":"sell","product_id":"BTC-USD","time":"2020-06-30T19:14:59.166644Z","sequence":180756547,"order_id":"7d776b77-71e0-4cb4-8a3c-1fea7746bbd4","reason":"canceled","price":"9437.82","remaining_size":"0.00728822"}
{"type":"received","side":"buy","product_id":"BTC-USD","time":"2020-06-30T19:14:59.185929Z","sequence":180756548,"order_id":"518a09e4-6a1c-49e1-9eec-cfa1f9cf03e4","order_type":"limit","size":"0.01","price":"100","client_oid":"1716fc85-6c5c-41fa-a511-9a4155b3b06a"}
{"type":"open","side":"buy","product_id":"BTC-USD","time":"2020-06-30T19:14:59.185929Z","sequence":180756549,"price":"100","order_id":"518a09e4-6a1c-49e1-9eec-cfa1f9cf03e4","remaining_size":"0.01"}
{"type":"done","side":"buy","product_id":"BTC-USD","time":"2020-06-30T19:14:59.192136Z","sequence":180756550,"order_id":"518a09e4-6a1c-49e1-9eec-cfa1f9cf03e4","reason":"canceled","price":"100","remaining_size":"0.01"}
{"type":"received","side":"sell","product_id":"BTC-USD","time":"2020-06-30T19:14:59.384034Z","sequence":180756551,"order_id":"90acf728-3bb5-406a-b83a-2abbb34343c7","order_type":"limit","size":"0.007384","price":"9438.66","client_oid":""}
{"type":"open","side":"sell","product_id":"BTC-USD","time":"2020-06-30T19:14:59.384034Z","sequence":180756552,"price":"9438.66","order_id":"90acf728-3bb5-406a-b83a-2abbb34343c7","remaining_size":"0.007384"}
{"type":"heartbeat","last_trade_id":0,"product_id":"BTC-USD","sequence":180756552,"time":"2020-06-30T19:14:59.735119Z"}
{"type":"received","side":"buy","product_id":"BTC-USD","time":"2020-06-30T19:15:00.140933Z","sequence":180756553,"order_id":"944673be-2e83-46ee-a9c6-3f240706268a","order_type":"limit","size":"0.0223","price":"9099.18","client_oid":""}
{"type":"open","side":"buy","product_id":"BTC-USD","time":"2020-06-30T19:15:00.140933Z","sequence":180756554,"price":"9099.18","order_id":"944673be-2e83-46ee-a9c6-3f240706268a","remaining_size":"0.0223"}
{"type":"done","side":"buy","product_id":"BTC-USD","time":"2020-06-30T19:15:00.582070Z","sequence":180756555,"order_id":"3a784603-2c9f-459c-9bdf-602cfc5def65","reason":"canceled","price":"9100.96","remaining_size":"0.0307"}
{"type":"heartbeat","last_trade_id":0,"product_id":"BTC-USD","sequence":180756555,"time":"2020-06-30T19:15:00.735119Z"}
{"type":"received","side":"buy","product_id":"BTC-USD","time":"2020-06-30T19:15:00.825090Z","sequence":180756556,"order_id":"90ccb0a2-3a8d-48e1-b499-3abe853700c7","order_type":"limit","size":"1.5","price":"9110.69","client_oid":""}
{"type":"open","side":"buy","product_id":"BTC-USD","time":"2020-06-30T19:15:00.825090Z","sequence":180756557,"price":"9110.69","order_id":"90ccb0a2-3a8d-48e1-b499-3abe853700c7","remaining_size":"1.5"}
{"type":"done","side":"buy","product_id":"BTC-USD","time":"2020-06-30T19:15:01.289436Z","sequence":180756558,"order_id":"85f9ad7f-e3e9-453b-b45e-e939442c9427","reason":"canceled","price":"9112.39","remaining_size":"7.6778"}
{"type":"received","side":"buy","product_id":"BTC-USD","time":"2020-06-30T19:15:01.320558Z","sequence":180756559,"order_id":"331137bc-8461-41a8-9540-ac8432613658","order_type":"limit","size":"0.049","price":"9103.65","client_oid":""}
{"type":"open","side":"buy","product_id":"BTC-USD","time":"2020-06-30T19:15:01.320558Z","sequence":180756560,"price":"9103.65","order_id":"331137bc-8461-41a8-9540-ac8432613658","remaining_size":"0.049"}
{"type":"done","side":"buy","product_id":"BTC-USD","time":"2020-06-30T19:15:01.334156Z","sequence":180756561,"order_id":"5e028cad-3ee7-4dea-9540-fc67842c1d38","reason":"canceled","price":"9107.96","remaining_size":"0.7968"}
{"type":"heartbeat","last_trade_id":0,"product_id":"BTC-USD","sequence":180756561,"time":"2020-06-30T19:15:01.735115Z"}
{"type":"done","side":"buy","product_id":"BTC-USD","time":"2020-06-30T19:15:01.778104Z","sequence":180756562,"order_id":"c6dd6b5a-6edb-4aa8-a7f3-e01917da31ab","reason":"canceled","price":"9112.31","remaining_size":"0.301"}
{"type":"received","side":"sell","product_id":"BTC-USD","time":"2020-06-30T19:15:01.894592Z","sequence":180756563,"order_id":"52c9fd6c-c332-4389-a142-3c796a264733","order_type":"limit","size":"0.0423","price":"9158.44","client_oid":""}
{"type":"open","side":"sell","product_id":"BTC-USD","time":"2020-06-30T19:15:01.894592Z","sequence":180756564,"price":"9158.44","order_id":"52c9fd6c-c332-4389-a142-3c796a264733","remaining_size":"0.0423"}
{"type":"received","side":"sell","product_id":"BTC-USD","time":"2020-06-30T19:15:02.244869Z","sequence":180756565,"order_id":"0076df23-2c5a-469e-b866-5d7394cb4889","order_type":"limit","size":"0.0423","price":"9159.91","client_oid":""}
{"type":"open","side":"sell","product_id":"BTC-USD","time":"2020-06-30T19:15:02.244869Z","sequence":180756566,"price":"9159.91","order_id":"0076df23-2c5a-469e-b866-5d7394cb4889","remaining_size":"0.0423"}
{"type":"received","side":"buy","product_id":"BTC-USD","time":"2020-06-30T19:15:02.491142Z","sequence":180756567,"order_id":"b5008080-745b-42f4-a359-1657f081be9c","order_type":"limit","size":"0.0271","price":"9112.04","client_oid":""}
{"type":"open","side":"buy","product_id":"BTC-USD","time":"2020-06-30T19:15:02.491142Z","sequence":180756568,"price":"9112.04","order_id":"b5008080-745b-42f4-a359-1657f081be9c","remaining_size":"0.0271"}
{"type":"received","side":"sell","product_id":"BTC-USD","time":"2020-06-30T19:15:02.742392Z","sequence":180756569,"order_id":"c92466d8-9320-4ece-87a9-544a2c9e52dc","order_type":"limit","size":"0.0658","price":"9112.98","client_oid":""}
{"type":"match","side":"buy","product_id":"BTC-USD","time":"2020-06-30T19:15:02.742392Z","sequence":180756570,"trade_id":14587577,"maker_order_id":"91b59a7c-6a07-4039-9536-21daf3cb3282","taker_order_id":"c92466d8-9320-4ece-87a9-544a2c9e52dc","size":"0.0658","price":"9120.8"}
{"type":"done","side":"sell","product_id":"BTC-USD","time":"2020-06-30T19:15:02.742392Z","sequence":180756571,"order_id":"c92466d8-9320-4ece-87a9-544a2c9e52dc","reason":"filled","price":"9112.98","remaining_size":"0"}
{"type":"heartbeat","last_trade_id":0,"product_id":"BTC-USD","sequence":180756571,"time":"2020-06-30T19:15:02.735115Z"}
{"type":"heartbeat","last_trade_id":0,"product_id":"BTC-USD","sequence":180756571,"time":"2020-06-30T19:15:03.735116Z"}
{"type":"received","side":"buy","product_id":"BTC-USD","time":"2020-06-30T19:15:04.154950Z","sequence":180756572,"order_id":"00fd3cfa-cf32-4ead-b6f4-028cc971f5ea","order_type":"limit","size":"0.0658","price":"9105.72","client_oid":""}
{"type":"open","side":"buy","product_id":"BTC-USD","time":"2020-06-30T19:15:04.154950Z","sequence":180756573,"price":"9105.72","order_id":"00fd3cfa-cf32-4ead-b6f4-028cc971f5ea","remaining_size":"0.0658"}
{"type":"received","side":"buy","product_id":"BTC-USD","time":"2020-06-30T19:15:04.456327Z","sequence":180756574,"order_id":"26526490-a0c0-425f-8140-f192d5ab4938","order_type":"limit","size":"0.0383","price":"9091.02","client_oid":""}
{"type":"open","side":"buy","product_id":"BTC-USD","time":"2020-06-30T19:15:04.456327Z","sequence":180756575,"price":"9091.02","order_id":"26526490-a0c0-425f-8140-f192d5ab4938","remaining_size":"0.0383"}
{"type":"heartbeat","last_trade_id":0,"product_id":"BTC-USD","sequence":180756575,"time":"2020-06-30T19:15:04.735117Z"}
{"type":"received","side":"sell","product_id":"BTC-USD","time":"2020-06-30T19:15:04.956563Z","sequence":180756576,"order_id":"14999781-132d-4da0-b2f3-750e45ab1690","order_type":"limit","size":"0.069","price":"9159.39","client_oid":""}
{"type":"open","side":"sell","product_id":"BTC-USD","time":"2020-06-30T19:15:04.956563Z","sequence":180756577,"price":"9159.39","order_id":"14999781-132d-4da0-b2f3-750e45ab1690","remaining_size":"0.069"}
{"type":"received","side":"buy","product_id":"BTC-USD","time":"2020-06-30T19:15:05.269115Z","sequence":180756578,"order_id":"f05d2dd4-978c-42d7-8d7c-69748f471efb","order_type":"limit","size":"0.9596","price":"9076.11","client_oid":""}
{"type":"open","side":"buy","product_id":"BTC-USD","time":"2020-06-30T19:15:05.269115Z","sequence":180756579,"price":"9076.11","order_id":"f05d2dd4-978c-42d7-8d7c-69748f471efb","remaining_size":"0.9596"}
{"type":"received","side":"buy","product_id":"BTC-USD","time":"2020-06-30T19:15:05.531417Z","sequence":180756580,"order_id":"6bc9d272-724d-4cc0-a24e-0116269f940e","order_type":"limit","size":"0.2505","price":"9111.57","client_oid":""}
{"type":"open","side":"buy","product_id":"BTC-USD","time":"2020-06-30T19:15:05.531417Z","sequence":180756581,"price":"9111.57","order_id":"6bc9d272-724d-4cc0-a24e-0116269f940e","remaining_size":"0.2505"}
{"type":"heartbeat","last_trade_id":0,"product_id":"BTC-USD","sequence":180756581,"time":"2020-06-30T19:15:05.735123Z"}
{"type":"received","side":"sell","product_id":"BTC-USD","time":"2020-06-30T19:15:05.894732Z","sequence":180756582,"order_id":"5f9858e8-68ab-4054-b961-ed99c61e9ae9","order_type":"limit","size":"0.0647","price":"9157.05","client_oid":""}
{"type":"open","side":"sell","product_id":"BTC-USD","time":"2020-06-30T19:15:05.894732Z","sequence":180756583,"price":"9157.05","order_id":"5f9858e8-68ab-4054-b961-ed99c61e9ae9","remaining_size":"0.0647"}
{"type":"received","side":"buy","product_id":"BTC-USD","time":"2020-06-30T19:15:06.350476Z","sequence":180756584,"order_id":"f54bed8e-a72d-4ca3-a0b9-085b6fecc1d5","order_type":"limit","size":"0.2653","price":"9111.59","client_oid":""}
{"type":"open","side":"buy","product_id":"BTC-USD","time":"2020-06-30T19:15:06.350476Z","sequence":180756585,"price":"9111.59","order_id":"f54bed8e-a72d-4ca3-a0b9-085b6fecc1d5","remaining_size":"0.2653"}
{"type":"done","side":"sell","product_id":"BTC-USD","time":"2020-06-30T19:15:06.382489Z","sequence":180756586,"order_id":"2a6056d2-0eb0-49c8-b8d0-9efb1dd45b9c","reason":"canceled","price":"9130.3","remaining_size":"0.5"}
{"type":"done","side":"sell","product_id":"BTC-USD","time":"2020-06-30T19:15:06.395279Z","sequence":180756587,"order_id":"0076df23-2c5a-469e-b866-5d7394cb4889","reason":"canceled","price":"9159.91","remaining_size":"0.0423"}
{"type":"done","side":"buy","product_id":"BTC-USD","time":"2020-06-30T19:15:06.601451Z","sequence":180756588,"order_id":"7e90a946-e2d2-4750-9bc8-1518295a0b5b","reason":"canceled","price":"9103.34","remaining_size":"0.0223"}
{"type":"received","side":"sell","product_id":"BTC-USD","time":"2020-06-30T19:15:06.637174Z","sequence":180756589,"order_id":"4f256a96-de01-49a0-9075-4bdf47afcf89","order_type":"limit","size":"4.3795","price":"9111.95","client_oid":""}
{"type":"match","side":"buy","product_id":"BTC-USD","time":"2020-06-30T19:15:06.637174Z","sequence":180756590,"trade_id":14587578,"maker_order_id":"91b59a7c-6a07-4039-9536-21daf3cb3282","taker_order_id":"4f256a96-de01-49a0-9075-4bdf47afcf89","size":"4.3795","price":"9120.8"}
{"type":"done","side":"sell","product_id":"BTC-USD","time":"2020-06-30T19:15:06.637174Z","sequence":180756591,"order_id":"4f256a96-de01-49a0-9075-4bdf47afcf89","reason":"filled","price":"9111.95","remaining_size":"0"}
{"type":"heartbeat","last_trade_id":0,"product_id":"BTC-USD","sequence":180756591,"time":"2020-06-30T19:15:06.735115Z"}
{"type":"received","side":"sell","product_id":"BTC-USD","time":"2020-06-30T19:15:06.772930Z","sequence":180756592,"order_id":"5e2c7d90-4321-45f4-822f-5f71166ce2bb","order_type":"limit","size":"0.02","price":"9126.36","client_oid":""}
{"type":"open","side":"sell","product_id":"BTC-USD","time":"2020-06-30T19:15:06.772930Z","sequence":180756593,"price":"9126.36","order_id":"5e2c7d90-4321-45f4-822f-5f71166ce2bb","remaining_size":"0.02"}
{"type":"heartbeat","last_trade_id":0,"product_id":"BTC-USD","sequence":180756593,"time":"2020-06-30T19:15:07.735112Z"}
{"type":"received","side":"sell","product_id":"BTC-USD","time":"2020-06-30T19:15:07.768205Z","sequence":180756594,"order_id":"93fe8372-23b1-47e1-be5d-accd5ec8fbf4","order_type":"limit","size":"4.5028","price":"9111.95","client_oid":""}
{"type":"match","side":"buy","product_id":"BTC-USD","time":"2020-06-30T19:15:07.768205Z","sequence":180756595,"trade_id":14587579,"maker_order_id":"91b59a7c-6a07-4039-9536-21daf3cb3282","taker_order_id":"93fe8372-23b1-47e1-be5d-accd5ec8fbf4","size":"4.5028","price":"9120.8"}
{"type":"done","side":"sell","product_id":"BTC-USD","time":"2020-06-30T19:15:07.768205Z","sequence":180756596,"order_id":"93fe8372-23b1-47e1-be5d-accd5ec8fbf4","reason":"filled","price":"9111.95","remaining_size":"0"}
{"type":"received","side":"buy","product_id":"BTC-USD","time":"2020-06-30T19:15:08.058861Z","sequence":180756597,"order_id":"32b7ec95-3f75-47ba-a21c-927ef7ee866d","order_type":"limit","size":"0.2506","price":"9111.6","client_oid":""}
{"type":"open","side":"buy","product_id":"BTC-USD","time":"2020-06-30T19:15:08.058861Z","sequence":180756598,"price":"9111.6","order_id":"32b7ec95-3f75-47ba-a21c-927ef7ee866d","remaining_size":"0.2506"}
{"type":"done","side":"sell","product_id":"BTC-USD","time":"2020-06-30T19:15:08.232029Z","sequence":180756599,"order_id":"4da119a8-62dc-4f71-adef-e9217196b180","reason":"canceled","price":"9159.92","remaining_size":"0.069"}
{"type":"received","side":"sell","product_id":"BTC-USD","time":"2020-06-30T19:15:08.329752Z","sequence":180756600,"order_id":"7bb368fa-c16d-4d60-932a-4ec42e0a9d68","order_type":"limit","size":"0.25","price":"9113.84","client_oid":""}
{"type":"match","side":"buy","product_id":"BTC-USD","time":"2020-06-30T19:15:08.329752Z","sequence":180756601,"trade_id":14587580,"maker_order_id":"91b59a7c-6a07-4039-9536-21daf3cb3282","taker_order_id":"7bb368fa-c16d-4d60-932a-4ec42e0a9d68","size":"0.25","price":"9120.8"}
{"type":"done","side":"sell","product_id":"BTC-USD","time":"2020-06-30T19:15:08.329752Z","sequence":180756602,"order_id":"7bb368fa-c16d-4d60-932a-4ec42e0a9d68","reason":"filled","price":"9113.84","remaining_size":"0"}
{"type":"done","side":"buy","product_id":"BTC-USD","time":"2020-06-30T19:15:08.496902Z","sequence":180756603,"order_id":"b5008080-745b-42f4-a359-1657f081be9c","reason":"canceled","price":"9112.04","remaining_size":"0.0271"}
{"type":"done","side":"buy","product_id":"BTC-USD","time":"2020-06-30T19:15:08.505662Z","sequence":180756604,"order_id":"00fd3cfa-cf32-4ead-b6f4-028cc971f5ea","reason":"canceled","price":"9105.72","remaining_size":"0.0658"}
{"type":"done","side":"buy","product_id":"BTC-USD","time":"2020-06-30T19:15:08.508596Z","sequence":180756605,"order_id":"4ba52283-2340-4f5a-9015-75d18e849dc7","reason":"canceled","price":"9086.64","remaining_size":"0.087"}
{"type":"done","side":"buy","product_id":"BTC-USD","time":"2020-06-30T19:15:08.517057Z","sequence":180756606,"order_id":"52e424c0-edf4-4891-8c05-417889e67f16","reason":"canceled","price":"9067.17","remaining_size":"0.063"}
{"type":"heartbeat","last_trade_id":0,"product_id":"BTC-USD","sequence":180756606,"time":"2020-06-30T19:15:08.735114Z"}
{"type":"received","side":"sell","product_id":"BTC-USD","time":"2020-06-30T19:15:08.923744Z","sequence":180756607,"order_id":"7ffac332-1908-465c-ac79-fd2dee0b5ee3","order_type":"limit","size":"0.0571","price":"9157.58","client_oid":""}
{"type":"open","side":"sell","product_id":"BTC-USD","time":"2020-06-30T19:15:08.923744Z","sequence":180756608,"price":"9157.58","order_id":"7ffac332-1908-465c-ac79-fd2dee0b5ee3","remaining_size":"0.0571"}
{"type":"received","side":"sell","product_id":"BTC-USD","time":"2020-06-30T19:15:09.169948Z","sequence":180756609,"order_id":"aa7182b0-eb59-4093-abd5-72aa30dd8fc4","order_type":"limit","size":"0.0329","price":"9157.04","client_oid":""}
{"type":"open","side":"sell","product_id":"BTC-USD","time":"2020-06-30T19:15:09.169948Z","sequence":180756610,"price":"9157.04","order_id":"aa7182b0-eb59-4093-abd5-72aa30dd8fc4","remaining_size":"0.0329"}
{"type":"received","side":"buy","product_id":"BTC-USD","time":"2020-06-30T19:15:09.732453Z","sequence":180756611,"order_id":"420eb792-3505-4d83-8cff-93256c3a4ace","order_type":"limit","size":"0.01","price":"9077.42","client_oid":""}
{"type":"open","side":"buy","product_id":"BTC-USD","time":"2020-06-30T19:15:09.732453Z","sequence":180756612,"price":"9077.42","order_id":"420eb792-3505-4d83-8cff-93256c3a4ace","remaining_size":"0.01"}
{"type":"heartbeat","last_trade_id":0,"product_id":"BTC-USD","sequence":180756612,"time":"2020-06-30T19:15:09.735117Z"}
{"type":"done","side":"buy","product_id":"BTC-USD","time":"2020-06-30T19:15:09.922282Z","sequence":180756613,"order_id":"32b7ec95-3f75-47ba-a21c-927ef7ee866d","reason":"canceled","price":"9111.6","remaining_size":"0.2506"}
{"type":"done","side":"buy","product_id":"BTC-USD","time":"2020-06-30T19:15:09.926049Z","sequence":180756614,"order_id":"fb074f90-f18b-4c98-a92e-5845cec7a31d","reason":"canceled","price":"9103.48","remaining_size":"0.0223"}
{"type":"received","side":"sell","product_id":"BTC-USD","time":"2020-06-30T19:15:10.294380Z","sequence":180756615,"order_id":"b9d8d4b1-6d97-499e-8854-664824554907","order_type":"limit","size":"0.1058","price":"9157.8","client_oid":""}
{"type":"open","side":"sell","product_id":"BTC-USD","time":"2020-06-30T19:15:10.294380Z","sequence":180756616,"price":"9157.8","order_id":"b9d8d4b1-6d97-499e-8854-664824554907","remaining_size":"0.1058"}
{"type":"received","side":"sell","product_id":"BTC-USD","time":"2020-06-30T19:15:10.554765Z","sequence":180756617,"order_id":"8ef7fc0f-fad2-4e66-8adc-cf01e3d5ffe0","order_type":"limit","size":"0.0278","price":"9156.96","client_oid":""}
{"type":"open","side":"sell","product_id":"BTC-USD","time":"2020-06-30T19:15:10.554765Z","sequence":180756618,"price":"9156.96","order_id":"8ef7fc0f-fad2-4e66-8adc-cf01e3d5ffe0","remaining_size":"0.0278"}
{"type":"received","side":"sell","product_id":"BTC-USD","time":"2020-06-30T19:15:10.662974Z","sequence":180756619,"order_id":"64dec0f3-edc4-48d9-a682-adfb4deb62bb","order_type":"market","size":"0.001","funds":"9.1208","client_oid":""}
{"type":"match","side":"buy","product_id":"BTC-USD","time":"2020-06-30T19:15:10.662974Z","sequence":180756620,"trade_id":14587581,"maker_order_id":"91b59a7c-6a07-4039-9536-21daf3cb3282","taker_order_id":"64dec0f3-edc4-48d9-a682-adfb4deb62bb","size":"0.001","price":"9120.8"}
{"type":"done","side":"sell","product_id":"BTC-USD","time":"2020-06-30T19:15:10.662974Z","sequence":180756621,"order_id":"64dec0f3-edc4-48d9-a682-adfb4deb62bb","reason":"filled","remaining_size":"0"}
{"type":"done","side":"sell","product_id":"BTC-USD","time":"2020-06-30T19:15:10.730343Z","sequence":180756622,"order_id":"5f9858e8-68ab-4054-b961-ed99c61e9ae9","reason":"canceled","price":"9157.05","remaining_size":"0.0647"}
{"type":"done","side":"sell","product_id":"BTC-USD","time":"2020-06-30T19:15:10.733574Z","sequence":180756623,"order_id":"7ffac332-1908-465c-ac79-fd2dee0b5ee3","reason":"canceled","price":"9157.58","remaining_size":"0.0571"}
{"type":"heartbeat","last_trade_id":0,"product_id":"BTC-USD","sequence":180756623,"time":"2020-06-30T19:15:10.735113Z"}
{"type":"done","side":"sell","product_id":"BTC-USD","time":"2020-06-30T19:15:10.991061Z","sequence":180756624,"order_id":"8cb77ce0-2af7-477f-a287-99fe442c82d7","reason":"canceled","price":"9142.27","remaining_size":"0.0443"}
{"type":"received","side":"sell","product_id":"BTC-USD","time":"2020-06-30T19:15:11.116811Z","sequence":180756625,"order_id":"8ea92269-dfaa-4b01-b71e-90f2553c0c7c","order_type":"limit","size":"0.069","price":"9156","client_oid":""}
{"type":"open","side":"sell","product_id":"BTC-USD","time":"2020-06-30T19:15:11.116811Z","sequence":180756626,"price":"9156","order_id":"8ea92269-dfaa-4b01-b71e-90f2553c0c7c","remaining_size":"0.069"}
{"type":"received","side":"sell","product_id":"BTC-USD","time":"2020-06-30T19:15:11.389422Z","sequence":180756627,"order_id":"ee5e73c0-5df9-40e5-8570-b8be65dc394f","order_type":"limit","size":"4.468","price":"9111.95","client_oid":""}
{"type":"match","side":"buy","product_id":"BTC-USD","time":"2020-06-30T19:15:11.389422Z","sequence":180756628,"trade_id":14587582,"maker_order_id":"91b59a7c-6a07-4039-9536-21daf3cb3282","taker_order_id":"ee5e73c0-5df9-40e5-8570-b8be65dc394f","size":"4.468","price":"9120.8"}
{"type":"done","side":"sell","product_id":"BTC-USD","time":"2020-06-30T19:15:11.389422Z","sequence":180756629,"order_id":"ee5e73c0-5df9-40e5-8570-b8be65dc394f","reason":"filled","price":"9111.95","remaining_size":"0"}
{"type":"received","side":"sell","product_id":"BTC-USD","time":"2020-06-30T19:15:11.684010Z","sequence":180756630,"order_id":"2d2039ad-850b-4e67-ba62-b4909f2c653e","order_type":"limit","size":"0.0149","price":"9158.94","client_oid":""}
{"type":"open","side":"sell","product_id":"BTC-USD","time":"2020-06-30T19:15:11.684010Z","sequence":180756631,"price":"9158.94","order_id":"2d2039ad-850b-4e67-ba62-b4909f2c653e","remaining_size":"0.0149"}
{"type":"heartbeat","last_trade_id":0,"product_id":"BTC-USD","sequence":180756631,"time":"2020-06-30T19:15:11.735122Z"}
{"type":"done","side":"sell","product_id":"BTC-USD","time":"2020-06-30T19:15:11.815013Z","sequence":180756632,"order_id":"8ef7fc0f-fad2-4e66-8adc-cf01e3d5ffe0","reason":"canceled","price":"9156.96","remaining_size":"0.0278"}
{"type":"received","side":"buy","product_id":"BTC-USD","time":"2020-06-30T19:15:11.972880Z","sequence":180756633,"order_id":"1f34bea0-91e0-4f89-820c-71577826ebf6","order_type":"limit","size":"0.0223","price":"9103.7","client_oid":""}
{"type":"open","side":"buy","product_id":"BTC-USD","time":"2020-06-30T19:15:11.972880Z","sequence":180756634,"price":"9103.7","order_id":"1f34bea0-91e0-4f89-820c-71577826ebf6","remaining_size":"0.0223"}
{"type":"heartbeat","last_trade_id":0,"product_id":"BTC-USD","sequence":180756634,"time":"2020-06-30T19:15:12.735119Z"}
{"type":"received","side":"sell","product_id":"BTC-USD","time":"2020-06-30T19:15:13.120517Z","sequence":180756635,"order_id":"48a87369-6208-47a0-afa3-7522d12d3853","order_type":"limit","size":"0.0658","price":"9112.99","client_oid":""}
{"type":"match","side":"buy","product_id":"BTC-USD","time":"2020-06-30T19:15:13.120517Z","sequence":180756636,"trade_id":14587583,"maker_order_id":"91b59a7c-6a07-4039-9536-21daf3cb3282","taker_order_id":"48a87369-6208-47a0-afa3-7522d12d3853","size":"0.0658","price":"9120.8"}
{"type":"done","side":"sell","product_id":"BTC-USD","time":"2020-06-30T19:15:13.120517Z","sequence":180756637,"order_id":"48a87369-6208-47a0-afa3-7522d12d3853","reason":"filled","price":"9112.99","remaining_size":"0"}
{"type":"done","side":"sell","product_id":"BTC-USD","time":"2020-06-30T19:15:13.597493Z","sequence":180756638,"order_id":"801a10b8-7277-43c8-8d24-6721c28f8ea5","reason":"canceled","price":"9145.45","remaining_size":"0.0547"}
{"type":"done","side":"sell","product_id":"BTC-USD","time":"2020-06-30T19:15:13.597537Z","sequence":180756639,"order_id":"2d2039ad-850b-4e67-ba62-b4909f2c653e","reason":"canceled","price":"9158.94","remaining_size":"0.0149"}
{"type":"received","side":"sell","product_id":"BTC-USD","time":"2020-06-30T19:15:13.677245Z","sequence":180756640,"order_id":"05cb3b35-4db3-4936-bd27-b7789f31f424","order_type":"limit","size":"0.0658","price":"9112.98","client_oid":""}
{"type":"match","side":"buy","product_id":"BTC-USD","time":"2020-06-30T19:15:13.677245Z","sequence":180756641,"trade_id":14587584,"maker_order_id":"91b59a7c-6a07-4039-9536-21daf3cb3282","taker_order_id":"05cb3b35-4db3-4936-bd27-b7789f31f424","size":"0.0658","price":"9120.8"}
{"type":"done","side":"sell","product_id":"BTC-USD","time":"2020-06-30T19:15:13.677245Z","sequence":180756642,"order_id":"05cb3b35-4db3-4936-bd27-b7789f31f424","reason":"filled","price":"9112.98","remaining_size":"0"}
{"type":"heartbeat","last_trade_id":0,"product_id":"BTC-USD","sequence":180756642,"time":"2020-06-30T19:15:13.735114Z"}
{"type":"received","side":"buy","product_id":"BTC-USD","time":"2020-06-30T19:15:13.972712Z","sequence":180756643,"order_id":"b36920b9-ac13-4a89-bb24-4add04c5ddba","order_type":"limit","size":"2.1879","price":"9094.89","client_oid":""}
{"type":"open","side":"buy","product_id":"BTC-USD","time":"2020-06-30T19:15:13.972712Z","sequence":180756644,"price":"9094.89","order_id":"b36920b9-ac13-4a89-bb24-4add04c5ddba","remaining_size":"2.1879"}
{"type":"received","side":"buy","product_id":"BTC-USD","time":"2020-06-30T19:15:14.038132Z","sequence":180756645,"order_id":"a9bcd0f0-ee7f-4811-bda8-690febe3f04b","order_type":"limit","size":"0.01","price":"100","client_oid":"ea6109d6-ac94-429e-8778-a78380990990"}
{"type":"open","side":"buy","product_id":"BTC-USD","time":"2020-06-30T19:15:14.038132Z","sequence":180756646,"price":"100","order_id":"a9bcd0f0-ee7f-4811-bda8-690febe3f04b","remaining_size":"0.01"}
{"type":"done","side":"buy","product_id":"BTC-USD","time":"2020-06-30T19:15:14.045145Z","sequence":180756647,"order_id":"a9bcd0f0-ee7f-4811-bda8-690febe3f04b","reason":"canceled","price":"100","remaining_size":"0.01"}
{"type":"received","side":"sell","product_id":"BTC-USD","time":"2020-06-30T19:15:14.228213Z","sequence":180756648,"order_id":"47b908ce-b8ef-44a9-820f-346989c9124c","order_type":"limit","size":"0.0781","price":"9112.43","client_oid":""}
{"type":"match","side":"buy","product_id":"BTC-USD","time":"2020-06-30T19:15:14.228213Z","sequence":180756649,"trade_id":14587585,"maker_order_id":"91b59a7c-6a07-4039-9536-21daf3cb3282","taker_order_id":"47b908ce-b8ef-44a9-820f-346989c9124c","size":"0.0781","price":"9120.8"}
{"type":"done","side":"sell","product_id":"BTC-USD","time":"2020-06-30T19:15:14.228213Z","sequence":180756650,"order_id":"47b908ce-b8ef-44a9-820f-346989c9124c","reason":"filled","price":"9112.43","remaining_size":"0"}
{"type":"heartbeat","last_trade_id":0,"product_id":"BTC-USD","sequence":180756650,"time":"2020-06-30T19:15:14.735120Z"}
{"type":"received","side":"sell","product_id":"BTC-USD","time":"2020-06-30T19:15:15.593756Z","sequence":180756651,"order_id":"49971880-d972-4491-9cad-92569eb8f7ac","order_type":"limit","size":"0.05","price":"9113.04","client_oid":""}
{"type":"match","side":"buy","product_id":"BTC-USD","time":"2020-06-30T19:15:15.593756Z","sequence":180756652,"trade_id":14587586,"maker_order_id":"91b59a7c-6a07-4039-9536-21daf3cb3282","taker_order_id":"49971880-d972-4491-9cad-92569eb8f7ac","size":"0.05","price":"9120.8"}
{"type":"done","side":"sell","product_id":"BTC-USD","time":"2020-06-30T19:15:15.593756Z","sequence":180756653,"order_id":"49971880-d972-4491-9cad-92569eb8f7ac","reason":"filled","price":"9113.04","remaining_size":"0"}
{"type":"heartbeat","last_trade_id":0,"product_id":"BTC-USD","sequence":180756653,"time":"2020-06-30T19:15:15.735128Z"}
{"type":"done","side":"sell","product_id":"BTC-USD","time":"2020-06-30T19:15:16.039775Z","sequence":180756654,"order_id":"8ea92269-dfaa-4b01-b71e-90f2553c0c7c","reason":"canceled","price":"9156","remaining_size":"0.069"}
{"type":"done","side":"sell","product_id":"BTC-USD","time":"2020-06-30T19:15:16.041118Z","sequence":180756655,"order_id":"14999781-132d-4da0-b2f3-750e45ab1690","reason":"canceled","price":"9159.39","remaining_size":"0.069"}
{"type":"received","side":"buy","product_id":"BTC-USD","time":"2020-06-30T19:15:16.139417Z","sequence":180756656,"order_id":"75fb6c35-123b-407d-b86f-eb02d2961c4d","order_type":"limit","size":"0.0036","price":"9111.44","client_oid":""}
{"type":"open","side":"buy","product_id":"BTC-USD","time":"2020-06-30T19:15:16.139417Z","sequence":180756657,"price":"9111.44","order_id":"75fb6c35-123b-407d-b86f-eb02d2961c4d","remaining_size":"0.0036"}
{"type":"received","side":"sell","product_id":"BTC-USD","time":"2020-06-30T19:15:16.418742Z","sequence":180756658,"order_id":"7d324cb8-b9e2-4f5e-8bff-6541372d3892","order_type":"limit","size":"0.0605","price":"9113.25","client_oid":""}
{"type":"match","side":"buy","product_id":"BTC-USD","time":"2020-06-30T19:15:16.418742Z","sequence":180756659,"trade_id":14587587,"maker_order_id":"91b59a7c-6a07-4039-9536-21daf3cb3282","taker_order_id":"7d324cb8-b9e2-4f5e-8bff-6541372d3892","size":"0.0605","price":"9120.8"}
{"type":"done","side":"sell","product_id":"BTC-USD","time":"2020-06-30T19:15:16.418742Z","sequence":180756660,"order_id":"7d324cb8-b9e2-4f5e-8bff-6541372d3892","reason":"filled","price":"9113.25","remaining_size":"0"}
{"type":"received","side":"sell","product_id":"BTC-USD","time":"2020-06-30T19:15:16.723743Z","sequence":180756661,"order_id":"9122edfa-669d-4a57-acd0-e977012cb9e2","order_type":"limit","size":"0.0725","price":"9112.72","client_oid":""}
{"type":"match","side":"buy","product_id":"BTC-USD","time":"2020-06-30T19:15:16.723743Z","sequence":180756662,"trade_id":14587588,"maker_order_id":"91b59a7c-6a07-4039-9536-21daf3cb3282","taker_order_id":"9122edfa-669d-4a57-acd0-e977012cb9e2","size":"0.0725","price":"9120.8"}
{"type":"done","side":"sell","product_id":"BTC-USD","time":"2020-06-30T19:15:16.723743Z","sequence":180756663,"order_id":"9122edfa-669d-4a57-acd0-e977012cb9e2","reason":"filled","price":"9112.72","remaining_size":"0"}
{"type":"heartbeat","last_trade_id":0,"product_id":"BTC-USD","sequence":180756663,"time":"2020-06-30T19:15:16.735118Z"}
{"type":"done","side":"buy","product_id":"BTC-USD","time":"2020-06-30T19:15:17.438363Z","sequence":180756664,"order_id":"75fb6c35-123b-407d-b86f-eb02d2961c4d","reason":"canceled","price":"9111.44","remaining_size":"0.0036"}
{"type":"done","side":"sell","product_id":"BTC-USD","time":"2020-06-30T19:15:17.691832Z","sequence":180756665,"order_id":"9814ecef-d73d-41a4-ad5a-4ff1014110d7","reason":"canceled","price":"9158.79","remaining_size":"0.01"}
{"type":"done","side":"sell","product_id":"BTC-USD","time":"2020-06-30T19:15:17.704147Z","sequence":180756666,"order_id":"aa7182b0-eb59-4093-abd5-72aa30dd8fc4","reason":"canceled","price":"9157.04","remaining_size":"0.0329"}
{"type":"heartbeat","last_trade_id":0,"product_id":"BTC-USD","sequence":180756666,"time":"2020-06-30T19:15:17.735095Z"}
{"type":"received","side":"buy","product_id":"BTC-USD","time":"2020-06-30T19:15:18.101437Z","sequence":180756667,"order_id":"3d7ea73d-26b7-4dc4-9f7d-2e7cb4cc0d5d","order_type":"limit","size":"0.5","price":"9085.88","client_oid":""}
{"type":"open","side":"buy","product_id":"BTC-USD","time":"2020-06-30T19:15:18.101437Z","sequence":180756668,"price":"9085.88","order_id":"3d7ea73d-26b7-4dc4-9f7d-2e7cb4cc0d5d","remaining_size":"0.5"}
{"type":"received","side":"buy","product_id":"BTC-USD","time":"2020-06-30T19:15:18.385962Z","sequence":180756669,"order_id":"40d9083e-43b7-4175-93e8-dcd21a1b84e3","order_type":"limit","size":"0.034","price":"9110.96","client_oid":""}
{"type":"open","side":"buy","product_id":"BTC-USD","time":"2020-06-30T19:15:18.385962Z","sequence":180756670,"price":"9110.96","order_id":"40d9083e-43b7-4175-93e8-dcd21a1b84e3","remaining_size":"0.034"}
{"type":"done","side":"buy","product_id":"BTC-USD","time":"2020-06-30T19:15:18.565254Z","sequence":180756671,"order_id":"420eb792-3505-4d83-8cff-93256c3a4ace","reason":"canceled","price":"9077.42","remaining_size":"0.01"}
{"type":"received","side":"buy","product_id":"BTC-USD","time":"2020-06-30T19:15:18.661278Z","sequence":180756672,"order_id":"b922ee25-8583-4e0b-8867-c87824242e1b","order_type":"limit","size":"0.049","price":"9103.26","client_oid":""}
{"type":"open","side":"buy","product_id":"BTC-USD","time":"2020-06-30T19:15:18.661278Z","sequence":180756673,"price":"9103.26","order_id":"b922ee25-8583-4e0b-8867-c87824242e1b","remaining_size":"0.049"}
{"type":"heartbeat","last_trade_id":0,"product_id":"BTC-USD","sequence":180756673,"time":"2020-06-30T19:15:18.735118Z"}
{"type":"done","side":"buy","product_id":"BTC-USD","time":"2020-06-30T19:15:18.810221Z","sequence":180756674,"order_id":"f54bed8e-a72d-4ca3-a0b9-085b6fecc1d5","reason":"canceled","price":"9111.59","remaining_size":"0.2653"}
{"type":"received","side":"sell","product_id":"BTC-USD","time":"2020-06-30T19:15:18.924855Z","sequence":180756675,"order_id":"a639b52c-d8ca-467e-83bc-7901ebc2cff4","order_type":"limit","size":"0.0329","price":"9155.78","client_oid":""}
{"type":"open","side":"sell","product_id":"BTC-USD","time":"2020-06-30T19:15:18.924855Z","sequence":180756676,"price":"9155.78","order_id":"a639b52c-d8ca-467e-83bc-7901ebc2cff4","remaining_size":"0.0329"}
{"type":"done","side":"buy","product_id":"BTC-USD","time":"2020-06-30T19:15:19.087499Z","sequence":180756677,"order_id":"331137bc-8461-41a8-9540-ac8432613658","reason":"canceled","price":"9103.65","remaining_size":"0.049"}
{"type":"done","side":"buy","product_id":"BTC-USD","time":"2020-06-30T19:15:19.100069Z","sequence":180756678,"order_id":"3d7ea73d-26b7-4dc4-9f7d-2e7cb4cc0d5d","reason":"canceled","price":"9085.88","remaining_size":"0.5"}
{"type":"done","side":"sell","product_id":"BTC-USD","time":"2020-06-30T19:15:19.393421Z","sequence":180756679,"order_id":"b9d8d4b1-6d97-499e-8854-664824554907","reason":"canceled","price":"9157.8","remaining_size":"0.1058"}
{"type":"received","side":"sell","product_id":"BTC-USD","time":"2020-06-30T19:15:19.480345Z","sequence":180756680,"order_id":"230b3517-c698-4ed4-8f9b-b473c552ba05","order_type":"limit","size":"0.0658","price":"9113.2","client_oid":""}
{"type":"match","side":"buy","product_id":"BTC-USD","time":"2020-06-30T19:15:19.480345Z","sequence":180756681,"trade_id":14587589,"maker_order_id":"91b59a7c-6a07-4039-9536-21daf3cb3282","taker_order_id":"230b3517-c698-4ed4-8f9b-b473c552ba05","size":"0.0658","price":"9120.8"}
{"type":"done","side":"sell","product_id":"BTC-USD","time":"2020-06-30T19:15:19.480345Z","sequence":180756682,"order_id":"230b3517-c698-4ed4-8f9b-b473c552ba05","reason":"filled","price":"9113.2","remaining_size":"0"}
{"type":"heartbeat","last_trade_id":0,"product_id":"BTC-USD","sequence":180756682,"time":"2020-06-30T19:15:19.735125Z"}
{"type":"received","side":"buy","product_id":"BTC-USD","time":"2020-06-30T19:15:19.752544Z","sequence":180756683,"order_id":"af6ddce1-10ef-491e-bc59-d3e8f7fb4dc2","order_type":"limit","size":"0.0148","price":"9112.07","client_oid":""}
{"type":"open","side":"buy","product_id":"BTC-USD","time":"2020-06-30T19:15:19.752544Z","sequence":180756684,"price":"9112.07","order_id":"af6ddce1-10ef-491e-bc59-d3e8f7fb4dc2","remaining_size":"0.0148"}
{"type":"done","side":"buy","product_id":"BTC-USD","time":"2020-06-30T19:15:20.176536Z","sequence":180756685,"order_id":"ca6c011b-7293-4ddd-a054-b2417bf7d91b","reason":"canceled","price":"9112.07","remaining_size":"0.05"}
{"type":"received","side":"sell","product_id":"BTC-USD","time":"2020-06-30T19:15:20.300074Z","sequence":180756686,"order_id":"9e9f5b0d-0840-42de-84dd-3e9a82f4954a","order_type":"limit","size":"0.0611","price":"9112.72","client_oid":""}
{"type":"match","side":"buy","product_id":"BTC-USD","time":"2020-06-30T19:15:20.300074Z","sequence":180756687,"trade_id":14587590,"maker_order_id":"91b59a7c-6a07-4039-9536-21daf3cb3282","taker_order_id":"9e9f5b0d-0840-42de-84dd-3e9a82f4954a","size":"0.0611","price":"9120.8"}
{"type":"done","side":"sell","product_id":"BTC-USD","time":"2020-06-30T19:15:20.300074Z","sequence":180756688,"order_id":"9e9f5b0d-0840-42de-84dd-3e9a82f4954a","reason":"filled","price":"9112.72","remaining_size":"0"}
{"type":"heartbeat","last_trade_id":0,"product_id":"BTC-USD","sequence":180756688,"time":"2020-06-30T19:15:20.735119Z"}
{"type":"received","side":"buy","product_id":"BTC-USD","time":"2020-06-30T19:15:20.850350Z","sequence":180756689,"order_id":"8cf99598-e756-48bd-93c9-dbd3ea59edb2","order_type":"limit","size":"0.0639","price":"9112.13","client_oid":""}
{"type":"open","side":"buy","product_id":"BTC-USD","time":"2020-06-30T19:15:20.850350Z","sequence":180756690,"price":"9112.13","order_id":"8cf99598-e756-48bd-93c9-dbd3ea59edb2","remaining_size":"0.0639"}
{"type":"received","side":"sell","product_id":"BTC-USD","time":"2020-06-30T19:15:21.682395Z","sequence":180756691,"order_id":"3e1a809e-9363-45f4-9400-ad42d7d88878","order_type":"limit","size":"0.05","price":"9112.67","client_oid":""}
{"type":"match","side":"buy","product_id":"BTC-USD","time":"2020-06-30T19:15:21.682395Z","sequence":180756692,"trade_id":14587591,"maker_order_id":"91b59a7c-6a07-4039-9536-21daf3cb3282","taker_order_id":"3e1a809e-9363-45f4-9400-ad42d7d88878","size":"0.05","price":"9120.8"}
{"type":"done","side":"sell","product_id":"BTC-USD","time":"2020-06-30T19:15:21.682395Z","sequence":180756693,"order_id":"3e1a809e-9363-45f4-9400-ad42d7d88878","reason":"filled","price":"9112.67","remaining_size":"0"}
{"type":"heartbeat","last_trade_id":0,"product_id":"BTC-USD","sequence":180756693,"time":"2020-06-30T19:15:21.735112Z"}
{"type":"received","side":"buy","product_id":"BTC-USD","time":"2020-06-30T19:15:21.939246Z","sequence":180756694,"order_id":"fee62d82-cf6b-43fc-8287-6faeab8ab5fe","order_type":"limit","size":"0.0012","price":"9111.51","client_oid":""}
{"type":"open","side":"buy","product_id":"BTC-USD","time":"2020-06-30T19:15:21.939246Z","sequence":180756695,"price":"9111.51","order_id":"fee62d82-cf6b-43fc-8287-6faeab8ab5fe","remaining_size":"0.0012"}
{"type":"received","side":"buy","product_id":"BTC-USD","time":"2020-06-30T19:15:22.507603Z","sequence":180756696,"order_id":"2c1b326b-b54b-4d8d-9e8e-2bf1424e0501","order_type":"limit","size":"0.11","price":"2","client_oid":""}
{"type":"open","side":"buy","product_id":"BTC-USD","time":"2020-06-30T19:15:22.507603Z","sequence":180756697,"price":"2","order_id":"2c1b326b-b54b-4d8d-9e8e-2bf1424e0501","remaining_size":"0.11"}
{"type":"done","side":"buy","product_id":"BTC-USD","time":"2020-06-30T19:15:22.699207Z","sequence":180756698,"order_id":"6bc9d272-724d-4cc0-a24e-0116269f940e","reason":"canceled","price":"9111.57","remaining_size":"0.2505"}
{"type":"heartbeat","last_trade_id":0,"product_id":"BTC-USD","sequence":180756698,"time":"2020-06-30T19:15:22.735121Z"}
{"type":"heartbeat","last_trade_id":0,"product_id":"BTC-USD","sequence":180756698,"time":"2020-06-30T19:15:23.735120Z"}
{"type":"received","side":"sell","product_id":"BTC-USD","time":"2020-06-30T19:15:24.253966Z","sequence":180756699,"order_id":"afeba595-8a04-49f5-837c-0e67c0723c87","order_type":"limit","size":"0.0278","price":"9157.98","client_oid":""}
{"type":"open","side":"sell","product_id":"BTC-USD","time":"2020-06-30T19:15:24.253966Z","sequence":180756700,"price":"9157.98","order_id":"afeba595-8a04-49f5-837c-0e67c0723c87","remaining_size":"0.0278"}
{"type":"received","side":"sell","product_id":"BTC-USD","time":"2020-06-30T19:15:24.527558Z","sequence":180756701,"order_id":"539c6f1a-83f2-4c9b-891d-2e25c82e8ce4","order_type":"limit","size":"0.0595","price":"9157.41","client_oid":""}
{"type":"open","side":"sell","product_id":"BTC-USD","time":"2020-06-30T19:15:24.527558Z","sequence":180756702,"price":"9157.41","order_id":"539c6f1a-83f2-4c9b-891d-2e25c82e8ce4","remaining_size":"0.0595"}
{"type":"heartbeat","last_trade_id":0,"product_id":"BTC-USD","sequence":180756702,"time":"2020-06-30T19:15:24.735118Z"}
{"type":"received","side":"buy","product_id":"BTC-USD","time":"2020-06-30T19:15:24.818743Z","sequence":180756703,"order_id":"ebb083b4-03a0-4702-a901-db83acdd6d3f","order_type":"limit","size":"0.04","price":"9109.32","client_oid":""}
{"type":"open","side":"buy","product_id":"BTC-USD","time":"2020-06-30T19:15:24.818743Z","sequence":180756704,"price":"9109.32","order_id":"ebb083b4-03a0-4702-a901-db83acdd6d3f","remaining_size":"0.04"}
{"type":"received","side":"sell","product_id":"BTC-USD","time":"2020-06-30T19:15:25.124825Z","sequence":180756705,"order_id":"2172d937-9c37-4181-a5a4-3a0b8c53a232","order_type":"limit","size":"0.0145","price":"9156.73","client_oid":""}
{"type":"open","side":"sell","product_id":"BTC-USD","time":"2020-06-30T19:15:25.124825Z","sequence":180756706,"price":"9156.73","order_id":"2172d937-9c37-4181-a5a4-3a0b8c53a232","remaining_size":"0.0145"}
{"type":"done","side":"buy","product_id":"BTC-USD","time":"2020-06-30T19:15:25.261861Z","sequence":180756707,"order_id":"b36920b9-ac13-4a89-bb24-4add04c5ddba","reason":"canceled","price":"9094.89","remaining_size":"2.1879"}
{"type":"heartbeat","last_trade_id":0,"product_id":"BTC-USD","sequence":180756707,"time":"2020-06-30T19:15:25.735121Z"}
{"type":"received","side":"buy","product_id":"BTC-USD","time":"2020-06-30T19:15:26.285237Z","sequence":180756708,"order_id":"e84b0d0f-f80e-444b-b988-c3aa58718997","order_type":"limit","size":"0.049","price":"9103.29","client_oid":""}
{"type":"open","side":"buy","product_id":"BTC-USD","time":"2020-06-30T19:15:26.285237Z","sequence":180756709,"price":"9103.29","order_id":"e84b0d0f-f80e-444b-b988-c3aa58718997","remaining_size":"0.049"}
{"type":"received","side":"buy","product_id":"BTC-USD","time":"2020-06-30T19:15:26.444445Z","sequence":180756710,"order_id":"10dcde27-e2ba-4018-b457-0ff85774ca25","order_type":"limit","size":"0.11","price":"2","client_oid":""}
{"type":"open","side":"buy","product_id":"BTC-USD","time":"2020-06-30T19:15:26.444445Z","sequence":180756711,"price":"2","order_id":"10dcde27-e2ba-4018-b457-0ff85774ca25","remaining_size":"0.11"}
{"type":"received","side":"buy","product_id":"BTC-USD","time":"2020-06-30T19:15:26.563602Z","sequence":180756712,"order_id":"871f6e9b-d579-4519-b9ed-cbf921ab556f","order_type":"limit","size":"0.01","price":"9091.1","client_oid":""}
{"type":"open","side":"buy","product_id":"BTC-USD","time":"2020-06-30T19:15:26.563602Z","sequence":180756713,"price":"9091.1","order_id":"871f6e9b-d579-4519-b9ed-cbf921ab556f","remaining_size":"0.01"}
{"type":"heartbeat","last_trade_id":0,"product_id":"BTC-USD","sequence":180756713,"time":"2020-06-30T19:15:26.735117Z"}
{"type":"done","side":"buy","product_id":"BTC-USD","time":"2020-06-30T19:15:26.755755Z","sequence":180756714,"order_id":"f05d2dd4-978c-42d7-8d7c-69748f471efb","reason":"canceled","price":"9076.11","remaining_size":"0.9596"}
{"type":"received","side":"buy","product_id":"BTC-USD","time":"2020-06-30T19:15:26.831374Z","sequence":180756715,"order_id":"09c0bc2b-d06a-4a73-8050-fa41b5b8f1ab","order_type":"limit","size":"0.0223","price":"9098.61","client_oid":""}
{"type":"open","side":"buy","product_id":"BTC-USD","time":"2020-06-30T19:15:26.831374Z","sequence":180756716,"price":"9098.61","order_id":"09c0bc2b-d06a-4a73-8050-fa41b5b8f1ab","remaining_size":"0.0223"}
{"type":"done","side":"buy","product_id":"BTC-USD","time":"2020-06-30T19:15:27.000050Z","sequence":180756717,"order_id":"e84b0d0f-f80e-444b-b988-c3aa58718997","reason":"canceled","price":"9103.29","remaining_size":"0.049"}
{"type":"done","side":"buy","product_id":"BTC-USD","time":"2020-06-30T19:15:27.005072Z","sequence":180756718,"order_id":"fee62d82-cf6b-43fc-8287-6faeab8ab5fe","reason":"canceled","price":"9111.51","remaining_size":"0.0012"}
{"type":"done","side":"buy","product_id":"BTC-USD","time":"2020-06-30T19:15:27.006146Z","sequence":180756719,"order_id":"944673be-2e83-46ee-a9c6-3f240706268a","reason":"canceled","price":"9099.18","remaining_size":"0.0223"}
{"type":"received","side":"sell","product_id":"BTC-USD","time":"2020-06-30T19:15:27.103091Z","sequence":180756720,"order_id":"362ad7c6-b281-46a6-8f32-c8a4ad37c16d","order_type":"limit","size":"2.187","price":"9113.24","client_oid":""}
{"type":"match","side":"buy","product_id":"BTC-USD","time":"2020-06-30T19:15:27.103091Z","sequence":180756721,"trade_id":14587592,"maker_order_id":"91b59a7c-6a07-4039-9536-21daf3cb3282","taker_order_id":"362ad7c6-b281-46a6-8f32-c8a4ad37c16d","size":"2.187","price":"9120.8"}
{"type":"done","side":"sell","product_id":"BTC-USD","time":"2020-06-30T19:15:27.103091Z","sequence":180756722,"order_id":"362ad7c6-b281-46a6-8f32-c8a4ad37c16d","reason":"filled","price":"9113.24","remaining_size":"0"}
{"type":"received","side":"sell","product_id":"BTC-USD","time":"2020-06-30T19:15:27.403337Z","sequence":180756723,"order_id":"961105df-0721-4a5e-9ea1-bcbf75dbfb52","order_type":"limit","size":"0.924","price":"9143.47","client_oid":""}
{"type":"open","side":"sell","product_id":"BTC-USD","time":"2020-06-30T19:15:27.403337Z","sequence":180756724,"price":"9143.47","order_id":"961105df-0721-4a5e-9ea1-bcbf75dbfb52","remaining_size":"0.924"}
{"type":"heartbeat","last_trade_id":0,"product_id":"BTC-USD","sequence":180756724,"time":"2020-06-30T19:15:27.735117Z"}
{"type":"done","side":"sell","product_id":"BTC-USD","time":"2020-06-30T19:15:27.838335Z","sequence":180756725,"order_id":"afeba595-8a04-49f5-837c-0e67c0723c87","reason":"canceled","price":"9157.98","remaining_size":"0.0278"}
{"type":"done","side":"sell","product_id":"BTC-USD","time":"2020-06-30T19:15:27.844020Z","sequence":180756726,"order_id":"2172d937-9c37-4181-a5a4-3a0b8c53a232","reason":"canceled","price":"9156.73","remaining_size":"0.0145"}
{"type":"received","side":"sell","product_id":"BTC-USD","time":"2020-06-30T19:15:27.961350Z","sequence":180756727,"order_id":"3b3919c0-dd48-42c0-88ab-7bff16ceb663","order_type":"limit","size":"0.2696","price":"9111.58","client_oid":""}
{"type":"match","side":"buy","product_id":"BTC-USD","time":"2020-06-30T19:15:27.961350Z","sequence":180756728,"trade_id":14587593,"maker_order_id":"91b59a7c-6a07-4039-9536-21daf3cb3282","taker_order_id":"3b3919c0-dd48-42c0-88ab-7bff16ceb663","size":"0.2696","price":"9120.8"}
{"type":"done","side":"sell","product_id":"BTC-USD","time":"2020-06-30T19:15:27.961350Z","sequence":180756729,"order_id":"3b3919c0-dd48-42c0-88ab-7bff16ceb663","reason":"filled","price":"9111.58","remaining_size":"0"}
{"type":"received","side":"sell","product_id":"BTC-USD","time":"2020-06-30T19:15:28.234579Z","sequence":180756730,"order_id":"c83c74a2-9d9d-421b-8d0f-63cabde4ae62","order_type":"limit","size":"0.5","price":"9129.81","client_oid":""}
{"type":"open","side":"sell","product_id":"BTC-USD","time":"2020-06-30T19:15:28.234579Z","sequence":180756731,"price":"9129.81","order_id":"c83c74a2-9d9d-421b-8d0f-63cabde4ae62","remaining_size":"0.5"}
{"type":"done","side":"sell","product_id":"BTC-USD","time":"2020-06-30T19:15:28.655323Z","sequence":180756732,"order_id":"539c6f1a-83f2-4c9b-891d-2e25c82e8ce4","reason":"canceled","price":"9157.41","remaining_size":"0.0595"}
{"type":"heartbeat","last_trade_id":0,"product_id":"BTC-USD","sequence":180756732,"time":"2020-06-30T19:15:28.735113Z"}
{"type":"received","side":"buy","product_id":"BTC-USD","time":"2020-06-30T19:15:29.027459Z","sequence":180756733,"order_id":"ca5b4e6f-5fc6-436f-992f-7b2cd662b402","order_type":"limit","size":"0.01","price":"100","client_oid":"c3c5aebc-7347-4429-97c7-59c4fb80cd1c"}
{"type":"open","side":"buy","product_id":"BTC-USD","time":"2020-06-30T19:15:29.027459Z","sequence":180756734,"price":"100","order_id":"ca5b4e6f-5fc6-436f-992f-7b2cd662b402","remaining_size":"0.01"}
{"type":"done","side":"buy","product_id":"BTC-USD","time":"2020-06-30T19:15:29.033680Z","sequence":180756735,"order_id":"ca5b4e6f-5fc6-436f-992f-7b2cd662b402","reason":"canceled","price":"100","remaining_size":"0.01"}
{"type":"received","side":"buy","product_id":"BTC-USD","time":"2020-06-30T19:15:29.075605Z","sequence":180756736,"order_id":"c033a84b-b66b-4d06-825b-def00ddb3954","order_type":"limit","size":"0.0319","price":"9111.58","client_oid":""}
{"type":"open","side":"buy","product_id":"BTC-USD","time":"2020-06-30T19:15:29.075605Z","sequence":180756737,"price":"9111.58","order_id":"c033a84b-b66b-4d06-825b-def00ddb3954","remaining_size":"0.0319"}
{"type":"done","side":"buy","product_id":"BTC-USD","time":"2020-06-30T19:15:29.270334Z","sequence":180756738,"order_id":"edda9118-3684-4d6d-b7d5-d5ef082ae948","reason":"canceled","price":"9078.78","remaining_size":"0.01"}
{"type":"done","side":"sell","product_id":"BTC-USD","time":"2020-06-30T19:15:29.273979Z","sequence":180756739,"order_id":"52c9fd6c-c332-4389-a142-3c796a264733","reason":"canceled","price":"9158.44","remaining_size":"0.0423"}
{"type":"received","side":"sell","product_id":"BTC-USD","time":"2020-06-30T19:15:29.652437Z","sequence":180756740,"order_id":"e2fe2d37-6047-4c01-b54e-5a6a8c9a4dd2","order_type":"limit","size":"3.6093","price":"9111.59","client_oid":""}
{"type":"match","side":"buy","product_id":"BTC-USD","time":"2020-06-30T19:15:29.652437Z","sequence":180756741,"trade_id":14587594,"maker_order_id":"91b59a7c-6a07-4039-9536-21daf3cb3282","taker_order_id":"e2fe2d37-6047-4c01-b54e-5a6a8c9a4dd2","size":"3.6093","price":"9120.8"}
{"type":"done","side":"sell","product_id":"BTC-USD","time":"2020-06-30T19:15:29.652437Z","sequence":180756742,"order_id":"e2fe2d37-6047-4c01-b54e-5a6a8c9a4dd2","reason":"filled","price":"9111.59","remaining_size":"0"}
{"type":"heartbeat","last_trade_id":0,"product_id":"BTC-USD","sequence":180756742,"time":"2020-06-30T19:15:29.735108Z"}
{"type":"received","side":"buy","product_id":"BTC-USD","time":"2020-06-30T19:15:29.934102Z","sequence":180756743,"order_id":"14b43b4d-6c02-4474-9aef-c820abc601df","order_type":"limit","size":"0.059","price":"9085.45","client_oid":""}
{"type":"open","side":"buy","product_id":"BTC-USD","time":"2020-06-30T19:15:29.934102Z","sequence":180756744,"price":"9085.45","order_id":"14b43b4d-6c02-4474-9aef-c820abc601df","remaining_size":"0.059"}
{"type":"done","side":"sell","product_id":"BTC-USD","time":"2020-06-30T19:15:30.107666Z","sequence":180756745,"order_id":"961105df-0721-4a5e-9ea1-bcbf75dbfb52","reason":"canceled","price":"9143.47","remaining_size":"0.924"}
{"type":"received","side":"sell","product_id":"BTC-USD","time":"2020-06-30T19:15:30.214975Z","sequence":180756746,"order_id":"c21081b2-937d-459e-ae3a-710d97ea9673","order_type":"limit","size":"0.9","price":"9113.23","client_oid":""}
{"type":"match","side":"buy","product_id":"BTC-USD","time":"2020-06-30T19:15:30.214975Z","sequence":180756747,"trade_id":14587595,"maker_order_id":"91b59a7c-6a07-4039-9536-21daf3cb3282","taker_order_id":"c21081b2-937d-459e-ae3a-710d97ea9673","size":"0.9","price":"9120.8"}
{"type":"done","side":"sell","product_id":"BTC-USD","time":"2020-06-30T19:15:30.214975Z","sequence":180756748,"order_id":"c21081b2-937d-459e-ae3a-710d97ea9673","reason":"filled","price":"9113.23","remaining_size":"0"}
{"type":"done","side":"buy","product_id":"BTC-USD","time":"2020-06-30T19:15:30.360833Z","sequence":180756749,"order_id":"b922ee25-8583-4e0b-8867-c87824242e1b","reason":"canceled","price":"9103.26","remaining_size":"0.049"}
{"type":"received","side":"sell","product_id":"BTC-USD","time":"2020-06-30T19:15:30.512144Z","sequence":180756750,"order_id":"f567e00d-d794-4c48-9ca3-e42d03a9294f","order_type":"limit","size":"0.002","price":"9221.63","client_oid":""}
{"type":"open","side":"sell","product_id":"BTC-USD","time":"2020-06-30T19:15:30.512144Z","sequence":180756751,"price":"9221.63","order_id":"f567e00d-d794-4c48-9ca3-e42d03a9294f","remaining_size":"0.002"}
{"type":"heartbeat","last_trade_id":0,"product_id":"BTC-USD","sequence":180756751,"time":"2020-06-30T19:15:30.735116Z"}
{"type":"received","side":"buy","product_id":"BTC-USD","time":"2020-06-30T19:15:30.924613Z","sequence":180756752,"order_id":"0310a17b-a027-4e11-a7c9-73e0eed9fab8","order_type":"limit","size":"0.16","price":"2","client_oid":""}
{"type":"open","side":"buy","product_id":"BTC-USD","time":"2020-06-30T19:15:30.924613Z","sequence":180756753,"price":"2","order_id":"0310a17b-a027-4e11-a7c9-73e0eed9fab8","remaining_size":"0.16"}
{"type":"received","side":"buy","product_id":"BTC-USD","time":"2020-06-30T19:15:31.055808Z","sequence":180756754,"order_id":"d54a4020-fda1-4f31-bac7-a13b425cb2ad","order_type":"limit","size":"0.049","price":"9103.26","client_oid":""}
{"type":"open","side":"buy","product_id":"BTC-USD","time":"2020-06-30T19:15:31.055808Z","sequence":180756755,"price":"9103.26","order_id":"d54a4020-fda1-4f31-bac7-a13b425cb2ad","remaining_size":"0.049"}
{"type":"received","side":"buy","product_id":"BTC-USD","time":"2020-06-30T19:15:31.336562Z","sequence":180756756,"order_id":"65fb765b-e549-43a3-9137-53c137c89f72","order_type":"limit","size":"0.0223","price":"9103.34","client_oid":""}
{"type":"open","side":"buy","product_id":"BTC-USD","time":"2020-06-30T19:15:31.336562Z","sequence":180756757,"price":"9103.34","order_id":"65fb765b-e549-43a3-9137-53c137c89f72","remaining_size":"0.0223"}
{"type":"heartbeat","last_trade_id":0,"product_id":"BTC-USD","sequence":180756757,"time":"2020-06-30T19:15:31.735109Z"}
{"type":"received","side":"sell","product_id":"BTC-USD","time":"2020-06-30T19:15:31.816078Z","sequence":180756758,"order_id":"cc0dbd08-bd2a-45e7-881e-2a94b9351aa2","order_type":"limit","size":"0.0329","price":"9157.24","client_oid":""}
{"type":"open","side":"sell","product_id":"BTC-USD","time":"2020-06-30T19:15:31.816078Z","sequence":180756759,"price":"9157.24","order_id":"cc0dbd08-bd2a-45e7-881e-2a94b9351aa2","remaining_size":"0.0329"}
{"type":"done","side":"buy","product_id":"BTC-USD","time":"2020-06-30T19:15:31.822258Z","sequence":180756760,"order_id":"1f34bea0-91e0-4f89-820c-71577826ebf6","reason":"canceled","price":"9103.7","remaining_size":"0.0223"}
{"type":"heartbeat","last_trade_id":0,"product_id":"BTC-USD","sequence":180756760,"time":"2020-06-30T19:15:32.735109Z"}
{"type":"received","side":"buy","product_id":"BTC-USD","time":"2020-06-30T19:15:32.784359Z","sequence":180756761,"order_id":"0eac780b-6838-44c9-8423-61ac080b7882","order_type":"limit","size":"0.0997","price":"9111.57","client_oid":""}
{"type":"open","side":"buy","product_id":"BTC-USD","time":"2020-06-30T19:15:32.784359Z","sequence":180756762,"price":"9111.57","order_id":"0eac780b-6838-44c9-8423-61ac080b7882","remaining_size":"0.0997"}
{"type":"heartbeat","last_trade_id":0,"product_id":"BTC-USD","sequence":180756762,"time":"2020-06-30T19:15:33.735118Z"}
{"type":"received","side":"sell","product_id":"BTC-USD","time":"2020-06-30T19:15:33.877701Z","sequence":180756763,"order_id":"f4d1f60c-77a1-459b-8563-04d1b3ac23bf","order_type":"limit","size":"1.0652","price":"9142.18","client_oid":""}
{"type":"open","side":"sell","product_id":"BTC-USD","time":"2020-06-30T19:15:33.877701Z","sequence":180756764,"price":"9142.18","order_id":"f4d1f60c-77a1-459b-8563-04d1b3ac23bf","remaining_size":"1.0652"}
{"type":"received","side":"sell","product_id":"BTC-USD","time":"2020-06-30T19:15:34.487217Z","sequence":180756765,"order_id":"67e79924-9a22-4b79-8196-2ff52e5f5b98","order_type":"limit","size":"0.0658","price":"9113.61","client_oid":""}
{"type":"match","side":"buy","product_id":"BTC-USD","time":"2020-06-30T19:15:34.487217Z","sequence":180756766,"trade_id":14587596,"maker_order_id":"91b59a7c-6a07-4039-9536-21daf3cb3282","taker_order_id":"67e79924-9a22-4b79-8196-2ff52e5f5b98","size":"0.0658","price":"9120.8"}
{"type":"done","side":"sell","product_id":"BTC-USD","time":"2020-06-30T19:15:34.487217Z","sequence":180756767,"order_id":"67e79924-9a22-4b79-8196-2ff52e5f5b98","reason":"filled","price":"9113.61","remaining_size":"0"}
{"type":"heartbeat","last_trade_id":0,"product_id":"BTC-USD","sequence":180756767,"time":"2020-06-30T19:15:34.735113Z"}
{"type":"received","side":"sell","product_id":"BTC-USD","time":"2020-06-30T19:15:35.313842Z","sequence":180756768,"order_id":"5fbf52ff-318e-4c11-b52d-1a276032dde6","order_type":"limit","size":"0.0333","price":"9158.3","client_oid":""}
{"type":"open","side":"sell","product_id":"BTC-USD","time":"2020-06-30T19:15:35.313842Z","sequence":180756769,"price":"9158.3","order_id":"5fbf52ff-318e-4c11-b52d-1a276032dde6","remaining_size":"0.0333"}
{"type":"received","side":"buy","product_id":"BTC-USD","time":"2020-06-30T19:15:35.348494Z","sequence":180756770,"order_id":"fc8e49e7-3049-42cb-8a77-75d8828ad5ee","order_type":"limit","size":"0.29","price":"2","client_oid":""}
{"type":"open","side":"buy","product_id":"BTC-USD","time":"2020-06-30T19:15:35.348494Z","sequence":180756771,"price":"2","order_id":"fc8e49e7-3049-42cb-8a77-75d8828ad5ee","remaining_size":"0.29"}
{"type":"heartbeat","last_trade_id":0,"product_id":"BTC-USD","sequence":180756771,"time":"2020-06-30T19:15:35.735112Z"}
{"type":"received","side":"sell","product_id":"BTC-USD","time":"2020-06-30T19:15:35.865733Z","sequence":180756772,"order_id":"5cee4c49-3014-481e-b53e-220f845d6501","order_type":"limit","size":"0.0658","price":"9113.31","client_oid":""}
{"type":"match","side":"buy","product_id":"BTC-USD","time":"2020-06-30T19:15:35.865733Z","sequence":180756773,"trade_id":14587597,"maker_order_id":"91b59a7c-6a07-4039-9536-21daf3cb3282","taker_order_id":"5cee4c49-3014-481e-b53e-220f845d6501","size":"0.0658","price":"9120.8"}
{"type":"done","side":"sell","product_id":"BTC-USD","time":"2020-06-30T19:15:35.865733Z","sequence":180756774,"order_id":"5cee4c49-3014-481e-b53e-220f845d6501","reason":"filled","price":"9113.31","remaining_size":"0"}
{"type":"received","side":"sell","product_id":"BTC-USD","time":"2020-06-30T19:15:36.153789Z","sequence":180756775,"order_id":"33c73b63-be02-4f07-8d16-ca83cc89918e","order_type":"limit","size":"0.0658","price":"9113.21","client_oid":""}
{"type":"match","side":"buy","product_id":"BTC-USD","time":"2020-06-30T19:15:36.153789Z","sequence":180756776,"trade_id":14587598,"maker_order_id":"91b59a7c-6a07-4039-9536-21daf3cb3282","taker_order_id":"33c73b63-be02-4f07-8d16-ca83cc89918e","size":"0.0658","price":"9120.8"}
{"type":"done","side":"sell","product_id":"BTC-USD","time":"2020-06-30T19:15:36.153789Z","sequence":180756777,"order_id":"33c73b63-be02-4f07-8d16-ca83cc89918e","reason":"filled","price":"9113.21","remaining_size":"0"}
{"type":"received","side":"sell","product_id":"BTC-USD","time":"2020-06-30T19:15:36.710476Z","sequence":180756778,"order_id":"c267252e-13f5-4458-a6d2-080cc85d5543","order_type":"limit","size":"0.9","price":"9114.62","client_oid":""}
{"type":"match","side":"buy","product_id":"BTC-USD","time":"2020-06-30T19:15:36.710476Z","sequence":180756779,"trade_id":14587599,"maker_order_id":"91b59a7c-6a07-4039-9536-21daf3cb3282","taker_order_id":"c267252e-13f5-4458-a6d2-080cc85d5543","size":"0.9","price":"9120.8"}
{"type":"done","side":"sell","product_id":"BTC-USD","time":"2020-06-30T19:15:36.710476Z","sequence":180756780,"order_id":"c267252e-13f5-4458-a6d2-080cc85d5543","reason":"filled","price":"9114.62","remaining_size":"0"}
{"type":"heartbeat","last_trade_id":0,"product_id":"BTC-USD","sequence":180756780,"time":"2020-06-30T19:15:36.735115Z"}
{"type":"received","side":"sell","product_id":"BTC-USD","time":"2020-06-30T19:15:36.989905Z","sequence":180756781,"order_id":"a7bd5805-9ccb-4206-b3e5-63ba378a7d69","order_type":"limit","size":"0.548","price":"9114.61","client_oid":""}
{"type":"match","side":"buy","product_id":"BTC-USD","time":"2020-06-30T19:15:36.989905Z","sequence":180756782,"trade_id":14587600,"maker_order_id":"91b59a7c-6a07-4039-9536-21daf3cb3282","taker_order_id":"a7bd5805-9ccb-4206-b3e5-63ba378a7d69","size":"0.548","price":"9120.8"}
{"type":"done","side":"sell","product_id":"BTC-USD","time":"2020-06-30T19:15:36.989905Z","sequence":180756783,"order_id":"a7bd5805-9ccb-4206-b3e5-63ba378a7d69","reason":"filled","price":"9114.61","remaining_size":"0"}
{"type":"done","side":"sell","product_id":"BTC-USD","time":"2020-06-30T19:15:37.409623Z","sequence":180756784,"order_id":"c83c74a2-9d9d-421b-8d0f-63cabde4ae62","reason":"canceled","price":"9129.81","remaining_size":"0.5"}
{"type":"received","side":"buy","product_id":"BTC-USD","time":"2020-06-30T19:15:37.569652Z","sequence":180756785,"order_id":"0cfef004-01a3-46c2-9e9d-b8104a060177","order_type":"limit","size":"0.8153","price":"9112.04","client_oid":""}
{"type":"open","side":"buy","product_id":"BTC-USD","time":"2020-06-30T19:15:37.569652Z","sequence":180756786,"price":"9112.04","order_id":"0cfef004-01a3-46c2-9e9d-b8104a060177","remaining_size":"0.8153"}
{"type":"heartbeat","last_trade_id":0,"product_id":"BTC-USD","sequence":180756786,"time":"2020-06-30T19:15:37.735114Z"}
{"type":"received","side":"sell","product_id":"BTC-USD","time":"2020-06-30T19:15:37.840625Z","sequence":180756787,"order_id":"273a5afa-32c0-4839-9853-ec5767e624f8","order_type":"limit","size":"0.0658","price":"9113.45","client_oid":""}
{"type":"match","side":"buy","product_id":"BTC-USD","time":"2020-06-30T19:15:37.840625Z","sequence":180756788,"trade_id":14587601,"maker_order_id":"91b59a7c-6a07-4039-9536-21daf3cb3282","taker_order_id":"273a5afa-32c0-4839-9853-ec5767e624f8","size":"0.0658","price":"9120.8"}
{"type":"done","side":"sell","product_id":"BTC-USD","time":"2020-06-30T19:15:37.840625Z","sequence":180756789,"order_id":"273a5afa-32c0-4839-9853-ec5767e624f8","reason":"filled","price":"9113.45","remaining_size":"0"}
{"type":"done","side":"buy","product_id":"BTC-USD","time":"2020-06-30T19:15:38.041459Z","sequence":180756790,"order_id":"26526490-a0c0-425f-8140-f192d5ab4938","reason":"canceled","price":"9091.02","remaining_size":"0.0383"}
{"type":"received","side":"sell","product_id":"BTC-USD","time":"2020-06-30T19:15:38.105816Z","sequence":180756791,"order_id":"4a3bb2e6-28ac-4ba1-b52c-ac4cc2fba403","order_type":"limit","size":"0.1","price":"9175.2","client_oid":""}
{"type":"open","side":"sell","product_id":"BTC-USD","time":"2020-06-30T19:15:38.105816Z","sequence":180756792,"price":"9175.2","order_id":"4a3bb2e6-28ac-4ba1-b52c-ac4cc2fba403","remaining_size":"0.1"}
{"type":"heartbeat","last_trade_id":0,"product_id":"BTC-USD","sequence":180756792,"time":"2020-06-30T19:15:38.735114Z"}
{"type":"received","side":"buy","product_id":"BTC-USD","time":"2020-06-30T19:15:39.224837Z","sequence":180756793,"order_id":"44135612-c206-4484-9a33-26592e4cd585","order_type":"limit","size":"3.06","price":"9088.71","client_oid":""}
{"type":"open","side":"buy","product_id":"BTC-USD","time":"2020-06-30T19:15:39.224837Z","sequence":180756794,"price":"9088.71","order_id":"44135612-c206-4484-9a33-26592e4cd585","remaining_size":"3.06"}
{"type":"done","side":"buy","product_id":"BTC-USD","time":"2020-06-30T19:15:39.659421Z","sequence":180756795,"order_id":"6974f2db-814b-473d-bf9e-7cd5286c6240","reason":"canceled","price":"9103.61","remaining_size":"0.049"}
{"type":"done","side":"buy","product_id":"BTC-USD","time":"2020-06-30T19:15:39.675055Z","sequence":180756796,"order_id":"0cfef004-01a3-46c2-9e9d-b8104a060177","reason":"canceled","price":"9112.04","remaining_size":"0.8153"}
{"type":"heartbeat","last_trade_id":0,"product_id":"BTC-USD","sequence":180756796,"time":"2020-06-30T19:15:39.735123Z"}
{"type":"received","side":"buy","product_id":"BTC-USD","time":"2020-06-30T19:15:39.808463Z","sequence":180756797,"order_id":"b54c926a-a3f7-4e3e-be4a-163793b8f13d","order_type":"limit","size":"0.29","price":"2","client_oid":""}
{"type":"open","side":"buy","product_id":"BTC-USD","time":"2020-06-30T19:15:39.808463Z","sequence":180756798,"price":"2","order_id":"b54c926a-a3f7-4e3e-be4a-163793b8f13d","remaining_size":"0.29"}
{"type":"received","side":"sell","product_id":"BTC-USD","time":"2020-06-30T19:15:40.313111Z","sequence":180756799,"order_id":"23b0ee00-393d-4e48-ae16-3cbcf6503687","order_type":"limit","size":"5.9606","price":"9112.05","client_oid":""}
{"type":"match","side":"buy","product_id":"BTC-USD","time":"2020-06-30T19:15:40.313111Z","sequence":180756800,"trade_id":14587602,"maker_order_id":"91b59a7c-6a07-4039-9536-21daf3cb3282","taker_order_id":"23b0ee00-393d-4e48-ae16-3cbcf6503687","size":"5.9606","price":"9120.8"}
{"type":"done","side":"sell","product_id":"BTC-USD","time":"2020-06-30T19:15:40.313111Z","sequence":180756801,"order_id":"23b0ee00-393d-4e48-ae16-3cbcf6503687","reason":"filled","price":"9112.05","remaining_size":"0"}
{"type":"received","side":"buy","product_id":"BTC-USD","time":"2020-06-30T19:15:40.669906Z","sequence":180756802,"order_id":"2837402a-4c0d-49c4-9d0b-bed5a0ea37be","order_type":"market","size":"0.001","funds":"9.12082","client_oid":""}
{"type":"match","side":"sell","product_id":"BTC-USD","time":"2020-06-30T19:15:40.669906Z","sequence":180756803,"trade_id":14587603,"maker_order_id":"36fe0734-4801-466d-b093-cccd411db09a","taker_order_id":"2837402a-4c0d-49c4-9d0b-bed5a0ea37be","size":"0.001","price":"9120.82"}
{"type":"done","side":"buy","product_id":"BTC-USD","time":"2020-06-30T19:15:40.669906Z","sequence":180756804,"order_id":"2837402a-4c0d-49c4-9d0b-bed5a0ea37be","reason":"filled","remaining_size":"0"}
{"type":"heartbeat","last_trade_id":0,"product_id":"BTC-USD","sequence":180756804,"time":"2020-06-30T19:15:40.735127Z"}
{"type":"received","side":"buy","product_id":"BTC-USD","time":"2020-06-30T19:15:41.488222Z","sequence":180756805,"order_id":"b5e757e0-0f3f-4719-a8d5-6594af13e1d9","order_type":"limit","size":"0.828","price":"9099.1","client_oid":""}
{"type":"open","side":"buy","product_id":"BTC-USD","time":"2020-06-30T19:15:41.488222Z","sequence":180756806,"price":"9099.1","order_id":"b5e757e0-0f3f-4719-a8d5-6594af13e1d9","remaining_size":"0.828"}
{"type":"heartbeat","last_trade_id":0,"product_id":"BTC-USD","sequence":180756806,"time":"2020-06-30T19:15:41.735128Z"}
{"type":"done","side":"buy","product_id":"BTC-USD","time":"2020-06-30T19:15:41.938154Z","sequence":180756807,"order_id":"871f6e9b-d579-4519-b9ed-cbf921ab556f","reason":"canceled","price":"9091.1","remaining_size":"0.01"}
{"type":"done","side":"buy","product_id":"BTC-USD","time":"2020-06-30T19:15:41.939446Z","sequence":180756808,"order_id":"af6ddce1-10ef-491e-bc59-d3e8f7fb4dc2","reason":"canceled","price":"9112.07","remaining_size":"0.0148"}
{"type":"received","side":"sell","product_id":"BTC-USD","time":"2020-06-30T19:15:42.093057Z","sequence":180756809,"order_id":"9f0b82d9-c92b-4882-8c8e-63008ba628cf","order_type":"limit","size":"0.069","price":"9156.37","client_oid":""}
{"type":"open","side":"sell","product_id":"BTC-USD","time":"2020-06-30T19:15:42.093057Z","sequence":180756810,"price":"9156.37","order_id":"9f0b82d9-c92b-4882-8c8e-63008ba628cf","remaining_size":"0.069"}
{"type":"received","side":"buy","product_id":"BTC-USD","time":"2020-06-30T19:15:42.397733Z","sequence":180756811,"order_id":"fac962b2-4beb-46c2-b715-f4d8628b3e91","order_type":"limit","size":"0.0012","price":"9111.07","client_oid":""}
{"type":"open","side":"buy","product_id":"BTC-USD","time":"2020-06-30T19:15:42.397733Z","sequence":180756812,"price":"9111.07","order_id":"fac962b2-4beb-46c2-b715-f4d8628b3e91","remaining_size":"0.0012"}
{"type":"done","side":"buy","product_id":"BTC-USD","time":"2020-06-30T19:15:42.580454Z","sequence":180756813,"order_id":"ebb083b4-03a0-4702-a901-db83acdd6d3f","reason":"canceled","price":"9109.32","remaining_size":"0.04"}
{"type":"done","side":"buy","product_id":"BTC-USD","time":"2020-06-30T19:15:42.582783Z","sequence":180756814,"order_id":"0eac780b-6838-44c9-8423-61ac080b7882","reason":"canceled","price":"9111.57","remaining_size":"0.0997"}
{"type":"done","side":"buy","product_id":"BTC-USD","time":"2020-06-30T19:15:42.585367Z","sequence":180756815,"order_id":"8cf99598-e756-48bd-93c9-dbd3ea59edb2","reason":"canceled","price":"9112.13","remaining_size":"0.0639"}
{"type":"received","side":"buy","product_id":"BTC-USD","time":"2020-06-30T19:15:42.672426Z","sequence":180756816,"order_id":"f151e52c-ccbf-411f-965c-4f848804c0e1","order_type":"limit","size":"17.547","price":"9109","client_oid":""}
{"type":"open","side":"buy","product_id":"BTC-USD","time":"2020-06-30T19:15:42.672426Z","sequence":180756817,"price":"9109","order_id":"f151e52c-ccbf-411f-965c-4f848804c0e1","remaining_size":"17.547"}
{"type":"heartbeat","last_trade_id":0,"product_id":"BTC-USD","sequence":180756817,"time":"2020-06-30T19:15:42.735123Z"}
{"type":"done","side":"buy","product_id":"BTC-USD","time":"2020-06-30T19:15:43.140807Z","sequence":180756818,"order_id":"44135612-c206-4484-9a33-26592e4cd585","reason":"canceled","price":"9088.71","remaining_size":"3.06"}
{"type":"received","side":"buy","product_id":"BTC-USD","time":"2020-06-30T19:15:43.542578Z","sequence":180756819,"order_id":"a03eb967-e26c-41f5-b197-c056abf6013f","order_type":"limit","size":"0.0223","price":"9103.3","client_oid":""}
{"type":"open","side":"buy","product_id":"BTC-USD","time":"2020-06-30T19:15:43.542578Z","sequence":180756820,"price":"9103.3","order_id":"a03eb967-e26c-41f5-b197-c056abf6013f","remaining_size":"0.0223"}
{"type":"heartbeat","last_trade_id":0,"product_id":"BTC-USD","sequence":180756820,"time":"2020-06-30T19:15:43.735124Z"}
{"type":"received","side":"buy","product_id":"BTC-USD","time":"2020-06-30T19:15:44.040765Z","sequence":180756821,"order_id":"8c2c8a9c-502e-4dfa-a06d-ff5208b3c23f","order_type":"limit","size":"0.01","price":"100","client_oid":"f0156aa3-d543-4f09-a547-8d3a2894b96d"}
{"type":"open","side":"buy","product_id":"BTC-USD","time":"2020-06-30T19:15:44.040765Z","sequence":180756822,"price":"100","order_id":"8c2c8a9c-502e-4dfa-a06d-ff5208b3c23f","remaining_size":"0.01"}
{"type":"done","side":"buy","product_id":"BTC-USD","time":"2020-06-30T19:15:44.047521Z","sequence":180756823,"order_id":"8c2c8a9c-502e-4dfa-a06d-ff5208b3c23f","reason":"canceled","price":"100","remaining_size":"0.01"}
{"type":"received","side":"sell","product_id":"BTC-USD","time":"2020-06-30T19:15:44.088935Z","sequence":180756824,"order_id":"85764518-1268-4b47-b069-24ba6de574ca","order_type":"limit","size":"0.05","price":"9114.02","client_oid":""}
{"type":"match","side":"buy","product_id":"BTC-USD","time":"2020-06-30T19:15:44.088935Z","sequence":180756825,"trade_id":14587604,"maker_order_id":"91b59a7c-6a07-4039-9536-21daf3cb3282","taker_order_id":"85764518-1268-4b47-b069-24ba6de574ca","size":"0.05","price":"9120.8"}
{"type":"done","side":"sell","product_id":"BTC-USD","time":"2020-06-30T19:15:44.088935Z","sequence":180756826,"order_id":"85764518-1268-4b47-b069-24ba6de574ca","reason":"filled","price":"9114.02","remaining_size":"0"}
{"type":"received","side":"sell","product_id":"BTC-USD","time":"2020-06-30T19:15:44.370422Z","sequence":180756827,"order_id":"431876aa-1e62-4283-8e49-edc1f78d0367","order_type":"limit","size":"0.0329","price":"9155.32","client_oid":""}
{"type":"open","side":"sell","product_id":"BTC-USD","time":"2020-06-30T19:15:44.370422Z","sequence":180756828,"price":"9155.32","order_id":"431876aa-1e62-4283-8e49-edc1f78d0367","remaining_size":"0.0329"}
{"type":"done","side":"sell","product_id":"BTC-USD","time":"2020-06-30T19:15:44.527579Z","sequence":180756829,"order_id":"cc0dbd08-bd2a-45e7-881e-2a94b9351aa2","reason":"canceled","price":"9157.24","remaining_size":"0.0329"}
{"type":"done","side":"sell","product_id":"BTC-USD","time":"2020-06-30T19:15:44.548406Z","sequence":180756830,"order_id":"f567e00d-d794-4c48-9ca3-e42d03a9294f","reason":"canceled","price":"9221.63","remaining_size":"0.002"}
{"type":"received","side":"sell","product_id":"BTC-USD","time":"2020-06-30T19:15:44.655195Z","sequence":180756831,"order_id":"91dd8691-8c07-4e74-839a-f51182e6342f","order_type":"limit","size":"0.0659","price":"9114.01","client_oid":""}
{"type":"match","side":"buy","product_id":"BTC-USD","time":"2020-06-30T19:15:44.655195Z","sequence":180756832,"trade_id":14587605,"maker_order_id":"91b59a7c-6a07-4039-9536-21daf3cb3282","taker_order_id":"91dd8691-8c07-4e74-839a-f51182e6342f","size":"0.0659","price":"9120.8"}
{"type":"done","side":"sell","product_id":"BTC-USD","time":"2020-06-30T19:15:44.655195Z","sequence":180756833,"order_id":"91dd8691-8c07-4e74-839a-f51182e6342f","reason":"filled","price":"9114.01","remaining_size":"0"}
{"type":"heartbeat","last_trade_id":0,"product_id":"BTC-USD","sequence":180756833,"time":"2020-06-30T19:15:44.735021Z"}
{"type":"received","side":"sell","product_id":"BTC-USD","time":"2020-06-30T19:15:44.933939Z","sequence":180756834,"order_id":"696f827b-9089-405b-8e85-f7c5a5a277ca","order_type":"limit","size":"0.069","price":"9154.89","client_oid":""}
{"type":"open","side":"sell","product_id":"BTC-USD","time":"2020-06-30T19:15:44.933939Z","sequence":180756835,"price":"9154.89","order_id":"696f827b-9089-405b-8e85-f7c5a5a277ca","remaining_size":"0.069"}
{"type":"done","side":"sell","product_id":"BTC-USD","time":"2020-06-30T19:15:45.070281Z","sequence":180756836,"order_id":"5fbf52ff-318e-4c11-b52d-1a276032dde6","reason":"canceled","price":"9158.3","remaining_size":"0.0333"}
{"type":"received","side":"buy","product_id":"BTC-USD","time":"2020-06-30T19:15:45.209549Z","sequence":180756837,"order_id":"f632d6e2-7f87-4af5-834a-9eeadb98ee59","order_type":"limit","size":"0.0223","price":"9103.28","client_oid":""}
{"type":"open","side":"buy","product_id":"BTC-USD","time":"2020-06-30T19:15:45.209549Z","sequence":180756838,"price":"9103.28","order_id":"f632d6e2-7f87-4af5-834a-9eeadb98ee59","remaining_size":"0.0223"}
{"type":"received","side":"sell","product_id":"BTC-USD","time":"2020-06-30T19:15:45.475733Z","sequence":180756839,"order_id":"0db4486e-dacb-4d20-bccd-95370791227b","order_type":"limit","size":"0.05","price":"9113.91","client_oid":""}
{"type":"match","side":"buy","product_id":"BTC-USD","time":"2020-06-30T19:15:45.475733Z","sequence":180756840,"trade_id":14587606,"maker_order_id":"91b59a7c-6a07-4039-9536-21daf3cb3282","taker_order_id":"0db4486e-dacb-4d20-bccd-95370791227b","size":"0.05","price":"9120.8"}
{"type":"done","side":"sell","product_id":"BTC-USD","time":"2020-06-30T19:15:45.475733Z","sequence":180756841,"order_id":"0db4486e-dacb-4d20-bccd-95370791227b","reason":"filled","price":"9113.91","remaining_size":"0"}
{"type":"done","side":"buy","product_id":"BTC-USD","time":"2020-06-30T19:15:45.652973Z","sequence":180756842,"order_id":"c033a84b-b66b-4d06-825b-def00ddb3954","reason":"canceled","price":"9111.58","remaining_size":"0.0319"}
{"type":"done","side":"buy","product_id":"BTC-USD","time":"2020-06-30T19:15:45.659009Z","sequence":180756843,"order_id":"b5e757e0-0f3f-4719-a8d5-6594af13e1d9","reason":"canceled","price":"9099.1","remaining_size":"0.828"}
{"type":"heartbeat","last_trade_id":0,"product_id":"BTC-USD","sequence":180756843,"time":"2020-06-30T19:15:45.735109Z"}
{"type":"received","side":"buy","product_id":"BTC-USD","time":"2020-06-30T19:15:46.012855Z","sequence":180756844,"order_id":"abf53f7a-1ce1-42cf-a7ee-005f6537e2bf","order_type":"limit","size":"0.34","price":"2","client_oid":""}
{"type":"open","side":"buy","product_id":"BTC-USD","time":"2020-06-30T19:15:46.012855Z","sequence":180756845,"price":"2","order_id":"abf53f7a-1ce1-42cf-a7ee-005f6537e2bf","remaining_size":"0.34"}
{"type":"received","side":"sell","product_id":"BTC-USD","time":"2020-06-30T19:15:46.320454Z","sequence":180756846,"order_id":"a9ddb845-319f-408a-9ca3-e68fa3b1e19e","order_type":"limit","size":"0.05","price":"9113.91","client_oid":""}
{"type":"match","side":"buy","product_id":"BTC-USD","time":"2020-06-30T19:15:46.320454Z","sequence":180756847,"trade_id":14587607,"maker_order_id":"91b59a7c-6a07-4039-9536-21daf3cb3282","taker_order_id":"a9ddb845-319f-408a-9ca3-e68fa3b1e19e","size":"0.05","price":"9120.8"}
{"type":"done","side":"sell","product_id":"BTC-USD","time":"2020-06-30T19:15:46.320454Z","sequence":180756848,"order_id":"a9ddb845-319f-408a-9ca3-e68fa3b1e19e","reason":"filled","price":"9113.91","remaining_size":"0"}
{"type":"received","side":"sell","product_id":"BTC-USD","time":"2020-06-30T19:15:46.592278Z","sequence":180756849,"order_id":"8dc2080e-1297-4661-8de7-d1691cf45697","order_type":"limit","size":"0.0659","price":"9113.9","client_oid":""}
{"type":"match","side":"buy","product_id":"BTC-USD","time":"2020-06-30T19:15:46.592278Z","sequence":180756850,"trade_id":14587608,"maker_order_id":"91b59a7c-6a07-4039-9536-21daf3cb3282","taker_order_id":"8dc2080e-1297-4661-8de7-d1691cf45697","size":"0.0659","price":"9120.8"}
{"type":"done","side":"sell","product_id":"BTC-USD","time":"2020-06-30T19:15:46.592278Z","sequence":180756851,"order_id":"8dc2080e-1297-4661-8de7-d1691cf45697","reason":"filled","price":"9113.9","remaining_size":"0"}
{"type":"heartbeat","last_trade_id":0,"product_id":"BTC-USD","sequence":180756851,"time":"2020-06-30T19:15:46.735112Z"}
{"type":"received","side":"sell","product_id":"BTC-USD","time":"2020-06-30T19:15:46.873307Z","sequence":180756852,"order_id":"0d10c23a-e8d4-4123-9cef-e63439925cad","order_type":"limit","size":"0.0659","price":"9113.84","client_oid":""}
{"type":"match","side":"buy","product_id":"BTC-USD","time":"2020-06-30T19:15:46.873307Z","sequence":180756853,"trade_id":14587609,"maker_order_id":"91b59a7c-6a07-4039-9536-21daf3cb3282","taker_order_id":"0d10c23a-e8d4-4123-9cef-e63439925cad","size":"0.0659","price":"9120.8"}
{"type":"done","side":"sell","product_id":"BTC-USD","time":"2020-06-30T19:15:46.873307Z","sequence":180756854,"order_id":"0d10c23a-e8d4-4123-9cef-e63439925cad","reason":"filled","price":"9113.84","remaining_size":"0"}
{"type":"received","side":"buy","product_id":"BTC-USD","time":"2020-06-30T19:15:47.134541Z","sequence":180756855,"order_id":"29210d07-674b-4c58-8fdd-95840d691a60","order_type":"limit","size":"0.0223","price":"9098.61","client_oid":""}
{"type":"open","side":"buy","product_id":"BTC-USD","time":"2020-06-30T19:15:47.134541Z","sequence":180756856,"price":"9098.61","order_id":"29210d07-674b-4c58-8fdd-95840d691a60","remaining_size":"0.0223"}
{"type":"done","side":"buy","product_id":"BTC-USD","time":"2020-06-30T19:15:47.563303Z","sequence":180756857,"order_id":"90ccb0a2-3a8d-48e1-b499-3abe853700c7","reason":"canceled","price":"9110.69","remaining_size":"1.5"}
{"type":"received","side":"sell","product_id":"BTC-USD","time":"2020-06-30T19:15:47.695684Z","sequence":180756858,"order_id":"7f641c68-0ff8-46df-81c3-bd0ecdba256b","order_type":"limit","size":"0.05","price":"9113.08","client_oid":""}
{"type":"match","side":"buy","product_id":"BTC-USD","time":"2020-06-30T19:15:47.695684Z","sequence":180756859,"trade_id":14587610,"maker_order_id":"91b59a7c-6a07-4039-9536-21daf3cb3282","taker_order_id":"7f641c68-0ff8-46df-81c3-bd0ecdba256b","size":"0.05","price":"9120.8"}
{"type":"done","side":"sell","product_id":"BTC-USD","time":"2020-06-30T19:15:47.695684Z","sequence":180756860,"order_id":"7f641c68-0ff8-46df-81c3-bd0ecdba256b","reason":"filled","price":"9113.08","remaining_size":"0"}
{"type":"heartbeat","last_trade_id":0,"product_id":"BTC-USD","sequence":180756860,"time":"2020-06-30T19:15:47.735121Z"}
{"type":"received","side":"sell","product_id":"BTC-USD","time":"2020-06-30T19:15:48.002855Z","sequence":180756861,"order_id":"df89002e-b093-4688-87f8-24b5d87da305","order_type":"limit","size":"0.0659","price":"9113.04","client_oid":""}
{"type":"match","side":"buy","product_id":"BTC-USD","time":"2020-06-30T19:15:48.002855Z","sequence":180756862,"trade_id":14587611,"maker_order_id":"91b59a7c-6a07-4039-9536-21daf3cb3282","taker_order_id":"df89002e-b093-4688-87f8-24b5d87da305","size":"0.0659","price":"9120.8"}
{"type":"done","side":"sell","product_id":"BTC-USD","time":"2020-06-30T19:15:48.002855Z","sequence":180756863,"order_id":"df89002e-b093-4688-87f8-24b5d87da305","reason":"filled","price":"9113.04","remaining_size":"0"}
{"type":"heartbeat","last_trade_id":0,"product_id":"BTC-USD","sequence":180756863,"time":"2020-06-30T19:15:48.735111Z"}
{"type":"received","side":"sell","product_id":"BTC-USD","time":"2020-06-30T19:15:48.833975Z","sequence":180756864,"order_id":"5318ea05-7d5f-46dd-a285-09d248f80fc0","order_type":"limit","size":"0.0659","price":"9112.93","client_oid":""}
{"type":"match","side":"buy","product_id":"BTC-USD","time":"2020-06-30T19:15:48.833975Z","sequence":180756865,"trade_id":14587612,"maker_order_id":"91b59a7c-6a07-4039-9536-21daf3cb3282","taker_order_id":"5318ea05-7d5f-46dd-a285-09d248f80fc0","size":"0.0659","price":"9120.8"}
{"type":"done","side":"sell","product_id":"BTC-USD","time":"2020-06-30T19:15:48.833975Z","sequence":180756866,"order_id":"5318ea05-7d5f-46dd-a285-09d248f80fc0","reason":"filled","price":"9112.93","remaining_size":"0"}
{"type":"received","side":"buy","product_id":"BTC-USD","time":"2020-06-30T19:15:49.106623Z","sequence":180756867,"order_id":"700b67e9-eb33-4016-95da-a63d35e40880","order_type":"limit","size":"0.0223","price":"9103.26","client_oid":""}
{"type":"open","side":"buy","product_id":"BTC-USD","time":"2020-06-30T19:15:49.106623Z","sequence":180756868,"price":"9103.26","order_id":"700b67e9-eb33-4016-95da-a63d35e40880","remaining_size":"0.0223"}
{"type":"heartbeat","last_trade_id":0,"product_id":"BTC-USD","sequence":180756868,"time":"2020-06-30T19:15:49.735115Z"}
{"type":"received","side":"sell","product_id":"BTC-USD","time":"2020-06-30T19:15:49.930385Z","sequence":180756869,"order_id":"83075288-3c81-430e-a8b5-671e72fd6a4a","order_type":"limit","size":"0.0659","price":"9113.65","client_oid":""}
{"type":"match","side":"buy","product_id":"BTC-USD","time":"2020-06-30T19:15:49.930385Z","sequence":180756870,"trade_id":14587613,"maker_order_id":"91b59a7c-6a07-4039-9536-21daf3cb3282","taker_order_id":"83075288-3c81-430e-a8b5-671e72fd6a4a","size":"0.0659","price":"9120.8"}
{"type":"done","side":"sell","product_id":"BTC-USD","time":"2020-06-30T19:15:49.930385Z","sequence":180756871,"order_id":"83075288-3c81-430e-a8b5-671e72fd6a4a","reason":"filled","price":"9113.65","remaining_size":"0"}
{"type":"received","side":"buy","product_id":"BTC-USD","time":"2020-06-30T19:15:50.436219Z","sequence":180756872,"order_id":"38e74cd0-3abf-4b86-bb9d-e89c7d566f7c","order_type":"limit","size":"0.36","price":"2","client_oid":""}
{"type":"open","side":"buy","product_id":"BTC-USD","time":"2020-06-30T19:15:50.436219Z","sequence":180756873,"price":"2","order_id":"38e74cd0-3abf-4b86-bb9d-e89c7d566f7c","remaining_size":"0.36"}
{"type":"received","side":"sell","product_id":"BTC-USD","time":"2020-06-30T19:15:50.522385Z","sequence":180756874,"order_id":"4be47f49-844a-4aa6-a319-8082801a71cb","order_type":"limit","size":"0.0659","price":"9113.98","client_oid":""}
{"type":"match","side":"buy","product_id":"BTC-USD","time":"2020-06-30T19:15:50.522385Z","sequence":180756875,"trade_id":14587614,"maker_order_id":"91b59a7c-6a07-4039-9536-21daf3cb3282","taker_order_id":"4be47f49-844a-4aa6-a319-8082801a71cb","size":"0.0659","price":"9120.8"}
{"type":"done","side":"sell","product_id":"BTC-USD","time":"2020-06-30T19:15:50.522385Z","sequence":180756876,"order_id":"4be47f49-844a-4aa6-a319-8082801a71cb","reason":"filled","price":"9113.98","remaining_size":"0"}
{"type":"heartbeat","last_trade_id":0,"product_id":"BTC-USD","sequence":180756876,"time":"2020-06-30T19:15:50.735121Z"}
{"type":"received","side":"buy","product_id":"BTC-USD","time":"2020-06-30T19:15:51.605988Z","sequence":180756877,"order_id":"ad2779bc-7c89-4c30-8a0c-9d85873fc82d","order_type":"limit","size":"0.543","price":"9111.05","client_oid":""}
{"type":"open","side":"buy","product_id":"BTC-USD","time":"2020-06-30T19:15:51.605988Z","sequence":180756878,"price":"9111.05","order_id":"ad2779bc-7c89-4c30-8a0c-9d85873fc82d","remaining_size":"0.543"}
{"type":"heartbeat","last_trade_id":0,"product_id":"BTC-USD","sequence":180756878,"time":"2020-06-30T19:15:51.735067Z"}
{"type":"done","side":"buy","product_id":"BTC-USD","time":"2020-06-30T19:15:51.804021Z","sequence":180756879,"order_id":"09c0bc2b-d06a-4a73-8050-fa41b5b8f1ab","reason":"canceled","price":"9098.61","remaining_size":"0.0223"}
{"type":"done","side":"buy","product_id":"BTC-USD","time":"2020-06-30T19:15:51.811375Z","sequence":180756880,"order_id":"f632d6e2-7f87-4af5-834a-9eeadb98ee59","reason":"canceled","price":"9103.28","remaining_size":"0.0223"}
{"type":"received","side":"sell","product_id":"BTC-USD","time":"2020-06-30T19:15:51.896456Z","sequence":180756881,"order_id":"b2c33b26-f5c9-4c28-86d1-c38c0b27b0f6","order_type":"limit","size":"0.2916","price":"9114.18","client_oid":""}
{"type":"match","side":"buy","product_id":"BTC-USD","time":"2020-06-30T19:15:51.896456Z","sequence":180756882,"trade_id":14587615,"maker_order_id":"91b59a7c-6a07-4039-9536-21daf3cb3282","taker_order_id":"b2c33b26-f5c9-4c28-86d1-c38c0b27b0f6","size":"0.2916","price":"9120.8"}
{"type":"done","side":"sell","product_id":"BTC-USD","time":"2020-06-30T19:15:51.896456Z","sequence":180756883,"order_id":"b2c33b26-f5c9-4c28-86d1-c38c0b27b0f6","reason":"filled","price":"9114.18","remaining_size":"0"}
{"type":"received","side":"buy","product_id":"BTC-USD","time":"2020-06-30T19:15:52.234090Z","sequence":180756884,"order_id":"14ca7108-9a82-4fe9-a1d1-3174b147b7e6","order_type":"limit","size":"0.1646","price":"9111.35","client_oid":""}
{"type":"open","side":"buy","product_id":"BTC-USD","time":"2020-06-30T19:15:52.234090Z","sequence":180756885,"price":"9111.35","order_id":"14ca7108-9a82-4fe9-a1d1-3174b147b7e6","remaining_size":"0.1646"}
{"type":"heartbeat","last_trade_id":0,"product_id":"BTC-USD","sequence":180756885,"time":"2020-06-30T19:15:52.735092Z"}
{"type":"received","side":"sell","product_id":"BTC-USD","time":"2020-06-30T19:15:52.764594Z","sequence":180756886,"order_id":"fc592a2e-57a4-4586-b273-f2eac9bfddd9","order_type":"limit","size":"0.0659","price":"9113.62","client_oid":""}
{"type":"match","side":"buy","product_id":"BTC-USD","time":"2020-06-30T19:15:52.764594Z","sequence":180756887,"trade_id":14587616,"maker_order_id":"91b59a7c-6a07-4039-9536-21daf3cb3282","taker_order_id":"fc592a2e-57a4-4586-b273-f2eac9bfddd9","size":"0.0659","price":"9120.8"}
{"type":"done","side":"sell","product_id":"BTC-USD","time":"2020-06-30T19:15:52.764594Z","sequence":180756888,"order_id":"fc592a2e-57a4-4586-b273-f2eac9bfddd9","reason":"filled","price":"9113.62","remaining_size":"0"}
{"type":"done","side":"sell","product_id":"BTC-USD","time":"2020-06-30T19:15:53.189504Z","sequence":180756889,"order_id":"4a3bb2e6-28ac-4ba1-b52c-ac4cc2fba403","reason":"canceled","price":"9175.2","remaining_size":"0.1"}
{"type":"done","side":"sell","product_id":"BTC-USD","time":"2020-06-30T19:15:53.192559Z","sequence":180756890,"order_id":"f4d1f60c-77a1-459b-8563-04d1b3ac23bf","reason":"canceled","price":"9142.18","remaining_size":"1.0652"}
{"type":"received","side":"sell","product_id":"BTC-USD","time":"2020-06-30T19:15:53.612074Z","sequence":180756891,"order_id":"b8c64164-15a3-492e-ae0d-7820aa9515c8","order_type":"limit","size":"0.0659","price":"9113.27","client_oid":""}
{"type":"match","side":"buy","product_id":"BTC-USD","time":"2020-06-30T19:15:53.612074Z","sequence":180756892,"trade_id":14587617,"maker_order_id":"91b59a7c-6a07-4039-9536-21daf3cb3282","taker_order_id":"b8c64164-15a3-492e-ae0d-7820aa9515c8","size":"0.0659","price":"9120.8"}
{"type":"done","side":"sell","product_id":"BTC-USD","time":"2020-06-30T19:15:53.612074Z","sequence":180756893,"order_id":"b8c64164-15a3-492e-ae0d-7820aa9515c8","reason":"filled","price":"9113.27","remaining_size":"0"}
{"type":"heartbeat","last_trade_id":0,"product_id":"BTC-USD","sequence":180756893,"time":"2020-06-30T19:15:53.735116Z"}
{"type":"done","side":"sell","product_id":"BTC-USD","time":"2020-06-30T19:15:54.063626Z","sequence":180756894,"order_id":"696f827b-9089-405b-8e85-f7c5a5a277ca","reason":"canceled","price":"9154.89","remaining_size":"0.069"}
{"type":"received","side":"sell","product_id":"BTC-USD","time":"2020-06-30T19:15:54.205961Z","sequence":180756895,"order_id":"2a118821-ab4a-4a87-bd86-2c123e5e13a4","order_type":"limit","size":"0.069","price":"9157.05","client_oid":""}
{"type":"open","side":"sell","product_id":"BTC-USD","time":"2020-06-30T19:15:54.205961Z","sequence":180756896,"price":"9157.05","order_id":"2a118821-ab4a-4a87-bd86-2c123e5e13a4","remaining_size":"0.069"}
{"type":"received","side":"sell","product_id":"BTC-USD","time":"2020-06-30T19:15:54.741847Z","sequence":180756897,"order_id":"fe3d3f94-426d-4808-87fb-28cfae88dd51","order_type":"limit","size":"0.0369","price":"9155.93","client_oid":""}
{"type":"open","side":"sell","product_id":"BTC-USD","time":"2020-06-30T19:15:54.741847Z","sequence":180756898,"price":"9155.93","order_id":"fe3d3f94-426d-4808-87fb-28cfae88dd51","remaining_size":"0.0369"}
{"type":"heartbeat","last_trade_id":0,"product_id":"BTC-USD","sequence":180756898,"time":"2020-06-30T19:15:54.735122Z"}
{"type":"received","side":"buy","product_id":"BTC-USD","time":"2020-06-30T19:15:54.954452Z","sequence":180756899,"order_id":"a6de95a8-8cd3-4960-a234-e2de376fb168","order_type":"limit","size":"0.11","price":"2","client_oid":""}
{"type":"open","side":"buy","product_id":"BTC-USD","time":"2020-06-30T19:15:54.954452Z","sequence":180756900,"price":"2","order_id":"a6de95a8-8cd3-4960-a234-e2de376fb168","remaining_size":"0.11"}
{"type":"heartbeat","last_trade_id":0,"product_id":"BTC-USD","sequence":180756900,"time":"2020-06-30T19:15:55.735110Z"}
{"type":"heartbeat","last_trade_id":0,"product_id":"BTC-USD","sequence":180756900,"time":"2020-06-30T19:15:56.735115Z"}
{"type":"received","side":"sell","product_id":"BTC-USD","time":"2020-06-30T19:15:56.951827Z","sequence":180756901,"order_id":"a4eb0702-0215-41f9-901e-544632404d27","order_type":"limit","size":"0.05","price":"9113.44","client_oid":""}
{"type":"match","side":"buy","product_id":"BTC-USD","time":"2020-06-30T19:15:56.951827Z","sequence":180756902,"trade_id":14587618,"maker_order_id":"91b59a7c-6a07-4039-9536-21daf3cb3282","taker_order_id":"a4eb0702-0215-41f9-901e-544632404d27","size":"0.05","price":"9120.8"}
{"type":"done","side":"sell","product_id":"BTC-USD","time":"2020-06-30T19:15:56.951827Z","sequence":180756903,"order_id":"a4eb0702-0215-41f9-901e-544632404d27","reason":"filled","price":"9113.44","remaining_size":"0"}
{"type":"received","side":"sell","product_id":"BTC-USD","time":"2020-06-30T19:15:57.234379Z","sequence":180756904,"order_id":"ab00b725-47d9-4694-aaa3-ab4bd7f91888","order_type":"limit","size":"0.9","price":"9114.65","client_oid":""}
{"type":"match","side":"buy","product_id":"BTC-USD","time":"2020-06-30T19:15:57.234379Z","sequence":180756905,"trade_id":14587619,"maker_order_id":"91b59a7c-6a07-4039-9536-21daf3cb3282","taker_order_id":"ab00b725-47d9-4694-aaa3-ab4bd7f91888","size":"0.9","price":"9120.8"}
{"type":"done","side":"sell","product_id":"BTC-USD","time":"2020-06-30T19:15:57.234379Z","sequence":180756906,"order_id":"ab00b725-47d9-4694-aaa3-ab4bd7f91888","reason":"filled","price":"9114.65","remaining_size":"0"}
{"type":"heartbeat","last_trade_id":0,"product_id":"BTC-USD","sequence":180756906,"time":"2020-06-30T19:15:57.735114Z"}
{"type":"received","side":"buy","product_id":"BTC-USD","time":"2020-06-30T19:15:57.817241Z","sequence":180756907,"order_id":"07f57f57-70ce-4bf9-8bf2-e443eebe7139","order_type":"limit","size":"0.023","price":"9078.68","client_oid":""}
{"type":"open","side":"buy","product_id":"BTC-USD","time":"2020-06-30T19:15:57.817241Z","sequence":180756908,"price":"9078.68","order_id":"07f57f57-70ce-4bf9-8bf2-e443eebe7139","remaining_size":"0.023"}
{"type":"received","side":"sell","product_id":"BTC-USD","time":"2020-06-30T19:15:58.092911Z","sequence":180756909,"order_id":"52583dc5-5466-4634-8e2b-e6f7e1adc530","order_type":"limit","size":"0.2","price":"9114.79","client_oid":""}
{"type":"match","side":"buy","product_id":"BTC-USD","time":"2020-06-30T19:15:58.092911Z","sequence":180756910,"trade_id":14587620,"maker_order_id":"91b59a7c-6a07-4039-9536-21daf3cb3282","taker_order_id":"52583dc5-5466-4634-8e2b-e6f7e1adc530","size":"0.2","price":"9120.8"}
{"type":"done","side":"sell","product_id":"BTC-USD","time":"2020-06-30T19:15:58.092911Z","sequence":180756911,"order_id":"52583dc5-5466-4634-8e2b-e6f7e1adc530","reason":"filled","price":"9114.79","remaining_size":"0"}
{"type":"done","side":"buy","product_id":"BTC-USD","time":"2020-06-30T19:15:58.252500Z","sequence":180756912,"order_id":"fac962b2-4beb-46c2-b715-f4d8628b3e91","reason":"canceled","price":"9111.07","remaining_size":"0.0012"}
{"type":"received","side":"sell","product_id":"BTC-USD","time":"2020-06-30T19:15:58.372032Z","sequence":180756913,"order_id":"df119119-0762-47b7-adce-7f98f42c9227","order_type":"limit","size":"0.069","price":"9155.23","client_oid":""}
{"type":"open","side":"sell","product_id":"BTC-USD","time":"2020-06-30T19:15:58.372032Z","sequence":180756914,"price":"9155.23","order_id":"df119119-0762-47b7-adce-7f98f42c9227","remaining_size":"0.069"}
{"type":"done","side":"sell","product_id":"BTC-USD","time":"2020-06-30T19:15:58.532421Z","sequence":180756915,"order_id":"fe3d3f94-426d-4808-87fb-28cfae88dd51","reason":"canceled","price":"9155.93","remaining_size":"0.0369"}
{"type":"received","side":"buy","product_id":"BTC-USD","time":"2020-06-30T19:15:58.655472Z","sequence":180756916,"order_id":"47f26271-5d0c-4a37-b4b8-96bdc900ab52","order_type":"limit","size":"0.0737","price":"9079.28","client_oid":""}
{"type":"open","side":"buy","product_id":"BTC-USD","time":"2020-06-30T19:15:58.655472Z","sequence":180756917,"price":"9079.28","order_id":"47f26271-5d0c-4a37-b4b8-96bdc900ab52","remaining_size":"0.0737"}
{"type":"heartbeat","last_trade_id":0,"product_id":"BTC-USD","sequence":180756917,"time":"2020-06-30T19:15:58.735112Z"}
{"type":"done","side":"buy","product_id":"BTC-USD","time":"2020-06-30T19:15:58.850259Z","sequence":180756918,"order_id":"ca03a0b3-dc33-418c-8b0e-69c28ed2ef4b","reason":"canceled","price":"8892.39","remaining_size":"0.04664204"}
{"type":"received","side":"buy","product_id":"BTC-USD","time":"2020-06-30T19:15:59.034977Z","sequence":180756919,"order_id":"39cc0fc2-48a7-49b8-9eb9-206400f8d6de","order_type":"limit","size":"0.01","price":"100","client_oid":"ba7c167d-84b2-4a37-b0f4-f445a8338d30"}
{"type":"open","side":"buy","product_id":"BTC-USD","time":"2020-06-30T19:15:59.034977Z","sequence":180756920,"price":"100","order_id":"39cc0fc2-48a7-49b8-9eb9-206400f8d6de","remaining_size":"0.01"}
{"type":"done","side":"buy","product_id":"BTC-USD","time":"2020-06-30T19:15:59.042462Z","sequence":180756921,"order_id":"39cc0fc2-48a7-49b8-9eb9-206400f8d6de","reason":"canceled","price":"100","remaining_size":"0.01"}
{"type":"received","side":"buy","product_id":"BTC-USD","time":"2020-06-30T19:15:59.092569Z","sequence":180756922,"order_id":"f31cafca-1fc5-4e0c-8183-39da259fe562","order_type":"limit","size":"0.04673688","price":"8891.62","client_oid":""}
{"type":"open","side":"buy","product_id":"BTC-USD","time":"2020-06-30T19:15:59.092569Z","sequence":180756923,"price":"8891.62","order_id":"f31cafca-1fc5-4e0c-8183-39da259fe562","remaining_size":"0.04673688"}
{"type":"received","side":"sell","product_id":"BTC-USD","time":"2020-06-30T19:15:59.232836Z","sequence":180756924,"order_id":"1735247d-e7bd-4fa7-b7e6-aaf4efe96f0d","order_type":"limit","size":"0.0659","price":"9113.52","client_oid":""}
{"type":"match","side":"buy","product_id":"BTC-USD","time":"2020-06-30T19:15:59.232836Z","sequence":180756925,"trade_id":14587621,"maker_order_id":"91b59a7c-6a07-4039-9536-21daf3cb3282","taker_order_id":"1735247d-e7bd-4fa7-b7e6-aaf4efe96f0d","size":"0.0659","price":"9120.8"}
{"type":"done","side":"sell","product_id":"BTC-USD","time":"2020-06-30T19:15:59.232836Z","sequence":180756926,"order_id":"1735247d-e7bd-4fa7-b7e6-aaf4efe96f0d","reason":"filled","price":"9113.52","remaining_size":"0"}
{"type":"received","side":"buy","product_id":"BTC-USD","time":"2020-06-30T19:15:59.312606Z","sequence":180756927,"order_id":"e174e454-cb71-49fa-835a-0cf4eec0beee","order_type":"limit","size":"0.04","price":"2","client_oid":""}
{"type":"open","side":"buy","product_id":"BTC-USD","time":"2020-06-30T19:15:59.312606Z","sequence":180756928,"price":"2","order_id":"e174e454-cb71-49fa-835a-0cf4eec0beee","remaining_size":"0.04"}
{"type":"done","side":"sell","product_id":"BTC-USD","time":"2020-06-30T19:15:59.355105Z","sequence":180756929,"order_id":"90acf728-3bb5-406a-b83a-2abbb34343c7","reason":"canceled","price":"9438.66","remaining_size":"0.007384"}
{"type":"received","side":"sell","product_id":"BTC-USD","time":"2020-06-30T19:15:59.539486Z","sequence":180756930,"order_id":"a943a649-066b-465c-9624-c1008e7d9f8c","order_type":"limit","size":"0.00747675","price":"9439.48","client_oid":""}
{"type":"open","side":"sell","product_id":"BTC-USD","time":"2020-06-30T19:15:59.539486Z","sequence":180756931,"price":"9439.48","order_id":"a943a649-066b-465c-9624-c1008e7d9f8c","remaining_size":"0.00747675"}
{"type":"heartbeat","last_trade_id":0,"product_id":"BTC-USD","sequence":180756931,"time":"2020-06-30T19:15:59.735112Z"}
{"type":"heartbeat","last_trade_id":0,"product_id":"BTC-USD","sequence":180756931,"time":"2020-06-30T19:16:00.735100Z"}
{"type":"received","side":"buy","product_id":"BTC-USD","time":"2020-06-30T19:16:01.265149Z","sequence":180756932,"order_id":"61331dca-f39f-458b-ae3d-ce620cf3e432","order_type":"limit","size":"0.049","price":"9103.29","client_oid":""}
{"type":"open","side":"buy","product_id":"BTC-USD","time":"2020-06-30T19:16:01.265149Z","sequence":180756933,"price":"9103.29","order_id":"61331dca-f39f-458b-ae3d-ce620cf3e432","remaining_size":"0.049"}
{"type":"received","side":"buy","product_id":"BTC-USD","time":"2020-06-30T19:16:01.553075Z","sequence":180756934,"order_id":"84206d18-4f08-4a4c-b902-93fd38757520","order_type":"limit","size":"0.049","price":"9103.31","client_oid":""}
{"type":"open","side":"buy","product_id":"BTC-USD","time":"2020-06-30T19:16:01.553075Z","sequence":180756935,"price":"9103.31","order_id":"84206d18-4f08-4a4c-b902-93fd38757520","remaining_size":"0.049"}
{"type":"done","side":"buy","product_id":"BTC-USD","time":"2020-06-30T19:16:01.729886Z","sequence":180756936,"order_id":"f151e52c-ccbf-411f-965c-4f848804c0e1","reason":"canceled","price":"9109","remaining_size":"17.547"}
{"type":"heartbeat","last_trade_id":0,"product_id":"BTC-USD","sequence":180756936,"time":"2020-06-30T19:16:01.735099Z"}
{"type":"done","side":"buy","product_id":"BTC-USD","time":"2020-06-30T19:16:01.749009Z","sequence":180756937,"order_id":"ad2779bc-7c89-4c30-8a0c-9d85873fc82d","reason":"canceled","price":"9111.05","remaining_size":"0.543"}
{"type":"done","side":"buy","product_id":"BTC-USD","time":"2020-06-30T19:16:01.991098Z","sequence":180756938,"order_id":"3494d785-f30c-4723-9a11-f97bfd3ad2be","reason":"canceled","price":"9111.98","remaining_size":"0.0581"}
{"type":"heartbeat","last_trade_id":0,"product_id":"BTC-USD","sequence":180756938,"time":"2020-06-30T19:16:02.735114Z"}
{"type":"received","side":"buy","product_id":"BTC-USD","time":"2020-06-30T19:16:02.929664Z","sequence":180756939,"order_id":"c9f169df-aa5a-4522-b2a7-80f8333ca7b2","order_type":"limit","size":"0.0418","price":"9110.16","client_oid":""}
{"type":"open","side":"buy","product_id":"BTC-USD","time":"2020-06-30T19:16:02.929664Z","sequence":180756940,"price":"9110.16","order_id":"c9f169df-aa5a-4522-b2a7-80f8333ca7b2","remaining_size":"0.0418"}
{"type":"done","side":"buy","product_id":"BTC-USD","time":"2020-06-30T19:16:03.340044Z","sequence":180756941,"order_id":"61331dca-f39f-458b-ae3d-ce620cf3e432","reason":"canceled","price":"9103.29","remaining_size":"0.049"}
{"type":"done","side":"buy","product_id":"BTC-USD","time":"2020-06-30T19:16:03.359862Z","sequence":180756942,"order_id":"14ca7108-9a82-4fe9-a1d1-3174b147b7e6","reason":"canceled","price":"9111.35","remaining_size":"0.1646"}
{"type":"received","side":"buy","product_id":"BTC-USD","time":"2020-06-30T19:16:03.514241Z","sequence":180756943,"order_id":"a19be837-5643-469f-9d6c-9f5883240bce","order_type":"limit","size":"8.0947","price":"9111.57","client_oid":""}
{"type":"open","side":"buy","product_id":"BTC-USD","time":"2020-06-30T19:16:03.514241Z","sequence":180756944,"price":"9111.57","order_id":"a19be837-5643-469f-9d6c-9f5883240bce","remaining_size":"8.0947"}
{"type":"heartbeat","last_trade_id":0,"product_id":"BTC-USD","sequence":180756944,"time":"2020-06-30T19:16:03.735116Z"}
{"type":"received","side":"buy","product_id":"BTC-USD","time":"2020-06-30T19:16:03.883135Z","sequence":180756945,"order_id":"17ee2b2c-14c2-4d5d-bc28-5449d8142050","order_type":"limit","size":"0.07","price":"2","client_oid":""}
{"type":"open","side":"buy","product_id":"BTC-USD","time":"2020-06-30T19:16:03.883135Z","sequence":180756946,"price":"2","order_id":"17ee2b2c-14c2-4d5d-bc28-5449d8142050","remaining_size":"0.07"}
{"type":"received","side":"sell","product_id":"BTC-USD","time":"2020-06-30T19:16:04.063756Z","sequence":180756947,"order_id":"91cbc022-b9c2-4133-a714-93649d207d05","order_type":"limit","size":"0.15","price":"9116.94","client_oid":""}
{"type":"match","side":"buy","product_id":"BTC-USD","time":"2020-06-30T19:16:04.063756Z","sequence":180756948,"trade_id":14587622,"maker_order_id":"91b59a7c-6a07-4039-9536-21daf3cb3282","taker_order_id":"91cbc022-b9c2-4133-a714-93649d207d05","size":"0.15","price":"9120.8"}
{"type":"done","side":"sell","product_id":"BTC-USD","time":"2020-06-30T19:16:04.063756Z","sequence":180756949,"order_id":"91cbc022-b9c2-4133-a714-93649d207d05","reason":"filled","price":"9116.94","remaining_size":"0"}
{"type":"received","side":"sell","product_id":"BTC-USD","time":"2020-06-30T19:16:04.408857Z","sequence":180756950,"order_id":"21c32eed-07e2-437c-979f-fee52f38438b","order_type":"limit","size":"3.4127","price":"9119.31","client_oid":""}
{"type":"match","side":"buy","product_id":"BTC-USD","time":"2020-06-30T19:16:04.408857Z","sequence":180756951,"trade_id":14587623,"maker_order_id":"91b59a7c-6a07-4039-9536-21daf3cb3282","taker_order_id":"21c32eed-07e2-437c-979f-fee52f38438b","size":"3.4127","price":"9120.8"}
{"type":"done","side":"sell","product_id":"BTC-USD","time":"2020-06-30T19:16:04.408857Z","sequence":180756952,"order_id":"21c32eed-07e2-437c-979f-fee52f38438b","reason":"filled","price":"9119.31","remaining_size":"0"}
{"type":"received","side":"sell","product_id":"BTC-USD","time":"2020-06-30T19:16:04.686281Z","sequence":180756953,"order_id":"efb5aecd-8dc5-4f04-b8c9-8d1959db2bbf","order_type":"limit","size":"0.001","price":"9170.37","client_oid":""}
{"type":"open","side":"sell","product_id":"BTC-USD","time":"2020-06-30T19:16:04.686281Z","sequence":180756954,"price":"9170.37","order_id":"efb5aecd-8dc5-4f04-b8c9-8d1959db2bbf","remaining_size":"0.001"}
{"type":"heartbeat","last_trade_id":0,"product_id":"BTC-USD","sequence":180756954,"time":"2020-06-30T19:16:04.735117Z"}
{"type":"done","side":"sell","product_id":"BTC-USD","time":"2020-06-30T19:16:04.803327Z","sequence":180756955,"order_id":"a639b52c-d8ca-467e-83bc-7901ebc2cff4","reason":"canceled","price":"9155.78","remaining_size":"0.0329"}
{"type":"received","side":"sell","product_id":"BTC-USD","time":"2020-06-30T19:16:04.970825Z","sequence":180756956,"order_id":"12f9e2dc-af75-41cf-a97b-5955f39c50ea","order_type":"limit","size":"0.003","price":"9291.19","client_oid":""}
{"type":"open","side":"sell","product_id":"BTC-USD","time":"2020-06-30T19:16:04.970825Z","sequence":180756957,"price":"9291.19","order_id":"12f9e2dc-af75-41cf-a97b-5955f39c50ea","remaining_size":"0.003"}
{"type":"received","side":"buy","product_id":"BTC-USD","time":"2020-06-30T19:16:05.253049Z","sequence":180756958,"order_id":"a411e61c-7054-41ee-9a94-45e8bede49e4","order_type":"limit","size":"0.0283","price":"9087.97","client_oid":""}
{"type":"open","side":"buy","product_id":"BTC-USD","time":"2020-06-30T19:16:05.253049Z","sequence":180756959,"price":"9087.97","order_id":"a411e61c-7054-41ee-9a94-45e8bede49e4","remaining_size":"0.0283"}
{"type":"done","side":"sell","product_id":"BTC-USD","time":"2020-06-30T19:16:05.431364Z","sequence":180756960,"order_id":"efb5aecd-8dc5-4f04-b8c9-8d1959db2bbf","reason":"canceled","price":"9170.37","remaining_size":"0.001"}
{"type":"done","side":"buy","product_id":"BTC-USD","time":"2020-06-30T19:16:05.495556Z","sequence":180756961,"order_id":"65fb765b-e549-43a3-9137-53c137c89f72","reason":"canceled","price":"9103.34","remaining_size":"0.0223"}
{"type":"done","side":"buy","product_id":"BTC-USD","time":"2020-06-30T19:16:05.518680Z","sequence":180756962,"order_id":"c9f169df-aa5a-4522-b2a7-80f8333ca7b2","reason":"canceled","price":"9110.16","remaining_size":"0.0418"}
{"type":"heartbeat","last_trade_id":0,"product_id":"BTC-USD","sequence":180756962,"time":"2020-06-30T19:16:05.735131Z"}
{"type":"received","side":"buy","product_id":"BTC-USD","time":"2020-06-30T19:16:05.836564Z","sequence":180756963,"order_id":"5f4c2a37-e003-4fab-8930-afada4b3d981","order_type":"limit","size":"0.3687","price":"9090.02","client_oid":""}
{"type":"open","side":"buy","product_id":"BTC-USD","time":"2020-06-30T19:16:05.836564Z","sequence":180756964,"price":"9090.02","order_id":"5f4c2a37-e003-4fab-8930-afada4b3d981","remaining_size":"0.3687"}
{"type":"done","side":"buy","product_id":"BTC-USD","time":"2020-06-30T19:16:06.034056Z","sequence":180756965,"order_id":"47f26271-5d0c-4a37-b4b8-96bdc900ab52","reason":"canceled","price":"9079.28","remaining_size":"0.0737"}
{"type":"done","side":"buy","product_id":"BTC-USD","time":"2020-06-30T19:16:06.039867Z","sequence":180756966,"order_id":"40d9083e-43b7-4175-93e8-dcd21a1b84e3","reason":"canceled","price":"9110.96","remaining_size":"0.034"}
{"type":"received","side":"buy","product_id":"BTC-USD","time":"2020-06-30T19:16:06.381068Z","sequence":180756967,"order_id":"a78b04e6-3499-4a93-bdc9-a803a1e32774","order_type":"limit","size":"0.049","price":"9103.38","client_oid":""}
{"type":"open","side":"buy","product_id":"BTC-USD","time":"2020-06-30T19:16:06.381068Z","sequence":180756968,"price":"9103.38","order_id":"a78b04e6-3499-4a93-bdc9-a803a1e32774","remaining_size":"0.049"}
{"type":"heartbeat","last_trade_id":0,"product_id":"BTC-USD","sequence":180756968,"time":"2020-06-30T19:16:06.735123Z"}
{"type":"received","side":"sell","product_id":"BTC-USD","time":"2020-06-30T19:16:07.246973Z","sequence":180756969,"order_id":"a330f9ff-4ddc-4598-91f8-61354069a2d5","order_type":"limit","size":"0.8879","price":"9115.73","client_oid":""}
{"type":"match","side":"buy","product_id":"BTC-USD","time":"2020-06-30T19:16:07.246973Z","sequence":180756970,"trade_id":14587624,"maker_order_id":"91b59a7c-6a07-4039-9536-21daf3cb3282","taker_order_id":"a330f9ff-4ddc-4598-91f8-61354069a2d5","size":"0.8879","price":"9120.8"}
{"type":"done","side":"sell","product_id":"BTC-USD","time":"2020-06-30T19:16:07.246973Z","sequence":180756971,"order_id":"a330f9ff-4ddc-4598-91f8-61354069a2d5","reason":"filled","price":"9115.73","remaining_size":"0"}
{"type":"received","side":"sell","product_id":"BTC-USD","time":"2020-06-30T19:16:07.497250Z","sequence":180756972,"order_id":"c23c8461-3a1d-4195-9e00-a81cbe9ed774","order_type":"limit","size":"0.05","price":"9114.03","client_oid":""}
{"type":"match","side":"buy","product_id":"BTC-USD","time":"2020-06-30T19:16:07.497250Z","sequence":180756973,"trade_id":14587625,"maker_order_id":"91b59a7c-6a07-4039-9536-21daf3cb3282","taker_order_id":"c23c8461-3a1d-4195-9e00-a81cbe9ed774","size":"0.05","price":"9120.8"}
{"type":"done","side":"sell","product_id":"BTC-USD","time":"2020-06-30T19:16:07.497250Z","sequence":180756974,"order_id":"c23c8461-3a1d-4195-9e00-a81cbe9ed774","reason":"filled","price":"9114.03","remaining_size":"0"}
{"type":"heartbeat","last_trade_id":0,"product_id":"BTC-USD","sequence":180756974,"time":"2020-06-30T19:16:07.735134Z"}
{"type":"received","side":"buy","product_id":"BTC-USD","time":"2020-06-30T19:16:08.069747Z","sequence":180756975,"order_id":"00d98d02-b381-4266-bb62-4caa3a6602d3","order_type":"limit","size":"0.37","price":"2","client_oid":""}
{"type":"open","side":"buy","product_id":"BTC-USD","time":"2020-06-30T19:16:08.069747Z","sequence":180756976,"price":"2","order_id":"00d98d02-b381-4266-bb62-4caa3a6602d3","remaining_size":"0.37"}
{"type":"received","side":"buy","product_id":"BTC-USD","time":"2020-06-30T19:16:08.358652Z","sequence":180756977,"order_id":"8f7f02a6-b810-4b57-98b6-2feda309270a","order_type":"limit","size":"0.01","price":"9086.59","client_oid":""}
{"type":"open","side":"buy","product_id":"BTC-USD","time":"2020-06-30T19:16:08.358652Z","sequence":180756978,"price":"9086.59","order_id":"8f7f02a6-b810-4b57-98b6-2feda309270a","remaining_size":"0.01"}
{"type":"heartbeat","last_trade_id":0,"product_id":"BTC-USD","sequence":180756978,"time":"2020-06-30T19:16:08.735122Z"}
{"type":"done","side":"buy","product_id":"BTC-USD","time":"2020-06-30T19:16:08.853300Z","sequence":180756979,"order_id":"84206d18-4f08-4a4c-b902-93fd38757520","reason":"canceled","price":"9103.31","remaining_size":"0.049"}
{"type":"received","side":"buy","product_id":"BTC-USD","time":"2020-06-30T19:16:08.879558Z","sequence":180756980,"order_id":"d5bcaa47-b04f-474f-b131-e8f01fc4df90","order_type":"limit","size":"0.0736","price":"9081.93","client_oid":""}
{"type":"open","side":"buy","product_id":"BTC-USD","time":"2020-06-30T19:16:08.879558Z","sequence":180756981,"price":"9081.93","order_id":"d5bcaa47-b04f-474f-b131-e8f01fc4df90","remaining_size":"0.0736"}
{"type":"received","side":"sell","product_id":"BTC-USD","time":"2020-06-30T19:16:09.160117Z","sequence":180756982,"order_id":"d37def80-ac45-457d-8798-bf7cd5805616","order_type":"limit","size":"0.0659","price":"9114.02","client_oid":""}
{"type":"match","side":"buy","product_id":"BTC-USD","time":"2020-06-30T19:16:09.160117Z","sequence":180756983,"trade_id":14587626,"maker_order_id":"91b59a7c-6a07-4039-9536-21daf3cb3282","taker_order_id":"d37def80-ac45-457d-8798-bf7cd5805616","size":"0.0659","price":"9120.8"}
{"type":"done","side":"sell","product_id":"BTC-USD","time":"2020-06-30T19:16:09.160117Z","sequence":180756984,"order_id":"d37def80-ac45-457d-8798-bf7cd5805616","reason":"filled","price":"9114.02","remaining_size":"0"}
{"type":"done","side":"buy","product_id":"BTC-USD","time":"2020-06-30T19:16:09.329483Z","sequence":180756985,"order_id":"07f57f57-70ce-4bf9-8bf2-e443eebe7139","reason":"canceled","price":"9078.68","remaining_size":"0.023"}
{"type":"done","side":"buy","product_id":"BTC-USD","time":"2020-06-30T19:16:09.331961Z","sequence":180756986,"order_id":"14b43b4d-6c02-4474-9aef-c820abc601df","reason":"canceled","price":"9085.45","remaining_size":"0.059"}
{"type":"done","side":"sell","product_id":"BTC-USD","time":"2020-06-30T19:16:09.352021Z","sequence":180756987,"order_id":"431876aa-1e62-4283-8e49-edc1f78d0367","reason":"canceled","price":"9155.32","remaining_size":"0.0329"}
{"type":"received","side":"buy","product_id":"BTC-USD","time":"2020-06-30T19:16:09.426988Z","sequence":180756988,"order_id":"181f0b13-726e-4ec5-acf4-22677523c424","order_type":"limit","size":"0.031","price":"9079.47","client_oid":""}
{"type":"open","side":"buy","product_id":"BTC-USD","time":"2020-06-30T19:16:09.426988Z","sequence":180756989,"price":"9079.47","order_id":"181f0b13-726e-4ec5-acf4-22677523c424","remaining_size":"0.031"}
{"type":"done","side":"buy","product_id":"BTC-USD","time":"2020-06-30T19:16:09.632523Z","sequence":180756990,"order_id":"8f7f02a6-b810-4b57-98b6-2feda309270a","reason":"canceled","price":"9086.59","remaining_size":"0.01"}
{"type":"heartbeat","last_trade_id":0,"product_id":"BTC-USD","sequence":180756990,"time":"2020-06-30T19:16:09.735118Z"}
{"type":"received","side":"sell","product_id":"BTC-USD","time":"2020-06-30T19:16:10.024467Z","sequence":180756991,"order_id":"2b353325-4385-42e9-8780-395baf59f288","order_type":"limit","size":"0.0659","price":"9114.02","client_oid":""}
{"type":"match","side":"buy","product_id":"BTC-USD","time":"2020-06-30T19:16:10.024467Z","sequence":180756992,"trade_id":14587627,"maker_order_id":"91b59a7c-6a07-4039-9536-21daf3cb3282","taker_order_id":"2b353325-4385-42e9-8780-395baf59f288","size":"0.0659","price":"9120.8"}
{"type":"done","side":"sell","product_id":"BTC-USD","time":"2020-06-30T19:16:10.024467Z","sequence":180756993,"order_id":"2b353325-4385-42e9-8780-395baf59f288","reason":"filled","price":"9114.02","remaining_size":"0"}
{"type":"received","side":"sell","product_id":"BTC-USD","time":"2020-06-30T19:16:10.600278Z","sequence":180756994,"order_id":"0faa2c69-f55b-4008-9207-fce22033676b","order_type":"limit","size":"0.0369","price":"9154.7","client_oid":""}
{"type":"open","side":"sell","product_id":"BTC-USD","time":"2020-06-30T19:16:10.600278Z","sequence":180756995,"price":"9154.7","order_id":"0faa2c69-f55b-4008-9207-fce22033676b","remaining_size":"0.0369"}
{"type":"heartbeat","last_trade_id":0,"product_id":"BTC-USD","sequence":180756995,"time":"2020-06-30T19:16:10.735031Z"}
{"type":"received","side":"buy","product_id":"BTC-USD","time":"2020-06-30T19:16:10.865448Z","sequence":180756996,"order_id":"9949bc59-415d-4822-a61d-472533907614","order_type":"limit","size":"0.049","price":"9103.39","client_oid":""}
{"type":"open","side":"buy","product_id":"BTC-USD","time":"2020-06-30T19:16:10.865448Z","sequence":180756997,"price":"9103.39","order_id":"9949bc59-415d-4822-a61d-472533907614","remaining_size":"0.049"}
{"type":"done","side":"sell","product_id":"BTC-USD","time":"2020-06-30T19:16:10.990579Z","sequence":180756998,"order_id":"9f0b82d9-c92b-4882-8c8e-63008ba628cf","reason":"canceled","price":"9156.37","remaining_size":"0.069"}
{"type":"received","side":"buy","product_id":"BTC-USD","time":"2020-06-30T19:16:11.147014Z","sequence":180756999,"order_id":"ce55a13b-4569-4b88-953f-288314f5821b","order_type":"limit","size":"4.279","price":"9111.57","client_oid":""}
{"type":"open","side":"buy","product_id":"BTC-USD","time":"2020-06-30T19:16:11.147014Z","sequence":180757000,"price":"9111.57","order_id":"ce55a13b-4569-4b88-953f-288314f5821b","remaining_size":"4.279"}
{"type":"received","side":"sell","product_id":"BTC-USD","time":"2020-06-30T19:16:11.265115Z","sequence":180757001,"order_id":"cc23a356-1f1f-4deb-8b55-1face442fcec","order_type":"market","size":"0.001","funds":"9.1208","client_oid":""}
{"type":"match","side":"buy","product_id":"BTC-USD","time":"2020-06-30T19:16:11.265115Z","sequence":180757002,"trade_id":14587628,"maker_order_id":"91b59a7c-6a07-4039-9536-21daf3cb3282","taker_order_id":"cc23a356-1f1f-4deb-8b55-1face442fcec","size":"0.001","price":"9120.8"}
{"type":"done","side":"sell","product_id":"BTC-USD","time":"2020-06-30T19:16:11.265115Z","sequence":180757003,"order_id":"cc23a356-1f1f-4deb-8b55-1face442fcec","reason":"filled","remaining_size":"0"}
{"type":"done","side":"buy","product_id":"BTC-USD","time":"2020-06-30T19:16:11.289535Z","sequence":180757004,"order_id":"d54a4020-fda1-4f31-bac7-a13b425cb2ad","reason":"canceled","price":"9103.26","remaining_size":"0.049"}
{"type":"done","side":"buy","product_id":"BTC-USD","time":"2020-06-30T19:16:11.305629Z","sequence":180757005,"order_id":"181f0b13-726e-4ec5-acf4-22677523c424","reason":"canceled","price":"9079.47","remaining_size":"0.031"}
{"type":"done","side":"buy","product_id":"BTC-USD","time":"2020-06-30T19:16:11.559160Z","sequence":180757006,"order_id":"9949bc59-415d-4822-a61d-472533907614","reason":"canceled","price":"9103.39","remaining_size":"0.049"}
{"type":"done","side":"buy","product_id":"BTC-USD","time":"2020-06-30T19:16:11.564164Z","sequence":180757007,"order_id":"a03eb967-e26c-41f5-b197-c056abf6013f","reason":"canceled","price":"9103.3","remaining_size":"0.0223"}
{"type":"heartbeat","last_trade_id":0,"product_id":"BTC-USD","sequence":180757007,"time":"2020-06-30T19:16:11.735173Z"}
{"type":"received","side":"buy","product_id":"BTC-USD","time":"2020-06-30T19:16:12.002992Z","sequence":180757008,"order_id":"0b60680b-c7a6-4816-917b-24a7cb1d5a62","order_type":"limit","size":"8.279","price":"9111.57","client_oid":""}
{"type":"open","side":"buy","product_id":"BTC-USD","time":"2020-06-30T19:16:12.002992Z","sequence":180757009,"price":"9111.57","order_id":"0b60680b-c7a6-4816-917b-24a7cb1d5a62","remaining_size":"8.279"}
{"type":"received","side":"buy","product_id":"BTC-USD","time":"2020-06-30T19:16:12.271591Z","sequence":180757010,"order_id":"45d875f5-97e5-4659-bee8-be8f3b30649b","order_type":"limit","size":"0.1518","price":"9074.54","client_oid":""}
{"type":"open","side":"buy","product_id":"BTC-USD","time":"2020-06-30T19:16:12.271591Z","sequence":180757011,"price":"9074.54","order_id":"45d875f5-97e5-4659-bee8-be8f3b30649b","remaining_size":"0.1518"}
{"type":"done","side":"buy","product_id":"BTC-USD","time":"2020-06-30T19:16:12.434610Z","sequence":180757012,"order_id":"a78b04e6-3499-4a93-bdc9-a803a1e32774","reason":"canceled","price":"9103.38","remaining_size":"0.049"}
{"type":"received","side":"sell","product_id":"BTC-USD","time":"2020-06-30T19:16:12.554423Z","sequence":180757013,"order_id":"8a96ba31-25e2-4eaa-b816-1ba104630810","order_type":"limit","size":"0.0149","price":"9157.17","client_oid":""}
{"type":"open","side":"sell","product_id":"BTC-USD","time":"2020-06-30T19:16:12.554423Z","sequence":180757014,"price":"9157.17","order_id":"8a96ba31-25e2-4eaa-b816-1ba104630810","remaining_size":"0.0149"}
{"type":"done","side":"buy","product_id":"BTC-USD","time":"2020-06-30T19:16:12.729852Z","sequence":180757015,"order_id":"5f4c2a37-e003-4fab-8930-afada4b3d981","reason":"canceled","price":"9090.02","remaining_size":"0.3687"}
{"type":"heartbeat","last_trade_id":0,"product_id":"BTC-USD","sequence":180757015,"time":"2020-06-30T19:16:12.735115Z"}
{"type":"received","side":"buy","product_id":"BTC-USD","time":"2020-06-30T19:16:12.879010Z","sequence":180757016,"order_id":"44dba4d2-bf74-425e-8527-614f7f62ce2d","order_type":"limit","size":"0.021","price":"9099.98","client_oid":""}
{"type":"open","side":"buy","product_id":"BTC-USD","time":"2020-06-30T19:16:12.879010Z","sequence":180757017,"price":"9099.98","order_id":"44dba4d2-bf74-425e-8527-614f7f62ce2d","remaining_size":"0.021"}
{"type":"received","side":"buy","product_id":"BTC-USD","time":"2020-06-30T19:16:13.492457Z","sequence":180757018,"order_id":"bcaf2a1b-2b26-45bb-9c94-66ef70d18240","order_type":"limit","size":"0.049","price":"9103.31","client_oid":""}
{"type":"open","side":"buy","product_id":"BTC-USD","time":"2020-06-30T19:16:13.492457Z","sequence":180757019,"price":"9103.31","order_id":"bcaf2a1b-2b26-45bb-9c94-66ef70d18240","remaining_size":"0.049"}
{"type":"heartbeat","last_trade_id":0,"product_id":"BTC-USD","sequence":180757019,"time":"2020-06-30T19:16:13.735135Z"}
{"type":"done","side":"buy","product_id":"BTC-USD","time":"2020-06-30T19:16:13.934296Z","sequence":180757020,"order_id":"700b67e9-eb33-4016-95da-a63d35e40880","reason":"canceled","price":"9103.26","remaining_size":"0.0223"}
{"type":"received","side":"buy","product_id":"BTC-USD","time":"2020-06-30T19:16:14.052630Z","sequence":180757021,"order_id":"6e2d82be-0333-4368-95ac-7763760aac63","order_type":"limit","size":"0.01","price":"100","client_oid":"75190baf-b2f7-434a-8eac-34452656a6f6"}
{"type":"open","side":"buy","product_id":"BTC-USD","time":"2020-06-30T19:16:14.052630Z","sequence":180757022,"price":"100","order_id":"6e2d82be-0333-4368-95ac-7763760aac63","remaining_size":"0.01"}
{"type":"done","side":"buy","product_id":"BTC-USD","time":"2020-06-30T19:16:14.058806Z","sequence":180757023,"order_id":"6e2d82be-0333-4368-95ac-7763760aac63","reason":"canceled","price":"100","remaining_size":"0.01"}
{"type":"received","side":"buy","product_id":"BTC-USD","time":"2020-06-30T19:16:14.295815Z","sequence":180757024,"order_id":"63214f5a-0d24-4dcc-85fa-3312f6d36c1a","order_type":"limit","size":"0.01","price":"9087.27","client_oid":""}
{"type":"open","side":"buy","product_id":"BTC-USD","time":"2020-06-30T19:16:14.295815Z","sequence":180757025,"price":"9087.27","order_id":"63214f5a-0d24-4dcc-85fa-3312f6d36c1a","remaining_size":"0.01"}
{"type":"heartbeat","last_trade_id":0,"product_id":"BTC-USD","sequence":180757025,"time":"2020-06-30T19:16:14.735075Z"}
{"type":"received","side":"buy","product_id":"BTC-USD","time":"2020-06-30T19:16:14.845571Z","sequence":180757026,"order_id":"127aae64-34cc-48aa-a665-37fb8f4f53a5","order_type":"limit","size":"0.049","price":"9103.39","client_oid":""}
{"type":"open","side":"buy","product_id":"BTC-USD","time":"2020-06-30T19:16:14.845571Z","sequence":180757027,"price":"9103.39","order_id":"127aae64-34cc-48aa-a665-37fb8f4f53a5","remaining_size":"0.049"}
{"type":"received","side":"sell","product_id":"BTC-USD","time":"2020-06-30T19:16:15.121528Z","sequence":180757028,"order_id":"cbcc250d-5380-4c46-84fb-14d6693d9081","order_type":"limit","size":"0.069","price":"9154.76","client_oid":""}
{"type":"open","side":"sell","product_id":"BTC-USD","time":"2020-06-30T19:16:15.121528Z","sequence":180757029,"price":"9154.76","order_id":"cbcc250d-5380-4c46-84fb-14d6693d9081","remaining_size":"0.069"}
{"type":"done","side":"buy","product_id":"BTC-USD","time":"2020-06-30T19:16:15.456046Z","sequence":180757030,"order_id":"29210d07-674b-4c58-8fdd-95840d691a60","reason":"canceled","price":"9098.61","remaining_size":"0.0223"}
{"type":"done","side":"sell","product_id":"BTC-USD","time":"2020-06-30T19:16:15.543060Z","sequence":180757031,"order_id":"12f9e2dc-af75-41cf-a97b-5955f39c50ea","reason":"canceled","price":"9291.19","remaining_size":"0.003"}
{"type":"done","side":"sell","product_id":"BTC-USD","time":"2020-06-30T19:16:15.555219Z","sequence":180757032,"order_id":"0faa2c69-f55b-4008-9207-fce22033676b","reason":"canceled","price":"9154.7","remaining_size":"0.0369"}
{"type":"heartbeat","last_trade_id":0,"product_id":"BTC-USD","sequence":180757032,"time":"2020-06-30T19:16:15.735122Z"}
{"type":"done","side":"buy","product_id":"BTC-USD","time":"2020-06-30T19:16:16.411156Z","sequence":180757033,"order_id":"44dba4d2-bf74-425e-8527-614f7f62ce2d","reason":"canceled","price":"9099.98","remaining_size":"0.021"}
{"type":"heartbeat","last_trade_id":0,"product_id":"BTC-USD","sequence":180757033,"time":"2020-06-30T19:16:16.735110Z"}
{"type":"heartbeat","last_trade_id":0,"product_id":"BTC-USD","sequence":180757033,"time":"2020-06-30T19:16:17.735112Z"}
{"type":"received","side":"sell","product_id":"BTC-USD","time":"2020-06-30T19:16:17.970662Z","sequence":180757034,"order_id":"a4600099-2ab6-4a77-b47f-26da342a6372","order_type":"limit","size":"0.0329","price":"9155.99","client_oid":""}
{"type":"open","side":"sell","product_id":"BTC-USD","time":"2020-06-30T19:16:17.970662Z","sequence":180757035,"price":"9155.99","order_id":"a4600099-2ab6-4a77-b47f-26da342a6372","remaining_size":"0.0329"}
{"type":"received","side":"sell","product_id":"BTC-USD","time":"2020-06-30T19:16:18.239682Z","sequence":180757036,"order_id":"d129124c-f911-429d-848a-e226ff01bcbf","order_type":"limit","size":"0.25","price":"9115.22","client_oid":""}
{"type":"match","side":"buy","product_id":"BTC-USD","time":"2020-06-30T19:16:18.239682Z","sequence":180757037,"trade_id":14587629,"maker_order_id":"91b59a7c-6a07-4039-9536-21daf3cb3282","taker_order_id":"d129124c-f911-429d-848a-e226ff01bcbf","size":"0.25","price":"9120.8"}
{"type":"done","side":"sell","product_id":"BTC-USD","time":"2020-06-30T19:16:18.239682Z","sequence":180757038,"order_id":"d129124c-f911-429d-848a-e226ff01bcbf","reason":"filled","price":"9115.22","remaining_size":"0"}
{"type":"heartbeat","last_trade_id":0,"product_id":"BTC-USD","sequence":180757038,"time":"2020-06-30T19:16:18.735113Z"}
{"type":"done","side":"sell","product_id":"BTC-USD","time":"2020-06-30T19:16:18.791457Z","sequence":180757039,"order_id":"a4600099-2ab6-4a77-b47f-26da342a6372","reason":"canceled","price":"9155.99","remaining_size":"0.0329"}
{"type":"received","side":"buy","product_id":"BTC-USD","time":"2020-06-30T19:16:19.120704Z","sequence":180757040,"order_id":"20bb693b-f533-416b-b987-3d522a039acf","order_type":"limit","size":"0.0377","price":"9069.56","client_oid":""}
{"type":"open","side":"buy","product_id":"BTC-USD","time":"2020-06-30T19:16:19.120704Z","sequence":180757041,"price":"9069.56","order_id":"20bb693b-f533-416b-b987-3d522a039acf","remaining_size":"0.0377"}
{"type":"heartbeat","last_trade_id":0,"product_id":"BTC-USD","sequence":180757041,"time":"2020-06-30T19:16:19.735031Z"}
{"type":"received","side":"sell","product_id":"BTC-USD","time":"2020-06-30T19:16:19.760000Z","sequence":180757042,"order_id":"bed5e25f-8d65-4778-b09a-d3aad96afbdd","order_type":"limit","size":"1.0236","price":"9111.58","client_oid":""}
{"type":"match","side":"buy","product_id":"BTC-USD","time":"2020-06-30T19:16:19.760000Z","sequence":180757043,"trade_id":14587630,"maker_order_id":"91b59a7c-6a07-4039-9536-21daf3cb3282","taker_order_id":"bed5e25f-8d65-4778-b09a-d3aad96afbdd","size":"1.0236","price":"9120.8"}
{"type":"done","side":"sell","product_id":"BTC-USD","time":"2020-06-30T19:16:19.760000Z","sequence":180757044,"order_id":"bed5e25f-8d65-4778-b09a-d3aad96afbdd","reason":"filled","price":"9111.58","remaining_size":"0"}
{"type":"received","side":"sell","product_id":"BTC-USD","time":"2020-06-30T19:16:20.024460Z","sequence":180757045,"order_id":"e155d094-0d6e-4454-8efe-ac1d29c3ee26","order_type":"limit","size":"0.0676","price":"9154.96","client_oid":""}
{"type":"open","side":"sell","product_id":"BTC-USD","time":"2020-06-30T19:16:20.024460Z","sequence":180757046,"price":"9154.96","order_id":"e155d094-0d6e-4454-8efe-ac1d29c3ee26","remaining_size":"0.0676"}
{"type":"received","side":"sell","product_id":"BTC-USD","time":"2020-06-30T19:16:20.307592Z","sequence":180757047,"order_id":"52dd7e4f-102c-4160-8ae0-a571605b58c7","order_type":"limit","size":"0.05","price":"9114.03","client_oid":""}
{"type":"match","side":"buy","product_id":"BTC-USD","time":"2020-06-30T19:16:20.307592Z","sequence":180757048,"trade_id":14587631,"maker_order_id":"91b59a7c-6a07-4039-9536-21daf3cb3282","taker_order_id":"52dd7e4f-102c-4160-8ae0-a571605b58c7","size":"0.05","price":"9120.8"}
{"type":"done","side":"sell","product_id":"BTC-USD","time":"2020-06-30T19:16:20.307592Z","sequence":180757049,"order_id":"52dd7e4f-102c-4160-8ae0-a571605b58c7","reason":"filled","price":"9114.03","remaining_size":"0"}
{"type":"heartbeat","last_trade_id":0,"product_id":"BTC-USD","sequence":180757049,"time":"2020-06-30T19:16:20.735162Z"}
{"type":"received","side":"sell","product_id":"BTC-USD","time":"2020-06-30T19:16:20.881279Z","sequence":180757050,"order_id":"5b9e53cb-49e8-43fa-81a0-8f85e875c23e","order_type":"limit","size":"0.0659","price":"9113.88","client_oid":""}
{"type":"match","side":"buy","product_id":"BTC-USD","time":"2020-06-30T19:16:20.881279Z","sequence":180757051,"trade_id":14587632,"maker_order_id":"91b59a7c-6a07-4039-9536-21daf3cb3282","taker_order_id":"5b9e53cb-49e8-43fa-81a0-8f85e875c23e","size":"0.0659","price":"9120.8"}
{"type":"done","side":"sell","product_id":"BTC-USD","time":"2020-06-30T19:16:20.881279Z","sequence":180757052,"order_id":"5b9e53cb-49e8-43fa-81a0-8f85e875c23e","reason":"filled","price":"9113.88","remaining_size":"0"}
{"type":"received","side":"sell","product_id":"BTC-USD","time":"2020-06-30T19:16:21.705297Z","sequence":180757053,"order_id":"d5acdab5-c124-4046-8b3b-17cfcce45607","order_type":"limit","size":"0.0676","price":"9155.29","client_oid":""}
{"type":"open","side":"sell","product_id":"BTC-USD","time":"2020-06-30T19:16:21.705297Z","sequence":180757054,"price":"9155.29","order_id":"d5acdab5-c124-4046-8b3b-17cfcce45607","remaining_size":"0.0676"}
{"type":"heartbeat","last_trade_id":0,"product_id":"BTC-USD","sequence":180757054,"time":"2020-06-30T19:16:21.735110Z"}
{"type":"received","side":"sell","product_id":"BTC-USD","time":"2020-06-30T19:16:22.268643Z","sequence":180757055,"order_id":"de4a1381-c775-4b91-a20f-c12b742cf2d9","order_type":"limit","size":"0.0546","price":"9151.01","client_oid":""}
{"type":"open","side":"sell","product_id":"BTC-USD","time":"2020-06-30T19:16:22.268643Z","sequence":180757056,"price":"9151.01","order_id":"de4a1381-c775-4b91-a20f-c12b742cf2d9","remaining_size":"0.0546"}
{"type":"heartbeat","last_trade_id":0,"product_id":"BTC-USD","sequence":180757056,"time":"2020-06-30T19:16:22.735114Z"}
{"type":"received","side":"buy","product_id":"BTC-USD","time":"2020-06-30T19:16:22.826682Z","sequence":180757057,"order_id":"6e66fc74-2f28-48f0-9e29-81fc24181f8e","order_type":"limit","size":"4.0655","price":"9111.57","client_oid":""}
{"type":"open","side":"buy","product_id":"BTC-USD","time":"2020-06-30T19:16:22.826682Z","sequence":180757058,"price":"9111.57","order_id":"6e66fc74-2f28-48f0-9e29-81fc24181f8e","remaining_size":"4.0655"}
{"type":"done","side":"buy","product_id":"BTC-USD","time":"2020-06-30T19:16:23.024307Z","sequence":180757059,"order_id":"a19be837-5643-469f-9d6c-9f5883240bce","reason":"canceled","price":"9111.57","remaining_size":"8.0947"}
{"type":"done","side":"buy","product_id":"BTC-USD","time":"2020-06-30T19:16:23.024780Z","sequence":180757060,"order_id":"63214f5a-0d24-4dcc-85fa-3312f6d36c1a","reason":"canceled","price":"9087.27","remaining_size":"0.01"}
{"type":"received","side":"buy","product_id":"BTC-USD","time":"2020-06-30T19:16:23.111309Z","sequence":180757061,"order_id":"0b3942c2-a910-4152-acea-006bba825744","order_type":"limit","size":"0.0105","price":"9075.35","client_oid":""}
{"type":"open","side":"buy","product_id":"BTC-USD","time":"2020-06-30T19:16:23.111309Z","sequence":180757062,"price":"9075.35","order_id":"0b3942c2-a910-4152-acea-006bba825744","remaining_size":"0.0105"}
{"type":"done","side":"buy","product_id":"BTC-USD","time":"2020-06-30T19:16:23.549513Z","sequence":180757063,"order_id":"20bb693b-f533-416b-b987-3d522a039acf","reason":"canceled","price":"9069.56","remaining_size":"0.0377"}
{"type":"received","side":"sell","product_id":"BTC-USD","time":"2020-06-30T19:16:23.615846Z","sequence":180757064,"order_id":"ddd91f97-ead7-4f46-b54e-a69d05f38638","order_type":"limit","size":"0.05","price":"9113.92","client_oid":""}
{"type":"match","side":"buy","product_id":"BTC-USD","time":"2020-06-30T19:16:23.615846Z","sequence":180757065,"trade_id":14587633,"maker_order_id":"91b59a7c-6a07-4039-9536-21daf3cb3282","taker_order_id":"ddd91f97-ead7-4f46-b54e-a69d05f38638","size":"0.05","price":"9120.8"}
{"type":"done","side":"sell","product_id":"BTC-USD","time":"2020-06-30T19:16:23.615846Z","sequence":180757066,"order_id":"ddd91f97-ead7-4f46-b54e-a69d05f38638","reason":"filled","price":"9113.92","remaining_size":"0"}
{"type":"received","side":"sell","product_id":"BTC-USD","time":"2020-06-30T19:16:23.672841Z","sequence":180757067,"order_id":"26689fef-0c21-4d49-be2e-1e5ed51f2beb","order_type":"limit","size":"0.0659","price":"9113.94","client_oid":""}
{"type":"match","side":"buy","product_id":"BTC-USD","time":"2020-06-30T19:16:23.672841Z","sequence":180757068,"trade_id":14587634,"maker_order_id":"91b59a7c-6a07-4039-9536-21daf3cb3282","taker_order_id":"26689fef-0c21-4d49-be2e-1e5ed51f2beb","size":"0.0659","price":"9120.8"}
{"type":"done","side":"sell","product_id":"BTC-USD","time":"2020-06-30T19:16:23.672841Z","sequence":180757069,"order_id":"26689fef-0c21-4d49-be2e-1e5ed51f2beb","reason":"filled","price":"9113.94","remaining_size":"0"}
{"type":"heartbeat","last_trade_id":0,"product_id":"BTC-USD","sequence":180757069,"time":"2020-06-30T19:16:23.735111Z"}
{"type":"received","side":"sell","product_id":"BTC-USD","time":"2020-06-30T19:16:24.562261Z","sequence":180757070,"order_id":"32dfefdc-0f39-4caf-bbdb-2b9e0359fcf9","order_type":"limit","size":"1.642","price":"9114.67","client_oid":""}
{"type":"match","side":"buy","product_id":"BTC-USD","time":"2020-06-30T19:16:24.562261Z","sequence":180757071,"trade_id":14587635,"maker_order_id":"91b59a7c-6a07-4039-9536-21daf3cb3282","taker_order_id":"32dfefdc-0f39-4caf-bbdb-2b9e0359fcf9","size":"1.642","price":"9120.8"}
{"type":"done","side":"sell","product_id":"BTC-USD","time":"2020-06-30T19:16:24.562261Z","sequence":180757072,"order_id":"32dfefdc-0f39-4caf-bbdb-2b9e0359fcf9","reason":"filled","price":"9114.67","remaining_size":"0"}
{"type":"heartbeat","last_trade_id":0,"product_id":"BTC-USD","sequence":180757072,"time":"2020-06-30T19:16:24.735117Z"}
{"type":"done","side":"sell","product_id":"BTC-USD","time":"2020-06-30T19:16:24.994051Z","sequence":180757073,"order_id":"cbcc250d-5380-4c46-84fb-14d6693d9081","reason":"canceled","price":"9154.76","remaining_size":"0.069"}
{"type":"received","side":"sell","product_id":"BTC-USD","time":"2020-06-30T19:16:25.178631Z","sequence":180757074,"order_id":"587e2b0f-8a7e-4240-b0c0-334b13c90430","order_type":"limit","size":"0.0659","price":"9113.91","client_oid":""}
{"type":"match","side":"buy","product_id":"BTC-USD","time":"2020-06-30T19:16:25.178631Z","sequence":180757075,"trade_id":14587636,"maker_order_id":"91b59a7c-6a07-4039-9536-21daf3cb3282","taker_order_id":"587e2b0f-8a7e-4240-b0c0-334b13c90430","size":"0.0659","price":"9120.8"}
{"type":"done","side":"sell","product_id":"BTC-USD","time":"2020-06-30T19:16:25.178631Z","sequence":180757076,"order_id":"587e2b0f-8a7e-4240-b0c0-334b13c90430","reason":"filled","price":"9113.91","remaining_size":"0"}
{"type":"done","side":"sell","product_id":"BTC-USD","time":"2020-06-30T19:16:25.378825Z","sequence":180757077,"order_id":"de4a1381-c775-4b91-a20f-c12b742cf2d9","reason":"canceled","price":"9151.01","remaining_size":"0.0546"}
{"type":"received","side":"sell","product_id":"BTC-USD","time":"2020-06-30T19:16:25.461755Z","sequence":180757078,"order_id":"54e93c0d-bc50-4a79-bb2d-fd7977405113","order_type":"limit","size":"0.0547","price":"9148.74","client_oid":""}
{"type":"open","side":"sell","product_id":"BTC-USD","time":"2020-06-30T19:16:25.461755Z","sequence":180757079,"price":"9148.74","order_id":"54e93c0d-bc50-4a79-bb2d-fd7977405113","remaining_size":"0.0547"}
{"type":"heartbeat","last_trade_id":0,"product_id":"BTC-USD","sequence":180757079,"time":"2020-06-30T19:16:25.735129Z"}
{"type":"received","side":"buy","product_id":"BTC-USD","time":"2020-06-30T19:16:26.299402Z","sequence":180757080,"order_id":"053a9e09-b148-47a2-9428-faeed98da26a","order_type":"limit","size":"0.0156","price":"9091.83","client_oid":""}
{"type":"open","side":"buy","product_id":"BTC-USD","time":"2020-06-30T19:16:26.299402Z","sequence":180757081,"price":"9091.83","order_id":"053a9e09-b148-47a2-9428-faeed98da26a","remaining_size":"0.0156"}
{"type":"received","side":"sell","product_id":"BTC-USD","time":"2020-06-30T19:16:26.562683Z","sequence":180757082,"order_id":"7527318c-4302-459c-a3e6-613912004d7a","order_type":"limit","size":"0.25","price":"9114.88","client_oid":""}
{"type":"match","side":"buy","product_id":"BTC-USD","time":"2020-06-30T19:16:26.562683Z","sequence":180757083,"trade_id":14587637,"maker_order_id":"91b59a7c-6a07-4039-9536-21daf3cb3282","taker_order_id":"7527318c-4302-459c-a3e6-613912004d7a","size":"0.25","price":"9120.8"}
{"type":"done","side":"sell","product_id":"BTC-USD","time":"2020-06-30T19:16:26.562683Z","sequence":180757084,"order_id":"7527318c-4302-459c-a3e6-613912004d7a","reason":"filled","price":"9114.88","remaining_size":"0"}
{"type":"heartbeat","last_trade_id":0,"product_id":"BTC-USD","sequence":180757084,"time":"2020-06-30T19:16:26.735121Z"}
{"type":"received","side":"sell","product_id":"BTC-USD","time":"2020-06-30T19:16:26.892217Z","sequence":180757085,"order_id":"35c0683f-20a9-4aad-b8b0-2ff77c773df6","order_type":"limit","size":"0.0236","price":"9121.08","client_oid":""}
{"type":"open","side":"sell","product_id":"BTC-USD","time":"2020-06-30T19:16:26.892217Z","sequence":180757086,"price":"9121.08","order_id":"35c0683f-20a9-4aad-b8b0-2ff77c773df6","remaining_size":"0.0236"}
{"type":"heartbeat","last_trade_id":0,"product_id":"BTC-USD","sequence":180757086,"time":"2020-06-30T19:16:27.735118Z"}
{"type":"heartbeat","last_trade_id":0,"product_id":"BTC-USD","sequence":180757086,"time":"2020-06-30T19:16:28.735120Z"}
{"type":"received","side":"buy","product_id":"BTC-USD","time":"2020-06-30T19:16:29.070896Z","sequence":180757087,"order_id":"90b8ded0-176f-4cf9-8164-de03e3b80466","order_type":"limit","size":"0.01","price":"100","client_oid":"9c8cec0b-99d3-4537-b800-95ea7608fc5d"}
{"type":"open","side":"buy","product_id":"BTC-USD","time":"2020-06-30T19:16:29.070896Z","sequence":180757088,"price":"100","order_id":"90b8ded0-176f-4cf9-8164-de03e3b80466","remaining_size":"0.01"}
{"type":"done","side":"buy","product_id":"BTC-USD","time":"2020-06-30T19:16:29.078292Z","sequence":180757089,"order_id":"90b8ded0-176f-4cf9-8164-de03e3b80466","reason":"canceled","price":"100","remaining_size":"0.01"}
{"type":"received","side":"buy","product_id":"BTC-USD","time":"2020-06-30T19:16:29.496882Z","sequence":180757090,"order_id":"6212da9a-e274-4930-ab99-35082a36ffbe","order_type":"limit","size":"8.4127","price":"9111.57","client_oid":""}
{"type":"open","side":"buy","product_id":"BTC-USD","time":"2020-06-30T19:16:29.496882Z","sequence":180757091,"price":"9111.57","order_id":"6212da9a-e274-4930-ab99-35082a36ffbe","remaining_size":"8.4127"}
{"type":"heartbeat","last_trade_id":0,"product_id":"BTC-USD","sequence":180757091,"time":"2020-06-30T19:16:29.735120Z"}
{"type":"heartbeat","last_trade_id":0,"product_id":"BTC-USD","sequence":180757091,"time":"2020-06-30T19:16:30.735118Z"}
{"type":"received","side":"sell","product_id":"BTC-USD","time":"2020-06-30T19:16:31.381350Z","sequence":180757092,"order_id":"79b4a026-6fbc-4579-b4ca-a2af8bc568c4","order_type":"limit","size":"0.0547","price":"9147.22","client_oid":""}
{"type":"open","side":"sell","product_id":"BTC-USD","time":"2020-06-30T19:16:31.381350Z","sequence":180757093,"price":"9147.22","order_id":"79b4a026-6fbc-4579-b4ca-a2af8bc568c4","remaining_size":"0.0547"}
{"type":"heartbeat","last_trade_id":0,"product_id":"BTC-USD","sequence":180757093,"time":"2020-06-30T19:16:31.735124Z"}
{"type":"received","side":"buy","product_id":"BTC-USD","time":"2020-06-30T19:16:32.136075Z","sequence":180757094,"order_id":"0453a3df-da33-4522-a933-1fc3446ce5cf","order_type":"limit","size":"0.0223","price":"9103.28","client_oid":""}
{"type":"open","side":"buy","product_id":"BTC-USD","time":"2020-06-30T19:16:32.136075Z","sequence":180757095,"price":"9103.28","order_id":"0453a3df-da33-4522-a933-1fc3446ce5cf","remaining_size":"0.0223"}
{"type":"done","side":"buy","product_id":"BTC-USD","time":"2020-06-30T19:16:32.542292Z","sequence":180757096,"order_id":"a411e61c-7054-41ee-9a94-45e8bede49e4","reason":"canceled","price":"9087.97","remaining_size":"0.0283"}
{"type":"done","side":"buy","product_id":"BTC-USD","time":"2020-06-30T19:16:32.545265Z","sequence":180757097,"order_id":"6e66fc74-2f28-48f0-9e29-81fc24181f8e","reason":"canceled","price":"9111.57","remaining_size":"4.0655"}
{"type":"heartbeat","last_trade_id":0,"product_id":"BTC-USD","sequence":180757097,"time":"2020-06-30T19:16:32.735120Z"}
{"type":"received","side":"buy","product_id":"BTC-USD","time":"2020-06-30T19:16:32.974839Z","sequence":180757098,"order_id":"b11b2381-ae7d-490a-8ddc-287c902ade55","order_type":"limit","size":"0.0736","price":"9077.38","client_oid":""}
{"type":"open","side":"buy","product_id":"BTC-USD","time":"2020-06-30T19:16:32.974839Z","sequence":180757099,"price":"9077.38","order_id":"b11b2381-ae7d-490a-8ddc-287c902ade55","remaining_size":"0.0736"}
{"type":"received","side":"sell","product_id":"BTC-USD","time":"2020-06-30T19:16:33.246197Z","sequence":180757100,"order_id":"1e850391-3c61-486f-b788-08a98edb39a4","order_type":"limit","size":"0.0201","price":"9136.31","client_oid":""}
{"type":"open","side":"sell","product_id":"BTC-USD","time":"2020-06-30T19:16:33.246197Z","sequence":180757101,"price":"9136.31","order_id":"1e850391-3c61-486f-b788-08a98edb39a4","remaining_size":"0.0201"}
{"type":"done","side":"buy","product_id":"BTC-USD","time":"2020-06-30T19:16:33.424415Z","sequence":180757102,"order_id":"6212da9a-e274-4930-ab99-35082a36ffbe","reason":"canceled","price":"9111.57","remaining_size":"8.4127"}
{"type":"received","side":"buy","product_id":"BTC-USD","time":"2020-06-30T19:16:33.521205Z","sequence":180757103,"order_id":"7d388917-a2d9-4d37-9f77-0c3e5ebcbd5f","order_type":"limit","size":"0.0105","price":"9075.27","client_oid":""}
{"type":"open","side":"buy","product_id":"BTC-USD","time":"2020-06-30T19:16:33.521205Z","sequence":180757104,"price":"9075.27","order_id":"7d388917-a2d9-4d37-9f77-0c3e5ebcbd5f","remaining_size":"0.0105"}
{"type":"heartbeat","last_trade_id":0,"product_id":"BTC-USD","sequence":180757104,"time":"2020-06-30T19:16:33.735054Z"}
{"type":"received","side":"buy","product_id":"BTC-USD","time":"2020-06-30T19:16:33.797293Z","sequence":180757105,"order_id":"6a5df3c3-7248-4872-9330-6cb6438f92ea","order_type":"limit","size":"0.0105","price":"9075.86","client_oid":""}
{"type":"open","side":"buy","product_id":"BTC-USD","time":"2020-06-30T19:16:33.797293Z","sequence":180757106,"price":"9075.86","order_id":"6a5df3c3-7248-4872-9330-6cb6438f92ea","remaining_size":"0.0105"}
{"type":"done","side":"buy","product_id":"BTC-USD","time":"2020-06-30T19:16:33.995552Z","sequence":180757107,"order_id":"b11b2381-ae7d-490a-8ddc-287c902ade55","reason":"canceled","price":"9077.38","remaining_size":"0.0736"}
{"type":"done","side":"buy","product_id":"BTC-USD","time":"2020-06-30T19:16:34.239058Z","sequence":180757108,"order_id":"45d875f5-97e5-4659-bee8-be8f3b30649b","reason":"canceled","price":"9074.54","remaining_size":"0.1518"}
{"type":"heartbeat","last_trade_id":0,"product_id":"BTC-USD","sequence":180757108,"time":"2020-06-30T19:16:34.735103Z"}
{"type":"received","side":"sell","product_id":"BTC-USD","time":"2020-06-30T19:16:34.922800Z","sequence":180757109,"order_id":"db25982d-6257-46aa-b8a8-e452983393cb","order_type":"limit","size":"0.0195","price":"9117.11","client_oid":""}
{"type":"match","side":"buy","product_id":"BTC-USD","time":"2020-06-30T19:16:34.922800Z","sequence":180757110,"trade_id":14587638,"maker_order_id":"91b59a7c-6a07-4039-9536-21daf3cb3282","taker_order_id":"db25982d-6257-46aa-b8a8-e452983393cb","size":"0.0195","price":"9120.8"}
{"type":"done","side":"sell","product_id":"BTC-USD","time":"2020-06-30T19:16:34.922800Z","sequence":180757111,"order_id":"db25982d-6257-46aa-b8a8-e452983393cb","reason":"filled","price":"9117.11","remaining_size":"0"}
{"type":"received","side":"sell","product_id":"BTC-USD","time":"2020-06-30T19:16:35.186795Z","sequence":180757112,"order_id":"1dbcbe52-b0c9-452b-beb1-54057047444c","order_type":"limit","size":"1.064","price":"9120.3","client_oid":""}
{"type":"match","side":"buy","product_id":"BTC-USD","time":"2020-06-30T19:16:35.186795Z","sequence":180757113,"trade_id":14587639,"maker_order_id":"91b59a7c-6a07-4039-9536-21daf3cb3282","taker_order_id":"1dbcbe52-b0c9-452b-beb1-54057047444c","size":"1.064","price":"9120.8"}
{"type":"done","side":"sell","product_id":"BTC-USD","time":"2020-06-30T19:16:35.186795Z","sequence":180757114,"order_id":"1dbcbe52-b0c9-452b-beb1-54057047444c","reason":"filled","price":"9120.3","remaining_size":"0"}
{"type":"heartbeat","last_trade_id":0,"product_id":"BTC-USD","sequence":180757114,"time":"2020-06-30T19:16:35.735093Z"}
{"type":"received","side":"buy","product_id":"BTC-USD","time":"2020-06-30T19:16:36.203085Z","sequence":180757115,"order_id":"a170fef1-cba5-41fb-bc98-d790294f3745","order_type":"limit","size":"0.01","price":"9083.04","client_oid":""}
{"type":"open","side":"buy","product_id":"BTC-USD","time":"2020-06-30T19:16:36.203085Z","sequence":180757116,"price":"9083.04","order_id":"a170fef1-cba5-41fb-bc98-d790294f3745","remaining_size":"0.01"}
{"type":"done","side":"buy","product_id":"BTC-USD","time":"2020-06-30T19:16:36.637176Z","sequence":180757117,"order_id":"127aae64-34cc-48aa-a665-37fb8f4f53a5","reason":"canceled","price":"9103.39","remaining_size":"0.049"}
{"type":"heartbeat","last_trade_id":0,"product_id":"BTC-USD","sequence":180757117,"time":"2020-06-30T19:16:36.735117Z"}
{"type":"received","side":"sell","product_id":"BTC-USD","time":"2020-06-30T19:16:36.767687Z","sequence":180757118,"order_id":"8d8d5ce4-181a-4ac3-adea-ae0a7ec22724","order_type":"limit","size":"0.9","price":"9117.05","client_oid":""}
{"type":"match","side":"buy","product_id":"BTC-USD","time":"2020-06-30T19:16:36.767687Z","sequence":180757119,"trade_id":14587640,"maker_order_id":"91b59a7c-6a07-4039-9536-21daf3cb3282","taker_order_id":"8d8d5ce4-181a-4ac3-adea-ae0a7ec22724","size":"0.9","price":"9120.8"}
{"type":"done","side":"sell","product_id":"BTC-USD","time":"2020-06-30T19:16:36.767687Z","sequence":180757120,"order_id":"8d8d5ce4-181a-4ac3-adea-ae0a7ec22724","reason":"filled","price":"9117.05","remaining_size":"0"}
{"type":"done","side":"sell","product_id":"BTC-USD","time":"2020-06-30T19:16:37.204166Z","sequence":180757121,"order_id":"79b4a026-6fbc-4579-b4ca-a2af8bc568c4","reason":"canceled","price":"9147.22","remaining_size":"0.0547"}
{"type":"done","side":"sell","product_id":"BTC-USD","time":"2020-06-30T19:16:37.206222Z","sequence":180757122,"order_id":"e155d094-0d6e-4454-8efe-ac1d29c3ee26","reason":"canceled","price":"9154.96","remaining_size":"0.0676"}
{"type":"done","side":"sell","product_id":"BTC-USD","time":"2020-06-30T19:16:37.210045Z","sequence":180757123,"order_id":"2a118821-ab4a-4a87-bd86-2c123e5e13a4","reason":"canceled","price":"9157.05","remaining_size":"0.069"}
{"type":"heartbeat","last_trade_id":0,"product_id":"BTC-USD","sequence":180757123,"time":"2020-06-30T19:16:37.735103Z"}
{"type":"heartbeat","last_trade_id":0,"product_id":"BTC-USD","sequence":180757123,"time":"2020-06-30T19:16:38.735101Z"}
{"type":"heartbeat","last_trade_id":0,"product_id":"BTC-USD","sequence":180757123,"time":"2020-06-30T19:16:39.735119Z"}
{"type":"received","side":"buy","product_id":"BTC-USD","time":"2020-06-30T19:16:39.890839Z","sequence":180757124,"order_id":"65132db9-e495-4b90-8577-dcb1d9152a34","order_type":"limit","size":"0.0121","price":"9116.02","client_oid":""}
{"type":"open","side":"buy","product_id":"BTC-USD","time":"2020-06-30T19:16:39.890839Z","sequence":180757125,"price":"9116.02","order_id":"65132db9-e495-4b90-8577-dcb1d9152a34","remaining_size":"0.0121"}
{"type":"received","side":"sell","product_id":"BTC-USD","time":"2020-06-30T19:16:40.159624Z","sequence":180757126,"order_id":"662c0259-dd71-4d6d-8504-dbf737ee9b82","order_type":"limit","size":"0.2084","price":"9117.77","client_oid":""}
{"type":"match","side":"buy","product_id":"BTC-USD","time":"2020-06-30T19:16:40.159624Z","sequence":180757127,"trade_id":14587641,"maker_order_id":"91b59a7c-6a07-4039-9536-21daf3cb3282","taker_order_id":"662c0259-dd71-4d6d-8504-dbf737ee9b82","size":"0.2084","price":"9120.8"}
{"type":"done","side":"sell","product_id":"BTC-USD","time":"2020-06-30T19:16:40.159624Z","sequence":180757128,"order_id":"662c0259-dd71-4d6d-8504-dbf737ee9b82","reason":"filled","price":"9117.77","remaining_size":"0"}
{"type":"done","side":"buy","product_id":"BTC-USD","time":"2020-06-30T19:16:40.335454Z","sequence":180757129,"order_id":"7d388917-a2d9-4d37-9f77-0c3e5ebcbd5f","reason":"canceled","price":"9075.27","remaining_size":"0.0105"}
{"type":"done","side":"buy","product_id":"BTC-USD","time":"2020-06-30T19:16:40.342754Z","sequence":180757130,"order_id":"a170fef1-cba5-41fb-bc98-d790294f3745","reason":"canceled","price":"9083.04","remaining_size":"0.01"}
{"type":"received","side":"sell","product_id":"BTC-USD","time":"2020-06-30T19:16:40.447613Z","sequence":180757131,"order_id":"30adfdb8-7214-43f2-a4f9-11e1585203c0","order_type":"limit","size":"0.25","price":"9117.89","client_oid":""}
{"type":"match","side":"buy","product_id":"BTC-USD","time":"2020-06-30T19:16:40.447613Z","sequence":180757132,"trade_id":14587642,"maker_order_id":"91b59a7c-6a07-4039-9536-21daf3cb3282","taker_order_id":"30adfdb8-7214-43f2-a4f9-11e1585203c0","size":"0.25","price":"9120.8"}
{"type":"done","side":"sell","product_id":"BTC-USD","time":"2020-06-30T19:16:40.447613Z","sequence":180757133,"order_id":"30adfdb8-7214-43f2-a4f9-11e1585203c0","reason":"filled","price":"9117.89","remaining_size":"0"}
{"type":"done","side":"sell","product_id":"BTC-USD","time":"2020-06-30T19:16:40.583079Z","sequence":180757134,"order_id":"df119119-0762-47b7-adce-7f98f42c9227","reason":"canceled","price":"9155.23","remaining_size":"0.069"}
{"type":"received","side":"sell","product_id":"BTC-USD","time":"2020-06-30T19:16:40.725347Z","sequence":180757135,"order_id":"7fbefa94-3793-456d-a28e-d1967c1f408e","order_type":"limit","size":"3.3494","price":"9145.23","client_oid":""}
{"type":"open","side":"sell","product_id":"BTC-USD","time":"2020-06-30T19:16:40.725347Z","sequence":180757136,"price":"9145.23","order_id":"7fbefa94-3793-456d-a28e-d1967c1f408e","remaining_size":"3.3494"}
{"type":"heartbeat","last_trade_id":0,"product_id":"BTC-USD","sequence":180757136,"time":"2020-06-30T19:16:40.735070Z"}
{"type":"done","side":"sell","product_id":"BTC-USD","time":"2020-06-30T19:16:40.910588Z","sequence":180757137,"order_id":"8a96ba31-25e2-4eaa-b816-1ba104630810","reason":"canceled","price":"9157.17","remaining_size":"0.0149"}
{"type":"received","side":"buy","product_id":"BTC-USD","time":"2020-06-30T19:16:41.259464Z","sequence":180757138,"order_id":"0a37792f-effc-4781-bca1-1f7c0adbed47","order_type":"market","size":"0.001","funds":"9.12082","client_oid":""}
{"type":"match","side":"sell","product_id":"BTC-USD","time":"2020-06-30T19:16:41.259464Z","sequence":180757139,"trade_id":14587643,"maker_order_id":"36fe0734-4801-466d-b093-cccd411db09a","taker_order_id":"0a37792f-effc-4781-bca1-1f7c0adbed47","size":"0.001","price":"9120.82"}
{"type":"done","side":"buy","product_id":"BTC-USD","time":"2020-06-30T19:16:41.259464Z","sequence":180757140,"order_id":"0a37792f-effc-4781-bca1-1f7c0adbed47","reason":"filled","remaining_size":"0"}
{"type":"received","side":"buy","product_id":"BTC-USD","time":"2020-06-30T19:16:41.266088Z","sequence":180757141,"order_id":"8ac47fa7-4e45-462c-9407-de161cf4daaf","order_type":"limit","size":"0.1663","price":"9116.25","client_oid":""}
{"type":"open","side":"buy","product_id":"BTC-USD","time":"2020-06-30T19:16:41.266088Z","sequence":180757142,"price":"9116.25","order_id":"8ac47fa7-4e45-462c-9407-de161cf4daaf","remaining_size":"0.1663"}
{"type":"received","side":"buy","product_id":"BTC-USD","time":"2020-06-30T19:16:41.527215Z","sequence":180757143,"order_id":"47314ecb-f8e5-4ae1-94c2-b51f615847c6","order_type":"limit","size":"0.0105","price":"9072.78","client_oid":""}
{"type":"open","side":"buy","product_id":"BTC-USD","time":"2020-06-30T19:16:41.527215Z","sequence":180757144,"price":"9072.78","order_id":"47314ecb-f8e5-4ae1-94c2-b51f615847c6","remaining_size":"0.0105"}
{"type":"done","side":"buy","product_id":"BTC-USD","time":"2020-06-30T19:16:41.692984Z","sequence":180757145,"order_id":"65132db9-e495-4b90-8577-dcb1d9152a34","reason":"canceled","price":"9116.02","remaining_size":"0.0121"}
{"type":"done","side":"buy","product_id":"BTC-USD","time":"2020-06-30T19:16:41.708580Z","sequence":180757146,"order_id":"053a9e09-b148-47a2-9428-faeed98da26a","reason":"canceled","price":"9091.83","remaining_size":"0.0156"}
{"type":"done","side":"buy","product_id":"BTC-USD","time":"2020-06-30T19:16:41.710363Z","sequence":180757147,"order_id":"ce55a13b-4569-4b88-953f-288314f5821b","reason":"canceled","price":"9111.57","remaining_size":"4.279"}
{"type":"done","side":"buy","product_id":"BTC-USD","time":"2020-06-30T19:16:41.711187Z","sequence":180757148,"order_id":"bcaf2a1b-2b26-45bb-9c94-66ef70d18240","reason":"canceled","price":"9103.31","remaining_size":"0.049"}
{"type":"heartbeat","last_trade_id":0,"product_id":"BTC-USD","sequence":180757148,"time":"2020-06-30T19:16:41.735099Z"}
{"type":"heartbeat","last_trade_id":0,"product_id":"BTC-USD","sequence":180757148,"time":"2020-06-30T19:16:42.735063Z"}
{"type":"received","side":"sell","product_id":"BTC-USD","time":"2020-06-30T19:16:42.938240Z","sequence":180757149,"order_id":"700fc70d-fa5f-4052-955a-4cb0020a6bed","order_type":"limit","size":"0.0658","price":"9118.48","client_oid":""}
{"type":"match","side":"buy","product_id":"BTC-USD","time":"2020-06-30T19:16:42.938240Z","sequence":180757150,"trade_id":14587644,"maker_order_id":"91b59a7c-6a07-4039-9536-21daf3cb3282","taker_order_id":"700fc70d-fa5f-4052-955a-4cb0020a6bed","size":"0.0658","price":"9120.8"}
{"type":"done","side":"sell","product_id":"BTC-USD","time":"2020-06-30T19:16:42.938240Z","sequence":180757151,"order_id":"700fc70d-fa5f-4052-955a-4cb0020a6bed","reason":"filled","price":"9118.48","remaining_size":"0"}
{"type":"received","side":"sell","product_id":"BTC-USD","time":"2020-06-30T19:16:43.472892Z","sequence":180757152,"order_id":"efc89e3a-9e99-4bab-adcf-735bb31d5b1c","order_type":"limit","size":"0.0837","price":"9117.87","client_oid":""}
{"type":"match","side":"buy","product_id":"BTC-USD","time":"2020-06-30T19:16:43.472892Z","sequence":180757153,"trade_id":14587645,"maker_order_id":"91b59a7c-6a07-4039-9536-21daf3cb3282","taker_order_id":"efc89e3a-9e99-4bab-adcf-735bb31d5b1c","size":"0.0837","price":"9120.8"}
{"type":"done","side":"sell","product_id":"BTC-USD","time":"2020-06-30T19:16:43.472892Z","sequence":180757154,"order_id":"efc89e3a-9e99-4bab-adcf-735bb31d5b1c","reason":"filled","price":"9117.87","remaining_size":"0"}
{"type":"heartbeat","last_trade_id":0,"product_id":"BTC-USD","sequence":180757154,"time":"2020-06-30T19:16:43.735119Z"}
{"type":"received","side":"sell","product_id":"BTC-USD","time":"2020-06-30T19:16:43.746327Z","sequence":180757155,"order_id":"6c416381-da72-492a-827b-76bb0ade11cf","order_type":"limit","size":"0.05","price":"9118.51","client_oid":""}
{"type":"match","side":"buy","product_id":"BTC-USD","time":"2020-06-30T19:16:43.746327Z","sequence":180757156,"trade_id":14587646,"maker_order_id":"91b59a7c-6a07-4039-9536-21daf3cb3282","taker_order_id":"6c416381-da72-492a-827b-76bb0ade11cf","size":"0.05","price":"9120.8"}
{"type":"done","side":"sell","product_id":"BTC-USD","time":"2020-06-30T19:16:43.746327Z","sequence":180757157,"order_id":"6c416381-da72-492a-827b-76bb0ade11cf","reason":"filled","price":"9118.51","remaining_size":"0"}
{"type":"done","side":"sell","product_id":"BTC-USD","time":"2020-06-30T19:16:43.963057Z","sequence":180757158,"order_id":"1e850391-3c61-486f-b788-08a98edb39a4","reason":"canceled","price":"9136.31","remaining_size":"0.0201"}
{"type":"received","side":"sell","product_id":"BTC-USD","time":"2020-06-30T19:16:44.017663Z","sequence":180757159,"order_id":"1407bc60-83c0-4f26-be2e-c0f64eee8393","order_type":"limit","size":"0.069","price":"9154.29","client_oid":""}
{"type":"open","side":"sell","product_id":"BTC-USD","time":"2020-06-30T19:16:44.017663Z","sequence":180757160,"price":"9154.29","order_id":"1407bc60-83c0-4f26-be2e-c0f64eee8393","remaining_size":"0.069"}
{"type":"received","side":"buy","product_id":"BTC-USD","time":"2020-06-30T19:16:44.048963Z","sequence":180757161,"order_id":"13f5fbb3-00be-45d1-9f56-5941bd064162","order_type":"limit","size":"0.01","price":"100","client_oid":"cae9071a-bbe1-4515-98e9-42bcb66c9663"}
{"type":"open","side":"buy","product_id":"BTC-USD","time":"2020-06-30T19:16:44.048963Z","sequence":180757162,"price":"100","order_id":"13f5fbb3-00be-45d1-9f56-5941bd064162","remaining_size":"0.01"}
{"type":"done","side":"buy","product_id":"BTC-USD","time":"2020-06-30T19:16:44.056056Z","sequence":180757163,"order_id":"13f5fbb3-00be-45d1-9f56-5941bd064162","reason":"canceled","price":"100","remaining_size":"0.01"}
{"type":"received","side":"sell","product_id":"BTC-USD","time":"2020-06-30T19:16:44.305987Z","sequence":180757164,"order_id":"68663011-f312-4cce-aab4-6112eaadbb0f","order_type":"limit","size":"0.0739","price":"9118.29","client_oid":""}
{"type":"match","side":"buy","product_id":"BTC-USD","time":"2020-06-30T19:16:44.305987Z","sequence":180757165,"trade_id":14587647,"maker_order_id":"91b59a7c-6a07-4039-9536-21daf3cb3282","taker_order_id":"68663011-f312-4cce-aab4-6112eaadbb0f","size":"0.0739","price":"9120.8"}
{"type":"done","side":"sell","product_id":"BTC-USD","time":"2020-06-30T19:16:44.305987Z","sequence":180757166,"order_id":"68663011-f312-4cce-aab4-6112eaadbb0f","reason":"filled","price":"9118.29","remaining_size":"0"}
{"type":"heartbeat","last_trade_id":0,"product_id":"BTC-USD","sequence":180757166,"time":"2020-06-30T19:16:44.735112Z"}
{"type":"received","side":"sell","product_id":"BTC-USD","time":"2020-06-30T19:16:45.381217Z","sequence":180757167,"order_id":"0e277545-eea7-4c77-9656-afaa6e606921","order_type":"limit","size":"0.0739","price":"9118.49","client_oid":""}
{"type":"match","side":"buy","product_id":"BTC-USD","time":"2020-06-30T19:16:45.381217Z","sequence":180757168,"trade_id":14587648,"maker_order_id":"91b59a7c-6a07-4039-9536-21daf3cb3282","taker_order_id":"0e277545-eea7-4c77-9656-afaa6e606921","size":"0.0739","price":"9120.8"}
{"type":"done","side":"sell","product_id":"BTC-USD","time":"2020-06-30T19:16:45.381217Z","sequence":180757169,"order_id":"0e277545-eea7-4c77-9656-afaa6e606921","reason":"filled","price":"9118.49","remaining_size":"0"}
{"type":"heartbeat","last_trade_id":0,"product_id":"BTC-USD","sequence":180757169,"time":"2020-06-30T19:16:45.735121Z"}
{"type":"received","side":"buy","product_id":"BTC-USD","time":"2020-06-30T19:16:45.947652Z","sequence":180757170,"order_id":"e3f049d5-f893-4d85-ad41-3985a206d688","order_type":"limit","size":"0.0052","price":"9116.94","client_oid":""}
{"type":"open","side":"buy","product_id":"BTC-USD","time":"2020-06-30T19:16:45.947652Z","sequence":180757171,"price":"9116.94","order_id":"e3f049d5-f893-4d85-ad41-3985a206d688","remaining_size":"0.0052"}
{"type":"heartbeat","last_trade_id":0,"product_id":"BTC-USD","sequence":180757171,"time":"2020-06-30T19:16:46.735108Z"}
{"type":"received","side":"sell","product_id":"BTC-USD","time":"2020-06-30T19:16:47.314815Z","sequence":180757172,"order_id":"12caa02d-0454-4dcf-8aac-c13daf0681ec","order_type":"limit","size":"0.2916","price":"9118.86","client_oid":""}
{"type":"match","side":"buy","product_id":"BTC-USD","time":"2020-06-30T19:16:47.314815Z","sequence":180757173,"trade_id":14587649,"maker_order_id":"91b59a7c-6a07-4039-9536-21daf3cb3282","taker_order_id":"12caa02d-0454-4dcf-8aac-c13daf0681ec","size":"0.2916","price":"9120.8"}
{"type":"done","side":"sell","product_id":"BTC-USD","time":"2020-06-30T19:16:47.314815Z","sequence":180757174,"order_id":"12caa02d-0454-4dcf-8aac-c13daf0681ec","reason":"filled","price":"9118.86","remaining_size":"0"}
{"type":"heartbeat","last_trade_id":0,"product_id":"BTC-USD","sequence":180757174,"time":"2020-06-30T19:16:47.735114Z"}
{"type":"received","side":"sell","product_id":"BTC-USD","time":"2020-06-30T19:16:47.903045Z","sequence":180757175,"order_id":"543435b8-3ce4-43f7-9129-ca7a5980f0ac","order_type":"limit","size":"0.01","price":"9143.11","client_oid":""}
{"type":"open","side":"sell","product_id":"BTC-USD","time":"2020-06-30T19:16:47.903045Z","sequence":180757176,"price":"9143.11","order_id":"543435b8-3ce4-43f7-9129-ca7a5980f0ac","remaining_size":"0.01"}
{"type":"done","side":"sell","product_id":"BTC-USD","time":"2020-06-30T19:16:48.330477Z","sequence":180757177,"order_id":"35c0683f-20a9-4aad-b8b0-2ff77c773df6","reason":"canceled","price":"9121.08","remaining_size":"0.0236"}
{"type":"heartbeat","last_trade_id":0,"product_id":"BTC-USD","sequence":180757177,"time":"2020-06-30T19:16:48.735112Z"}
{"type":"received","side":"buy","product_id":"BTC-USD","time":"2020-06-30T19:16:49.246565Z","sequence":180757178,"order_id":"d5dcbcb3-727b-4424-9a98-393e4b1f2790","order_type":"limit","size":"0.0223","price":"9108.81","client_oid":""}
{"type":"open","side":"buy","product_id":"BTC-USD","time":"2020-06-30T19:16:49.246565Z","sequence":180757179,"price":"9108.81","order_id":"d5dcbcb3-727b-4424-9a98-393e4b1f2790","remaining_size":"0.0223"}
{"type":"heartbeat","last_trade_id":0,"product_id":"BTC-USD","sequence":180757179,"time":"2020-06-30T19:16:49.735113Z"}
{"type":"received","side":"sell","product_id":"BTC-USD","time":"2020-06-30T19:16:49.822114Z","sequence":180757180,"order_id":"c7757681-f055-4ddc-bedf-e749fe6cef25","order_type":"limit","size":"0.0195","price":"9117.66","client_oid":""}
{"type":"match","side":"buy","product_id":"BTC-USD","time":"2020-06-30T19:16:49.822114Z","sequence":180757181,"trade_id":14587650,"maker_order_id":"91b59a7c-6a07-4039-9536-21daf3cb3282","taker_order_id":"c7757681-f055-4ddc-bedf-e749fe6cef25","size":"0.0195","price":"9120.8"}
{"type":"done","side":"sell","product_id":"BTC-USD","time":"2020-06-30T19:16:49.822114Z","sequence":180757182,"order_id":"c7757681-f055-4ddc-bedf-e749fe6cef25","reason":"filled","price":"9117.66","remaining_size":"0"}
{"type":"received","side":"buy","product_id":"BTC-USD","time":"2020-06-30T19:16:50.103641Z","sequence":180757183,"order_id":"39ca3b16-9bf9-4666-8a50-180b3d416ab8","order_type":"limit","size":"0.0399","price":"9118.15","client_oid":""}
{"type":"open","side":"buy","product_id":"BTC-USD","time":"2020-06-30T19:16:50.103641Z","sequence":180757184,"price":"9118.15","order_id":"39ca3b16-9bf9-4666-8a50-180b3d416ab8","remaining_size":"0.0399"}
{"type":"done","side":"sell","product_id":"BTC-USD","time":"2020-06-30T19:16:50.260402Z","sequence":180757185,"order_id":"1407bc60-83c0-4f26-be2e-c0f64eee8393","reason":"canceled","price":"9154.29","remaining_size":"0.069"}
{"type":"done","side":"buy","product_id":"BTC-USD","time":"2020-06-30T19:16:50.304284Z","sequence":180757186,"order_id":"d5dcbcb3-727b-4424-9a98-393e4b1f2790","reason":"canceled","price":"9108.81","remaining_size":"0.0223"}
{"type":"done","side":"buy","product_id":"BTC-USD","time":"2020-06-30T19:16:50.312287Z","sequence":180757187,"order_id":"0b3942c2-a910-4152-acea-006bba825744","reason":"canceled","price":"9075.35","remaining_size":"0.0105"}
{"type":"done","side":"buy","product_id":"BTC-USD","time":"2020-06-30T19:16:50.324898Z","sequence":180757188,"order_id":"e3f049d5-f893-4d85-ad41-3985a206d688","reason":"canceled","price":"9116.94","remaining_size":"0.0052"}
{"type":"received","side":"buy","product_id":"BTC-USD","time":"2020-06-30T19:16:50.646464Z","sequence":180757189,"order_id":"9f2c9206-9a66-46f5-bdaf-43b08913f517","order_type":"limit","size":"0.0543","price":"9118.15","client_oid":""}
{"type":"open","side":"buy","product_id":"BTC-USD","time":"2020-06-30T19:16:50.646464Z","sequence":180757190,"price":"9118.15","order_id":"9f2c9206-9a66-46f5-bdaf-43b08913f517","remaining_size":"0.0543"}
{"type":"heartbeat","last_trade_id":0,"product_id":"BTC-USD","sequence":180757190,"time":"2020-06-30T19:16:50.735126Z"}
{"type":"done","side":"buy","product_id":"BTC-USD","time":"2020-06-30T19:16:51.066276Z","sequence":180757191,"order_id":"0453a3df-da33-4522-a933-1fc3446ce5cf","reason":"canceled","price":"9103.28","remaining_size":"0.0223"}
{"type":"done","side":"buy","product_id":"BTC-USD","time":"2020-06-30T19:16:51.074872Z","sequence":180757192,"order_id":"8ac47fa7-4e45-462c-9407-de161cf4daaf","reason":"canceled","price":"9116.25","remaining_size":"0.1663"}
{"type":"heartbeat","last_trade_id":0,"product_id":"BTC-USD","sequence":180757192,"time":"2020-06-30T19:16:51.735120Z"}
{"type":"received","side":"sell","product_id":"BTC-USD","time":"2020-06-30T19:16:51.785494Z","sequence":180757193,"order_id":"663c6e3c-d920-43d7-83bd-c4136af10925","order_type":"limit","size":"0.05","price":"9118.84","client_oid":""}
{"type":"match","side":"buy","product_id":"BTC-USD","time":"2020-06-30T19:16:51.785494Z","sequence":180757194,"trade_id":14587651,"maker_order_id":"91b59a7c-6a07-4039-9536-21daf3cb3282","taker_order_id":"663c6e3c-d920-43d7-83bd-c4136af10925","size":"0.05","price":"9120.8"}
{"type":"done","side":"sell","product_id":"BTC-USD","time":"2020-06-30T19:16:51.785494Z","sequence":180757195,"order_id":"663c6e3c-d920-43d7-83bd-c4136af10925","reason":"filled","price":"9118.84","remaining_size":"0"}
{"type":"received","side":"sell","product_id":"BTC-USD","time":"2020-06-30T19:16:52.347760Z","sequence":180757196,"order_id":"2e1f8423-82e6-4979-a8ee-9b592fede3eb","order_type":"limit","size":"0.0658","price":"9118.66","client_oid":""}
{"type":"match","side":"buy","product_id":"BTC-USD","time":"2020-06-30T19:16:52.347760Z","sequence":180757197,"trade_id":14587652,"maker_order_id":"91b59a7c-6a07-4039-9536-21daf3cb3282","taker_order_id":"2e1f8423-82e6-4979-a8ee-9b592fede3eb","size":"0.0658","price":"9120.8"}
{"type":"done","side":"sell","product_id":"BTC-USD","time":"2020-06-30T19:16:52.347760Z","sequence":180757198,"order_id":"2e1f8423-82e6-4979-a8ee-9b592fede3eb","reason":"filled","price":"9118.66","remaining_size":"0"}
{"type":"received","side":"sell","product_id":"BTC-USD","time":"2020-06-30T19:16:52.530634Z","sequence":180757199,"order_id":"2978b578-7d8b-429b-aa7b-4e834294baa7","order_type":"limit","size":"0.0399","price":"9118.24","client_oid":""}
{"type":"match","side":"buy","product_id":"BTC-USD","time":"2020-06-30T19:16:52.530634Z","sequence":180757200,"trade_id":14587653,"maker_order_id":"91b59a7c-6a07-4039-9536-21daf3cb3282","taker_order_id":"2978b578-7d8b-429b-aa7b-4e834294baa7","size":"0.0399","price":"9120.8"}
{"type":"done","side":"sell","product_id":"BTC-USD","time":"2020-06-30T19:16:52.530634Z","sequence":180757201,"order_id":"2978b578-7d8b-429b-aa7b-4e834294baa7","reason":"filled","price":"9118.24","remaining_size":"0"}
{"type":"received","side":"sell","product_id":"BTC-USD","time":"2020-06-30T19:16:52.620615Z","sequence":180757202,"order_id":"43fc89f3-1931-4106-87d5-3c445c13106a","order_type":"limit","size":"0.0278","price":"9154.56","client_oid":""}
{"type":"open","side":"sell","product_id":"BTC-USD","time":"2020-06-30T19:16:52.620615Z","sequence":180757203,"price":"9154.56","order_id":"43fc89f3-1931-4106-87d5-3c445c13106a","remaining_size":"0.0278"}
{"type":"heartbeat","last_trade_id":0,"product_id":"BTC-USD","sequence":180757203,"time":"2020-06-30T19:16:52.735112Z"}
{"type":"received","side":"buy","product_id":"BTC-USD","time":"2020-06-30T19:16:52.894675Z","sequence":180757204,"order_id":"a9894b38-c015-4716-84bd-fe437a1b1a25","order_type":"limit","size":"0.01","price":"9082.56","client_oid":""}
{"type":"open","side":"buy","product_id":"BTC-USD","time":"2020-06-30T19:16:52.894675Z","sequence":180757205,"price":"9082.56","order_id":"a9894b38-c015-4716-84bd-fe437a1b1a25","remaining_size":"0.01"}
{"type":"done","side":"buy","product_id":"BTC-USD","time":"2020-06-30T19:16:53.329855Z","sequence":180757206,"order_id":"47314ecb-f8e5-4ae1-94c2-b51f615847c6","reason":"canceled","price":"9072.78","remaining_size":"0.0105"}
{"type":"heartbeat","last_trade_id":0,"product_id":"BTC-USD","sequence":180757206,"time":"2020-06-30T19:16:53.735090Z"}
{"type":"received","side":"sell","product_id":"BTC-USD","time":"2020-06-30T19:16:54.038650Z","sequence":180757207,"order_id":"84c0ff57-687a-404c-8d42-99afb8607988","order_type":"limit","size":"0.0278","price":"9154.83","client_oid":""}
{"type":"open","side":"sell","product_id":"BTC-USD","time":"2020-06-30T19:16:54.038650Z","sequence":180757208,"price":"9154.83","order_id":"84c0ff57-687a-404c-8d42-99afb8607988","remaining_size":"0.0278"}
{"type":"heartbeat","last_trade_id":0,"product_id":"BTC-USD","sequence":180757208,"time":"2020-06-30T19:16:54.735094Z"}
{"type":"received","side":"sell","product_id":"BTC-USD","time":"2020-06-30T19:16:54.865140Z","sequence":180757209,"order_id":"6b50883f-6783-49ca-bcb2-5f8409989556","order_type":"limit","size":"0.0531","price":"9118.55","client_oid":""}
{"type":"match","side":"buy","product_id":"BTC-USD","time":"2020-06-30T19:16:54.865140Z","sequence":180757210,"trade_id":14587654,"maker_order_id":"91b59a7c-6a07-4039-9536-21daf3cb3282","taker_order_id":"6b50883f-6783-49ca-bcb2-5f8409989556","size":"0.0531","price":"9120.8"}
{"type":"done","side":"sell","product_id":"BTC-USD","time":"2020-06-30T19:16:54.865140Z","sequence":180757211,"order_id":"6b50883f-6783-49ca-bcb2-5f8409989556","reason":"filled","price":"9118.55","remaining_size":"0"}
{"type":"received","side":"buy","product_id":"BTC-USD","time":"2020-06-30T19:16:55.143150Z","sequence":180757212,"order_id":"a1e82340-b929-49a3-a5b6-10d92a1af974","order_type":"limit","size":"0.0719","price":"9117.1","client_oid":""}
{"type":"open","side":"buy","product_id":"BTC-USD","time":"2020-06-30T19:16:55.143150Z","sequence":180757213,"price":"9117.1","order_id":"a1e82340-b929-49a3-a5b6-10d92a1af974","remaining_size":"0.0719"}
{"type":"heartbeat","last_trade_id":0,"product_id":"BTC-USD","sequence":180757213,"time":"2020-06-30T19:16:55.735116Z"}
{"type":"received","side":"buy","product_id":"BTC-USD","time":"2020-06-30T19:16:56.252368Z","sequence":180757214,"order_id":"83797f8e-bcf1-4d13-8b17-b1c8fe424681","order_type":"limit","size":"0.1229","price":"9118.13","client_oid":""}
{"type":"open","side":"buy","product_id":"BTC-USD","time":"2020-06-30T19:16:56.252368Z","sequence":180757215,"price":"9118.13","order_id":"83797f8e-bcf1-4d13-8b17-b1c8fe424681","remaining_size":"0.1229"}
{"type":"received","side":"sell","product_id":"BTC-USD","time":"2020-06-30T19:16:56.532034Z","sequence":180757216,"order_id":"94c9febc-5835-4932-b98f-0797c55afe21","order_type":"limit","size":"0.0329","price":"9155.37","client_oid":""}
{"type":"open","side":"sell","product_id":"BTC-USD","time":"2020-06-30T19:16:56.532034Z","sequence":180757217,"price":"9155.37","order_id":"94c9febc-5835-4932-b98f-0797c55afe21","remaining_size":"0.0329"}
{"type":"done","side":"buy","product_id":"BTC-USD","time":"2020-06-30T19:16:56.661693Z","sequence":180757218,"order_id":"6a5df3c3-7248-4872-9330-6cb6438f92ea","reason":"canceled","price":"9075.86","remaining_size":"0.0105"}
{"type":"heartbeat","last_trade_id":0,"product_id":"BTC-USD","sequence":180757218,"time":"2020-06-30T19:16:56.735116Z"}
{"type":"received","side":"buy","product_id":"BTC-USD","time":"2020-06-30T19:16:57.073889Z","sequence":180757219,"order_id":"ab741a32-38b3-434a-b52f-0605a1950a10","order_type":"limit","size":"0.14","price":"9117.66","client_oid":""}
{"type":"open","side":"buy","product_id":"BTC-USD","time":"2020-06-30T19:16:57.073889Z","sequence":180757220,"price":"9117.66","order_id":"ab741a32-38b3-434a-b52f-0605a1950a10","remaining_size":"0.14"}
{"type":"received","side":"sell","product_id":"BTC-USD","time":"2020-06-30T19:16:57.631299Z","sequence":180757221,"order_id":"af0ffeb8-7648-4bc6-9bc3-a16c5ddd71a1","order_type":"limit","size":"1.64","price":"9119.49","client_oid":""}
{"type":"match","side":"buy","product_id":"BTC-USD","time":"2020-06-30T19:16:57.631299Z","sequence":180757222,"trade_id":14587655,"maker_order_id":"91b59a7c-6a07-4039-9536-21daf3cb3282","taker_order_id":"af0ffeb8-7648-4bc6-9bc3-a16c5ddd71a1","size":"1.64","price":"9120.8"}
{"type":"done","side":"sell","product_id":"BTC-USD","time":"2020-06-30T19:16:57.631299Z","sequence":180757223,"order_id":"af0ffeb8-7648-4bc6-9bc3-a16c5ddd71a1","reason":"filled","price":"9119.49","remaining_size":"0"}
{"type":"heartbeat","last_trade_id":0,"product_id":"BTC-USD","sequence":180757223,"time":"2020-06-30T19:16:57.735113Z"}
{"type":"done","side":"sell","product_id":"BTC-USD","time":"2020-06-30T19:16:58.323065Z","sequence":180757224,"order_id":"54e93c0d-bc50-4a79-bb2d-fd7977405113","reason":"canceled","price":"9148.74","remaining_size":"0.0547"}
{"type":"received","side":"buy","product_id":"BTC-USD","time":"2020-06-30T19:16:58.722799Z","sequence":180757225,"order_id":"760e192c-1ee9-4c44-87cc-b815b3ca3258","order_type":"limit","size":"15.521","price":"9113.79","client_oid":""}
{"type":"open","side":"buy","product_id":"BTC-USD","time":"2020-06-30T19:16:58.722799Z","sequence":180757226,"price":"9113.79","order_id":"760e192c-1ee9-4c44-87cc-b815b3ca3258","remaining_size":"15.521"}
{"type":"heartbeat","last_trade_id":0,"product_id":"BTC-USD","sequence":180757226,"time":"2020-06-30T19:16:58.735117Z"}
{"type":"done","side":"buy","product_id":"BTC-USD","time":"2020-06-30T19:16:58.894153Z","sequence":180757227,"order_id":"f31cafca-1fc5-4e0c-8183-39da259fe562","reason":"canceled","price":"8891.62","remaining_size":"0.04673688"}
{"type":"received","side":"buy","product_id":"BTC-USD","time":"2020-06-30T19:16:59.118872Z","sequence":180757228,"order_id":"9fda4b85-26ee-4f15-97f1-415e2bf38aee","order_type":"limit","size":"0.01","price":"100","client_oid":"bf152e55-2d5c-46ce-99d3-84448c6f3b85"}
{"type":"open","side":"buy","product_id":"BTC-USD","time":"2020-06-30T19:16:59.118872Z","sequence":180757229,"price":"100","order_id":"9fda4b85-26ee-4f15-97f1-415e2bf38aee","remaining_size":"0.01"}
{"type":"done","side":"buy","product_id":"BTC-USD","time":"2020-06-30T19:16:59.125112Z","sequence":180757230,"order_id":"9fda4b85-26ee-4f15-97f1-415e2bf38aee","reason":"canceled","price":"100","remaining_size":"0.01"}
{"type":"received","side":"sell","product_id":"BTC-USD","time":"2020-06-30T19:16:59.274989Z","sequence":180757231,"order_id":"816f25d3-e270-4578-aed1-bbd85baf6243","order_type":"limit","size":"0.035","price":"9121.93","client_oid":""}
{"type":"open","side":"sell","product_id":"BTC-USD","time":"2020-06-30T19:16:59.274989Z","sequence":180757232,"price":"9121.93","order_id":"816f25d3-e270-4578-aed1-bbd85baf6243","remaining_size":"0.035"}
{"type":"received","side":"buy","product_id":"BTC-USD","time":"2020-06-30T19:16:59.415327Z","sequence":180757233,"order_id":"d4fe4324-78ae-4550-9509-defa9edc8c99","order_type":"limit","size":"0.04683127","price":"8890.86","client_oid":""}
{"type":"open","side":"buy","product_id":"BTC-USD","time":"2020-06-30T19:16:59.415327Z","sequence":180757234,"price":"8890.86","order_id":"d4fe4324-78ae-4550-9509-defa9edc8c99","remaining_size":"0.04683127"}
{"type":"received","side":"sell","product_id":"BTC-USD","time":"2020-06-30T19:16:59.551878Z","sequence":180757235,"order_id":"ca00a969-bd94-48a9-8ac5-a310a3e686b3","order_type":"limit","size":"0.4074","price":"9119.38","client_oid":""}
{"type":"match","side":"buy","product_id":"BTC-USD","time":"2020-06-30T19:16:59.551878Z","sequence":180757236,"trade_id":14587656,"maker_order_id":"91b59a7c-6a07-4039-9536-21daf3cb3282","taker_order_id":"ca00a969-bd94-48a9-8ac5-a310a3e686b3","size":"0.4074","price":"9120.8"}
{"type":"done","side":"sell","product_id":"BTC-USD","time":"2020-06-30T19:16:59.551878Z","sequence":180757237,"order_id":"ca00a969-bd94-48a9-8ac5-a310a3e686b3","reason":"filled","price":"9119.38","remaining_size":"0"}
{"type":"heartbeat","last_trade_id":0,"product_id":"BTC-USD","sequence":180757237,"time":"2020-06-30T19:16:59.735113Z"}
{"type":"received","side":"buy","product_id":"BTC-USD","time":"2020-06-30T19:16:59.833555Z","sequence":180757238,"order_id":"3cc4e66a-66cd-4335-83ec-26059b3826e1","order_type":"limit","size":"0.5","price":"9118.37","client_oid":""}
{"type":"open","side":"buy","product_id":"BTC-USD","time":"2020-06-30T19:16:59.833555Z","sequence":180757239,"price":"9118.37","order_id":"3cc4e66a-66cd-4335-83ec-26059b3826e1","remaining_size":"0.5"}
{"type":"done","side":"sell","product_id":"BTC-USD","time":"2020-06-30T19:16:59.958020Z","sequence":180757240,"order_id":"a943a649-066b-465c-9624-c1008e7d9f8c","reason":"canceled","price":"9439.48","remaining_size":"0.00747675"}
{"type":"done","side":"sell","product_id":"BTC-USD","time":"2020-06-30T19:16:59.990231Z","sequence":180757241,"order_id":"543435b8-3ce4-43f7-9129-ca7a5980f0ac","reason":"canceled","price":"9143.11","remaining_size":"0.01"}
{"type":"received","side":"buy","product_id":"BTC-USD","time":"2020-06-30T19:17:00.105161Z","sequence":180757242,"order_id":"56e1a966-6c0e-4371-abae-c1fc58f83ec7","order_type":"limit","size":"1.5878","price":"9114.28","client_oid":""}
{"type":"open","side":"buy","product_id":"BTC-USD","time":"2020-06-30T19:17:00.105161Z","sequence":180757243,"price":"9114.28","order_id":"56e1a966-6c0e-4371-abae-c1fc58f83ec7","remaining_size":"1.5878"}
{"type":"received","side":"sell","product_id":"BTC-USD","time":"2020-06-30T19:17:00.328472Z","sequence":180757244,"order_id":"3eff7076-9cb0-454b-9de5-e7f5ec6c306a","order_type":"limit","size":"0.00756905","price":"9440.29","client_oid":""}
{"type":"open","side":"sell","product_id":"BTC-USD","time":"2020-06-30T19:17:00.328472Z","sequence":180757245,"price":"9440.29","order_id":"3eff7076-9cb0-454b-9de5-e7f5ec6c306a","remaining_size":"0.00756905"}
{"type":"done","side":"buy","product_id":"BTC-USD","time":"2020-06-30T19:17:00.543428Z","sequence":180757246,"order_id":"83797f8e-bcf1-4d13-8b17-b1c8fe424681","reason":"canceled","price":"9118.13","remaining_size":"0.1229"}
{"type":"heartbeat","last_trade_id":0,"product_id":"BTC-USD","sequence":180757246,"time":"2020-06-30T19:17:00.735110Z"}
{"type":"received","side":"buy","product_id":"BTC-USD","time":"2020-06-30T19:17:00.746700Z","sequence":180757247,"order_id":"2966a768-1804-4f6e-9a80-3c990484579f","order_type":"limit","size":"0.0658","price":"9108.89","client_oid":""}
{"type":"open","side":"buy","product_id":"BTC-USD","time":"2020-06-30T19:17:00.746700Z","sequence":180757248,"price":"9108.89","order_id":"2966a768-1804-4f6e-9a80-3c990484579f","remaining_size":"0.0658"}
{"type":"received","side":"buy","product_id":"BTC-USD","time":"2020-06-30T19:17:00.968318Z","sequence":180757249,"order_id":"7a281102-3084-4d80-84ee-b2ee2448138d","order_type":"limit","size":"1","price":"9118.41","client_oid":""}
{"type":"open","side":"buy","product_id":"BTC-USD","time":"2020-06-30T19:17:00.968318Z","sequence":180757250,"price":"9118.41","order_id":"7a281102-3084-4d80-84ee-b2ee2448138d","remaining_size":"1"}
{"type":"done","side":"buy","product_id":"BTC-USD","time":"2020-06-30T19:17:01.184394Z","sequence":180757251,"order_id":"760e192c-1ee9-4c44-87cc-b815b3ca3258","reason":"canceled","price":"9113.79","remaining_size":"15.521"}
{"type":"done","side":"buy","product_id":"BTC-USD","time":"2020-06-30T19:17:01.184515Z","sequence":180757252,"order_id":"39ca3b16-9bf9-4666-8a50-180b3d416ab8","reason":"canceled","price":"9118.15","remaining_size":"0.0399"}
{"type":"heartbeat","last_trade_id":0,"product_id":"BTC-USD","sequence":180757252,"time":"2020-06-30T19:17:01.735125Z"}
{"type":"received","side":"sell","product_id":"BTC-USD","time":"2020-06-30T19:17:01.808301Z","sequence":180757253,"order_id":"114701a6-0f71-4776-8230-fbe5409417b8","order_type":"limit","size":"0.543","price":"9122.93","client_oid":""}
{"type":"open","side":"sell","product_id":"BTC-USD","time":"2020-06-30T19:17:01.808301Z","sequence":180757254,"price":"9122.93","order_id":"114701a6-0f71-4776-8230-fbe5409417b8","remaining_size":"0.543"}
{"type":"done","side":"buy","product_id":"BTC-USD","time":"2020-06-30T19:17:01.961646Z","sequence":180757255,"order_id":"56e1a966-6c0e-4371-abae-c1fc58f83ec7","reason":"canceled","price":"9114.28","remaining_size":"1.5878"}
{"type":"received","side":"sell","product_id":"BTC-USD","time":"2020-06-30T19:17:02.475850Z","sequence":180757256,"order_id":"85c423bc-4b92-4b70-93fb-74605b5c1f09","order_type":"limit","size":"0.541","price":"9123.11","client_oid":""}
{"type":"open","side":"sell","product_id":"BTC-USD","time":"2020-06-30T19:17:02.475850Z","sequence":180757257,"price":"9123.11","order_id":"85c423bc-4b92-4b70-93fb-74605b5c1f09","remaining_size":"0.541"}
{"type":"heartbeat","last_trade_id":0,"product_id":"BTC-USD","sequence":180757257,"time":"2020-06-30T19:17:02.735115Z"}
{"type":"done","side":"sell","product_id":"BTC-USD","time":"2020-06-30T19:17:02.927294Z","sequence":180757258,"order_id":"43fc89f3-1931-4106-87d5-3c445c13106a","reason":"canceled","price":"9154.56","remaining_size":"0.0278"}
{"type":"received","side":"buy","product_id":"BTC-USD","time":"2020-06-30T19:17:03.039936Z","sequence":180757259,"order_id":"8206509a-e0b6-4a34-b6bb-595331803cfe","order_type":"limit","size":"3.5646","price":"9119.37","client_oid":""}
{"type":"open","side":"buy","product_id":"BTC-USD","time":"2020-06-30T19:17:03.039936Z","sequence":180757260,"price":"9119.37","order_id":"8206509a-e0b6-4a34-b6bb-595331803cfe","remaining_size":"3.5646"}
{"type":"done","side":"buy","product_id":"BTC-USD","time":"2020-06-30T19:17:03.547516Z","sequence":180757261,"order_id":"9f2c9206-9a66-46f5-bdaf-43b08913f517","reason":"canceled","price":"9118.15","remaining_size":"0.0543"}
{"type":"received","side":"buy","product_id":"BTC-USD","time":"2020-06-30T19:17:03.615800Z","sequence":180757262,"order_id":"9423a7a9-c9ba-4b61-9c96-62cf490d25df","order_type":"limit","size":"0.5","price":"9117.47","client_oid":""}
{"type":"open","side":"buy","product_id":"BTC-USD","time":"2020-06-30T19:17:03.615800Z","sequence":180757263,"price":"9117.47","order_id":"9423a7a9-c9ba-4b61-9c96-62cf490d25df","remaining_size":"0.5"}
{"type":"heartbeat","last_trade_id":0,"product_id":"BTC-USD","sequence":180757263,"time":"2020-06-30T19:17:03.735113Z"}
{"type":"received","side":"sell","product_id":"BTC-USD","time":"2020-06-30T19:17:03.905557Z","sequence":180757264,"order_id":"37c65818-2fdb-4737-8c32-59eebe405528","order_type":"limit","size":"0.0658","price":"9119.26","client_oid":""}
{"type":"match","side":"buy","product_id":"BTC-USD","time":"2020-06-30T19:17:03.905557Z","sequence":180757265,"trade_id":14587657,"maker_order_id":"91b59a7c-6a07-4039-9536-21daf3cb3282","taker_order_id":"37c65818-2fdb-4737-8c32-59eebe405528","size":"0.0658","price":"9120.8"}
{"type":"done","side":"sell","product_id":"BTC-USD","time":"2020-06-30T19:17:03.905557Z","sequence":180757266,"order_id":"37c65818-2fdb-4737-8c32-59eebe405528","reason":"filled","price":"9119.26","remaining_size":"0"}
{"type":"done","side":"sell","product_id":"BTC-USD","time":"2020-06-30T19:17:04.140364Z","sequence":180757267,"order_id":"7fbefa94-3793-456d-a28e-d1967c1f408e","reason":"canceled","price":"9145.23","remaining_size":"3.3494"}
{"type":"heartbeat","last_trade_id":0,"product_id":"BTC-USD","sequence":180757267,"time":"2020-06-30T19:17:04.735107Z"}
{"type":"received","side":"buy","product_id":"BTC-USD","time":"2020-06-30T19:17:05.223633Z","sequence":180757268,"order_id":"e629f6f7-6f85-46d5-bf11-8caf5e19dabf","order_type":"limit","size":"0.0658","price":"9108.78","client_oid":""}
{"type":"open","side":"buy","product_id":"BTC-USD","time":"2020-06-30T19:17:05.223633Z","sequence":180757269,"price":"9108.78","order_id":"e629f6f7-6f85-46d5-bf11-8caf5e19dabf","remaining_size":"0.0658"}
{"type":"received","side":"sell","product_id":"BTC-USD","time":"2020-06-30T19:17:05.514292Z","sequence":180757270,"order_id":"16040849-ac2f-4e37-9e8f-b34d31a31500","order_type":"limit","size":"0.01","price":"9144.8","client_oid":""}
{"type":"open","side":"sell","product_id":"BTC-USD","time":"2020-06-30T19:17:05.514292Z","sequence":180757271,"price":"9144.8","order_id":"16040849-ac2f-4e37-9e8f-b34d31a31500","remaining_size":"0.01"}
{"type":"done","side":"buy","product_id":"BTC-USD","time":"2020-06-30T19:17:05.743964Z","sequence":180757272,"order_id":"a9894b38-c015-4716-84bd-fe437a1b1a25","reason":"canceled","price":"9082.56","remaining_size":"0.01"}
{"type":"heartbeat","last_trade_id":0,"product_id":"BTC-USD","sequence":180757272,"time":"2020-06-30T19:17:05.735048Z"}
{"type":"received","side":"buy","product_id":"BTC-USD","time":"2020-06-30T19:17:06.627736Z","sequence":180757273,"order_id":"68f51b1d-5afc-4541-8f83-f38390f63f54","order_type":"limit","size":"0.0306","price":"9108.86","client_oid":""}
{"type":"open","side":"buy","product_id":"BTC-USD","time":"2020-06-30T19:17:06.627736Z","sequence":180757274,"price":"9108.86","order_id":"68f51b1d-5afc-4541-8f83-f38390f63f54","remaining_size":"0.0306"}
{"type":"heartbeat","last_trade_id":0,"product_id":"BTC-USD","sequence":180757274,"time":"2020-06-30T19:17:06.735117Z"}
{"type":"done","side":"buy","product_id":"BTC-USD","time":"2020-06-30T19:17:07.046690Z","sequence":180757275,"order_id":"2966a768-1804-4f6e-9a80-3c990484579f","reason":"canceled","price":"9108.89","remaining_size":"0.0658"}
{"type":"received","side":"buy","product_id":"BTC-USD","time":"2020-06-30T19:17:07.199549Z","sequence":180757276,"order_id":"4b66e3df-9a94-452c-8b72-69732f8020aa","order_type":"limit","size":"0.0222","price":"9111.5","client_oid":""}
{"type":"open","side":"buy","product_id":"BTC-USD","time":"2020-06-30T19:17:07.199549Z","sequence":180757277,"price":"9111.5","order_id":"4b66e3df-9a94-452c-8b72-69732f8020aa","remaining_size":"0.0222"}
{"type":"received","side":"sell","product_id":"BTC-USD","time":"2020-06-30T19:17:07.737444Z","sequence":180757278,"order_id":"097c3111-cc52-4ee4-9358-277304bf31a5","order_type":"limit","size":"0.471","price":"9119.29","client_oid":""}
{"type":"match","side":"buy","product_id":"BTC-USD","time":"2020-06-30T19:17:07.737444Z","sequence":180757279,"trade_id":14587658,"maker_order_id":"91b59a7c-6a07-4039-9536-21daf3cb3282","taker_order_id":"097c3111-cc52-4ee4-9358-277304bf31a5","size":"0.471","price":"9120.8"}
{"type":"done","side":"sell","product_id":"BTC-USD","time":"2020-06-30T19:17:07.737444Z","sequence":180757280,"order_id":"097c3111-cc52-4ee4-9358-277304bf31a5","reason":"filled","price":"9119.29","remaining_size":"0"}
{"type":"heartbeat","last_trade_id":0,"product_id":"BTC-USD","sequence":180757280,"time":"2020-06-30T19:17:07.735116Z"}
{"type":"heartbeat","last_trade_id":0,"product_id":"BTC-USD","sequence":180757280,"time":"2020-06-30T19:17:08.735119Z"}
{"type":"received","side":"buy","product_id":"BTC-USD","time":"2020-06-30T19:17:09.131710Z","sequence":180757281,"order_id":"7f0ef5d8-52e3-49dd-9f41-45e95ce31716","order_type":"limit","size":"0.0493","price":"9115.97","client_oid":""}
{"type":"open","side":"buy","product_id":"BTC-USD","time":"2020-06-30T19:17:09.131710Z","sequence":180757282,"price":"9115.97","order_id":"7f0ef5d8-52e3-49dd-9f41-45e95ce31716","remaining_size":"0.0493"}
{"type":"received","side":"buy","product_id":"BTC-USD","time":"2020-06-30T19:17:09.402313Z","sequence":180757283,"order_id":"55466822-82d3-4de3-bd5f-5b1e024096a9","order_type":"limit","size":"0.0567","price":"9094.08","client_oid":""}
{"type":"open","side":"buy","product_id":"BTC-USD","time":"2020-06-30T19:17:09.402313Z","sequence":180757284,"price":"9094.08","order_id":"55466822-82d3-4de3-bd5f-5b1e024096a9","remaining_size":"0.0567"}
{"type":"done","side":"buy","product_id":"BTC-USD","time":"2020-06-30T19:17:09.566359Z","sequence":180757285,"order_id":"d5bcaa47-b04f-474f-b131-e8f01fc4df90","reason":"canceled","price":"9081.93","remaining_size":"0.0736"}
{"type":"received","side":"buy","product_id":"BTC-USD","time":"2020-06-30T19:17:09.691509Z","sequence":180757286,"order_id":"4a8589eb-32f2-45d1-95e7-3dcadc3c0f0a","order_type":"limit","size":"0.5","price":"9117.77","client_oid":""}
{"type":"open","side":"buy","product_id":"BTC-USD","time":"2020-06-30T19:17:09.691509Z","sequence":180757287,"price":"9117.77","order_id":"4a8589eb-32f2-45d1-95e7-3dcadc3c0f0a","remaining_size":"0.5"}
{"type":"heartbeat","last_trade_id":0,"product_id":"BTC-USD","sequence":180757287,"time":"2020-06-30T19:17:09.735110Z"}
{"type":"done","side":"buy","product_id":"BTC-USD","time":"2020-06-30T19:17:09.845385Z","sequence":180757288,"order_id":"68f51b1d-5afc-4541-8f83-f38390f63f54","reason":"canceled","price":"9108.86","remaining_size":"0.0306"}
{"type":"received","side":"sell","product_id":"BTC-USD","time":"2020-06-30T19:17:10.487248Z","sequence":180757289,"order_id":"b598045f-d108-428a-8031-2cc113936fe6","order_type":"limit","size":"0.0244","price":"9141.83","client_oid":""}
{"type":"open","side":"sell","product_id":"BTC-USD","time":"2020-06-30T19:17:10.487248Z","sequence":180757290,"price":"9141.83","order_id":"b598045f-d108-428a-8031-2cc113936fe6","remaining_size":"0.0244"}
{"type":"heartbeat","last_trade_id":0,"product_id":"BTC-USD","sequence":180757290,"time":"2020-06-30T19:17:10.735108Z"}
{"type":"done","side":"sell","product_id":"BTC-USD","time":"2020-06-30T19:17:10.919378Z","sequence":180757291,"order_id":"16040849-ac2f-4e37-9e8f-b34d31a31500","reason":"canceled","price":"9144.8","remaining_size":"0.01"}
{"type":"received","side":"sell","product_id":"BTC-USD","time":"2020-06-30T19:17:11.074041Z","sequence":180757292,"order_id":"1c24cfd1-c0fe-4d62-942e-662ca63f8fab","order_type":"market","size":"0.001","funds":"9.1208","client_oid":""}
{"type":"match","side":"buy","product_id":"BTC-USD","time":"2020-06-30T19:17:11.074041Z","sequence":180757293,"trade_id":14587659,"maker_order_id":"91b59a7c-6a07-4039-9536-21daf3cb3282","taker_order_id":"1c24cfd1-c0fe-4d62-942e-662ca63f8fab","size":"0.001","price":"9120.8"}
{"type":"done","side":"sell","product_id":"BTC-USD","time":"2020-06-30T19:17:11.074041Z","sequence":180757294,"order_id":"1c24cfd1-c0fe-4d62-942e-662ca63f8fab","reason":"filled","remaining_size":"0"}
{"type":"received","side":"buy","product_id":"BTC-USD","time":"2020-06-30T19:17:11.336532Z","sequence":180757295,"order_id":"60328261-934c-414b-89d0-85358c9b14f9","order_type":"limit","size":"0.9","price":"9118.85","client_oid":""}
{"type":"open","side":"buy","product_id":"BTC-USD","time":"2020-06-30T19:17:11.336532Z","sequence":180757296,"price":"9118.85","order_id":"60328261-934c-414b-89d0-85358c9b14f9","remaining_size":"0.9"}
{"type":"received","side":"sell","product_id":"BTC-USD","time":"2020-06-30T19:17:11.603086Z","sequence":180757297,"order_id":"928db34a-2a35-47a4-ba8c-8a39c6965cb1","order_type":"limit","size":"2.185","price":"9121.03","client_oid":""}
{"type":"open","side":"sell","product_id":"BTC-USD","time":"2020-06-30T19:17:11.603086Z","sequence":180757298,"price":"9121.03","order_id":"928db34a-2a35-47a4-ba8c-8a39c6965cb1","remaining_size":"2.185"}
{"type":"heartbeat","last_trade_id":0,"product_id":"BTC-USD","sequence":180757298,"time":"2020-06-30T19:17:11.735110Z"}
{"type":"done","side":"buy","product_id":"BTC-USD","time":"2020-06-30T19:17:11.771601Z","sequence":180757299,"order_id":"3cc4e66a-66cd-4335-83ec-26059b3826e1","reason":"canceled","price":"9118.37","remaining_size":"0.5"}
{"type":"done","side":"sell","product_id":"BTC-USD","time":"2020-06-30T19:17:12.041775Z","sequence":180757300,"order_id":"114701a6-0f71-4776-8230-fbe5409417b8","reason":"canceled","price":"9122.93","remaining_size":"0.543"}
{"type":"done","side":"sell","product_id":"BTC-USD","time":"2020-06-30T19:17:12.053177Z","sequence":180757301,"order_id":"b598045f-d108-428a-8031-2cc113936fe6","reason":"canceled","price":"9141.83","remaining_size":"0.0244"}
{"type":"done","side":"buy","product_id":"BTC-USD","time":"2020-06-30T19:17:12.562007Z","sequence":180757302,"order_id":"ab741a32-38b3-434a-b52f-0605a1950a10","reason":"canceled","price":"9117.66","remaining_size":"0.14"}
{"type":"received","side":"sell","product_id":"BTC-USD","time":"2020-06-30T19:17:12.686052Z","sequence":180757303,"order_id":"39e9cd21-b0ae-46af-9e9d-f48293f9c04f","order_type":"limit","size":"0.05","price":"9120.21","client_oid":""}
{"type":"match","side":"buy","product_id":"BTC-USD","time":"2020-06-30T19:17:12.686052Z","sequence":180757304,"trade_id":14587660,"maker_order_id":"91b59a7c-6a07-4039-9536-21daf3cb3282","taker_order_id":"39e9cd21-b0ae-46af-9e9d-f48293f9c04f","size":"0.05","price":"9120.8"}
{"type":"done","side":"sell","product_id":"BTC-USD","time":"2020-06-30T19:17:12.686052Z","sequence":180757305,"order_id":"39e9cd21-b0ae-46af-9e9d-f48293f9c04f","reason":"filled","price":"9120.21","remaining_size":"0"}
{"type":"heartbeat","last_trade_id":0,"product_id":"BTC-USD","sequence":180757305,"time":"2020-06-30T19:17:12.735113Z"}
{"type":"received","side":"buy","product_id":"BTC-USD","time":"2020-06-30T19:17:12.956461Z","sequence":180757306,"order_id":"e7adb1c5-6ce1-4e89-ba50-8fd4a6d606a0","order_type":"limit","size":"0.1145","price":"9118.31","client_oid":""}
{"type":"open","side":"buy","product_id":"BTC-USD","time":"2020-06-30T19:17:12.956461Z","sequence":180757307,"price":"9118.31","order_id":"e7adb1c5-6ce1-4e89-ba50-8fd4a6d606a0","remaining_size":"0.1145"}
{"type":"done","side":"sell","product_id":"BTC-USD","time":"2020-06-30T19:17:13.108537Z","sequence":180757308,"order_id":"84c0ff57-687a-404c-8d42-99afb8607988","reason":"canceled","price":"9154.83","remaining_size":"0.0278"}
{"type":"done","side":"sell","product_id":"BTC-USD","time":"2020-06-30T19:17:13.137872Z","sequence":180757309,"order_id":"928db34a-2a35-47a4-ba8c-8a39c6965cb1","reason":"canceled","price":"9121.03","remaining_size":"2.185"}
{"type":"done","side":"buy","product_id":"BTC-USD","time":"2020-06-30T19:17:13.197054Z","sequence":180757310,"order_id":"a1e82340-b929-49a3-a5b6-10d92a1af974","reason":"canceled","price":"9117.1","remaining_size":"0.0719"}
{"type":"heartbeat","last_trade_id":0,"product_id":"BTC-USD","sequence":180757310,"time":"2020-06-30T19:17:13.735110Z"}
{"type":"received","side":"sell","product_id":"BTC-USD","time":"2020-06-30T19:17:13.786407Z","sequence":180757311,"order_id":"4aeb23e4-0fe5-458b-addf-31343a2fc9c6","order_type":"limit","size":"0.1621","price":"9123.13","client_oid":""}
{"type":"open","side":"sell","product_id":"BTC-USD","time":"2020-06-30T19:17:13.786407Z","sequence":180757312,"price":"9123.13","order_id":"4aeb23e4-0fe5-458b-addf-31343a2fc9c6","remaining_size":"0.1621"}
{"type":"received","side":"buy","product_id":"BTC-USD","time":"2020-06-30T19:17:14.021828Z","sequence":180757313,"order_id":"e5275f96-f568-4d55-beab-9f06e34005c8","order_type":"limit","size":"0.01","price":"100","client_oid":"a7e97764-b517-47f2-bdb1-29501d34e9a3"}
{"type":"open","side":"buy","product_id":"BTC-USD","time":"2020-06-30T19:17:14.021828Z","sequence":180757314,"price":"100","order_id":"e5275f96-f568-4d55-beab-9f06e34005c8","remaining_size":"0.01"}
{"type":"done","side":"buy","product_id":"BTC-USD","time":"2020-06-30T19:17:14.028774Z","sequence":180757315,"order_id":"e5275f96-f568-4d55-beab-9f06e34005c8","reason":"canceled","price":"100","remaining_size":"0.01"}
{"type":"received","side":"buy","product_id":"BTC-USD","time":"2020-06-30T19:17:14.331037Z","sequence":180757316,"order_id":"61fbcd9c-9d45-4028-9f7a-e0bf0c1db536","order_type":"limit","size":"0.125","price":"9119.69","client_oid":""}
{"type":"open","side":"buy","product_id":"BTC-USD","time":"2020-06-30T19:17:14.331037Z","sequence":180757317,"price":"9119.69","order_id":"61fbcd9c-9d45-4028-9f7a-e0bf0c1db536","remaining_size":"0.125"}
{"type":"received","side":"buy","product_id":"BTC-USD","time":"2020-06-30T19:17:14.606510Z","sequence":180757318,"order_id":"cd4dc46f-1661-4303-82c5-91df73be906c","order_type":"limit","size":"0.1","price":"9102.43","client_oid":""}
{"type":"open","side":"buy","product_id":"BTC-USD","time":"2020-06-30T19:17:14.606510Z","sequence":180757319,"price":"9102.43","order_id":"cd4dc46f-1661-4303-82c5-91df73be906c","remaining_size":"0.1"}
{"type":"heartbeat","last_trade_id":0,"product_id":"BTC-USD","sequence":180757319,"time":"2020-06-30T19:17:14.735109Z"}
{"type":"done","side":"buy","product_id":"BTC-USD","time":"2020-06-30T19:17:15.141442Z","sequence":180757320,"order_id":"e7adb1c5-6ce1-4e89-ba50-8fd4a6d606a0","reason":"canceled","price":"9118.31","remaining_size":"0.1145"}
{"type":"received","side":"sell","product_id":"BTC-USD","time":"2020-06-30T19:17:15.447116Z","sequence":180757321,"order_id":"00c6e3cf-549f-44a6-b47f-f9214be883aa","order_type":"limit","size":"0.025","price":"9121.51","client_oid":""}
{"type":"open","side":"sell","product_id":"BTC-USD","time":"2020-06-30T19:17:15.447116Z","sequence":180757322,"price":"9121.51","order_id":"00c6e3cf-549f-44a6-b47f-f9214be883aa","remaining_size":"0.025"}
{"type":"received","side":"buy","product_id":"BTC-USD","time":"2020-06-30T19:17:15.730831Z","sequence":180757323,"order_id":"1199591c-ab5e-43e3-92bf-ffb8ac74ba4d","order_type":"limit","size":"0.01","price":"9094.9","client_oid":""}
{"type":"open","side":"buy","product_id":"BTC-USD","time":"2020-06-30T19:17:15.730831Z","sequence":180757324,"price":"9094.9","order_id":"1199591c-ab5e-43e3-92bf-ffb8ac74ba4d","remaining_size":"0.01"}
{"type":"heartbeat","last_trade_id":0,"product_id":"BTC-USD","sequence":180757324,"time":"2020-06-30T19:17:15.735112Z"}
{"type":"done","side":"sell","product_id":"BTC-USD","time":"2020-06-30T19:17:15.871078Z","sequence":180757325,"order_id":"85c423bc-4b92-4b70-93fb-74605b5c1f09","reason":"canceled","price":"9123.11","remaining_size":"0.541"}
{"type":"received","side":"sell","product_id":"BTC-USD","time":"2020-06-30T19:17:16.554515Z","sequence":180757326,"order_id":"388d7568-a8f7-4046-bb5e-019bfa20d841","order_type":"limit","size":"0.15","price":"9120.56","client_oid":""}
{"type":"match","side":"buy","product_id":"BTC-USD","time":"2020-06-30T19:17:16.554515Z","sequence":180757327,"trade_id":14587661,"maker_order_id":"91b59a7c-6a07-4039-9536-21daf3cb3282","taker_order_id":"388d7568-a8f7-4046-bb5e-019bfa20d841","size":"0.15","price":"9120.8"}
{"type":"done","side":"sell","product_id":"BTC-USD","time":"2020-06-30T19:17:16.554515Z","sequence":180757328,"order_id":"388d7568-a8f7-4046-bb5e-019bfa20d841","reason":"filled","price":"9120.56","remaining_size":"0"}
{"type":"heartbeat","last_trade_id":0,"product_id":"BTC-USD","sequence":180757328,"time":"2020-06-30T19:17:16.735068Z"}
{"type":"received","side":"buy","product_id":"BTC-USD","time":"2020-06-30T19:17:16.818522Z","sequence":180757329,"order_id":"bea4d332-815a-4ae3-a786-e42484027339","order_type":"limit","size":"0.01","price":"9081.9","client_oid":""}
{"type":"open","side":"buy","product_id":"BTC-USD","time":"2020-06-30T19:17:16.818522Z","sequence":180757330,"price":"9081.9","order_id":"bea4d332-815a-4ae3-a786-e42484027339","remaining_size":"0.01"}
{"type":"done","side":"sell","product_id":"BTC-USD","time":"2020-06-30T19:17:17.007768Z","sequence":180757331,"order_id":"4aeb23e4-0fe5-458b-addf-31343a2fc9c6","reason":"canceled","price":"9123.13","remaining_size":"0.1621"}
{"type":"done","side":"buy","product_id":"BTC-USD","time":"2020-06-30T19:17:17.259352Z","sequence":180757332,"order_id":"1199591c-ab5e-43e3-92bf-ffb8ac74ba4d","reason":"canceled","price":"9094.9","remaining_size":"0.01"}
{"type":"done","side":"buy","product_id":"BTC-USD","time":"2020-06-30T19:17:17.260558Z","sequence":180757333,"order_id":"cd4dc46f-1661-4303-82c5-91df73be906c","reason":"canceled","price":"9102.43","remaining_size":"0.1"}
{"type":"received","side":"buy","product_id":"BTC-USD","time":"2020-06-30T19:17:17.649165Z","sequence":180757334,"order_id":"b4b0aadf-eda5-40df-b938-13f6775c4035","order_type":"limit","size":"0.01","price":"9072.05","client_oid":""}
{"type":"open","side":"buy","product_id":"BTC-USD","time":"2020-06-30T19:17:17.649165Z","sequence":180757335,"price":"9072.05","order_id":"b4b0aadf-eda5-40df-b938-13f6775c4035","remaining_size":"0.01"}
{"type":"heartbeat","last_trade_id":0,"product_id":"BTC-USD","sequence":180757335,"time":"2020-06-30T19:17:17.735046Z"}
{"type":"received","side":"sell","product_id":"BTC-USD","time":"2020-06-30T19:17:17.935497Z","sequence":180757336,"order_id":"2950b228-3c7c-44df-b614-53628f22a2f7","order_type":"limit","size":"0.2916","price":"9120.66","client_oid":""}
{"type":"match","side":"buy","product_id":"BTC-USD","time":"2020-06-30T19:17:17.935497Z","sequence":180757337,"trade_id":14587662,"maker_order_id":"91b59a7c-6a07-4039-9536-21daf3cb3282","taker_order_id":"2950b228-3c7c-44df-b614-53628f22a2f7","size":"0.2916","price":"9120.8"}
{"type":"done","side":"sell","product_id":"BTC-USD","time":"2020-06-30T19:17:17.935497Z","sequence":180757338,"order_id":"2950b228-3c7c-44df-b614-53628f22a2f7","reason":"filled","price":"9120.66","remaining_size":"0"}
{"type":"done","side":"buy","product_id":"BTC-USD","time":"2020-06-30T19:17:18.095610Z","sequence":180757339,"order_id":"0b60680b-c7a6-4816-917b-24a7cb1d5a62","reason":"canceled","price":"9111.57","remaining_size":"8.279"}
{"type":"done","side":"buy","product_id":"BTC-USD","time":"2020-06-30T19:17:18.097568Z","sequence":180757340,"order_id":"bea4d332-815a-4ae3-a786-e42484027339","reason":"canceled","price":"9081.9","remaining_size":"0.01"}
