{"type":"open","side":"buy","product_id":"BTC-USD","time":"2020-06-30T19:12:45.267604Z","sequence":180755734,"price":"9077.25","order_id":"e969f413-878c-4898-a0a1-fcf947f37138","remaining_size":"0.0693"}
{"type":"done","side":"buy","product_id":"BTC-USD","time":"2020-06-30T19:12:45.479126Z","sequence":180755735,"order_id":"4ff73e45-486d-451b-9c80-d20f074a6718","reason":"canceled","price":"9104.61","remaining_size":"0.132"}
{"type":"received","side":"buy","product_id":"BTC-USD","time":"2020-06-30T19:12:45.532407Z","sequence":180755736,"order_id":"2b702a3e-f699-4d49-8c35-1a1f08d8ff95","order_type":"limit","size":"0.544","price":"9100.21","client_oid":""}
{"type":"open","side":"buy","product_id":"BTC-USD","time":"2020-06-30T19:12:45.532407Z","sequence":180755737,"price":"9100.21","order_id":"2b702a3e-f699-4d49-8c35-1a1f08d8ff95","remaining_size":"0.544"}
{"type":"heartbeat","last_trade_id":0,"product_id":"BTC-USD","sequence":180755737,"time":"2020-06-30T19:12:45.735126Z"}
{"type":"received","side":"sell","product_id":"BTC-USD","time":"2020-06-30T19:12:45.804806Z","sequence":180755738,"order_id":"5d718d45-e416-4482-b8cb-ec13f8091954","order_type":"limit","size":"0.069","price":"9161.08","client_oid":""}
{"type":"open","side":"sell","product_id":"BTC-USD","time":"2020-06-30T19:12:45.804806Z","sequence":180755739,"price":"9161.08","order_id":"5d718d45-e416-4482-b8cb-ec13f8091954","remaining_size":"0.069"}
{"type":"received","side":"buy","product_id":"BTC-USD","time":"2020-06-30T19:12:46.074246Z","sequence":180755740,"order_id":"50e5e116-5724-4d9c-9609-d24b49ff4d33","order_type":"limit","size":"0.0279","price":"9078.91","client_oid":""}
{"type":"open","side":"buy","product_id":"BTC-USD","time":"2020-06-30T19:12:46.074246Z","sequence":180755741,"price":"9078.91","order_id":"50e5e116-5724-4d9c-9609-d24b49ff4d33","remaining_size":"0.0279"}
{"type":"done","side":"sell","product_id":"BTC-USD","time":"2020-06-30T19:12:46.222593Z","sequence":180755742,"order_id":"2d98a71d-8595-463e-b219-d8a949ecc7f4","reason":"canceled","price":"9203.18","remaining_size":"0.002"}
{"type":"done","side":"sell","product_id":"BTC-USD","time":"2020-06-30T19:12:46.234479Z","sequence":180755743,"order_id":"c58fe32a-a3b4-4d2d-a126-63a3217cca09","reason":"canceled","price":"9126.17","remaining_size":"0.5145"}
{"type":"received","side":"buy","product_id":"BTC-USD","time":"2020-06-30T19:12:46.356332Z","sequence":180755744,"order_id":"8d7295ff-6de4-4740-a7a4-3485c7994f44","order_type":"limit","size":"0.0371","price":"9078.09","client_oid":""}
{"type":"open","side":"buy","product_id":"BTC-USD","time":"2020-06-30T19:12:46.356332Z","sequence":180755745,"price":"9078.09","order_id":"8d7295ff-6de4-4740-a7a4-3485c7994f44","remaining_size":"0.0371"}
{"type":"received","side":"buy","product_id":"BTC-USD","time":"2020-06-30T19:12:46.631857Z","sequence":180755746,"order_id":"6a3126e7-dca7-4e88-9234-f307677c382c","order_type":"limit","size":"0.04","price":"9102.52","client_oid":""}
{"type":"open","side":"buy","product_id":"BTC-USD","time":"2020-06-30T19:12:46.631857Z","sequence":180755747,"price":"9102.52","order_id":"6a3126e7-dca7-4e88-9234-f307677c382c","remaining_size":"0.04"}
{"type":"heartbeat","last_trade_id":0,"product_id":"BTC-USD","sequence":180755747,"time":"2020-06-30T19:12:46.735113Z"}
{"type":"received","side":"sell","product_id":"BTC-USD","time":"2020-06-30T19:12:46.901239Z","sequence":180755748,"order_id":"c69315e7-e5af-4484-baee-584d71597611","order_type":"limit","size":"5.8652","price":"9103.34","client_oid":""}
{"type":"match","side":"buy","product_id":"BTC-USD","time":"2020-06-30T19:12:46.901239Z","sequence":180755749,"trade_id":14587478,"maker_order_id":"91b59a7c-6a07-4039-9536-21daf3cb3282","taker_order_id":"c69315e7-e5af-4484-baee-584d71597611","size":"5.8652","price":"9120.8"}
{"type":"done","side":"sell","product_id":"BTC-USD","time":"2020-06-30T19:12:46.901239Z","sequence":180755750,"order_id":"c69315e7-e5af-4484-baee-584d71597611","reason":"filled","price":"9103.34","remaining_size":"0"}
{"type":"received","side":"sell","product_id":"BTC-USD","time":"2020-06-30T19:12:47.462756Z","sequence":180755751,"order_id":"98e4cb56-1e1b-42f5-88f3-4ef5e696f75f","order_type":"limit","size":"0.069","price":"9160.69","client_oid":""}
{"type":"open","side":"sell","product_id":"BTC-USD","time":"2020-06-30T19:12:47.462756Z","sequence":180755752,"price":"9160.69","order_id":"98e4cb56-1e1b-42f5-88f3-4ef5e696f75f","remaining_size":"0.069"}
{"type":"done","side":"buy","product_id":"BTC-USD","time":"2020-06-30T19:12:47.650832Z","sequence":180755753,"order_id":"c76defa4-3cb4-4608-9dd3-b2942ef47008","reason":"canceled","price":"9079.69","remaining_size":"0.0661"}
{"type":"heartbeat","last_trade_id":0,"product_id":"BTC-USD","sequence":180755753,"time":"2020-06-30T19:12:47.735028Z"}
{"type":"received","side":"sell","product_id":"BTC-USD","time":"2020-06-30T19:12:47.767828Z","sequence":180755754,"order_id":"c8661b94-adc5-413c-8850-9b6b701b29ee","order_type":"limit","size":"0.01","price":"9160.8","client_oid":""}
{"type":"open","side":"sell","product_id":"BTC-USD","time":"2020-06-30T19:12:47.767828Z","sequence":180755755,"price":"9160.8","order_id":"c8661b94-adc5-413c-8850-9b6b701b29ee","remaining_size":"0.01"}
{"type":"received","side":"buy","product_id":"BTC-USD","time":"2020-06-30T19:12:48.036515Z","sequence":180755756,"order_id":"3935b756-96d8-4ce9-955d-42eb93f2667f","order_type":"limit","size":"0.04","price":"9103","client_oid":""}
{"type":"open","side":"buy","product_id":"BTC-USD","time":"2020-06-30T19:12:48.036515Z","sequence":180755757,"price":"9103","order_id":"3935b756-96d8-4ce9-955d-42eb93f2667f","remaining_size":"0.04"}
{"type":"done","side":"sell","product_id":"BTC-USD","time":"2020-06-30T19:12:48.183224Z","sequence":180755758,"order_id":"98e4cb56-1e1b-42f5-88f3-4ef5e696f75f","reason":"canceled","price":"9160.69","remaining_size":"0.069"}
{"type":"heartbeat","last_trade_id":0,"product_id":"BTC-USD","sequence":180755758,"time":"2020-06-30T19:12:48.735170Z"}
{"type":"received","side":"buy","product_id":"BTC-USD","time":"2020-06-30T19:12:49.199124Z","sequence":180755759,"order_id":"69f86165-c5b0-4ad9-b361-c3ba1eee4a47","order_type":"limit","size":"0.0314","price":"9082.57","client_oid":""}
{"type":"open","side":"buy","product_id":"BTC-USD","time":"2020-06-30T19:12:49.199124Z","sequence":180755760,"price":"9082.57","order_id":"69f86165-c5b0-4ad9-b361-c3ba1eee4a47","remaining_size":"0.0314"}
{"type":"received","side":"buy","product_id":"BTC-USD","time":"2020-06-30T19:12:49.484232Z","sequence":180755761,"order_id":"476fb058-abc5-4881-9e54-6daaa0081211","order_type":"limit","size":"0.0296","price":"9083.8","client_oid":""}
{"type":"open","side":"buy","product_id":"BTC-USD","time":"2020-06-30T19:12:49.484232Z","sequence":180755762,"price":"9083.8","order_id":"476fb058-abc5-4881-9e54-6daaa0081211","remaining_size":"0.0296"}
{"type":"done","side":"buy","product_id":"BTC-USD","time":"2020-06-30T19:12:49.639478Z","sequence":180755763,"order_id":"3935b756-96d8-4ce9-955d-42eb93f2667f","reason":"canceled","price":"9103","remaining_size":"0.04"}
{"type":"done","side":"buy","product_id":"BTC-USD","time":"2020-06-30T19:12:49.651868Z","sequence":180755764,"order_id":"2b702a3e-f699-4d49-8c35-1a1f08d8ff95","reason":"canceled","price":"9100.21","remaining_size":"0.544"}
{"type":"heartbeat","last_trade_id":0,"product_id":"BTC-USD","sequence":180755764,"time":"2020-06-30T19:12:49.735112Z"}
{"type":"received","side":"sell","product_id":"BTC-USD","time":"2020-06-30T19:12:49.996650Z","sequence":180755765,"order_id":"a546f68a-94ad-4312-a54f-1a979536cac7","order_type":"market","size":"0.1","client_oid":""}
{"type":"match","side":"buy","product_id":"BTC-USD","time":"2020-06-30T19:12:49.996650Z","sequence":180755766,"trade_id":14587479,"maker_order_id":"91b59a7c-6a07-4039-9536-21daf3cb3282","taker_order_id":"a546f68a-94ad-4312-a54f-1a979536cac7","size":"0.1","price":"9120.8"}
{"type":"done","side":"sell","product_id":"BTC-USD","time":"2020-06-30T19:12:49.996650Z","sequence":180755767,"order_id":"a546f68a-94ad-4312-a54f-1a979536cac7","reason":"filled","remaining_size":"0"}
{"type":"received","side":"sell","product_id":"BTC-USD","time":"2020-06-30T19:12:50.300073Z","sequence":180755768,"order_id":"5927e09b-daf4-488e-8a66-5cc335dfdd94","order_type":"limit","size":"0.05","price":"9102.92","client_oid":""}
{"type":"match","side":"buy","product_id":"BTC-USD","time":"2020-06-30T19:12:50.300073Z","sequence":180755769,"trade_id":14587480,"maker_order_id":"91b59a7c-6a07-4039-9536-21daf3cb3282","taker_order_id":"5927e09b-daf4-488e-8a66-5cc335dfdd94","size":"0.05","price":"9120.8"}
{"type":"done","side":"sell","product_id":"BTC-USD","time":"2020-06-30T19:12:50.300073Z","sequence":180755770,"order_id":"5927e09b-daf4-488e-8a66-5cc335dfdd94","reason":"filled","price":"9102.92","remaining_size":"0"}
{"type":"heartbeat","last_trade_id":0,"product_id":"BTC-USD","sequence":180755770,"time":"2020-06-30T19:12:50.735110Z"}
{"type":"received","side":"buy","product_id":"BTC-USD","time":"2020-06-30T19:12:50.833763Z","sequence":180755771,"order_id":"1b8e6395-9179-4fcc-9979-730962bacf23","order_type":"limit","size":"0.0112","price":"9089.09","client_oid":""}
{"type":"open","side":"buy","product_id":"BTC-USD","time":"2020-06-30T19:12:50.833763Z","sequence":180755772,"price":"9089.09","order_id":"1b8e6395-9179-4fcc-9979-730962bacf23","remaining_size":"0.0112"}
{"type":"received","side":"buy","product_id":"BTC-USD","time":"2020-06-30T19:12:51.105765Z","sequence":180755773,"order_id":"489a402f-e7f8-4a03-b188-09c1b2406b48","order_type":"limit","size":"0.0331","price":"9074.53","client_oid":""}
{"type":"open","side":"buy","product_id":"BTC-USD","time":"2020-06-30T19:12:51.105765Z","sequence":180755774,"price":"9074.53","order_id":"489a402f-e7f8-4a03-b188-09c1b2406b48","remaining_size":"0.0331"}
{"type":"done","side":"buy","product_id":"BTC-USD","time":"2020-06-30T19:12:51.305106Z","sequence":180755775,"order_id":"69f86165-c5b0-4ad9-b361-c3ba1eee4a47","reason":"canceled","price":"9082.57","remaining_size":"0.0314"}
{"type":"heartbeat","last_trade_id":0,"product_id":"BTC-USD","sequence":180755775,"time":"2020-06-30T19:12:51.735109Z"}
{"type":"received","side":"buy","product_id":"BTC-USD","time":"2020-06-30T19:12:51.944478Z","sequence":180755776,"order_id":"9a9bfdcb-1459-469d-b219-8ebc65657636","order_type":"limit","size":"0.023","price":"9080.31","client_oid":""}
{"type":"open","side":"buy","product_id":"BTC-USD","time":"2020-06-30T19:12:51.944478Z","sequence":180755777,"price":"9080.31","order_id":"9a9bfdcb-1459-469d-b219-8ebc65657636","remaining_size":"0.023"}
{"type":"done","side":"buy","product_id":"BTC-USD","time":"2020-06-30T19:12:52.375361Z","sequence":180755778,"order_id":"476fb058-abc5-4881-9e54-6daaa0081211","reason":"canceled","price":"9083.8","remaining_size":"0.0296"}
{"type":"done","side":"buy","product_id":"BTC-USD","time":"2020-06-30T19:12:52.379445Z","sequence":180755779,"order_id":"489a402f-e7f8-4a03-b188-09c1b2406b48","reason":"canceled","price":"9074.53","remaining_size":"0.0331"}
{"type":"received","side":"sell","product_id":"BTC-USD","time":"2020-06-30T19:12:52.485462Z","sequence":180755780,"order_id":"3b6e05f8-d3d0-4242-812d-9160f21ce06b","order_type":"limit","size":"0.0622","price":"9102.24","client_oid":""}
{"type":"match","side":"buy","product_id":"BTC-USD","time":"2020-06-30T19:12:52.485462Z","sequence":180755781,"trade_id":14587481,"maker_order_id":"91b59a7c-6a07-4039-9536-21daf3cb3282","taker_order_id":"3b6e05f8-d3d0-4242-812d-9160f21ce06b","size":"0.0622","price":"9120.8"}
{"type":"done","side":"sell","product_id":"BTC-USD","time":"2020-06-30T19:12:52.485462Z","sequence":180755782,"order_id":"3b6e05f8-d3d0-4242-812d-9160f21ce06b","reason":"filled","price":"9102.24","remaining_size":"0"}
{"type":"done","side":"sell","product_id":"BTC-USD","time":"2020-06-30T19:12:52.670526Z","sequence":180755783,"order_id":"baf95f26-e300-42c4-a7e3-462a0b02bbbb","reason":"canceled","price":"9160.24","remaining_size":"0.0527"}
{"type":"heartbeat","last_trade_id":0,"product_id":"BTC-USD","sequence":180755783,"time":"2020-06-30T19:12:52.735117Z"}
{"type":"received","side":"sell","product_id":"BTC-USD","time":"2020-06-30T19:12:52.757527Z","sequence":180755784,"order_id":"7f1e07a3-ada1-4e4c-b772-047a9f5b4cdf","order_type":"limit","size":"0.0108","price":"9132.33","client_oid":""}
{"type":"open","side":"sell","product_id":"BTC-USD","time":"2020-06-30T19:12:52.757527Z","sequence":180755785,"price":"9132.33","order_id":"7f1e07a3-ada1-4e4c-b772-047a9f5b4cdf","remaining_size":"0.0108"}
{"type":"received","side":"buy","product_id":"BTC-USD","time":"2020-06-30T19:12:53.040336Z","sequence":180755786,"order_id":"0f6e527f-46c4-4ce9-852a-a7e1045aa5b5","order_type":"limit","size":"0.5139","price":"9093.04","client_oid":""}
{"type":"open","side":"buy","product_id":"BTC-USD","time":"2020-06-30T19:12:53.040336Z","sequence":180755787,"price":"9093.04","order_id":"0f6e527f-46c4-4ce9-852a-a7e1045aa5b5","remaining_size":"0.5139"}
{"type":"done","side":"sell","product_id":"BTC-USD","time":"2020-06-30T19:12:53.185102Z","sequence":180755788,"order_id":"7fd3a374-21c6-49a5-8787-e83e302c2e3c","reason":"canceled","price":"9128.98","remaining_size":"1.2309"}
{"type":"done","side":"buy","product_id":"BTC-USD","time":"2020-06-30T19:12:53.273150Z","sequence":180755789,"order_id":"bbd7fb66-ec8f-46bb-bd0a-8255480b6a1a","reason":"canceled","price":"9070.48","remaining_size":"0.0235"}
{"type":"received","side":"sell","product_id":"BTC-USD","time":"2020-06-30T19:12:53.343014Z","sequence":180755790,"order_id":"89174054-34d6-4d9f-8a36-d57ddfea8826","order_type":"limit","size":"0.0108","price":"9132.33","client_oid":""}
{"type":"open","side":"sell","product_id":"BTC-USD","time":"2020-06-30T19:12:53.343014Z","sequence":180755791,"price":"9132.33","order_id":"89174054-34d6-4d9f-8a36-d57ddfea8826","remaining_size":"0.0108"}
{"type":"heartbeat","last_trade_id":0,"product_id":"BTC-USD","sequence":180755791,"time":"2020-06-30T19:12:53.735118Z"}
{"type":"done","side":"sell","product_id":"BTC-USD","time":"2020-06-30T19:12:54.395555Z","sequence":180755792,"order_id":"d3bb600e-7c64-49db-bda8-1e6f3aa58798","reason":"canceled","price":"9126.17","remaining_size":"0.5145"}
{"type":"heartbeat","last_trade_id":0,"product_id":"BTC-USD","sequence":180755792,"time":"2020-06-30T19:12:54.735115Z"}
{"type":"received","side":"sell","product_id":"BTC-USD","time":"2020-06-30T19:12:55.045798Z","sequence":180755793,"order_id":"fe84e464-14e1-4ee2-b668-7fe4f527cf89","order_type":"limit","size":"0.0814","price":"9160.44","client_oid":""}
{"type":"open","side":"sell","product_id":"BTC-USD","time":"2020-06-30T19:12:55.045798Z","sequence":180755794,"price":"9160.44","order_id":"fe84e464-14e1-4ee2-b668-7fe4f527cf89","remaining_size":"0.0814"}
{"type":"done","side":"sell","product_id":"BTC-USD","time":"2020-06-30T19:12:55.499587Z","sequence":180755795,"order_id":"89174054-34d6-4d9f-8a36-d57ddfea8826","reason":"canceled","price":"9132.33","remaining_size":"0.0108"}
{"type":"heartbeat","last_trade_id":0,"product_id":"BTC-USD","sequence":180755795,"time":"2020-06-30T19:12:55.735119Z"}
{"type":"received","side":"buy","product_id":"BTC-USD","time":"2020-06-30T19:12:56.452041Z","sequence":180755796,"order_id":"60f4a673-c212-40c6-b81e-4a72b9e3b1b6","order_type":"limit","size":"0.063","price":"9073.03","client_oid":""}
{"type":"open","side":"buy","product_id":"BTC-USD","time":"2020-06-30T19:12:56.452041Z","sequence":180755797,"price":"9073.03","order_id":"60f4a673-c212-40c6-b81e-4a72b9e3b1b6","remaining_size":"0.063"}
{"type":"heartbeat","last_trade_id":0,"product_id":"BTC-USD","sequence":180755797,"time":"2020-06-30T19:12:56.735112Z"}
{"type":"received","side":"buy","product_id":"BTC-USD","time":"2020-06-30T19:12:57.296347Z","sequence":180755798,"order_id":"3da33c77-8c94-45ec-b50e-c2390d03ae62","order_type":"limit","size":"0.125","price":"9074.26","client_oid":""}
{"type":"open","side":"buy","product_id":"BTC-USD","time":"2020-06-30T19:12:57.296347Z","sequence":180755799,"price":"9074.26","order_id":"3da33c77-8c94-45ec-b50e-c2390d03ae62","remaining_size":"0.125"}
{"type":"heartbeat","last_trade_id":0,"product_id":"BTC-USD","sequence":180755799,"time":"2020-06-30T19:12:57.735115Z"}
{"type":"done","side":"buy","product_id":"BTC-USD","time":"2020-06-30T19:12:57.757676Z","sequence":180755800,"order_id":"9a9bfdcb-1459-469d-b219-8ebc65657636","reason":"canceled","price":"9080.31","remaining_size":"0.023"}
{"type":"received","side":"sell","product_id":"BTC-USD","time":"2020-06-30T19:12:57.848691Z","sequence":180755801,"order_id":"7a4f11d6-b2df-419a-b91e-7b021298d3bd","order_type":"limit","size":"0.004","price":"9292.79","client_oid":""}
{"type":"open","side":"sell","product_id":"BTC-USD","time":"2020-06-30T19:12:57.848691Z","sequence":180755802,"price":"9292.79","order_id":"7a4f11d6-b2df-419a-b91e-7b021298d3bd","remaining_size":"0.004"}
{"type":"done","side":"buy","product_id":"BTC-USD","time":"2020-06-30T19:12:58.034780Z","sequence":180755803,"order_id":"0f6e527f-46c4-4ce9-852a-a7e1045aa5b5","reason":"canceled","price":"9093.04","remaining_size":"0.5139"}
{"type":"received","side":"buy","product_id":"BTC-USD","time":"2020-06-30T19:12:58.410210Z","sequence":180755804,"order_id":"73a70550-b4cb-4e45-b742-a1dfa3fe48b6","order_type":"limit","size":"0.0283","price":"9085.26","client_oid":""}
{"type":"open","side":"buy","product_id":"BTC-USD","time":"2020-06-30T19:12:58.410210Z","sequence":180755805,"price":"9085.26","order_id":"73a70550-b4cb-4e45-b742-a1dfa3fe48b6","remaining_size":"0.0283"}
{"type":"done","side":"buy","product_id":"BTC-USD","time":"2020-06-30T19:12:58.479602Z","sequence":180755806,"order_id":"2129da63-d170-4bed-a8bc-52db9a261cf2","reason":"canceled","price":"8894.82","remaining_size":"0.04634155"}
{"type":"received","side":"buy","product_id":"BTC-USD","time":"2020-06-30T19:12:58.719683Z","sequence":180755807,"order_id":"92324264-221a-4cd5-b203-267131faf428","order_type":"limit","size":"0.04644306","price":"8894","client_oid":""}
{"type":"open","side":"buy","product_id":"BTC-USD","time":"2020-06-30T19:12:58.719683Z","sequence":180755808,"price":"8894","order_id":"92324264-221a-4cd5-b203-267131faf428","remaining_size":"0.04644306"}
{"type":"heartbeat","last_trade_id":0,"product_id":"BTC-USD","sequence":180755808,"time":"2020-06-30T19:12:58.735111Z"}
{"type":"received","side":"buy","product_id":"BTC-USD","time":"2020-06-30T19:12:58.984533Z","sequence":180755809,"order_id":"f27dd767-6e7a-46c8-8b32-43f8764e2f76","order_type":"limit","size":"0.0737","price":"9075.05","client_oid":""}
{"type":"open","side":"buy","product_id":"BTC-USD","time":"2020-06-30T19:12:58.984533Z","sequence":180755810,"price":"9075.05","order_id":"f27dd767-6e7a-46c8-8b32-43f8764e2f76","remaining_size":"0.0737"}
{"type":"received","side":"buy","product_id":"BTC-USD","time":"2020-06-30T19:12:59.028498Z","sequence":180755811,"order_id":"297e2649-484e-4450-b818-bc67a3797c36","order_type":"limit","size":"0.01","price":"100","client_oid":"457de6e6-3592-4269-ad28-1dac7c1878be"}
{"type":"open","side":"buy","product_id":"BTC-USD","time":"2020-06-30T19:12:59.028498Z","sequence":180755812,"price":"100","order_id":"297e2649-484e-4450-b818-bc67a3797c36","remaining_size":"0.01"}
{"type":"done","side":"buy","product_id":"BTC-USD","time":"2020-06-30T19:12:59.034896Z","sequence":180755813,"order_id":"297e2649-484e-4450-b818-bc67a3797c36","reason":"canceled","price":"100","remaining_size":"0.01"}
{"type":"done","side":"sell","product_id":"BTC-USD","time":"2020-06-30T19:12:59.217286Z","sequence":180755814,"order_id":"31cdeae0-dc8e-4e9f-a855-60668a893061","reason":"canceled","price":"9436.09","remaining_size":"0.00709009"}
{"type":"received","side":"sell","product_id":"BTC-USD","time":"2020-06-30T19:12:59.423507Z","sequence":180755815,"order_id":"ce032b68-b73b-4d61-83f6-1e9e4a6d770a","order_type":"limit","size":"0.00718939","price":"9436.96","client_oid":""}
{"type":"open","side":"sell","product_id":"BTC-USD","time":"2020-06-30T19:12:59.423507Z","sequence":180755816,"price":"9436.96","order_id":"ce032b68-b73b-4d61-83f6-1e9e4a6d770a","remaining_size":"0.00718939"}
{"type":"heartbeat","last_trade_id":0,"product_id":"BTC-USD","sequence":180755816,"time":"2020-06-30T19:12:59.735117Z"}
{"type":"received","side":"sell","product_id":"BTC-USD","time":"2020-06-30T19:12:59.830720Z","sequence":180755817,"order_id":"84b169b4-bc89-462b-ba38-537eb16e120e","order_type":"limit","size":"2.189","price":"9101.51","client_oid":""}
{"type":"match","side":"buy","product_id":"BTC-USD","time":"2020-06-30T19:12:59.830720Z","sequence":180755818,"trade_id":14587482,"maker_order_id":"91b59a7c-6a07-4039-9536-21daf3cb3282","taker_order_id":"84b169b4-bc89-462b-ba38-537eb16e120e","size":"2.189","price":"9120.8"}
{"type":"done","side":"sell","product_id":"BTC-USD","time":"2020-06-30T19:12:59.830720Z","sequence":180755819,"order_id":"84b169b4-bc89-462b-ba38-537eb16e120e","reason":"filled","price":"9101.51","remaining_size":"0"}
{"type":"done","side":"sell","product_id":"BTC-USD","time":"2020-06-30T19:13:00.283027Z","sequence":180755820,"order_id":"fe84e464-14e1-4ee2-b668-7fe4f527cf89","reason":"canceled","price":"9160.44","remaining_size":"0.0814"}
{"type":"received","side":"sell","product_id":"BTC-USD","time":"2020-06-30T19:13:00.391119Z","sequence":180755821,"order_id":"f62b4190-9883-4f5c-ac2d-8448eddf3de2","order_type":"limit","size":"2.3361","price":"9123.7","client_oid":""}
{"type":"open","side":"sell","product_id":"BTC-USD","time":"2020-06-30T19:13:00.391119Z","sequence":180755822,"price":"9123.7","order_id":"f62b4190-9883-4f5c-ac2d-8448eddf3de2","remaining_size":"2.3361"}
{"type":"received","side":"buy","product_id":"BTC-USD","time":"2020-06-30T19:13:00.591830Z","sequence":180755823,"order_id":"e043453b-8a9f-4b13-bf5f-d5d7a6f8fe54","order_type":"limit","size":"0.0032","price":"9101.51","client_oid":""}
{"type":"open","side":"buy","product_id":"BTC-USD","time":"2020-06-30T19:13:00.591830Z","sequence":180755824,"price":"9101.51","order_id":"e043453b-8a9f-4b13-bf5f-d5d7a6f8fe54","remaining_size":"0.0032"}
{"type":"received","side":"sell","product_id":"BTC-USD","time":"2020-06-30T19:13:00.645986Z","sequence":180755825,"order_id":"da1e4208-55d6-43b9-8c57-b9e7d6b0a622","order_type":"limit","size":"1.5","price":"9100.34","client_oid":""}
{"type":"match","side":"buy","product_id":"BTC-USD","time":"2020-06-30T19:13:00.645986Z","sequence":180755826,"trade_id":14587483,"maker_order_id":"91b59a7c-6a07-4039-9536-21daf3cb3282","taker_order_id":"da1e4208-55d6-43b9-8c57-b9e7d6b0a622","size":"1.5","price":"9120.8"}
{"type":"done","side":"sell","product_id":"BTC-USD","time":"2020-06-30T19:13:00.645986Z","sequence":180755827,"order_id":"da1e4208-55d6-43b9-8c57-b9e7d6b0a622","reason":"filled","price":"9100.34","remaining_size":"0"}
{"type":"heartbeat","last_trade_id":0,"product_id":"BTC-USD","sequence":180755827,"time":"2020-06-30T19:13:00.735113Z"}
{"type":"done","side":"sell","product_id":"BTC-USD","time":"2020-06-30T19:13:00.808546Z","sequence":180755828,"order_id":"7a4f11d6-b2df-419a-b91e-7b021298d3bd","reason":"canceled","price":"9292.79","remaining_size":"0.004"}
{"type":"received","side":"buy","product_id":"BTC-USD","time":"2020-06-30T19:13:01.194982Z","sequence":180755829,"order_id":"ef012c98-bdc5-474e-9de7-3183eb0f177a","order_type":"limit","size":"0.0467","price":"9063.7","client_oid":""}
{"type":"open","side":"buy","product_id":"BTC-USD","time":"2020-06-30T19:13:01.194982Z","sequence":180755830,"price":"9063.7","order_id":"ef012c98-bdc5-474e-9de7-3183eb0f177a","remaining_size":"0.0467"}
{"type":"received","side":"sell","product_id":"BTC-USD","time":"2020-06-30T19:13:01.472680Z","sequence":180755831,"order_id":"1917b9df-93f6-4d9c-820f-1059c442f337","order_type":"limit","size":"2.6107","price":"9122.4","client_oid":""}
{"type":"open","side":"sell","product_id":"BTC-USD","time":"2020-06-30T19:13:01.472680Z","sequence":180755832,"price":"9122.4","order_id":"1917b9df-93f6-4d9c-820f-1059c442f337","remaining_size":"2.6107"}
{"type":"done","side":"buy","product_id":"BTC-USD","time":"2020-06-30T19:13:01.658817Z","sequence":180755833,"order_id":"8d7295ff-6de4-4740-a7a4-3485c7994f44","reason":"canceled","price":"9078.09","remaining_size":"0.0371"}
{"type":"heartbeat","last_trade_id":0,"product_id":"BTC-USD","sequence":180755833,"time":"2020-06-30T19:13:01.735122Z"}
{"type":"done","side":"sell","product_id":"BTC-USD","time":"2020-06-30T19:13:01.898768Z","sequence":180755834,"order_id":"4d07ead6-26bf-4b8a-8197-d8a0fceed7cf","reason":"canceled","price":"9161.21","remaining_size":"0.0383"}
{"type":"done","side":"sell","product_id":"BTC-USD","time":"2020-06-30T19:13:02.034774Z","sequence":180755835,"order_id":"f62b4190-9883-4f5c-ac2d-8448eddf3de2","reason":"canceled","price":"9123.7","remaining_size":"2.3361"}
{"type":"received","side":"buy","product_id":"BTC-USD","time":"2020-06-30T19:13:02.733109Z","sequence":180755836,"order_id":"42c309e3-c4a4-4297-82a7-07cfd22030fe","order_type":"limit","size":"0.044","price":"9073.09","client_oid":""}
{"type":"open","side":"buy","product_id":"BTC-USD","time":"2020-06-30T19:13:02.733109Z","sequence":180755837,"price":"9073.09","order_id":"42c309e3-c4a4-4297-82a7-07cfd22030fe","remaining_size":"0.044"}
{"type":"heartbeat","last_trade_id":0,"product_id":"BTC-USD","sequence":180755837,"time":"2020-06-30T19:13:02.735118Z"}
{"type":"received","side":"buy","product_id":"BTC-USD","time":"2020-06-30T19:13:02.911801Z","sequence":180755838,"order_id":"98a27131-32f1-42e9-85dc-b6ca756c235b","order_type":"limit","size":"0.7308","price":"9089.56","client_oid":""}
{"type":"open","side":"buy","product_id":"BTC-USD","time":"2020-06-30T19:13:02.911801Z","sequence":180755839,"price":"9089.56","order_id":"98a27131-32f1-42e9-85dc-b6ca756c235b","remaining_size":"0.7308"}
{"type":"done","side":"buy","product_id":"BTC-USD","time":"2020-06-30T19:13:03.097308Z","sequence":180755840,"order_id":"1b8e6395-9179-4fcc-9979-730962bacf23","reason":"canceled","price":"9089.09","remaining_size":"0.0112"}
{"type":"received","side":"sell","product_id":"BTC-USD","time":"2020-06-30T19:13:03.432516Z","sequence":180755841,"order_id":"5b56383e-6d1c-449b-b6ee-c086cef7d4a7","order_type":"limit","size":"0.05","price":"9093.53","client_oid":""}
{"type":"match","side":"buy","product_id":"BTC-USD","time":"2020-06-30T19:13:03.432516Z","sequence":180755842,"trade_id":14587484,"maker_order_id":"91b59a7c-6a07-4039-9536-21daf3cb3282","taker_order_id":"5b56383e-6d1c-449b-b6ee-c086cef7d4a7","size":"0.05","price":"9120.8"}
{"type":"done","side":"sell","product_id":"BTC-USD","time":"2020-06-30T19:13:03.432516Z","sequence":180755843,"order_id":"5b56383e-6d1c-449b-b6ee-c086cef7d4a7","reason":"filled","price":"9093.53","remaining_size":"0"}
{"type":"done","side":"buy","product_id":"BTC-USD","time":"2020-06-30T19:13:03.491031Z","sequence":180755844,"order_id":"e969f413-878c-4898-a0a1-fcf947f37138","reason":"canceled","price":"9077.25","remaining_size":"0.0693"}
{"type":"done","side":"buy","product_id":"BTC-USD","time":"2020-06-30T19:13:03.498292Z","sequence":180755845,"order_id":"ed74b5fe-9b91-4712-a728-c27de8f0b878","reason":"canceled","price":"9081.32","remaining_size":"0.0967"}
{"type":"done","side":"buy","product_id":"BTC-USD","time":"2020-06-30T19:13:03.515824Z","sequence":180755846,"order_id":"6a3126e7-dca7-4e88-9234-f307677c382c","reason":"canceled","price":"9102.52","remaining_size":"0.04"}
{"type":"done","side":"buy","product_id":"BTC-USD","time":"2020-06-30T19:13:03.519683Z","sequence":180755847,"order_id":"42c309e3-c4a4-4297-82a7-07cfd22030fe","reason":"canceled","price":"9073.09","remaining_size":"0.044"}
{"type":"received","side":"buy","product_id":"BTC-USD","time":"2020-06-30T19:13:03.707739Z","sequence":180755848,"order_id":"59f69d76-d12b-489b-8e48-0efce90b834f","order_type":"limit","size":"0.7308","price":"9085.01","client_oid":""}
{"type":"open","side":"buy","product_id":"BTC-USD","time":"2020-06-30T19:13:03.707739Z","sequence":180755849,"price":"9085.01","order_id":"59f69d76-d12b-489b-8e48-0efce90b834f","remaining_size":"0.7308"}
{"type":"heartbeat","last_trade_id":0,"product_id":"BTC-USD","sequence":180755849,"time":"2020-06-30T19:13:03.735118Z"}
{"type":"received","side":"sell","product_id":"BTC-USD","time":"2020-06-30T19:13:04.247730Z","sequence":180755850,"order_id":"66288655-406d-4439-994f-a7e1a3755fc1","order_type":"limit","size":"7.6084","price":"9089.84","client_oid":""}
{"type":"match","side":"buy","product_id":"BTC-USD","time":"2020-06-30T19:13:04.247730Z","sequence":180755851,"trade_id":14587485,"maker_order_id":"91b59a7c-6a07-4039-9536-21daf3cb3282","taker_order_id":"66288655-406d-4439-994f-a7e1a3755fc1","size":"7.6084","price":"9120.8"}
{"type":"done","side":"sell","product_id":"BTC-USD","time":"2020-06-30T19:13:04.247730Z","sequence":180755852,"order_id":"66288655-406d-4439-994f-a7e1a3755fc1","reason":"filled","price":"9089.84","remaining_size":"0"}
{"type":"received","side":"buy","product_id":"BTC-USD","time":"2020-06-30T19:13:04.520800Z","sequence":180755853,"order_id":"20909af1-d105-43f9-ba64-6ed7dc6dd45c","order_type":"limit","size":"0.0689","price":"9074.75","client_oid":""}
{"type":"open","side":"buy","product_id":"BTC-USD","time":"2020-06-30T19:13:04.520800Z","sequence":180755854,"price":"9074.75","order_id":"20909af1-d105-43f9-ba64-6ed7dc6dd45c","remaining_size":"0.0689"}
{"type":"done","side":"sell","product_id":"BTC-USD","time":"2020-06-30T19:13:04.714580Z","sequence":180755855,"order_id":"71f794b4-572d-4d9e-9fe7-b4e600bf945e","reason":"canceled","price":"9128.82","remaining_size":"1.3826"}
{"type":"done","side":"sell","product_id":"BTC-USD","time":"2020-06-30T19:13:04.722551Z","sequence":180755856,"order_id":"7f1e07a3-ada1-4e4c-b772-047a9f5b4cdf","reason":"canceled","price":"9132.33","remaining_size":"0.0108"}
{"type":"done","side":"buy","product_id":"BTC-USD","time":"2020-06-30T19:13:04.731992Z","sequence":180755857,"order_id":"ef012c98-bdc5-474e-9de7-3183eb0f177a","reason":"canceled","price":"9063.7","remaining_size":"0.0467"}
{"type":"heartbeat","last_trade_id":0,"product_id":"BTC-USD","sequence":180755857,"time":"2020-06-30T19:13:04.735034Z"}
{"type":"received","side":"buy","product_id":"BTC-USD","time":"2020-06-30T19:13:04.827873Z","sequence":180755858,"order_id":"bf67b5b0-d134-4443-ad9b-d4e1842c42b2","order_type":"limit","size":"0.0689","price":"9075.58","client_oid":""}
{"type":"open","side":"buy","product_id":"BTC-USD","time":"2020-06-30T19:13:04.827873Z","sequence":180755859,"price":"9075.58","order_id":"bf67b5b0-d134-4443-ad9b-d4e1842c42b2","remaining_size":"0.0689"}
{"type":"received","side":"buy","product_id":"BTC-USD","time":"2020-06-30T19:13:05.098251Z","sequence":180755860,"order_id":"ad19d38b-83f8-42de-87d9-95eaa135f062","order_type":"limit","size":"0.1327","price":"9093.69","client_oid":""}
{"type":"open","side":"buy","product_id":"BTC-USD","time":"2020-06-30T19:13:05.098251Z","sequence":180755861,"price":"9093.69","order_id":"ad19d38b-83f8-42de-87d9-95eaa135f062","remaining_size":"0.1327"}
{"type":"heartbeat","last_trade_id":0,"product_id":"BTC-USD","sequence":180755861,"time":"2020-06-30T19:13:05.735181Z"}
{"type":"received","side":"sell","product_id":"BTC-USD","time":"2020-06-30T19:13:06.448866Z","sequence":180755862,"order_id":"3f62d0fc-b897-4a9d-86a5-62e51b3c7b0e","order_type":"limit","size":"0.0964","price":"9156.07","client_oid":""}
{"type":"open","side":"sell","product_id":"BTC-USD","time":"2020-06-30T19:13:06.448866Z","sequence":180755863,"price":"9156.07","order_id":"3f62d0fc-b897-4a9d-86a5-62e51b3c7b0e","remaining_size":"0.0964"}
{"type":"done","side":"buy","product_id":"BTC-USD","time":"2020-06-30T19:13:06.464314Z","sequence":180755864,"order_id":"f27dd767-6e7a-46c8-8b32-43f8764e2f76","reason":"canceled","price":"9075.05","remaining_size":"0.0737"}
{"type":"received","side":"buy","product_id":"BTC-USD","time":"2020-06-30T19:13:06.723838Z","sequence":180755865,"order_id":"125c6ed2-2607-43f8-b936-09980a3c9539","order_type":"limit","size":"1.5154","price":"9088.02","client_oid":""}
{"type":"open","side":"buy","product_id":"BTC-USD","time":"2020-06-30T19:13:06.723838Z","sequence":180755866,"price":"9088.02","order_id":"125c6ed2-2607-43f8-b936-09980a3c9539","remaining_size":"1.5154"}
{"type":"heartbeat","last_trade_id":0,"product_id":"BTC-USD","sequence":180755866,"time":"2020-06-30T19:13:06.735117Z"}
{"type":"received","side":"buy","product_id":"BTC-USD","time":"2020-06-30T19:13:07.297627Z","sequence":180755867,"order_id":"986f2db5-fe2c-4bd5-a0ab-cf6cc2ad97b9","order_type":"limit","size":"0.0235","price":"9069.93","client_oid":""}
{"type":"open","side":"buy","product_id":"BTC-USD","time":"2020-06-30T19:13:07.297627Z","sequence":180755868,"price":"9069.93","order_id":"986f2db5-fe2c-4bd5-a0ab-cf6cc2ad97b9","remaining_size":"0.0235"}
{"type":"received","side":"sell","product_id":"BTC-USD","time":"2020-06-30T19:13:07.563846Z","sequence":180755869,"order_id":"ffb85008-fa46-4ac7-b347-6d3a77dc3de2","order_type":"limit","size":"0.15","price":"9102.59","client_oid":""}
{"type":"match","side":"buy","product_id":"BTC-USD","time":"2020-06-30T19:13:07.563846Z","sequence":180755870,"trade_id":14587486,"maker_order_id":"91b59a7c-6a07-4039-9536-21daf3cb3282","taker_order_id":"ffb85008-fa46-4ac7-b347-6d3a77dc3de2","size":"0.15","price":"9120.8"}
{"type":"done","side":"sell","product_id":"BTC-USD","time":"2020-06-30T19:13:07.563846Z","sequence":180755871,"order_id":"ffb85008-fa46-4ac7-b347-6d3a77dc3de2","reason":"filled","price":"9102.59","remaining_size":"0"}
{"type":"heartbeat","last_trade_id":0,"product_id":"BTC-USD","sequence":180755871,"time":"2020-06-30T19:13:07.735120Z"}
{"type":"received","side":"buy","product_id":"BTC-USD","time":"2020-06-30T19:13:08.116432Z","sequence":180755872,"order_id":"6bd53dbc-7f0c-4b3d-bd03-ede7c0c459c0","order_type":"limit","size":"0.035","price":"9082.32","client_oid":""}
{"type":"open","side":"buy","product_id":"BTC-USD","time":"2020-06-30T19:13:08.116432Z","sequence":180755873,"price":"9082.32","order_id":"6bd53dbc-7f0c-4b3d-bd03-ede7c0c459c0","remaining_size":"0.035"}
{"type":"done","side":"buy","product_id":"BTC-USD","time":"2020-06-30T19:13:08.323979Z","sequence":180755874,"order_id":"59f69d76-d12b-489b-8e48-0efce90b834f","reason":"canceled","price":"9085.01","remaining_size":"0.7308"}
{"type":"done","side":"buy","product_id":"BTC-USD","time":"2020-06-30T19:13:08.328974Z","sequence":180755875,"order_id":"bf67b5b0-d134-4443-ad9b-d4e1842c42b2","reason":"canceled","price":"9075.58","remaining_size":"0.0689"}
{"type":"received","side":"sell","product_id":"BTC-USD","time":"2020-06-30T19:13:08.393153Z","sequence":180755876,"order_id":"bbe2ba6a-2c7c-41c7-8708-a07bd4e19454","order_type":"limit","size":"0.9","price":"9097.91","client_oid":""}
{"type":"match","side":"buy","product_id":"BTC-USD","time":"2020-06-30T19:13:08.393153Z","sequence":180755877,"trade_id":14587487,"maker_order_id":"91b59a7c-6a07-4039-9536-21daf3cb3282","taker_order_id":"bbe2ba6a-2c7c-41c7-8708-a07bd4e19454","size":"0.9","price":"9120.8"}
{"type":"done","side":"sell","product_id":"BTC-USD","time":"2020-06-30T19:13:08.393153Z","sequence":180755878,"order_id":"bbe2ba6a-2c7c-41c7-8708-a07bd4e19454","reason":"filled","price":"9097.91","remaining_size":"0"}
{"type":"received","side":"sell","product_id":"BTC-USD","time":"2020-06-30T19:13:08.671949Z","sequence":180755879,"order_id":"c634eafe-2fcf-4f77-abe3-ba62a57cc17e","order_type":"limit","size":"0.0088","price":"9094.46","client_oid":""}
{"type":"match","side":"buy","product_id":"BTC-USD","time":"2020-06-30T19:13:08.671949Z","sequence":180755880,"trade_id":14587488,"maker_order_id":"91b59a7c-6a07-4039-9536-21daf3cb3282","taker_order_id":"c634eafe-2fcf-4f77-abe3-ba62a57cc17e","size":"0.0088","price":"9120.8"}
{"type":"done","side":"sell","product_id":"BTC-USD","time":"2020-06-30T19:13:08.671949Z","sequence":180755881,"order_id":"c634eafe-2fcf-4f77-abe3-ba62a57cc17e","reason":"filled","price":"9094.46","remaining_size":"0"}
{"type":"heartbeat","last_trade_id":0,"product_id":"BTC-USD","sequence":180755881,"time":"2020-06-30T19:13:08.735116Z"}
{"type":"done","side":"sell","product_id":"BTC-USD","time":"2020-06-30T19:13:08.839067Z","sequence":180755882,"order_id":"c8661b94-adc5-413c-8850-9b6b701b29ee","reason":"canceled","price":"9160.8","remaining_size":"0.01"}
{"type":"received","side":"sell","product_id":"BTC-USD","time":"2020-06-30T19:13:09.234697Z","sequence":180755883,"order_id":"22c4fb1d-79d2-494c-a867-3f83498ef0d1","order_type":"limit","size":"3.99","price":"9100.19","client_oid":""}
{"type":"match","side":"buy","product_id":"BTC-USD","time":"2020-06-30T19:13:09.234697Z","sequence":180755884,"trade_id":14587489,"maker_order_id":"91b59a7c-6a07-4039-9536-21daf3cb3282","taker_order_id":"22c4fb1d-79d2-494c-a867-3f83498ef0d1","size":"3.99","price":"9120.8"}
{"type":"done","side":"sell","product_id":"BTC-USD","time":"2020-06-30T19:13:09.234697Z","sequence":180755885,"order_id":"22c4fb1d-79d2-494c-a867-3f83498ef0d1","reason":"filled","price":"9100.19","remaining_size":"0"}
{"type":"heartbeat","last_trade_id":0,"product_id":"BTC-USD","sequence":180755885,"time":"2020-06-30T19:13:09.735114Z"}
{"type":"received","side":"sell","product_id":"BTC-USD","time":"2020-06-30T19:13:10.038766Z","sequence":180755886,"order_id":"bea32de6-ee34-4c88-ad83-6d28371dda5b","order_type":"limit","size":"0.11","price":"9097.84","client_oid":""}
{"type":"match","side":"buy","product_id":"BTC-USD","time":"2020-06-30T19:13:10.038766Z","sequence":180755887,"trade_id":14587490,"maker_order_id":"91b59a7c-6a07-4039-9536-21daf3cb3282","taker_order_id":"bea32de6-ee34-4c88-ad83-6d28371dda5b","size":"0.11","price":"9120.8"}
{"type":"done","side":"sell","product_id":"BTC-USD","time":"2020-06-30T19:13:10.038766Z","sequence":180755888,"order_id":"bea32de6-ee34-4c88-ad83-6d28371dda5b","reason":"filled","price":"9097.84","remaining_size":"0"}
{"type":"done","side":"sell","product_id":"BTC-USD","time":"2020-06-30T19:13:10.479351Z","sequence":180755889,"order_id":"1917b9df-93f6-4d9c-820f-1059c442f337","reason":"canceled","price":"9122.4","remaining_size":"2.6107"}
{"type":"heartbeat","last_trade_id":0,"product_id":"BTC-USD","sequence":180755889,"time":"2020-06-30T19:13:10.735124Z"}
{"type":"received","side":"buy","product_id":"BTC-USD","time":"2020-06-30T19:13:10.871848Z","sequence":180755890,"order_id":"ec9d733c-af8b-492c-beeb-cfa1ad346588","order_type":"limit","size":"13.1992","price":"9098.27","client_oid":""}
{"type":"open","side":"buy","product_id":"BTC-USD","time":"2020-06-30T19:13:10.871848Z","sequence":180755891,"price":"9098.27","order_id":"ec9d733c-af8b-492c-beeb-cfa1ad346588","remaining_size":"13.1992"}
{"type":"done","side":"buy","product_id":"BTC-USD","time":"2020-06-30T19:13:11.343861Z","sequence":180755892,"order_id":"125c6ed2-2607-43f8-b936-09980a3c9539","reason":"canceled","price":"9088.02","remaining_size":"1.5154"}
{"type":"done","side":"buy","product_id":"BTC-USD","time":"2020-06-30T19:13:11.346076Z","sequence":180755893,"order_id":"6fcd8f9f-be7d-4005-a21c-c2bdc641689a","reason":"canceled","price":"9100.22","remaining_size":"0.8159"}
{"type":"done","side":"buy","product_id":"BTC-USD","time":"2020-06-30T19:13:11.352960Z","sequence":180755894,"order_id":"50e5e116-5724-4d9c-9609-d24b49ff4d33","reason":"canceled","price":"9078.91","remaining_size":"0.0279"}
{"type":"received","side":"sell","product_id":"BTC-USD","time":"2020-06-30T19:13:11.413586Z","sequence":180755895,"order_id":"bab320c6-b132-47d3-8c3a-990e6db01517","order_type":"limit","size":"0.0296","price":"9128.65","client_oid":""}
{"type":"open","side":"sell","product_id":"BTC-USD","time":"2020-06-30T19:13:11.413586Z","sequence":180755896,"price":"9128.65","order_id":"bab320c6-b132-47d3-8c3a-990e6db01517","remaining_size":"0.0296"}
{"type":"received","side":"sell","product_id":"BTC-USD","time":"2020-06-30T19:13:11.656504Z","sequence":180755897,"order_id":"5b689cba-1716-4ab3-a977-a807cc807a36","order_type":"market","size":"0.001","funds":"9.1208","client_oid":""}
{"type":"match","side":"buy","product_id":"BTC-USD","time":"2020-06-30T19:13:11.656504Z","sequence":180755898,"trade_id":14587491,"maker_order_id":"91b59a7c-6a07-4039-9536-21daf3cb3282","taker_order_id":"5b689cba-1716-4ab3-a977-a807cc807a36","size":"0.001","price":"9120.8"}
{"type":"done","side":"sell","product_id":"BTC-USD","time":"2020-06-30T19:13:11.656504Z","sequence":180755899,"order_id":"5b689cba-1716-4ab3-a977-a807cc807a36","reason":"filled","remaining_size":"0"}
{"type":"received","side":"buy","product_id":"BTC-USD","time":"2020-06-30T19:13:11.706722Z","sequence":180755900,"order_id":"d8c19c79-5a78-42d6-813e-70fadb8dce2b","order_type":"limit","size":"0.3299","price":"9092.39","client_oid":""}
{"type":"open","side":"buy","product_id":"BTC-USD","time":"2020-06-30T19:13:11.706722Z","sequence":180755901,"price":"9092.39","order_id":"d8c19c79-5a78-42d6-813e-70fadb8dce2b","remaining_size":"0.3299"}
{"type":"heartbeat","last_trade_id":0,"product_id":"BTC-USD","sequence":180755901,"time":"2020-06-30T19:13:11.735114Z"}
{"type":"received","side":"buy","product_id":"BTC-USD","time":"2020-06-30T19:13:11.989274Z","sequence":180755902,"order_id":"7e280100-4407-4712-b293-64cab0dff28c","order_type":"limit","size":"0.0356","price":"9078.87","client_oid":""}
{"type":"open","side":"buy","product_id":"BTC-USD","time":"2020-06-30T19:13:11.989274Z","sequence":180755903,"price":"9078.87","order_id":"7e280100-4407-4712-b293-64cab0dff28c","remaining_size":"0.0356"}
{"type":"done","side":"buy","product_id":"BTC-USD","time":"2020-06-30T19:13:12.133928Z","sequence":180755904,"order_id":"ad19d38b-83f8-42de-87d9-95eaa135f062","reason":"canceled","price":"9093.69","remaining_size":"0.1327"}
{"type":"received","side":"buy","product_id":"BTC-USD","time":"2020-06-30T19:13:12.247268Z","sequence":180755905,"order_id":"e3f797e3-8535-4609-8e5c-dbce33d70c92","order_type":"limit","size":"0.0157","price":"9070.04","client_oid":""}
{"type":"open","side":"buy","product_id":"BTC-USD","time":"2020-06-30T19:13:12.247268Z","sequence":180755906,"price":"9070.04","order_id":"e3f797e3-8535-4609-8e5c-dbce33d70c92","remaining_size":"0.0157"}
{"type":"done","side":"buy","product_id":"BTC-USD","time":"2020-06-30T19:13:12.423211Z","sequence":180755907,"order_id":"6bd53dbc-7f0c-4b3d-bd03-ede7c0c459c0","reason":"canceled","price":"9082.32","remaining_size":"0.035"}
{"type":"done","side":"buy","product_id":"BTC-USD","time":"2020-06-30T19:13:12.448070Z","sequence":180755908,"order_id":"1a64c913-01dd-4ef1-bffc-d5ece08a93dc","reason":"canceled","price":"9104.61","remaining_size":"0.133"}
{"type":"heartbeat","last_trade_id":0,"product_id":"BTC-USD","sequence":180755908,"time":"2020-06-30T19:13:12.735112Z"}
{"type":"received","side":"sell","product_id":"BTC-USD","time":"2020-06-30T19:13:13.413032Z","sequence":180755909,"order_id":"2b0f4e57-b517-45f2-9660-2c9de1d6229f","order_type":"limit","size":"0.0691","price":"9147.85","client_oid":""}
{"type":"open","side":"sell","product_id":"BTC-USD","time":"2020-06-30T19:13:13.413032Z","sequence":180755910,"price":"9147.85","order_id":"2b0f4e57-b517-45f2-9660-2c9de1d6229f","remaining_size":"0.0691"}
{"type":"heartbeat","last_trade_id":0,"product_id":"BTC-USD","sequence":180755910,"time":"2020-06-30T19:13:13.735109Z"}
{"type":"received","side":"buy","product_id":"BTC-USD","time":"2020-06-30T19:13:13.979538Z","sequence":180755911,"order_id":"283c6e7c-ed13-4266-977e-ad62979d7ad7","order_type":"limit","size":"0.0285","price":"9078.87","client_oid":""}
{"type":"open","side":"buy","product_id":"BTC-USD","time":"2020-06-30T19:13:13.979538Z","sequence":180755912,"price":"9078.87","order_id":"283c6e7c-ed13-4266-977e-ad62979d7ad7","remaining_size":"0.0285"}
{"type":"received","side":"buy","product_id":"BTC-USD","time":"2020-06-30T19:13:14.023204Z","sequence":180755913,"order_id":"f9a31d35-7b3e-40f6-bd0a-b1cc2484e94a","order_type":"limit","size":"0.01","price":"100","client_oid":"f05141f4-0e4a-4937-b2fd-aef55e2b9f09"}
{"type":"open","side":"buy","product_id":"BTC-USD","time":"2020-06-30T19:13:14.023204Z","sequence":180755914,"price":"100","order_id":"f9a31d35-7b3e-40f6-bd0a-b1cc2484e94a","remaining_size":"0.01"}
{"type":"done","side":"buy","product_id":"BTC-USD","time":"2020-06-30T19:13:14.030729Z","sequence":180755915,"order_id":"f9a31d35-7b3e-40f6-bd0a-b1cc2484e94a","reason":"canceled","price":"100","remaining_size":"0.01"}
{"type":"done","side":"buy","product_id":"BTC-USD","time":"2020-06-30T19:13:14.356093Z","sequence":180755916,"order_id":"73a70550-b4cb-4e45-b742-a1dfa3fe48b6","reason":"canceled","price":"9085.26","remaining_size":"0.0283"}
{"type":"done","side":"buy","product_id":"BTC-USD","time":"2020-06-30T19:13:14.418716Z","sequence":180755917,"order_id":"7e280100-4407-4712-b293-64cab0dff28c","reason":"canceled","price":"9078.87","remaining_size":"0.0356"}
{"type":"done","side":"buy","product_id":"BTC-USD","time":"2020-06-30T19:13:14.421033Z","sequence":180755918,"order_id":"98a27131-32f1-42e9-85dc-b6ca756c235b","reason":"canceled","price":"9089.56","remaining_size":"0.7308"}
{"type":"heartbeat","last_trade_id":0,"product_id":"BTC-USD","sequence":180755918,"time":"2020-06-30T19:13:14.735119Z"}
{"type":"received","side":"sell","product_id":"BTC-USD","time":"2020-06-30T19:13:14.790713Z","sequence":180755919,"order_id":"ef592dbf-f398-479f-a3a0-474a728d0bdc","order_type":"limit","size":"1.645","price":"9100.57","client_oid":""}
{"type":"match","side":"buy","product_id":"BTC-USD","time":"2020-06-30T19:13:14.790713Z","sequence":180755920,"trade_id":14587492,"maker_order_id":"91b59a7c-6a07-4039-9536-21daf3cb3282","taker_order_id":"ef592dbf-f398-479f-a3a0-474a728d0bdc","size":"1.645","price":"9120.8"}
{"type":"done","side":"sell","product_id":"BTC-USD","time":"2020-06-30T19:13:14.790713Z","sequence":180755921,"order_id":"ef592dbf-f398-479f-a3a0-474a728d0bdc","reason":"filled","price":"9100.57","remaining_size":"0"}
{"type":"done","side":"sell","product_id":"BTC-USD","time":"2020-06-30T19:13:15.220210Z","sequence":180755922,"order_id":"2b9e6380-625f-450b-a5fc-bd9a5c2e75ab","reason":"canceled","price":"9128.9","remaining_size":"1.2189"}
{"type":"received","side":"sell","product_id":"BTC-USD","time":"2020-06-30T19:13:15.347762Z","sequence":180755923,"order_id":"73e35a8f-7ee6-4c35-aed5-dea551701898","order_type":"limit","size":"1.3144","price":"9111","client_oid":""}
{"type":"match","side":"buy","product_id":"BTC-USD","time":"2020-06-30T19:13:15.347762Z","sequence":180755924,"trade_id":14587493,"maker_order_id":"91b59a7c-6a07-4039-9536-21daf3cb3282","taker_order_id":"73e35a8f-7ee6-4c35-aed5-dea551701898","size":"1.3144","price":"9120.8"}
{"type":"done","side":"sell","product_id":"BTC-USD","time":"2020-06-30T19:13:15.347762Z","sequence":180755925,"order_id":"73e35a8f-7ee6-4c35-aed5-dea551701898","reason":"filled","price":"9111","remaining_size":"0"}
{"type":"heartbeat","last_trade_id":0,"product_id":"BTC-USD","sequence":180755925,"time":"2020-06-30T19:13:15.735112Z"}
{"type":"done","side":"sell","product_id":"BTC-USD","time":"2020-06-30T19:13:15.801205Z","sequence":180755926,"order_id":"2b0f4e57-b517-45f2-9660-2c9de1d6229f","reason":"canceled","price":"9147.85","remaining_size":"0.0691"}
{"type":"received","side":"sell","product_id":"BTC-USD","time":"2020-06-30T19:13:15.912655Z","sequence":180755927,"order_id":"0cb1d248-3f8c-4fbb-a4e4-c81eea0b6fda","order_type":"limit","size":"0.0691","price":"9142.83","client_oid":""}
{"type":"open","side":"sell","product_id":"BTC-USD","time":"2020-06-30T19:13:15.912655Z","sequence":180755928,"price":"9142.83","order_id":"0cb1d248-3f8c-4fbb-a4e4-c81eea0b6fda","remaining_size":"0.0691"}
{"type":"received","side":"sell","product_id":"BTC-USD","time":"2020-06-30T19:13:16.475182Z","sequence":180755929,"order_id":"460d26ea-0ba5-4709-ad70-ea45fde67d71","order_type":"limit","size":"0.0547","price":"9140.87","client_oid":""}
{"type":"open","side":"sell","product_id":"BTC-USD","time":"2020-06-30T19:13:16.475182Z","sequence":180755930,"price":"9140.87","order_id":"460d26ea-0ba5-4709-ad70-ea45fde67d71","remaining_size":"0.0547"}
{"type":"heartbeat","last_trade_id":0,"product_id":"BTC-USD","sequence":180755930,"time":"2020-06-30T19:13:16.735116Z"}
{"type":"received","side":"sell","product_id":"BTC-USD","time":"2020-06-30T19:13:17.296605Z","sequence":180755931,"order_id":"0866c9a7-ba97-4428-812e-b3956b9553f7","order_type":"limit","size":"45","price":"9135","client_oid":""}
{"type":"open","side":"sell","product_id":"BTC-USD","time":"2020-06-30T19:13:17.296605Z","sequence":180755932,"price":"9135","order_id":"0866c9a7-ba97-4428-812e-b3956b9553f7","remaining_size":"45"}
{"type":"done","side":"sell","product_id":"BTC-USD","time":"2020-06-30T19:13:17.722513Z","sequence":180755933,"order_id":"3f62d0fc-b897-4a9d-86a5-62e51b3c7b0e","reason":"canceled","price":"9156.07","remaining_size":"0.0964"}
{"type":"heartbeat","last_trade_id":0,"product_id":"BTC-USD","sequence":180755933,"time":"2020-06-30T19:13:17.735115Z"}
{"type":"received","side":"buy","product_id":"BTC-USD","time":"2020-06-30T19:13:18.431532Z","sequence":180755934,"order_id":"fc577c94-21e0-428e-ba21-2647d22be2ec","order_type":"limit","size":"0.088","price":"9041.22","client_oid":""}
{"type":"open","side":"buy","product_id":"BTC-USD","time":"2020-06-30T19:13:18.431532Z","sequence":180755935,"price":"9041.22","order_id":"fc577c94-21e0-428e-ba21-2647d22be2ec","remaining_size":"0.088"}
{"type":"received","side":"buy","product_id":"BTC-USD","time":"2020-06-30T19:13:18.699155Z","sequence":180755936,"order_id":"0bc5ac6f-807c-49e7-ac04-c2ba1793749c","order_type":"limit","size":"0.02","price":"9068.13","client_oid":""}
{"type":"open","side":"buy","product_id":"BTC-USD","time":"2020-06-30T19:13:18.699155Z","sequence":180755937,"price":"9068.13","order_id":"0bc5ac6f-807c-49e7-ac04-c2ba1793749c","remaining_size":"0.02"}
{"type":"heartbeat","last_trade_id":0,"product_id":"BTC-USD","sequence":180755937,"time":"2020-06-30T19:13:18.735119Z"}
{"type":"received","side":"sell","product_id":"BTC-USD","time":"2020-06-30T19:13:18.982320Z","sequence":180755938,"order_id":"a0953a58-d214-4580-8dd7-67ec35ac3e59","order_type":"limit","size":"4.9542","price":"9100","client_oid":""}
{"type":"match","side":"buy","product_id":"BTC-USD","time":"2020-06-30T19:13:18.982320Z","sequence":180755939,"trade_id":14587494,"maker_order_id":"91b59a7c-6a07-4039-9536-21daf3cb3282","taker_order_id":"a0953a58-d214-4580-8dd7-67ec35ac3e59","size":"4.9542","price":"9120.8"}
{"type":"done","side":"sell","product_id":"BTC-USD","time":"2020-06-30T19:13:18.982320Z","sequence":180755940,"order_id":"a0953a58-d214-4580-8dd7-67ec35ac3e59","reason":"filled","price":"9100","remaining_size":"0"}
{"type":"done","side":"buy","product_id":"BTC-USD","time":"2020-06-30T19:13:19.116616Z","sequence":180755941,"order_id":"e3f797e3-8535-4609-8e5c-dbce33d70c92","reason":"canceled","price":"9070.04","remaining_size":"0.0157"}
{"type":"done","side":"buy","product_id":"BTC-USD","time":"2020-06-30T19:13:19.117819Z","sequence":180755942,"order_id":"fc577c94-21e0-428e-ba21-2647d22be2ec","reason":"canceled","price":"9041.22","remaining_size":"0.088"}
{"type":"done","side":"buy","product_id":"BTC-USD","time":"2020-06-30T19:13:19.120881Z","sequence":180755943,"order_id":"e043453b-8a9f-4b13-bf5f-d5d7a6f8fe54","reason":"canceled","price":"9101.51","remaining_size":"0.0032"}
{"type":"received","side":"sell","product_id":"BTC-USD","time":"2020-06-30T19:13:19.267099Z","sequence":180755944,"order_id":"eca67175-b3e9-4b8f-b0c7-beb9a91030de","order_type":"limit","size":"0.4187","price":"9098.61","client_oid":""}
{"type":"match","side":"buy","product_id":"BTC-USD","time":"2020-06-30T19:13:19.267099Z","sequence":180755945,"trade_id":14587495,"maker_order_id":"91b59a7c-6a07-4039-9536-21daf3cb3282","taker_order_id":"eca67175-b3e9-4b8f-b0c7-beb9a91030de","size":"0.4187","price":"9120.8"}
{"type":"done","side":"sell","product_id":"BTC-USD","time":"2020-06-30T19:13:19.267099Z","sequence":180755946,"order_id":"eca67175-b3e9-4b8f-b0c7-beb9a91030de","reason":"filled","price":"9098.61","remaining_size":"0"}
{"type":"done","side":"sell","product_id":"BTC-USD","time":"2020-06-30T19:13:19.451407Z","sequence":180755947,"order_id":"460d26ea-0ba5-4709-ad70-ea45fde67d71","reason":"canceled","price":"9140.87","remaining_size":"0.0547"}
{"type":"heartbeat","last_trade_id":0,"product_id":"BTC-USD","sequence":180755947,"time":"2020-06-30T19:13:19.735113Z"}
{"type":"received","side":"buy","product_id":"BTC-USD","time":"2020-06-30T19:13:19.848002Z","sequence":180755948,"order_id":"27ce9adb-221c-4a1c-88c8-d95890b3bc92","order_type":"limit","size":"2.2905","price":"9091.7","client_oid":""}
{"type":"open","side":"buy","product_id":"BTC-USD","time":"2020-06-30T19:13:19.848002Z","sequence":180755949,"price":"9091.7","order_id":"27ce9adb-221c-4a1c-88c8-d95890b3bc92","remaining_size":"2.2905"}
{"type":"received","side":"sell","product_id":"BTC-USD","time":"2020-06-30T19:13:20.106139Z","sequence":180755950,"order_id":"09ea60c2-f710-4d75-9548-4cacc4c0a938","order_type":"limit","size":"0.15","price":"9108.14","client_oid":""}
{"type":"match","side":"buy","product_id":"BTC-USD","time":"2020-06-30T19:13:20.106139Z","sequence":180755951,"trade_id":14587496,"maker_order_id":"91b59a7c-6a07-4039-9536-21daf3cb3282","taker_order_id":"09ea60c2-f710-4d75-9548-4cacc4c0a938","size":"0.15","price":"9120.8"}
{"type":"done","side":"sell","product_id":"BTC-USD","time":"2020-06-30T19:13:20.106139Z","sequence":180755952,"order_id":"09ea60c2-f710-4d75-9548-4cacc4c0a938","reason":"filled","price":"9108.14","remaining_size":"0"}
{"type":"received","side":"sell","product_id":"BTC-USD","time":"2020-06-30T19:13:20.619062Z","sequence":180755953,"order_id":"9ff6cf62-f140-4a68-a1f4-83faa0316ac0","order_type":"limit","size":"0.0547","price":"9141.65","client_oid":""}
{"type":"open","side":"sell","product_id":"BTC-USD","time":"2020-06-30T19:13:20.619062Z","sequence":180755954,"price":"9141.65","order_id":"9ff6cf62-f140-4a68-a1f4-83faa0316ac0","remaining_size":"0.0547"}
{"type":"heartbeat","last_trade_id":0,"product_id":"BTC-USD","sequence":180755954,"time":"2020-06-30T19:13:20.735118Z"}
{"type":"received","side":"buy","product_id":"BTC-USD","time":"2020-06-30T19:13:20.922573Z","sequence":180755955,"order_id":"f3ea189e-a16f-4813-8735-8523c015cc00","order_type":"limit","size":"0.0283","price":"9086.71","client_oid":""}
{"type":"open","side":"buy","product_id":"BTC-USD","time":"2020-06-30T19:13:20.922573Z","sequence":180755956,"price":"9086.71","order_id":"f3ea189e-a16f-4813-8735-8523c015cc00","remaining_size":"0.0283"}
{"type":"done","side":"buy","product_id":"BTC-USD","time":"2020-06-30T19:13:21.338248Z","sequence":180755957,"order_id":"ec9d733c-af8b-492c-beeb-cfa1ad346588","reason":"canceled","price":"9098.27","remaining_size":"13.1992"}
{"type":"done","side":"buy","product_id":"BTC-USD","time":"2020-06-30T19:13:21.338329Z","sequence":180755958,"order_id":"986f2db5-fe2c-4bd5-a0ab-cf6cc2ad97b9","reason":"canceled","price":"9069.93","remaining_size":"0.0235"}
{"type":"done","side":"buy","product_id":"BTC-USD","time":"2020-06-30T19:13:21.350641Z","sequence":180755959,"order_id":"283c6e7c-ed13-4266-977e-ad62979d7ad7","reason":"canceled","price":"9078.87","remaining_size":"0.0285"}
{"type":"received","side":"buy","product_id":"BTC-USD","time":"2020-06-30T19:13:21.450718Z","sequence":180755960,"order_id":"26b4b326-b4b2-4e25-abcb-3f3f2ec059be","order_type":"limit","size":"3.65","price":"9100.79","client_oid":""}
{"type":"open","side":"buy","product_id":"BTC-USD","time":"2020-06-30T19:13:21.450718Z","sequence":180755961,"price":"9100.79","order_id":"26b4b326-b4b2-4e25-abcb-3f3f2ec059be","remaining_size":"3.65"}
{"type":"received","side":"buy","product_id":"BTC-USD","time":"2020-06-30T19:13:21.726100Z","sequence":180755962,"order_id":"d1bab5e0-8693-4f9b-9df3-d0ca0263d202","order_type":"limit","size":"3.7182","price":"9100.77","client_oid":""}
{"type":"open","side":"buy","product_id":"BTC-USD","time":"2020-06-30T19:13:21.726100Z","sequence":180755963,"price":"9100.77","order_id":"d1bab5e0-8693-4f9b-9df3-d0ca0263d202","remaining_size":"3.7182"}
{"type":"heartbeat","last_trade_id":0,"product_id":"BTC-USD","sequence":180755963,"time":"2020-06-30T19:13:21.735122Z"}
{"type":"received","side":"buy","product_id":"BTC-USD","time":"2020-06-30T19:13:21.996085Z","sequence":180755964,"order_id":"f763dde7-caa0-404b-9cb9-766544cb0595","order_type":"limit","size":"0.0328","price":"9080.1","client_oid":""}
{"type":"open","side":"buy","product_id":"BTC-USD","time":"2020-06-30T19:13:21.996085Z","sequence":180755965,"price":"9080.1","order_id":"f763dde7-caa0-404b-9cb9-766544cb0595","remaining_size":"0.0328"}
{"type":"heartbeat","last_trade_id":0,"product_id":"BTC-USD","sequence":180755965,"time":"2020-06-30T19:13:22.735117Z"}
{"type":"received","side":"sell","product_id":"BTC-USD","time":"2020-06-30T19:13:22.819990Z","sequence":180755966,"order_id":"3a3db76d-3b75-4a49-a4c3-a54b93aff333","order_type":"limit","size":"3.4266","price":"9106.49","client_oid":""}
{"type":"match","side":"buy","product_id":"BTC-USD","time":"2020-06-30T19:13:22.819990Z","sequence":180755967,"trade_id":14587497,"maker_order_id":"91b59a7c-6a07-4039-9536-21daf3cb3282","taker_order_id":"3a3db76d-3b75-4a49-a4c3-a54b93aff333","size":"3.4266","price":"9120.8"}
{"type":"done","side":"sell","product_id":"BTC-USD","time":"2020-06-30T19:13:22.819990Z","sequence":180755968,"order_id":"3a3db76d-3b75-4a49-a4c3-a54b93aff333","reason":"filled","price":"9106.49","remaining_size":"0"}
{"type":"done","side":"buy","product_id":"BTC-USD","time":"2020-06-30T19:13:23.016419Z","sequence":180755969,"order_id":"20909af1-d105-43f9-ba64-6ed7dc6dd45c","reason":"canceled","price":"9074.75","remaining_size":"0.0689"}
{"type":"done","side":"buy","product_id":"BTC-USD","time":"2020-06-30T19:13:23.524966Z","sequence":180755970,"order_id":"0bc5ac6f-807c-49e7-ac04-c2ba1793749c","reason":"canceled","price":"9068.13","remaining_size":"0.02"}
{"type":"heartbeat","last_trade_id":0,"product_id":"BTC-USD","sequence":180755970,"time":"2020-06-30T19:13:23.735117Z"}
{"type":"received","side":"buy","product_id":"BTC-USD","time":"2020-06-30T19:13:24.529808Z","sequence":180755971,"order_id":"54b6cbd3-e925-4a41-beac-d21cd048a877","order_type":"limit","size":"3.1449","price":"9100.81","client_oid":""}
{"type":"open","side":"buy","product_id":"BTC-USD","time":"2020-06-30T19:13:24.529808Z","sequence":180755972,"price":"9100.81","order_id":"54b6cbd3-e925-4a41-beac-d21cd048a877","remaining_size":"3.1449"}
{"type":"heartbeat","last_trade_id":0,"product_id":"BTC-USD","sequence":180755972,"time":"2020-06-30T19:13:24.735112Z"}
{"type":"received","side":"sell","product_id":"BTC-USD","time":"2020-06-30T19:13:25.375048Z","sequence":180755973,"order_id":"49ded3ea-8192-41fa-bcbc-93f8010638ba","order_type":"limit","size":"0.0691","price":"9148.24","client_oid":""}
{"type":"open","side":"sell","product_id":"BTC-USD","time":"2020-06-30T19:13:25.375048Z","sequence":180755974,"price":"9148.24","order_id":"49ded3ea-8192-41fa-bcbc-93f8010638ba","remaining_size":"0.0691"}
{"type":"received","side":"sell","product_id":"BTC-USD","time":"2020-06-30T19:13:25.637876Z","sequence":180755975,"order_id":"dd3bb524-82b2-493a-83f3-3023ed177f01","order_type":"limit","size":"0.0691","price":"9147.42","client_oid":""}
{"type":"open","side":"sell","product_id":"BTC-USD","time":"2020-06-30T19:13:25.637876Z","sequence":180755976,"price":"9147.42","order_id":"dd3bb524-82b2-493a-83f3-3023ed177f01","remaining_size":"0.0691"}
{"type":"heartbeat","last_trade_id":0,"product_id":"BTC-USD","sequence":180755976,"time":"2020-06-30T19:13:25.735119Z"}
{"type":"done","side":"sell","product_id":"BTC-USD","time":"2020-06-30T19:13:26.078485Z","sequence":180755977,"order_id":"5d718d45-e416-4482-b8cb-ec13f8091954","reason":"canceled","price":"9161.08","remaining_size":"0.069"}
{"type":"received","side":"sell","product_id":"BTC-USD","time":"2020-06-30T19:13:26.200647Z","sequence":180755978,"order_id":"ddad9efb-7a18-4e2c-b87b-ef5194bed7de","order_type":"limit","size":"3.265","price":"9132.67","client_oid":""}
{"type":"open","side":"sell","product_id":"BTC-USD","time":"2020-06-30T19:13:26.200647Z","sequence":180755979,"price":"9132.67","order_id":"ddad9efb-7a18-4e2c-b87b-ef5194bed7de","remaining_size":"3.265"}
{"type":"done","side":"sell","product_id":"BTC-USD","time":"2020-06-30T19:13:26.346452Z","sequence":180755980,"order_id":"49ded3ea-8192-41fa-bcbc-93f8010638ba","reason":"canceled","price":"9148.24","remaining_size":"0.0691"}
{"type":"done","side":"sell","product_id":"BTC-USD","time":"2020-06-30T19:13:26.356349Z","sequence":180755981,"order_id":"0866c9a7-ba97-4428-812e-b3956b9553f7","reason":"canceled","price":"9135","remaining_size":"45"}
{"type":"received","side":"sell","product_id":"BTC-USD","time":"2020-06-30T19:13:26.730509Z","sequence":180755982,"order_id":"2acf3ed9-14c1-4c3b-a036-90ef8ee709b2","order_type":"limit","size":"0.9","price":"9104.42","client_oid":""}
{"type":"match","side":"buy","product_id":"BTC-USD","time":"2020-06-30T19:13:26.730509Z","sequence":180755983,"trade_id":14587498,"maker_order_id":"91b59a7c-6a07-4039-9536-21daf3cb3282","taker_order_id":"2acf3ed9-14c1-4c3b-a036-90ef8ee709b2","size":"0.9","price":"9120.8"}
{"type":"done","side":"sell","product_id":"BTC-USD","time":"2020-06-30T19:13:26.730509Z","sequence":180755984,"order_id":"2acf3ed9-14c1-4c3b-a036-90ef8ee709b2","reason":"filled","price":"9104.42","remaining_size":"0"}
{"type":"heartbeat","last_trade_id":0,"product_id":"BTC-USD","sequence":180755984,"time":"2020-06-30T19:13:26.735117Z"}
{"type":"received","side":"sell","product_id":"BTC-USD","time":"2020-06-30T19:13:27.572531Z","sequence":180755985,"order_id":"f21cb164-f11f-466f-b705-b9f9c2b3e63c","order_type":"limit","size":"0.0691","price":"9143.91","client_oid":""}
{"type":"open","side":"sell","product_id":"BTC-USD","time":"2020-06-30T19:13:27.572531Z","sequence":180755986,"price":"9143.91","order_id":"f21cb164-f11f-466f-b705-b9f9c2b3e63c","remaining_size":"0.0691"}
{"type":"heartbeat","last_trade_id":0,"product_id":"BTC-USD","sequence":180755986,"time":"2020-06-30T19:13:27.735116Z"}
{"type":"received","side":"sell","product_id":"BTC-USD","time":"2020-06-30T19:13:28.115389Z","sequence":180755987,"order_id":"7fac3ec1-75c6-49c9-a716-05276d398569","order_type":"limit","size":"3.999","price":"9115.36","client_oid":""}
{"type":"match","side":"buy","product_id":"BTC-USD","time":"2020-06-30T19:13:28.115389Z","sequence":180755988,"trade_id":14587499,"maker_order_id":"91b59a7c-6a07-4039-9536-21daf3cb3282","taker_order_id":"7fac3ec1-75c6-49c9-a716-05276d398569","size":"3.999","price":"9120.8"}
{"type":"done","side":"sell","product_id":"BTC-USD","time":"2020-06-30T19:13:28.115389Z","sequence":180755989,"order_id":"7fac3ec1-75c6-49c9-a716-05276d398569","reason":"filled","price":"9115.36","remaining_size":"0"}
{"type":"received","side":"buy","product_id":"BTC-USD","time":"2020-06-30T19:13:28.677601Z","sequence":180755990,"order_id":"070e73cf-6746-4262-aa74-bc9ca78d9e8f","order_type":"limit","size":"0.1126","price":"9101.31","client_oid":""}
{"type":"open","side":"buy","product_id":"BTC-USD","time":"2020-06-30T19:13:28.677601Z","sequence":180755991,"price":"9101.31","order_id":"070e73cf-6746-4262-aa74-bc9ca78d9e8f","remaining_size":"0.1126"}
{"type":"heartbeat","last_trade_id":0,"product_id":"BTC-USD","sequence":180755991,"time":"2020-06-30T19:13:28.735117Z"}
{"type":"received","side":"buy","product_id":"BTC-USD","time":"2020-06-30T19:13:29.019387Z","sequence":180755992,"order_id":"c75c481c-9b4d-4b3d-ba7a-8e4e21672387","order_type":"limit","size":"0.01","price":"100","client_oid":"0d9d9b29-e172-4d5c-b245-331fd6f79901"}
{"type":"open","side":"buy","product_id":"BTC-USD","time":"2020-06-30T19:13:29.019387Z","sequence":180755993,"price":"100","order_id":"c75c481c-9b4d-4b3d-ba7a-8e4e21672387","remaining_size":"0.01"}
{"type":"done","side":"buy","product_id":"BTC-USD","time":"2020-06-30T19:13:29.028812Z","sequence":180755994,"order_id":"c75c481c-9b4d-4b3d-ba7a-8e4e21672387","reason":"canceled","price":"100","remaining_size":"0.01"}
{"type":"received","side":"sell","product_id":"BTC-USD","time":"2020-06-30T19:13:29.482472Z","sequence":180755995,"order_id":"f54931f3-7e77-46e9-8f3b-ed985f6a284e","order_type":"limit","size":"1.9894","price":"9109.52","client_oid":""}
{"type":"match","side":"buy","product_id":"BTC-USD","time":"2020-06-30T19:13:29.482472Z","sequence":180755996,"trade_id":14587500,"maker_order_id":"91b59a7c-6a07-4039-9536-21daf3cb3282","taker_order_id":"f54931f3-7e77-46e9-8f3b-ed985f6a284e","size":"1.9894","price":"9120.8"}
{"type":"done","side":"sell","product_id":"BTC-USD","time":"2020-06-30T19:13:29.482472Z","sequence":180755997,"order_id":"f54931f3-7e77-46e9-8f3b-ed985f6a284e","reason":"filled","price":"9109.52","remaining_size":"0"}
{"type":"heartbeat","last_trade_id":0,"product_id":"BTC-USD","sequence":180755997,"time":"2020-06-30T19:13:29.735115Z"}
{"type":"done","side":"sell","product_id":"BTC-USD","time":"2020-06-30T19:13:29.899559Z","sequence":180755998,"order_id":"e60a9628-ba77-45b5-a6a8-ff39c22fcbba","reason":"canceled","price":"9177.67","remaining_size":"0.1"}
{"type":"received","side":"buy","product_id":"BTC-USD","time":"2020-06-30T19:13:30.046651Z","sequence":180755999,"order_id":"e09f7027-1877-4f2f-9042-4f984b6269ba","order_type":"limit","size":"0.5","price":"9103.86","client_oid":""}
{"type":"open","side":"buy","product_id":"BTC-USD","time":"2020-06-30T19:13:30.046651Z","sequence":180756000,"price":"9103.86","order_id":"e09f7027-1877-4f2f-9042-4f984b6269ba","remaining_size":"0.5"}
{"type":"received","side":"sell","product_id":"BTC-USD","time":"2020-06-30T19:13:30.306685Z","sequence":180756001,"order_id":"f274caf8-94ae-448d-a9ef-66b1b23586bf","order_type":"limit","size":"0.05","price":"9109.18","client_oid":""}
{"type":"match","side":"buy","product_id":"BTC-USD","time":"2020-06-30T19:13:30.306685Z","sequence":180756002,"trade_id":14587501,"maker_order_id":"91b59a7c-6a07-4039-9536-21daf3cb3282","taker_order_id":"f274caf8-94ae-448d-a9ef-66b1b23586bf","size":"0.05","price":"9120.8"}
{"type":"done","side":"sell","product_id":"BTC-USD","time":"2020-06-30T19:13:30.306685Z","sequence":180756003,"order_id":"f274caf8-94ae-448d-a9ef-66b1b23586bf","reason":"filled","price":"9109.18","remaining_size":"0"}
{"type":"done","side":"buy","product_id":"BTC-USD","time":"2020-06-30T19:13:30.500347Z","sequence":180756004,"order_id":"3da33c77-8c94-45ec-b50e-c2390d03ae62","reason":"canceled","price":"9074.26","remaining_size":"0.125"}
{"type":"heartbeat","last_trade_id":0,"product_id":"BTC-USD","sequence":180756004,"time":"2020-06-30T19:13:30.735111Z"}
{"type":"received","side":"sell","product_id":"BTC-USD","time":"2020-06-30T19:13:31.149289Z","sequence":180756005,"order_id":"fc202a72-1c37-4627-a166-8a2f86771894","order_type":"limit","size":"0.05","price":"9109.12","client_oid":""}
{"type":"match","side":"buy","product_id":"BTC-USD","time":"2020-06-30T19:13:31.149289Z","sequence":180756006,"trade_id":14587502,"maker_order_id":"91b59a7c-6a07-4039-9536-21daf3cb3282","taker_order_id":"fc202a72-1c37-4627-a166-8a2f86771894","size":"0.05","price":"9120.8"}
{"type":"done","side":"sell","product_id":"BTC-USD","time":"2020-06-30T19:13:31.149289Z","sequence":180756007,"order_id":"fc202a72-1c37-4627-a166-8a2f86771894","reason":"filled","price":"9109.12","remaining_size":"0"}
{"type":"received","side":"buy","product_id":"BTC-USD","time":"2020-06-30T19:13:31.425196Z","sequence":180756008,"order_id":"ccb2f267-e1a8-42c3-923a-fc961a3f319d","order_type":"limit","size":"1.122","price":"9098.27","client_oid":""}
{"type":"open","side":"buy","product_id":"BTC-USD","time":"2020-06-30T19:13:31.425196Z","sequence":180756009,"price":"9098.27","order_id":"ccb2f267-e1a8-42c3-923a-fc961a3f319d","remaining_size":"1.122"}
{"type":"heartbeat","last_trade_id":0,"product_id":"BTC-USD","sequence":180756009,"time":"2020-06-30T19:13:31.735112Z"}
{"type":"done","side":"buy","product_id":"BTC-USD","time":"2020-06-30T19:13:31.905365Z","sequence":180756010,"order_id":"d8c19c79-5a78-42d6-813e-70fadb8dce2b","reason":"canceled","price":"9092.39","remaining_size":"0.3299"}
{"type":"received","side":"buy","product_id":"BTC-USD","time":"2020-06-30T19:13:32.543112Z","sequence":180756011,"order_id":"bae23e5c-b2e3-465d-86de-b3de14695bc7","order_type":"limit","size":"0.1213","price":"9085.4","client_oid":""}
{"type":"open","side":"buy","product_id":"BTC-USD","time":"2020-06-30T19:13:32.543112Z","sequence":180756012,"price":"9085.4","order_id":"bae23e5c-b2e3-465d-86de-b3de14695bc7","remaining_size":"0.1213"}
{"type":"heartbeat","last_trade_id":0,"product_id":"BTC-USD","sequence":180756012,"time":"2020-06-30T19:13:32.735108Z"}
{"type":"received","side":"sell","product_id":"BTC-USD","time":"2020-06-30T19:13:33.399177Z","sequence":180756013,"order_id":"8a3cdaee-cfdc-4a03-b733-ed80e0557908","order_type":"limit","size":"0.285","price":"9111.07","client_oid":""}
{"type":"match","side":"buy","product_id":"BTC-USD","time":"2020-06-30T19:13:33.399177Z","sequence":180756014,"trade_id":14587503,"maker_order_id":"91b59a7c-6a07-4039-9536-21daf3cb3282","taker_order_id":"8a3cdaee-cfdc-4a03-b733-ed80e0557908","size":"0.285","price":"9120.8"}
{"type":"done","side":"sell","product_id":"BTC-USD","time":"2020-06-30T19:13:33.399177Z","sequence":180756015,"order_id":"8a3cdaee-cfdc-4a03-b733-ed80e0557908","reason":"filled","price":"9111.07","remaining_size":"0"}
{"type":"received","side":"sell","product_id":"BTC-USD","time":"2020-06-30T19:13:33.653202Z","sequence":180756016,"order_id":"51c1b6a4-ca93-47d6-8d22-44153cbe4a74","order_type":"limit","size":"0.0659","price":"9110.48","client_oid":""}
{"type":"match","side":"buy","product_id":"BTC-USD","time":"2020-06-30T19:13:33.653202Z","sequence":180756017,"trade_id":14587504,"maker_order_id":"91b59a7c-6a07-4039-9536-21daf3cb3282","taker_order_id":"51c1b6a4-ca93-47d6-8d22-44153cbe4a74","size":"0.0659","price":"9120.8"}
{"type":"done","side":"sell","product_id":"BTC-USD","time":"2020-06-30T19:13:33.653202Z","sequence":180756018,"order_id":"51c1b6a4-ca93-47d6-8d22-44153cbe4a74","reason":"filled","price":"9110.48","remaining_size":"0"}
{"type":"heartbeat","last_trade_id":0,"product_id":"BTC-USD","sequence":180756018,"time":"2020-06-30T19:13:33.735120Z"}
{"type":"done","side":"sell","product_id":"BTC-USD","time":"2020-06-30T19:13:33.841668Z","sequence":180756019,"order_id":"dd3bb524-82b2-493a-83f3-3023ed177f01","reason":"canceled","price":"9147.42","remaining_size":"0.0691"}
{"type":"done","side":"sell","product_id":"BTC-USD","time":"2020-06-30T19:13:33.904185Z","sequence":180756020,"order_id":"9ff6cf62-f140-4a68-a1f4-83faa0316ac0","reason":"canceled","price":"9141.65","remaining_size":"0.0547"}
{"type":"received","side":"sell","product_id":"BTC-USD","time":"2020-06-30T19:13:33.958661Z","sequence":180756021,"order_id":"c9729346-5759-4f05-8185-38f915582904","order_type":"limit","size":"0.9","price":"9110.18","client_oid":""}
{"type":"match","side":"buy","product_id":"BTC-USD","time":"2020-06-30T19:13:33.958661Z","sequence":180756022,"trade_id":14587505,"maker_order_id":"91b59a7c-6a07-4039-9536-21daf3cb3282","taker_order_id":"c9729346-5759-4f05-8185-38f915582904","size":"0.9","price":"9120.8"}
{"type":"done","side":"sell","product_id":"BTC-USD","time":"2020-06-30T19:13:33.958661Z","sequence":180756023,"order_id":"c9729346-5759-4f05-8185-38f915582904","reason":"filled","price":"9110.18","remaining_size":"0"}
{"type":"done","side":"sell","product_id":"BTC-USD","time":"2020-06-30T19:13:34.109755Z","sequence":180756024,"order_id":"0cb1d248-3f8c-4fbb-a4e4-c81eea0b6fda","reason":"canceled","price":"9142.83","remaining_size":"0.0691"}
{"type":"received","side":"buy","product_id":"BTC-USD","time":"2020-06-30T19:13:34.203979Z","sequence":180756025,"order_id":"eb3fb2e6-cb4e-416d-9ad1-6ccd02d0089a","order_type":"limit","size":"18.5746","price":"9105.5","client_oid":""}
{"type":"open","side":"buy","product_id":"BTC-USD","time":"2020-06-30T19:13:34.203979Z","sequence":180756026,"price":"9105.5","order_id":"eb3fb2e6-cb4e-416d-9ad1-6ccd02d0089a","remaining_size":"18.5746"}
{"type":"done","side":"sell","product_id":"BTC-USD","time":"2020-06-30T19:13:34.387713Z","sequence":180756027,"order_id":"bab320c6-b132-47d3-8c3a-990e6db01517","reason":"canceled","price":"9128.65","remaining_size":"0.0296"}
{"type":"done","side":"buy","product_id":"BTC-USD","time":"2020-06-30T19:13:34.637532Z","sequence":180756028,"order_id":"d1bab5e0-8693-4f9b-9df3-d0ca0263d202","reason":"canceled","price":"9100.77","remaining_size":"3.7182"}
{"type":"done","side":"buy","product_id":"BTC-USD","time":"2020-06-30T19:13:34.643443Z","sequence":180756029,"order_id":"f763dde7-caa0-404b-9cb9-766544cb0595","reason":"canceled","price":"9080.1","remaining_size":"0.0328"}
{"type":"done","side":"buy","product_id":"BTC-USD","time":"2020-06-30T19:13:34.643452Z","sequence":180756030,"order_id":"070e73cf-6746-4262-aa74-bc9ca78d9e8f","reason":"canceled","price":"9101.31","remaining_size":"0.1126"}
{"type":"heartbeat","last_trade_id":0,"product_id":"BTC-USD","sequence":180756030,"time":"2020-06-30T19:13:34.735114Z"}
{"type":"received","side":"buy","product_id":"BTC-USD","time":"2020-06-30T19:13:34.759030Z","sequence":180756031,"order_id":"478ec4fe-ebaf-4cf9-95a9-0a82bc10fe03","order_type":"limit","size":"0.0235","price":"9069.48","client_oid":""}
{"type":"open","side":"buy","product_id":"BTC-USD","time":"2020-06-30T19:13:34.759030Z","sequence":180756032,"price":"9069.48","order_id":"478ec4fe-ebaf-4cf9-95a9-0a82bc10fe03","remaining_size":"0.0235"}
{"type":"received","side":"sell","product_id":"BTC-USD","time":"2020-06-30T19:13:35.019851Z","sequence":180756033,"order_id":"f4d7910a-3643-432a-9dca-865635029324","order_type":"limit","size":"0.1","price":"9175.49","client_oid":""}
{"type":"open","side":"sell","product_id":"BTC-USD","time":"2020-06-30T19:13:35.019851Z","sequence":180756034,"price":"9175.49","order_id":"f4d7910a-3643-432a-9dca-865635029324","remaining_size":"0.1"}
{"type":"received","side":"buy","product_id":"BTC-USD","time":"2020-06-30T19:13:35.292883Z","sequence":180756035,"order_id":"fe6f97b3-1cfe-4361-b991-a0872569cb51","order_type":"limit","size":"0.0533","price":"9086.59","client_oid":""}
{"type":"open","side":"buy","product_id":"BTC-USD","time":"2020-06-30T19:13:35.292883Z","sequence":180756036,"price":"9086.59","order_id":"fe6f97b3-1cfe-4361-b991-a0872569cb51","remaining_size":"0.0533"}
{"type":"received","side":"buy","product_id":"BTC-USD","time":"2020-06-30T19:13:35.570781Z","sequence":180756037,"order_id":"47df50d1-abd3-4239-9b2d-59c04383bfed","order_type":"limit","size":"0.0519","price":"9087.82","client_oid":""}
{"type":"open","side":"buy","product_id":"BTC-USD","time":"2020-06-30T19:13:35.570781Z","sequence":180756038,"price":"9087.82","order_id":"47df50d1-abd3-4239-9b2d-59c04383bfed","remaining_size":"0.0519"}
{"type":"heartbeat","last_trade_id":0,"product_id":"BTC-USD","sequence":180756038,"time":"2020-06-30T19:13:35.735106Z"}
{"type":"received","side":"buy","product_id":"BTC-USD","time":"2020-06-30T19:13:35.846353Z","sequence":180756039,"order_id":"ce2b001d-5ea4-47d6-a5eb-4a91cf507d12","order_type":"limit","size":"18.011","price":"9105.5","client_oid":""}
{"type":"open","side":"buy","product_id":"BTC-USD","time":"2020-06-30T19:13:35.846353Z","sequence":180756040,"price":"9105.5","order_id":"ce2b001d-5ea4-47d6-a5eb-4a91cf507d12","remaining_size":"18.011"}
{"type":"received","side":"buy","product_id":"BTC-USD","time":"2020-06-30T19:13:36.120019Z","sequence":180756041,"order_id":"4f647110-58cc-4573-8eda-218fdb4163c9","order_type":"limit","size":"13.911","price":"9105.5","client_oid":""}
{"type":"open","side":"buy","product_id":"BTC-USD","time":"2020-06-30T19:13:36.120019Z","sequence":180756042,"price":"9105.5","order_id":"4f647110-58cc-4573-8eda-218fdb4163c9","remaining_size":"13.911"}
{"type":"received","side":"sell","product_id":"BTC-USD","time":"2020-06-30T19:13:36.396973Z","sequence":180756043,"order_id":"fcd0f47e-ab74-4051-a4ad-58aebe2ae6f1","order_type":"limit","size":"1.0099","price":"9107.98","client_oid":""}
{"type":"match","side":"buy","product_id":"BTC-USD","time":"2020-06-30T19:13:36.396973Z","sequence":180756044,"trade_id":14587506,"maker_order_id":"91b59a7c-6a07-4039-9536-21daf3cb3282","taker_order_id":"fcd0f47e-ab74-4051-a4ad-58aebe2ae6f1","size":"1.0099","price":"9120.8"}
{"type":"done","side":"sell","product_id":"BTC-USD","time":"2020-06-30T19:13:36.396973Z","sequence":180756045,"order_id":"fcd0f47e-ab74-4051-a4ad-58aebe2ae6f1","reason":"filled","price":"9107.98","remaining_size":"0"}
{"type":"received","side":"buy","product_id":"BTC-USD","time":"2020-06-30T19:13:36.663713Z","sequence":180756046,"order_id":"bd461a8f-fca1-4f65-a72d-166825904880","order_type":"limit","size":"0.3439","price":"9081.72","client_oid":""}
{"type":"open","side":"buy","product_id":"BTC-USD","time":"2020-06-30T19:13:36.663713Z","sequence":180756047,"price":"9081.72","order_id":"bd461a8f-fca1-4f65-a72d-166825904880","remaining_size":"0.3439"}
{"type":"heartbeat","last_trade_id":0,"product_id":"BTC-USD","sequence":180756047,"time":"2020-06-30T19:13:36.735091Z"}
{"type":"done","side":"buy","product_id":"BTC-USD","time":"2020-06-30T19:13:37.106482Z","sequence":180756048,"order_id":"478ec4fe-ebaf-4cf9-95a9-0a82bc10fe03","reason":"canceled","price":"9069.48","remaining_size":"0.0235"}
{"type":"heartbeat","last_trade_id":0,"product_id":"BTC-USD","sequence":180756048,"time":"2020-06-30T19:13:37.735115Z"}
{"type":"received","side":"buy","product_id":"BTC-USD","time":"2020-06-30T19:13:37.787409Z","sequence":180756049,"order_id":"fcc05e38-ff4e-4ce4-a3a1-fcf18dcca305","order_type":"limit","size":"0.7277","price":"9094.06","client_oid":""}
{"type":"open","side":"buy","product_id":"BTC-USD","time":"2020-06-30T19:13:37.787409Z","sequence":180756050,"price":"9094.06","order_id":"fcc05e38-ff4e-4ce4-a3a1-fcf18dcca305","remaining_size":"0.7277"}
{"type":"received","side":"buy","product_id":"BTC-USD","time":"2020-06-30T19:13:38.064555Z","sequence":180756051,"order_id":"a1fba462-fce3-4333-a2b9-a76ada75742c","order_type":"limit","size":"17.061","price":"9105.5","client_oid":""}
{"type":"open","side":"buy","product_id":"BTC-USD","time":"2020-06-30T19:13:38.064555Z","sequence":180756052,"price":"9105.5","order_id":"a1fba462-fce3-4333-a2b9-a76ada75742c","remaining_size":"17.061"}
{"type":"done","side":"buy","product_id":"BTC-USD","time":"2020-06-30T19:13:38.229871Z","sequence":180756053,"order_id":"26b4b326-b4b2-4e25-abcb-3f3f2ec059be","reason":"canceled","price":"9100.79","remaining_size":"3.65"}
{"type":"received","side":"sell","product_id":"BTC-USD","time":"2020-06-30T19:13:38.617537Z","sequence":180756054,"order_id":"7b01d394-5660-4d19-ad7c-460e0c3dfc3e","order_type":"limit","size":"0.0691","price":"9151.48","client_oid":""}
{"type":"open","side":"sell","product_id":"BTC-USD","time":"2020-06-30T19:13:38.617537Z","sequence":180756055,"price":"9151.48","order_id":"7b01d394-5660-4d19-ad7c-460e0c3dfc3e","remaining_size":"0.0691"}
{"type":"heartbeat","last_trade_id":0,"product_id":"BTC-USD","sequence":180756055,"time":"2020-06-30T19:13:38.735112Z"}
{"type":"received","side":"sell","product_id":"BTC-USD","time":"2020-06-30T19:13:38.953494Z","sequence":180756056,"order_id":"13d2dcd3-d8ed-493e-bc71-35600c57168a","order_type":"limit","size":"0.0582","price":"9181.63","client_oid":""}
{"type":"open","side":"sell","product_id":"BTC-USD","time":"2020-06-30T19:13:38.953494Z","sequence":180756057,"price":"9181.63","order_id":"13d2dcd3-d8ed-493e-bc71-35600c57168a","remaining_size":"0.0582"}
{"type":"received","side":"sell","product_id":"BTC-USD","time":"2020-06-30T19:13:39.497135Z","sequence":180756058,"order_id":"ad264542-bd7e-4aba-914a-e038f0e1fc33","order_type":"limit","size":"1.0393","price":"9138.72","client_oid":""}
{"type":"open","side":"sell","product_id":"BTC-USD","time":"2020-06-30T19:13:39.497135Z","sequence":180756059,"price":"9138.72","order_id":"ad264542-bd7e-4aba-914a-e038f0e1fc33","remaining_size":"1.0393"}
{"type":"heartbeat","last_trade_id":0,"product_id":"BTC-USD","sequence":180756059,"time":"2020-06-30T19:13:39.735069Z"}
{"type":"done","side":"sell","product_id":"BTC-USD","time":"2020-06-30T19:13:39.924164Z","sequence":180756060,"order_id":"ddad9efb-7a18-4e2c-b87b-ef5194bed7de","reason":"canceled","price":"9132.67","remaining_size":"3.265"}
{"type":"received","side":"sell","product_id":"BTC-USD","time":"2020-06-30T19:13:40.056410Z","sequence":180756061,"order_id":"37ab1f6c-5a23-4c41-bb72-5e404a53f19e","order_type":"limit","size":"0.0659","price":"9110.52","client_oid":""}
{"type":"match","side":"buy","product_id":"BTC-USD","time":"2020-06-30T19:13:40.056410Z","sequence":180756062,"trade_id":14587507,"maker_order_id":"91b59a7c-6a07-4039-9536-21daf3cb3282","taker_order_id":"37ab1f6c-5a23-4c41-bb72-5e404a53f19e","size":"0.0659","price":"9120.8"}
{"type":"done","side":"sell","product_id":"BTC-USD","time":"2020-06-30T19:13:40.056410Z","sequence":180756063,"order_id":"37ab1f6c-5a23-4c41-bb72-5e404a53f19e","reason":"filled","price":"9110.52","remaining_size":"0"}
{"type":"received","side":"sell","product_id":"BTC-USD","time":"2020-06-30T19:13:40.322481Z","sequence":180756064,"order_id":"e857f517-a2d4-4e69-8bfc-37cfc40aaa2c","order_type":"limit","size":"0.0659","price":"9110.44","client_oid":""}
{"type":"match","side":"buy","product_id":"BTC-USD","time":"2020-06-30T19:13:40.322481Z","sequence":180756065,"trade_id":14587508,"maker_order_id":"91b59a7c-6a07-4039-9536-21daf3cb3282","taker_order_id":"e857f517-a2d4-4e69-8bfc-37cfc40aaa2c","size":"0.0659","price":"9120.8"}
{"type":"done","side":"sell","product_id":"BTC-USD","time":"2020-06-30T19:13:40.322481Z","sequence":180756066,"order_id":"e857f517-a2d4-4e69-8bfc-37cfc40aaa2c","reason":"filled","price":"9110.44","remaining_size":"0"}
{"type":"done","side":"sell","product_id":"BTC-USD","time":"2020-06-30T19:13:40.511066Z","sequence":180756067,"order_id":"7b01d394-5660-4d19-ad7c-460e0c3dfc3e","reason":"canceled","price":"9151.48","remaining_size":"0.0691"}
{"type":"received","side":"sell","product_id":"BTC-USD","time":"2020-06-30T19:13:40.597071Z","sequence":180756068,"order_id":"0be78577-9238-4a76-9e46-b3336ec0b4ba","order_type":"limit","size":"0.045","price":"9135.74","client_oid":""}
{"type":"open","side":"sell","product_id":"BTC-USD","time":"2020-06-30T19:13:40.597071Z","sequence":180756069,"price":"9135.74","order_id":"0be78577-9238-4a76-9e46-b3336ec0b4ba","remaining_size":"0.045"}
{"type":"heartbeat","last_trade_id":0,"product_id":"BTC-USD","sequence":180756069,"time":"2020-06-30T19:13:40.735091Z"}
{"type":"done","side":"sell","product_id":"BTC-USD","time":"2020-06-30T19:13:41.033674Z","sequence":180756070,"order_id":"f4d7910a-3643-432a-9dca-865635029324","reason":"canceled","price":"9175.49","remaining_size":"0.1"}
{"type":"received","side":"sell","product_id":"BTC-USD","time":"2020-06-30T19:13:41.147058Z","sequence":180756071,"order_id":"e60c5235-0da1-45e2-8887-52661e7157ac","order_type":"limit","size":"0.05","price":"9107.43","client_oid":""}
{"type":"match","side":"buy","product_id":"BTC-USD","time":"2020-06-30T19:13:41.147058Z","sequence":180756072,"trade_id":14587509,"maker_order_id":"91b59a7c-6a07-4039-9536-21daf3cb3282","taker_order_id":"e60c5235-0da1-45e2-8887-52661e7157ac","size":"0.05","price":"9120.8"}
{"type":"done","side":"sell","product_id":"BTC-USD","time":"2020-06-30T19:13:41.147058Z","sequence":180756073,"order_id":"e60c5235-0da1-45e2-8887-52661e7157ac","reason":"filled","price":"9107.43","remaining_size":"0"}
{"type":"received","side":"buy","product_id":"BTC-USD","time":"2020-06-30T19:13:41.270741Z","sequence":180756074,"order_id":"c9a28e51-3a76-4a8b-aac7-8f272d0816b7","order_type":"market","size":"0.001","funds":"9.12082","client_oid":""}
{"type":"match","side":"sell","product_id":"BTC-USD","time":"2020-06-30T19:13:41.270741Z","sequence":180756075,"trade_id":14587510,"maker_order_id":"36fe0734-4801-466d-b093-cccd411db09a","taker_order_id":"c9a28e51-3a76-4a8b-aac7-8f272d0816b7","size":"0.001","price":"9120.82"}
{"type":"done","side":"buy","product_id":"BTC-USD","time":"2020-06-30T19:13:41.270741Z","sequence":180756076,"order_id":"c9a28e51-3a76-4a8b-aac7-8f272d0816b7","reason":"filled","remaining_size":"0"}
{"type":"received","side":"sell","product_id":"BTC-USD","time":"2020-06-30T19:13:41.414959Z","sequence":180756077,"order_id":"d279ceb0-2f57-4df4-92e4-ddb22504791b","order_type":"limit","size":"1.1363","price":"9133.56","client_oid":""}
{"type":"open","side":"sell","product_id":"BTC-USD","time":"2020-06-30T19:13:41.414959Z","sequence":180756078,"price":"9133.56","order_id":"d279ceb0-2f57-4df4-92e4-ddb22504791b","remaining_size":"1.1363"}
{"type":"received","side":"buy","product_id":"BTC-USD","time":"2020-06-30T19:13:41.696726Z","sequence":180756079,"order_id":"6fb9e748-0fa1-407f-9ea8-381151207869","order_type":"limit","size":"16.4964","price":"9105.5","client_oid":""}
{"type":"open","side":"buy","product_id":"BTC-USD","time":"2020-06-30T19:13:41.696726Z","sequence":180756080,"price":"9105.5","order_id":"6fb9e748-0fa1-407f-9ea8-381151207869","remaining_size":"16.4964"}
{"type":"heartbeat","last_trade_id":0,"product_id":"BTC-USD","sequence":180756080,"time":"2020-06-30T19:13:41.735118Z"}
{"type":"done","side":"buy","product_id":"BTC-USD","time":"2020-06-30T19:13:41.886892Z","sequence":180756081,"order_id":"e09f7027-1877-4f2f-9042-4f984b6269ba","reason":"canceled","price":"9103.86","remaining_size":"0.5"}
{"type":"done","side":"buy","product_id":"BTC-USD","time":"2020-06-30T19:13:41.895505Z","sequence":180756082,"order_id":"47df50d1-abd3-4239-9b2d-59c04383bfed","reason":"canceled","price":"9087.82","remaining_size":"0.0519"}
{"type":"done","side":"buy","product_id":"BTC-USD","time":"2020-06-30T19:13:41.902295Z","sequence":180756083,"order_id":"4f647110-58cc-4573-8eda-218fdb4163c9","reason":"canceled","price":"9105.5","remaining_size":"13.911"}
{"type":"received","side":"sell","product_id":"BTC-USD","time":"2020-06-30T19:13:41.961708Z","sequence":180756084,"order_id":"72b12e98-439c-42d4-80ce-73b2eb78687a","order_type":"limit","size":"0.0659","price":"9110.47","client_oid":""}
{"type":"match","side":"buy","product_id":"BTC-USD","time":"2020-06-30T19:13:41.961708Z","sequence":180756085,"trade_id":14587511,"maker_order_id":"91b59a7c-6a07-4039-9536-21daf3cb3282","taker_order_id":"72b12e98-439c-42d4-80ce-73b2eb78687a","size":"0.0659","price":"9120.8"}
{"type":"done","side":"sell","product_id":"BTC-USD","time":"2020-06-30T19:13:41.961708Z","sequence":180756086,"order_id":"72b12e98-439c-42d4-80ce-73b2eb78687a","reason":"filled","price":"9110.47","remaining_size":"0"}
{"type":"received","side":"sell","product_id":"BTC-USD","time":"2020-06-30T19:13:42.257577Z","sequence":180756087,"order_id":"528a983e-2d4b-493e-a838-fa2fd0beef03","order_type":"limit","size":"0.0111","price":"9135.77","client_oid":""}
{"type":"open","side":"sell","product_id":"BTC-USD","time":"2020-06-30T19:13:42.257577Z","sequence":180756088,"price":"9135.77","order_id":"528a983e-2d4b-493e-a838-fa2fd0beef03","remaining_size":"0.0111"}
{"type":"heartbeat","last_trade_id":0,"product_id":"BTC-USD","sequence":180756088,"time":"2020-06-30T19:13:42.735116Z"}
{"type":"received","side":"sell","product_id":"BTC-USD","time":"2020-06-30T19:13:43.074474Z","sequence":180756089,"order_id":"0204fe08-fe10-47b6-bda2-1f3fcb15dd5d","order_type":"limit","size":"5","price":"9130","client_oid":""}
{"type":"open","side":"sell","product_id":"BTC-USD","time":"2020-06-30T19:13:43.074474Z","sequence":180756090,"price":"9130","order_id":"0204fe08-fe10-47b6-bda2-1f3fcb15dd5d","remaining_size":"5"}
{"type":"received","side":"sell","product_id":"BTC-USD","time":"2020-06-30T19:13:43.345554Z","sequence":180756091,"order_id":"f4850864-3794-4f76-8c0c-7c7166dd1768","order_type":"limit","size":"1.645","price":"9110.73","client_oid":""}
{"type":"match","side":"buy","product_id":"BTC-USD","time":"2020-06-30T19:13:43.345554Z","sequence":180756092,"trade_id":14587512,"maker_order_id":"91b59a7c-6a07-4039-9536-21daf3cb3282","taker_order_id":"f4850864-3794-4f76-8c0c-7c7166dd1768","size":"1.645","price":"9120.8"}
{"type":"done","side":"sell","product_id":"BTC-USD","time":"2020-06-30T19:13:43.345554Z","sequence":180756093,"order_id":"f4850864-3794-4f76-8c0c-7c7166dd1768","reason":"filled","price":"9110.73","remaining_size":"0"}
{"type":"done","side":"sell","product_id":"BTC-USD","time":"2020-06-30T19:13:43.592833Z","sequence":180756094,"order_id":"ad264542-bd7e-4aba-914a-e038f0e1fc33","reason":"canceled","price":"9138.72","remaining_size":"1.0393"}
{"type":"done","side":"sell","product_id":"BTC-USD","time":"2020-06-30T19:13:43.593612Z","sequence":180756095,"order_id":"13d2dcd3-d8ed-493e-bc71-35600c57168a","reason":"canceled","price":"9181.63","remaining_size":"0.0582"}
{"type":"received","side":"buy","product_id":"BTC-USD","time":"2020-06-30T19:13:43.660666Z","sequence":180756096,"order_id":"48b72cd8-220b-4141-9c28-72a717e35d31","order_type":"limit","size":"8.0556","price":"9105.52","client_oid":""}
{"type":"open","side":"buy","product_id":"BTC-USD","time":"2020-06-30T19:13:43.660666Z","sequence":180756097,"price":"9105.52","order_id":"48b72cd8-220b-4141-9c28-72a717e35d31","remaining_size":"8.0556"}
{"type":"heartbeat","last_trade_id":0,"product_id":"BTC-USD","sequence":180756097,"time":"2020-06-30T19:13:43.735113Z"}
{"type":"received","side":"buy","product_id":"BTC-USD","time":"2020-06-30T19:13:44.062642Z","sequence":180756098,"order_id":"7ae897f6-7765-4303-8c4b-6cc08a230a2a","order_type":"limit","size":"0.01","price":"100","client_oid":"0946829b-15c6-4404-aa12-6bd2f18c990f"}
{"type":"open","side":"buy","product_id":"BTC-USD","time":"2020-06-30T19:13:44.062642Z","sequence":180756099,"price":"100","order_id":"7ae897f6-7765-4303-8c4b-6cc08a230a2a","remaining_size":"0.01"}
{"type":"done","side":"buy","product_id":"BTC-USD","time":"2020-06-30T19:13:44.068801Z","sequence":180756100,"order_id":"7ae897f6-7765-4303-8c4b-6cc08a230a2a","reason":"canceled","price":"100","remaining_size":"0.01"}
{"type":"done","side":"buy","product_id":"BTC-USD","time":"2020-06-30T19:13:44.104906Z","sequence":180756101,"order_id":"a1fba462-fce3-4333-a2b9-a76ada75742c","reason":"canceled","price":"9105.5","remaining_size":"17.061"}
{"type":"received","side":"sell","product_id":"BTC-USD","time":"2020-06-30T19:13:44.475096Z","sequence":180756102,"order_id":"8ead09fb-15ac-4081-b8a1-60f44f3fe242","order_type":"limit","size":"0.1","price":"9128.35","client_oid":""}
{"type":"open","side":"sell","product_id":"BTC-USD","time":"2020-06-30T19:13:44.475096Z","sequence":180756103,"price":"9128.35","order_id":"8ead09fb-15ac-4081-b8a1-60f44f3fe242","remaining_size":"0.1"}
{"type":"heartbeat","last_trade_id":0,"product_id":"BTC-USD","sequence":180756103,"time":"2020-06-30T19:13:44.734954Z"}
{"type":"received","side":"sell","product_id":"BTC-USD","time":"2020-06-30T19:13:45.320598Z","sequence":180756104,"order_id":"ea20b553-98a1-4958-9222-8d1b305ab3a3","order_type":"limit","size":"0.8821","price":"9133.58","client_oid":""}
{"type":"open","side":"sell","product_id":"BTC-USD","time":"2020-06-30T19:13:45.320598Z","sequence":180756105,"price":"9133.58","order_id":"ea20b553-98a1-4958-9222-8d1b305ab3a3","remaining_size":"0.8821"}
{"type":"received","side":"buy","product_id":"BTC-USD","time":"2020-06-30T19:13:45.595015Z","sequence":180756106,"order_id":"e904f17a-b66c-4bf4-bf49-99c7c2c1e4f4","order_type":"limit","size":"0.5","price":"9103.31","client_oid":""}
{"type":"open","side":"buy","product_id":"BTC-USD","time":"2020-06-30T19:13:45.595015Z","sequence":180756107,"price":"9103.31","order_id":"e904f17a-b66c-4bf4-bf49-99c7c2c1e4f4","remaining_size":"0.5"}
{"type":"heartbeat","last_trade_id":0,"product_id":"BTC-USD","sequence":180756107,"time":"2020-06-30T19:13:45.735127Z"}
{"type":"received","side":"buy","product_id":"BTC-USD","time":"2020-06-30T19:13:45.873325Z","sequence":180756108,"order_id":"79687c72-6697-48f2-bf09-f195445e5201","order_type":"limit","size":"0.0879","price":"9047.28","client_oid":""}
{"type":"open","side":"buy","product_id":"BTC-USD","time":"2020-06-30T19:13:45.873325Z","sequence":180756109,"price":"9047.28","order_id":"79687c72-6697-48f2-bf09-f195445e5201","remaining_size":"0.0879"}
{"type":"done","side":"sell","product_id":"BTC-USD","time":"2020-06-30T19:13:45.919544Z","sequence":180756110,"order_id":"528a983e-2d4b-493e-a838-fa2fd0beef03","reason":"canceled","price":"9135.77","remaining_size":"0.0111"}
{"type":"done","side":"buy","product_id":"BTC-USD","time":"2020-06-30T19:13:46.022413Z","sequence":180756111,"order_id":"f3ea189e-a16f-4813-8735-8523c015cc00","reason":"canceled","price":"9086.71","remaining_size":"0.0283"}
{"type":"done","side":"buy","product_id":"BTC-USD","time":"2020-06-30T19:13:46.032534Z","sequence":180756112,"order_id":"ccb2f267-e1a8-42c3-923a-fc961a3f319d","reason":"canceled","price":"9098.27","remaining_size":"1.122"}
{"type":"received","side":"sell","product_id":"BTC-USD","time":"2020-06-30T19:13:46.164208Z","sequence":180756113,"order_id":"c8cad702-dbfc-4d06-adef-3f9cb5d1c37f","order_type":"limit","size":"5.2887","price":"9105.53","client_oid":""}
{"type":"match","side":"buy","product_id":"BTC-USD","time":"2020-06-30T19:13:46.164208Z","sequence":180756114,"trade_id":14587513,"maker_order_id":"91b59a7c-6a07-4039-9536-21daf3cb3282","taker_order_id":"c8cad702-dbfc-4d06-adef-3f9cb5d1c37f","size":"5.2887","price":"9120.8"}
{"type":"done","side":"sell","product_id":"BTC-USD","time":"2020-06-30T19:13:46.164208Z","sequence":180756115,"order_id":"c8cad702-dbfc-4d06-adef-3f9cb5d1c37f","reason":"filled","price":"9105.53","remaining_size":"0"}
{"type":"done","side":"buy","product_id":"BTC-USD","time":"2020-06-30T19:13:46.315177Z","sequence":180756116,"order_id":"fcc05e38-ff4e-4ce4-a3a1-fcf18dcca305","reason":"canceled","price":"9094.06","remaining_size":"0.7277"}
{"type":"received","side":"sell","product_id":"BTC-USD","time":"2020-06-30T19:13:46.418695Z","sequence":180756117,"order_id":"412484fe-0751-4f8c-b2bd-df0219b14a74","order_type":"limit","size":"1.1895","price":"9138.74","client_oid":""}
{"type":"open","side":"sell","product_id":"BTC-USD","time":"2020-06-30T19:13:46.418695Z","sequence":180756118,"price":"9138.74","order_id":"412484fe-0751-4f8c-b2bd-df0219b14a74","remaining_size":"1.1895"}
{"type":"done","side":"sell","product_id":"BTC-USD","time":"2020-06-30T19:13:46.595059Z","sequence":180756119,"order_id":"ea20b553-98a1-4958-9222-8d1b305ab3a3","reason":"canceled","price":"9133.58","remaining_size":"0.8821"}
{"type":"heartbeat","last_trade_id":0,"product_id":"BTC-USD","sequence":180756119,"time":"2020-06-30T19:13:46.735118Z"}
{"type":"received","side":"sell","product_id":"BTC-USD","time":"2020-06-30T19:13:47.549579Z","sequence":180756120,"order_id":"60ba5b3c-4bc5-48d3-bf73-3ebe57f9cde3","order_type":"limit","size":"0.05","price":"9109.82","client_oid":""}
{"type":"match","side":"buy","product_id":"BTC-USD","time":"2020-06-30T19:13:47.549579Z","sequence":180756121,"trade_id":14587514,"maker_order_id":"91b59a7c-6a07-4039-9536-21daf3cb3282","taker_order_id":"60ba5b3c-4bc5-48d3-bf73-3ebe57f9cde3","size":"0.05","price":"9120.8"}
{"type":"done","side":"sell","product_id":"BTC-USD","time":"2020-06-30T19:13:47.549579Z","sequence":180756122,"order_id":"60ba5b3c-4bc5-48d3-bf73-3ebe57f9cde3","reason":"filled","price":"9109.82","remaining_size":"0"}
{"type":"heartbeat","last_trade_id":0,"product_id":"BTC-USD","sequence":180756122,"time":"2020-06-30T19:13:47.735112Z"}
{"type":"received","side":"buy","product_id":"BTC-USD","time":"2020-06-30T19:13:47.818075Z","sequence":180756123,"order_id":"32c6aefb-be64-41dc-9981-4a2bad5740d6","order_type":"limit","size":"0.01","price":"9078.84","client_oid":""}
{"type":"open","side":"buy","product_id":"BTC-USD","time":"2020-06-30T19:13:47.818075Z","sequence":180756124,"price":"9078.84","order_id":"32c6aefb-be64-41dc-9981-4a2bad5740d6","remaining_size":"0.01"}
{"type":"done","side":"sell","product_id":"BTC-USD","time":"2020-06-30T19:13:48.017538Z","sequence":180756125,"order_id":"8ead09fb-15ac-4081-b8a1-60f44f3fe242","reason":"canceled","price":"9128.35","remaining_size":"0.1"}
{"type":"done","side":"buy","product_id":"BTC-USD","time":"2020-06-30T19:13:48.269647Z","sequence":180756126,"order_id":"bae23e5c-b2e3-465d-86de-b3de14695bc7","reason":"canceled","price":"9085.4","remaining_size":"0.1213"}
{"type":"done","side":"buy","product_id":"BTC-USD","time":"2020-06-30T19:13:48.269903Z","sequence":180756127,"order_id":"eb3fb2e6-cb4e-416d-9ad1-6ccd02d0089a","reason":"canceled","price":"9105.5","remaining_size":"18.5746"}
{"type":"heartbeat","last_trade_id":0,"product_id":"BTC-USD","sequence":180756127,"time":"2020-06-30T19:13:48.735111Z"}
{"type":"received","side":"buy","product_id":"BTC-USD","time":"2020-06-30T19:13:49.237680Z","sequence":180756128,"order_id":"cd2355a1-4125-48a9-becf-32b3aabee270","order_type":"limit","size":"12.5442","price":"9105.54","client_oid":""}
{"type":"open","side":"buy","product_id":"BTC-USD","time":"2020-06-30T19:13:49.237680Z","sequence":180756129,"price":"9105.54","order_id":"cd2355a1-4125-48a9-becf-32b3aabee270","remaining_size":"12.5442"}
{"type":"done","side":"buy","product_id":"BTC-USD","time":"2020-06-30T19:13:49.626063Z","sequence":180756130,"order_id":"6fb9e748-0fa1-407f-9ea8-381151207869","reason":"canceled","price":"9105.5","remaining_size":"16.4964"}
{"type":"done","side":"buy","product_id":"BTC-USD","time":"2020-06-30T19:13:49.626375Z","sequence":180756131,"order_id":"54b6cbd3-e925-4a41-beac-d21cd048a877","reason":"canceled","price":"9100.81","remaining_size":"3.1449"}
{"type":"heartbeat","last_trade_id":0,"product_id":"BTC-USD","sequence":180756131,"time":"2020-06-30T19:13:49.735116Z"}
{"type":"received","side":"sell","product_id":"BTC-USD","time":"2020-06-30T19:13:49.778529Z","sequence":180756132,"order_id":"06bd4ce0-4c72-47c2-a893-d6d460af58d9","order_type":"limit","size":"0.05","price":"9109.62","client_oid":""}
{"type":"match","side":"buy","product_id":"BTC-USD","time":"2020-06-30T19:13:49.778529Z","sequence":180756133,"trade_id":14587515,"maker_order_id":"91b59a7c-6a07-4039-9536-21daf3cb3282","taker_order_id":"06bd4ce0-4c72-47c2-a893-d6d460af58d9","size":"0.05","price":"9120.8"}
{"type":"done","side":"sell","product_id":"BTC-USD","time":"2020-06-30T19:13:49.778529Z","sequence":180756134,"order_id":"06bd4ce0-4c72-47c2-a893-d6d460af58d9","reason":"filled","price":"9109.62","remaining_size":"0"}
{"type":"received","side":"sell","product_id":"BTC-USD","time":"2020-06-30T19:13:50.057515Z","sequence":180756135,"order_id":"9d331116-7664-4f99-a09b-b627d442ca9f","order_type":"limit","size":"0.9","price":"9108.47","client_oid":""}
{"type":"match","side":"buy","product_id":"BTC-USD","time":"2020-06-30T19:13:50.057515Z","sequence":180756136,"trade_id":14587516,"maker_order_id":"91b59a7c-6a07-4039-9536-21daf3cb3282","taker_order_id":"9d331116-7664-4f99-a09b-b627d442ca9f","size":"0.9","price":"9120.8"}
{"type":"done","side":"sell","product_id":"BTC-USD","time":"2020-06-30T19:13:50.057515Z","sequence":180756137,"order_id":"9d331116-7664-4f99-a09b-b627d442ca9f","reason":"filled","price":"9108.47","remaining_size":"0"}
{"type":"received","side":"sell","product_id":"BTC-USD","time":"2020-06-30T19:13:50.327773Z","sequence":180756138,"order_id":"37736856-9841-48ce-b552-ecda0b60fd6a","order_type":"limit","size":"0.9","price":"9109.27","client_oid":""}
{"type":"match","side":"buy","product_id":"BTC-USD","time":"2020-06-30T19:13:50.327773Z","sequence":180756139,"trade_id":14587517,"maker_order_id":"91b59a7c-6a07-4039-9536-21daf3cb3282","taker_order_id":"37736856-9841-48ce-b552-ecda0b60fd6a","size":"0.9","price":"9120.8"}
{"type":"done","side":"sell","product_id":"BTC-USD","time":"2020-06-30T19:13:50.327773Z","sequence":180756140,"order_id":"37736856-9841-48ce-b552-ecda0b60fd6a","reason":"filled","price":"9109.27","remaining_size":"0"}
{"type":"done","side":"sell","product_id":"BTC-USD","time":"2020-06-30T19:13:50.486797Z","sequence":180756141,"order_id":"0204fe08-fe10-47b6-bda2-1f3fcb15dd5d","reason":"canceled","price":"9130","remaining_size":"5"}
{"type":"heartbeat","last_trade_id":0,"product_id":"BTC-USD","sequence":180756141,"time":"2020-06-30T19:13:50.735127Z"}
{"type":"received","side":"sell","product_id":"BTC-USD","time":"2020-06-30T19:13:51.434404Z","sequence":180756142,"order_id":"c55962f5-ae10-41a3-bdce-a3ad4c82aa5c","order_type":"limit","size":"0.0131","price":"9106.72","client_oid":""}
{"type":"match","side":"buy","product_id":"BTC-USD","time":"2020-06-30T19:13:51.434404Z","sequence":180756143,"trade_id":14587518,"maker_order_id":"91b59a7c-6a07-4039-9536-21daf3cb3282","taker_order_id":"c55962f5-ae10-41a3-bdce-a3ad4c82aa5c","size":"0.0131","price":"9120.8"}
{"type":"done","side":"sell","product_id":"BTC-USD","time":"2020-06-30T19:13:51.434404Z","sequence":180756144,"order_id":"c55962f5-ae10-41a3-bdce-a3ad4c82aa5c","reason":"filled","price":"9106.72","remaining_size":"0"}
{"type":"received","side":"sell","product_id":"BTC-USD","time":"2020-06-30T19:13:51.711751Z","sequence":180756145,"order_id":"d2758668-0572-432b-8946-fa905ad323a1","order_type":"limit","size":"0.06","price":"9107.63","client_oid":""}
{"type":"match","side":"buy","product_id":"BTC-USD","time":"2020-06-30T19:13:51.711751Z","sequence":180756146,"trade_id":14587519,"maker_order_id":"91b59a7c-6a07-4039-9536-21daf3cb3282","taker_order_id":"d2758668-0572-432b-8946-fa905ad323a1","size":"0.06","price":"9120.8"}
{"type":"done","side":"sell","product_id":"BTC-USD","time":"2020-06-30T19:13:51.711751Z","sequence":180756147,"order_id":"d2758668-0572-432b-8946-fa905ad323a1","reason":"filled","price":"9107.63","remaining_size":"0"}
{"type":"heartbeat","last_trade_id":0,"product_id":"BTC-USD","sequence":180756147,"time":"2020-06-30T19:13:51.735099Z"}
{"type":"received","side":"buy","product_id":"BTC-USD","time":"2020-06-30T19:13:51.996138Z","sequence":180756148,"order_id":"a7ca22f0-cfe8-408b-8c6f-5d407e0d93f6","order_type":"limit","size":"0.01","price":"9086.24","client_oid":""}
{"type":"open","side":"buy","product_id":"BTC-USD","time":"2020-06-30T19:13:51.996138Z","sequence":180756149,"price":"9086.24","order_id":"a7ca22f0-cfe8-408b-8c6f-5d407e0d93f6","remaining_size":"0.01"}
{"type":"done","side":"sell","product_id":"BTC-USD","time":"2020-06-30T19:13:52.164816Z","sequence":180756150,"order_id":"d279ceb0-2f57-4df4-92e4-ddb22504791b","reason":"canceled","price":"9133.56","remaining_size":"1.1363"}
{"type":"done","side":"sell","product_id":"BTC-USD","time":"2020-06-30T19:13:52.170186Z","sequence":180756151,"order_id":"f21cb164-f11f-466f-b705-b9f9c2b3e63c","reason":"canceled","price":"9143.91","remaining_size":"0.0691"}
{"type":"done","side":"buy","product_id":"BTC-USD","time":"2020-06-30T19:13:52.241109Z","sequence":180756152,"order_id":"e904f17a-b66c-4bf4-bf49-99c7c2c1e4f4","reason":"canceled","price":"9103.31","remaining_size":"0.5"}
{"type":"done","side":"buy","product_id":"BTC-USD","time":"2020-06-30T19:13:52.247614Z","sequence":180756153,"order_id":"bd461a8f-fca1-4f65-a72d-166825904880","reason":"canceled","price":"9081.72","remaining_size":"0.3439"}
{"type":"done","side":"buy","product_id":"BTC-USD","time":"2020-06-30T19:13:52.252414Z","sequence":180756154,"order_id":"32c6aefb-be64-41dc-9981-4a2bad5740d6","reason":"canceled","price":"9078.84","remaining_size":"0.01"}
{"type":"heartbeat","last_trade_id":0,"product_id":"BTC-USD","sequence":180756154,"time":"2020-06-30T19:13:52.735097Z"}
{"type":"received","side":"buy","product_id":"BTC-USD","time":"2020-06-30T19:13:52.925986Z","sequence":180756155,"order_id":"4b6926ca-c78a-4e3a-8b98-510ce43bcba9","order_type":"limit","size":"0.3296","price":"9101.96","client_oid":""}
{"type":"open","side":"buy","product_id":"BTC-USD","time":"2020-06-30T19:13:52.925986Z","sequence":180756156,"price":"9101.96","order_id":"4b6926ca-c78a-4e3a-8b98-510ce43bcba9","remaining_size":"0.3296"}
{"type":"done","side":"buy","product_id":"BTC-USD","time":"2020-06-30T19:13:53.347885Z","sequence":180756157,"order_id":"a7ca22f0-cfe8-408b-8c6f-5d407e0d93f6","reason":"canceled","price":"9086.24","remaining_size":"0.01"}
{"type":"done","side":"buy","product_id":"BTC-USD","time":"2020-06-30T19:13:53.349871Z","sequence":180756158,"order_id":"ce2b001d-5ea4-47d6-a5eb-4a91cf507d12","reason":"canceled","price":"9105.5","remaining_size":"18.011"}
{"type":"heartbeat","last_trade_id":0,"product_id":"BTC-USD","sequence":180756158,"time":"2020-06-30T19:13:53.735126Z"}
{"type":"received","side":"sell","product_id":"BTC-USD","time":"2020-06-30T19:13:53.751732Z","sequence":180756159,"order_id":"db8549d8-01d4-48cc-86d8-f5ceb416df6c","order_type":"limit","size":"0.0766","price":"9160.58","client_oid":""}
{"type":"open","side":"sell","product_id":"BTC-USD","time":"2020-06-30T19:13:53.751732Z","sequence":180756160,"price":"9160.58","order_id":"db8549d8-01d4-48cc-86d8-f5ceb416df6c","remaining_size":"0.0766"}
{"type":"received","side":"sell","product_id":"BTC-USD","time":"2020-06-30T19:13:54.030506Z","sequence":180756161,"order_id":"887f6009-46b6-4c61-af4d-897f7885767a","order_type":"limit","size":"1.1391","price":"9118.99","client_oid":""}
{"type":"match","side":"buy","product_id":"BTC-USD","time":"2020-06-30T19:13:54.030506Z","sequence":180756162,"trade_id":14587520,"maker_order_id":"91b59a7c-6a07-4039-9536-21daf3cb3282","taker_order_id":"887f6009-46b6-4c61-af4d-897f7885767a","size":"1.1391","price":"9120.8"}
{"type":"done","side":"sell","product_id":"BTC-USD","time":"2020-06-30T19:13:54.030506Z","sequence":180756163,"order_id":"887f6009-46b6-4c61-af4d-897f7885767a","reason":"filled","price":"9118.99","remaining_size":"0"}
{"type":"received","side":"buy","product_id":"BTC-USD","time":"2020-06-30T19:13:54.284068Z","sequence":180756164,"order_id":"43a7410f-de57-4f03-8f42-8bcd92c76315","order_type":"limit","size":"0.0283","price":"9091.33","client_oid":""}
{"type":"open","side":"buy","product_id":"BTC-USD","time":"2020-06-30T19:13:54.284068Z","sequence":180756165,"price":"9091.33","order_id":"43a7410f-de57-4f03-8f42-8bcd92c76315","remaining_size":"0.0283"}
{"type":"done","side":"buy","product_id":"BTC-USD","time":"2020-06-30T19:13:54.715830Z","sequence":180756166,"order_id":"cd2355a1-4125-48a9-becf-32b3aabee270","reason":"canceled","price":"9105.54","remaining_size":"12.5442"}
{"type":"done","side":"buy","product_id":"BTC-USD","time":"2020-06-30T19:13:54.723698Z","sequence":180756167,"order_id":"79687c72-6697-48f2-bf09-f195445e5201","reason":"canceled","price":"9047.28","remaining_size":"0.0879"}
{"type":"heartbeat","last_trade_id":0,"product_id":"BTC-USD","sequence":180756167,"time":"2020-06-30T19:13:54.735115Z"}
{"type":"done","side":"buy","product_id":"BTC-USD","time":"2020-06-30T19:13:54.746044Z","sequence":180756168,"order_id":"60f4a673-c212-40c6-b81e-4a72b9e3b1b6","reason":"canceled","price":"9073.03","remaining_size":"0.063"}
{"type":"received","side":"sell","product_id":"BTC-USD","time":"2020-06-30T19:13:54.836560Z","sequence":180756169,"order_id":"c8aa6c7e-d74f-4025-82b4-c1aec416ed71","order_type":"limit","size":"0.9002","price":"9104.55","client_oid":""}
{"type":"match","side":"buy","product_id":"BTC-USD","time":"2020-06-30T19:13:54.836560Z","sequence":180756170,"trade_id":14587521,"maker_order_id":"91b59a7c-6a07-4039-9536-21daf3cb3282","taker_order_id":"c8aa6c7e-d74f-4025-82b4-c1aec416ed71","size":"0.9002","price":"9120.8"}
{"type":"done","side":"sell","product_id":"BTC-USD","time":"2020-06-30T19:13:54.836560Z","sequence":180756171,"order_id":"c8aa6c7e-d74f-4025-82b4-c1aec416ed71","reason":"filled","price":"9104.55","remaining_size":"0"}
{"type":"received","side":"buy","product_id":"BTC-USD","time":"2020-06-30T19:13:55.251455Z","sequence":180756172,"order_id":"e9af355c-f0cd-4411-a05c-4d4a9a651a01","order_type":"limit","size":"0.1153","price":"9083.72","client_oid":""}
{"type":"open","side":"buy","product_id":"BTC-USD","time":"2020-06-30T19:13:55.251455Z","sequence":180756173,"price":"9083.72","order_id":"e9af355c-f0cd-4411-a05c-4d4a9a651a01","remaining_size":"0.1153"}
{"type":"heartbeat","last_trade_id":0,"product_id":"BTC-USD","sequence":180756173,"time":"2020-06-30T19:13:55.735096Z"}
{"type":"received","side":"sell","product_id":"BTC-USD","time":"2020-06-30T19:13:56.335852Z","sequence":180756174,"order_id":"09f43539-eb0f-4f21-a402-5ec518a8ad17","order_type":"limit","size":"5.377","price":"9113.75","client_oid":""}
{"type":"match","side":"buy","product_id":"BTC-USD","time":"2020-06-30T19:13:56.335852Z","sequence":180756175,"trade_id":14587522,"maker_order_id":"91b59a7c-6a07-4039-9536-21daf3cb3282","taker_order_id":"09f43539-eb0f-4f21-a402-5ec518a8ad17","size":"5.377","price":"9120.8"}
{"type":"done","side":"sell","product_id":"BTC-USD","time":"2020-06-30T19:13:56.335852Z","sequence":180756176,"order_id":"09f43539-eb0f-4f21-a402-5ec518a8ad17","reason":"filled","price":"9113.75","remaining_size":"0"}
{"type":"heartbeat","last_trade_id":0,"product_id":"BTC-USD","sequence":180756176,"time":"2020-06-30T19:13:56.735096Z"}
{"type":"received","side":"sell","product_id":"BTC-USD","time":"2020-06-30T19:13:56.971082Z","sequence":180756177,"order_id":"686e89f9-29d5-4896-a619-072b3347c24f","order_type":"limit","size":"0.3715","price":"9112.79","client_oid":""}
{"type":"match","side":"buy","product_id":"BTC-USD","time":"2020-06-30T19:13:56.971082Z","sequence":180756178,"trade_id":14587523,"maker_order_id":"91b59a7c-6a07-4039-9536-21daf3cb3282","taker_order_id":"686e89f9-29d5-4896-a619-072b3347c24f","size":"0.3715","price":"9120.8"}
{"type":"done","side":"sell","product_id":"BTC-USD","time":"2020-06-30T19:13:56.971082Z","sequence":180756179,"order_id":"686e89f9-29d5-4896-a619-072b3347c24f","reason":"filled","price":"9112.79","remaining_size":"0"}
{"type":"received","side":"buy","product_id":"BTC-USD","time":"2020-06-30T19:13:57.251673Z","sequence":180756180,"order_id":"aaacaa6b-4dd8-4e0f-b747-bc2b4e43a60d","order_type":"limit","size":"15.397","price":"9104.3","client_oid":""}
{"type":"open","side":"buy","product_id":"BTC-USD","time":"2020-06-30T19:13:57.251673Z","sequence":180756181,"price":"9104.3","order_id":"aaacaa6b-4dd8-4e0f-b747-bc2b4e43a60d","remaining_size":"15.397"}
{"type":"received","side":"buy","product_id":"BTC-USD","time":"2020-06-30T19:13:57.518851Z","sequence":180756182,"order_id":"00fb51a2-9fba-4419-8eb1-c6ee2d01c5d2","order_type":"limit","size":"1.1114","price":"9107.79","client_oid":""}
{"type":"open","side":"buy","product_id":"BTC-USD","time":"2020-06-30T19:13:57.518851Z","sequence":180756183,"price":"9107.79","order_id":"00fb51a2-9fba-4419-8eb1-c6ee2d01c5d2","remaining_size":"1.1114"}
{"type":"heartbeat","last_trade_id":0,"product_id":"BTC-USD","sequence":180756183,"time":"2020-06-30T19:13:57.735099Z"}
{"type":"received","side":"sell","product_id":"BTC-USD","time":"2020-06-30T19:13:58.346773Z","sequence":180756184,"order_id":"17260450-eff6-45d8-8375-a99cd0412de2","order_type":"limit","size":"0.0659","price":"9108.49","client_oid":""}
{"type":"match","side":"buy","product_id":"BTC-USD","time":"2020-06-30T19:13:58.346773Z","sequence":180756185,"trade_id":14587524,"maker_order_id":"91b59a7c-6a07-4039-9536-21daf3cb3282","taker_order_id":"17260450-eff6-45d8-8375-a99cd0412de2","size":"0.0659","price":"9120.8"}
{"type":"done","side":"sell","product_id":"BTC-USD","time":"2020-06-30T19:13:58.346773Z","sequence":180756186,"order_id":"17260450-eff6-45d8-8375-a99cd0412de2","reason":"filled","price":"9108.49","remaining_size":"0"}
{"type":"done","side":"buy","product_id":"BTC-USD","time":"2020-06-30T19:13:58.507472Z","sequence":180756187,"order_id":"92324264-221a-4cd5-b203-267131faf428","reason":"canceled","price":"8894","remaining_size":"0.04644306"}
{"type":"received","side":"sell","product_id":"BTC-USD","time":"2020-06-30T19:13:58.619436Z","sequence":180756188,"order_id":"082a7abc-bfb2-4846-b9d3-76800bcf6dd2","order_type":"limit","size":"0.545","price":"9112.09","client_oid":""}
{"type":"match","side":"buy","product_id":"BTC-USD","time":"2020-06-30T19:13:58.619436Z","sequence":180756189,"trade_id":14587525,"maker_order_id":"91b59a7c-6a07-4039-9536-21daf3cb3282","taker_order_id":"082a7abc-bfb2-4846-b9d3-76800bcf6dd2","size":"0.545","price":"9120.8"}
{"type":"done","side":"sell","product_id":"BTC-USD","time":"2020-06-30T19:13:58.619436Z","sequence":180756190,"order_id":"082a7abc-bfb2-4846-b9d3-76800bcf6dd2","reason":"filled","price":"9112.09","remaining_size":"0"}
{"type":"received","side":"buy","product_id":"BTC-USD","time":"2020-06-30T19:13:58.722732Z","sequence":180756191,"order_id":"c20df563-781d-4fab-be58-dd824f58978b","order_type":"limit","size":"0.04654411","price":"8893.18","client_oid":""}
{"type":"open","side":"buy","product_id":"BTC-USD","time":"2020-06-30T19:13:58.722732Z","sequence":180756192,"price":"8893.18","order_id":"c20df563-781d-4fab-be58-dd824f58978b","remaining_size":"0.04654411"}
{"type":"heartbeat","last_trade_id":0,"product_id":"BTC-USD","sequence":180756192,"time":"2020-06-30T19:13:58.735099Z"}
{"type":"done","side":"sell","product_id":"BTC-USD","time":"2020-06-30T19:13:58.981258Z","sequence":180756193,"order_id":"ce032b68-b73b-4d61-83f6-1e9e4a6d770a","reason":"canceled","price":"9436.96","remaining_size":"0.00718939"}
{"type":"received","side":"buy","product_id":"BTC-USD","time":"2020-06-30T19:13:59.029105Z","sequence":180756194,"order_id":"4be981cb-6706-4fe3-916f-249da07ec6d4","order_type":"limit","size":"0.01","price":"100","client_oid":"31fb1b35-f0ab-49ee-b183-cbcfc0f8066f"}
{"type":"open","side":"buy","product_id":"BTC-USD","time":"2020-06-30T19:13:59.029105Z","sequence":180756195,"price":"100","order_id":"4be981cb-6706-4fe3-916f-249da07ec6d4","remaining_size":"0.01"}
{"type":"done","side":"buy","product_id":"BTC-USD","time":"2020-06-30T19:13:59.036094Z","sequence":180756196,"order_id":"4be981cb-6706-4fe3-916f-249da07ec6d4","reason":"canceled","price":"100","remaining_size":"0.01"}
{"type":"received","side":"sell","product_id":"BTC-USD","time":"2020-06-30T19:13:59.222835Z","sequence":180756197,"order_id":"7d776b77-71e0-4cb4-8a3c-1fea7746bbd4","order_type":"limit","size":"0.00728822","price":"9437.82","client_oid":""}
{"type":"open","side":"sell","product_id":"BTC-USD","time":"2020-06-30T19:13:59.222835Z","sequence":180756198,"price":"9437.82","order_id":"7d776b77-71e0-4cb4-8a3c-1fea7746bbd4","remaining_size":"0.00728822"}
{"type":"heartbeat","last_trade_id":0,"product_id":"BTC-USD","sequence":180756198,"time":"2020-06-30T19:13:59.735109Z"}
{"type":"received","side":"sell","product_id":"BTC-USD","time":"2020-06-30T19:14:00.338338Z","sequence":180756199,"order_id":"2c8d4cf1-2a89-43f7-9e6c-2c5274e168f1","order_type":"limit","size":"0.0359","price":"9111.26","client_oid":""}
{"type":"match","side":"buy","product_id":"BTC-USD","time":"2020-06-30T19:14:00.338338Z","sequence":180756200,"trade_id":14587526,"maker_order_id":"91b59a7c-6a07-4039-9536-21daf3cb3282","taker_order_id":"2c8d4cf1-2a89-43f7-9e6c-2c5274e168f1","size":"0.0359","price":"9120.8"}
{"type":"done","side":"sell","product_id":"BTC-USD","time":"2020-06-30T19:14:00.338338Z","sequence":180756201,"order_id":"2c8d4cf1-2a89-43f7-9e6c-2c5274e168f1","reason":"filled","price":"9111.26","remaining_size":"0"}
{"type":"received","side":"sell","product_id":"BTC-USD","time":"2020-06-30T19:14:00.614085Z","sequence":180756202,"order_id":"b7557a1e-fa9c-41a1-a3cc-3f29a2830f1d","order_type":"limit","size":"0.0149","price":"9162.24","client_oid":""}
{"type":"open","side":"sell","product_id":"BTC-USD","time":"2020-06-30T19:14:00.614085Z","sequence":180756203,"price":"9162.24","order_id":"b7557a1e-fa9c-41a1-a3cc-3f29a2830f1d","remaining_size":"0.0149"}
{"type":"heartbeat","last_trade_id":0,"product_id":"BTC-USD","sequence":180756203,"time":"2020-06-30T19:14:00.735123Z"}
{"type":"done","side":"sell","product_id":"BTC-USD","time":"2020-06-30T19:14:00.781023Z","sequence":180756204,"order_id":"db8549d8-01d4-48cc-86d8-f5ceb416df6c","reason":"canceled","price":"9160.58","remaining_size":"0.0766"}
{"type":"received","side":"buy","product_id":"BTC-USD","time":"2020-06-30T19:14:00.909609Z","sequence":180756205,"order_id":"e35bfa1b-ae15-4fcd-83cd-3caf264fd815","order_type":"limit","size":"0.0659","price":"9103.25","client_oid":""}
{"type":"open","side":"buy","product_id":"BTC-USD","time":"2020-06-30T19:14:00.909609Z","sequence":180756206,"price":"9103.25","order_id":"e35bfa1b-ae15-4fcd-83cd-3caf264fd815","remaining_size":"0.0659"}
{"type":"received","side":"sell","product_id":"BTC-USD","time":"2020-06-30T19:14:01.187088Z","sequence":180756207,"order_id":"2b494fa7-0c09-42d7-9465-9a14f610338c","order_type":"limit","size":"0.0147","price":"9121.5","client_oid":""}
{"type":"open","side":"sell","product_id":"BTC-USD","time":"2020-06-30T19:14:01.187088Z","sequence":180756208,"price":"9121.5","order_id":"2b494fa7-0c09-42d7-9465-9a14f610338c","remaining_size":"0.0147"}
{"type":"received","side":"sell","product_id":"BTC-USD","time":"2020-06-30T19:14:01.477033Z","sequence":180756209,"order_id":"83fa9f06-9b8a-46d1-b966-ed17cda99bb1","order_type":"limit","size":"0.3293","price":"9111.03","client_oid":""}
{"type":"match","side":"buy","product_id":"BTC-USD","time":"2020-06-30T19:14:01.477033Z","sequence":180756210,"trade_id":14587527,"maker_order_id":"91b59a7c-6a07-4039-9536-21daf3cb3282","taker_order_id":"83fa9f06-9b8a-46d1-b966-ed17cda99bb1","size":"0.3293","price":"9120.8"}
{"type":"done","side":"sell","product_id":"BTC-USD","time":"2020-06-30T19:14:01.477033Z","sequence":180756211,"order_id":"83fa9f06-9b8a-46d1-b966-ed17cda99bb1","reason":"filled","price":"9111.03","remaining_size":"0"}
{"type":"done","side":"sell","product_id":"BTC-USD","time":"2020-06-30T19:14:01.718904Z","sequence":180756212,"order_id":"b7557a1e-fa9c-41a1-a3cc-3f29a2830f1d","reason":"canceled","price":"9162.24","remaining_size":"0.0149"}
{"type":"heartbeat","last_trade_id":0,"product_id":"BTC-USD","sequence":180756212,"time":"2020-06-30T19:14:01.735120Z"}
{"type":"received","side":"sell","product_id":"BTC-USD","time":"2020-06-30T19:14:01.844856Z","sequence":180756213,"order_id":"e256d31d-98af-4789-89b2-03612fb05ff9","order_type":"limit","size":"0.0145","price":"9160.96","client_oid":""}
{"type":"open","side":"sell","product_id":"BTC-USD","time":"2020-06-30T19:14:01.844856Z","sequence":180756214,"price":"9160.96","order_id":"e256d31d-98af-4789-89b2-03612fb05ff9","remaining_size":"0.0145"}
{"type":"received","side":"sell","product_id":"BTC-USD","time":"2020-06-30T19:14:02.534056Z","sequence":180756215,"order_id":"e95e405e-2c32-49cb-b6b1-861a20ab6264","order_type":"limit","size":"0.0145","price":"9160.25","client_oid":""}
{"type":"open","side":"sell","product_id":"BTC-USD","time":"2020-06-30T19:14:02.534056Z","sequence":180756216,"price":"9160.25","order_id":"e95e405e-2c32-49cb-b6b1-861a20ab6264","remaining_size":"0.0145"}
{"type":"heartbeat","last_trade_id":0,"product_id":"BTC-USD","sequence":180756216,"time":"2020-06-30T19:14:02.735115Z"}
{"type":"received","side":"sell","product_id":"BTC-USD","time":"2020-06-30T19:14:02.858730Z","sequence":180756217,"order_id":"71226fe3-674f-41cc-a02e-2af1c2b3a439","order_type":"limit","size":"0.0325","price":"9119.3","client_oid":""}
{"type":"match","side":"buy","product_id":"BTC-USD","time":"2020-06-30T19:14:02.858730Z","sequence":180756218,"trade_id":14587528,"maker_order_id":"91b59a7c-6a07-4039-9536-21daf3cb3282","taker_order_id":"71226fe3-674f-41cc-a02e-2af1c2b3a439","size":"0.0325","price":"9120.8"}
{"type":"done","side":"sell","product_id":"BTC-USD","time":"2020-06-30T19:14:02.858730Z","sequence":180756219,"order_id":"71226fe3-674f-41cc-a02e-2af1c2b3a439","reason":"filled","price":"9119.3","remaining_size":"0"}
{"type":"heartbeat","last_trade_id":0,"product_id":"BTC-USD","sequence":180756219,"time":"2020-06-30T19:14:03.735022Z"}
{"type":"received","side":"sell","product_id":"BTC-USD","time":"2020-06-30T19:14:03.754558Z","sequence":180756220,"order_id":"286a3c65-4d17-47f9-b13e-b758ac12458e","order_type":"limit","size":"0.1835","price":"9108.49","client_oid":""}
{"type":"match","side":"buy","product_id":"BTC-USD","time":"2020-06-30T19:14:03.754558Z","sequence":180756221,"trade_id":14587529,"maker_order_id":"91b59a7c-6a07-4039-9536-21daf3cb3282","taker_order_id":"286a3c65-4d17-47f9-b13e-b758ac12458e","size":"0.1835","price":"9120.8"}
{"type":"done","side":"sell","product_id":"BTC-USD","time":"2020-06-30T19:14:03.754558Z","sequence":180756222,"order_id":"286a3c65-4d17-47f9-b13e-b758ac12458e","reason":"filled","price":"9108.49","remaining_size":"0"}
{"type":"received","side":"sell","product_id":"BTC-USD","time":"2020-06-30T19:14:03.974994Z","sequence":180756223,"order_id":"cdeaba59-6819-4502-ba2f-3c11cdc2762d","order_type":"limit","size":"0.1835","price":"9108.49","client_oid":""}
{"type":"match","side":"buy","product_id":"BTC-USD","time":"2020-06-30T19:14:03.974994Z","sequence":180756224,"trade_id":14587530,"maker_order_id":"91b59a7c-6a07-4039-9536-21daf3cb3282","taker_order_id":"cdeaba59-6819-4502-ba2f-3c11cdc2762d","size":"0.1835","price":"9120.8"}
{"type":"done","side":"sell","product_id":"BTC-USD","time":"2020-06-30T19:14:03.974994Z","sequence":180756225,"order_id":"cdeaba59-6819-4502-ba2f-3c11cdc2762d","reason":"filled","price":"9108.49","remaining_size":"0"}
{"type":"done","side":"sell","product_id":"BTC-USD","time":"2020-06-30T19:14:04.156369Z","sequence":180756226,"order_id":"412484fe-0751-4f8c-b2bd-df0219b14a74","reason":"canceled","price":"9138.74","remaining_size":"1.1895"}
{"type":"heartbeat","last_trade_id":0,"product_id":"BTC-USD","sequence":180756226,"time":"2020-06-30T19:14:04.735172Z"}
{"type":"received","side":"sell","product_id":"BTC-USD","time":"2020-06-30T19:14:05.376089Z","sequence":180756227,"order_id":"b9aa3df5-f693-4519-bee4-5524c928f861","order_type":"limit","size":"0.0149","price":"9161.82","client_oid":""}
{"type":"open","side":"sell","product_id":"BTC-USD","time":"2020-06-30T19:14:05.376089Z","sequence":180756228,"price":"9161.82","order_id":"b9aa3df5-f693-4519-bee4-5524c928f861","remaining_size":"0.0149"}
{"type":"received","side":"sell","product_id":"BTC-USD","time":"2020-06-30T19:14:05.649981Z","sequence":180756229,"order_id":"7bc8fde6-c0f5-4de7-8571-fcf788fe37d5","order_type":"limit","size":"0.0659","price":"9109.93","client_oid":""}
{"type":"match","side":"buy","product_id":"BTC-USD","time":"2020-06-30T19:14:05.649981Z","sequence":180756230,"trade_id":14587531,"maker_order_id":"91b59a7c-6a07-4039-9536-21daf3cb3282","taker_order_id":"7bc8fde6-c0f5-4de7-8571-fcf788fe37d5","size":"0.0659","price":"9120.8"}
{"type":"done","side":"sell","product_id":"BTC-USD","time":"2020-06-30T19:14:05.649981Z","sequence":180756231,"order_id":"7bc8fde6-c0f5-4de7-8571-fcf788fe37d5","reason":"filled","price":"9109.93","remaining_size":"0"}
{"type":"heartbeat","last_trade_id":0,"product_id":"BTC-USD","sequence":180756231,"time":"2020-06-30T19:14:05.735117Z"}
{"type":"done","side":"sell","product_id":"BTC-USD","time":"2020-06-30T19:14:05.787218Z","sequence":180756232,"order_id":"e256d31d-98af-4789-89b2-03612fb05ff9","reason":"canceled","price":"9160.96","remaining_size":"0.0145"}
{"type":"received","side":"buy","product_id":"BTC-USD","time":"2020-06-30T19:14:05.923254Z","sequence":180756233,"order_id":"e489e2df-9b2f-481a-b84f-3aadc31f28c2","order_type":"limit","size":"4.2484","price":"9108.48","client_oid":""}
{"type":"open","side":"buy","product_id":"BTC-USD","time":"2020-06-30T19:14:05.923254Z","sequence":180756234,"price":"9108.48","order_id":"e489e2df-9b2f-481a-b84f-3aadc31f28c2","remaining_size":"4.2484"}
{"type":"done","side":"buy","product_id":"BTC-USD","time":"2020-06-30T19:14:06.360665Z","sequence":180756235,"order_id":"48b72cd8-220b-4141-9c28-72a717e35d31","reason":"canceled","price":"9105.52","remaining_size":"8.0556"}
{"type":"done","side":"buy","product_id":"BTC-USD","time":"2020-06-30T19:14:06.365745Z","sequence":180756236,"order_id":"4b6926ca-c78a-4e3a-8b98-510ce43bcba9","reason":"canceled","price":"9101.96","remaining_size":"0.3296"}
{"type":"received","side":"sell","product_id":"BTC-USD","time":"2020-06-30T19:14:06.502522Z","sequence":180756237,"order_id":"18c79bff-b997-4cb5-859f-5e0a1782483f","order_type":"limit","size":"0.0359","price":"9111.13","client_oid":""}
{"type":"match","side":"buy","product_id":"BTC-USD","time":"2020-06-30T19:14:06.502522Z","sequence":180756238,"trade_id":14587532,"maker_order_id":"91b59a7c-6a07-4039-9536-21daf3cb3282","taker_order_id":"18c79bff-b997-4cb5-859f-5e0a1782483f","size":"0.0359","price":"9120.8"}
{"type":"done","side":"sell","product_id":"BTC-USD","time":"2020-06-30T19:14:06.502522Z","sequence":180756239,"order_id":"18c79bff-b997-4cb5-859f-5e0a1782483f","reason":"filled","price":"9111.13","remaining_size":"0"}
{"type":"heartbeat","last_trade_id":0,"product_id":"BTC-USD","sequence":180756239,"time":"2020-06-30T19:14:06.735110Z"}
{"type":"received","side":"sell","product_id":"BTC-USD","time":"2020-06-30T19:14:06.771079Z","sequence":180756240,"order_id":"788315d4-eb32-4d8b-8011-e1e5723ba8d9","order_type":"limit","size":"0.1058","price":"9161.34","client_oid":""}
{"type":"open","side":"sell","product_id":"BTC-USD","time":"2020-06-30T19:14:06.771079Z","sequence":180756241,"price":"9161.34","order_id":"788315d4-eb32-4d8b-8011-e1e5723ba8d9","remaining_size":"0.1058"}
{"type":"heartbeat","last_trade_id":0,"product_id":"BTC-USD","sequence":180756241,"time":"2020-06-30T19:14:07.735109Z"}
{"type":"received","side":"buy","product_id":"BTC-USD","time":"2020-06-30T19:14:08.524968Z","sequence":180756242,"order_id":"05c8ef17-d55a-4c51-8f46-3b6f5a8d04bf","order_type":"limit","size":"0.052","price":"9084.49","client_oid":""}
{"type":"open","side":"buy","product_id":"BTC-USD","time":"2020-06-30T19:14:08.524968Z","sequence":180756243,"price":"9084.49","order_id":"05c8ef17-d55a-4c51-8f46-3b6f5a8d04bf","remaining_size":"0.052"}
{"type":"heartbeat","last_trade_id":0,"product_id":"BTC-USD","sequence":180756243,"time":"2020-06-30T19:14:08.735120Z"}
{"type":"received","side":"buy","product_id":"BTC-USD","time":"2020-06-30T19:14:08.818259Z","sequence":180756244,"order_id":"e494f02a-c921-4452-84e1-b75b8ecac86c","order_type":"limit","size":"0.7308","price":"9107.53","client_oid":""}
{"type":"open","side":"buy","product_id":"BTC-USD","time":"2020-06-30T19:14:08.818259Z","sequence":180756245,"price":"9107.53","order_id":"e494f02a-c921-4452-84e1-b75b8ecac86c","remaining_size":"0.7308"}
{"type":"done","side":"buy","product_id":"BTC-USD","time":"2020-06-30T19:14:08.954199Z","sequence":180756246,"order_id":"e489e2df-9b2f-481a-b84f-3aadc31f28c2","reason":"canceled","price":"9108.48","remaining_size":"4.2484"}
{"type":"received","side":"sell","product_id":"BTC-USD","time":"2020-06-30T19:14:09.082399Z","sequence":180756247,"order_id":"0295ea63-22b6-419e-80f4-17f7403d14a2","order_type":"limit","size":"0.0659","price":"9110.06","client_oid":""}
{"type":"match","side":"buy","product_id":"BTC-USD","time":"2020-06-30T19:14:09.082399Z","sequence":180756248,"trade_id":14587533,"maker_order_id":"91b59a7c-6a07-4039-9536-21daf3cb3282","taker_order_id":"0295ea63-22b6-419e-80f4-17f7403d14a2","size":"0.0659","price":"9120.8"}
{"type":"done","side":"sell","product_id":"BTC-USD","time":"2020-06-30T19:14:09.082399Z","sequence":180756249,"order_id":"0295ea63-22b6-419e-80f4-17f7403d14a2","reason":"filled","price":"9110.06","remaining_size":"0"}
{"type":"received","side":"buy","product_id":"BTC-USD","time":"2020-06-30T19:14:09.657535Z","sequence":180756250,"order_id":"3888a58d-770e-4656-b7e7-26aac99cf4a6","order_type":"limit","size":"0.0659","price":"9104.43","client_oid":""}
{"type":"open","side":"buy","product_id":"BTC-USD","time":"2020-06-30T19:14:09.657535Z","sequence":180756251,"price":"9104.43","order_id":"3888a58d-770e-4656-b7e7-26aac99cf4a6","remaining_size":"0.0659"}
{"type":"heartbeat","last_trade_id":0,"product_id":"BTC-USD","sequence":180756251,"time":"2020-06-30T19:14:09.735116Z"}
{"type":"received","side":"sell","product_id":"BTC-USD","time":"2020-06-30T19:14:10.226392Z","sequence":180756252,"order_id":"008140a4-c860-4fc2-8424-55f882f37a8c","order_type":"limit","size":"0.0359","price":"9111.7","client_oid":""}
{"type":"match","side":"buy","product_id":"BTC-USD","time":"2020-06-30T19:14:10.226392Z","sequence":180756253,"trade_id":14587534,"maker_order_id":"91b59a7c-6a07-4039-9536-21daf3cb3282","taker_order_id":"008140a4-c860-4fc2-8424-55f882f37a8c","size":"0.0359","price":"9120.8"}
{"type":"done","side":"sell","product_id":"BTC-USD","time":"2020-06-30T19:14:10.226392Z","sequence":180756254,"order_id":"008140a4-c860-4fc2-8424-55f882f37a8c","reason":"filled","price":"9111.7","remaining_size":"0"}
{"type":"done","side":"sell","product_id":"BTC-USD","time":"2020-06-30T19:14:10.352411Z","sequence":180756255,"order_id":"e95e405e-2c32-49cb-b6b1-861a20ab6264","reason":"canceled","price":"9160.25","remaining_size":"0.0145"}
{"type":"received","side":"sell","product_id":"BTC-USD","time":"2020-06-30T19:14:10.495330Z","sequence":180756256,"order_id":"32d28636-9afd-460f-956c-02a73a343165","order_type":"limit","size":"2.2332","price":"9143.07","client_oid":""}
{"type":"open","side":"sell","product_id":"BTC-USD","time":"2020-06-30T19:14:10.495330Z","sequence":180756257,"price":"9143.07","order_id":"32d28636-9afd-460f-956c-02a73a343165","remaining_size":"2.2332"}
{"type":"heartbeat","last_trade_id":0,"product_id":"BTC-USD","sequence":180756257,"time":"2020-06-30T19:14:10.735033Z"}
{"type":"received","side":"sell","product_id":"BTC-USD","time":"2020-06-30T19:14:10.863252Z","sequence":180756258,"order_id":"7d61c84f-a87c-492c-b2ed-557cc9bb4675","order_type":"market","size":"0.001","funds":"9.1208","client_oid":""}
{"type":"match","side":"buy","product_id":"BTC-USD","time":"2020-06-30T19:14:10.863252Z","sequence":180756259,"trade_id":14587535,"maker_order_id":"91b59a7c-6a07-4039-9536-21daf3cb3282","taker_order_id":"7d61c84f-a87c-492c-b2ed-557cc9bb4675","size":"0.001","price":"9120.8"}
{"type":"done","side":"sell","product_id":"BTC-USD","time":"2020-06-30T19:14:10.863252Z","sequence":180756260,"order_id":"7d61c84f-a87c-492c-b2ed-557cc9bb4675","reason":"filled","remaining_size":"0"}
{"type":"received","side":"sell","product_id":"BTC-USD","time":"2020-06-30T19:14:11.058101Z","sequence":180756261,"order_id":"17f3d724-2937-4a21-8212-07a9b852bb0f","order_type":"limit","size":"0.069","price":"9161.86","client_oid":""}
{"type":"open","side":"sell","product_id":"BTC-USD","time":"2020-06-30T19:14:11.058101Z","sequence":180756262,"price":"9161.86","order_id":"17f3d724-2937-4a21-8212-07a9b852bb0f","remaining_size":"0.069"}
{"type":"heartbeat","last_trade_id":0,"product_id":"BTC-USD","sequence":180756262,"time":"2020-06-30T19:14:11.735170Z"}
{"type":"received","side":"buy","product_id":"BTC-USD","time":"2020-06-30T19:14:11.871337Z","sequence":180756263,"order_id":"880faeb7-1666-409d-bfd6-7cf1df9a0d9c","order_type":"limit","size":"0.0659","price":"9104.45","client_oid":""}
{"type":"open","side":"buy","product_id":"BTC-USD","time":"2020-06-30T19:14:11.871337Z","sequence":180756264,"price":"9104.45","order_id":"880faeb7-1666-409d-bfd6-7cf1df9a0d9c","remaining_size":"0.0659"}
{"type":"done","side":"buy","product_id":"BTC-USD","time":"2020-06-30T19:14:12.310508Z","sequence":180756265,"order_id":"e9af355c-f0cd-4411-a05c-4d4a9a651a01","reason":"canceled","price":"9083.72","remaining_size":"0.1153"}
{"type":"done","side":"buy","product_id":"BTC-USD","time":"2020-06-30T19:14:12.311256Z","sequence":180756266,"order_id":"3888a58d-770e-4656-b7e7-26aac99cf4a6","reason":"canceled","price":"9104.43","remaining_size":"0.0659"}
{"type":"received","side":"buy","product_id":"BTC-USD","time":"2020-06-30T19:14:12.447113Z","sequence":180756267,"order_id":"47b5056f-a227-478e-b2ab-6bc02b414fb6","order_type":"limit","size":"0.0888","price":"9085.73","client_oid":""}
{"type":"open","side":"buy","product_id":"BTC-USD","time":"2020-06-30T19:14:12.447113Z","sequence":180756268,"price":"9085.73","order_id":"47b5056f-a227-478e-b2ab-6bc02b414fb6","remaining_size":"0.0888"}
{"type":"received","side":"sell","product_id":"BTC-USD","time":"2020-06-30T19:14:12.696646Z","sequence":180756269,"order_id":"83469635-0f68-4499-9119-dd3e31253fe0","order_type":"limit","size":"0.1","price":"9179.22","client_oid":""}
{"type":"open","side":"sell","product_id":"BTC-USD","time":"2020-06-30T19:14:12.696646Z","sequence":180756270,"price":"9179.22","order_id":"83469635-0f68-4499-9119-dd3e31253fe0","remaining_size":"0.1"}
{"type":"heartbeat","last_trade_id":0,"product_id":"BTC-USD","sequence":180756270,"time":"2020-06-30T19:14:12.735117Z"}
{"type":"done","side":"buy","product_id":"BTC-USD","time":"2020-06-30T19:14:12.870545Z","sequence":180756271,"order_id":"43a7410f-de57-4f03-8f42-8bcd92c76315","reason":"canceled","price":"9091.33","remaining_size":"0.0283"}
{"type":"done","side":"buy","product_id":"BTC-USD","time":"2020-06-30T19:14:12.888353Z","sequence":180756272,"order_id":"05c8ef17-d55a-4c51-8f46-3b6f5a8d04bf","reason":"canceled","price":"9084.49","remaining_size":"0.052"}
{"type":"received","side":"sell","product_id":"BTC-USD","time":"2020-06-30T19:14:12.962538Z","sequence":180756273,"order_id":"1ae385dd-4bdb-4bb2-a20a-f72cd24db03d","order_type":"limit","size":"0.0359","price":"9111.27","client_oid":""}
{"type":"match","side":"buy","product_id":"BTC-USD","time":"2020-06-30T19:14:12.962538Z","sequence":180756274,"trade_id":14587536,"maker_order_id":"91b59a7c-6a07-4039-9536-21daf3cb3282","taker_order_id":"1ae385dd-4bdb-4bb2-a20a-f72cd24db03d","size":"0.0359","price":"9120.8"}
{"type":"done","side":"sell","product_id":"BTC-USD","time":"2020-06-30T19:14:12.962538Z","sequence":180756275,"order_id":"1ae385dd-4bdb-4bb2-a20a-f72cd24db03d","reason":"filled","price":"9111.27","remaining_size":"0"}
{"type":"done","side":"sell","product_id":"BTC-USD","time":"2020-06-30T19:14:13.122953Z","sequence":180756276,"order_id":"32d28636-9afd-460f-956c-02a73a343165","reason":"canceled","price":"9143.07","remaining_size":"2.2332"}
{"type":"received","side":"buy","product_id":"BTC-USD","time":"2020-06-30T19:14:13.251422Z","sequence":180756277,"order_id":"a238473b-1392-45c4-91d3-cbf8f75d8268","order_type":"limit","size":"0.548","price":"9106.82","client_oid":""}
{"type":"open","side":"buy","product_id":"BTC-USD","time":"2020-06-30T19:14:13.251422Z","sequence":180756278,"price":"9106.82","order_id":"a238473b-1392-45c4-91d3-cbf8f75d8268","remaining_size":"0.548"}
{"type":"heartbeat","last_trade_id":0,"product_id":"BTC-USD","sequence":180756278,"time":"2020-06-30T19:14:13.735122Z"}
{"type":"received","side":"buy","product_id":"BTC-USD","time":"2020-06-30T19:14:13.820582Z","sequence":180756279,"order_id":"8825890f-35fe-4f7a-a147-d951924eba77","order_type":"limit","size":"0.01","price":"9076.86","client_oid":""}
{"type":"open","side":"buy","product_id":"BTC-USD","time":"2020-06-30T19:14:13.820582Z","sequence":180756280,"price":"9076.86","order_id":"8825890f-35fe-4f7a-a147-d951924eba77","remaining_size":"0.01"}
{"type":"received","side":"buy","product_id":"BTC-USD","time":"2020-06-30T19:14:14.036182Z","sequence":180756281,"order_id":"426a921c-bd0e-4c69-b3d3-364d385da4fe","order_type":"limit","size":"0.01","price":"100","client_oid":"66a2336e-9118-4058-97cb-df7cd5444b06"}
{"type":"open","side":"buy","product_id":"BTC-USD","time":"2020-06-30T19:14:14.036182Z","sequence":180756282,"price":"100","order_id":"426a921c-bd0e-4c69-b3d3-364d385da4fe","remaining_size":"0.01"}
{"type":"done","side":"buy","product_id":"BTC-USD","time":"2020-06-30T19:14:14.042334Z","sequence":180756283,"order_id":"426a921c-bd0e-4c69-b3d3-364d385da4fe","reason":"canceled","price":"100","remaining_size":"0.01"}
{"type":"received","side":"sell","product_id":"BTC-USD","time":"2020-06-30T19:14:14.136763Z","sequence":180756284,"order_id":"94cd15a2-e907-4585-9d93-2d30696ec0a0","order_type":"limit","size":"0.8883","price":"9141.71","client_oid":""}
{"type":"open","side":"sell","product_id":"BTC-USD","time":"2020-06-30T19:14:14.136763Z","sequence":180756285,"price":"9141.71","order_id":"94cd15a2-e907-4585-9d93-2d30696ec0a0","remaining_size":"0.8883"}
{"type":"done","side":"sell","product_id":"BTC-USD","time":"2020-06-30T19:14:14.278857Z","sequence":180756286,"order_id":"83469635-0f68-4499-9119-dd3e31253fe0","reason":"canceled","price":"9179.22","remaining_size":"0.1"}
{"type":"done","side":"sell","product_id":"BTC-USD","time":"2020-06-30T19:14:14.290718Z","sequence":180756287,"order_id":"17f3d724-2937-4a21-8212-07a9b852bb0f","reason":"canceled","price":"9161.86","remaining_size":"0.069"}
{"type":"received","side":"sell","product_id":"BTC-USD","time":"2020-06-30T19:14:14.381414Z","sequence":180756288,"order_id":"76bdd832-18ad-4a17-b83e-3eda1b604124","order_type":"limit","size":"0.176","price":"9108.5","client_oid":""}
{"type":"match","side":"buy","product_id":"BTC-USD","time":"2020-06-30T19:14:14.381414Z","sequence":180756289,"trade_id":14587537,"maker_order_id":"91b59a7c-6a07-4039-9536-21daf3cb3282","taker_order_id":"76bdd832-18ad-4a17-b83e-3eda1b604124","size":"0.176","price":"9120.8"}
{"type":"done","side":"sell","product_id":"BTC-USD","time":"2020-06-30T19:14:14.381414Z","sequence":180756290,"order_id":"76bdd832-18ad-4a17-b83e-3eda1b604124","reason":"filled","price":"9108.5","remaining_size":"0"}
{"type":"received","side":"buy","product_id":"BTC-USD","time":"2020-06-30T19:14:14.667761Z","sequence":180756291,"order_id":"cde69bef-401d-44b4-80ce-50d4bbb7d175","order_type":"limit","size":"2.3946","price":"9104.99","client_oid":""}
{"type":"open","side":"buy","product_id":"BTC-USD","time":"2020-06-30T19:14:14.667761Z","sequence":180756292,"price":"9104.99","order_id":"cde69bef-401d-44b4-80ce-50d4bbb7d175","remaining_size":"2.3946"}
{"type":"heartbeat","last_trade_id":0,"product_id":"BTC-USD","sequence":180756292,"time":"2020-06-30T19:14:14.735118Z"}
{"type":"received","side":"buy","product_id":"BTC-USD","time":"2020-06-30T19:14:14.934307Z","sequence":180756293,"order_id":"084aee79-e8c1-49fe-97a0-2f226626b711","order_type":"limit","size":"0.0024","price":"9107.99","client_oid":""}
{"type":"open","side":"buy","product_id":"BTC-USD","time":"2020-06-30T19:14:14.934307Z","sequence":180756294,"price":"9107.99","order_id":"084aee79-e8c1-49fe-97a0-2f226626b711","remaining_size":"0.0024"}
{"type":"done","side":"buy","product_id":"BTC-USD","time":"2020-06-30T19:14:15.104661Z","sequence":180756295,"order_id":"47b5056f-a227-478e-b2ab-6bc02b414fb6","reason":"canceled","price":"9085.73","remaining_size":"0.0888"}
{"type":"done","side":"buy","product_id":"BTC-USD","time":"2020-06-30T19:14:15.106907Z","sequence":180756296,"order_id":"880faeb7-1666-409d-bfd6-7cf1df9a0d9c","reason":"canceled","price":"9104.45","remaining_size":"0.0659"}
{"type":"received","side":"sell","product_id":"BTC-USD","time":"2020-06-30T19:14:15.218020Z","sequence":180756297,"order_id":"3d12aa68-8e3f-4cab-b647-b4347d522fcd","order_type":"limit","size":"0.9","price":"9113.3","client_oid":""}
{"type":"match","side":"buy","product_id":"BTC-USD","time":"2020-06-30T19:14:15.218020Z","sequence":180756298,"trade_id":14587538,"maker_order_id":"91b59a7c-6a07-4039-9536-21daf3cb3282","taker_order_id":"3d12aa68-8e3f-4cab-b647-b4347d522fcd","size":"0.9","price":"9120.8"}
{"type":"done","side":"sell","product_id":"BTC-USD","time":"2020-06-30T19:14:15.218020Z","sequence":180756299,"order_id":"3d12aa68-8e3f-4cab-b647-b4347d522fcd","reason":"filled","price":"9113.3","remaining_size":"0"}
{"type":"heartbeat","last_trade_id":0,"product_id":"BTC-USD","sequence":180756299,"time":"2020-06-30T19:14:15.735119Z"}
{"type":"received","side":"sell","product_id":"BTC-USD","time":"2020-06-30T19:14:15.759072Z","sequence":180756300,"order_id":"4b47bf36-a866-4477-a805-bc3ce7a5e364","order_type":"limit","size":"0.1177","price":"9112.31","client_oid":""}
{"type":"match","side":"buy","product_id":"BTC-USD","time":"2020-06-30T19:14:15.759072Z","sequence":180756301,"trade_id":14587539,"maker_order_id":"91b59a7c-6a07-4039-9536-21daf3cb3282","taker_order_id":"4b47bf36-a866-4477-a805-bc3ce7a5e364","size":"0.1177","price":"9120.8"}
{"type":"done","side":"sell","product_id":"BTC-USD","time":"2020-06-30T19:14:15.759072Z","sequence":180756302,"order_id":"4b47bf36-a866-4477-a805-bc3ce7a5e364","reason":"filled","price":"9112.31","remaining_size":"0"}
{"type":"done","side":"buy","product_id":"BTC-USD","time":"2020-06-30T19:14:15.894116Z","sequence":180756303,"order_id":"fe6f97b3-1cfe-4361-b991-a0872569cb51","reason":"canceled","price":"9086.59","remaining_size":"0.0533"}
{"type":"received","side":"sell","product_id":"BTC-USD","time":"2020-06-30T19:14:16.612026Z","sequence":180756304,"order_id":"c0b6f370-a9f8-4e2c-b758-7278bdefeb23","order_type":"limit","size":"0.3088","price":"9112.46","client_oid":""}
{"type":"match","side":"buy","product_id":"BTC-USD","time":"2020-06-30T19:14:16.612026Z","sequence":180756305,"trade_id":14587540,"maker_order_id":"91b59a7c-6a07-4039-9536-21daf3cb3282","taker_order_id":"c0b6f370-a9f8-4e2c-b758-7278bdefeb23","size":"0.3088","price":"9120.8"}
{"type":"done","side":"sell","product_id":"BTC-USD","time":"2020-06-30T19:14:16.612026Z","sequence":180756306,"order_id":"c0b6f370-a9f8-4e2c-b758-7278bdefeb23","reason":"filled","price":"9112.46","remaining_size":"0"}
{"type":"heartbeat","last_trade_id":0,"product_id":"BTC-USD","sequence":180756306,"time":"2020-06-30T19:14:16.735120Z"}
{"type":"done","side":"sell","product_id":"BTC-USD","time":"2020-06-30T19:14:17.048941Z","sequence":180756307,"order_id":"b9aa3df5-f693-4519-bee4-5524c928f861","reason":"canceled","price":"9161.82","remaining_size":"0.0149"}
{"type":"received","side":"sell","product_id":"BTC-USD","time":"2020-06-30T19:14:17.411100Z","sequence":180756308,"order_id":"b1dadc1c-f2f1-4cb2-a137-7302b2cacf8f","order_type":"limit","size":"0.545","price":"9114.13","client_oid":""}
{"type":"match","side":"buy","product_id":"BTC-USD","time":"2020-06-30T19:14:17.411100Z","sequence":180756309,"trade_id":14587541,"maker_order_id":"91b59a7c-6a07-4039-9536-21daf3cb3282","taker_order_id":"b1dadc1c-f2f1-4cb2-a137-7302b2cacf8f","size":"0.545","price":"9120.8"}
{"type":"done","side":"sell","product_id":"BTC-USD","time":"2020-06-30T19:14:17.411100Z","sequence":180756310,"order_id":"b1dadc1c-f2f1-4cb2-a137-7302b2cacf8f","reason":"filled","price":"9114.13","remaining_size":"0"}
{"type":"received","side":"buy","product_id":"BTC-USD","time":"2020-06-30T19:14:17.692300Z","sequence":180756311,"order_id":"a7296e08-f0bb-4745-8e91-a2f04c9fd976","order_type":"limit","size":"0.6114","price":"9111.62","client_oid":""}
{"type":"open","side":"buy","product_id":"BTC-USD","time":"2020-06-30T19:14:17.692300Z","sequence":180756312,"price":"9111.62","order_id":"a7296e08-f0bb-4745-8e91-a2f04c9fd976","remaining_size":"0.6114"}
{"type":"heartbeat","last_trade_id":0,"product_id":"BTC-USD","sequence":180756312,"time":"2020-06-30T19:14:17.735115Z"}
{"type":"done","side":"sell","product_id":"BTC-USD","time":"2020-06-30T19:14:17.826571Z","sequence":180756313,"order_id":"788315d4-eb32-4d8b-8011-e1e5723ba8d9","reason":"canceled","price":"9161.34","remaining_size":"0.1058"}
{"type":"received","side":"sell","product_id":"BTC-USD","time":"2020-06-30T19:14:17.971723Z","sequence":180756314,"order_id":"f6623bdd-c307-4097-8648-d0344159c704","order_type":"limit","size":"4.5693","price":"9112.32","client_oid":""}
{"type":"match","side":"buy","product_id":"BTC-USD","time":"2020-06-30T19:14:17.971723Z","sequence":180756315,"trade_id":14587542,"maker_order_id":"91b59a7c-6a07-4039-9536-21daf3cb3282","taker_order_id":"f6623bdd-c307-4097-8648-d0344159c704","size":"4.5693","price":"9120.8"}
{"type":"done","side":"sell","product_id":"BTC-USD","time":"2020-06-30T19:14:17.971723Z","sequence":180756316,"order_id":"f6623bdd-c307-4097-8648-d0344159c704","reason":"filled","price":"9112.32","remaining_size":"0"}
{"type":"received","side":"sell","product_id":"BTC-USD","time":"2020-06-30T19:14:18.257333Z","sequence":180756317,"order_id":"039aa775-4a4c-43da-8d25-7b35304dc99d","order_type":"limit","size":"0.0658","price":"9113.93","client_oid":""}
{"type":"match","side":"buy","product_id":"BTC-USD","time":"2020-06-30T19:14:18.257333Z","sequence":180756318,"trade_id":14587543,"maker_order_id":"91b59a7c-6a07-4039-9536-21daf3cb3282","taker_order_id":"039aa775-4a4c-43da-8d25-7b35304dc99d","size":"0.0658","price":"9120.8"}
{"type":"done","side":"sell","product_id":"BTC-USD","time":"2020-06-30T19:14:18.257333Z","sequence":180756319,"order_id":"039aa775-4a4c-43da-8d25-7b35304dc99d","reason":"filled","price":"9113.93","remaining_size":"0"}
{"type":"received","side":"buy","product_id":"BTC-USD","time":"2020-06-30T19:14:18.545944Z","sequence":180756320,"order_id":"b7b97d6f-f35c-4c20-9d1b-cfab38a5cc7e","order_type":"limit","size":"0.8444","price":"9112.31","client_oid":""}
{"type":"open","side":"buy","product_id":"BTC-USD","time":"2020-06-30T19:14:18.545944Z","sequence":180756321,"price":"9112.31","order_id":"b7b97d6f-f35c-4c20-9d1b-cfab38a5cc7e","remaining_size":"0.8444"}
{"type":"heartbeat","last_trade_id":0,"product_id":"BTC-USD","sequence":180756321,"time":"2020-06-30T19:14:18.735119Z"}
{"type":"received","side":"buy","product_id":"BTC-USD","time":"2020-06-30T19:14:19.244471Z","sequence":180756322,"order_id":"e6fe646e-22d0-4fb0-8050-66cbfb313b97","order_type":"limit","size":"0.0782","price":"9071.43","client_oid":""}
{"type":"open","side":"buy","product_id":"BTC-USD","time":"2020-06-30T19:14:19.244471Z","sequence":180756323,"price":"9071.43","order_id":"e6fe646e-22d0-4fb0-8050-66cbfb313b97","remaining_size":"0.0782"}
{"type":"received","side":"buy","product_id":"BTC-USD","time":"2020-06-30T19:14:19.520376Z","sequence":180756324,"order_id":"1695e0d1-b2f2-4e51-bce9-66d1412f27fa","order_type":"limit","size":"0.9636","price":"9112.31","client_oid":""}
{"type":"open","side":"buy","product_id":"BTC-USD","time":"2020-06-30T19:14:19.520376Z","sequence":180756325,"price":"9112.31","order_id":"1695e0d1-b2f2-4e51-bce9-66d1412f27fa","remaining_size":"0.9636"}
{"type":"heartbeat","last_trade_id":0,"product_id":"BTC-USD","sequence":180756325,"time":"2020-06-30T19:14:19.735123Z"}
{"type":"received","side":"sell","product_id":"BTC-USD","time":"2020-06-30T19:14:19.809969Z","sequence":180756326,"order_id":"cd9d26c3-0537-4a45-afa1-0feeea3edd52","order_type":"limit","size":"0.0658","price":"9113.77","client_oid":""}
{"type":"match","side":"buy","product_id":"BTC-USD","time":"2020-06-30T19:14:19.809969Z","sequence":180756327,"trade_id":14587544,"maker_order_id":"91b59a7c-6a07-4039-9536-21daf3cb3282","taker_order_id":"cd9d26c3-0537-4a45-afa1-0feeea3edd52","size":"0.0658","price":"9120.8"}
{"type":"done","side":"sell","product_id":"BTC-USD","time":"2020-06-30T19:14:19.809969Z","sequence":180756328,"order_id":"cd9d26c3-0537-4a45-afa1-0feeea3edd52","reason":"filled","price":"9113.77","remaining_size":"0"}
{"type":"done","side":"buy","product_id":"BTC-USD","time":"2020-06-30T19:14:19.937647Z","sequence":180756329,"order_id":"e494f02a-c921-4452-84e1-b75b8ecac86c","reason":"canceled","price":"9107.53","remaining_size":"0.7308"}
{"type":"done","side":"sell","product_id":"BTC-USD","time":"2020-06-30T19:14:20.222362Z","sequence":180756330,"order_id":"0be78577-9238-4a76-9e46-b3336ec0b4ba","reason":"canceled","price":"9135.74","remaining_size":"0.045"}
{"type":"received","side":"buy","product_id":"BTC-USD","time":"2020-06-30T19:14:20.364148Z","sequence":180756331,"order_id":"c694ef6b-0d62-4dc7-87ac-f8747f6f1041","order_type":"limit","size":"1.2089","price":"9112.31","client_oid":""}
{"type":"open","side":"buy","product_id":"BTC-USD","time":"2020-06-30T19:14:20.364148Z","sequence":180756332,"price":"9112.31","order_id":"c694ef6b-0d62-4dc7-87ac-f8747f6f1041","remaining_size":"1.2089"}
{"type":"heartbeat","last_trade_id":0,"product_id":"BTC-USD","sequence":180756332,"time":"2020-06-30T19:14:20.735119Z"}
{"type":"done","side":"buy","product_id":"BTC-USD","time":"2020-06-30T19:14:20.800086Z","sequence":180756333,"order_id":"1695e0d1-b2f2-4e51-bce9-66d1412f27fa","reason":"canceled","price":"9112.31","remaining_size":"0.9636"}
{"type":"received","side":"buy","product_id":"BTC-USD","time":"2020-06-30T19:14:21.468359Z","sequence":180756334,"order_id":"a9661af8-ff9c-4bae-aeb2-10d16a1c6da7","order_type":"limit","size":"1.4475","price":"9112.31","client_oid":""}
{"type":"open","side":"buy","product_id":"BTC-USD","time":"2020-06-30T19:14:21.468359Z","sequence":180756335,"price":"9112.31","order_id":"a9661af8-ff9c-4bae-aeb2-10d16a1c6da7","remaining_size":"1.4475"}
{"type":"heartbeat","last_trade_id":0,"product_id":"BTC-USD","sequence":180756335,"time":"2020-06-30T19:14:21.735068Z"}
{"type":"received","side":"buy","product_id":"BTC-USD","time":"2020-06-30T19:14:22.299770Z","sequence":180756336,"order_id":"c6dd6b5a-6edb-4aa8-a7f3-e01917da31ab","order_type":"limit","size":"0.301","price":"9112.31","client_oid":""}
{"type":"open","side":"buy","product_id":"BTC-USD","time":"2020-06-30T19:14:22.299770Z","sequence":180756337,"price":"9112.31","order_id":"c6dd6b5a-6edb-4aa8-a7f3-e01917da31ab","remaining_size":"0.301"}
{"type":"received","side":"sell","product_id":"BTC-USD","time":"2020-06-30T19:14:22.602868Z","sequence":180756338,"order_id":"717e005f-b8a8-457a-93f0-8f38ef828d25","order_type":"limit","size":"0.2572","price":"9112.14","client_oid":""}
{"type":"match","side":"buy","product_id":"BTC-USD","time":"2020-06-30T19:14:22.602868Z","sequence":180756339,"trade_id":14587545,"maker_order_id":"91b59a7c-6a07-4039-9536-21daf3cb3282","taker_order_id":"717e005f-b8a8-457a-93f0-8f38ef828d25","size":"0.2572","price":"9120.8"}
{"type":"done","side":"sell","product_id":"BTC-USD","time":"2020-06-30T19:14:22.602868Z","sequence":180756340,"order_id":"717e005f-b8a8-457a-93f0-8f38ef828d25","reason":"filled","price":"9112.14","remaining_size":"0"}
{"type":"heartbeat","last_trade_id":0,"product_id":"BTC-USD","sequence":180756340,"time":"2020-06-30T19:14:22.735097Z"}
{"type":"received","side":"sell","product_id":"BTC-USD","time":"2020-06-30T19:14:23.408937Z","sequence":180756341,"order_id":"17fb9045-53d3-466a-a0f7-89f70da27e56","order_type":"limit","size":"0.069","price":"9160.53","client_oid":""}
{"type":"open","side":"sell","product_id":"BTC-USD","time":"2020-06-30T19:14:23.408937Z","sequence":180756342,"price":"9160.53","order_id":"17fb9045-53d3-466a-a0f7-89f70da27e56","remaining_size":"0.069"}
{"type":"heartbeat","last_trade_id":0,"product_id":"BTC-USD","sequence":180756342,"time":"2020-06-30T19:14:23.735117Z"}
{"type":"received","side":"sell","product_id":"BTC-USD","time":"2020-06-30T19:14:24.220935Z","sequence":180756343,"order_id":"54559fbc-c302-45b4-b837-a1088f990eff","order_type":"limit","size":"0.9","price":"9113.98","client_oid":""}
{"type":"match","side":"buy","product_id":"BTC-USD","time":"2020-06-30T19:14:24.220935Z","sequence":180756344,"trade_id":14587546,"maker_order_id":"91b59a7c-6a07-4039-9536-21daf3cb3282","taker_order_id":"54559fbc-c302-45b4-b837-a1088f990eff","size":"0.9","price":"9120.8"}
{"type":"done","side":"sell","product_id":"BTC-USD","time":"2020-06-30T19:14:24.220935Z","sequence":180756345,"order_id":"54559fbc-c302-45b4-b837-a1088f990eff","reason":"filled","price":"9113.98","remaining_size":"0"}
{"type":"done","side":"sell","product_id":"BTC-USD","time":"2020-06-30T19:14:24.404590Z","sequence":180756346,"order_id":"17fb9045-53d3-466a-a0f7-89f70da27e56","reason":"canceled","price":"9160.53","remaining_size":"0.069"}
{"type":"received","side":"buy","product_id":"BTC-USD","time":"2020-06-30T19:14:24.502550Z","sequence":180756347,"order_id":"ecd5e04a-e6de-4f6f-a183-a145568106e7","order_type":"limit","size":"0.2525","price":"9111.81","client_oid":""}
{"type":"open","side":"buy","product_id":"BTC-USD","time":"2020-06-30T19:14:24.502550Z","sequence":180756348,"price":"9111.81","order_id":"ecd5e04a-e6de-4f6f-a183-a145568106e7","remaining_size":"0.2525"}
{"type":"heartbeat","last_trade_id":0,"product_id":"BTC-USD","sequence":180756348,"time":"2020-06-30T19:14:24.735071Z"}
{"type":"received","side":"sell","product_id":"BTC-USD","time":"2020-06-30T19:14:24.803736Z","sequence":180756349,"order_id":"694954fc-b43f-43f3-86d8-87bb685d585b","order_type":"limit","size":"1.5","price":"9113.97","client_oid":""}
{"type":"match","side":"buy","product_id":"BTC-USD","time":"2020-06-30T19:14:24.803736Z","sequence":180756350,"trade_id":14587547,"maker_order_id":"91b59a7c-6a07-4039-9536-21daf3cb3282","taker_order_id":"694954fc-b43f-43f3-86d8-87bb685d585b","size":"1.5","price":"9120.8"}
{"type":"done","side":"sell","product_id":"BTC-USD","time":"2020-06-30T19:14:24.803736Z","sequence":180756351,"order_id":"694954fc-b43f-43f3-86d8-87bb685d585b","reason":"filled","price":"9113.97","remaining_size":"0"}
{"type":"done","side":"buy","product_id":"BTC-USD","time":"2020-06-30T19:14:24.947343Z","sequence":180756352,"order_id":"8825890f-35fe-4f7a-a147-d951924eba77","reason":"canceled","price":"9076.86","remaining_size":"0.01"}
{"type":"done","side":"buy","product_id":"BTC-USD","time":"2020-06-30T19:14:24.951199Z","sequence":180756353,"order_id":"e6fe646e-22d0-4fb0-8050-66cbfb313b97","reason":"canceled","price":"9071.43","remaining_size":"0.0782"}
{"type":"received","side":"buy","product_id":"BTC-USD","time":"2020-06-30T19:14:25.090301Z","sequence":180756354,"order_id":"7e90a946-e2d2-4750-9bc8-1518295a0b5b","order_type":"limit","size":"0.0223","price":"9103.34","client_oid":""}
{"type":"open","side":"buy","product_id":"BTC-USD","time":"2020-06-30T19:14:25.090301Z","sequence":180756355,"price":"9103.34","order_id":"7e90a946-e2d2-4750-9bc8-1518295a0b5b","remaining_size":"0.0223"}
{"type":"received","side":"sell","product_id":"BTC-USD","time":"2020-06-30T19:14:25.453276Z","sequence":180756356,"order_id":"ce489b22-22a5-4de3-9334-a84224fd409d","order_type":"limit","size":"0.05","price":"9113.95","client_oid":""}
{"type":"match","side":"buy","product_id":"BTC-USD","time":"2020-06-30T19:14:25.453276Z","sequence":180756357,"trade_id":14587548,"maker_order_id":"91b59a7c-6a07-4039-9536-21daf3cb3282","taker_order_id":"ce489b22-22a5-4de3-9334-a84224fd409d","size":"0.05","price":"9120.8"}
{"type":"done","side":"sell","product_id":"BTC-USD","time":"2020-06-30T19:14:25.453276Z","sequence":180756358,"order_id":"ce489b22-22a5-4de3-9334-a84224fd409d","reason":"filled","price":"9113.95","remaining_size":"0"}
{"type":"done","side":"buy","product_id":"BTC-USD","time":"2020-06-30T19:14:25.500113Z","sequence":180756359,"order_id":"00fb51a2-9fba-4419-8eb1-c6ee2d01c5d2","reason":"canceled","price":"9107.79","remaining_size":"1.1114"}
{"type":"done","side":"buy","product_id":"BTC-USD","time":"2020-06-30T19:14:25.506593Z","sequence":180756360,"order_id":"c694ef6b-0d62-4dc7-87ac-f8747f6f1041","reason":"canceled","price":"9112.31","remaining_size":"1.2089"}
{"type":"heartbeat","last_trade_id":0,"product_id":"BTC-USD","sequence":180756360,"time":"2020-06-30T19:14:25.735097Z"}
{"type":"done","side":"sell","product_id":"BTC-USD","time":"2020-06-30T19:14:25.887830Z","sequence":180756361,"order_id":"2b494fa7-0c09-42d7-9465-9a14f610338c","reason":"canceled","price":"9121.5","remaining_size":"0.0147"}
{"type":"done","side":"sell","product_id":"BTC-USD","time":"2020-06-30T19:14:25.894763Z","sequence":180756362,"order_id":"94cd15a2-e907-4585-9d93-2d30696ec0a0","reason":"canceled","price":"9141.71","remaining_size":"0.8883"}
{"type":"received","side":"sell","product_id":"BTC-USD","time":"2020-06-30T19:14:26.034592Z","sequence":180756363,"order_id":"2181cde4-61e2-47a7-aede-087bd506ef0b","order_type":"limit","size":"4.2357","price":"9112.19","client_oid":""}
{"type":"match","side":"buy","product_id":"BTC-USD","time":"2020-06-30T19:14:26.034592Z","sequence":180756364,"trade_id":14587549,"maker_order_id":"91b59a7c-6a07-4039-9536-21daf3cb3282","taker_order_id":"2181cde4-61e2-47a7-aede-087bd506ef0b","size":"4.2357","price":"9120.8"}
{"type":"done","side":"sell","product_id":"BTC-USD","time":"2020-06-30T19:14:26.034592Z","sequence":180756365,"order_id":"2181cde4-61e2-47a7-aede-087bd506ef0b","reason":"filled","price":"9112.19","remaining_size":"0"}
{"type":"heartbeat","last_trade_id":0,"product_id":"BTC-USD","sequence":180756365,"time":"2020-06-30T19:14:26.735085Z"}
{"type":"received","side":"sell","product_id":"BTC-USD","time":"2020-06-30T19:14:26.869619Z","sequence":180756366,"order_id":"dd39a220-43ea-4219-9cfe-8bb238e90fdb","order_type":"limit","size":"0.9","price":"9113.9","client_oid":""}
{"type":"match","side":"buy","product_id":"BTC-USD","time":"2020-06-30T19:14:26.869619Z","sequence":180756367,"trade_id":14587550,"maker_order_id":"91b59a7c-6a07-4039-9536-21daf3cb3282","taker_order_id":"dd39a220-43ea-4219-9cfe-8bb238e90fdb","size":"0.9","price":"9120.8"}
{"type":"done","side":"sell","product_id":"BTC-USD","time":"2020-06-30T19:14:26.869619Z","sequence":180756368,"order_id":"dd39a220-43ea-4219-9cfe-8bb238e90fdb","reason":"filled","price":"9113.9","remaining_size":"0"}
{"type":"received","side":"buy","product_id":"BTC-USD","time":"2020-06-30T19:14:27.418122Z","sequence":180756369,"order_id":"fb074f90-f18b-4c98-a92e-5845cec7a31d","order_type":"limit","size":"0.0223","price":"9103.48","client_oid":""}
{"type":"open","side":"buy","product_id":"BTC-USD","time":"2020-06-30T19:14:27.418122Z","sequence":180756370,"price":"9103.48","order_id":"fb074f90-f18b-4c98-a92e-5845cec7a31d","remaining_size":"0.0223"}
{"type":"received","side":"buy","product_id":"BTC-USD","time":"2020-06-30T19:14:27.697449Z","sequence":180756371,"order_id":"7b094650-0b0d-40a2-83bf-76a72ffdb2b5","order_type":"limit","size":"0.0737","price":"9074.46","client_oid":""}
{"type":"open","side":"buy","product_id":"BTC-USD","time":"2020-06-30T19:14:27.697449Z","sequence":180756372,"price":"9074.46","order_id":"7b094650-0b0d-40a2-83bf-76a72ffdb2b5","remaining_size":"0.0737"}
{"type":"heartbeat","last_trade_id":0,"product_id":"BTC-USD","sequence":180756372,"time":"2020-06-30T19:14:27.735094Z"}
{"type":"done","side":"buy","product_id":"BTC-USD","time":"2020-06-30T19:14:27.844151Z","sequence":180756373,"order_id":"cde69bef-401d-44b4-80ce-50d4bbb7d175","reason":"canceled","price":"9104.99","remaining_size":"2.3946"}
{"type":"done","side":"buy","product_id":"BTC-USD","time":"2020-06-30T19:14:27.847198Z","sequence":180756374,"order_id":"27ce9adb-221c-4a1c-88c8-d95890b3bc92","reason":"canceled","price":"9091.7","remaining_size":"2.2905"}
{"type":"done","side":"buy","product_id":"BTC-USD","time":"2020-06-30T19:14:27.970816Z","sequence":180756375,"order_id":"a7296e08-f0bb-4745-8e91-a2f04c9fd976","reason":"canceled","price":"9111.62","remaining_size":"0.6114"}
{"type":"heartbeat","last_trade_id":0,"product_id":"BTC-USD","sequence":180756375,"time":"2020-06-30T19:14:28.735036Z"}
{"type":"received","side":"buy","product_id":"BTC-USD","time":"2020-06-30T19:14:29.017442Z","sequence":180756376,"order_id":"e9a12732-20e0-43bb-8d58-a24679b569a8","order_type":"limit","size":"0.01","price":"100","client_oid":"52a38a3c-5236-4606-8b35-1bc4b8e5968f"}
{"type":"open","side":"buy","product_id":"BTC-USD","time":"2020-06-30T19:14:29.017442Z","sequence":180756377,"price":"100","order_id":"e9a12732-20e0-43bb-8d58-a24679b569a8","remaining_size":"0.01"}
{"type":"done","side":"buy","product_id":"BTC-USD","time":"2020-06-30T19:14:29.027256Z","sequence":180756378,"order_id":"e9a12732-20e0-43bb-8d58-a24679b569a8","reason":"canceled","price":"100","remaining_size":"0.01"}
{"type":"received","side":"sell","product_id":"BTC-USD","time":"2020-06-30T19:14:29.151322Z","sequence":180756379,"order_id":"b5df9214-2132-47c0-b8b8-6912d3e38970","order_type":"limit","size":"0.0033","price":"9118.33","client_oid":""}
{"type":"match","side":"buy","product_id":"BTC-USD","time":"2020-06-30T19:14:29.151322Z","sequence":180756380,"trade_id":14587551,"maker_order_id":"91b59a7c-6a07-4039-9536-21daf3cb3282","taker_order_id":"b5df9214-2132-47c0-b8b8-6912d3e38970","size":"0.0033","price":"9120.8"}
{"type":"done","side":"sell","product_id":"BTC-USD","time":"2020-06-30T19:14:29.151322Z","sequence":180756381,"order_id":"b5df9214-2132-47c0-b8b8-6912d3e38970","reason":"filled","price":"9118.33","remaining_size":"0"}
{"type":"received","side":"buy","product_id":"BTC-USD","time":"2020-06-30T19:14:29.718794Z","sequence":180756382,"order_id":"5e028cad-3ee7-4dea-9540-fc67842c1d38","order_type":"limit","size":"0.7968","price":"9107.96","client_oid":""}
{"type":"open","side":"buy","product_id":"BTC-USD","time":"2020-06-30T19:14:29.718794Z","sequence":180756383,"price":"9107.96","order_id":"5e028cad-3ee7-4dea-9540-fc67842c1d38","remaining_size":"0.7968"}
{"type":"heartbeat","last_trade_id":0,"product_id":"BTC-USD","sequence":180756383,"time":"2020-06-30T19:14:29.735170Z"}
{"type":"received","side":"buy","product_id":"BTC-USD","time":"2020-06-30T19:14:30.286622Z","sequence":180756384,"order_id":"bf5fb77e-a2aa-4a29-9fb8-4e3fe5ee57be","order_type":"limit","size":"1.0339","price":"9112.18","client_oid":""}
{"type":"open","side":"buy","product_id":"BTC-USD","time":"2020-06-30T19:14:30.286622Z","sequence":180756385,"price":"9112.18","order_id":"bf5fb77e-a2aa-4a29-9fb8-4e3fe5ee57be","remaining_size":"1.0339"}
{"type":"received","side":"buy","product_id":"BTC-USD","time":"2020-06-30T19:14:30.549206Z","sequence":180756386,"order_id":"5db12265-cfc9-4b9e-b8d7-152607a4926b","order_type":"limit","size":"0.0737","price":"9076.92","client_oid":""}
{"type":"open","side":"buy","product_id":"BTC-USD","time":"2020-06-30T19:14:30.549206Z","sequence":180756387,"price":"9076.92","order_id":"5db12265-cfc9-4b9e-b8d7-152607a4926b","remaining_size":"0.0737"}
{"type":"done","side":"buy","product_id":"BTC-USD","time":"2020-06-30T19:14:30.740626Z","sequence":180756388,"order_id":"b7b97d6f-f35c-4c20-9d1b-cfab38a5cc7e","reason":"canceled","price":"9112.31","remaining_size":"0.8444"}
{"type":"heartbeat","last_trade_id":0,"product_id":"BTC-USD","sequence":180756388,"time":"2020-06-30T19:14:30.735124Z"}
{"type":"heartbeat","last_trade_id":0,"product_id":"BTC-USD","sequence":180756388,"time":"2020-06-30T19:14:31.735122Z"}
{"type":"received","side":"buy","product_id":"BTC-USD","time":"2020-06-30T19:14:32.537210Z","sequence":180756389,"order_id":"6974f2db-814b-473d-bf9e-7cd5286c6240","order_type":"limit","size":"0.049","price":"9103.61","client_oid":""}
{"type":"open","side":"buy","product_id":"BTC-USD","time":"2020-06-30T19:14:32.537210Z","sequence":180756390,"price":"9103.61","order_id":"6974f2db-814b-473d-bf9e-7cd5286c6240","remaining_size":"0.049"}
{"type":"heartbeat","last_trade_id":0,"product_id":"BTC-USD","sequence":180756390,"time":"2020-06-30T19:14:32.735120Z"}
{"type":"received","side":"sell","product_id":"BTC-USD","time":"2020-06-30T19:14:33.655116Z","sequence":180756391,"order_id":"d0f626cf-5742-4c8f-ae3f-500a9106bcd4","order_type":"limit","size":"0.05","price":"9112.91","client_oid":""}
{"type":"match","side":"buy","product_id":"BTC-USD","time":"2020-06-30T19:14:33.655116Z","sequence":180756392,"trade_id":14587552,"maker_order_id":"91b59a7c-6a07-4039-9536-21daf3cb3282","taker_order_id":"d0f626cf-5742-4c8f-ae3f-500a9106bcd4","size":"0.05","price":"9120.8"}
{"type":"done","side":"sell","product_id":"BTC-USD","time":"2020-06-30T19:14:33.655116Z","sequence":180756393,"order_id":"d0f626cf-5742-4c8f-ae3f-500a9106bcd4","reason":"filled","price":"9112.91","remaining_size":"0"}
{"type":"heartbeat","last_trade_id":0,"product_id":"BTC-USD","sequence":180756393,"time":"2020-06-30T19:14:33.735123Z"}
{"type":"received","side":"sell","product_id":"BTC-USD","time":"2020-06-30T19:14:34.467518Z","sequence":180756394,"order_id":"ca4b735a-594b-4a1f-9034-9fe771e1b786","order_type":"limit","size":"0.05","price":"9113.04","client_oid":""}
{"type":"match","side":"buy","product_id":"BTC-USD","time":"2020-06-30T19:14:34.467518Z","sequence":180756395,"trade_id":14587553,"maker_order_id":"91b59a7c-6a07-4039-9536-21daf3cb3282","taker_order_id":"ca4b735a-594b-4a1f-9034-9fe771e1b786","size":"0.05","price":"9120.8"}
{"type":"done","side":"sell","product_id":"BTC-USD","time":"2020-06-30T19:14:34.467518Z","sequence":180756396,"order_id":"ca4b735a-594b-4a1f-9034-9fe771e1b786","reason":"filled","price":"9113.04","remaining_size":"0"}
{"type":"heartbeat","last_trade_id":0,"product_id":"BTC-USD","sequence":180756396,"time":"2020-06-30T19:14:34.735117Z"}
{"type":"received","side":"sell","product_id":"BTC-USD","time":"2020-06-30T19:14:34.751308Z","sequence":180756397,"order_id":"8383a37c-59ff-4ad6-a0a4-3dcbf0e7e412","order_type":"limit","size":"0.0013","price":"9113.34","client_oid":""}
{"type":"match","side":"buy","product_id":"BTC-USD","time":"2020-06-30T19:14:34.751308Z","sequence":180756398,"trade_id":14587554,"maker_order_id":"91b59a7c-6a07-4039-9536-21daf3cb3282","taker_order_id":"8383a37c-59ff-4ad6-a0a4-3dcbf0e7e412","size":"0.0013","price":"9120.8"}
{"type":"done","side":"sell","product_id":"BTC-USD","time":"2020-06-30T19:14:34.751308Z","sequence":180756399,"order_id":"8383a37c-59ff-4ad6-a0a4-3dcbf0e7e412","reason":"filled","price":"9113.34","remaining_size":"0"}
{"type":"received","side":"sell","product_id":"BTC-USD","time":"2020-06-30T19:14:35.358126Z","sequence":180756400,"order_id":"01ffe599-530d-4227-b17c-734723e6099e","order_type":"limit","size":"0.0625","price":"9113.24","client_oid":""}
{"type":"match","side":"buy","product_id":"BTC-USD","time":"2020-06-30T19:14:35.358126Z","sequence":180756401,"trade_id":14587555,"maker_order_id":"91b59a7c-6a07-4039-9536-21daf3cb3282","taker_order_id":"01ffe599-530d-4227-b17c-734723e6099e","size":"0.0625","price":"9120.8"}
{"type":"done","side":"sell","product_id":"BTC-USD","time":"2020-06-30T19:14:35.358126Z","sequence":180756402,"order_id":"01ffe599-530d-4227-b17c-734723e6099e","reason":"filled","price":"9113.24","remaining_size":"0"}
{"type":"heartbeat","last_trade_id":0,"product_id":"BTC-USD","sequence":180756402,"time":"2020-06-30T19:14:35.735121Z"}
{"type":"received","side":"sell","product_id":"BTC-USD","time":"2020-06-30T19:14:35.864324Z","sequence":180756403,"order_id":"2cd701b4-a35f-4cfb-82f3-5709dc153368","order_type":"limit","size":"0.01","price":"9161.55","client_oid":""}
{"type":"open","side":"sell","product_id":"BTC-USD","time":"2020-06-30T19:14:35.864324Z","sequence":180756404,"price":"9161.55","order_id":"2cd701b4-a35f-4cfb-82f3-5709dc153368","remaining_size":"0.01"}
{"type":"received","side":"buy","product_id":"BTC-USD","time":"2020-06-30T19:14:36.114301Z","sequence":180756405,"order_id":"3494d785-f30c-4723-9a11-f97bfd3ad2be","order_type":"limit","size":"0.0581","price":"9111.98","client_oid":""}
{"type":"open","side":"buy","product_id":"BTC-USD","time":"2020-06-30T19:14:36.114301Z","sequence":180756406,"price":"9111.98","order_id":"3494d785-f30c-4723-9a11-f97bfd3ad2be","remaining_size":"0.0581"}
{"type":"done","side":"buy","product_id":"BTC-USD","time":"2020-06-30T19:14:36.543502Z","sequence":180756407,"order_id":"ecd5e04a-e6de-4f6f-a183-a145568106e7","reason":"canceled","price":"9111.81","remaining_size":"0.2525"}
{"type":"heartbeat","last_trade_id":0,"product_id":"BTC-USD","sequence":180756407,"time":"2020-06-30T19:14:36.735123Z"}
{"type":"received","side":"sell","product_id":"BTC-USD","time":"2020-06-30T19:14:36.948050Z","sequence":180756408,"order_id":"351c3f83-3605-4c2c-b4fe-3ae8fdeaf048","order_type":"limit","size":"0.05","price":"9113.15","client_oid":""}
{"type":"match","side":"buy","product_id":"BTC-USD","time":"2020-06-30T19:14:36.948050Z","sequence":180756409,"trade_id":14587556,"maker_order_id":"91b59a7c-6a07-4039-9536-21daf3cb3282","taker_order_id":"351c3f83-3605-4c2c-b4fe-3ae8fdeaf048","size":"0.05","price":"9120.8"}
{"type":"done","side":"sell","product_id":"BTC-USD","time":"2020-06-30T19:14:36.948050Z","sequence":180756410,"order_id":"351c3f83-3605-4c2c-b4fe-3ae8fdeaf048","reason":"filled","price":"9113.15","remaining_size":"0"}
{"type":"received","side":"buy","product_id":"BTC-USD","time":"2020-06-30T19:14:37.210819Z","sequence":180756411,"order_id":"b7390e6c-1b00-4dcf-a7f3-0eac0feec6bf","order_type":"limit","size":"0.0892","price":"9071.04","client_oid":""}
{"type":"open","side":"buy","product_id":"BTC-USD","time":"2020-06-30T19:14:37.210819Z","sequence":180756412,"price":"9071.04","order_id":"b7390e6c-1b00-4dcf-a7f3-0eac0feec6bf","remaining_size":"0.0892"}
{"type":"done","side":"buy","product_id":"BTC-USD","time":"2020-06-30T19:14:37.661616Z","sequence":180756413,"order_id":"aaacaa6b-4dd8-4e0f-b747-bc2b4e43a60d","reason":"canceled","price":"9104.3","remaining_size":"15.397"}
{"type":"heartbeat","last_trade_id":0,"product_id":"BTC-USD","sequence":180756413,"time":"2020-06-30T19:14:37.735120Z"}
{"type":"received","side":"buy","product_id":"BTC-USD","time":"2020-06-30T19:14:38.052905Z","sequence":180756414,"order_id":"85f9ad7f-e3e9-453b-b45e-e939442c9427","order_type":"limit","size":"7.6778","price":"9112.39","client_oid":""}
{"type":"open","side":"buy","product_id":"BTC-USD","time":"2020-06-30T19:14:38.052905Z","sequence":180756415,"price":"9112.39","order_id":"85f9ad7f-e3e9-453b-b45e-e939442c9427","remaining_size":"7.6778"}
{"type":"done","side":"buy","product_id":"BTC-USD","time":"2020-06-30T19:14:38.483625Z","sequence":180756416,"order_id":"bf5fb77e-a2aa-4a29-9fb8-4e3fe5ee57be","reason":"canceled","price":"9112.18","remaining_size":"1.0339"}
{"type":"received","side":"buy","product_id":"BTC-USD","time":"2020-06-30T19:14:38.610444Z","sequence":180756417,"order_id":"80b60463-2b0d-48c6-acb2-9630e7abff35","order_type":"limit","size":"0.002","price":"9017.56","client_oid":""}
{"type":"open","side":"buy","product_id":"BTC-USD","time":"2020-06-30T19:14:38.610444Z","sequence":180756418,"price":"9017.56","order_id":"80b60463-2b0d-48c6-acb2-9630e7abff35","remaining_size":"0.002"}
{"type":"heartbeat","last_trade_id":0,"product_id":"BTC-USD","sequence":180756418,"time":"2020-06-30T19:14:38.735124Z"}
{"type":"received","side":"sell","product_id":"BTC-USD","time":"2020-06-30T19:14:39.191812Z","sequence":180756419,"order_id":"ef0195ef-d4ed-4d61-baa9-1a4281567fdd","order_type":"limit","size":"0.002","price":"9253.18","client_oid":""}
{"type":"open","side":"sell","product_id":"BTC-USD","time":"2020-06-30T19:14:39.191812Z","sequence":180756420,"price":"9253.18","order_id":"ef0195ef-d4ed-4d61-baa9-1a4281567fdd","remaining_size":"0.002"}
{"type":"heartbeat","last_trade_id":0,"product_id":"BTC-USD","sequence":180756420,"time":"2020-06-30T19:14:39.735127Z"}
{"type":"received","side":"sell","product_id":"BTC-USD","time":"2020-06-30T19:14:40.014121Z","sequence":180756421,"order_id":"5417d20c-9c97-42a2-9fbb-cd58a97a6e0b","order_type":"limit","size":"0.0149","price":"9160.03","client_oid":""}
{"type":"open","side":"sell","product_id":"BTC-USD","time":"2020-06-30T19:14:40.014121Z","sequence":180756422,"price":"9160.03","order_id":"5417d20c-9c97-42a2-9fbb-cd58a97a6e0b","remaining_size":"0.0149"}
{"type":"received","side":"sell","product_id":"BTC-USD","time":"2020-06-30T19:14:40.285582Z","sequence":180756423,"order_id":"a5a1aec3-a8f3-4525-978b-7df8b52b4894","order_type":"limit","size":"0.069","price":"9159.34","client_oid":""}
{"type":"open","side":"sell","product_id":"BTC-USD","time":"2020-06-30T19:14:40.285582Z","sequence":180756424,"price":"9159.34","order_id":"a5a1aec3-a8f3-4525-978b-7df8b52b4894","remaining_size":"0.069"}
{"type":"received","side":"sell","product_id":"BTC-USD","time":"2020-06-30T19:14:40.561373Z","sequence":180756425,"order_id":"9814ecef-d73d-41a4-ad5a-4ff1014110d7","order_type":"limit","size":"0.01","price":"9158.79","client_oid":""}
{"type":"open","side":"sell","product_id":"BTC-USD","time":"2020-06-30T19:14:40.561373Z","sequence":180756426,"price":"9158.79","order_id":"9814ecef-d73d-41a4-ad5a-4ff1014110d7","remaining_size":"0.01"}
{"type":"heartbeat","last_trade_id":0,"product_id":"BTC-USD","sequence":180756426,"time":"2020-06-30T19:14:40.735147Z"}
{"type":"received","side":"sell","product_id":"BTC-USD","time":"2020-06-30T19:14:41.105068Z","sequence":180756427,"order_id":"145e6a33-2376-4c69-87cc-74bde78cf8be","order_type":"limit","size":"0.0658","price":"9113.44","client_oid":""}
{"type":"match","side":"buy","product_id":"BTC-USD","time":"2020-06-30T19:14:41.105068Z","sequence":180756428,"trade_id":14587557,"maker_order_id":"91b59a7c-6a07-4039-9536-21daf3cb3282","taker_order_id":"145e6a33-2376-4c69-87cc-74bde78cf8be","size":"0.0658","price":"9120.8"}
{"type":"done","side":"sell","product_id":"BTC-USD","time":"2020-06-30T19:14:41.105068Z","sequence":180756429,"order_id":"145e6a33-2376-4c69-87cc-74bde78cf8be","reason":"filled","price":"9113.44","remaining_size":"0"}
{"type":"received","side":"sell","product_id":"BTC-USD","time":"2020-06-30T19:14:41.384645Z","sequence":180756430,"order_id":"8cb77ce0-2af7-477f-a287-99fe442c82d7","order_type":"limit","size":"0.0443","price":"9142.27","client_oid":""}
{"type":"open","side":"sell","product_id":"BTC-USD","time":"2020-06-30T19:14:41.384645Z","sequence":180756431,"price":"9142.27","order_id":"8cb77ce0-2af7-477f-a287-99fe442c82d7","remaining_size":"0.0443"}
{"type":"received","side":"buy","product_id":"BTC-USD","time":"2020-06-30T19:14:41.464298Z","sequence":180756432,"order_id":"c9e7b512-dffa-4154-ac47-6bd145fd7886","order_type":"market","size":"0.001","funds":"9.12082","client_oid":""}
{"type":"match","side":"sell","product_id":"BTC-USD","time":"2020-06-30T19:14:41.464298Z","sequence":180756433,"trade_id":14587558,"maker_order_id":"36fe0734-4801-466d-b093-cccd411db09a","taker_order_id":"c9e7b512-dffa-4154-ac47-6bd145fd7886","size":"0.001","price":"9120.82"}
{"type":"done","side":"buy","product_id":"BTC-USD","time":"2020-06-30T19:14:41.464298Z","sequence":180756434,"order_id":"c9e7b512-dffa-4154-ac47-6bd145fd7886","reason":"filled","remaining_size":"0"}
{"type":"heartbeat","last_trade_id":0,"product_id":"BTC-USD","sequence":180756434,"time":"2020-06-30T19:14:41.735130Z"}
{"type":"received","side":"sell","product_id":"BTC-USD","time":"2020-06-30T19:14:41.936733Z","sequence":180756435,"order_id":"4a23224d-2fef-41d1-8d39-9645e585d1d2","order_type":"limit","size":"0.069","price":"9159","client_oid":""}
{"type":"open","side":"sell","product_id":"BTC-USD","time":"2020-06-30T19:14:41.936733Z","sequence":180756436,"price":"9159","order_id":"4a23224d-2fef-41d1-8d39-9645e585d1d2","remaining_size":"0.069"}
{"type":"received","side":"sell","product_id":"BTC-USD","time":"2020-06-30T19:14:42.506101Z","sequence":180756437,"order_id":"8ac18727-b2fc-45f7-94fd-113f55a2298f","order_type":"limit","size":"0.276","price":"9112.39","client_oid":""}
{"type":"match","side":"buy","product_id":"BTC-USD","time":"2020-06-30T19:14:42.506101Z","sequence":180756438,"trade_id":14587559,"maker_order_id":"91b59a7c-6a07-4039-9536-21daf3cb3282","taker_order_id":"8ac18727-b2fc-45f7-94fd-113f55a2298f","size":"0.276","price":"9120.8"}
{"type":"done","side":"sell","product_id":"BTC-USD","time":"2020-06-30T19:14:42.506101Z","sequence":180756439,"order_id":"8ac18727-b2fc-45f7-94fd-113f55a2298f","reason":"filled","price":"9112.39","remaining_size":"0"}
{"type":"heartbeat","last_trade_id":0,"product_id":"BTC-USD","sequence":180756439,"time":"2020-06-30T19:14:42.735134Z"}
{"type":"received","side":"sell","product_id":"BTC-USD","time":"2020-06-30T19:14:43.036071Z","sequence":180756440,"order_id":"eb87598e-c267-423a-80ef-fe661e48230f","order_type":"limit","size":"0.9","price":"9113.55","client_oid":""}
{"type":"match","side":"buy","product_id":"BTC-USD","time":"2020-06-30T19:14:43.036071Z","sequence":180756441,"trade_id":14587560,"maker_order_id":"91b59a7c-6a07-4039-9536-21daf3cb3282","taker_order_id":"eb87598e-c267-423a-80ef-fe661e48230f","size":"0.9","price":"9120.8"}
{"type":"done","side":"sell","product_id":"BTC-USD","time":"2020-06-30T19:14:43.036071Z","sequence":180756442,"order_id":"eb87598e-c267-423a-80ef-fe661e48230f","reason":"filled","price":"9113.55","remaining_size":"0"}
{"type":"received","side":"sell","product_id":"BTC-USD","time":"2020-06-30T19:14:43.305924Z","sequence":180756443,"order_id":"7a95e25a-ce6f-4987-bce1-5ab0e7ef79cc","order_type":"limit","size":"0.7969","price":"9118.44","client_oid":""}
{"type":"match","side":"buy","product_id":"BTC-USD","time":"2020-06-30T19:14:43.305924Z","sequence":180756444,"trade_id":14587561,"maker_order_id":"91b59a7c-6a07-4039-9536-21daf3cb3282","taker_order_id":"7a95e25a-ce6f-4987-bce1-5ab0e7ef79cc","size":"0.7969","price":"9120.8"}
{"type":"done","side":"sell","product_id":"BTC-USD","time":"2020-06-30T19:14:43.305924Z","sequence":180756445,"order_id":"7a95e25a-ce6f-4987-bce1-5ab0e7ef79cc","reason":"filled","price":"9118.44","remaining_size":"0"}
{"type":"done","side":"sell","product_id":"BTC-USD","time":"2020-06-30T19:14:43.475593Z","sequence":180756446,"order_id":"ef0195ef-d4ed-4d61-baa9-1a4281567fdd","reason":"canceled","price":"9253.18","remaining_size":"0.002"}
{"type":"received","side":"buy","product_id":"BTC-USD","time":"2020-06-30T19:14:43.567096Z","sequence":180756447,"order_id":"d29f6a16-9aea-45ef-b8d2-696eae5d90b8","order_type":"limit","size":"0.0012","price":"9111.89","client_oid":""}
{"type":"open","side":"buy","product_id":"BTC-USD","time":"2020-06-30T19:14:43.567096Z","sequence":180756448,"price":"9111.89","order_id":"d29f6a16-9aea-45ef-b8d2-696eae5d90b8","remaining_size":"0.0012"}
{"type":"heartbeat","last_trade_id":0,"product_id":"BTC-USD","sequence":180756448,"time":"2020-06-30T19:14:43.735124Z"}
{"type":"received","side":"buy","product_id":"BTC-USD","time":"2020-06-30T19:14:43.853750Z","sequence":180756449,"order_id":"e5857c6d-c6a8-4b21-8558-aa5565e65c45","order_type":"limit","size":"0.0466","price":"9071.54","client_oid":""}
{"type":"open","side":"buy","product_id":"BTC-USD","time":"2020-06-30T19:14:43.853750Z","sequence":180756450,"price":"9071.54","order_id":"e5857c6d-c6a8-4b21-8558-aa5565e65c45","remaining_size":"0.0466"}
{"type":"done","side":"buy","product_id":"BTC-USD","time":"2020-06-30T19:14:43.978993Z","sequence":180756451,"order_id":"a9661af8-ff9c-4bae-aeb2-10d16a1c6da7","reason":"canceled","price":"9112.31","remaining_size":"1.4475"}
{"type":"done","side":"buy","product_id":"BTC-USD","time":"2020-06-30T19:14:44.052155Z","sequence":180756452,"order_id":"b7390e6c-1b00-4dcf-a7f3-0eac0feec6bf","reason":"canceled","price":"9071.04","remaining_size":"0.0892"}
{"type":"received","side":"buy","product_id":"BTC-USD","time":"2020-06-30T19:14:44.054993Z","sequence":180756453,"order_id":"b23e4e10-a457-4f97-b3b6-f348fcae58d9","order_type":"limit","size":"0.01","price":"100","client_oid":"ff915336-cc43-40aa-ba3a-c193c547ec4b"}
{"type":"open","side":"buy","product_id":"BTC-USD","time":"2020-06-30T19:14:44.054993Z","sequence":180756454,"price":"100","order_id":"b23e4e10-a457-4f97-b3b6-f348fcae58d9","remaining_size":"0.01"}
{"type":"done","side":"buy","product_id":"BTC-USD","time":"2020-06-30T19:14:44.061514Z","sequence":180756455,"order_id":"b23e4e10-a457-4f97-b3b6-f348fcae58d9","reason":"canceled","price":"100","remaining_size":"0.01"}
{"type":"done","side":"buy","product_id":"BTC-USD","time":"2020-06-30T19:14:44.062764Z","sequence":180756456,"order_id":"e35bfa1b-ae15-4fcd-83cd-3caf264fd815","reason":"canceled","price":"9103.25","remaining_size":"0.0659"}
{"type":"received","side":"buy","product_id":"BTC-USD","time":"2020-06-30T19:14:44.697423Z","sequence":180756457,"order_id":"40f18941-0c6e-49e6-b3bd-bdc26053f402","order_type":"limit","size":"0.1175","price":"9071.12","client_oid":""}
{"type":"open","side":"buy","product_id":"BTC-USD","time":"2020-06-30T19:14:44.697423Z","sequence":180756458,"price":"9071.12","order_id":"40f18941-0c6e-49e6-b3bd-bdc26053f402","remaining_size":"0.1175"}
{"type":"heartbeat","last_trade_id":0,"product_id":"BTC-USD","sequence":180756458,"time":"2020-06-30T19:14:44.735132Z"}
{"type":"received","side":"sell","product_id":"BTC-USD","time":"2020-06-30T19:14:44.960218Z","sequence":180756459,"order_id":"f83f3c2f-c8f3-4ca6-ae45-0adf4f2a947f","order_type":"limit","size":"0.25","price":"9114.83","client_oid":""}
{"type":"match","side":"buy","product_id":"BTC-USD","time":"2020-06-30T19:14:44.960218Z","sequence":180756460,"trade_id":14587562,"maker_order_id":"91b59a7c-6a07-4039-9536-21daf3cb3282","taker_order_id":"f83f3c2f-c8f3-4ca6-ae45-0adf4f2a947f","size":"0.25","price":"9120.8"}
{"type":"done","side":"sell","product_id":"BTC-USD","time":"2020-06-30T19:14:44.960218Z","sequence":180756461,"order_id":"f83f3c2f-c8f3-4ca6-ae45-0adf4f2a947f","reason":"filled","price":"9114.83","remaining_size":"0"}
{"type":"done","side":"buy","product_id":"BTC-USD","time":"2020-06-30T19:14:45.125102Z","sequence":180756462,"order_id":"80b60463-2b0d-48c6-acb2-9630e7abff35","reason":"canceled","price":"9017.56","remaining_size":"0.002"}
{"type":"done","side":"buy","product_id":"BTC-USD","time":"2020-06-30T19:14:45.127924Z","sequence":180756463,"order_id":"5db12265-cfc9-4b9e-b8d7-152607a4926b","reason":"canceled","price":"9076.92","remaining_size":"0.0737"}
{"type":"received","side":"sell","product_id":"BTC-USD","time":"2020-06-30T19:14:45.242636Z","sequence":180756464,"order_id":"4da119a8-62dc-4f71-adef-e9217196b180","order_type":"limit","size":"0.069","price":"9159.92","client_oid":""}
{"type":"open","side":"sell","product_id":"BTC-USD","time":"2020-06-30T19:14:45.242636Z","sequence":180756465,"price":"9159.92","order_id":"4da119a8-62dc-4f71-adef-e9217196b180","remaining_size":"0.069"}
{"type":"received","side":"sell","product_id":"BTC-USD","time":"2020-06-30T19:14:45.527244Z","sequence":180756466,"order_id":"1f0dc839-9273-4523-9878-3a80f8a33ecd","order_type":"limit","size":"0.4418","price":"9111.95","client_oid":""}
{"type":"match","side":"buy","product_id":"BTC-USD","time":"2020-06-30T19:14:45.527244Z","sequence":180756467,"trade_id":14587563,"maker_order_id":"91b59a7c-6a07-4039-9536-21daf3cb3282","taker_order_id":"1f0dc839-9273-4523-9878-3a80f8a33ecd","size":"0.4418","price":"9120.8"}
{"type":"done","side":"sell","product_id":"BTC-USD","time":"2020-06-30T19:14:45.527244Z","sequence":180756468,"order_id":"1f0dc839-9273-4523-9878-3a80f8a33ecd","reason":"filled","price":"9111.95","remaining_size":"0"}
{"type":"heartbeat","last_trade_id":0,"product_id":"BTC-USD","sequence":180756468,"time":"2020-06-30T19:14:45.735119Z"}
{"type":"received","side":"buy","product_id":"BTC-USD","time":"2020-06-30T19:14:46.340560Z","sequence":180756469,"order_id":"52e424c0-edf4-4891-8c05-417889e67f16","order_type":"limit","size":"0.063","price":"9067.17","client_oid":""}
{"type":"open","side":"buy","product_id":"BTC-USD","time":"2020-06-30T19:14:46.340560Z","sequence":180756470,"price":"9067.17","order_id":"52e424c0-edf4-4891-8c05-417889e67f16","remaining_size":"0.063"}
{"type":"heartbeat","last_trade_id":0,"product_id":"BTC-USD","sequence":180756470,"time":"2020-06-30T19:14:46.735112Z"}
{"type":"done","side":"buy","product_id":"BTC-USD","time":"2020-06-30T19:14:46.789058Z","sequence":180756471,"order_id":"7b094650-0b0d-40a2-83bf-76a72ffdb2b5","reason":"canceled","price":"9074.46","remaining_size":"0.0737"}
{"type":"received","side":"sell","product_id":"BTC-USD","time":"2020-06-30T19:14:47.732744Z","sequence":180756472,"order_id":"e465214a-50b2-4908-a029-3e1e6778724b","order_type":"limit","size":"0.0013","price":"9111.96","client_oid":""}
{"type":"match","side":"buy","product_id":"BTC-USD","time":"2020-06-30T19:14:47.732744Z","sequence":180756473,"trade_id":14587564,"maker_order_id":"91b59a7c-6a07-4039-9536-21daf3cb3282","taker_order_id":"e465214a-50b2-4908-a029-3e1e6778724b","size":"0.0013","price":"9120.8"}
{"type":"done","side":"sell","product_id":"BTC-USD","time":"2020-06-30T19:14:47.732744Z","sequence":180756474,"order_id":"e465214a-50b2-4908-a029-3e1e6778724b","reason":"filled","price":"9111.96","remaining_size":"0"}
{"type":"heartbeat","last_trade_id":0,"product_id":"BTC-USD","sequence":180756474,"time":"2020-06-30T19:14:47.735113Z"}
{"type":"received","side":"sell","product_id":"BTC-USD","time":"2020-06-30T19:14:48.298815Z","sequence":180756475,"order_id":"b119a939-80bc-446e-8a90-3dc8ac6969df","order_type":"limit","size":"0.0658","price":"9113.63","client_oid":""}
{"type":"match","side":"buy","product_id":"BTC-USD","time":"2020-06-30T19:14:48.298815Z","sequence":180756476,"trade_id":14587565,"maker_order_id":"91b59a7c-6a07-4039-9536-21daf3cb3282","taker_order_id":"b119a939-80bc-446e-8a90-3dc8ac6969df","size":"0.0658","price":"9120.8"}
{"type":"done","side":"sell","product_id":"BTC-USD","time":"2020-06-30T19:14:48.298815Z","sequence":180756477,"order_id":"b119a939-80bc-446e-8a90-3dc8ac6969df","reason":"filled","price":"9113.63","remaining_size":"0"}
{"type":"received","side":"sell","product_id":"BTC-USD","time":"2020-06-30T19:14:48.644604Z","sequence":180756478,"order_id":"dd4d98e6-1165-4a21-908e-4bc3b1e980c1","order_type":"limit","size":"0.0383","price":"9158.22","client_oid":""}
{"type":"open","side":"sell","product_id":"BTC-USD","time":"2020-06-30T19:14:48.644604Z","sequence":180756479,"price":"9158.22","order_id":"dd4d98e6-1165-4a21-908e-4bc3b1e980c1","remaining_size":"0.0383"}
{"type":"heartbeat","last_trade_id":0,"product_id":"BTC-USD","sequence":180756479,"time":"2020-06-30T19:14:48.735117Z"}
{"type":"done","side":"sell","product_id":"BTC-USD","time":"2020-06-30T19:14:49.040108Z","sequence":180756480,"order_id":"5417d20c-9c97-42a2-9fbb-cd58a97a6e0b","reason":"canceled","price":"9160.03","remaining_size":"0.0149"}
{"type":"heartbeat","last_trade_id":0,"product_id":"BTC-USD","sequence":180756480,"time":"2020-06-30T19:14:49.735116Z"}
{"type":"received","side":"buy","product_id":"BTC-USD","time":"2020-06-30T19:14:49.901239Z","sequence":180756481,"order_id":"edda9118-3684-4d6d-b7d5-d5ef082ae948","order_type":"limit","size":"0.01","price":"9078.78","client_oid":""}
{"type":"open","side":"buy","product_id":"BTC-USD","time":"2020-06-30T19:14:49.901239Z","sequence":180756482,"price":"9078.78","order_id":"edda9118-3684-4d6d-b7d5-d5ef082ae948","remaining_size":"0.01"}
{"type":"done","side":"buy","product_id":"BTC-USD","time":"2020-06-30T19:14:50.339418Z","sequence":180756483,"order_id":"e5857c6d-c6a8-4b21-8558-aa5565e65c45","reason":"canceled","price":"9071.54","remaining_size":"0.0466"}
{"type":"received","side":"buy","product_id":"BTC-USD","time":"2020-06-30T19:14:50.445902Z","sequence":180756484,"order_id":"22baf2bf-9af1-4a21-8c84-54a3dbd4e1e3","order_type":"limit","size":"0.0293","price":"9073.66","client_oid":""}
{"type":"open","side":"buy","product_id":"BTC-USD","time":"2020-06-30T19:14:50.445902Z","sequence":180756485,"price":"9073.66","order_id":"22baf2bf-9af1-4a21-8c84-54a3dbd4e1e3","remaining_size":"0.0293"}
{"type":"received","side":"buy","product_id":"BTC-USD","time":"2020-06-30T19:14:50.745442Z","sequence":180756486,"order_id":"3a784603-2c9f-459c-9bdf-602cfc5def65","order_type":"limit","size":"0.0307","price":"9100.96","client_oid":""}
{"type":"open","side":"buy","product_id":"BTC-USD","time":"2020-06-30T19:14:50.745442Z","sequence":180756487,"price":"9100.96","order_id":"3a784603-2c9f-459c-9bdf-602cfc5def65","remaining_size":"0.0307"}
{"type":"heartbeat","last_trade_id":0,"product_id":"BTC-USD","sequence":180756487,"time":"2020-06-30T19:14:50.735050Z"}
{"type":"done","side":"buy","product_id":"BTC-USD","time":"2020-06-30T19:14:50.893586Z","sequence":180756488,"order_id":"a238473b-1392-45c4-91d3-cbf8f75d8268","reason":"canceled","price":"9106.82","remaining_size":"0.548"}
{"type":"done","side":"buy","product_id":"BTC-USD","time":"2020-06-30T19:14:50.900426Z","sequence":180756489,"order_id":"40f18941-0c6e-49e6-b3bd-bdc26053f402","reason":"canceled","price":"9071.12","remaining_size":"0.1175"}
{"type":"received","side":"sell","product_id":"BTC-USD","time":"2020-06-30T19:14:51.025892Z","sequence":180756490,"order_id":"eb88fb3b-8316-402c-a359-3393eac8b2f1","order_type":"limit","size":"0.0658","price":"9113.32","client_oid":""}
{"type":"match","side":"buy","product_id":"BTC-USD","time":"2020-06-30T19:14:51.025892Z","sequence":180756491,"trade_id":14587566,"maker_order_id":"91b59a7c-6a07-4039-9536-21daf3cb3282","taker_order_id":"eb88fb3b-8316-402c-a359-3393eac8b2f1","size":"0.0658","price":"9120.8"}
{"type":"done","side":"sell","product_id":"BTC-USD","time":"2020-06-30T19:14:51.025892Z","sequence":180756492,"order_id":"eb88fb3b-8316-402c-a359-3393eac8b2f1","reason":"filled","price":"9113.32","remaining_size":"0"}
{"type":"received","side":"sell","product_id":"BTC-USD","time":"2020-06-30T19:14:51.291072Z","sequence":180756493,"order_id":"98112b2a-b167-417a-ab96-cd1c46846957","order_type":"limit","size":"0.0298","price":"9112.78","client_oid":""}
{"type":"match","side":"buy","product_id":"BTC-USD","time":"2020-06-30T19:14:51.291072Z","sequence":180756494,"trade_id":14587567,"maker_order_id":"91b59a7c-6a07-4039-9536-21daf3cb3282","taker_order_id":"98112b2a-b167-417a-ab96-cd1c46846957","size":"0.0298","price":"9120.8"}
{"type":"done","side":"sell","product_id":"BTC-USD","time":"2020-06-30T19:14:51.291072Z","sequence":180756495,"order_id":"98112b2a-b167-417a-ab96-cd1c46846957","reason":"filled","price":"9112.78","remaining_size":"0"}
{"type":"done","side":"sell","product_id":"BTC-USD","time":"2020-06-30T19:14:51.465634Z","sequence":180756496,"order_id":"dd4d98e6-1165-4a21-908e-4bc3b1e980c1","reason":"canceled","price":"9158.22","remaining_size":"0.0383"}
{"type":"heartbeat","last_trade_id":0,"product_id":"BTC-USD","sequence":180756496,"time":"2020-06-30T19:14:51.735109Z"}
{"type":"done","side":"sell","product_id":"BTC-USD","time":"2020-06-30T19:14:51.773364Z","sequence":180756497,"order_id":"2cd701b4-a35f-4cfb-82f3-5709dc153368","reason":"canceled","price":"9161.55","remaining_size":"0.01"}
{"type":"received","side":"sell","product_id":"BTC-USD","time":"2020-06-30T19:14:51.844768Z","sequence":180756498,"order_id":"cb42e851-0696-49ab-856b-a43cc6ae1c62","order_type":"limit","size":"0.0919","price":"9112.67","client_oid":""}
{"type":"match","side":"buy","product_id":"BTC-USD","time":"2020-06-30T19:14:51.844768Z","sequence":180756499,"trade_id":14587568,"maker_order_id":"91b59a7c-6a07-4039-9536-21daf3cb3282","taker_order_id":"cb42e851-0696-49ab-856b-a43cc6ae1c62","size":"0.0919","price":"9120.8"}
{"type":"done","side":"sell","product_id":"BTC-USD","time":"2020-06-30T19:14:51.844768Z","sequence":180756500,"order_id":"cb42e851-0696-49ab-856b-a43cc6ae1c62","reason":"filled","price":"9112.67","remaining_size":"0"}
{"type":"received","side":"sell","product_id":"BTC-USD","time":"2020-06-30T19:14:52.116048Z","sequence":180756501,"order_id":"4ead6db6-e191-4eab-8502-b2f2870bb3f2","order_type":"limit","size":"0.05","price":"9112.57","client_oid":""}
{"type":"match","side":"buy","product_id":"BTC-USD","time":"2020-06-30T19:14:52.116048Z","sequence":180756502,"trade_id":14587569,"maker_order_id":"91b59a7c-6a07-4039-9536-21daf3cb3282","taker_order_id":"4ead6db6-e191-4eab-8502-b2f2870bb3f2","size":"0.05","price":"9120.8"}
{"type":"done","side":"sell","product_id":"BTC-USD","time":"2020-06-30T19:14:52.116048Z","sequence":180756503,"order_id":"4ead6db6-e191-4eab-8502-b2f2870bb3f2","reason":"filled","price":"9112.57","remaining_size":"0"}
{"type":"received","side":"buy","product_id":"BTC-USD","time":"2020-06-30T19:14:52.390361Z","sequence":180756504,"order_id":"4ba52283-2340-4f5a-9015-75d18e849dc7","order_type":"limit","size":"0.087","price":"9086.64","client_oid":""}
{"type":"open","side":"buy","product_id":"BTC-USD","time":"2020-06-30T19:14:52.390361Z","sequence":180756505,"price":"9086.64","order_id":"4ba52283-2340-4f5a-9015-75d18e849dc7","remaining_size":"0.087"}
{"type":"heartbeat","last_trade_id":0,"product_id":"BTC-USD","sequence":180756505,"time":"2020-06-30T19:14:52.735115Z"}
{"type":"done","side":"buy","product_id":"BTC-USD","time":"2020-06-30T19:14:52.888230Z","sequence":180756506,"order_id":"d29f6a16-9aea-45ef-b8d2-696eae5d90b8","reason":"canceled","price":"9111.89","remaining_size":"0.0012"}
{"type":"done","side":"buy","product_id":"BTC-USD","time":"2020-06-30T19:14:52.918043Z","sequence":180756507,"order_id":"084aee79-e8c1-49fe-97a0-2f226626b711","reason":"canceled","price":"9107.99","remaining_size":"0.0024"}
{"type":"received","side":"sell","product_id":"BTC-USD","time":"2020-06-30T19:14:52.961404Z","sequence":180756508,"order_id":"24d76474-7c04-4a41-8227-c43de29b147e","order_type":"limit","size":"0.0527","price":"9159.51","client_oid":""}
{"type":"open","side":"sell","product_id":"BTC-USD","time":"2020-06-30T19:14:52.961404Z","sequence":180756509,"price":"9159.51","order_id":"24d76474-7c04-4a41-8227-c43de29b147e","remaining_size":"0.0527"}
{"type":"done","side":"sell","product_id":"BTC-USD","time":"2020-06-30T19:14:53.471286Z","sequence":180756510,"order_id":"a5a1aec3-a8f3-4525-978b-7df8b52b4894","reason":"canceled","price":"9159.34","remaining_size":"0.069"}
{"type":"received","side":"sell","product_id":"BTC-USD","time":"2020-06-30T19:14:53.509128Z","sequence":180756511,"order_id":"a299ea8a-eced-4ff5-b7b9-550bd0185397","order_type":"limit","size":"0.098","price":"9111.96","client_oid":""}
{"type":"match","side":"buy","product_id":"BTC-USD","time":"2020-06-30T19:14:53.509128Z","sequence":180756512,"trade_id":14587570,"maker_order_id":"91b59a7c-6a07-4039-9536-21daf3cb3282","taker_order_id":"a299ea8a-eced-4ff5-b7b9-550bd0185397","size":"0.098","price":"9120.8"}
{"type":"done","side":"sell","product_id":"BTC-USD","time":"2020-06-30T19:14:53.509128Z","sequence":180756513,"order_id":"a299ea8a-eced-4ff5-b7b9-550bd0185397","reason":"filled","price":"9111.96","remaining_size":"0"}
{"type":"done","side":"sell","product_id":"BTC-USD","time":"2020-06-30T19:14:53.694616Z","sequence":180756514,"order_id":"24d76474-7c04-4a41-8227-c43de29b147e","reason":"canceled","price":"9159.51","remaining_size":"0.0527"}
{"type":"heartbeat","last_trade_id":0,"product_id":"BTC-USD","sequence":180756514,"time":"2020-06-30T19:14:53.735119Z"}
{"type":"received","side":"sell","product_id":"BTC-USD","time":"2020-06-30T19:14:53.798047Z","sequence":180756515,"order_id":"8ade02db-42f1-4202-8871-84acb345bd92","order_type":"limit","size":"0.05","price":"9112.79","client_oid":""}
{"type":"match","side":"buy","product_id":"BTC-USD","time":"2020-06-30T19:14:53.798047Z","sequence":180756516,"trade_id":14587571,"maker_order_id":"91b59a7c-6a07-4039-9536-21daf3cb3282","taker_order_id":"8ade02db-42f1-4202-8871-84acb345bd92","size":"0.05","price":"9120.8"}
{"type":"done","side":"sell","product_id":"BTC-USD","time":"2020-06-30T19:14:53.798047Z","sequence":180756517,"order_id":"8ade02db-42f1-4202-8871-84acb345bd92","reason":"filled","price":"9112.79","remaining_size":"0"}
{"type":"received","side":"sell","product_id":"BTC-USD","time":"2020-06-30T19:14:54.108260Z","sequence":180756518,"order_id":"809d6dca-9184-4c1f-8c9b-e11a14874fe3","order_type":"limit","size":"0.014","price":"9112.78","client_oid":""}
{"type":"match","side":"buy","product_id":"BTC-USD","time":"2020-06-30T19:14:54.108260Z","sequence":180756519,"trade_id":14587572,"maker_order_id":"91b59a7c-6a07-4039-9536-21daf3cb3282","taker_order_id":"809d6dca-9184-4c1f-8c9b-e11a14874fe3","size":"0.014","price":"9120.8"}
{"type":"done","side":"sell","product_id":"BTC-USD","time":"2020-06-30T19:14:54.108260Z","sequence":180756520,"order_id":"809d6dca-9184-4c1f-8c9b-e11a14874fe3","reason":"filled","price":"9112.78","remaining_size":"0"}
{"type":"heartbeat","last_trade_id":0,"product_id":"BTC-USD","sequence":180756520,"time":"2020-06-30T19:14:54.735109Z"}
{"type":"received","side":"sell","product_id":"BTC-USD","time":"2020-06-30T19:14:54.888869Z","sequence":180756521,"order_id":"ac5e6678-bbc4-4579-b2d9-1763542c4a9e","order_type":"limit","size":"0.0149","price":"9159.41","client_oid":""}
{"type":"open","side":"sell","product_id":"BTC-USD","time":"2020-06-30T19:14:54.888869Z","sequence":180756522,"price":"9159.41","order_id":"ac5e6678-bbc4-4579-b2d9-1763542c4a9e","remaining_size":"0.0149"}
{"type":"heartbeat","last_trade_id":0,"product_id":"BTC-USD","sequence":180756522,"time":"2020-06-30T19:14:55.735118Z"}
{"type":"received","side":"sell","product_id":"BTC-USD","time":"2020-06-30T19:14:56.552425Z","sequence":180756523,"order_id":"801a10b8-7277-43c8-8d24-6721c28f8ea5","order_type":"limit","size":"0.0547","price":"9145.45","client_oid":""}
{"type":"open","side":"sell","product_id":"BTC-USD","time":"2020-06-30T19:14:56.552425Z","sequence":180756524,"price":"9145.45","order_id":"801a10b8-7277-43c8-8d24-6721c28f8ea5","remaining_size":"0.0547"}
{"type":"heartbeat","last_trade_id":0,"product_id":"BTC-USD","sequence":180756524,"time":"2020-06-30T19:14:56.735115Z"}
{"type":"done","side":"sell","product_id":"BTC-USD","time":"2020-06-30T19:14:56.975564Z","sequence":180756525,"order_id":"4a23224d-2fef-41d1-8d39-9645e585d1d2","reason":"canceled","price":"9159","remaining_size":"0.069"}
{"type":"received","side":"sell","product_id":"BTC-USD","time":"2020-06-30T19:14:57.113875Z","sequence":180756526,"order_id":"9c99b9b1-a405-400c-8288-0325ec2ac50d","order_type":"limit","size":"0.9","price":"9112.75","client_oid":""}
{"type":"match","side":"buy","product_id":"BTC-USD","time":"2020-06-30T19:14:57.113875Z","sequence":180756527,"trade_id":14587573,"maker_order_id":"91b59a7c-6a07-4039-9536-21daf3cb3282","taker_order_id":"9c99b9b1-a405-400c-8288-0325ec2ac50d","size":"0.9","price":"9120.8"}
{"type":"done","side":"sell","product_id":"BTC-USD","time":"2020-06-30T19:14:57.113875Z","sequence":180756528,"order_id":"9c99b9b1-a405-400c-8288-0325ec2ac50d","reason":"filled","price":"9112.75","remaining_size":"0"}
{"type":"received","side":"sell","product_id":"BTC-USD","time":"2020-06-30T19:14:57.366254Z","sequence":180756529,"order_id":"2a6056d2-0eb0-49c8-b8d0-9efb1dd45b9c","order_type":"limit","size":"0.5","price":"9130.3","client_oid":""}
{"type":"open","side":"sell","product_id":"BTC-USD","time":"2020-06-30T19:14:57.366254Z","sequence":180756530,"price":"9130.3","order_id":"2a6056d2-0eb0-49c8-b8d0-9efb1dd45b9c","remaining_size":"0.5"}
{"type":"done","side":"sell","product_id":"BTC-USD","time":"2020-06-30T19:14:57.565954Z","sequence":180756531,"order_id":"ac5e6678-bbc4-4579-b2d9-1763542c4a9e","reason":"canceled","price":"9159.41","remaining_size":"0.0149"}
{"type":"heartbeat","last_trade_id":0,"product_id":"BTC-USD","sequence":180756531,"time":"2020-06-30T19:14:57.735117Z"}
{"type":"received","side":"buy","product_id":"BTC-USD","time":"2020-06-30T19:14:57.913136Z","sequence":180756532,"order_id":"ca6c011b-7293-4ddd-a054-b2417bf7d91b","order_type":"limit","size":"0.05","price":"9112.07","client_oid":""}
{"type":"open","side":"buy","product_id":"BTC-USD","time":"2020-06-30T19:14:57.913136Z","sequence":180756533,"price":"9112.07","order_id":"ca6c011b-7293-4ddd-a054-b2417bf7d91b","remaining_size":"0.05"}
{"type":"received","side":"sell","product_id":"BTC-USD","time":"2020-06-30T19:14:58.185353Z","sequence":180756534,"order_id":"884c829b-31cc-4016-bfc4-5bbf6ba962e1","order_type":"limit","size":"0.0658","price":"9113.37","client_oid":""}
{"type":"match","side":"buy","product_id":"BTC-USD","time":"2020-06-30T19:14:58.185353Z","sequence":180756535,"trade_id":14587574,"maker_order_id":"91b59a7c-6a07-4039-9536-21daf3cb3282","taker_order_id":"884c829b-31cc-4016-bfc4-5bbf6ba962e1","size":"0.0658","price":"9120.8"}
{"type":"done","side":"sell","product_id":"BTC-USD","time":"2020-06-30T19:14:58.185353Z","sequence":180756536,"order_id":"884c829b-31cc-4016-bfc4-5bbf6ba962e1","reason":"filled","price":"9113.37","remaining_size":"0"}
{"type":"done","side":"buy","product_id":"BTC-USD","time":"2020-06-30T19:14:58.361055Z","sequence":180756537,"order_id":"22baf2bf-9af1-4a21-8c84-54a3dbd4e1e3","reason":"canceled","price":"9073.66","remaining_size":"0.0293"}
