[270, {"b": [["11659.70000", "0.00000000", "1596666806.500560"], ["11610.00000", "0.17085000", "1596666698.121910", "r"]], "c": "812778800"}, "book-100", "XBT/USD"]
[270, {"a": [["11702.50000", "0.00000000", "1596666806.501956"], ["11728.00000", "2.99792678", "1596666801.269211", "r"]], "c": "812778800"}, "book-100", "XBT/USD"]
[270, {"b": [["11651.10000", "1.53253397", "1596666806.503396"]], "c": "812778800"}, "book-100", "XBT/USD"]
[270, {"b": [["11663.20000", "0.42800000", "1596666806.588815"]], "c": "3317253431"}, "book-100", "XBT/USD"]
[270, {"a": [["11722.60000", "23.57900000", "1596666806.604937"]], "c": "3317253431"}, "book-100", "XBT/USD"]
[270, {"a": [["11705.70000", "1.38069086", "1596666806.606276"]], "c": "3317253431"}, "book-100", "XBT/USD"]
[270, {"a": [["11690.50000", "4.42637087", "1596666806.613607"]], "c": "3317253431"}, "book-100", "XBT/USD"]
[270, {"a": [["11702.40000", "0.00000000", "1596666806.633347"], ["11728.00000", "2.99792678", "1596666801.269211", "r"]], "c": "3317253431"}, "book-100", "XBT/USD"]
[270, {"a": [["11672.90000", "0.41352978", "1596666806.635813"]], "c": "3417533585"}, "book-100", "XBT/USD"]
[270, {"a": [["11694.00000", "0.89778821", "1596666806.637714"]], "c": "3417533585"}, "book-100", "XBT/USD"]
[270, {"a": [["11679.70000", "0.51442529", "1596666806.642058"]], "c": "3417533585"}, "book-100", "XBT/USD"]
[270, {"a": [["11692.20000", "0.56056962", "1596666806.642721"]], "c": "3417533585"}, "book-100", "XBT/USD"]
[270, {"b": [["11664.80000", "17.47634362", "1596666806.656061"]], "c": "2483485667"}, "book-100", "XBT/USD"]
[270, {"b": [["11664.80000", "17.72634362", "1596666806.657562"]], "c": "2959383483"}, "book-100", "XBT/USD"]
[270, {"b": [["11664.20000", "0.95576324", "1596666806.787307"]], "c": "1645519679"}, "book-100", "XBT/USD"]
[270, {"b": [["11644.90000", "0.90127959", "1596666806.803463"]], "c": "1645519679"}, "book-100", "XBT/USD"]
[270, {"a": [["11679.60000", "0.00437521", "1596666806.806243"]], "c": "1645519679"}, "book-100", "XBT/USD"]
[270, {"b": [["11663.20000", "0.00000000", "1596666806.827949"], ["11610.00000", "0.17085000", "1596666698.121910", "r"]], "c": "1041113316"}, "book-100", "XBT/USD"]
[270, {"b": [["11656.20000", "8.73900000", "1596666806.857542"]], "c": "1041113316"}, "book-100", "XBT/USD"]
[270, {"b": [["11664.80000", "17.47634362", "1596666806.965587"]], "c": "1536858946"}, "book-100", "XBT/USD"]
[270, {"a": [["11678.20000", "0.00000000", "1596666806.970053"], ["11726.30000", "1.78600000", "1596666787.006488", "r"]], "c": "1536858946"}, "book-100", "XBT/USD"]
[270, {"b": [["11651.70000", "0.33907353", "1596666806.971804"]], "c": "1536858946"}, "book-100", "XBT/USD"]
[270, {"b": [["11651.80000", "0.00000000", "1596666806.995310"], ["11609.90000", "0.01286300", "1596666804.525088", "r"]], "c": "1536858946"}, "book-100", "XBT/USD"]
[270, {"b": [["11656.30000", "0.04218469", "1596666806.996719"]], "c": "1536858946"}, "book-100", "XBT/USD"]
[270, {"a": [["11675.70000", "0.00000000", "1596666807.031794"], ["11726.60000", "0.00700000", "1596666737.891214", "r"]], "c": "1536858946"}, "book-100", "XBT/USD"]
[270, {"b": [["11637.00000", "0.00000000", "1596666807.038289"], ["11609.90000", "0.01286300", "1596666804.525088", "r"]], "c": "1536858946"}, "book-100", "XBT/USD"]
[270, {"a": [["11678.60000", "1.50000000", "1596666807.162147"]], "c": "1536858946"}, "book-100", "XBT/USD"]
[270, {"b": [["11664.80000", "17.72634362", "1596666807.171522"]], "c": "1041113316"}, "book-100", "XBT/USD"]
[270, {"b": [["11664.70000", "1.50000000", "1596666807.183545"]], "c": "3805666012"}, "book-100", "XBT/USD"]
[270, {"b": [["11664.80000", "18.15434362", "1596666807.257228"]], "c": "1002334414"}, "book-100", "XBT/USD"]
[270, {"b": [["11644.70000", "0.05287327", "1596666807.329244"]], "c": "1002334414"}, "book-100", "XBT/USD"]
[270, {"a": [["11673.90000", "0.00000000", "1596666807.436633"], ["11726.60000", "0.00700000", "1596666737.891214", "r"]], "c": "1337464644"}, "book-100", "XBT/USD"]
[270, {"a": [["11673.30000", "0.25827373", "1596666807.509645"]], "c": "3740374476"}, "book-100", "XBT/USD"]
[270, {"b": [["11664.80000", "18.64484362", "1596666807.637494"]], "c": "4008845765"}, "book-100", "XBT/USD"]
[270, {"b": [["11660.70000", "0.00000000", "1596666807.804815"], ["11610.00000", "0.17085000", "1596666698.121910", "r"]], "c": "4008845765"}, "book-100", "XBT/USD"]
[270, {"b": [["11649.00000", "0.00000000", "1596666807.811846"], ["11609.90000", "0.01286300", "1596666804.525088", "r"]], "c": "4008845765"}, "book-100", "XBT/USD"]
[270, {"a": [["11675.30000", "0.09621094", "1596666807.833716"]], "c": "4008845765"}, "book-100", "XBT/USD"]
[270, {"b": [["11646.70000", "0.72496419", "1596666807.834873"]], "c": "4008845765"}, "book-100", "XBT/USD"]
[270, {"a": [["11679.60000", "0.01808247", "1596666807.934534"]], "c": "4008845765"}, "book-100", "XBT/USD"]
[270, {"b": [["11654.90000", "0.00000000", "1596666807.996798"], ["11609.80000", "21.20000000", "1596666704.766154", "r"]], "c": "4008845765"}, "book-100", "XBT/USD"]
[270, {"b": [["11664.80000", "18.39484362", "1596666808.017628"]], "c": "2964404814"}, "book-100", "XBT/USD"]
[270, {"a": [["11687.20000", "0.00000000", "1596666808.133460"], ["11726.30000", "1.78600000", "1596666787.006488", "r"]], "c": "2964404814"}, "book-100", "XBT/USD"]
[270, {"a": [["11679.60000", "0.01370726", "1596666808.151317"]], "c": "2964404814"}, "book-100", "XBT/USD"]
[270, {"b": [["11616.80000", "0.74865639", "1596666808.185237"]], "c": "2964404814"}, "book-100", "XBT/USD"]
[270, {"b": [["11664.80000", "18.79484362", "1596666808.224088"]], "c": "3292161148"}, "book-100", "XBT/USD"]
[270, {"b": [["11656.00000", "2.00000000", "1596666808.331010"]], "c": "3292161148"}, "book-100", "XBT/USD"]
[270, {"b": [["11664.80000", "19.79484362", "1596666808.332736"]], "c": "464130539"}, "book-100", "XBT/USD"]
[270, {"a": [["11680.20000", "0.00000000", "1596666808.343220"], ["11726.60000", "0.00700000", "1596666737.891214", "r"]], "c": "464130539"}, "book-100", "XBT/USD"]
[270, {"a": [["11688.30000", "0.74865639", "1596666808.347718"]], "c": "464130539"}, "book-100", "XBT/USD"]
[270, {"b": [["11653.80000", "0.92400000", "1596666808.352396"]], "c": "464130539"}, "book-100", "XBT/USD"]
[270, {"a": [["11680.30000", "2.85734812", "1596666808.356671"]], "c": "464130539"}, "book-100", "XBT/USD"]
[270, {"a": [["11674.50000", "0.25826217", "1596666808.383162"]], "c": "984931486"}, "book-100", "XBT/USD"]
[270, {"a": [["11673.30000", "0.00000000", "1596666808.396528"], ["11726.30000", "1.78600000", "1596666787.006488", "r"]], "c": "2667754584"}, "book-100", "XBT/USD"]
[270, {"b": [["11619.10000", "0.00000000", "1596666808.421700"], ["11610.00000", "0.17085000", "1596666698.121910", "r"]], "c": "2667754584"}, "book-100", "XBT/USD"]
[270, {"b": [["11664.80000", "20.04484362", "1596666808.425123"]], "c": "3716119830"}, "book-100", "XBT/USD"]
[270, {"b": [["11661.60000", "0.00000000", "1596666808.449878"], ["11609.90000", "0.01286300", "1596666804.525088", "r"]], "c": "3135240129"}, "book-100", "XBT/USD"]
[270, {"a": [["11684.80000", "6.56208278", "1596666808.515254"]], "c": "3135240129"}, "book-100", "XBT/USD"]
[270, {"a": [["11673.40000", "0.00000000", "1596666808.529758"], ["11726.30000", "1.78600000", "1596666787.006488", "r"]], "c": "2069457186"}, "book-100", "XBT/USD"]
[270, {"a": [["11679.60000", "0.00000000", "1596666808.562944"], ["11726.60000", "0.00700000", "1596666737.891214", "r"]], "c": "2069457186"}, "book-100", "XBT/USD"]
[270, {"a": [["11697.30000", "1.79038572", "1596666808.572482"]], "c": "2069457186"}, "book-100", "XBT/USD"]
[270, {"a": [["11700.00000", "0.52000000", "1596666808.575260"]], "c": "2069457186"}, "book-100", "XBT/USD"]
[270, {"b": [["11664.80000", "19.79484362", "1596666808.579291"]], "c": "958701676"}, "book-100", "XBT/USD"]
[270, {"a": [["11685.70000", "0.33814396", "1596666808.580168"]], "c": "958701676"}, "book-100", "XBT/USD"]
[270, {"a": [["11692.50000", "0.00000000", "1596666808.580611"], ["11726.30000", "1.78600000", "1596666787.006488", "r"]], "c": "958701676"}, "book-100", "XBT/USD"]
[270, {"a": [["11706.70000", "0.89515286", "1596666808.583113"]], "c": "958701676"}, "book-100", "XBT/USD"]
[270, {"a": [["11689.10000", "0.70989576", "1596666808.586255"]], "c": "958701676"}, "book-100", "XBT/USD"]
[270, {"a": [["11691.50000", "1.41950007", "1596666808.589603"]], "c": "958701676"}, "book-100", "XBT/USD"]
[270, {"a": [["11695.00000", "0.34846326", "1596666808.593515"]], "c": "958701676"}, "book-100", "XBT/USD"]
[270, {"a": [["11691.50000", "1.66847691", "1596666808.595370"]], "c": "958701676"}, "book-100", "XBT/USD"]
[270, {"a": [["11679.70000", "0.00000000", "1596666808.606586"], ["11725.30000", "0.01286300", "1596666804.528425", "r"]], "c": "958701676"}, "book-100", "XBT/USD"]
[270, {"a": [["11692.20000", "0.00000000", "1596666808.608300"], ["11725.40000", "1.99666304", "1596666743.823724", "r"]], "c": "958701676"}, "book-100", "XBT/USD"]
[270, {"b": [["11624.80000", "6.62640598", "1596666808.610014"]], "c": "958701676"}, "book-100", "XBT/USD"]
[270, {"a": [["11692.60000", "0.00000000", "1596666808.610114"], ["11725.50000", "1.06000000", "1596666771.224459", "r"]], "c": "958701676"}, "book-100", "XBT/USD"]
[270, {"b": [["11614.20000", "0.00000000", "1596666808.630471"], ["11609.90000", "0.01286300", "1596666804.525088", "r"]], "c": "958701676"}, "book-100", "XBT/USD"]
[270, {"a": [["11680.80000", "5.37247623", "1596666808.631968"]], "c": "958701676"}, "book-100", "XBT/USD"]
[270, {"b": [["11613.90000", "0.00000000", "1596666808.633008"], ["11609.80000", "21.20000000", "1596666704.766154", "r"]], "c": "958701676"}, "book-100", "XBT/USD"]
[270, {"a": [["11670.20000", "0.00000000", "1596666808.651590"], ["11725.50000", "1.06000000", "1596666771.224459", "r"]], "c": "4218352962"}, "book-100", "XBT/USD"]
[270, {"b": [["11664.20000", "1.05197418", "1596666808.652926"]], "c": "949163207"}, "book-100", "XBT/USD"]
[270, {"b": [["11661.50000", "8.83598437", "1596666808.657572"]], "c": "1205188905"}, "book-100", "XBT/USD"]
[270, {"a": [["11674.90000", "4.28000000", "1596666808.672095"]], "c": "2102515780"}, "book-100", "XBT/USD"]
[270, {"b": [["11651.10000", "0.00000000", "1596666808.699191"], ["11607.70000", "8.40000000", "1596666777.775135", "r"]], "c": "2102515780"}, "book-100", "XBT/USD"]
[270, {"b": [["11664.80000", "20.04484362", "1596666808.788397"]], "c": "3967273242"}, "book-100", "XBT/USD"]
[270, {"a": [["11679.10000", "0.00366249", "1596666808.812657"]], "c": "3967273242"}, "book-100", "XBT/USD"]
[270, {"b": [["11664.80000", "19.55434362", "1596666808.874017"]], "c": "2122939111"}, "book-100", "XBT/USD"]
[270, {"a": [["11671.90000", "0.38465385", "1596666808.877394"]], "c": "4226166985"}, "book-100", "XBT/USD"]
[270, {"b": [["11610.00000", "0.00000000", "1596666808.961852"], ["11607.00000", "0.17085000", "1596666720.750083", "r"]], "c": "4226166985"}, "book-100", "XBT/USD"]
[270, {"a": [["11699.70000", "0.89735082", "1596666808.982605"]], "c": "4226166985"}, "book-100", "XBT/USD"]
[270, {"a": [["11714.80000", "1.99881632", "1596666809.038669"]], "c": "4226166985"}, "book-100", "XBT/USD"]
[270, {"b": [["11664.80000", "20.04484362", "1596666809.062627"]], "c": "1763214132"}, "book-100", "XBT/USD"]
[270, {"b": [["11664.80000", "19.79484362", "1596666809.098682"]], "c": "4164850282"}, "book-100", "XBT/USD"]
[270, {"b": [["11607.00000", "0.00000000", "1596666809.115336"], ["11604.10000", "1.51500000", "1596666763.121463", "r"]], "c": "4164850282"}, "book-100", "XBT/USD"]
[270, {"b": [["11653.80000", "0.00000000", "1596666809.140456"], ["11603.20000", "2.50039088", "1596666777.334144", "r"]], "c": "4164850282"}, "book-100", "XBT/USD"]
[270, {"b": [["11627.30000", "0.02878826", "1596666809.213390"]], "c": "4164850282"}, "book-100", "XBT/USD"]
[270, {"b": [["11664.80000", "20.04484362", "1596666809.354312"]], "c": "1763214132"}, "book-100", "XBT/USD"]
[270, {"b": [["11664.80000", "19.55434362", "1596666809.449248"]], "c": "4226166985"}, "book-100", "XBT/USD"]
[270, {"b": [["11634.00000", "0.17085000", "1596666809.509316"]], "c": "4226166985"}, "book-100", "XBT/USD"]
[270, {"b": [["11664.80000", "19.30434362", "1596666809.510661"]], "c": "3540323814"}, "book-100", "XBT/USD"]
[270, {"a": [["11679.80000", "0.00000000", "1596666809.680365"], ["11722.20000", "3.01549629", "1596666746.821117", "r"]], "c": "3540323814"}, "book-100", "XBT/USD"]
[270, {"a": [["11686.00000", "0.00000000", "1596666809.700860"], ["11722.60000", "23.57900000", "1596666806.604937", "r"]], "c": "3540323814"}, "book-100", "XBT/USD"]
[270, {"b": [["11664.80000", "19.55434362", "1596666809.702198"]], "c": "4226166985"}, "book-100", "XBT/USD"]
[270, {"a": [["11675.10000", "0.64253738", "1596666809.746281"]], "c": "4226166985"}, "book-100", "XBT/USD"]
[270, {"a": [["11709.70000", "7.64407863", "1596666809.746941"]], "c": "4226166985"}, "book-100", "XBT/USD"]
[270, {"a": [["11679.10000", "0.00000000", "1596666809.876183"], ["11722.60000", "23.57900000", "1596666806.604937", "r"]], "c": "4226166985"}, "book-100", "XBT/USD"]
[270, {"a": [["11680.20000", "0.00593004", "1596666809.878360"]], "c": "4226166985"}, "book-100", "XBT/USD"]
[270, {"b": [["11664.30000", "1.50000000", "1596666810.114241"]], "c": "3277144125"}, "book-100", "XBT/USD"]
[270, {"b": [["11624.30000", "13.91509321", "1596666810.193599"]], "c": "3277144125"}, "book-100", "XBT/USD"]
[270, {"a": [["11685.20000", "0.89000000", "1596666810.325890"]], "c": "3277144125"}, "book-100", "XBT/USD"]
[270, {"a": [["11677.70000", "0.10300000", "1596666810.575288"]], "c": "3277144125"}, "book-100", "XBT/USD"]
[270, {"b": [["11662.90000", "0.00000000", "1596666810.575825"], ["11609.80000", "21.20000000", "1596666704.766154", "r"]], "c": "3195930128"}, "book-100", "XBT/USD"]
[270, {"b": [["11663.10000", "0.00000000", "1596666810.576022"], ["11607.70000", "8.40000000", "1596666777.775135", "r"]], "c": "1436495861"}, "book-100", "XBT/USD"]
[270, {"b": [["11663.00000", "0.00000000", "1596666810.597410"], ["11604.10000", "1.51500000", "1596666763.121463", "r"]], "c": "1435225486"}, "book-100", "XBT/USD"]
[270, {"a": [["11685.20000", "1.51758000", "1596666810.617493"]], "c": "1435225486"}, "book-100", "XBT/USD"]
[270, {"b": [["11634.00000", "0.00000000", "1596666810.675921"], ["11603.20000", "2.50039088", "1596666777.334144", "r"]], "c": "1435225486"}, "book-100", "XBT/USD"]
[270, {"b": [["11664.20000", "0.95576324", "1596666810.757879"]], "c": "3425382577"}, "book-100", "XBT/USD"]
[270, {"a": [["11675.30000", "0.00000000", "1596666810.767862"], ["11722.20000", "3.01549629", "1596666746.821117", "r"]], "c": "3425382577"}, "book-100", "XBT/USD"]
[270, {"a": [["11672.90000", "0.00000000", "1596666810.772996"], ["11722.60000", "23.57900000", "1596666806.604937", "r"]], "c": "483943801"}, "book-100", "XBT/USD"]
[270, {"a": [["11678.80000", "0.00000000", "1596666810.915172"], ["11725.30000", "0.01286300", "1596666804.528425", "r"]], "c": "483943801"}, "book-100", "XBT/USD"]
[270, {"b": [["11664.80000", "20.04484362", "1596666810.956461"]], "c": "3745912171"}, "book-100", "XBT/USD"]
[270, {"b": [["11658.90000", "0.30000000", "1596666810.997733"]], "c": "3745912171"}, "book-100", "XBT/USD"]
[270, {"a": [["11675.10000", "2.34353738", "1596666811.042240"]], "c": "3745912171"}, "book-100", "XBT/USD"]
[270, {"b": [["11647.10000", "0.00000000", "1596666811.043203"], ["11602.60000", "1.48021868", "1596666784.125874", "r"]], "c": "3745912171"}, "book-100", "XBT/USD"]
[270, {"b": [["11639.00000", "0.00000000", "1596666811.043634"], ["11602.20000", "2.01681621", "1596666634.588713", "r"]], "c": "3745912171"}, "book-100", "XBT/USD"]
[270, {"a": [["11671.60000", "0.41352978", "1596666811.052111"]], "c": "1927146739"}, "book-100", "XBT/USD"]
[270, {"b": [["11645.50000", "0.00000000", "1596666811.057472"], ["11602.10000", "11.25550194", "1596666780.609892", "r"]], "c": "1927146739"}, "book-100", "XBT/USD"]
[270, {"b": [["11664.80000", "20.26984362", "1596666811.150762"]], "c": "2799868482"}, "book-100", "XBT/USD"]
[270, {"b": [["11603.20000", "0.00000000", "1596666811.170521"], ["11601.10000", "3.00166376", "1596666779.976375", "r"]], "c": "2799868482"}, "book-100", "XBT/USD"]
[270, {"b": [["11643.70000", "0.00000000", "1596666811.218046"], ["11600.40000", "0.90458128", "1596666777.993986", "r"]], "c": "2799868482"}, "book-100", "XBT/USD"]
[270, {"b": [["11637.90000", "0.00000000", "1596666811.219279"], ["11600.10000", "0.05000000", "1596666747.910313", "r"]], "c": "2799868482"}, "book-100", "XBT/USD"]
[270, {"a": [["11699.70000", "1.88937915", "1596666811.361360"]], "c": "2799868482"}, "book-100", "XBT/USD"]
[270, {"a": [["11693.80000", "0.49626442", "1596666811.396960"]], "c": "2799868482"}, "book-100", "XBT/USD"]
[270, {"b": [["11640.00000", "8.31242334", "1596666811.416862"]], "c": "2799868482"}, "book-100", "XBT/USD"]
[270, {"a": [["11685.20000", "0.62758000", "1596666811.427512"]], "c": "2799868482"}, "book-100", "XBT/USD"]
[270, {"b": [["11617.50000", "2.49761864", "1596666811.445738"]], "c": "2799868482"}, "book-100", "XBT/USD"]
[270, {"b": [["11655.80000", "0.49788233", "1596666811.449053"]], "c": "2799868482"}, "book-100", "XBT/USD"]
[270, {"b": [["11650.00000", "0.99626041", "1596666811.450659"]], "c": "2799868482"}, "book-100", "XBT/USD"]
[270, {"b": [["11659.30000", "0.24966445", "1596666811.554104"]], "c": "2799868482"}, "book-100", "XBT/USD"]
[270, {"b": [["11651.10000", "0.57463238", "1596666811.554715"]], "c": "2799868482"}, "book-100", "XBT/USD"]
[270, {"b": [["11655.80000", "0.84751752", "1596666811.574014"]], "c": "2799868482"}, "book-100", "XBT/USD"]
[270, {"a": [["11682.10000", "0.69867000", "1596666811.611060"]], "c": "2799868482"}, "book-100", "XBT/USD"]
[270, {"a": [["11671.60000", "0.00000000", "1596666811.635375"], ["11722.20000", "3.01549629", "1596666746.821117", "r"]], "c": "192504794"}, "book-100", "XBT/USD"]
[270, {"b": [["11664.80000", "20.01984362", "1596666811.636999"]], "c": "2775715032"}, "book-100", "XBT/USD"]
[270, {"b": [["11649.10000", "0.00000000", "1596666811.642528"], ["11602.20000", "2.01681621", "1596666634.588713", "r"]], "c": "2775715032"}, "book-100", "XBT/USD"]
[270, {"b": [["11634.30000", "0.00000000", "1596666811.645711"], ["11602.10000", "11.25550194", "1596666780.609892", "r"]], "c": "2775715032"}, "book-100", "XBT/USD"]
[270, {"b": [["11646.70000", "0.00000000", "1596666811.649393"], ["11601.10000", "3.00166376", "1596666779.976375", "r"]], "c": "2775715032"}, "book-100", "XBT/USD"]
[270, {"b": [["11640.00000", "7.10000000", "1596666811.655864"]], "c": "2775715032"}, "book-100", "XBT/USD"]
[270, {"b": [["11664.80000", "20.26984362", "1596666811.785636"]], "c": "192504794"}, "book-100", "XBT/USD"]
[270, {"a": [["11672.30000", "0.41352978", "1596666811.795894"]], "c": "3063663968"}, "book-100", "XBT/USD"]
[270, {"b": [["11656.80000", "2.87209444", "1596666811.872572"]], "c": "3063663968"}, "book-100", "XBT/USD"]
[270, {"a": [["11674.90000", "0.00000000", "1596666811.874616"], ["11722.20000", "3.01549629", "1596666746.821117", "r"]], "c": "1901299966"}, "book-100", "XBT/USD"]
[270, {"b": [["11659.00000", "0.00000000", "1596666811.963805"], ["11601.10000", "3.00166376", "1596666779.976375", "r"]], "c": "1901299966"}, "book-100", "XBT/USD"]
[270, {"a": [["11689.10000", "0.00000000", "1596666811.966495"], ["11722.60000", "23.57900000", "1596666806.604937", "r"]], "c": "1901299966"}, "book-100", "XBT/USD"]
[270, {"a": [["11685.70000", "0.00000000", "1596666811.968671"], ["11725.30000", "0.01286300", "1596666804.528425", "r"]], "c": "1901299966"}, "book-100", "XBT/USD"]
[270, {"b": [["11660.30000", "0.85711766", "1596666812.030869"]], "c": "1901299966"}, "book-100", "XBT/USD"]
[270, {"a": [["11673.70000", "4.27500000", "1596666812.054654"]], "c": "4211652070"}, "book-100", "XBT/USD"]
[270, {"a": [["11704.70000", "0.00000000", "1596666812.090478"], ["11725.30000", "0.01286300", "1596666804.528425", "r"]], "c": "4211652070"}, "book-100", "XBT/USD"]
[270, {"a": [["11706.20000", "2.24701466", "1596666812.092481"]], "c": "4211652070"}, "book-100", "XBT/USD"]
[270, {"a": [["11674.50000", "0.00000000", "1596666812.135432"], ["11725.30000", "0.01286300", "1596666804.528425", "r"]], "c": "1753296294"}, "book-100", "XBT/USD"]
[270, {"a": [["11697.30000", "0.00000000", "1596666812.168253"], ["11725.40000", "1.99666304", "1596666743.823724", "r"]], "c": "1753296294"}, "book-100", "XBT/USD"]
[270, {"a": [["11684.70000", "0.00000000", "1596666812.198592"], ["11725.50000", "1.06000000", "1596666771.224459", "r"]], "c": "1753296294"}, "book-100", "XBT/USD"]
[270, {"a": [["11675.30000", "0.64258250", "1596666812.203903"]], "c": "1753296294"}, "book-100", "XBT/USD"]
[270, {"b": [["11664.80000", "21.12662029", "1596666812.204043"]], "c": "3515854607"}, "book-100", "XBT/USD"]
[270, {"b": [["11664.70000", "2.35677667", "1596666812.204302"]], "c": "3432242468"}, "book-100", "XBT/USD"]
[270, {"b": [["11660.00000", "0.85677667", "1596666812.204800"]], "c": "3432242468"}, "book-100", "XBT/USD"]
[270, {"a": [["11673.60000", "0.25827962", "1596666812.236869"]], "c": "2417664303"}, "book-100", "XBT/USD"]
[270, {"a": [["11691.50000", "0.24897684", "1596666812.284835"]], "c": "2417664303"}, "book-100", "XBT/USD"]
[270, {"a": [["11682.60000", "0.11169632", "1596666812.421253"]], "c": "2417664303"}, "book-100", "XBT/USD"]
[270, {"a": [["11682.70000", "0.33823079", "1596666812.486598"]], "c": "2417664303"}, "book-100", "XBT/USD"]
[270, {"a": [["11674.90000", "0.04250000", "1596666812.493745"]], "c": "2417664303"}, "book-100", "XBT/USD"]
[270, {"a": [["11682.00000", "0.08250000", "1596666812.495688"]], "c": "2417664303"}, "book-100", "XBT/USD"]
[270, {"b": [["11624.80000", "0.00000000", "1596666812.657037"], ["11601.10000", "3.00166376", "1596666779.976375", "r"]], "c": "2417664303"}, "book-100", "XBT/USD"]
[270, {"b": [["11664.80000", "20.63612029", "1596666812.658466"]], "c": "3694060171"}, "book-100", "XBT/USD"]
[270, {"a": [["11684.80000", "0.00000000", "1596666812.747790"], ["11722.10000", "7.70000000", "1596666696.315517", "r"]], "c": "3694060171"}, "book-100", "XBT/USD"]
[270, {"b": [["11630.20000", "6.62344344", "1596666812.834532"]], "c": "3694060171"}, "book-100", "XBT/USD"]
[270, {"b": [["11664.80000", "21.12662029", "1596666812.857359"]], "c": "2417664303"}, "book-100", "XBT/USD"]
[270, {"a": [["11675.10000", "0.64253738", "1596666812.866637"]], "c": "2417664303"}, "book-100", "XBT/USD"]
[270, {"b": [["11660.50000", "2.25626837", "1596666812.866763"]], "c": "3245730528"}, "book-100", "XBT/USD"]
[270, {"a": [["11672.30000", "0.00000000", "1596666812.880078"], ["11722.20000", "3.01549629", "1596666746.821117", "r"]], "c": "265476445"}, "book-100", "XBT/USD"]
[270, {"b": [["11664.80000", "20.87662029", "1596666812.899508"]], "c": "3083588245"}, "book-100", "XBT/USD"]
[270, {"a": [["11690.40000", "6.55877097", "1596666812.916730"]], "c": "3083588245"}, "book-100", "XBT/USD"]
[270, {"b": [["11661.50000", "1.03598437", "1596666812.922533"]], "c": "1798725184"}, "book-100", "XBT/USD"]
[270, {"b": [["11659.50000", "0.00000000", "1596666812.932477"], ["11602.10000", "11.25550194", "1596666780.609892", "r"]], "c": "1798725184"}, "book-100", "XBT/USD"]
[270, {"a": [["11676.80000", "0.00000000", "1596666812.943051"], ["11722.20000", "3.01549629", "1596666746.821117", "r"]], "c": "1798725184"}, "book-100", "XBT/USD"]
[270, {"b": [["11664.20000", "0.85676324", "1596666812.949276"]], "c": "555952760"}, "book-100", "XBT/USD"]
[270, {"a": [["11690.50000", "3.52831387", "1596666812.986993"]], "c": "555952760"}, "book-100", "XBT/USD"]
[270, {"a": [["11696.40000", "0.00000000", "1596666812.989471"], ["11722.60000", "23.57900000", "1596666806.604937", "r"]], "c": "555952760"}, "book-100", "XBT/USD"]
[270, {"a": [["11694.00000", "0.00000000", "1596666812.991013"], ["11725.30000", "0.01286300", "1596666804.528425", "r"]], "c": "555952760"}, "book-100", "XBT/USD"]
[270, {"a": [["11699.70000", "0.99202833", "1596666812.991203"]], "c": "555952760"}, "book-100", "XBT/USD"]
[270, {"b": [["11664.80000", "10.87675026", "1596666813.003492"]], "c": "3494795238"}, "book-100", "XBT/USD"]
[270, {"b": [["11656.80000", "0.00000000", "1596666813.013547"], ["11601.10000", "3.00166376", "1596666779.976375", "r"]], "c": "3494795238"}, "book-100", "XBT/USD"]
[270, {"a": [["11670.30000", "0.41352978", "1596666813.027043"]], "c": "3698084993"}, "book-100", "XBT/USD"]
[270, {"b": [["11662.90000", "0.25000000", "1596666813.042982"]], "c": "1889840571"}, "book-100", "XBT/USD"]
[270, {"b": [["11664.80000", "10.38625026", "1596666813.047583"]], "c": "2518687703"}, "book-100", "XBT/USD"]
[270, {"b": [["11649.40000", "0.00000000", "1596666813.062601"], ["11601.10000", "3.00166376", "1596666779.976375", "r"]], "c": "2518687703"}, "book-100", "XBT/USD"]
[270, {"a": [["11671.80000", "0.10300000", "1596666813.067789"]], "c": "1093462437"}, "book-100", "XBT/USD"]
[270, {"a": [["11683.60000", "0.00000000", "1596666813.083354"], ["11722.60000", "23.57900000", "1596666806.604937", "r"]], "c": "1093462437"}, "book-100", "XBT/USD"]
[270, {"b": [["11664.70000", "0.85677667", "1596666813.090518"]], "c": "1515247024"}, "book-100", "XBT/USD"]
[270, {"b": [["11664.80000", "9.88625026", "1596666813.105638"]], "c": "3433568631"}, "book-100", "XBT/USD"]
[270, {"b": [["11664.80000", "9.38625026", "1596666813.114428"]], "c": "1029649010"}, "book-100", "XBT/USD"]
[270, {"b": [["11656.00000", "0.00000000", "1596666813.123316"], ["11600.40000", "3.15159594", "1596666812.086864", "r"]], "c": "1029649010"}, "book-100", "XBT/USD"]
[270, {"a": [["11681.10000", "0.69934850", "1596666813.149099"]], "c": "1029649010"}, "book-100", "XBT/USD"]
[270, {"a": [["11670.30000", "0.00000000", "1596666813.149890"], ["11722.60000", "23.57900000", "1596666806.604937", "r"]], "c": "2217126322"}, "book-100", "XBT/USD"]
[270, {"b": [["11662.90000", "0.00000000", "1596666813.186961"], ["11600.10000", "0.05000000", "1596666747.910313", "r"]], "c": "2772727329"}, "book-100", "XBT/USD"]
[270, {"b": [["11664.80000", "9.23625026", "1596666813.192322"]], "c": "973589430"}, "book-100", "XBT/USD"]
[270, {"a": [["11679.30000", "0.66292000", "1596666813.209909"]], "c": "973589430"}, "book-100", "XBT/USD"]
[270, {"b": [["11662.00000", "9.99987003", "1596666813.210482"]], "c": "1328520366"}, "book-100", "XBT/USD"]
[270, {"a": [["11689.50000", "0.00000000", "1596666813.215035"], ["11722.60000", "23.57900000", "1596666806.604937", "r"]], "c": "1328520366"}, "book-100", "XBT/USD"]
[270, {"b": [["11656.30000", "0.05559889", "1596666813.216925"]], "c": "1328520366"}, "book-100", "XBT/USD"]
[270, {"b": [["11656.30000", "0.01341420", "1596666813.218520"]], "c": "1328520366"}, "book-100", "XBT/USD"]
[270, {"a": [["11707.90000", "10.19785743", "1596666813.227760"]], "c": "1328520366"}, "book-100", "XBT/USD"]
[270, {"a": [["11680.60000", "0.50000000", "1596666813.235617"]], "c": "1328520366"}, "book-100", "XBT/USD"]
[270, {"b": [["11659.80000", "2.35717205", "1596666813.243498"]], "c": "1328520366"}, "book-100", "XBT/USD"]
[270, {"b": [["11664.40000", "0.00000000", "1596666813.256627"], ["11600.10000", "0.05000000", "1596666747.910313", "r"]], "c": "60320707"}, "book-100", "XBT/USD"]
[270, {"a": [["11668.90000", "0.41352978", "1596666813.291010"]], "c": "3395791082"}, "book-100", "XBT/USD"]
[270, {"a": [["11687.60000", "0.89798984", "1596666813.301934"]], "c": "3395791082"}, "book-100", "XBT/USD"]
[270, {"a": [["11695.80000", "0.89736025", "1596666813.308623"]], "c": "3395791082"}, "book-100", "XBT/USD"]
[270, {"b": [["11657.10000", "2.59350293", "1596666813.310955"]], "c": "3395791082"}, "book-100", "XBT/USD"]
[270, {"a": [["11691.10000", "0.89772100", "1596666813.311501"]], "c": "3395791082"}, "book-100", "XBT/USD"]
[270, {"a": [["11688.70000", "0.30000000", "1596666813.324036"]], "c": "3395791082"}, "book-100", "XBT/USD"]
[270, {"b": [["11661.40000", "0.25000000", "1596666813.324124"]], "c": "3599979836"}, "book-100", "XBT/USD"]
[270, {"b": [["11662.00000", "0.00000000", "1596666813.327479"], ["11600.40000", "3.15159594", "1596666812.086864", "r"]], "c": "2131472922"}, "book-100", "XBT/USD"]
[270, {"b": [["11656.30000", "0.00000000", "1596666813.341811"], ["11600.10000", "0.05000000", "1596666747.910313", "r"]], "c": "2131472922"}, "book-100", "XBT/USD"]
[270, {"a": [["11687.30000", "0.00000000", "1596666813.359434"], ["11719.80000", "0.30235286", "1596666806.428536", "r"]], "c": "2131472922"}, "book-100", "XBT/USD"]
[270, {"a": [["11675.30000", "0.00000000", "1596666813.368174"], ["11721.00000", "0.80800000", "1596666805.599144", "r"]], "c": "2131472922"}, "book-100", "XBT/USD"]
[270, {"b": [["11654.50000", "0.04219120", "1596666813.372307"]], "c": "2131472922"}, "book-100", "XBT/USD"]
[270, {"a": [["11676.70000", "0.78466000", "1596666813.406906"]], "c": "2131472922"}, "book-100", "XBT/USD"]
[270, {"a": [["11685.20000", "0.00000000", "1596666813.409196"], ["11721.00000", "0.80800000", "1596666805.599144", "r"]], "c": "2131472922"}, "book-100", "XBT/USD"]
[270, {"a": [["11682.30000", "1.64160000", "1596666813.420048"]], "c": "2131472922"}, "book-100", "XBT/USD"]
[270, {"a": [["11673.90000", "3.23683769", "1596666813.428770"]], "c": "2131472922"}, "book-100", "XBT/USD"]
[270, {"a": [["11671.90000", "0.00000000", "1596666813.447252"], ["11719.80000", "0.30235286", "1596666806.428536", "r"]], "c": "3088588769"}, "book-100", "XBT/USD"]
[270, {"a": [["11673.70000", "0.00000000", "1596666813.458159"], ["11721.00000", "0.80800000", "1596666805.599144", "r"]], "c": "3353586064"}, "book-100", "XBT/USD"]
[270, {"b": [["11660.50000", "0.00000000", "1596666813.461655"], ["11600.10000", "0.05000000", "1596666747.910313", "r"]], "c": "2968309354"}, "book-100", "XBT/USD"]
[270, {"a": [["11671.80000", "4.37600000", "1596666813.468202"]], "c": "41581000"}, "book-100", "XBT/USD"]
[270, {"a": [["11674.10000", "0.94118000", "1596666813.475480"]], "c": "893099979"}, "book-100", "XBT/USD"]
[270, {"a": [["11682.10000", "0.00000000", "1596666813.481536"], ["11721.00000", "0.80800000", "1596666805.599144", "r"]], "c": "893099979"}, "book-100", "XBT/USD"]
[270, {"b": [["11661.30000", "0.40300000", "1596666813.481704"]], "c": "1590641623"}, "book-100", "XBT/USD"]
[270, {"b": [["11658.30000", "0.94118000", "1596666813.486145"]], "c": "1590641623"}, "book-100", "XBT/USD"]
[270, {"b": [["11661.30000", "0.30000000", "1596666813.520148"]], "c": "3725758937"}, "book-100", "XBT/USD"]
[270, {"a": [["11677.30000", "0.00000000", "1596666813.564334"], ["11721.70000", "2.47549182", "1596666772.357495", "r"]], "c": "3725758937"}, "book-100", "XBT/USD"]
[270, {"b": [["11661.40000", "0.00000000", "1596666813.590406"], ["11600.10000", "0.05000000", "1596666747.910313", "r"]], "c": "4268779935"}, "book-100", "XBT/USD"]
[270, {"a": [["11668.90000", "0.00000000", "1596666813.598249"], ["11722.10000", "7.70000000", "1596666696.315517", "r"]], "c": "232915741"}, "book-100", "XBT/USD"]
[270, {"b": [["11659.30000", "0.00000000", "1596666813.605749"], ["11600.00000", "0.02931034", "1596666720.289823", "r"]], "c": "232915741"}, "book-100", "XBT/USD"]
[270, {"b": [["11654.50000", "0.00000000", "1596666813.682653"], ["11599.60000", "3.04585670", "1596666779.021471", "r"]], "c": "232915741"}, "book-100", "XBT/USD"]
[270, {"b": [["11654.50000", "0.00705760", "1596666813.682893"]], "c": "232915741"}, "book-100", "XBT/USD"]
[270, {"a": [["11670.70000", "0.36494560", "1596666813.695592"]], "c": "908818127"}, "book-100", "XBT/USD"]
[270, {"b": [["11662.50000", "0.25000000", "1596666813.732709"]], "c": "4087354751"}, "book-100", "XBT/USD"]
[270, {"a": [["11669.70000", "0.41352978", "1596666813.733362"]], "c": "2324642295"}, "book-100", "XBT/USD"]
[270, {"b": [["11652.80000", "0.10500000", "1596666813.783472"]], "c": "2324642295"}, "book-100", "XBT/USD"]
[270, {"b": [["11664.80000", "8.77625026", "1596666813.790819"]], "c": "3951226493"}, "book-100", "XBT/USD"]
[270, {"b": [["11664.80000", "8.67625026", "1596666813.802010"]], "c": "454605521"}, "book-100", "XBT/USD"]
[270, {"b": [["11660.00000", "10.85664670", "1596666813.865896"]], "c": "454605521"}, "book-100", "XBT/USD"]
[270, {"b": [["11660.00000", "0.85677667", "1596666813.992701"]], "c": "454605521"}, "book-100", "XBT/USD"]
[270, {"a": [["11693.80000", "0.00000000", "1596666814.126272"], ["11721.70000", "2.47549182", "1596666772.357495", "r"]], "c": "454605521"}, "book-100", "XBT/USD"]
[270, {"a": [["11699.70000", "0.00000000", "1596666814.127207"], ["11722.10000", "7.70000000", "1596666696.315517", "r"]], "c": "454605521"}, "book-100", "XBT/USD"]
[270, {"a": [["11691.50000", "0.00000000", "1596666814.155073"], ["11722.20000", "3.01549629", "1596666746.821117", "r"]], "c": "454605521"}, "book-100", "XBT/USD"]
[270, {"b": [["11664.80000", "10.37725026", "1596666814.236727"]], "c": "771494319"}, "book-100", "XBT/USD"]
[270, {"a": [["11673.30000", "1.70000000", "1596666814.245932"]], "c": "4100641263"}, "book-100", "XBT/USD"]
[270, {"a": [["11673.60000", "0.00000000", "1596666814.310712"], ["11722.20000", "3.01549629", "1596666746.821117", "r"]], "c": "1717940255"}, "book-100", "XBT/USD"]
[270, {"a": [["11695.00000", "0.00000000", "1596666814.349328"], ["11722.60000", "23.57900000", "1596666806.604937", "r"]], "c": "1717940255"}, "book-100", "XBT/USD"]
[270, {"b": [["11660.10000", "0.09700000", "1596666814.374989"]], "c": "1717940255"}, "book-100", "XBT/USD"]
[270, {"a": [["11671.70000", "0.25832147", "1596666814.411063"]], "c": "785504307"}, "book-100", "XBT/USD"]
[270, {"a": [["11709.70000", "7.20507863", "1596666814.449677"]], "c": "785504307"}, "book-100", "XBT/USD"]
[270, {"b": [["11652.90000", "0.04219699", "1596666814.487769"]], "c": "785504307"}, "book-100", "XBT/USD"]
[270, {"a": [["11683.70000", "0.43900000", "1596666814.493178"]], "c": "785504307"}, "book-100", "XBT/USD"]
[270, {"b": [["11654.50000", "0.00000000", "1596666814.559788"], ["11601.10000", "3.00166376", "1596666779.976375", "r"]], "c": "785504307"}, "book-100", "XBT/USD"]
[270, {"a": [["11690.00000", "0.53642574", "1596666814.581404"]], "c": "785504307"}, "book-100", "XBT/USD"]
[270, {"a": [["11695.90000", "0.99235064", "1596666814.585248"]], "c": "785504307"}, "book-100", "XBT/USD"]
[270, {"a": [["11671.70000", "0.80992147", "1596666814.614727"]], "c": "1335110652"}, "book-100", "XBT/USD"]
[270, {"a": [["11664.90000", "0.00000000", "1596666814.661269"], ["11722.10000", "7.70000000", "1596666696.315517", "r"]], "c": "1641200704"}, "book-100", "XBT/USD"]
[270, {"a": [["11719.80000", "0.00000000", "1596666814.711925"], ["11722.20000", "3.01549629", "1596666746.821117", "r"]], "c": "1641200704"}, "book-100", "XBT/USD"]
[270, {"b": [["11664.80000", "9.87725026", "1596666814.721115"]], "c": "1548689888"}, "book-100", "XBT/USD"]
[270, {"b": [["11664.90000", "1.00000000", "1596666814.740821"]], "c": "3165891814"}, "book-100", "XBT/USD"]
[270, {"b": [["11616.80000", "0.00000000", "1596666814.766046"], ["11601.10000", "3.00166376", "1596666779.976375", "r"]], "c": "3165891814"}, "book-100", "XBT/USD"]
[270, {"a": [["11688.30000", "0.00000000", "1596666814.782935"], ["11722.60000", "23.57900000", "1596666806.604937", "r"]], "c": "3165891814"}, "book-100", "XBT/USD"]
[270, {"b": [["11618.60000", "0.74869883", "1596666814.806162"]], "c": "3165891814"}, "book-100", "XBT/USD"]
[270, {"a": [["11688.40000", "0.74869883", "1596666814.809894"]], "c": "3165891814"}, "book-100", "XBT/USD"]
[270, {"b": [["11664.80000", "8.87725026", "1596666814.823816"]], "c": "1450020086"}, "book-100", "XBT/USD"]
[270, {"b": [["11622.00000", "0.17085000", "1596666814.845980"]], "c": "1450020086"}, "book-100", "XBT/USD"]
[270, {"b": [["11662.50000", "0.00000000", "1596666814.854813"], ["11602.10000", "11.25550194", "1596666780.609892", "r"]], "c": "4030894096"}, "book-100", "XBT/USD"]
[270, {"a": [["11669.70000", "0.00000000", "1596666814.859265"], ["11722.60000", "23.57900000", "1596666806.604937", "r"]], "c": "1204288297"}, "book-100", "XBT/USD"]
[270, {"b": [["11664.80000", "8.86925026", "1596666814.860460"]], "c": "1997871052"}, "book-100", "XBT/USD"]
[270, {"b": [["11665.00000", "0.08572249", "1596666814.887957"]], "c": "2951796736"}, "book-100", "XBT/USD"]
[270, {"b": [["11664.90000", "1.22500000", "1596666814.898322"]], "c": "2504848729"}, "book-100", "XBT/USD"]
[270, {"b": [["11664.80000", "7.16825026", "1596666814.912079"]], "c": "1378072455"}, "book-100", "XBT/USD"]
[270, {"a": [["11670.80000", "0.41352978", "1596666815.001632"]], "c": "672813787"}, "book-100", "XBT/USD"]
[270, {"b": [["11663.60000", "0.25000000", "1596666815.006288"]], "c": "454211987"}, "book-100", "XBT/USD"]
[270, {"b": [["11647.50000", "0.71231953", "1596666815.068156"]], "c": "454211987"}, "book-100", "XBT/USD"]
[270, {"a": [["11685.20000", "0.71002137", "1596666815.068481"]], "c": "454211987"}, "book-100", "XBT/USD"]
[270, {"a": [["11687.60000", "2.31774099", "1596666815.068734"]], "c": "454211987"}, "book-100", "XBT/USD"]
[270, {"a": [["11693.40000", "1.79070209", "1596666815.070199"]], "c": "454211987"}, "book-100", "XBT/USD"]
[270, {"b": [["11664.90000", "3.37500000", "1596666815.084870"]], "c": "3985410719"}, "book-100", "XBT/USD"]
[270, {"b": [["11664.90000", "1.22500000", "1596666815.146878"]], "c": "454211987"}, "book-100", "XBT/USD"]
[270, {"b": [["11664.90000", "0.22500000", "1596666815.149268"]], "c": "227147968"}, "book-100", "XBT/USD"]
[270, {"a": [["11673.70000", "0.64261944", "1596666815.207977"]], "c": "3319970297"}, "book-100", "XBT/USD"]
[270, {"a": [["11676.20000", "0.85692380", "1596666815.208081"]], "c": "3319970297"}, "book-100", "XBT/USD"]
[270, {"a": [["11715.00000", "0.17085000", "1596666815.232616"]], "c": "3319970297"}, "book-100", "XBT/USD"]
[270, {"a": [["11681.20000", "1.93653600", "1596666815.328171"]], "c": "3319970297"}, "book-100", "XBT/USD"]
[270, {"a": [["11670.80000", "0.00000000", "1596666815.480226"], ["11719.70000", "3.50602221", "1596666789.365232", "r"]], "c": "3890711282"}, "book-100", "XBT/USD"]
[270, {"b": [["11663.60000", "0.00000000", "1596666815.481149"], ["11602.60000", "1.48021868", "1596666784.125874", "r"]], "c": "3572457914"}, "book-100", "XBT/USD"]
[270, {"a": [["11672.40000", "0.64269285", "1596666815.498115"]], "c": "978542568"}, "book-100", "XBT/USD"]
[270, {"b": [["11664.80000", "6.57550430", "1596666815.498667"]], "c": "3346809718"}, "book-100", "XBT/USD"]
[270, {"a": [["11674.90000", "0.00000000", "1596666815.519429"], ["11719.70000", "3.50602221", "1596666789.365232", "r"]], "c": "3346809718"}, "book-100", "XBT/USD"]
[270, {"a": [["11687.70000", "0.24901791", "1596666815.586423"]], "c": "3346809718"}, "book-100", "XBT/USD"]
[270, {"a": [["11691.20000", "0.34852070", "1596666815.587599"]], "c": "3346809718"}, "book-100", "XBT/USD"]
[270, {"b": [["11656.10000", "0.24969300", "1596666815.600905"]], "c": "3346809718"}, "book-100", "XBT/USD"]
[270, {"a": [["11679.20000", "0.87259832", "1596666815.611075"]], "c": "3346809718"}, "book-100", "XBT/USD"]
[270, {"a": [["11680.20000", "0.00000000", "1596666815.612985"], ["11719.60000", "2.98021891", "1596666782.974175", "r"]], "c": "3346809718"}, "book-100", "XBT/USD"]
[270, {"a": [["11672.20000", "0.41352978", "1596666815.632725"]], "c": "671144980"}, "book-100", "XBT/USD"]
[270, {"b": [["11665.00000", "0.33572249", "1596666815.653133"]], "c": "799483232"}, "book-100", "XBT/USD"]
[270, {"a": [["11673.30000", "0.00000000", "1596666815.733232"], ["11719.60000", "2.98021891", "1596666782.974175", "r"]], "c": "2002679055"}, "book-100", "XBT/USD"]
[270, {"b": [["11665.10000", "0.44807540", "1596666815.742982"]], "c": "1964626551"}, "book-100", "XBT/USD"]
[270, {"b": [["11661.10000", "0.82006000", "1596666815.847450"]], "c": "1964626551"}, "book-100", "XBT/USD"]
[270, {"b": [["11663.30000", "0.95297418", "1596666815.928684"]], "c": "3566896831"}, "book-100", "XBT/USD"]
[270, {"a": [["11671.90000", "0.09621094", "1596666815.976936"]], "c": "2641949099"}, "book-100", "XBT/USD"]
[270, {"b": [["11664.30000", "0.00000000", "1596666816.079996"], ["11607.70000", "8.40000000", "1596666777.775135", "r"]], "c": "2063976478"}, "book-100", "XBT/USD"]
[270, {"b": [["11665.20000", "0.08572176", "1596666816.202183"]], "c": "3212019187"}, "book-100", "XBT/USD"]
[270, {"b": [["11664.80000", "6.17550430", "1596666816.224019"]], "c": "3691351673"}, "book-100", "XBT/USD"]
[270, {"b": [["11622.00000", "0.00000000", "1596666816.428056"], ["11607.70000", "8.40000000", "1596666777.775135", "r"]], "c": "3691351673"}, "book-100", "XBT/USD"]
[270, {"b": [["11665.10000", "0.00000000", "1596666816.429227"], ["11604.10000", "1.51500000", "1596666763.121463", "r"]], "c": "1272466250"}, "book-100", "XBT/USD"]
[270, {"a": [["11706.20000", "0.00000000", "1596666816.456973"], ["11719.60000", "2.98021891", "1596666782.974175", "r"]], "c": "1272466250"}, "book-100", "XBT/USD"]
[270, {"a": [["11690.50000", "0.00000000", "1596666816.515344"], ["11719.70000", "3.50602221", "1596666789.365232", "r"]], "c": "1272466250"}, "book-100", "XBT/USD"]
[270, {"a": [["11672.20000", "0.00000000", "1596666816.581738"], ["11721.00000", "0.80800000", "1596666805.599144", "r"]], "c": "640489639"}, "book-100", "XBT/USD"]
[270, {"b": [["11665.00000", "0.08572249", "1596666816.588336"]], "c": "3137213629"}, "book-100", "XBT/USD"]
[270, {"b": [["11654.80000", "3.32810587", "1596666816.650205"]], "c": "3137213629"}, "book-100", "XBT/USD"]
[270, {"b": [["11661.60000", "2.00000000", "1596666816.677636"]], "c": "3968208584"}, "book-100", "XBT/USD"]
[270, {"b": [["11665.30000", "0.25831197", "1596666816.682863"]], "c": "1156007711"}, "book-100", "XBT/USD"]
[270, {"b": [["11665.30000", "0.83682898", "1596666816.757183"]], "c": "3915471935"}, "book-100", "XBT/USD"]
[270, {"a": [["11681.10000", "8.99934850", "1596666816.757455"]], "c": "3915471935"}, "book-100", "XBT/USD"]
[270, {"b": [["11664.30000", "0.25000000", "1596666816.772543"]], "c": "3977931889"}, "book-100", "XBT/USD"]
[270, {"a": [["11671.50000", "0.41352978", "1596666816.791991"]], "c": "1187339896"}, "book-100", "XBT/USD"]
[270, {"b": [["11666.10000", "0.50000000", "1596666816.813753"]], "c": "1560179907"}, "book-100", "XBT/USD"]
[270, {"b": [["11666.10000", "3.75000000", "1596666816.874816"]], "c": "3058177838"}, "book-100", "XBT/USD"]
[270, {"b": [["11665.40000", "0.08572102", "1596666816.895125"]], "c": "1975065482"}, "book-100", "XBT/USD"]
[270, {"b": [["11666.10000", "0.50000000", "1596666816.936768"]], "c": "379440910"}, "book-100", "XBT/USD"]
[270, {"b": [["11658.60000", "0.00352856", "1596666816.971740"]], "c": "379440910"}, "book-100", "XBT/USD"]
[270, {"a": [["11678.60000", "0.00000000", "1596666816.971905"], ["11721.00000", "0.80800000", "1596666805.599144", "r"]], "c": "379440910"}, "book-100", "XBT/USD"]
[270, {"b": [["11664.80000", "5.74750430", "1596666817.028800"]], "c": "762573270"}, "book-100", "XBT/USD"]
[270, {"b": [["11665.30000", "0.25831197", "1596666817.068829"]], "c": "2727088562"}, "book-100", "XBT/USD"]
[270, {"b": [["11659.80000", "1.50000000", "1596666817.077473"]], "c": "2727088562"}, "book-100", "XBT/USD"]
[270, {"b": [["11664.10000", "0.00000000", "1596666817.078051"], ["11612.30000", "7.00000000", "1596666617.080387", "r"]], "c": "2727088562"}, "book-100", "XBT/USD"]
[270, {"a": [["11682.70000", "0.00000000", "1596666817.095534"], ["11721.70000", "2.47549182", "1596666772.357495", "r"]], "c": "2727088562"}, "book-100", "XBT/USD"]
[270, {"a": [["11685.20000", "0.00000000", "1596666817.128713"], ["11722.10000", "7.70000000", "1596666696.315517", "r"]], "c": "2727088562"}, "book-100", "XBT/USD"]
[270, {"a": [["11687.60000", "0.89798984", "1596666817.129196"]], "c": "2727088562"}, "book-100", "XBT/USD"]
[270, {"a": [["11674.30000", "1.50000000", "1596666817.133753"]], "c": "2727088562"}, "book-100", "XBT/USD"]
[270, {"b": [["11635.40000", "0.00000000", "1596666817.133855"], ["11611.90000", "1.06000000", "1596666780.430510", "r"]], "c": "2727088562"}, "book-100", "XBT/USD"]
[270, {"a": [["11682.60000", "0.00000000", "1596666817.135912"], ["11722.10000", "7.70000000", "1596666696.315517", "r"]], "c": "2727088562"}, "book-100", "XBT/USD"]
[270, {"a": [["11687.90000", "3.52849373", "1596666817.144461"]], "c": "2727088562"}, "book-100", "XBT/USD"]
[270, {"b": [["11648.90000", "3.20758770", "1596666817.159111"]], "c": "2727088562"}, "book-100", "XBT/USD"]
[270, {"a": [["11671.60000", "0.75551922", "1596666817.199380"]], "c": "318078947"}, "book-100", "XBT/USD"]
[270, {"a": [["11696.60000", "0.56200000", "1596666817.205744"]], "c": "318078947"}, "book-100", "XBT/USD"]
[270, {"a": [["11671.60000", "0.00000000", "1596666817.250691"], ["11721.00000", "0.80800000", "1596666805.599144", "r"]], "c": "2727088562"}, "book-100", "XBT/USD"]
[270, {"a": [["11690.40000", "0.00000000", "1596666817.252987"], ["11721.70000", "2.47549182", "1596666772.357495", "r"]], "c": "2727088562"}, "book-100", "XBT/USD"]
[270, {"b": [["11640.20000", "0.00000000", "1596666817.264213"], ["11611.90000", "1.06000000", "1596666780.430510", "r"]], "c": "2727088562"}, "book-100", "XBT/USD"]
[270, {"b": [["11658.60000", "0.00000000", "1596666817.284852"], ["11611.70000", "0.37132924", "1596666797.216118", "r"]], "c": "2727088562"}, "book-100", "XBT/USD"]
[270, {"a": [["11671.70000", "0.55160000", "1596666817.288929"]], "c": "1189336863"}, "book-100", "XBT/USD"]
[270, {"a": [["11671.40000", "0.75551922", "1596666817.297293"]], "c": "3942493678"}, "book-100", "XBT/USD"]
[270, {"b": [["11647.50000", "0.00000000", "1596666817.300899"], ["11609.90000", "0.01286300", "1596666804.525088", "r"]], "c": "3942493678"}, "book-100", "XBT/USD"]
[270, {"b": [["11666.10000", "0.92800000", "1596666817.304158"]], "c": "1260691532"}, "book-100", "XBT/USD"]
[270, {"a": [["11688.40000", "0.00000000", "1596666817.313826"], ["11721.70000", "2.47549182", "1596666772.357495", "r"]], "c": "1260691532"}, "book-100", "XBT/USD"]
[270, {"a": [["11692.20000", "6.55910761", "1596666817.331320"]], "c": "1260691532"}, "book-100", "XBT/USD"]
[270, {"a": [["11671.40000", "0.00000000", "1596666817.345995"], ["11721.70000", "2.47549182", "1596666772.357495", "r"]], "c": "3879393981"}, "book-100", "XBT/USD"]
[270, {"a": [["11681.70000", "0.11169453", "1596666817.354886"]], "c": "3879393981"}, "book-100", "XBT/USD"]
[270, {"a": [["11671.40000", "0.25831539", "1596666817.378610"]], "c": "3111537023"}, "book-100", "XBT/USD"]
[270, {"b": [["11666.10000", "1.51613320", "1596666817.381164"]], "c": "3016179488"}, "book-100", "XBT/USD"]
[270, {"b": [["11645.00000", "0.00000000", "1596666817.385393"], ["11609.80000", "21.20000000", "1596666704.766154", "r"]], "c": "3016179488"}, "book-100", "XBT/USD"]
[270, {"b": [["11639.20000", "0.00000000", "1596666817.385693"], ["11607.70000", "8.40000000", "1596666777.775135", "r"]], "c": "3016179488"}, "book-100", "XBT/USD"]
[270, {"a": [["11693.40000", "8.86080403", "1596666817.414617"]], "c": "3016179488"}, "book-100", "XBT/USD"]
[270, {"b": [["11649.90000", "2.00924626", "1596666817.444432"]], "c": "3016179488"}, "book-100", "XBT/USD"]
[270, {"a": [["11685.20000", "0.71002137", "1596666817.514383"]], "c": "3016179488"}, "book-100", "XBT/USD"]
[270, {"a": [["11681.80000", "0.33820382", "1596666817.514750"]], "c": "3016179488"}, "book-100", "XBT/USD"]
[270, {"a": [["11687.50000", "1.41976330", "1596666817.517034"]], "c": "3016179488"}, "book-100", "XBT/USD"]
[270, {"b": [["11649.40000", "0.71220335", "1596666817.560420"]], "c": "3016179488"}, "book-100", "XBT/USD"]
[270, {"a": [["11676.90000", "5.20675890", "1596666817.631395"]], "c": "3016179488"}, "book-100", "XBT/USD"]
[270, {"a": [["11674.20000", "0.01491076", "1596666817.770079"]], "c": "3016179488"}, "book-100", "XBT/USD"]
[270, {"b": [["11661.00000", "0.01491076", "1596666817.770758"]], "c": "3016179488"}, "book-100", "XBT/USD"]
[270, {"b": [["11651.70000", "0.00000000", "1596666817.791215"], ["11609.90000", "0.01286300", "1596666804.525088", "r"]], "c": "3016179488"}, "book-100", "XBT/USD"]
[270, {"b": [["11647.00000", "0.00000000", "1596666817.795576"], ["11609.80000", "21.20000000", "1596666704.766154", "r"]], "c": "3016179488"}, "book-100", "XBT/USD"]
[270, {"b": [["11644.40000", "0.00000000", "1596666817.828776"], ["11609.30000", "2.01627299", "1596666817.684177", "r"]], "c": "3016179488"}, "book-100", "XBT/USD"]
[270, {"b": [["11649.40000", "0.00000000", "1596666817.828920"], ["11607.70000", "8.40000000", "1596666777.775135", "r"]], "c": "3016179488"}, "book-100", "XBT/USD"]
[270, {"b": [["11659.80000", "1.57455382", "1596666817.831012"]], "c": "3016179488"}, "book-100", "XBT/USD"]
[270, {"a": [["11674.70000", "0.07455382", "1596666817.831094"]], "c": "3016179488"}, "book-100", "XBT/USD"]
[270, {"b": [["11639.60000", "0.90031324", "1596666817.836625"]], "c": "3016179488"}, "book-100", "XBT/USD"]
[270, {"b": [["11654.30000", "3.53866658", "1596666817.844029"]], "c": "3016179488"}, "book-100", "XBT/USD"]
[270, {"b": [["11648.50000", "3.54042855", "1596666817.849432"]], "c": "3016179488"}, "book-100", "XBT/USD"]
[270, {"b": [["11648.60000", "0.00000000", "1596666817.852033"], ["11609.30000", "2.01627299", "1596666817.684177", "r"]], "c": "3016179488"}, "book-100", "XBT/USD"]
[270, {"b": [["11651.40000", "0.17892917", "1596666817.887647"]], "c": "3016179488"}, "book-100", "XBT/USD"]
[270, {"b": [["11666.10000", "1.60185128", "1596666817.900300"]], "c": "1351444823"}, "book-100", "XBT/USD"]
[270, {"a": [["11676.20000", "1.03585722", "1596666817.945023"]], "c": "1351444823"}, "book-100", "XBT/USD"]
[270, {"b": [["11644.90000", "0.00000000", "1596666817.961876"], ["11609.30000", "2.01627299", "1596666817.684177", "r"]], "c": "1351444823"}, "book-100", "XBT/USD"]
[270, {"a": [["11674.30000", "0.00000000", "1596666817.970622"], ["11715.00000", "0.17085000", "1596666815.232616", "r"]], "c": "1351444823"}, "book-100", "XBT/USD"]
[270, {"b": [["11659.80000", "0.07455382", "1596666817.971321"]], "c": "1351444823"}, "book-100", "XBT/USD"]
[270, {"a": [["11671.70000", "0.59410000", "1596666818.018326"]], "c": "776516376"}, "book-100", "XBT/USD"]
[270, {"b": [["11661.70000", "0.04250000", "1596666818.019509"]], "c": "776516376"}, "book-100", "XBT/USD"]
[270, {"a": [["11674.10000", "0.00000000", "1596666818.030204"], ["11715.30000", "6.10000000", "1596666635.445451", "r"]], "c": "776516376"}, "book-100", "XBT/USD"]
[270, {"b": [["11641.10000", "0.00000000", "1596666818.048568"], ["11609.30000", "2.01627299", "1596666817.684177", "r"]], "c": "776516376"}, "book-100", "XBT/USD"]
[270, {"b": [["11656.00000", "0.90061020", "1596666818.089280"]], "c": "776516376"}, "book-100", "XBT/USD"]
[270, {"b": [["11647.80000", "0.90124423", "1596666818.099884"]], "c": "776516376"}, "book-100", "XBT/USD"]
[270, {"b": [["11660.70000", "1.50000000", "1596666818.118311"]], "c": "776516376"}, "book-100", "XBT/USD"]
[270, {"b": [["11666.10000", "1.95185128", "1596666818.175672"]], "c": "1621941286"}, "book-100", "XBT/USD"]
[270, {"a": [["11675.30000", "1.50000000", "1596666818.177243"]], "c": "1621941286"}, "book-100", "XBT/USD"]
[270, {"b": [["11666.10000", "2.59452638", "1596666818.199675"]], "c": "760242242"}, "book-100", "XBT/USD"]
[270, {"b": [["11666.00000", "0.64267510", "1596666818.200458"]], "c": "3321752558"}, "book-100", "XBT/USD"]
[270, {"a": [["11681.10000", "0.69934850", "1596666818.248846"]], "c": "3321752558"}, "book-100", "XBT/USD"]
[270, {"a": [["11670.70000", "0.00000000", "1596666818.283168"], ["11715.30000", "6.10000000", "1596666635.445451", "r"]], "c": "826391495"}, "book-100", "XBT/USD"]
[270, {"b": [["11666.10000", "6.87152638", "1596666818.284366"]], "c": "1461322022"}, "book-100", "XBT/USD"]
[270, {"b": [["11652.50000", "0.90088072", "1596666818.293534"]], "c": "1461322022"}, "book-100", "XBT/USD"]
[270, {"a": [["11674.20000", "0.00000000", "1596666818.475968"], ["11717.80000", "1.99812614", "1596666759.535617", "r"]], "c": "1461322022"}, "book-100", "XBT/USD"]
[270, {"b": [["11645.30000", "0.00000000", "1596666818.478002"], ["11611.90000", "1.06000000", "1596666780.430510", "r"]], "c": "1461322022"}, "book-100", "XBT/USD"]
[270, {"a": [["11671.90000", "0.00000000", "1596666818.478404"], ["11718.50000", "24.30000000", "1596666641.380470", "r"]], "c": "2951426418"}, "book-100", "XBT/USD"]
[270, {"b": [["11663.80000", "0.93854000", "1596666818.480657"]], "c": "2951426418"}, "book-100", "XBT/USD"]
[270, {"b": [["11664.00000", "9.99987003", "1596666818.480791"]], "c": "2951426418"}, "book-100", "XBT/USD"]
[270, {"a": [["11672.50000", "1.26169451", "1596666818.556338"]], "c": "1357386481"}, "book-100", "XBT/USD"]
[270, {"b": [["11664.80000", "1.46750430", "1596666818.655186"]], "c": "1132207186"}, "book-100", "XBT/USD"]
[270, {"a": [["11676.20000", "0.85692380", "1596666818.655242"]], "c": "1132207186"}, "book-100", "XBT/USD"]
[270, {"a": [["11683.90000", "0.01490914", "1596666818.669687"]], "c": "1132207186"}, "book-100", "XBT/USD"]
[270, {"b": [["11643.90000", "0.00000000", "1596666818.720835"], ["11612.30000", "7.00000000", "1596666617.080387", "r"]], "c": "1132207186"}, "book-100", "XBT/USD"]
[270, {"b": [["11665.30000", "0.00000000", "1596666818.760300"], ["11612.00000", "0.01285771", "1596666818.534397", "r"]], "c": "2932758738"}, "book-100", "XBT/USD"]
[270, {"a": [["11675.50000", "0.15000000", "1596666818.837873"]], "c": "2932758738"}, "book-100", "XBT/USD"]
[270, {"a": [["11678.30000", "0.17891675", "1596666818.838430"]], "c": "2932758738"}, "book-100", "XBT/USD"]
[270, {"b": [["11666.10000", "7.12984286", "1596666818.861260"]], "c": "944933318"}, "book-100", "XBT/USD"]
[270, {"a": [["11676.10000", "0.15000000", "1596666818.927732"]], "c": "944933318"}, "book-100", "XBT/USD"]
[270, {"b": [["11663.30000", "0.85676324", "1596666818.966167"]], "c": "944933318"}, "book-100", "XBT/USD"]
[270, {"b": [["11649.00000", "4.00000000", "1596666818.966999"]], "c": "944933318"}, "book-100", "XBT/USD"]
[270, {"a": [["11673.90000", "3.33304863", "1596666819.002379"]], "c": "944933318"}, "book-100", "XBT/USD"]
[270, {"b": [["11665.30000", "0.09621094", "1596666819.111366"]], "c": "1897477499"}, "book-100", "XBT/USD"]
[270, {"b": [["11664.00000", "0.00000000", "1596666819.119784"], ["11612.30000", "7.00000000", "1596666617.080387", "r"]], "c": "1897477499"}, "book-100", "XBT/USD"]
[270, {"a": [["11680.20000", "0.56486365", "1596666819.153804"]], "c": "1897477499"}, "book-100", "XBT/USD"]
[270, {"a": [["11692.10000", "0.51030670", "1596666819.154634"]], "c": "1897477499"}, "book-100", "XBT/USD"]
[270, {"a": [["11674.70000", "0.00000000", "1596666819.324277"], ["11713.80000", "0.37309062", "1596666771.863547", "r"]], "c": "1897477499"}, "book-100", "XBT/USD"]
[270, {"b": [["11665.60000", "1.35000000", "1596666819.368037"]], "c": "1692958434"}, "book-100", "XBT/USD"]
[270, {"a": [["11671.30000", "0.75551922", "1596666819.377055"]], "c": "341387758"}, "book-100", "XBT/USD"]
[270, {"a": [["11671.30000", "0.00000000", "1596666819.431039"], ["11713.80000", "0.37309062", "1596666771.863547", "r"]], "c": "1692958434"}, "book-100", "XBT/USD"]
[270, {"a": [["11671.30000", "0.75551922", "1596666819.482384"]], "c": "341387758"}, "book-100", "XBT/USD"]
[270, {"a": [["11685.80000", "0.07454864", "1596666819.516178"]], "c": "341387758"}, "book-100", "XBT/USD"]
[270, {"a": [["11671.30000", "0.00000000", "1596666819.539603"], ["11711.50000", "1.99898326", "1596666797.632161", "r"]], "c": "1692958434"}, "book-100", "XBT/USD"]
[270, {"a": [["11671.40000", "0.00000000", "1596666819.553258"], ["11713.80000", "0.37309062", "1596666771.863547", "r"]], "c": "3612845299"}, "book-100", "XBT/USD"]
[270, {"b": [["11663.00000", "9.99987003", "1596666819.571687"]], "c": "3612845299"}, "book-100", "XBT/USD"]
[270, {"b": [["11665.60000", "0.00000000", "1596666819.573047"], ["11612.50000", "2.30777706", "1596666782.171350", "r"]], "c": "2830699139"}, "book-100", "XBT/USD"]
[270, {"a": [["11671.30000", "0.75551922", "1596666819.590386"]], "c": "193477780"}, "book-100", "XBT/USD"]
[270, {"a": [["11671.30000", "0.00000000", "1596666819.637316"], ["11713.80000", "0.37309062", "1596666771.863547", "r"]], "c": "2830699139"}, "book-100", "XBT/USD"]
[270, {"a": [["11671.70000", "0.85240851", "1596666819.651107"]], "c": "1949699061"}, "book-100", "XBT/USD"]
[270, {"b": [["11664.30000", "0.00000000", "1596666820.016464"], ["11612.30000", "7.00000000", "1596666617.080387", "r"]], "c": "1315944107"}, "book-100", "XBT/USD"]
[270, {"a": [["11671.50000", "0.00000000", "1596666820.021954"], ["11714.80000", "1.99881632", "1596666809.038669", "r"]], "c": "1906469059"}, "book-100", "XBT/USD"]
[270, {"b": [["11655.80000", "0.49788233", "1596666820.070660"]], "c": "1906469059"}, "book-100", "XBT/USD"]
[270, {"a": [["11706.70000", "0.00000000", "1596666820.083300"], ["11715.00000", "0.17085000", "1596666815.232616", "r"]], "c": "1906469059"}, "book-100", "XBT/USD"]
[270, {"a": [["11681.80000", "0.00000000", "1596666820.092440"], ["11715.30000", "6.10000000", "1596666635.445451", "r"]], "c": "1906469059"}, "book-100", "XBT/USD"]
[270, {"a": [["11685.20000", "0.00000000", "1596666820.092524"], ["11717.80000", "1.99812614", "1596666759.535617", "r"]], "c": "1906469059"}, "book-100", "XBT/USD"]
[270, {"a": [["11687.50000", "0.00000000", "1596666820.092596"], ["11718.50000", "24.30000000", "1596666641.380470", "r"]], "c": "1906469059"}, "book-100", "XBT/USD"]
[270, {"a": [["11675.40000", "0.15000000", "1596666820.120781"]], "c": "1906469059"}, "book-100", "XBT/USD"]
[270, {"b": [["11655.80000", "0.00000000", "1596666820.131223"], ["11611.90000", "1.06000000", "1596666780.430510", "r"]], "c": "1906469059"}, "book-100", "XBT/USD"]
[270, {"a": [["11681.70000", "0.00000000", "1596666820.152771"], ["11718.50000", "24.30000000", "1596666641.380470", "r"]], "c": "1906469059"}, "book-100", "XBT/USD"]
[270, {"a": [["11681.20000", "1.04653600", "1596666820.165214"]], "c": "1906469059"}, "book-100", "XBT/USD"]
[270, {"a": [["11671.10000", "0.41352978", "1596666820.174569"]], "c": "1754065232"}, "book-100", "XBT/USD"]
[270, {"b": [["11664.00000", "0.25000000", "1596666820.177375"]], "c": "1754065232"}, "book-100", "XBT/USD"]
[270, {"a": [["11674.40000", "0.15000000", "1596666820.249147"]], "c": "1754065232"}, "book-100", "XBT/USD"]
[270, {"a": [["11675.10000", "0.00000000", "1596666820.263849"], ["11717.80000", "1.99812614", "1596666759.535617", "r"]], "c": "1754065232"}, "book-100", "XBT/USD"]
[270, {"b": [["11663.00000", "0.00000000", "1596666820.310385"], ["11611.90000", "1.06000000", "1596666780.430510", "r"]], "c": "1754065232"}, "book-100", "XBT/USD"]
[270, {"a": [["11674.40000", "0.00000000", "1596666820.317413"], ["11718.50000", "24.30000000", "1596666641.380470", "r"]], "c": "1754065232"}, "book-100", "XBT/USD"]
[270, {"a": [["11671.00000", "0.64273250", "1596666820.339467"]], "c": "893268928"}, "book-100", "XBT/USD"]
[270, {"a": [["11671.60000", "0.75551922", "1596666820.368459"]], "c": "3253315884"}, "book-100", "XBT/USD"]
[270, {"a": [["11674.20000", "0.15000000", "1596666820.424949"]], "c": "3253315884"}, "book-100", "XBT/USD"]
[270, {"a": [["11671.60000", "0.00000000", "1596666820.425723"], ["11715.30000", "6.10000000", "1596666635.445451", "r"]], "c": "893268928"}, "book-100", "XBT/USD"]
[270, {"b": [["11622.00000", "0.17085000", "1596666820.444419"]], "c": "893268928"}, "book-100", "XBT/USD"]
[270, {"a": [["11671.60000", "0.57230000", "1596666820.453153"]], "c": "2993753575"}, "book-100", "XBT/USD"]
[270, {"a": [["11671.70000", "0.30080851", "1596666820.503477"]], "c": "3815964174"}, "book-100", "XBT/USD"]
[270, {"a": [["11679.80000", "0.11169510", "1596666820.533241"]], "c": "3815964174"}, "book-100", "XBT/USD"]
[270, {"a": [["11671.70000", "0.87310851", "1596666820.551313"]], "c": "1825577867"}, "book-100", "XBT/USD"]
[270, {"b": [["11664.80000", "1.38177667", "1596666820.556501"]], "c": "1477542771"}, "book-100", "XBT/USD"]
[270, {"a": [["11671.60000", "0.00000000", "1596666820.558278"], ["11715.00000", "0.17085000", "1596666815.232616", "r"]], "c": "2188328947"}, "book-100", "XBT/USD"]
[270, {"a": [["11705.60000", "5.26337449", "1596666820.562782"]], "c": "2188328947"}, "book-100", "XBT/USD"]
[270, {"b": [["11651.00000", "0.34977923", "1596666820.576914"]], "c": "2188328947"}, "book-100", "XBT/USD"]
[270, {"a": [["11700.90000", "0.89559657", "1596666820.585109"]], "c": "2188328947"}, "book-100", "XBT/USD"]
[270, {"a": [["11712.00000", "0.17085000", "1596666820.608539"]], "c": "2188328947"}, "book-100", "XBT/USD"]
[270, {"a": [["11680.00000", "0.33825482", "1596666820.674276"]], "c": "2188328947"}, "book-100", "XBT/USD"]
[270, {"a": [["11683.30000", "0.71013449", "1596666820.674370"]], "c": "2188328947"}, "book-100", "XBT/USD"]
[270, {"a": [["11685.70000", "1.41997729", "1596666820.675570"]], "c": "2188328947"}, "book-100", "XBT/USD"]
[270, {"b": [["11658.30000", "1.28006443", "1596666820.704794"]], "c": "2188328947"}, "book-100", "XBT/USD"]
[270, {"b": [["11650.90000", "0.54226312", "1596666820.707517"]], "c": "2188328947"}, "book-100", "XBT/USD"]
[270, {"b": [["11655.00000", "0.71185880", "1596666820.713461"]], "c": "2188328947"}, "book-100", "XBT/USD"]
[270, {"b": [["11652.60000", "1.42401083", "1596666820.713752"]], "c": "2188328947"}, "book-100", "XBT/USD"]
[270, {"b": [["11646.80000", "1.79786092", "1596666820.741419"]], "c": "2188328947"}, "book-100", "XBT/USD"]
[270, {"a": [["11705.60000", "1.98337449", "1596666820.829303"]], "c": "2188328947"}, "book-100", "XBT/USD"]
[270, {"a": [["11674.20000", "0.00000000", "1596666820.939929"], ["11711.50000", "1.99898326", "1596666797.632161", "r"]], "c": "2188328947"}, "book-100", "XBT/USD"]
[270, {"a": [["11681.10000", "7.39934850", "1596666820.983596"]], "c": "2188328947"}, "book-100", "XBT/USD"]
[270, {"b": [["11651.60000", "0.92100000", "1596666821.008727"]], "c": "2188328947"}, "book-100", "XBT/USD"]
[270, {"a": [["11671.60000", "0.57230000", "1596666821.026725"]], "c": "1477542771"}, "book-100", "XBT/USD"]
[270, {"a": [["11671.70000", "0.30080851", "1596666821.034291"]], "c": "3618858742"}, "book-100", "XBT/USD"]
[270, {"b": [["11652.60000", "0.00000000", "1596666821.163890"], ["11614.80000", "3.08717099", "1596666746.879208", "r"]], "c": "3618858742"}, "book-100", "XBT/USD"]
[270, {"b": [["11655.00000", "0.00000000", "1596666821.164603"], ["11613.60000", "3.55198121", "1596666780.634357", "r"]], "c": "3618858742"}, "book-100", "XBT/USD"]
[270, {"b": [["11658.30000", "0.94118000", "1596666821.165203"]], "c": "3618858742"}, "book-100", "XBT/USD"]
[270, {"b": [["11618.60000", "0.00000000", "1596666821.206207"], ["11613.00000", "0.17085000", "1596666803.224745", "r"]], "c": "3618858742"}, "book-100", "XBT/USD"]
[270, {"b": [["11618.20000", "0.74872002", "1596666821.244798"]], "c": "3618858742"}, "book-100", "XBT/USD"]
[270, {"a": [["11687.80000", "0.74872002", "1596666821.247151"]], "c": "3618858742"}, "book-100", "XBT/USD"]
[270, {"b": [["11662.50000", "9.99987003", "1596666821.403046"]], "c": "3618858742"}, "book-100", "XBT/USD"]
[270, {"b": [["11656.50000", "0.71176719", "1596666821.419363"]], "c": "3618858742"}, "book-100", "XBT/USD"]
[270, {"b": [["11659.90000", "0.33883793", "1596666821.420001"]], "c": "3618858742"}, "book-100", "XBT/USD"]
[270, {"b": [["11654.20000", "1.42381533", "1596666821.440100"]], "c": "3618858742"}, "book-100", "XBT/USD"]
[270, {"a": [["11674.20000", "0.15000000", "1596666821.479182"]], "c": "3618858742"}, "book-100", "XBT/USD"]
[270, {"b": [["11650.90000", "0.49806312", "1596666821.632785"]], "c": "3618858742"}, "book-100", "XBT/USD"]
[270, {"a": [["11671.70000", "0.04250000", "1596666821.725659"]], "c": "966475802"}, "book-100", "XBT/USD"]
[270, {"a": [["11671.50000", "0.25831671", "1596666821.826554"]], "c": "8611615"}, "book-100", "XBT/USD"]
[270, {"a": [["11671.70000", "0.61480000", "1596666821.828092"]], "c": "3897580110"}, "book-100", "XBT/USD"]
[270, {"a": [["11671.60000", "0.00000000", "1596666821.831173"], ["11710.60000", "2.80039129", "1596666770.582883", "r"]], "c": "17977778"}, "book-100", "XBT/USD"]
[270, {"a": [["11674.20000", "0.00000000", "1596666821.927447"], ["11710.70000", "3.52183532", "1596666711.393054", "r"]], "c": "17977778"}, "book-100", "XBT/USD"]
[270, {"b": [["11662.50000", "0.00000000", "1596666822.015788"], ["11616.70000", "2.01459953", "1596666777.763006", "r"]], "c": "17977778"}, "book-100", "XBT/USD"]
[270, {"a": [["11673.90000", "3.23683769", "1596666822.052256"]], "c": "17977778"}, "book-100", "XBT/USD"]
[270, {"b": [["11665.30000", "0.00000000", "1596666822.077055"], ["11615.60000", "0.20000000", "1596666623.308321", "r"]], "c": "1632952268"}, "book-100", "XBT/USD"]
[270, {"b": [["11652.90000", "0.00000000", "1596666822.150738"], ["11614.80000", "3.08717099", "1596666746.879208", "r"]], "c": "1632952268"}, "book-100", "XBT/USD"]
[270, {"b": [["11652.90000", "0.00705760", "1596666822.150860"]], "c": "1632952268"}, "book-100", "XBT/USD"]
[270, {"a": [["11679.80000", "0.00000000", "1596666822.171025"], ["11711.10000", "0.75800000", "1596666806.349295", "r"]], "c": "1632952268"}, "book-100", "XBT/USD"]
[270, {"b": [["11650.90000", "0.00000000", "1596666822.171548"], ["11614.80000", "3.08717099", "1596666746.879208", "r"]], "c": "1632952268"}, "book-100", "XBT/USD"]
[270, {"a": [["11683.30000", "0.00000000", "1596666822.180958"], ["11711.50000", "1.99898326", "1596666797.632161", "r"]], "c": "1632952268"}, "book-100", "XBT/USD"]
[270, {"b": [["11646.80000", "0.00000000", "1596666822.182074"], ["11613.60000", "3.55198121", "1596666780.634357", "r"]], "c": "1632952268"}, "book-100", "XBT/USD"]
[270, {"b": [["11656.00000", "0.00000000", "1596666822.182364"], ["11613.00000", "0.17085000", "1596666803.224745", "r"]], "c": "1632952268"}, "book-100", "XBT/USD"]
[270, {"b": [["11656.50000", "0.00000000", "1596666822.184953"], ["11612.50000", "2.30777706", "1596666782.171350", "r"]], "c": "1632952268"}, "book-100", "XBT/USD"]
[270, {"b": [["11656.10000", "0.00000000", "1596666822.188935"], ["11612.30000", "7.00000000", "1596666617.080387", "r"]], "c": "1632952268"}, "book-100", "XBT/USD"]
[270, {"a": [["11680.00000", "0.00000000", "1596666822.194175"], ["11712.00000", "0.17085000", "1596666820.608539", "r"]], "c": "1632952268"}, "book-100", "XBT/USD"]
[270, {"b": [["11652.50000", "0.00000000", "1596666822.197154"], ["11611.90000", "1.06000000", "1596666780.430510", "r"]], "c": "1632952268"}, "book-100", "XBT/USD"]
[270, {"b": [["11651.00000", "0.00000000", "1596666822.200594"], ["11611.70000", "0.37132924", "1596666797.216118", "r"]], "c": "1632952268"}, "book-100", "XBT/USD"]
[270, {"b": [["11639.90000", "0.00000000", "1596666822.214138"], ["11609.90000", "0.01285771", "1596666819.557595", "r"]], "c": "1632952268"}, "book-100", "XBT/USD"]
[270, {"b": [["11637.40000", "0.00000000", "1596666822.250765"], ["11609.80000", "21.20000000", "1596666704.766154", "r"]], "c": "1632952268"}, "book-100", "XBT/USD"]
[270, {"a": [["11682.70000", "0.11169423", "1596666822.396442"]], "c": "1632952268"}, "book-100", "XBT/USD"]
[270, {"b": [["11654.20000", "0.00000000", "1596666822.436894"], ["11609.30000", "2.01627299", "1596666817.684177", "r"]], "c": "1632952268"}, "book-100", "XBT/USD"]
[270, {"b": [["11659.90000", "0.00000000", "1596666822.444177"], ["11607.70000", "8.40000000", "1596666777.775135", "r"]], "c": "1632952268"}, "book-100", "XBT/USD"]
[270, {"b": [["11653.20000", "0.49797123", "1596666822.499249"]], "c": "1632952268"}, "book-100", "XBT/USD"]
[270, {"a": [["11674.20000", "0.15000000", "1596666822.501432"]], "c": "1632952268"}, "book-100", "XBT/USD"]
[270, {"a": [["11682.00000", "0.00000000", "1596666822.522515"], ["11711.50000", "1.99898326", "1596666797.632161", "r"]], "c": "1632952268"}, "book-100", "XBT/USD"]
[270, {"b": [["11643.50000", "2.01080180", "1596666822.525930"]], "c": "1632952268"}, "book-100", "XBT/USD"]
[270, {"b": [["11660.70000", "0.00000000", "1596666822.526007"], ["11609.30000", "2.01627299", "1596666817.684177", "r"]], "c": "1632952268"}, "book-100", "XBT/USD"]
[270, {"b": [["11656.30000", "0.24972871", "1596666822.575356"]], "c": "1632952268"}, "book-100", "XBT/USD"]
[270, {"b": [["11652.80000", "0.45472520", "1596666822.576954"]], "c": "1632952268"}, "book-100", "XBT/USD"]
[270, {"b": [["11662.00000", "9.99987003", "1596666822.658667"]], "c": "1632952268"}, "book-100", "XBT/USD"]
[270, {"b": [["11659.00000", "1.50000000", "1596666822.673617"]], "c": "1632952268"}, "book-100", "XBT/USD"]
[270, {"b": [["11656.80000", "0.71174888", "1596666822.692440"]], "c": "1632952268"}, "book-100", "XBT/USD"]
[270, {"a": [["11682.80000", "0.33817375", "1596666822.696990"]], "c": "1632952268"}, "book-100", "XBT/USD"]
[270, {"b": [["11660.20000", "0.33882921", "1596666822.699422"]], "c": "1632952268"}, "book-100", "XBT/USD"]
[270, {"a": [["11686.20000", "0.70995827", "1596666822.701266"]], "c": "1632952268"}, "book-100", "XBT/USD"]
[270, {"b": [["11654.50000", "1.42377868", "1596666822.704578"]], "c": "1632952268"}, "book-100", "XBT/USD"]
[270, {"a": [["11702.40000", "0.08250000", "1596666822.793983"]], "c": "1632952268"}, "book-100", "XBT/USD"]
[270, {"b": [["11663.90000", "0.08250000", "1596666822.795553"]], "c": "1632952268"}, "book-100", "XBT/USD"]
[270, {"a": [["11674.20000", "0.00000000", "1596666822.929879"], ["11710.70000", "3.52183532", "1596666711.393054", "r"]], "c": "1632952268"}, "book-100", "XBT/USD"]
[270, {"b": [["11650.40000", "7.09679465", "1596666822.993047"]], "c": "1632952268"}, "book-100", "XBT/USD"]
[270, {"b": [["11661.70000", "0.00000000", "1596666823.054542"], ["11613.00000", "0.17085000", "1596666803.224745", "r"]], "c": "1632952268"}, "book-100", "XBT/USD"]
[270, {"a": [["11671.70000", "0.57230000", "1596666823.056215"]], "c": "968766263"}, "book-100", "XBT/USD"]
[270, {"b": [["11662.50000", "0.09900000", "1596666823.089248"]], "c": "968766263"}, "book-100", "XBT/USD"]
[270, {"b": [["11652.90000", "0.00000000", "1596666823.184102"], ["11613.00000", "0.17085000", "1596666803.224745", "r"]], "c": "968766263"}, "book-100", "XBT/USD"]
[270, {"b": [["11653.30000", "0.04219554", "1596666823.185421"]], "c": "968766263"}, "book-100", "XBT/USD"]
[270, {"b": [["11662.00000", "0.00000000", "1596666823.245301"], ["11613.00000", "0.17085000", "1596666803.224745", "r"]], "c": "968766263"}, "book-100", "XBT/USD"]
[270, {"a": [["11672.60000", "0.04250000", "1596666823.335127"]], "c": "3841455976"}, "book-100", "XBT/USD"]
[270, {"b": [["11663.40000", "0.04250000", "1596666823.335354"]], "c": "3841455976"}, "book-100", "XBT/USD"]
[270, {"a": [["11704.80000", "2.24716779", "1596666823.342478"]], "c": "3841455976"}, "book-100", "XBT/USD"]
[270, {"b": [["11662.50000", "10.09887003", "1596666823.421509"]], "c": "3841455976"}, "book-100", "XBT/USD"]
[270, {"b": [["11650.50000", "0.00431614", "1596666823.628398"]], "c": "3841455976"}, "book-100", "XBT/USD"]
[270, {"a": [["11687.50000", "0.00438186", "1596666823.632944"]], "c": "3841455976"}, "book-100", "XBT/USD"]
[270, {"a": [["11674.20000", "0.15000000", "1596666823.756575"]], "c": "3841455976"}, "book-100", "XBT/USD"]
[270, {"b": [["11659.20000", "0.00000000", "1596666823.760983"], ["11613.60000", "3.55198121", "1596666780.634357", "r"]], "c": "3841455976"}, "book-100", "XBT/USD"]
[270, {"b": [["11650.50000", "0.00000000", "1596666823.822183"], ["11613.00000", "0.17085000", "1596666803.224745", "r"]], "c": "3841455976"}, "book-100", "XBT/USD"]
[270, {"b": [["11666.10000", "7.34171286", "1596666823.864051"]], "c": "1042196628"}, "book-100", "XBT/USD"]
[270, {"b": [["11641.20000", "2.90181799", "1596666823.884813"]], "c": "1042196628"}, "book-100", "XBT/USD"]
[270, {"b": [["11652.80000", "1.35564546", "1596666823.890808"]], "c": "1042196628"}, "book-100", "XBT/USD"]
[270, {"b": [["11656.30000", "1.15037845", "1596666823.893596"]], "c": "1042196628"}, "book-100", "XBT/USD"]
[270, {"a": [["11674.20000", "0.00000000", "1596666823.931581"], ["11710.10000", "0.89650546", "1596666771.484931", "r"]], "c": "1042196628"}, "book-100", "XBT/USD"]
[270, {"b": [["11665.60000", "0.39000000", "1596666824.338566"]], "c": "2525731290"}, "book-100", "XBT/USD"]
[270, {"a": [["11674.00000", "0.15000000", "1596666824.505618"]], "c": "2525731290"}, "book-100", "XBT/USD"]
[270, {"b": [["11662.50000", "0.09900000", "1596666824.528213"]], "c": "2525731290"}, "book-100", "XBT/USD"]
[270, {"b": [["11662.00000", "9.99987003", "1596666825.620053"]], "c": "2525731290"}, "book-100", "XBT/USD"]
[270, {"b": [["11651.40000", "0.00000000", "1596666825.622391"], ["11613.60000", "3.55198121", "1596666780.634357", "r"]], "c": "2525731290"}, "book-100", "XBT/USD"]
[270, {"a": [["11674.00000", "0.00000000", "1596666825.622524"], ["11710.10000", "0.89650546", "1596666771.484931", "r"]], "c": "2525731290"}, "book-100", "XBT/USD"]
[270, {"b": [["11659.80000", "0.00000000", "1596666825.624150"], ["11613.00000", "0.17085000", "1596666803.224745", "r"]], "c": "2525731290"}, "book-100", "XBT/USD"]
[270, {"a": [["11686.20000", "0.00000000", "1596666825.639317"], ["11710.40000", "1.16811308", "1596666772.597033", "r"]], "c": "2525731290"}, "book-100", "XBT/USD"]
[270, {"b": [["11660.20000", "0.00000000", "1596666825.641215"], ["11612.50000", "2.30777706", "1596666782.171350", "r"]], "c": "2525731290"}, "book-100", "XBT/USD"]
[270, {"b": [["11661.00000", "0.00000000", "1596666825.645345"], ["11612.30000", "7.00000000", "1596666617.080387", "r"]], "c": "2525731290"}, "book-100", "XBT/USD"]
[270, {"b": [["11656.30000", "0.24972871", "1596666825.653689"]], "c": "2525731290"}, "book-100", "XBT/USD"]
[270, {"a": [["11694.20000", "2.30766000", "1596666825.679905"]], "c": "2525731290"}, "book-100", "XBT/USD"]
[270, {"a": [["11671.10000", "0.00000000", "1596666825.680685"], ["11710.60000", "2.80039129", "1596666770.582883", "r"]], "c": "501086180"}, "book-100", "XBT/USD"]
[270, {"b": [["11656.80000", "0.00000000", "1596666825.680931"], ["11612.00000", "0.01285771", "1596666823.628491", "r"]], "c": "501086180"}, "book-100", "XBT/USD"]
[270, {"b": [["11664.00000", "0.00000000", "1596666825.682049"], ["11611.90000", "1.06000000", "1596666780.430510", "r"]], "c": "501086180"}, "book-100", "XBT/USD"]
[270, {"a": [["11682.70000", "0.00000000", "1596666825.686841"], ["11710.70000", "3.52183532", "1596666711.393054", "r"]], "c": "501086180"}, "book-100", "XBT/USD"]
[270, {"a": [["11682.80000", "0.00000000", "1596666825.692920"], ["11711.10000", "0.75800000", "1596666806.349295", "r"]], "c": "501086180"}, "book-100", "XBT/USD"]
[270, {"b": [["11662.00000", "0.00000000", "1596666825.732611"], ["11611.70000", "0.37132924", "1596666797.216118", "r"]], "c": "501086180"}, "book-100", "XBT/USD"]
[270, {"a": [["11683.90000", "0.00000000", "1596666825.757836"], ["11711.50000", "1.99898326", "1596666797.632161", "r"]], "c": "501086180"}, "book-100", "XBT/USD"]
[270, {"a": [["11674.10000", "0.15000000", "1596666825.796988"]], "c": "501086180"}, "book-100", "XBT/USD"]
[270, {"b": [["11660.30000", "0.93167229", "1596666825.832520"]], "c": "501086180"}, "book-100", "XBT/USD"]
[270, {"b": [["11619.00000", "7.17085000", "1596666825.832740"]], "c": "501086180"}, "book-100", "XBT/USD"]
[270, {"b": [["11665.50000", "0.25000000", "1596666825.841396"]], "c": "1677093719"}, "book-100", "XBT/USD"]
[270, {"b": [["11654.70000", "0.17893112", "1596666825.846169"]], "c": "1677093719"}, "book-100", "XBT/USD"]
[270, {"a": [["11672.70000", "1.46342447", "1596666825.874321"]], "c": "2640583858"}, "book-100", "XBT/USD"]
[270, {"b": [["11661.30000", "0.31491093", "1596666825.897185"]], "c": "2640583858"}, "book-100", "XBT/USD"]
[270, {"b": [["11660.40000", "3.69150115", "1596666825.905285"]], "c": "2640583858"}, "book-100", "XBT/USD"]
[270, {"a": [["11671.40000", "0.25831541", "1596666825.909881"]], "c": "22516713"}, "book-100", "XBT/USD"]
[270, {"a": [["11679.20000", "0.91538349", "1596666825.910977"]], "c": "22516713"}, "book-100", "XBT/USD"]
[270, {"a": [["11671.50000", "0.00000000", "1596666825.922644"], ["11711.10000", "0.75800000", "1596666806.349295", "r"]], "c": "3748936711"}, "book-100", "XBT/USD"]
[270, {"a": [["11679.20000", "0.90023761", "1596666825.940985"]], "c": "3748936711"}, "book-100", "XBT/USD"]
[270, {"a": [["11674.10000", "0.00000000", "1596666825.949625"], ["11711.50000", "1.99898326", "1596666797.632161", "r"]], "c": "3748936711"}, "book-100", "XBT/USD"]
[270, {"b": [["11663.50000", "9.99987003", "1596666825.958721"]], "c": "3748936711"}, "book-100", "XBT/USD"]
[270, {"a": [["11673.80000", "0.01491122", "1596666825.980388"]], "c": "3748936711"}, "book-100", "XBT/USD"]
[270, {"a": [["11680.30000", "2.96904750", "1596666825.987148"]], "c": "3748936711"}, "book-100", "XBT/USD"]
[270, {"a": [["11678.30000", "0.00000000", "1596666825.987763"], ["11711.50000", "1.99898326", "1596666797.632161", "r"]], "c": "3748936711"}, "book-100", "XBT/USD"]
[270, {"a": [["11676.70000", "0.00000000", "1596666826.053329"], ["11712.00000", "0.17085000", "1596666820.608539", "r"]], "c": "3748936711"}, "book-100", "XBT/USD"]
[270, {"b": [["11663.50000", "0.00000000", "1596666826.138147"], ["11612.00000", "0.01285771", "1596666823.628491", "r"]], "c": "3748936711"}, "book-100", "XBT/USD"]
[270, {"a": [["11676.20000", "1.03585762", "1596666826.168598"]], "c": "3748936711"}, "book-100", "XBT/USD"]
[270, {"b": [["11665.30000", "0.09621094", "1596666826.182221"]], "c": "3855928610"}, "book-100", "XBT/USD"]
[270, {"a": [["11673.90000", "3.33304863", "1596666826.184183"]], "c": "3855928610"}, "book-100", "XBT/USD"]
[270, {"a": [["11679.20000", "0.85745244", "1596666826.192455"]], "c": "3855928610"}, "book-100", "XBT/USD"]
[270, {"a": [["11680.10000", "0.04278188", "1596666826.193186"]], "c": "3855928610"}, "book-100", "XBT/USD"]
[270, {"b": [["11655.80000", "0.90068838", "1596666826.247670"]], "c": "3855928610"}, "book-100", "XBT/USD"]
[270, {"a": [["11691.90000", "2.00261579", "1596666826.250220"]], "c": "3855928610"}, "book-100", "XBT/USD"]
[270, {"b": [["11664.50000", "9.99987003", "1596666826.327036"]], "c": "3855928610"}, "book-100", "XBT/USD"]
[270, {"b": [["11625.60000", "0.00000000", "1596666826.360927"], ["11612.50000", "2.30777706", "1596666782.171350", "r"]], "c": "3855928610"}, "book-100", "XBT/USD"]
[270, {"a": [["11680.10000", "0.00000000", "1596666826.394880"], ["11711.50000", "1.99898326", "1596666797.632161", "r"]], "c": "3855928610"}, "book-100", "XBT/USD"]
[270, {"a": [["11677.20000", "3.03567804", "1596666826.396754"]], "c": "3855928610"}, "book-100", "XBT/USD"]
[270, {"a": [["11679.10000", "0.00366249", "1596666826.398487"]], "c": "3855928610"}, "book-100", "XBT/USD"]
[270, {"a": [["11703.60000", "3.27000000", "1596666826.416160"]], "c": "3855928610"}, "book-100", "XBT/USD"]
[270, {"a": [["11671.00000", "0.00000000", "1596666826.465399"], ["11710.70000", "3.52183532", "1596666711.393054", "r"]], "c": "3579110043"}, "book-100", "XBT/USD"]
[270, {"a": [["11674.90000", "0.15000000", "1596666826.479784"]], "c": "3579110043"}, "book-100", "XBT/USD"]
[270, {"b": [["11657.10000", "0.00000000", "1596666826.483626"], ["11612.30000", "7.00000000", "1596666617.080387", "r"]], "c": "3579110043"}, "book-100", "XBT/USD"]
[270, {"a": [["11675.30000", "0.00000000", "1596666826.483910"], ["11710.70000", "3.52183532", "1596666711.393054", "r"]], "c": "3579110043"}, "book-100", "XBT/USD"]
[270, {"a": [["11675.40000", "0.79262106", "1596666826.521561"]], "c": "3579110043"}, "book-100", "XBT/USD"]
[270, {"a": [["11673.90000", "0.09621094", "1596666826.557699"]], "c": "3579110043"}, "book-100", "XBT/USD"]
[270, {"a": [["11671.40000", "0.00000000", "1596666826.561031"], ["11711.10000", "0.75800000", "1596666806.349295", "r"]], "c": "1550769352"}, "book-100", "XBT/USD"]
[270, {"a": [["11671.80000", "4.27300000", "1596666826.576614"]], "c": "4214466316"}, "book-100", "XBT/USD"]
[270, {"a": [["11676.20000", "0.85692380", "1596666826.580387"]], "c": "4214466316"}, "book-100", "XBT/USD"]
[270, {"a": [["11672.30000", "0.25830483", "1596666826.604093"]], "c": "2094036699"}, "book-100", "XBT/USD"]
[270, {"a": [["11677.30000", "1.50000000", "1596666826.634871"]], "c": "2094036699"}, "book-100", "XBT/USD"]
[270, {"a": [["11685.80000", "0.00000000", "1596666826.644881"], ["11710.70000", "3.52183532", "1596666711.393054", "r"]], "c": "2094036699"}, "book-100", "XBT/USD"]
[270, {"a": [["11679.20000", "0.90023761", "1596666826.690588"]], "c": "2094036699"}, "book-100", "XBT/USD"]
[270, {"a": [["11679.10000", "0.00000000", "1596666826.691882"], ["11711.10000", "0.75800000", "1596666806.349295", "r"]], "c": "2094036699"}, "book-100", "XBT/USD"]
[270, {"b": [["11666.10000", "7.34971286", "1596666826.756571"]], "c": "4094986043"}, "book-100", "XBT/USD"]
[270, {"a": [["11678.30000", "0.17890293", "1596666826.778269"]], "c": "4094986043"}, "book-100", "XBT/USD"]
[270, {"a": [["11677.30000", "0.00000000", "1596666826.780899"], ["11711.10000", "0.75800000", "1596666806.349295", "r"]], "c": "4094986043"}, "book-100", "XBT/USD"]
[270, {"a": [["11674.90000", "0.00000000", "1596666826.821242"], ["11711.50000", "1.99898326", "1596666797.632161", "r"]], "c": "4094986043"}, "book-100", "XBT/USD"]
[270, {"a": [["11676.80000", "0.07454289", "1596666826.830483"]], "c": "4094986043"}, "book-100", "XBT/USD"]
[270, {"a": [["11678.60000", "1.50000000", "1596666826.927965"]], "c": "4094986043"}, "book-100", "XBT/USD"]
[270, {"a": [["11673.80000", "0.00000000", "1596666826.971877"], ["11711.10000", "0.75800000", "1596666806.349295", "r"]], "c": "4094986043"}, "book-100", "XBT/USD"]
[270, {"b": [["11659.00000", "0.00000000", "1596666826.972998"], ["11612.00000", "0.01285771", "1596666823.628491", "r"]], "c": "4094986043"}, "book-100", "XBT/USD"]
[270, {"a": [["11675.50000", "0.00000000", "1596666827.003040"], ["11711.50000", "1.99898326", "1596666797.632161", "r"]], "c": "4094986043"}, "book-100", "XBT/USD"]
[270, {"a": [["11675.40000", "0.64262106", "1596666827.003435"]], "c": "4094986043"}, "book-100", "XBT/USD"]
[270, {"b": [["11634.90000", "0.70560000", "1596666827.003823"]], "c": "4094986043"}, "book-100", "XBT/USD"]
[270, {"a": [["11703.60000", "0.00000000", "1596666827.004941"], ["11712.00000", "0.17085000", "1596666820.608539", "r"]], "c": "4094986043"}, "book-100", "XBT/USD"]
[270, {"a": [["11681.70000", "0.82006000", "1596666827.007259"]], "c": "4094986043"}, "book-100", "XBT/USD"]
[270, {"a": [["11679.30000", "0.00000000", "1596666827.011722"], ["11712.00000", "0.17085000", "1596666820.608539", "r"]], "c": "4094986043"}, "book-100", "XBT/USD"]
[270, {"a": [["11681.10000", "0.69934850", "1596666827.025787"]], "c": "4094986043"}, "book-100", "XBT/USD"]
[270, {"b": [["11666.10000", "9.05971286", "1596666827.044792"]], "c": "3334102690"}, "book-100", "XBT/USD"]
[270, {"a": [["11675.80000", "0.15000000", "1596666827.087343"]], "c": "3334102690"}, "book-100", "XBT/USD"]
[270, {"b": [["11662.60000", "1.50000000", "1596666827.120991"]], "c": "3334102690"}, "book-100", "XBT/USD"]
[270, {"b": [["11666.10000", "9.45971286", "1596666827.189307"]], "c": "2362966643"}, "book-100", "XBT/USD"]
[270, {"b": [["11651.90000", "0.04472077", "1596666827.189926"]], "c": "2362966643"}, "book-100", "XBT/USD"]
[270, {"a": [["11687.50000", "0.00000000", "1596666827.192508"], ["11712.00000", "0.17085000", "1596666820.608539", "r"]], "c": "2362966643"}, "book-100", "XBT/USD"]
[270, {"a": [["11679.20000", "0.85745244", "1596666827.213994"]], "c": "2362966643"}, "book-100", "XBT/USD"]
[270, {"a": [["11680.10000", "0.04278187", "1596666827.215043"]], "c": "2362966643"}, "book-100", "XBT/USD"]
[270, {"a": [["11679.20000", "0.90217170", "1596666827.344624"]], "c": "2362966643"}, "book-100", "XBT/USD"]
[270, {"b": [["11649.10000", "1.79751190", "1596666827.476031"]], "c": "2362966643"}, "book-100", "XBT/USD"]
[270, {"b": [["11660.60000", "0.33881871", "1596666827.483150"]], "c": "2362966643"}, "book-100", "XBT/USD"]
[270, {"a": [["11684.10000", "0.71008822", "1596666827.483392"]], "c": "2362966643"}, "book-100", "XBT/USD"]
[270, {"b": [["11657.20000", "0.71172681", "1596666827.495528"]], "c": "2362966643"}, "book-100", "XBT/USD"]
[270, {"a": [["11680.70000", "0.33823567", "1596666827.500069"]], "c": "2362966643"}, "book-100", "XBT/USD"]
[270, {"a": [["11672.50000", "0.86059682", "1596666827.503954"]], "c": "2608532311"}, "book-100", "XBT/USD"]
[270, {"a": [["11675.70000", "0.15000000", "1596666827.615431"]], "c": "2608532311"}, "book-100", "XBT/USD"]
[270, {"b": [["11651.30000", "0.13415797", "1596666827.662966"]], "c": "2608532311"}, "book-100", "XBT/USD"]
[270, {"a": [["11672.70000", "1.04989469", "1596666827.666978"]], "c": "2227693331"}, "book-100", "XBT/USD"]
[270, {"b": [["11665.50000", "0.00000000", "1596666827.667828"], ["11615.60000", "0.20000000", "1596666623.308321", "r"]], "c": "1100835532"}, "book-100", "XBT/USD"]
[270, {"b": [["11649.00000", "0.00000000", "1596666827.722541"], ["11614.80000", "3.08717099", "1596666746.879208", "r"]], "c": "1100835532"}, "book-100", "XBT/USD"]
[270, {"a": [["11673.30000", "0.41262204", "1596666827.750116"]], "c": "1820372910"}, "book-100", "XBT/USD"]
[270, {"b": [["11664.50000", "0.00000000", "1596666827.763960"], ["11613.60000", "3.55198121", "1596666780.634357", "r"]], "c": "1820372910"}, "book-100", "XBT/USD"]
[270, {"b": [["11666.10000", "7.74971286", "1596666827.771371"]], "c": "1580103223"}, "book-100", "XBT/USD"]
[270, {"a": [["11680.20000", "0.60764516", "1596666827.796397"]], "c": "1580103223"}, "book-100", "XBT/USD"]
[270, {"b": [["11664.50000", "0.25000000", "1596666827.827476"]], "c": "1580103223"}, "book-100", "XBT/USD"]
[270, {"a": [["11680.10000", "0.00000000", "1596666827.882635"], ["11710.60000", "2.80039129", "1596666770.582883", "r"]], "c": "1580103223"}, "book-100", "XBT/USD"]
[270, {"a": [["11680.70000", "0.47239658", "1596666827.889043"]], "c": "1580103223"}, "book-100", "XBT/USD"]
[270, {"b": [["11652.00000", "4.00000000", "1596666827.958343"]], "c": "1580103223"}, "book-100", "XBT/USD"]
[270, {"a": [["11671.70000", "0.98582978", "1596666827.959662"]], "c": "3406046036"}, "book-100", "XBT/USD"]
[270, {"b": [["11663.00000", "9.99987003", "1596666827.996877"]], "c": "3406046036"}, "book-100", "XBT/USD"]
[270, {"b": [["11662.60000", "0.00000000", "1596666828.042207"], ["11615.60000", "0.20000000", "1596666623.308321", "r"]], "c": "3406046036"}, "book-100", "XBT/USD"]
[270, {"a": [["11687.80000", "0.00000000", "1596666828.181048"], ["11710.70000", "3.52183532", "1596666711.393054", "r"]], "c": "3406046036"}, "book-100", "XBT/USD"]
[270, {"b": [["11660.70000", "1.50000000", "1596666828.191597"]], "c": "3406046036"}, "book-100", "XBT/USD"]
[270, {"b": [["11618.20000", "0.00000000", "1596666828.204293"], ["11615.60000", "0.20000000", "1596666623.308321", "r"]], "c": "3406046036"}, "book-100", "XBT/USD"]
[270, {"b": [["11618.30000", "0.74873346", "1596666828.215698"]], "c": "3406046036"}, "book-100", "XBT/USD"]
[270, {"a": [["11687.00000", "0.74873346", "1596666828.218645"]], "c": "3406046036"}, "book-100", "XBT/USD"]
[270, {"a": [["11672.30000", "0.00000000", "1596666828.656208"], ["11710.70000", "3.52183532", "1596666711.393054", "r"]], "c": "1039455319"}, "book-100", "XBT/USD"]
[270, {"b": [["11663.00000", "0.00000000", "1596666828.680046"], ["11615.60000", "0.20000000", "1596666623.308321", "r"]], "c": "1039455319"}, "book-100", "XBT/USD"]
[270, {"a": [["11672.30000", "0.25830326", "1596666828.751211"]], "c": "552504860"}, "book-100", "XBT/USD"]
[270, {"b": [["11660.70000", "0.00000000", "1596666828.971837"], ["11614.80000", "3.08717099", "1596666746.879208", "r"]], "c": "552504860"}, "book-100", "XBT/USD"]
[270, {"a": [["11671.80000", "0.00000000", "1596666829.015735"], ["11710.70000", "3.52183532", "1596666711.393054", "r"]], "c": "960056583"}, "book-100", "XBT/USD"]
[270, {"a": [["11678.60000", "0.00000000", "1596666829.016076"], ["11711.10000", "0.75800000", "1596666806.349295", "r"]], "c": "960056583"}, "book-100", "XBT/USD"]
[270, {"b": [["11664.50000", "10.24987003", "1596666829.019053"]], "c": "960056583"}, "book-100", "XBT/USD"]
[270, {"b": [["11662.70000", "1.50000000", "1596666829.117693"]], "c": "960056583"}, "book-100", "XBT/USD"]
[270, {"a": [["11678.50000", "1.50000000", "1596666829.166505"]], "c": "960056583"}, "book-100", "XBT/USD"]
[270, {"a": [["11671.70000", "0.57230000", "1596666829.346948"]], "c": "2888215759"}, "book-100", "XBT/USD"]
[270, {"b": [["11664.50000", "9.99987003", "1596666829.353888"]], "c": "2888215759"}, "book-100", "XBT/USD"]
[270, {"b": [["11661.60000", "2.43800000", "1596666829.357463"]], "c": "2888215759"}, "book-100", "XBT/USD"]
[270, {"b": [["11656.20000", "8.30000000", "1596666829.367128"]], "c": "2888215759"}, "book-100", "XBT/USD"]
[270, {"a": [["11674.10000", "4.28200000", "1596666829.494287"]], "c": "2888215759"}, "book-100", "XBT/USD"]
[270, {"a": [["11675.70000", "0.00000000", "1596666829.824633"], ["11710.70000", "3.52183532", "1596666711.393054", "r"]], "c": "2888215759"}, "book-100", "XBT/USD"]
[270, {"a": [["11675.80000", "0.00000000", "1596666829.831214"], ["11711.10000", "0.75800000", "1596666806.349295", "r"]], "c": "2888215759"}, "book-100", "XBT/USD"]
[270, {"b": [["11665.00000", "0.00000000", "1596666829.906948"], ["11614.80000", "3.08717099", "1596666746.879208", "r"]], "c": "2837758111"}, "book-100", "XBT/USD"]
[270, {"b": [["11665.50000", "0.25000000", "1596666830.020568"]], "c": "3363815000"}, "book-100", "XBT/USD"]
[270, {"a": [["11672.70000", "1.46342447", "1596666830.032197"]], "c": "1206737363"}, "book-100", "XBT/USD"]
[270, {"a": [["11672.40000", "0.00000000", "1596666830.051953"], ["11711.50000", "1.99898326", "1596666797.632161", "r"]], "c": "4227263318"}, "book-100", "XBT/USD"]
[270, {"a": [["11676.00000", "0.64257917", "1596666830.109110"]], "c": "4227263318"}, "book-100", "XBT/USD"]
[270, {"a": [["11672.70000", "1.04989469", "1596666830.225426"]], "c": "456206803"}, "book-100", "XBT/USD"]
[270, {"b": [["11665.50000", "0.00000000", "1596666830.229699"], ["11614.80000", "3.08717099", "1596666746.879208", "r"]], "c": "3550336160"}, "book-100", "XBT/USD"]
[270, {"a": [["11678.30000", "0.00000000", "1596666830.304163"], ["11711.50000", "1.99898326", "1596666797.632161", "r"]], "c": "3550336160"}, "book-100", "XBT/USD"]
[270, {"a": [["11676.10000", "0.00000000", "1596666830.356878"], ["11713.80000", "0.37309062", "1596666771.863547", "r"]], "c": "3550336160"}, "book-100", "XBT/USD"]
[270, {"b": [["11663.40000", "0.00000000", "1596666830.377292"], ["11613.60000", "3.55198121", "1596666780.634357", "r"]], "c": "3550336160"}, "book-100", "XBT/USD"]
[270, {"a": [["11672.60000", "0.00000000", "1596666830.377569"], ["11714.80000", "1.99881632", "1596666809.038669", "r"]], "c": "3851115260"}, "book-100", "XBT/USD"]
[270, {"b": [["11666.10000", "7.99971286", "1596666830.381391"]], "c": "3107180301"}, "book-100", "XBT/USD"]
[270, {"a": [["11673.80000", "0.41352978", "1596666830.382413"]], "c": "1605423072"}, "book-100", "XBT/USD"]
[270, {"b": [["11663.70000", "2.81320005", "1596666830.438371"]], "c": "1605423072"}, "book-100", "XBT/USD"]
[270, {"b": [["11666.10000", "7.74971286", "1596666830.510694"]], "c": "50878993"}, "book-100", "XBT/USD"]
[270, {"a": [["11673.80000", "0.00000000", "1596666830.537147"], ["11714.80000", "1.99881632", "1596666809.038669", "r"]], "c": "3851115260"}, "book-100", "XBT/USD"]
[270, {"a": [["11673.70000", "0.00000000", "1596666830.549218"], ["11715.00000", "0.17085000", "1596666815.232616", "r"]], "c": "1534117260"}, "book-100", "XBT/USD"]
[270, {"a": [["11673.30000", "0.00000000", "1596666830.652703"], ["11715.30000", "6.10000000", "1596666635.445451", "r"]], "c": "2212912174"}, "book-100", "XBT/USD"]
[270, {"a": [["11674.50000", "0.04250000", "1596666830.654555"]], "c": "2923770746"}, "book-100", "XBT/USD"]
[270, {"b": [["11666.10000", "7.79221286", "1596666830.654884"]], "c": "482779149"}, "book-100", "XBT/USD"]
[270, {"b": [["11666.10000", "8.29221286", "1596666830.657798"]], "c": "2148436317"}, "book-100", "XBT/USD"]
[270, {"b": [["11660.40000", "0.85711766", "1596666830.661262"]], "c": "2148436317"}, "book-100", "XBT/USD"]
[270, {"a": [["11680.50000", "2.93909928", "1596666830.661437"]], "c": "2148436317"}, "book-100", "XBT/USD"]
[270, {"b": [["11666.10000", "8.54221286", "1596666830.661539"]], "c": "1474377571"}, "book-100", "XBT/USD"]
[270, {"b": [["11660.00000", "0.00000000", "1596666830.664844"], ["11613.60000", "3.55198121", "1596666780.634357", "r"]], "c": "1474377571"}, "book-100", "XBT/USD"]
[270, {"a": [["11676.20000", "0.00000000", "1596666830.665099"], ["11715.00000", "0.17085000", "1596666815.232616", "r"]], "c": "1474377571"}, "book-100", "XBT/USD"]
[270, {"a": [["11673.90000", "0.50974072", "1596666830.687509"]], "c": "2197656020"}, "book-100", "XBT/USD"]
[270, {"a": [["11672.30000", "0.00000000", "1596666830.713088"], ["11715.30000", "6.10000000", "1596666635.445451", "r"]], "c": "4079997736"}, "book-100", "XBT/USD"]
[270, {"b": [["11666.10000", "8.64221286", "1596666830.749735"]], "c": "3325258673"}, "book-100", "XBT/USD"]
[270, {"a": [["11676.80000", "0.00000000", "1596666830.764436"], ["11717.80000", "1.99812614", "1596666759.535617", "r"]], "c": "3325258673"}, "book-100", "XBT/USD"]
[270, {"a": [["11680.70000", "0.33823567", "1596666830.786257"]], "c": "3325258673"}, "book-100", "XBT/USD"]
[270, {"a": [["11677.20000", "0.00000000", "1596666830.797051"], ["11718.00000", "0.17085000", "1596666826.000796", "r"]], "c": "3325258673"}, "book-100", "XBT/USD"]
[270, {"a": [["11705.30000", "2.00000000", "1596666830.864042"]], "c": "3325258673"}, "book-100", "XBT/USD"]
[270, {"a": [["11674.20000", "0.40550762", "1596666830.879316"]], "c": "805670561"}, "book-100", "XBT/USD"]
[270, {"b": [["11665.20000", "0.00000000", "1596666830.892905"], ["11613.00000", "0.17085000", "1596666803.224745", "r"]], "c": "2285262521"}, "book-100", "XBT/USD"]
[270, {"a": [["11713.80000", "0.00000000", "1596666831.000111"], ["11717.80000", "1.99812614", "1596666759.535617", "r"]], "c": "2285262521"}, "book-100", "XBT/USD"]
[270, {"a": [["11683.00000", "0.13414624", "1596666831.001549"]], "c": "2285262521"}, "book-100", "XBT/USD"]
[270, {"a": [["11673.80000", "0.25827966", "1596666831.020235"]], "c": "4251034589"}, "book-100", "XBT/USD"]
[270, {"a": [["11684.10000", "0.00000000", "1596666831.166253"], ["11715.30000", "6.10000000", "1596666635.445451", "r"]], "c": "4251034589"}, "book-100", "XBT/USD"]
[270, {"a": [["11680.70000", "0.00000000", "1596666831.169389"], ["11717.80000", "1.99812614", "1596666759.535617", "r"]], "c": "4251034589"}, "book-100", "XBT/USD"]
[270, {"a": [["11715.00000", "0.00000000", "1596666831.187077"], ["11718.00000", "0.17085000", "1596666826.000796", "r"]], "c": "4251034589"}, "book-100", "XBT/USD"]
[270, {"b": [["11666.10000", "9.14221286", "1596666831.267867"]], "c": "3636015476"}, "book-100", "XBT/USD"]
[270, {"a": [["11673.90000", "0.41352978", "1596666831.315006"]], "c": "3066387643"}, "book-100", "XBT/USD"]
[270, {"b": [["11625.00000", "0.42085000", "1596666831.337904"]], "c": "3066387643"}, "book-100", "XBT/USD"]
[270, {"a": [["11682.70000", "0.33817777", "1596666831.466946"]], "c": "3066387643"}, "book-100", "XBT/USD"]
[270, {"a": [["11686.00000", "0.70997277", "1596666831.476026"]], "c": "3066387643"}, "book-100", "XBT/USD"]
[270, {"a": [["11673.90000", "0.00000000", "1596666831.486503"], ["11717.80000", "1.99812614", "1596666759.535617", "r"]], "c": "2776150202"}, "book-100", "XBT/USD"]
[271, [["11666.20000", "0.01490874", "1596666831.494715", "b", "l", ""]], "trade", "XBT/USD"]
[270, {"a": [["11666.20000", "0.08509126", "1596666831.494715"]], "c": "823924942"}, "book-100", "XBT/USD"]
[270, {"b": [["11666.10000", "10.14221286", "1596666831.550756"]], "c": "1272110742"}, "book-100", "XBT/USD"]
[270, {"b": [["11648.90000", "0.00000000", "1596666831.603782"], ["11612.50000", "2.30777706", "1596666782.171350", "r"]], "c": "1272110742"}, "book-100", "XBT/USD"]
[270, {"b": [["11666.10000", "12.39221286", "1596666831.604116"]], "c": "1002546251"}, "book-100", "XBT/USD"]
[270, {"a": [["11679.20000", "0.85745244", "1596666831.633550"]], "c": "1002546251"}, "book-100", "XBT/USD"]
[270, {"a": [["11681.10000", "0.00000000", "1596666831.644655"], ["11718.00000", "0.17085000", "1596666826.000796", "r"]], "c": "1002546251"}, "book-100", "XBT/USD"]
[270, {"b": [["11666.10000", "10.14221286", "1596666831.688358"]], "c": "1272110742"}, "book-100", "XBT/USD"]
[270, {"a": [["11673.00000", "0.41352978", "1596666831.695499"]], "c": "2356090774"}, "book-100", "XBT/USD"]
[270, {"a": [["11684.30000", "1.33625900", "1596666831.713538"]], "c": "2356090774"}, "book-100", "XBT/USD"]
[270, {"a": [["11676.90000", "0.00000000", "1596666831.759324"], ["11718.00000", "0.17085000", "1596666826.000796", "r"]], "c": "2356090774"}, "book-100", "XBT/USD"]
[270, {"a": [["11681.00000", "0.04471474", "1596666831.819040"]], "c": "2356090774"}, "book-100", "XBT/USD"]
[270, {"b": [["11657.50000", "0.00000000", "1596666831.870260"], ["11612.30000", "7.00000000", "1596666617.080387", "r"]], "c": "2356090774"}, "book-100", "XBT/USD"]
[270, {"b": [["11665.40000", "0.00000000", "1596666831.902537"], ["11611.90000", "1.06000000", "1596666780.430510", "r"]], "c": "1064928464"}, "book-100", "XBT/USD"]
[270, {"a": [["11680.30000", "2.85734812", "1596666831.931078"]], "c": "1064928464"}, "book-100", "XBT/USD"]
[270, {"a": [["11683.70000", "0.00000000", "1596666831.949076"], ["11718.00000", "0.17085000", "1596666826.000796", "r"]], "c": "1064928464"}, "book-100", "XBT/USD"]
[270, {"b": [["11660.60000", "0.00000000", "1596666831.955631"], ["11611.70000", "0.37132924", "1596666797.216118", "r"]], "c": "1064928464"}, "book-100", "XBT/USD"]
[270, {"b": [["11654.30000", "0.00000000", "1596666831.962245"], ["11609.80000", "21.20000000", "1596666704.766154", "r"]], "c": "1064928464"}, "book-100", "XBT/USD"]
[270, {"a": [["11692.30000", "8.93900000", "1596666831.999204"]], "c": "1064928464"}, "book-100", "XBT/USD"]
[270, {"b": [["11628.30000", "0.00000000", "1596666832.003330"], ["11609.30000", "2.01627299", "1596666817.684177", "r"]], "c": "1064928464"}, "book-100", "XBT/USD"]
[270, {"b": [["11649.90000", "0.00000000", "1596666832.011783"], ["11607.70000", "8.40000000", "1596666777.775135", "r"]], "c": "1064928464"}, "book-100", "XBT/USD"]
[270, {"a": [["11680.50000", "2.95509893", "1596666832.021071"]], "c": "1064928464"}, "book-100", "XBT/USD"]
[270, {"a": [["11680.20000", "0.56486365", "1596666832.022282"]], "c": "1064928464"}, "book-100", "XBT/USD"]
[270, {"a": [["11673.00000", "0.00000000", "1596666832.031373"], ["11718.50000", "24.30000000", "1596666641.380470", "r"]], "c": "4173614544"}, "book-100", "XBT/USD"]
[270, {"b": [["11657.20000", "0.00000000", "1596666832.044983"], ["11604.10000", "1.51500000", "1596666763.121463", "r"]], "c": "4173614544"}, "book-100", "XBT/USD"]
[270, {"a": [["11718.00000", "0.00000000", "1596666832.171099"], ["11719.60000", "2.98021891", "1596666782.974175", "r"]], "c": "4173614544"}, "book-100", "XBT/USD"]
[270, {"a": [["11673.90000", "0.41352978", "1596666832.184493"]], "c": "1265767019"}, "book-100", "XBT/USD"]
[270, {"b": [["11665.90000", "0.64253888", "1596666832.203033"]], "c": "1400111644"}, "book-100", "XBT/USD"]
[270, {"a": [["11690.30000", "0.85667567", "1596666832.203251"]], "c": "1400111644"}, "book-100", "XBT/USD"]
[270, {"a": [["11677.30000", "0.64250675", "1596666832.241183"]], "c": "1400111644"}, "book-100", "XBT/USD"]
[270, {"a": [["11680.80000", "0.00000000", "1596666832.241379"], ["11717.80000", "1.99812614", "1596666759.535617", "r"]], "c": "1400111644"}, "book-100", "XBT/USD"]
[270, {"b": [["11654.50000", "0.00000000", "1596666832.241595"], ["11604.10000", "1.51500000", "1596666763.121463", "r"]], "c": "1400111644"}, "book-100", "XBT/USD"]
[270, {"b": [["11650.40000", "0.00000000", "1596666832.246935"], ["11602.60000", "1.48021868", "1596666784.125874", "r"]], "c": "1400111644"}, "book-100", "XBT/USD"]
[270, {"a": [["11676.70000", "0.09621094", "1596666832.290708"]], "c": "1400111644"}, "book-100", "XBT/USD"]
[270, {"b": [["11656.80000", "3.53794266", "1596666832.318228"]], "c": "1400111644"}, "book-100", "XBT/USD"]
[270, {"a": [["11681.40000", "0.11169904", "1596666832.340666"]], "c": "1400111644"}, "book-100", "XBT/USD"]
[270, {"a": [["11685.60000", "6.01756039", "1596666832.344190"]], "c": "1400111644"}, "book-100", "XBT/USD"]
[270, {"a": [["11680.50000", "2.93909928", "1596666832.352305"]], "c": "1400111644"}, "book-100", "XBT/USD"]
[270, {"a": [["11680.50000", "2.95876147", "1596666832.354664"]], "c": "1400111644"}, "book-100", "XBT/USD"]
[270, {"b": [["11653.20000", "0.00000000", "1596666832.396818"], ["11602.60000", "1.48021868", "1596666784.125874", "r"]], "c": "1400111644"}, "book-100", "XBT/USD"]
[270, {"b": [["11653.00000", "2.00876997", "1596666832.436104"]], "c": "1400111644"}, "book-100", "XBT/USD"]
[270, {"b": [["11635.60000", "2.01177390", "1596666832.580746"]], "c": "1400111644"}, "book-100", "XBT/USD"]
[270, {"b": [["11662.70000", "1.83875770", "1596666832.580821"]], "c": "1400111644"}, "book-100", "XBT/USD"]
[270, {"b": [["11652.80000", "1.00592026", "1596666832.585198"]], "c": "1400111644"}, "book-100", "XBT/USD"]
[270, {"b": [["11659.40000", "0.71159251", "1596666832.585351"]], "c": "1400111644"}, "book-100", "XBT/USD"]
[270, {"b": [["11657.00000", "1.52147804", "1596666832.627680"]], "c": "1400111644"}, "book-100", "XBT/USD"]
[270, {"b": [["11656.30000", "0.00000000", "1596666832.628621"], ["11607.70000", "8.40000000", "1596666777.775135", "r"]], "c": "1400111644"}, "book-100", "XBT/USD"]
[270, {"b": [["11664.00000", "1.00000000", "1596666832.679916"]], "c": "1400111644"}, "book-100", "XBT/USD"]
[270, {"b": [["11656.30000", "0.49783681", "1596666832.736352"]], "c": "1400111644"}, "book-100", "XBT/USD"]
[270, {"b": [["11655.80000", "0.00000000", "1596666832.751533"], ["11609.30000", "2.01627299", "1596666817.684177", "r"]], "c": "1400111644"}, "book-100", "XBT/USD"]
[270, {"b": [["11652.80000", "0.10500000", "1596666832.751699"]], "c": "1400111644"}, "book-100", "XBT/USD"]
[270, {"b": [["11655.80000", "0.34957555", "1596666832.756967"]], "c": "1400111644"}, "book-100", "XBT/USD"]
[270, {"b": [["11659.30000", "0.24962186", "1596666832.766074"]], "c": "1400111644"}, "book-100", "XBT/USD"]
[270, {"b": [["11663.90000", "0.00000000", "1596666832.804300"], ["11609.80000", "21.20000000", "1596666704.766154", "r"]], "c": "1400111644"}, "book-100", "XBT/USD"]
[270, {"a": [["11702.40000", "0.00000000", "1596666832.805537"], ["11714.80000", "1.99881632", "1596666809.038669", "r"]], "c": "1400111644"}, "book-100", "XBT/USD"]
[270, {"b": [["11654.70000", "0.00000000", "1596666832.917525"], ["11609.30000", "2.01627299", "1596666817.684177", "r"]], "c": "1400111644"}, "book-100", "XBT/USD"]
[270, {"b": [["11660.30000", "0.85711766", "1596666832.917792"]], "c": "1400111644"}, "book-100", "XBT/USD"]
[270, {"b": [["11661.30000", "0.30000000", "1596666832.977034"]], "c": "1400111644"}, "book-100", "XBT/USD"]
[270, {"b": [["11634.20000", "0.00000000", "1596666833.028201"], ["11607.70000", "8.40000000", "1596666777.775135", "r"]], "c": "1400111644"}, "book-100", "XBT/USD"]
[270, {"b": [["11659.40000", "0.00000000", "1596666833.034905"], ["11604.10000", "1.51500000", "1596666763.121463", "r"]], "c": "1400111644"}, "book-100", "XBT/USD"]
[270, {"b": [["11649.10000", "0.00000000", "1596666833.037365"], ["11602.60000", "1.48021868", "1596666784.125874", "r"]], "c": "1400111644"}, "book-100", "XBT/USD"]
[270, {"b": [["11666.10000", "10.22471286", "1596666833.044323"]], "c": "3028846359"}, "book-100", "XBT/USD"]
[270, {"a": [["11681.10000", "0.08250000", "1596666833.044933"]], "c": "3028846359"}, "book-100", "XBT/USD"]
[270, {"b": [["11659.20000", "0.90019215", "1596666833.066660"]], "c": "3028846359"}, "book-100", "XBT/USD"]
[270, {"b": [["11655.70000", "0.90046247", "1596666833.098762"]], "c": "3028846359"}, "book-100", "XBT/USD"]
[270, {"a": [["11673.80000", "0.00000000", "1596666833.199059"], ["11714.80000", "1.99881632", "1596666809.038669", "r"]], "c": "2206321311"}, "book-100", "XBT/USD"]
[270, {"a": [["11685.70000", "0.00000000", "1596666833.273871"], ["11715.30000", "6.10000000", "1596666635.445451", "r"]], "c": "2206321311"}, "book-100", "XBT/USD"]
[270, {"a": [["11681.40000", "0.00000000", "1596666833.277940"], ["11717.80000", "1.99812614", "1596666759.535617", "r"]], "c": "2206321311"}, "book-100", "XBT/USD"]
[270, {"a": [["11673.80000", "0.25826848", "1596666833.301905"]], "c": "3110910259"}, "book-100", "XBT/USD"]
[270, {"b": [["11640.90000", "1.96862341", "1596666833.326570"]], "c": "3110910259"}, "book-100", "XBT/USD"]
[270, {"b": [["11652.50000", "1.79712369", "1596666833.331650"]], "c": "3110910259"}, "book-100", "XBT/USD"]
[270, {"b": [["11660.60000", "0.71157324", "1596666833.359760"]], "c": "3110910259"}, "book-100", "XBT/USD"]
[270, {"a": [["11683.60000", "0.11169838", "1596666833.543090"]], "c": "3110910259"}, "book-100", "XBT/USD"]
[270, {"b": [["11613.70000", "0.01285771", "1596666833.590378"]], "c": "3110910259"}, "book-100", "XBT/USD"]
[270, {"b": [["11653.10000", "0.00434561", "1596666833.590657"]], "c": "3110910259"}, "book-100", "XBT/USD"]
[270, {"a": [["11689.90000", "0.10438186", "1596666833.591146"]], "c": "3110910259"}, "book-100", "XBT/USD"]
[270, {"a": [["11689.40000", "1.41964018", "1596666833.607652"]], "c": "3110910259"}, "book-100", "XBT/USD"]
[270, {"b": [["11653.30000", "0.00000000", "1596666834.137453"], ["11611.90000", "1.06000000", "1596666780.430510", "r"]], "c": "3110910259"}, "book-100", "XBT/USD"]
[270, {"b": [["11656.30000", "0.50234603", "1596666834.229224"]], "c": "3110910259"}, "book-100", "XBT/USD"]
[270, {"a": [["11676.50000", "1.70200000", "1596666834.270178"]], "c": "3110910259"}, "book-100", "XBT/USD"]
[270, {"b": [["11651.90000", "0.00000000", "1596666834.308470"], ["11611.70000", "0.37132924", "1596666797.216118", "r"]], "c": "3110910259"}, "book-100", "XBT/USD"]
[270, {"b": [["11618.30000", "0.00000000", "1596666834.462083"], ["11609.80000", "21.20000000", "1596666704.766154", "r"]], "c": "3110910259"}, "book-100", "XBT/USD"]
[270, {"b": [["11618.80000", "0.74859482", "1596666834.463427"]], "c": "3110910259"}, "book-100", "XBT/USD"]
[270, {"a": [["11687.00000", "0.00000000", "1596666834.464249"], ["11711.50000", "1.99898326", "1596666797.632161", "r"]], "c": "3110910259"}, "book-100", "XBT/USD"]
[270, {"a": [["11687.30000", "0.74859482", "1596666834.475507"]], "c": "3110910259"}, "book-100", "XBT/USD"]
[270, {"b": [["11655.70000", "0.94517635", "1596666834.504116"]], "c": "3110910259"}, "book-100", "XBT/USD"]
[270, {"b": [["11666.10000", "10.22740519", "1596666834.576080"]], "c": "2495791980"}, "book-100", "XBT/USD"]
[270, {"b": [["11651.30000", "0.00000000", "1596666834.778048"], ["11609.80000", "21.20000000", "1596666704.766154", "r"]], "c": "2495791980"}, "book-100", "XBT/USD"]
[270, {"b": [["11655.20000", "0.88700000", "1596666834.816462"]], "c": "2495791980"}, "book-100", "XBT/USD"]
[270, {"b": [["11651.60000", "0.00000000", "1596666834.837144"], ["11609.80000", "21.20000000", "1596666704.766154", "r"]], "c": "2495791980"}, "book-100", "XBT/USD"]
[270, {"a": [["11677.30000", "0.00000000", "1596666834.870930"], ["11711.50000", "1.99898326", "1596666797.632161", "r"]], "c": "2495791980"}, "book-100", "XBT/USD"]
[270, {"b": [["11653.40000", "7.09377209", "1596666834.895086"]], "c": "2495791980"}, "book-100", "XBT/USD"]
[270, {"b": [["11653.00000", "5.21548702", "1596666834.921954"]], "c": "2495791980"}, "book-100", "XBT/USD"]
[270, {"b": [["11646.00000", "0.00000000", "1596666834.939462"], ["11609.80000", "21.20000000", "1596666704.766154", "r"]], "c": "2495791980"}, "book-100", "XBT/USD"]
[270, {"b": [["11651.30000", "1.00890000", "1596666834.942281"]], "c": "2495791980"}, "book-100", "XBT/USD"]
[270, {"b": [["11666.10000", "9.97740519", "1596666834.949867"]], "c": "3413459580"}, "book-100", "XBT/USD"]
[270, {"b": [["11655.10000", "0.13414235", "1596666834.973704"]], "c": "3413459580"}, "book-100", "XBT/USD"]
[270, {"a": [["11673.80000", "0.00000000", "1596666834.976536"], ["11714.80000", "1.99881632", "1596666809.038669", "r"]], "c": "2471960605"}, "book-100", "XBT/USD"]
[270, {"a": [["11674.40000", "0.25825454", "1596666834.979560"]], "c": "2879259170"}, "book-100", "XBT/USD"]
[270, {"a": [["11696.60000", "0.00000000", "1596666834.982984"], ["11714.80000", "1.99881632", "1596666809.038669", "r"]], "c": "2879259170"}, "book-100", "XBT/USD"]
[270, {"a": [["11681.20000", "0.02573600", "1596666835.013165"]], "c": "2879259170"}, "book-100", "XBT/USD"]
[270, {"a": [["11686.50000", "0.97450000", "1596666835.014621"]], "c": "2879259170"}, "book-100", "XBT/USD"]
[270, {"a": [["11674.30000", "0.64247060", "1596666835.039015"]], "c": "1944374651"}, "book-100", "XBT/USD"]
[270, {"a": [["11684.90000", "0.00000000", "1596666835.074594"], ["11711.50000", "1.99898326", "1596666797.632161", "r"]], "c": "1944374651"}, "book-100", "XBT/USD"]
[270, {"b": [["11666.10000", "10.22740519", "1596666835.107063"]], "c": "169789248"}, "book-100", "XBT/USD"]
[270, {"a": [["11695.40000", "2.29920000", "1596666835.136695"]], "c": "169789248"}, "book-100", "XBT/USD"]
[270, {"a": [["11676.50000", "0.00000000", "1596666835.146774"], ["11711.50000", "1.99898326", "1596666797.632161", "r"]], "c": "169789248"}, "book-100", "XBT/USD"]
[270, {"b": [["11666.10000", "9.82740519", "1596666835.189317"]], "c": "2809690690"}, "book-100", "XBT/USD"]
[270, {"a": [["11680.20000", "0.00000000", "1596666835.282726"], ["11714.80000", "1.99881632", "1596666809.038669", "r"]], "c": "2809690690"}, "book-100", "XBT/USD"]
[270, {"b": [["11666.10000", "8.82740519", "1596666835.327448"]], "c": "1474440942"}, "book-100", "XBT/USD"]
[270, {"a": [["11673.90000", "0.00000000", "1596666835.356908"], ["11715.30000", "6.10000000", "1596666635.445451", "r"]], "c": "3174848078"}, "book-100", "XBT/USD"]
[270, {"a": [["11676.70000", "0.00000000", "1596666835.362973"], ["11717.80000", "1.99812614", "1596666759.535617", "r"]], "c": "3174848078"}, "book-100", "XBT/USD"]
[270, {"b": [["11666.10000", "8.78490519", "1596666835.379497"]], "c": "943141557"}, "book-100", "XBT/USD"]
[270, {"a": [["11674.50000", "0.00000000", "1596666835.381969"], ["11718.50000", "24.30000000", "1596666641.380470", "r"]], "c": "3665527606"}, "book-100", "XBT/USD"]
[270, {"b": [["11665.30000", "0.00000000", "1596666835.400991"], ["11611.70000", "0.37132924", "1596666797.216118", "r"]], "c": "3053706856"}, "book-100", "XBT/USD"]
[270, {"b": [["11618.80000", "0.00000000", "1596666835.467006"], ["11609.80000", "21.20000000", "1596666704.766154", "r"]], "c": "3053706856"}, "book-100", "XBT/USD"]
[270, {"a": [["11676.00000", "0.00000000", "1596666835.493571"], ["11719.60000", "2.98021891", "1596666782.974175", "r"]], "c": "3053706856"}, "book-100", "XBT/USD"]
[270, {"a": [["11690.30000", "0.00000000", "1596666835.493754"], ["11719.70000", "3.50602221", "1596666789.365232", "r"]], "c": "3053706856"}, "book-100", "XBT/USD"]
[270, {"a": [["11673.10000", "0.41352978", "1596666835.503640"]], "c": "2335440101"}, "book-100", "XBT/USD"]
[270, {"b": [["11666.10000", "8.82740519", "1596666835.598790"]], "c": "916776153"}, "book-100", "XBT/USD"]
[270, {"a": [["11682.50000", "0.88000000", "1596666835.861443"]], "c": "916776153"}, "book-100", "XBT/USD"]
[270, {"a": [["11675.30000", "0.04250000", "1596666836.127760"]], "c": "916776153"}, "book-100", "XBT/USD"]
[270, {"a": [["11692.10000", "1.11817209", "1596666836.480027"]], "c": "916776153"}, "book-100", "XBT/USD"]
[270, {"b": [["11628.00000", "0.17085000", "1596666836.683393"]], "c": "916776153"}, "book-100", "XBT/USD"]
[270, {"a": [["11683.60000", "0.00000000", "1596666836.737518"], ["11718.50000", "24.30000000", "1596666641.380470", "r"]], "c": "916776153"}, "book-100", "XBT/USD"]
[270, {"a": [["11718.00000", "0.17085000", "1596666836.842357"]], "c": "916776153"}, "book-100", "XBT/USD"]
[270, {"b": [["11653.10000", "0.00000000", "1596666836.882194"], ["11609.80000", "21.20000000", "1596666704.766154", "r"]], "c": "916776153"}, "book-100", "XBT/USD"]
[270, {"a": [["11676.90000", "0.09621094", "1596666836.902742"]], "c": "916776153"}, "book-100", "XBT/USD"]
[270, {"a": [["11689.40000", "0.00000000", "1596666836.921223"], ["11718.00000", "0.17085000", "1596666836.842357", "r"]], "c": "916776153"}, "book-100", "XBT/USD"]
[270, {"b": [["11665.50000", "0.09621094", "1596666836.942345"]], "c": "2071475172"}, "book-100", "XBT/USD"]
[270, {"a": [["11674.40000", "0.00000000", "1596666837.058965"], ["11718.50000", "24.30000000", "1596666641.380470", "r"]], "c": "3492822674"}, "book-100", "XBT/USD"]
[270, {"b": [["11653.10000", "0.00433181", "1596666837.067726"]], "c": "3492822674"}, "book-100", "XBT/USD"]
[270, {"a": [["11692.10000", "0.51030670", "1596666837.092709"]], "c": "3492822674"}, "book-100", "XBT/USD"]
[270, {"a": [["11674.00000", "0.25826478", "1596666837.156565"]], "c": "3241470469"}, "book-100", "XBT/USD"]
[270, {"a": [["11704.80000", "0.00000000", "1596666837.164463"], ["11718.50000", "24.30000000", "1596666641.380470", "r"]], "c": "3241470469"}, "book-100", "XBT/USD"]
[270, {"a": [["11680.20000", "0.46398388", "1596666837.276640"]], "c": "3241470469"}, "book-100", "XBT/USD"]
[270, {"a": [["11682.50000", "0.99086150", "1596666837.376295"]], "c": "3241470469"}, "book-100", "XBT/USD"]
[271, [["11666.10000", "0.50000000", "1596666837.393141", "s", "m", ""], ["11666.10000", "0.42800000", "1596666837.395468", "s", "m", ""], ["11666.10000", "0.58813320", "1596666837.397933", "s", "m", ""], ["11666.10000", "0.08571808", "1596666837.399781", "s", "m", ""], ["11666.10000", "0.35000000", "1596666837.401304", "s", "m", ""], ["11666.10000", "0.64267510", "1596666837.403170", "s", "m", ""], ["11666.10000", "2.61223252", "1596666837.404900", "s", "m", ""]], "trade", "XBT/USD"]
[270, {"b": [["11666.10000", "8.32740519", "1596666837.393141"], ["11666.10000", "7.89940519", "1596666837.395468"], ["11666.10000", "7.31127199", "1596666837.397933"], ["11666.10000", "7.22555391", "1596666837.399781"], ["11666.10000", "6.87555391", "1596666837.401304"], ["11666.10000", "6.23287881", "1596666837.403170"], ["11666.10000", "3.62064629", "1596666837.404900"]], "c": "3799157499"}, "book-100", "XBT/USD"]
[270, {"b": [["11666.10000", "1.95587881", "1596666837.502129"]], "c": "631789595"}, "book-100", "XBT/USD"]
[270, {"b": [["11656.30000", "0.49783681", "1596666837.507053"]], "c": "631789595"}, "book-100", "XBT/USD"]
[270, {"b": [["11666.10000", "6.23087881", "1596666837.514129"]], "c": "474231345"}, "book-100", "XBT/USD"]
[270, {"b": [["11636.00000", "0.00000000", "1596666837.560536"], ["11611.70000", "0.37132924", "1596666797.216118", "r"]], "c": "474231345"}, "book-100", "XBT/USD"]
[270, {"b": [["11643.50000", "0.00000000", "1596666837.565764"], ["11609.80000", "21.20000000", "1596666704.766154", "r"]], "c": "474231345"}, "book-100", "XBT/USD"]
[270, {"b": [["11635.80000", "0.00000000", "1596666837.576867"], ["11609.30000", "2.01627299", "1596666817.684177", "r"]], "c": "474231345"}, "book-100", "XBT/USD"]
[270, {"a": [["11682.70000", "0.00000000", "1596666837.577726"], ["11718.50000", "24.30000000", "1596666641.380470", "r"]], "c": "474231345"}, "book-100", "XBT/USD"]
[270, {"b": [["11665.70000", "1.00000000", "1596666837.583640"]], "c": "2245045368"}, "book-100", "XBT/USD"]
[270, {"b": [["11636.90000", "0.00000000", "1596666837.587208"], ["11609.30000", "2.01627299", "1596666817.684177", "r"]], "c": "2245045368"}, "book-100", "XBT/USD"]
[270, {"b": [["11657.00000", "0.09800000", "1596666837.588157"]], "c": "2245045368"}, "book-100", "XBT/USD"]
[270, {"a": [["11686.00000", "0.00000000", "1596666837.595366"], ["11719.60000", "2.98021891", "1596666782.974175", "r"]], "c": "2245045368"}, "book-100", "XBT/USD"]
[270, {"b": [["11666.10000", "6.73087881", "1596666837.595524"]], "c": "29468390"}, "book-100", "XBT/USD"]
[270, {"b": [["11647.80000", "0.00000000", "1596666837.602887"], ["11607.70000", "8.40000000", "1596666777.775135", "r"]], "c": "29468390"}, "book-100", "XBT/USD"]
[270, {"b": [["11639.60000", "0.00000000", "1596666837.607974"], ["11604.10000", "1.51500000", "1596666763.121463", "r"]], "c": "29468390"}, "book-100", "XBT/USD"]
[270, {"a": [["11687.30000", "0.00000000", "1596666837.630441"], ["11719.70000", "3.50602221", "1596666789.365232", "r"]], "c": "29468390"}, "book-100", "XBT/USD"]
[270, {"a": [["11687.90000", "0.00000000", "1596666837.682268"], ["11721.00000", "0.97885000", "1596666831.502501", "r"]], "c": "29468390"}, "book-100", "XBT/USD"]
[270, {"b": [["11648.50000", "0.00000000", "1596666837.687554"], ["11602.60000", "1.48021868", "1596666784.125874", "r"]], "c": "29468390"}, "book-100", "XBT/USD"]
[270, {"b": [["11666.10000", "6.48087881", "1596666837.731202"]], "c": "3678286756"}, "book-100", "XBT/USD"]
[270, {"b": [["11644.90000", "0.89974995", "1596666837.733208"]], "c": "3678286756"}, "book-100", "XBT/USD"]
[270, {"b": [["11641.90000", "1.49538379", "1596666837.874122"]], "c": "3678286756"}, "book-100", "XBT/USD"]
[270, {"b": [["11665.10000", "0.25000000", "1596666837.916814"]], "c": "1981391131"}, "book-100", "XBT/USD"]
[270, {"a": [["11673.10000", "0.00000000", "1596666837.941099"], ["11721.70000", "2.47549182", "1596666772.357495", "r"]], "c": "2975330562"}, "book-100", "XBT/USD"]
[270, {"b": [["11648.10000", "2.00936632", "1596666838.003266"]], "c": "2975330562"}, "book-100", "XBT/USD"]
[270, {"a": [["11673.60000", "0.64251320", "1596666838.052731"]], "c": "2469786155"}, "book-100", "XBT/USD"]
[270, {"a": [["11682.50000", "0.88000000", "1596666838.078267"]], "c": "2469786155"}, "book-100", "XBT/USD"]
[270, {"b": [["11655.30000", "0.04218830", "1596666838.084580"]], "c": "2469786155"}, "book-100", "XBT/USD"]
[270, {"b": [["11651.80000", "0.90072660", "1596666838.088742"]], "c": "2469786155"}, "book-100", "XBT/USD"]
[270, {"b": [["11666.10000", "6.56659689", "1596666838.089591"]], "c": "1451887810"}, "book-100", "XBT/USD"]
[270, {"a": [["11677.00000", "0.85667355", "1596666838.095320"]], "c": "1451887810"}, "book-100", "XBT/USD"]
[270, {"b": [["11653.10000", "0.00000000", "1596666838.131718"], ["11611.70000", "0.37132924", "1596666797.216118", "r"]], "c": "1451887810"}, "book-100", "XBT/USD"]
[270, {"a": [["11692.60000", "3.52737780", "1596666838.170631"]], "c": "1451887810"}, "book-100", "XBT/USD"]
[270, {"b": [["11651.60000", "3.53979004", "1596666838.174883"]], "c": "1451887810"}, "book-100", "XBT/USD"]
[270, {"b": [["11655.30000", "0.00000000", "1596666838.212838"], ["11611.70000", "0.37132924", "1596666797.216118", "r"]], "c": "1451887810"}, "book-100", "XBT/USD"]
[270, {"a": [["11672.30000", "0.41352978", "1596666838.219597"]], "c": "527103589"}, "book-100", "XBT/USD"]
[270, {"b": [["11656.30000", "0.54002149", "1596666838.221922"]], "c": "527103589"}, "book-100", "XBT/USD"]
[270, {"b": [["11666.10000", "7.07661473", "1596666838.338199"]], "c": "1530859152"}, "book-100", "XBT/USD"]
[270, {"a": [["11673.60000", "0.00000000", "1596666838.366456"], ["11719.60000", "2.98021891", "1596666782.974175", "r"]], "c": "893580070"}, "book-100", "XBT/USD"]
[270, {"a": [["11684.40000", "0.11086106", "1596666838.452494"]], "c": "893580070"}, "book-100", "XBT/USD"]
[270, {"b": [["11659.30000", "1.67304223", "1596666838.601143"]], "c": "893580070"}, "book-100", "XBT/USD"]
[270, {"a": [["11690.30000", "1.41964578", "1596666838.605679"]], "c": "893580070"}, "book-100", "XBT/USD"]
[270, {"a": [["11684.60000", "0.33817579", "1596666838.645603"]], "c": "893580070"}, "book-100", "XBT/USD"]
[270, {"a": [["11687.90000", "0.70996865", "1596666838.651857"]], "c": "893580070"}, "book-100", "XBT/USD"]
[270, {"a": [["11686.30000", "0.00300000", "1596666838.856195"]], "c": "893580070"}, "book-100", "XBT/USD"]
[270, {"b": [["11660.60000", "0.00000000", "1596666839.355810"], ["11609.80000", "21.20000000", "1596666704.766154", "r"]], "c": "893580070"}, "book-100", "XBT/USD"]
[270, {"b": [["11661.90000", "0.71155151", "1596666839.735558"]], "c": "893580070"}, "book-100", "XBT/USD"]
[270, {"a": [["11668.80000", "0.00000000", "1596666839.791866"], ["11715.30000", "6.10000000", "1596666635.445451", "r"]], "c": "1309047365"}, "book-100", "XBT/USD"]
[270, {"b": [["11642.10000", "0.00000000", "1596666839.791972"], ["11609.80000", "21.20000000", "1596666704.766154", "r"]], "c": "1309047365"}, "book-100", "XBT/USD"]
[270, {"a": [["11675.40000", "2.34262106", "1596666839.837213"]], "c": "1309047365"}, "book-100", "XBT/USD"]
[270, {"b": [["11652.10000", "0.03100000", "1596666839.845758"]], "c": "1309047365"}, "book-100", "XBT/USD"]
[270, {"a": [["11678.60000", "0.01000000", "1596666839.846531"]], "c": "1309047365"}, "book-100", "XBT/USD"]
[270, {"b": [["11662.70000", "1.50000000", "1596666839.856913"]], "c": "1309047365"}, "book-100", "XBT/USD"]
[270, {"a": [["11678.50000", "0.00000000", "1596666839.970147"], ["11715.30000", "6.10000000", "1596666635.445451", "r"]], "c": "1309047365"}, "book-100", "XBT/USD"]
[270, {"b": [["11662.70000", "0.00000000", "1596666839.971875"], ["11609.80000", "21.20000000", "1596666704.766154", "r"]], "c": "1309047365"}, "book-100", "XBT/USD"]
[270, {"b": [["11663.70000", "4.31320005", "1596666840.152087"]], "c": "1309047365"}, "book-100", "XBT/USD"]
[270, {"a": [["11673.60000", "0.64247613", "1596666840.199677"]], "c": "1147645230"}, "book-100", "XBT/USD"]
[270, {"b": [["11665.30000", "0.33873529", "1596666840.200529"]], "c": "2046776184"}, "book-100", "XBT/USD"]
[270, {"b": [["11666.10000", "7.71928983", "1596666840.203412"]], "c": "3272466622"}, "book-100", "XBT/USD"]
[270, {"a": [["11678.30000", "1.50000000", "1596666840.243689"]], "c": "3272466622"}, "book-100", "XBT/USD"]
[270, {"a": [["11679.20000", "1.65594244", "1596666840.458976"]], "c": "3272466622"}, "book-100", "XBT/USD"]
[270, {"a": [["11674.00000", "0.00000000", "1596666840.721551"], ["11714.80000", "1.99881632", "1596666809.038669", "r"]], "c": "2481797624"}, "book-100", "XBT/USD"]
[270, {"b": [["11665.10000", "0.00000000", "1596666840.787112"], ["11609.80000", "21.20000000", "1596666704.766154", "r"]], "c": "3056600746"}, "book-100", "XBT/USD"]
[270, {"a": [["11672.30000", "0.00000000", "1596666840.794181"], ["11715.30000", "6.10000000", "1596666635.445451", "r"]], "c": "2483146222"}, "book-100", "XBT/USD"]
[270, {"a": [["11680.50000", "2.93909928", "1596666840.900931"]], "c": "2483146222"}, "book-100", "XBT/USD"]
[270, {"a": [["11680.40000", "0.00366258", "1596666840.902630"]], "c": "2483146222"}, "book-100", "XBT/USD"]
[270, {"b": [["11663.40000", "0.25000000", "1596666840.931723"]], "c": "2483146222"}, "book-100", "XBT/USD"]
[270, {"a": [["11670.70000", "0.41352978", "1596666840.935334"]], "c": "46601571"}, "book-100", "XBT/USD"]
[270, {"b": [["11642.40000", "7.10107281", "1596666840.964863"]], "c": "46601571"}, "book-100", "XBT/USD"]
[270, {"b": [["11642.10000", "6.41998798", "1596666840.975064"]], "c": "46601571"}, "book-100", "XBT/USD"]
[270, {"a": [["11675.40000", "1.70000000", "1596666841.096141"]], "c": "46601571"}, "book-100", "XBT/USD"]
[270, {"a": [["11674.20000", "0.00000000", "1596666841.109481"], ["11714.80000", "1.99881632", "1596666809.038669", "r"]], "c": "2877706123"}, "book-100", "XBT/USD"]
[270, {"a": [["11673.50000", "0.25827019", "1596666841.171380"]], "c": "2097923239"}, "book-100", "XBT/USD"]
[270, {"a": [["11688.10000", "0.74860717", "1596666841.175257"]], "c": "2097923239"}, "book-100", "XBT/USD"]
[270, {"a": [["11677.10000", "2.03212498", "1596666841.175613"]], "c": "2097923239"}, "book-100", "XBT/USD"]
[270, {"b": [["11619.70000", "0.74860717", "1596666841.177463"]], "c": "2097923239"}, "book-100", "XBT/USD"]
[270, {"a": [["11680.40000", "0.00000000", "1596666841.240040"], ["11711.10000", "0.75800000", "1596666806.349295", "r"]], "c": "2097923239"}, "book-100", "XBT/USD"]
[270, {"b": [["11612.50000", "0.00857706", "1596666841.240139"]], "c": "2097923239"}, "book-100", "XBT/USD"]
[270, {"a": [["11680.50000", "2.94276182", "1596666841.241198"]], "c": "2097923239"}, "book-100", "XBT/USD"]
[270, {"b": [["11664.80000", "1.15677667", "1596666841.250782"]], "c": "728035837"}, "book-100", "XBT/USD"]
[270, {"b": [["11628.00000", "0.00000000", "1596666841.252650"], ["11612.30000", "7.00000000", "1596666617.080387", "r"]], "c": "728035837"}, "book-100", "XBT/USD"]
[270, {"b": [["11663.40000", "0.00000000", "1596666841.261742"], ["11611.90000", "1.06000000", "1596666780.430510", "r"]], "c": "728035837"}, "book-100", "XBT/USD"]
[270, {"b": [["11660.50000", "3.19753716", "1596666841.279116"]], "c": "728035837"}, "book-100", "XBT/USD"]
[270, {"a": [["11678.60000", "0.00000000", "1596666841.292452"], ["11711.50000", "1.99898326", "1596666797.632161", "r"]], "c": "728035837"}, "book-100", "XBT/USD"]
[270, {"b": [["11628.00000", "2.29920000", "1596666841.320252"]], "c": "728035837"}, "book-100", "XBT/USD"]
[270, {"a": [["11680.50000", "0.00366254", "1596666841.333465"]], "c": "728035837"}, "book-100", "XBT/USD"]
[270, {"a": [["11678.10000", "0.01000000", "1596666841.345317"]], "c": "728035837"}, "book-100", "XBT/USD"]
[270, {"a": [["11673.10000", "0.82354905", "1596666841.386751"]], "c": "2548310555"}, "book-100", "XBT/USD"]
[270, {"b": [["11664.10000", "0.25000000", "1596666841.406325"]], "c": "2548310555"}, "book-100", "XBT/USD"]
[270, {"b": [["11663.70000", "1.50000000", "1596666841.413347"]], "c": "2548310555"}, "book-100", "XBT/USD"]
[270, {"b": [["11613.70000", "0.00000000", "1596666841.516976"], ["11612.50000", "0.00857706", "1596666841.240139", "r"]], "c": "2548310555"}, "book-100", "XBT/USD"]
[270, {"a": [["11680.90000", "0.04278687", "1596666841.531202"]], "c": "2548310555"}, "book-100", "XBT/USD"]
[270, {"a": [["11680.50000", "0.00000000", "1596666841.569731"], ["11710.70000", "3.52183532", "1596666711.393054", "r"]], "c": "2548310555"}, "book-100", "XBT/USD"]
[270, {"b": [["11655.70000", "0.90046247", "1596666841.642050"]], "c": "2548310555"}, "book-100", "XBT/USD"]
[270, {"a": [["11689.90000", "0.10000000", "1596666841.677994"]], "c": "2548310555"}, "book-100", "XBT/USD"]
[270, {"a": [["11670.70000", "0.00000000", "1596666841.798014"], ["11711.10000", "0.75800000", "1596666806.349295", "r"]], "c": "70809796"}, "book-100", "XBT/USD"]
[270, {"b": [["11657.70000", "0.04471763", "1596666841.865600"]], "c": "70809796"}, "book-100", "XBT/USD"]
[270, {"a": [["11671.10000", "0.41352978", "1596666841.967833"]], "c": "3322362222"}, "book-100", "XBT/USD"]
[270, {"b": [["11655.10000", "0.00000000", "1596666842.069526"], ["11612.50000", "0.00857706", "1596666841.240139", "r"]], "c": "3322362222"}, "book-100", "XBT/USD"]
[270, {"a": [["11686.90000", "0.00000000", "1596666842.110304"], ["11711.10000", "0.75800000", "1596666806.349295", "r"]], "c": "3322362222"}, "book-100", "XBT/USD"]
[270, {"a": [["11674.30000", "0.00000000", "1596666842.110649"], ["11711.50000", "1.99898326", "1596666797.632161", "r"]], "c": "3102047017"}, "book-100", "XBT/USD"]
[270, {"b": [["11616.00000", "0.17085000", "1596666842.228991"]], "c": "3102047017"}, "book-100", "XBT/USD"]
[270, {"b": [["11657.10000", "0.13415231", "1596666842.269215"]], "c": "3102047017"}, "book-100", "XBT/USD"]
[270, {"a": [["11674.90000", "0.09621094", "1596666843.060192"]], "c": "3102047017"}, "book-100", "XBT/USD"]
[270, {"a": [["11671.70000", "1.21486653", "1596666843.102333"]], "c": "1876481992"}, "book-100", "XBT/USD"]
[270, {"a": [["11672.60000", "0.64252488", "1596666843.103660"]], "c": "3066358391"}, "book-100", "XBT/USD"]
[270, {"a": [["11676.50000", "0.85672996", "1596666843.103764"]], "c": "3066358391"}, "book-100", "XBT/USD"]
[270, {"b": [["11666.10000", "9.42628983", "1596666843.142766"]], "c": "481162604"}, "book-100", "XBT/USD"]
[270, {"b": [["11625.00000", "0.25000000", "1596666843.196410"]], "c": "481162604"}, "book-100", "XBT/USD"]
[270, {"a": [["11673.50000", "0.00000000", "1596666843.292497"], ["11710.70000", "3.52183532", "1596666711.393054", "r"]], "c": "3900876549"}, "book-100", "XBT/USD"]
[270, {"b": [["11664.00000", "0.00000000", "1596666843.345607"], ["11613.00000", "0.17085000", "1596666803.224745", "r"]], "c": "3900876549"}, "book-100", "XBT/USD"]
[270, {"b": [["11661.60000", "2.00000000", "1596666843.367825"]], "c": "3900876549"}, "book-100", "XBT/USD"]
[270, {"a": [["11673.50000", "0.25827927", "1596666843.389681"]], "c": "3716095525"}, "book-100", "XBT/USD"]
[270, {"b": [["11652.90000", "0.43800000", "1596666843.415527"]], "c": "3716095525"}, "book-100", "XBT/USD"]
[270, {"a": [["11676.90000", "0.00000000", "1596666843.547340"], ["11710.70000", "3.52183532", "1596666711.393054", "r"]], "c": "3716095525"}, "book-100", "XBT/USD"]
[270, {"b": [["11652.90000", "1.43800000", "1596666843.554382"]], "c": "3716095525"}, "book-100", "XBT/USD"]
[270, {"b": [["11665.70000", "0.00000000", "1596666843.867730"], ["11613.00000", "0.17085000", "1596666803.224745", "r"]], "c": "2544980011"}, "book-100", "XBT/USD"]
[270, {"a": [["11699.40000", "0.75900000", "1596666844.294984"]], "c": "2544980011"}, "book-100", "XBT/USD"]
[270, {"a": [["11692.30000", "8.50000000", "1596666844.698621"]], "c": "2544980011"}, "book-100", "XBT/USD"]
[270, {"a": [["11680.50000", "0.43900000", "1596666844.753700"]], "c": "2544980011"}, "book-100", "XBT/USD"]
[270, {"a": [["11687.90000", "0.00000000", "1596666844.892198"], ["11710.60000", "2.80039129", "1596666770.582883", "r"]], "c": "2544980011"}, "book-100", "XBT/USD"]
[270, {"b": [["11650.40000", "0.00443524", "1596666844.892994"]], "c": "2544980011"}, "book-100", "XBT/USD"]
[270, {"a": [["11684.60000", "0.00000000", "1596666844.893434"], ["11710.70000", "3.52183532", "1596666711.393054", "r"]], "c": "2544980011"}, "book-100", "XBT/USD"]
[270, {"a": [["11684.40000", "0.00000000", "1596666845.042691"], ["11711.10000", "0.75800000", "1596666806.349295", "r"]], "c": "2544980011"}, "book-100", "XBT/USD"]
[270, {"b": [["11664.90000", "0.00000000", "1596666845.108545"], ["11613.00000", "0.17085000", "1596666803.224745", "r"]], "c": "3515018037"}, "book-100", "XBT/USD"]
[270, {"a": [["11684.50000", "0.00000000", "1596666845.128356"], ["11711.50000", "1.99898326", "1596666797.632161", "r"]], "c": "3515018037"}, "book-100", "XBT/USD"]
[270, {"a": [["11674.50000", "0.85678760", "1596666845.183367"]], "c": "3515018037"}, "book-100", "XBT/USD"]
[270, {"a": [["11685.40000", "0.71006071", "1596666845.249566"]], "c": "3515018037"}, "book-100", "XBT/USD"]
[270, {"a": [["11682.00000", "0.11086347", "1596666845.353247"]], "c": "3515018037"}, "book-100", "XBT/USD"]
[270, {"a": [["11682.10000", "0.33821966", "1596666845.360909"]], "c": "3515018037"}, "book-100", "XBT/USD"]
[270, {"a": [["11687.10000", "0.74861583", "1596666845.412567"]], "c": "3515018037"}, "book-100", "XBT/USD"]
[270, {"a": [["11704.60000", "4.55577516", "1596666845.416734"]], "c": "3515018037"}, "book-100", "XBT/USD"]
[270, {"a": [["11688.10000", "0.00000000", "1596666845.417372"], ["11710.40000", "1.16811308", "1596666772.597033", "r"]], "c": "3515018037"}, "book-100", "XBT/USD"]
[270, {"a": [["11688.00000", "0.00438186", "1596666845.456208"]], "c": "3515018037"}, "book-100", "XBT/USD"]
[270, {"a": [["11690.30000", "0.00000000", "1596666845.456323"], ["11710.40000", "1.16811308", "1596666772.597033", "r"]], "c": "3515018037"}, "book-100", "XBT/USD"]
[270, {"b": [["11620.60000", "0.74861583", "1596666845.456952"]], "c": "3515018037"}, "book-100", "XBT/USD"]
[270, {"a": [["11673.50000", "0.00000000", "1596666845.467622"], ["11710.60000", "2.80039129", "1596666770.582883", "r"]], "c": "772016586"}, "book-100", "XBT/USD"]
[270, {"a": [["11692.60000", "0.00000000", "1596666845.474710"], ["11710.70000", "3.52183532", "1596666711.393054", "r"]], "c": "772016586"}, "book-100", "XBT/USD"]
[270, {"b": [["11619.70000", "0.00000000", "1596666845.478893"], ["11613.00000", "0.17085000", "1596666803.224745", "r"]], "c": "772016586"}, "book-100", "XBT/USD"]
[270, {"a": [["11673.00000", "0.25828008", "1596666845.564174"]], "c": "2836711723"}, "book-100", "XBT/USD"]
[270, {"b": [["11630.20000", "0.00000000", "1596666845.643709"], ["11612.50000", "0.00857706", "1596666841.240139", "r"]], "c": "2836711723"}, "book-100", "XBT/USD"]
[270, {"a": [["11689.20000", "3.52870627", "1596666845.720243"]], "c": "2836711723"}, "book-100", "XBT/USD"]
[270, {"b": [["11630.20000", "6.62344344", "1596666845.725247"]], "c": "2836711723"}, "book-100", "XBT/USD"]
[270, {"a": [["11680.90000", "0.00000000", "1596666845.742348"], ["11710.60000", "2.80039129", "1596666770.582883", "r"]], "c": "2836711723"}, "book-100", "XBT/USD"]
[270, {"a": [["11672.40000", "0.01027431", "1596666845.743941"]], "c": "3749205255"}, "book-100", "XBT/USD"]
[270, {"b": [["11650.40000", "0.00000000", "1596666845.792863"], ["11612.50000", "0.00857706", "1596666841.240139", "r"]], "c": "3749205255"}, "book-100", "XBT/USD"]
[270, {"a": [["11687.20000", "1.41990271", "1596666845.824342"]], "c": "3749205255"}, "book-100", "XBT/USD"]
[271, [["11666.20000", "0.08509126", "1596666846.272758", "b", "l", ""], ["11671.10000", "0.41352978", "1596666846.286755", "b", "l", ""]], "trade", "XBT/USD"]
[270, {"a": [["11666.20000", "0.00000000", "1596666846.272758"], ["11710.40000", "1.16811308", "1596666772.597033", "r"], ["11671.10000", "0.00000000", "1596666846.286755"], ["11710.60000", "2.80039129", "1596666770.582883", "r"]], "c": "676122187"}, "book-100", "XBT/USD"]
[270, {"b": [["11666.20000", "5.25000000", "1596666846.366176"]], "c": "678379198"}, "book-100", "XBT/USD"]
[270, {"a": [["11705.70000", "0.89689086", "1596666846.372224"]], "c": "678379198"}, "book-100", "XBT/USD"]
[270, {"b": [["11666.10000", "8.92628983", "1596666846.379990"]], "c": "3864335029"}, "book-100", "XBT/USD"]
[270, {"a": [["11672.50000", "0.87087104", "1596666846.423676"]], "c": "2620163216"}, "book-100", "XBT/USD"]
[270, {"b": [["11666.10000", "8.42628983", "1596666846.432008"]], "c": "1500610847"}, "book-100", "XBT/USD"]
[270, {"b": [["11666.20000", "5.47500000", "1596666846.436905"]], "c": "2786785532"}, "book-100", "XBT/USD"]
[270, {"a": [["11672.40000", "0.00000000", "1596666846.444346"], ["11710.70000", "3.52183532", "1596666711.393054", "r"]], "c": "2238566969"}, "book-100", "XBT/USD"]
[270, {"b": [["11666.20000", "0.22500000", "1596666846.444936"]], "c": "1804122628"}, "book-100", "XBT/USD"]
[270, {"b": [["11664.10000", "0.00000000", "1596666846.451934"], ["11612.50000", "0.00857706", "1596666841.240139", "r"]], "c": "1804122628"}, "book-100", "XBT/USD"]
[270, {"b": [["11666.10000", "8.16797335", "1596666846.456065"]], "c": "3247138298"}, "book-100", "XBT/USD"]
[270, {"a": [["11674.40000", "0.25000000", "1596666846.456688"]], "c": "969497869"}, "book-100", "XBT/USD"]
[270, {"b": [["11666.10000", "8.15997335", "1596666846.486299"]], "c": "2783378625"}, "book-100", "XBT/USD"]
[270, {"b": [["11612.50000", "0.00000000", "1596666846.488588"], ["11612.30000", "7.00000000", "1596666617.080387", "r"]], "c": "2783378625"}, "book-100", "XBT/USD"]
[270, {"b": [["11666.00000", "0.00000000", "1596666846.498921"], ["11611.90000", "1.06000000", "1596666780.430510", "r"]], "c": "3572643915"}, "book-100", "XBT/USD"]
[270, {"b": [["11666.10000", "7.51729825", "1596666846.499505"]], "c": "1524888838"}, "book-100", "XBT/USD"]
[270, {"b": [["11665.90000", "0.00000000", "1596666846.500266"], ["11611.70000", "0.37132924", "1596666797.216118", "r"]], "c": "3073950926"}, "book-100", "XBT/USD"]
[270, {"b": [["11666.70000", "0.50000000", "1596666846.503318"]], "c": "3771039358"}, "book-100", "XBT/USD"]
[270, {"b": [["11666.30000", "0.08569751", "1596666846.549568"]], "c": "4165644523"}, "book-100", "XBT/USD"]
[270, {"b": [["11666.30000", "0.34397501", "1596666846.555425"]], "c": "2082061588"}, "book-100", "XBT/USD"]
[270, {"b": [["11666.70000", "0.72500000", "1596666846.565520"]], "c": "4160330437"}, "book-100", "XBT/USD"]
[270, {"b": [["11666.10000", "7.47479825", "1596666846.572225"]], "c": "3291122899"}, "book-100", "XBT/USD"]
[270, {"b": [["11666.60000", "0.50000000", "1596666846.590756"]], "c": "2249244433"}, "book-100", "XBT/USD"]
[270, {"b": [["11666.10000", "7.37479825", "1596666846.592622"]], "c": "1228493813"}, "book-100", "XBT/USD"]
[270, {"a": [["11675.30000", "0.00000000", "1596666846.614620"], ["11710.70000", "3.52183532", "1596666711.393054", "r"]], "c": "1228493813"}, "book-100", "XBT/USD"]
[270, {"a": [["11674.40000", "0.00000000", "1596666846.650512"], ["11711.10000", "0.75800000", "1596666806.349295", "r"]], "c": "1773129000"}, "book-100", "XBT/USD"]
[270, {"a": [["11671.60000", "0.12968408", "1596666846.660340"]], "c": "2537761308"}, "book-100", "XBT/USD"]
[270, {"b": [["11666.10000", "6.86478041", "1596666846.748462"]], "c": "403784593"}, "book-100", "XBT/USD"]
[270, {"b": [["11666.40000", "0.10000000", "1596666846.791804"]], "c": "2458682518"}, "book-100", "XBT/USD"]
[270, {"a": [["11674.20000", "0.25000000", "1596666846.801737"]], "c": "149052566"}, "book-100", "XBT/USD"]
[270, {"a": [["11672.50000", "0.86059682", "1596666846.805261"]], "c": "2834792846"}, "book-100", "XBT/USD"]
[270, {"a": [["11672.40000", "0.01027431", "1596666846.806839"]], "c": "2900333866"}, "book-100", "XBT/USD"]
[270, {"b": [["11664.90000", "0.04250000", "1596666846.814122"]], "c": "3337276553"}, "book-100", "XBT/USD"]
[270, {"a": [["11674.40000", "0.04250000", "1596666846.815243"]], "c": "3337276553"}, "book-100", "XBT/USD"]
[271, [["11671.60000", "0.00200000", "1596666846.828442", "b", "m", ""]], "trade", "XBT/USD"]
[270, {"a": [["11671.60000", "0.12768408", "1596666846.828442"]], "c": "941554423"}, "book-100", "XBT/USD"]
[270, {"a": [["11682.30000", "0.00000000", "1596666846.849015"], ["11710.40000", "1.16811308", "1596666772.597033", "r"]], "c": "941554423"}, "book-100", "XBT/USD"]
[270, {"a": [["11688.30000", "1.64160000", "1596666846.883080"]], "c": "941554423"}, "book-100", "XBT/USD"]
[270, {"b": [["11666.60000", "0.00000000", "1596666846.970234"], ["11613.60000", "3.55198121", "1596666780.634357", "r"]], "c": "1198271619"}, "book-100", "XBT/USD"]
[270, {"b": [["11625.10000", "0.00856780", "1596666847.055215"]], "c": "1198271619"}, "book-100", "XBT/USD"]
[270, {"b": [["11667.20000", "0.50000000", "1596666847.116028"]], "c": "292324003"}, "book-100", "XBT/USD"]
[270, {"b": [["11666.80000", "0.50998724", "1596666847.131860"]], "c": "1378924547"}, "book-100", "XBT/USD"]
[270, {"b": [["11667.20000", "5.75000000", "1596666847.180649"]], "c": "789908204"}, "book-100", "XBT/USD"]
[270, {"b": [["11623.60000", "0.00000000", "1596666847.231239"], ["11615.60000", "0.20000000", "1596666623.308321", "r"]], "c": "789908204"}, "book-100", "XBT/USD"]
[270, {"b": [["11667.20000", "0.50000000", "1596666847.246585"]], "c": "1378924547"}, "book-100", "XBT/USD"]
[270, {"a": [["11682.00000", "0.00000000", "1596666847.430653"], ["11710.40000", "1.16811308", "1596666772.597033", "r"]], "c": "1378924547"}, "book-100", "XBT/USD"]
[270, {"b": [["11622.60000", "0.00000000", "1596666847.433328"], ["11614.80000", "3.08717099", "1596666746.879208", "r"]], "c": "1378924547"}, "book-100", "XBT/USD"]
[270, {"a": [["11682.10000", "0.00000000", "1596666847.433389"], ["11710.60000", "2.80039129", "1596666770.582883", "r"]], "c": "1378924547"}, "book-100", "XBT/USD"]
[270, {"a": [["11685.40000", "0.00000000", "1596666847.439437"], ["11710.70000", "3.52183532", "1596666711.393054", "r"]], "c": "1378924547"}, "book-100", "XBT/USD"]
[270, {"b": [["11666.80000", "0.00000000", "1596666847.443077"], ["11613.60000", "3.55198121", "1596666780.634357", "r"]], "c": "292324003"}, "book-100", "XBT/USD"]
[270, {"b": [["11622.70000", "0.00000000", "1596666847.455342"], ["11613.00000", "0.17085000", "1596666803.224745", "r"]], "c": "292324003"}, "book-100", "XBT/USD"]
[270, {"b": [["11667.30000", "0.08569421", "1596666847.518364"]], "c": "3762781548"}, "book-100", "XBT/USD"]
[270, {"a": [["11673.00000", "0.00000000", "1596666847.637987"], ["11711.10000", "0.75800000", "1596666806.349295", "r"]], "c": "4282398891"}, "book-100", "XBT/USD"]
[270, {"a": [["11673.50000", "0.25827923", "1596666847.740115"]], "c": "3962370907"}, "book-100", "XBT/USD"]
[270, {"a": [["11684.00000", "0.11086301", "1596666847.759844"]], "c": "3962370907"}, "book-100", "XBT/USD"]
[270, {"b": [["11667.40000", "0.49032644", "1596666847.768983"]], "c": "2765488649"}, "book-100", "XBT/USD"]
[270, {"b": [["11666.20000", "15.22500000", "1596666847.802884"]], "c": "3683036766"}, "book-100", "XBT/USD"]
[270, {"b": [["11630.80000", "2.32247796", "1596666847.806192"]], "c": "3683036766"}, "book-100", "XBT/USD"]
[270, {"b": [["11669.40000", "0.64257807", "1596666847.845620"]], "c": "3546155328"}, "book-100", "XBT/USD"]
[270, {"b": [["11667.40000", "1.13290805", "1596666847.846041"]], "c": "1786488316"}, "book-100", "XBT/USD"]
[270, {"b": [["11668.90000", "0.64258161", "1596666847.846194"]], "c": "2438963081"}, "book-100", "XBT/USD"]
[270, {"a": [["11686.30000", "0.00000000", "1596666847.862210"], ["11710.70000", "3.52183532", "1596666711.393054", "r"]], "c": "2438963081"}, "book-100", "XBT/USD"]
[270, {"b": [["11669.40000", "3.29257807", "1596666847.904902"]], "c": "675491470"}, "book-100", "XBT/USD"]
[270, {"b": [["11666.30000", "0.43997501", "1596666847.915868"]], "c": "3387677490"}, "book-100", "XBT/USD"]
[270, {"a": [["11674.60000", "0.00000000", "1596666847.926359"], ["11711.10000", "0.75800000", "1596666806.349295", "r"]], "c": "3387677490"}, "book-100", "XBT/USD"]
[270, {"b": [["11652.10000", "0.00000000", "1596666847.928921"], ["11616.00000", "0.17085000", "1596666842.228991", "r"]], "c": "3387677490"}, "book-100", "XBT/USD"]
[270, {"a": [["11684.00000", "0.00000000", "1596666847.937990"], ["11711.50000", "1.99898326", "1596666797.632161", "r"]], "c": "3387677490"}, "book-100", "XBT/USD"]
[270, {"b": [["11669.40000", "0.64257807", "1596666847.964207"]], "c": "1895262773"}, "book-100", "XBT/USD"]
[270, {"a": [["11674.20000", "0.00000000", "1596666847.977048"], ["11714.80000", "1.99881632", "1596666809.038669", "r"]], "c": "1895262773"}, "book-100", "XBT/USD"]
[270, {"a": [["11678.10000", "0.00000000", "1596666847.996848"], ["11715.00000", "0.17085000", "1596666842.524286", "r"]], "c": "1895262773"}, "book-100", "XBT/USD"]
[270, {"b": [["11667.50000", "4.27700000", "1596666848.022279"]], "c": "89595873"}, "book-100", "XBT/USD"]
[270, {"a": [["11678.10000", "0.01000000", "1596666848.094597"]], "c": "89595873"}, "book-100", "XBT/USD"]
[270, {"b": [["11667.40000", "0.64258161", "1596666848.100421"]], "c": "2913470402"}, "book-100", "XBT/USD"]
[270, {"a": [["11675.00000", "0.26821000", "1596666848.175742"]], "c": "2913470402"}, "book-100", "XBT/USD"]
[270, {"b": [["11667.20000", "0.00000000", "1596666848.180600"], ["11616.00000", "0.17085000", "1596666842.228991", "r"]], "c": "900159440"}, "book-100", "XBT/USD"]
[270, {"b": [["11666.10000", "2.58978041", "1596666848.284326"]], "c": "535788430"}, "book-100", "XBT/USD"]
[270, {"b": [["11625.00000", "0.42085000", "1596666848.289266"]], "c": "535788430"}, "book-100", "XBT/USD"]
[270, {"b": [["11652.10000", "0.03100000", "1596666848.290901"]], "c": "535788430"}, "book-100", "XBT/USD"]
[270, {"b": [["11666.40000", "0.00000000", "1596666848.308442"], ["11616.00000", "0.17085000", "1596666842.228991", "r"]], "c": "174180099"}, "book-100", "XBT/USD"]
[270, {"b": [["11669.50000", "0.50986924", "1596666848.433955"]], "c": "899439002"}, "book-100", "XBT/USD"]
[270, {"b": [["11668.20000", "0.50000000", "1596666848.443435"]], "c": "278556082"}, "book-100", "XBT/USD"]
[270, {"a": [["11675.00000", "0.01821000", "1596666848.496119"]], "c": "278556082"}, "book-100", "XBT/USD"]
[270, {"a": [["11682.80000", "0.09900000", "1596666848.505688"]], "c": "278556082"}, "book-100", "XBT/USD"]
[270, {"b": [["11652.80000", "0.00000000", "1596666848.508880"], ["11616.70000", "2.01459953", "1596666777.763006", "r"]], "c": "278556082"}, "book-100", "XBT/USD"]
[270, {"a": [["11672.30000", "0.84000000", "1596666848.567650"]], "c": "3916752333"}, "book-100", "XBT/USD"]
[270, {"b": [["11668.20000", "0.00000000", "1596666848.592096"], ["11616.00000", "0.17085000", "1596666842.228991", "r"]], "c": "4125088703"}, "book-100", "XBT/USD"]
[270, {"a": [["11682.50000", "0.99086336", "1596666848.613410"]], "c": "4125088703"}, "book-100", "XBT/USD"]
[270, {"a": [["11679.20000", "0.85745244", "1596666848.629060"]], "c": "4125088703"}, "book-100", "XBT/USD"]
[270, {"b": [["11666.30000", "0.18169751", "1596666848.632703"]], "c": "292939266"}, "book-100", "XBT/USD"]
[270, {"b": [["11658.30000", "0.00000000", "1596666848.632855"], ["11615.60000", "0.20000000", "1596666623.308321", "r"]], "c": "292939266"}, "book-100", "XBT/USD"]
[270, {"a": [["11676.10000", "0.25000000", "1596666848.665413"]], "c": "292939266"}, "book-100", "XBT/USD"]
[270, {"a": [["11672.40000", "0.00000000", "1596666848.694116"], ["11711.10000", "0.75800000", "1596666806.349295", "r"]], "c": "2210801634"}, "book-100", "XBT/USD"]
[270, {"a": [["11672.50000", "0.87087104", "1596666848.697026"]], "c": "362690976"}, "book-100", "XBT/USD"]
[270, {"a": [["11674.90000", "0.00000000", "1596666848.729183"], ["11711.50000", "1.99898326", "1596666797.632161", "r"]], "c": "362690976"}, "book-100", "XBT/USD"]
[270, {"b": [["11667.60000", "0.25828064", "1596666848.733673"]], "c": "1412298641"}, "book-100", "XBT/USD"]
[270, {"b": [["11669.10000", "0.50000000", "1596666848.741472"]], "c": "3018748911"}, "book-100", "XBT/USD"]
[270, {"b": [["11666.10000", "0.88278041", "1596666848.757993"]], "c": "3018748911"}, "book-100", "XBT/USD"]
[270, {"b": [["11667.40000", "2.34658161", "1596666848.780382"]], "c": "1373806078"}, "book-100", "XBT/USD"]
[270, {"b": [["11666.30000", "0.86033751", "1596666848.869210"]], "c": "1922253113"}, "book-100", "XBT/USD"]
[270, {"b": [["11657.70000", "0.00000000", "1596666848.938927"], ["11616.00000", "0.17085000", "1596666842.228991", "r"]], "c": "1922253113"}, "book-100", "XBT/USD"]
[270, {"b": [["11666.10000", "0.88008808", "1596666849.059555"]], "c": "1922253113"}, "book-100", "XBT/USD"]
[270, {"b": [["11668.90000", "0.00000000", "1596666849.149035"], ["11615.60000", "0.20000000", "1596666623.308321", "r"]], "c": "4236382427"}, "book-100", "XBT/USD"]
[270, {"b": [["11664.00000", "2.12796684", "1596666849.166352"]], "c": "4236382427"}, "book-100", "XBT/USD"]
[270, {"a": [["11677.70000", "0.00000000", "1596666849.168230"], ["11714.80000", "1.99881632", "1596666809.038669", "r"]], "c": "4236382427"}, "book-100", "XBT/USD"]
[270, {"a": [["11673.50000", "0.00000000", "1596666849.170492"], ["11715.00000", "0.17085000", "1596666842.524286", "r"]], "c": "3923012129"}, "book-100", "XBT/USD"]
[270, {"b": [["11669.70000", "0.10300000", "1596666849.172530"]], "c": "1033600582"}, "book-100", "XBT/USD"]
[270, {"b": [["11659.00000", "0.04471515", "1596666849.202664"]], "c": "1033600582"}, "book-100", "XBT/USD"]
[270, {"b": [["11668.30000", "0.09621094", "1596666849.207269"]], "c": "3470251369"}, "book-100", "XBT/USD"]
[270, {"b": [["11670.10000", "0.40000000", "1596666849.207448"]], "c": "2184073161"}, "book-100", "XBT/USD"]
[270, {"b": [["11660.30000", "0.00000000", "1596666849.208416"], ["11617.50000", "2.49761864", "1596666811.445738", "r"]], "c": "2184073161"}, "book-100", "XBT/USD"]
[270, {"b": [["11667.40000", "1.70400000", "1596666849.208771"]], "c": "1992744318"}, "book-100", "XBT/USD"]
[270, {"a": [["11674.50000", "0.00000000", "1596666849.209218"], ["11715.30000", "6.10000000", "1596666635.445451", "r"]], "c": "1992744318"}, "book-100", "XBT/USD"]
[270, {"a": [["11671.70000", "0.57230000", "1596666849.209515"]], "c": "903212343"}, "book-100", "XBT/USD"]
[270, {"a": [["11676.10000", "0.00000000", "1596666849.216192"], ["11717.80000", "1.99812614", "1596666759.535617", "r"]], "c": "903212343"}, "book-100", "XBT/USD"]
[270, {"a": [["11674.00000", "0.25825954", "1596666849.225258"]], "c": "3771612082"}, "book-100", "XBT/USD"]
[270, {"b": [["11669.10000", "0.00000000", "1596666849.234962"], ["11617.40000", "0.75800000", "1596666775.482846", "r"]], "c": "2764493320"}, "book-100", "XBT/USD"]
[270, {"b": [["11665.50000", "0.00000000", "1596666849.237308"], ["11616.70000", "2.01459953", "1596666777.763006", "r"]], "c": "2764493320"}, "book-100", "XBT/USD"]
[270, {"b": [["11657.00000", "0.00000000", "1596666849.255349"], ["11616.00000", "0.17085000", "1596666842.228991", "r"]], "c": "2764493320"}, "book-100", "XBT/USD"]
[270, {"a": [["11680.70000", "2.76108060", "1596666849.275778"]], "c": "2764493320"}, "book-100", "XBT/USD"]
[270, {"b": [["11660.50000", "0.00000000", "1596666849.297375"], ["11615.60000", "0.20000000", "1596666623.308321", "r"]], "c": "2764493320"}, "book-100", "XBT/USD"]
[270, {"a": [["11674.10000", "0.00000000", "1596666849.304799"], ["11715.30000", "6.10000000", "1596666635.445451", "r"]], "c": "3145752326"}, "book-100", "XBT/USD"]
[270, {"b": [["11669.40000", "0.00000000", "1596666849.306483"], ["11614.80000", "3.08717099", "1596666746.879208", "r"]], "c": "115826039"}, "book-100", "XBT/USD"]
[270, {"a": [["11672.50000", "0.01027422", "1596666849.309457"]], "c": "3431507256"}, "book-100", "XBT/USD"]
[270, {"b": [["11667.70000", "0.10000000", "1596666849.311129"]], "c": "2423722365"}, "book-100", "XBT/USD"]
[270, {"a": [["11672.30000", "0.00000000", "1596666849.337698"], ["11717.80000", "1.99812614", "1596666759.535617", "r"]], "c": "3556197348"}, "book-100", "XBT/USD"]
[270, {"a": [["11675.40000", "0.00000000", "1596666849.342909"], ["11718.00000", "0.17085000", "1596666836.842357", "r"]], "c": "3556197348"}, "book-100", "XBT/USD"]
[270, {"a": [["11677.80000", "0.25000000", "1596666849.351074"]], "c": "3556197348"}, "book-100", "XBT/USD"]
[270, {"a": [["11681.00000", "0.00000000", "1596666849.356484"], ["11718.00000", "0.17085000", "1596666836.842357", "r"]], "c": "3556197348"}, "book-100", "XBT/USD"]
[270, {"a": [["11683.00000", "0.00000000", "1596666849.356591"], ["11718.40000", "0.48360000", "1596666846.374528", "r"]], "c": "3556197348"}, "book-100", "XBT/USD"]
[270, {"b": [["11657.10000", "0.00000000", "1596666849.356842"], ["11614.80000", "3.08717099", "1596666746.879208", "r"]], "c": "3556197348"}, "book-100", "XBT/USD"]
[270, {"a": [["11672.70000", "0.71694128", "1596666849.364767"]], "c": "215617726"}, "book-100", "XBT/USD"]
[270, {"b": [["11664.50000", "0.00000000", "1596666849.368369"], ["11613.60000", "3.55198121", "1596666780.634357", "r"]], "c": "215617726"}, "book-100", "XBT/USD"]
[270, {"b": [["11670.90000", "0.50000000", "1596666849.374867"]], "c": "1494173554"}, "book-100", "XBT/USD"]
[270, {"b": [["11669.50000", "0.00000000", "1596666849.399748"], ["11613.60000", "3.55198121", "1596666780.634357", "r"]], "c": "202399252"}, "book-100", "XBT/USD"]
[270, {"a": [["11677.10000", "0.00000000", "1596666849.413428"], ["11718.50000", "24.30000000", "1596666641.380470", "r"]], "c": "202399252"}, "book-100", "XBT/USD"]
[270, {"b": [["11661.10000", "0.00000000", "1596666849.418336"], ["11613.00000", "0.17085000", "1596666803.224745", "r"]], "c": "202399252"}, "book-100", "XBT/USD"]
[270, {"b": [["11668.70000", "1.01426000", "1596666849.422392"]], "c": "903127394"}, "book-100", "XBT/USD"]
[270, {"a": [["11672.60000", "0.00000000", "1596666849.426829"], ["11719.60000", "2.98021891", "1596666782.974175", "r"]], "c": "1135548973"}, "book-100", "XBT/USD"]
[270, {"a": [["11672.60000", "0.01027413", "1596666849.439892"]], "c": "719848977"}, "book-100", "XBT/USD"]
[270, {"b": [["11667.40000", "0.00000000", "1596666849.445815"], ["11613.00000", "0.17085000", "1596666803.224745", "r"]], "c": "169302676"}, "book-100", "XBT/USD"]
[270, {"a": [["11672.70000", "0.49552697", "1596666849.450255"]], "c": "2482648417"}, "book-100", "XBT/USD"]
[270, {"a": [["11678.30000", "0.00000000", "1596666849.450466"], ["11719.60000", "2.98021891", "1596666782.974175", "r"]], "c": "2482648417"}, "book-100", "XBT/USD"]
[270, {"b": [["11668.90000", "1.70200000", "1596666849.450987"]], "c": "693736106"}, "book-100", "XBT/USD"]
[270, {"a": [["11673.10000", "0.00000000", "1596666849.452873"], ["11719.70000", "3.50602221", "1596666789.365232", "r"]], "c": "2533409074"}, "book-100", "XBT/USD"]
[270, {"b": [["11670.20000", "0.10000000", "1596666849.465925"]], "c": "2463208802"}, "book-100", "XBT/USD"]
[270, {"a": [["11672.70000", "0.00000000", "1596666849.497066"], ["11721.00000", "0.97885000", "1596666831.502501", "r"]], "c": "2303515095"}, "book-100", "XBT/USD"]
[270, {"b": [["11660.90000", "6.70000000", "1596666849.499062"]], "c": "2303515095"}, "book-100", "XBT/USD"]
[270, {"a": [["11674.00000", "0.00000000", "1596666849.500260"], ["11721.70000", "2.47549182", "1596666772.357495", "r"]], "c": "143714530"}, "book-100", "XBT/USD"]
[270, {"a": [["11681.10000", "0.00000000", "1596666849.525361"], ["11722.10000", "7.70000000", "1596666696.315517", "r"]], "c": "143714530"}, "book-100", "XBT/USD"]
[270, {"b": [["11666.10000", "0.79758808", "1596666849.526103"]], "c": "143714530"}, "book-100", "XBT/USD"]
[270, {"a": [["11687.20000", "0.00000000", "1596666849.557402"], ["11722.20000", "3.01549629", "1596666746.821117", "r"]], "c": "143714530"}, "book-100", "XBT/USD"]
[270, {"a": [["11676.90000", "0.09621094", "1596666849.560489"]], "c": "1879668784"}, "book-100", "XBT/USD"]
[270, {"a": [["11681.70000", "0.00000000", "1596666849.564271"], ["11722.20000", "3.01549629", "1596666746.821117", "r"]], "c": "1879668784"}, "book-100", "XBT/USD"]
[270, {"a": [["11683.00000", "0.04470745", "1596666849.583733"]], "c": "1879668784"}, "book-100", "XBT/USD"]
[270, {"a": [["11678.70000", "0.00000000", "1596666849.616581"], ["11722.20000", "3.01549629", "1596666746.821117", "r"]], "c": "1879668784"}, "book-100", "XBT/USD"]
[270, {"a": [["11700.70000", "1.85666144", "1596666849.618097"]], "c": "1879668784"}, "book-100", "XBT/USD"]
[270, {"a": [["11715.00000", "0.00000000", "1596666849.638581"], ["11722.20000", "3.01549629", "1596666746.821117", "r"]], "c": "1879668784"}, "book-100", "XBT/USD"]
[270, {"a": [["11696.80000", "0.00000000", "1596666849.647080"], ["11722.60000", "23.57900000", "1596666806.604937", "r"]], "c": "1879668784"}, "book-100", "XBT/USD"]
[270, {"b": [["11644.80000", "0.00000000", "1596666849.650925"], ["11614.80000", "3.08717099", "1596666746.879208", "r"]], "c": "1879668784"}, "book-100", "XBT/USD"]
[270, {"b": [["11659.00000", "0.54471515", "1596666849.658461"]], "c": "1879668784"}, "book-100", "XBT/USD"]
[270, {"a": [["11686.90000", "0.10100000", "1596666849.679803"]], "c": "1879668784"}, "book-100", "XBT/USD"]
[270, {"a": [["11672.50000", "0.00000000", "1596666849.681554"], ["11722.60000", "23.57900000", "1596666806.604937", "r"]], "c": "1115278879"}, "book-100", "XBT/USD"]
[270, {"a": [["11688.00000", "0.00000000", "1596666849.685351"], ["11722.80000", "0.25848395", "1596666814.771934", "r"]], "c": "1115278879"}, "book-100", "XBT/USD"]
[270, {"a": [["11672.60000", "0.00000000", "1596666849.689918"], ["11724.00000", "0.17085000", "1596666848.446099", "r"]], "c": "147483710"}, "book-100", "XBT/USD"]
[270, {"a": [["11673.50000", "0.02763284", "1596666849.694612"]], "c": "663713498"}, "book-100", "XBT/USD"]
[270, {"a": [["11673.60000", "0.00000000", "1596666849.699375"], ["11724.00000", "0.17085000", "1596666848.446099", "r"]], "c": "2704697187"}, "book-100", "XBT/USD"]
[270, {"b": [["11671.00000", "0.44616952", "1596666849.713833"]], "c": "4275994086"}, "book-100", "XBT/USD"]
[270, {"a": [["11676.40000", "0.25823462", "1596666849.717208"]], "c": "2406047948"}, "book-100", "XBT/USD"]
[270, {"a": [["11684.80000", "0.13412105", "1596666849.726322"]], "c": "2406047948"}, "book-100", "XBT/USD"]
[270, {"b": [["11658.80000", "0.13412105", "1596666849.726683"]], "c": "2406047948"}, "book-100", "XBT/USD"]
[270, {"b": [["11667.30000", "2.97613199", "1596666849.740739"]], "c": "2406047948"}, "book-100", "XBT/USD"]
[270, {"a": [["11682.40000", "0.45370551", "1596666849.749744"]], "c": "2406047948"}, "book-100", "XBT/USD"]
[270, {"b": [["11636.80000", "0.00000000", "1596666849.761984"], ["11615.60000", "0.20000000", "1596666623.308321", "r"]], "c": "2406047948"}, "book-100", "XBT/USD"]
[270, {"b": [["11670.90000", "0.50800000", "1596666849.763609"]], "c": "2584638770"}, "book-100", "XBT/USD"]
[270, {"a": [["11680.80000", "1.50000000", "1596666849.766231"]], "c": "2584638770"}, "book-100", "XBT/USD"]
[270, {"a": [["11675.30000", "0.82976212", "1596666849.769113"]], "c": "1890992254"}, "book-100", "XBT/USD"]
[270, {"b": [["11667.70000", "0.18250000", "1596666849.769601"]], "c": "514413697"}, "book-100", "XBT/USD"]
[270, {"a": [["11682.70000", "0.08250000", "1596666849.770949"]], "c": "514413697"}, "book-100", "XBT/USD"]
[270, {"b": [["11660.40000", "0.00000000", "1596666849.771589"], ["11614.80000", "3.08717099", "1596666746.879208", "r"]], "c": "514413697"}, "book-100", "XBT/USD"]
[270, {"b": [["11667.70000", "0.08250000", "1596666849.823664"]], "c": "219386779"}, "book-100", "XBT/USD"]
[270, {"a": [["11679.90000", "0.86936108", "1596666849.847964"]], "c": "219386779"}, "book-100", "XBT/USD"]
[270, {"a": [["11684.30000", "0.69925183", "1596666849.852678"]], "c": "219386779"}, "book-100", "XBT/USD"]
[270, {"a": [["11680.20000", "0.00000000", "1596666849.856307"], ["11721.00000", "0.97885000", "1596666831.502501", "r"]], "c": "219386779"}, "book-100", "XBT/USD"]
[270, {"b": [["11664.90000", "0.00000000", "1596666849.877969"], ["11613.60000", "3.55198121", "1596666780.634357", "r"]], "c": "219386779"}, "book-100", "XBT/USD"]
[270, {"a": [["11674.40000", "0.00000000", "1596666849.880945"], ["11721.70000", "2.47549182", "1596666772.357495", "r"]], "c": "1435704258"}, "book-100", "XBT/USD"]
[270, {"b": [["11664.00000", "0.00000000", "1596666849.881764"], ["11613.00000", "0.17085000", "1596666803.224745", "r"]], "c": "1435704258"}, "book-100", "XBT/USD"]
[270, {"a": [["11680.80000", "0.00000000", "1596666849.911913"], ["11722.10000", "7.70000000", "1596666696.315517", "r"]], "c": "1435704258"}, "book-100", "XBT/USD"]
[270, {"a": [["11673.50000", "0.00000000", "1596666849.940573"], ["11722.20000", "3.01549629", "1596666746.821117", "r"]], "c": "1276395053"}, "book-100", "XBT/USD"]
[270, {"a": [["11674.30000", "0.05313798", "1596666849.942507"]], "c": "3248645848"}, "book-100", "XBT/USD"]
[270, {"a": [["11698.20000", "0.00000000", "1596666849.962525"], ["11722.20000", "3.01549629", "1596666746.821117", "r"]], "c": "3248645848"}, "book-100", "XBT/USD"]
[270, {"a": [["11697.60000", "0.00000000", "1596666849.976288"], ["11722.60000", "23.57900000", "1596666806.604937", "r"]], "c": "3248645848"}, "book-100", "XBT/USD"]
[270, {"a": [["11691.20000", "0.00000000", "1596666849.977110"], ["11722.80000", "0.25848395", "1596666814.771934", "r"]], "c": "3248645848"}, "book-100", "XBT/USD"]
[270, {"a": [["11687.70000", "0.00000000", "1596666849.980313"], ["11724.00000", "0.17085000", "1596666848.446099", "r"]], "c": "3248645848"}, "book-100", "XBT/USD"]
[270, {"a": [["11691.10000", "0.00000000", "1596666849.980819"], ["11725.40000", "1.99666304", "1596666743.823724", "r"]], "c": "3248645848"}, "book-100", "XBT/USD"]
[270, {"a": [["11692.80000", "0.00000000", "1596666849.981259"], ["11725.50000", "1.06000000", "1596666771.224459", "r"]], "c": "3248645848"}, "book-100", "XBT/USD"]
[270, {"a": [["11687.60000", "0.00000000", "1596666849.986589"], ["11726.30000", "1.78600000", "1596666787.006488", "r"]], "c": "3248645848"}, "book-100", "XBT/USD"]
[270, {"a": [["11682.50000", "0.88000000", "1596666850.006938"]], "c": "3248645848"}, "book-100", "XBT/USD"]
[270, {"a": [["11698.40000", "0.00000000", "1596666850.008704"], ["11727.40000", "7.40000000", "1596666699.130230", "r"]], "c": "3248645848"}, "book-100", "XBT/USD"]
[270, {"a": [["11683.90000", "1.98214066", "1596666850.014258"]], "c": "3248645848"}, "book-100", "XBT/USD"]
[270, {"a": [["11680.00000", "0.49627419", "1596666850.073480"]], "c": "3248645848"}, "book-100", "XBT/USD"]
[270, {"b": [["11667.70000", "0.12500000", "1596666850.097283"]], "c": "3890887812"}, "book-100", "XBT/USD"]
[270, {"b": [["11643.60000", "3.54191847", "1596666850.108661"]], "c": "3890887812"}, "book-100", "XBT/USD"]
[270, {"a": [["11680.00000", "0.83797584", "1596666850.128055"]], "c": "3890887812"}, "book-100", "XBT/USD"]
[270, {"a": [["11682.40000", "1.03832984", "1596666850.130094"]], "c": "3890887812"}, "book-100", "XBT/USD"]
[270, {"a": [["11722.80000", "0.00000000", "1596666850.134222"], ["11726.30000", "1.78600000", "1596666787.006488", "r"]], "c": "3890887812"}, "book-100", "XBT/USD"]
[270, {"a": [["11677.50000", "0.04250000", "1596666850.137518"]], "c": "2334202359"}, "book-100", "XBT/USD"]
[270, {"a": [["11679.90000", "1.08118327", "1596666850.182277"]], "c": "2334202359"}, "book-100", "XBT/USD"]
[270, {"a": [["11690.00000", "0.04000000", "1596666850.184898"]], "c": "2334202359"}, "book-100", "XBT/USD"]
[270, {"b": [["11668.80000", "0.10000000", "1596666850.187317"]], "c": "3455118611"}, "book-100", "XBT/USD"]
[270, {"a": [["11680.70000", "0.00000000", "1596666850.189478"], ["11726.30000", "1.78600000", "1596666787.006488", "r"]], "c": "3455118611"}, "book-100", "XBT/USD"]
[270, {"a": [["11674.30000", "0.00000000", "1596666850.195214"], ["11727.40000", "7.40000000", "1596666699.130230", "r"]], "c": "4112054338"}, "book-100", "XBT/USD"]
[270, {"a": [["11674.90000", "0.05313798", "1596666850.199537"]], "c": "1282460338"}, "book-100", "XBT/USD"]
[270, {"a": [["11696.40000", "0.89754778", "1596666850.210407"]], "c": "1282460338"}, "book-100", "XBT/USD"]
[270, {"a": [["11696.40000", "1.24596933", "1596666850.214212"]], "c": "1282460338"}, "book-100", "XBT/USD"]
[270, {"a": [["11692.80000", "0.24894916", "1596666850.214964"]], "c": "1282460338"}, "book-100", "XBT/USD"]
[270, {"a": [["11701.00000", "0.57218181", "1596666850.215634"]], "c": "1282460338"}, "book-100", "XBT/USD"]
[270, {"a": [["11686.10000", "0.00000000", "1596666850.229728"], ["11725.40000", "2.25560036", "1596666850.228085", "r"]], "c": "1282460338"}, "book-100", "XBT/USD"]
[270, {"a": [["11702.80000", "1.16576018", "1596666850.230672"]], "c": "1282460338"}, "book-100", "XBT/USD"]
[270, {"a": [["11692.20000", "0.00000000", "1596666850.244364"], ["11725.50000", "1.06000000", "1596666771.224459", "r"]], "c": "1282460338"}, "book-100", "XBT/USD"]
[270, {"a": [["11677.40000", "1.71200000", "1596666850.244758"]], "c": "2924361812"}, "book-100", "XBT/USD"]
[270, {"a": [["11689.20000", "0.00000000", "1596666850.255823"], ["11725.50000", "1.06000000", "1596666771.224459", "r"]], "c": "2924361812"}, "book-100", "XBT/USD"]
[270, {"a": [["11692.90000", "0.89781644", "1596666850.258011"]], "c": "2924361812"}, "book-100", "XBT/USD"]
[270, {"a": [["11685.90000", "1.08882361", "1596666850.258684"]], "c": "2924361812"}, "book-100", "XBT/USD"]
[270, {"a": [["11683.10000", "1.50000000", "1596666850.272157"]], "c": "2924361812"}, "book-100", "XBT/USD"]
[270, {"a": [["11708.60000", "3.52225560", "1596666850.285578"]], "c": "2924361812"}, "book-100", "XBT/USD"]
[270, {"a": [["11708.60000", "5.02595511", "1596666850.305826"]], "c": "2924361812"}, "book-100", "XBT/USD"]
[270, {"a": [["11718.00000", "0.00000000", "1596666850.312812"], ["11724.00000", "0.17085000", "1596666848.446099", "r"]], "c": "2924361812"}, "book-100", "XBT/USD"]
[270, {"a": [["11692.20000", "6.55843437", "1596666850.326365"]], "c": "2924361812"}, "book-100", "XBT/USD"]
[270, {"a": [["11684.40000", "0.11086292", "1596666850.464640"]], "c": "2924361812"}, "book-100", "XBT/USD"]
[270, {"b": [["11671.50000", "0.50000000", "1596666850.470428"]], "c": "1713204420"}, "book-100", "XBT/USD"]
[270, {"a": [["11694.50000", "0.49618757", "1596666850.497155"]], "c": "1713204420"}, "book-100", "XBT/USD"]
[270, {"a": [["11720.80000", "0.75800000", "1596666850.512768"]], "c": "1713204420"}, "book-100", "XBT/USD"]
[270, {"b": [["11671.50000", "5.70000000", "1596666850.530687"]], "c": "2352489470"}, "book-100", "XBT/USD"]
[270, {"a": [["11677.60000", "0.00000000", "1596666850.535872"], ["11722.10000", "7.70000000", "1596666696.315517", "r"]], "c": "2352489470"}, "book-100", "XBT/USD"]
[270, {"a": [["11677.40000", "0.00000000", "1596666850.538418"], ["11722.20000", "3.01549629", "1596666746.821117", "r"]], "c": "3316865601"}, "book-100", "XBT/USD"]
[270, {"a": [["11679.60000", "0.09800000", "1596666850.575506"]], "c": "3316865601"}, "book-100", "XBT/USD"]
[270, {"b": [["11671.50000", "0.50000000", "1596666850.595074"]], "c": "2216926754"}, "book-100", "XBT/USD"]
[270, {"a": [["11683.90000", "2.68774066", "1596666850.608823"]], "c": "2216926754"}, "book-100", "XBT/USD"]
[270, {"a": [["11674.20000", "0.64246792", "1596666850.612252"]], "c": "227103877"}, "book-100", "XBT/USD"]
[270, {"b": [["11670.70000", "0.64246792", "1596666850.613333"]], "c": "1375744128"}, "book-100", "XBT/USD"]
[270, {"b": [["11671.40000", "0.64240641", "1596666850.613598"]], "c": "2824312548"}, "book-100", "XBT/USD"]
[270, {"b": [["11671.50000", "1.14240641", "1596666850.614595"]], "c": "1895660194"}, "book-100", "XBT/USD"]
[270, {"a": [["11675.00000", "0.66071089", "1596666850.614832"]], "c": "2283131236"}, "book-100", "XBT/USD"]
[270, {"a": [["11676.30000", "0.64243566", "1596666850.616952"]], "c": "1289532721"}, "book-100", "XBT/USD"]
[270, {"a": [["11693.40000", "12.38763813", "1596666850.617531"]], "c": "1289532721"}, "book-100", "XBT/USD"]
[270, {"a": [["11687.00000", "0.85666786", "1596666850.623403"]], "c": "1289532721"}, "book-100", "XBT/USD"]
[270, {"b": [["11667.60000", "1.11486152", "1596666850.623538"]], "c": "1289532721"}, "book-100", "XBT/USD"]
[270, {"b": [["11670.90000", "0.50000000", "1596666850.629934"]], "c": "972082682"}, "book-100", "XBT/USD"]
[270, {"b": [["11663.80000", "0.00000000", "1596666850.665059"], ["11616.00000", "0.17085000", "1596666842.228991", "r"]], "c": "972082682"}, "book-100", "XBT/USD"]
[270, {"b": [["11667.50000", "5.13366786", "1596666850.676063"]], "c": "972082682"}, "book-100", "XBT/USD"]
[270, {"b": [["11671.50000", "1.95742641", "1596666850.679548"]], "c": "2749885143"}, "book-100", "XBT/USD"]
[270, {"b": [["11671.00000", "0.00000000", "1596666850.701987"], ["11615.60000", "0.20000000", "1596666623.308321", "r"]], "c": "3795580883"}, "book-100", "XBT/USD"]
[270, {"a": [["11674.10000", "0.05313798", "1596666850.745607"]], "c": "4214545968"}, "book-100", "XBT/USD"]
[270, {"a": [["11674.90000", "0.00000000", "1596666850.746710"], ["11720.80000", "0.75800000", "1596666850.512768", "r"]], "c": "1839652123"}, "book-100", "XBT/USD"]
[270, {"b": [["11671.50000", "1.96542641", "1596666850.748495"]], "c": "4191930234"}, "book-100", "XBT/USD"]
[270, {"a": [["11676.90000", "0.00000000", "1596666850.771892"], ["11721.00000", "0.97885000", "1596666831.502501", "r"]], "c": "194399532"}, "book-100", "XBT/USD"]
[270, {"b": [["11667.60000", "0.85658088", "1596666850.803755"]], "c": "194399532"}, "book-100", "XBT/USD"]
[270, {"b": [["11670.90000", "0.00000000", "1596666850.813473"], ["11614.80000", "3.08717099", "1596666746.879208", "r"]], "c": "3587768773"}, "book-100", "XBT/USD"]
[270, {"b": [["11670.80000", "0.25821696", "1596666850.901487"]], "c": "2907275084"}, "book-100", "XBT/USD"]
[270, {"b": [["11670.40000", "0.50000000", "1596666850.955682"]], "c": "3166936430"}, "book-100", "XBT/USD"]
[270, {"a": [["11683.10000", "0.00000000", "1596666850.970713"], ["11721.70000", "2.47549182", "1596666772.357495", "r"]], "c": "3166936430"}, "book-100", "XBT/USD"]
[270, {"b": [["11663.70000", "0.00000000", "1596666850.971604"], ["11615.60000", "0.20000000", "1596666623.308321", "r"]], "c": "3166936430"}, "book-100", "XBT/USD"]
[270, {"b": [["11618.30000", "1.51500000", "1596666850.975183"]], "c": "3166936430"}, "book-100", "XBT/USD"]
[270, {"b": [["11671.50000", "2.45627011", "1596666851.020357"]], "c": "29101297"}, "book-100", "XBT/USD"]
[270, {"a": [["11705.20000", "0.00000000", "1596666851.097092"], ["11722.10000", "7.70000000", "1596666696.315517", "r"]], "c": "29101297"}, "book-100", "XBT/USD"]
[270, {"a": [["11683.90000", "4.18774066", "1596666851.120232"]], "c": "29101297"}, "book-100", "XBT/USD"]
[270, {"b": [["11668.20000", "1.50000000", "1596666851.120310"]], "c": "29101297"}, "book-100", "XBT/USD"]
[270, {"b": [["11670.50000", "4.27700000", "1596666851.197765"]], "c": "1294861584"}, "book-100", "XBT/USD"]
[270, {"a": [["11694.20000", "0.00000000", "1596666851.197968"], ["11722.20000", "3.01549629", "1596666746.821117", "r"]], "c": "1294861584"}, "book-100", "XBT/USD"]
[270, {"b": [["11668.80000", "0.00000000", "1596666851.401445"], ["11616.70000", "2.01459953", "1596666777.763006", "r"]], "c": "1294861584"}, "book-100", "XBT/USD"]
[270, {"b": [["11667.50000", "0.85666786", "1596666851.407523"]], "c": "1294861584"}, "book-100", "XBT/USD"]
[270, {"a": [["11674.20000", "0.00000000", "1596666851.429545"], ["11722.60000", "23.57900000", "1596666806.604937", "r"]], "c": "2757117840"}, "book-100", "XBT/USD"]
[270, {"a": [["11700.60000", "2.37479942", "1596666851.430629"]], "c": "2757117840"}, "book-100", "XBT/USD"]
[270, {"b": [["11663.30000", "0.00000000", "1596666851.430706"], ["11616.00000", "0.17085000", "1596666842.228991", "r"]], "c": "2757117840"}, "book-100", "XBT/USD"]
[270, {"a": [["11677.00000", "0.00000000", "1596666851.432392"], ["11722.60000", "23.57900000", "1596666806.604937", "r"]], "c": "901115677"}, "book-100", "XBT/USD"]
[270, {"a": [["11689.00000", "0.70990184", "1596666851.454069"]], "c": "901115677"}, "book-100", "XBT/USD"]
[270, {"a": [["11685.60000", "6.35570724", "1596666851.461664"]], "c": "901115677"}, "book-100", "XBT/USD"]
[270, {"a": [["11685.90000", "0.70882361", "1596666851.465884"]], "c": "901115677"}, "book-100", "XBT/USD"]
[270, {"b": [["11658.00000", "0.38000000", "1596666851.469454"]], "c": "901115677"}, "book-100", "XBT/USD"]
[270, {"a": [["11676.40000", "4.53823462", "1596666851.475646"]], "c": "1877535653"}, "book-100", "XBT/USD"]
[270, {"a": [["11691.30000", "1.41952436", "1596666851.484063"]], "c": "1877535653"}, "book-100", "XBT/USD"]
[270, {"b": [["11631.60000", "2.81964866", "1596666851.487838"]], "c": "1877535653"}, "book-100", "XBT/USD"]
[270, {"a": [["11689.60000", "0.38000000", "1596666851.488933"]], "c": "1877535653"}, "book-100", "XBT/USD"]
[270, {"a": [["11676.50000", "0.00000000", "1596666851.509101"], ["11722.10000", "7.70000000", "1596666696.315517", "r"]], "c": "1902422889"}, "book-100", "XBT/USD"]
[270, {"a": [["11674.10000", "0.00000000", "1596666851.557666"], ["11722.20000", "3.01549629", "1596666746.821117", "r"]], "c": "2371151159"}, "book-100", "XBT/USD"]
[270, {"a": [["11674.90000", "0.05313798", "1596666851.558072"]], "c": "96077065"}, "book-100", "XBT/USD"]
[270, {"a": [["11676.40000", "0.25823462", "1596666851.620932"]], "c": "1187246612"}, "book-100", "XBT/USD"]
[270, {"a": [["11676.40000", "0.00000000", "1596666851.783330"], ["11722.20000", "3.01549629", "1596666746.821117", "r"]], "c": "2498539738"}, "book-100", "XBT/USD"]
[270, {"a": [["11677.40000", "0.25819720", "1596666851.796456"]], "c": "3014227801"}, "book-100", "XBT/USD"]
[270, {"b": [["11666.50000", "9.99987003", "1596666851.800197"]], "c": "3014227801"}, "book-100", "XBT/USD"]
[270, {"a": [["11674.90000", "0.00000000", "1596666851.822897"], ["11722.20000", "3.01549629", "1596666746.821117", "r"]], "c": "4003343514"}, "book-100", "XBT/USD"]
[270, {"a": [["11671.60000", "0.14728534", "1596666851.825776"]], "c": "3386265855"}, "book-100", "XBT/USD"]
[270, {"a": [["11677.70000", "4.27900000", "1596666851.835155"]], "c": "3855353927"}, "book-100", "XBT/USD"]
[270, {"a": [["11687.10000", "0.00000000", "1596666851.840188"], ["11722.20000", "3.01549629", "1596666746.821117", "r"]], "c": "3855353927"}, "book-100", "XBT/USD"]
[270, {"b": [["11625.20000", "4.29692836", "1596666851.841075"]], "c": "3855353927"}, "book-100", "XBT/USD"]
[270, {"b": [["11620.60000", "0.00000000", "1596666851.842418"], ["11617.40000", "0.75800000", "1596666775.482846", "r"]], "c": "3855353927"}, "book-100", "XBT/USD"]
[270, {"a": [["11688.70000", "1.04849143", "1596666851.856630"]], "c": "3855353927"}, "book-100", "XBT/USD"]
[270, {"b": [["11670.60000", "0.01490397", "1596666852.069581"]], "c": "1230363454"}, "book-100", "XBT/USD"]
[270, {"a": [["11680.10000", "0.01490397", "1596666852.070282"]], "c": "1230363454"}, "book-100", "XBT/USD"]
[270, {"b": [["11665.00000", "0.07451985", "1596666852.128665"]], "c": "1230363454"}, "book-100", "XBT/USD"]
[270, {"a": [["11684.30000", "0.00000000", "1596666852.170427"], ["11722.20000", "3.01549629", "1596666746.821117", "r"]], "c": "1230363454"}, "book-100", "XBT/USD"]
[270, {"b": [["11659.10000", "0.17884763", "1596666852.186964"]], "c": "1230363454"}, "book-100", "XBT/USD"]
[270, {"a": [["11682.50000", "0.95451985", "1596666852.187058"]], "c": "1230363454"}, "book-100", "XBT/USD"]
[270, {"b": [["11642.30000", "21.00000000", "1596666852.193550"]], "c": "1230363454"}, "book-100", "XBT/USD"]
[270, {"b": [["11652.90000", "1.00000000", "1596666852.225827"]], "c": "1230363454"}, "book-100", "XBT/USD"]
[270, {"b": [["11666.20000", "15.66300000", "1596666852.229299"]], "c": "1230363454"}, "book-100", "XBT/USD"]
[270, {"a": [["11687.00000", "1.55583756", "1596666852.231498"]], "c": "1230363454"}, "book-100", "XBT/USD"]
[270, {"a": [["11684.70000", "0.17884760", "1596666852.249785"]], "c": "1230363454"}, "book-100", "XBT/USD"]
[270, {"a": [["11671.60000", "0.01960126", "1596666852.250472"]], "c": "551342864"}, "book-100", "XBT/USD"]
[270, {"b": [["11668.30000", "0.00000000", "1596666852.329627"], ["11618.90000", "0.48560000", "1596666782.022335", "r"]], "c": "551342864"}, "book-100", "XBT/USD"]
[270, {"b": [["11652.90000", "0.00000000", "1596666852.407118"], ["11618.30000", "1.51500000", "1596666850.975183", "r"]], "c": "551342864"}, "book-100", "XBT/USD"]
[270, {"a": [["11685.60000", "6.01756039", "1596666852.478947"]], "c": "551342864"}, "book-100", "XBT/USD"]
[270, {"a": [["11691.30000", "0.00000000", "1596666852.491858"], ["11722.20000", "3.01549629", "1596666746.821117", "r"]], "c": "551342864"}, "book-100", "XBT/USD"]
[270, {"b": [["11654.40000", "0.00000000", "1596666852.493401"], ["11617.50000", "2.49761864", "1596666811.445738", "r"]], "c": "551342864"}, "book-100", "XBT/USD"]
[270, {"a": [["11692.90000", "0.00000000", "1596666852.494138"], ["11722.60000", "23.57900000", "1596666806.604937", "r"]], "c": "551342864"}, "book-100", "XBT/USD"]
[270, {"a": [["11694.50000", "0.00000000", "1596666852.494423"], ["11724.00000", "0.17085000", "1596666848.446099", "r"]], "c": "551342864"}, "book-100", "XBT/USD"]
[270, {"a": [["11696.40000", "0.34842155", "1596666852.501899"]], "c": "551342864"}, "book-100", "XBT/USD"]
[270, {"a": [["11689.00000", "0.00000000", "1596666852.505279"], ["11725.40000", "2.25560036", "1596666850.228085", "r"]], "c": "551342864"}, "book-100", "XBT/USD"]
[270, {"a": [["11682.50000", "0.07451985", "1596666852.551229"]], "c": "551342864"}, "book-100", "XBT/USD"]
[270, {"a": [["11680.50000", "0.00000000", "1596666852.570394"], ["11726.30000", "1.78600000", "1596666787.006488", "r"]], "c": "551342864"}, "book-100", "XBT/USD"]
[270, {"b": [["11666.10000", "0.71187000", "1596666852.596282"]], "c": "551342864"}, "book-100", "XBT/USD"]
[270, {"a": [["11695.60000", "0.43900000", "1596666852.631214"]], "c": "551342864"}, "book-100", "XBT/USD"]
[270, {"a": [["11708.50000", "6.38248884", "1596666852.675408"]], "c": "551342864"}, "book-100", "XBT/USD"]
[270, {"b": [["11669.70000", "0.00000000", "1596666852.676860"], ["11617.40000", "0.75800000", "1596666775.482846", "r"]], "c": "3989385073"}, "book-100", "XBT/USD"]
[270, {"b": [["11666.20000", "16.66300000", "1596666852.699043"]], "c": "3989385073"}, "book-100", "XBT/USD"]
[270, {"a": [["11682.40000", "0.45370551", "1596666852.775696"]], "c": "3989385073"}, "book-100", "XBT/USD"]
[270, {"a": [["11691.20000", "1.41953650", "1596666852.794965"]], "c": "3989385073"}, "book-100", "XBT/USD"]
[270, {"a": [["11688.80000", "0.70991398", "1596666852.798509"]], "c": "3989385073"}, "book-100", "XBT/USD"]
[270, {"a": [["11694.60000", "0.89768593", "1596666852.828678"]], "c": "3989385073"}, "book-100", "XBT/USD"]
[270, {"a": [["11691.10000", "0.89795467", "1596666852.848663"]], "c": "3989385073"}, "book-100", "XBT/USD"]
[270, {"b": [["11668.20000", "0.00000000", "1596666852.855815"], ["11616.70000", "2.01459953", "1596666777.763006", "r"]], "c": "3989385073"}, "book-100", "XBT/USD"]
[270, {"b": [["11670.60000", "0.00000000", "1596666852.870717"], ["11616.00000", "0.17085000", "1596666842.228991", "r"]], "c": "766759633"}, "book-100", "XBT/USD"]
[270, {"a": [["11693.30000", "0.49637860", "1596666852.881728"]], "c": "766759633"}, "book-100", "XBT/USD"]
[270, {"b": [["11670.00000", "0.04000000", "1596666852.917766"]], "c": "1885192862"}, "book-100", "XBT/USD"]
[270, {"a": [["11683.30000", "0.68471899", "1596666852.958270"]], "c": "1885192862"}, "book-100", "XBT/USD"]
[270, {"b": [["11670.80000", "0.00000000", "1596666853.003176"], ["11616.00000", "0.17085000", "1596666842.228991", "r"]], "c": "2665974150"}, "book-100", "XBT/USD"]
[270, {"b": [["11666.10000", "2.21187000", "1596666853.018019"]], "c": "2665974150"}, "book-100", "XBT/USD"]
[270, {"a": [["11677.80000", "0.00000000", "1596666853.034563"], ["11721.00000", "0.97885000", "1596666831.502501", "r"]], "c": "2164803842"}, "book-100", "XBT/USD"]
[270, {"b": [["11671.50000", "2.71446727", "1596666853.080754"]], "c": "3397886511"}, "book-100", "XBT/USD"]
[270, {"a": [["11685.40000", "0.33815264", "1596666853.147910"]], "c": "3397886511"}, "book-100", "XBT/USD"]
[270, {"a": [["11677.40000", "0.90057877", "1596666853.205221"]], "c": "539441530"}, "book-100", "XBT/USD"]
[270, {"b": [["11669.80000", "0.85650876", "1596666853.205323"]], "c": "3238375961"}, "book-100", "XBT/USD"]
[270, {"a": [["11689.60000", "1.23650876", "1596666853.207487"]], "c": "3238375961"}, "book-100", "XBT/USD"]
[270, {"a": [["11689.70000", "0.85650876", "1596666853.208180"]], "c": "3238375961"}, "book-100", "XBT/USD"]
[270, {"a": [["11677.30000", "0.25000000", "1596666853.238831"]], "c": "531672670"}, "book-100", "XBT/USD"]
[270, {"a": [["11677.60000", "1.70100000", "1596666853.565982"]], "c": "4050262056"}, "book-100", "XBT/USD"]
[270, {"a": [["11677.40000", "0.64238157", "1596666853.871066"]], "c": "1104357010"}, "book-100", "XBT/USD"]
[270, {"b": [["11631.00000", "0.17085000", "1596666853.947044"]], "c": "1104357010"}, "book-100", "XBT/USD"]
[270, {"a": [["11677.60000", "0.00000000", "1596666854.010512"], ["11719.60000", "2.98021891", "1596666782.974175", "r"]], "c": "3219794637"}, "book-100", "XBT/USD"]
[270, {"a": [["11671.60000", "0.00000000", "1596666854.044226"], ["11719.70000", "3.50602221", "1596666789.365232", "r"]], "c": "609003895"}, "book-100", "XBT/USD"]
[270, {"b": [["11671.50000", "2.21446727", "1596666854.108237"]], "c": "2332551524"}, "book-100", "XBT/USD"]
[270, {"b": [["11666.10000", "2.00000000", "1596666854.112840"]], "c": "2332551524"}, "book-100", "XBT/USD"]
[270, {"a": [["11677.20000", "0.25819493", "1596666854.545667"]], "c": "1443965574"}, "book-100", "XBT/USD"]
[270, {"a": [["11674.90000", "0.05313798", "1596666854.547947"]], "c": "1278727212"}, "book-100", "XBT/USD"]
[270, {"a": [["11692.20000", "0.00000000", "1596666854.645708"], ["11719.60000", "2.98021891", "1596666782.974175", "r"]], "c": "1278727212"}, "book-100", "XBT/USD"]
[270, {"b": [["11630.20000", "0.00000000", "1596666854.727759"], ["11616.70000", "2.01459953", "1596666777.763006", "r"]], "c": "1278727212"}, "book-100", "XBT/USD"]
[270, {"b": [["11635.20000", "6.62076804", "1596666854.810830"]], "c": "1278727212"}, "book-100", "XBT/USD"]
[270, {"a": [["11695.70000", "6.55669579", "1596666854.892117"]], "c": "1278727212"}, "book-100", "XBT/USD"]
[270, {"a": [["11683.30000", "0.00000000", "1596666854.986724"], ["11719.60000", "2.98021891", "1596666782.974175", "r"]], "c": "1278727212"}, "book-100", "XBT/USD"]
[271, [["11671.50000", "0.25000000", "1596666855.236098", "s", "m", ""]], "trade", "XBT/USD"]
[270, {"b": [["11671.50000", "1.96446727", "1596666855.236098"]], "c": "651639639"}, "book-100", "XBT/USD"]
[270, {"b": [["11671.50000", "2.18946727", "1596666855.256841"]], "c": "1408756731"}, "book-100", "XBT/USD"]
[270, {"b": [["11671.60000", "0.50000000", "1596666855.258500"]], "c": "2471110802"}, "book-100", "XBT/USD"]
[270, {"a": [["11692.10000", "0.00000000", "1596666855.264728"], ["11719.70000", "3.50602221", "1596666789.365232", "r"]], "c": "2471110802"}, "book-100", "XBT/USD"]
[270, {"b": [["11671.60000", "5.70000000", "1596666855.332946"]], "c": "3886221273"}, "book-100", "XBT/USD"]
[270, {"b": [["11671.50000", "1.93127011", "1596666855.351012"]], "c": "2183211218"}, "book-100", "XBT/USD"]
[270, {"b": [["11671.60000", "0.50000000", "1596666855.394684"]], "c": "4140304281"}, "book-100", "XBT/USD"]
[270, {"a": [["11697.90000", "0.57740848", "1596666855.449836"]], "c": "4140304281"}, "book-100", "XBT/USD"]
[270, {"a": [["11685.50000", "0.49755891", "1596666855.452308"]], "c": "4140304281"}, "book-100", "XBT/USD"]
[270, {"b": [["11671.60000", "0.75819020", "1596666855.453885"]], "c": "1787805327"}, "book-100", "XBT/USD"]
[270, {"b": [["11671.50000", "1.92327011", "1596666855.460676"]], "c": "2866148039"}, "book-100", "XBT/USD"]
[270, {"b": [["11666.50000", "0.00000000", "1596666855.732163"], ["11617.40000", "0.75800000", "1596666775.482846", "r"]], "c": "2866148039"}, "book-100", "XBT/USD"]
[270, {"a": [["11685.10000", "0.88000000", "1596666855.759154"]], "c": "2866148039"}, "book-100", "XBT/USD"]
[270, {"b": [["11670.40000", "0.00000000", "1596666855.920470"], ["11616.70000", "2.01459953", "1596666777.763006", "r"]], "c": "308738240"}, "book-100", "XBT/USD"]
[270, {"a": [["11692.20000", "0.00438186", "1596666855.922637"]], "c": "308738240"}, "book-100", "XBT/USD"]
[270, {"b": [["11651.20000", "0.00429763", "1596666855.924666"]], "c": "308738240"}, "book-100", "XBT/USD"]
[270, {"a": [["11677.30000", "0.00000000", "1596666855.926487"], ["11718.40000", "0.48360000", "1596666846.374528", "r"]], "c": "1204166088"}, "book-100", "XBT/USD"]
[270, {"a": [["11680.60000", "2.68536054", "1596666856.024038"]], "c": "1204166088"}, "book-100", "XBT/USD"]
[270, {"a": [["11704.60000", "2.30891053", "1596666856.061039"]], "c": "1204166088"}, "book-100", "XBT/USD"]
[270, {"a": [["11676.20000", "0.25000000", "1596666856.095110"]], "c": "286919282"}, "book-100", "XBT/USD"]
[270, {"b": [["11669.00000", "0.50000000", "1596666856.097945"]], "c": "903665223"}, "book-100", "XBT/USD"]
[270, {"a": [["11675.30000", "0.00000000", "1596666856.138136"], ["11718.40000", "0.48360000", "1596666846.374528", "r"]], "c": "1294548940"}, "book-100", "XBT/USD"]
[270, {"a": [["11683.90000", "2.20560000", "1596666856.174091"]], "c": "1294548940"}, "book-100", "XBT/USD"]
[270, {"b": [["11659.00000", "0.50000000", "1596666856.297129"]], "c": "1294548940"}, "book-100", "XBT/USD"]
[270, {"b": [["11671.50000", "1.10825011", "1596666856.299489"]], "c": "1067935408"}, "book-100", "XBT/USD"]
[270, {"b": [["11664.00000", "1.90063191", "1596666856.330181"]], "c": "1067935408"}, "book-100", "XBT/USD"]
[270, {"a": [["11674.10000", "0.82767866", "1596666856.378141"]], "c": "1454250095"}, "book-100", "XBT/USD"]
[270, {"b": [["11668.90000", "0.00000000", "1596666856.437621"], ["11617.50000", "2.49761864", "1596666811.445738", "r"]], "c": "1454250095"}, "book-100", "XBT/USD"]
[270, {"b": [["11667.30000", "0.08569421", "1596666856.464471"]], "c": "1454250095"}, "book-100", "XBT/USD"]
[270, {"a": [["11685.10000", "0.00000000", "1596666856.506620"], ["11718.40000", "0.48360000", "1596666846.374528", "r"]], "c": "1454250095"}, "book-100", "XBT/USD"]
[270, {"a": [["11674.00000", "0.05313798", "1596666856.515680"]], "c": "737471118"}, "book-100", "XBT/USD"]
[270, {"a": [["11674.90000", "0.00000000", "1596666856.515762"], ["11718.40000", "0.48360000", "1596666846.374528", "r"]], "c": "3664883353"}, "book-100", "XBT/USD"]
[270, {"a": [["11677.00000", "0.10300000", "1596666856.643402"]], "c": "2344862526"}, "book-100", "XBT/USD"]
[270, {"a": [["11677.40000", "0.00000000", "1596666856.664647"], ["11718.40000", "0.48360000", "1596666846.374528", "r"]], "c": "2091178736"}, "book-100", "XBT/USD"]
[270, {"a": [["11708.00000", "9.30763305", "1596666856.672214"]], "c": "2091178736"}, "book-100", "XBT/USD"]
[270, {"a": [["11675.40000", "0.64242109", "1596666856.721309"]], "c": "3905412814"}, "book-100", "XBT/USD"]
[270, {"a": [["11677.20000", "0.00000000", "1596666856.740288"], ["11718.40000", "0.48360000", "1596666846.374528", "r"]], "c": "2707276692"}, "book-100", "XBT/USD"]
[270, {"a": [["11676.90000", "0.25820460", "1596666856.835466"]], "c": "1309684442"}, "book-100", "XBT/USD"]
[270, {"b": [["11658.80000", "0.00000000", "1596666856.837636"], ["11617.40000", "0.75800000", "1596666775.482846", "r"]], "c": "1309684442"}, "book-100", "XBT/USD"]
[270, {"b": [["11631.00000", "0.00000000", "1596666856.901378"], ["11616.70000", "2.01459953", "1596666777.763006", "r"]], "c": "1309684442"}, "book-100", "XBT/USD"]
[270, {"a": [["11683.90000", "0.70560000", "1596666856.972973"]], "c": "1309684442"}, "book-100", "XBT/USD"]
[270, {"a": [["11681.80000", "1.50000000", "1596666857.128222"]], "c": "1309684442"}, "book-100", "XBT/USD"]
[270, {"b": [["11651.20000", "0.00000000", "1596666857.131651"], ["11616.00000", "0.17085000", "1596666842.228991", "r"]], "c": "1309684442"}, "book-100", "XBT/USD"]
[270, {"b": [["11670.10000", "0.00000000", "1596666857.207491"], ["11615.60000", "0.20000000", "1596666623.308321", "r"]], "c": "1637798579"}, "book-100", "XBT/USD"]
[270, {"b": [["11653.50000", "0.00441854", "1596666857.319680"]], "c": "1637798579"}, "book-100", "XBT/USD"]
[270, {"b": [["11666.10000", "0.50000000", "1596666857.353803"]], "c": "1637798579"}, "book-100", "XBT/USD"]
[270, {"a": [["11676.20000", "4.52400000", "1596666857.448715"]], "c": "1973049640"}, "book-100", "XBT/USD"]
[270, {"a": [["11680.60000", "2.18536054", "1596666857.483233"]], "c": "1973049640"}, "book-100", "XBT/USD"]
[270, {"a": [["11686.30000", "0.50000000", "1596666857.500818"]], "c": "1973049640"}, "book-100", "XBT/USD"]
[270, {"a": [["11684.40000", "0.00000000", "1596666857.520199"], ["11715.30000", "6.10000000", "1596666635.445451", "r"]], "c": "1973049640"}, "book-100", "XBT/USD"]
[270, {"b": [["11653.00000", "2.00876997", "1596666857.520426"]], "c": "1973049640"}, "book-100", "XBT/USD"]
[270, {"b": [["11671.60000", "0.50000000", "1596666857.524004"]], "c": "2178067392"}, "book-100", "XBT/USD"]
[270, {"a": [["11685.40000", "0.00000000", "1596666857.525221"], ["11717.80000", "1.99812614", "1596666759.535617", "r"]], "c": "2178067392"}, "book-100", "XBT/USD"]
[270, {"a": [["11688.80000", "0.00000000", "1596666857.527015"], ["11718.40000", "0.48360000", "1596666846.374528", "r"]], "c": "2178067392"}, "book-100", "XBT/USD"]
[270, {"a": [["11698.90000", "0.00000000", "1596666857.528333"], ["11718.50000", "24.30000000", "1596666641.380470", "r"]], "c": "2178067392"}, "book-100", "XBT/USD"]
[270, {"a": [["11691.90000", "0.00000000", "1596666857.531826"], ["11719.60000", "2.98021891", "1596666782.974175", "r"]], "c": "2178067392"}, "book-100", "XBT/USD"]
[270, {"a": [["11704.60000", "0.00000000", "1596666857.587948"], ["11719.70000", "3.50602221", "1596666789.365232", "r"]], "c": "2178067392"}, "book-100", "XBT/USD"]
[270, {"b": [["11659.30000", "1.42342037", "1596666857.604819"]], "c": "2178067392"}, "book-100", "XBT/USD"]
[270, {"b": [["11655.80000", "0.00000000", "1596666857.611036"], ["11615.60000", "0.20000000", "1596666623.308321", "r"]], "c": "2178067392"}, "book-100", "XBT/USD"]
[270, {"b": [["11670.80000", "0.25820609", "1596666857.629782"]], "c": "82086712"}, "book-100", "XBT/USD"]
[270, {"b": [["11659.20000", "0.00000000", "1596666857.671395"], ["11615.60000", "0.20000000", "1596666623.308321", "r"]], "c": "82086712"}, "book-100", "XBT/USD"]
[270, {"b": [["11641.20000", "2.00000000", "1596666857.672388"]], "c": "82086712"}, "book-100", "XBT/USD"]
[270, {"b": [["11655.70000", "0.00000000", "1596666857.675119"], ["11614.80000", "3.08717099", "1596666746.879208", "r"]], "c": "82086712"}, "book-100", "XBT/USD"]
[270, {"b": [["11623.50000", "0.00000000", "1596666857.676884"], ["11613.60000", "3.55198121", "1596666780.634357", "r"]], "c": "82086712"}, "book-100", "XBT/USD"]
[270, {"a": [["11687.60000", "0.33803202", "1596666857.749602"]], "c": "82086712"}, "book-100", "XBT/USD"]
[270, {"b": [["11658.60000", "0.34949229", "1596666857.813922"]], "c": "82086712"}, "book-100", "XBT/USD"]
[270, {"a": [["11687.50000", "0.11091258", "1596666857.815504"]], "c": "82086712"}, "book-100", "XBT/USD"]
[270, {"b": [["11656.80000", "0.00000000", "1596666857.843292"], ["11613.60000", "3.55198121", "1596666780.634357", "r"]], "c": "82086712"}, "book-100", "XBT/USD"]
[270, {"a": [["11675.40000", "0.00000000", "1596666857.845497"], ["11719.60000", "2.98021891", "1596666782.974175", "r"]], "c": "1566137078"}, "book-100", "XBT/USD"]
[270, {"b": [["11653.50000", "0.00000000", "1596666857.888365"], ["11613.00000", "0.17085000", "1596666803.224745", "r"]], "c": "1566137078"}, "book-100", "XBT/USD"]
[270, {"a": [["11692.20000", "0.00000000", "1596666857.888955"], ["11719.70000", "3.50602221", "1596666789.365232", "r"]], "c": "1566137078"}, "book-100", "XBT/USD"]
[270, {"b": [["11667.80000", "1.50000000", "1596666857.943434"]], "c": "1566137078"}, "book-100", "XBT/USD"]
[270, {"a": [["11676.30000", "0.00000000", "1596666857.946570"], ["11720.80000", "0.75800000", "1596666850.512768", "r"]], "c": "3534286160"}, "book-100", "XBT/USD"]
[270, {"a": [["11685.50000", "0.00000000", "1596666857.947411"], ["11721.00000", "0.80800000", "1596666854.976031", "r"]], "c": "3534286160"}, "book-100", "XBT/USD"]
[270, {"a": [["11689.70000", "0.00000000", "1596666857.947947"], ["11721.70000", "2.47549182", "1596666772.357495", "r"]], "c": "3534286160"}, "book-100", "XBT/USD"]
[270, {"b": [["11646.80000", "0.90124687", "1596666857.958675"]], "c": "3534286160"}, "book-100", "XBT/USD"]
[270, {"a": [["11691.00000", "0.70966080", "1596666857.958908"]], "c": "3534286160"}, "book-100", "XBT/USD"]
[270, {"b": [["11632.90000", "0.90232376", "1596666857.959009"]], "c": "3534286160"}, "book-100", "XBT/USD"]
[270, {"b": [["11662.00000", "0.24956457", "1596666857.959423"]], "c": "3534286160"}, "book-100", "XBT/USD"]
[270, {"b": [["11668.70000", "1.11047094", "1596666857.960239"]], "c": "3534286160"}, "book-100", "XBT/USD"]
[270, {"a": [["11677.70000", "0.00000000", "1596666857.960525"], ["11721.70000", "2.47549182", "1596666772.357495", "r"]], "c": "969332708"}, "book-100", "XBT/USD"]
[270, {"b": [["11661.90000", "1.61163144", "1596666857.969036"]], "c": "969332708"}, "book-100", "XBT/USD"]
[270, {"b": [["11658.40000", "0.90035014", "1596666857.971610"]], "c": "969332708"}, "book-100", "XBT/USD"]
[270, {"b": [["11616.70000", "0.00000000", "1596666858.031250"], ["11616.00000", "0.17085000", "1596666842.228991", "r"]], "c": "969332708"}, "book-100", "XBT/USD"]
[270, {"a": [["11697.90000", "0.00000000", "1596666858.130416"], ["11722.10000", "7.70000000", "1596666696.315517", "r"]], "c": "969332708"}, "book-100", "XBT/USD"]
[270, {"a": [["11681.70000", "0.48016283", "1596666858.130835"]], "c": "969332708"}, "book-100", "XBT/USD"]
[270, {"b": [["11659.40000", "3.53772521", "1596666858.198555"]], "c": "969332708"}, "book-100", "XBT/USD"]
[270, {"a": [["11699.00000", "2.00115282", "1596666858.214040"]], "c": "969332708"}, "book-100", "XBT/USD"]
[270, {"b": [["11665.30000", "0.00000000", "1596666858.233641"], ["11616.00000", "0.17085000", "1596666842.228991", "r"]], "c": "969332708"}, "book-100", "XBT/USD"]
[270, {"b": [["11661.90000", "0.90007993", "1596666858.238218"]], "c": "969332708"}, "book-100", "XBT/USD"]
[270, {"b": [["11659.30000", "0.00000000", "1596666858.239051"], ["11615.60000", "0.20000000", "1596666623.308321", "r"]], "c": "969332708"}, "book-100", "XBT/USD"]
[270, {"b": [["11656.30000", "0.04218468", "1596666858.239113"]], "c": "969332708"}, "book-100", "XBT/USD"]
[270, {"a": [["11685.50000", "0.45923490", "1596666858.314759"]], "c": "969332708"}, "book-100", "XBT/USD"]
[270, {"a": [["11681.70000", "0.00000000", "1596666858.315219"], ["11721.00000", "0.80800000", "1596666854.976031", "r"]], "c": "969332708"}, "book-100", "XBT/USD"]
[270, {"b": [["11652.50000", "0.00000000", "1596666858.487095"], ["11614.80000", "3.08717099", "1596666746.879208", "r"]], "c": "969332708"}, "book-100", "XBT/USD"]
[270, {"b": [["11626.90000", "2.01356225", "1596666858.488093"]], "c": "969332708"}, "book-100", "XBT/USD"]
[270, {"a": [["11688.70000", "0.30000000", "1596666858.516313"]], "c": "969332708"}, "book-100", "XBT/USD"]
[270, {"b": [["11625.10000", "0.75701265", "1596666858.516566"]], "c": "969332708"}, "book-100", "XBT/USD"]
[270, {"a": [["11691.90000", "0.74844485", "1596666858.517109"]], "c": "969332708"}, "book-100", "XBT/USD"]
[270, {"b": [["11659.00000", "0.99782993", "1596666858.519108"]], "c": "969332708"}, "book-100", "XBT/USD"]
[270, {"b": [["11625.20000", "3.54843693", "1596666858.530403"]], "c": "969332708"}, "book-100", "XBT/USD"]
[270, {"a": [["11687.50000", "0.00000000", "1596666858.537400"], ["11721.00000", "0.80800000", "1596666854.976031", "r"]], "c": "969332708"}, "book-100", "XBT/USD"]
[270, {"a": [["11691.00000", "0.00000000", "1596666858.562928"], ["11721.70000", "2.47549182", "1596666772.357495", "r"]], "c": "969332708"}, "book-100", "XBT/USD"]
[271, [["11671.60000", "0.50000000", "1596666858.567692", "s", "m", ""], ["11671.50000", "0.39240641", "1596666858.572299", "s", "m", ""], ["11671.50000", "0.10759359", "1596666858.574956", "s", "m", ""]], "trade", "XBT/USD"]
[270, {"b": [["11671.60000", "0.00000000", "1596666858.567692"], ["11614.80000", "3.08717099", "1596666746.879208", "r"], ["11671.50000", "0.71584370", "1596666858.572299"], ["11671.50000", "0.60825011", "1596666858.574956"]], "c": "1248818140"}, "book-100", "XBT/USD"]
[270, {"a": [["11687.60000", "0.00000000", "1596666858.578981"], ["11722.10000", "7.70000000", "1596666696.315517", "r"]], "c": "1248818140"}, "book-100", "XBT/USD"]
[270, {"a": [["11685.50000", "0.00000000", "1596666858.579039"], ["11722.20000", "3.01549629", "1596666746.821117", "r"]], "c": "1248818140"}, "book-100", "XBT/USD"]
[270, {"b": [["11666.50000", "9.99987003", "1596666858.716985"]], "c": "1248818140"}, "book-100", "XBT/USD"]
[270, {"b": [["11652.00000", "0.00000000", "1596666858.728724"], ["11614.80000", "3.08717099", "1596666746.879208", "r"]], "c": "1248818140"}, "book-100", "XBT/USD"]
[270, {"a": [["11681.70000", "0.48577277", "1596666858.766352"]], "c": "1248818140"}, "book-100", "XBT/USD"]
[270, {"a": [["11685.50000", "0.11091305", "1596666858.766725"]], "c": "1248818140"}, "book-100", "XBT/USD"]
[270, {"a": [["11682.70000", "0.81382000", "1596666858.777131"]], "c": "1248818140"}, "book-100", "XBT/USD"]
[270, {"a": [["11676.90000", "0.00000000", "1596666858.913079"], ["11722.10000", "7.70000000", "1596666696.315517", "r"]], "c": "2699116984"}, "book-100", "XBT/USD"]
[270, {"b": [["11655.80000", "3.20621495", "1596666858.955677"]], "c": "2699116984"}, "book-100", "XBT/USD"]
[270, {"b": [["11655.30000", "4.00000000", "1596666858.955773"]], "c": "2699116984"}, "book-100", "XBT/USD"]
[270, {"a": [["11676.10000", "0.25821832", "1596666859.013118"]], "c": "679553316"}, "book-100", "XBT/USD"]
[270, {"a": [["11693.30000", "1.08700548", "1596666859.085383"]], "c": "679553316"}, "book-100", "XBT/USD"]
[270, {"a": [["11671.60000", "0.50000000", "1596666859.192523"]], "c": "4294215234"}, "book-100", "XBT/USD"]
[270, {"b": [["11671.50000", "1.25065652", "1596666859.199964"]], "c": "3770880668"}, "book-100", "XBT/USD"]
[270, {"a": [["11674.40000", "0.64241978", "1596666859.200951"]], "c": "3741564603"}, "book-100", "XBT/USD"]
[270, {"a": [["11673.80000", "0.64245940", "1596666859.201058"]], "c": "610823323"}, "book-100", "XBT/USD"]
[270, {"a": [["11676.90000", "0.85661254", "1596666859.203044"]], "c": "1209092899"}, "book-100", "XBT/USD"]
[270, {"b": [["11664.90000", "0.00857000", "1596666859.263740"]], "c": "1209092899"}, "book-100", "XBT/USD"]
[270, {"b": [["11659.10000", "0.00000000", "1596666859.272600"], ["11616.00000", "0.17085000", "1596666842.228991", "r"]], "c": "1209092899"}, "book-100", "XBT/USD"]
[270, {"a": [["11682.50000", "0.00000000", "1596666859.273108"], ["11719.70000", "3.50602221", "1596666789.365232", "r"]], "c": "1209092899"}, "book-100", "XBT/USD"]
[270, {"a": [["11684.70000", "0.00000000", "1596666859.327103"], ["11720.80000", "0.75800000", "1596666850.512768", "r"]], "c": "1209092899"}, "book-100", "XBT/USD"]
[270, {"a": [["11673.70000", "0.02763260", "1596666859.328325"]], "c": "4099409043"}, "book-100", "XBT/USD"]
[270, {"a": [["11674.00000", "0.00000000", "1596666859.333921"], ["11720.80000", "0.75800000", "1596666850.512768", "r"]], "c": "3616539458"}, "book-100", "XBT/USD"]
[270, {"b": [["11628.00000", "2.47005000", "1596666859.444856"]], "c": "3616539458"}, "book-100", "XBT/USD"]
[270, {"b": [["11670.80000", "0.00000000", "1596666860.169036"], ["11615.60000", "0.20000000", "1596666623.308321", "r"]], "c": "3728990391"}, "book-100", "XBT/USD"]
[270, {"b": [["11670.60000", "0.25822343", "1596666860.191274"]], "c": "3522275031"}, "book-100", "XBT/USD"]
[270, {"a": [["11675.00000", "0.01821000", "1596666860.194346"]], "c": "1349378462"}, "book-100", "XBT/USD"]
[270, {"a": [["11672.70000", "0.43500000", "1596666860.213281"]], "c": "3437958254"}, "book-100", "XBT/USD"]
[270, {"b": [["11665.00000", "0.00000000", "1596666860.235254"], ["11615.60000", "0.20000000", "1596666623.308321", "r"]], "c": "3437958254"}, "book-100", "XBT/USD"]
[270, {"b": [["11655.20000", "0.00000000", "1596666860.262713"], ["11614.80000", "3.08717099", "1596666746.879208", "r"]], "c": "3437958254"}, "book-100", "XBT/USD"]
[270, {"a": [["11699.40000", "0.00000000", "1596666860.264489"], ["11720.80000", "0.75800000", "1596666850.512768", "r"]], "c": "3437958254"}, "book-100", "XBT/USD"]
[270, {"b": [["11657.50000", "0.54300000", "1596666860.271133"]], "c": "3437958254"}, "book-100", "XBT/USD"]
[270, {"a": [["11673.70000", "0.00000000", "1596666860.353567"], ["11721.00000", "0.97885000", "1596666860.230720", "r"]], "c": "208314484"}, "book-100", "XBT/USD"]
[270, {"a": [["11700.60000", "0.00000000", "1596666861.399386"], ["11721.70000", "2.47549182", "1596666772.357495", "r"]], "c": "208314484"}, "book-100", "XBT/USD"]
[270, {"a": [["11693.30000", "0.49637860", "1596666861.454905"]], "c": "208314484"}, "book-100", "XBT/USD"]
[270, {"a": [["11684.40000", "0.87000000", "1596666861.479745"]], "c": "208314484"}, "book-100", "XBT/USD"]
[270, {"b": [["11671.40000", "0.00000000", "1596666861.493468"], ["11614.80000", "3.08717099", "1596666746.879208", "r"]], "c": "394125619"}, "book-100", "XBT/USD"]
[270, {"a": [["11677.30000", "0.09621094", "1596666861.495192"]], "c": "394125619"}, "book-100", "XBT/USD"]
[270, {"b": [["11667.80000", "0.00000000", "1596666861.497948"], ["11613.60000", "3.55198121", "1596666780.634357", "r"]], "c": "1999600256"}, "book-100", "XBT/USD"]
[270, {"a": [["11681.70000", "0.00000000", "1596666861.499577"], ["11721.00000", "0.97885000", "1596666860.230720", "r"]], "c": "1999600256"}, "book-100", "XBT/USD"]
[270, {"b": [["11669.00000", "0.00000000", "1596666861.521542"], ["11613.00000", "0.17085000", "1596666803.224745", "r"]], "c": "1573142610"}, "book-100", "XBT/USD"]
[270, {"a": [["11672.60000", "0.00661168", "1596666861.522231"]], "c": "2892197313"}, "book-100", "XBT/USD"]
[270, {"a": [["11708.00000", "7.06128545", "1596666861.528220"]], "c": "2892197313"}, "book-100", "XBT/USD"]
[270, {"a": [["11699.00000", "0.00000000", "1596666861.532476"], ["11721.00000", "0.97885000", "1596666860.230720", "r"]], "c": "2892197313"}, "book-100", "XBT/USD"]
[270, {"a": [["11673.80000", "0.00000000", "1596666861.533192"], ["11721.70000", "2.47549182", "1596666772.357495", "r"]], "c": "1427125272"}, "book-100", "XBT/USD"]
