[270, {"as": [["11655.50000", "0.95920959", "1596667601.787043"], ["11659.00000", "0.64328889", "1596667607.236086"], ["11660.10000", "0.92466000", "1596667611.254156"], ["11661.10000", "0.26275721", "1596667609.959882"], ["11661.30000", "0.85712194", "1596667606.228244"], ["11661.40000", "0.06450000", "1596667606.890951"], ["11661.50000", "4.27800000", "1596667593.984231"], ["11662.60000", "1.82498950", "1596667581.953527"], ["11662.70000", "0.09700000", "1596667586.441771"], ["11663.10000", "0.85761815", "1596667597.196695"], ["11663.30000", "1.74950000", "1596667609.180684"], ["11663.90000", "0.01000000", "1596667608.031330"], ["11664.00000", "0.78675000", "1596667605.187299"], ["11665.10000", "0.43900000", "1596667584.403266"], ["11665.20000", "0.10200000", "1596667608.937613"], ["11665.30000", "0.85750549", "1596667582.046862"], ["11665.50000", "1.50000000", "1596667604.826297"], ["11665.90000", "0.15000000", "1596667611.276182"], ["11666.00000", "0.15000000", "1596667605.912070"], ["11666.10000", "0.24621094", "1596667604.055573"], ["11666.40000", "0.04470007", "1596667610.077312"], ["11666.90000", "0.85755817", "1596667584.390565"], ["11667.00000", "0.13410198", "1596667610.554378"], ["11667.60000", "1.90983129", "1596667582.060368"], ["11668.10000", "0.88144710", "1596667570.125262"], ["11668.20000", "0.69973418", "1596667592.560436"], ["11668.30000", "0.09300000", "1596667546.004395"], ["11668.40000", "5.68010579", "1596667597.326596"], ["11669.10000", "0.08250000", "1596667593.452467"], ["11669.20000", "0.48081489", "1596667587.002511"], ["11669.30000", "0.10000000", "1596667571.763672"], ["11669.60000", "0.11078149", "1596667611.349139"], ["11670.00000", "45.46812939", "1596667581.280914"], ["11670.70000", "0.30000000", "1596667581.331591"], ["11671.20000", "0.10333612", "1596667596.159338"], ["11671.40000", "7.50000000", "1596667606.970186"], ["11671.60000", "0.27100000", "1596667582.302449"], ["11672.10000", "2.00000000", "1596667596.372067"], ["11672.70000", "0.71382863", "1596667583.466103"], ["11673.10000", "0.38000000", "1596667593.473669"], ["11673.20000", "1.03220000", "1596667590.191367"], ["11673.50000", "3.30243668", "1596667598.422909"], ["11675.00000", "0.01821000", "1596667539.553743"], ["11675.10000", "4.02901152", "1596667596.823839"], ["11676.00000", "0.50000000", "1596667594.822995"], ["11676.40000", "6.82260060", "1596667587.469465"], ["11676.50000", "6.50000000", "1596667585.423060"], ["11676.80000", "1.85680000", "1596667594.692473"], ["11677.00000", "1.25907958", "1596667598.423973"], ["11678.40000", "0.74918454", "1596667605.088986"], ["11679.30000", "11.48365860", "1596667599.346517"], ["11679.40000", "3.79705117", "1596667604.239512"], ["11680.40000", "0.00438186", "1596667609.748554"], ["11680.50000", "2.29920000", "1596667254.567453"], ["11680.70000", "0.00300000", "1596667550.233933"], ["11680.80000", "0.30000000", "1596667591.963066"], ["11680.90000", "3.53027518", "1596667596.712301"], ["11681.00000", "0.57306538", "1596667596.321203"], ["11681.20000", "0.02573600", "1596667320.881931"], ["11681.70000", "0.90977150", "1596667598.423181"], ["11681.80000", "0.63355184", "1596667597.252474"], ["11681.90000", "8.00000000", "1596667596.163100"], ["11682.50000", "0.61783923", "1596667610.722435"], ["11682.60000", "3.12017451", "1596667530.933332"], ["11683.90000", "0.99323623", "1596667596.162925"], ["11684.40000", "2.00582747", "1596667596.377230"], ["11685.00000", "0.10000000", "1596667591.953421"], ["11687.30000", "8.20000000", "1596667061.296774"], ["11688.20000", "0.05292020", "1596667586.337764"], ["11688.40000", "0.71100000", "1596667589.481114"], ["11688.70000", "1.80546411", "1596667600.853222"], ["11689.90000", "0.10000000", "1596667326.899060"], ["11690.00000", "0.04000000", "1596667586.146170"], ["11690.30000", "1.50624231", "1596667596.480982"], ["11690.80000", "0.30000000", "1596667519.992612"], ["11690.90000", "2.00000000", "1596667590.248024"], ["11692.30000", "8.50000000", "1596667579.147300"], ["11692.60000", "0.99320000", "1596667568.085607"], ["11693.70000", "10.19784115", "1596667596.384709"], ["11693.80000", "2.00321220", "1596667596.166987"], ["11693.90000", "0.02827293", "1596667589.730706"], ["11694.70000", "2.31356525", "1596667326.967997"], ["11695.30000", "12.08135207", "1596667596.152450"], ["11695.40000", "6.38910319", "1596667560.165057"], ["11695.70000", "1.98477870", "1596667326.842807"], ["11695.90000", "1.95619450", "1596667556.468674"], ["11696.30000", "2.24857993", "1596667603.047777"], ["11698.00000", "6.50000000", "1596667287.541035"], ["11698.50000", "1.16913329", "1596667186.881827"], ["11699.00000", "1.11290000", "1596667575.530209"], ["11699.10000", "7.23721332", "1596667519.616038"], ["11699.90000", "0.10000000", "1596666079.896762"], ["11700.00000", "0.52000000", "1596667297.741607"], ["11700.30000", "0.75800000", "1596667540.971903"], ["11700.60000", "2.00132141", "1596667327.635197"], ["11701.10000", "0.01796445", "1596667535.981575"], ["11704.10000", "8.30000000", "1596667058.485416"], ["11704.60000", "18.00000000", "1596667150.934570"], ["11706.00000", "0.17085000", "1596667592.196118"], ["11706.20000", "0.75800000", "1596666915.495628"]], "bs": [["11655.40000", "2.37178984", "1596667605.910894"], ["11655.30000", "4.92114493", "1596667586.831096"], ["11655.10000", "1.70300000", "1596667609.250748"], ["11654.80000", "0.09621094", "1596667595.303126"], ["11654.40000", "0.85752658", "1596667580.913647"], ["11654.00000", "0.08250000", "1596667593.409169"], ["11653.90000", "4.00000000", "1596667588.141018"], ["11653.80000", "0.04250000", "1596667585.589918"], ["11653.60000", "2.00000000", "1596667582.710213"], ["11652.00000", "0.30000000", "1596667585.629280"], ["11651.70000", "0.09600000", "1596667596.948299"], ["11651.50000", "9.99987003", "1596667609.106749"], ["11651.40000", "0.74068237", "1596667610.994156"], ["11651.30000", "0.16200000", "1596667598.941616"], ["11651.00000", "0.43900000", "1596667599.403250"], ["11650.90000", "0.85788244", "1596667600.357431"], ["11650.70000", "1.50000000", "1596667593.823399"], ["11650.30000", "0.65165123", "1596667610.070859"], ["11650.20000", "0.85802765", "1596667611.267369"], ["11649.10000", "0.10353216", "1596667591.354460"], ["11649.00000", "0.49063268", "1596667596.218234"], ["11648.80000", "0.10200000", "1596667608.697891"], ["11648.60000", "0.04470007", "1596667610.004263"], ["11648.10000", "0.50000000", "1596667566.154431"], ["11647.70000", "0.85817361", "1596667519.129626"], ["11647.00000", "0.24984618", "1596667591.580239"], ["11646.80000", "1.57034573", "1596667610.488058"], ["11646.70000", "1.42254744", "1596667591.854164"], ["11645.10000", "1.01263087", "1596667590.196505"], ["11644.60000", "0.98873000", "1596667583.170225"], ["11644.50000", "6.50000000", "1596667524.426038"], ["11644.40000", "0.30000000", "1596667548.839247"], ["11644.00000", "3.29161002", "1596667591.842656"], ["11643.50000", "0.34988980", "1596667591.583879"], ["11643.20000", "0.27100000", "1596667582.116822"], ["11642.90000", "3.54185800", "1596667590.489891"], ["11642.30000", "0.49838271", "1596667596.314703"], ["11641.70000", "0.89992554", "1596667601.179841"], ["11641.60000", "1.29290525", "1596667593.473580"], ["11641.50000", "1.57671852", "1596667607.204300"], ["11641.00000", "1.21216912", "1596667591.721512"], ["11640.90000", "5.00597313", "1596667592.008564"], ["11640.80000", "7.10111316", "1596667592.894314"], ["11640.40000", "5.40000000", "1596667520.064801"], ["11640.00000", "3.47932253", "1596667603.742286"], ["11639.10000", "2.01331188", "1596667589.817665"], ["11638.60000", "0.99709070", "1596667591.908666"], ["11638.10000", "1.02650000", "1596667605.068810"], ["11637.10000", "3.54362329", "1596667605.012548"], ["11637.00000", "0.91326611", "1596667589.970437"], ["11635.90000", "0.57519440", "1596667590.387760"], ["11635.30000", "2.01396941", "1596667591.490240"], ["11635.10000", "7.30000000", "1596667457.976797"], ["11633.20000", "0.05292380", "1596667554.256572"], ["11632.00000", "0.91365868", "1596667591.830569"], ["11631.90000", "0.90061388", "1596667591.582705"], ["11631.30000", "2.00000000", "1596667578.730227"], ["11631.00000", "2.01259608", "1596667584.548458"], ["11630.90000", "1.11290000", "1596667519.492665"], ["11630.10000", "8.60000000", "1596667416.448898"], ["11629.60000", "3.54642542", "1596667591.885059"], ["11629.40000", "1.51413010", "1596667591.730440"], ["11629.30000", "6.42632243", "1596667592.004715"], ["11629.20000", "7.10819644", "1596667592.899865"], ["11628.30000", "0.10580252", "1596667577.166616"], ["11628.20000", "1.49697372", "1596667591.086802"], ["11627.40000", "1.96769710", "1596667590.192548"], ["11627.00000", "0.49800000", "1596667609.885088"], ["11626.20000", "0.70560000", "1596667297.005277"], ["11625.00000", "0.25000000", "1596667580.295481"], ["11624.40000", "0.02875454", "1596667593.611961"], ["11624.30000", "6.01696172", "1596667587.365562"], ["11624.00000", "8.00000000", "1596667283.563592"], ["11623.70000", "2.01597927", "1596667591.488348"], ["11623.30000", "8.60000000", "1596667523.839323"], ["11622.50000", "0.98830000", "1596667568.085853"], ["11619.60000", "0.00900000", "1596667544.028763"], ["11619.00000", "7.00000000", "1596667582.175505"], ["11617.50000", "3.05720000", "1596667595.283178"], ["11617.30000", "0.74918454", "1596667605.087830"], ["11617.20000", "0.75800000", "1596667569.471522"], ["11616.60000", "1.99795807", "1596667591.352648"], ["11616.20000", "3.54999901", "1596667598.726747"], ["11616.00000", "1.34835129", "1596667582.994356"], ["11615.60000", "0.20000000", "1596667524.155155"], ["11615.10000", "0.91542834", "1596667189.083020"], ["11613.90000", "0.50000000", "1596667608.501579"], ["11613.00000", "0.17085000", "1596667381.469054"], ["11612.60000", "16.25666216", "1596667595.342778"], ["11612.30000", "7.00000000", "1596667548.784533"], ["11612.20000", "2.82363108", "1596667404.188840"], ["11610.00000", "0.17085000", "1596667315.364133"], ["11609.80000", "21.20000000", "1596666704.766154"], ["11609.20000", "0.36802762", "1596667584.548837"], ["11607.70000", "8.40000000", "1596666861.504830"], ["11607.00000", "2.19049777", "1596667416.122932"], ["11606.80000", "0.02000000", "1596667530.002131"], ["11605.70000", "0.48590000", "1596667320.163774"], ["11605.60000", "0.00858221", "1596667350.675538"], ["11604.00000", "0.17085000", "1596667596.346758"]]}, "book-100", "XBT/USD"]
[270, {"b": [["11646.80000", "0.85897021", "1596667611.368460"]], "c": "991082583"}, "book-100", "XBT/USD"]
[270, {"b": [["11642.30000", "0.00000000", "1596667611.370608"], ["11603.90000", "1.51500000", "1596667192.515227", "r"]], "c": "991082583"}, "book-100", "XBT/USD"]
[270, {"b": [["11653.90000", "5.56000000", "1596667611.442945"]], "c": "3214414139"}, "book-100", "XBT/USD"]
[270, {"a": [["11678.30000", "0.74919466", "1596667611.450568"]], "c": "3214414139"}, "book-100", "XBT/USD"]
[270, {"a": [["11678.40000", "0.00000000", "1596667611.451953"], ["11706.20000", "0.75800000", "1596666915.495628", "r"]], "c": "3214414139"}, "book-100", "XBT/USD"]
[270, {"b": [["11655.10000", "0.00000000", "1596667611.548230"], ["11603.30000", "0.01719338", "1596667403.925442", "r"]], "c": "2341976907"}, "book-100", "XBT/USD"]
[270, {"a": [["11670.00000", "44.61085970", "1596667611.549195"]], "c": "2341976907"}, "book-100", "XBT/USD"]
[270, {"a": [["11663.30000", "0.04250000", "1596667611.568261"]], "c": "2341976907"}, "book-100", "XBT/USD"]
[270, {"b": [["11654.20000", "1.71000000", "1596667611.572185"]], "c": "3794257726"}, "book-100", "XBT/USD"]
[270, {"a": [["11662.40000", "1.70400000", "1596667611.577525"]], "c": "145443456"}, "book-100", "XBT/USD"]
[270, {"b": [["11644.70000", "0.49827999", "1596667611.633633"]], "c": "145443456"}, "book-100", "XBT/USD"]
[270, {"b": [["11649.10000", "0.81490686", "1596667611.636511"]], "c": "145443456"}, "book-100", "XBT/USD"]
[270, {"b": [["11652.50000", "0.33865102", "1596667611.640761"]], "c": "2674749418"}, "book-100", "XBT/USD"]
[270, {"a": [["11669.70000", "0.33815188", "1596667611.644493"]], "c": "2674749418"}, "book-100", "XBT/USD"]
[270, {"a": [["11673.10000", "1.08991211", "1596667611.651330"]], "c": "2674749418"}, "book-100", "XBT/USD"]
[270, {"b": [["11653.80000", "0.00000000", "1596667611.791705"], ["11604.00000", "0.17085000", "1596667596.346758", "r"]], "c": "2537393822"}, "book-100", "XBT/USD"]
[270, {"a": [["11663.30000", "0.00000000", "1596667611.830145"], ["11706.00000", "0.17085000", "1596667592.196118", "r"]], "c": "2537393822"}, "book-100", "XBT/USD"]
[270, {"a": [["11665.10000", "0.00000000", "1596667611.913578"], ["11706.20000", "0.75800000", "1596666915.495628", "r"]], "c": "2537393822"}, "book-100", "XBT/USD"]
[270, {"a": [["11669.90000", "0.43900000", "1596667611.959895"]], "c": "2537393822"}, "book-100", "XBT/USD"]
[270, {"b": [["11652.60000", "0.04250000", "1596667612.052741"]], "c": "3254279417"}, "book-100", "XBT/USD"]
[270, {"a": [["11662.30000", "0.04250000", "1596667612.054829"]], "c": "3542062061"}, "book-100", "XBT/USD"]
[270, {"b": [["11651.40000", "0.00000000", "1596667612.138037"], ["11604.00000", "0.17085000", "1596667596.346758", "r"]], "c": "3542062061"}, "book-100", "XBT/USD"]
[270, {"a": [["11662.40000", "0.00000000", "1596667612.159761"], ["11706.00000", "0.17085000", "1596667592.196118", "r"]], "c": "3231506165"}, "book-100", "XBT/USD"]
[270, {"a": [["11669.60000", "0.00000000", "1596667612.182214"], ["11706.20000", "0.75800000", "1596666915.495628", "r"]], "c": "3231506165"}, "book-100", "XBT/USD"]
[270, {"a": [["11673.10000", "0.38000000", "1596667612.188906"]], "c": "3231506165"}, "book-100", "XBT/USD"]
[270, {"a": [["11669.70000", "0.00000000", "1596667612.189043"], ["11706.40000", "0.48380000", "1596667320.444995", "r"]], "c": "3231506165"}, "book-100", "XBT/USD"]
[270, {"a": [["11667.70000", "0.11078149", "1596667612.377282"]], "c": "3231506165"}, "book-100", "XBT/USD"]
[270, {"a": [["11667.80000", "0.33820694", "1596667612.437639"]], "c": "3231506165"}, "book-100", "XBT/USD"]
[270, {"b": [["11652.50000", "1.07933339", "1596667612.465933"]], "c": "3647185570"}, "book-100", "XBT/USD"]
[270, {"b": [["11647.80000", "0.86018000", "1596667612.952866"]], "c": "3647185570"}, "book-100", "XBT/USD"]
[270, {"b": [["11641.50000", "0.71900000", "1596667613.288282"]], "c": "3647185570"}, "book-100", "XBT/USD"]
[270, {"a": [["11658.30000", "0.64331444", "1596667613.347674"]], "c": "1365270242"}, "book-100", "XBT/USD"]
[270, {"a": [["11657.60000", "0.64334901", "1596667613.348057"]], "c": "455271175"}, "book-100", "XBT/USD"]
[270, {"b": [["11653.10000", "0.85776263", "1596667613.348173"]], "c": "1241222510"}, "book-100", "XBT/USD"]
[270, {"a": [["11662.60000", "2.68274209", "1596667613.348750"]], "c": "1241222510"}, "book-100", "XBT/USD"]
[270, {"b": [["11646.80000", "1.71675801", "1596667613.349397"]], "c": "1241222510"}, "book-100", "XBT/USD"]
[270, {"a": [["11660.60000", "0.85779868", "1596667613.425149"]], "c": "1836051054"}, "book-100", "XBT/USD"]
[270, {"a": [["11695.20000", "2.24864612", "1596667613.497064"]], "c": "1836051054"}, "book-100", "XBT/USD"]
[270, {"a": [["11696.30000", "0.00000000", "1596667613.499553"], ["11701.10000", "0.01796445", "1596667535.981575", "r"]], "c": "1836051054"}, "book-100", "XBT/USD"]
[270, {"a": [["11680.40000", "0.00000000", "1596667613.663974"], ["11704.10000", "8.30000000", "1596667058.485416", "r"]], "c": "1836051054"}, "book-100", "XBT/USD"]
[270, {"a": [["11666.10000", "0.15000000", "1596667613.744147"]], "c": "1836051054"}, "book-100", "XBT/USD"]
[270, {"a": [["11671.20000", "0.81347513", "1596667613.746376"]], "c": "1836051054"}, "book-100", "XBT/USD"]
[270, {"a": [["11663.30000", "0.09621094", "1596667613.864870"]], "c": "1836051054"}, "book-100", "XBT/USD"]
[270, {"b": [["11654.90000", "1.70100000", "1596667613.977961"]], "c": "3487413595"}, "book-100", "XBT/USD"]
[270, {"b": [["11654.20000", "0.00000000", "1596667613.980249"], ["11605.70000", "0.48590000", "1596667320.163774", "r"]], "c": "3082873604"}, "book-100", "XBT/USD"]
[270, {"a": [["11663.10000", "2.56761815", "1596667613.993360"]], "c": "3082873604"}, "book-100", "XBT/USD"]
[270, {"a": [["11661.10000", "0.00477673", "1596667614.114239"]], "c": "3788517945"}, "book-100", "XBT/USD"]
[270, {"a": [["11695.30000", "10.59287814", "1596667614.125902"]], "c": "3788517945"}, "book-100", "XBT/USD"]
[270, {"a": [["11695.40000", "0.00000000", "1596667614.128300"], ["11704.10000", "8.30000000", "1596667058.485416", "r"]], "c": "3788517945"}, "book-100", "XBT/USD"]
[270, {"a": [["11683.90000", "0.00000000", "1596667614.129667"], ["11704.60000", "18.00000000", "1596667150.934570", "r"]], "c": "3788517945"}, "book-100", "XBT/USD"]
[270, {"a": [["11695.30000", "7.06692408", "1596667614.131508"]], "c": "3788517945"}, "book-100", "XBT/USD"]
[270, {"a": [["11695.30000", "0.00000000", "1596667614.133377"], ["11706.20000", "0.75800000", "1596666915.495628", "r"]], "c": "3788517945"}, "book-100", "XBT/USD"]
[270, {"b": [["11649.10000", "0.10353216", "1596667614.175798"]], "c": "3788517945"}, "book-100", "XBT/USD"]
[270, {"b": [["11652.50000", "0.74068237", "1596667614.182807"]], "c": "3788517945"}, "book-100", "XBT/USD"]
[270, {"a": [["11660.50000", "0.25799237", "1596667614.215176"]], "c": "2135428344"}, "book-100", "XBT/USD"]
[270, {"a": [["11663.10000", "0.85761815", "1596667614.239867"]], "c": "2135428344"}, "book-100", "XBT/USD"]
[270, {"a": [["11661.10000", "0.00000000", "1596667614.243478"], ["11706.20000", "0.75800000", "1596666915.495628", "r"]], "c": "3363309943"}, "book-100", "XBT/USD"]
[270, {"b": [["11638.10000", "0.99550000", "1596667614.274729"]], "c": "3363309943"}, "book-100", "XBT/USD"]
[270, {"a": [["11690.80000", "1.78894542", "1596667614.275867"]], "c": "3363309943"}, "book-100", "XBT/USD"]
[270, {"a": [["11661.20000", "0.00477669", "1596667614.319688"]], "c": "1100138888"}, "book-100", "XBT/USD"]
[270, {"b": [["11637.10000", "3.57462329", "1596667614.330152"]], "c": "1100138888"}, "book-100", "XBT/USD"]
[270, {"a": [["11681.50000", "0.99342054", "1596667614.393838"]], "c": "1100138888"}, "book-100", "XBT/USD"]
[270, {"b": [["11650.10000", "0.33877389", "1596667614.487484"]], "c": "1100138888"}, "book-100", "XBT/USD"]
[270, {"b": [["11646.80000", "2.42838476", "1596667614.492833"]], "c": "1100138888"}, "book-100", "XBT/USD"]
[270, {"b": [["11637.10000", "3.54362329", "1596667614.547473"]], "c": "1100138888"}, "book-100", "XBT/USD"]
[270, {"a": [["11657.50000", "0.22500000", "1596667614.557570"]], "c": "1793517177"}, "book-100", "XBT/USD"]
[270, {"a": [["11690.90000", "5.52725551", "1596667614.557816"]], "c": "1793517177"}, "book-100", "XBT/USD"]
[270, {"a": [["11665.10000", "0.67645589", "1596667614.586184"]], "c": "1793517177"}, "book-100", "XBT/USD"]
[270, {"b": [["11638.10000", "1.02650000", "1596667614.602971"]], "c": "1793517177"}, "book-100", "XBT/USD"]
[270, {"b": [["11613.90000", "0.00000000", "1596667614.743874"], ["11605.70000", "0.48590000", "1596667320.163774", "r"]], "c": "1793517177"}, "book-100", "XBT/USD"]
[270, {"a": [["11661.50000", "0.00000000", "1596667614.802729"], ["11701.10000", "0.01796445", "1596667535.981575", "r"]], "c": "1793517177"}, "book-100", "XBT/USD"]
[270, {"a": [["11660.30000", "4.28100000", "1596667614.805044"]], "c": "2468634688"}, "book-100", "XBT/USD"]
[270, {"a": [["11688.40000", "0.00000000", "1596667614.808242"], ["11701.10000", "0.01796445", "1596667535.981575", "r"]], "c": "2468634688"}, "book-100", "XBT/USD"]
[270, {"a": [["11685.40000", "0.92600000", "1596667614.808355"]], "c": "2468634688"}, "book-100", "XBT/USD"]
[270, {"b": [["11641.50000", "0.00000000", "1596667614.808409"], ["11605.60000", "0.00858221", "1596667350.675538", "r"]], "c": "2468634688"}, "book-100", "XBT/USD"]
[270, {"b": [["11640.50000", "0.74400000", "1596667614.808574"]], "c": "2468634688"}, "book-100", "XBT/USD"]
[270, {"a": [["11690.90000", "11.91861590", "1596667614.931529"]], "c": "2468634688"}, "book-100", "XBT/USD"]
[270, {"b": [["11654.90000", "0.00000000", "1596667614.968411"], ["11605.60000", "0.00858221", "1596667350.675538", "r"]], "c": "3964520234"}, "book-100", "XBT/USD"]
[270, {"a": [["11667.70000", "2.11078149", "1596667615.145931"]], "c": "3964520234"}, "book-100", "XBT/USD"]
[270, {"b": [["11651.50000", "0.00000000", "1596667615.164809"], ["11604.00000", "0.17085000", "1596667596.346758", "r"]], "c": "3964520234"}, "book-100", "XBT/USD"]
[270, {"a": [["11665.10000", "0.00000000", "1596667615.199650"], ["11701.10000", "0.01796445", "1596667535.981575", "r"]], "c": "3964520234"}, "book-100", "XBT/USD"]
[270, {"a": [["11665.50000", "0.00000000", "1596667615.676886"], ["11704.10000", "8.30000000", "1596667058.485416", "r"]], "c": "3964520234"}, "book-100", "XBT/USD"]
[270, {"a": [["11665.10000", "0.65582154", "1596667615.729181"]], "c": "3964520234"}, "book-100", "XBT/USD"]
[270, {"a": [["11664.70000", "1.50000000", "1596667615.825655"]], "c": "3964520234"}, "book-100", "XBT/USD"]
[270, {"a": [["11657.60000", "0.00000000", "1596667616.033436"], ["11701.10000", "0.01796445", "1596667535.981575", "r"]], "c": "2006614148"}, "book-100", "XBT/USD"]
[270, {"a": [["11671.90000", "0.85774373", "1596667616.103536"]], "c": "2006614148"}, "book-100", "XBT/USD"]
[270, {"a": [["11671.90000", "0.00000000", "1596667616.159253"], ["11701.10000", "0.01796445", "1596667535.981575", "r"]], "c": "2006614148"}, "book-100", "XBT/USD"]
[270, {"a": [["11665.10000", "0.00000000", "1596667616.248918"], ["11704.10000", "8.30000000", "1596667058.485416", "r"]], "c": "2006614148"}, "book-100", "XBT/USD"]
[270, {"a": [["11660.50000", "0.00000000", "1596667616.286245"], ["11704.60000", "18.00000000", "1596667150.934570", "r"]], "c": "3061725570"}, "book-100", "XBT/USD"]
[270, {"a": [["11664.60000", "0.66072522", "1596667616.297511"]], "c": "3061725570"}, "book-100", "XBT/USD"]
[270, {"b": [["11646.80000", "1.71675801", "1596667616.319863"]], "c": "3061725570"}, "book-100", "XBT/USD"]
[270, {"b": [["11655.30000", "6.62714493", "1596667616.363509"]], "c": "1078762868"}, "book-100", "XBT/USD"]
[270, {"a": [["11663.50000", "1.71200000", "1596667616.374812"]], "c": "1078762868"}, "book-100", "XBT/USD"]
[270, {"a": [["11661.10000", "0.25798755", "1596667616.386626"]], "c": "206263937"}, "book-100", "XBT/USD"]
[270, {"b": [["11646.80000", "1.58265603", "1596667616.429143"]], "c": "206263937"}, "book-100", "XBT/USD"]
[270, {"b": [["11650.10000", "0.00000000", "1596667616.440490"], ["11603.90000", "1.51500000", "1596667192.515227", "r"]], "c": "206263937"}, "book-100", "XBT/USD"]
[270, {"a": [["11667.80000", "0.00000000", "1596667616.564216"], ["11701.10000", "0.01796445", "1596667535.981575", "r"]], "c": "206263937"}, "book-100", "XBT/USD"]
[270, {"b": [["11646.80000", "1.71676679", "1596667616.641795"]], "c": "206263937"}, "book-100", "XBT/USD"]
[270, {"b": [["11654.50000", "9.99987003", "1596667616.803306"]], "c": "3657326377"}, "book-100", "XBT/USD"]
