[270, {"as": [["11666.30000", "8.28603456", "1596667309.342346"], ["11666.40000", "0.01000000", "1596667309.275146"], ["11666.50000", "0.75551922", "1596667309.417858"], ["11666.60000", "1.59844400", "1596667309.366188"], ["11666.70000", "0.65000000", "1596667307.567232"], ["11666.80000", "0.85740490", "1596667301.281962"], ["11666.90000", "4.38421094", "1596667306.277593"], ["11667.00000", "0.85744932", "1596667303.656114"], ["11667.20000", "5.96460110", "1596667296.401582"], ["11667.70000", "0.35396399", "1596667303.579994"], ["11667.90000", "1.02890000", "1596667308.921051"], ["11668.50000", "0.10200000", "1596667307.570754"], ["11668.60000", "0.02766631", "1596667302.743511"], ["11668.70000", "0.85726635", "1596667276.402529"], ["11669.10000", "3.19817571", "1596667276.554371"], ["11669.30000", "0.10000000", "1596667298.029199"], ["11669.40000", "0.43900000", "1596667294.393572"], ["11670.00000", "46.40525970", "1596667308.873833"], ["11670.30000", "1.22180487", "1596667259.005296"], ["11670.50000", "6.68000000", "1596667305.230550"], ["11670.80000", "0.85722144", "1596667279.977519"], ["11670.90000", "0.10000000", "1596667301.391319"], ["11671.10000", "0.65441594", "1596667291.451585"], ["11671.30000", "0.85719129", "1596667299.554360"], ["11671.40000", "0.49191584", "1596667296.241524"], ["11671.70000", "0.96778000", "1596667308.877906"], ["11671.90000", "0.11078149", "1596667300.196188"], ["11672.00000", "0.33844837", "1596667303.965749"], ["11672.60000", "0.00438186", "1596667309.177727"], ["11672.70000", "0.70560000", "1596667276.398892"], ["11674.00000", "0.85720585", "1596667280.783560"], ["11674.70000", "0.49716099", "1596667309.142010"], ["11674.80000", "0.46801036", "1596667208.101663"], ["11675.00000", "0.01821000", "1596667215.003486"], ["11675.30000", "0.71054068", "1596667303.986256"], ["11675.70000", "7.10000000", "1596667290.196005"], ["11675.90000", "0.91081495", "1596667309.364099"], ["11676.90000", "0.10000000", "1596667227.314812"], ["11677.20000", "0.10334405", "1596667277.996698"], ["11678.10000", "0.30000000", "1596667276.285314"], ["11679.20000", "0.24916356", "1596667278.821022"], ["11679.60000", "0.72325973", "1596667278.000379"], ["11680.50000", "2.29920000", "1596667254.567453"], ["11680.60000", "0.91044846", "1596667309.367439"], ["11681.20000", "0.02573600", "1596667271.890949"], ["11681.40000", "3.53030102", "1596667308.949043"], ["11681.90000", "8.00000000", "1596667148.975999"], ["11682.10000", "6.57947332", "1596667226.847705"], ["11682.20000", "0.34873940", "1596667279.980886"], ["11682.50000", "0.74921333", "1596667307.209811"], ["11683.40000", "0.74800000", "1596667301.995679"], ["11683.70000", "0.00300000", "1596667261.018259"], ["11683.90000", "7.07403788", "1596667300.028322"], ["11684.00000", "3.19767190", "1596667285.127048"], ["11684.40000", "3.21261186", "1596667279.995052"], ["11684.70000", "1.79172157", "1596667264.941816"], ["11685.00000", "0.10000000", "1596667214.858992"], ["11685.90000", "6.10940387", "1596667306.085320"], ["11686.50000", "3.52909308", "1596667207.230979"], ["11686.80000", "0.57263528", "1596667207.205732"], ["11687.30000", "8.20000000", "1596667061.296774"], ["11688.70000", "0.30000000", "1596666965.080034"], ["11689.90000", "1.58954363", "1596667309.101420"], ["11690.00000", "0.04000000", "1596667298.692216"], ["11690.20000", "0.75800000", "1596667297.995005"], ["11692.30000", "8.50000000", "1596667275.427629"], ["11692.80000", "2.00319802", "1596667209.725128"], ["11693.80000", "2.00321220", "1596667276.287351"], ["11696.00000", "0.02829753", "1596667288.015763"], ["11697.00000", "0.89567025", "1596667210.356884"], ["11698.00000", "6.50000000", "1596667287.541035"], ["11698.20000", "0.55288183", "1596667304.444975"], ["11698.50000", "1.16913329", "1596667186.881827"], ["11699.10000", "8.74376206", "1596667301.391984"], ["11699.20000", "9.91294729", "1596667308.943922"], ["11699.30000", "9.02402698", "1596667214.096102"], ["11699.90000", "0.10000000", "1596666079.896762"], ["11700.00000", "0.52000000", "1596667297.741607"], ["11701.10000", "0.01796445", "1596667275.317755"], ["11701.60000", "2.24872670", "1596667309.306377"], ["11701.80000", "1.51500000", "1596667297.997834"], ["11702.80000", "1.11290000", "1596667171.005121"], ["11703.90000", "20.00000000", "1596667295.045542"], ["11704.10000", "8.30000000", "1596667058.485416"], ["11704.60000", "18.00000000", "1596667150.934570"], ["11704.90000", "2.31095980", "1596667182.102245"], ["11705.60000", "1.98337449", "1596666820.829303"], ["11705.90000", "0.35595985", "1596667270.090195"], ["11706.20000", "0.75800000", "1596666915.495628"], ["11709.70000", "7.20507863", "1596666814.449677"], ["11710.70000", "3.52183532", "1596666711.393054"], ["11711.40000", "0.01285760", "1596667309.185455"], ["11711.50000", "1.99898326", "1596666797.632161"], ["11712.00000", "0.17085000", "1596667309.378153"], ["11713.00000", "0.28391641", "1596667303.803089"], ["11713.20000", "1.06000000", "1596667294.495154"], ["11715.30000", "6.10000000", "1596666635.445451"], ["11717.80000", "1.99812614", "1596666759.535617"], ["11718.00000", "0.17085000", "1596666994.200702"], ["11718.40000", "4.75039410", "1596667296.009860"]], "bs": [["11666.20000", "7.42559146", "1596667309.355052"], ["11661.50000", "0.57230000", "1596667290.570064"], ["11655.10000", "0.25801854", "1596667309.060377"], ["11655.00000", "0.09800000", "1596667300.891688"], ["11653.40000", "0.85759009", "1596667306.359958"], ["11652.10000", "0.16461000", "1596667301.453542"], ["11651.20000", "1.50000000", "1596667307.148154"], ["11651.10000", "0.16517000", "1596667309.160372"], ["11650.80000", "0.16513000", "1596667298.259658"], ["11649.60000", "0.08250000", "1596667302.234127"], ["11649.00000", "0.85735784", "1596667280.204073"], ["11648.90000", "0.30000000", "1596667294.483573"], ["11648.50000", "0.43800000", "1596667302.874304"], ["11646.50000", "0.95367842", "1596667309.392889"], ["11645.00000", "0.85755783", "1596667296.636100"], ["11644.90000", "2.92530547", "1596667308.921747"], ["11643.30000", "2.00000000", "1596667306.589787"], ["11642.50000", "0.92517000", "1596667309.242426"], ["11641.80000", "0.10500000", "1596667309.362838"], ["11641.20000", "0.49819534", "1596667297.172299"], ["11641.10000", "0.10371510", "1596667309.310931"], ["11641.00000", "0.05288189", "1596667149.410192"], ["11640.00000", "7.10000000", "1596667197.405160"], ["11639.30000", "3.05016036", "1596667309.289803"], ["11638.90000", "0.68000000", "1596667302.478374"], ["11638.60000", "0.35003839", "1596667308.921808"], ["11638.30000", "3.54345652", "1596667308.942739"], ["11638.10000", "0.72619282", "1596667309.366802"], ["11637.50000", "1.79918125", "1596667308.895372"], ["11637.40000", "0.66700000", "1596667300.598439"], ["11637.00000", "0.91385961", "1596667306.292361"], ["11636.80000", "3.54378935", "1596667307.014038"], ["11635.90000", "1.21453647", "1596667307.138947"], ["11635.10000", "7.30000000", "1596667309.304394"], ["11634.40000", "1.88070000", "1596667309.120464"], ["11634.30000", "0.50000000", "1596667296.498797"], ["11633.80000", "0.57531995", "1596667294.433802"], ["11633.30000", "3.21175051", "1596667308.925778"], ["11632.90000", "3.01147322", "1596667309.390285"], ["11632.80000", "0.99250000", "1596667308.923877"], ["11632.70000", "6.95488283", "1596667282.892361"], ["11632.40000", "0.02874665", "1596667297.354040"], ["11630.90000", "1.11290000", "1596666962.030868"], ["11630.20000", "2.01341570", "1596667305.910217"], ["11630.10000", "8.60000000", "1596666873.959071"], ["11630.00000", "0.91440966", "1596667306.276283"], ["11628.90000", "0.30000000", "1596667292.785465"], ["11627.70000", "0.10576396", "1596667182.152737"], ["11627.60000", "1.97059171", "1596667307.952006"], ["11626.20000", "0.70560000", "1596667297.005277"], ["11625.20000", "3.54843693", "1596667212.771986"], ["11625.10000", "0.00856780", "1596666864.899828"], ["11625.00000", "0.25000000", "1596667280.858863"], ["11624.20000", "2.89837698", "1596667296.889577"], ["11624.10000", "2.01069373", "1596667297.549859"], ["11624.00000", "8.00000000", "1596667283.563592"], ["11622.40000", "2.32544230", "1596667300.658688"], ["11622.00000", "0.17085000", "1596667308.889980"], ["11621.20000", "1.51597149", "1596667305.900821"], ["11621.10000", "2.82148728", "1596667223.156385"], ["11620.80000", "0.02000000", "1596667239.793596"], ["11620.60000", "1.50751397", "1596667297.963760"], ["11620.40000", "6.43034000", "1596667303.916900"], ["11619.00000", "7.00000000", "1596667292.369985"], ["11618.90000", "0.48560000", "1596666782.022335"], ["11617.60000", "2.01542111", "1596667226.945517"], ["11617.50000", "4.79681864", "1596667153.879904"], ["11616.20000", "0.74921333", "1596667307.203177"], ["11616.00000", "1.17750129", "1596667279.481640"], ["11615.60000", "0.20000000", "1596667195.894963"], ["11615.50000", "2.01596378", "1596667297.915814"], ["11615.10000", "0.91542834", "1596667189.083020"], ["11613.60000", "3.55198121", "1596666780.634357"], ["11613.00000", "0.17085000", "1596667302.765781"], ["11612.30000", "7.00000000", "1596666617.080387"], ["11612.00000", "1.03370000", "1596667294.474097"], ["11609.80000", "21.20000000", "1596666704.766154"], ["11609.30000", "2.01627299", "1596666817.684177"], ["11607.80000", "13.93487293", "1596667297.980362"], ["11607.70000", "8.40000000", "1596666861.504830"], ["11607.00000", "0.17085000", "1596666870.943401"], ["11606.30000", "0.75800000", "1596667297.976092"], ["11604.00000", "0.17085000", "1596667290.973264"], ["11603.90000", "1.51500000", "1596667192.515227"], ["11603.30000", "0.01719338", "1596667239.786769"], ["11602.80000", "0.75800000", "1596667297.502419"], ["11602.60000", "1.48021868", "1596666784.125874"], ["11602.10000", "11.25550194", "1596666780.609892"], ["11601.10000", "3.00166376", "1596667216.223075"], ["11601.00000", "0.17085000", "1596667296.917971"], ["11600.80000", "1.06000000", "1596667292.363391"], ["11600.50000", "3.54195852", "1596666820.729492"], ["11600.40000", "0.90458128", "1596666816.038277"], ["11600.20000", "2.24872670", "1596667309.306093"], ["11600.10000", "0.05000000", "1596667199.410129"], ["11600.00000", "0.49274162", "1596667211.396329"], ["11599.60000", "3.04585670", "1596666779.021471"], ["11598.80000", "10.88860000", "1596666792.969132"], ["11597.40000", "0.01285760", "1596667309.171925"], ["11597.30000", "20.41881220", "1596667122.448757"]]}, "book-100", "XBT/USD"]
[271, [["11666.20000", "0.13459008", "1596667310.342466", "s", "l", ""]], "trade", "XBT/USD"]
[270, {"b": [["11666.20000", "7.29100138", "1596667310.342467"]], "c": "458952367"}, "book-100", "XBT/USD"]
[270, {"a": [["11677.10000", "0.08720616", "1596667310.357269"]], "c": "458952367"}, "book-100", "XBT/USD"]
[270, {"b": [["11644.90000", "0.00000000", "1596667310.357430"], ["11596.10000", "5.80000000", "1596667059.348718", "r"]], "c": "458952367"}, "book-100", "XBT/USD"]
[270, {"a": [["11684.70000", "0.00000000", "1596667310.358054"], ["11718.40000", "4.75039410", "1596667296.009860", "r"]], "c": "458952367"}, "book-100", "XBT/USD"]
[270, {"a": [["11666.30000", "18.28603456", "1596667310.361110"]], "c": "844369735"}, "book-100", "XBT/USD"]
[270, {"b": [["11638.00000", "1.42570502", "1596667310.367017"]], "c": "844369735"}, "book-100", "XBT/USD"]
[270, {"b": [["11640.30000", "0.71271166", "1596667310.367494"]], "c": "844369735"}, "book-100", "XBT/USD"]
[270, {"a": [["11675.30000", "0.00000000", "1596667310.367821"], ["11718.50000", "24.30000000", "1596666641.380470", "r"]], "c": "844369735"}, "book-100", "XBT/USD"]
[270, {"b": [["11638.90000", "0.30000000", "1596667310.368740"]], "c": "844369735"}, "book-100", "XBT/USD"]
[270, {"b": [["11632.70000", "0.00000000", "1596667310.371940"], ["11597.30000", "20.41881220", "1596667122.448757", "r"]], "c": "844369735"}, "book-100", "XBT/USD"]
[270, {"a": [["11672.00000", "0.00000000", "1596667310.372178"], ["11719.60000", "1.46521891", "1596667186.806464", "r"]], "c": "844369735"}, "book-100", "XBT/USD"]
[270, {"b": [["11643.70000", "0.33928740", "1596667310.373518"]], "c": "844369735"}, "book-100", "XBT/USD"]
[270, {"a": [["11672.40000", "0.91108806", "1596667310.377286"]], "c": "844369735"}, "book-100", "XBT/USD"]
[270, {"b": [["11633.90000", "0.38000000", "1596667310.380790"]], "c": "844369735"}, "book-100", "XBT/USD"]
[270, {"a": [["11686.80000", "0.00000000", "1596667310.393684"], ["11719.60000", "1.46521891", "1596667186.806464", "r"]], "c": "844369735"}, "book-100", "XBT/USD"]
[270, {"b": [["11632.10000", "0.03100000", "1596667310.396079"]], "c": "844369735"}, "book-100", "XBT/USD"]
[270, {"a": [["11699.20000", "6.38767122", "1596667310.398334"]], "c": "844369735"}, "book-100", "XBT/USD"]
[270, {"b": [["11651.20000", "0.00000000", "1596667310.400732"], ["11598.80000", "10.88860000", "1596666792.969132", "r"]], "c": "3441614892"}, "book-100", "XBT/USD"]
[270, {"a": [["11697.00000", "0.00000000", "1596667310.402301"], ["11719.70000", "3.50602221", "1596667124.435441", "r"]], "c": "3441614892"}, "book-100", "XBT/USD"]
[270, {"a": [["11684.00000", "0.00000000", "1596667310.406105"], ["11721.00000", "0.97885000", "1596666999.630339", "r"]], "c": "3441614892"}, "book-100", "XBT/USD"]
[270, {"a": [["11669.10000", "4.05591571", "1596667310.408159"]], "c": "3441614892"}, "book-100", "XBT/USD"]
[270, {"a": [["11699.30000", "7.06539901", "1596667310.409555"]], "c": "3441614892"}, "book-100", "XBT/USD"]
[270, {"a": [["11681.30000", "0.47508868", "1596667310.410483"]], "c": "3441614892"}, "book-100", "XBT/USD"]
[271, [["11666.20000", "0.05354300", "1596667310.551249", "s", "l", ""]], "trade", "XBT/USD"]
[270, {"b": [["11666.20000", "7.23745838", "1596667310.551249"]], "c": "401592565"}, "book-100", "XBT/USD"]
[270, {"b": [["11623.20000", "3.54805992", "1596667310.557421"]], "c": "401592565"}, "book-100", "XBT/USD"]
[270, {"b": [["11646.60000", "0.66480064", "1596667310.558861"]], "c": "401592565"}, "book-100", "XBT/USD"]
[270, {"a": [["11684.40000", "2.00429570", "1596667310.560315"]], "c": "401592565"}, "book-100", "XBT/USD"]
[270, {"a": [["11692.80000", "0.00000000", "1596667310.563266"], ["11721.00000", "0.97885000", "1596666999.630339", "r"]], "c": "401592565"}, "book-100", "XBT/USD"]
[271, [["11666.20000", "0.04486351", "1596667310.573940", "s", "l", ""]], "trade", "XBT/USD"]
[270, {"b": [["11666.20000", "7.19259487", "1596667310.573940"]], "c": "284873785"}, "book-100", "XBT/USD"]
[270, {"b": [["11645.50000", "0.01279085", "1596667310.578337"]], "c": "284873785"}, "book-100", "XBT/USD"]
[270, {"a": [["11671.90000", "0.00000000", "1596667310.579609"], ["11721.70000", "2.47549182", "1596667020.397127", "r"]], "c": "284873785"}, "book-100", "XBT/USD"]
[270, {"a": [["11667.70000", "0.21976352", "1596667310.581078"]], "c": "1977905906"}, "book-100", "XBT/USD"]
[270, {"a": [["11699.20000", "0.00000000", "1596667310.581217"], ["11722.10000", "7.70000000", "1596667141.794522", "r"]], "c": "1977905906"}, "book-100", "XBT/USD"]
[271, [["11666.20000", "2.76784233", "1596667310.587028", "s", "l", ""]], "trade", "XBT/USD"]
[270, {"b": [["11666.20000", "4.42475254", "1596667310.587028"]], "c": "2172560703"}, "book-100", "XBT/USD"]
[270, {"a": [["11683.90000", "0.00000000", "1596667310.597249"], ["11722.20000", "3.01549629", "1596666746.821117", "r"]], "c": "2172560703"}, "book-100", "XBT/USD"]
[270, {"b": [["11649.00000", "0.00000000", "1596667310.604288"], ["11600.00000", "0.49274162", "1596667211.396329", "r"]], "c": "859217822"}, "book-100", "XBT/USD"]
[270, {"a": [["11677.20000", "0.00000000", "1596667310.606136"], ["11722.40000", "3.51809513", "1596667188.914618", "r"]], "c": "859217822"}, "book-100", "XBT/USD"]
[270, {"a": [["11680.60000", "1.90426819", "1596667310.607848"]], "c": "859217822"}, "book-100", "XBT/USD"]
[270, {"a": [["11672.40000", "2.33259135", "1596667310.608677"]], "c": "859217822"}, "book-100", "XBT/USD"]
[270, {"b": [["11613.00000", "0.00000000", "1596667310.609172"], ["11599.60000", "3.04585670", "1596666779.021471", "r"]], "c": "859217822"}, "book-100", "XBT/USD"]
[270, {"a": [["11679.60000", "0.00000000", "1596667310.615585"], ["11722.50000", "2.99817310", "1596667303.730755", "r"]], "c": "859217822"}, "book-100", "XBT/USD"]
[270, {"a": [["11713.00000", "0.00000000", "1596667310.616174"], ["11722.60000", "23.57900000", "1596667192.593725", "r"]], "c": "859217822"}, "book-100", "XBT/USD"]
[270, {"a": [["11687.60000", "0.90990317", "1596667310.620030"]], "c": "859217822"}, "book-100", "XBT/USD"]
[270, {"a": [["11682.20000", "0.00000000", "1596667310.631432"], ["11722.60000", "23.57900000", "1596667192.593725", "r"]], "c": "859217822"}, "book-100", "XBT/USD"]
[270, {"a": [["11699.30000", "0.00000000", "1596667310.631574"], ["11722.80000", "2.97068603", "1596667184.622235", "r"]], "c": "859217822"}, "book-100", "XBT/USD"]
[270, {"b": [["11642.20000", "1.50000000", "1596667310.633500"]], "c": "859217822"}, "book-100", "XBT/USD"]
[270, {"b": [["11655.00000", "0.00000000", "1596667310.634417"], ["11599.60000", "3.04585670", "1596666779.021471", "r"]], "c": "3977818098"}, "book-100", "XBT/USD"]
[270, {"a": [["11674.00000", "0.00000000", "1596667310.638949"], ["11724.00000", "0.17085000", "1596667005.007164", "r"]], "c": "3977818098"}, "book-100", "XBT/USD"]
[271, [["11666.20000", "4.42475254", "1596667310.646460", "s", "l", ""]], "trade", "XBT/USD"]
[270, {"a": [["11666.20000", "0.01667350", "1596667310.645772"]]}, {"b": [["11666.20000", "0.00000000", "1596667310.646460"], ["11598.80000", "10.88860000", "1596666792.969132", "r"]], "c": "3398352818"}, "book-100", "XBT/USD"]
[270, {"b": [["11653.40000", "0.00000000", "1596667310.654593"], ["11597.40000", "0.01285760", "1596667309.171925", "r"]], "c": "122830116"}, "book-100", "XBT/USD"]
[270, {"a": [["11666.30000", "17.54266644", "1596667310.654721"]], "c": "4020031926"}, "book-100", "XBT/USD"]
[270, {"b": [["11632.40000", "7.13433691", "1596667310.655771"]], "c": "4020031926"}, "book-100", "XBT/USD"]
[271, [["11661.50000", "0.06000000", "1596667310.657233", "s", "l", ""]], "trade", "XBT/USD"]
[270, {"b": [["11661.50000", "0.51230000", "1596667310.657233"]], "c": "1724715431"}, "book-100", "XBT/USD"]
[270, {"b": [["11649.40000", "4.28900000", "1596667310.662549"]], "c": "1021507203"}, "book-100", "XBT/USD"]
[270, {"b": [["11639.60000", "0.87554000", "1596667310.665944"]], "c": "1021507203"}, "book-100", "XBT/USD"]
[270, {"a": [["11681.30000", "0.00000000", "1596667310.675105"], ["11724.00000", "0.17085000", "1596667005.007164", "r"]], "c": "1021507203"}, "book-100", "XBT/USD"]
[270, {"a": [["11679.20000", "0.00000000", "1596667310.677714"], ["11725.30000", "0.90700471", "1596667184.374139", "r"]], "c": "1021507203"}, "book-100", "XBT/USD"]
[270, {"a": [["11666.30000", "17.66466644", "1596667310.678076"]], "c": "767857544"}, "book-100", "XBT/USD"]
[270, {"b": [["11640.00000", "0.00000000", "1596667310.678715"], ["11598.80000", "10.88860000", "1596666792.969132", "r"]], "c": "767857544"}, "book-100", "XBT/USD"]
[270, {"a": [["11681.40000", "0.00000000", "1596667310.679019"], ["11725.40000", "1.99666304", "1596667295.955196", "r"]], "c": "767857544"}, "book-100", "XBT/USD"]
[270, {"a": [["11699.10000", "7.23721332", "1596667310.680080"]], "c": "767857544"}, "book-100", "XBT/USD"]
[270, {"a": [["11666.30000", "21.41466644", "1596667310.681299"]], "c": "636057990"}, "book-100", "XBT/USD"]
[270, {"a": [["11677.10000", "0.00000000", "1596667310.686783"], ["11726.30000", "1.78600000", "1596666787.006488", "r"]], "c": "636057990"}, "book-100", "XBT/USD"]
[270, {"b": [["11642.50000", "0.00000000", "1596667310.686975"], ["11597.40000", "0.01285760", "1596667309.171925", "r"]], "c": "636057990"}, "book-100", "XBT/USD"]
[270, {"a": [["11667.50000", "0.15300000", "1596667310.698522"]], "c": "636057990"}, "book-100", "XBT/USD"]
[270, {"b": [["11655.10000", "0.00000000", "1596667310.700107"], ["11597.30000", "20.41881220", "1596667122.448757", "r"]], "c": "2269525036"}, "book-100", "XBT/USD"]
[270, {"a": [["11684.40000", "0.00000000", "1596667310.701553"], ["11726.30000", "1.78600000", "1596666787.006488", "r"]], "c": "2269525036"}, "book-100", "XBT/USD"]
[270, {"b": [["11620.80000", "7.13268313", "1596667310.703743"]], "c": "2269525036"}, "book-100", "XBT/USD"]
[270, {"a": [["11666.30000", "21.51666644", "1596667310.707357"]], "c": "4221756666"}, "book-100", "XBT/USD"]
[270, {"a": [["11666.70000", "0.50000000", "1596667310.709369"]], "c": "2900163710"}, "book-100", "XBT/USD"]
[271, [["11661.50000", "0.06001200", "1596667310.713183", "s", "l", ""]], "trade", "XBT/USD"]
[270, {"b": [["11661.50000", "0.45228800", "1596667310.713183"]], "c": "1652706456"}, "book-100", "XBT/USD"]
[270, {"a": [["11710.60000", "0.28391641", "1596667310.718106"]], "c": "1652706456"}, "book-100", "XBT/USD"]
[270, {"a": [["11686.50000", "0.00000000", "1596667310.719422"], ["11726.30000", "1.78600000", "1596666787.006488", "r"]], "c": "1652706456"}, "book-100", "XBT/USD"]
[270, {"b": [["11641.90000", "0.01279489", "1596667310.719561"]], "c": "1652706456"}, "book-100", "XBT/USD"]
[270, {"b": [["11645.50000", "0.00000000", "1596667310.720124"], ["11597.30000", "20.41881220", "1596667122.448757", "r"]], "c": "1652706456"}, "book-100", "XBT/USD"]
[270, {"b": [["11651.10000", "0.00000000", "1596667310.723061"], ["11596.10000", "5.80000000", "1596667059.348718", "r"]], "c": "3353126215"}, "book-100", "XBT/USD"]
[270, {"b": [["11650.80000", "0.00000000", "1596667310.724144"], ["11594.40000", "23.57900000", "1596666841.115872", "r"]], "c": "4161370170"}, "book-100", "XBT/USD"]
[270, {"a": [["11666.30000", "21.25870554", "1596667310.743246"]], "c": "549109719"}, "book-100", "XBT/USD"]
[270, {"a": [["11661.60000", "0.50000000", "1596667310.751609"]], "c": "3252267465"}, "book-100", "XBT/USD"]
[270, {"a": [["11676.90000", "0.00000000", "1596667310.759397"], ["11726.30000", "1.78600000", "1596666787.006488", "r"]], "c": "3252267465"}, "book-100", "XBT/USD"]
[270, {"a": [["11666.50000", "0.00000000", "1596667310.765752"], ["11727.00000", "0.17085000", "1596666854.102829", "r"]], "c": "968199570"}, "book-100", "XBT/USD"]
[270, {"a": [["11666.30000", "20.57889149", "1596667310.770701"]], "c": "2739298370"}, "book-100", "XBT/USD"]
[270, {"a": [["11666.30000", "20.20800474", "1596667310.776769"]], "c": "2043162713"}, "book-100", "XBT/USD"]
[270, {"b": [["11642.20000", "0.00000000", "1596667310.780416"], ["11593.00000", "0.95780000", "1596666771.513632", "r"]], "c": "2043162713"}, "book-100", "XBT/USD"]
[270, {"a": [["11666.30000", "19.56505498", "1596667310.785622"]], "c": "2626278388"}, "book-100", "XBT/USD"]
[270, {"b": [["11652.10000", "0.00000000", "1596667310.786742"], ["11592.90000", "0.80800000", "1596666806.224022", "r"]], "c": "2139372545"}, "book-100", "XBT/USD"]
[270, {"a": [["11666.30000", "15.81505498", "1596667310.791940"]], "c": "1860691969"}, "book-100", "XBT/USD"]
[270, {"b": [["11646.60000", "0.00000000", "1596667310.802223"], ["11590.50000", "8.10000000", "1596667252.761482", "r"]], "c": "2770032720"}, "book-100", "XBT/USD"]
[270, {"a": [["11666.20000", "0.77219272", "1596667310.839677"]], "c": "2349866645"}, "book-100", "XBT/USD"]
[270, {"a": [["11666.90000", "0.09621094", "1596667310.843667"]], "c": "3633557637"}, "book-100", "XBT/USD"]
[270, {"a": [["11666.30000", "15.68594173", "1596667310.868474"]], "c": "1956842253"}, "book-100", "XBT/USD"]
[270, {"a": [["11661.60000", "0.59800000", "1596667310.870396"]], "c": "2693435704"}, "book-100", "XBT/USD"]
