[270, {"as": [["11665.20000", "0.48264976", "1596669136.898296"], ["11665.30000", "0.64286067", "1596669129.447785"], ["11666.30000", "0.64283027", "1596669123.592600"], ["11667.00000", "1.00577945", "1596669126.760061"], ["11668.00000", "0.25784732", "1596669135.614422"], ["11668.10000", "0.64280140", "1596669134.818062"], ["11668.60000", "0.01000000", "1596669137.184934"], ["11668.70000", "0.73635082", "1596669137.022540"], ["11668.80000", "4.27800000", "1596669137.131031"], ["11668.90000", "1.31088920", "1596669121.074347"], ["11669.00000", "0.95029516", "1596669133.918073"], ["11669.10000", "1.75841658", "1596669120.588094"], ["11669.30000", "0.10000000", "1596669121.164672"], ["11669.40000", "0.85714222", "1596669120.587311"], ["11669.80000", "0.04250000", "1596669122.272819"], ["11670.00000", "43.90525970", "1596669066.144853"], ["11670.10000", "1.71000000", "1596669136.893828"], ["11670.60000", "1.83219198", "1596669137.046823"], ["11670.70000", "0.21976352", "1596669124.062670"], ["11670.90000", "0.49551540", "1596669124.268289"], ["11671.00000", "0.10300000", "1596669119.257136"], ["11672.00000", "0.09621094", "1596669135.358141"], ["11672.20000", "0.85685516", "1596669121.061200"], ["11672.40000", "0.85692097", "1596669120.654617"], ["11673.30000", "0.88795004", "1596669100.835799"], ["11673.40000", "0.72903000", "1596669118.840276"], ["11673.80000", "0.09600000", "1596669134.769695"], ["11674.40000", "0.15000000", "1596669113.892817"], ["11674.50000", "0.84954672", "1596669123.760052"], ["11674.90000", "0.19468741", "1596669130.882945"], ["11675.00000", "0.01821000", "1596669109.068240"], ["11675.20000", "0.85714891", "1596669027.585857"], ["11675.30000", "0.85670381", "1596669103.202325"], ["11675.70000", "0.44905886", "1596669130.643525"], ["11676.40000", "0.08250000", "1596669119.389418"], ["11676.50000", "2.97175453", "1596669134.291902"], ["11676.60000", "0.47673462", "1596669073.360738"], ["11678.00000", "0.13403890", "1596669131.773228"], ["11678.10000", "0.70560000", "1596669107.282060"], ["11678.50000", "6.50000000", "1596669120.543743"], ["11679.10000", "0.71017567", "1596669128.271384"], ["11679.50000", "0.50000000", "1596669100.778730"], ["11679.90000", "2.09100000", "1596669077.009137"], ["11680.10000", "0.30000000", "1596669119.372760"], ["11680.40000", "0.10323627", "1596669127.789127"], ["11681.00000", "5.96028659", "1596669130.595873"], ["11681.10000", "3.52379255", "1596669103.428676"], ["11681.20000", "0.02573600", "1596669063.748291"], ["11681.30000", "2.29920000", "1596668873.708889"], ["11681.40000", "1.42007168", "1596669129.293974"], ["11681.60000", "0.97171419", "1596669130.601075"], ["11681.80000", "0.97040000", "1596669035.806453"], ["11681.90000", "0.38000000", "1596669119.590080"], ["11682.00000", "5.90000000", "1596669119.579321"], ["11682.70000", "0.90954891", "1596669120.241904"], ["11683.60000", "0.00438186", "1596669134.060635"], ["11683.70000", "8.18017510", "1596669119.337927"], ["11684.70000", "0.74857130", "1596669134.425138"], ["11685.00000", "4.19210065", "1596669121.214701"], ["11685.10000", "1.60000000", "1596669120.730771"], ["11685.70000", "0.49647083", "1596668961.570261"], ["11686.00000", "0.90931860", "1596668968.318012"], ["11686.10000", "0.43900000", "1596669137.326685"], ["11686.20000", "0.34853729", "1596668972.556259"], ["11687.30000", "8.20000000", "1596668790.261966"], ["11687.50000", "2.32565760", "1596668912.406381"], ["11688.20000", "0.57252450", "1596668959.306029"], ["11688.50000", "4.99680206", "1596669122.976493"], ["11688.70000", "0.99270035", "1596668938.927092"], ["11689.90000", "0.10000000", "1596668827.877674"], ["11690.00000", "1.24765605", "1596669064.341854"], ["11690.10000", "3.52674781", "1596668960.300902"], ["11690.20000", "2.00483946", "1596669084.213853"], ["11690.30000", "7.06987726", "1596669001.023799"], ["11690.40000", "0.30000000", "1596668790.244684"], ["11690.90000", "0.90891095", "1596669120.246371"], ["11691.30000", "0.00300000", "1596669133.035766"], ["11692.30000", "8.50000000", "1596667892.430053"], ["11692.80000", "0.90920712", "1596668784.799785"], ["11693.50000", "1.48858686", "1596668812.038853"], ["11693.70000", "7.06725561", "1596668796.225485"], ["11694.90000", "3.52575380", "1596668744.231695"], ["11695.00000", "1.00030000", "1596668951.454381"], ["11695.30000", "0.89558128", "1596668978.689019"], ["11696.10000", "0.55400000", "1596669125.994628"], ["11697.10000", "4.00300389", "1596669127.474232"], ["11697.50000", "1.50502040", "1596668958.993184"], ["11698.00000", "8.45878728", "1596668956.001232"], ["11698.40000", "10.20622436", "1596668962.772550"], ["11698.50000", "6.40610852", "1596668960.064912"], ["11699.10000", "0.05287970", "1596669101.534443"], ["11699.90000", "0.10000000", "1596668550.388278"], ["11700.00000", "0.52000000", "1596668583.766368"], ["11700.20000", "1.00980000", "1596668634.157193"], ["11700.40000", "0.30000000", "1596668832.729128"], ["11701.10000", "0.01796445", "1596668951.834947"], ["11701.20000", "1.98348600", "1596669006.627853"], ["11701.30000", "0.90820501", "1596669039.522688"], ["11701.50000", "1.11290000", "1596668781.494521"], ["11702.00000", "0.02832779", "1596669100.217919"]], "bs": [["11665.10000", "0.34000000", "1596669133.514410"], ["11663.90000", "0.25783800", "1596669137.094341"], ["11663.30000", "0.64280140", "1596669134.815312"], ["11663.00000", "2.00000000", "1596669132.269888"], ["11662.60000", "4.27600000", "1596669135.406804"], ["11662.50000", "0.64284393", "1596669134.816992"], ["11662.00000", "2.26093025", "1596669134.494344"], ["11661.80000", "0.30000000", "1596668938.332881"], ["11661.60000", "0.64289994", "1596669123.593749"], ["11661.50000", "0.74068237", "1596669134.470662"], ["11661.10000", "0.08250000", "1596669120.445734"], ["11660.90000", "0.85707486", "1596669131.836573"], ["11660.50000", "0.04250000", "1596669119.262528"], ["11660.40000", "0.85714255", "1596668933.284339"], ["11660.00000", "1.78279722", "1596669056.138789"], ["11659.70000", "2.93910649", "1596669133.715728"], ["11659.50000", "0.09700000", "1596669134.483349"], ["11658.20000", "0.85721125", "1596668934.680059"], ["11658.00000", "1.00792097", "1596669134.880258"], ["11657.00000", "0.10000000", "1596669068.509460"], ["11656.80000", "0.66281072", "1596669135.029980"], ["11656.70000", "0.85719992", "1596669123.592099"], ["11656.20000", "0.04469307", "1596669132.752491"], ["11655.60000", "0.13407920", "1596669132.746766"], ["11655.40000", "0.08580000", "1596668959.116817"], ["11655.10000", "1.18586000", "1596669128.028202"], ["11654.70000", "0.71166248", "1596669130.603295"], ["11654.60000", "0.09800000", "1596668914.809259"], ["11654.50000", "1.92460000", "1596669134.811358"], ["11654.40000", "0.10353609", "1596669111.957598"], ["11654.20000", "1.44218428", "1596669137.144569"], ["11654.10000", "0.74400000", "1596669125.998331"], ["11653.40000", "0.43800000", "1596669120.293255"], ["11652.60000", "1.10655848", "1596669121.129618"], ["11652.40000", "0.97332000", "1596669126.457640"], ["11652.30000", "1.33679971", "1596669121.135728"], ["11652.10000", "0.91208449", "1596669111.936967"], ["11651.80000", "0.85692097", "1596669120.574110"], ["11651.60000", "0.30000000", "1596669064.444134"], ["11651.20000", "6.50000000", "1596668989.549084"], ["11650.40000", "0.38000000", "1596669119.539930"], ["11649.90000", "0.49806184", "1596669058.922923"], ["11649.50000", "3.53921879", "1596669123.943803"], ["11648.90000", "0.34965671", "1596669048.801338"], ["11648.70000", "1.00000000", "1596669124.812199"], ["11648.60000", "0.91235854", "1596669049.879704"], ["11648.20000", "1.21120014", "1596669112.486165"], ["11647.80000", "3.21709123", "1596669115.912871"], ["11647.00000", "7.70000000", "1596668960.228136"], ["11646.70000", "1.79730181", "1596669059.419868"], ["11646.60000", "2.01190039", "1596669059.246555"], ["11646.10000", "0.99629167", "1596669112.228458"], ["11646.00000", "7.09705727", "1596668986.420498"], ["11645.40000", "2.44185891", "1596668961.356005"], ["11645.10000", "4.45375572", "1596668986.175638"], ["11643.80000", "3.59891527", "1596669059.142263"], ["11643.00000", "0.98190000", "1596669122.866499"], ["11642.70000", "0.57476194", "1596668963.720667"], ["11642.10000", "0.03200000", "1596669133.800129"], ["11641.70000", "0.05288275", "1596669038.151980"], ["11641.60000", "0.30000000", "1596669121.346458"], ["11641.40000", "8.10000000", "1596668956.340593"], ["11641.10000", "3.28000000", "1596669136.796660"], ["11639.00000", "1.11290000", "1596669108.571534"], ["11638.60000", "2.01303831", "1596668889.843014"], ["11636.80000", "6.40000000", "1596668858.745613"], ["11636.00000", "2.01078592", "1596668984.718692"], ["11635.90000", "6.44197811", "1596668984.005434"], ["11635.70000", "0.90016860", "1596668964.427490"], ["11635.20000", "6.45280947", "1596669126.445792"], ["11635.10000", "17.66702998", "1596668974.273432"], ["11634.90000", "2.21906405", "1596669002.079895"], ["11634.00000", "0.91353811", "1596669118.884396"], ["11633.40000", "0.49800000", "1596669131.809112"], ["11633.10000", "0.02880380", "1596669103.561121"], ["11632.90000", "7.10374788", "1596668890.845388"], ["11632.00000", "7.69660753", "1596668860.965471"], ["11631.80000", "1.96978237", "1596668859.525378"], ["11631.60000", "3.54525923", "1596668859.484260"], ["11631.50000", "0.10576434", "1596669003.427419"], ["11631.00000", "0.17085000", "1596669127.835333"], ["11630.60000", "0.00900000", "1596669130.566653"], ["11628.00000", "0.17085000", "1596669133.227575"], ["11627.30000", "6.30000000", "1596668622.833411"], ["11626.90000", "1.03170000", "1596669062.400585"], ["11625.20000", "1.17634434", "1596669111.795105"], ["11625.00000", "0.58747374", "1596669121.553259"], ["11624.90000", "3.54659601", "1596669112.203540"], ["11624.40000", "2.01636432", "1596668842.290962"], ["11624.10000", "0.75800000", "1596669032.148731"], ["11623.60000", "20.30000000", "1596669019.375341"], ["11623.50000", "0.74857130", "1596669134.381167"], ["11622.80000", "6.90000000", "1596668499.924331"], ["11622.00000", "0.17085000", "1596668865.749616"], ["11621.70000", "0.02000000", "1596668983.570912"], ["11620.20000", "2.82164042", "1596668859.526087"], ["11619.80000", "13.92048211", "1596668954.355098"], ["11619.00000", "0.17085000", "1596668814.638662"], ["11618.90000", "0.00857235", "1596668772.999721"], ["11617.80000", "0.75800000", "1596668746.479365"]]}, "book-100", "XBT/USD"]
[270, {"b": [["11664.00000", "0.10000000", "1596669137.562720"]], "c": "3449523998"}, "book-100", "XBT/USD"]
[270, {"b": [["11662.30000", "0.01491423", "1596669138.025232"]], "c": "2210701526"}, "book-100", "XBT/USD"]
[270, {"a": [["11673.10000", "0.01491423", "1596669138.025542"]], "c": "2210701526"}, "book-100", "XBT/USD"]
[270, {"b": [["11659.80000", "0.07457120", "1596669138.082233"]], "c": "2210701526"}, "book-100", "XBT/USD"]
[270, {"b": [["11661.10000", "0.26147075", "1596669138.137119"]], "c": "2210701526"}, "book-100", "XBT/USD"]
[270, {"a": [["11673.70000", "0.07457120", "1596669138.377717"]], "c": "2210701526"}, "book-100", "XBT/USD"]
[270, {"a": [["11676.40000", "0.62031387", "1596669138.554998"]], "c": "2210701526"}, "book-100", "XBT/USD"]
[270, {"a": [["11669.10000", "0.85709658", "1596669138.570781"]], "c": "2210701526"}, "book-100", "XBT/USD"]
[270, {"a": [["11677.50000", "0.17897084", "1596669138.734976"]], "c": "2210701526"}, "book-100", "XBT/USD"]
[270, {"a": [["11665.20000", "2.48264976", "1596669138.934238"]], "c": "3812445175"}, "book-100", "XBT/USD"]
[270, {"a": [["11679.90000", "0.09100000", "1596669138.990614"]], "c": "3812445175"}, "book-100", "XBT/USD"]
[270, {"b": [["11625.00000", "0.75832374", "1596669139.015141"]], "c": "3812445175"}, "book-100", "XBT/USD"]
[270, {"a": [["11665.20000", "0.48264976", "1596669139.106344"]], "c": "2210701526"}, "book-100", "XBT/USD"]
[270, {"b": [["11663.90000", "0.00000000", "1596669139.170169"], ["11619.00000", "0.17085000", "1596668814.638662", "r"]], "c": "2951297823"}, "book-100", "XBT/USD"]
[270, {"b": [["11664.10000", "0.25784178", "1596669139.272301"]], "c": "1723610390"}, "book-100", "XBT/USD"]
[270, {"b": [["11664.00000", "0.00000000", "1596669139.409994"], ["11619.00000", "0.17085000", "1596668814.638662", "r"]], "c": "3470070274"}, "book-100", "XBT/USD"]
[270, {"b": [["11664.10000", "0.35784178", "1596669139.593827"]], "c": "3316792198"}, "book-100", "XBT/USD"]
[270, {"b": [["11656.20000", "0.00000000", "1596669139.878003"], ["11618.90000", "0.00857235", "1596668772.999721", "r"]], "c": "3316792198"}, "book-100", "XBT/USD"]
[270, {"b": [["11633.40000", "0.00000000", "1596669140.019337"], ["11617.80000", "0.75800000", "1596668746.479365", "r"]], "c": "3316792198"}, "book-100", "XBT/USD"]
[270, {"b": [["11656.90000", "0.04468632", "1596669140.101077"]], "c": "3316792198"}, "book-100", "XBT/USD"]
[270, {"b": [["11654.20000", "1.42338816", "1596669140.158671"]], "c": "3316792198"}, "book-100", "XBT/USD"]
[270, {"b": [["11654.20000", "1.42656677", "1596669140.162289"]], "c": "3316792198"}, "book-100", "XBT/USD"]
[270, {"a": [["11683.60000", "0.00000000", "1596669140.182911"], ["11701.30000", "0.90820501", "1596669039.522688", "r"]], "c": "3316792198"}, "book-100", "XBT/USD"]
[270, {"b": [["11655.60000", "0.00000000", "1596669140.491316"], ["11617.80000", "0.75800000", "1596668746.479365", "r"]], "c": "3316792198"}, "book-100", "XBT/USD"]
[270, {"b": [["11655.90000", "5.30000000", "1596669140.505168"]], "c": "3316792198"}, "book-100", "XBT/USD"]
[270, {"a": [["11688.40000", "0.53730320", "1596669140.512099"]], "c": "3316792198"}, "book-100", "XBT/USD"]
[270, {"b": [["11652.40000", "0.00000000", "1596669140.524927"], ["11617.80000", "0.75800000", "1596668746.479365", "r"]], "c": "3316792198"}, "book-100", "XBT/USD"]
[270, {"a": [["11670.10000", "0.00000000", "1596669140.546617"], ["11701.30000", "0.90820501", "1596669039.522688", "r"]], "c": "3316792198"}, "book-100", "XBT/USD"]
[270, {"b": [["11641.10000", "0.00000000", "1596669140.600083"], ["11617.70000", "6.10000000", "1596668348.496250", "r"]], "c": "3316792198"}, "book-100", "XBT/USD"]
[270, {"b": [["11654.20000", "1.44536289", "1596669140.608399"]], "c": "3316792198"}, "book-100", "XBT/USD"]
[270, {"b": [["11654.20000", "1.44218428", "1596669140.609075"]], "c": "3316792198"}, "book-100", "XBT/USD"]
[270, {"b": [["11660.40000", "1.54432255", "1596669140.645165"]], "c": "3316792198"}, "book-100", "XBT/USD"]
[270, {"a": [["11675.70000", "0.11078149", "1596669140.662160"]], "c": "3316792198"}, "book-100", "XBT/USD"]
[270, {"b": [["11656.30000", "0.13405763", "1596669140.691045"]], "c": "3316792198"}, "book-100", "XBT/USD"]
[270, {"a": [["11673.70000", "0.00000000", "1596669140.719590"], ["11701.50000", "1.11290000", "1596668781.494521", "r"]], "c": "3316792198"}, "book-100", "XBT/USD"]
[271, [["11665.20000", "0.45500000", "1596669140.739895", "b", "m", ""], ["11665.20000", "0.02764976", "1596669140.753100", "b", "m", ""], ["11665.30000", "0.64286067", "1596669140.755169", "b", "m", ""], ["11666.30000", "0.64283027", "1596669140.757319", "b", "m", ""], ["11667.00000", "0.15607461", "1596669140.760167", "b", "m", ""], ["11667.00000", "0.07558469", "1596669140.764289", "b", "m", ""]], "trade", "XBT/USD"]
[270, {"a": [["11665.20000", "0.02764976", "1596669140.739895"], ["11665.20000", "0.00000000", "1596669140.753100"], ["11702.00000", "0.02832779", "1596669100.217919", "r"], ["11665.30000", "0.00000000", "1596669140.755169"], ["11702.20000", "2.24673098", "1596669134.395861", "r"], ["11666.30000", "0.00000000", "1596669140.757320"], ["11702.90000", "3.52358543", "1596668612.362288", "r"], ["11667.00000", "0.84970484", "1596669140.760167"], ["11667.00000", "0.77412015", "1596669140.764289"]], "c": "1580652978"}, "book-100", "XBT/USD"]
[270, {"a": [["11673.10000", "0.00000000", "1596669140.768613"], ["11703.00000", "7.60000000", "1596668684.240172", "r"]], "c": "1580652978"}, "book-100", "XBT/USD"]
[270, {"a": [["11684.70000", "0.00000000", "1596669140.768701"], ["11703.60000", "2.80129308", "1596668634.214259", "r"]], "c": "1580652978"}, "book-100", "XBT/USD"]
[270, {"a": [["11674.50000", "0.15000000", "1596669140.774989"]], "c": "1580652978"}, "book-100", "XBT/USD"]
[270, {"a": [["11685.10000", "2.34858139", "1596669140.812191"]], "c": "1580652978"}, "book-100", "XBT/USD"]
[270, {"b": [["11665.20000", "3.55000000", "1596669140.831784"]], "c": "284417006"}, "book-100", "XBT/USD"]
[270, {"a": [["11677.20000", "0.69946485", "1596669140.846572"]], "c": "284417006"}, "book-100", "XBT/USD"]
[270, {"a": [["11676.40000", "0.08250000", "1596669140.874234"]], "c": "284417006"}, "book-100", "XBT/USD"]
[270, {"a": [["11665.30000", "0.50000000", "1596669140.887433"]], "c": "3002248112"}, "book-100", "XBT/USD"]
[270, {"b": [["11661.50000", "0.00000000", "1596669140.915334"], ["11617.80000", "0.75800000", "1596668746.479365", "r"]], "c": "3002248112"}, "book-100", "XBT/USD"]
[270, {"a": [["11680.90000", "0.01179445", "1596669140.918536"]], "c": "3002248112"}, "book-100", "XBT/USD"]
[270, {"a": [["11675.10000", "0.07456736", "1596669140.920968"]], "c": "3002248112"}, "book-100", "XBT/USD"]
[270, {"b": [["11665.20000", "0.00000000", "1596669140.945572"], ["11617.70000", "6.10000000", "1596668348.496250", "r"]], "c": "943191441"}, "book-100", "XBT/USD"]
[270, {"a": [["11668.00000", "0.00000000", "1596669140.951590"], ["11702.20000", "2.24673098", "1596669134.395861", "r"]], "c": "3506659762"}, "book-100", "XBT/USD"]
[270, {"a": [["11674.20000", "0.01491309", "1596669140.966036"]], "c": "3506659762"}, "book-100", "XBT/USD"]
[270, {"a": [["11665.30000", "0.00000000", "1596669141.024706"], ["11702.20000", "2.24673098", "1596669134.395861", "r"]], "c": "4243926957"}, "book-100", "XBT/USD"]
[270, {"b": [["11655.10000", "0.50000000", "1596669141.033030"]], "c": "4243926957"}, "book-100", "XBT/USD"]
[270, {"a": [["11688.40000", "0.00000000", "1596669141.069817"], ["11702.90000", "3.52358543", "1596668612.362288", "r"]], "c": "4243926957"}, "book-100", "XBT/USD"]
[270, {"a": [["11668.00000", "0.25783108", "1596669141.070922"]], "c": "1684464369"}, "book-100", "XBT/USD"]
[270, {"b": [["11662.10000", "0.74068237", "1596669141.091557"]], "c": "2415799935"}, "book-100", "XBT/USD"]
[270, {"b": [["11665.20000", "0.39874871", "1596669141.123266"]], "c": "3976663618"}, "book-100", "XBT/USD"]
[270, {"a": [["11676.50000", "3.31000984", "1596669141.166046"]], "c": "3976663618"}, "book-100", "XBT/USD"]
[270, {"a": [["11665.30000", "0.50000000", "1596669141.194446"]], "c": "2241858983"}, "book-100", "XBT/USD"]
[270, {"a": [["11666.50000", "2.00000000", "1596669141.239472"]], "c": "2642390690"}, "book-100", "XBT/USD"]
[270, {"b": [["11633.40000", "0.49800000", "1596669141.275333"]], "c": "2642390690"}, "book-100", "XBT/USD"]
[270, {"a": [["11674.10000", "1.70000000", "1596669141.280382"]], "c": "2642390690"}, "book-100", "XBT/USD"]
[270, {"b": [["11661.60000", "0.00000000", "1596669141.280918"], ["11618.90000", "0.00857235", "1596668772.999721", "r"]], "c": "2642390690"}, "book-100", "XBT/USD"]
[270, {"a": [["11666.40000", "0.64282616", "1596669141.339861"]], "c": "2110101833"}, "book-100", "XBT/USD"]
[270, {"a": [["11666.30000", "0.64283027", "1596669141.340007"]], "c": "4248983212"}, "book-100", "XBT/USD"]
[270, {"b": [["11664.00000", "0.64282616", "1596669141.366377"]], "c": "2136761585"}, "book-100", "XBT/USD"]
[270, {"a": [["11668.70000", "0.00000000", "1596669141.418945"], ["11701.20000", "1.98348600", "1596669006.627853", "r"]], "c": "2796246824"}, "book-100", "XBT/USD"]
[270, {"a": [["11666.20000", "0.73635082", "1596669141.463386"]], "c": "33062415"}, "book-100", "XBT/USD"]
[270, {"b": [["11662.80000", "0.69186000", "1596669141.515520"]], "c": "2728406239"}, "book-100", "XBT/USD"]
[270, {"b": [["11648.70000", "0.00000000", "1596669141.654475"], ["11619.00000", "0.17085000", "1596668814.638662", "r"]], "c": "2728406239"}, "book-100", "XBT/USD"]
[270, {"a": [["11674.50000", "0.00000000", "1596669141.695564"], ["11701.20000", "1.98348600", "1596669006.627853", "r"]], "c": "2728406239"}, "book-100", "XBT/USD"]
[270, {"a": [["11674.90000", "0.04468741", "1596669141.701290"]], "c": "2728406239"}, "book-100", "XBT/USD"]
[270, {"b": [["11654.20000", "1.44536289", "1596669141.710130"]], "c": "2728406239"}, "book-100", "XBT/USD"]
[270, {"b": [["11665.20000", "0.00000000", "1596669141.713660"], ["11618.90000", "0.00857235", "1596668772.999721", "r"]], "c": "3446537910"}, "book-100", "XBT/USD"]
[270, {"b": [["11662.80000", "0.00000000", "1596669141.717224"], ["11617.80000", "0.75800000", "1596668746.479365", "r"]], "c": "1665267292"}, "book-100", "XBT/USD"]
[270, {"a": [["11665.30000", "0.00000000", "1596669141.768743"], ["11701.30000", "0.90820501", "1596669039.522688", "r"]], "c": "1364891846"}, "book-100", "XBT/USD"]
[270, {"a": [["11665.20000", "0.50000000", "1596669141.816436"]], "c": "1967867525"}, "book-100", "XBT/USD"]
[270, {"b": [["11664.70000", "0.28000000", "1596669141.822207"]], "c": "2864987693"}, "book-100", "XBT/USD"]
[270, {"b": [["11654.20000", "1.42656677", "1596669141.862598"]], "c": "2864987693"}, "book-100", "XBT/USD"]
[270, {"b": [["11656.50000", "0.99200000", "1596669141.899536"]], "c": "2864987693"}, "book-100", "XBT/USD"]
[270, {"a": [["11670.30000", "1.70600000", "1596669142.509516"]], "c": "2864987693"}, "book-100", "XBT/USD"]
[270, {"a": [["11681.40000", "3.42007168", "1596669142.545747"]], "c": "2864987693"}, "book-100", "XBT/USD"]
[271, [["11665.20000", "0.02300000", "1596669142.940377", "b", "m", ""]], "trade", "XBT/USD"]
[270, {"a": [["11665.20000", "0.47700000", "1596669142.940377"]], "c": "192767554"}, "book-100", "XBT/USD"]
[270, {"b": [["11665.10000", "2.89000000", "1596669143.304858"]], "c": "194827892"}, "book-100", "XBT/USD"]
[270, {"b": [["11662.10000", "0.00000000", "1596669143.344036"], ["11618.90000", "0.00857235", "1596668772.999721", "r"]], "c": "2369879309"}, "book-100", "XBT/USD"]
[270, {"b": [["11665.10000", "0.34000000", "1596669143.366413"]], "c": "1123748132"}, "book-100", "XBT/USD"]
[270, {"b": [["11662.00000", "0.55393025", "1596669143.462468"]], "c": "367875443"}, "book-100", "XBT/USD"]
[270, {"b": [["11661.60000", "0.74068237", "1596669143.543905"]], "c": "367875443"}, "book-100", "XBT/USD"]
[270, {"b": [["11643.90000", "0.00457472", "1596669143.727993"]], "c": "367875443"}, "book-100", "XBT/USD"]
[270, {"a": [["11666.20000", "0.00000000", "1596669143.733056"], ["11701.20000", "1.98348600", "1596669006.627853", "r"]], "c": "3202272684"}, "book-100", "XBT/USD"]
[270, {"a": [["11683.60000", "0.00438186", "1596669143.756984"]], "c": "3202272684"}, "book-100", "XBT/USD"]
[270, {"a": [["11666.10000", "0.73635082", "1596669143.778445"]], "c": "3159495261"}, "book-100", "XBT/USD"]
[270, {"a": [["11666.10000", "0.00000000", "1596669143.824213"], ["11701.10000", "0.01796445", "1596668951.834947", "r"]], "c": "3202272684"}, "book-100", "XBT/USD"]
[270, {"a": [["11666.00000", "0.73635082", "1596669143.867267"]], "c": "1843932536"}, "book-100", "XBT/USD"]
[270, {"a": [["11666.30000", "0.00000000", "1596669143.891077"], ["11701.10000", "0.01796445", "1596668951.834947", "r"]], "c": "162243150"}, "book-100", "XBT/USD"]
[270, {"a": [["11666.00000", "0.00000000", "1596669143.921336"], ["11701.20000", "1.98348600", "1596669006.627853", "r"]], "c": "3814227539"}, "book-100", "XBT/USD"]
[270, {"a": [["11669.40000", "0.00000000", "1596669143.932980"], ["11701.30000", "0.90820501", "1596669039.522688", "r"]], "c": "3814227539"}, "book-100", "XBT/USD"]
[270, {"a": [["11668.80000", "0.00000000", "1596669143.949884"], ["11701.50000", "1.11290000", "1596668781.494521", "r"]], "c": "3978313479"}, "book-100", "XBT/USD"]
