[270, {"as": [["11652.30000", "1.54278080", "1596667916.242771"], ["11654.10000", "0.01000000", "1596667899.804340"], ["11659.00000", "1.67168000", "1596667911.964662"], ["11659.10000", "2.07427719", "1596667894.045329"], ["11659.20000", "2.93475458", "1596667902.966226"], ["11660.00000", "3.10000000", "1596667913.879122"], ["11660.70000", "2.00000000", "1596667916.864128"], ["11660.80000", "4.28300000", "1596667913.369966"], ["11660.90000", "0.85746317", "1596667914.191733"], ["11662.30000", "0.64325715", "1596667913.561514"], ["11662.40000", "0.64321659", "1596667916.212743"], ["11662.70000", "0.49090844", "1596667912.948469"], ["11663.70000", "0.04250000", "1596667916.191571"], ["11663.80000", "1.91448667", "1596667916.251228"], ["11664.30000", "0.10300000", "1596667914.973346"], ["11664.60000", "0.85766433", "1596667895.556982"], ["11664.90000", "0.08250000", "1596667910.954260"], ["11665.00000", "0.85755126", "1596667885.846845"], ["11666.20000", "1.50000000", "1596667914.121102"], ["11667.00000", "0.55900847", "1596667914.176685"], ["11667.20000", "1.73613458", "1596667912.681909"], ["11667.60000", "0.96458000", "1596667915.092980"], ["11667.70000", "0.69702387", "1596667914.891514"], ["11667.80000", "0.70560000", "1596667905.000428"], ["11668.80000", "0.50000000", "1596667911.793658"], ["11669.30000", "0.10000000", "1596667725.682463"], ["11669.40000", "0.33861518", "1596667916.395820"], ["11669.50000", "0.69969596", "1596667915.669659"], ["11669.70000", "0.11078149", "1596667914.640504"], ["11669.80000", "0.85819726", "1596667902.252616"], ["11670.00000", "43.90525970", "1596667913.551476"], ["11670.30000", "0.85800987", "1596667905.260241"], ["11670.60000", "0.30000000", "1596667891.387622"], ["11671.10000", "3.70883344", "1596667915.346068"], ["11671.20000", "0.65267749", "1596667914.277715"], ["11671.70000", "6.21540540", "1596667904.902437"], ["11671.80000", "5.20000000", "1596667870.914136"], ["11672.10000", "0.38000000", "1596667914.482639"], ["11672.40000", "0.97420000", "1596667913.668338"], ["11672.80000", "0.71088475", "1596667916.398458"], ["11673.00000", "0.85772743", "1596667913.551397"], ["11673.20000", "0.10334739", "1596667914.695402"], ["11674.60000", "0.85777771", "1596667913.552890"], ["11675.00000", "0.01821000", "1596667898.332657"], ["11675.10000", "1.42148940", "1596667916.395324"], ["11675.40000", "4.51883285", "1596667914.325551"], ["11675.50000", "1.63357998", "1596667914.694111"], ["11675.80000", "0.43900000", "1596667902.994786"], ["11675.90000", "0.34906884", "1596667914.942261"], ["11676.00000", "5.10000000", "1596667857.511429"], ["11677.90000", "3.53159007", "1596667914.599580"], ["11678.20000", "0.74930279", "1596667912.676044"], ["11678.80000", "0.51604662", "1596667914.182308"], ["11678.90000", "4.02819791", "1596667915.304373"], ["11679.00000", "0.91001799", "1596667914.801393"], ["11680.70000", "2.00612320", "1596667906.583648"], ["11680.80000", "0.30000000", "1596667730.365123"], ["11680.90000", "7.07692672", "1596667916.819260"], ["11681.20000", "0.02573600", "1596667743.443916"], ["11681.40000", "3.21424985", "1596667914.691891"], ["11681.60000", "0.34904521", "1596667901.907402"], ["11681.90000", "8.00000000", "1596667893.353561"], ["11682.00000", "1.00770000", "1596667893.311830"], ["11682.10000", "5.64889471", "1596667705.518861"], ["11682.40000", "5.88869620", "1596667915.579786"], ["11683.70000", "0.99336144", "1596667914.647061"], ["11683.80000", "0.05293643", "1596667903.376477"], ["11684.30000", "0.90964860", "1596667906.291675"], ["11684.40000", "0.00300000", "1596667833.025347"], ["11684.90000", "6.39596921", "1596667904.938771"], ["11685.30000", "0.89700000", "1596667914.383890"], ["11685.60000", "2.00000000", "1596667902.770332"], ["11686.70000", "1.96081289", "1596667906.192801"], ["11687.30000", "8.20000000", "1596667061.296774"], ["11688.10000", "7.07262686", "1596667911.103308"], ["11688.30000", "3.52844773", "1596667909.190298"], ["11689.90000", "0.10000000", "1596667326.899060"], ["11690.00000", "0.04000000", "1596667586.146170"], ["11690.10000", "2.29920000", "1596667684.421614"], ["11690.40000", "2.99612706", "1596667894.241122"], ["11690.60000", "0.75800000", "1596667896.700157"], ["11690.80000", "0.30000000", "1596667706.691674"], ["11691.60000", "0.02831275", "1596667891.421580"], ["11692.30000", "8.50000000", "1596667892.430053"], ["11692.40000", "2.00411577", "1596667906.600330"], ["11695.30000", "2.24899812", "1596667910.627956"], ["11696.60000", "1.16965211", "1596667901.843847"], ["11698.00000", "6.50000000", "1596667764.064891"], ["11698.30000", "2.80320844", "1596667906.180176"], ["11699.00000", "1.11290000", "1596667743.279977"], ["11699.60000", "20.43455784", "1596667908.878026"], ["11699.90000", "3.62494941", "1596667909.097572"], ["11700.00000", "0.52000000", "1596667900.689690"], ["11700.60000", "2.00132141", "1596667743.437665"], ["11701.10000", "0.01796445", "1596667535.981575"], ["11702.20000", "1.51500000", "1596667895.990387"], ["11702.50000", "2.30957145", "1596667892.925062"], ["11704.00000", "1.98332376", "1596667892.361722"], ["11704.10000", "8.30000000", "1596667058.485416"], ["11704.60000", "18.00000000", "1596667881.119389"]], "bs": [["11652.20000", "4.56270547", "1596667916.880225"], ["11652.10000", "0.48203438", "1596667913.343038"], ["11651.80000", "4.28000000", "1596667911.824956"], ["11651.70000", "0.64352960", "1596667908.695885"], ["11651.40000", "0.69791000", "1596667910.175148"], ["11651.20000", "0.85772743", "1596667916.531033"], ["11651.10000", "0.74068237", "1596667916.024128"], ["11650.60000", "0.64356579", "1596667911.803416"], ["11650.40000", "0.85792554", "1596667915.901508"], ["11649.70000", "2.41832797", "1596667913.889084"], ["11649.60000", "0.08250000", "1596667910.507517"], ["11649.00000", "9.99987003", "1596667914.421616"], ["11648.50000", "0.67894000", "1596667910.007498"], ["11647.80000", "0.85759334", "1596667906.010056"], ["11647.70000", "1.50000000", "1596667913.039912"], ["11647.10000", "0.10200000", "1596667900.999816"], ["11646.20000", "0.69405459", "1596667913.368104"], ["11646.10000", "0.85766342", "1596667911.624406"], ["11645.80000", "1.92064000", "1596667910.565085"], ["11645.30000", "2.03263641", "1596667904.512274"], ["11645.20000", "8.95772076", "1596667910.047412"], ["11644.90000", "0.10359855", "1596667911.878192"], ["11644.80000", "0.02576473", "1596667914.882370"], ["11644.70000", "1.94890000", "1596667913.339856"], ["11644.60000", "1.15153426", "1596667912.027291"], ["11644.30000", "0.10300000", "1596667900.687575"], ["11642.60000", "0.72533308", "1596667911.890868"], ["11642.30000", "1.42535006", "1596667912.030437"], ["11642.10000", "2.00000000", "1596667916.040968"], ["11642.00000", "0.30000000", "1596667890.242774"], ["11641.70000", "0.63300000", "1596667914.401612"], ["11641.50000", "0.85788155", "1596667892.858104"], ["11641.40000", "0.09700000", "1596667897.774309"], ["11641.20000", "0.49849401", "1596667914.636066"], ["11640.90000", "0.91303998", "1596667904.595381"], ["11640.60000", "0.38000000", "1596667914.481531"], ["11640.30000", "0.35013641", "1596667913.638103"], ["11639.60000", "6.50000000", "1596667914.007071"], ["11639.20000", "0.91312978", "1596667912.020193"], ["11637.80000", "4.42414239", "1596667915.567722"], ["11637.40000", "2.91067106", "1596667910.022347"], ["11637.30000", "0.99620000", "1596667913.670094"], ["11637.00000", "2.01358772", "1596667916.794981"], ["11636.10000", "0.50000000", "1596667901.080347"], ["11635.60000", "0.57545645", "1596667913.631847"], ["11635.40000", "0.99748501", "1596667915.461311"], ["11635.10000", "9.09976907", "1596667916.770600"], ["11633.20000", "0.05292594", "1596667914.545643"], ["11633.10000", "3.54519050", "1596667909.094953"], ["11632.30000", "3.44631601", "1596667901.482520"], ["11632.00000", "0.30000000", "1596667907.106642"], ["11631.80000", "0.91377491", "1596667902.397670"], ["11631.50000", "2.97543772", "1596667903.052020"], ["11630.90000", "1.11290000", "1596667902.454881"], ["11630.10000", "8.60000000", "1596667899.711208"], ["11629.00000", "2.01508189", "1596667902.633152"], ["11628.60000", "0.90125664", "1596667913.637355"], ["11628.10000", "0.03100000", "1596667899.801627"], ["11626.90000", "7.10979481", "1596667916.821835"], ["11626.20000", "6.42900799", "1596667915.572355"], ["11625.90000", "6.80560000", "1596667914.279579"], ["11625.80000", "0.91422587", "1596667904.605174"], ["11625.50000", "2.00000000", "1596667893.735191"], ["11625.00000", "0.25000000", "1596667914.338686"], ["11624.00000", "14.48253557", "1596667915.855408"], ["11623.90000", "1.17664368", "1596667661.856627"], ["11623.80000", "0.91396904", "1596667899.575313"], ["11623.50000", "5.14375579", "1596667661.787438"], ["11623.20000", "1.49783330", "1596667894.239861"], ["11622.70000", "0.02877341", "1596667895.433104"], ["11622.00000", "0.66885000", "1596667915.147631"], ["11621.70000", "1.51581161", "1596667894.975716"], ["11621.40000", "0.10584264", "1596667893.023066"], ["11620.50000", "2.01346801", "1596667897.685130"], ["11620.40000", "1.97200499", "1596667916.576958"], ["11619.90000", "2.01579242", "1596667661.590770"], ["11619.00000", "7.17085000", "1596667906.160929"], ["11617.50000", "2.29920000", "1596667895.985095"], ["11615.60000", "0.20000000", "1596667524.155155"], ["11614.70000", "2.01780324", "1596667895.927331"], ["11612.30000", "7.00000000", "1596667548.784533"], ["11612.10000", "3.55105569", "1596667661.029906"], ["11612.00000", "1.04950000", "1596667892.886807"], ["11609.80000", "21.20000000", "1596666704.766154"], ["11608.90000", "13.93355253", "1596667914.201337"], ["11607.90000", "0.75800000", "1596667895.993068"], ["11607.70000", "8.40000000", "1596666861.504830"], ["11607.40000", "2.74914996", "1596667912.679200"], ["11607.30000", "5.57163332", "1596667898.020182"], ["11607.00000", "0.17085000", "1596667899.798824"], ["11606.80000", "0.02000000", "1596667530.002131"], ["11606.50000", "2.49957874", "1596667631.914751"], ["11605.70000", "0.48590000", "1596667662.750190"], ["11605.60000", "0.00858221", "1596667350.675538"], ["11604.00000", "0.17085000", "1596667886.545059"], ["11603.90000", "1.51500000", "1596667192.515227"], ["11603.20000", "0.75800000", "1596667895.514200"], ["11602.10000", "7.70000000", "1596667719.295606"], ["11601.00000", "0.17085000", "1596667717.088683"], ["11600.70000", "3.45580629", "1596667893.225216"]]}, "book-100", "XBT/USD"]
[270, {"b": [["11631.80000", "0.00000000", "1596667917.091965"], ["11600.60000", "3.55457595", "1596667787.416388", "r"]], "c": "2990270648"}, "book-100", "XBT/USD"]
[270, {"a": [["11683.30000", "0.90948715", "1596667917.134846"]], "c": "2990270648"}, "book-100", "XBT/USD"]
[270, {"b": [["11651.60000", "0.09621094", "1596667917.141213"]], "c": "1564831892"}, "book-100", "XBT/USD"]
[270, {"b": [["11622.00000", "0.17085000", "1596667917.145353"]], "c": "1564831892"}, "book-100", "XBT/USD"]
[270, {"a": [["11663.40000", "0.09621094", "1596667917.155657"]], "c": "1564831892"}, "book-100", "XBT/USD"]
[270, {"a": [["11664.60000", "2.85766433", "1596667917.224843"]], "c": "1564831892"}, "book-100", "XBT/USD"]
[270, {"b": [["11616.00000", "0.17085000", "1596667917.272615"]], "c": "1564831892"}, "book-100", "XBT/USD"]
[270, {"b": [["11640.90000", "0.00000000", "1596667917.414513"], ["11600.70000", "3.45580629", "1596667893.225216", "r"]], "c": "1564831892"}, "book-100", "XBT/USD"]
[270, {"b": [["11648.30000", "0.33922855", "1596667917.477078"]], "c": "1564831892"}, "book-100", "XBT/USD"]
[270, {"b": [["11642.30000", "0.00000000", "1596667917.546587"], ["11600.70000", "3.45580629", "1596667893.225216", "r"]], "c": "1564831892"}, "book-100", "XBT/USD"]
[270, {"b": [["11635.10000", "7.30000000", "1596667917.551953"]], "c": "1564831892"}, "book-100", "XBT/USD"]
[270, {"b": [["11644.60000", "0.43900000", "1596667917.552260"]], "c": "1564831892"}, "book-100", "XBT/USD"]
[270, {"b": [["11620.40000", "0.00000000", "1596667917.561698"], ["11600.60000", "3.55457595", "1596667787.416388", "r"]], "c": "1564831892"}, "book-100", "XBT/USD"]
[270, {"a": [["11664.60000", "0.85766433", "1596667917.574392"]], "c": "1564831892"}, "book-100", "XBT/USD"]
[270, {"a": [["11658.90000", "0.51130000", "1596667917.576570"]], "c": "1815570195"}, "book-100", "XBT/USD"]
[270, {"a": [["11652.30000", "1.00000000", "1596667917.580014"]], "c": "1857974897"}, "book-100", "XBT/USD"]
[270, {"b": [["11652.20000", "5.05320547", "1596667917.650228"]], "c": "1892144259"}, "book-100", "XBT/USD"]
[270, {"b": [["11648.30000", "0.00000000", "1596667917.667025"], ["11600.40000", "3.04390225", "1596667887.457186", "r"]], "c": "1892144259"}, "book-100", "XBT/USD"]
[270, {"b": [["11647.70000", "0.00000000", "1596667917.762943"], ["11600.30000", "3.00051863", "1596667659.125212", "r"]], "c": "1892144259"}, "book-100", "XBT/USD"]
[270, {"b": [["11652.20000", "4.56270547", "1596667917.833495"]], "c": "1857974897"}, "book-100", "XBT/USD"]
[270, {"b": [["11651.20000", "2.35772743", "1596667917.916987"]], "c": "2594159435"}, "book-100", "XBT/USD"]
[270, {"a": [["11663.60000", "0.01492403", "1596667918.156620"]], "c": "2594159435"}, "book-100", "XBT/USD"]
[270, {"b": [["11652.00000", "0.01492403", "1596667918.156785"]], "c": "4151891606"}, "book-100", "XBT/USD"]
[270, {"b": [["11652.00000", "0.08954416", "1596667918.157716"]], "c": "2439890910"}, "book-100", "XBT/USD"]
[270, {"b": [["11636.10000", "1.41317634", "1596667918.175263"]], "c": "2439890910"}, "book-100", "XBT/USD"]
[270, {"b": [["11644.30000", "1.01553327", "1596667918.179736"]], "c": "2439890910"}, "book-100", "XBT/USD"]
[270, {"b": [["11647.90000", "0.17908831", "1596667918.218784"]], "c": "2439890910"}, "book-100", "XBT/USD"]
[270, {"a": [["11664.10000", "0.07462013", "1596667918.218981"]], "c": "2439890910"}, "book-100", "XBT/USD"]
[270, {"b": [["11626.50000", "0.49800000", "1596667918.316584"]], "c": "2439890910"}, "book-100", "XBT/USD"]
[270, {"a": [["11667.60000", "1.14366762", "1596667918.344293"]], "c": "2439890910"}, "book-100", "XBT/USD"]
[270, {"b": [["11652.20000", "4.56788697", "1596667918.489018"]], "c": "3817315290"}, "book-100", "XBT/USD"]
[270, {"b": [["11652.20000", "5.05838697", "1596667918.764367"]], "c": "1523364735"}, "book-100", "XBT/USD"]
[270, {"a": [["11683.30000", "1.48252169", "1596667918.959809"]], "c": "1523364735"}, "book-100", "XBT/USD"]
[270, {"b": [["11651.10000", "0.00000000", "1596667918.959876"], ["11600.60000", "3.55457595", "1596667787.416388", "r"]], "c": "2091358149"}, "book-100", "XBT/USD"]
[270, {"a": [["11675.10000", "1.67080984", "1596667918.961896"]], "c": "2091358149"}, "book-100", "XBT/USD"]
[270, {"b": [["11644.40000", "0.24997776", "1596667918.963672"]], "c": "2091358149"}, "book-100", "XBT/USD"]
[270, {"a": [["11657.40000", "0.09700000", "1596667919.000202"]], "c": "2969044479"}, "book-100", "XBT/USD"]
[270, {"a": [["11662.40000", "0.00000000", "1596667919.030312"], ["11701.10000", "0.01796445", "1596667535.981575", "r"]], "c": "2969044479"}, "book-100", "XBT/USD"]
[270, {"a": [["11663.20000", "3.17390855", "1596667919.032361"]], "c": "2969044479"}, "book-100", "XBT/USD"]
[270, {"b": [["11652.20000", "4.55838697", "1596667919.039794"]], "c": "1684320966"}, "book-100", "XBT/USD"]
[270, {"a": [["11660.90000", "0.00000000", "1596667919.048748"], ["11701.10000", "0.01796445", "1596667535.981575", "r"]], "c": "1684320966"}, "book-100", "XBT/USD"]
[270, {"b": [["11652.20000", "4.05838697", "1596667919.095249"]], "c": "624946543"}, "book-100", "XBT/USD"]
[270, {"a": [["11660.20000", "0.64329236", "1596667919.098395"]], "c": "3221653326"}, "book-100", "XBT/USD"]
[270, {"b": [["11650.60000", "0.00000000", "1596667919.101702"], ["11600.60000", "3.55457595", "1596667787.416388", "r"]], "c": "193542804"}, "book-100", "XBT/USD"]
[270, {"b": [["11646.50000", "2.09980036", "1596667919.107694"]], "c": "193542804"}, "book-100", "XBT/USD"]
[270, {"a": [["11669.50000", "0.00000000", "1596667919.115177"], ["11701.10000", "0.01796445", "1596667535.981575", "r"]], "c": "193542804"}, "book-100", "XBT/USD"]
[270, {"b": [["11648.30000", "0.74068237", "1596667919.118788"]], "c": "193542804"}, "book-100", "XBT/USD"]
[270, {"a": [["11660.80000", "0.00000000", "1596667919.126838"], ["11702.20000", "1.51500000", "1596667895.990387", "r"]], "c": "193542804"}, "book-100", "XBT/USD"]
[270, {"b": [["11644.80000", "0.00000000", "1596667919.130827"], ["11600.70000", "3.45580629", "1596667893.225216", "r"]], "c": "193542804"}, "book-100", "XBT/USD"]
[270, {"b": [["11652.00000", "0.01492403", "1596667919.139656"]], "c": "1944643111"}, "book-100", "XBT/USD"]
[270, {"b": [["11652.20000", "3.64338697", "1596667919.141478"]], "c": "1694291860"}, "book-100", "XBT/USD"]
[270, {"a": [["11667.20000", "0.00000000", "1596667919.174928"], ["11702.50000", "2.30957145", "1596667892.925062", "r"]], "c": "1694291860"}, "book-100", "XBT/USD"]
[270, {"a": [["11666.20000", "2.19979485", "1596667919.179526"]], "c": "1694291860"}, "book-100", "XBT/USD"]
[270, {"b": [["11651.20000", "0.85772743", "1596667919.203693"]], "c": "492678916"}, "book-100", "XBT/USD"]
[270, {"a": [["11669.70000", "0.00000000", "1596667919.208645"], ["11704.00000", "1.98332376", "1596667892.361722", "r"]], "c": "492678916"}, "book-100", "XBT/USD"]
[270, {"b": [["11642.70000", "0.04223397", "1596667919.218326"]], "c": "492678916"}, "book-100", "XBT/USD"]
[270, {"b": [["11651.40000", "0.00000000", "1596667919.236554"], ["11600.70000", "3.45580629", "1596667893.225216", "r"]], "c": "889008661"}, "book-100", "XBT/USD"]
[270, {"a": [["11662.20000", "0.78619000", "1596667919.244486"]], "c": "889008661"}, "book-100", "XBT/USD"]
[270, {"a": [["11667.70000", "0.02854588", "1596667919.250795"]], "c": "889008661"}, "book-100", "XBT/USD"]
[270, {"b": [["11649.70000", "0.00000000", "1596667919.263613"], ["11600.60000", "3.55457595", "1596667787.416388", "r"]], "c": "3211599616"}, "book-100", "XBT/USD"]
[270, {"a": [["11662.30000", "0.00000000", "1596667919.285894"], ["11704.00000", "1.98332376", "1596667892.361722", "r"]], "c": "3211599616"}, "book-100", "XBT/USD"]
[270, {"a": [["11678.20000", "0.00000000", "1596667919.287377"], ["11704.10000", "8.30000000", "1596667058.485416", "r"]], "c": "3211599616"}, "book-100", "XBT/USD"]
[270, {"b": [["11652.20000", "3.15288697", "1596667919.287659"]], "c": "336886619"}, "book-100", "XBT/USD"]
[270, {"b": [["11607.40000", "1.99984717", "1596667919.289044"]], "c": "336886619"}, "book-100", "XBT/USD"]
[270, {"a": [["11660.60000", "0.25800336", "1596667919.289257"]], "c": "2657617272"}, "book-100", "XBT/USD"]
[270, {"a": [["11661.30000", "0.64322614", "1596667919.291078"]], "c": "2657617272"}, "book-100", "XBT/USD"]
[270, {"a": [["11663.70000", "0.00000000", "1596667919.291558"], ["11704.00000", "1.98332376", "1596667892.361722", "r"]], "c": "2657617272"}, "book-100", "XBT/USD"]
[270, {"a": [["11679.70000", "0.74915923", "1596667919.310689"]], "c": "2657617272"}, "book-100", "XBT/USD"]
[270, {"b": [["11609.70000", "0.74915923", "1596667919.310797"]], "c": "2657617272"}, "book-100", "XBT/USD"]
[270, {"a": [["11655.80000", "0.85420800", "1596667919.313681"]], "c": "3934878122"}, "book-100", "XBT/USD"]
[270, {"b": [["11646.20000", "0.00000000", "1596667919.333553"], ["11600.60000", "3.55457595", "1596667787.416388", "r"]], "c": "3934878122"}, "book-100", "XBT/USD"]
[270, {"a": [["11662.10000", "0.69291999", "1596667919.334936"]], "c": "3934878122"}, "book-100", "XBT/USD"]
[270, {"b": [["11652.20000", "2.75288697", "1596667919.348373"]], "c": "4161935952"}, "book-100", "XBT/USD"]
[270, {"b": [["11652.00000", "0.00000000", "1596667919.350849"], ["11600.40000", "3.04390225", "1596667887.457186", "r"]], "c": "2545601727"}, "book-100", "XBT/USD"]
[270, {"a": [["11682.40000", "4.09603284", "1596667919.352381"]], "c": "2545601727"}, "book-100", "XBT/USD"]
[270, {"b": [["11647.70000", "1.50000000", "1596667919.354109"]], "c": "2545601727"}, "book-100", "XBT/USD"]
[270, {"b": [["11648.50000", "0.00000000", "1596667919.354869"], ["11600.40000", "3.04390225", "1596667887.457186", "r"]], "c": "1476768107"}, "book-100", "XBT/USD"]
[270, {"a": [["11675.10000", "0.24932044", "1596667919.356405"]], "c": "1476768107"}, "book-100", "XBT/USD"]
[270, {"a": [["11672.80000", "0.00000000", "1596667919.362315"], ["11702.20000", "1.51500000", "1596667895.990387", "r"]], "c": "1476768107"}, "book-100", "XBT/USD"]
[270, {"a": [["11677.90000", "0.00000000", "1596667919.368940"], ["11702.50000", "2.30957145", "1596667892.925062", "r"]], "c": "1476768107"}, "book-100", "XBT/USD"]
[270, {"a": [["11669.40000", "0.00000000", "1596667919.376472"], ["11704.00000", "1.98332376", "1596667892.361722", "r"]], "c": "1476768107"}, "book-100", "XBT/USD"]
[270, {"b": [["11642.70000", "0.00000000", "1596667919.379892"], ["11600.30000", "3.00051863", "1596667659.125212", "r"]], "c": "1476768107"}, "book-100", "XBT/USD"]
[270, {"a": [["11675.50000", "0.72328919", "1596667919.380227"]], "c": "1476768107"}, "book-100", "XBT/USD"]
[270, {"b": [["11652.20000", "2.66706663", "1596667919.380879"]], "c": "826342781"}, "book-100", "XBT/USD"]
[270, {"a": [["11679.00000", "0.00000000", "1596667919.382329"], ["11704.10000", "8.30000000", "1596667058.485416", "r"]], "c": "826342781"}, "book-100", "XBT/USD"]
[270, {"b": [["11641.80000", "0.02577128", "1596667919.386969"]], "c": "826342781"}, "book-100", "XBT/USD"]
[270, {"b": [["11652.20000", "2.36706663", "1596667919.394527"]], "c": "1880859348"}, "book-100", "XBT/USD"]
[270, {"b": [["11647.90000", "0.00000000", "1596667919.439492"], ["11600.30000", "3.00051863", "1596667659.125212", "r"]], "c": "1880859348"}, "book-100", "XBT/USD"]
[270, {"b": [["11652.20000", "2.40956663", "1596667919.440057"]], "c": "889644486"}, "book-100", "XBT/USD"]
[270, {"a": [["11661.20000", "0.04250000", "1596667919.441019"]], "c": "889644486"}, "book-100", "XBT/USD"]
[270, {"b": [["11648.30000", "0.00000000", "1596667919.455224"], ["11600.10000", "0.05000000", "1596667808.971124", "r"]], "c": "2178867467"}, "book-100", "XBT/USD"]
[270, {"a": [["11659.80000", "2.71880574", "1596667919.482192"]], "c": "2139945618"}, "book-100", "XBT/USD"]
[270, {"b": [["11647.70000", "0.00000000", "1596667919.499443"], ["11600.00000", "0.46774162", "1596667672.299279", "r"]], "c": "2139945618"}, "book-100", "XBT/USD"]
[270, {"b": [["11641.80000", "0.00000000", "1596667919.511853"], ["11598.80000", "10.88860000", "1596667583.730204", "r"]], "c": "2139945618"}, "book-100", "XBT/USD"]
[270, {"b": [["11651.80000", "0.00000000", "1596667919.512839"], ["11598.20000", "0.36020033", "1596667907.373151", "r"]], "c": "2426538994"}, "book-100", "XBT/USD"]
[270, {"b": [["11639.70000", "0.02577522", "1596667919.514247"]], "c": "2426538994"}, "book-100", "XBT/USD"]
[270, {"a": [["11661.30000", "0.00000000", "1596667919.517574"], ["11704.00000", "1.98332376", "1596667892.361722", "r"]], "c": "2426538994"}, "book-100", "XBT/USD"]
[270, {"a": [["11674.60000", "0.00000000", "1596667919.518597"], ["11704.10000", "8.30000000", "1596667058.485416", "r"]], "c": "2426538994"}, "book-100", "XBT/USD"]
[270, {"a": [["11658.50000", "0.63246000", "1596667919.523243"]], "c": "725230260"}, "book-100", "XBT/USD"]
