[270, {"as": [["11667.10000", "0.12784648", "1596669443.242869"], ["11667.20000", "0.50000000", "1596669442.799512"], ["11667.60000", "0.05313798", "1596669443.489807"], ["11667.70000", "0.73635082", "1596669443.286091"], ["11667.80000", "0.51240151", "1596669442.724518"], ["11668.00000", "0.64279514", "1596669429.756687"], ["11668.40000", "0.64286037", "1596669442.793800"], ["11668.60000", "0.01000000", "1596669430.684370"], ["11668.70000", "0.25781682", "1596669443.486287"], ["11668.80000", "0.15000000", "1596669442.928175"], ["11668.90000", "0.78860000", "1596669443.174842"], ["11669.00000", "0.95029516", "1596669429.700185"], ["11669.30000", "4.37500000", "1596669377.798069"], ["11670.00000", "44.76226097", "1596669241.870295"], ["11670.20000", "0.04250000", "1596669390.800570"], ["11670.30000", "0.85706689", "1596669354.250314"], ["11670.90000", "0.49551540", "1596669256.098573"], ["11671.00000", "0.21976352", "1596669195.647290"], ["11671.10000", "0.33409662", "1596669422.898158"], ["11671.60000", "1.50000000", "1596669434.053892"], ["11671.90000", "0.48144780", "1596669385.671940"], ["11672.20000", "0.85685516", "1596669433.875256"], ["11672.30000", "0.09621094", "1596669437.037734"], ["11673.30000", "0.88795004", "1596669360.843364"], ["11673.80000", "0.09600000", "1596669134.769695"], ["11674.60000", "2.04162952", "1596669435.153590"], ["11674.80000", "1.25000000", "1596669396.442912"], ["11675.00000", "0.01821000", "1596669377.613351"], ["11675.20000", "0.85714891", "1596669211.461992"], ["11676.00000", "0.04471338", "1596669403.251130"], ["11676.50000", "0.11100000", "1596669419.728296"], ["11676.60000", "0.62916000", "1596669380.722187"], ["11676.80000", "0.61078149", "1596669427.174211"], ["11676.90000", "0.33832274", "1596669426.722910"], ["11677.20000", "0.02700000", "1596669433.386658"], ["11677.60000", "0.13413445", "1596669442.862998"], ["11678.00000", "0.69944172", "1596669420.933668"], ["11678.10000", "0.70560000", "1596669418.104024"], ["11679.70000", "0.10327498", "1596669316.118783"], ["11679.90000", "2.09100000", "1596669318.695248"], ["11680.00000", "0.85718556", "1596669379.208040"], ["11680.10000", "1.01017173", "1596669401.982623"], ["11680.90000", "0.38000000", "1596669388.922021"], ["11681.10000", "3.52379255", "1596669382.845237"], ["11681.20000", "0.02573600", "1596669353.732810"], ["11681.30000", "2.29920000", "1596668873.708889"], ["11681.80000", "1.82744225", "1596669400.975523"], ["11681.90000", "1.42013486", "1596669315.539368"], ["11682.00000", "6.62278256", "1596669315.600744"], ["11682.10000", "1.10609127", "1596669414.196052"], ["11682.20000", "0.90974147", "1596669390.409469"], ["11683.40000", "1.77330000", "1596669414.928373"], ["11683.60000", "6.18163688", "1596669439.860935"], ["11683.70000", "7.00950253", "1596669439.868146"], ["11684.40000", "3.52876164", "1596669315.675981"], ["11684.50000", "0.49655652", "1596669315.453291"], ["11685.00000", "0.66377627", "1596669231.628223"], ["11685.10000", "1.60000000", "1596669147.198829"], ["11685.60000", "0.34861506", "1596669315.634249"], ["11685.70000", "0.90946900", "1596669315.875683"], ["11687.10000", "7.07094270", "1596669335.057643"], ["11687.20000", "1.20727714", "1596669351.169760"], ["11687.30000", "8.20000000", "1596668790.261966"], ["11687.50000", "2.32565760", "1596668912.406381"], ["11687.60000", "2.00463652", "1596669330.228105"], ["11688.40000", "0.61206863", "1596669419.917741"], ["11688.50000", "4.99680206", "1596669122.976493"], ["11690.00000", "0.04000000", "1596669413.776139"], ["11690.10000", "3.52674781", "1596668960.300902"], ["11690.20000", "0.99262881", "1596669329.696167"], ["11690.30000", "0.57249448", "1596669329.688956"], ["11690.40000", "0.30000000", "1596668790.244684"], ["11690.90000", "0.90891095", "1596669120.246371"], ["11691.90000", "2.00000000", "1596669391.210310"], ["11692.20000", "0.64579267", "1596669385.223321"], ["11692.30000", "8.50000000", "1596667892.430053"], ["11692.90000", "2.00384320", "1596669348.244920"], ["11695.00000", "1.00030000", "1596668951.454381"], ["11695.30000", "0.89558128", "1596669315.167664"], ["11697.50000", "2.41349169", "1596669326.286222"], ["11697.90000", "10.20623317", "1596669321.087873"], ["11698.00000", "6.50000000", "1596669345.547690"], ["11698.50000", "6.40610852", "1596668960.064912"], ["11698.60000", "1.95822352", "1596669405.941607"], ["11698.70000", "3.55265622", "1596669401.323083"], ["11699.10000", "0.05287970", "1596669101.534443"], ["11699.20000", "1.48775147", "1596669323.402689"], ["11699.90000", "0.10000000", "1596669201.791829"], ["11700.00000", "0.52000000", "1596669385.906932"], ["11700.20000", "1.00980000", "1596669321.477088"], ["11700.40000", "7.44635184", "1596669406.413027"], ["11701.10000", "0.01796445", "1596669343.389094"], ["11701.20000", "2.24659931", "1596669440.371060"], ["11701.50000", "1.11290000", "1596669432.691736"], ["11703.00000", "7.60000000", "1596669153.978484"], ["11704.60000", "18.00000000", "1596667881.119389"], ["11706.00000", "1.51600000", "1596668809.372526"], ["11708.50000", "8.50097969", "1596668951.654293"], ["11709.30000", "1.16783315", "1596668959.472877"], ["11709.70000", "0.00507863", "1596668161.410923"]], "bs": [["11666.60000", "2.64277370", "1596669443.446692"], ["11666.50000", "2.64277370", "1596669443.213771"], ["11665.90000", "0.06632622", "1596669443.076886"], ["11665.80000", "0.64278812", "1596669410.857516"], ["11665.50000", "0.25781512", "1596669443.488306"], ["11665.40000", "0.64000000", "1596669423.357701"], ["11665.20000", "0.01054570", "1596669442.906500"], ["11665.00000", "0.00200000", "1596669385.246215"], ["11664.10000", "0.16214000", "1596669442.368101"], ["11663.90000", "0.16214000", "1596669438.332138"], ["11663.80000", "0.16215000", "1596669432.475387"], ["11663.70000", "0.09621094", "1596669438.337670"], ["11663.60000", "1.70700000", "1596669437.589808"], ["11663.20000", "0.99580000", "1596669425.050753"], ["11663.00000", "4.28400000", "1596669443.510683"], ["11662.90000", "0.74068237", "1596669442.999899"], ["11662.80000", "2.85714260", "1596669443.178425"], ["11661.90000", "0.08250000", "1596669406.413128"], ["11661.80000", "0.30000000", "1596669420.265362"], ["11660.90000", "0.89957486", "1596669390.798676"], ["11660.80000", "1.05779388", "1596669421.415799"], ["11660.40000", "7.80000000", "1596669390.718738"], ["11660.00000", "1.78279722", "1596669360.336724"], ["11659.50000", "0.95422246", "1596669317.575246"], ["11659.20000", "2.61913819", "1596669435.131443"], ["11658.40000", "0.04470949", "1596669442.168354"], ["11658.20000", "0.85721125", "1596669238.179693"], ["11657.50000", "0.69682404", "1596669381.650940"], ["11657.40000", "1.19096844", "1596669421.419263"], ["11657.20000", "0.13413049", "1596669442.518818"], ["11657.00000", "0.20345960", "1596669397.487116"], ["11656.00000", "0.04218578", "1596669441.385900"], ["11655.90000", "5.30000000", "1596669359.503445"], ["11655.10000", "1.92337807", "1596669421.417194"], ["11654.60000", "1.67936758", "1596669396.720313"], ["11654.50000", "0.24969076", "1596669386.759646"], ["11654.40000", "0.62000000", "1596669442.561954"], ["11654.30000", "0.91183258", "1596669403.592677"], ["11653.40000", "2.78176173", "1596669326.045372"], ["11652.40000", "0.49790258", "1596669354.545499"], ["11652.30000", "0.61220500", "1596669272.791851"], ["11652.10000", "3.53857143", "1596669377.769340"], ["11651.80000", "0.43800000", "1596669422.791916"], ["11651.60000", "0.30000000", "1596669379.421791"], ["11651.50000", "0.98200000", "1596669423.021032"], ["11651.30000", "0.34963237", "1596669390.481088"], ["11651.20000", "6.50000000", "1596668989.549084"], ["11651.00000", "0.91209912", "1596669218.016781"], ["11649.50000", "2.01110201", "1596669438.723632"], ["11649.40000", "0.38000000", "1596669313.465018"], ["11649.10000", "1.79710785", "1596669401.981451"], ["11649.00000", "7.09463152", "1596669227.005116"], ["11648.20000", "1.21120014", "1596669112.486165"], ["11647.80000", "3.21709123", "1596669115.912871"], ["11647.00000", "7.70000000", "1596668960.228136"], ["11646.40000", "0.57463770", "1596669213.773899"], ["11646.10000", "3.66629167", "1596669413.454073"], ["11645.40000", "2.44185891", "1596668961.356005"], ["11645.10000", "4.45375572", "1596668986.175638"], ["11643.80000", "3.59891527", "1596669059.142263"], ["11643.10000", "0.03200000", "1596669430.708115"], ["11643.00000", "2.99429325", "1596669318.677778"], ["11641.70000", "0.05288275", "1596669388.982281"], ["11641.60000", "0.30000000", "1596669240.334009"], ["11641.40000", "8.10000000", "1596668956.340593"], ["11640.20000", "0.89996248", "1596669421.395094"], ["11639.40000", "0.91300813", "1596669218.014960"], ["11639.00000", "1.11290000", "1596669108.571534"], ["11637.70000", "1.49555357", "1596669421.379209"], ["11637.60000", "6.13856613", "1596669433.129562"], ["11637.50000", "1.96860663", "1596669401.981533"], ["11637.20000", "3.54305085", "1596669401.701365"], ["11637.00000", "2.01078500", "1596669396.591614"], ["11636.80000", "6.40000000", "1596668858.745613"], ["11635.90000", "6.44197811", "1596668984.005434"], ["11635.50000", "0.49800000", "1596669441.251358"], ["11635.10000", "17.66702998", "1596669251.957495"], ["11634.90000", "2.21906405", "1596669318.499104"], ["11632.90000", "7.10374788", "1596668890.845388"], ["11632.00000", "6.20000000", "1596669421.111869"], ["11631.70000", "0.35846461", "1596669396.334868"], ["11631.60000", "2.01418770", "1596669401.074108"], ["11631.50000", "0.10576434", "1596669003.427419"], ["11631.00000", "0.17085000", "1596669431.823972"], ["11630.90000", "0.02881113", "1596669405.362451"], ["11628.00000", "0.17085000", "1596669133.227575"], ["11627.30000", "6.30000000", "1596668622.833411"], ["11626.90000", "1.03170000", "1596669062.400585"], ["11625.80000", "2.32351853", "1596669401.453160"], ["11625.50000", "1.99621865", "1596669315.490214"], ["11625.20000", "1.92487177", "1596669439.861219"], ["11625.00000", "0.75832374", "1596669139.015141"], ["11624.90000", "3.54659601", "1596669191.571708"], ["11624.10000", "0.75800000", "1596669032.148731"], ["11623.70000", "0.91418709", "1596669159.699747"], ["11623.60000", "20.30000000", "1596669019.375341"], ["11622.80000", "6.90000000", "1596669366.456311"], ["11622.00000", "0.17085000", "1596668865.749616"], ["11621.70000", "0.02000000", "1596668983.570912"], ["11620.20000", "2.82164042", "1596668859.526087"]]}, "book-100", "XBT/USD"]
[270, {"b": [["11639.50000", "0.00433782", "1596669444.415494"]], "c": "2031397726"}, "book-100", "XBT/USD"]
[270, {"a": [["11687.00000", "0.00438186", "1596669444.445098"]], "c": "2031397726"}, "book-100", "XBT/USD"]
[270, {"b": [["11639.50000", "0.00000000", "1596669444.751868"], ["11620.20000", "2.82164042", "1596668859.526087", "r"]], "c": "2031397726"}, "book-100", "XBT/USD"]
[270, {"a": [["11687.00000", "0.00000000", "1596669444.752357"], ["11709.70000", "0.00507863", "1596668161.410923", "r"]], "c": "2031397726"}, "book-100", "XBT/USD"]
[270, {"b": [["11666.60000", "0.64277370", "1596669445.062110"]], "c": "3515327593"}, "book-100", "XBT/USD"]
[270, {"a": [["11667.00000", "0.02765196", "1596669445.102503"]], "c": "2501427533"}, "book-100", "XBT/USD"]
[270, {"a": [["11667.60000", "0.00000000", "1596669445.105133"], ["11709.70000", "0.00507863", "1596668161.410923", "r"]], "c": "688226573"}, "book-100", "XBT/USD"]
[270, {"a": [["11667.20000", "0.00000000", "1596669445.247552"], ["11710.30000", "20.00000000", "1596669307.242378", "r"]], "c": "1570838757"}, "book-100", "XBT/USD"]
[270, {"b": [["11666.50000", "0.64277370", "1596669445.465523"]], "c": "1541797316"}, "book-100", "XBT/USD"]
[270, {"a": [["11668.70000", "0.00000000", "1596669445.550810"], ["11710.40000", "23.57900000", "1596669119.464484", "r"]], "c": "991641691"}, "book-100", "XBT/USD"]
[270, {"b": [["11664.00000", "0.10000000", "1596669445.613038"]], "c": "1163512485"}, "book-100", "XBT/USD"]
[270, {"a": [["11668.70000", "0.25781678", "1596669445.647248"]], "c": "3426424510"}, "book-100", "XBT/USD"]
[270, {"a": [["11667.10000", "0.00000000", "1596669445.701185"], ["11710.40000", "23.57900000", "1596669119.464484", "r"]], "c": "441467445"}, "book-100", "XBT/USD"]
[270, {"a": [["11666.90000", "0.12793330", "1596669445.712312"]], "c": "900200749"}, "book-100", "XBT/USD"]
[270, {"a": [["11667.00000", "0.00000000", "1596669445.847773"], ["11710.40000", "23.57900000", "1596669119.464484", "r"]], "c": "2020703480"}, "book-100", "XBT/USD"]
[270, {"a": [["11666.80000", "0.02765244", "1596669445.852762"]], "c": "1826231410"}, "book-100", "XBT/USD"]
[270, {"a": [["11666.90000", "0.00000000", "1596669446.135435"], ["11710.40000", "23.57900000", "1596669119.464484", "r"]], "c": "880057922"}, "book-100", "XBT/USD"]
[270, {"a": [["11683.70000", "6.26097510", "1596669446.138352"]], "c": "880057922"}, "book-100", "XBT/USD"]
[270, {"b": [["11646.10000", "0.99629167", "1596669446.151883"]], "c": "880057922"}, "book-100", "XBT/USD"]
[270, {"b": [["11625.20000", "1.17634434", "1596669446.163801"]], "c": "880057922"}, "book-100", "XBT/USD"]
[270, {"b": [["11664.00000", "0.00000000", "1596669446.170945"], ["11620.20000", "2.82164042", "1596668859.526087", "r"]], "c": "1245058236"}, "book-100", "XBT/USD"]
[270, {"b": [["11625.30000", "0.74850465", "1596669446.179984"]], "c": "1245058236"}, "book-100", "XBT/USD"]
[270, {"a": [["11684.00000", "0.74850465", "1596669446.188679"]], "c": "1245058236"}, "book-100", "XBT/USD"]
[270, {"a": [["11666.70000", "0.12793129", "1596669446.211851"]], "c": "3455260078"}, "book-100", "XBT/USD"]
[270, {"a": [["11666.80000", "0.00000000", "1596669446.268167"], ["11710.30000", "20.00000000", "1596669307.242378", "r"]], "c": "4244556890"}, "book-100", "XBT/USD"]
[270, {"a": [["11667.60000", "0.05313798", "1596669446.268544"]], "c": "3307247013"}, "book-100", "XBT/USD"]
[270, {"b": [["11664.00000", "0.10000000", "1596669446.324638"]], "c": "3143769947"}, "book-100", "XBT/USD"]
[270, {"a": [["11667.50000", "0.12792315", "1596669446.643264"]], "c": "3154688665"}, "book-100", "XBT/USD"]
[270, {"a": [["11666.70000", "0.00000000", "1596669446.645321"], ["11709.70000", "0.00507863", "1596668161.410923", "r"]], "c": "1936145470"}, "book-100", "XBT/USD"]
[270, {"a": [["11667.30000", "0.50000000", "1596669446.716135"]], "c": "3843802324"}, "book-100", "XBT/USD"]
[270, {"a": [["11667.40000", "0.05313798", "1596669446.783681"]], "c": "78969066"}, "book-100", "XBT/USD"]
[270, {"a": [["11667.60000", "0.00000000", "1596669446.783803"], ["11709.30000", "1.16783315", "1596668959.472877", "r"]], "c": "1736768863"}, "book-100", "XBT/USD"]
[270, {"b": [["11664.00000", "0.00000000", "1596669446.921309"], ["11621.70000", "0.02000000", "1596668983.570912", "r"]], "c": "432437153"}, "book-100", "XBT/USD"]
[270, {"a": [["11667.20000", "0.02765149", "1596669447.038572"]], "c": "1698886441"}, "book-100", "XBT/USD"]
[270, {"a": [["11667.40000", "0.00000000", "1596669447.040963"], ["11709.30000", "1.16783315", "1596668959.472877", "r"]], "c": "232377187"}, "book-100", "XBT/USD"]
[270, {"a": [["11667.20000", "0.15557769", "1596669447.048412"]], "c": "2293782378"}, "book-100", "XBT/USD"]
[270, {"a": [["11667.50000", "0.00000000", "1596669447.048559"], ["11709.70000", "0.00507863", "1596668161.410923", "r"]], "c": "2463081461"}, "book-100", "XBT/USD"]
[270, {"a": [["11677.20000", "0.00000000", "1596669447.142059"], ["11710.30000", "20.00000000", "1596669307.242378", "r"]], "c": "2463081461"}, "book-100", "XBT/USD"]
[270, {"b": [["11664.00000", "0.10000000", "1596669447.148024"]], "c": "3968674059"}, "book-100", "XBT/USD"]
[270, {"a": [["11685.70000", "1.34846900", "1596669447.166632"]], "c": "3968674059"}, "book-100", "XBT/USD"]
[270, {"a": [["11667.20000", "0.12792620", "1596669447.290244"]], "c": "1511575442"}, "book-100", "XBT/USD"]
[270, {"a": [["11667.10000", "0.02765173", "1596669447.293160"]], "c": "2869628416"}, "book-100", "XBT/USD"]
[270, {"a": [["11667.20000", "0.00000000", "1596669447.462966"], ["11710.30000", "20.00000000", "1596669307.242378", "r"]], "c": "4272353631"}, "book-100", "XBT/USD"]
[270, {"a": [["11667.10000", "0.00000000", "1596669447.594212"], ["11710.40000", "23.57900000", "1596669119.464484", "r"]], "c": "2324195575"}, "book-100", "XBT/USD"]
[270, {"a": [["11667.10000", "0.12792395", "1596669447.594725"]], "c": "4183454431"}, "book-100", "XBT/USD"]
[270, {"a": [["11667.20000", "0.02765149", "1596669447.595436"]], "c": "1410418976"}, "book-100", "XBT/USD"]
[270, {"a": [["11668.70000", "0.00000000", "1596669447.823393"], ["11710.30000", "20.00000000", "1596669307.242378", "r"]], "c": "3098547450"}, "book-100", "XBT/USD"]
[270, {"a": [["11667.00000", "0.02765196", "1596669447.844344"]], "c": "3068361475"}, "book-100", "XBT/USD"]
[270, {"a": [["11667.20000", "0.00000000", "1596669447.845988"], ["11710.30000", "20.00000000", "1596669307.242378", "r"]], "c": "4179381802"}, "book-100", "XBT/USD"]
[270, {"b": [["11664.00000", "0.00000000", "1596669447.854200"], ["11621.70000", "0.02000000", "1596668983.570912", "r"]], "c": "2271134932"}, "book-100", "XBT/USD"]
[270, {"a": [["11668.70000", "0.25781713", "1596669447.923238"]], "c": "2874792146"}, "book-100", "XBT/USD"]
[270, {"b": [["11664.00000", "0.10000000", "1596669448.070938"]], "c": "3575337516"}, "book-100", "XBT/USD"]
[270, {"a": [["11667.10000", "0.00000000", "1596669448.302497"], ["11710.30000", "20.00000000", "1596669307.242378", "r"]], "c": "1006335485"}, "book-100", "XBT/USD"]
[270, {"a": [["11666.90000", "0.12793416", "1596669448.303599"]], "c": "47603814"}, "book-100", "XBT/USD"]
[270, {"a": [["11667.20000", "0.02765149", "1596669448.430843"]], "c": "2618241858"}, "book-100", "XBT/USD"]
[270, {"a": [["11667.00000", "0.00000000", "1596669448.442604"], ["11709.70000", "0.00507863", "1596668161.410923", "r"]], "c": "967867127"}, "book-100", "XBT/USD"]
[270, {"b": [["11651.50000", "0.00000000", "1596669448.569724"], ["11621.70000", "0.02000000", "1596668983.570912", "r"]], "c": "967867127"}, "book-100", "XBT/USD"]
[270, {"b": [["11651.80000", "0.00000000", "1596669448.577944"], ["11620.20000", "2.82164042", "1596668859.526087", "r"]], "c": "967867127"}, "book-100", "XBT/USD"]
[270, {"b": [["11658.50000", "0.43800000", "1596669448.599150"]], "c": "967867127"}, "book-100", "XBT/USD"]
[270, {"a": [["11667.20000", "0.00000000", "1596669448.682432"], ["11710.30000", "20.00000000", "1596669307.242378", "r"]], "c": "240567754"}, "book-100", "XBT/USD"]
[270, {"a": [["11666.80000", "0.02765244", "1596669448.684190"]], "c": "623025460"}, "book-100", "XBT/USD"]
[270, {"b": [["11664.00000", "0.00000000", "1596669448.714763"], ["11620.20000", "2.82164042", "1596668859.526087", "r"]], "c": "1533024202"}, "book-100", "XBT/USD"]
[270, {"a": [["11667.10000", "0.12792735", "1596669448.726486"]], "c": "3692261204"}, "book-100", "XBT/USD"]
[270, {"a": [["11666.90000", "0.00000000", "1596669448.730292"], ["11709.70000", "0.00507863", "1596668161.410923", "r"]], "c": "473653061"}, "book-100", "XBT/USD"]
[270, {"b": [["11658.50000", "1.41000000", "1596669448.745967"]], "c": "473653061"}, "book-100", "XBT/USD"]
[270, {"b": [["11664.00000", "0.10000000", "1596669448.883964"]], "c": "1652151739"}, "book-100", "XBT/USD"]
[270, {"a": [["11666.80000", "0.00000000", "1596669448.931970"], ["11710.30000", "20.00000000", "1596669307.242378", "r"]], "c": "778844919"}, "book-100", "XBT/USD"]
[270, {"a": [["11667.00000", "0.02765196", "1596669448.943914"]], "c": "1281165772"}, "book-100", "XBT/USD"]
[270, {"b": [["11666.20000", "0.79270000", "1596669449.135093"]], "c": "2383927181"}, "book-100", "XBT/USD"]
[270, {"a": [["11667.10000", "0.00000000", "1596669449.156062"], ["11710.30000", "20.00000000", "1596669307.242378", "r"]], "c": "4189170620"}, "book-100", "XBT/USD"]
[270, {"a": [["11666.70000", "0.12792042", "1596669449.173431"]], "c": "3800634308"}, "book-100", "XBT/USD"]
[270, {"a": [["11667.20000", "0.02765149", "1596669449.284241"]], "c": "1241429941"}, "book-100", "XBT/USD"]
[270, {"a": [["11667.00000", "0.00000000", "1596669449.294679"], ["11709.70000", "0.00507863", "1596668161.410923", "r"]], "c": "3656321365"}, "book-100", "XBT/USD"]
[270, {"b": [["11646.10000", "3.65629167", "1596669449.357403"]], "c": "3656321365"}, "book-100", "XBT/USD"]
[270, {"b": [["11635.50000", "0.00000000", "1596669449.449253"], ["11621.70000", "0.02000000", "1596668983.570912", "r"]], "c": "3656321365"}, "book-100", "XBT/USD"]
[270, {"b": [["11664.00000", "0.00000000", "1596669449.499353"], ["11620.20000", "2.82164042", "1596668859.526087", "r"]], "c": "3656321365"}, "book-100", "XBT/USD"]
[270, {"a": [["11667.10000", "0.12793401", "1596669449.620529"]], "c": "3756751374"}, "book-100", "XBT/USD"]
[270, {"a": [["11666.70000", "0.00000000", "1596669449.621763"], ["11709.70000", "0.00507863", "1596668161.410923", "r"]], "c": "738655678"}, "book-100", "XBT/USD"]
[270, {"b": [["11664.00000", "0.10000000", "1596669449.675552"]], "c": "738655678"}, "book-100", "XBT/USD"]
[270, {"a": [["11686.10000", "0.00300000", "1596669449.695953"]], "c": "738655678"}, "book-100", "XBT/USD"]
[270, {"a": [["11667.20000", "0.00000000", "1596669449.747228"], ["11709.70000", "0.00507863", "1596668161.410923", "r"]], "c": "3255857120"}, "book-100", "XBT/USD"]
[270, {"a": [["11667.10000", "2.12793401", "1596669449.912015"]], "c": "4124241827"}, "book-100", "XBT/USD"]
[270, {"a": [["11667.30000", "0.00000000", "1596669449.933718"], ["11710.30000", "20.00000000", "1596669307.242378", "r"]], "c": "3445998345"}, "book-100", "XBT/USD"]
[270, {"a": [["11666.70000", "0.02765267", "1596669449.940754"]], "c": "3073674271"}, "book-100", "XBT/USD"]
[270, {"b": [["11657.50000", "1.12698390", "1596669449.941085"]], "c": "3073674271"}, "book-100", "XBT/USD"]
[270, {"a": [["11667.70000", "0.00000000", "1596669449.958837"], ["11710.30000", "20.00000000", "1596669307.242378", "r"]], "c": "1891195725"}, "book-100", "XBT/USD"]
[270, {"a": [["11668.50000", "0.15000000", "1596669449.971819"]], "c": "109349559"}, "book-100", "XBT/USD"]
[270, {"a": [["11668.70000", "0.00000000", "1596669450.001701"], ["11710.30000", "20.00000000", "1596669307.242378", "r"]], "c": "4019535683"}, "book-100", "XBT/USD"]
[270, {"a": [["11667.00000", "0.73635082", "1596669450.005109"]], "c": "2769991826"}, "book-100", "XBT/USD"]
[270, {"a": [["11668.60000", "0.16000000", "1596669450.007546"]], "c": "3019117547"}, "book-100", "XBT/USD"]
[270, {"a": [["11667.10000", "2.00000000", "1596669450.029116"]], "c": "1553477904"}, "book-100", "XBT/USD"]
[270, {"a": [["11667.10000", "0.00000000", "1596669450.051954"], ["11710.30000", "20.00000000", "1596669307.242378", "r"]], "c": "2144690970"}, "book-100", "XBT/USD"]
[270, {"a": [["11666.70000", "0.00000000", "1596669450.067914"], ["11710.40000", "23.57900000", "1596669119.464484", "r"]], "c": "950006372"}, "book-100", "XBT/USD"]
[270, {"a": [["11667.00000", "0.76400278", "1596669450.071200"]], "c": "2053448595"}, "book-100", "XBT/USD"]
[270, {"b": [["11657.20000", "0.00000000", "1596669450.099036"], ["11620.20000", "2.82164042", "1596668859.526087", "r"]], "c": "2053448595"}, "book-100", "XBT/USD"]
[270, {"a": [["11668.80000", "0.40781582", "1596669450.099876"]], "c": "2058979411"}, "book-100", "XBT/USD"]
[270, {"a": [["11667.00000", "0.02765196", "1596669450.112014"]], "c": "620723209"}, "book-100", "XBT/USD"]
[270, {"a": [["11667.20000", "0.12793661", "1596669450.116093"]], "c": "2232147399"}, "book-100", "XBT/USD"]
[270, {"a": [["11667.70000", "0.73635082", "1596669450.156425"]], "c": "3345816371"}, "book-100", "XBT/USD"]
