[270, {"as": [["11635.20000", "0.50392966", "1596668217.192704"], ["11641.00000", "0.14100000", "1596668189.175938"], ["11642.20000", "0.85850885", "1596668197.762981"], ["11643.70000", "0.10200000", "1596668205.441802"], ["11643.80000", "0.33038373", "1596668192.207481"], ["11644.40000", "0.25835587", "1596668219.568575"], ["11644.50000", "1.57099162", "1596668196.724602"], ["11644.70000", "0.64409028", "1596668218.202724"], ["11645.10000", "4.28500000", "1596668197.543580"], ["11645.50000", "0.64420113", "1596668196.933834"], ["11645.60000", "0.09621094", "1596668216.013295"], ["11646.40000", "0.04250000", "1596668215.811690"], ["11646.50000", "0.01000000", "1596668199.560726"], ["11646.60000", "0.64415340", "1596668199.454100"], ["11646.80000", "0.96000000", "1596668206.817677"], ["11647.00000", "0.09900000", "1596668197.111647"], ["11647.20000", "1.70700000", "1596668219.355570"], ["11647.40000", "6.37500423", "1596668186.648304"], ["11647.60000", "2.82207868", "1596668206.028524"], ["11648.30000", "0.87420747", "1596668202.814711"], ["11648.80000", "2.35945517", "1596668215.361163"], ["11649.10000", "2.07473036", "1596668202.875429"], ["11650.00000", "0.45504561", "1596668196.836382"], ["11650.40000", "0.04479304", "1596668210.793797"], ["11650.70000", "1.56486140", "1596668189.240848"], ["11650.80000", "2.69588352", "1596668208.125365"], ["11651.00000", "0.70025487", "1596668198.705180"], ["11651.30000", "0.67463024", "1596668186.165841"], ["11651.40000", "0.13437912", "1596668211.335843"], ["11651.50000", "1.10611314", "1596668214.533058"], ["11651.60000", "0.50000000", "1596668199.032673"], ["11652.30000", "0.76645242", "1596668113.216048"], ["11652.40000", "0.11078149", "1596668208.366523"], ["11652.50000", "0.08250000", "1596668215.811833"], ["11652.60000", "0.33906357", "1596668206.927000"], ["11654.20000", "0.05313798", "1596668214.409414"], ["11654.30000", "2.48944730", "1596668214.639037"], ["11654.40000", "0.90289000", "1596668209.468720"], ["11655.30000", "0.10348372", "1596668203.606928"], ["11656.00000", "0.71182580", "1596668206.925287"], ["11656.10000", "0.85916770", "1596668189.238614"], ["11656.60000", "0.72424510", "1596668198.022063"], ["11656.70000", "7.20659670", "1596668198.003513"], ["11657.10000", "7.90000000", "1596668111.153469"], ["11657.30000", "0.85907618", "1596668189.269575"], ["11657.40000", "1.42336797", "1596668199.430321"], ["11657.50000", "0.38000000", "1596668201.462866"], ["11658.20000", "1.02560000", "1596668212.638737"], ["11659.10000", "0.20000000", "1596668079.775421"], ["11659.50000", "3.53689960", "1596668199.400301"], ["11659.60000", "3.20460178", "1596668156.333017"], ["11659.70000", "7.58667870", "1596668199.679479"], ["11660.00000", "3.85882812", "1596668202.201535"], ["11660.40000", "0.30000000", "1596668038.851611"], ["11661.30000", "0.00438186", "1596668212.607308"], ["11661.40000", "1.79546954", "1596668197.546726"], ["11661.50000", "3.21937185", "1596668215.134785"], ["11661.80000", "1.10267113", "1596668218.518467"], ["11662.00000", "0.91117567", "1596668200.806405"], ["11662.10000", "2.29920000", "1596668201.396099"], ["11662.20000", "5.70000000", "1596668067.708048"], ["11663.70000", "0.60918283", "1596668212.003393"], ["11663.80000", "4.53039431", "1596668151.815563"], ["11663.90000", "1.48503180", "1596668150.753515"], ["11666.30000", "6.80000000", "1596667942.286965"], ["11667.00000", "0.02833548", "1596668193.539095"], ["11667.10000", "0.05300565", "1596668166.869626"], ["11667.30000", "2.00829310", "1596668074.735098"], ["11668.10000", "0.98000000", "1596668211.868231"], ["11669.30000", "0.10000000", "1596667725.682463"], ["11670.00000", "43.90525970", "1596668081.156110"], ["11670.40000", "0.96940000", "1596668198.632365"], ["11670.60000", "0.30000000", "1596668183.931852"], ["11670.80000", "1.80844262", "1596668100.724141"], ["11671.70000", "0.77381376", "1596668201.223934"], ["11671.80000", "5.20000000", "1596668116.651465"], ["11673.10000", "6.53305518", "1596668074.955254"], ["11674.40000", "1.96304237", "1596668077.818638"], ["11675.00000", "0.01821000", "1596667942.934773"], ["11675.20000", "20.10000000", "1596668124.441396"], ["11675.60000", "13.48242016", "1596668079.276816"], ["11676.00000", "5.10000000", "1596667950.984665"], ["11676.20000", "0.75800000", "1596668185.505686"], ["11678.20000", "0.75800000", "1596668063.060561"], ["11678.90000", "2.00629837", "1596668074.674665"], ["11679.20000", "2.25177042", "1596668216.445897"], ["11680.60000", "0.30000000", "1596668193.129381"], ["11681.20000", "0.02573600", "1596667743.443916"], ["11681.90000", "8.00000000", "1596667893.353561"], ["11682.10000", "5.64889471", "1596668128.388976"], ["11682.70000", "0.48430000", "1596668063.968111"], ["11684.70000", "5.84205810", "1596668075.446389"], ["11684.80000", "4.06670802", "1596668074.975205"], ["11685.00000", "1.11290000", "1596668072.496942"], ["11686.00000", "2.80639281", "1596668077.802339"], ["11686.50000", "1.51500000", "1596668107.208493"], ["11686.90000", "20.00000000", "1596668197.229568"], ["11687.00000", "22.20000000", "1596667944.916814"], ["11687.30000", "8.20000000", "1596667061.296774"], ["11689.90000", "0.10000000", "1596667326.899060"]], "bs": [["11635.10000", "20.97949220", "1596668218.451408"], ["11635.00000", "4.28900000", "1596668189.560824"], ["11634.90000", "0.65939211", "1596668202.755536"], ["11634.80000", "0.64444605", "1596668189.210339"], ["11634.70000", "0.07473037", "1596668202.814222"], ["11634.50000", "0.09621094", "1596668203.599681"], ["11634.30000", "2.00000000", "1596668211.368065"], ["11634.20000", "0.85907618", "1596668215.213076"], ["11633.90000", "0.38832497", "1596668202.720009"], ["11633.50000", "0.85926140", "1596668206.934603"], ["11633.40000", "0.85916770", "1596668189.222021"], ["11632.70000", "0.69901598", "1596668197.960923"], ["11632.60000", "7.50000000", "1596668197.673892"], ["11632.40000", "0.17935059", "1596668217.420784"], ["11632.20000", "0.76153000", "1596668198.215725"], ["11631.10000", "0.59461799", "1596668185.621716"], ["11630.70000", "0.04479035", "1596668217.775197"], ["11630.60000", "0.10369488", "1596668201.567418"], ["11630.50000", "0.71338649", "1596668202.717082"], ["11630.40000", "1.78610000", "1596668206.735982"], ["11630.30000", "1.49000000", "1596668174.537802"], ["11630.20000", "3.79220025", "1596668200.410235"], ["11629.30000", "0.35329683", "1596668204.245083"], ["11629.10000", "0.13436946", "1596668218.385066"], ["11628.70000", "0.44000000", "1596668200.507492"], ["11628.50000", "0.87655000", "1596668217.575259"], ["11628.30000", "0.72600771", "1596668201.566870"], ["11628.20000", "1.42705519", "1596668202.726640"], ["11628.10000", "7.25917285", "1596668186.057621"], ["11628.00000", "0.99200000", "1596668198.124126"], ["11627.40000", "0.91388531", "1596668198.985765"], ["11627.00000", "3.54736848", "1596668203.603582"], ["11626.90000", "0.04229135", "1596668218.181658"], ["11626.80000", "0.70540000", "1596668182.211196"], ["11626.70000", "0.85951499", "1596668201.309470"], ["11626.50000", "0.38000000", "1596668200.451073"], ["11626.10000", "0.49906981", "1596668201.392431"], ["11625.00000", "0.25000000", "1596668173.536875"], ["11624.90000", "0.35054819", "1596668201.558911"], ["11624.50000", "0.75500000", "1596668211.780516"], ["11624.40000", "0.09900000", "1596668188.174631"], ["11624.00000", "0.00436192", "1596668212.605654"], ["11623.90000", "0.91416048", "1596668211.734927"], ["11623.80000", "8.10000000", "1596668077.087850"], ["11623.50000", "2.01557943", "1596668203.388933"], ["11623.40000", "1.21408239", "1596668203.608285"], ["11623.10000", "0.50000000", "1596668131.288474"], ["11622.00000", "0.30000000", "1596668178.071280"], ["11621.60000", "3.21522088", "1596668198.213707"], ["11621.30000", "7.11282506", "1596668188.322737"], ["11620.90000", "1.80183215", "1596668190.890974"], ["11620.50000", "1.02380000", "1596668197.034621"], ["11620.10000", "0.03100000", "1596668195.716685"], ["11619.30000", "1.49062269", "1596668188.864712"], ["11619.00000", "7.99870960", "1596668188.433513"], ["11618.80000", "3.54928916", "1596668191.919474"], ["11617.60000", "2.63650047", "1596668181.342168"], ["11615.70000", "2.48790161", "1596668066.503933"], ["11615.60000", "0.20000000", "1596668185.818629"], ["11614.00000", "4.01753320", "1596668200.538985"], ["11613.20000", "0.05300392", "1596668197.338611"], ["11612.90000", "1.49900354", "1596668087.446687"], ["11612.30000", "7.91506656", "1596668188.864634"], ["11612.20000", "0.90235598", "1596668189.274687"], ["11612.00000", "0.30000000", "1596668063.274667"], ["11611.40000", "0.49800000", "1596668212.981594"], ["11610.90000", "1.51651389", "1596668201.748164"], ["11610.80000", "1.97364855", "1596668202.716643"], ["11610.30000", "2.01811373", "1596668097.531455"], ["11610.00000", "13.72733454", "1596668196.993423"], ["11608.40000", "3.55241504", "1596668186.355165"], ["11608.20000", "6.51090657", "1596668199.612532"], ["11608.10000", "1.11290000", "1596668062.849580"], ["11607.70000", "8.40000000", "1596666861.504830"], ["11607.00000", "0.17085000", "1596668197.422772"], ["11606.80000", "0.02000000", "1596668049.083198"], ["11605.70000", "21.90000000", "1596668199.083244"], ["11605.60000", "1.04116415", "1596668152.572937"], ["11605.30000", "0.70560000", "1596668150.494951"], ["11604.50000", "0.10597364", "1596668201.304076"], ["11604.00000", "0.17085000", "1596668202.423455"], ["11603.70000", "2.00036063", "1596668188.223750"], ["11603.20000", "2.01629766", "1596668066.158510"], ["11602.10000", "7.70000000", "1596667719.295606"], ["11601.20000", "3.53713972", "1596668197.653382"], ["11601.00000", "2.99733812", "1596668146.920494"], ["11600.50000", "1.02780000", "1596668198.633387"], ["11600.30000", "2.01993025", "1596668063.650275"], ["11600.10000", "0.05000000", "1596667808.971124"], ["11600.00000", "0.46774162", "1596667672.299279"], ["11598.00000", "0.17085000", "1596668211.499962"], ["11597.70000", "0.75926089", "1596668218.515713"], ["11597.30000", "18.40000000", "1596668078.198778"], ["11597.20000", "3.55598197", "1596668068.386899"], ["11596.90000", "0.91616873", "1596668204.938795"], ["11596.10000", "5.80000000", "1596667570.336610"], ["11595.60000", "0.75800000", "1596668167.204107"], ["11595.00000", "0.17085000", "1596668180.611187"], ["11594.50000", "2.29920000", "1596668093.755650"], ["11593.90000", "13.95157954", "1596668200.603838"]]}, "book-100", "XBT/USD"]
[270, {"a": [["11661.30000", "0.00000000", "1596668219.972547"], ["11690.00000", "0.04000000", "1596667586.146170", "r"]], "c": "1746640276"}, "book-100", "XBT/USD"]
[270, {"a": [["11646.60000", "0.00000000", "1596668220.281601"], ["11690.60000", "2.00429046", "1596668074.026932", "r"]], "c": "1746640276"}, "book-100", "XBT/USD"]
[270, {"a": [["11646.50000", "0.00000000", "1596668220.337287"], ["11691.40000", "23.57900000", "1596668160.826165", "r"]], "c": "1746640276"}, "book-100", "XBT/USD"]
[270, {"a": [["11644.00000", "0.64411535", "1596668220.346485"]], "c": "1582609663"}, "book-100", "XBT/USD"]
[270, {"a": [["11644.30000", "0.67620000", "1596668220.351396"]], "c": "864240594"}, "book-100", "XBT/USD"]
[270, {"a": [["11646.60000", "0.01000000", "1596668220.391109"]], "c": "864240594"}, "book-100", "XBT/USD"]
[270, {"a": [["11660.30000", "0.00438186", "1596668220.588488"]], "c": "864240594"}, "book-100", "XBT/USD"]
[270, {"a": [["11651.00000", "0.00000000", "1596668220.871207"], ["11689.90000", "0.10000000", "1596667326.899060", "r"]], "c": "864240594"}, "book-100", "XBT/USD"]
[270, {"b": [["11635.10000", "20.23880983", "1596668220.924457"]], "c": "655008862"}, "book-100", "XBT/USD"]
[270, {"a": [["11653.40000", "0.70018235", "1596668220.935269"]], "c": "655008862"}, "book-100", "XBT/USD"]
[270, {"a": [["11649.10000", "2.00000000", "1596668221.023097"]], "c": "655008862"}, "book-100", "XBT/USD"]
[270, {"a": [["11650.40000", "0.00000000", "1596668221.049045"], ["11689.90000", "0.10000000", "1596667326.899060", "r"]], "c": "655008862"}, "book-100", "XBT/USD"]
[270, {"a": [["11644.40000", "0.00000000", "1596668221.053206"], ["11690.00000", "0.04000000", "1596667586.146170", "r"]], "c": "606174293"}, "book-100", "XBT/USD"]
[270, {"a": [["11651.40000", "0.00000000", "1596668221.077417"], ["11690.60000", "2.00429046", "1596668074.026932", "r"]], "c": "606174293"}, "book-100", "XBT/USD"]
[270, {"a": [["11644.40000", "0.67620000", "1596668221.894671"]], "c": "1333319301"}, "book-100", "XBT/USD"]
[270, {"a": [["11644.30000", "3.38044097", "1596668221.895096"]], "c": "2563443832"}, "book-100", "XBT/USD"]
[270, {"a": [["11643.70000", "0.36036690", "1596668221.900336"]], "c": "851634679"}, "book-100", "XBT/USD"]
[270, {"a": [["11649.10000", "2.04479238", "1596668221.908714"]], "c": "851634679"}, "book-100", "XBT/USD"]
[270, {"a": [["11649.70000", "0.13437714", "1596668221.909076"]], "c": "851634679"}, "book-100", "XBT/USD"]
[270, {"a": [["11648.00000", "0.91093000", "1596668221.909514"]], "c": "851634679"}, "book-100", "XBT/USD"]
[270, {"b": [["11624.00000", "0.00000000", "1596668221.909853"], ["11593.10000", "0.48610000", "1596668062.904254", "r"]], "c": "851634679"}, "book-100", "XBT/USD"]
[270, {"a": [["11644.30000", "2.70424097", "1596668221.911204"]], "c": "2798443374"}, "book-100", "XBT/USD"]
[270, {"b": [["11634.70000", "0.00000000", "1596668221.924176"], ["11592.90000", "0.80800000", "1596668169.200165", "r"]], "c": "584561827"}, "book-100", "XBT/USD"]
[271, [["11635.10000", "0.19560769", "1596668221.932881", "s", "m", ""], ["11635.10000", "0.00050726", "1596668221.935194", "s", "m", ""], ["11635.10000", "0.00000132", "1596668221.936558", "s", "m", ""]], "trade", "XBT/USD"]
[270, {"b": [["11635.10000", "20.04320214", "1596668221.932881"], ["11635.10000", "20.04269488", "1596668221.935194"], ["11635.10000", "20.04269356", "1596668221.936559"]], "c": "3252697575"}, "book-100", "XBT/USD"]
[270, {"a": [["11645.10000", "0.00000000", "1596668221.943318"], ["11689.90000", "0.10000000", "1596667326.899060", "r"]], "c": "3252697575"}, "book-100", "XBT/USD"]
[270, {"b": [["11611.40000", "0.00000000", "1596668221.947276"], ["11592.00000", "0.17085000", "1596668134.764860", "r"]], "c": "3252697575"}, "book-100", "XBT/USD"]
[270, {"a": [["11643.80000", "4.62138373", "1596668221.947605"]], "c": "709850946"}, "book-100", "XBT/USD"]
[270, {"b": [["11634.00000", "0.74068237", "1596668221.985923"]], "c": "203715198"}, "book-100", "XBT/USD"]
[270, {"a": [["11646.40000", "0.00000000", "1596668222.021490"], ["11690.00000", "0.04000000", "1596667586.146170", "r"]], "c": "203715198"}, "book-100", "XBT/USD"]
[270, {"a": [["11645.50000", "0.00000000", "1596668222.066304"], ["11690.60000", "2.00429046", "1596668074.026932", "r"]], "c": "203715198"}, "book-100", "XBT/USD"]
[270, {"b": [["11635.10000", "20.28340983", "1596668222.068642"]], "c": "3343199709"}, "book-100", "XBT/USD"]
[270, {"b": [["11624.00000", "0.00430124", "1596668222.107698"]], "c": "3343199709"}, "book-100", "XBT/USD"]
[270, {"b": [["11611.50000", "0.00435515", "1596668222.303960"]], "c": "3343199709"}, "book-100", "XBT/USD"]
[270, {"b": [["11624.00000", "0.00000000", "1596668222.352613"], ["11593.10000", "0.48610000", "1596668062.904254", "r"]], "c": "3343199709"}, "book-100", "XBT/USD"]
[270, {"a": [["11647.60000", "0.00000000", "1596668222.387242"], ["11691.40000", "23.57900000", "1596668160.826165", "r"]], "c": "3343199709"}, "book-100", "XBT/USD"]
[270, {"a": [["11646.60000", "1.72400000", "1596668222.415314"]], "c": "3343199709"}, "book-100", "XBT/USD"]
[270, {"a": [["11645.50000", "0.04250000", "1596668222.429634"]], "c": "3343199709"}, "book-100", "XBT/USD"]
[270, {"a": [["11647.40000", "6.52500423", "1596668222.542608"]], "c": "3343199709"}, "book-100", "XBT/USD"]
[270, {"b": [["11635.10000", "20.50514983", "1596668222.542932"]], "c": "3944263351"}, "book-100", "XBT/USD"]
[270, {"a": [["11647.20000", "0.00000000", "1596668222.599922"], ["11691.40000", "23.57900000", "1596668160.826165", "r"]], "c": "3944263351"}, "book-100", "XBT/USD"]
[270, {"b": [["11634.00000", "0.00000000", "1596668223.628033"], ["11592.90000", "0.80800000", "1596668169.200165", "r"]], "c": "3446909835"}, "book-100", "XBT/USD"]
[270, {"a": [["11643.70000", "0.10200000", "1596668223.629906"]], "c": "2701693937"}, "book-100", "XBT/USD"]
[270, {"a": [["11647.50000", "0.15000000", "1596668223.630144"]], "c": "2701693937"}, "book-100", "XBT/USD"]
[270, {"b": [["11610.20000", "0.49800000", "1596668223.630902"]], "c": "2701693937"}, "book-100", "XBT/USD"]
[270, {"a": [["11644.20000", "0.25836014", "1596668223.631654"]], "c": "4169581063"}, "book-100", "XBT/USD"]
[270, {"a": [["11643.30000", "0.64414594", "1596668223.633051"]], "c": "1081243319"}, "book-100", "XBT/USD"]
[270, {"a": [["11660.30000", "0.00000000", "1596668223.637526"], ["11690.00000", "0.04000000", "1596667586.146170", "r"]], "c": "1081243319"}, "book-100", "XBT/USD"]
[270, {"a": [["11656.70000", "1.16127613", "1596668223.641564"]], "c": "1081243319"}, "book-100", "XBT/USD"]
[270, {"a": [["11653.40000", "0.00000000", "1596668223.643224"], ["11690.60000", "2.00429046", "1596668074.026932", "r"]], "c": "1081243319"}, "book-100", "XBT/USD"]
[270, {"a": [["11647.40000", "6.37500423", "1596668223.644434"]], "c": "1081243319"}, "book-100", "XBT/USD"]
[271, [["11635.10000", "0.15998866", "1596668223.646162", "s", "m", ""], ["11635.10000", "0.00025557", "1596668223.648617", "s", "m", ""], ["11635.10000", "0.00000040", "1596668223.650187", "s", "m", ""]], "trade", "XBT/USD"]
[270, {"b": [["11635.10000", "20.34516117", "1596668223.646162"], ["11635.10000", "20.34490560", "1596668223.648617"], ["11635.10000", "20.34490520", "1596668223.650187"]], "c": "4181569224"}, "book-100", "XBT/USD"]
[271, [["11635.10000", "0.09903910", "1596668223.665478", "s", "l", ""], ["11635.10000", "0.00518150", "1596668223.667077", "s", "l", ""], ["11635.10000", "0.14288012", "1596668223.668973", "s", "l", ""], ["11635.10000", "0.01185966", "1596668223.670298", "s", "l", ""], ["11635.10000", "0.33254490", "1596668223.674174", "s", "l", ""], ["11635.10000", "0.54226544", "1596668223.677109", "s", "l", ""], ["11635.10000", "0.00800000", "1596668223.679001", "s", "l", ""], ["11635.10000", "0.28500000", "1596668223.680419", "s", "l", ""], ["11635.10000", "0.25841567", "1596668223.681755", "s", "l", ""], ["11635.10000", "0.64444605", "1596668223.683543", "s", "l", ""], ["11635.10000", "1.00000000", "1596668223.685252", "s", "l", ""], ["11635.10000", "2.00000000", "1596668223.686968", "s", "l", ""], ["11635.10000", "0.50000000", "1596668223.689322", "s", "l", ""], ["11635.10000", "0.50000000", "1596668223.690909", "s", "l", ""], ["11635.10000", "0.08594646", "1596668223.692429", "s", "l", ""], ["11635.10000", "0.15000000", "1596668223.693908", "s", "l", ""], ["11635.10000", "1.71700000", "1596668223.695320", "s", "l", ""], ["11635.10000", "6.71742110", "1596668223.697647", "s", "l", ""]], "trade", "XBT/USD"]
[270, {"b": [["11635.10000", "20.24586610", "1596668223.665478"], ["11635.10000", "20.24068460", "1596668223.667077"], ["11635.10000", "20.09780448", "1596668223.668973"], ["11635.10000", "20.08594482", "1596668223.670298"], ["11635.10000", "19.75339992", "1596668223.674174"], ["11635.10000", "19.21113448", "1596668223.677109"], ["11635.10000", "19.20313448", "1596668223.679001"], ["11635.10000", "18.91813448", "1596668223.680419"], ["11635.10000", "18.65971881", "1596668223.681755"], ["11635.10000", "18.01527276", "1596668223.683544"], ["11635.10000", "17.01527276", "1596668223.685253"], ["11635.10000", "15.01527276", "1596668223.686968"], ["11635.10000", "14.51527276", "1596668223.689322"], ["11635.10000", "14.01527276", "1596668223.690909"], ["11635.10000", "13.92932630", "1596668223.692429"], ["11635.10000", "13.77932630", "1596668223.693908"], ["11635.10000", "12.06232630", "1596668223.695320"], ["11635.10000", "5.34490520", "1596668223.697647"]], "c": "753399349"}, "book-100", "XBT/USD"]
[270, {"a": [["11650.90000", "0.70025827", "1596668223.719622"]], "c": "753399349"}, "book-100", "XBT/USD"]
[270, {"a": [["11644.40000", "0.00000000", "1596668223.729620"], ["11690.60000", "2.00429046", "1596668074.026932", "r"]], "c": "4105089087"}, "book-100", "XBT/USD"]
[270, {"a": [["11643.60000", "0.67340000", "1596668223.731317"]], "c": "3334221253"}, "book-100", "XBT/USD"]
[270, {"a": [["11656.50000", "6.03597194", "1596668223.742783"]], "c": "3334221253"}, "book-100", "XBT/USD"]
[270, {"a": [["11647.90000", "0.15000000", "1596668223.783381"]], "c": "3334221253"}, "book-100", "XBT/USD"]
[270, {"b": [["11635.10000", "6.34490520", "1596668223.812308"]], "c": "207869552"}, "book-100", "XBT/USD"]
[270, {"b": [["11633.40000", "1.59985007", "1596668223.854377"]], "c": "1781533745"}, "book-100", "XBT/USD"]
[270, {"b": [["11611.50000", "0.00000000", "1596668223.875068"], ["11592.90000", "0.80800000", "1596668169.200165", "r"]], "c": "1781533745"}, "book-100", "XBT/USD"]
[270, {"b": [["11612.40000", "2.01607807", "1596668223.876197"]], "c": "1781533745"}, "book-100", "XBT/USD"]
[270, {"b": [["11628.00000", "0.00000000", "1596668223.910236"], ["11592.90000", "0.80800000", "1596668169.200165", "r"]], "c": "1781533745"}, "book-100", "XBT/USD"]
[270, {"b": [["11628.70000", "0.00000000", "1596668223.914243"], ["11592.00000", "0.17085000", "1596668134.764860", "r"]], "c": "1781533745"}, "book-100", "XBT/USD"]
[270, {"b": [["11635.10000", "6.50514983", "1596668223.958604"]], "c": "2855481156"}, "book-100", "XBT/USD"]
[270, {"b": [["11635.00000", "0.00000000", "1596668223.961833"], ["11591.10000", "5.40000000", "1596668029.529055", "r"]], "c": "1380006316"}, "book-100", "XBT/USD"]
[270, {"b": [["11635.10000", "6.60418893", "1596668223.964076"]], "c": "1919120195"}, "book-100", "XBT/USD"]
[270, {"a": [["11651.30000", "0.00000000", "1596668223.977571"], ["11689.90000", "0.10000000", "1596667326.899060", "r"]], "c": "1919120195"}, "book-100", "XBT/USD"]
[270, {"b": [["11610.00000", "14.16733454", "1596668223.982187"]], "c": "1919120195"}, "book-100", "XBT/USD"]
[270, {"a": [["11651.50000", "0.64045000", "1596668224.009134"]], "c": "1919120195"}, "book-100", "XBT/USD"]
[270, {"a": [["11663.70000", "0.00000000", "1596668224.009624"], ["11690.00000", "0.04000000", "1596667586.146170", "r"]], "c": "1919120195"}, "book-100", "XBT/USD"]
[270, {"b": [["11603.20000", "0.00000000", "1596668224.013728"], ["11589.00000", "0.17085000", "1596668163.415816", "r"]], "c": "1919120195"}, "book-100", "XBT/USD"]
[270, {"a": [["11647.30000", "0.15000000", "1596668224.023704"]], "c": "1919120195"}, "book-100", "XBT/USD"]
[270, {"a": [["11643.20000", "0.72090000", "1596668224.024700"]], "c": "1944983400"}, "book-100", "XBT/USD"]
[270, {"b": [["11635.10000", "6.69013539", "1596668224.033048"]], "c": "3711444685"}, "book-100", "XBT/USD"]
[270, {"a": [["11643.60000", "0.00000000", "1596668224.033252"], ["11689.90000", "0.10000000", "1596667326.899060", "r"]], "c": "631910253"}, "book-100", "XBT/USD"]
[270, {"b": [["11610.00000", "15.16733454", "1596668224.079213"]], "c": "631910253"}, "book-100", "XBT/USD"]
[270, {"b": [["11633.40000", "0.85916770", "1596668224.089634"]], "c": "3684844642"}, "book-100", "XBT/USD"]
[270, {"a": [["11646.60000", "0.01000000", "1596668224.127229"]], "c": "3684844642"}, "book-100", "XBT/USD"]
[270, {"b": [["11635.10000", "3.40768646", "1596668224.185236"]], "c": "979097175"}, "book-100", "XBT/USD"]
[270, {"a": [["11650.60000", "0.66843989", "1596668224.192430"]], "c": "979097175"}, "book-100", "XBT/USD"]
[270, {"b": [["11626.20000", "0.45369254", "1596668224.192821"]], "c": "979097175"}, "book-100", "XBT/USD"]
[270, {"a": [["11669.90000", "0.60374108", "1596668224.192882"]], "c": "979097175"}, "book-100", "XBT/USD"]
[270, {"a": [["11657.00000", "0.47057064", "1596668224.192937"]], "c": "979097175"}, "book-100", "XBT/USD"]
[270, {"b": [["11632.50000", "0.74068237", "1596668224.246099"]], "c": "979097175"}, "book-100", "XBT/USD"]
[270, {"a": [["11648.30000", "0.85926140", "1596668224.257957"]], "c": "979097175"}, "book-100", "XBT/USD"]
[270, {"a": [["11643.70000", "0.85751922", "1596668224.295394"]], "c": "3341566775"}, "book-100", "XBT/USD"]
[270, {"b": [["11635.10000", "3.55768646", "1596668224.325044"]], "c": "3769342036"}, "book-100", "XBT/USD"]
[270, {"a": [["11646.90000", "0.15000000", "1596668224.383338"]], "c": "3769342036"}, "book-100", "XBT/USD"]
[270, {"a": [["11660.00000", "3.00000000", "1596668224.431758"]], "c": "3769342036"}, "book-100", "XBT/USD"]
[270, {"a": [["11657.00000", "0.00000000", "1596668224.499991"], ["11686.90000", "20.00000000", "1596668197.229568", "r"]], "c": "3769342036"}, "book-100", "XBT/USD"]
[270, {"b": [["11632.40000", "0.00000000", "1596668224.514478"], ["11591.10000", "5.40000000", "1596668029.529055", "r"]], "c": "3769342036"}, "book-100", "XBT/USD"]
[270, {"b": [["11632.20000", "0.00000000", "1596668224.526373"], ["11589.00000", "0.17085000", "1596668163.415816", "r"]], "c": "3769342036"}, "book-100", "XBT/USD"]
[270, {"a": [["11642.10000", "0.72090000", "1596668224.527579"]], "c": "107593740"}, "book-100", "XBT/USD"]
[270, {"a": [["11643.20000", "0.00000000", "1596668224.531784"], ["11686.90000", "20.00000000", "1596668197.229568", "r"]], "c": "1988724391"}, "book-100", "XBT/USD"]
[270, {"a": [["11643.70000", "0.10200000", "1596668224.563433"]], "c": "2348684231"}, "book-100", "XBT/USD"]
[270, {"b": [["11635.10000", "2.05768646", "1596668224.570253"]], "c": "1600300286"}, "book-100", "XBT/USD"]
