[270, {"as": [["11663.10000", "2.20274173", "1596668832.857133"], ["11663.30000", "0.68470000", "1596668832.859905"], ["11664.00000", "0.64298651", "1596668831.322460"], ["11664.50000", "0.85036000", "1596668831.034156"], ["11664.60000", "1.50000000", "1596668832.381409"], ["11664.70000", "0.64293636", "1596668831.362402"], ["11664.90000", "4.28000000", "1596668831.974995"], ["11665.50000", "0.64290404", "1596668831.369598"], ["11666.60000", "0.01000000", "1596668831.068875"], ["11666.90000", "0.69728334", "1596668832.505441"], ["11667.00000", "2.09600000", "1596668831.401731"], ["11668.10000", "0.04250000", "1596668832.013554"], ["11668.20000", "0.85724848", "1596668831.332940"], ["11669.00000", "0.00216537", "1596668828.232476"], ["11669.10000", "3.37787555", "1596668831.756886"], ["11669.30000", "0.10000000", "1596668832.226760"], ["11669.90000", "0.09800000", "1596668795.364756"], ["11670.00000", "43.90525970", "1596668820.398492"], ["11670.40000", "1.03464177", "1596668808.124177"], ["11670.50000", "0.85704332", "1596668794.232666"], ["11670.60000", "0.85707213", "1596668829.191874"], ["11671.60000", "0.09621094", "1596668827.169343"], ["11671.70000", "1.70900000", "1596668827.975453"], ["11671.90000", "0.69962493", "1596668832.779080"], ["11672.30000", "0.48762341", "1596668820.186804"], ["11672.40000", "0.70560000", "1596668831.815219"], ["11672.90000", "0.09200000", "1596668788.165014"], ["11673.00000", "0.85745309", "1596668815.870898"], ["11673.30000", "0.99873153", "1596668831.579435"], ["11673.50000", "0.50000000", "1596668810.499224"], ["11675.00000", "0.10071000", "1596668830.436562"], ["11675.10000", "0.04474429", "1596668828.068717"], ["11675.60000", "0.13422910", "1596668829.756186"], ["11675.80000", "1.29624984", "1596668821.143734"], ["11676.30000", "6.23753270", "1596668821.138224"], ["11676.40000", "1.09331452", "1596668832.543243"], ["11676.70000", "1.00434000", "1596668821.985306"], ["11677.00000", "6.50000000", "1596668827.942735"], ["11678.20000", "0.72309020", "1596668832.680353"], ["11678.30000", "0.24915102", "1596668832.585736"], ["11678.40000", "1.56584358", "1596668832.528344"], ["11678.80000", "0.38000000", "1596668832.479477"], ["11678.90000", "4.48423847", "1596668781.839002"], ["11680.40000", "0.30000000", "1596668812.826311"], ["11680.50000", "0.49673612", "1596668832.483707"], ["11681.20000", "6.11032810", "1596668831.707974"], ["11681.30000", "2.29920000", "1596668791.506140"], ["11681.80000", "2.09640692", "1596668832.598830"], ["11681.90000", "8.90976234", "1596668832.508679"], ["11683.00000", "0.74897201", "1596668832.087140"], ["11683.10000", "0.38000000", "1596668829.455300"], ["11684.20000", "0.00438186", "1596668828.244071"], ["11684.30000", "1.04940000", "1596668754.526173"], ["11684.60000", "1.20793164", "1596668831.939670"], ["11684.80000", "2.00543397", "1596668831.878032"], ["11685.00000", "0.99338906", "1596668791.115728"], ["11685.10000", "1.60000000", "1596668789.369431"], ["11686.10000", "0.57271105", "1596668790.612503"], ["11687.00000", "0.90985557", "1596668790.256473"], ["11687.10000", "0.00300000", "1596668785.759801"], ["11687.20000", "7.07090602", "1596668830.952702"], ["11687.30000", "8.20000000", "1596668790.261966"], ["11687.50000", "2.32565760", "1596668697.579888"], ["11688.30000", "0.77700000", "1596668815.799957"], ["11689.30000", "2.00542208", "1596668725.552094"], ["11689.90000", "0.10000000", "1596668827.877674"], ["11690.00000", "0.04000000", "1596668655.941686"], ["11690.40000", "0.30000000", "1596668790.244684"], ["11692.30000", "8.50000000", "1596667892.430053"], ["11692.80000", "0.90920712", "1596668784.799785"], ["11692.90000", "0.89587660", "1596668725.618183"], ["11693.30000", "6.41047390", "1596668792.843491"], ["11693.50000", "1.48858686", "1596668812.038853"], ["11693.70000", "7.06725561", "1596668796.225485"], ["11693.80000", "2.00360128", "1596668609.712332"], ["11694.90000", "3.52575380", "1596668744.231695"], ["11695.60000", "0.05288987", "1596668766.299266"], ["11698.00000", "9.96574127", "1596668747.429502"], ["11698.10000", "0.02832341", "1596668797.639268"], ["11699.90000", "0.10000000", "1596668550.388278"], ["11700.00000", "0.52000000", "1596668583.766368"], ["11700.20000", "1.00980000", "1596668634.157193"], ["11700.40000", "0.30000000", "1596668832.729128"], ["11701.10000", "10.22422668", "1596668779.463997"], ["11701.20000", "3.15247249", "1596668612.926737"], ["11701.30000", "0.90820501", "1596668612.289215"], ["11701.50000", "1.11290000", "1596668781.494521"], ["11702.50000", "2.30801166", "1596668778.302190"], ["11702.90000", "3.52358543", "1596668612.362288"], ["11703.00000", "7.60000000", "1596668684.240172"], ["11703.60000", "2.80129308", "1596668634.214259"], ["11704.60000", "18.00000000", "1596667881.119389"], ["11705.50000", "0.51421029", "1596668822.696412"], ["11706.00000", "1.51600000", "1596668809.372526"], ["11708.50000", "6.50000000", "1596668498.075266"], ["11709.70000", "0.00507863", "1596668161.410923"], ["11710.00000", "2.00158438", "1596668640.482256"], ["11710.40000", "23.57900000", "1596668746.250805"], ["11710.50000", "2.47738097", "1596668674.279438"], ["11710.70000", "3.52099687", "1596668676.663708"]], "bs": [["11663.00000", "0.59990000", "1596668825.038724"], ["11662.60000", "0.09621094", "1596668831.209813"], ["11661.80000", "0.94293738", "1596668828.005738"], ["11661.10000", "0.25789401", "1596668831.749720"], ["11660.40000", "0.85714255", "1596668829.105165"], ["11660.00000", "1.78279722", "1596668791.350586"], ["11659.90000", "0.08250000", "1596668831.756696"], ["11659.80000", "0.57000000", "1596668819.110475"], ["11658.80000", "0.74068237", "1596668832.103595"], ["11658.50000", "0.04250000", "1596668832.013768"], ["11658.30000", "4.38300000", "1596668831.950469"], ["11658.20000", "0.85721125", "1596668823.918939"], ["11657.80000", "0.85734137", "1596668821.138412"], ["11657.00000", "2.00000000", "1596668827.036063"], ["11656.90000", "0.15000000", "1596668830.208346"], ["11656.80000", "0.15000000", "1596668814.786875"], ["11656.60000", "0.15000000", "1596668814.796472"], ["11655.50000", "0.85738346", "1596668819.862529"], ["11655.40000", "0.94327509", "1596668814.775451"], ["11654.60000", "0.09800000", "1596668793.371406"], ["11654.30000", "0.04474420", "1596668832.252793"], ["11654.00000", "0.00200000", "1596668754.391116"], ["11653.80000", "0.65837408", "1596668831.259503"], ["11653.70000", "0.13423698", "1596668830.720976"], ["11652.60000", "0.47323381", "1596668818.940454"], ["11652.40000", "0.85694128", "1596668783.521842"], ["11652.30000", "0.61220500", "1596668830.514017"], ["11652.10000", "0.10200000", "1596668818.941030"], ["11652.00000", "0.43900000", "1596668824.998046"], ["11651.70000", "2.39230534", "1596668832.564035"], ["11651.60000", "0.30000000", "1596668832.455583"], ["11651.20000", "5.70000000", "1596668820.731425"], ["11650.70000", "1.93840000", "1596668823.141824"], ["11649.30000", "0.04221003", "1596668831.347402"], ["11649.20000", "0.30000000", "1596668682.046001"], ["11648.80000", "0.98200000", "1596668823.187379"], ["11648.10000", "0.85724848", "1596668831.322227"], ["11647.30000", "0.38000000", "1596668832.460758"], ["11647.20000", "0.09600000", "1596668790.907729"], ["11647.00000", "8.55731535", "1596668831.324119"], ["11645.50000", "0.00459547", "1596668829.420921"], ["11645.40000", "2.44185891", "1596668762.684408"], ["11645.30000", "1.42451973", "1596668830.907689"], ["11645.10000", "0.70100000", "1596668810.575205"], ["11644.90000", "0.91291218", "1596668829.672455"], ["11644.20000", "0.50000000", "1596668791.788850"], ["11643.80000", "3.59891527", "1596668796.050669"], ["11643.10000", "0.10364241", "1596668799.279452"], ["11642.80000", "1.03870000", "1596668823.306396"], ["11642.50000", "3.54144949", "1596668829.678966"], ["11641.40000", "9.01318665", "1596668830.988908"], ["11640.90000", "0.24999906", "1596668799.909101"], ["11640.70000", "0.72564643", "1596668799.279871"], ["11640.40000", "0.49845911", "1596668810.844755"], ["11640.10000", "0.03200000", "1596668831.069669"], ["11639.50000", "1.79850399", "1596668830.742801"], ["11639.30000", "2.36324797", "1596668830.342187"], ["11637.20000", "0.34339359", "1596668832.276348"], ["11636.80000", "7.31354763", "1596668829.759930"], ["11636.70000", "3.54321463", "1596668829.666788"], ["11636.10000", "0.05290565", "1596668807.720493"], ["11635.10000", "3.26702998", "1596668722.310064"], ["11635.00000", "3.26074592", "1596668803.896139"], ["11634.30000", "2.01125164", "1596668829.673373"], ["11634.20000", "6.48597991", "1596668825.665375"], ["11634.10000", "1.21269154", "1596668830.261701"], ["11632.80000", "0.57539821", "1596668826.381917"], ["11632.70000", "0.99759860", "1596668798.979170"], ["11632.00000", "6.20000000", "1596668579.084169"], ["11631.00000", "2.01506410", "1596668810.849433"], ["11630.00000", "0.49800000", "1596668831.366069"], ["11627.70000", "0.90083202", "1596668829.795678"], ["11627.50000", "0.91415605", "1596668810.824616"], ["11627.30000", "6.30000000", "1596668622.833411"], ["11626.60000", "0.70560000", "1596668752.456072"], ["11625.30000", "3.46790089", "1596668811.090497"], ["11625.10000", "4.65957301", "1596668810.951128"], ["11625.00000", "0.58747374", "1596668830.338118"], ["11624.10000", "0.75800000", "1596668751.014765"], ["11623.60000", "20.30000000", "1596668613.953585"], ["11623.40000", "0.02879253", "1596668801.833879"], ["11623.20000", "0.10583116", "1596668721.861220"], ["11622.80000", "6.90000000", "1596668499.924331"], ["11622.00000", "0.17085000", "1596668832.882876"], ["11620.20000", "7.96597770", "1596668636.528876"], ["11619.00000", "0.17085000", "1596668814.638662"], ["11618.90000", "0.00857235", "1596668772.999721"], ["11617.90000", "0.74897201", "1596668828.803782"], ["11617.80000", "0.75800000", "1596668746.479365"], ["11617.70000", "6.10000000", "1596668348.496250"], ["11617.00000", "0.48560000", "1596668765.432198"], ["11616.70000", "2.01655680", "1596668624.124633"], ["11616.20000", "1.02520000", "1596668785.995040"], ["11616.00000", "0.17085000", "1596668797.322398"], ["11615.90000", "4.46475061", "1596668829.670026"], ["11615.60000", "0.20000000", "1596668504.739520"], ["11614.90000", "13.92635477", "1596668747.360156"], ["11613.60000", "0.00900000", "1596668634.701883"], ["11613.00000", "2.47005000", "1596668745.469538"], ["11612.40000", "1.06000000", "1596668754.370261"]]}, "book-100", "XBT/USD"]
[270, {"a": [["11666.60000", "0.00000000", "1596668832.996920"], ["11713.30000", "0.48370000", "1596668765.365747", "r"]], "c": "3530277754"}, "book-100", "XBT/USD"]
[270, {"a": [["11681.20000", "0.02573600", "1596668833.002917"]], "c": "3530277754"}, "book-100", "XBT/USD"]
[270, {"a": [["11699.70000", "2.24798697", "1596668833.006821"]], "c": "3530277754"}, "book-100", "XBT/USD"]
[270, {"a": [["11666.80000", "0.01000000", "1596668833.052495"]], "c": "2223258566"}, "book-100", "XBT/USD"]
[270, {"a": [["11665.40000", "0.25788968", "1596668833.079673"]], "c": "360917042"}, "book-100", "XBT/USD"]
[270, {"a": [["11683.00000", "0.00000000", "1596668833.081122"], ["11710.50000", "2.47738097", "1596668674.279438", "r"]], "c": "360917042"}, "book-100", "XBT/USD"]
[270, {"b": [["11634.20000", "0.00000000", "1596668833.097880"], ["11612.30000", "7.00000000", "1596668730.212404", "r"]], "c": "360917042"}, "book-100", "XBT/USD"]
[270, {"b": [["11647.00000", "7.70000000", "1596668833.111093"]], "c": "360917042"}, "book-100", "XBT/USD"]
[270, {"a": [["11663.10000", "1.70274173", "1596668833.141456"]], "c": "3293999868"}, "book-100", "XBT/USD"]
[270, {"a": [["11678.80000", "6.87204561", "1596668833.280747"]], "c": "3293999868"}, "book-100", "XBT/USD"]
[270, {"a": [["11663.10000", "2.20274173", "1596668833.317058"]], "c": "360917042"}, "book-100", "XBT/USD"]
[270, {"b": [["11632.10000", "5.92894488", "1596668833.370866"]], "c": "360917042"}, "book-100", "XBT/USD"]
[270, {"a": [["11684.20000", "0.00000000", "1596668833.416947"], ["11710.70000", "3.52099687", "1596668676.663708", "r"]], "c": "360917042"}, "book-100", "XBT/USD"]
[270, {"b": [["11645.50000", "0.00000000", "1596668833.417152"], ["11612.30000", "7.00000000", "1596668730.212404", "r"]], "c": "360917042"}, "book-100", "XBT/USD"]
[270, {"a": [["11683.10000", "0.00000000", "1596668833.459243"], ["11713.30000", "0.48370000", "1596668765.365747", "r"]], "c": "360917042"}, "book-100", "XBT/USD"]
[270, {"b": [["11622.00000", "0.00000000", "1596668833.770082"], ["11611.00000", "2.82398241", "1596668695.165433", "r"]], "c": "360917042"}, "book-100", "XBT/USD"]
[270, {"b": [["11661.10000", "0.00000000", "1596668833.829906"], ["11610.90000", "2.01819797", "1596668831.877375", "r"]], "c": "2793837105"}, "book-100", "XBT/USD"]
[270, {"b": [["11658.80000", "0.00000000", "1596668833.865185"], ["11610.60000", "1.51500000", "1596668744.969089", "r"]], "c": "2534235276"}, "book-100", "XBT/USD"]
[270, {"a": [["11687.10000", "3.53082768", "1596668833.926237"]], "c": "2534235276"}, "book-100", "XBT/USD"]
[270, {"b": [["11661.90000", "0.25788834", "1596668833.926330"]], "c": "3867606977"}, "book-100", "XBT/USD"]
[270, {"a": [["11681.30000", "5.82877931", "1596668833.926509"]], "c": "3867606977"}, "book-100", "XBT/USD"]
[270, {"a": [["11684.70000", "3.20704332", "1596668833.939549"]], "c": "3867606977"}, "book-100", "XBT/USD"]
[270, {"b": [["11617.90000", "0.00000000", "1596668833.972146"], ["11610.60000", "1.51500000", "1596668744.969089", "r"]], "c": "3867606977"}, "book-100", "XBT/USD"]
[270, {"b": [["11659.40000", "0.74068237", "1596668834.061179"]], "c": "3178547140"}, "book-100", "XBT/USD"]
[270, {"a": [["11672.90000", "0.59038621", "1596668834.143976"]], "c": "3178547140"}, "book-100", "XBT/USD"]
[270, {"a": [["11687.00000", "1.48657199", "1596668834.144509"]], "c": "3178547140"}, "book-100", "XBT/USD"]
[270, {"b": [["11659.70000", "0.64299073", "1596668834.200095"]], "c": "1715139314"}, "book-100", "XBT/USD"]
[270, {"a": [["11678.50000", "1.42047690", "1596668834.449833"]], "c": "1715139314"}, "book-100", "XBT/USD"]
[270, {"a": [["11684.30000", "2.84101678", "1596668834.452666"]], "c": "1715139314"}, "book-100", "XBT/USD"]
[270, {"b": [["11648.10000", "1.56934056", "1596668834.458613"]], "c": "1715139314"}, "book-100", "XBT/USD"]
[270, {"b": [["11651.50000", "0.33899252", "1596668834.458950"]], "c": "1715139314"}, "book-100", "XBT/USD"]
[270, {"a": [["11672.80000", "0.33837394", "1596668834.464891"]], "c": "1715139314"}, "book-100", "XBT/USD"]
[270, {"a": [["11676.20000", "0.71037836", "1596668834.475736"]], "c": "1715139314"}, "book-100", "XBT/USD"]
[270, {"a": [["11667.00000", "2.00000000", "1596668834.635690"]], "c": "1715139314"}, "book-100", "XBT/USD"]
[270, {"b": [["11657.10000", "0.10200000", "1596668834.648159"]], "c": "1715139314"}, "book-100", "XBT/USD"]
[270, {"b": [["11635.20000", "2.71000000", "1596668835.116572"]], "c": "1715139314"}, "book-100", "XBT/USD"]
[270, {"a": [["11663.10000", "4.20274173", "1596668835.156665"]], "c": "355021792"}, "book-100", "XBT/USD"]
[270, {"b": [["11618.50000", "0.74899231", "1596668835.167155"]], "c": "355021792"}, "book-100", "XBT/USD"]
[270, {"a": [["11681.80000", "2.84539923", "1596668835.170988"]], "c": "355021792"}, "book-100", "XBT/USD"]
[270, {"a": [["11675.10000", "0.00000000", "1596668835.190558"], ["11710.40000", "23.57900000", "1596668746.250805", "r"]], "c": "355021792"}, "book-100", "XBT/USD"]
[270, {"a": [["11664.40000", "0.75551922", "1596668835.260854"]], "c": "810963993"}, "book-100", "XBT/USD"]
[270, {"a": [["11672.70000", "0.04474747", "1596668835.400576"]], "c": "810963993"}, "book-100", "XBT/USD"]
[270, {"a": [["11690.20000", "2.49000000", "1596668835.875799"]], "c": "810963993"}, "book-100", "XBT/USD"]
[270, {"a": [["11671.70000", "0.00000000", "1596668835.984670"], ["11709.70000", "0.00507863", "1596668161.410923", "r"]], "c": "810963993"}, "book-100", "XBT/USD"]
[270, {"a": [["11667.80000", "1.71400000", "1596668835.989362"]], "c": "810963993"}, "book-100", "XBT/USD"]
[270, {"a": [["11664.40000", "0.00000000", "1596668836.037644"], ["11709.70000", "0.00507863", "1596668161.410923", "r"]], "c": "355021792"}, "book-100", "XBT/USD"]
[270, {"b": [["11640.10000", "0.00000000", "1596668836.044819"], ["11613.00000", "2.47005000", "1596668745.469538", "r"]], "c": "355021792"}, "book-100", "XBT/USD"]
[270, {"a": [["11666.80000", "0.00000000", "1596668836.045190"], ["11710.00000", "2.00158438", "1596668640.482256", "r"]], "c": "427159498"}, "book-100", "XBT/USD"]
[270, {"b": [["11641.10000", "0.03200000", "1596668836.099343"]], "c": "427159498"}, "book-100", "XBT/USD"]
[270, {"b": [["11659.60000", "1.70200000", "1596668836.134788"]], "c": "3748123238"}, "book-100", "XBT/USD"]
[270, {"a": [["11688.30000", "0.00000000", "1596668836.146193"], ["11710.40000", "23.57900000", "1596668746.250805", "r"]], "c": "3748123238"}, "book-100", "XBT/USD"]
[270, {"b": [["11645.10000", "0.00000000", "1596668836.152435"], ["11613.60000", "0.00900000", "1596668634.701883", "r"]], "c": "3748123238"}, "book-100", "XBT/USD"]
[270, {"a": [["11690.50000", "0.67900000", "1596668836.165615"]], "c": "3748123238"}, "book-100", "XBT/USD"]
[270, {"b": [["11659.70000", "0.00000000", "1596668836.221295"], ["11613.00000", "2.47005000", "1596668745.469538", "r"]], "c": "376163430"}, "book-100", "XBT/USD"]
[270, {"b": [["11661.70000", "0.64295888", "1596668836.279040"]], "c": "1413435253"}, "book-100", "XBT/USD"]
[270, {"a": [["11673.30000", "0.88795004", "1596668836.335439"]], "c": "1413435253"}, "book-100", "XBT/USD"]
[270, {"b": [["11639.80000", "7.10031688", "1596668836.372426"]], "c": "1413435253"}, "book-100", "XBT/USD"]
[270, {"b": [["11628.20000", "7.10739998", "1596668836.374813"]], "c": "1413435253"}, "book-100", "XBT/USD"]
[270, {"a": [["11687.20000", "0.00000000", "1596668836.377638"], ["11710.40000", "23.57900000", "1596668746.250805", "r"]], "c": "1413435253"}, "book-100", "XBT/USD"]
[270, {"b": [["11647.70000", "0.76000000", "1596668836.604582"]], "c": "1413435253"}, "book-100", "XBT/USD"]
[270, {"a": [["11668.10000", "0.05250000", "1596668836.613760"]], "c": "1413435253"}, "book-100", "XBT/USD"]
[270, {"a": [["11672.70000", "0.15552896", "1596668836.626845"]], "c": "1413435253"}, "book-100", "XBT/USD"]
[270, {"b": [["11640.40000", "0.00000000", "1596668836.656873"], ["11615.60000", "0.20000000", "1596668504.739520", "r"]], "c": "1413435253"}, "book-100", "XBT/USD"]
[270, {"b": [["11632.70000", "0.00000000", "1596668836.680572"], ["11614.90000", "13.92635477", "1596668747.360156", "r"]], "c": "1413435253"}, "book-100", "XBT/USD"]
[270, {"b": [["11659.60000", "0.00000000", "1596668836.737135"], ["11613.60000", "0.00900000", "1596668634.701883", "r"]], "c": "4283438736"}, "book-100", "XBT/USD"]
[270, {"b": [["11659.20000", "1.70200000", "1596668836.746130"]], "c": "4283438736"}, "book-100", "XBT/USD"]
[270, {"a": [["11668.10000", "0.04250000", "1596668836.789609"]], "c": "4283438736"}, "book-100", "XBT/USD"]
[270, {"a": [["11668.30000", "0.01491804", "1596668836.804748"]], "c": "4283438736"}, "book-100", "XBT/USD"]
[270, {"b": [["11656.70000", "0.01491804", "1596668836.807016"]], "c": "4283438736"}, "book-100", "XBT/USD"]
[270, {"a": [["11664.50000", "0.00000000", "1596668836.824406"], ["11710.40000", "23.57900000", "1596668746.250805", "r"]], "c": "4224473860"}, "book-100", "XBT/USD"]
[270, {"b": [["11653.90000", "0.76437000", "1596668836.825579"]], "c": "4224473860"}, "book-100", "XBT/USD"]
[270, {"a": [["11666.90000", "1.46165334", "1596668836.830475"]], "c": "4237188885"}, "book-100", "XBT/USD"]
[270, {"b": [["11654.70000", "0.07459020", "1596668836.858634"]], "c": "4237188885"}, "book-100", "XBT/USD"]
[270, {"a": [["11671.10000", "0.07459020", "1596668836.859619"]], "c": "4237188885"}, "book-100", "XBT/USD"]
[270, {"a": [["11666.90000", "1.47165334", "1596668836.867133"]], "c": "1624597748"}, "book-100", "XBT/USD"]
[270, {"b": [["11643.50000", "0.49831569", "1596668836.889960"]], "c": "1624597748"}, "book-100", "XBT/USD"]
[270, {"a": [["11665.40000", "0.00000000", "1596668836.897507"], ["11710.40000", "23.57900000", "1596668746.250805", "r"]], "c": "2350898818"}, "book-100", "XBT/USD"]
[270, {"a": [["11674.50000", "0.17901711", "1596668836.919509"]], "c": "2350898818"}, "book-100", "XBT/USD"]
[270, {"a": [["11663.10000", "3.70274173", "1596668836.925299"]], "c": "1479514654"}, "book-100", "XBT/USD"]
[270, {"b": [["11653.00000", "0.17901711", "1596668836.926680"]], "c": "1479514654"}, "book-100", "XBT/USD"]
[270, {"b": [["11634.10000", "0.00000000", "1596668836.936679"], ["11616.20000", "1.02520000", "1596668785.995040", "r"]], "c": "1479514654"}, "book-100", "XBT/USD"]
[270, {"a": [["11671.90000", "0.00000000", "1596668836.970320"], ["11710.40000", "23.57900000", "1596668746.250805", "r"]], "c": "1479514654"}, "book-100", "XBT/USD"]
[270, {"b": [["11620.20000", "6.45099427", "1596668836.974183"]], "c": "1479514654"}, "book-100", "XBT/USD"]
[270, {"a": [["11663.10000", "1.70274173", "1596668836.991512"]], "c": "2943706636"}, "book-100", "XBT/USD"]
[270, {"a": [["11666.80000", "0.25788446", "1596668836.992032"]], "c": "320564364"}, "book-100", "XBT/USD"]
[270, {"b": [["11643.10000", "0.00000000", "1596668837.002843"], ["11616.00000", "0.17085000", "1596668797.322398", "r"]], "c": "320564364"}, "book-100", "XBT/USD"]
[270, {"b": [["11637.70000", "0.99712808", "1596668837.031078"]], "c": "320564364"}, "book-100", "XBT/USD"]
[270, {"a": [["11674.20000", "0.69955449", "1596668837.038002"]], "c": "320564364"}, "book-100", "XBT/USD"]
[270, {"b": [["11641.10000", "0.00000000", "1596668837.044174"], ["11616.00000", "0.17085000", "1596668797.322398", "r"]], "c": "320564364"}, "book-100", "XBT/USD"]
[270, {"b": [["11620.20000", "0.00000000", "1596668837.078649"], ["11615.90000", "4.46475061", "1596668829.670026", "r"]], "c": "320564364"}, "book-100", "XBT/USD"]
[270, {"b": [["11640.10000", "0.03200000", "1596668837.109787"]], "c": "320564364"}, "book-100", "XBT/USD"]
[270, {"a": [["11668.10000", "0.00000000", "1596668837.111010"], ["11710.00000", "2.00158438", "1596668640.482256", "r"]], "c": "320564364"}, "book-100", "XBT/USD"]
[270, {"b": [["11659.90000", "0.00000000", "1596668837.112200"], ["11615.90000", "4.46475061", "1596668829.670026", "r"]], "c": "2293539390"}, "book-100", "XBT/USD"]
[270, {"a": [["11675.00000", "0.01821000", "1596668837.112687"]], "c": "2293539390"}, "book-100", "XBT/USD"]
[270, {"a": [["11675.60000", "0.00000000", "1596668837.129063"], ["11710.40000", "23.57900000", "1596668746.250805", "r"]], "c": "2293539390"}, "book-100", "XBT/USD"]
[270, {"b": [["11616.80000", "1.99784406", "1596668837.161044"]], "c": "2293539390"}, "book-100", "XBT/USD"]
[270, {"b": [["11658.50000", "0.00000000", "1596668837.164632"], ["11615.90000", "4.46475061", "1596668829.670026", "r"]], "c": "2293539390"}, "book-100", "XBT/USD"]
[270, {"a": [["11664.50000", "0.75551922", "1596668837.170918"]], "c": "1975396926"}, "book-100", "XBT/USD"]
[270, {"b": [["11640.70000", "0.00000000", "1596668837.248407"], ["11615.60000", "0.20000000", "1596668504.739520", "r"]], "c": "1975396926"}, "book-100", "XBT/USD"]
