[270, {"a": [["11667.20000", "0.00000000", "1596666751.690178"], ["11691.60000", "2.80491857", "1596666648.819519", "r"]], "c": "1148928589"}, "book-100", "XBT/USD"]
[270, {"b": [["11641.60000", "0.00000000", "1596666751.767785"], ["11602.20000", "2.01681621", "1596666634.588713", "r"]], "c": "1148928589"}, "book-100", "XBT/USD"]
[270, {"b": [["11638.20000", "0.85877308", "1596666751.770470"]], "c": "1148928589"}, "book-100", "XBT/USD"]
[270, {"a": [["11654.00000", "1.50000000", "1596666751.896208"]], "c": "1148928589"}, "book-100", "XBT/USD"]
[270, {"b": [["11645.20000", "0.22100000", "1596666752.028363"]], "c": "1148928589"}, "book-100", "XBT/USD"]
[271, [["11649.60000", "0.23000000", "1596666752.032125", "b", "l", ""], ["11649.70000", "0.47175810", "1596666752.035130", "b", "l", ""], ["11650.00000", "0.38332906", "1596666752.036551", "b", "l", ""], ["11650.30000", "0.20230073", "1596666752.038043", "b", "l", ""]], "trade", "XBT/USD"]
[270, {"a": [["11649.60000", "0.00000000", "1596666752.032125"], ["11691.60000", "2.80491857", "1596666648.819519", "r"], ["11649.70000", "0.00000000", "1596666752.035131"], ["11691.90000", "0.89806591", "1596666649.630348", "r"], ["11650.00000", "0.00015670", "1596666752.036551"], ["11650.00000", "0.00000000", "1596666752.037824"], ["11692.10000", "4.49523792", "1596666702.300008", "r"], ["11650.30000", "0.44146057", "1596666752.038043"]], "c": "2555209578"}, "book-100", "XBT/USD"]
[270, {"a": [["11650.30000", "0.00000000", "1596666752.094340"], ["11692.30000", "8.50000000", "1596666502.813701", "r"]], "c": "1966759430"}, "book-100", "XBT/USD"]
[270, {"a": [["11652.90000", "0.00000000", "1596666752.128176"], ["11692.70000", "1.75400000", "1596666164.005133", "r"]], "c": "4162570828"}, "book-100", "XBT/USD"]
[270, {"b": [["11638.10000", "0.29487739", "1596666752.144378"]], "c": "4162570828"}, "book-100", "XBT/USD"]
[270, {"a": [["11656.90000", "0.00000000", "1596666752.176064"], ["11693.30000", "0.48410000", "1596666703.085185", "r"]], "c": "4162570828"}, "book-100", "XBT/USD"]
[270, {"a": [["11653.30000", "0.75551922", "1596666752.182682"]], "c": "2548241615"}, "book-100", "XBT/USD"]
[270, {"b": [["11634.50000", "0.00000000", "1596666752.188102"], ["11602.10000", "7.70000000", "1596666410.902600", "r"]], "c": "2548241615"}, "book-100", "XBT/USD"]
[270, {"a": [["11652.40000", "0.00000000", "1596666752.215109"], ["11693.30000", "0.48410000", "1596666703.085185", "r"]], "c": "3484179585"}, "book-100", "XBT/USD"]
[270, {"a": [["11662.60000", "0.83923000", "1596666752.235408"]], "c": "3484179585"}, "book-100", "XBT/USD"]
[270, {"a": [["11650.80000", "0.00000000", "1596666752.288755"], ["11693.30000", "0.48410000", "1596666703.085185", "r"]], "c": "399972311"}, "book-100", "XBT/USD"]
[270, {"a": [["11656.10000", "0.00000000", "1596666752.289897"], ["11693.70000", "1.16987239", "1596666701.085240", "r"]], "c": "399972311"}, "book-100", "XBT/USD"]
[270, {"a": [["11654.30000", "0.41352978", "1596666752.302722"]], "c": "2624360843"}, "book-100", "XBT/USD"]
[270, {"a": [["11650.70000", "0.12138811", "1596666752.322935"]], "c": "1840244660"}, "book-100", "XBT/USD"]
[270, {"a": [["11656.60000", "0.01000000", "1596666752.341806"]], "c": "1840244660"}, "book-100", "XBT/USD"]
[270, {"b": [["11645.20000", "0.13850000", "1596666752.418543"]], "c": "1840244660"}, "book-100", "XBT/USD"]
[270, {"b": [["11637.30000", "0.00000000", "1596666752.596941"], ["11601.40000", "13.94256021", "1596666708.975741", "r"]], "c": "1840244660"}, "book-100", "XBT/USD"]
[270, {"b": [["11649.60000", "2.20000000", "1596666752.607591"]], "c": "1449909391"}, "book-100", "XBT/USD"]
[270, {"a": [["11656.70000", "0.00000000", "1596666752.615366"], ["11692.70000", "1.75400000", "1596666164.005133", "r"]], "c": "1449909391"}, "book-100", "XBT/USD"]
[270, {"b": [["11645.80000", "0.00000000", "1596666752.620634"], ["11601.40000", "13.94256021", "1596666708.975741", "r"]], "c": "1449909391"}, "book-100", "XBT/USD"]
[270, {"a": [["11653.20000", "0.25872529", "1596666752.622778"]], "c": "819887354"}, "book-100", "XBT/USD"]
[270, {"b": [["11646.30000", "0.00000000", "1596666752.649732"], ["11601.00000", "0.17085000", "1596666692.102814", "r"]], "c": "1396028650"}, "book-100", "XBT/USD"]
[270, {"a": [["11664.00000", "5.70000000", "1596666752.653475"]], "c": "1396028650"}, "book-100", "XBT/USD"]
[270, {"a": [["11654.50000", "0.00000000", "1596666752.657619"], ["11692.30000", "8.50000000", "1596666502.813701", "r"]], "c": "1396028650"}, "book-100", "XBT/USD"]
[270, {"a": [["11653.30000", "0.00000000", "1596666752.670504"], ["11692.70000", "1.75400000", "1596666164.005133", "r"]], "c": "235037119"}, "book-100", "XBT/USD"]
[270, {"a": [["11656.60000", "0.00000000", "1596666752.682793"], ["11693.30000", "0.48410000", "1596666703.085185", "r"]], "c": "235037119"}, "book-100", "XBT/USD"]
[270, {"b": [["11649.60000", "0.00000000", "1596666752.683016"], ["11600.90000", "1.03470000", "1596666745.340027", "r"]], "c": "2967934596"}, "book-100", "XBT/USD"]
[270, {"a": [["11650.70000", "0.00000000", "1596666752.732237"], ["11693.70000", "1.16987239", "1596666701.085240", "r"]], "c": "1887802960"}, "book-100", "XBT/USD"]
[270, {"a": [["11651.60000", "0.12136553", "1596666752.732419"]], "c": "1255821895"}, "book-100", "XBT/USD"]
[270, {"b": [["11606.20000", "0.75003603", "1596666752.736623"]], "c": "1255821895"}, "book-100", "XBT/USD"]
[270, {"a": [["11656.90000", "0.01000000", "1596666752.737682"]], "c": "1255821895"}, "book-100", "XBT/USD"]
[270, {"a": [["11666.20000", "0.85003603", "1596666752.740851"]], "c": "1255821895"}, "book-100", "XBT/USD"]
[270, {"b": [["11645.90000", "0.00000000", "1596666752.766682"], ["11600.90000", "1.03470000", "1596666745.340027", "r"]], "c": "2907514731"}, "book-100", "XBT/USD"]
[270, {"b": [["11637.50000", "0.13438685", "1596666752.772575"]], "c": "2907514731"}, "book-100", "XBT/USD"]
[270, {"b": [["11646.80000", "0.89375319", "1596666752.825656"]], "c": "377380982"}, "book-100", "XBT/USD"]
[270, {"a": [["11662.10000", "1.36609684", "1596666752.869627"]], "c": "377380982"}, "book-100", "XBT/USD"]
[270, {"a": [["11649.60000", "0.42140041", "1596666753.107437"]], "c": "1592415007"}, "book-100", "XBT/USD"]
[270, {"a": [["11683.60000", "0.00000000", "1596666753.341847"], ["11692.30000", "8.50000000", "1596666502.813701", "r"]], "c": "1592415007"}, "book-100", "XBT/USD"]
[270, {"b": [["11648.40000", "0.64370427", "1596666753.419154"]], "c": "3026648727"}, "book-100", "XBT/USD"]
[270, {"b": [["11647.20000", "4.28600000", "1596666753.421413"]], "c": "3121152869"}, "book-100", "XBT/USD"]
[270, {"b": [["11645.30000", "0.08250000", "1596666753.468740"]], "c": "1706634348"}, "book-100", "XBT/USD"]
[270, {"a": [["11660.80000", "0.08250000", "1596666753.469694"]], "c": "1706634348"}, "book-100", "XBT/USD"]
[270, {"b": [["11649.50000", "0.89924912", "1596666753.528150"]], "c": "559036476"}, "book-100", "XBT/USD"]
[271, [["11649.50000", "0.07809993", "1596666753.563700", "s", "m", ""]], "trade", "XBT/USD"]
[270, {"b": [["11649.50000", "0.82114919", "1596666753.563700"]], "c": "3652716796"}, "book-100", "XBT/USD"]
[270, {"a": [["11651.60000", "0.00000000", "1596666753.624389"], ["11692.30000", "8.50000000", "1596666502.813701", "r"]], "c": "3081575605"}, "book-100", "XBT/USD"]
[270, {"a": [["11651.70000", "0.00000000", "1596666753.630743"], ["11692.70000", "1.75400000", "1596666164.005133", "r"]], "c": "3737628664"}, "book-100", "XBT/USD"]
[270, {"a": [["11653.30000", "0.75551922", "1596666753.684229"]], "c": "2698172161"}, "book-100", "XBT/USD"]
[270, {"a": [["11650.90000", "0.64373805", "1596666753.690597"]], "c": "1889671252"}, "book-100", "XBT/USD"]
[270, {"a": [["11651.30000", "0.64373547", "1596666753.690782"]], "c": "520594709"}, "book-100", "XBT/USD"]
[270, {"a": [["11653.00000", "0.64374206", "1596666753.691110"]], "c": "3127199526"}, "book-100", "XBT/USD"]
[270, {"b": [["11649.50000", "1.46489125", "1596666753.691252"]], "c": "3604649312"}, "book-100", "XBT/USD"]
[270, {"a": [["11653.30000", "0.00000000", "1596666753.740823"], ["11691.90000", "0.89806591", "1596666649.630348", "r"]], "c": "1351649097"}, "book-100", "XBT/USD"]
[270, {"b": [["11608.90000", "0.00000000", "1596666753.837390"], ["11601.40000", "13.94256021", "1596666708.975741", "r"]], "c": "1351649097"}, "book-100", "XBT/USD"]
[270, {"b": [["11617.30000", "0.70560000", "1596666753.909677"]], "c": "1351649097"}, "book-100", "XBT/USD"]
[270, {"b": [["11642.40000", "0.00000000", "1596666754.114102"], ["11601.40000", "13.94256021", "1596666708.975741", "r"]], "c": "1351649097"}, "book-100", "XBT/USD"]
[270, {"a": [["11654.60000", "0.09621094", "1596666754.358412"]], "c": "1351649097"}, "book-100", "XBT/USD"]
[270, {"a": [["11665.00000", "4.04806000", "1596666754.370385"]], "c": "1351649097"}, "book-100", "XBT/USD"]
[270, {"b": [["11646.10000", "0.09621094", "1596666754.404187"]], "c": "3163311901"}, "book-100", "XBT/USD"]
[270, {"a": [["11652.30000", "0.00000000", "1596666754.417312"], ["11691.90000", "0.89806591", "1596666649.630348", "r"]], "c": "4205884695"}, "book-100", "XBT/USD"]
[270, {"b": [["11646.80000", "0.64375319", "1596666754.431267"]], "c": "1351603693"}, "book-100", "XBT/USD"]
[270, {"a": [["11661.70000", "0.00000000", "1596666754.537204"], ["11692.10000", "4.49523792", "1596666702.300008", "r"]], "c": "1351603693"}, "book-100", "XBT/USD"]
[270, {"b": [["11647.10000", "0.00000000", "1596666754.539210"], ["11601.40000", "13.94256021", "1596666708.975741", "r"]], "c": "3184925216"}, "book-100", "XBT/USD"]
[270, {"a": [["11649.60000", "0.00000000", "1596666754.587281"], ["11692.30000", "8.50000000", "1596666502.813701", "r"]], "c": "660658161"}, "book-100", "XBT/USD"]
[270, {"b": [["11643.10000", "0.00000000", "1596666754.606034"], ["11601.00000", "0.17085000", "1596666692.102814", "r"]], "c": "660658161"}, "book-100", "XBT/USD"]
[270, {"b": [["11647.80000", "0.25000000", "1596666754.633302"]], "c": "4253669940"}, "book-100", "XBT/USD"]
[270, {"a": [["11650.90000", "0.00000000", "1596666754.675863"], ["11692.70000", "1.75400000", "1596666164.005133", "r"]], "c": "4258757833"}, "book-100", "XBT/USD"]
[270, {"a": [["11653.20000", "0.00000000", "1596666754.722776"], ["11693.30000", "0.48410000", "1596666703.085185", "r"]], "c": "1407418378"}, "book-100", "XBT/USD"]
[270, {"b": [["11648.20000", "0.42900000", "1596666754.803529"]], "c": "917501734"}, "book-100", "XBT/USD"]
[270, {"b": [["11642.40000", "0.33937298", "1596666754.814260"]], "c": "917501734"}, "book-100", "XBT/USD"]
[270, {"a": [["11653.30000", "0.25871664", "1596666754.818242"]], "c": "3435465773"}, "book-100", "XBT/USD"]
[270, {"b": [["11639.00000", "0.71289144", "1596666754.818681"]], "c": "3435465773"}, "book-100", "XBT/USD"]
[270, {"a": [["11666.10000", "0.76437339", "1596666754.830845"]], "c": "3435465773"}, "book-100", "XBT/USD"]
[270, {"a": [["11658.10000", "2.00000000", "1596666754.848671"]], "c": "3435465773"}, "book-100", "XBT/USD"]
[270, {"a": [["11664.00000", "0.00000000", "1596666754.849392"], ["11693.30000", "0.48410000", "1596666703.085185", "r"]], "c": "3435465773"}, "book-100", "XBT/USD"]
[270, {"a": [["11654.30000", "0.00000000", "1596666754.890368"], ["11693.70000", "1.16987239", "1596666701.085240", "r"]], "c": "1336371540"}, "book-100", "XBT/USD"]
[270, {"a": [["11651.30000", "0.00000000", "1596666754.899819"], ["11694.10000", "20.00000000", "1596666705.854859", "r"]], "c": "2735497663"}, "book-100", "XBT/USD"]
[270, {"a": [["11651.20000", "0.41978675", "1596666754.902681"]], "c": "2596822493"}, "book-100", "XBT/USD"]
[270, {"a": [["11662.80000", "0.00000000", "1596666754.986587"], ["11694.10000", "20.00000000", "1596666705.854859", "r"]], "c": "2596822493"}, "book-100", "XBT/USD"]
[270, {"b": [["11642.10000", "1.70800000", "1596666754.995919"]], "c": "2596822493"}, "book-100", "XBT/USD"]
[270, {"a": [["11658.50000", "1.71500000", "1596666755.012335"]], "c": "2596822493"}, "book-100", "XBT/USD"]
[270, {"b": [["11647.80000", "0.00000000", "1596666755.032125"], ["11602.30000", "2.01774694", "1596666748.156295", "r"]], "c": "1762549915"}, "book-100", "XBT/USD"]
[270, {"a": [["11656.10000", "0.41352978", "1596666755.036656"]], "c": "1762549915"}, "book-100", "XBT/USD"]
[270, {"a": [["11653.20000", "0.42712642", "1596666755.045324"]], "c": "3044660043"}, "book-100", "XBT/USD"]
[270, {"b": [["11640.40000", "8.20000000", "1596666755.052689"]], "c": "3044660043"}, "book-100", "XBT/USD"]
[270, {"a": [["11652.90000", "0.75551922", "1596666755.061458"]], "c": "1342539722"}, "book-100", "XBT/USD"]
[270, {"a": [["11662.70000", "0.33878227", "1596666755.064101"]], "c": "1342539722"}, "book-100", "XBT/USD"]
[270, {"a": [["11650.80000", "0.12141339", "1596666755.064501"]], "c": "2497932204"}, "book-100", "XBT/USD"]
[270, {"a": [["11652.90000", "0.00000000", "1596666755.107575"], ["11692.10000", "4.49523792", "1596666702.300008", "r"]], "c": "99200198"}, "book-100", "XBT/USD"]
[270, {"b": [["11647.20000", "0.00000000", "1596666755.138858"], ["11602.30000", "2.01774694", "1596666748.156295", "r"]], "c": "708927584"}, "book-100", "XBT/USD"]
[270, {"b": [["11648.30000", "0.25000000", "1596666755.177806"]], "c": "4029442511"}, "book-100", "XBT/USD"]
[270, {"b": [["11648.40000", "0.00000000", "1596666755.199796"], ["11602.30000", "2.01774694", "1596666748.156295", "r"]], "c": "387981749"}, "book-100", "XBT/USD"]
[270, {"a": [["11652.90000", "0.75551922", "1596666755.268647"]], "c": "2039209211"}, "book-100", "XBT/USD"]
[270, {"a": [["11658.50000", "0.00000000", "1596666755.340991"], ["11692.10000", "4.49523792", "1596666702.300008", "r"]], "c": "2039209211"}, "book-100", "XBT/USD"]
[270, {"a": [["11652.90000", "0.00000000", "1596666755.342621"], ["11692.30000", "8.50000000", "1596666502.813701", "r"]], "c": "387981749"}, "book-100", "XBT/USD"]
[270, {"a": [["11652.90000", "0.75551922", "1596666755.399194"]], "c": "2039209211"}, "book-100", "XBT/USD"]
[270, {"a": [["11652.90000", "0.00000000", "1596666755.453119"], ["11692.30000", "8.50000000", "1596666502.813701", "r"]], "c": "387981749"}, "book-100", "XBT/USD"]
[270, {"b": [["11649.50000", "1.06489125", "1596666755.457647"]], "c": "3871252907"}, "book-100", "XBT/USD"]
[270, {"a": [["11663.60000", "0.00000000", "1596666755.458951"], ["11692.70000", "1.75400000", "1596666164.005133", "r"]], "c": "3871252907"}, "book-100", "XBT/USD"]
[270, {"a": [["11667.50000", "0.38000000", "1596666755.465002"]], "c": "3871252907"}, "book-100", "XBT/USD"]
[270, {"a": [["11660.90000", "0.85867306", "1596666755.465390"]], "c": "3871252907"}, "book-100", "XBT/USD"]
[270, {"a": [["11656.10000", "0.00000000", "1596666755.486784"], ["11692.70000", "1.75400000", "1596666164.005133", "r"]], "c": "3871252907"}, "book-100", "XBT/USD"]
[270, {"a": [["11652.90000", "0.75551922", "1596666755.509855"]], "c": "2283101413"}, "book-100", "XBT/USD"]
[270, {"b": [["11645.30000", "1.08250000", "1596666755.541565"]], "c": "3058981962"}, "book-100", "XBT/USD"]
[270, {"a": [["11652.90000", "0.00000000", "1596666755.590459"], ["11692.70000", "1.75400000", "1596666164.005133", "r"]], "c": "463658699"}, "book-100", "XBT/USD"]
[270, {"a": [["11652.80000", "0.75551922", "1596666755.638170"]], "c": "664988872"}, "book-100", "XBT/USD"]
[270, {"a": [["11654.90000", "0.41352978", "1596666755.667159"]], "c": "664988872"}, "book-100", "XBT/USD"]
[270, {"a": [["11651.10000", "0.12140883", "1596666755.686147"]], "c": "302250047"}, "book-100", "XBT/USD"]
[270, {"a": [["11650.80000", "0.00000000", "1596666755.687701"], ["11692.10000", "4.49523792", "1596666702.300008", "r"]], "c": "1660986813"}, "book-100", "XBT/USD"]
[270, {"a": [["11652.80000", "0.00000000", "1596666755.788010"], ["11692.30000", "8.50000000", "1596666502.813701", "r"]], "c": "3183925415"}, "book-100", "XBT/USD"]
[270, {"b": [["11649.00000", "0.00000000", "1596666755.844391"], ["11602.20000", "2.01681621", "1596666634.588713", "r"]], "c": "234578738"}, "book-100", "XBT/USD"]
[270, {"a": [["11661.90000", "0.13437624", "1596666755.868981"]], "c": "234578738"}, "book-100", "XBT/USD"]
[270, {"b": [["11646.90000", "4.29000000", "1596666755.873523"]], "c": "1634914728"}, "book-100", "XBT/USD"]
[270, {"b": [["11649.50000", "1.46489125", "1596666755.875489"]], "c": "1543403819"}, "book-100", "XBT/USD"]
[270, {"b": [["11647.90000", "0.93229000", "1596666755.888623"]], "c": "316542618"}, "book-100", "XBT/USD"]
[270, {"a": [["11653.00000", "0.00000000", "1596666755.895580"], ["11692.30000", "8.50000000", "1596666502.813701", "r"]], "c": "4146190653"}, "book-100", "XBT/USD"]
[270, {"a": [["11652.20000", "0.64367154", "1596666755.962437"]], "c": "1064053638"}, "book-100", "XBT/USD"]
[270, {"b": [["11650.10000", "0.64365624", "1596666755.964115"]], "c": "2836468642"}, "book-100", "XBT/USD"]
[270, {"a": [["11654.40000", "0.68416693", "1596666755.966412"]], "c": "2025334840"}, "book-100", "XBT/USD"]
[270, {"b": [["11650.00000", "0.64365624", "1596666755.966788"]], "c": "3753410920"}, "book-100", "XBT/USD"]
[270, {"a": [["11652.60000", "0.64365624", "1596666755.970885"]], "c": "1672716206"}, "book-100", "XBT/USD"]
[270, {"b": [["11642.30000", "0.00000000", "1596666756.015775"], ["11603.10000", "0.00858405", "1596666739.130412", "r"]], "c": "1672716206"}, "book-100", "XBT/USD"]
[270, {"b": [["11621.90000", "0.00000000", "1596666756.179003"], ["11602.80000", "0.75800000", "1596666731.483110", "r"]], "c": "1672716206"}, "book-100", "XBT/USD"]
[270, {"b": [["11639.50000", "0.00000000", "1596666756.179079"], ["11602.30000", "2.01774694", "1596666748.156295", "r"]], "c": "1672716206"}, "book-100", "XBT/USD"]
[270, {"a": [["11651.20000", "0.00000000", "1596666756.190733"], ["11692.10000", "4.49523792", "1596666702.300008", "r"]], "c": "142470113"}, "book-100", "XBT/USD"]
[270, {"b": [["11649.50000", "1.26499206", "1596666756.252095"]], "c": "2585698000"}, "book-100", "XBT/USD"]
[270, {"b": [["11637.90000", "1.56000000", "1596666756.392038"]], "c": "2585698000"}, "book-100", "XBT/USD"]
[270, {"b": [["11645.10000", "2.20309486", "1596666756.396630"]], "c": "2585698000"}, "book-100", "XBT/USD"]
[270, {"a": [["11660.30000", "2.49371793", "1596666756.417299"]], "c": "2585698000"}, "book-100", "XBT/USD"]
[270, {"a": [["11678.60000", "0.63000000", "1596666756.423469"]], "c": "2585698000"}, "book-100", "XBT/USD"]
[270, {"b": [["11634.00000", "0.62900000", "1596666756.423684"]], "c": "2585698000"}, "book-100", "XBT/USD"]
[270, {"b": [["11632.60000", "0.00000000", "1596666756.442805"], ["11602.80000", "0.75800000", "1596666731.483110", "r"]], "c": "2585698000"}, "book-100", "XBT/USD"]
[270, {"a": [["11651.10000", "0.00000000", "1596666756.501516"], ["11691.90000", "0.89806591", "1596666649.630348", "r"]], "c": "88422772"}, "book-100", "XBT/USD"]
[270, {"a": [["11652.10000", "0.12148416", "1596666756.503786"]], "c": "2820199406"}, "book-100", "XBT/USD"]
[270, {"a": [["11651.00000", "0.59686449", "1596666756.526919"]], "c": "2283437685"}, "book-100", "XBT/USD"]
[270, {"a": [["11657.00000", "0.87052737", "1596666756.559340"]], "c": "2283437685"}, "book-100", "XBT/USD"]
[270, {"a": [["11654.90000", "0.00000000", "1596666756.596762"], ["11691.60000", "2.80491857", "1596666648.819519", "r"]], "c": "2283437685"}, "book-100", "XBT/USD"]
[270, {"b": [["11645.20000", "0.09600000", "1596666756.630043"]], "c": "2283437685"}, "book-100", "XBT/USD"]
[270, {"a": [["11654.40000", "0.64365624", "1596666756.630774"]], "c": "2283437685"}, "book-100", "XBT/USD"]
[270, {"a": [["11659.10000", "0.00000000", "1596666756.642435"], ["11691.90000", "0.89806591", "1596666649.630348", "r"]], "c": "2283437685"}, "book-100", "XBT/USD"]
[270, {"a": [["11662.60000", "0.00000000", "1596666756.694796"], ["11692.10000", "4.49523792", "1596666702.300008", "r"]], "c": "2283437685"}, "book-100", "XBT/USD"]
[270, {"a": [["11652.20000", "0.00000000", "1596666756.731275"], ["11692.30000", "8.50000000", "1596666502.813701", "r"]], "c": "3054486298"}, "book-100", "XBT/USD"]
[270, {"a": [["11655.20000", "0.41352978", "1596666756.742872"]], "c": "3054486298"}, "book-100", "XBT/USD"]
[270, {"b": [["11649.50000", "0.62125000", "1596666756.757912"]], "c": "3641884751"}, "book-100", "XBT/USD"]
[270, {"a": [["11653.30000", "0.00000000", "1596666756.811221"], ["11692.30000", "8.50000000", "1596666502.813701", "r"]], "c": "1239104617"}, "book-100", "XBT/USD"]
[270, {"a": [["11660.20000", "0.04479127", "1596666756.842800"]], "c": "1239104617"}, "book-100", "XBT/USD"]
[270, {"a": [["11656.20000", "0.04051069", "1596666756.858878"]], "c": "1239104617"}, "book-100", "XBT/USD"]
[270, {"b": [["11646.20000", "0.04250000", "1596666756.859806"]], "c": "1239104617"}, "book-100", "XBT/USD"]
[270, {"a": [["11653.70000", "0.25870461", "1596666756.890216"]], "c": "893384264"}, "book-100", "XBT/USD"]
[270, {"b": [["11637.60000", "0.00000000", "1596666756.928188"], ["11602.80000", "0.75800000", "1596666731.483110", "r"]], "c": "893384264"}, "book-100", "XBT/USD"]
[270, {"a": [["11666.20000", "0.10000000", "1596666756.949682"]], "c": "893384264"}, "book-100", "XBT/USD"]
[270, {"a": [["11683.50000", "2.25105769", "1596666756.949868"]], "c": "893384264"}, "book-100", "XBT/USD"]
[270, {"b": [["11606.20000", "0.00000000", "1596666756.950357"], ["11602.30000", "2.01774694", "1596666748.156295", "r"]], "c": "893384264"}, "book-100", "XBT/USD"]
[270, {"a": [["11652.60000", "0.00000000", "1596666756.954555"], ["11691.60000", "2.80491857", "1596666648.819519", "r"]], "c": "2396933806"}, "book-100", "XBT/USD"]
[270, {"a": [["11654.70000", "0.00000000", "1596666756.954886"], ["11691.90000", "0.89806591", "1596666649.630348", "r"]], "c": "2396933806"}, "book-100", "XBT/USD"]
[270, {"b": [["11638.20000", "0.00000000", "1596666756.955484"], ["11602.20000", "2.01681621", "1596666634.588713", "r"]], "c": "2396933806"}, "book-100", "XBT/USD"]
[270, {"a": [["11666.00000", "0.75001288", "1596666756.956820"]], "c": "2396933806"}, "book-100", "XBT/USD"]
[270, {"a": [["11662.70000", "0.00000000", "1596666756.972904"], ["11691.90000", "0.89806591", "1596666649.630348", "r"]], "c": "2396933806"}, "book-100", "XBT/USD"]
[270, {"a": [["11650.90000", "0.12148025", "1596666756.974053"]], "c": "3025514304"}, "book-100", "XBT/USD"]
[270, {"b": [["11635.90000", "0.00000000", "1596666756.987090"], ["11602.10000", "7.70000000", "1596666410.902600", "r"]], "c": "3025514304"}, "book-100", "XBT/USD"]
[270, {"b": [["11644.20000", "3.18275833", "1596666757.004749"]], "c": "3025514304"}, "book-100", "XBT/USD"]
[270, {"a": [["11652.10000", "0.00000000", "1596666757.005395"], ["11691.90000", "0.89806591", "1596666649.630348", "r"]], "c": "1534781197"}, "book-100", "XBT/USD"]
[270, {"a": [["11661.10000", "0.00000000", "1596666757.009219"], ["11692.10000", "4.49523792", "1596666702.300008", "r"]], "c": "1534781197"}, "book-100", "XBT/USD"]
[270, {"b": [["11606.40000", "0.75001288", "1596666757.012965"]], "c": "1534781197"}, "book-100", "XBT/USD"]
[270, {"a": [["11655.20000", "0.00000000", "1596666757.057473"], ["11692.30000", "8.50000000", "1596666502.813701", "r"]], "c": "1534781197"}, "book-100", "XBT/USD"]
[270, {"a": [["11654.60000", "0.00000000", "1596666757.057653"], ["11692.70000", "1.75400000", "1596666164.005133", "r"]], "c": "2271045742"}, "book-100", "XBT/USD"]
[270, {"a": [["11661.90000", "0.00000000", "1596666757.059650"], ["11693.30000", "0.48410000", "1596666703.085185", "r"]], "c": "2271045742"}, "book-100", "XBT/USD"]
[270, {"a": [["11662.10000", "0.00000000", "1596666757.061105"], ["11693.70000", "1.16987239", "1596666701.085240", "r"]], "c": "2271045742"}, "book-100", "XBT/USD"]
[270, {"a": [["11655.10000", "0.09600000", "1596666757.070050"]], "c": "2271045742"}, "book-100", "XBT/USD"]
[270, {"a": [["11663.20000", "0.00000000", "1596666757.126103"], ["11694.10000", "20.00000000", "1596666705.854859", "r"]], "c": "2271045742"}, "book-100", "XBT/USD"]
[270, {"a": [["11660.20000", "0.00000000", "1596666757.143775"], ["11696.80000", "1.98460791", "1596666708.392556", "r"]], "c": "2271045742"}, "book-100", "XBT/USD"]
[270, {"b": [["11640.90000", "0.00000000", "1596666757.168538"], ["11602.20000", "2.01681621", "1596666634.588713", "r"]], "c": "2271045742"}, "book-100", "XBT/USD"]
[270, {"a": [["11655.50000", "0.41352978", "1596666757.258068"]], "c": "2271045742"}, "book-100", "XBT/USD"]
[270, {"a": [["11664.40000", "0.13436674", "1596666757.306605"]], "c": "2271045742"}, "book-100", "XBT/USD"]
[270, {"b": [["11636.70000", "1.42606469", "1596666757.315214"]], "c": "2271045742"}, "book-100", "XBT/USD"]
[270, {"a": [["11663.30000", "0.33876484", "1596666757.330044"]], "c": "2271045742"}, "book-100", "XBT/USD"]
[270, {"a": [["11658.00000", "1.28656505", "1596666757.367694"]], "c": "2271045742"}, "book-100", "XBT/USD"]
[270, {"a": [["11662.30000", "0.04478875", "1596666757.375855"]], "c": "2271045742"}, "book-100", "XBT/USD"]
[270, {"a": [["11664.60000", "0.67878907", "1596666757.376623"]], "c": "2271045742"}, "book-100", "XBT/USD"]
[270, {"b": [["11650.20000", "0.47500000", "1596666757.381580"]], "c": "3510682380"}, "book-100", "XBT/USD"]
[270, {"a": [["11658.80000", "0.00000000", "1596666757.400652"], ["11692.30000", "8.50000000", "1596666502.813701", "r"]], "c": "3510682380"}, "book-100", "XBT/USD"]
[270, {"a": [["11663.20000", "0.11262745", "1596666757.410390"]], "c": "3510682380"}, "book-100", "XBT/USD"]
[270, {"b": [["11646.10000", "0.00000000", "1596666757.457123"], ["11602.30000", "2.01774694", "1596666748.156295", "r"]], "c": "3510682380"}, "book-100", "XBT/USD"]
[270, {"a": [["11666.10000", "0.71123541", "1596666757.471436"]], "c": "3510682380"}, "book-100", "XBT/USD"]
[270, {"a": [["11663.60000", "0.01037495", "1596666757.471724"]], "c": "3510682380"}, "book-100", "XBT/USD"]
[270, {"b": [["11643.10000", "1.00000000", "1596666757.540567"]], "c": "3510682380"}, "book-100", "XBT/USD"]
[270, {"a": [["11658.90000", "1.78450741", "1596666757.587790"]], "c": "3510682380"}, "book-100", "XBT/USD"]
[270, {"a": [["11653.70000", "0.00000000", "1596666757.725164"], ["11692.10000", "4.49523792", "1596666702.300008", "r"]], "c": "1101838584"}, "book-100", "XBT/USD"]
[270, {"a": [["11654.30000", "0.25869426", "1596666757.780815"]], "c": "540360276"}, "book-100", "XBT/USD"]
[270, {"a": [["11651.00000", "0.00000000", "1596666757.795871"], ["11692.10000", "4.49523792", "1596666702.300008", "r"]], "c": "2500214991"}, "book-100", "XBT/USD"]
[270, {"a": [["11658.90000", "1.35558999", "1596666757.997573"]], "c": "2500214991"}, "book-100", "XBT/USD"]
[270, {"a": [["11659.00000", "2.66070000", "1596666758.080176"]], "c": "2500214991"}, "book-100", "XBT/USD"]
[270, {"a": [["11654.70000", "0.64358143", "1596666758.105986"]], "c": "3097019432"}, "book-100", "XBT/USD"]
[270, {"b": [["11650.50000", "0.64363475", "1596666758.106086"]], "c": "3840477030"}, "book-100", "XBT/USD"]
[270, {"a": [["11655.40000", "0.64359325", "1596666758.107265"]], "c": "3840477030"}, "book-100", "XBT/USD"]
[270, {"b": [["11649.00000", "0.85812434", "1596666758.107663"]], "c": "534400474"}, "book-100", "XBT/USD"]
[270, {"a": [["11667.20000", "0.85812434", "1596666758.108419"]], "c": "534400474"}, "book-100", "XBT/USD"]
[270, {"a": [["11667.30000", "1.75782304", "1596666758.108527"]], "c": "534400474"}, "book-100", "XBT/USD"]
[270, {"b": [["11614.90000", "0.00000000", "1596666758.152803"], ["11603.10000", "0.00858405", "1596666739.130412", "r"]], "c": "534400474"}, "book-100", "XBT/USD"]
[270, {"a": [["11659.70000", "0.53793400", "1596666758.195473"]], "c": "534400474"}, "book-100", "XBT/USD"]
[270, {"a": [["11653.10000", "0.12155662", "1596666758.269149"]], "c": "2320539387"}, "book-100", "XBT/USD"]
[270, {"a": [["11650.90000", "0.00000000", "1596666758.271738"], ["11691.00000", "0.55961699", "1596666748.037839", "r"]], "c": "3775863713"}, "book-100", "XBT/USD"]
[270, {"b": [["11646.90000", "0.00000000", "1596666758.286800"], ["11602.80000", "0.75800000", "1596666731.483110", "r"]], "c": "3775863713"}, "book-100", "XBT/USD"]
[270, {"b": [["11648.40000", "4.28900000", "1596666758.287182"]], "c": "911425703"}, "book-100", "XBT/USD"]
[270, {"a": [["11655.10000", "0.00000000", "1596666758.359433"], ["11691.30000", "2.00311243", "1596666619.337977", "r"]], "c": "911425703"}, "book-100", "XBT/USD"]
[270, {"b": [["11643.10000", "0.00000000", "1596666758.363337"], ["11602.80000", "0.75800000", "1596666731.483110", "r"]], "c": "911425703"}, "book-100", "XBT/USD"]
[270, {"b": [["11630.20000", "0.00438149", "1596666758.365070"]], "c": "911425703"}, "book-100", "XBT/USD"]
[270, {"b": [["11635.00000", "0.00000000", "1596666758.378637"], ["11602.80000", "0.75800000", "1596666731.483110", "r"]], "c": "911425703"}, "book-100", "XBT/USD"]
[270, {"b": [["11631.60000", "4.00000000", "1596666758.392446"]], "c": "911425703"}, "book-100", "XBT/USD"]
[270, {"b": [["11639.70000", "0.00000000", "1596666758.404906"], ["11602.80000", "0.75800000", "1596666731.483110", "r"]], "c": "911425703"}, "book-100", "XBT/USD"]
[270, {"b": [["11648.30000", "0.00000000", "1596666758.417583"], ["11602.30000", "2.01774694", "1596666748.156295", "r"]], "c": "3473080291"}, "book-100", "XBT/USD"]
[270, {"a": [["11655.50000", "0.00000000", "1596666758.425329"], ["11691.60000", "2.80491857", "1596666648.819519", "r"]], "c": "3473080291"}, "book-100", "XBT/USD"]
[270, {"b": [["11642.40000", "0.00000000", "1596666758.438170"], ["11602.20000", "2.01681621", "1596666634.588713", "r"]], "c": "3473080291"}, "book-100", "XBT/USD"]
[270, {"b": [["11639.00000", "0.00000000", "1596666758.440442"], ["11602.10000", "7.70000000", "1596666410.902600", "r"]], "c": "3473080291"}, "book-100", "XBT/USD"]
[270, {"a": [["11653.00000", "0.55922651", "1596666758.519246"]], "c": "1419370764"}, "book-100", "XBT/USD"]
[270, {"a": [["11654.30000", "0.00000000", "1596666758.529217"], ["11691.60000", "2.80491857", "1596666648.819519", "r"]], "c": "2029093063"}, "book-100", "XBT/USD"]
[270, {"a": [["11663.80000", "0.10500000", "1596666758.538861"]], "c": "2029093063"}, "book-100", "XBT/USD"]
[270, {"a": [["11669.90000", "0.00438186", "1596666758.541738"]], "c": "2029093063"}, "book-100", "XBT/USD"]
[270, {"b": [["11649.90000", "0.25000000", "1596666758.561460"]], "c": "784310541"}, "book-100", "XBT/USD"]
[270, {"a": [["11654.90000", "0.25867917", "1596666758.571758"]], "c": "791961763"}, "book-100", "XBT/USD"]
[270, {"a": [["11662.30000", "0.00000000", "1596666758.581880"], ["11691.00000", "0.55961699", "1596666748.037839", "r"]], "c": "791961763"}, "book-100", "XBT/USD"]
[270, {"a": [["11665.10000", "0.00000000", "1596666758.611400"], ["11691.30000", "2.00311243", "1596666619.337977", "r"]], "c": "791961763"}, "book-100", "XBT/USD"]
[270, {"a": [["11656.80000", "0.41352978", "1596666758.623361"]], "c": "791961763"}, "book-100", "XBT/USD"]
[270, {"a": [["11653.80000", "0.00000000", "1596666758.638212"], ["11691.30000", "2.00311243", "1596666619.337977", "r"]], "c": "2415413508"}, "book-100", "XBT/USD"]
[270, {"b": [["11650.20000", "0.00000000", "1596666758.655826"], ["11602.10000", "7.70000000", "1596666410.902600", "r"]], "c": "2767770806"}, "book-100", "XBT/USD"]
[270, {"a": [["11656.90000", "0.00000000", "1596666758.676530"], ["11691.60000", "2.80491857", "1596666648.819519", "r"]], "c": "2767770806"}, "book-100", "XBT/USD"]
[270, {"a": [["11663.30000", "0.00000000", "1596666758.726858"], ["11691.90000", "0.89806591", "1596666649.630348", "r"]], "c": "2767770806"}, "book-100", "XBT/USD"]
[270, {"a": [["11656.60000", "0.01000000", "1596666758.728648"]], "c": "2767770806"}, "book-100", "XBT/USD"]
[270, {"a": [["11654.00000", "0.00000000", "1596666758.728714"], ["11691.90000", "0.89806591", "1596666649.630348", "r"]], "c": "3385117664"}, "book-100", "XBT/USD"]
[270, {"a": [["11666.10000", "0.00000000", "1596666758.731771"], ["11692.10000", "4.49523792", "1596666702.300008", "r"]], "c": "3385117664"}, "book-100", "XBT/USD"]
[270, {"a": [["11670.30000", "0.00000000", "1596666758.733476"], ["11692.30000", "8.50000000", "1596666502.813701", "r"]], "c": "3385117664"}, "book-100", "XBT/USD"]
[270, {"b": [["11648.20000", "0.00000000", "1596666758.782430"], ["11601.40000", "13.94256021", "1596666708.975741", "r"]], "c": "686043897"}, "book-100", "XBT/USD"]
[270, {"a": [["11670.00000", "0.00000000", "1596666758.808990"], ["11692.70000", "1.75400000", "1596666164.005133", "r"]], "c": "686043897"}, "book-100", "XBT/USD"]
[270, {"b": [["11640.40000", "0.00000000", "1596666758.810148"], ["11601.00000", "0.17085000", "1596666692.102814", "r"]], "c": "686043897"}, "book-100", "XBT/USD"]
[270, {"a": [["11663.60000", "0.05516073", "1596666758.832084"]], "c": "686043897"}, "book-100", "XBT/USD"]
[270, {"a": [["11656.30000", "1.83826614", "1596666758.875364"]], "c": "686043897"}, "book-100", "XBT/USD"]
[270, {"a": [["11664.60000", "0.00000000", "1596666758.879812"], ["11693.30000", "0.48410000", "1596666703.085185", "r"]], "c": "686043897"}, "book-100", "XBT/USD"]
[270, {"b": [["11642.30000", "0.33937589", "1596666758.898079"]], "c": "686043897"}, "book-100", "XBT/USD"]
[270, {"b": [["11630.20000", "0.00000000", "1596666758.899556"], ["11601.00000", "0.17085000", "1596666692.102814", "r"]], "c": "686043897"}, "book-100", "XBT/USD"]
[270, {"b": [["11638.10000", "1.19696692", "1596666758.918083"]], "c": "686043897"}, "book-100", "XBT/USD"]
[270, {"a": [["11654.40000", "0.00000000", "1596666758.918938"], ["11693.70000", "1.16987239", "1596666701.085240", "r"]], "c": "352317170"}, "book-100", "XBT/USD"]
[270, {"b": [["11650.10000", "0.00000000", "1596666758.919811"], ["11600.90000", "1.03470000", "1596666745.340027", "r"]], "c": "1682576011"}, "book-100", "XBT/USD"]
[270, {"a": [["11654.70000", "0.00000000", "1596666758.919902"], ["11694.10000", "20.00000000", "1596666705.854859", "r"]], "c": "1919315472"}, "book-100", "XBT/USD"]
[270, {"a": [["11667.80000", "0.10340146", "1596666758.920120"]], "c": "1919315472"}, "book-100", "XBT/USD"]
[270, {"b": [["11650.00000", "0.00000000", "1596666758.920823"], ["11600.10000", "0.05000000", "1596666747.910313", "r"]], "c": "3925364474"}, "book-100", "XBT/USD"]
[270, {"a": [["11658.00000", "0.00000000", "1596666758.923198"], ["11694.10000", "20.00000000", "1596666705.854859", "r"]], "c": "3925364474"}, "book-100", "XBT/USD"]
[270, {"b": [["11635.50000", "0.00000000", "1596666758.949661"], ["11600.00000", "0.02931034", "1596666720.289823", "r"]], "c": "3925364474"}, "book-100", "XBT/USD"]
[270, {"b": [["11637.00000", "0.04225465", "1596666758.950934"]], "c": "3925364474"}, "book-100", "XBT/USD"]
[270, {"b": [["11642.10000", "0.00000000", "1596666758.984122"], ["11600.00000", "0.02931034", "1596666720.289823", "r"]], "c": "3925364474"}, "book-100", "XBT/USD"]
[270, {"b": [["11640.00000", "7.40000000", "1596666758.992874"]], "c": "3925364474"}, "book-100", "XBT/USD"]
[270, {"a": [["11684.60000", "0.00000000", "1596666758.994793"], ["11696.80000", "1.98460791", "1596666708.392556", "r"]], "c": "3925364474"}, "book-100", "XBT/USD"]
[270, {"b": [["11649.10000", "1.70900000", "1596666758.995170"]], "c": "21704167"}, "book-100", "XBT/USD"]
[270, {"a": [["11657.30000", "1.70500000", "1596666758.999392"]], "c": "21704167"}, "book-100", "XBT/USD"]
[270, {"a": [["11653.40000", "0.00000000", "1596666759.013569"], ["11696.80000", "1.98460791", "1596666708.392556", "r"]], "c": "905663350"}, "book-100", "XBT/USD"]
[270, {"a": [["11659.70000", "0.00000000", "1596666759.024385"], ["11698.00000", "6.50000000", "1596665849.372318", "r"]], "c": "905663350"}, "book-100", "XBT/USD"]
[270, {"a": [["11672.00000", "0.00000000", "1596666759.024996"], ["11699.50000", "2.48018651", "1596666596.614575", "r"]], "c": "905663350"}, "book-100", "XBT/USD"]
[270, {"a": [["11659.00000", "1.56070000", "1596666759.027670"]], "c": "905663350"}, "book-100", "XBT/USD"]
[270, {"a": [["11658.90000", "0.85881622", "1596666759.044439"]], "c": "905663350"}, "book-100", "XBT/USD"]
[270, {"a": [["11656.10000", "0.25866648", "1596666759.066511"]], "c": "1933314142"}, "book-100", "XBT/USD"]
[270, {"b": [["11649.10000", "2.12222484", "1596666759.072291"]], "c": "451430766"}, "book-100", "XBT/USD"]
[270, {"a": [["11653.10000", "0.00000000", "1596666759.091667"], ["11699.50000", "2.48018651", "1596666596.614575", "r"]], "c": "2756091655"}, "book-100", "XBT/USD"]
[270, {"a": [["11652.90000", "0.12153498", "1596666759.092233"]], "c": "2467002309"}, "book-100", "XBT/USD"]
[270, {"b": [["11648.00000", "0.10000000", "1596666759.095433"]], "c": "1017510292"}, "book-100", "XBT/USD"]
[270, {"a": [["11663.70000", "0.00000000", "1596666759.118924"], ["11699.50000", "2.48018651", "1596666596.614575", "r"]], "c": "1017510292"}, "book-100", "XBT/USD"]
[270, {"b": [["11648.40000", "0.00000000", "1596666759.120450"], ["11600.10000", "0.05000000", "1596666747.910313", "r"]], "c": "1072487109"}, "book-100", "XBT/USD"]
[270, {"a": [["11657.20000", "0.00000000", "1596666759.131462"], ["11699.90000", "0.10000000", "1596666079.896762", "r"]], "c": "1072487109"}, "book-100", "XBT/USD"]
[270, {"a": [["11664.90000", "0.49774813", "1596666759.172360"]], "c": "1072487109"}, "book-100", "XBT/USD"]
[270, {"a": [["11667.20000", "1.55789056", "1596666759.187162"]], "c": "1072487109"}, "book-100", "XBT/USD"]
[270, {"a": [["11654.90000", "0.00000000", "1596666759.195958"], ["11699.90000", "0.10000000", "1596666079.896762", "r"]], "c": "1294944657"}, "book-100", "XBT/USD"]
[270, {"a": [["11660.80000", "0.52263104", "1596666759.214589"]], "c": "1294944657"}, "book-100", "XBT/USD"]
[270, {"a": [["11673.90000", "0.63504685", "1596666759.215626"]], "c": "1294944657"}, "book-100", "XBT/USD"]
[270, {"a": [["11691.30000", "0.00000000", "1596666759.241523"], ["11699.90000", "0.10000000", "1596666079.896762", "r"]], "c": "1294944657"}, "book-100", "XBT/USD"]
[270, {"a": [["11670.20000", "0.00000000", "1596666759.243833"], ["11700.00000", "0.52000000", "1596666697.653648", "r"]], "c": "1294944657"}, "book-100", "XBT/USD"]
[270, {"a": [["11667.90000", "0.00000000", "1596666759.255159"], ["11701.10000", "0.01796445", "1596665962.941606", "r"]], "c": "1294944657"}, "book-100", "XBT/USD"]
[270, {"a": [["11668.90000", "7.10000000", "1596666759.264875"]], "c": "1294944657"}, "book-100", "XBT/USD"]
[270, {"a": [["11668.20000", "0.00000000", "1596666759.265626"], ["11701.40000", "23.40000000", "1596666447.014661", "r"]], "c": "1294944657"}, "book-100", "XBT/USD"]
[270, {"a": [["11659.90000", "0.48489022", "1596666759.279888"]], "c": "1294944657"}, "book-100", "XBT/USD"]
[270, {"a": [["11665.00000", "3.30840000", "1596666759.300575"]], "c": "1294944657"}, "book-100", "XBT/USD"]
[270, {"b": [["11638.10000", "1.15217082", "1596666759.300928"]], "c": "1294944657"}, "book-100", "XBT/USD"]
[270, {"a": [["11653.20000", "0.00000000", "1596666759.386332"], ["11701.40000", "23.40000000", "1596666447.014661", "r"]], "c": "3091403313"}, "book-100", "XBT/USD"]
[270, {"a": [["11665.20000", "0.67599671", "1596666759.438822"]], "c": "3091403313"}, "book-100", "XBT/USD"]
[270, {"a": [["11653.00000", "0.00000000", "1596666759.440832"], ["11701.40000", "23.40000000", "1596666447.014661", "r"]], "c": "1971110705"}, "book-100", "XBT/USD"]
[270, {"a": [["11667.40000", "2.34055242", "1596666759.446571"]], "c": "1971110705"}, "book-100", "XBT/USD"]
[270, {"a": [["11671.60000", "0.00000000", "1596666759.446934"], ["11701.50000", "2.00069507", "1596666706.346367", "r"]], "c": "1971110705"}, "book-100", "XBT/USD"]
[270, {"a": [["11673.30000", "0.49715890", "1596666759.482223"]], "c": "1971110705"}, "book-100", "XBT/USD"]
[270, {"b": [["11639.80000", "0.04478281", "1596666759.493627"]], "c": "1971110705"}, "book-100", "XBT/USD"]
[270, {"b": [["11649.90000", "0.00000000", "1596666759.519388"], ["11600.10000", "0.05000000", "1596666747.910313", "r"]], "c": "1248227943"}, "book-100", "XBT/USD"]
[270, {"a": [["11656.80000", "0.00000000", "1596666759.525923"], ["11701.50000", "2.00069507", "1596666706.346367", "r"]], "c": "1321002584"}, "book-100", "XBT/USD"]
[270, {"b": [["11645.50000", "1.00000000", "1596666759.528839"]], "c": "1321002584"}, "book-100", "XBT/USD"]
[270, {"a": [["11659.20000", "0.00000000", "1596666759.533820"], ["11702.50000", "23.57900000", "1596666155.599282", "r"]], "c": "1321002584"}, "book-100", "XBT/USD"]
[270, {"b": [["11647.50000", "9.99987003", "1596666759.554134"]], "c": "110452112"}, "book-100", "XBT/USD"]
[270, {"a": [["11664.20000", "1.89751649", "1596666759.570501"]], "c": "110452112"}, "book-100", "XBT/USD"]
[270, {"a": [["11656.60000", "0.00000000", "1596666759.578115"], ["11702.50000", "23.57900000", "1596666155.599282", "r"]], "c": "2220498593"}, "book-100", "XBT/USD"]
[270, {"a": [["11663.60000", "0.01037495", "1596666759.578309"]], "c": "2220498593"}, "book-100", "XBT/USD"]
[270, {"a": [["11664.40000", "0.00000000", "1596666759.578470"], ["11704.10000", "8.30000000", "1596666665.290916", "r"]], "c": "2220498593"}, "book-100", "XBT/USD"]
[270, {"b": [["11622.00000", "0.17085000", "1596666759.597610"]], "c": "2220498593"}, "book-100", "XBT/USD"]
[270, {"b": [["11650.60000", "0.30000000", "1596666759.601750"]], "c": "2208552951"}, "book-100", "XBT/USD"]
[270, {"a": [["11667.40000", "0.91830000", "1596666759.603381"]], "c": "2208552951"}, "book-100", "XBT/USD"]
[270, {"a": [["11660.30000", "0.00000000", "1596666759.604901"], ["11706.80000", "3.00107058", "1596666756.974795", "r"]], "c": "2208552951"}, "book-100", "XBT/USD"]
[270, {"a": [["11659.70000", "1.26572391", "1596666759.607927"]], "c": "2208552951"}, "book-100", "XBT/USD"]
[270, {"a": [["11654.90000", "0.08582439", "1596666759.614603"]], "c": "15813327"}, "book-100", "XBT/USD"]
[270, {"a": [["11658.70000", "0.00000000", "1596666759.621180"], ["11704.10000", "8.30000000", "1596666665.290916", "r"]], "c": "15813327"}, "book-100", "XBT/USD"]
[270, {"a": [["11670.90000", "0.00000000", "1596666759.627071"], ["11706.80000", "3.00107058", "1596666756.974795", "r"]], "c": "15813327"}, "book-100", "XBT/USD"]
[270, {"a": [["11656.90000", "0.01000000", "1596666759.629356"]], "c": "670628489"}, "book-100", "XBT/USD"]
[270, {"a": [["11660.80000", "0.08250000", "1596666759.631625"]], "c": "670628489"}, "book-100", "XBT/USD"]
[270, {"b": [["11651.10000", "0.09900000", "1596666759.634249"]], "c": "1276739846"}, "book-100", "XBT/USD"]
[270, {"a": [["11655.40000", "0.00000000", "1596666759.654278"], ["11706.80000", "3.00107058", "1596666756.974795", "r"]], "c": "2057252423"}, "book-100", "XBT/USD"]
[270, {"b": [["11649.20000", "1.00000000", "1596666759.659408"]], "c": "1739729253"}, "book-100", "XBT/USD"]
[270, {"a": [["11656.10000", "0.00000000", "1596666759.659873"], ["11709.60000", "0.01287603", "1596666751.292879", "r"]], "c": "956065765"}, "book-100", "XBT/USD"]
[270, {"b": [["11647.60000", "1.86625052", "1596666759.662475"]], "c": "956065765"}, "book-100", "XBT/USD"]
[270, {"b": [["11652.10000", "0.25000000", "1596666759.664003"]], "c": "446949457"}, "book-100", "XBT/USD"]
[270, {"a": [["11659.40000", "0.41352978", "1596666759.666216"]], "c": "446949457"}, "book-100", "XBT/USD"]
[270, {"a": [["11656.30000", "0.33826614", "1596666759.676580"]], "c": "2866670213"}, "book-100", "XBT/USD"]
[270, {"a": [["11671.20000", "1.07273204", "1596666759.693085"]], "c": "2866670213"}, "book-100", "XBT/USD"]
[270, {"a": [["11680.30000", "0.00000000", "1596666759.699900"], ["11709.60000", "0.01287603", "1596666751.292879", "r"]], "c": "2866670213"}, "book-100", "XBT/USD"]
[270, {"a": [["11664.70000", "0.33872418", "1596666759.703297"]], "c": "2866670213"}, "book-100", "XBT/USD"]
[270, {"b": [["11637.20000", "0.00000000", "1596666759.705134"], ["11602.80000", "0.75800000", "1596666731.483110", "r"]], "c": "2866670213"}, "book-100", "XBT/USD"]
[270, {"b": [["11612.40000", "1.02210000", "1596666759.705973"]], "c": "2866670213"}, "book-100", "XBT/USD"]
[270, {"b": [["11645.10000", "0.92120000", "1596666759.709664"]], "c": "2866670213"}, "book-100", "XBT/USD"]
[270, {"b": [["11649.10000", "1.70900000", "1596666759.712826"]], "c": "2574150846"}, "book-100", "XBT/USD"]
[270, {"b": [["11649.50000", "0.22125000", "1596666759.715134"]], "c": "2489348235"}, "book-100", "XBT/USD"]
[270, {"b": [["11634.90000", "0.00000000", "1596666759.719116"], ["11602.80000", "0.75800000", "1596666731.483110", "r"]], "c": "2489348235"}, "book-100", "XBT/USD"]
[270, {"b": [["11652.80000", "0.50000000", "1596666759.720393"]], "c": "3015820198"}, "book-100", "XBT/USD"]
[270, {"b": [["11625.50000", "0.00000000", "1596666759.743055"], ["11602.80000", "0.75800000", "1596666731.483110", "r"]], "c": "3015820198"}, "book-100", "XBT/USD"]
[270, {"b": [["11630.00000", "0.00000000", "1596666759.743296"], ["11602.30000", "2.01774694", "1596666748.156295", "r"]], "c": "3015820198"}, "book-100", "XBT/USD"]
[270, {"a": [["11665.00000", "2.29920000", "1596666759.745719"]], "c": "3015820198"}, "book-100", "XBT/USD"]
[270, {"b": [["11645.30000", "0.08250000", "1596666759.746163"]], "c": "3015820198"}, "book-100", "XBT/USD"]
[270, {"b": [["11635.30000", "0.97770000", "1596666759.747213"]], "c": "3015820198"}, "book-100", "XBT/USD"]
[270, {"a": [["11659.70000", "0.00000000", "1596666759.747279"], ["11709.60000", "0.01287603", "1596666751.292879", "r"]], "c": "3015820198"}, "book-100", "XBT/USD"]
[270, {"a": [["11670.40000", "0.95510000", "1596666759.749336"]], "c": "3015820198"}, "book-100", "XBT/USD"]
[270, {"a": [["11663.20000", "0.00000000", "1596666759.751725"], ["11709.60000", "0.01287603", "1596666751.292879", "r"]], "c": "3015820198"}, "book-100", "XBT/USD"]
[270, {"a": [["11667.80000", "0.00000000", "1596666759.752147"], ["11709.70000", "7.20507863", "1596666620.257365", "r"]], "c": "3015820198"}, "book-100", "XBT/USD"]
[270, {"a": [["11672.50000", "0.00000000", "1596666759.755384"], ["11710.70000", "3.52183532", "1596666711.393054", "r"]], "c": "3015820198"}, "book-100", "XBT/USD"]
[270, {"a": [["11672.30000", "0.00000000", "1596666759.758449"], ["11711.00000", "3.52207482", "1596666594.088624", "r"]], "c": "3015820198"}, "book-100", "XBT/USD"]
[270, {"a": [["11657.30000", "0.00000000", "1596666759.758963"], ["11711.10000", "2.97327583", "1596666728.385477", "r"]], "c": "853582542"}, "book-100", "XBT/USD"]
[270, {"a": [["11656.30000", "0.00000000", "1596666759.760279"], ["11711.20000", "0.89630055", "1596666591.787115", "r"]], "c": "3536310930"}, "book-100", "XBT/USD"]
[270, {"b": [["11639.60000", "0.50000000", "1596666759.765197"]], "c": "3536310930"}, "book-100", "XBT/USD"]
[270, {"a": [["11658.90000", "0.00000000", "1596666759.765505"], ["11714.50000", "1.06000000", "1596666759.236412", "r"]], "c": "496516269"}, "book-100", "XBT/USD"]
[270, {"a": [["11682.40000", "1.89487854", "1596666759.768927"]], "c": "496516269"}, "book-100", "XBT/USD"]
[270, {"a": [["11671.20000", "0.72359939", "1596666759.770135"]], "c": "496516269"}, "book-100", "XBT/USD"]
[270, {"b": [["11650.60000", "0.76222411", "1596666759.773607"]], "c": "4007204199"}, "book-100", "XBT/USD"]
[270, {"a": [["11654.20000", "0.00000000", "1596666759.774702"], ["11715.00000", "0.17085000", "1596666587.247011", "r"]], "c": "1231138516"}, "book-100", "XBT/USD"]
[270, {"a": [["11670.80000", "0.00000000", "1596666759.776891"], ["11715.20000", "4.26795957", "1596666710.979332", "r"]], "c": "1231138516"}, "book-100", "XBT/USD"]
[270, {"a": [["11656.80000", "0.25863782", "1596666759.778616"]], "c": "822406442"}, "book-100", "XBT/USD"]
[270, {"b": [["11606.10000", "0.48590000", "1596666759.780057"]], "c": "822406442"}, "book-100", "XBT/USD"]
[270, {"a": [["11672.90000", "0.00000000", "1596666759.782455"], ["11715.20000", "4.26795957", "1596666710.979332", "r"]], "c": "822406442"}, "book-100", "XBT/USD"]
[270, {"b": [["11647.50000", "0.00000000", "1596666759.787696"], ["11603.10000", "0.00858405", "1596666739.130412", "r"]], "c": "822406442"}, "book-100", "XBT/USD"]
[270, {"b": [["11641.80000", "0.00000000", "1596666759.790534"], ["11602.80000", "0.75800000", "1596666731.483110", "r"]], "c": "822406442"}, "book-100", "XBT/USD"]
[270, {"b": [["11652.80000", "5.45000000", "1596666759.792782"]], "c": "3038127986"}, "book-100", "XBT/USD"]
[270, {"a": [["11667.20000", "0.85812434", "1596666759.793165"]], "c": "3038127986"}, "book-100", "XBT/USD"]
[270, {"b": [["11646.20000", "0.00000000", "1596666759.793867"], ["11602.30000", "2.01774694", "1596666748.156295", "r"]], "c": "3038127986"}, "book-100", "XBT/USD"]
[270, {"a": [["11672.20000", "0.00000000", "1596666759.794459"], ["11715.30000", "6.10000000", "1596666635.445451", "r"]], "c": "3038127986"}, "book-100", "XBT/USD"]
[270, {"b": [["11650.50000", "0.00000000", "1596666759.795543"], ["11602.20000", "2.01681621", "1596666634.588713", "r"]], "c": "4063674197"}, "book-100", "XBT/USD"]
[270, {"b": [["11641.90000", "0.85835073", "1596666759.797452"]], "c": "4063674197"}, "book-100", "XBT/USD"]
[270, {"a": [["11656.20000", "0.00000000", "1596666759.797618"], ["11717.80000", "1.99812614", "1596666759.535617", "r"]], "c": "1030869619"}, "book-100", "XBT/USD"]
[270, {"a": [["11656.90000", "0.00000000", "1596666759.802777"], ["11718.00000", "0.17085000", "1596665992.519802", "r"]], "c": "1492079523"}, "book-100", "XBT/USD"]
[270, {"a": [["11677.60000", "0.00000000", "1596666759.809154"], ["11718.50000", "24.30000000", "1596666641.380470", "r"]], "c": "1492079523"}, "book-100", "XBT/USD"]
[270, {"b": [["11641.90000", "0.00000000", "1596666759.810041"], ["11602.10000", "7.70000000", "1596666410.902600", "r"]], "c": "1492079523"}, "book-100", "XBT/USD"]
[270, {"b": [["11630.10000", "10.40045769", "1596666759.810866"]], "c": "1492079523"}, "book-100", "XBT/USD"]
[270, {"b": [["11652.10000", "0.00000000", "1596666759.818350"], ["11601.40000", "13.94256021", "1596666708.975741", "r"]], "c": "2470005357"}, "book-100", "XBT/USD"]
[270, {"b": [["11650.60000", "1.46120411", "1596666759.821179"]], "c": "2212624631"}, "book-100", "XBT/USD"]
[270, {"b": [["11637.90000", "0.00000000", "1596666759.821738"], ["11601.00000", "0.17085000", "1596666692.102814", "r"]], "c": "2212624631"}, "book-100", "XBT/USD"]
[270, {"a": [["11673.90000", "0.00000000", "1596666759.825804"], ["11719.60000", "1.46521891", "1596666747.719598", "r"]], "c": "2212624631"}, "book-100", "XBT/USD"]
[270, {"a": [["11665.90000", "0.50912805", "1596666759.826427"]], "c": "2212624631"}, "book-100", "XBT/USD"]
[270, {"b": [["11618.90000", "0.00000000", "1596666759.826606"], ["11600.10000", "0.05000000", "1596666747.910313", "r"]], "c": "2212624631"}, "book-100", "XBT/USD"]
[270, {"a": [["11667.40000", "0.96307800", "1596666759.830196"]], "c": "2212624631"}, "book-100", "XBT/USD"]
[270, {"a": [["11668.00000", "0.13433400", "1596666759.839004"]], "c": "2212624631"}, "book-100", "XBT/USD"]
[270, {"b": [["11649.60000", "4.28100000", "1596666759.840524"]], "c": "1164405501"}, "book-100", "XBT/USD"]
[270, {"a": [["11674.00000", "0.00300000", "1596666759.841073"]], "c": "1164405501"}, "book-100", "XBT/USD"]
[270, {"a": [["11658.00000", "0.75551922", "1596666759.842626"]], "c": "3455086730"}, "book-100", "XBT/USD"]
[270, {"a": [["11667.40000", "2.46307800", "1596666759.844511"]], "c": "3455086730"}, "book-100", "XBT/USD"]
[270, {"b": [["11644.20000", "0.00000000", "1596666759.845533"], ["11600.10000", "0.05000000", "1596666747.910313", "r"]], "c": "3455086730"}, "book-100", "XBT/USD"]
[270, {"a": [["11658.10000", "0.00000000", "1596666759.846075"], ["11718.00000", "0.17085000", "1596665992.519802", "r"]], "c": "3525629029"}, "book-100", "XBT/USD"]
[270, {"a": [["11667.40000", "1.54477800", "1596666759.857453"]], "c": "3525629029"}, "book-100", "XBT/USD"]
[270, {"a": [["11682.50000", "0.57303959", "1596666759.858407"]], "c": "3525629029"}, "book-100", "XBT/USD"]
[270, {"a": [["11656.80000", "0.00000000", "1596666759.867522"], ["11718.00000", "0.17085000", "1596665992.519802", "r"]], "c": "3706263916"}, "book-100", "XBT/USD"]
[270, {"b": [["11652.80000", "0.50000000", "1596666759.868170"]], "c": "1958278506"}, "book-100", "XBT/USD"]
[270, {"b": [["11650.90000", "0.15000000", "1596666759.869178"]], "c": "4011448178"}, "book-100", "XBT/USD"]
[270, {"a": [["11662.20000", "0.00000000", "1596666759.872403"], ["11718.50000", "24.30000000", "1596666641.380470", "r"]], "c": "4011448178"}, "book-100", "XBT/USD"]
[270, {"a": [["11671.20000", "0.00000000", "1596666759.873416"], ["11719.60000", "1.46521891", "1596666747.719598", "r"]], "c": "4011448178"}, "book-100", "XBT/USD"]
[270, {"a": [["11657.00000", "0.00000000", "1596666759.876514"], ["11719.70000", "3.50602221", "1596666743.346655", "r"]], "c": "3387534203"}, "book-100", "XBT/USD"]
[270, {"a": [["11665.20000", "0.00000000", "1596666759.878874"], ["11720.10000", "0.02000000", "1596666119.730609", "r"]], "c": "3387534203"}, "book-100", "XBT/USD"]
[270, {"b": [["11631.10000", "1.24457152", "1596666759.879149"]], "c": "3387534203"}, "book-100", "XBT/USD"]
[270, {"a": [["11663.60000", "0.00000000", "1596666759.884263"], ["11721.00000", "0.17085000", "1596665847.340288", "r"]], "c": "3387534203"}, "book-100", "XBT/USD"]
[270, {"a": [["11663.70000", "0.01296485", "1596666759.885393"]], "c": "3387534203"}, "book-100", "XBT/USD"]
[270, {"a": [["11675.70000", "0.00000000", "1596666759.892118"], ["11721.00000", "0.17085000", "1596665847.340288", "r"]], "c": "3387534203"}, "book-100", "XBT/USD"]
[270, {"a": [["11658.00000", "0.00000000", "1596666759.893110"], ["11722.10000", "7.70000000", "1596666696.315517", "r"]], "c": "264146509"}, "book-100", "XBT/USD"]
[270, {"a": [["11659.40000", "0.00000000", "1596666759.896420"], ["11722.20000", "3.01549629", "1596666746.821117", "r"]], "c": "246020753"}, "book-100", "XBT/USD"]
[270, {"a": [["11690.00000", "0.09293363", "1596666759.900711"]], "c": "246020753"}, "book-100", "XBT/USD"]
[270, {"a": [["11664.70000", "0.00000000", "1596666759.902365"], ["11724.00000", "0.17085000", "1596665931.095534", "r"]], "c": "246020753"}, "book-100", "XBT/USD"]
[270, {"a": [["11668.80000", "1.79965322", "1596666759.908215"]], "c": "246020753"}, "book-100", "XBT/USD"]
[270, {"a": [["11671.90000", "0.10336514", "1596666759.932679"]], "c": "246020753"}, "book-100", "XBT/USD"]
[270, {"b": [["11645.50000", "0.00000000", "1596666759.937390"], ["11600.10000", "0.05000000", "1596666747.910313", "r"]], "c": "246020753"}, "book-100", "XBT/USD"]
[270, {"b": [["11637.50000", "0.00000000", "1596666759.942935"], ["11600.00000", "0.02931034", "1596666720.289823", "r"]], "c": "246020753"}, "book-100", "XBT/USD"]
[270, {"b": [["11648.50000", "9.99987003", "1596666759.948124"]], "c": "246020753"}, "book-100", "XBT/USD"]
[270, {"b": [["11649.60000", "0.00000000", "1596666759.951615"], ["11600.00000", "0.02931034", "1596666720.289823", "r"]], "c": "4277733005"}, "book-100", "XBT/USD"]
[270, {"b": [["11652.80000", "0.75000000", "1596666759.969751"]], "c": "1811409287"}, "book-100", "XBT/USD"]
[270, {"a": [["11690.10000", "0.00000000", "1596666759.973192"], ["11722.20000", "3.01549629", "1596666746.821117", "r"]], "c": "1811409287"}, "book-100", "XBT/USD"]
[270, {"a": [["11705.30000", "1.51500000", "1596666759.981994"]], "c": "1811409287"}, "book-100", "XBT/USD"]
[270, {"a": [["11667.40000", "0.04477800", "1596666759.988667"]], "c": "1811409287"}, "book-100", "XBT/USD"]
[270, {"a": [["11660.80000", "0.00000000", "1596666759.993689"], ["11722.20000", "3.01549629", "1596666746.821117", "r"]], "c": "4101163403"}, "book-100", "XBT/USD"]
[270, {"b": [["11650.70000", "0.04250000", "1596666759.993851"]], "c": "273960507"}, "book-100", "XBT/USD"]
[270, {"a": [["11660.80000", "0.04051069", "1596666759.994020"]], "c": "1405104986"}, "book-100", "XBT/USD"]
[270, {"a": [["11665.90000", "0.00000000", "1596666760.018798"], ["11722.20000", "3.01549629", "1596666746.821117", "r"]], "c": "1405104986"}, "book-100", "XBT/USD"]
[270, {"a": [["11671.20000", "0.24938887", "1596666760.031216"]], "c": "1405104986"}, "book-100", "XBT/USD"]
[270, {"a": [["11657.10000", "0.01000000", "1596666760.031358"]], "c": "2442798214"}, "book-100", "XBT/USD"]
[270, {"a": [["11670.10000", "0.69967909", "1596666760.031445"]], "c": "2442798214"}, "book-100", "XBT/USD"]
[270, {"a": [["11652.90000", "0.00000000", "1596666760.033244"], ["11721.00000", "0.17085000", "1596665847.340288", "r"]], "c": "843520769"}, "book-100", "XBT/USD"]
[270, {"a": [["11663.70000", "1.40330302", "1596666760.034543"]], "c": "1742824036"}, "book-100", "XBT/USD"]
[270, {"b": [["11649.60000", "1.27044710", "1596666760.034624"]], "c": "435993933"}, "book-100", "XBT/USD"]
[270, {"a": [["11654.80000", "0.12180664", "1596666760.038343"]], "c": "426481632"}, "book-100", "XBT/USD"]
[270, {"a": [["11715.20000", "0.00000000", "1596666760.043264"], ["11721.00000", "0.17085000", "1596665847.340288", "r"]], "c": "426481632"}, "book-100", "XBT/USD"]
[270, {"b": [["11645.30000", "0.00000000", "1596666760.044058"], ["11600.10000", "0.05000000", "1596666747.910313", "r"]], "c": "426481632"}, "book-100", "XBT/USD"]
[270, {"a": [["11680.10000", "1.20852312", "1596666760.045407"]], "c": "426481632"}, "book-100", "XBT/USD"]
[270, {"a": [["11660.90000", "0.00000000", "1596666760.045539"], ["11721.00000", "0.17085000", "1596665847.340288", "r"]], "c": "1303428872"}, "book-100", "XBT/USD"]
[270, {"a": [["11667.30000", "0.85812434", "1596666760.054130"]], "c": "1303428872"}, "book-100", "XBT/USD"]
[270, {"a": [["11662.40000", "0.45011062", "1596666760.058728"]], "c": "2554918020"}, "book-100", "XBT/USD"]
[270, {"a": [["11654.90000", "0.00000000", "1596666760.062808"], ["11721.00000", "0.17085000", "1596665847.340288", "r"]], "c": "4275585727"}, "book-100", "XBT/USD"]
[270, {"a": [["11667.40000", "0.48377800", "1596666760.065412"]], "c": "4275585727"}, "book-100", "XBT/USD"]
[270, {"a": [["11682.30000", "0.99355179", "1596666760.065926"]], "c": "4275585727"}, "book-100", "XBT/USD"]
[270, {"a": [["11664.10000", "0.75551922", "1596666760.068116"]], "c": "4275585727"}, "book-100", "XBT/USD"]
[270, {"a": [["11691.00000", "0.00000000", "1596666760.068535"], ["11720.10000", "0.02000000", "1596666119.730609", "r"]], "c": "4275585727"}, "book-100", "XBT/USD"]
[270, {"a": [["11691.60000", "4.29406078", "1596666760.070902"]], "c": "4275585727"}, "book-100", "XBT/USD"]
[270, {"b": [["11652.10000", "0.40794455", "1596666760.071514"]], "c": "3286966130"}, "book-100", "XBT/USD"]
[270, {"b": [["11650.60000", "0.99898000", "1596666760.089847"]], "c": "144347945"}, "book-100", "XBT/USD"]
[270, {"a": [["11668.00000", "0.00000000", "1596666760.092257"], ["11721.00000", "0.17085000", "1596665847.340288", "r"]], "c": "144347945"}, "book-100", "XBT/USD"]
[270, {"b": [["11652.80000", "0.25000000", "1596666760.094435"]], "c": "1472158338"}, "book-100", "XBT/USD"]
[270, {"a": [["11680.00000", "2.00459268", "1596666760.095941"]], "c": "1472158338"}, "book-100", "XBT/USD"]
[270, {"a": [["11668.90000", "0.00000000", "1596666760.102379"], ["11721.00000", "0.17085000", "1596665847.340288", "r"]], "c": "1472158338"}, "book-100", "XBT/USD"]
[270, {"b": [["11654.20000", "0.10100000", "1596666760.105037"]], "c": "2875941089"}, "book-100", "XBT/USD"]
[270, {"b": [["11624.70000", "0.00000000", "1596666760.124623"], ["11601.00000", "0.17085000", "1596666692.102814", "r"]], "c": "2875941089"}, "book-100", "XBT/USD"]
[270, {"a": [["11667.50000", "1.06990395", "1596666760.129732"]], "c": "2875941089"}, "book-100", "XBT/USD"]
[270, {"a": [["11669.40000", "1.50000000", "1596666760.136443"]], "c": "2875941089"}, "book-100", "XBT/USD"]
[270, {"a": [["11693.70000", "1.72948938", "1596666760.141797"]], "c": "2875941089"}, "book-100", "XBT/USD"]
[270, {"a": [["11664.10000", "0.00000000", "1596666760.147017"], ["11721.00000", "0.17085000", "1596665847.340288", "r"]], "c": "2875941089"}, "book-100", "XBT/USD"]
[270, {"a": [["11663.70000", "1.39033817", "1596666760.161616"]], "c": "3249010514"}, "book-100", "XBT/USD"]
[270, {"a": [["11661.50000", "0.01037682", "1596666760.162168"]], "c": "3901358241"}, "book-100", "XBT/USD"]
[270, {"a": [["11677.60000", "0.89903818", "1596666760.175017"]], "c": "3901358241"}, "book-100", "XBT/USD"]
[270, {"a": [["11682.30000", "1.89222827", "1596666760.176550"]], "c": "3901358241"}, "book-100", "XBT/USD"]
[270, {"a": [["11663.80000", "0.00000000", "1596666760.210208"], ["11720.10000", "0.02000000", "1596666119.730609", "r"]], "c": "3901358241"}, "book-100", "XBT/USD"]
[270, {"a": [["11663.70000", "0.00000000", "1596666760.210386"], ["11721.00000", "0.17085000", "1596665847.340288", "r"]], "c": "3901358241"}, "book-100", "XBT/USD"]
[270, {"a": [["11664.00000", "0.88274602", "1596666760.213150"]], "c": "3901358241"}, "book-100", "XBT/USD"]
[270, {"b": [["11640.70000", "0.13430729", "1596666760.214307"]], "c": "3901358241"}, "book-100", "XBT/USD"]
[270, {"b": [["11649.70000", "0.53930000", "1596666760.215633"]], "c": "3478205649"}, "book-100", "XBT/USD"]
[270, {"b": [["11631.10000", "1.21357152", "1596666760.216131"]], "c": "3478205649"}, "book-100", "XBT/USD"]
[270, {"b": [["11642.70000", "0.00000000", "1596666760.217333"], ["11601.40000", "13.94256021", "1596666708.975741", "r"]], "c": "3478205649"}, "book-100", "XBT/USD"]
[270, {"a": [["11687.20000", "0.00000000", "1596666760.220329"], ["11721.00000", "0.17085000", "1596665847.340288", "r"]], "c": "3478205649"}, "book-100", "XBT/USD"]
[270, {"b": [["11652.90000", "0.30000000", "1596666760.220890"]], "c": "3292769148"}, "book-100", "XBT/USD"]
[270, {"b": [["11652.80000", "0.00000000", "1596666760.223925"], ["11601.40000", "13.94256021", "1596666708.975741", "r"]], "c": "965850903"}, "book-100", "XBT/USD"]
[270, {"b": [["11640.10000", "0.54430000", "1596666760.226178"]], "c": "965850903"}, "book-100", "XBT/USD"]
[270, {"a": [["11666.10000", "0.08250000", "1596666760.229318"]], "c": "965850903"}, "book-100", "XBT/USD"]
[270, {"a": [["11677.80000", "0.34894709", "1596666760.230754"]], "c": "965850903"}, "book-100", "XBT/USD"]
[270, {"a": [["11657.10000", "0.00000000", "1596666760.232495"], ["11720.10000", "0.02000000", "1596666119.730609", "r"]], "c": "830251617"}, "book-100", "XBT/USD"]
[270, {"a": [["11671.20000", "0.00000000", "1596666760.239689"], ["11721.00000", "0.17085000", "1596665847.340288", "r"]], "c": "830251617"}, "book-100", "XBT/USD"]
[270, {"b": [["11651.20000", "0.08250000", "1596666760.242908"]], "c": "1645126302"}, "book-100", "XBT/USD"]
[270, {"a": [["11689.60000", "0.00000000", "1596666760.245343"], ["11722.10000", "7.70000000", "1596666696.315517", "r"]], "c": "1645126302"}, "book-100", "XBT/USD"]
[270, {"a": [["11673.30000", "1.19333890", "1596666760.250679"]], "c": "1645126302"}, "book-100", "XBT/USD"]
[270, {"a": [["11659.70000", "0.25858306", "1596666760.253563"]], "c": "841013705"}, "book-100", "XBT/USD"]
[270, {"a": [["11675.60000", "0.00000000", "1596666760.267685"], ["11722.10000", "7.70000000", "1596666696.315517", "r"]], "c": "841013705"}, "book-100", "XBT/USD"]
[270, {"b": [["11644.70000", "0.00000000", "1596666760.272296"], ["11601.40000", "13.94256021", "1596666708.975741", "r"]], "c": "841013705"}, "book-100", "XBT/USD"]
[270, {"b": [["11602.00000", "1.06000000", "1596666760.274147"]], "c": "841013705"}, "book-100", "XBT/USD"]
[270, {"a": [["11667.90000", "0.11262565", "1596666760.279087"]], "c": "841013705"}, "book-100", "XBT/USD"]
[270, {"b": [["11633.10000", "0.03100000", "1596666760.283943"]], "c": "841013705"}, "book-100", "XBT/USD"]
[270, {"a": [["11658.90000", "0.01000000", "1596666760.286154"]], "c": "2556400717"}, "book-100", "XBT/USD"]
[270, {"b": [["11650.80000", "2.03852169", "1596666760.287712"]], "c": "1413809575"}, "book-100", "XBT/USD"]
[270, {"a": [["11664.20000", "0.00000000", "1596666760.290480"], ["11721.00000", "0.17085000", "1596665847.340288", "r"]], "c": "1413809575"}, "book-100", "XBT/USD"]
[270, {"b": [["11645.10000", "0.00000000", "1596666760.298122"], ["11602.10000", "7.70000000", "1596666410.902600", "r"]], "c": "1413809575"}, "book-100", "XBT/USD"]
[270, {"b": [["11648.50000", "0.00000000", "1596666760.308919"], ["11602.00000", "1.06000000", "1596666760.274147", "r"]], "c": "1413809575"}, "book-100", "XBT/USD"]
[270, {"a": [["11674.30000", "8.92340724", "1596666760.309561"]], "c": "1413809575"}, "book-100", "XBT/USD"]
[270, {"b": [["11640.10000", "0.00000000", "1596666760.327021"], ["11601.40000", "13.94256021", "1596666708.975741", "r"]], "c": "1413809575"}, "book-100", "XBT/USD"]
[270, {"b": [["11649.20000", "0.00000000", "1596666760.329059"], ["11601.00000", "0.17085000", "1596666692.102814", "r"]], "c": "1413809575"}, "book-100", "XBT/USD"]
[270, {"a": [["11684.50000", "0.00000000", "1596666760.333269"], ["11722.10000", "7.70000000", "1596666696.315517", "r"]], "c": "1413809575"}, "book-100", "XBT/USD"]
[270, {"a": [["11668.80000", "3.12942397", "1596666760.336794"]], "c": "1413809575"}, "book-100", "XBT/USD"]
[270, {"a": [["11662.40000", "0.00000000", "1596666760.339456"], ["11722.20000", "3.01549629", "1596666746.821117", "r"]], "c": "1413809575"}, "book-100", "XBT/USD"]
[270, {"b": [["11654.70000", "0.50000000", "1596666760.340954"]], "c": "2561784916"}, "book-100", "XBT/USD"]
[270, {"a": [["11689.50000", "10.19791223", "1596666760.345602"]], "c": "2561784916"}, "book-100", "XBT/USD"]
[270, {"a": [["11665.00000", "0.00000000", "1596666760.350036"], ["11722.20000", "3.01549629", "1596666746.821117", "r"]], "c": "2561784916"}, "book-100", "XBT/USD"]
[270, {"a": [["11664.00000", "1.22684819", "1596666760.356356"]], "c": "2561784916"}, "book-100", "XBT/USD"]
[270, {"a": [["11686.50000", "0.00000000", "1596666760.359959"], ["11724.00000", "0.17085000", "1596665931.095534", "r"]], "c": "2561784916"}, "book-100", "XBT/USD"]
[270, {"a": [["11663.90000", "0.22131455", "1596666760.372424"]], "c": "2561784916"}, "book-100", "XBT/USD"]
[270, {"a": [["11667.50000", "0.38000000", "1596666760.379824"]], "c": "2561784916"}, "book-100", "XBT/USD"]
[270, {"b": [["11653.40000", "0.25000000", "1596666760.379925"]], "c": "1555856579"}, "book-100", "XBT/USD"]
[270, {"b": [["11652.10000", "0.00000000", "1596666760.386728"], ["11601.40000", "13.94256021", "1596666708.975741", "r"]], "c": "2141298065"}, "book-100", "XBT/USD"]
[270, {"a": [["11685.90000", "2.00358060", "1596666760.388532"]], "c": "2141298065"}, "book-100", "XBT/USD"]
[270, {"b": [["11654.70000", "3.65000000", "1596666760.397681"]], "c": "1788028645"}, "book-100", "XBT/USD"]
[270, {"b": [["11645.40000", "6.10000000", "1596666760.402029"]], "c": "1788028645"}, "book-100", "XBT/USD"]
[270, {"b": [["11654.30000", "0.41031692", "1596666760.405377"]], "c": "2743930140"}, "book-100", "XBT/USD"]
[270, {"a": [["11669.80000", "0.13430597", "1596666760.413709"]], "c": "2743930140"}, "book-100", "XBT/USD"]
[270, {"a": [["11675.00000", "2.31741000", "1596666760.419622"]], "c": "2743930140"}, "book-100", "XBT/USD"]
[270, {"b": [["11647.60000", "0.00000000", "1596666760.421813"], ["11602.00000", "1.06000000", "1596666760.274147", "r"]], "c": "2743930140"}, "book-100", "XBT/USD"]
[270, {"a": [["11674.40000", "0.89928461", "1596666760.438454"]], "c": "2743930140"}, "book-100", "XBT/USD"]
[270, {"b": [["11633.10000", "0.00000000", "1596666760.452093"], ["11601.40000", "13.94256021", "1596666708.975741", "r"]], "c": "2743930140"}, "book-100", "XBT/USD"]
[270, {"a": [["11654.80000", "0.00000000", "1596666760.453660"], ["11721.00000", "0.17085000", "1596665847.340288", "r"]], "c": "2628506460"}, "book-100", "XBT/USD"]
[270, {"a": [["11715.00000", "0.00000000", "1596666760.461657"], ["11722.10000", "7.70000000", "1596666696.315517", "r"]], "c": "2628506460"}, "book-100", "XBT/USD"]
[270, {"b": [["11654.70000", "0.50000000", "1596666760.461918"]], "c": "627518414"}, "book-100", "XBT/USD"]
[270, {"a": [["11654.90000", "0.12211575", "1596666760.474206"]], "c": "1765992623"}, "book-100", "XBT/USD"]
[270, {"a": [["11658.90000", "0.00000000", "1596666760.481560"], ["11722.10000", "7.70000000", "1596666696.315517", "r"]], "c": "789087954"}, "book-100", "XBT/USD"]
[270, {"a": [["11660.70000", "0.64335748", "1596666760.492428"]], "c": "217404670"}, "book-100", "XBT/USD"]
[270, {"b": [["11654.70000", "1.14324789", "1596666760.498689"]], "c": "286922922"}, "book-100", "XBT/USD"]
[270, {"b": [["11654.70000", "0.64324789", "1596666760.504548"]], "c": "3905676641"}, "book-100", "XBT/USD"]
[270, {"a": [["11683.00000", "2.18196359", "1596666760.506821"]], "c": "3905676641"}, "book-100", "XBT/USD"]
[270, {"a": [["11673.70000", "0.38000000", "1596666760.510187"]], "c": "3905676641"}, "book-100", "XBT/USD"]
[270, {"a": [["11664.20000", "0.85772141", "1596666760.511437"]], "c": "3905676641"}, "book-100", "XBT/USD"]
[270, {"b": [["11653.20000", "0.85766386", "1596666760.512600"]], "c": "2282582314"}, "book-100", "XBT/USD"]
[270, {"a": [["11661.00000", "0.64332521", "1596666760.512740"]], "c": "4026106550"}, "book-100", "XBT/USD"]
[270, {"a": [["11669.40000", "2.35801129", "1596666760.512953"]], "c": "4026106550"}, "book-100", "XBT/USD"]
[270, {"b": [["11654.60000", "0.64324789", "1596666760.513549"]], "c": "3305476416"}, "book-100", "XBT/USD"]
[270, {"b": [["11652.80000", "0.85776695", "1596666760.514556"]], "c": "3702130011"}, "book-100", "XBT/USD"]
[270, {"a": [["11673.00000", "0.85780998", "1596666760.516471"]], "c": "3702130011"}, "book-100", "XBT/USD"]
[270, {"a": [["11667.40000", "0.43900000", "1596666760.517095"]], "c": "3702130011"}, "book-100", "XBT/USD"]
[270, {"b": [["11649.80000", "0.85790142", "1596666760.517403"]], "c": "3702130011"}, "book-100", "XBT/USD"]
[270, {"b": [["11651.00000", "0.53930000", "1596666760.529864"]], "c": "3702130011"}, "book-100", "XBT/USD"]
[270, {"b": [["11641.00000", "0.38000000", "1596666760.531034"]], "c": "3702130011"}, "book-100", "XBT/USD"]
[270, {"b": [["11649.70000", "0.00000000", "1596666760.534614"], ["11602.80000", "0.75800000", "1596666731.483110", "r"]], "c": "3702130011"}, "book-100", "XBT/USD"]
[270, {"a": [["11673.30000", "0.69618000", "1596666760.539295"]], "c": "3702130011"}, "book-100", "XBT/USD"]
[270, {"a": [["11689.90000", "0.10000000", "1596666760.544999"]], "c": "3702130011"}, "book-100", "XBT/USD"]
[270, {"a": [["11675.40000", "0.24929916", "1596666760.545968"]], "c": "3702130011"}, "book-100", "XBT/USD"]
[270, {"a": [["11705.20000", "0.75800000", "1596666760.546082"]], "c": "3702130011"}, "book-100", "XBT/USD"]
[270, {"a": [["11663.80000", "0.01000000", "1596666760.557669"]], "c": "3702130011"}, "book-100", "XBT/USD"]
[270, {"b": [["11654.50000", "0.64324789", "1596666760.562434"]], "c": "2178506949"}, "book-100", "XBT/USD"]
[270, {"b": [["11637.10000", "0.03100000", "1596666760.568412"]], "c": "2178506949"}, "book-100", "XBT/USD"]
[270, {"b": [["11649.10000", "0.00000000", "1596666760.589301"], ["11603.10000", "0.00858405", "1596666739.130412", "r"]], "c": "2178506949"}, "book-100", "XBT/USD"]
[270, {"a": [["11662.90000", "0.64324789", "1596666760.599605"]], "c": "2178506949"}, "book-100", "XBT/USD"]
[270, {"a": [["11659.80000", "0.00000000", "1596666760.601589"], ["11714.50000", "1.06000000", "1596666759.236412", "r"]], "c": "2595899683"}, "book-100", "XBT/USD"]
[270, {"b": [["11650.60000", "2.70198000", "1596666760.607168"]], "c": "2595899683"}, "book-100", "XBT/USD"]
[270, {"a": [["11668.50000", "0.67581482", "1596666760.631017"]], "c": "2595899683"}, "book-100", "XBT/USD"]
[270, {"a": [["11658.90000", "0.41215731", "1596666760.636542"]], "c": "1643263183"}, "book-100", "XBT/USD"]
[270, {"b": [["11652.70000", "0.42900000", "1596666760.645316"]], "c": "3192041928"}, "book-100", "XBT/USD"]
[270, {"a": [["11661.00000", "0.00000000", "1596666760.653378"], ["11711.20000", "0.89630055", "1596666591.787115", "r"]], "c": "1201445460"}, "book-100", "XBT/USD"]
[270, {"b": [["11647.20000", "1.00000000", "1596666760.666636"]], "c": "1201445460"}, "book-100", "XBT/USD"]
[270, {"a": [["11665.90000", "0.70560000", "1596666760.670857"]], "c": "1201445460"}, "book-100", "XBT/USD"]
[270, {"b": [["11654.70000", "3.61124789", "1596666760.672941"]], "c": "3175716955"}, "book-100", "XBT/USD"]
[270, {"a": [["11661.60000", "0.00000000", "1596666760.691200"], ["11711.20000", "0.89630055", "1596666591.787115", "r"]], "c": "3468507888"}, "book-100", "XBT/USD"]
[270, {"a": [["11668.10000", "0.50000000", "1596666760.693163"]], "c": "3468507888"}, "book-100", "XBT/USD"]
[270, {"a": [["11669.20000", "0.04476478", "1596666760.709485"]], "c": "3468507888"}, "book-100", "XBT/USD"]
[270, {"b": [["11654.30000", "0.00000000", "1596666760.715925"], ["11603.60000", "0.75800000", "1596666702.965229", "r"]], "c": "2449659853"}, "book-100", "XBT/USD"]
[270, {"a": [["11659.70000", "0.00000000", "1596666760.723780"], ["11711.10000", "2.97327583", "1596666728.385477", "r"]], "c": "3671400525"}, "book-100", "XBT/USD"]
[270, {"a": [["11663.80000", "0.00000000", "1596666760.726775"], ["11711.20000", "0.89630055", "1596666591.787115", "r"]], "c": "161741912"}, "book-100", "XBT/USD"]
[270, {"a": [["11660.60000", "0.25855185", "1596666760.746051"]], "c": "3334934354"}, "book-100", "XBT/USD"]
[270, {"b": [["11650.60000", "0.99898000", "1596666760.779874"]], "c": "3334934354"}, "book-100", "XBT/USD"]
[270, {"a": [["11660.70000", "0.00000000", "1596666760.783715"], ["11711.20000", "0.89630055", "1596666591.787115", "r"]], "c": "116480886"}, "book-100", "XBT/USD"]
[270, {"a": [["11662.80000", "0.01000000", "1596666760.788866"]], "c": "808233631"}, "book-100", "XBT/USD"]
[270, {"a": [["11661.50000", "0.00000000", "1596666760.820096"], ["11711.20000", "0.89630055", "1596666591.787115", "r"]], "c": "558087641"}, "book-100", "XBT/USD"]
[270, {"a": [["11662.80000", "0.03136212", "1596666760.821663"]], "c": "2482420571"}, "book-100", "XBT/USD"]
[270, {"a": [["11670.90000", "5.72691333", "1596666760.825724"]], "c": "2482420571"}, "book-100", "XBT/USD"]
[270, {"a": [["11668.80000", "1.79965322", "1596666760.833982"]], "c": "2482420571"}, "book-100", "XBT/USD"]
[270, {"a": [["11670.10000", "0.00000000", "1596666760.851340"], ["11711.20000", "0.89630055", "1596666591.787115", "r"]], "c": "2482420571"}, "book-100", "XBT/USD"]
[270, {"a": [["11673.30000", "0.00000000", "1596666760.862674"], ["11714.50000", "1.06000000", "1596666759.236412", "r"]], "c": "2482420571"}, "book-100", "XBT/USD"]
[270, {"a": [["11704.60000", "2.30891053", "1596666760.872896"]], "c": "2482420571"}, "book-100", "XBT/USD"]
[270, {"b": [["11649.70000", "0.10000000", "1596666760.877550"]], "c": "2482420571"}, "book-100", "XBT/USD"]
[270, {"a": [["11669.40000", "0.85801129", "1596666760.878769"]], "c": "2482420571"}, "book-100", "XBT/USD"]
[270, {"a": [["11658.90000", "0.00000000", "1596666760.879707"], ["11714.50000", "1.06000000", "1596666759.236412", "r"]], "c": "3727618273"}, "book-100", "XBT/USD"]
[270, {"a": [["11676.00000", "0.78431000", "1596666760.880150"]], "c": "3727618273"}, "book-100", "XBT/USD"]
[270, {"a": [["11668.50000", "0.00000000", "1596666760.880911"], ["11714.50000", "1.06000000", "1596666759.236412", "r"]], "c": "3727618273"}, "book-100", "XBT/USD"]
[270, {"b": [["11653.40000", "0.00000000", "1596666760.885326"], ["11603.60000", "0.75800000", "1596666702.965229", "r"]], "c": "3284738587"}, "book-100", "XBT/USD"]
[270, {"a": [["11664.30000", "0.00000000", "1596666760.890753"], ["11715.30000", "6.10000000", "1596666635.445451", "r"]], "c": "3284738587"}, "book-100", "XBT/USD"]
[270, {"a": [["11673.20000", "0.69958355", "1596666760.917837"]], "c": "3284738587"}, "book-100", "XBT/USD"]
[270, {"a": [["11671.90000", "0.00000000", "1596666760.923441"], ["11715.30000", "6.10000000", "1596666635.445451", "r"]], "c": "3284738587"}, "book-100", "XBT/USD"]
[270, {"a": [["11674.30000", "8.20000000", "1596666760.923668"]], "c": "3284738587"}, "book-100", "XBT/USD"]
[270, {"a": [["11660.60000", "0.00000000", "1596666760.942348"], ["11717.80000", "1.99812614", "1596666759.535617", "r"]], "c": "1050817566"}, "book-100", "XBT/USD"]
[270, {"a": [["11682.40000", "0.99630000", "1596666760.957351"]], "c": "1050817566"}, "book-100", "XBT/USD"]
[270, {"a": [["11674.40000", "0.00000000", "1596666760.966621"], ["11718.50000", "24.30000000", "1596666641.380470", "r"]], "c": "1050817566"}, "book-100", "XBT/USD"]
[270, {"b": [["11613.90000", "0.78684034", "1596666760.978313"]], "c": "1050817566"}, "book-100", "XBT/USD"]
[270, {"a": [["11685.30000", "0.00000000", "1596666760.981168"], ["11719.60000", "1.46521891", "1596666747.719598", "r"]], "c": "1050817566"}, "book-100", "XBT/USD"]
[270, {"a": [["11664.20000", "0.00000000", "1596666760.996340"], ["11719.70000", "3.50602221", "1596666743.346655", "r"]], "c": "3673485449"}, "book-100", "XBT/USD"]
[270, {"b": [["11621.60000", "0.49800000", "1596666761.000806"]], "c": "3673485449"}, "book-100", "XBT/USD"]
[270, {"a": [["11667.90000", "0.00000000", "1596666761.008083"], ["11720.10000", "0.02000000", "1596666119.730609", "r"]], "c": "3673485449"}, "book-100", "XBT/USD"]
[270, {"b": [["11654.80000", "0.41277936", "1596666761.028645"]], "c": "2639907033"}, "book-100", "XBT/USD"]
[270, {"a": [["11671.70000", "1.50000000", "1596666761.030028"]], "c": "2639907033"}, "book-100", "XBT/USD"]
[270, {"b": [["11642.20000", "0.00000000", "1596666761.043984"], ["11604.00000", "0.17085000", "1596666711.074347", "r"]], "c": "2639907033"}, "book-100", "XBT/USD"]
[270, {"b": [["11654.80000", "0.87996728", "1596666761.046594"]], "c": "1064389263"}, "book-100", "XBT/USD"]
[270, {"a": [["11668.70000", "0.76758998", "1596666761.047615"]], "c": "1064389263"}, "book-100", "XBT/USD"]
[270, {"b": [["11654.30000", "0.25000000", "1596666761.049940"]], "c": "501022521"}, "book-100", "XBT/USD"]
[270, {"a": [["11665.80000", "0.75551922", "1596666761.057728"]], "c": "501022521"}, "book-100", "XBT/USD"]
[270, {"a": [["11665.80000", "0.00000000", "1596666761.115370"], ["11719.70000", "3.50602221", "1596666743.346655", "r"]], "c": "501022521"}, "book-100", "XBT/USD"]
[270, {"a": [["11669.80000", "0.83225332", "1596666761.131064"]], "c": "501022521"}, "book-100", "XBT/USD"]
[270, {"a": [["11662.80000", "0.01000000", "1596666761.134781"]], "c": "1893801479"}, "book-100", "XBT/USD"]
[270, {"a": [["11665.80000", "0.01036671", "1596666761.136498"]], "c": "1893801479"}, "book-100", "XBT/USD"]
[270, {"a": [["11657.90000", "0.43898194", "1596666761.161487"]], "c": "2598583280"}, "book-100", "XBT/USD"]
[270, {"a": [["11660.50000", "0.41352978", "1596666761.163582"]], "c": "471247443"}, "book-100", "XBT/USD"]
[270, {"a": [["11664.90000", "0.00000000", "1596666761.165327"], ["11718.50000", "24.30000000", "1596666641.380470", "r"]], "c": "471247443"}, "book-100", "XBT/USD"]
[270, {"a": [["11665.80000", "0.76588593", "1596666761.166861"]], "c": "471247443"}, "book-100", "XBT/USD"]
[270, {"a": [["11700.00000", "2.52116603", "1596666761.171667"]], "c": "471247443"}, "book-100", "XBT/USD"]
[270, {"b": [["11654.20000", "1.00064000", "1596666761.173926"]], "c": "858516183"}, "book-100", "XBT/USD"]
[270, {"a": [["11666.70000", "0.10200000", "1596666761.178859"]], "c": "858516183"}, "book-100", "XBT/USD"]
[270, {"b": [["11649.70000", "0.00000000", "1596666761.191764"], ["11604.00000", "0.17085000", "1596666711.074347", "r"]], "c": "858516183"}, "book-100", "XBT/USD"]
[270, {"a": [["11674.40000", "0.10334301", "1596666761.191946"]], "c": "858516183"}, "book-100", "XBT/USD"]
[270, {"a": [["11667.50000", "0.00000000", "1596666761.197386"], ["11717.80000", "1.99812614", "1596666759.535617", "r"]], "c": "858516183"}, "book-100", "XBT/USD"]
[270, {"a": [["11676.70000", "0.72325856", "1596666761.206235"]], "c": "858516183"}, "book-100", "XBT/USD"]
[270, {"a": [["11665.80000", "0.01036671", "1596666761.213873"]], "c": "858516183"}, "book-100", "XBT/USD"]
[270, {"b": [["11637.70000", "0.00000000", "1596666761.218039"], ["11603.60000", "0.75800000", "1596666702.965229", "r"]], "c": "858516183"}, "book-100", "XBT/USD"]
[270, {"a": [["11659.90000", "0.00000000", "1596666761.223035"], ["11717.80000", "1.99812614", "1596666759.535617", "r"]], "c": "323630448"}, "book-100", "XBT/USD"]
[270, {"a": [["11665.80000", "0.00000000", "1596666761.386306"], ["11718.50000", "24.30000000", "1596666641.380470", "r"]], "c": "323630448"}, "book-100", "XBT/USD"]
[270, {"a": [["11660.40000", "0.01037780", "1596666761.387037"]], "c": "1191162892"}, "book-100", "XBT/USD"]
[270, {"a": [["11660.50000", "0.00000000", "1596666761.391678"], ["11718.50000", "24.30000000", "1596666641.380470", "r"]], "c": "1829122582"}, "book-100", "XBT/USD"]
[270, {"b": [["11654.50000", "4.92924789", "1596666761.420495"]], "c": "3404263321"}, "book-100", "XBT/USD"]
[270, {"a": [["11663.10000", "4.28100000", "1596666761.424517"]], "c": "2734605745"}, "book-100", "XBT/USD"]
[270, {"b": [["11649.60000", "0.00000000", "1596666761.438763"], ["11603.10000", "0.00858405", "1596666739.130412", "r"]], "c": "2734605745"}, "book-100", "XBT/USD"]
[270, {"b": [["11634.30000", "0.49882341", "1596666761.461227"]], "c": "2734605745"}, "book-100", "XBT/USD"]
[270, {"a": [["11669.80000", "0.69794735", "1596666761.468876"]], "c": "2734605745"}, "book-100", "XBT/USD"]
[270, {"a": [["11661.00000", "0.41352978", "1596666761.550799"]], "c": "424468086"}, "book-100", "XBT/USD"]
[270, {"a": [["11665.80000", "1.36216045", "1596666761.559052"]], "c": "424468086"}, "book-100", "XBT/USD"]
[270, {"b": [["11652.70000", "0.00000000", "1596666761.577115"], ["11602.80000", "0.75800000", "1596666731.483110", "r"]], "c": "146533163"}, "book-100", "XBT/USD"]
[270, {"a": [["11664.40000", "0.49656912", "1596666761.577832"]], "c": "146533163"}, "book-100", "XBT/USD"]
[270, {"a": [["11669.80000", "0.00000000", "1596666761.631426"], ["11714.50000", "1.06000000", "1596666759.236412", "r"]], "c": "146533163"}, "book-100", "XBT/USD"]
[270, {"a": [["11660.70000", "0.01037753", "1596666761.641931"]], "c": "3169371483"}, "book-100", "XBT/USD"]
[270, {"a": [["11670.30000", "0.13429058", "1596666761.660401"]], "c": "3169371483"}, "book-100", "XBT/USD"]
[270, {"a": [["11662.90000", "0.00000000", "1596666761.676199"], ["11711.20000", "0.89630055", "1596666591.787115", "r"]], "c": "808856231"}, "book-100", "XBT/USD"]
[270, {"a": [["11662.80000", "0.00000000", "1596666761.733686"], ["11714.50000", "1.06000000", "1596666759.236412", "r"]], "c": "1945062266"}, "book-100", "XBT/USD"]
[270, {"b": [["11634.70000", "0.00000000", "1596666761.762373"], ["11602.30000", "2.01774694", "1596666748.156295", "r"]], "c": "1945062266"}, "book-100", "XBT/USD"]
[270, {"b": [["11629.80000", "0.00000000", "1596666761.763012"], ["11602.20000", "2.01681621", "1596666634.588713", "r"]], "c": "1945062266"}, "book-100", "XBT/USD"]
[270, {"a": [["11677.80000", "0.00000000", "1596666761.763455"], ["11715.30000", "6.10000000", "1596666635.445451", "r"]], "c": "1945062266"}, "book-100", "XBT/USD"]
[270, {"a": [["11683.10000", "0.00000000", "1596666761.765347"], ["11717.80000", "1.99812614", "1596666759.535617", "r"]], "c": "1945062266"}, "book-100", "XBT/USD"]
[270, {"b": [["11642.30000", "0.00000000", "1596666761.765804"], ["11602.10000", "7.70000000", "1596666410.902600", "r"]], "c": "1945062266"}, "book-100", "XBT/USD"]
[270, {"a": [["11675.40000", "0.00000000", "1596666761.767248"], ["11718.50000", "24.30000000", "1596666641.380470", "r"]], "c": "1945062266"}, "book-100", "XBT/USD"]
[270, {"b": [["11636.70000", "0.00000000", "1596666761.785104"], ["11602.00000", "1.06000000", "1596666760.274147", "r"]], "c": "1945062266"}, "book-100", "XBT/USD"]
[270, {"b": [["11631.20000", "2.01273345", "1596666761.785250"]], "c": "1945062266"}, "book-100", "XBT/USD"]
[270, {"b": [["11631.20000", "0.00000000", "1596666761.790267"], ["11601.40000", "13.94256021", "1596666708.975741", "r"]], "c": "1945062266"}, "book-100", "XBT/USD"]
[270, {"a": [["11663.00000", "0.01000000", "1596666761.793090"]], "c": "3900947783"}, "book-100", "XBT/USD"]
[270, {"b": [["11636.90000", "0.00000000", "1596666761.793309"], ["11601.00000", "0.17085000", "1596666692.102814", "r"]], "c": "3900947783"}, "book-100", "XBT/USD"]
[270, {"a": [["11684.10000", "0.00000000", "1596666761.798333"], ["11718.50000", "24.30000000", "1596666641.380470", "r"]], "c": "3900947783"}, "book-100", "XBT/USD"]
[270, {"b": [["11631.10000", "0.00000000", "1596666761.799735"], ["11600.10000", "0.05000000", "1596666747.910313", "r"]], "c": "3900947783"}, "book-100", "XBT/USD"]
[270, {"b": [["11638.10000", "0.90208953", "1596666761.813531"]], "c": "3900947783"}, "book-100", "XBT/USD"]
[270, {"b": [["11631.40000", "0.00000000", "1596666761.814885"], ["11600.00000", "0.02931034", "1596666720.289823", "r"]], "c": "3900947783"}, "book-100", "XBT/USD"]
[270, {"a": [["11679.30000", "1.44899666", "1596666761.835616"]], "c": "3900947783"}, "book-100", "XBT/USD"]
[270, {"b": [["11654.80000", "6.12996728", "1596666761.837086"]], "c": "1919047961"}, "book-100", "XBT/USD"]
[270, {"a": [["11676.90000", "0.71052371", "1596666761.837194"]], "c": "1919047961"}, "book-100", "XBT/USD"]
[270, {"a": [["11685.10000", "8.18781368", "1596666761.840264"]], "c": "1919047961"}, "book-100", "XBT/USD"]
[270, {"b": [["11636.20000", "0.00000000", "1596666761.841599"], ["11599.70000", "0.00900000", "1596666739.190302", "r"]], "c": "1919047961"}, "book-100", "XBT/USD"]
[270, {"a": [["11673.60000", "0.33844027", "1596666761.846135"]], "c": "1919047961"}, "book-100", "XBT/USD"]
[270, {"b": [["11638.10000", "0.00000000", "1596666761.854323"], ["11598.60000", "5.85498227", "1596666746.869996", "r"]], "c": "1919047961"}, "book-100", "XBT/USD"]
[270, {"a": [["11661.00000", "0.00000000", "1596666761.883705"], ["11717.80000", "1.99812614", "1596666759.535617", "r"]], "c": "1075439522"}, "book-100", "XBT/USD"]
[270, {"a": [["11669.80000", "0.66571746", "1596666761.883921"]], "c": "1075439522"}, "book-100", "XBT/USD"]
[270, {"b": [["11625.40000", "0.00000000", "1596666761.888211"], ["11598.00000", "0.36375245", "1596666759.447426", "r"]], "c": "1075439522"}, "book-100", "XBT/USD"]
[270, {"b": [["11634.30000", "0.00000000", "1596666761.889601"], ["11596.30000", "19.40000000", "1596666706.107317", "r"]], "c": "1075439522"}, "book-100", "XBT/USD"]
[270, {"b": [["11654.80000", "0.87996728", "1596666761.897377"]], "c": "1263658347"}, "book-100", "XBT/USD"]
[270, {"b": [["11638.40000", "0.35010184", "1596666761.917046"]], "c": "1263658347"}, "book-100", "XBT/USD"]
[270, {"a": [["11679.70000", "0.34886386", "1596666761.918118"]], "c": "1263658347"}, "book-100", "XBT/USD"]
[270, {"b": [["11633.70000", "0.57539967", "1596666761.918317"]], "c": "1263658347"}, "book-100", "XBT/USD"]
[270, {"a": [["11691.40000", "0.89618075", "1596666761.930060"]], "c": "1263658347"}, "book-100", "XBT/USD"]
[270, {"b": [["11641.10000", "2.00000000", "1596666761.935011"]], "c": "1263658347"}, "book-100", "XBT/USD"]
[270, {"b": [["11645.50000", "1.37157442", "1596666761.939637"]], "c": "1263658347"}, "book-100", "XBT/USD"]
[270, {"b": [["11654.80000", "1.27996728", "1596666761.942425"]], "c": "1458511394"}, "book-100", "XBT/USD"]
[270, {"b": [["11654.80000", "0.81277936", "1596666761.942747"]], "c": "966507979"}, "book-100", "XBT/USD"]
[270, {"a": [["11663.10000", "0.00000000", "1596666761.962611"], ["11714.50000", "1.06000000", "1596666759.236412", "r"]], "c": "4060245273"}, "book-100", "XBT/USD"]
[270, {"a": [["11657.90000", "0.00000000", "1596666761.965015"], ["11715.30000", "6.10000000", "1596666635.445451", "r"]], "c": "925467429"}, "book-100", "XBT/USD"]
[270, {"a": [["11671.70000", "0.00000000", "1596666761.970566"], ["11717.80000", "1.99812614", "1596666759.535617", "r"]], "c": "925467429"}, "book-100", "XBT/USD"]
[270, {"a": [["11660.40000", "0.00000000", "1596666761.979303"], ["11718.50000", "24.30000000", "1596666641.380470", "r"]], "c": "652001218"}, "book-100", "XBT/USD"]
[270, {"a": [["11694.10000", "0.00000000", "1596666761.979873"], ["11719.60000", "1.46521891", "1596666747.719598", "r"]], "c": "652001218"}, "book-100", "XBT/USD"]
[270, {"a": [["11701.10000", "20.01796445", "1596666761.981489"]], "c": "652001218"}, "book-100", "XBT/USD"]
[270, {"a": [["11664.10000", "0.09900000", "1596666761.981738"]], "c": "2757601928"}, "book-100", "XBT/USD"]
[270, {"b": [["11601.40000", "0.00000000", "1596666761.981797"], ["11599.70000", "0.00900000", "1596666739.190302", "r"]], "c": "2757601928"}, "book-100", "XBT/USD"]
[270, {"b": [["11639.20000", "0.00000000", "1596666761.989695"], ["11598.60000", "5.85498227", "1596666746.869996", "r"]], "c": "2757601928"}, "book-100", "XBT/USD"]
[270, {"a": [["11670.70000", "0.09800000", "1596666761.990957"]], "c": "2757601928"}, "book-100", "XBT/USD"]
[270, {"b": [["11607.90000", "16.26281554", "1596666762.001665"]], "c": "2757601928"}, "book-100", "XBT/USD"]
[270, {"a": [["11689.50000", "0.00000000", "1596666762.003807"], ["11718.50000", "24.30000000", "1596666641.380470", "r"]], "c": "2757601928"}, "book-100", "XBT/USD"]
[270, {"a": [["11677.60000", "1.39601402", "1596666762.011549"]], "c": "2757601928"}, "book-100", "XBT/USD"]
[270, {"a": [["11670.30000", "0.24691532", "1596666762.011876"]], "c": "2757601928"}, "book-100", "XBT/USD"]
[270, {"a": [["11676.20000", "0.24926317", "1596666762.013209"]], "c": "2757601928"}, "book-100", "XBT/USD"]
[270, {"b": [["11653.90000", "0.42900000", "1596666762.015541"]], "c": "3940186833"}, "book-100", "XBT/USD"]
[270, {"a": [["11663.00000", "0.00000000", "1596666762.017469"], ["11718.50000", "24.30000000", "1596666641.380470", "r"]], "c": "1222279417"}, "book-100", "XBT/USD"]
[270, {"a": [["11679.30000", "0.02824126", "1596666762.020998"]], "c": "1222279417"}, "book-100", "XBT/USD"]
[270, {"a": [["11676.90000", "0.00000000", "1596666762.029066"], ["11719.60000", "1.46521891", "1596666747.719598", "r"]], "c": "1222279417"}, "book-100", "XBT/USD"]
[270, {"a": [["11673.60000", "0.00000000", "1596666762.031002"], ["11719.70000", "3.50602221", "1596666743.346655", "r"]], "c": "1222279417"}, "book-100", "XBT/USD"]
[270, {"b": [["11603.60000", "0.00000000", "1596666762.032350"], ["11598.60000", "5.85498227", "1596666746.869996", "r"]], "c": "1222279417"}, "book-100", "XBT/USD"]
[270, {"b": [["11640.70000", "0.85980259", "1596666762.049191"]], "c": "1222279417"}, "book-100", "XBT/USD"]
[270, {"b": [["11646.70000", "0.33922195", "1596666762.067624"]], "c": "1222279417"}, "book-100", "XBT/USD"]
[270, {"b": [["11641.00000", "1.80542982", "1596666762.071147"]], "c": "1222279417"}, "book-100", "XBT/USD"]
[270, {"b": [["11654.60000", "1.11794876", "1596666762.072002"]], "c": "288805288"}, "book-100", "XBT/USD"]
[270, {"a": [["11663.80000", "0.01000000", "1596666762.074791"]], "c": "591259340"}, "book-100", "XBT/USD"]
[270, {"b": [["11636.80000", "0.00000000", "1596666762.091534"], ["11598.60000", "5.85498227", "1596666746.869996", "r"]], "c": "591259340"}, "book-100", "XBT/USD"]
[270, {"a": [["11669.80000", "0.00000000", "1596666762.142111"], ["11719.70000", "3.50602221", "1596666743.346655", "r"]], "c": "591259340"}, "book-100", "XBT/USD"]
[270, {"a": [["11693.70000", "1.16987239", "1596666762.150969"]], "c": "591259340"}, "book-100", "XBT/USD"]
[270, {"b": [["11641.80000", "0.24999971", "1596666762.163429"]], "c": "591259340"}, "book-100", "XBT/USD"]
[270, {"a": [["11699.70000", "0.55961699", "1596666762.210449"]], "c": "591259340"}, "book-100", "XBT/USD"]
[270, {"b": [["11640.00000", "7.10000000", "1596666762.219408"]], "c": "591259340"}, "book-100", "XBT/USD"]
[270, {"a": [["11663.80000", "4.28900000", "1596666762.223273"]], "c": "1376871437"}, "book-100", "XBT/USD"]
[270, {"a": [["11659.40000", "0.41872140", "1596666762.224506"]], "c": "1011889215"}, "book-100", "XBT/USD"]
[270, {"a": [["11671.10000", "0.33851276", "1596666762.264930"]], "c": "1011889215"}, "book-100", "XBT/USD"]
[270, {"a": [["11685.10000", "6.39584557", "1596666762.274114"]], "c": "1011889215"}, "book-100", "XBT/USD"]
[270, {"a": [["11676.80000", "1.42105959", "1596666762.278181"]], "c": "1011889215"}, "book-100", "XBT/USD"]
[270, {"a": [["11709.60000", "0.00000000", "1596666762.283870"], ["11717.80000", "1.99812614", "1596666759.535617", "r"]], "c": "1011889215"}, "book-100", "XBT/USD"]
[270, {"b": [["11643.00000", "0.10362171", "1596666762.317711"]], "c": "1011889215"}, "book-100", "XBT/USD"]
[270, {"b": [["11638.80000", "0.49863259", "1596666762.343924"]], "c": "1011889215"}, "book-100", "XBT/USD"]
[270, {"a": [["11662.70000", "0.25853138", "1596666762.344296"]], "c": "1124124361"}, "book-100", "XBT/USD"]
[270, {"a": [["11661.10000", "0.41352978", "1596666762.361023"]], "c": "4014966694"}, "book-100", "XBT/USD"]
[270, {"a": [["11674.50000", "0.71066978", "1596666762.369744"]], "c": "4014966694"}, "book-100", "XBT/USD"]
[270, {"a": [["11671.30000", "0.65805229", "1596666762.381600"]], "c": "4014966694"}, "book-100", "XBT/USD"]
[270, {"a": [["11683.90000", "3.53060956", "1596666762.464695"]], "c": "4014966694"}, "book-100", "XBT/USD"]
[270, {"a": [["11678.10000", "3.53236306", "1596666762.506417"]], "c": "4014966694"}, "book-100", "XBT/USD"]
[270, {"b": [["11645.50000", "0.00000000", "1596666762.517951"], ["11600.00000", "0.02931034", "1596666720.289823", "r"]], "c": "4014966694"}, "book-100", "XBT/USD"]
[270, {"b": [["11654.80000", "1.30216414", "1596666762.576613"]], "c": "1463994275"}, "book-100", "XBT/USD"]
[270, {"b": [["11634.90000", "1.21321807", "1596666762.598235"]], "c": "1463994275"}, "book-100", "XBT/USD"]
[270, {"a": [["11667.40000", "0.00000000", "1596666762.606456"], ["11711.00000", "3.52207482", "1596666594.088624", "r"]], "c": "1463994275"}, "book-100", "XBT/USD"]
[270, {"b": [["11654.80000", "1.80216414", "1596666762.607684"]], "c": "668582919"}, "book-100", "XBT/USD"]
[270, {"a": [["11662.80000", "1.50000000", "1596666762.611294"]], "c": "1661847196"}, "book-100", "XBT/USD"]
[270, {"a": [["11669.90000", "0.00000000", "1596666762.614527"], ["11711.00000", "3.52207482", "1596666594.088624", "r"]], "c": "1661847196"}, "book-100", "XBT/USD"]
[270, {"a": [["11663.80000", "4.27900000", "1596666762.666156"]], "c": "2425095825"}, "book-100", "XBT/USD"]
[270, {"b": [["11640.20000", "3.54386428", "1596666762.672398"]], "c": "2425095825"}, "book-100", "XBT/USD"]
[270, {"b": [["11654.30000", "0.00000000", "1596666762.706013"], ["11600.10000", "0.05000000", "1596666747.910313", "r"]], "c": "3907748298"}, "book-100", "XBT/USD"]
[270, {"a": [["11674.50000", "0.00000000", "1596666762.731521"], ["11711.10000", "2.97327583", "1596666728.385477", "r"]], "c": "3907748298"}, "book-100", "XBT/USD"]
[270, {"a": [["11662.60000", "0.01000000", "1596666762.735609"]], "c": "4213874565"}, "book-100", "XBT/USD"]
[270, {"b": [["11641.10000", "0.00000000", "1596666762.805085"], ["11600.00000", "0.02931034", "1596666720.289823", "r"]], "c": "4213874565"}, "book-100", "XBT/USD"]
[270, {"b": [["11654.60000", "0.64324789", "1596666762.808499"]], "c": "68348924"}, "book-100", "XBT/USD"]
[270, {"b": [["11630.10000", "8.60000000", "1596666762.827574"]], "c": "68348924"}, "book-100", "XBT/USD"]
[270, {"b": [["11643.30000", "0.71257412", "1596666762.838437"]], "c": "68348924"}, "book-100", "XBT/USD"]
[270, {"b": [["11628.70000", "2.08000000", "1596666762.840692"]], "c": "68348924"}, "book-100", "XBT/USD"]
[270, {"b": [["11653.70000", "0.25000000", "1596666762.924637"]], "c": "386838349"}, "book-100", "XBT/USD"]
[270, {"a": [["11705.60000", "0.43900000", "1596666762.985179"]], "c": "386838349"}, "book-100", "XBT/USD"]
[270, {"a": [["11662.80000", "0.00000000", "1596666763.045518"], ["11711.00000", "3.52207482", "1596666594.088624", "r"]], "c": "782182533"}, "book-100", "XBT/USD"]
[270, {"b": [["11651.30000", "1.37151601", "1596666763.061108"]], "c": "782182533"}, "book-100", "XBT/USD"]
[270, {"a": [["11663.80000", "0.00000000", "1596666763.064574"], ["11711.10000", "2.97327583", "1596666728.385477", "r"]], "c": "1712430783"}, "book-100", "XBT/USD"]
[270, {"a": [["11661.10000", "0.00000000", "1596666763.116437"], ["11711.20000", "0.89630055", "1596666591.787115", "r"]], "c": "1450800549"}, "book-100", "XBT/USD"]
[270, {"b": [["11604.10000", "1.51500000", "1596666763.121463"]], "c": "1450800549"}, "book-100", "XBT/USD"]
[270, {"a": [["11661.80000", "4.28400000", "1596666763.153837"]], "c": "2165770919"}, "book-100", "XBT/USD"]
[270, {"a": [["11662.60000", "0.00000000", "1596666763.157282"], ["11711.20000", "0.89630055", "1596666591.787115", "r"]], "c": "1007604485"}, "book-100", "XBT/USD"]
[270, {"b": [["11653.70000", "0.00000000", "1596666763.175502"], ["11602.10000", "7.70000000", "1596666410.902600", "r"]], "c": "3987242275"}, "book-100", "XBT/USD"]
[270, {"b": [["11654.80000", "1.31277936", "1596666763.225090"]], "c": "832308049"}, "book-100", "XBT/USD"]
[270, {"b": [["11650.90000", "0.00000000", "1596666763.250220"], ["11602.00000", "1.06000000", "1596666760.274147", "r"]], "c": "832308049"}, "book-100", "XBT/USD"]
[270, {"b": [["11650.70000", "0.00000000", "1596666763.267052"], ["11601.00000", "0.17085000", "1596666692.102814", "r"]], "c": "832308049"}, "book-100", "XBT/USD"]
[270, {"a": [["11667.10000", "0.64316890", "1596666763.287753"]], "c": "832308049"}, "book-100", "XBT/USD"]
[270, {"a": [["11660.80000", "0.00000000", "1596666763.293772"], ["11711.20000", "0.89630055", "1596666591.787115", "r"]], "c": "2280891752"}, "book-100", "XBT/USD"]
[270, {"b": [["11652.90000", "0.76946633", "1596666763.299494"]], "c": "3041581509"}, "book-100", "XBT/USD"]
[270, {"a": [["11683.80000", "0.59681610", "1596666763.316869"]], "c": "3041581509"}, "book-100", "XBT/USD"]
[270, {"a": [["11665.60000", "0.64316890", "1596666763.370953"]], "c": "3041581509"}, "book-100", "XBT/USD"]
[270, {"a": [["11663.60000", "0.01000000", "1596666763.426530"]], "c": "4182240329"}, "book-100", "XBT/USD"]
[270, {"b": [["11635.10000", "10.51227158", "1596666763.474164"]], "c": "4182240329"}, "book-100", "XBT/USD"]
[270, {"a": [["11670.30000", "0.11262474", "1596666763.487079"]], "c": "4182240329"}, "book-100", "XBT/USD"]
[270, {"a": [["11671.10000", "0.00000000", "1596666763.487329"], ["11711.00000", "3.52207482", "1596666594.088624", "r"]], "c": "4182240329"}, "book-100", "XBT/USD"]
[270, {"a": [["11681.10000", "3.19962170", "1596666763.489197"]], "c": "4182240329"}, "book-100", "XBT/USD"]
[270, {"a": [["11664.40000", "1.13977869", "1596666763.489671"]], "c": "4182240329"}, "book-100", "XBT/USD"]
[270, {"b": [["11654.50000", "5.17924789", "1596666763.491164"]], "c": "2734779537"}, "book-100", "XBT/USD"]
[270, {"a": [["11669.30000", "0.47798387", "1596666763.491617"]], "c": "2734779537"}, "book-100", "XBT/USD"]
[270, {"b": [["11651.20000", "0.00000000", "1596666763.492720"], ["11600.10000", "0.05000000", "1596666747.910313", "r"]], "c": "2734779537"}, "book-100", "XBT/USD"]
[270, {"a": [["11670.90000", "6.47668707", "1596666763.493104"]], "c": "2734779537"}, "book-100", "XBT/USD"]
[270, {"a": [["11665.80000", "0.00000000", "1596666763.493190"], ["11710.70000", "3.52183532", "1596666711.393054", "r"]], "c": "2734779537"}, "book-100", "XBT/USD"]
[270, {"a": [["11666.00000", "0.00000000", "1596666763.493943"], ["11711.00000", "3.52207482", "1596666594.088624", "r"]], "c": "2734779537"}, "book-100", "XBT/USD"]
[270, {"b": [["11654.40000", "0.00453416", "1596666763.496054"]], "c": "1767504285"}, "book-100", "XBT/USD"]
[270, {"a": [["11670.30000", "2.11262474", "1596666763.500633"]], "c": "1767504285"}, "book-100", "XBT/USD"]
[270, {"a": [["11661.70000", "0.02136413", "1596666763.501166"]], "c": "100439943"}, "book-100", "XBT/USD"]
[270, {"a": [["11691.70000", "0.89813678", "1596666763.502616"]], "c": "100439943"}, "book-100", "XBT/USD"]
[270, {"b": [["11606.40000", "0.00000000", "1596666763.503157"], ["11600.10000", "0.05000000", "1596666747.910313", "r"]], "c": "100439943"}, "book-100", "XBT/USD"]
[270, {"a": [["11660.70000", "0.00000000", "1596666763.507322"], ["11710.70000", "3.52183532", "1596666711.393054", "r"]], "c": "3226127895"}, "book-100", "XBT/USD"]
[270, {"b": [["11653.00000", "0.04250000", "1596666763.518380"]], "c": "100708468"}, "book-100", "XBT/USD"]
[270, {"a": [["11666.10000", "0.00000000", "1596666763.519286"], ["11711.00000", "3.52207482", "1596666594.088624", "r"]], "c": "100708468"}, "book-100", "XBT/USD"]
[270, {"a": [["11678.20000", "0.85755853", "1596666763.521362"]], "c": "100708468"}, "book-100", "XBT/USD"]
[270, {"a": [["11662.60000", "0.04051069", "1596666763.528870"]], "c": "233431915"}, "book-100", "XBT/USD"]
[270, {"b": [["11651.30000", "0.00000000", "1596666763.537887"], ["11600.10000", "0.05000000", "1596666747.910313", "r"]], "c": "233431915"}, "book-100", "XBT/USD"]
[270, {"a": [["11663.60000", "0.00000000", "1596666763.581923"], ["11710.70000", "3.52183532", "1596666711.393054", "r"]], "c": "860902622"}, "book-100", "XBT/USD"]
[270, {"a": [["11663.80000", "0.01000000", "1596666763.632005"]], "c": "1521584006"}, "book-100", "XBT/USD"]
[270, {"a": [["11671.30000", "0.00000000", "1596666763.639784"], ["11710.70000", "3.52183532", "1596666711.393054", "r"]], "c": "1521584006"}, "book-100", "XBT/USD"]
[270, {"b": [["11653.00000", "0.00000000", "1596666763.652515"], ["11600.00000", "0.02931034", "1596666720.289823", "r"]], "c": "2477124624"}, "book-100", "XBT/USD"]
[270, {"a": [["11669.20000", "0.00000000", "1596666763.670525"], ["11711.00000", "3.52207482", "1596666594.088624", "r"]], "c": "2477124624"}, "book-100", "XBT/USD"]
[270, {"a": [["11659.40000", "0.00000000", "1596666763.674209"], ["11711.10000", "2.97327583", "1596666728.385477", "r"]], "c": "2817128160"}, "book-100", "XBT/USD"]
[270, {"a": [["11662.60000", "0.00000000", "1596666763.681251"], ["11711.20000", "0.89630055", "1596666591.787115", "r"]], "c": "301892278"}, "book-100", "XBT/USD"]
[270, {"a": [["11670.90000", "5.72691333", "1596666763.734905"]], "c": "301892278"}, "book-100", "XBT/USD"]
[270, {"a": [["11674.00000", "0.75270298", "1596666763.738539"]], "c": "301892278"}, "book-100", "XBT/USD"]
[270, {"b": [["11629.90000", "2.01368088", "1596666763.761685"]], "c": "301892278"}, "book-100", "XBT/USD"]
[270, {"b": [["11635.70000", "2.01267713", "1596666763.763590"]], "c": "301892278"}, "book-100", "XBT/USD"]
[270, {"a": [["11665.50000", "0.04051069", "1596666763.836533"]], "c": "301892278"}, "book-100", "XBT/USD"]
[270, {"a": [["11671.70000", "0.71215670", "1596666763.893746"]], "c": "301892278"}, "book-100", "XBT/USD"]
[270, {"a": [["11661.40000", "0.41543364", "1596666763.906815"]], "c": "2269477312"}, "book-100", "XBT/USD"]
[270, {"b": [["11639.40000", "0.00000000", "1596666763.911693"], ["11600.10000", "0.05000000", "1596666747.910313", "r"]], "c": "2269477312"}, "book-100", "XBT/USD"]
[270, {"b": [["11648.50000", "0.43900000", "1596666763.923260"]], "c": "2269477312"}, "book-100", "XBT/USD"]
[270, {"a": [["11672.00000", "1.26817635", "1596666763.970045"]], "c": "2269477312"}, "book-100", "XBT/USD"]
[270, {"b": [["11635.20000", "1.79965334", "1596666764.013374"]], "c": "2269477312"}, "book-100", "XBT/USD"]
[270, {"a": [["11699.70000", "3.43961699", "1596666764.043025"]], "c": "2269477312"}, "book-100", "XBT/USD"]
[270, {"a": [["11677.00000", "0.85761277", "1596666764.098007"]], "c": "2269477312"}, "book-100", "XBT/USD"]
[270, {"b": [["11642.60000", "0.90192446", "1596666764.099596"]], "c": "2269477312"}, "book-100", "XBT/USD"]
[270, {"b": [["11607.80000", "0.74977374", "1596666764.099854"]], "c": "2269477312"}, "book-100", "XBT/USD"]
[270, {"a": [["11662.20000", "0.41352978", "1596666764.105931"]], "c": "770824401"}, "book-100", "XBT/USD"]
[270, {"a": [["11663.20000", "1.50000000", "1596666764.107258"]], "c": "988957956"}, "book-100", "XBT/USD"]
[270, {"b": [["11653.30000", "1.39086192", "1596666764.111537"]], "c": "3229002747"}, "book-100", "XBT/USD"]
[270, {"a": [["11676.50000", "0.89930593", "1596666764.112098"]], "c": "3229002747"}, "book-100", "XBT/USD"]
[270, {"b": [["11639.10000", "0.90219568", "1596666764.113226"]], "c": "3229002747"}, "book-100", "XBT/USD"]
[270, {"a": [["11654.90000", "0.00000000", "1596666764.122293"], ["11705.30000", "1.51500000", "1596666759.981994", "r"]], "c": "1402434292"}, "book-100", "XBT/USD"]
[270, {"a": [["11672.00000", "0.00000000", "1596666764.133344"], ["11705.60000", "0.43900000", "1596666762.985179", "r"]], "c": "1402434292"}, "book-100", "XBT/USD"]
[270, {"a": [["11663.80000", "0.00000000", "1596666764.171078"], ["11706.80000", "3.00107058", "1596666756.974795", "r"]], "c": "2518069840"}, "book-100", "XBT/USD"]
[270, {"b": [["11654.90000", "0.50000000", "1596666764.179627"]], "c": "227022408"}, "book-100", "XBT/USD"]
[270, {"b": [["11654.80000", "0.81277936", "1596666764.231376"]], "c": "2781790030"}, "book-100", "XBT/USD"]
[270, {"b": [["11654.90000", "5.75000000", "1596666764.257815"]], "c": "1188309468"}, "book-100", "XBT/USD"]
[270, {"b": [["11654.90000", "6.05000000", "1596666764.263596"]], "c": "1128338595"}, "book-100", "XBT/USD"]
[270, {"a": [["11669.30000", "0.00000000", "1596666764.287118"], ["11709.70000", "7.20507863", "1596666620.257365", "r"]], "c": "1128338595"}, "book-100", "XBT/USD"]
[270, {"a": [["11693.80000", "7.07045583", "1596666764.303729"]], "c": "1128338595"}, "book-100", "XBT/USD"]
[270, {"a": [["11682.10000", "7.07753712", "1596666764.303933"]], "c": "1128338595"}, "book-100", "XBT/USD"]
[270, {"b": [["11636.60000", "7.10521084", "1596666764.314901"]], "c": "1128338595"}, "book-100", "XBT/USD"]
[270, {"a": [["11663.10000", "0.01000000", "1596666764.383980"]], "c": "285250171"}, "book-100", "XBT/USD"]
[270, {"a": [["11662.70000", "0.00000000", "1596666764.404483"], ["11705.60000", "0.43900000", "1596666762.985179", "r"]], "c": "992857700"}, "book-100", "XBT/USD"]
[270, {"b": [["11645.00000", "0.00000000", "1596666764.420429"], ["11603.10000", "0.00858405", "1596666739.130412", "r"]], "c": "992857700"}, "book-100", "XBT/USD"]
[270, {"a": [["11664.40000", "0.49656912", "1596666764.421093"]], "c": "992857700"}, "book-100", "XBT/USD"]
[270, {"b": [["11654.50000", "4.92924789", "1596666764.421884"]], "c": "1452564104"}, "book-100", "XBT/USD"]
[270, {"a": [["11667.30000", "0.00000000", "1596666764.425041"], ["11706.80000", "3.00107058", "1596666756.974795", "r"]], "c": "1452564104"}, "book-100", "XBT/USD"]
[270, {"a": [["11662.20000", "0.00000000", "1596666764.432866"], ["11709.70000", "7.20507863", "1596666620.257365", "r"]], "c": "1801784017"}, "book-100", "XBT/USD"]
[270, {"a": [["11667.20000", "0.00000000", "1596666764.439655"], ["11710.70000", "3.52183532", "1596666711.393054", "r"]], "c": "1801784017"}, "book-100", "XBT/USD"]
[270, {"b": [["11650.00000", "9.99987003", "1596666764.461380"]], "c": "1801784017"}, "book-100", "XBT/USD"]
[270, {"a": [["11668.60000", "1.36280926", "1596666764.473448"]], "c": "1801784017"}, "book-100", "XBT/USD"]
[270, {"b": [["11654.90000", "0.80000000", "1596666764.484834"]], "c": "3886183029"}, "book-100", "XBT/USD"]
[270, {"b": [["11646.80000", "0.00000000", "1596666764.486240"], ["11603.10000", "0.00858405", "1596666739.130412", "r"]], "c": "3886183029"}, "book-100", "XBT/USD"]
[270, {"a": [["11663.00000", "0.25852151", "1596666764.502271"]], "c": "766118906"}, "book-100", "XBT/USD"]
[270, {"b": [["11637.10000", "0.00000000", "1596666764.559786"], ["11602.80000", "0.75800000", "1596666731.483110", "r"]], "c": "766118906"}, "book-100", "XBT/USD"]
[270, {"b": [["11650.00000", "0.00000000", "1596666764.565756"], ["11602.30000", "2.01774694", "1596666748.156295", "r"]], "c": "766118906"}, "book-100", "XBT/USD"]
[270, {"a": [["11663.10000", "0.42352978", "1596666764.582084"]], "c": "2580130407"}, "book-100", "XBT/USD"]
[270, {"a": [["11668.70000", "0.46758998", "1596666764.586613"]], "c": "2580130407"}, "book-100", "XBT/USD"]
[270, {"b": [["11610.80000", "0.00000000", "1596666764.587656"], ["11602.20000", "2.01681621", "1596666634.588713", "r"]], "c": "2580130407"}, "book-100", "XBT/USD"]
[270, {"a": [["11683.20000", "0.00000000", "1596666764.601829"], ["11709.70000", "7.20507863", "1596666620.257365", "r"]], "c": "2580130407"}, "book-100", "XBT/USD"]
[270, {"a": [["11665.50000", "0.13672163", "1596666764.616226"]], "c": "2580130407"}, "book-100", "XBT/USD"]
[270, {"b": [["11654.90000", "1.05000000", "1596666764.618820"]], "c": "3955249767"}, "book-100", "XBT/USD"]
[270, {"b": [["11641.10000", "0.03100000", "1596666764.628701"]], "c": "3955249767"}, "book-100", "XBT/USD"]
[270, {"a": [["11671.70000", "0.00000000", "1596666764.644839"], ["11710.70000", "3.52183532", "1596666711.393054", "r"]], "c": "3955249767"}, "book-100", "XBT/USD"]
[270, {"b": [["11654.20000", "1.09685094", "1596666764.649389"]], "c": "3409594278"}, "book-100", "XBT/USD"]
[270, {"a": [["11672.10000", "0.00000000", "1596666764.665974"], ["11711.00000", "3.52207482", "1596666594.088624", "r"]], "c": "3409594278"}, "book-100", "XBT/USD"]
[270, {"a": [["11693.00000", "1.11290000", "1596666764.687033"]], "c": "3409594278"}, "book-100", "XBT/USD"]
[270, {"a": [["11678.70000", "6.53385953", "1596666764.746827"]], "c": "3409594278"}, "book-100", "XBT/USD"]
[270, {"b": [["11651.00000", "10.53917003", "1596666764.782393"]], "c": "3409594278"}, "book-100", "XBT/USD"]
[270, {"a": [["11661.80000", "0.00000000", "1596666764.825734"], ["11711.00000", "3.52207482", "1596666594.088624", "r"]], "c": "259652474"}, "book-100", "XBT/USD"]
[270, {"a": [["11663.10000", "0.01000000", "1596666764.879288"]], "c": "2306407480"}, "book-100", "XBT/USD"]
[270, {"a": [["11672.20000", "0.68680312", "1596666764.891380"]], "c": "2306407480"}, "book-100", "XBT/USD"]
[270, {"b": [["11654.50000", "4.28600000", "1596666764.948754"]], "c": "91143923"}, "book-100", "XBT/USD"]
[270, {"a": [["11701.00000", "0.75800000", "1596666764.966093"]], "c": "91143923"}, "book-100", "XBT/USD"]
[270, {"a": [["11690.30000", "0.00000000", "1596666764.966207"], ["11710.70000", "3.52183532", "1596666711.393054", "r"]], "c": "91143923"}, "book-100", "XBT/USD"]
[270, {"a": [["11662.50000", "0.41352978", "1596666765.015248"]], "c": "3995856862"}, "book-100", "XBT/USD"]
[270, {"b": [["11633.30000", "0.05292056", "1596666765.053869"]], "c": "3995856862"}, "book-100", "XBT/USD"]
[270, {"a": [["11698.70000", "0.30000000", "1596666765.082128"]], "c": "3995856862"}, "book-100", "XBT/USD"]
[270, {"b": [["11654.70000", "3.71124789", "1596666765.149455"]], "c": "436553848"}, "book-100", "XBT/USD"]
[270, {"a": [["11664.00000", "5.50384819", "1596666765.417591"]], "c": "3553156322"}, "book-100", "XBT/USD"]
[270, {"b": [["11654.90000", "1.13580045", "1596666765.603492"]], "c": "1853136682"}, "book-100", "XBT/USD"]
[270, {"b": [["11619.30000", "5.95037875", "1596666765.610895"]], "c": "1853136682"}, "book-100", "XBT/USD"]
[270, {"a": [["11663.10000", "0.00000000", "1596666765.624190"], ["11709.70000", "7.20507863", "1596666620.257365", "r"]], "c": "979473024"}, "book-100", "XBT/USD"]
[270, {"b": [["11654.90000", "2.13580045", "1596666765.626864"]], "c": "2174749304"}, "book-100", "XBT/USD"]
[270, {"a": [["11701.10000", "0.01796445", "1596666765.631617"]], "c": "2174749304"}, "book-100", "XBT/USD"]
[270, {"a": [["11668.00000", "0.01000000", "1596666765.675473"]], "c": "2174749304"}, "book-100", "XBT/USD"]
[270, {"a": [["11668.60000", "0.00000000", "1596666765.688006"], ["11709.70000", "7.20507863", "1596666620.257365", "r"]], "c": "2174749304"}, "book-100", "XBT/USD"]
[270, {"b": [["11654.70000", "3.61124789", "1596666765.761011"]], "c": "1972284894"}, "book-100", "XBT/USD"]
[270, {"b": [["11628.70000", "0.00000000", "1596666765.820631"], ["11602.80000", "0.75800000", "1596666731.483110", "r"]], "c": "1972284894"}, "book-100", "XBT/USD"]
[270, {"b": [["11607.90000", "2.32806266", "1596666765.851930"]], "c": "1972284894"}, "book-100", "XBT/USD"]
[270, {"a": [["11672.90000", "1.37777300", "1596666766.007028"]], "c": "1972284894"}, "book-100", "XBT/USD"]
[270, {"b": [["11625.00000", "0.42085000", "1596666766.042737"]], "c": "1972284894"}, "book-100", "XBT/USD"]
[270, {"b": [["11654.90000", "2.23580045", "1596666766.049727"]], "c": "3209778795"}, "book-100", "XBT/USD"]
[270, {"b": [["11654.70000", "3.68584629", "1596666766.074419"]], "c": "1249604503"}, "book-100", "XBT/USD"]
[270, {"a": [["11668.10000", "0.51491968", "1596666766.076608"]], "c": "1249604503"}, "book-100", "XBT/USD"]
[270, {"b": [["11644.10000", "0.00000000", "1596666766.077100"], ["11602.30000", "2.01774694", "1596666748.156295", "r"]], "c": "1249604503"}, "book-100", "XBT/USD"]
[270, {"b": [["11643.00000", "0.00000000", "1596666766.080232"], ["11602.20000", "2.01681621", "1596666634.588713", "r"]], "c": "1249604503"}, "book-100", "XBT/USD"]
[270, {"b": [["11654.70000", "3.70076597", "1596666766.082774"]], "c": "452594658"}, "book-100", "XBT/USD"]
[270, {"b": [["11646.70000", "0.00000000", "1596666766.103005"], ["11602.10000", "7.70000000", "1596666410.902600", "r"]], "c": "452594658"}, "book-100", "XBT/USD"]
[270, {"b": [["11643.30000", "0.00000000", "1596666766.113158"], ["11602.00000", "1.06000000", "1596666760.274147", "r"]], "c": "452594658"}, "book-100", "XBT/USD"]
[270, {"a": [["11663.20000", "0.00000000", "1596666766.114510"], ["11709.70000", "7.20507863", "1596666620.257365", "r"]], "c": "2305233116"}, "book-100", "XBT/USD"]
[270, {"a": [["11668.70000", "0.54218830", "1596666766.134678"]], "c": "2305233116"}, "book-100", "XBT/USD"]
[270, {"b": [["11643.20000", "0.17903596", "1596666766.152199"]], "c": "2305233116"}, "book-100", "XBT/USD"]
[270, {"b": [["11637.00000", "0.00000000", "1596666766.177627"], ["11602.00000", "1.06000000", "1596666760.274147", "r"]], "c": "2305233116"}, "book-100", "XBT/USD"]
[270, {"b": [["11640.30000", "0.04224267", "1596666766.187384"]], "c": "2305233116"}, "book-100", "XBT/USD"]
[270, {"a": [["11671.00000", "0.17903472", "1596666766.193977"]], "c": "2305233116"}, "book-100", "XBT/USD"]
[270, {"a": [["11668.70000", "0.07459832", "1596666766.199618"]], "c": "2305233116"}, "book-100", "XBT/USD"]
[270, {"a": [["11664.80000", "1.50000000", "1596666766.266017"]], "c": "2305233116"}, "book-100", "XBT/USD"]
[270, {"b": [["11634.00000", "0.00000000", "1596666766.339835"], ["11602.00000", "1.06000000", "1596666760.274147", "r"]], "c": "2305233116"}, "book-100", "XBT/USD"]
[270, {"b": [["11642.90000", "0.92800000", "1596666766.352589"]], "c": "2305233116"}, "book-100", "XBT/USD"]
[270, {"b": [["11644.30000", "2.00000000", "1596666766.357890"]], "c": "2305233116"}, "book-100", "XBT/USD"]
[270, {"b": [["11635.30000", "0.00000000", "1596666766.388492"], ["11602.10000", "7.70000000", "1596666410.902600", "r"]], "c": "2305233116"}, "book-100", "XBT/USD"]
[270, {"b": [["11640.60000", "1.04430000", "1596666766.388649"]], "c": "2305233116"}, "book-100", "XBT/USD"]
[270, {"b": [["11624.70000", "10.60000000", "1596666766.391904"]], "c": "2305233116"}, "book-100", "XBT/USD"]
[270, {"a": [["11665.60000", "0.00000000", "1596666766.395632"], ["11706.80000", "3.00107058", "1596666756.974795", "r"]], "c": "2305233116"}, "book-100", "XBT/USD"]
[270, {"a": [["11669.60000", "0.64300800", "1596666766.453021"]], "c": "2305233116"}, "book-100", "XBT/USD"]
[270, {"a": [["11680.90000", "0.85746341", "1596666766.454036"]], "c": "2305233116"}, "book-100", "XBT/USD"]
[270, {"b": [["11654.50000", "5.14346341", "1596666766.454181"]], "c": "1932277689"}, "book-100", "XBT/USD"]
[270, {"b": [["11654.80000", "1.67024277", "1596666766.454312"]], "c": "3413426600"}, "book-100", "XBT/USD"]
[270, {"a": [["11680.80000", "0.85746341", "1596666766.454507"]], "c": "3413426600"}, "book-100", "XBT/USD"]
[270, {"b": [["11654.90000", "2.87886281", "1596666766.496112"]], "c": "979604535"}, "book-100", "XBT/USD"]
[270, {"a": [["11668.00000", "0.65309756", "1596666766.496690"]], "c": "979604535"}, "book-100", "XBT/USD"]
[270, {"b": [["11654.40000", "0.00000000", "1596666766.496751"], ["11602.20000", "2.01681621", "1596666634.588713", "r"]], "c": "835274874"}, "book-100", "XBT/USD"]
[270, {"a": [["11673.10000", "0.44997136", "1596666766.505851"]], "c": "835274874"}, "book-100", "XBT/USD"]
[270, {"a": [["11670.40000", "0.00000000", "1596666766.514813"], ["11705.20000", "0.75800000", "1596666760.546082", "r"]], "c": "835274874"}, "book-100", "XBT/USD"]
[270, {"a": [["11675.70000", "1.00180000", "1596666766.521506"]], "c": "835274874"}, "book-100", "XBT/USD"]
[270, {"b": [["11642.70000", "0.10366403", "1596666766.575901"]], "c": "835274874"}, "book-100", "XBT/USD"]
[270, {"a": [["11670.30000", "2.00000000", "1596666766.578630"]], "c": "835274874"}, "book-100", "XBT/USD"]
[270, {"a": [["11678.60000", "0.00000000", "1596666766.669597"], ["11705.20000", "0.75800000", "1596666760.546082", "r"]], "c": "835274874"}, "book-100", "XBT/USD"]
[270, {"a": [["11663.00000", "0.00000000", "1596666766.674081"], ["11705.30000", "1.51500000", "1596666759.981994", "r"]], "c": "494172644"}, "book-100", "XBT/USD"]
[270, {"b": [["11653.30000", "0.00000000", "1596666766.685238"], ["11602.20000", "2.01681621", "1596666634.588713", "r"]], "c": "895261547"}, "book-100", "XBT/USD"]
[270, {"b": [["11654.90000", "2.62886281", "1596666766.705502"]], "c": "1575222557"}, "book-100", "XBT/USD"]
[270, {"a": [["11671.80000", "0.11270034", "1596666766.745332"]], "c": "1575222557"}, "book-100", "XBT/USD"]
[270, {"b": [["11639.80000", "0.00000000", "1596666766.830655"], ["11602.10000", "7.70000000", "1596666410.902600", "r"]], "c": "1575222557"}, "book-100", "XBT/USD"]
[270, {"a": [["11663.80000", "0.25849429", "1596666766.833428"]], "c": "3076120747"}, "book-100", "XBT/USD"]
[270, {"b": [["11654.70000", "0.73276597", "1596666767.037827"]], "c": "2540973621"}, "book-100", "XBT/USD"]
[270, {"b": [["11654.80000", "2.96334682", "1596666767.048705"]], "c": "2218784987"}, "book-100", "XBT/USD"]
[270, {"a": [["11665.50000", "0.04051069", "1596666767.205890"]], "c": "2218784987"}, "book-100", "XBT/USD"]
[270, {"b": [["11644.90000", "0.33930012", "1596666767.249925"]], "c": "2218784987"}, "book-100", "XBT/USD"]
[270, {"b": [["11641.50000", "0.71273835", "1596666767.250296"]], "c": "2218784987"}, "book-100", "XBT/USD"]
[270, {"a": [["11675.90000", "0.71063845", "1596666767.258703"]], "c": "2218784987"}, "book-100", "XBT/USD"]
[270, {"a": [["11672.50000", "0.33849783", "1596666767.263381"]], "c": "2218784987"}, "book-100", "XBT/USD"]
[270, {"a": [["11684.00000", "1.79227272", "1596666767.265790"]], "c": "2218784987"}, "book-100", "XBT/USD"]
[270, {"b": [["11640.70000", "0.72549530", "1596666767.266742"]], "c": "2218784987"}, "book-100", "XBT/USD"]
[270, {"b": [["11654.90000", "2.87886281", "1596666767.343254"]], "c": "3874125321"}, "book-100", "XBT/USD"]
[270, {"a": [["11665.50000", "0.00000000", "1596666767.469783"], ["11702.50000", "23.57900000", "1596666155.599282", "r"]], "c": "3874125321"}, "book-100", "XBT/USD"]
[270, {"a": [["11673.70000", "0.00000000", "1596666767.476091"], ["11704.10000", "8.30000000", "1596666665.290916", "r"]], "c": "3874125321"}, "book-100", "XBT/USD"]
[270, {"b": [["11644.70000", "0.38000000", "1596666767.484357"]], "c": "3874125321"}, "book-100", "XBT/USD"]
[270, {"a": [["11677.40000", "0.38000000", "1596666767.491209"]], "c": "3874125321"}, "book-100", "XBT/USD"]
[270, {"a": [["11668.70000", "0.56507510", "1596666767.676562"]], "c": "3874125321"}, "book-100", "XBT/USD"]
[270, {"a": [["11683.50000", "0.00000000", "1596666767.732053"], ["11704.10000", "8.30000000", "1596666665.290916", "r"]], "c": "3874125321"}, "book-100", "XBT/USD"]
[270, {"a": [["11667.90000", "0.09621094", "1596666767.733847"]], "c": "3874125321"}, "book-100", "XBT/USD"]
[270, {"b": [["11654.40000", "0.54000000", "1596666767.805393"]], "c": "3908343561"}, "book-100", "XBT/USD"]
[270, {"a": [["11661.40000", "0.00000000", "1596666767.809288"], ["11704.10000", "8.30000000", "1596666665.290916", "r"]], "c": "2159728637"}, "book-100", "XBT/USD"]
[270, {"a": [["11661.70000", "0.00000000", "1596666767.941441"], ["11704.60000", "2.30891053", "1596666760.872896", "r"]], "c": "1273262687"}, "book-100", "XBT/USD"]
[270, {"b": [["11654.90000", "2.62886281", "1596666767.986449"]], "c": "691141773"}, "book-100", "XBT/USD"]
[270, {"a": [["11679.30000", "0.00000000", "1596666768.072748"], ["11705.20000", "0.75800000", "1596666760.546082", "r"]], "c": "691141773"}, "book-100", "XBT/USD"]
[270, {"a": [["11662.40000", "0.02766857", "1596666768.078618"]], "c": "814646483"}, "book-100", "XBT/USD"]
[270, {"a": [["11662.40000", "0.45418340", "1596666768.092371"]], "c": "4103405053"}, "book-100", "XBT/USD"]
[270, {"a": [["11694.40000", "2.24996306", "1596666768.103742"]], "c": "4103405053"}, "book-100", "XBT/USD"]
[270, {"b": [["11612.80000", "13.92887314", "1596666768.142714"]], "c": "4103405053"}, "book-100", "XBT/USD"]
[270, {"b": [["11654.90000", "2.87886281", "1596666768.157817"]], "c": "2520871727"}, "book-100", "XBT/USD"]
[270, {"a": [["11662.40000", "0.42651483", "1596666768.223954"]], "c": "2694991232"}, "book-100", "XBT/USD"]
[270, {"a": [["11662.30000", "0.02136303", "1596666768.235025"]], "c": "199665375"}, "book-100", "XBT/USD"]
[270, {"b": [["11654.90000", "2.62886281", "1596666768.290696"]], "c": "1764960269"}, "book-100", "XBT/USD"]
[270, {"b": [["11641.00000", "1.42542982", "1596666768.479266"]], "c": "1764960269"}, "book-100", "XBT/USD"]
[270, {"b": [["11654.90000", "2.87886281", "1596666768.593610"]], "c": "199665375"}, "book-100", "XBT/USD"]
[270, {"b": [["11651.00000", "0.53930000", "1596666768.703484"]], "c": "199665375"}, "book-100", "XBT/USD"]
[270, {"b": [["11654.90000", "2.62886281", "1596666768.742365"]], "c": "1764960269"}, "book-100", "XBT/USD"]
[270, {"b": [["11654.90000", "2.77886281", "1596666768.746018"]], "c": "850548484"}, "book-100", "XBT/USD"]
[270, {"a": [["11670.90000", "0.00000000", "1596666768.817750"], ["11704.10000", "8.30000000", "1596666665.290916", "r"]], "c": "850548484"}, "book-100", "XBT/USD"]
[270, {"b": [["11633.80000", "0.00442580", "1596666768.839735"]], "c": "850548484"}, "book-100", "XBT/USD"]
[270, {"a": [["11679.60000", "0.00438186", "1596666768.842334"]], "c": "850548484"}, "book-100", "XBT/USD"]
[270, {"a": [["11671.70000", "0.43900000", "1596666768.883705"]], "c": "850548484"}, "book-100", "XBT/USD"]
[270, {"a": [["11677.60000", "0.49697584", "1596666768.890280"]], "c": "850548484"}, "book-100", "XBT/USD"]
[270, {"a": [["11675.70000", "7.07099978", "1596666768.940243"]], "c": "850548484"}, "book-100", "XBT/USD"]
[270, {"a": [["11663.80000", "0.00000000", "1596666768.947450"], ["11702.50000", "23.57900000", "1596666155.599282", "r"]], "c": "3517549702"}, "book-100", "XBT/USD"]
[270, {"b": [["11640.30000", "0.00000000", "1596666768.964970"], ["11604.00000", "0.17085000", "1596666711.074347", "r"]], "c": "3517549702"}, "book-100", "XBT/USD"]
[270, {"b": [["11645.50000", "0.03380691", "1596666768.988363"]], "c": "3517549702"}, "book-100", "XBT/USD"]
[270, {"b": [["11654.90000", "3.02886281", "1596666768.989376"]], "c": "1215189676"}, "book-100", "XBT/USD"]
[270, {"a": [["11663.80000", "0.25848541", "1596666769.045510"]], "c": "2186902535"}, "book-100", "XBT/USD"]
[270, {"a": [["11662.30000", "0.00000000", "1596666769.062787"], ["11702.50000", "23.57900000", "1596666155.599282", "r"]], "c": "183547294"}, "book-100", "XBT/USD"]
[270, {"b": [["11654.20000", "0.99585094", "1596666769.073477"]], "c": "2626622421"}, "book-100", "XBT/USD"]
[270, {"a": [["11662.30000", "0.01688718", "1596666769.073960"]], "c": "138762027"}, "book-100", "XBT/USD"]
[270, {"a": [["11672.90000", "0.00000000", "1596666769.086425"], ["11702.50000", "23.57900000", "1596666155.599282", "r"]], "c": "138762027"}, "book-100", "XBT/USD"]
[270, {"a": [["11682.50000", "1.47188365", "1596666769.108867"]], "c": "138762027"}, "book-100", "XBT/USD"]
[270, {"b": [["11645.50000", "0.00000000", "1596666769.116203"], ["11604.00000", "0.17085000", "1596666711.074347", "r"]], "c": "138762027"}, "book-100", "XBT/USD"]
[270, {"b": [["11653.00000", "9.99987003", "1596666769.140013"]], "c": "1431369818"}, "book-100", "XBT/USD"]
[270, {"b": [["11645.50000", "0.02737542", "1596666769.146814"]], "c": "1431369818"}, "book-100", "XBT/USD"]
[270, {"b": [["11633.80000", "0.00000000", "1596666769.151196"], ["11604.10000", "1.51500000", "1596666763.121463", "r"]], "c": "1431369818"}, "book-100", "XBT/USD"]
[270, {"b": [["11647.20000", "3.21586700", "1596666769.162037"]], "c": "1431369818"}, "book-100", "XBT/USD"]
[270, {"b": [["11621.60000", "0.00000000", "1596666769.207583"], ["11604.00000", "0.17085000", "1596666711.074347", "r"]], "c": "1431369818"}, "book-100", "XBT/USD"]
[270, {"b": [["11645.50000", "0.05475056", "1596666769.274449"]], "c": "1431369818"}, "book-100", "XBT/USD"]
[270, {"b": [["11645.50000", "0.02737514", "1596666769.275906"]], "c": "1431369818"}, "book-100", "XBT/USD"]
[270, {"b": [["11650.80000", "0.00000000", "1596666769.296927"], ["11603.10000", "0.00858405", "1596666739.130412", "r"]], "c": "1431369818"}, "book-100", "XBT/USD"]
[270, {"a": [["11668.00000", "1.99189664", "1596666769.326911"]], "c": "1431369818"}, "book-100", "XBT/USD"]
[270, {"a": [["11678.70000", "0.30000000", "1596666769.351953"]], "c": "1431369818"}, "book-100", "XBT/USD"]
[270, {"a": [["11666.00000", "1.71400000", "1596666769.404995"]], "c": "1431369818"}, "book-100", "XBT/USD"]
[270, {"a": [["11679.90000", "6.23316569", "1596666769.437384"]], "c": "1431369818"}, "book-100", "XBT/USD"]
[270, {"a": [["11668.00000", "0.65309756", "1596666769.601985"]], "c": "1431369818"}, "book-100", "XBT/USD"]
[270, {"b": [["11654.90000", "2.77886281", "1596666769.745139"]], "c": "3432457840"}, "book-100", "XBT/USD"]
[270, {"a": [["11662.50000", "0.00000000", "1596666769.746996"], ["11701.50000", "2.00069507", "1596666706.346367", "r"]], "c": "1793757084"}, "book-100", "XBT/USD"]
[270, {"a": [["11664.00000", "1.22684819", "1596666769.772480"]], "c": "2113638588"}, "book-100", "XBT/USD"]
[270, {"a": [["11668.10000", "0.01491968", "1596666769.780971"]], "c": "2113638588"}, "book-100", "XBT/USD"]
[270, {"a": [["11668.70000", "0.07459832", "1596666769.806259"]], "c": "2113638588"}, "book-100", "XBT/USD"]
[270, {"a": [["11666.00000", "0.00000000", "1596666769.828766"], ["11702.50000", "23.57900000", "1596666155.599282", "r"]], "c": "2113638588"}, "book-100", "XBT/USD"]
[270, {"a": [["11669.50000", "1.37061422", "1596666769.832564"]], "c": "2113638588"}, "book-100", "XBT/USD"]
[270, {"a": [["11662.40000", "0.00000000", "1596666769.869861"], ["11702.50000", "23.57900000", "1596666155.599282", "r"]], "c": "1000648885"}, "book-100", "XBT/USD"]
[270, {"a": [["11664.80000", "0.00000000", "1596666769.882335"], ["11704.10000", "8.30000000", "1596666665.290916", "r"]], "c": "612886426"}, "book-100", "XBT/USD"]
[270, {"a": [["11662.60000", "0.41352978", "1596666769.887247"]], "c": "1740755705"}, "book-100", "XBT/USD"]
[270, {"b": [["11654.90000", "3.02886281", "1596666769.888251"]], "c": "4261809363"}, "book-100", "XBT/USD"]
[270, {"a": [["11674.30000", "0.00000000", "1596666769.933057"], ["11704.10000", "8.30000000", "1596666665.290916", "r"]], "c": "4261809363"}, "book-100", "XBT/USD"]
[270, {"a": [["11672.10000", "1.79201630", "1596666769.937109"]], "c": "4261809363"}, "book-100", "XBT/USD"]
[270, {"b": [["11650.90000", "7.80000000", "1596666769.938969"]], "c": "4261809363"}, "book-100", "XBT/USD"]
[270, {"b": [["11654.80000", "2.56334682", "1596666769.942485"], ["11654.90000", "3.42886281", "1596666769.942602"]], "c": "1073757245"}, "book-100", "XBT/USD"]
[270, {"b": [["11653.80000", "0.09600000", "1596666769.944766"]], "c": "1696908565"}, "book-100", "XBT/USD"]
[270, {"a": [["11673.20000", "0.00000000", "1596666769.957609"], ["11704.10000", "8.30000000", "1596666665.290916", "r"]], "c": "1696908565"}, "book-100", "XBT/USD"]
[270, {"b": [["11613.10000", "0.00000000", "1596666769.970395"], ["11604.00000", "0.17085000", "1596666711.074347", "r"]], "c": "1696908565"}, "book-100", "XBT/USD"]
[270, {"b": [["11645.50000", "0.06959895", "1596666769.987029"]], "c": "1696908565"}, "book-100", "XBT/USD"]
[270, {"b": [["11645.50000", "0.04222381", "1596666769.987863"]], "c": "1696908565"}, "book-100", "XBT/USD"]
[270, {"a": [["11678.10000", "0.00000000", "1596666769.990188"], ["11704.60000", "2.30891053", "1596666760.872896", "r"]], "c": "1696908565"}, "book-100", "XBT/USD"]
[270, {"a": [["11662.30000", "0.00000000", "1596666769.997843"], ["11705.20000", "0.75800000", "1596666760.546082", "r"]], "c": "4091728617"}, "book-100", "XBT/USD"]
[270, {"a": [["11677.60000", "0.00000000", "1596666769.998349"], ["11705.30000", "1.51500000", "1596666759.981994", "r"]], "c": "4091728617"}, "book-100", "XBT/USD"]
[270, {"a": [["11663.70000", "0.02319016", "1596666769.998480"]], "c": "981286960"}, "book-100", "XBT/USD"]
[270, {"a": [["11674.40000", "0.00000000", "1596666770.002696"], ["11705.30000", "1.51500000", "1596666759.981994", "r"]], "c": "981286960"}, "book-100", "XBT/USD"]
[270, {"a": [["11676.70000", "0.00000000", "1596666770.003760"], ["11706.10000", "20.00000000", "1596666768.403913", "r"]], "c": "981286960"}, "book-100", "XBT/USD"]
[270, {"a": [["11676.20000", "0.00000000", "1596666770.006153"], ["11706.80000", "3.00107058", "1596666756.974795", "r"]], "c": "981286960"}, "book-100", "XBT/USD"]
[270, {"b": [["11654.90000", "3.17886281", "1596666770.010019"]], "c": "3563937674"}, "book-100", "XBT/USD"]
[270, {"a": [["11685.10000", "0.00000000", "1596666770.010543"], ["11709.70000", "7.20507863", "1596666620.257365", "r"]], "c": "3563937674"}, "book-100", "XBT/USD"]
[270, {"a": [["11669.50000", "0.00000000", "1596666770.011651"], ["11710.70000", "3.52183532", "1596666711.393054", "r"]], "c": "3563937674"}, "book-100", "XBT/USD"]
[270, {"a": [["11675.50000", "0.69951679", "1596666770.020526"]], "c": "3563937674"}, "book-100", "XBT/USD"]
[270, {"a": [["11674.30000", "1.50000000", "1596666770.033881"]], "c": "3563937674"}, "book-100", "XBT/USD"]
[270, {"a": [["11664.10000", "0.00000000", "1596666770.037491"], ["11709.70000", "7.20507863", "1596666620.257365", "r"]], "c": "723544115"}, "book-100", "XBT/USD"]
[270, {"a": [["11676.50000", "0.00000000", "1596666770.038022"], ["11710.70000", "3.52183532", "1596666711.393054", "r"]], "c": "723544115"}, "book-100", "XBT/USD"]
[270, {"a": [["11670.30000", "0.00000000", "1596666770.054806"], ["11711.00000", "3.52207482", "1596666594.088624", "r"]], "c": "723544115"}, "book-100", "XBT/USD"]
[270, {"a": [["11672.50000", "0.00000000", "1596666770.056033"], ["11711.10000", "2.97327583", "1596666728.385477", "r"]], "c": "723544115"}, "book-100", "XBT/USD"]
[270, {"a": [["11676.80000", "0.00000000", "1596666770.061085"], ["11711.20000", "0.89630055", "1596666591.787115", "r"]], "c": "723544115"}, "book-100", "XBT/USD"]
[270, {"a": [["11685.20000", "0.00000000", "1596666770.061248"], ["11714.50000", "1.06000000", "1596666759.236412", "r"]], "c": "723544115"}, "book-100", "XBT/USD"]
[270, {"b": [["11654.90000", "3.67886281", "1596666770.073132"]], "c": "1955987265"}, "book-100", "XBT/USD"]
[270, {"a": [["11668.80000", "0.00000000", "1596666770.073265"], ["11715.30000", "6.10000000", "1596666635.445451", "r"]], "c": "1955987265"}, "book-100", "XBT/USD"]
[270, {"a": [["11671.80000", "0.00000000", "1596666770.074742"], ["11717.70000", "0.01287006", "1596666768.839831", "r"]], "c": "1955987265"}, "book-100", "XBT/USD"]
[270, {"a": [["11662.60000", "0.00000000", "1596666770.086178"], ["11717.80000", "1.99812614", "1596666759.535617", "r"]], "c": "3201297064"}, "book-100", "XBT/USD"]
[270, {"b": [["11654.90000", "3.77686281", "1596666770.087824"]], "c": "1874670221"}, "book-100", "XBT/USD"]
[270, {"a": [["11680.10000", "0.00000000", "1596666770.090633"], ["11718.50000", "24.30000000", "1596666641.380470", "r"]], "c": "1874670221"}, "book-100", "XBT/USD"]
[270, {"a": [["11664.00000", "0.88274602", "1596666770.094957"]], "c": "1967115837"}, "book-100", "XBT/USD"]
[270, {"a": [["11664.00000", "0.00000000", "1596666770.095949"], ["11719.60000", "1.46521891", "1596666747.719598", "r"]], "c": "2701336393"}, "book-100", "XBT/USD"]
[270, {"a": [["11680.00000", "0.00000000", "1596666770.096432"], ["11719.70000", "3.50602221", "1596666743.346655", "r"]], "c": "2701336393"}, "book-100", "XBT/USD"]
[270, {"a": [["11691.60000", "1.48914221", "1596666770.103227"]], "c": "2701336393"}, "book-100", "XBT/USD"]
[270, {"a": [["11667.10000", "1.07644419", "1596666770.108340"]], "c": "1153428534"}, "book-100", "XBT/USD"]
[270, {"a": [["11675.90000", "0.00000000", "1596666770.108514"], ["11720.10000", "0.02000000", "1596666119.730609", "r"]], "c": "1153428534"}, "book-100", "XBT/USD"]
[270, {"a": [["11668.70000", "0.00000000", "1596666770.110599"], ["11721.00000", "0.80800000", "1596666761.523908", "r"]], "c": "1153428534"}, "book-100", "XBT/USD"]
[270, {"a": [["11668.10000", "0.00000000", "1596666770.113224"], ["11722.10000", "7.70000000", "1596666696.315517", "r"]], "c": "1153428534"}, "book-100", "XBT/USD"]
[270, {"a": [["11663.90000", "0.00000000", "1596666770.113796"], ["11722.20000", "3.01549629", "1596666746.821117", "r"]], "c": "2252861562"}, "book-100", "XBT/USD"]
[270, {"b": [["11653.00000", "0.00000000", "1596666770.120104"], ["11603.10000", "0.00858405", "1596666739.130412", "r"]], "c": "2252861562"}, "book-100", "XBT/USD"]
[270, {"a": [["11669.40000", "0.00000000", "1596666770.129930"], ["11725.40000", "1.99666304", "1596666743.823724", "r"]], "c": "2252861562"}, "book-100", "XBT/USD"]
[270, {"a": [["11663.80000", "0.00000000", "1596666770.140155"], ["11726.60000", "0.00700000", "1596666737.891214", "r"]], "c": "3496577837"}, "book-100", "XBT/USD"]
[270, {"a": [["11671.70000", "1.19451922", "1596666770.141865"]], "c": "3496577837"}, "book-100", "XBT/USD"]
[270, {"a": [["11679.70000", "0.00000000", "1596666770.160678"], ["11727.00000", "0.17085000", "1596665935.290778", "r"]], "c": "3496577837"}, "book-100", "XBT/USD"]
[270, {"a": [["11664.40000", "0.00000000", "1596666770.160994"], ["11727.40000", "7.40000000", "1596666699.130230", "r"]], "c": "2080696974"}, "book-100", "XBT/USD"]
[270, {"a": [["11675.50000", "1.19951679", "1596666770.161627"]], "c": "2080696974"}, "book-100", "XBT/USD"]
[270, {"a": [["11672.20000", "0.00000000", "1596666770.164049"], ["11729.00000", "9.29631056", "1596665758.165359", "r"]], "c": "2080696974"}, "book-100", "XBT/USD"]
[270, {"a": [["11682.50000", "0.89884406", "1596666770.164675"]], "c": "2080696974"}, "book-100", "XBT/USD"]
[270, {"b": [["11630.00000", "0.10583740", "1596666770.171499"]], "c": "2080696974"}, "book-100", "XBT/USD"]
[270, {"a": [["11691.90000", "0.00000000", "1596666770.177979"], ["11730.00000", "0.17085000", "1596666259.012402", "r"]], "c": "2080696974"}, "book-100", "XBT/USD"]
[270, {"a": [["11674.30000", "0.00000000", "1596666770.178146"], ["11731.20000", "0.01000000", "1596665559.440935", "r"]], "c": "2080696974"}, "book-100", "XBT/USD"]
[270, {"a": [["11671.00000", "0.00000000", "1596666770.179132"], ["11732.30000", "19.70000000", "1596666762.007788", "r"]], "c": "2080696974"}, "book-100", "XBT/USD"]
[270, {"a": [["11692.10000", "0.96780000", "1596666770.187018"]], "c": "2080696974"}, "book-100", "XBT/USD"]
[270, {"a": [["11671.70000", "0.43900000", "1596666770.187866"]], "c": "2080696974"}, "book-100", "XBT/USD"]
[270, {"a": [["11683.70000", "0.85724552", "1596666770.188834"]], "c": "2080696974"}, "book-100", "XBT/USD"]
[270, {"b": [["11640.90000", "2.43523583", "1596666770.204284"]], "c": "2080696974"}, "book-100", "XBT/USD"]
[270, {"a": [["11667.50000", "4.27400000", "1596666770.207129"]], "c": "2049347198"}, "book-100", "XBT/USD"]
[270, {"a": [["11681.30000", "0.72307248", "1596666770.226120"]], "c": "2049347198"}, "book-100", "XBT/USD"]
[270, {"a": [["11664.40000", "0.41352978", "1596666770.228993"]], "c": "82829879"}, "book-100", "XBT/USD"]
[270, {"a": [["11665.80000", "0.25846946", "1596666770.237741"]], "c": "1396477586"}, "book-100", "XBT/USD"]
[270, {"a": [["11674.90000", "0.75551922", "1596666770.241936"]], "c": "1396477586"}, "book-100", "XBT/USD"]
[270, {"b": [["11649.60000", "0.04220895", "1596666770.253690"]], "c": "1396477586"}, "book-100", "XBT/USD"]
[270, {"a": [["11687.20000", "1.20795388", "1596666770.256391"]], "c": "1396477586"}, "book-100", "XBT/USD"]
[270, {"a": [["11676.00000", "0.00000000", "1596666770.266930"], ["11726.60000", "0.00700000", "1596666737.891214", "r"]], "c": "1396477586"}, "book-100", "XBT/USD"]
[270, {"a": [["11664.30000", "0.02318896", "1596666770.270696"]], "c": "3432654849"}, "book-100", "XBT/USD"]
[270, {"a": [["11663.70000", "0.00000000", "1596666770.272445"], ["11726.60000", "0.00700000", "1596666737.891214", "r"]], "c": "559487476"}, "book-100", "XBT/USD"]
[270, {"a": [["11679.10000", "0.89623000", "1596666770.274124"]], "c": "559487476"}, "book-100", "XBT/USD"]
[270, {"a": [["11667.90000", "0.00000000", "1596666770.282439"], ["11726.60000", "0.00700000", "1596666737.891214", "r"]], "c": "559487476"}, "book-100", "XBT/USD"]
[270, {"a": [["11674.90000", "0.00000000", "1596666770.290264"], ["11727.00000", "0.17085000", "1596665935.290778", "r"]], "c": "559487476"}, "book-100", "XBT/USD"]
[270, {"a": [["11675.40000", "3.26075425", "1596666770.298349"]], "c": "559487476"}, "book-100", "XBT/USD"]
[270, {"a": [["11683.40000", "0.49672137", "1596666770.315633"]], "c": "559487476"}, "book-100", "XBT/USD"]
[270, {"a": [["11681.00000", "0.89873886", "1596666770.325376"]], "c": "559487476"}, "book-100", "XBT/USD"]
[270, {"a": [["11677.60000", "1.50000000", "1596666770.325573"]], "c": "559487476"}, "book-100", "XBT/USD"]
[270, {"a": [["11671.60000", "1.39382008", "1596666770.334795"]], "c": "559487476"}, "book-100", "XBT/USD"]
[270, {"a": [["11683.00000", "0.00000000", "1596666770.341737"], ["11722.10000", "7.70000000", "1596666696.315517", "r"]], "c": "559487476"}, "book-100", "XBT/USD"]
[270, {"b": [["11650.90000", "9.74044429", "1596666770.344001"]], "c": "559487476"}, "book-100", "XBT/USD"]
[270, {"a": [["11665.80000", "0.56476946", "1596666770.344675"]], "c": "15526504"}, "book-100", "XBT/USD"]
[270, {"a": [["11683.70000", "0.00000000", "1596666770.346475"], ["11722.20000", "3.01549629", "1596666746.821117", "r"]], "c": "15526504"}, "book-100", "XBT/USD"]
[270, {"a": [["11679.00000", "0.10331641", "1596666770.350016"]], "c": "15526504"}, "book-100", "XBT/USD"]
[270, {"b": [["11640.90000", "0.00000000", "1596666770.350221"], ["11604.10000", "1.51500000", "1596666763.121463", "r"]], "c": "15526504"}, "book-100", "XBT/USD"]
[270, {"b": [["11645.50000", "0.00000000", "1596666770.350443"], ["11604.00000", "0.17085000", "1596666711.074347", "r"]], "c": "15526504"}, "book-100", "XBT/USD"]
[270, {"a": [["11672.00000", "0.75551922", "1596666770.350917"]], "c": "15526504"}, "book-100", "XBT/USD"]
[270, {"b": [["11625.40000", "0.49800000", "1596666770.374310"]], "c": "15526504"}, "book-100", "XBT/USD"]
[270, {"a": [["11675.50000", "1.85201941", "1596666770.399203"]], "c": "15526504"}, "book-100", "XBT/USD"]
[270, {"a": [["11672.00000", "0.00000000", "1596666770.400634"], ["11722.10000", "7.70000000", "1596666696.315517", "r"]], "c": "15526504"}, "book-100", "XBT/USD"]
[270, {"b": [["11645.20000", "0.00000000", "1596666770.412574"], ["11604.00000", "0.17085000", "1596666711.074347", "r"]], "c": "15526504"}, "book-100", "XBT/USD"]
[270, {"a": [["11672.10000", "0.00000000", "1596666770.447344"], ["11722.20000", "3.01549629", "1596666746.821117", "r"]], "c": "15526504"}, "book-100", "XBT/USD"]
[270, {"a": [["11671.60000", "2.14933930", "1596666770.449230"]], "c": "15526504"}, "book-100", "XBT/USD"]
[270, {"b": [["11647.20000", "1.00000000", "1596666770.493022"]], "c": "15526504"}, "book-100", "XBT/USD"]
[270, {"b": [["11654.90000", "2.77686281", "1596666770.496549"]], "c": "4034313924"}, "book-100", "XBT/USD"]
[270, {"a": [["11671.60000", "1.39382008", "1596666770.500553"]], "c": "4034313924"}, "book-100", "XBT/USD"]
[270, {"a": [["11687.10000", "2.00334705", "1596666770.518694"]], "c": "4034313924"}, "book-100", "XBT/USD"]
[270, {"a": [["11674.90000", "0.11269914", "1596666770.529326"]], "c": "4034313924"}, "book-100", "XBT/USD"]
[270, {"a": [["11666.70000", "0.00000000", "1596666770.547004"], ["11722.10000", "7.70000000", "1596666696.315517", "r"]], "c": "3114848812"}, "book-100", "XBT/USD"]
[270, {"a": [["11675.40000", "4.01627347", "1596666770.560827"]], "c": "3114848812"}, "book-100", "XBT/USD"]
[270, {"b": [["11654.90000", "12.77673284", "1596666770.569741"]], "c": "1988577337"}, "book-100", "XBT/USD"]
[270, {"a": [["11681.40000", "1.42060771", "1596666770.581113"]], "c": "1988577337"}, "book-100", "XBT/USD"]
[270, {"a": [["11688.60000", "2.31688694", "1596666770.582703"]], "c": "1988577337"}, "book-100", "XBT/USD"]
[270, {"a": [["11710.60000", "2.80039129", "1596666770.582883"]], "c": "1988577337"}, "book-100", "XBT/USD"]
[270, {"a": [["11698.90000", "1.95885702", "1596666770.583016"]], "c": "1988577337"}, "book-100", "XBT/USD"]
[270, {"a": [["11670.80000", "0.33918579", "1596666770.589110"]], "c": "1988577337"}, "book-100", "XBT/USD"]
[270, {"a": [["11670.80000", "1.21473524", "1596666770.593856"]], "c": "1988577337"}, "book-100", "XBT/USD"]
[270, {"a": [["11675.40000", "3.26075425", "1596666770.637278"]], "c": "1988577337"}, "book-100", "XBT/USD"]
[270, {"a": [["11670.80000", "1.71578367", "1596666770.653389"]], "c": "1988577337"}, "book-100", "XBT/USD"]
[270, {"b": [["11642.80000", "2.43476851", "1596666770.658591"]], "c": "1988577337"}, "book-100", "XBT/USD"]
[270, {"a": [["11677.60000", "0.00000000", "1596666770.663105"], ["11719.60000", "1.46521891", "1596666747.719598", "r"]], "c": "1988577337"}, "book-100", "XBT/USD"]
[270, {"a": [["11655.00000", "0.00000000", "1596666770.668762"], ["11719.70000", "3.50602221", "1596666743.346655", "r"]], "c": "3454063957"}, "book-100", "XBT/USD"]
[270, {"a": [["11675.00000", "3.07292922", "1596666770.685911"]], "c": "3454063957"}, "book-100", "XBT/USD"]
[270, {"b": [["11654.80000", "1.27024277", "1596666770.718193"]], "c": "3674857258"}, "book-100", "XBT/USD"]
[270, {"a": [["11693.30000", "0.00000000", "1596666770.724006"], ["11720.10000", "0.02000000", "1596666119.730609", "r"]], "c": "3674857258"}, "book-100", "XBT/USD"]
[270, {"a": [["11705.70000", "0.48380000", "1596666770.726024"]], "c": "3674857258"}, "book-100", "XBT/USD"]
[270, {"b": [["11654.90000", "12.27673284", "1596666770.731301"]], "c": "1950523193"}, "book-100", "XBT/USD"]
[270, {"a": [["11675.00000", "2.31741000", "1596666770.733239"]], "c": "1950523193"}, "book-100", "XBT/USD"]
[270, {"b": [["11649.80000", "0.00000000", "1596666770.737212"], ["11604.00000", "0.17085000", "1596666711.074347", "r"]], "c": "1950523193"}, "book-100", "XBT/USD"]
[270, {"b": [["11649.00000", "0.00000000", "1596666770.737411"], ["11603.10000", "0.00858405", "1596666739.130412", "r"]], "c": "1950523193"}, "book-100", "XBT/USD"]
[270, {"b": [["11654.90000", "11.63367048", "1596666770.737563"]], "c": "1104475045"}, "book-100", "XBT/USD"]
[270, {"b": [["11654.60000", "0.00000000", "1596666770.737693"], ["11602.80000", "0.75800000", "1596666731.483110", "r"]], "c": "1036494871"}, "book-100", "XBT/USD"]
[270, {"b": [["11654.70000", "0.08951808", "1596666770.737953"]], "c": "2895321236"}, "book-100", "XBT/USD"]
[270, {"a": [["11667.10000", "0.43327529", "1596666770.738041"]], "c": "739360545"}, "book-100", "XBT/USD"]
[270, {"a": [["11665.70000", "0.30600000", "1596666770.772317"]], "c": "2825264281"}, "book-100", "XBT/USD"]
[270, {"b": [["11644.30000", "0.00000000", "1596666770.772427"], ["11602.30000", "2.01774694", "1596666748.156295", "r"]], "c": "2825264281"}, "book-100", "XBT/USD"]
[270, {"a": [["11670.00000", "0.09621094", "1596666770.778183"]], "c": "2825264281"}, "book-100", "XBT/USD"]
[270, {"a": [["11665.80000", "0.25846946", "1596666770.779289"]], "c": "2841720237"}, "book-100", "XBT/USD"]
[270, {"a": [["11670.60000", "0.21066681", "1596666770.787409"]], "c": "2841720237"}, "book-100", "XBT/USD"]
[270, {"a": [["11664.40000", "0.00000000", "1596666770.798816"], ["11718.50000", "24.30000000", "1596666641.380470", "r"]], "c": "1690071914"}, "book-100", "XBT/USD"]
[270, {"a": [["11675.70000", "7.40940484", "1596666770.805092"]], "c": "1690071914"}, "book-100", "XBT/USD"]
[270, {"a": [["11679.00000", "0.81376623", "1596666770.805620"]], "c": "1690071914"}, "book-100", "XBT/USD"]
[270, {"a": [["11675.50000", "1.19951679", "1596666770.807416"]], "c": "1690071914"}, "book-100", "XBT/USD"]
[270, {"b": [["11654.90000", "1.63380045", "1596666770.809943"]], "c": "3964636755"}, "book-100", "XBT/USD"]
[270, {"a": [["11675.30000", "0.75551922", "1596666770.811536"]], "c": "3964636755"}, "book-100", "XBT/USD"]
[270, {"a": [["11699.70000", "2.88000000", "1596666770.820935"]], "c": "3964636755"}, "book-100", "XBT/USD"]
[270, {"b": [["11607.80000", "0.00000000", "1596666770.824255"], ["11602.20000", "2.01681621", "1596666634.588713", "r"]], "c": "3964636755"}, "book-100", "XBT/USD"]
[270, {"a": [["11680.10000", "0.74919681", "1596666770.824563"]], "c": "3964636755"}, "book-100", "XBT/USD"]
[270, {"b": [["11609.60000", "0.74919681", "1596666770.825817"]], "c": "3964636755"}, "book-100", "XBT/USD"]
[270, {"a": [["11674.00000", "0.00300000", "1596666770.828063"]], "c": "3964636755"}, "book-100", "XBT/USD"]
[270, {"a": [["11667.10000", "0.00000000", "1596666770.834063"], ["11717.80000", "1.99812614", "1596666759.535617", "r"]], "c": "1893269022"}, "book-100", "XBT/USD"]
[270, {"b": [["11654.90000", "1.53380045", "1596666770.849499"]], "c": "4181641542"}, "book-100", "XBT/USD"]
[270, {"a": [["11675.30000", "0.00000000", "1596666770.863145"], ["11718.50000", "24.30000000", "1596666641.380470", "r"]], "c": "4181641542"}, "book-100", "XBT/USD"]
[270, {"a": [["11702.20000", "0.55961699", "1596666770.872695"]], "c": "4181641542"}, "book-100", "XBT/USD"]
[270, {"b": [["11654.80000", "0.85746341", "1596666770.907968"]], "c": "3192928011"}, "book-100", "XBT/USD"]
[270, {"a": [["11665.60000", "0.02318639", "1596666770.932772"]], "c": "762427777"}, "book-100", "XBT/USD"]
[270, {"a": [["11664.30000", "0.00000000", "1596666770.933376"], ["11717.80000", "1.99812614", "1596666759.535617", "r"]], "c": "1377976655"}, "book-100", "XBT/USD"]
[270, {"a": [["11665.70000", "0.71952978", "1596666770.953724"]], "c": "3255676911"}, "book-100", "XBT/USD"]
[270, {"b": [["11658.90000", "1.70100000", "1596666771.013610"]], "c": "866000058"}, "book-100", "XBT/USD"]
[270, {"b": [["11655.60000", "0.10000000", "1596666771.014902"]], "c": "3504282818"}, "book-100", "XBT/USD"]
[270, {"a": [["11690.00000", "0.04000000", "1596666771.019513"]], "c": "3504282818"}, "book-100", "XBT/USD"]
[270, {"a": [["11667.00000", "0.10300000", "1596666771.030810"]], "c": "1806094943"}, "book-100", "XBT/USD"]
[270, {"a": [["11665.60000", "0.32958639", "1596666771.032665"]], "c": "232098471"}, "book-100", "XBT/USD"]
[270, {"b": [["11654.90000", "1.13380045", "1596666771.062642"]], "c": "2063359711"}, "book-100", "XBT/USD"]
[270, {"b": [["11658.90000", "2.20100000", "1596666771.066075"]], "c": "1587428999"}, "book-100", "XBT/USD"]
[270, {"a": [["11665.70000", "0.41352978", "1596666771.079013"]], "c": "3548529423"}, "book-100", "XBT/USD"]
[270, {"b": [["11658.90000", "6.90100000", "1596666771.107321"]], "c": "320488982"}, "book-100", "XBT/USD"]
[270, {"a": [["11665.60000", "0.30640000", "1596666771.124175"]], "c": "2659260149"}, "book-100", "XBT/USD"]
[270, {"a": [["11665.60000", "0.32109824", "1596666771.125132"]], "c": "3764792522"}, "book-100", "XBT/USD"]
[270, {"a": [["11665.50000", "0.42114495", "1596666771.136504"]], "c": "3736000105"}, "book-100", "XBT/USD"]
[270, {"b": [["11655.00000", "0.52689846", "1596666771.145690"]], "c": "714335091"}, "book-100", "XBT/USD"]
[270, {"a": [["11676.50000", "0.69812691", "1596666771.146624"]], "c": "714335091"}, "book-100", "XBT/USD"]
[270, {"b": [["11658.90000", "2.20100000", "1596666771.162619"]], "c": "1312347062"}, "book-100", "XBT/USD"]
[270, {"b": [["11654.90000", "0.98380045", "1596666771.169350"]], "c": "1771020276"}, "book-100", "XBT/USD"]
[270, {"b": [["11654.50000", "0.85746341", "1596666771.188189"]], "c": "1001087443"}, "book-100", "XBT/USD"]
[270, {"b": [["11657.40000", "0.09900000", "1596666771.213279"]], "c": "954992722"}, "book-100", "XBT/USD"]
[270, {"b": [["11647.90000", "0.00000000", "1596666771.213714"], ["11604.00000", "0.17085000", "1596666711.074347", "r"]], "c": "954992722"}, "book-100", "XBT/USD"]
[270, {"a": [["11714.50000", "0.00000000", "1596666771.223787"], ["11715.30000", "6.10000000", "1596666635.445451", "r"]], "c": "954992722"}, "book-100", "XBT/USD"]
[270, {"b": [["11625.00000", "0.25000000", "1596666771.229093"]], "c": "954992722"}, "book-100", "XBT/USD"]
[270, {"b": [["11653.90000", "0.00000000", "1596666771.247269"], ["11603.10000", "0.00858405", "1596666739.130412", "r"]], "c": "954992722"}, "book-100", "XBT/USD"]
[270, {"a": [["11665.60000", "0.30640000", "1596666771.253725"]], "c": "440833411"}, "book-100", "XBT/USD"]
[270, {"b": [["11655.70000", "1.00000000", "1596666771.427534"]], "c": "1666630658"}, "book-100", "XBT/USD"]
[270, {"a": [["11674.90000", "0.86821836", "1596666771.433377"]], "c": "1666630658"}, "book-100", "XBT/USD"]
[270, {"b": [["11658.90000", "3.23387000", "1596666771.434663"]], "c": "2913264791"}, "book-100", "XBT/USD"]
[270, {"a": [["11691.00000", "0.93100000", "1596666771.462371"]], "c": "2913264791"}, "book-100", "XBT/USD"]
[270, {"a": [["11677.60000", "1.50000000", "1596666771.466917"]], "c": "2913264791"}, "book-100", "XBT/USD"]
[270, {"b": [["11658.90000", "3.48387000", "1596666771.469983"]], "c": "1455550704"}, "book-100", "XBT/USD"]
[270, {"b": [["11655.00000", "2.67189846", "1596666771.477769"]], "c": "740008295"}, "book-100", "XBT/USD"]
[270, {"b": [["11658.90000", "3.91287000", "1596666771.481174"]], "c": "1144679652"}, "book-100", "XBT/USD"]
[270, {"a": [["11674.90000", "0.11269914", "1596666771.483713"]], "c": "1144679652"}, "book-100", "XBT/USD"]
[270, {"a": [["11710.10000", "0.89650546", "1596666771.484931"]], "c": "1144679652"}, "book-100", "XBT/USD"]
[270, {"b": [["11655.00000", "2.14500000", "1596666771.485540"]], "c": "436959687"}, "book-100", "XBT/USD"]
[270, {"b": [["11655.00000", "3.41901343", "1596666771.489633"]], "c": "4063686335"}, "book-100", "XBT/USD"]
[270, {"b": [["11650.60000", "1.00155000", "1596666771.491802"]], "c": "4063686335"}, "book-100", "XBT/USD"]
[270, {"a": [["11665.50000", "0.42735381", "1596666771.492866"]], "c": "3650984531"}, "book-100", "XBT/USD"]
[270, {"b": [["11658.90000", "4.21287000", "1596666771.494128"]], "c": "2084348091"}, "book-100", "XBT/USD"]
[270, {"a": [["11692.10000", "0.00000000", "1596666771.513069"], ["11711.10000", "2.97327583", "1596666728.385477", "r"]], "c": "2084348091"}, "book-100", "XBT/USD"]
[270, {"b": [["11657.40000", "0.24900000", "1596666771.515252"]], "c": "2116066225"}, "book-100", "XBT/USD"]
[270, {"b": [["11656.50000", "9.99987003", "1596666771.522798"]], "c": "3063500868"}, "book-100", "XBT/USD"]
[270, {"a": [["11674.00000", "0.75851922", "1596666771.531201"]], "c": "3063500868"}, "book-100", "XBT/USD"]
[270, {"b": [["11655.60000", "0.00000000", "1596666771.571276"], ["11604.00000", "0.17085000", "1596666711.074347", "r"]], "c": "2570197409"}, "book-100", "XBT/USD"]
[270, {"b": [["11642.80000", "0.00000000", "1596666771.583081"], ["11603.10000", "0.00858405", "1596666739.130412", "r"]], "c": "2570197409"}, "book-100", "XBT/USD"]
[270, {"a": [["11674.00000", "0.00300000", "1596666771.587732"]], "c": "2570197409"}, "book-100", "XBT/USD"]
[270, {"a": [["11665.40000", "0.01469849", "1596666771.622714"]], "c": "845124728"}, "book-100", "XBT/USD"]
[270, {"a": [["11665.50000", "0.42114495", "1596666771.625862"]], "c": "2601966837"}, "book-100", "XBT/USD"]
[270, {"b": [["11658.90000", "4.61287000", "1596666771.720683"]], "c": "4020077255"}, "book-100", "XBT/USD"]
[270, {"b": [["11657.50000", "0.10000000", "1596666771.767816"]], "c": "3476875741"}, "book-100", "XBT/USD"]
[270, {"b": [["11657.50000", "0.18250000", "1596666771.785631"]], "c": "1083823025"}, "book-100", "XBT/USD"]
[270, {"b": [["11657.50000", "0.22500000", "1596666771.785706"]], "c": "3441907512"}, "book-100", "XBT/USD"]
[270, {"a": [["11669.50000", "0.04051069", "1596666771.786343"]], "c": "3441907512"}, "book-100", "XBT/USD"]
[270, {"a": [["11673.90000", "0.08250000", "1596666771.786767"]], "c": "3441907512"}, "book-100", "XBT/USD"]
[270, {"b": [["11658.90000", "8.89187000", "1596666771.806660"]], "c": "345314570"}, "book-100", "XBT/USD"]
[270, {"b": [["11658.90000", "9.37407580", "1596666771.806838"]], "c": "3067394938"}, "book-100", "XBT/USD"]
[270, {"a": [["11687.40000", "3.52885645", "1596666771.829650"]], "c": "3067394938"}, "book-100", "XBT/USD"]
[270, {"a": [["11687.40000", "0.00000000", "1596666771.830401"], ["11710.70000", "3.52183532", "1596666711.393054", "r"]], "c": "3067394938"}, "book-100", "XBT/USD"]
[270, {"a": [["11681.10000", "0.00000000", "1596666771.838142"], ["11711.00000", "3.52207482", "1596666594.088624", "r"]], "c": "3067394938"}, "book-100", "XBT/USD"]
[270, {"a": [["11693.70000", "0.00000000", "1596666771.851040"], ["11711.10000", "2.97327583", "1596666728.385477", "r"]], "c": "3067394938"}, "book-100", "XBT/USD"]
[270, {"b": [["11641.50000", "0.00000000", "1596666771.861272"], ["11603.10000", "0.00858405", "1596666739.130412", "r"]], "c": "3067394938"}, "book-100", "XBT/USD"]
[270, {"b": [["11644.90000", "0.00000000", "1596666771.863250"], ["11602.80000", "0.75800000", "1596666731.483110", "r"]], "c": "3067394938"}, "book-100", "XBT/USD"]
[270, {"a": [["11682.30000", "0.99355179", "1596666771.873151"]], "c": "3067394938"}, "book-100", "XBT/USD"]
[270, {"a": [["11699.50000", "0.00000000", "1596666771.876788"], ["11711.20000", "0.89630055", "1596666591.787115", "r"]], "c": "3067394938"}, "book-100", "XBT/USD"]
[270, {"a": [["11682.30000", "0.00000000", "1596666771.897328"], ["11713.80000", "0.37309062", "1596666771.863547", "r"]], "c": "3067394938"}, "book-100", "XBT/USD"]
[270, {"a": [["11677.60000", "0.00000000", "1596666771.970932"], ["11715.30000", "6.10000000", "1596666635.445451", "r"]], "c": "3067394938"}, "book-100", "XBT/USD"]
[270, {"a": [["11697.60000", "1.50602111", "1596666772.062638"]], "c": "3067394938"}, "book-100", "XBT/USD"]
[270, {"a": [["11694.40000", "0.00000000", "1596666772.093288"], ["11715.30000", "6.10000000", "1596666635.445451", "r"]], "c": "3067394938"}, "book-100", "XBT/USD"]
[270, {"b": [["11655.00000", "2.14500000", "1596666772.093902"]], "c": "4001576449"}, "book-100", "XBT/USD"]
[270, {"a": [["11668.30000", "1.50000000", "1596666772.119675"]], "c": "4001576449"}, "book-100", "XBT/USD"]
[270, {"a": [["11689.00000", "0.89812376", "1596666772.122173"]], "c": "4001576449"}, "book-100", "XBT/USD"]
[270, {"b": [["11650.60000", "0.70155000", "1596666772.147492"]], "c": "4001576449"}, "book-100", "XBT/USD"]
[270, {"b": [["11653.20000", "0.86220643", "1596666772.209460"]], "c": "4001576449"}, "book-100", "XBT/USD"]
[270, {"b": [["11656.60000", "1.39258443", "1596666772.237903"]], "c": "3554824395"}, "book-100", "XBT/USD"]
[270, {"a": [["11665.80000", "0.00000000", "1596666772.311153"], ["11713.80000", "0.37309062", "1596666771.863547", "r"]], "c": "4016665151"}, "book-100", "XBT/USD"]
[270, {"a": [["11689.00000", "1.89109056", "1596666772.315970"]], "c": "4016665151"}, "book-100", "XBT/USD"]
[270, {"a": [["11665.30000", "0.25844721", "1596666772.410368"]], "c": "26290909"}, "book-100", "XBT/USD"]
[270, {"a": [["11679.60000", "0.00000000", "1596666772.522602"], ["11713.80000", "0.37309062", "1596666771.863547", "r"]], "c": "26290909"}, "book-100", "XBT/USD"]
[270, {"a": [["11681.20000", "0.27489197", "1596666772.585513"]], "c": "26290909"}, "book-100", "XBT/USD"]
[270, {"a": [["11684.70000", "0.34871387", "1596666772.594236"]], "c": "26290909"}, "book-100", "XBT/USD"]
[270, {"a": [["11710.40000", "1.16811308", "1596666772.597033"]], "c": "26290909"}, "book-100", "XBT/USD"]
[270, {"a": [["11689.40000", "0.57265674", "1596666772.607952"]], "c": "26290909"}, "book-100", "XBT/USD"]
[270, {"a": [["11706.80000", "0.00000000", "1596666772.636108"], ["11711.10000", "2.97327583", "1596666728.385477", "r"]], "c": "26290909"}, "book-100", "XBT/USD"]
[270, {"a": [["11671.60000", "0.00000000", "1596666772.636298"], ["11711.20000", "0.89630055", "1596666591.787115", "r"]], "c": "26290909"}, "book-100", "XBT/USD"]
[270, {"a": [["11665.70000", "0.00000000", "1596666772.650672"], ["11713.80000", "0.37309062", "1596666771.863547", "r"]], "c": "3894497466"}, "book-100", "XBT/USD"]
[270, {"b": [["11648.00000", "0.00000000", "1596666772.721222"], ["11602.80000", "0.75800000", "1596666731.483110", "r"]], "c": "3894497466"}, "book-100", "XBT/USD"]
[270, {"a": [["11675.60000", "1.30703706", "1596666772.739231"]], "c": "3894497466"}, "book-100", "XBT/USD"]
[270, {"a": [["11665.50000", "0.00000000", "1596666772.740534"], ["11713.80000", "0.37309062", "1596666771.863547", "r"]], "c": "2089985757"}, "book-100", "XBT/USD"]
[270, {"b": [["11635.20000", "4.80965334", "1596666772.809762"]], "c": "2089985757"}, "book-100", "XBT/USD"]
[270, {"a": [["11671.70000", "0.00000000", "1596666772.889537"], ["11715.30000", "6.10000000", "1596666635.445451", "r"]], "c": "2089985757"}, "book-100", "XBT/USD"]
[270, {"a": [["11701.30000", "0.43900000", "1596666772.935856"]], "c": "2089985757"}, "book-100", "XBT/USD"]
[270, {"a": [["11667.00000", "0.53008443", "1596666772.978946"]], "c": "2441354451"}, "book-100", "XBT/USD"]
[270, {"a": [["11667.00000", "0.42708443", "1596666773.021581"]], "c": "1218660566"}, "book-100", "XBT/USD"]
[270, {"b": [["11642.10000", "0.71264393", "1596666773.053920"]], "c": "1218660566"}, "book-100", "XBT/USD"]
[270, {"b": [["11645.50000", "0.33925517", "1596666773.059099"]], "c": "1218660566"}, "book-100", "XBT/USD"]
[270, {"b": [["11654.70000", "0.01491968", "1596666773.133003"]], "c": "4090314347"}, "book-100", "XBT/USD"]
[270, {"b": [["11654.70000", "0.00000000", "1596666773.133837"], ["11603.10000", "0.00858405", "1596666739.130412", "r"]], "c": "2161921084"}, "book-100", "XBT/USD"]
[270, {"a": [["11675.60000", "0.00000000", "1596666773.164905"], ["11715.30000", "6.10000000", "1596666635.445451", "r"]], "c": "2161921084"}, "book-100", "XBT/USD"]
[270, {"a": [["11676.40000", "0.53552475", "1596666773.181158"]], "c": "2161921084"}, "book-100", "XBT/USD"]
[270, {"a": [["11692.20000", "0.53894935", "1596666773.181216"]], "c": "2161921084"}, "book-100", "XBT/USD"]
[270, {"a": [["11683.80000", "0.00000000", "1596666773.182562"], ["11713.80000", "0.37309062", "1596666771.863547", "r"]], "c": "2161921084"}, "book-100", "XBT/USD"]
[270, {"b": [["11622.00000", "0.00000000", "1596666773.184029"], ["11602.80000", "0.75800000", "1596666731.483110", "r"]], "c": "2161921084"}, "book-100", "XBT/USD"]
[270, {"b": [["11643.20000", "0.00000000", "1596666773.192817"], ["11602.30000", "2.01774694", "1596666748.156295", "r"]], "c": "2161921084"}, "book-100", "XBT/USD"]
[270, {"b": [["11658.70000", "0.64293414", "1596666773.203242"]], "c": "4200970971"}, "book-100", "XBT/USD"]
[270, {"b": [["11656.60000", "2.24982995", "1596666773.204587"]], "c": "1743490756"}, "book-100", "XBT/USD"]
[270, {"b": [["11658.80000", "0.64293414", "1596666773.204675"]], "c": "3417628700"}, "book-100", "XBT/USD"]
[270, {"a": [["11673.40000", "0.85724552", "1596666773.205288"]], "c": "3417628700"}, "book-100", "XBT/USD"]
[270, {"a": [["11671.50000", "0.64292366", "1596666773.206046"]], "c": "3417628700"}, "book-100", "XBT/USD"]
[270, {"b": [["11658.90000", "10.01700994", "1596666773.210473"]], "c": "2159280520"}, "book-100", "XBT/USD"]
[270, {"b": [["11656.50000", "10.85711555", "1596666773.235767"]], "c": "715052618"}, "book-100", "XBT/USD"]
[270, {"a": [["11673.80000", "1.32472781", "1596666773.243270"]], "c": "715052618"}, "book-100", "XBT/USD"]
[270, {"b": [["11635.20000", "1.79965334", "1596666773.541666"]], "c": "715052618"}, "book-100", "XBT/USD"]
[270, {"a": [["11666.20000", "0.51352978", "1596666773.603412"]], "c": "3306807925"}, "book-100", "XBT/USD"]
[270, {"a": [["11679.00000", "2.81376623", "1596666773.611156"]], "c": "3306807925"}, "book-100", "XBT/USD"]
[271, [["11659.00000", "0.01078477", "1596666773.840075", "b", "m", ""]], "trade", "XBT/USD"]
[270, {"a": [["11659.00000", "1.54991523", "1596666773.840075"]], "c": "147520815"}, "book-100", "XBT/USD"]
[270, {"a": [["11670.00000", "0.00000000", "1596666773.867853"], ["11711.10000", "2.97327583", "1596666728.385477", "r"]], "c": "147520815"}, "book-100", "XBT/USD"]
[270, {"b": [["11654.20000", "0.89964000", "1596666773.888025"]], "c": "147520815"}, "book-100", "XBT/USD"]
[270, {"a": [["11674.50000", "0.09800000", "1596666773.925668"]], "c": "147520815"}, "book-100", "XBT/USD"]
[270, {"a": [["11683.00000", "3.52997363", "1596666773.938696"]], "c": "147520815"}, "book-100", "XBT/USD"]
[270, {"a": [["11709.90000", "3.52186457", "1596666773.954225"]], "c": "147520815"}, "book-100", "XBT/USD"]
[270, {"b": [["11658.90000", "10.24700994", "1596666773.955780"]], "c": "990100040"}, "book-100", "XBT/USD"]
[270, {"a": [["11698.20000", "3.52538698", "1596666773.961151"]], "c": "990100040"}, "book-100", "XBT/USD"]
[270, {"a": [["11668.30000", "0.00000000", "1596666773.970604"], ["11710.60000", "2.80039129", "1596666770.582883", "r"]], "c": "3251871071"}, "book-100", "XBT/USD"]
[270, {"b": [["11657.40000", "0.09900000", "1596666774.050517"]], "c": "3713617679"}, "book-100", "XBT/USD"]
[270, {"b": [["11603.10000", "0.00000000", "1596666774.057567"], ["11602.80000", "0.75800000", "1596666731.483110", "r"]], "c": "3713617679"}, "book-100", "XBT/USD"]
[270, {"a": [["11665.40000", "0.00000000", "1596666774.079630"], ["11710.70000", "3.52183532", "1596666711.393054", "r"]], "c": "3494066279"}, "book-100", "XBT/USD"]
[270, {"a": [["11665.20000", "0.00630420", "1596666774.079760"]], "c": "3550744664"}, "book-100", "XBT/USD"]
[270, {"a": [["11667.90000", "1.50000000", "1596666774.119511"]], "c": "3150167461"}, "book-100", "XBT/USD"]
[270, {"a": [["11676.50000", "0.00000000", "1596666774.150351"], ["11710.60000", "2.80039129", "1596666770.582883", "r"]], "c": "3150167461"}, "book-100", "XBT/USD"]
[270, {"b": [["11658.90000", "10.33278096", "1596666774.168600"]], "c": "1302194360"}, "book-100", "XBT/USD"]
[270, {"b": [["11609.60000", "0.00000000", "1596666774.182808"], ["11602.30000", "2.01774694", "1596666748.156295", "r"]], "c": "1302194360"}, "book-100", "XBT/USD"]
[270, {"b": [["11655.80000", "2.00000000", "1596666774.326034"]], "c": "2783447123"}, "book-100", "XBT/USD"]
[270, {"b": [["11658.90000", "10.48278096", "1596666774.341963"]], "c": "2390743821"}, "book-100", "XBT/USD"]
[270, {"a": [["11680.10000", "0.00000000", "1596666774.351953"], ["11710.70000", "3.52183532", "1596666711.393054", "r"]], "c": "2390743821"}, "book-100", "XBT/USD"]
[270, {"a": [["11676.50000", "0.69497565", "1596666774.400883"]], "c": "2390743821"}, "book-100", "XBT/USD"]
[270, {"a": [["11665.30000", "0.00000000", "1596666774.487098"], ["11710.70000", "3.52183532", "1596666711.393054", "r"]], "c": "1797032413"}, "book-100", "XBT/USD"]
[270, {"a": [["11673.80000", "0.00000000", "1596666774.536137"], ["11711.00000", "3.52207482", "1596666594.088624", "r"]], "c": "1797032413"}, "book-100", "XBT/USD"]
[270, {"a": [["11665.50000", "0.25844835", "1596666774.585160"]], "c": "2577465193"}, "book-100", "XBT/USD"]
[270, {"b": [["11658.90000", "11.48278096", "1596666774.621056"]], "c": "3283832628"}, "book-100", "XBT/USD"]
[270, {"b": [["11651.30000", "1.70460000", "1596666774.638360"]], "c": "3283832628"}, "book-100", "XBT/USD"]
[270, {"a": [["11665.20000", "0.00000000", "1596666774.647096"], ["11711.00000", "3.52207482", "1596666594.088624", "r"]], "c": "76537690"}, "book-100", "XBT/USD"]
[270, {"a": [["11665.50000", "0.26475239", "1596666774.650791"]], "c": "3673380656"}, "book-100", "XBT/USD"]
[270, {"a": [["11686.70000", "3.19723263", "1596666774.667973"]], "c": "3673380656"}, "book-100", "XBT/USD"]
[270, {"a": [["11698.40000", "6.38806991", "1596666774.672253"]], "c": "3673380656"}, "book-100", "XBT/USD"]
[270, {"b": [["11655.00000", "0.00000000", "1596666774.676023"], ["11602.80000", "0.75800000", "1596666731.483110", "r"]], "c": "3212765156"}, "book-100", "XBT/USD"]
[270, {"a": [["11685.90000", "0.00000000", "1596666774.686130"], ["11710.70000", "3.52183532", "1596666711.393054", "r"]], "c": "3212765156"}, "book-100", "XBT/USD"]
[270, {"a": [["11679.00000", "2.10331641", "1596666774.696801"]], "c": "3212765156"}, "book-100", "XBT/USD"]
[270, {"b": [["11655.70000", "0.00000000", "1596666774.707593"], ["11602.30000", "2.01774694", "1596666748.156295", "r"]], "c": "1759322134"}, "book-100", "XBT/USD"]
[270, {"a": [["11682.10000", "0.00000000", "1596666774.717499"], ["11711.00000", "3.52207482", "1596666594.088624", "r"]], "c": "1759322134"}, "book-100", "XBT/USD"]
[270, {"a": [["11674.90000", "0.00000000", "1596666774.721563"], ["11711.10000", "2.97327583", "1596666728.385477", "r"]], "c": "1759322134"}, "book-100", "XBT/USD"]
[270, {"a": [["11675.70000", "7.07099978", "1596666774.722007"]], "c": "1759322134"}, "book-100", "XBT/USD"]
[270, {"a": [["11683.90000", "0.00000000", "1596666774.724723"], ["11711.20000", "0.89630055", "1596666591.787115", "r"]], "c": "1759322134"}, "book-100", "XBT/USD"]
[270, {"a": [["11673.00000", "2.15095957", "1596666774.786368"]], "c": "1759322134"}, "book-100", "XBT/USD"]
[270, {"b": [["11647.20000", "0.00000000", "1596666774.865552"], ["11602.20000", "2.01681621", "1596666634.588713", "r"]], "c": "1759322134"}, "book-100", "XBT/USD"]
[270, {"a": [["11670.20000", "0.09621094", "1596666774.878700"]], "c": "1759322134"}, "book-100", "XBT/USD"]
[270, {"b": [["11658.30000", "0.09621094", "1596666774.903897"]], "c": "3446853738"}, "book-100", "XBT/USD"]
[270, {"a": [["11676.50000", "0.00000000", "1596666774.904121"], ["11711.20000", "0.89630055", "1596666591.787115", "r"]], "c": "3446853738"}, "book-100", "XBT/USD"]
[270, {"a": [["11673.00000", "0.85780998", "1596666774.921423"]], "c": "3446853738"}, "book-100", "XBT/USD"]
[270, {"b": [["11656.60000", "0.85724552", "1596666774.922587"]], "c": "3643944115"}, "book-100", "XBT/USD"]
[270, {"a": [["11691.40000", "4.42361818", "1596666774.950292"]], "c": "3643944115"}, "book-100", "XBT/USD"]
[270, {"b": [["11655.40000", "1.00000000", "1596666775.045813"]], "c": "1737742668"}, "book-100", "XBT/USD"]
[270, {"a": [["11677.40000", "0.49270611", "1596666775.099460"]], "c": "1737742668"}, "book-100", "XBT/USD"]
[270, {"b": [["11651.30000", "0.00000000", "1596666775.120804"], ["11602.30000", "2.01774694", "1596666748.156295", "r"]], "c": "1737742668"}, "book-100", "XBT/USD"]
[270, {"a": [["11678.50000", "0.64594479", "1596666775.151325"]], "c": "1737742668"}, "book-100", "XBT/USD"]
[270, {"a": [["11677.40000", "0.83103452", "1596666775.178032"]], "c": "1737742668"}, "book-100", "XBT/USD"]
[270, {"b": [["11657.50000", "0.12500000", "1596666775.181171"]], "c": "801066828"}, "book-100", "XBT/USD"]
[270, {"a": [["11680.80000", "1.56774625", "1596666775.219090"]], "c": "801066828"}, "book-100", "XBT/USD"]
[270, {"a": [["11696.80000", "2.03751523", "1596666775.273662"]], "c": "801066828"}, "book-100", "XBT/USD"]
[270, {"a": [["11688.90000", "7.07163183", "1596666775.275733"]], "c": "801066828"}, "book-100", "XBT/USD"]
[270, {"b": [["11656.70000", "1.36398173", "1596666775.323373"]], "c": "97109367"}, "book-100", "XBT/USD"]
[270, {"a": [["11675.60000", "1.32902964", "1596666775.323641"]], "c": "97109367"}, "book-100", "XBT/USD"]
[270, {"b": [["11657.50000", "0.08250000", "1596666775.365241"]], "c": "974440751"}, "book-100", "XBT/USD"]
[270, {"a": [["11678.50000", "0.00000000", "1596666775.403462"], ["11711.00000", "3.52207482", "1596666594.088624", "r"]], "c": "974440751"}, "book-100", "XBT/USD"]
[270, {"b": [["11648.90000", "0.38000000", "1596666775.462562"]], "c": "974440751"}, "book-100", "XBT/USD"]
[270, {"b": [["11617.40000", "0.75800000", "1596666775.482846"]], "c": "974440751"}, "book-100", "XBT/USD"]
[270, {"a": [["11694.80000", "2.00114567", "1596666775.536547"]], "c": "974440751"}, "book-100", "XBT/USD"]
[270, {"b": [["11658.90000", "11.23278096", "1596666775.564632"]], "c": "175250263"}, "book-100", "XBT/USD"]
[270, {"a": [["11679.10000", "1.57983525", "1596666775.650465"]], "c": "175250263"}, "book-100", "XBT/USD"]
[270, {"b": [["11658.90000", "11.48278096", "1596666775.796203"]], "c": "974440751"}, "book-100", "XBT/USD"]
[270, {"b": [["11631.60000", "0.00000000", "1596666776.003937"], ["11604.00000", "0.17085000", "1596666711.074347", "r"]], "c": "974440751"}, "book-100", "XBT/USD"]
[270, {"a": [["11665.50000", "0.25844835", "1596666776.214867"]], "c": "2029993461"}, "book-100", "XBT/USD"]
[270, {"a": [["11675.50000", "1.20668269", "1596666776.227887"]], "c": "2029993461"}, "book-100", "XBT/USD"]
[270, {"b": [["11649.70000", "4.00000000", "1596666776.238008"]], "c": "2029993461"}, "book-100", "XBT/USD"]
[270, {"a": [["11675.60000", "0.00000000", "1596666776.340230"], ["11711.00000", "3.52207482", "1596666594.088624", "r"]], "c": "2029993461"}, "book-100", "XBT/USD"]
[270, {"b": [["11606.60000", "0.36139355", "1596666776.377050"]], "c": "2029993461"}, "book-100", "XBT/USD"]
[270, {"a": [["11679.10000", "0.89623000", "1596666776.410256"]], "c": "2029993461"}, "book-100", "XBT/USD"]
[270, {"b": [["11644.70000", "0.00000000", "1596666776.464659"], ["11604.10000", "1.51500000", "1596666763.121463", "r"]], "c": "2029993461"}, "book-100", "XBT/USD"]
[270, {"a": [["11675.60000", "0.01036696", "1596666776.472313"]], "c": "2029993461"}, "book-100", "XBT/USD"]
[270, {"a": [["11675.50000", "1.19951679", "1596666776.472389"]], "c": "2029993461"}, "book-100", "XBT/USD"]
[270, {"a": [["11673.00000", "2.22242711", "1596666776.519736"]], "c": "2029993461"}, "book-100", "XBT/USD"]
[270, {"a": [["11679.90000", "0.00000000", "1596666776.612412"], ["11711.00000", "3.52207482", "1596666594.088624", "r"]], "c": "2029993461"}, "book-100", "XBT/USD"]
[270, {"a": [["11678.30000", "0.68385410", "1596666776.660302"]], "c": "2029993461"}, "book-100", "XBT/USD"]
[270, {"b": [["11619.30000", "0.00000000", "1596666776.694989"], ["11604.00000", "0.17085000", "1596666711.074347", "r"]], "c": "2029993461"}, "book-100", "XBT/USD"]
[270, {"a": [["11665.50000", "0.00000000", "1596666776.756219"], ["11711.00000", "3.52207482", "1596666594.088624", "r"]], "c": "4012924140"}, "book-100", "XBT/USD"]
[270, {"a": [["11685.80000", "6.23108509", "1596666776.774596"]], "c": "4012924140"}, "book-100", "XBT/USD"]
[270, {"b": [["11624.80000", "5.94771703", "1596666776.852092"]], "c": "4012924140"}, "book-100", "XBT/USD"]
[270, {"a": [["11665.80000", "0.25844025", "1596666776.857735"]], "c": "1886345829"}, "book-100", "XBT/USD"]
[270, {"b": [["11618.70000", "0.00000000", "1596666776.986879"], ["11604.00000", "0.17085000", "1596666711.074347", "r"]], "c": "1886345829"}, "book-100", "XBT/USD"]
[270, {"a": [["11679.00000", "2.00000000", "1596666777.004976"]], "c": "1886345829"}, "book-100", "XBT/USD"]
[270, {"b": [["11618.50000", "0.00000000", "1596666777.010356"], ["11602.30000", "2.01774694", "1596666748.156295", "r"]], "c": "1886345829"}, "book-100", "XBT/USD"]
[270, {"a": [["11681.30000", "0.00000000", "1596666777.010852"], ["11710.70000", "3.52183532", "1596666711.393054", "r"]], "c": "1886345829"}, "book-100", "XBT/USD"]
[270, {"a": [["11696.80000", "0.05290732", "1596666777.011404"]], "c": "1886345829"}, "book-100", "XBT/USD"]
[270, {"b": [["11638.80000", "0.00000000", "1596666777.011484"], ["11602.20000", "2.01681621", "1596666634.588713", "r"]], "c": "1886345829"}, "book-100", "XBT/USD"]
[270, {"b": [["11641.00000", "0.00000000", "1596666777.011584"], ["11602.10000", "7.70000000", "1596666410.902600", "r"]], "c": "1886345829"}, "book-100", "XBT/USD"]
[270, {"b": [["11622.90000", "0.00000000", "1596666777.012489"], ["11602.00000", "1.06000000", "1596666760.274147", "r"]], "c": "1886345829"}, "book-100", "XBT/USD"]
[270, {"a": [["11684.00000", "0.00000000", "1596666777.017561"], ["11711.00000", "3.52207482", "1596666594.088624", "r"]], "c": "1886345829"}, "book-100", "XBT/USD"]
[270, {"b": [["11641.80000", "0.00000000", "1596666777.017876"], ["11601.00000", "0.17085000", "1596666771.979393", "r"]], "c": "1886345829"}, "book-100", "XBT/USD"]
[270, {"a": [["11677.40000", "0.49270611", "1596666777.019481"]], "c": "1886345829"}, "book-100", "XBT/USD"]
[270, {"b": [["11638.40000", "0.00000000", "1596666777.020297"], ["11600.10000", "0.05000000", "1596666747.910313", "r"]], "c": "1886345829"}, "book-100", "XBT/USD"]
[270, {"b": [["11631.00000", "0.00000000", "1596666777.021005"], ["11600.00000", "0.02931034", "1596666720.289823", "r"]], "c": "1886345829"}, "book-100", "XBT/USD"]
[270, {"a": [["11684.70000", "0.00000000", "1596666777.021283"], ["11711.10000", "2.97327583", "1596666728.385477", "r"]], "c": "1886345829"}, "book-100", "XBT/USD"]
[270, {"a": [["11681.20000", "0.02573600", "1596666777.022549"]], "c": "1886345829"}, "book-100", "XBT/USD"]
[270, {"a": [["11677.40000", "0.38000000", "1596666777.023426"]], "c": "1886345829"}, "book-100", "XBT/USD"]
[270, {"a": [["11683.00000", "0.00000000", "1596666777.024878"], ["11711.20000", "0.89630055", "1596666591.787115", "r"]], "c": "1886345829"}, "book-100", "XBT/USD"]
[270, {"b": [["11640.70000", "0.00000000", "1596666777.025558"], ["11598.60000", "5.85498227", "1596666746.869996", "r"]], "c": "1886345829"}, "book-100", "XBT/USD"]
[270, {"b": [["11645.50000", "0.00000000", "1596666777.025938"], ["11596.40000", "4.31168293", "1596666764.100846", "r"]], "c": "1886345829"}, "book-100", "XBT/USD"]
[270, {"a": [["11680.80000", "0.85746341", "1596666777.027243"]], "c": "1886345829"}, "book-100", "XBT/USD"]
[270, {"a": [["11691.60000", "0.00000000", "1596666777.027497"], ["11713.80000", "0.37309062", "1596666771.863547", "r"]], "c": "1886345829"}, "book-100", "XBT/USD"]
[270, {"b": [["11642.10000", "0.00000000", "1596666777.028797"], ["11595.50000", "7.80000000", "1596666735.579667", "r"]], "c": "1886345829"}, "book-100", "XBT/USD"]
[270, {"a": [["11683.40000", "0.00000000", "1596666777.029117"], ["11715.30000", "6.10000000", "1596666635.445451", "r"]], "c": "1886345829"}, "book-100", "XBT/USD"]
[270, {"b": [["11619.50000", "0.00000000", "1596666777.031500"], ["11595.20000", "2.01970706", "1596666763.756520", "r"]], "c": "1886345829"}, "book-100", "XBT/USD"]
[270, {"b": [["11619.20000", "0.00000000", "1596666777.031911"], ["11593.60000", "18.30000000", "1596666774.492313", "r"]], "c": "1886345829"}, "book-100", "XBT/USD"]
[270, {"b": [["11642.70000", "0.00000000", "1596666777.032033"], ["11593.00000", "0.95780000", "1596666771.513632", "r"]], "c": "1886345829"}, "book-100", "XBT/USD"]
[270, {"a": [["11681.00000", "0.00000000", "1596666777.033770"], ["11717.80000", "1.99812614", "1596666759.535617", "r"]], "c": "1886345829"}, "book-100", "XBT/USD"]
[270, {"a": [["11673.00000", "0.85780998", "1596666777.039939"]], "c": "1886345829"}, "book-100", "XBT/USD"]
[270, {"b": [["11630.70000", "0.00000000", "1596666777.046287"], ["11592.90000", "0.80800000", "1596666471.264849", "r"]], "c": "1886345829"}, "book-100", "XBT/USD"]
[270, {"b": [["11631.50000", "0.00000000", "1596666777.050380"], ["11589.90000", "6.90000000", "1596666166.290818", "r"]], "c": "1886345829"}, "book-100", "XBT/USD"]
[270, {"b": [["11620.30000", "0.00000000", "1596666777.056056"], ["11589.00000", "3.54547328", "1596666762.265610", "r"]], "c": "1886345829"}, "book-100", "XBT/USD"]
[270, {"b": [["11625.30000", "1.97109902", "1596666777.205009"]], "c": "1886345829"}, "book-100", "XBT/USD"]
[270, {"b": [["11642.70000", "1.42521440", "1596666777.205608"]], "c": "1886345829"}, "book-100", "XBT/USD"]
[270, {"a": [["11680.30000", "0.11270498", "1596666777.240536"]], "c": "1886345829"}, "book-100", "XBT/USD"]
[270, {"a": [["11686.20000", "0.72228665", "1596666777.250470"]], "c": "1886345829"}, "book-100", "XBT/USD"]
[270, {"a": [["11683.80000", "0.10320500", "1596666777.250547"]], "c": "1886345829"}, "book-100", "XBT/USD"]
[270, {"b": [["11625.90000", "1.51429725", "1596666777.254056"]], "c": "1886345829"}, "book-100", "XBT/USD"]
[270, {"b": [["11643.30000", "0.72494793", "1596666777.255217"]], "c": "1886345829"}, "book-100", "XBT/USD"]
[270, {"b": [["11608.30000", "0.74907470", "1596666777.267520"]], "c": "1886345829"}, "book-100", "XBT/USD"]
[270, {"a": [["11685.40000", "0.74907470", "1596666777.274309"]], "c": "1886345829"}, "book-100", "XBT/USD"]
[270, {"a": [["11675.50000", "0.50000000", "1596666777.279171"]], "c": "1886345829"}, "book-100", "XBT/USD"]
[270, {"b": [["11635.70000", "0.00000000", "1596666777.286943"], ["11593.60000", "18.30000000", "1596666774.492313", "r"]], "c": "1886345829"}, "book-100", "XBT/USD"]
[270, {"b": [["11613.80000", "0.00000000", "1596666777.287735"], ["11593.00000", "0.95780000", "1596666771.513632", "r"]], "c": "1886345829"}, "book-100", "XBT/USD"]
[270, {"b": [["11602.30000", "0.00000000", "1596666777.301385"], ["11592.90000", "0.80800000", "1596666471.264849", "r"]], "c": "1886345829"}, "book-100", "XBT/USD"]
[270, {"b": [["11644.40000", "0.24994338", "1596666777.322500"]], "c": "1886345829"}, "book-100", "XBT/USD"]
[270, {"b": [["11629.30000", "0.90096451", "1596666777.323540"]], "c": "1886345829"}, "book-100", "XBT/USD"]
[270, {"a": [["11686.20000", "0.97133602", "1596666777.324494"]], "c": "1886345829"}, "book-100", "XBT/USD"]
[270, {"a": [["11689.70000", "0.34856472", "1596666777.324883"]], "c": "1886345829"}, "book-100", "XBT/USD"]
[270, {"a": [["11703.70000", "1.48735197", "1596666777.331546"]], "c": "1886345829"}, "book-100", "XBT/USD"]
[270, {"b": [["11626.30000", "1.49725375", "1596666777.333312"]], "c": "1886345829"}, "book-100", "XBT/USD"]
[270, {"b": [["11641.40000", "0.49843722", "1596666777.333379"]], "c": "1886345829"}, "book-100", "XBT/USD"]
[270, {"b": [["11603.20000", "2.50039088", "1596666777.334144"]], "c": "1886345829"}, "book-100", "XBT/USD"]
[270, {"a": [["11688.50000", "0.49642872", "1596666777.334923"]], "c": "1886345829"}, "book-100", "XBT/USD"]
[270, {"b": [["11635.60000", "0.99737136", "1596666777.339165"]], "c": "1886345829"}, "book-100", "XBT/USD"]
[270, {"b": [["11658.90000", "11.58278096", "1596666777.352478"]], "c": "3853038325"}, "book-100", "XBT/USD"]
[270, {"b": [["11629.90000", "0.00000000", "1596666777.357966"], ["11596.40000", "4.31168293", "1596666764.100846", "r"]], "c": "3853038325"}, "book-100", "XBT/USD"]
[270, {"a": [["11675.60000", "1.39485622", "1596666777.374440"]], "c": "3853038325"}, "book-100", "XBT/USD"]
[270, {"b": [["11610.10000", "0.00000000", "1596666777.440097"], ["11595.50000", "7.80000000", "1596666735.579667", "r"]], "c": "3853038325"}, "book-100", "XBT/USD"]
[270, {"b": [["11640.20000", "0.00000000", "1596666777.441088"], ["11595.20000", "2.01970706", "1596666763.756520", "r"]], "c": "3853038325"}, "book-100", "XBT/USD"]
[270, {"b": [["11621.70000", "0.00000000", "1596666777.443131"], ["11593.60000", "18.30000000", "1596666774.492313", "r"]], "c": "3853038325"}, "book-100", "XBT/USD"]
[270, {"b": [["11598.60000", "2.29920000", "1596666777.443905"]], "c": "3853038325"}, "book-100", "XBT/USD"]
[270, {"b": [["11639.10000", "0.00000000", "1596666777.566644"], ["11593.00000", "0.95780000", "1596666771.513632", "r"]], "c": "3853038325"}, "book-100", "XBT/USD"]
[270, {"b": [["11610.70000", "0.00000000", "1596666777.570566"], ["11592.90000", "0.80800000", "1596666471.264849", "r"]], "c": "3853038325"}, "book-100", "XBT/USD"]
[270, {"b": [["11624.60000", "0.00000000", "1596666777.570952"], ["11589.90000", "6.90000000", "1596666166.290818", "r"]], "c": "3853038325"}, "book-100", "XBT/USD"]
[270, {"b": [["11639.90000", "2.01058414", "1596666777.585467"]], "c": "3853038325"}, "book-100", "XBT/USD"]
[270, {"b": [["11635.20000", "0.00000000", "1596666777.733064"], ["11589.90000", "6.90000000", "1596666166.290818", "r"]], "c": "3853038325"}, "book-100", "XBT/USD"]
[270, {"b": [["11644.90000", "1.22619537", "1596666777.737032"]], "c": "3853038325"}, "book-100", "XBT/USD"]
[270, {"b": [["11625.30000", "0.00000000", "1596666777.743220"], ["11589.90000", "6.90000000", "1596666166.290818", "r"]], "c": "3853038325"}, "book-100", "XBT/USD"]
[270, {"b": [["11606.90000", "0.00000000", "1596666777.744127"], ["11589.00000", "3.54547328", "1596666762.265610", "r"]], "c": "3853038325"}, "book-100", "XBT/USD"]
[270, {"b": [["11642.70000", "0.00000000", "1596666777.746373"], ["11587.00000", "3.55934204", "1596666746.867590", "r"]], "c": "3853038325"}, "book-100", "XBT/USD"]
[270, {"a": [["11672.10000", "2.88885326", "1596666777.748426"]], "c": "3853038325"}, "book-100", "XBT/USD"]
[270, {"b": [["11626.30000", "0.00000000", "1596666777.749554"], ["11586.20000", "3.00500211", "1596666626.428727", "r"]], "c": "3853038325"}, "book-100", "XBT/USD"]
[270, {"b": [["11641.40000", "0.00000000", "1596666777.753610"], ["11585.90000", "1.48215236", "1596666745.788273", "r"]], "c": "3853038325"}, "book-100", "XBT/USD"]
[270, {"b": [["11635.60000", "0.00000000", "1596666777.756843"], ["11585.50000", "0.00509766", "1596666166.036585", "r"]], "c": "3853038325"}, "book-100", "XBT/USD"]
[270, {"b": [["11616.70000", "2.01459953", "1596666777.763006"]], "c": "3853038325"}, "book-100", "XBT/USD"]
[270, {"b": [["11645.70000", "2.00958279", "1596666777.765048"]], "c": "3853038325"}, "book-100", "XBT/USD"]
[270, {"b": [["11642.60000", "0.00000000", "1596666777.765416"], ["11585.90000", "1.48215236", "1596666745.788273", "r"]], "c": "3853038325"}, "book-100", "XBT/USD"]
[270, {"b": [["11607.70000", "8.40000000", "1596666777.775135"]], "c": "3853038325"}, "book-100", "XBT/USD"]
[270, {"a": [["11686.20000", "1.86927587", "1596666777.789168"]], "c": "3853038325"}, "book-100", "XBT/USD"]
[270, {"b": [["11644.40000", "1.15110657", "1596666777.798512"]], "c": "3853038325"}, "book-100", "XBT/USD"]
[270, {"a": [["11667.00000", "0.00000000", "1596666777.832546"], ["11710.60000", "2.80039129", "1596666770.582883", "r"]], "c": "477799765"}, "book-100", "XBT/USD"]
[270, {"b": [["11636.00000", "2.06000000", "1596666777.835869"]], "c": "477799765"}, "book-100", "XBT/USD"]
[270, {"a": [["11683.80000", "0.81330547", "1596666777.847326"]], "c": "477799765"}, "book-100", "XBT/USD"]
[270, {"a": [["11692.00000", "1.79090142", "1596666777.847630"]], "c": "477799765"}, "book-100", "XBT/USD"]
[270, {"b": [["11653.40000", "0.71195289", "1596666777.849269"]], "c": "477799765"}, "book-100", "XBT/USD"]
[270, {"a": [["11680.40000", "0.33824151", "1596666777.852463"]], "c": "477799765"}, "book-100", "XBT/USD"]
[270, {"b": [["11656.80000", "0.33892630", "1596666777.855997"]], "c": "2758941344"}, "book-100", "XBT/USD"]
[270, {"b": [["11622.00000", "0.17085000", "1596666777.873179"]], "c": "2758941344"}, "book-100", "XBT/USD"]
[270, {"a": [["11675.40000", "0.00000000", "1596666777.884091"], ["11710.40000", "1.16811308", "1596666772.597033", "r"]], "c": "2758941344"}, "book-100", "XBT/USD"]
[270, {"a": [["11675.60000", "1.38448926", "1596666777.889153"]], "c": "2758941344"}, "book-100", "XBT/USD"]
[270, {"a": [["11675.60000", "1.39165510", "1596666777.891348"]], "c": "2758941344"}, "book-100", "XBT/USD"]
[270, {"b": [["11636.60000", "0.00000000", "1596666777.952779"], ["11589.00000", "3.54547328", "1596666762.265610", "r"]], "c": "2758941344"}, "book-100", "XBT/USD"]
[270, {"b": [["11649.60000", "0.00000000", "1596666777.988502"], ["11587.00000", "3.55934204", "1596666746.867590", "r"]], "c": "2758941344"}, "book-100", "XBT/USD"]
[270, {"a": [["11682.50000", "0.00000000", "1596666777.993688"], ["11710.60000", "2.80039129", "1596666770.582883", "r"]], "c": "2758941344"}, "book-100", "XBT/USD"]
[270, {"b": [["11600.40000", "0.90458128", "1596666777.993986"]], "c": "2758941344"}, "book-100", "XBT/USD"]
[270, {"b": [["11623.50000", "0.90278356", "1596666778.009912"]], "c": "2758941344"}, "book-100", "XBT/USD"]
[270, {"b": [["11649.80000", "0.03905899", "1596666778.010188"]], "c": "2758941344"}, "book-100", "XBT/USD"]
[270, {"b": [["11637.40000", "0.90170525", "1596666778.010279"]], "c": "2758941344"}, "book-100", "XBT/USD"]
[270, {"b": [["11652.50000", "0.90053677", "1596666778.010920"]], "c": "2758941344"}, "book-100", "XBT/USD"]
[270, {"b": [["11649.00000", "0.90080734", "1596666778.011227"]], "c": "2758941344"}, "book-100", "XBT/USD"]
[270, {"a": [["11681.40000", "0.00000000", "1596666778.025198"], ["11710.70000", "3.52183532", "1596666711.393054", "r"]], "c": "2758941344"}, "book-100", "XBT/USD"]
[270, {"a": [["11668.20000", "0.41231858", "1596666778.081277"]], "c": "1443421363"}, "book-100", "XBT/USD"]
[270, {"b": [["11645.60000", "0.10354354", "1596666778.106808"]], "c": "1443421363"}, "book-100", "XBT/USD"]
[270, {"b": [["11640.90000", "0.35002594", "1596666778.111956"]], "c": "1443421363"}, "book-100", "XBT/USD"]
[270, {"b": [["11628.30000", "2.01258983", "1596666778.116930"]], "c": "1443421363"}, "book-100", "XBT/USD"]
[270, {"a": [["11677.90000", "0.69944195", "1596666778.118339"]], "c": "1443421363"}, "book-100", "XBT/USD"]
[270, {"b": [["11644.90000", "0.00000000", "1596666778.120596"], ["11596.40000", "4.31168293", "1596666764.100846", "r"]], "c": "1443421363"}, "book-100", "XBT/USD"]
[270, {"b": [["11649.80000", "0.05598269", "1596666778.140777"]], "c": "1443421363"}, "book-100", "XBT/USD"]
[270, {"b": [["11653.20000", "0.85766386", "1596666778.144971"]], "c": "1443421363"}, "book-100", "XBT/USD"]
[270, {"b": [["11649.80000", "0.01692370", "1596666778.147183"]], "c": "1443421363"}, "book-100", "XBT/USD"]
[270, {"a": [["11689.70000", "1.24623572", "1596666778.235644"]], "c": "1443421363"}, "book-100", "XBT/USD"]
[270, {"b": [["11645.00000", "1.14385175", "1596666778.266046"]], "c": "1443421363"}, "book-100", "XBT/USD"]
[270, {"a": [["11702.20000", "0.00000000", "1596666778.363923"], ["11710.60000", "2.80039129", "1596666770.582883", "r"]], "c": "1443421363"}, "book-100", "XBT/USD"]
[270, {"b": [["11656.70000", "0.00000000", "1596666778.397903"], ["11596.40000", "4.31168293", "1596666764.100846", "r"]], "c": "3321182319"}, "book-100", "XBT/USD"]
[270, {"a": [["11693.10000", "1.02430000", "1596666778.415300"]], "c": "3321182319"}, "book-100", "XBT/USD"]
[270, {"b": [["11612.40000", "0.00000000", "1596666778.415471"], ["11595.50000", "7.80000000", "1596666735.579667", "r"]], "c": "3321182319"}, "book-100", "XBT/USD"]
[270, {"a": [["11682.40000", "0.00000000", "1596666778.416455"], ["11710.60000", "2.80039129", "1596666770.582883", "r"]], "c": "3321182319"}, "book-100", "XBT/USD"]
[270, {"b": [["11623.00000", "1.03040000", "1596666778.422874"]], "c": "3321182319"}, "book-100", "XBT/USD"]
[270, {"b": [["11635.10000", "7.30000000", "1596666778.438111"]], "c": "3321182319"}, "book-100", "XBT/USD"]
[270, {"b": [["11645.60000", "0.00000000", "1596666778.462463"], ["11595.50000", "7.80000000", "1596666735.579667", "r"]], "c": "3321182319"}, "book-100", "XBT/USD"]
[270, {"b": [["11634.90000", "0.00000000", "1596666778.463444"], ["11595.20000", "2.01970706", "1596666763.756520", "r"]], "c": "3321182319"}, "book-100", "XBT/USD"]
[270, {"b": [["11643.30000", "0.00000000", "1596666778.463930"], ["11593.60000", "18.30000000", "1596666774.492313", "r"]], "c": "3321182319"}, "book-100", "XBT/USD"]
[270, {"a": [["11677.40000", "0.00000000", "1596666778.469497"], ["11710.70000", "3.52183532", "1596666711.393054", "r"]], "c": "3321182319"}, "book-100", "XBT/USD"]
[270, {"b": [["11607.90000", "0.00000000", "1596666778.471396"], ["11593.00000", "0.95780000", "1596666771.513632", "r"]], "c": "3321182319"}, "book-100", "XBT/USD"]
[270, {"a": [["11681.20000", "0.40573600", "1596666778.474742"]], "c": "3321182319"}, "book-100", "XBT/USD"]
[270, {"b": [["11625.90000", "0.00000000", "1596666778.489036"], ["11592.90000", "0.80800000", "1596666471.264849", "r"]], "c": "3321182319"}, "book-100", "XBT/USD"]
[270, {"a": [["11686.20000", "3.28918514", "1596666778.492114"]], "c": "3321182319"}, "book-100", "XBT/USD"]
[270, {"b": [["11644.40000", "0.90116319", "1596666778.505189"]], "c": "3321182319"}, "book-100", "XBT/USD"]
[270, {"b": [["11640.90000", "0.00000000", "1596666778.506041"], ["11589.90000", "6.90000000", "1596666166.290818", "r"]], "c": "3321182319"}, "book-100", "XBT/USD"]
[270, {"a": [["11665.80000", "0.00000000", "1596666778.541659"], ["11711.00000", "3.52207482", "1596666594.088624", "r"]], "c": "3553963645"}, "book-100", "XBT/USD"]
[270, {"b": [["11645.00000", "1.22471804", "1596666778.543154"]], "c": "3553963645"}, "book-100", "XBT/USD"]
[270, {"b": [["11633.70000", "0.00000000", "1596666778.543359"], ["11589.00000", "3.54547328", "1596666762.265610", "r"]], "c": "3553963645"}, "book-100", "XBT/USD"]
[270, {"a": [["11668.00000", "0.01000000", "1596666778.543443"]], "c": "3887868824"}, "book-100", "XBT/USD"]
[270, {"b": [["11609.00000", "0.00000000", "1596666778.543588"], ["11587.00000", "3.55934204", "1596666746.867590", "r"]], "c": "3887868824"}, "book-100", "XBT/USD"]
[270, {"a": [["11672.00000", "0.64287226", "1596666778.604130"]], "c": "3887868824"}, "book-100", "XBT/USD"]
[270, {"b": [["11629.30000", "0.00000000", "1596666778.611274"], ["11586.20000", "3.00500211", "1596666626.428727", "r"]], "c": "3887868824"}, "book-100", "XBT/USD"]
[270, {"b": [["11658.90000", "12.97117130", "1596666778.637996"]], "c": "4196384165"}, "book-100", "XBT/USD"]
[270, {"b": [["11645.00000", "1.14385175", "1596666778.689051"]], "c": "4196384165"}, "book-100", "XBT/USD"]
[270, {"b": [["11649.70000", "0.00000000", "1596666778.716773"], ["11585.90000", "1.48215236", "1596666745.788273", "r"]], "c": "4196384165"}, "book-100", "XBT/USD"]
[270, {"b": [["11651.70000", "0.72442529", "1596666778.747370"]], "c": "4196384165"}, "book-100", "XBT/USD"]
[270, {"b": [["11654.00000", "0.10346890", "1596666778.748501"]], "c": "4196384165"}, "book-100", "XBT/USD"]
[270, {"b": [["11634.30000", "1.51320392", "1596666778.748595"]], "c": "4196384165"}, "book-100", "XBT/USD"]
[270, {"b": [["11645.00000", "0.00000000", "1596666778.750816"], ["11587.00000", "3.55934204", "1596666746.867590", "r"]], "c": "4196384165"}, "book-100", "XBT/USD"]
[270, {"b": [["11622.70000", "2.32394502", "1596666778.750927"]], "c": "4196384165"}, "book-100", "XBT/USD"]
[270, {"b": [["11645.90000", "1.21142816", "1596666778.751749"]], "c": "4196384165"}, "book-100", "XBT/USD"]
[270, {"b": [["11649.70000", "0.34984775", "1596666778.756359"]], "c": "4196384165"}, "book-100", "XBT/USD"]
[270, {"b": [["11653.20000", "1.10748006", "1596666778.758547"]], "c": "4196384165"}, "book-100", "XBT/USD"]
[270, {"b": [["11649.80000", "0.00000000", "1596666778.845980"], ["11589.90000", "6.90000000", "1596666166.290818", "r"]], "c": "4196384165"}, "book-100", "XBT/USD"]
[270, {"b": [["11649.60000", "0.01692370", "1596666778.847519"]], "c": "4196384165"}, "book-100", "XBT/USD"]
[270, {"a": [["11666.20000", "0.10000000", "1596666778.862144"]], "c": "91830546"}, "book-100", "XBT/USD"]
[270, {"a": [["11673.10000", "0.00000000", "1596666778.890247"], ["11711.00000", "3.52207482", "1596666594.088624", "r"]], "c": "91830546"}, "book-100", "XBT/USD"]
[270, {"b": [["11645.30000", "1.22496097", "1596666778.894363"]], "c": "91830546"}, "book-100", "XBT/USD"]
[270, {"b": [["11645.80000", "0.00484587", "1596666778.917719"]], "c": "91830546"}, "book-100", "XBT/USD"]
[270, {"a": [["11685.30000", "0.00438186", "1596666778.918295"]], "c": "91830546"}, "book-100", "XBT/USD"]
[270, {"a": [["11701.30000", "0.00000000", "1596666778.939130"], ["11711.00000", "3.52207482", "1596666594.088624", "r"]], "c": "91830546"}, "book-100", "XBT/USD"]
[270, {"b": [["11625.40000", "0.00000000", "1596666778.957244"], ["11593.00000", "0.95780000", "1596666771.513632", "r"]], "c": "91830546"}, "book-100", "XBT/USD"]
[270, {"b": [["11649.90000", "4.00000000", "1596666778.957648"]], "c": "91830546"}, "book-100", "XBT/USD"]
[270, {"a": [["11703.40000", "2.24814371", "1596666778.964736"]], "c": "91830546"}, "book-100", "XBT/USD"]
[270, {"a": [["11668.20000", "0.00000000", "1596666778.966649"], ["11711.00000", "3.52207482", "1596666594.088624", "r"]], "c": "1886653967"}, "book-100", "XBT/USD"]
[270, {"a": [["11675.10000", "0.43900000", "1596666778.995826"]], "c": "1886653967"}, "book-100", "XBT/USD"]
[270, {"b": [["11599.60000", "3.04585670", "1596666779.021471"]], "c": "1886653967"}, "book-100", "XBT/USD"]
[270, {"a": [["11667.80000", "0.41352978", "1596666779.058377"]], "c": "354578540"}, "book-100", "XBT/USD"]
[270, {"a": [["11666.10000", "0.25843073", "1596666779.105748"]], "c": "3395007535"}, "book-100", "XBT/USD"]
[270, {"b": [["11645.30000", "0.00000000", "1596666779.116215"], ["11593.60000", "18.30000000", "1596666774.492313", "r"]], "c": "3395007535"}, "book-100", "XBT/USD"]
[270, {"a": [["11667.90000", "0.00000000", "1596666779.122147"], ["11710.60000", "2.80039129", "1596666770.582883", "r"]], "c": "2721223843"}, "book-100", "XBT/USD"]
[270, {"b": [["11645.80000", "1.80330052", "1596666779.133479"]], "c": "2721223843"}, "book-100", "XBT/USD"]
[270, {"b": [["11634.20000", "1.97008252", "1596666779.137395"]], "c": "2721223843"}, "book-100", "XBT/USD"]
[270, {"b": [["11651.60000", "1.42448104", "1596666779.139588"]], "c": "2721223843"}, "book-100", "XBT/USD"]
[270, {"a": [["11675.60000", "1.86255412", "1596666779.157522"]], "c": "2721223843"}, "book-100", "XBT/USD"]
[270, {"a": [["11678.30000", "0.00000000", "1596666779.158969"], ["11710.70000", "3.52183532", "1596666711.393054", "r"]], "c": "2721223843"}, "book-100", "XBT/USD"]
[270, {"a": [["11670.20000", "0.50896711", "1596666779.181694"]], "c": "2721223843"}, "book-100", "XBT/USD"]
[270, {"a": [["11706.10000", "0.00000000", "1596666779.219934"], ["11711.00000", "3.52207482", "1596666594.088624", "r"]], "c": "2721223843"}, "book-100", "XBT/USD"]
[270, {"b": [["11612.80000", "0.00000000", "1596666779.221019"], ["11595.20000", "2.01970706", "1596666763.756520", "r"]], "c": "2721223843"}, "book-100", "XBT/USD"]
[270, {"b": [["11617.90000", "13.92275867", "1596666779.227455"]], "c": "2721223843"}, "book-100", "XBT/USD"]
[270, {"b": [["11649.60000", "0.00000000", "1596666779.260127"], ["11595.20000", "2.01970706", "1596666763.756520", "r"]], "c": "2721223843"}, "book-100", "XBT/USD"]
[270, {"b": [["11645.40000", "7.32446914", "1596666779.260899"]], "c": "2721223843"}, "book-100", "XBT/USD"]
[270, {"b": [["11649.60000", "0.01692404", "1596666779.264967"]], "c": "2721223843"}, "book-100", "XBT/USD"]
[270, {"a": [["11668.40000", "1.50000000", "1596666779.270414"]], "c": "3266136042"}, "book-100", "XBT/USD"]
[270, {"b": [["11653.40000", "0.00000000", "1596666779.371004"], ["11595.20000", "2.01970706", "1596666763.756520", "r"]], "c": "3266136042"}, "book-100", "XBT/USD"]
[270, {"b": [["11656.80000", "0.00000000", "1596666779.371604"], ["11593.60000", "18.30000000", "1596666774.492313", "r"]], "c": "798309286"}, "book-100", "XBT/USD"]
[270, {"a": [["11679.60000", "0.68498040", "1596666779.405164"]], "c": "798309286"}, "book-100", "XBT/USD"]
[270, {"b": [["11650.90000", "9.78464429", "1596666779.509387"]], "c": "798309286"}, "book-100", "XBT/USD"]
[270, {"b": [["11648.50000", "0.00000000", "1596666779.510255"], ["11593.00000", "0.95780000", "1596666771.513632", "r"]], "c": "798309286"}, "book-100", "XBT/USD"]
[270, {"a": [["11670.20000", "0.41275617", "1596666779.519023"]], "c": "798309286"}, "book-100", "XBT/USD"]
[270, {"b": [["11656.00000", "0.43900000", "1596666779.523600"]], "c": "3238469081"}, "book-100", "XBT/USD"]
[270, {"a": [["11666.10000", "0.00000000", "1596666779.533439"], ["11710.70000", "3.52183532", "1596666711.393054", "r"]], "c": "1958049992"}, "book-100", "XBT/USD"]
[270, {"a": [["11699.70000", "0.00000000", "1596666779.579034"], ["11711.00000", "3.52207482", "1596666594.088624", "r"]], "c": "1958049992"}, "book-100", "XBT/USD"]
[270, {"b": [["11658.90000", "12.72117130", "1596666779.596865"]], "c": "2430550864"}, "book-100", "XBT/USD"]
[270, {"b": [["11608.40000", "0.01286565", "1596666779.598024"]], "c": "2430550864"}, "book-100", "XBT/USD"]
[270, {"b": [["11622.60000", "2.82206979", "1596666779.606566"]], "c": "2430550864"}, "book-100", "XBT/USD"]
[270, {"b": [["11649.60000", "0.00000000", "1596666779.621022"], ["11595.20000", "2.01970706", "1596666763.756520", "r"]], "c": "2430550864"}, "book-100", "XBT/USD"]
[270, {"b": [["11650.00000", "0.01692353", "1596666779.623022"]], "c": "2430550864"}, "book-100", "XBT/USD"]
[270, {"a": [["11667.40000", "0.25842155", "1596666779.627261"]], "c": "494317788"}, "book-100", "XBT/USD"]
[270, {"b": [["11645.90000", "1.29357012", "1596666779.634542"]], "c": "494317788"}, "book-100", "XBT/USD"]
[270, {"a": [["11676.20000", "2.31657252", "1596666779.707022"]], "c": "494317788"}, "book-100", "XBT/USD"]
[270, {"b": [["11658.90000", "12.32117130", "1596666779.720749"]], "c": "613416381"}, "book-100", "XBT/USD"]
[270, {"a": [["11668.40000", "0.00000000", "1596666779.728277"], ["11710.70000", "3.52183532", "1596666711.393054", "r"]], "c": "3210731979"}, "book-100", "XBT/USD"]
[270, {"b": [["11658.90000", "12.72117130", "1596666779.741249"]], "c": "2259070122"}, "book-100", "XBT/USD"]
[270, {"b": [["11650.00000", "0.00000000", "1596666779.754422"], ["11595.20000", "2.01970706", "1596666763.756520", "r"]], "c": "2259070122"}, "book-100", "XBT/USD"]
[270, {"b": [["11654.20000", "3.48549837", "1596666779.835181"]], "c": "2259070122"}, "book-100", "XBT/USD"]
[270, {"b": [["11658.90000", "12.81817130", "1596666779.841288"]], "c": "2579812754"}, "book-100", "XBT/USD"]
[270, {"a": [["11669.50000", "0.00000000", "1596666779.846408"], ["11711.00000", "3.52207482", "1596666594.088624", "r"]], "c": "3528117512"}, "book-100", "XBT/USD"]
[270, {"b": [["11649.90000", "0.00000000", "1596666779.863730"], ["11593.60000", "18.30000000", "1596666774.492313", "r"]], "c": "3528117512"}, "book-100", "XBT/USD"]
[270, {"a": [["11672.10000", "0.00000000", "1596666779.870216"], ["11711.10000", "2.97327583", "1596666728.385477", "r"]], "c": "3528117512"}, "book-100", "XBT/USD"]
[270, {"b": [["11645.80000", "1.79845465", "1596666779.896708"]], "c": "3528117512"}, "book-100", "XBT/USD"]
[270, {"b": [["11608.40000", "0.00000000", "1596666779.896794"], ["11593.00000", "0.95780000", "1596666771.513632", "r"]], "c": "3528117512"}, "book-100", "XBT/USD"]
[270, {"b": [["11601.10000", "3.00166376", "1596666779.976375"]], "c": "3528117512"}, "book-100", "XBT/USD"]
[270, {"b": [["11650.90000", "10.28278322", "1596666779.979511"]], "c": "3528117512"}, "book-100", "XBT/USD"]
[270, {"b": [["11645.10000", "0.99677408", "1596666779.984245"]], "c": "3528117512"}, "book-100", "XBT/USD"]
[270, {"b": [["11650.90000", "8.34233893", "1596666779.992028"]], "c": "3528117512"}, "book-100", "XBT/USD"]
[270, {"a": [["11677.90000", "0.00000000", "1596666780.005027"], ["11711.20000", "20.89630055", "1596666779.227248", "r"]], "c": "3528117512"}, "book-100", "XBT/USD"]
[270, {"a": [["11669.60000", "0.00000000", "1596666780.061598"], ["11713.70000", "0.30235286", "1596666778.413392", "r"]], "c": "1107452426"}, "book-100", "XBT/USD"]
[270, {"b": [["11654.90000", "0.89800000", "1596666780.061842"]], "c": "1107452426"}, "book-100", "XBT/USD"]
[270, {"b": [["11650.10000", "4.00000000", "1596666780.101052"]], "c": "1107452426"}, "book-100", "XBT/USD"]
[270, {"b": [["11632.60000", "0.49800000", "1596666780.151579"]], "c": "1107452426"}, "book-100", "XBT/USD"]
[270, {"a": [["11667.80000", "0.00000000", "1596666780.186474"], ["11713.80000", "0.37309062", "1596666771.863547", "r"]], "c": "2088442341"}, "book-100", "XBT/USD"]
[270, {"a": [["11675.60000", "0.47806486", "1596666780.202797"]], "c": "2088442341"}, "book-100", "XBT/USD"]
[270, {"a": [["11667.40000", "0.00000000", "1596666780.210586"], ["11715.00000", "0.17085000", "1596666778.029752", "r"]], "c": "2425898479"}, "book-100", "XBT/USD"]
[270, {"a": [["11673.00000", "0.00000000", "1596666780.215804"], ["11715.30000", "6.10000000", "1596666635.445451", "r"]], "c": "2425898479"}, "book-100", "XBT/USD"]
[270, {"a": [["11670.10000", "0.25838561", "1596666780.221606"]], "c": "2559528461"}, "book-100", "XBT/USD"]
[270, {"a": [["11671.50000", "0.00000000", "1596666780.262043"], ["11715.30000", "6.10000000", "1596666635.445451", "r"]], "c": "2559528461"}, "book-100", "XBT/USD"]
[270, {"a": [["11674.90000", "0.75551922", "1596666780.263993"]], "c": "2559528461"}, "book-100", "XBT/USD"]
[270, {"b": [["11640.60000", "0.00000000", "1596666780.280600"], ["11595.50000", "7.80000000", "1596666735.579667", "r"]], "c": "2559528461"}, "book-100", "XBT/USD"]
