[275, ["11418.20000", "11418.30000", "1596625625.226425", "0.24953801", "3.04709891"], "spread", "XBT/USD"]
[271, [["11418.20000", "0.00749300", "1596625627.033075", "s", "m", ""]], "trade", "XBT/USD"]
[275, ["11418.20000", "11418.30000", "1596625627.033075", "0.24204501", "3.04709891"], "spread", "XBT/USD"]
[275, ["11418.20000", "11418.30000", "1596625627.107903", "0.24204501", "7.49709891"], "spread", "XBT/USD"]
[275, ["11418.20000", "11418.30000", "1596625627.143279", "0.24204501", "5.49709891"], "spread", "XBT/USD"]
[275, ["11418.20000", "11418.30000", "1596625627.201789", "0.24204501", "1.04709891"], "spread", "XBT/USD"]
[275, ["11418.20000", "11418.30000", "1596625627.369702", "0.24204501", "1.23209891"], "spread", "XBT/USD"]
[275, ["11418.20000", "11418.30000", "1596625628.431366", "0.24204501", "0.68500000"], "spread", "XBT/USD"]
[275, ["11418.20000", "11418.30000", "1596625628.732641", "2.24204501", "0.68500000"], "spread", "XBT/USD"]
[275, ["11418.20000", "11418.30000", "1596625629.122821", "0.24204501", "0.68500000"], "spread", "XBT/USD"]
[275, ["11418.20000", "11418.30000", "1596625631.760987", "2.24204501", "0.68500000"], "spread", "XBT/USD"]
[275, ["11418.20000", "11418.30000", "1596625631.958606", "2.50496429", "0.68500000"], "spread", "XBT/USD"]
[275, ["11418.20000", "11418.30000", "1596625632.483525", "3.16189436", "0.68500000"], "spread", "XBT/USD"]
[275, ["11418.20000", "11418.30000", "1596625632.629671", "3.16189436", "0.18500000"], "spread", "XBT/USD"]
[275, ["11418.20000", "11419.90000", "1596625632.483525", "3.16189436", "0.65693531"], "spread", "XBT/USD"]
[275, ["11418.20000", "11419.90000", "1596625634.031125", "2.89897508", "0.65693531"], "spread", "XBT/USD"]
[275, ["11418.30000", "11419.90000", "1596625634.130385", "0.26290514", "0.65693531"], "spread", "XBT/USD"]
[275, ["11418.30000", "11419.70000", "1596625634.214752", "0.26290514", "2.00000000"], "spread", "XBT/USD"]
[275, ["11418.30000", "11419.70000", "1596625634.666167", "0.28044300", "2.00000000"], "spread", "XBT/USD"]
[275, ["11418.30000", "11419.40000", "1596625634.887538", "0.28044300", "0.65694471"], "spread", "XBT/USD"]
[275, ["11418.30000", "11419.30000", "1596625635.095413", "0.28044300", "0.17500000"], "spread", "XBT/USD"]
[275, ["11418.30000", "11419.30000", "1596625635.538741", "0.28044300", "2.17500000"], "spread", "XBT/USD"]
[275, ["11418.30000", "11419.30000", "1596625635.731740", "0.28044300", "0.17500000"], "spread", "XBT/USD"]
[275, ["11418.30000", "11419.30000", "1596625635.769772", "2.28044300", "0.17500000"], "spread", "XBT/USD"]
[275, ["11418.30000", "11419.30000", "1596625635.973967", "0.28044300", "0.17500000"], "spread", "XBT/USD"]
[275, ["11418.30000", "11419.20000", "1596625636.456868", "0.28044300", "2.00000000"], "spread", "XBT/USD"]
[275, ["11418.30000", "11419.40000", "1596625635.973967", "0.28044300", "0.65694471"], "spread", "XBT/USD"]
[275, ["11418.30000", "11419.10000", "1596625637.451261", "0.28044300", "2.00000000"], "spread", "XBT/USD"]
[275, ["11418.30000", "11419.00000", "1596625637.543019", "0.28044300", "0.33500000"], "spread", "XBT/USD"]
[275, ["11418.30000", "11419.00000", "1596625637.991005", "0.01753786", "0.33500000"], "spread", "XBT/USD"]
[275, ["11418.20000", "11419.00000", "1596625637.543019", "0.88143707", "0.33500000"], "spread", "XBT/USD"]
[275, ["11418.20000", "11419.00000", "1596625642.893538", "0.88143707", "2.33500000"], "spread", "XBT/USD"]
[275, ["11418.20000", "11419.00000", "1596625643.113016", "0.88143707", "2.00000000"], "spread", "XBT/USD"]
[271, [["11419.00000", "0.13126966", "1596625643.176158", "b", "l", ""]], "trade", "XBT/USD"]
[275, ["11418.20000", "11419.00000", "1596625643.176158", "0.88143707", "1.86873034"], "spread", "XBT/USD"]
[275, ["11418.20000", "11419.00000", "1596625643.357801", "0.22450700", "1.86873034"], "spread", "XBT/USD"]
[275, ["11418.20000", "11418.80000", "1596625643.422406", "0.22450700", "0.65698580"], "spread", "XBT/USD"]
[275, ["11418.70000", "11418.80000", "1596625643.545712", "0.50000000", "0.65698580"], "spread", "XBT/USD"]
[275, ["11418.70000", "11419.40000", "1596625643.545712", "0.50000000", "0.65694471"], "spread", "XBT/USD"]
[275, ["11418.20000", "11419.40000", "1596625643.548777", "2.22450700", "0.65694471"], "spread", "XBT/USD"]
[275, ["11418.70000", "11419.40000", "1596625643.715729", "2.00000000", "0.65694471"], "spread", "XBT/USD"]
[275, ["11418.20000", "11419.40000", "1596625643.548777", "2.22450700", "0.65694471"], "spread", "XBT/USD"]
[275, ["11418.20000", "11419.40000", "1596625644.529221", "0.22450700", "0.65694471"], "spread", "XBT/USD"]
[271, [["11419.40000", "0.26167586", "1596625644.965240", "b", "l", ""]], "trade", "XBT/USD"]
[275, ["11418.20000", "11419.40000", "1596625644.965240", "0.22450700", "0.39526885"], "spread", "XBT/USD"]
[275, ["11418.20000", "11419.40000", "1596625646.363208", "2.22450700", "0.39526885"], "spread", "XBT/USD"]
[275, ["11418.30000", "11419.40000", "1596625648.275512", "0.26291837", "0.39526885"], "spread", "XBT/USD"]
[275, ["11419.30000", "11419.40000", "1596625648.425657", "0.50000000", "0.39526885"], "spread", "XBT/USD"]
[275, ["11419.30000", "11419.90000", "1596625648.425657", "0.50000000", "0.65693531"], "spread", "XBT/USD"]
[275, ["11418.30000", "11419.90000", "1596625648.275512", "0.26291837", "0.65693531"], "spread", "XBT/USD"]
[275, ["11418.40000", "11419.90000", "1596625648.788628", "0.65694691", "0.65693531"], "spread", "XBT/USD"]
[275, ["11418.90000", "11419.90000", "1596625648.789154", "0.65692091", "0.65693531"], "spread", "XBT/USD"]
[275, ["11418.40000", "11419.90000", "1596625648.788628", "0.65694691", "0.65693531"], "spread", "XBT/USD"]
[275, ["11418.40000", "11419.90000", "1596625648.922002", "2.65694691", "0.65693531"], "spread", "XBT/USD"]
[275, ["11418.40000", "11419.80000", "1596625649.053168", "2.65694691", "0.48623696"], "spread", "XBT/USD"]
[275, ["11418.40000", "11419.80000", "1596625649.559837", "2.00000000", "0.48623696"], "spread", "XBT/USD"]
[275, ["11418.50000", "11419.80000", "1596625650.448569", "0.26290814", "0.48623696"], "spread", "XBT/USD"]
[275, ["11418.60000", "11419.80000", "1596625650.844190", "0.39000000", "0.48623696"], "spread", "XBT/USD"]
[275, ["11419.00000", "11419.80000", "1596625650.977408", "2.00000000", "0.48623696"], "spread", "XBT/USD"]
[275, ["11419.00000", "11419.50000", "1596625651.448657", "2.00000000", "0.65695461"], "spread", "XBT/USD"]
[275, ["11419.00000", "11419.90000", "1596625650.977408", "2.00000000", "0.65693531"], "spread", "XBT/USD"]
[275, ["11418.60000", "11419.90000", "1596625650.844190", "0.39000000", "0.65693531"], "spread", "XBT/USD"]
[275, ["11418.60000", "11419.90000", "1596625652.551868", "0.39000000", "2.65693531"], "spread", "XBT/USD"]
[275, ["11418.60000", "11419.80000", "1596625652.888363", "0.39000000", "0.53215921"], "spread", "XBT/USD"]
[275, ["11418.10000", "11419.80000", "1596625652.888363", "0.26291711", "0.53215921"], "spread", "XBT/USD"]
[275, ["11418.10000", "11419.50000", "1596625653.574767", "0.26291711", "0.65695826"], "spread", "XBT/USD"]
[275, ["11418.40000", "11419.50000", "1596625653.575072", "0.65694191", "0.65695826"], "spread", "XBT/USD"]
[275, ["11419.30000", "11419.50000", "1596625654.182469", "0.22458706", "0.65695826"], "spread", "XBT/USD"]
[275, ["11419.30000", "11419.90000", "1596625654.297633", "0.22458706", "0.65693531"], "spread", "XBT/USD"]
[275, ["11419.30000", "11420.00000", "1596625654.182469", "0.22458706", "0.19830000"], "spread", "XBT/USD"]
[275, ["11419.30000", "11420.00000", "1596625656.045783", "2.22458706", "0.19830000"], "spread", "XBT/USD"]
[275, ["11419.40000", "11420.00000", "1596625656.142549", "0.59000000", "0.19830000"], "spread", "XBT/USD"]
[275, ["11419.40000", "11420.00000", "1596625656.276581", "2.59000000", "0.19830000"], "spread", "XBT/USD"]
[275, ["11419.40000", "11420.00000", "1596625656.342227", "3.49574000", "0.19830000"], "spread", "XBT/USD"]
[275, ["11419.90000", "11420.00000", "1596625656.429062", "0.50000000", "0.19830000"], "spread", "XBT/USD"]
[275, ["11419.90000", "11420.00000", "1596625656.565140", "2.50000000", "0.19830000"], "spread", "XBT/USD"]
[275, ["11419.90000", "11420.00000", "1596625656.869086", "2.50000000", "0.20156318"], "spread", "XBT/USD"]
[275, ["11419.90000", "11420.00000", "1596625657.271923", "0.50000000", "0.20156318"], "spread", "XBT/USD"]
[275, ["11419.90000", "11420.00000", "1596625657.529295", "0.53713097", "0.20156318"], "spread", "XBT/USD"]
[275, ["11419.90000", "11420.00000", "1596625658.036930", "1.25713097", "0.20156318"], "spread", "XBT/USD"]
[275, ["11419.90000", "11420.00000", "1596625658.187033", "1.65713097", "0.20156318"], "spread", "XBT/USD"]
[275, ["11419.90000", "11420.00000", "1596625659.528619", "2.31394192", "0.20156318"], "spread", "XBT/USD"]
[275, ["11419.90000", "11420.00000", "1596625659.565296", "2.31394192", "0.22385615"], "spread", "XBT/USD"]
[275, ["11419.90000", "11420.00000", "1596625660.034126", "2.57680807", "0.22385615"], "spread", "XBT/USD"]
[275, ["11419.90000", "11420.00000", "1596625660.451611", "3.17680807", "0.22385615"], "spread", "XBT/USD"]
[275, ["11419.90000", "11420.00000", "1596625660.648997", "2.57680807", "0.22385615"], "spread", "XBT/USD"]
[275, ["11419.90000", "11420.00000", "1596625661.596809", "3.17680807", "0.22385615"], "spread", "XBT/USD"]
[275, ["11419.90000", "11420.00000", "1596625661.613936", "3.13967710", "0.22385615"], "spread", "XBT/USD"]
[275, ["11419.90000", "11420.00000", "1596625661.737351", "3.13967710", "0.25948054"], "spread", "XBT/USD"]
[275, ["11419.90000", "11420.00000", "1596625661.800080", "3.63967710", "0.25948054"], "spread", "XBT/USD"]
[275, ["11419.90000", "11420.00000", "1596625661.854999", "5.63967710", "0.25948054"], "spread", "XBT/USD"]
[275, ["11419.90000", "11420.00000", "1596625663.146938", "5.67680315", "0.25948054"], "spread", "XBT/USD"]
[275, ["11419.90000", "11420.00000", "1596625663.166532", "5.17680315", "0.25948054"], "spread", "XBT/USD"]
[275, ["11419.90000", "11420.00000", "1596625663.199216", "5.17680315", "0.27729477"], "spread", "XBT/USD"]
[275, ["11419.90000", "11420.00000", "1596625663.459069", "5.67680315", "0.27729477"], "spread", "XBT/USD"]
[275, ["11419.90000", "11420.00000", "1596625664.558141", "5.17680315", "0.27729477"], "spread", "XBT/USD"]
[275, ["11419.90000", "11420.00000", "1596625664.745777", "5.67680315", "0.27729477"], "spread", "XBT/USD"]
[275, ["11419.90000", "11420.00000", "1596625664.923136", "5.63967710", "0.27729477"], "spread", "XBT/USD"]
[275, ["11419.90000", "11420.00000", "1596625665.312877", "5.67569129", "0.27729477"], "spread", "XBT/USD"]
[275, ["11419.90000", "11420.00000", "1596625665.880243", "5.67569129", "0.28374015"], "spread", "XBT/USD"]
0.00000000", "1596625626.873521"], ["11374.70000", "17.40000000", "1596624672.337224", "r"]], "c": "3350522975"}, "book-100", "XBT/USD"]
[270, {"b": [["11375.40000", "2.28694768", "1596625626.910098"]], "c": "3350522975"}, "book-100", "XBT/USD"]
[271, [["11418.20000", "0.00749300", "1596625627.033075", "s", "m", ""]], "trade", "XBT/USD"]
[270, {"b": [["11418.20000", "0.24204501", "1596625627.033075"]], "c": "1092641599"}, "book-100", "XBT/USD"]
[270, {"a": [["11418.30000", "7.49709891", "1596625627.107903"]], "c": "1127833321"}, "book-100", "XBT/USD"]
[270, {"a": [["11418.30000", "5.49709891", "1596625627.143279"]], "c": "817106507"}, "book-100", "XBT/USD"]
[270, {"a": [["11439.00000", "0.18439000", "1596625627.175383"]], "c": "817106507"}, "book-100", "XBT/USD"]
[270, {"a": [["11418.30000", "1.04709891", "1596625627.201789"]], "c": "850211741"}, "book-100", "XBT/USD"]
[270, {"a": [["11418.30000", "1.23209891", "1596625627.369702"]], "c": "4107556052"}, "book-100", "XBT/USD"]
[270, {"a": [["11420.20000", "0.00000000", "1596625627.513004"], ["11455.90000", "2.53126934", "1596625369.045883", "r"]], "c": "505178854"}, "book-100", "XBT/USD"]
[270, {"a": [["11419.90000", "0.26293688", "1596625627.608437"]], "c": "111493900"}, "book-100", "XBT/USD"]
[270, {"b": [["11414.10000", "5.25097238", "1596625627.644974"]], "c": "2250130546"}, "book-100", "XBT/USD"]
[270, {"b": [["11417.00000", "0.65697406", "1596625627.882501"]], "c": "2047913636"}, "book-100", "XBT/USD"]
[270, {"a": [["11418.80000", "0.65699163", "1596625627.951873"]], "c": "2852603186"}, "book-100", "XBT/USD"]
[270, {"b": [["11415.20000", "2.34200000", "1596625627.983290"]], "c": "870494630"}, "book-100", "XBT/USD"]
[270, {"b": [["11397.10000", "0.00443076", "1596625627.984411"]], "c": "870494630"}, "book-100", "XBT/USD"]
[270, {"a": [["11425.70000", "0.00000000", "1596625628.199350"], ["11455.70000", "0.01000000", "1596625592.291853", "r"]], "c": "870494630"}, "book-100", "XBT/USD"]
[270, {"a": [["11451.60000", "0.58233651", "1596625628.313864"]], "c": "870494630"}, "book-100", "XBT/USD"]
[270, {"b": [["11392.30000", "0.00000000", "1596625628.383985"], ["11375.90000", "6.40000000", "1596624852.612143", "r"]], "c": "870494630"}, "book-100", "XBT/USD"]
[270, {"a": [["11425.40000", "0.51406013", "1596625628.390464"]], "c": "870494630"}, "book-100", "XBT/USD"]
[270, {"a": [["11418.30000", "0.68500000", "1596625628.431366"]], "c": "271948320"}, "book-100", "XBT/USD"]
[270, {"a": [["11451.20000", "5.41238625", "1596625628.687007"]], "c": "271948320"}, "book-100", "XBT/USD"]
[270, {"b": [["11416.20000", "0.00000000", "1596625628.692453"], ["11375.40000", "2.28694768", "1596625626.910098", "r"]], "c": "4153749894"}, "book-100", "XBT/USD"]
[270, {"b": [["11418.20000", "2.24204501", "1596625628.732641"]], "c": "1124252780"}, "book-100", "XBT/USD"]
[270, {"b": [["11415.30000", "0.61320000", "1596625628.742135"]], "c": "1695692733"}, "book-100", "XBT/USD"]
[270, {"b": [["11414.80000", "0.00000000", "1596625628.748447"], ["11375.40000", "2.28694768", "1596625626.910098", "r"]], "c": "88017748"}, "book-100", "XBT/USD"]
[270, {"b": [["11417.90000", "0.26292654", "1596625628.792702"]], "c": "885137486"}, "book-100", "XBT/USD"]
[270, {"a": [["11427.20000", "0.00000000", "1596625628.931776"], ["11455.90000", "2.53126934", "1596625369.045883", "r"]], "c": "885137486"}, "book-100", "XBT/USD"]
[270, {"a": [["11419.90000", "0.00000000", "1596625628.943812"], ["11456.80000", "17.00000000", "1596625364.678785", "r"]], "c": "1578540906"}, "book-100", "XBT/USD"]
[270, {"a": [["11420.90000", "0.26292114", "1596625629.003844"]], "c": "624298537"}, "book-100", "XBT/USD"]
[270, {"b": [["11418.20000", "0.24204501", "1596625629.122821"]], "c": "1970574975"}, "book-100", "XBT/USD"]
[270, {"b": [["11409.90000", "0.00000000", "1596625629.144570"], ["11375.40000", "2.28694768", "1596625626.910098", "r"]], "c": "1970574975"}, "book-100", "XBT/USD"]
[270, {"b": [["11410.60000", "0.00000000", "1596625629.144648"], ["11374.70000", "17.40000000", "1596624672.337224", "r"]], "c": "1970574975"}, "book-100", "XBT/USD"]
[270, {"b": [["11399.40000", "0.06698460", "1596625629.673104"]], "c": "1970574975"}, "book-100", "XBT/USD"]
[270, {"b": [["11399.40000", "0.04151493", "1596625629.673281"]], "c": "1970574975"}, "book-100", "XBT/USD"]
[270, {"a": [["11418.80000", "0.00000000", "1596625630.234419"], ["11456.80000", "17.00000000", "1596625364.678785", "r"]], "c": "1334496986"}, "book-100", "XBT/USD"]
[270, {"b": [["11417.10000", "1.02397000", "1596625630.251294"]], "c": "2987704013"}, "book-100", "XBT/USD"]
[270, {"a": [["11421.00000", "1.29293531", "1596625630.290864"]], "c": "1717896571"}, "book-100", "XBT/USD"]
[270, {"a": [["11421.00000", "0.63600000", "1596625630.371390"]], "c": "2987704013"}, "book-100", "XBT/USD"]
[270, {"a": [["11432.70000", "0.00000000", "1596625630.531121"], ["11456.90000", "0.75800000", "1596625363.968189", "r"]], "c": "2987704013"}, "book-100", "XBT/USD"]
[270, {"b": [["11375.40000", "0.00000000", "1596625630.586516"], ["11374.70000", "17.40000000", "1596624672.337224", "r"]], "c": "2987704013"}, "book-100", "XBT/USD"]
[270, {"a": [["11432.90000", "0.00438186", "1596625630.723021"]], "c": "2987704013"}, "book-100", "XBT/USD"]
[270, {"b": [["11410.70000", "0.87464681", "1596625630.787058"]], "c": "2987704013"}, "book-100", "XBT/USD"]
[270, {"b": [["11414.10000", "0.87597238", "1596625630.798011"]], "c": "170889393"}, "book-100", "XBT/USD"]
[270, {"b": [["11416.20000", "4.37000000", "1596625630.809269"]], "c": "1937845777"}, "book-100", "XBT/USD"]
[270, {"b": [["11399.40000", "0.00000000", "1596625630.867916"], ["11374.70000", "17.40000000", "1596624672.337224", "r"]], "c": "1937845777"}, "book-100", "XBT/USD"]
[270, {"b": [["11400.30000", "0.04151166", "1596625630.869309"]], "c": "1937845777"}, "book-100", "XBT/USD"]
[270, {"b": [["11412.60000", "1.50000000", "1596625630.931059"]], "c": "1937845777"}, "book-100", "XBT/USD"]
[270, {"b": [["11393.00000", "0.76202928", "1596625630.981138"]], "c": "1937845777"}, "book-100", "XBT/USD"]
[270, {"a": [["11451.00000", "0.94641928", "1596625630.982247"]], "c": "1937845777"}, "book-100", "XBT/USD"]
[270, {"a": [["11420.90000", "0.00000000", "1596625631.068616"], ["11456.90000", "0.75800000", "1596625363.968189", "r"]], "c": "1961922323"}, "book-100", "XBT/USD"]
[270, {"a": [["11420.40000", "0.26292468", "1596625631.173097"]], "c": "3131189627"}, "book-100", "XBT/USD"]
[270, {"b": [["11411.50000", "0.00000000", "1596625631.445871"], ["11377.00000", "0.01000000", "1596625490.378603", "r"]], "c": "3131189627"}, "book-100", "XBT/USD"]
[270, {"b": [["11405.90000", "0.00000000", "1596625631.453443"], ["11375.90000", "6.40000000", "1596624852.612143", "r"]], "c": "3131189627"}, "book-100", "XBT/USD"]
[270, {"b": [["11408.20000", "0.00000000", "1596625631.486898"], ["11374.70000", "17.40000000", "1596624672.337224", "r"]], "c": "3131189627"}, "book-100", "XBT/USD"]
[270, {"b": [["11399.10000", "1.00000000", "1596625631.529952"]], "c": "3131189627"}, "book-100", "XBT/USD"]
[270, {"a": [["11428.50000", "0.00000000", "1596625631.723943"], ["11456.90000", "0.75800000", "1596625363.968189", "r"]], "c": "3131189627"}, "book-100", "XBT/USD"]
[270, {"b": [["11418.20000", "2.24204501", "1596625631.760987"]], "c": "303425692"}, "book-100", "XBT/USD"]
[270, {"b": [["11411.80000", "1.21711857", "1596625631.783171"]], "c": "303425692"}, "book-100", "XBT/USD"]
[270, {"b": [["11408.50000", "0.71634158", "1596625631.785173"]], "c": "303425692"}, "book-100", "XBT/USD"]
[270, {"b": [["11406.20000", "1.53497206", "1596625631.797680"]], "c": "303425692"}, "book-100", "XBT/USD"]
[270, {"a": [["11423.20000", "0.87597854", "1596625631.845782"]], "c": "303425692"}, "book-100", "XBT/USD"]
[270, {"b": [["11417.90000", "0.00000000", "1596625631.860930"], ["11374.70000", "17.40000000", "1596624672.337224", "r"]], "c": "724269465"}, "book-100", "XBT/USD"]
[270, {"a": [["11423.50000", "0.27200000", "1596625631.884157"]], "c": "724269465"}, "book-100", "XBT/USD"]
[270, {"b": [["11418.20000", "2.50496429", "1596625631.958606"]], "c": "3304319058"}, "book-100", "XBT/USD"]
[270, {"b": [["11416.10000", "0.00000000", "1596625632.250975"], ["11372.90000", "2.84396565", "1596625550.669918", "r"]], "c": "1162300508"}, "book-100", "XBT/USD"]
[270, {"a": [["11419.20000", "0.00000000", "1596625632.424155"], ["11456.90000", "0.75800000", "1596625363.968189", "r"]], "c": "2966811655"}, "book-100", "XBT/USD"]
[270, {"a": [["11419.90000", "0.65693531", "1596625632.481525"]], "c": "1564871762"}, "book-100", "XBT/USD"]
[270, {"a": [["11421.40000", "0.65693007", "1596625632.483239"]], "c": "3723466351"}, "book-100", "XBT/USD"]
[270, {"b": [["11418.20000", "3.16189436", "1596625632.483525"]], "c": "2136867940"}, "book-100", "XBT/USD"]
[270, {"a": [["11424.60000", "0.13717726", "1596625632.560598"]], "c": "2136867940"}, "book-100", "XBT/USD"]
[270, {"a": [["11418.30000", "0.18500000", "1596625632.629671"]], "c": "3329062938"}, "book-100", "XBT/USD"]
[270, {"a": [["11432.40000", "0.73498000", "1596625632.824839"]], "c": "3329062938"}, "book-100", "XBT/USD"]
[270, {"b": [["11408.80000", "0.09600000", "1596625632.876945"]], "c": "3329062938"}, "book-100", "XBT/USD"]
[270, {"b": [["11407.00000", "0.00000000", "1596625632.880397"], ["11372.70000", "0.00875794", "1596625621.339904", "r"]], "c": "3329062938"}, "book-100", "XBT/USD"]
[270, {"a": [["11420.40000", "0.00000000", "1596625632.898533"], ["11455.90000", "2.53126934", "1596625369.045883", "r"]], "c": "4214351506"}, "book-100", "XBT/USD"]
[270, {"a": [["11421.00000", "0.89891038", "1596625632.945548"]], "c": "181495146"}, "book-100", "XBT/USD"]
[270, {"b": [["11408.60000", "0.67178142", "1596625633.009787"]], "c": "181495146"}, "book-100", "XBT/USD"]
[270, {"a": [["11430.10000", "0.00000000", "1596625633.236462"], ["11456.80000", "17.00000000", "1596625364.678785", "r"]], "c": "181495146"}, "book-100", "XBT/USD"]
[270, {"a": [["11421.40000", "0.00000000", "1596625633.243520"], ["11456.90000", "0.75800000", "1596625363.968189", "r"]], "c": "2556640739"}, "book-100", "XBT/USD"]
[270, {"a": [["11418.30000", "0.00000000", "1596625633.461506"], ["11457.00000", "1.29947966", "1596625609.016089", "r"]], "c": "3239844245"}, "book-100", "XBT/USD"]
[270, {"a": [["11439.00000", "0.00000000", "1596625633.681442"], ["11457.80000", "0.75800000", "1596624637.825563", "r"]], "c": "3239844245"}, "book-100", "XBT/USD"]
[270, {"b": [["11409.70000", "0.00000000", "1596625634.019036"], ["11372.70000", "0.00875794", "1596625621.339904", "r"]], "c": "3239844245"}, "book-100", "XBT/USD"]
[270, {"b": [["11418.20000", "2.89897508", "1596625634.031125"]], "c": "1714762496"}, "book-100", "XBT/USD"]
[270, {"a": [["11425.40000", "0.44156013", "1596625634.060038"]], "c": "1714762496"}, "book-100", "XBT/USD"]
[270, {"b": [["11418.30000", "0.26290514", "1596625634.130385"]], "c": "1668454052"}, "book-100", "XBT/USD"]
[270, {"a": [["11419.70000", "2.00000000", "1596625634.214752"]], "c": "2520173859"}, "book-100", "XBT/USD"]
[270, {"b": [["11418.20000", "0.89897508", "1596625634.236657"]], "c": "2865142804"}, "book-100", "XBT/USD"]
[270, {"b": [["11411.10000", "0.07250000", "1596625634.343406"]], "c": "2865142804"}, "book-100", "XBT/USD"]
[270, {"b": [["11418.20000", "0.88143707", "1596625634.364257"]], "c": "3918916405"}, "book-100", "XBT/USD"]
[270, {"a": [["11425.70000", "0.07250000", "1596625634.384256"]], "c": "3918916405"}, "book-100", "XBT/USD"]
[270, {"b": [["11410.10000", "1.84754310", "1596625634.659619"]], "c": "3918916405"}, "book-100", "XBT/USD"]
[270, {"a": [["11425.40000", "2.57983300", "1596625634.665934"]], "c": "3918916405"}, "book-100", "XBT/USD"]
[270, {"b": [["11418.30000", "0.28044300", "1596625634.666167"]], "c": "638095682"}, "book-100", "XBT/USD"]
[270, {"a": [["11419.40000", "0.65694471", "1596625634.887538"]], "c": "3649291545"}, "book-100", "XBT/USD"]
[270, {"a": [["11419.30000", "0.17500000", "1596625635.095413"]], "c": "3363152735"}, "book-100", "XBT/USD"]
[270, {"a": [["11421.00000", "0.63600000", "1596625635.218196"]], "c": "94616879"}, "book-100", "XBT/USD"]
