[270, {"a": [["11896.70000", "1.32705286", "1596737083.033938"]], "c": "4273504998"}, "book-100", "XBT/USD"]
[270, {"a": [["11876.50000", "0.00000000", "1596737083.076492"], ["11907.20000", "6.18638192", "1596736972.522950", "r"]], "c": "4273504998"}, "book-100", "XBT/USD"]
[270, {"a": [["11875.90000", "0.69462553", "1596737083.137390"]], "c": "4273504998"}, "book-100", "XBT/USD"]
[270, {"a": [["11894.30000", "0.28550236", "1596737083.259841"]], "c": "4273504998"}, "book-100", "XBT/USD"]
[270, {"a": [["11889.90000", "0.00000000", "1596737083.483867"], ["11907.00000", "8.54095785", "1596737002.155356", "r"]], "c": "4273504998"}, "book-100", "XBT/USD"]
[270, {"a": [["11904.70000", "1.24182769", "1596737083.484625"]], "c": "4273504998"}, "book-100", "XBT/USD"]
[270, {"b": [["11859.90000", "0.33041246", "1596737083.625766"]], "c": "4273504998"}, "book-100", "XBT/USD"]
[270, {"a": [["11884.80000", "0.32972021", "1596737083.628263"]], "c": "4273504998"}, "book-100", "XBT/USD"]
[270, {"b": [["11853.50000", "0.00000000", "1596737083.645670"], ["11811.80000", "4.23305508", "1596736972.960659", "r"]], "c": "4273504998"}, "book-100", "XBT/USD"]
[270, {"a": [["11888.20000", "0.69221441", "1596737083.651777"]], "c": "4273504998"}, "book-100", "XBT/USD"]
[270, {"b": [["11865.00000", "0.00000000", "1596737083.661064"], ["11811.70000", "5.70000000", "1596736886.902857", "r"]], "c": "1226213963"}, "book-100", "XBT/USD"]
[270, {"b": [["11855.80000", "0.53200827", "1596737083.662081"]], "c": "1226213963"}, "book-100", "XBT/USD"]
[270, {"b": [["11815.20000", "0.00000000", "1596737083.663153"], ["11808.80000", "2.66090576", "1596736784.110515", "r"]], "c": "1226213963"}, "book-100", "XBT/USD"]
[270, {"a": [["11897.20000", "0.00000000", "1596737083.666274"], ["11906.70000", "0.02328140", "1596737056.573166", "r"]], "c": "1226213963"}, "book-100", "XBT/USD"]
[270, {"b": [["11834.60000", "0.00000000", "1596737083.668095"], ["11808.70000", "9.70000000", "1596737024.924486", "r"]], "c": "1226213963"}, "book-100", "XBT/USD"]
[270, {"a": [["11895.70000", "0.43380571", "1596737083.672152"]], "c": "1226213963"}, "book-100", "XBT/USD"]
[270, {"b": [["11816.50000", "2.20886139", "1596737083.672362"]], "c": "1226213963"}, "book-100", "XBT/USD"]
[270, {"a": [["11896.70000", "2.06300668", "1596737083.673738"]], "c": "1226213963"}, "book-100", "XBT/USD"]
[270, {"a": [["11873.30000", "0.94206388", "1596737083.694360"]], "c": "1226213963"}, "book-100", "XBT/USD"]
[270, {"a": [["11871.00000", "0.00000000", "1596737083.695696"], ["11906.70000", "0.02328140", "1596737056.573166", "r"]], "c": "2712916302"}, "book-100", "XBT/USD"]
[270, {"a": [["11898.00000", "0.00000000", "1596737083.717452"], ["11907.00000", "8.54095785", "1596737002.155356", "r"]], "c": "2712916302"}, "book-100", "XBT/USD"]
[270, {"a": [["11895.70000", "0.00000000", "1596737083.855889"], ["11907.20000", "6.18638192", "1596736972.522950", "r"]], "c": "2712916302"}, "book-100", "XBT/USD"]
[270, {"a": [["11870.30000", "3.22438067", "1596737083.910395"]], "c": "3210969569"}, "book-100", "XBT/USD"]
[270, {"a": [["11870.30000", "3.03173067", "1596737084.005652"]], "c": "2712916302"}, "book-100", "XBT/USD"]
[270, {"b": [["11853.80000", "0.00675479", "1596737084.176360"]], "c": "2712916302"}, "book-100", "XBT/USD"]
[270, {"b": [["11834.30000", "0.73595382", "1596737084.213040"]], "c": "2712916302"}, "book-100", "XBT/USD"]
[270, {"a": [["11870.20000", "0.24015000", "1596737084.218397"]], "c": "3208490759"}, "book-100", "XBT/USD"]
[270, {"a": [["11889.90000", "0.46595977", "1596737084.246318"]], "c": "3208490759"}, "book-100", "XBT/USD"]
[270, {"a": [["11870.40000", "2.00500000", "1596737084.275139"]], "c": "2191861354"}, "book-100", "XBT/USD"]
[270, {"b": [["11853.80000", "0.00000000", "1596737084.305876"], ["11811.70000", "5.70000000", "1596736886.902857", "r"]], "c": "2191861354"}, "book-100", "XBT/USD"]
[270, {"b": [["11853.50000", "0.00675485", "1596737084.307033"]], "c": "2191861354"}, "book-100", "XBT/USD"]
[270, {"a": [["11904.80000", "0.00000000", "1596737084.339961"], ["11907.20000", "6.18638192", "1596736972.522950", "r"]], "c": "2191861354"}, "book-100", "XBT/USD"]
[270, {"a": [["11899.70000", "0.00000000", "1596737084.620880"], ["11907.50000", "3.26133727", "1596736967.970398", "r"]], "c": "2191861354"}, "book-100", "XBT/USD"]
[270, {"a": [["11889.80000", "0.20838930", "1596737085.292827"]], "c": "2191861354"}, "book-100", "XBT/USD"]
[270, {"a": [["11871.30000", "0.00000000", "1596737085.367138"], ["11907.80000", "2.11548927", "1596737083.667681", "r"]], "c": "3930938654"}, "book-100", "XBT/USD"]
[270, {"a": [["11869.80000", "7.84186378", "1596737085.382699"]], "c": "2162062883"}, "book-100", "XBT/USD"]
[270, {"a": [["11870.20000", "0.04750000", "1596737085.516588"]], "c": "3620269126"}, "book-100", "XBT/USD"]
[270, {"b": [["11859.40000", "0.97212000", "1596737085.589979"]], "c": "3620269126"}, "book-100", "XBT/USD"]
[270, {"a": [["11870.30000", "3.22438067", "1596737085.613797"]], "c": "3373841641"}, "book-100", "XBT/USD"]
[270, {"b": [["11849.10000", "0.00000000", "1596737085.630483"], ["11811.80000", "4.23305508", "1596736972.960659", "r"]], "c": "3373841641"}, "book-100", "XBT/USD"]
[270, {"b": [["11867.00000", "0.00000000", "1596737085.639280"], ["11811.70000", "5.70000000", "1596736886.902857", "r"]], "c": "1332869178"}, "book-100", "XBT/USD"]
[270, {"b": [["11866.40000", "0.25272019", "1596737085.715482"]], "c": "2488677878"}, "book-100", "XBT/USD"]
[270, {"a": [["11897.20000", "3.09559164", "1596737085.758510"]], "c": "2488677878"}, "book-100", "XBT/USD"]
[270, {"a": [["11897.20000", "3.59559164", "1596737085.788769"]], "c": "2488677878"}, "book-100", "XBT/USD"]
[270, {"b": [["11847.30000", "0.00444047", "1596737085.827548"]], "c": "2488677878"}, "book-100", "XBT/USD"]
[270, {"b": [["11852.40000", "0.00675546", "1596737085.834379"]], "c": "2488677878"}, "book-100", "XBT/USD"]
[270, {"b": [["11853.50000", "0.00000000", "1596737085.846704"], ["11813.30000", "0.99420000", "1596736809.783550", "r"]], "c": "2488677878"}, "book-100", "XBT/USD"]
[270, {"b": [["11857.70000", "0.00000000", "1596737085.904549"], ["11811.80000", "4.23305508", "1596736972.960659", "r"]], "c": "2488677878"}, "book-100", "XBT/USD"]
[270, {"b": [["11852.40000", "0.00000000", "1596737085.958409"], ["11811.70000", "5.70000000", "1596736886.902857", "r"]], "c": "2488677878"}, "book-100", "XBT/USD"]
[270, {"b": [["11852.40000", "0.00675539", "1596737085.967449"]], "c": "2488677878"}, "book-100", "XBT/USD"]
[270, {"b": [["11847.30000", "0.00000000", "1596737086.013438"], ["11811.70000", "5.70000000", "1596736886.902857", "r"]], "c": "2488677878"}, "book-100", "XBT/USD"]
[270, {"b": [["11854.70000", "0.00000000", "1596737086.095653"], ["11808.80000", "2.66090576", "1596736784.110515", "r"]], "c": "2488677878"}, "book-100", "XBT/USD"]
[270, {"b": [["11852.40000", "0.00000000", "1596737086.219050"], ["11808.70000", "9.70000000", "1596737024.924486", "r"]], "c": "2488677878"}, "book-100", "XBT/USD"]
[270, {"b": [["11852.40000", "0.00675519", "1596737086.219766"]], "c": "2488677878"}, "book-100", "XBT/USD"]
[270, {"b": [["11850.80000", "3.27647499", "1596737086.307611"]], "c": "2488677878"}, "book-100", "XBT/USD"]
[270, {"a": [["11881.90000", "6.60000000", "1596737086.517750"]], "c": "2488677878"}, "book-100", "XBT/USD"]
[270, {"b": [["11855.80000", "1.22611439", "1596737086.549295"]], "c": "2488677878"}, "book-100", "XBT/USD"]
[270, {"a": [["11870.30000", "3.03173067", "1596737086.645575"]], "c": "2324063577"}, "book-100", "XBT/USD"]
[270, {"b": [["11856.10000", "0.00000000", "1596737086.689839"], ["11808.80000", "2.66090576", "1596736784.110515", "r"]], "c": "2324063577"}, "book-100", "XBT/USD"]
[270, {"b": [["11850.70000", "1.00830000", "1596737086.701439"]], "c": "2324063577"}, "book-100", "XBT/USD"]
[270, {"b": [["11866.40000", "0.00000000", "1596737086.706741"], ["11808.80000", "2.66090576", "1596736784.110515", "r"]], "c": "151426579"}, "book-100", "XBT/USD"]
[270, {"b": [["11865.90000", "0.00000000", "1596737086.720484"], ["11808.70000", "9.70000000", "1596737024.924486", "r"]], "c": "2418634294"}, "book-100", "XBT/USD"]
[270, {"a": [["11872.30000", "0.00000000", "1596737086.735032"], ["11907.80000", "2.11548927", "1596737083.667681", "r"]], "c": "2418634294"}, "book-100", "XBT/USD"]
[270, {"a": [["11880.30000", "0.00000000", "1596737086.753075"], ["11907.90000", "2.38150000", "1596736895.960018", "r"]], "c": "2418634294"}, "book-100", "XBT/USD"]
[270, {"a": [["11869.80000", "8.04051378", "1596737086.765520"]], "c": "1248597927"}, "book-100", "XBT/USD"]
[270, {"a": [["11879.90000", "0.01000000", "1596737086.785478"]], "c": "1248597927"}, "book-100", "XBT/USD"]
[270, {"a": [["11878.20000", "7.20000000", "1596737086.791647"]], "c": "1248597927"}, "book-100", "XBT/USD"]
[270, {"b": [["11864.20000", "0.00000000", "1596737086.800588"], ["11808.00000", "0.17065000", "1596737017.603163", "r"]], "c": "3766169477"}, "book-100", "XBT/USD"]
[270, {"b": [["11863.80000", "0.00000000", "1596737086.801517"], ["11807.70000", "3.28855406", "1596736821.611246", "r"]], "c": "1073613599"}, "book-100", "XBT/USD"]
[270, {"b": [["11865.10000", "0.00000000", "1596737086.810023"], ["11807.50000", "2.19772556", "1596736916.776430", "r"]], "c": "323512296"}, "book-100", "XBT/USD"]
[270, {"b": [["11859.90000", "0.79641246", "1596737086.813043"]], "c": "323512296"}, "book-100", "XBT/USD"]
[270, {"a": [["11873.30000", "0.10000000", "1596737086.818536"]], "c": "323512296"}, "book-100", "XBT/USD"]
[270, {"b": [["11855.70000", "0.00000000", "1596737086.819321"], ["11806.30000", "5.40000000", "1596737051.417403", "r"]], "c": "323512296"}, "book-100", "XBT/USD"]
[270, {"a": [["11876.80000", "0.69329456", "1596737086.821706"]], "c": "323512296"}, "book-100", "XBT/USD"]
[270, {"b": [["11857.40000", "0.10931312", "1596737086.835773"]], "c": "323512296"}, "book-100", "XBT/USD"]
[270, {"b": [["11865.20000", "0.00000000", "1596737086.856568"], ["11805.90000", "0.15000000", "1596735155.182015", "r"]], "c": "780958454"}, "book-100", "XBT/USD"]
[270, {"a": [["11878.60000", "0.00000000", "1596737086.858419"], ["11907.80000", "2.11548927", "1596737083.667681", "r"]], "c": "780958454"}, "book-100", "XBT/USD"]
[270, {"a": [["11869.80000", "8.54051378", "1596737086.865696"]], "c": "1679186797"}, "book-100", "XBT/USD"]
[270, {"b": [["11852.40000", "0.01351058", "1596737086.870532"]], "c": "1679186797"}, "book-100", "XBT/USD"]
[270, {"b": [["11861.50000", "0.00000000", "1596737086.874951"], ["11805.20000", "0.34533000", "1596735143.806373", "r"]], "c": "2568075261"}, "book-100", "XBT/USD"]
[270, {"a": [["11873.50000", "0.00000000", "1596737086.879028"], ["11907.90000", "2.38150000", "1596736895.960018", "r"]], "c": "2568075261"}, "book-100", "XBT/USD"]
[270, {"b": [["11852.40000", "0.00675539", "1596737086.880676"]], "c": "2568075261"}, "book-100", "XBT/USD"]
[270, {"a": [["11902.20000", "0.00000000", "1596737086.888124"], ["11908.30000", "1.58322230", "1596736949.361051", "r"]], "c": "2568075261"}, "book-100", "XBT/USD"]
[270, {"b": [["11855.80000", "1.19044251", "1596737086.897969"]], "c": "2568075261"}, "book-100", "XBT/USD"]
[270, {"a": [["11870.00000", "0.88179242", "1596737086.904339"]], "c": "88796675"}, "book-100", "XBT/USD"]
[270, {"a": [["11907.80000", "0.00000000", "1596737086.904803"], ["11908.90000", "1.06880000", "1596736841.521829", "r"]], "c": "88796675"}, "book-100", "XBT/USD"]
[270, {"b": [["11862.60000", "0.00000000", "1596737086.920960"], ["11805.00000", "0.17065000", "1596737034.949636", "r"]], "c": "3971897700"}, "book-100", "XBT/USD"]
[270, {"a": [["11879.20000", "0.17587963", "1596737086.923099"]], "c": "3971897700"}, "book-100", "XBT/USD"]
[270, {"b": [["11863.30000", "0.10000000", "1596737086.926071"]], "c": "3156124147"}, "book-100", "XBT/USD"]
[270, {"b": [["11857.40000", "0.00000000", "1596737086.942332"], ["11805.00000", "0.17065000", "1596737034.949636", "r"]], "c": "3156124147"}, "book-100", "XBT/USD"]
[270, {"b": [["11859.90000", "0.46600000", "1596737086.958191"]], "c": "3156124147"}, "book-100", "XBT/USD"]
[270, {"b": [["11840.80000", "0.00000000", "1596737086.963716"], ["11804.80000", "3.28996656", "1596736677.195153", "r"]], "c": "3156124147"}, "book-100", "XBT/USD"]
[270, {"a": [["11869.80000", "9.32750378", "1596737086.970816"]], "c": "2062853190"}, "book-100", "XBT/USD"]
[270, {"b": [["11853.10000", "0.38000000", "1596737086.972502"]], "c": "2062853190"}, "book-100", "XBT/USD"]
[270, {"b": [["11856.30000", "0.78699000", "1596737086.977829"]], "c": "2062853190"}, "book-100", "XBT/USD"]
[270, {"a": [["11877.30000", "0.84210816", "1596737086.985657"]], "c": "2062853190"}, "book-100", "XBT/USD"]
[270, {"b": [["11852.40000", "0.00000000", "1596737086.994636"], ["11804.80000", "3.28996656", "1596736677.195153", "r"]], "c": "2062853190"}, "book-100", "XBT/USD"]
[270, {"b": [["11851.50000", "0.07215418", "1596737086.996726"]], "c": "2062853190"}, "book-100", "XBT/USD"]
[270, {"b": [["11863.30000", "0.00000000", "1596737087.008951"], ["11804.80000", "3.28996656", "1596736677.195153", "r"]], "c": "1467216994"}, "book-100", "XBT/USD"]
[270, {"b": [["11859.40000", "0.00000000", "1596737087.014524"], ["11803.60000", "3.21918392", "1596736692.311968", "r"]], "c": "1467216994"}, "book-100", "XBT/USD"]
[270, {"a": [["11871.10000", "0.09621094", "1596737087.014916"]], "c": "605904276"}, "book-100", "XBT/USD"]
[270, {"b": [["11861.70000", "0.07329444", "1596737087.022286"]], "c": "3615519876"}, "book-100", "XBT/USD"]
[270, {"b": [["11859.70000", "0.17590666", "1596737087.022511"]], "c": "3615519876"}, "book-100", "XBT/USD"]
[270, {"b": [["11853.50000", "0.02300000", "1596737087.023892"]], "c": "3615519876"}, "book-100", "XBT/USD"]
[270, {"b": [["11854.60000", "0.00000000", "1596737087.024315"], ["11805.00000", "0.17065000", "1596737034.949636", "r"]], "c": "3615519876"}, "book-100", "XBT/USD"]
[270, {"b": [["11863.30000", "0.10000000", "1596737087.057878"]], "c": "2621486878"}, "book-100", "XBT/USD"]
[270, {"a": [["11874.10000", "0.84226556", "1596737087.063903"]], "c": "2621486878"}, "book-100", "XBT/USD"]
[270, {"b": [["11853.70000", "1.52298246", "1596737087.066828"]], "c": "2621486878"}, "book-100", "XBT/USD"]
[270, {"a": [["11887.20000", "0.43788857", "1596737087.101950"]], "c": "2621486878"}, "book-100", "XBT/USD"]
[270, {"a": [["11889.90000", "0.00000000", "1596737087.102146"], ["11908.30000", "1.58322230", "1596736949.361051", "r"]], "c": "2621486878"}, "book-100", "XBT/USD"]
[270, {"b": [["11863.30000", "0.00000000", "1596737087.104508"], ["11805.00000", "0.17065000", "1596737034.949636", "r"]], "c": "3615519876"}, "book-100", "XBT/USD"]
[270, {"a": [["11876.10000", "0.09250000", "1596737087.112569"]], "c": "3615519876"}, "book-100", "XBT/USD"]
[270, {"a": [["11873.50000", "0.64938338", "1596737087.116243"]], "c": "3615519876"}, "book-100", "XBT/USD"]
[270, {"b": [["11851.50000", "0.10642841", "1596737087.137506"]], "c": "3615519876"}, "book-100", "XBT/USD"]
[270, {"a": [["11870.20000", "0.14650000", "1596737087.149175"]], "c": "2099524892"}, "book-100", "XBT/USD"]
[270, {"a": [["11870.30000", "2.40000000", "1596737087.150279"]], "c": "1929023768"}, "book-100", "XBT/USD"]
[270, {"b": [["11864.70000", "0.00000000", "1596737087.205939"], ["11804.80000", "3.28996656", "1596736677.195153", "r"]], "c": "3072658198"}, "book-100", "XBT/USD"]
[270, {"a": [["11887.70000", "0.00000000", "1596737087.258938"], ["11907.90000", "2.38150000", "1596736895.960018", "r"]], "c": "3072658198"}, "book-100", "XBT/USD"]
[270, {"a": [["11898.60000", "2.11972822", "1596737087.300185"]], "c": "3072658198"}, "book-100", "XBT/USD"]
[270, {"a": [["11870.00000", "0.63179242", "1596737087.308514"]], "c": "799912494"}, "book-100", "XBT/USD"]
[270, {"a": [["11877.60000", "0.00000000", "1596737087.309764"], ["11907.90000", "2.38150000", "1596736895.960018", "r"]], "c": "799912494"}, "book-100", "XBT/USD"]
[270, {"b": [["11855.80000", "0.49633639", "1596737087.326932"]], "c": "799912494"}, "book-100", "XBT/USD"]
[270, {"b": [["11853.40000", "0.00000000", "1596737087.339937"], ["11803.60000", "3.21918392", "1596736692.311968", "r"]], "c": "799912494"}, "book-100", "XBT/USD"]
[270, {"b": [["11855.00000", "0.00000000", "1596737087.367088"], ["11803.30000", "0.95003592", "1596736676.897446", "r"]], "c": "799912494"}, "book-100", "XBT/USD"]
[270, {"a": [["11871.40000", "0.29990130", "1596737087.370283"]], "c": "1329446869"}, "book-100", "XBT/USD"]
[270, {"a": [["11874.60000", "3.16985413", "1596737087.396446"]], "c": "1329446869"}, "book-100", "XBT/USD"]
[270, {"b": [["11853.40000", "0.10937297", "1596737087.423899"]], "c": "1329446869"}, "book-100", "XBT/USD"]
[270, {"b": [["11854.20000", "0.68090000", "1596737087.426174"]], "c": "1329446869"}, "book-100", "XBT/USD"]
[270, {"b": [["11857.00000", "0.56849327", "1596737087.436085"]], "c": "1329446869"}, "book-100", "XBT/USD"]
[270, {"b": [["11851.30000", "4.38683883", "1596737087.438595"]], "c": "1329446869"}, "book-100", "XBT/USD"]
[270, {"b": [["11854.30000", "0.00000000", "1596737087.438937"], ["11803.30000", "0.95003592", "1596736676.897446", "r"]], "c": "1329446869"}, "book-100", "XBT/USD"]
[270, {"b": [["11851.20000", "0.00000000", "1596737087.449058"], ["11802.00000", "7.67065000", "1596737087.435994", "r"]], "c": "1329446869"}, "book-100", "XBT/USD"]
[270, {"a": [["11877.50000", "0.00000000", "1596737087.452465"], ["11908.30000", "1.58322230", "1596736949.361051", "r"]], "c": "1329446869"}, "book-100", "XBT/USD"]
[270, {"b": [["11847.60000", "0.38000000", "1596737087.453338"]], "c": "1329446869"}, "book-100", "XBT/USD"]
[270, {"a": [["11884.80000", "0.00000000", "1596737087.453889"], ["11908.90000", "1.06880000", "1596736841.521829", "r"]], "c": "1329446869"}, "book-100", "XBT/USD"]
[270, {"b": [["11853.10000", "0.00000000", "1596737087.454084"], ["11802.00000", "7.67065000", "1596737087.435994", "r"]], "c": "1329446869"}, "book-100", "XBT/USD"]
[270, {"a": [["11877.60000", "0.04440539", "1596737087.454474"]], "c": "1329446869"}, "book-100", "XBT/USD"]
[270, {"a": [["11869.80000", "9.57750378", "1596737087.462856"]], "c": "3158154974"}, "book-100", "XBT/USD"]
[270, {"b": [["11851.30000", "1.27946341", "1596737087.469097"]], "c": "3158154974"}, "book-100", "XBT/USD"]
[270, {"a": [["11890.80000", "1.70588508", "1596737087.473917"]], "c": "3158154974"}, "book-100", "XBT/USD"]
[270, {"a": [["11888.20000", "0.00000000", "1596737087.485494"], ["11908.90000", "1.06880000", "1596736841.521829", "r"]], "c": "3158154974"}, "book-100", "XBT/USD"]
[270, {"a": [["11879.60000", "0.38000000", "1596737087.496321"]], "c": "3158154974"}, "book-100", "XBT/USD"]
[270, {"b": [["11856.20000", "3.08361506", "1596737087.549521"]], "c": "3158154974"}, "book-100", "XBT/USD"]
[270, {"a": [["11878.00000", "0.00000000", "1596737087.558991"], ["11908.90000", "1.06880000", "1596736841.521829", "r"]], "c": "3158154974"}, "book-100", "XBT/USD"]
[270, {"a": [["11883.40000", "0.00000000", "1596737087.617863"], ["11909.10000", "1.00200000", "1596736809.784670", "r"]], "c": "3158154974"}, "book-100", "XBT/USD"]
[270, {"b": [["11861.20000", "0.00000000", "1596737087.618558"], ["11802.00000", "7.67065000", "1596737087.435994", "r"]], "c": "275814709"}, "book-100", "XBT/USD"]
[270, {"b": [["11848.40000", "1.09961486", "1596737087.625352"]], "c": "275814709"}, "book-100", "XBT/USD"]
[270, {"b": [["11851.90000", "0.20466444", "1596737087.637319"]], "c": "275814709"}, "book-100", "XBT/USD"]
[270, {"b": [["11851.90000", "0.97039109", "1596737087.662383"]], "c": "275814709"}, "book-100", "XBT/USD"]
[270, {"b": [["11863.30000", "0.10000000", "1596737087.671418"]], "c": "628383272"}, "book-100", "XBT/USD"]
[270, {"b": [["11847.20000", "8.04624702", "1596737087.682033"]], "c": "628383272"}, "book-100", "XBT/USD"]
[270, {"b": [["11860.80000", "0.00000000", "1596737087.693568"], ["11803.30000", "0.95003592", "1596736676.897446", "r"]], "c": "1190784547"}, "book-100", "XBT/USD"]
[270, {"b": [["11851.40000", "0.00000000", "1596737087.701454"], ["11802.00000", "7.67065000", "1596737087.435994", "r"]], "c": "1190784547"}, "book-100", "XBT/USD"]
[270, {"b": [["11858.70000", "0.00000000", "1596737087.741627"], ["11801.90000", "4.67249674", "1596736908.903243", "r"]], "c": "1190784547"}, "book-100", "XBT/USD"]
[270, {"b": [["11863.30000", "0.00000000", "1596737087.744719"], ["11801.80000", "3.19470719", "1596736911.648608", "r"]], "c": "3164712327"}, "book-100", "XBT/USD"]
[270, {"a": [["11882.40000", "0.00000000", "1596737087.750304"], ["11909.90000", "6.20000000", "1596736825.518690", "r"]], "c": "3164712327"}, "book-100", "XBT/USD"]
[270, {"a": [["11893.40000", "0.00000000", "1596737087.773454"], ["11910.00000", "0.36067000", "1596736968.148143", "r"]], "c": "3164712327"}, "book-100", "XBT/USD"]
[270, {"a": [["11876.20000", "0.00000000", "1596737087.807863"], ["11910.50000", "1.68800000", "1596736995.994117", "r"]], "c": "3164712327"}, "book-100", "XBT/USD"]
[270, {"a": [["11890.80000", "0.76309500", "1596737087.811119"]], "c": "3164712327"}, "book-100", "XBT/USD"]
[270, {"a": [["11869.80000", "9.72750378", "1596737087.811689"]], "c": "2810031515"}, "book-100", "XBT/USD"]
[270, {"b": [["11845.50000", "2.19051174", "1596737087.814701"]], "c": "2810031515"}, "book-100", "XBT/USD"]
[270, {"a": [["11890.80000", "0.00000000", "1596737087.817352"], ["11910.70000", "1.58924162", "1596736944.279722", "r"]], "c": "2810031515"}, "book-100", "XBT/USD"]
[270, {"b": [["11850.80000", "3.38247499", "1596737087.847965"]], "c": "2810031515"}, "book-100", "XBT/USD"]
[270, {"b": [["11846.80000", "0.00000000", "1596737087.853292"], ["11801.80000", "3.19470719", "1596736911.648608", "r"]], "c": "2810031515"}, "book-100", "XBT/USD"]
[270, {"b": [["11855.00000", "0.09621094", "1596737087.858780"]], "c": "2810031515"}, "book-100", "XBT/USD"]
[270, {"a": [["11877.70000", "0.28399999", "1596737087.860361"]], "c": "2810031515"}, "book-100", "XBT/USD"]
[270, {"a": [["11875.90000", "0.00000000", "1596737087.896673"], ["11911.10000", "2.17890497", "1596737013.284792", "r"]], "c": "2810031515"}, "book-100", "XBT/USD"]
[270, {"a": [["11887.20000", "0.00000000", "1596737087.910144"], ["11911.60000", "0.75800000", "1596737003.974614", "r"]], "c": "2810031515"}, "book-100", "XBT/USD"]
[270, {"a": [["11870.30000", "2.00000000", "1596737087.913988"], ["11869.80000", "10.12750378", "1596737087.915164"]], "c": "1825494508"}, "book-100", "XBT/USD"]
[270, {"a": [["11879.20000", "0.00000000", "1596737087.924851"], ["11913.00000", "0.17065000", "1596736890.849460", "r"]], "c": "1825494508"}, "book-100", "XBT/USD"]
[270, {"b": [["11857.40000", "0.27100000", "1596737087.975999"]], "c": "1825494508"}, "book-100", "XBT/USD"]
[270, {"b": [["11866.00000", "0.00000000", "1596737088.004362"], ["11801.90000", "4.67249674", "1596736908.903243", "r"]], "c": "631325308"}, "book-100", "XBT/USD"]
[270, {"b": [["11808.00000", "0.00000000", "1596737088.004650"], ["11801.80000", "3.19470719", "1596736911.648608", "r"]], "c": "631325308"}, "book-100", "XBT/USD"]
[270, {"b": [["11856.30000", "0.00000000", "1596737088.009725"], ["11800.00000", "17.03324285", "1596736993.942623", "r"]], "c": "631325308"}, "book-100", "XBT/USD"]
[270, {"b": [["11853.50000", "0.00000000", "1596737088.010618"], ["11799.20000", "23.14040000", "1596736141.974806", "r"]], "c": "631325308"}, "book-100", "XBT/USD"]
[270, {"b": [["11851.30000", "0.00000000", "1596737088.011207"], ["11799.00000", "0.17065000", "1596736867.992954", "r"]], "c": "631325308"}, "book-100", "XBT/USD"]
[270, {"b": [["11861.70000", "0.00000000", "1596737088.020463"], ["11796.30000", "10.90540000", "1596736141.718106", "r"]], "c": "3306392903"}, "book-100", "XBT/USD"]
[270, {"b": [["11853.00000", "0.88564000", "1596737088.044623"]], "c": "3306392903"}, "book-100", "XBT/USD"]
[270, {"a": [["11888.40000", "0.87241128", "1596737088.047095"]], "c": "3306392903"}, "book-100", "XBT/USD"]
[270, {"b": [["11849.50000", "0.53031999", "1596737088.048100"]], "c": "3306392903"}, "book-100", "XBT/USD"]
[270, {"a": [["11885.70000", "5.89564730", "1596737088.082510"]], "c": "3306392903"}, "book-100", "XBT/USD"]
[270, {"b": [["11853.10000", "0.02300000", "1596737088.083092"]], "c": "3306392903"}, "book-100", "XBT/USD"]
[270, {"b": [["11851.20000", "1.38875107", "1596737088.093499"]], "c": "3306392903"}, "book-100", "XBT/USD"]
[270, {"a": [["11885.60000", "0.46586517", "1596737088.099854"]], "c": "3306392903"}, "book-100", "XBT/USD"]
[270, {"b": [["11853.50000", "0.69424080", "1596737088.106652"]], "c": "3306392903"}, "book-100", "XBT/USD"]
[270, {"a": [["11873.60000", "0.50000000", "1596737088.117647"]], "c": "3306392903"}, "book-100", "XBT/USD"]
[270, {"a": [["11874.50000", "0.66496637", "1596737088.134689"]], "c": "3306392903"}, "book-100", "XBT/USD"]
[270, {"a": [["11877.70000", "0.00000000", "1596737088.151492"], ["11911.10000", "2.17890497", "1596737013.284792", "r"]], "c": "3306392903"}, "book-100", "XBT/USD"]
[270, {"a": [["11872.70000", "0.28399999", "1596737088.187293"]], "c": "3306392903"}, "book-100", "XBT/USD"]
[270, {"a": [["11871.00000", "0.40020112", "1596737088.203944"]], "c": "449001022"}, "book-100", "XBT/USD"]
[270, {"b": [["11863.50000", "0.10000000", "1596737088.219125"]], "c": "3270610855"}, "book-100", "XBT/USD"]
[270, {"a": [["11872.70000", "0.56299999", "1596737088.220769"]], "c": "3270610855"}, "book-100", "XBT/USD"]
[270, {"b": [["11863.30000", "0.10000000", "1596737088.235942"]], "c": "596138801"}, "book-100", "XBT/USD"]
[270, {"a": [["11869.90000", "0.00000000", "1596737088.252572"], ["11910.70000", "1.58924162", "1596736944.279722", "r"]], "c": "1068839126"}, "book-100", "XBT/USD"]
[270, {"a": [["11878.90000", "0.00000000", "1596737088.263938"], ["11911.10000", "2.17890497", "1596737013.284792", "r"]], "c": "1068839126"}, "book-100", "XBT/USD"]
[270, {"b": [["11863.30000", "0.00000000", "1596737088.284402"], ["11802.00000", "7.67065000", "1596737087.435994", "r"]], "c": "3737969728"}, "book-100", "XBT/USD"]
[270, {"a": [["11877.60000", "0.00000000", "1596737088.292148"], ["11911.60000", "0.75800000", "1596737003.974614", "r"]], "c": "3737969728"}, "book-100", "XBT/USD"]
[270, {"a": [["11878.10000", "0.04440539", "1596737088.293475"]], "c": "3737969728"}, "book-100", "XBT/USD"]
[270, {"a": [["11871.80000", "0.18656000", "1596737088.293545"]], "c": "4125907960"}, "book-100", "XBT/USD"]
[270, {"b": [["11853.10000", "0.00000000", "1596737088.314982"], ["11801.90000", "4.67249674", "1596736908.903243", "r"]], "c": "4125907960"}, "book-100", "XBT/USD"]
[270, {"a": [["11876.90000", "0.85992960", "1596737088.316496"]], "c": "4125907960"}, "book-100", "XBT/USD"]
[270, {"b": [["11863.30000", "0.10000000", "1596737088.337122"]], "c": "345345902"}, "book-100", "XBT/USD"]
[270, {"a": [["11888.30000", "0.94297567", "1596737088.343959"]], "c": "345345902"}, "book-100", "XBT/USD"]
[270, {"b": [["11849.00000", "0.47078264", "1596737088.351799"]], "c": "345345902"}, "book-100", "XBT/USD"]
[270, {"b": [["11849.00000", "0.00000000", "1596737088.362056"], ["11801.90000", "4.67249674", "1596736908.903243", "r"]], "c": "345345902"}, "book-100", "XBT/USD"]
[270, {"a": [["11869.80000", "10.82750378", "1596737088.369653"]], "c": "1340579024"}, "book-100", "XBT/USD"]
[270, {"b": [["11857.00000", "0.23800000", "1596737088.374012"]], "c": "1340579024"}, "book-100", "XBT/USD"]
[270, {"b": [["11851.10000", "0.27711207", "1596737088.376445"]], "c": "1340579024"}, "book-100", "XBT/USD"]
[270, {"b": [["11848.80000", "0.00000000", "1596737088.378891"], ["11801.80000", "3.19470719", "1596736911.648608", "r"]], "c": "1340579024"}, "book-100", "XBT/USD"]
[270, {"b": [["11848.70000", "0.00000000", "1596737088.389221"], ["11800.00000", "17.03324285", "1596736993.942623", "r"]], "c": "1340579024"}, "book-100", "XBT/USD"]
[270, {"b": [["11855.00000", "0.00000000", "1596737088.397728"], ["11799.20000", "23.14040000", "1596736141.974806", "r"]], "c": "1340579024"}, "book-100", "XBT/USD"]
[270, {"b": [["11853.70000", "0.57727578", "1596737088.399571"]], "c": "1340579024"}, "book-100", "XBT/USD"]
[270, {"b": [["11843.80000", "1.28073270", "1596737088.402281"]], "c": "1340579024"}, "book-100", "XBT/USD"]
[270, {"b": [["11862.90000", "0.00000000", "1596737088.403876"], ["11799.20000", "23.14040000", "1596736141.974806", "r"]], "c": "2408957716"}, "book-100", "XBT/USD"]
[270, {"a": [["11905.70000", "0.50000000", "1596737088.410554"]], "c": "2408957716"}, "book-100", "XBT/USD"]
[270, {"a": [["11869.80000", "10.92650378", "1596737088.413356"]], "c": "859869782"}, "book-100", "XBT/USD"]
[270, {"a": [["11869.80000", "10.22650378", "1596737088.414373"]], "c": "963944559"}, "book-100", "XBT/USD"]
[270, {"b": [["11863.30000", "0.00000000", "1596737088.424682"], ["11799.00000", "0.17065000", "1596736867.992954", "r"]], "c": "4059953982"}, "book-100", "XBT/USD"]
[270, {"b": [["11855.90000", "0.33688307", "1596737088.429904"]], "c": "4059953982"}, "book-100", "XBT/USD"]
[270, {"a": [["11869.80000", "10.72650378", "1596737088.431285"]], "c": "2523540435"}, "book-100", "XBT/USD"]
[270, {"a": [["11869.80000", "12.22650378", "1596737088.442409"]], "c": "2188422044"}, "book-100", "XBT/USD"]
[270, {"a": [["11884.00000", "0.00000000", "1596737088.446442"], ["11910.70000", "1.58924162", "1596736944.279722", "r"]], "c": "2188422044"}, "book-100", "XBT/USD"]
[270, {"a": [["11869.90000", "0.70000000", "1596737088.464006"]], "c": "3043852227"}, "book-100", "XBT/USD"]
[270, {"a": [["11898.00000", "0.17065000", "1596737088.466567"]], "c": "3043852227"}, "book-100", "XBT/USD"]
[270, {"b": [["11851.00000", "7.73699140", "1596737088.477656"]], "c": "3043852227"}, "book-100", "XBT/USD"]
[270, {"b": [["11861.30000", "0.25280305", "1596737088.477798"]], "c": "1625959518"}, "book-100", "XBT/USD"]
[270, {"b": [["11859.80000", "0.33701308", "1596737088.477950"]], "c": "3200071280"}, "book-100", "XBT/USD"]
[270, {"a": [["11872.40000", "0.84243363", "1596737088.478244"]], "c": "3200071280"}, "book-100", "XBT/USD"]
[270, {"a": [["11869.90000", "1.33193158", "1596737088.479207"]], "c": "232941836"}, "book-100", "XBT/USD"]
[270, {"a": [["11870.10000", "0.84253271", "1596737088.479358"]], "c": "169283079"}, "book-100", "XBT/USD"]
[270, {"a": [["11869.80000", "13.06907950", "1596737088.479510"]], "c": "3909860313"}, "book-100", "XBT/USD"]
[270, {"b": [["11848.10000", "0.33704772", "1596737088.480851"]], "c": "3909860313"}, "book-100", "XBT/USD"]
[270, {"a": [["11885.60000", "0.00000000", "1596737088.509260"], ["11909.90000", "6.20000000", "1596736825.518690", "r"]], "c": "3909860313"}, "book-100", "XBT/USD"]
[270, {"a": [["11869.80000", "14.16907950", "1596737088.510472"]], "c": "2238014718"}, "book-100", "XBT/USD"]
[270, {"a": [["11869.90000", "0.63193158", "1596737088.511839"]], "c": "4225990637"}, "book-100", "XBT/USD"]
[270, {"b": [["11843.40000", "0.00000000", "1596737088.516621"], ["11800.00000", "17.03324285", "1596736993.942623", "r"]], "c": "4225990637"}, "book-100", "XBT/USD"]
[270, {"b": [["11830.10000", "2.62605599", "1596737088.573358"]], "c": "4225990637"}, "book-100", "XBT/USD"]
[270, {"b": [["11841.50000", "1.06135654", "1596737088.658228"]], "c": "4225990637"}, "book-100", "XBT/USD"]
[270, {"b": [["11867.80000", "0.00000000", "1596737088.663107"], ["11801.80000", "3.19470719", "1596736911.648608", "r"]], "c": "2018857360"}, "book-100", "XBT/USD"]
[270, {"a": [["11876.80000", "0.96429456", "1596737088.665252"]], "c": "2018857360"}, "book-100", "XBT/USD"]
[270, {"a": [["11885.60000", "0.54475927", "1596737088.690594"]], "c": "2018857360"}, "book-100", "XBT/USD"]
[270, {"b": [["11836.20000", "0.05224265", "1596737088.722293"]], "c": "2018857360"}, "book-100", "XBT/USD"]
[270, {"b": [["11841.20000", "0.47115358", "1596737088.753992"]], "c": "2018857360"}, "book-100", "XBT/USD"]
[270, {"b": [["11856.60000", "0.09600000", "1596737088.891673"]], "c": "2018857360"}, "book-100", "XBT/USD"]
[270, {"a": [["11869.80000", "13.66907950", "1596737088.977637"]], "c": "3822451021"}, "book-100", "XBT/USD"]
[270, {"b": [["11805.00000", "0.00000000", "1596737089.133686"], ["11802.00000", "7.67065000", "1596737087.435994", "r"]], "c": "3822451021"}, "book-100", "XBT/USD"]
[270, {"b": [["11860.40000", "1.68200000", "1596737089.303726"]], "c": "3003580554"}, "book-100", "XBT/USD"]
[270, {"a": [["11897.20000", "0.50000000", "1596737089.393804"]], "c": "3003580554"}, "book-100", "XBT/USD"]
[270, {"b": [["11843.80000", "3.03423819", "1596737089.400215"]], "c": "3003580554"}, "book-100", "XBT/USD"]
[270, {"a": [["11882.30000", "0.32977810", "1596737089.400944"]], "c": "3003580554"}, "book-100", "XBT/USD"]
[270, {"a": [["11888.40000", "0.76337570", "1596737089.403141"]], "c": "3003580554"}, "book-100", "XBT/USD"]
[270, {"a": [["11885.70000", "6.58798321", "1596737089.403254"]], "c": "3003580554"}, "book-100", "XBT/USD"]
[270, {"a": [["11888.10000", "1.38439227", "1596737089.411192"]], "c": "3003580554"}, "book-100", "XBT/USD"]
[270, {"a": [["11889.80000", "0.20400744", "1596737089.413256"]], "c": "3003580554"}, "book-100", "XBT/USD"]
[270, {"a": [["11894.30000", "0.00000000", "1596737089.438962"], ["11908.90000", "1.06880000", "1596736841.521829", "r"]], "c": "3003580554"}, "book-100", "XBT/USD"]
[270, {"b": [["11855.60000", "0.33052079", "1596737089.441968"]], "c": "3003580554"}, "book-100", "XBT/USD"]
[270, {"a": [["11874.50000", "0.00000000", "1596737089.449682"], ["11909.10000", "1.00200000", "1596736809.784670", "r"]], "c": "3003580554"}, "book-100", "XBT/USD"]
[270, {"b": [["11851.10000", "0.25411207", "1596737089.496710"]], "c": "3003580554"}, "book-100", "XBT/USD"]
[270, {"a": [["11869.80000", "14.16907950", "1596737089.502488"]], "c": "1274949195"}, "book-100", "XBT/USD"]
[270, {"b": [["11860.40000", "0.00000000", "1596737089.507234"], ["11803.30000", "0.95003592", "1596736676.897446", "r"]], "c": "2018857360"}, "book-100", "XBT/USD"]
[270, {"b": [["11850.10000", "0.02300000", "1596737089.551693"]], "c": "2018857360"}, "book-100", "XBT/USD"]
[270, {"a": [["11885.90000", "0.10907661", "1596737089.646806"]], "c": "2018857360"}, "book-100", "XBT/USD"]
[270, {"a": [["11872.60000", "0.68613989", "1596737089.660721"]], "c": "2018857360"}, "book-100", "XBT/USD"]
[270, {"a": [["11869.80000", "13.66907950", "1596737089.896366"]], "c": "3822451021"}, "book-100", "XBT/USD"]
[270, {"b": [["11841.30000", "1.89379419", "1596737089.989080"]], "c": "3822451021"}, "book-100", "XBT/USD"]
[270, {"a": [["11869.80000", "13.41907950", "1596737089.989945"]], "c": "1613251680"}, "book-100", "XBT/USD"]
[270, {"b": [["11849.50000", "1.47648526", "1596737089.991821"]], "c": "1613251680"}, "book-100", "XBT/USD"]
[270, {"a": [["11891.80000", "0.28556884", "1596737090.057975"]], "c": "1613251680"}, "book-100", "XBT/USD"]
[270, {"a": [["11873.50000", "0.00000000", "1596737090.066051"], ["11908.30000", "1.58322230", "1596736949.361051", "r"]], "c": "1613251680"}, "book-100", "XBT/USD"]
[270, {"a": [["11885.60000", "0.00000000", "1596737090.355196"], ["11908.90000", "1.06880000", "1596736841.521829", "r"]], "c": "1613251680"}, "book-100", "XBT/USD"]
[270, {"a": [["11872.10000", "0.64893229", "1596737090.391812"]], "c": "1613251680"}, "book-100", "XBT/USD"]
[270, {"b": [["11863.20000", "0.00000000", "1596737090.466079"], ["11803.30000", "0.95003592", "1596736676.897446", "r"]], "c": "101710425"}, "book-100", "XBT/USD"]
[270, {"a": [["11869.80000", "13.91907950", "1596737090.489683"]], "c": "1098917317"}, "book-100", "XBT/USD"]
[270, {"b": [["11834.20000", "0.00000000", "1596737090.496446"], ["11802.00000", "7.67065000", "1596737087.435994", "r"]], "c": "1098917317"}, "book-100", "XBT/USD"]
[270, {"a": [["11893.70000", "3.00000000", "1596737090.500604"]], "c": "1098917317"}, "book-100", "XBT/USD"]
[270, {"a": [["11872.60000", "0.00000000", "1596737090.539621"], ["11908.30000", "1.58322230", "1596736949.361051", "r"]], "c": "1098917317"}, "book-100", "XBT/USD"]
[270, {"a": [["11885.70000", "0.69233591", "1596737090.577761"]], "c": "1098917317"}, "book-100", "XBT/USD"]
[270, {"a": [["11873.50000", "6.30000000", "1596737090.655841"]], "c": "1098917317"}, "book-100", "XBT/USD"]
[270, {"b": [["11827.90000", "5.47601262", "1596737090.658778"]], "c": "1098917317"}, "book-100", "XBT/USD"]
[270, {"a": [["11872.40000", "1.49582380", "1596737090.695694"]], "c": "1098917317"}, "book-100", "XBT/USD"]
[270, {"b": [["11838.50000", "0.00000000", "1596737090.698882"], ["11802.00000", "7.67065000", "1596737087.435994", "r"]], "c": "1098917317"}, "book-100", "XBT/USD"]
[270, {"b": [["11841.10000", "3.27930321", "1596737090.714937"]], "c": "1098917317"}, "book-100", "XBT/USD"]
[270, {"a": [["11879.90000", "5.90793067", "1596737090.738822"]], "c": "1098917317"}, "book-100", "XBT/USD"]
[270, {"b": [["11834.30000", "0.00000000", "1596737090.791615"], ["11802.00000", "7.67065000", "1596737087.435994", "r"]], "c": "1098917317"}, "book-100", "XBT/USD"]
[270, {"a": [["11896.70000", "1.32705286", "1596737090.791678"]], "c": "1098917317"}, "book-100", "XBT/USD"]
[270, {"b": [["11831.70000", "0.73618854", "1596737090.792087"]], "c": "1098917317"}, "book-100", "XBT/USD"]
[270, {"b": [["11836.50000", "0.01000000", "1596737090.918434"]], "c": "1098917317"}, "book-100", "XBT/USD"]
[270, {"b": [["11852.60000", "0.09621094", "1596737090.929560"]], "c": "1098917317"}, "book-100", "XBT/USD"]
[270, {"a": [["11884.10000", "0.42754046", "1596737091.023526"]], "c": "1098917317"}, "book-100", "XBT/USD"]
[270, {"a": [["11894.50000", "0.73618854", "1596737091.033001"]], "c": "1098917317"}, "book-100", "XBT/USD"]
[270, {"b": [["11861.50000", "4.21000000", "1596737091.034245"]], "c": "3134948533"}, "book-100", "XBT/USD"]
[270, {"a": [["11890.70000", "9.06562417", "1596737091.077321"]], "c": "3134948533"}, "book-100", "XBT/USD"]
[270, {"b": [["11853.50000", "0.00000000", "1596737091.135519"], ["11804.80000", "3.28996656", "1596736677.195153", "r"]], "c": "3134948533"}, "book-100", "XBT/USD"]
[270, {"a": [["11884.10000", "0.00000000", "1596737091.252229"], ["11907.50000", "3.26133727", "1596736967.970398", "r"]], "c": "3134948533"}, "book-100", "XBT/USD"]
[270, {"a": [["11884.10000", "0.43080051", "1596737091.442478"]], "c": "3134948533"}, "book-100", "XBT/USD"]
[271, [["11869.70000", "0.00815367", "1596737091.508303", "s", "l", ""]], "trade", "XBT/USD"]
[270, {"b": [["11869.70000", "0.19184633", "1596737091.508303"]], "c": "4191443157"}, "book-100", "XBT/USD"]
[270, {"a": [["11869.80000", "14.61907950", "1596737091.573511"]], "c": "4231884885"}, "book-100", "XBT/USD"]
[270, {"b": [["11851.70000", "0.69432207", "1596737091.652701"]], "c": "4231884885"}, "book-100", "XBT/USD"]
[270, {"b": [["11851.90000", "0.76572665", "1596737091.652774"]], "c": "4231884885"}, "book-100", "XBT/USD"]
[270, {"b": [["11842.10000", "0.65000000", "1596737091.667812"]], "c": "4231884885"}, "book-100", "XBT/USD"]
[270, {"a": [["11896.80000", "0.00000000", "1596737091.702547"], ["11907.50000", "3.26133727", "1596736967.970398", "r"]], "c": "4231884885"}, "book-100", "XBT/USD"]
[270, {"b": [["11850.80000", "0.10600000", "1596737091.709742"]], "c": "4231884885"}, "book-100", "XBT/USD"]
[270, {"a": [["11884.10000", "0.00000000", "1596737091.761785"], ["11907.90000", "2.38150000", "1596736895.960018", "r"]], "c": "4231884885"}, "book-100", "XBT/USD"]
[270, {"b": [["11843.10000", "3.10949229", "1596737091.882346"]], "c": "4231884885"}, "book-100", "XBT/USD"]
[270, {"a": [["11893.70000", "6.09626341", "1596737091.885892"]], "c": "4231884885"}, "book-100", "XBT/USD"]
[270, {"b": [["11846.50000", "3.27780841", "1596737091.902596"]], "c": "4231884885"}, "book-100", "XBT/USD"]
[270, {"b": [["11851.90000", "0.00000000", "1596737091.938676"], ["11806.30000", "5.40000000", "1596737051.417403", "r"]], "c": "4231884885"}, "book-100", "XBT/USD"]
[270, {"a": [["11885.60000", "0.59499591", "1596737091.943418"]], "c": "4231884885"}, "book-100", "XBT/USD"]
[270, {"a": [["11893.70000", "7.84241207", "1596737092.076865"]], "c": "4231884885"}, "book-100", "XBT/USD"]
[270, {"a": [["11872.40000", "0.84243363", "1596737092.134817"]], "c": "4231884885"}, "book-100", "XBT/USD"]
[270, {"b": [["11848.90000", "0.20474610", "1596737092.220928"]], "c": "4231884885"}, "book-100", "XBT/USD"]
[270, {"a": [["11872.30000", "0.68082059", "1596737092.296772"]], "c": "4231884885"}, "book-100", "XBT/USD"]
[270, {"b": [["11848.80000", "0.76592699", "1596737092.297391"]], "c": "4231884885"}, "book-100", "XBT/USD"]
[270, {"a": [["11885.60000", "0.00000000", "1596737092.353106"], ["11907.50000", "3.26133727", "1596736967.970398", "r"]], "c": "4231884885"}, "book-100", "XBT/USD"]
[270, {"a": [["11896.70000", "0.05222663", "1596737092.464944"]], "c": "4231884885"}, "book-100", "XBT/USD"]
[270, {"a": [["11884.10000", "0.44662467", "1596737092.533529"]], "c": "4231884885"}, "book-100", "XBT/USD"]
[270, {"b": [["11836.50000", "0.00000000", "1596737092.653645"], ["11807.50000", "2.19772556", "1596736916.776430", "r"]], "c": "4231884885"}, "book-100", "XBT/USD"]
[270, {"b": [["11842.90000", "6.49595105", "1596737092.667342"]], "c": "4231884885"}, "book-100", "XBT/USD"]
[270, {"a": [["11893.60000", "1.27537011", "1596737092.687076"]], "c": "4231884885"}, "book-100", "XBT/USD"]
[270, {"a": [["11884.10000", "0.00000000", "1596737092.860241"], ["11907.20000", "6.18638192", "1596736972.522950", "r"]], "c": "4231884885"}, "book-100", "XBT/USD"]
[270, {"b": [["11855.60000", "0.00000000", "1596737092.923427"], ["11807.50000", "2.19772556", "1596736916.776430", "r"]], "c": "4231884885"}, "book-100", "XBT/USD"]
[270, {"b": [["11853.40000", "0.00000000", "1596737092.943184"], ["11806.30000", "5.40000000", "1596737051.417403", "r"]], "c": "4231884885"}, "book-100", "XBT/USD"]
[270, {"b": [["11835.50000", "0.01000000", "1596737092.979206"]], "c": "4231884885"}, "book-100", "XBT/USD"]
[270, {"a": [["11884.10000", "0.43098215", "1596737093.042980"]], "c": "4231884885"}, "book-100", "XBT/USD"]
[270, {"b": [["11851.10000", "0.36350898", "1596737093.124882"]], "c": "4231884885"}, "book-100", "XBT/USD"]
[270, {"b": [["11854.60000", "0.33054868", "1596737093.326666"]], "c": "4231884885"}, "book-100", "XBT/USD"]
[270, {"a": [["11895.00000", "0.42065000", "1596737093.949715"]], "c": "4231884885"}, "book-100", "XBT/USD"]
[270, {"a": [["11897.20000", "0.00000000", "1596737093.994379"], ["11907.20000", "6.18638192", "1596736972.522950", "r"]], "c": "4231884885"}, "book-100", "XBT/USD"]
[270, {"a": [["11869.80000", "14.52007950", "1596737094.087361"]], "c": "1353964947"}, "book-100", "XBT/USD"]
[270, {"b": [["11859.20000", "0.10300000", "1596737094.089974"]], "c": "1353964947"}, "book-100", "XBT/USD"]
[270, {"a": [["11874.10000", "0.00000000", "1596737094.270062"], ["11907.50000", "3.26133727", "1596736967.970398", "r"]], "c": "1353964947"}, "book-100", "XBT/USD"]
[270, {"b": [["11835.50000", "0.00000000", "1596737094.479250"], ["11807.70000", "3.28855406", "1596736821.611246", "r"]], "c": "1353964947"}, "book-100", "XBT/USD"]
[270, {"a": [["11872.40000", "1.68473078", "1596737094.494811"]], "c": "1353964947"}, "book-100", "XBT/USD"]
[270, {"a": [["11869.80000", "14.02007950", "1596737094.646686"]], "c": "925109630"}, "book-100", "XBT/USD"]
[270, {"b": [["11835.00000", "0.01000000", "1596737094.656098"]], "c": "925109630"}, "book-100", "XBT/USD"]
[270, {"a": [["11879.90000", "0.01000000", "1596737094.688957"]], "c": "925109630"}, "book-100", "XBT/USD"]
[270, {"a": [["11885.70000", "0.00000000", "1596737094.721674"], ["11907.90000", "2.38150000", "1596736895.960018", "r"]], "c": "925109630"}, "book-100", "XBT/USD"]
[270, {"a": [["11882.30000", "0.00000000", "1596737094.723805"], ["11908.30000", "1.58322230", "1596736949.361051", "r"]], "c": "925109630"}, "book-100", "XBT/USD"]
[270, {"a": [["11881.80000", "5.89793067", "1596737094.773634"]], "c": "925109630"}, "book-100", "XBT/USD"]
[270, {"a": [["11893.20000", "0.00000000", "1596737094.798745"], ["11908.30000", "1.58322230", "1596736949.361051", "r"]], "c": "925109630"}, "book-100", "XBT/USD"]
[270, {"a": [["11898.80000", "3.26359125", "1596737094.802836"]], "c": "925109630"}, "book-100", "XBT/USD"]
[270, {"a": [["11872.10000", "0.00000000", "1596737094.803874"], ["11908.90000", "1.06880000", "1596736841.521829", "r"]], "c": "925109630"}, "book-100", "XBT/USD"]
[270, {"a": [["11896.50000", "0.00000000", "1596737094.840804"], ["11909.10000", "1.00200000", "1596736809.784670", "r"]], "c": "925109630"}, "book-100", "XBT/USD"]
[270, {"b": [["11849.90000", "0.23800000", "1596737094.841035"]], "c": "925109630"}, "book-100", "XBT/USD"]
[270, {"b": [["11857.00000", "0.00000000", "1596737094.841193"], ["11808.70000", "9.70000000", "1596737024.924486", "r"]], "c": "925109630"}, "book-100", "XBT/USD"]
[270, {"a": [["11888.10000", "0.00000000", "1596737095.026450"], ["11909.90000", "6.20000000", "1596736825.518690", "r"]], "c": "925109630"}, "book-100", "XBT/USD"]
[270, {"a": [["11894.60000", "0.94257776", "1596737095.049764"]], "c": "925109630"}, "book-100", "XBT/USD"]
[270, {"a": [["11889.90000", "0.94295035", "1596737095.050765"]], "c": "925109630"}, "book-100", "XBT/USD"]
[270, {"a": [["11870.50000", "0.61697934", "1596737095.055665"]], "c": "2391987505"}, "book-100", "XBT/USD"]
[270, {"a": [["11894.70000", "0.80000000", "1596737095.166912"]], "c": "2391987505"}, "book-100", "XBT/USD"]
[270, {"a": [["11892.20000", "2.18210153", "1596737095.170532"]], "c": "2391987505"}, "book-100", "XBT/USD"]
[270, {"b": [["11816.50000", "0.00000000", "1596737095.184235"], ["11807.70000", "3.28855406", "1596736821.611246", "r"]], "c": "2391987505"}, "book-100", "XBT/USD"]
[270, {"a": [["11894.50000", "0.00000000", "1596737095.188978"], ["11908.30000", "1.58322230", "1596736949.361051", "r"]], "c": "2391987505"}, "book-100", "XBT/USD"]
[270, {"b": [["11831.70000", "0.00000000", "1596737095.189749"], ["11807.50000", "2.19772556", "1596736916.776430", "r"]], "c": "2391987505"}, "book-100", "XBT/USD"]
[270, {"a": [["11883.70000", "2.69245243", "1596737095.201733"]], "c": "2391987505"}, "book-100", "XBT/USD"]
[270, {"a": [["11872.40000", "0.84243363", "1596737095.204717"]], "c": "2391987505"}, "book-100", "XBT/USD"]
[270, {"a": [["11894.90000", "0.73617368", "1596737095.209985"]], "c": "2391987505"}, "book-100", "XBT/USD"]
[270, {"b": [["11813.30000", "3.20372129", "1596737095.215240"]], "c": "2391987505"}, "book-100", "XBT/USD"]
[270, {"a": [["11880.30000", "0.32983362", "1596737095.215603"]], "c": "2391987505"}, "book-100", "XBT/USD"]
[270, {"b": [["11831.10000", "0.73617368", "1596737095.216146"]], "c": "2391987505"}, "book-100", "XBT/USD"]
[270, {"a": [["11896.60000", "0.00000000", "1596737095.426144"], ["11907.90000", "2.38150000", "1596736895.960018", "r"]], "c": "2391987505"}, "book-100", "XBT/USD"]
[270, {"a": [["11886.10000", "1.38962851", "1596737095.447226"]], "c": "2391987505"}, "book-100", "XBT/USD"]
[270, {"a": [["11869.80000", "14.86244534", "1596737095.471306"]], "c": "2155056768"}, "book-100", "XBT/USD"]
[270, {"a": [["11898.80000", "0.00000000", "1596737095.475010"], ["11908.30000", "1.58322230", "1596736949.361051", "r"]], "c": "2155056768"}, "book-100", "XBT/USD"]
[270, {"b": [["11855.50000", "0.89362000", "1596737095.679575"]], "c": "2155056768"}, "book-100", "XBT/USD"]
[270, {"a": [["11872.30000", "0.00000000", "1596737095.740015"], ["11908.90000", "1.06880000", "1596736841.521829", "r"]], "c": "2155056768"}, "book-100", "XBT/USD"]
[270, {"b": [["11843.30000", "0.00430630", "1596737095.804440"]], "c": "2155056768"}, "book-100", "XBT/USD"]
[270, {"a": [["11884.00000", "0.00438186", "1596737095.805685"]], "c": "2155056768"}, "book-100", "XBT/USD"]
[270, {"a": [["11869.80000", "14.46244534", "1596737095.915149"]], "c": "3163966931"}, "book-100", "XBT/USD"]
[270, {"b": [["11861.60000", "0.10000000", "1596737095.969858"]], "c": "1609336501"}, "book-100", "XBT/USD"]
[270, {"b": [["11861.60000", "0.00000000", "1596737096.026646"], ["11808.80000", "2.66090576", "1596736784.110515", "r"]], "c": "3163966931"}, "book-100", "XBT/USD"]
[270, {"a": [["11872.10000", "0.67980380", "1596737096.036437"]], "c": "3163966931"}, "book-100", "XBT/USD"]
[270, {"a": [["11894.40000", "3.26450611", "1596737096.042150"]], "c": "3163966931"}, "book-100", "XBT/USD"]
[270, {"b": [["11861.60000", "0.10000000", "1596737096.074376"]], "c": "1609336501"}, "book-100", "XBT/USD"]
[270, {"b": [["11861.60000", "0.00000000", "1596737096.133551"], ["11808.80000", "2.66090576", "1596736784.110515", "r"]], "c": "3163966931"}, "book-100", "XBT/USD"]
[270, {"a": [["11895.00000", "0.25000000", "1596737096.166524"]], "c": "3163966931"}, "book-100", "XBT/USD"]
[270, {"a": [["11889.80000", "0.00000000", "1596737096.422869"], ["11907.90000", "2.38150000", "1596736895.960018", "r"]], "c": "3163966931"}, "book-100", "XBT/USD"]
[270, {"a": [["11884.10000", "0.00000000", "1596737096.523790"], ["11908.30000", "1.58322230", "1596736949.361051", "r"]], "c": "3163966931"}, "book-100", "XBT/USD"]
[270, {"a": [["11886.10000", "1.59373248", "1596737096.592600"]], "c": "3163966931"}, "book-100", "XBT/USD"]
[270, {"a": [["11903.90000", "1.59024654", "1596737096.689627"]], "c": "3163966931"}, "book-100", "XBT/USD"]
[270, {"a": [["11885.70000", "0.64524333", "1596737096.709953"]], "c": "3163966931"}, "book-100", "XBT/USD"]
[270, {"b": [["11859.20000", "0.00000000", "1596737096.820491"], ["11808.70000", "9.70000000", "1596737024.924486", "r"]], "c": "3163966931"}, "book-100", "XBT/USD"]
[270, {"a": [["11891.90000", "0.00000000", "1596737096.876811"], ["11907.90000", "2.38150000", "1596736895.960018", "r"]], "c": "3163966931"}, "book-100", "XBT/USD"]
[270, {"a": [["11885.90000", "0.00000000", "1596737096.970316"], ["11908.30000", "1.58322230", "1596736949.361051", "r"]], "c": "3163966931"}, "book-100", "XBT/USD"]
[270, {"a": [["11891.80000", "0.00000000", "1596737096.981025"], ["11908.90000", "1.06880000", "1596736841.521829", "r"]], "c": "3163966931"}, "book-100", "XBT/USD"]
[270, {"a": [["11898.30000", "0.00000000", "1596737097.043728"], ["11909.10000", "1.00200000", "1596736809.784670", "r"]], "c": "3163966931"}, "book-100", "XBT/USD"]
[270, {"a": [["11888.10000", "0.52857217", "1596737097.061577"]], "c": "3163966931"}, "book-100", "XBT/USD"]
[270, {"a": [["11871.10000", "0.00000000", "1596737097.061871"], ["11909.10000", "1.00200000", "1596736809.784670", "r"]], "c": "2714403770"}, "book-100", "XBT/USD"]
[270, {"a": [["11885.70000", "0.00000000", "1596737097.119253"], ["11909.90000", "6.20000000", "1596736825.518690", "r"]], "c": "2714403770"}, "book-100", "XBT/USD"]
[270, {"a": [["11897.60000", "0.00000000", "1596737097.180535"], ["11910.00000", "0.36067000", "1596736968.148143", "r"]], "c": "2714403770"}, "book-100", "XBT/USD"]
[270, {"a": [["11876.10000", "0.00000000", "1596737097.242171"], ["11910.50000", "1.68800000", "1596736995.994117", "r"]], "c": "2714403770"}, "book-100", "XBT/USD"]
[270, {"a": [["11885.70000", "0.57814924", "1596737097.309046"]], "c": "2714403770"}, "book-100", "XBT/USD"]
[270, {"a": [["11870.50000", "0.71319028", "1596737097.385070"]], "c": "1890424160"}, "book-100", "XBT/USD"]
[270, {"a": [["11888.40000", "0.00000000", "1596737097.392491"], ["11910.50000", "1.68800000", "1596736995.994117", "r"]], "c": "1890424160"}, "book-100", "XBT/USD"]
[270, {"a": [["11884.00000", "0.00000000", "1596737097.413494"], ["11911.10000", "2.17890497", "1596737013.284792", "r"]], "c": "1890424160"}, "book-100", "XBT/USD"]
[270, {"b": [["11861.60000", "0.10000000", "1596737097.447019"]], "c": "2480365062"}, "book-100", "XBT/USD"]
[270, {"a": [["11883.20000", "0.10911073", "1596737097.450849"]], "c": "2480365062"}, "book-100", "XBT/USD"]
[270, {"a": [["11870.20000", "0.04750000", "1596737097.483854"]], "c": "1372547596"}, "book-100", "XBT/USD"]
[270, {"b": [["11861.60000", "0.00000000", "1596737097.497111"], ["11808.70000", "9.70000000", "1596737024.924486", "r"]], "c": "2998247786"}, "book-100", "XBT/USD"]
[270, {"b": [["11859.60000", "0.10000000", "1596737097.504217"]], "c": "2998247786"}, "book-100", "XBT/USD"]
[270, {"a": [["11873.20000", "0.09250000", "1596737097.513239"]], "c": "2998247786"}, "book-100", "XBT/USD"]
[270, {"a": [["11893.90000", "1.05662884", "1596737097.552140"]], "c": "2998247786"}, "book-100", "XBT/USD"]
[270, {"a": [["11884.10000", "0.00438186", "1596737097.613717"]], "c": "2998247786"}, "book-100", "XBT/USD"]
[270, {"a": [["11893.80000", "0.46913521", "1596737097.719345"]], "c": "2998247786"}, "book-100", "XBT/USD"]
[270, {"a": [["11885.50000", "0.76362732", "1596737097.725450"]], "c": "2998247786"}, "book-100", "XBT/USD"]
[270, {"a": [["11889.10000", "0.28567345", "1596737097.734087"]], "c": "2998247786"}, "book-100", "XBT/USD"]
[270, {"a": [["11872.00000", "0.00000000", "1596737097.991882"], ["11908.30000", "1.58322230", "1596736949.361051", "r"]], "c": "2998247786"}, "book-100", "XBT/USD"]
[270, {"a": [["11885.70000", "0.00000000", "1596737098.029033"], ["11908.90000", "1.06880000", "1596736841.521829", "r"]], "c": "2998247786"}, "book-100", "XBT/USD"]
[270, {"a": [["11884.10000", "0.42815124", "1596737098.210710"]], "c": "2998247786"}, "book-100", "XBT/USD"]
[270, {"a": [["11871.90000", "0.00000000", "1596737098.347607"], ["11909.10000", "1.00200000", "1596736809.784670", "r"]], "c": "2998247786"}, "book-100", "XBT/USD"]
[270, {"a": [["11884.10000", "0.42376938", "1596737098.458875"]], "c": "2998247786"}, "book-100", "XBT/USD"]
[270, {"a": [["11884.10000", "0.00000000", "1596737098.562688"], ["11909.90000", "6.20000000", "1596736825.518690", "r"]], "c": "2998247786"}, "book-100", "XBT/USD"]
[270, {"b": [["11816.80000", "0.00000000", "1596737098.751104"], ["11808.70000", "9.70000000", "1596737024.924486", "r"]], "c": "2998247786"}, "book-100", "XBT/USD"]
[270, {"a": [["11885.40000", "0.60198099", "1596737098.751268"]], "c": "2998247786"}, "book-100", "XBT/USD"]
[270, {"a": [["11892.00000", "6.46925117", "1596737098.754679"]], "c": "2998247786"}, "book-100", "XBT/USD"]
[270, {"a": [["11895.00000", "0.42065000", "1596737099.270287"]], "c": "2998247786"}, "book-100", "XBT/USD"]
[270, {"a": [["11890.70000", "5.80000000", "1596737099.413935"]], "c": "2998247786"}, "book-100", "XBT/USD"]
[270, {"a": [["11888.30000", "0.00000000", "1596737099.426308"], ["11909.10000", "1.00200000", "1596736809.784670", "r"]], "c": "2998247786"}, "book-100", "XBT/USD"]
[270, {"a": [["11869.80000", "14.71244534", "1596737099.680266"]], "c": "4099116964"}, "book-100", "XBT/USD"]
[270, {"a": [["11888.20000", "3.26620864", "1596737099.756823"]], "c": "4099116964"}, "book-100", "XBT/USD"]
[270, {"b": [["11848.10000", "0.00000000", "1596737099.872878"], ["11807.70000", "3.28855406", "1596736821.611246", "r"]], "c": "4099116964"}, "book-100", "XBT/USD"]
[270, {"b": [["11863.50000", "0.35277124", "1596737099.934720"]], "c": "238061436"}, "book-100", "XBT/USD"]
[270, {"a": [["11872.70000", "0.28399999", "1596737100.034020"]], "c": "238061436"}, "book-100", "XBT/USD"]
[270, {"a": [["11872.70000", "0.00000000", "1596737100.036889"], ["11909.10000", "1.00200000", "1596736809.784670", "r"]], "c": "238061436"}, "book-100", "XBT/USD"]
[270, {"a": [["11884.20000", "0.95693446", "1596737100.085301"]], "c": "238061436"}, "book-100", "XBT/USD"]
[270, {"b": [["11859.00000", "0.99226000", "1596737100.205740"]], "c": "238061436"}, "book-100", "XBT/USD"]
[270, {"a": [["11873.60000", "0.00000000", "1596737100.229427"], ["11909.90000", "6.20000000", "1596736825.518690", "r"]], "c": "238061436"}, "book-100", "XBT/USD"]
[270, {"a": [["11879.30000", "0.50000000", "1596737100.239635"]], "c": "238061436"}, "book-100", "XBT/USD"]
[270, {"a": [["11884.60000", "0.28899999", "1596737100.244982"]], "c": "238061436"}, "book-100", "XBT/USD"]
[270, {"a": [["11873.50000", "0.00000000", "1596737100.318496"], ["11909.10000", "1.00200000", "1596736809.784670", "r"]], "c": "238061436"}, "book-100", "XBT/USD"]
[270, {"b": [["11859.50000", "2.44887727", "1596737100.318613"]], "c": "238061436"}, "book-100", "XBT/USD"]
[270, {"b": [["11861.60000", "0.10000000", "1596737100.374990"]], "c": "3981069338"}, "book-100", "XBT/USD"]
[270, {"a": [["11885.40000", "0.00000000", "1596737100.422980"], ["11909.90000", "6.20000000", "1596736825.518690", "r"]], "c": "3981069338"}, "book-100", "XBT/USD"]
[270, {"a": [["11895.00000", "0.25000000", "1596737100.454512"]], "c": "3981069338"}, "book-100", "XBT/USD"]
[270, {"b": [["11856.20000", "0.00000000", "1596737100.460505"], ["11808.80000", "2.66090576", "1596736784.110515", "r"]], "c": "3981069338"}, "book-100", "XBT/USD"]
[270, {"a": [["11869.80000", "14.46244534", "1596737100.526867"]], "c": "2880201428"}, "book-100", "XBT/USD"]
[270, {"b": [["11850.10000", "0.00000000", "1596737100.554807"], ["11808.70000", "9.70000000", "1596737024.924486", "r"]], "c": "2880201428"}, "book-100", "XBT/USD"]
[270, {"b": [["11861.60000", "0.00000000", "1596737100.580519"], ["11807.70000", "3.28855406", "1596736821.611246", "r"]], "c": "1222027698"}, "book-100", "XBT/USD"]
[270, {"a": [["11886.00000", "0.44438808", "1596737100.604154"]], "c": "1222027698"}, "book-100", "XBT/USD"]
[270, {"b": [["11851.10000", "0.38650898", "1596737100.637116"]], "c": "1222027698"}, "book-100", "XBT/USD"]
[270, {"a": [["11905.70000", "0.00000000", "1596737100.638945"], ["11909.90000", "6.20000000", "1596736825.518690", "r"]], "c": "1222027698"}, "book-100", "XBT/USD"]
[270, {"a": [["11870.20000", "0.29750000", "1596737100.760438"]], "c": "2364682980"}, "book-100", "XBT/USD"]
[270, {"b": [["11848.40000", "0.28661486", "1596737100.847643"]], "c": "2364682980"}, "book-100", "XBT/USD"]
[270, {"b": [["11845.20000", "2.90223143", "1596737100.847953"]], "c": "2364682980"}, "book-100", "XBT/USD"]
[270, {"a": [["11891.40000", "0.00000000", "1596737100.873952"], ["11910.00000", "0.36067000", "1596736968.148143", "r"]], "c": "2364682980"}, "book-100", "XBT/USD"]
[270, {"b": [["11861.30000", "0.00000000", "1596737100.875413"], ["11807.50000", "2.19772556", "1596736916.776430", "r"]], "c": "3800749610"}, "book-100", "XBT/USD"]
[270, {"a": [["11871.80000", "0.00000000", "1596737101.049401"], ["11910.30000", "0.50000000", "1596737100.424231", "r"]], "c": "3800749610"}, "book-100", "XBT/USD"]
[270, {"b": [["11830.70000", "0.73611898", "1596737101.688053"]], "c": "3800749610"}, "book-100", "XBT/USD"]
[270, {"b": [["11861.50000", "0.00000000", "1596737101.689305"], ["11807.50000", "2.19772556", "1596736916.776430", "r"]], "c": "4153687908"}, "book-100", "XBT/USD"]
[270, {"a": [["11894.90000", "0.00000000", "1596737101.691050"], ["11910.50000", "1.68800000", "1596736995.994117", "r"]], "c": "4153687908"}, "book-100", "XBT/USD"]
[270, {"a": [["11895.00000", "0.98611898", "1596737101.692822"]], "c": "4153687908"}, "book-100", "XBT/USD"]
[270, {"b": [["11859.70000", "0.00000000", "1596737101.703460"], ["11806.30000", "5.40000000", "1596737051.417403", "r"]], "c": "880023111"}, "book-100", "XBT/USD"]
[270, {"b": [["11831.10000", "0.00000000", "1596737101.705090"], ["11805.90000", "0.15000000", "1596735155.182015", "r"]], "c": "880023111"}, "book-100", "XBT/USD"]
[270, {"b": [["11863.60000", "4.20300000", "1596737101.720464"]], "c": "3866778201"}, "book-100", "XBT/USD"]
[270, {"b": [["11851.10000", "0.36350898", "1596737101.753390"]], "c": "3866778201"}, "book-100", "XBT/USD"]
[270, {"a": [["11886.40000", "0.94308224", "1596737101.787119"]], "c": "3866778201"}, "book-100", "XBT/USD"]
[270, {"b": [["11850.10000", "0.02300000", "1596737101.842684"]], "c": "3866778201"}, "book-100", "XBT/USD"]
[270, {"b": [["11843.30000", "0.00000000", "1596737101.851038"], ["11806.30000", "5.40000000", "1596737051.417403", "r"]], "c": "3866778201"}, "book-100", "XBT/USD"]
[270, {"b": [["11845.20000", "0.71100000", "1596737101.868372"]], "c": "3866778201"}, "book-100", "XBT/USD"]
[270, {"a": [["11875.60000", "0.04396549", "1596737101.884297"]], "c": "3866778201"}, "book-100", "XBT/USD"]
[270, {"a": [["11870.20000", "0.04750000", "1596737101.886513"]], "c": "1689684483"}, "book-100", "XBT/USD"]
[270, {"b": [["11863.50000", "0.25277124", "1596737101.995903"]], "c": "2425892261"}, "book-100", "XBT/USD"]
[270, {"b": [["11859.70000", "0.04396571", "1596737102.015518"]], "c": "1271350284"}, "book-100", "XBT/USD"]
[270, {"b": [["11851.20000", "0.00000000", "1596737102.110944"], ["11806.30000", "5.40000000", "1596737051.417403", "r"]], "c": "1271350284"}, "book-100", "XBT/USD"]
[270, {"b": [["11836.20000", "2.24428906", "1596737102.202366"]], "c": "1271350284"}, "book-100", "XBT/USD"]
[270, {"b": [["11863.70000", "0.10000000", "1596737102.272874"]], "c": "3790067545"}, "book-100", "XBT/USD"]
[270, {"a": [["11869.80000", "14.86244534", "1596737102.317567"]], "c": "130045309"}, "book-100", "XBT/USD"]
[270, {"a": [["11875.70000", "0.13189764", "1596737103.055940"]], "c": "130045309"}, "book-100", "XBT/USD"]
[270, {"b": [["11848.10000", "1.38893087", "1596737103.060330"]], "c": "130045309"}, "book-100", "XBT/USD"]
[270, {"b": [["11849.50000", "0.94616527", "1596737103.065048"]], "c": "130045309"}, "book-100", "XBT/USD"]
[270, {"b": [["11858.20000", "0.13189771", "1596737103.067160"]], "c": "130045309"}, "book-100", "XBT/USD"]
[270, {"a": [["11897.70000", "0.00000000", "1596737103.071752"], ["11910.00000", "0.36067000", "1596736968.148143", "r"]], "c": "130045309"}, "book-100", "XBT/USD"]
[270, {"b": [["11858.80000", "0.33703938", "1596737103.083954"]], "c": "130045309"}, "book-100", "XBT/USD"]
[270, {"b": [["11851.70000", "0.00000000", "1596737103.095817"], ["11808.70000", "9.70000000", "1596737024.924486", "r"]], "c": "130045309"}, "book-100", "XBT/USD"]
[270, {"a": [["11894.70000", "0.30000000", "1596737103.373511"]], "c": "130045309"}, "book-100", "XBT/USD"]
[270, {"b": [["11863.50000", "0.00000000", "1596737103.377444"], ["11807.70000", "3.28855406", "1596736821.611246", "r"]], "c": "3777433552"}, "book-100", "XBT/USD"]
[270, {"b": [["11845.20000", "1.24149196", "1596737103.408688"]], "c": "3777433552"}, "book-100", "XBT/USD"]
[270, {"a": [["11889.20000", "0.68090000", "1596737103.432242"]], "c": "3777433552"}, "book-100", "XBT/USD"]
[270, {"a": [["11886.00000", "0.00000000", "1596737103.470199"], ["11910.00000", "0.36067000", "1596736968.148143", "r"]], "c": "3777433552"}, "book-100", "XBT/USD"]
[270, {"a": [["11898.60000", "0.00000000", "1596737103.470782"], ["11910.30000", "0.50000000", "1596737100.424231", "r"]], "c": "3777433552"}, "book-100", "XBT/USD"]
[270, {"a": [["11885.70000", "0.43717408", "1596737103.664092"]], "c": "3777433552"}, "book-100", "XBT/USD"]
[270, {"a": [["11898.60000", "2.15885227", "1596737103.665733"]], "c": "3777433552"}, "book-100", "XBT/USD"]
[270, {"b": [["11854.60000", "0.00000000", "1596737104.640221"], ["11807.50000", "2.19772556", "1596736916.776430", "r"]], "c": "3777433552"}, "book-100", "XBT/USD"]
[270, {"b": [["11862.10000", "1.67600000", "1596737104.747019"]], "c": "300425947"}, "book-100", "XBT/USD"]
[270, {"a": [["11870.50000", "2.39219028", "1596737104.747739"]], "c": "7964279"}, "book-100", "XBT/USD"]
[270, {"a": [["11869.80000", "15.11244534", "1596737104.767078"]], "c": "109001807"}, "book-100", "XBT/USD"]
[270, {"b": [["11810.40000", "1.59707601", "1596737104.790410"]], "c": "109001807"}, "book-100", "XBT/USD"]
[270, {"a": [["11894.20000", "0.50000000", "1596737104.802633"]], "c": "109001807"}, "book-100", "XBT/USD"]
[270, {"b": [["11859.00000", "0.00000000", "1596737104.891756"], ["11807.70000", "3.28855406", "1596736821.611246", "r"]], "c": "109001807"}, "book-100", "XBT/USD"]
[270, {"b": [["11849.90000", "0.93235995", "1596737104.937186"]], "c": "109001807"}, "book-100", "XBT/USD"]
[270, {"a": [["11898.60000", "0.00000000", "1596737104.984859"], ["11909.90000", "6.20000000", "1596736825.518690", "r"]], "c": "109001807"}, "book-100", "XBT/USD"]
[270, {"a": [["11885.70000", "0.00000000", "1596737104.988220"], ["11910.00000", "0.36067000", "1596736968.148143", "r"]], "c": "109001807"}, "book-100", "XBT/USD"]
[270, {"a": [["11883.70000", "0.69245243", "1596737105.079572"]], "c": "109001807"}, "book-100", "XBT/USD"]
[270, {"a": [["11904.90000", "2.17180055", "1596737105.181006"]], "c": "109001807"}, "book-100", "XBT/USD"]
[270, {"b": [["11861.90000", "0.25279222", "1596737105.200793"]], "c": "2574745959"}, "book-100", "XBT/USD"]
[270, {"a": [["11872.10000", "0.00000000", "1596737105.227033"], ["11910.00000", "0.36067000", "1596736968.148143", "r"]], "c": "2574745959"}, "book-100", "XBT/USD"]
[270, {"b": [["11853.40000", "0.33054996", "1596737105.251776"]], "c": "2574745959"}, "book-100", "XBT/USD"]
[270, {"a": [["11869.80000", "14.86244534", "1596737105.252152"]], "c": "2977120067"}, "book-100", "XBT/USD"]
[270, {"a": [["11891.90000", "0.46229234", "1596737105.255077"]], "c": "2977120067"}, "book-100", "XBT/USD"]
[270, {"b": [["11843.90000", "0.00445804", "1596737105.310336"]], "c": "2977120067"}, "book-100", "XBT/USD"]
[270, {"a": [["11871.30000", "0.67967651", "1596737105.339071"]], "c": "1330695788"}, "book-100", "XBT/USD"]
[270, {"a": [["11886.30000", "0.00438186", "1596737105.345978"]], "c": "1330695788"}, "book-100", "XBT/USD"]
[270, {"a": [["11891.90000", "0.00000000", "1596737105.447328"], ["11909.10000", "1.00200000", "1596736809.784670", "r"]], "c": "1330695788"}, "book-100", "XBT/USD"]
[270, {"a": [["11869.80000", "15.11244534", "1596737105.522225"]], "c": "1733587016"}, "book-100", "XBT/USD"]
[270, {"b": [["11862.10000", "0.00000000", "1596737105.562346"], ["11808.80000", "2.66090576", "1596736784.110515", "r"]], "c": "1868764869"}, "book-100", "XBT/USD"]
[270, {"b": [["11843.90000", "0.00000000", "1596737105.624785"], ["11808.70000", "9.70000000", "1596737024.924486", "r"]], "c": "1868764869"}, "book-100", "XBT/USD"]
[270, {"a": [["11904.90000", "0.00000000", "1596737105.633924"], ["11909.90000", "6.20000000", "1596736825.518690", "r"]], "c": "1868764869"}, "book-100", "XBT/USD"]
[270, {"a": [["11885.70000", "0.42520157", "1596737105.636816"]], "c": "1868764869"}, "book-100", "XBT/USD"]
[270, {"b": [["11813.30000", "0.99420000", "1596737105.758942"]], "c": "1868764869"}, "book-100", "XBT/USD"]
[270, {"b": [["11813.60000", "2.20925604", "1596737105.763221"]], "c": "1868764869"}, "book-100", "XBT/USD"]
[270, {"a": [["11898.60000", "2.15244304", "1596737105.817327"]], "c": "1868764869"}, "book-100", "XBT/USD"]
[270, {"b": [["11851.00000", "7.40000000", "1596737105.894959"]], "c": "1868764869"}, "book-100", "XBT/USD"]
[270, {"a": [["11870.50000", "0.71319028", "1596737106.262690"]], "c": "2424088097"}, "book-100", "XBT/USD"]
[270, {"b": [["11861.90000", "0.00000000", "1596737106.900586"], ["11808.70000", "9.70000000", "1596737024.924486", "r"]], "c": "3063328062"}, "book-100", "XBT/USD"]
[270, {"b": [["11845.20000", "0.71100000", "1596737106.985067"]], "c": "3063328062"}, "book-100", "XBT/USD"]
[270, {"a": [["11885.70000", "0.00000000", "1596737106.986517"], ["11909.10000", "1.00200000", "1596736809.784670", "r"]], "c": "3063328062"}, "book-100", "XBT/USD"]
[270, {"b": [["11813.60000", "0.00000000", "1596737107.019350"], ["11807.70000", "3.28855406", "1596736821.611246", "r"]], "c": "3063328062"}, "book-100", "XBT/USD"]
[270, {"b": [["11849.90000", "0.23800000", "1596737107.028043"]], "c": "3063328062"}, "book-100", "XBT/USD"]
[270, {"b": [["11853.40000", "0.00000000", "1596737107.039291"], ["11807.50000", "2.19772556", "1596736916.776430", "r"]], "c": "3063328062"}, "book-100", "XBT/USD"]
[270, {"b": [["11813.50000", "2.20918357", "1596737107.051422"]], "c": "3063328062"}, "book-100", "XBT/USD"]
[270, {"a": [["11875.60000", "0.00000000", "1596737107.059823"], ["11909.80000", "0.50000000", "1596737106.462324", "r"]], "c": "3063328062"}, "book-100", "XBT/USD"]
[270, {"b": [["11848.10000", "0.00000000", "1596737107.097918"], ["11807.50000", "2.19772556", "1596736916.776430", "r"]], "c": "3063328062"}, "book-100", "XBT/USD"]
[270, {"b": [["11850.10000", "0.00000000", "1596737107.098075"], ["11806.30000", "5.40000000", "1596737051.417403", "r"]], "c": "3063328062"}, "book-100", "XBT/USD"]
[270, {"a": [["11876.90000", "0.84192960", "1596737107.098185"]], "c": "3063328062"}, "book-100", "XBT/USD"]
[270, {"b": [["11851.60000", "0.02300000", "1596737107.146114"]], "c": "3063328062"}, "book-100", "XBT/USD"]
[270, {"a": [["11877.90000", "0.01800000", "1596737107.146345"]], "c": "3063328062"}, "book-100", "XBT/USD"]
[270, {"a": [["11885.70000", "0.45217253", "1596737107.175438"]], "c": "3063328062"}, "book-100", "XBT/USD"]
[270, {"b": [["11847.70000", "0.53029971", "1596737107.206772"]], "c": "3063328062"}, "book-100", "XBT/USD"]
[270, {"a": [["11878.00000", "0.04396606", "1596737107.268762"]], "c": "3063328062"}, "book-100", "XBT/USD"]
[270, {"b": [["11849.90000", "0.00000000", "1596737107.479230"], ["11807.50000", "2.19772556", "1596736916.776430", "r"]], "c": "3063328062"}, "book-100", "XBT/USD"]
[270, {"b": [["11861.60000", "0.23800000", "1596737107.551098"]], "c": "965987777"}, "book-100", "XBT/USD"]
[270, {"b": [["11851.60000", "0.00000000", "1596737107.601376"], ["11807.50000", "2.19772556", "1596736916.776430", "r"]], "c": "965987777"}, "book-100", "XBT/USD"]
[270, {"b": [["11852.10000", "0.02300000", "1596737107.649766"]], "c": "965987777"}, "book-100", "XBT/USD"]
[270, {"b": [["11831.30000", "0.73605640", "1596737107.869072"]], "c": "965987777"}, "book-100", "XBT/USD"]
[270, {"a": [["11895.30000", "0.73605640", "1596737107.871375"]], "c": "965987777"}, "book-100", "XBT/USD"]
[270, {"a": [["11895.00000", "0.25000000", "1596737107.904596"]], "c": "965987777"}, "book-100", "XBT/USD"]
[270, {"b": [["11849.60000", "1.38874910", "1596737108.058741"]], "c": "965987777"}, "book-100", "XBT/USD"]
[270, {"b": [["11851.90000", "0.69423980", "1596737108.062206"]], "c": "965987777"}, "book-100", "XBT/USD"]
[270, {"b": [["11855.40000", "0.33049278", "1596737108.062706"]], "c": "965987777"}, "book-100", "XBT/USD"]
[270, {"b": [["11830.70000", "0.00000000", "1596737108.170695"], ["11810.40000", "1.59707601", "1596737104.790410", "r"]], "c": "965987777"}, "book-100", "XBT/USD"]
[270, {"b": [["11848.70000", "0.33705128", "1596737108.200232"]], "c": "965987777"}, "book-100", "XBT/USD"]
[270, {"b": [["11863.30000", "0.25277350", "1596737108.200346"]], "c": "3502395334"}, "book-100", "XBT/USD"]
[270, {"b": [["11862.50000", "2.31110000", "1596737108.451515"]], "c": "3055608093"}, "book-100", "XBT/USD"]
[270, {"a": [["11870.90000", "1.68100000", "1596737108.466520"]], "c": "795329788"}, "book-100", "XBT/USD"]
[270, {"a": [["11877.90000", "0.00000000", "1596737108.579594"], ["11907.90000", "2.38150000", "1596736895.960018", "r"]], "c": "795329788"}, "book-100", "XBT/USD"]
[270, {"b": [["11852.10000", "0.00000000", "1596737108.579932"], ["11811.70000", "5.70000000", "1596736886.902857", "r"]], "c": "795329788"}, "book-100", "XBT/USD"]
[270, {"b": [["11851.10000", "0.38650898", "1596737108.628425"]], "c": "795329788"}, "book-100", "XBT/USD"]
[270, {"a": [["11876.90000", "0.85992960", "1596737108.628918"]], "c": "795329788"}, "book-100", "XBT/USD"]
[270, {"b": [["11863.30000", "0.00000000", "1596737108.654474"], ["11810.40000", "1.59707601", "1596737104.790410", "r"]], "c": "2448992817"}, "book-100", "XBT/USD"]
[270, {"a": [["11869.80000", "14.86244534", "1596737108.658586"]], "c": "2550009865"}, "book-100", "XBT/USD"]
[270, {"b": [["11862.50000", "0.63710000", "1596737108.772713"]], "c": "4182031718"}, "book-100", "XBT/USD"]
[270, {"b": [["11863.70000", "0.00000000", "1596737108.788755"], ["11808.80000", "2.66090576", "1596736784.110515", "r"]], "c": "1995583704"}, "book-100", "XBT/USD"]
[270, {"b": [["11843.90000", "0.00428804", "1596737108.832462"]], "c": "1995583704"}, "book-100", "XBT/USD"]
[270, {"b": [["11851.10000", "0.36350898", "1596737108.848172"]], "c": "1995583704"}, "book-100", "XBT/USD"]
[270, {"a": [["11876.90000", "0.84192960", "1596737108.850105"]], "c": "1995583704"}, "book-100", "XBT/USD"]
[270, {"a": [["11875.90000", "0.01800000", "1596737108.897258"]], "c": "1995583704"}, "book-100", "XBT/USD"]
[270, {"b": [["11850.10000", "0.02300000", "1596737108.897473"]], "c": "1995583704"}, "book-100", "XBT/USD"]
[270, {"a": [["11869.80000", "14.94669311", "1596737109.049058"]], "c": "4040855575"}, "book-100", "XBT/USD"]
[270, {"a": [["11875.00000", "2.00000000", "1596737109.074235"]], "c": "4040855575"}, "book-100", "XBT/USD"]
[270, {"b": [["11843.90000", "0.00000000", "1596737109.204483"], ["11810.40000", "1.59707601", "1596737104.790410", "r"]], "c": "4040855575"}, "book-100", "XBT/USD"]
[270, {"a": [["11886.30000", "0.00000000", "1596737109.389920"], ["11907.50000", "3.26133727", "1596736967.970398", "r"]], "c": "4040855575"}, "book-100", "XBT/USD"]
[270, {"a": [["11869.80000", "15.19669311", "1596737109.558444"]], "c": "284845959"}, "book-100", "XBT/USD"]
[270, {"a": [["11888.80000", "0.69500000", "1596737109.561958"]], "c": "284845959"}, "book-100", "XBT/USD"]
[270, {"a": [["11869.80000", "14.94669311", "1596737109.870330"]], "c": "4040855575"}, "book-100", "XBT/USD"]
[270, {"a": [["11876.70000", "1.81322481", "1596737109.895859"]], "c": "4040855575"}, "book-100", "XBT/USD"]
[270, {"a": [["11876.70000", "1.15038670", "1596737109.902396"]], "c": "4040855575"}, "book-100", "XBT/USD"]
[270, {"a": [["11876.80000", "0.27100000", "1596737109.906716"]], "c": "4040855575"}, "book-100", "XBT/USD"]
[270, {"a": [["11876.70000", "1.01894234", "1596737109.908052"]], "c": "4040855575"}, "book-100", "XBT/USD"]
[270, {"a": [["11876.00000", "0.10200000", "1596737109.917722"]], "c": "4040855575"}, "book-100", "XBT/USD"]
[270, {"a": [["11876.70000", "0.64197094", "1596737109.920473"]], "c": "4040855575"}, "book-100", "XBT/USD"]
[270, {"b": [["11850.10000", "0.00000000", "1596737109.925083"], ["11808.80000", "2.66090576", "1596736784.110515", "r"]], "c": "4040855575"}, "book-100", "XBT/USD"]
[270, {"a": [["11875.90000", "0.00000000", "1596737109.925266"], ["11907.50000", "3.26133727", "1596736967.970398", "r"]], "c": "4040855575"}, "book-100", "XBT/USD"]
[270, {"a": [["11874.90000", "0.01800000", "1596737109.974832"]], "c": "4040855575"}, "book-100", "XBT/USD"]
[270, {"b": [["11859.70000", "0.00000000", "1596737109.975400"], ["11808.70000", "9.70000000", "1596737024.924486", "r"]], "c": "3088075759"}, "book-100", "XBT/USD"]
[270, {"a": [["11873.80000", "0.69338345", "1596737109.975762"]], "c": "3088075759"}, "book-100", "XBT/USD"]
[270, {"b": [["11849.10000", "0.02300000", "1596737109.981938"]], "c": "3088075759"}, "book-100", "XBT/USD"]
[270, {"a": [["11870.30000", "2.21253134", "1596737110.111986"]], "c": "1338623544"}, "book-100", "XBT/USD"]
[270, {"b": [["11862.30000", "0.00000000", "1596737110.115783"], ["11808.70000", "9.70000000", "1596737024.924486", "r"]], "c": "2390299030"}, "book-100", "XBT/USD"]
[270, {"a": [["11870.30000", "2.34669494", "1596737110.117810"]], "c": "215677852"}, "book-100", "XBT/USD"]
[270, {"a": [["11870.30000", "2.73078254", "1596737110.134154"]], "c": "2726990148"}, "book-100", "XBT/USD"]
[270, {"a": [["11876.70000", "0.00000000", "1596737110.139079"], ["11907.20000", "6.18638192", "1596736972.522950", "r"]], "c": "2726990148"}, "book-100", "XBT/USD"]
[270, {"a": [["11870.30000", "3.03199714", "1596737110.148781"]], "c": "3193338338"}, "book-100", "XBT/USD"]
[270, {"a": [["11869.80000", "14.54669311", "1596737110.317601"]], "c": "766367898"}, "book-100", "XBT/USD"]
[270, {"a": [["11869.80000", "15.20953122", "1596737110.339454"]], "c": "2697516475"}, "book-100", "XBT/USD"]
[270, {"a": [["11873.20000", "6.59250000", "1596737110.399572"]], "c": "2697516475"}, "book-100", "XBT/USD"]
[270, {"a": [["11869.80000", "15.85150216", "1596737110.579572"]], "c": "820704555"}, "book-100", "XBT/USD"]
[270, {"a": [["11871.30000", "0.00000000", "1596737110.882577"], ["11907.50000", "3.26133727", "1596736967.970398", "r"]], "c": "820704555"}, "book-100", "XBT/USD"]
[270, {"b": [["11854.20000", "0.00000000", "1596737110.899967"], ["11807.70000", "3.28855406", "1596736821.611246", "r"]], "c": "820704555"}, "book-100", "XBT/USD"]
[270, {"b": [["11847.40000", "0.68090000", "1596737110.969209"]], "c": "820704555"}, "book-100", "XBT/USD"]
[270, {"b": [["11860.90000", "0.25281637", "1596737111.203344"]], "c": "2973455648"}, "book-100", "XBT/USD"]
[270, {"b": [["11861.60000", "0.49080099", "1596737111.205916"]], "c": "700436822"}, "book-100", "XBT/USD"]
[270, {"a": [["11870.80000", "0.69805190", "1596737111.298517"]], "c": "3424282435"}, "book-100", "XBT/USD"]
[270, {"b": [["11817.60000", "0.00000000", "1596737111.401508"], ["11808.70000", "9.70000000", "1596737024.924486", "r"]], "c": "3424282435"}, "book-100", "XBT/USD"]
[270, {"a": [["11884.60000", "0.00000000", "1596737111.517430"], ["11907.50000", "3.26133727", "1596736967.970398", "r"]], "c": "3424282435"}, "book-100", "XBT/USD"]
[270, {"a": [["11884.20000", "0.67293447", "1596737111.770406"]], "c": "3424282435"}, "book-100", "XBT/USD"]
[270, {"a": [["11874.00000", "0.28399999", "1596737111.777747"]], "c": "3424282435"}, "book-100", "XBT/USD"]
[270, {"a": [["11869.80000", "16.10150216", "1596737112.332301"]], "c": "1623815639"}, "book-100", "XBT/USD"]
[270, {"a": [["11906.30000", "0.50000000", "1596737112.402138"]], "c": "1623815639"}, "book-100", "XBT/USD"]
[270, {"b": [["11849.10000", "0.00000000", "1596737112.405400"], ["11807.80000", "1.06000000", "1596737111.250147", "r"]], "c": "1623815639"}, "book-100", "XBT/USD"]
[270, {"b": [["11860.40000", "0.01466005", "1596737112.480093"]], "c": "840655953"}, "book-100", "XBT/USD"]
[270, {"a": [["11871.70000", "0.01466005", "1596737112.481926"]], "c": "840655953"}, "book-100", "XBT/USD"]
[270, {"b": [["11850.10000", "0.02300000", "1596737112.482086"]], "c": "840655953"}, "book-100", "XBT/USD"]
[270, {"a": [["11872.20000", "1.03793046", "1596737112.537355"]], "c": "840655953"}, "book-100", "XBT/USD"]
[270, {"b": [["11860.00000", "0.07330046", "1596737112.539280"]], "c": "3772943557"}, "book-100", "XBT/USD"]
[270, {"a": [["11874.90000", "0.00000000", "1596737112.561706"], ["11907.00000", "8.54095785", "1596737002.155356", "r"]], "c": "3772943557"}, "book-100", "XBT/USD"]
[270, {"a": [["11873.80000", "0.86930598", "1596737112.601919"]], "c": "3772943557"}, "book-100", "XBT/USD"]
[270, {"a": [["11875.90000", "0.01800000", "1596737112.615452"]], "c": "3772943557"}, "book-100", "XBT/USD"]
[270, {"a": [["11873.60000", "0.30900000", "1596737112.630211"]], "c": "3772943557"}, "book-100", "XBT/USD"]
[270, {"b": [["11858.40000", "0.17592253", "1596737112.934273"]], "c": "3772943557"}, "book-100", "XBT/USD"]
[270, {"b": [["11843.20000", "0.00000000", "1596737113.000076"], ["11810.40000", "1.59707601", "1596737104.790410", "r"]], "c": "3772943557"}, "book-100", "XBT/USD"]
[270, {"a": [["11894.20000", "0.00000000", "1596737113.019053"], ["11906.70000", "0.02328140", "1596737056.573166", "r"]], "c": "3772943557"}, "book-100", "XBT/USD"]
[270, {"a": [["11869.80000", "15.85150216", "1596737113.718489"]], "c": "2642823034"}, "book-100", "XBT/USD"]
[270, {"b": [["11850.10000", "0.00000000", "1596737113.771715"], ["11808.80000", "2.66090576", "1596736784.110515", "r"]], "c": "2642823034"}, "book-100", "XBT/USD"]
[270, {"a": [["11875.90000", "0.00000000", "1596737113.772294"], ["11907.00000", "8.54095785", "1596737002.155356", "r"]], "c": "2642823034"}, "book-100", "XBT/USD"]
[270, {"b": [["11849.10000", "0.02300000", "1596737113.820378"]], "c": "2642823034"}, "book-100", "XBT/USD"]
[270, {"a": [["11874.90000", "0.01800000", "1596737113.821883"]], "c": "2642823034"}, "book-100", "XBT/USD"]
[270, {"a": [["11878.00000", "0.00000000", "1596737114.340856"], ["11907.00000", "8.54095785", "1596737002.155356", "r"]], "c": "2642823034"}, "book-100", "XBT/USD"]
[270, {"a": [["11869.80000", "16.10150216", "1596737114.436397"]], "c": "3772943557"}, "book-100", "XBT/USD"]
[270, {"b": [["11810.40000", "0.00000000", "1596737114.574593"], ["11808.80000", "2.66090576", "1596736784.110515", "r"]], "c": "3772943557"}, "book-100", "XBT/USD"]
[270, {"a": [["11893.80000", "0.96913521", "1596737114.602087"]], "c": "3772943557"}, "book-100", "XBT/USD"]
[270, {"a": [["11869.80000", "15.85150216", "1596737114.783496"]], "c": "2642823034"}, "book-100", "XBT/USD"]
[270, {"b": [["11830.90000", "0.73610054", "1596737115.080999"]], "c": "2642823034"}, "book-100", "XBT/USD"]
[270, {"a": [["11895.40000", "0.73610054", "1596737115.081609"]], "c": "2642823034"}, "book-100", "XBT/USD"]
[270, {"b": [["11831.30000", "0.00000000", "1596737115.083374"], ["11808.80000", "2.66090576", "1596736784.110515", "r"]], "c": "2642823034"}, "book-100", "XBT/USD"]
[270, {"a": [["11895.30000", "0.00000000", "1596737115.084843"], ["11907.00000", "8.54095785", "1596737002.155356", "r"]], "c": "2642823034"}, "book-100", "XBT/USD"]
[270, {"b": [["11861.60000", "0.25280099", "1596737115.298073"]], "c": "657473389"}, "book-100", "XBT/USD"]
[270, {"a": [["11869.80000", "16.10150216", "1596737115.389937"]], "c": "1515517138"}, "book-100", "XBT/USD"]
[270, {"b": [["11845.30000", "0.23800000", "1596737115.410081"]], "c": "1515517138"}, "book-100", "XBT/USD"]
[270, {"a": [["11869.80000", "15.85150216", "1596737115.672071"]], "c": "657473389"}, "book-100", "XBT/USD"]
[270, {"a": [["11895.00000", "0.42065000", "1596737115.793548"]], "c": "657473389"}, "book-100", "XBT/USD"]
[270, {"b": [["11843.20000", "0.00426945", "1596737116.114063"]], "c": "657473389"}, "book-100", "XBT/USD"]
[270, {"a": [["11885.40000", "0.00438186", "1596737116.114250"]], "c": "657473389"}, "book-100", "XBT/USD"]
[270, {"a": [["11906.70000", "0.00000000", "1596737116.280820"], ["11907.00000", "8.54095785", "1596737002.155356", "r"]], "c": "657473389"}, "book-100", "XBT/USD"]
[270, {"b": [["11843.20000", "0.00000000", "1596737116.491054"], ["11811.70000", "5.70000000", "1596736886.902857", "r"]], "c": "657473389"}, "book-100", "XBT/USD"]
[270, {"a": [["11906.10000", "0.00000000", "1596737116.531653"], ["11907.20000", "6.18638192", "1596736972.522950", "r"]], "c": "657473389"}, "book-100", "XBT/USD"]
[270, {"a": [["11893.70000", "4.74614866", "1596737116.545055"]], "c": "657473389"}, "book-100", "XBT/USD"]
[270, {"a": [["11904.60000", "0.02329731", "1596737116.563077"]], "c": "657473389"}, "book-100", "XBT/USD"]
[270, {"a": [["11900.30000", "0.73381520", "1596737116.696146"]], "c": "657473389"}, "book-100", "XBT/USD"]
[270, {"a": [["11902.20000", "1.58369712", "1596737116.990726"]], "c": "657473389"}, "book-100", "XBT/USD"]
[270, {"a": [["11893.60000", "0.00000000", "1596737117.040003"], ["11906.30000", "0.50000000", "1596737112.402138", "r"]], "c": "657473389"}, "book-100", "XBT/USD"]
[270, {"a": [["11890.30000", "1.27576370", "1596737117.168696"]], "c": "657473389"}, "book-100", "XBT/USD"]
[270, {"a": [["11877.30000", "0.00000000", "1596737118.436765"], ["11906.30000", "0.50000000", "1596737112.402138", "r"]], "c": "657473389"}, "book-100", "XBT/USD"]
[270, {"a": [["11870.20000", "0.89025099", "1596737118.494557"]], "c": "2998651719"}, "book-100", "XBT/USD"]
[270, {"b": [["11852.60000", "0.00000000", "1596737118.550616"], ["11808.80000", "2.66090576", "1596736784.110515", "r"]], "c": "2998651719"}, "book-100", "XBT/USD"]
[270, {"a": [["11870.50000", "0.80940122", "1596737118.553800"]], "c": "594617324"}, "book-100", "XBT/USD"]
[270, {"b": [["11852.60000", "0.09621094", "1596737118.555357"]], "c": "594617324"}, "book-100", "XBT/USD"]
[270, {"a": [["11874.90000", "0.00000000", "1596737118.572954"], ["11907.00000", "8.54095785", "1596737002.155356", "r"]], "c": "594617324"}, "book-100", "XBT/USD"]
[270, {"a": [["11906.30000", "0.00000000", "1596737118.582248"], ["11907.20000", "6.18638192", "1596736972.522950", "r"]], "c": "594617324"}, "book-100", "XBT/USD"]
[270, {"b": [["11849.10000", "0.00000000", "1596737118.605729"], ["11808.80000", "2.66090576", "1596736784.110515", "r"]], "c": "594617324"}, "book-100", "XBT/USD"]
[270, {"a": [["11873.90000", "0.01800000", "1596737118.624546"]], "c": "594617324"}, "book-100", "XBT/USD"]
[270, {"b": [["11848.10000", "0.02300000", "1596737118.655740"]], "c": "594617324"}, "book-100", "XBT/USD"]
[270, {"a": [["11869.80000", "16.10150216", "1596737118.694068"]], "c": "2027088186"}, "book-100", "XBT/USD"]
[270, {"a": [["11870.50000", "0.71319028", "1596737118.776483"]], "c": "3910664593"}, "book-100", "XBT/USD"]
[270, {"a": [["11869.80000", "15.85150216", "1596737119.144170"]], "c": "2998651719"}, "book-100", "XBT/USD"]
[270, {"a": [["11870.80000", "0.00000000", "1596737119.193064"], ["11907.20000", "6.18638192", "1596736972.522950", "r"]], "c": "2212761883"}, "book-100", "XBT/USD"]
[270, {"a": [["11873.90000", "0.00000000", "1596737119.245352"], ["11907.50000", "3.26133727", "1596736967.970398", "r"]], "c": "2212761883"}, "book-100", "XBT/USD"]
[270, {"a": [["11874.90000", "0.01800000", "1596737119.292688"]], "c": "2212761883"}, "book-100", "XBT/USD"]
[271, [["11869.70000", "0.19184633", "1596737119.471320", "s", "l", ""]], "trade", "XBT/USD"]
[270, {"a": [["11869.70000", "0.00015367", "1596737119.470578"]]}, {"b": [["11869.70000", "0.00000000", "1596737119.471320"], ["11808.80000", "2.66090576", "1596736784.110515", "r"]], "c": "4195391398"}, "book-100", "XBT/USD"]
[270, {"a": [["11869.80000", "15.35150216", "1596737119.546171"]], "c": "1343541951"}, "book-100", "XBT/USD"]
[270, {"a": [["11874.90000", "0.00000000", "1596737119.549962"], ["11907.20000", "6.18638192", "1596736972.522950", "r"]], "c": "1343541951"}, "book-100", "XBT/USD"]
[270, {"a": [["11869.80000", "15.15150216", "1596737119.550354"]], "c": "2005047297"}, "book-100", "XBT/USD"]
[270, {"a": [["11869.80000", "14.45150216", "1596737119.551606"]], "c": "3500322658"}, "book-100", "XBT/USD"]
[270, {"a": [["11869.70000", "0.25015367", "1596737119.554261"]], "c": "683256256"}, "book-100", "XBT/USD"]
[270, {"a": [["11869.70000", "0.46921367", "1596737119.559151"]], "c": "1975414397"}, "book-100", "XBT/USD"]
[270, {"a": [["11869.80000", "14.25285216", "1596737119.561904"]], "c": "1978968288"}, "book-100", "XBT/USD"]
[270, {"a": [["11869.80000", "13.75285216", "1596737119.563075"]], "c": "2815854272"}, "book-100", "XBT/USD"]
[270, {"b": [["11859.60000", "0.00000000", "1596737119.568365"], ["11808.70000", "9.70000000", "1596737024.924486", "r"]], "c": "2987976785"}, "book-100", "XBT/USD"]
[270, {"a": [["11869.80000", "13.84985216", "1596737119.570518"]], "c": "2464626279"}, "book-100", "XBT/USD"]
[270, {"a": [["11869.80000", "13.34985216", "1596737119.571312"]], "c": "4129725154"}, "book-100", "XBT/USD"]
[270, {"a": [["11869.60000", "0.01975817", "1596737119.572403"]], "c": "2252525560"}, "book-100", "XBT/USD"]
[270, {"a": [["11873.90000", "0.01800000", "1596737119.598294"]], "c": "2252525560"}, "book-100", "XBT/USD"]
[270, {"b": [["11860.10000", "2.01298879", "1596737119.604219"]], "c": "714885612"}, "book-100", "XBT/USD"]
[270, {"a": [["11869.80000", "13.33009400", "1596737119.636650"]], "c": "4240752498"}, "book-100", "XBT/USD"]
[270, {"a": [["11866.80000", "0.25000000", "1596737119.638709"]], "c": "4173452624"}, "book-100", "XBT/USD"]
[270, {"a": [["11869.60000", "0.23881817", "1596737119.641279"]], "c": "3891187337"}, "book-100", "XBT/USD"]
[270, {"a": [["11875.40000", "0.00000000", "1596737119.663154"], ["11906.00000", "0.05458243", "1596736960.945412", "r"]], "c": "3891187337"}, "book-100", "XBT/USD"]
[270, {"a": [["11869.90000", "0.00000000", "1596737119.672194"], ["11907.00000", "8.54095785", "1596737002.155356", "r"]], "c": "142262216"}, "book-100", "XBT/USD"]
[270, {"a": [["11870.10000", "0.00000000", "1596737119.672351"], ["11907.20000", "6.18638192", "1596736972.522950", "r"]], "c": "1430100547"}, "book-100", "XBT/USD"]
[270, {"a": [["11870.00000", "0.00000000", "1596737119.672512"], ["11907.50000", "3.26133727", "1596736967.970398", "r"]], "c": "1084655623"}, "book-100", "XBT/USD"]
[270, {"a": [["11875.10000", "0.00000000", "1596737119.672909"], ["11907.90000", "2.38150000", "1596736895.960018", "r"]], "c": "1084655623"}, "book-100", "XBT/USD"]
[270, {"a": [["11876.90000", "0.00000000", "1596737119.676157"], ["11908.90000", "1.06880000", "1596736841.521829", "r"]], "c": "1084655623"}, "book-100", "XBT/USD"]
[270, {"a": [["11869.80000", "12.54310400", "1596737119.695314"]], "c": "2576708964"}, "book-100", "XBT/USD"]
[270, {"a": [["11873.80000", "0.69338345", "1596737119.698518"]], "c": "2576708964"}, "book-100", "XBT/USD"]
[270, {"a": [["11873.90000", "0.00000000", "1596737119.748662"], ["11909.10000", "1.00200000", "1596736809.784670", "r"]], "c": "2576708964"}, "book-100", "XBT/USD"]
[270, {"a": [["11869.80000", "12.13099838", "1596737119.758423"]], "c": "3147507470"}, "book-100", "XBT/USD"]
[270, {"a": [["11866.80000", "0.00000000", "1596737119.773196"], ["11909.80000", "0.50000000", "1596737118.392266", "r"]], "c": "1464049420"}, "book-100", "XBT/USD"]
[270, {"a": [["11872.50000", "0.00000000", "1596737119.804993"], ["11909.90000", "6.20000000", "1596736825.518690", "r"]], "c": "1464049420"}, "book-100", "XBT/USD"]
[270, {"a": [["11874.90000", "0.01800000", "1596737119.807181"]], "c": "1464049420"}, "book-100", "XBT/USD"]
[270, {"a": [["11869.80000", "12.04675061", "1596737119.858019"]], "c": "2695129630"}, "book-100", "XBT/USD"]
[270, {"b": [["11858.40000", "0.00000000", "1596737119.902732"], ["11807.80000", "1.06000000", "1596737111.250147", "r"]], "c": "2695129630"}, "book-100", "XBT/USD"]
[270, {"a": [["11872.10000", "0.17591691", "1596737119.904025"]], "c": "2695129630"}, "book-100", "XBT/USD"]
[270, {"a": [["11869.50000", "0.85540000", "1596737119.927193"]], "c": "2505030532"}, "book-100", "XBT/USD"]
[270, {"a": [["11866.10000", "0.50000000", "1596737119.946881"]], "c": "2533465371"}, "book-100", "XBT/USD"]
[270, {"a": [["11869.80000", "10.54675061", "1596737119.946944"]], "c": "3433528498"}, "book-100", "XBT/USD"]
[270, {"a": [["11868.40000", "0.25000000", "1596737119.963708"]], "c": "3059216980"}, "book-100", "XBT/USD"]
[270, {"a": [["11885.40000", "0.00000000", "1596737119.966915"], ["11907.90000", "2.38150000", "1596736895.960018", "r"]], "c": "3059216980"}, "book-100", "XBT/USD"]
[270, {"b": [["11858.10000", "0.95501000", "1596737119.985001"]], "c": "3059216980"}, "book-100", "XBT/USD"]
[270, {"a": [["11869.50000", "1.07446000", "1596737119.989430"]], "c": "840911587"}, "book-100", "XBT/USD"]
[270, {"a": [["11880.30000", "0.00000000", "1596737120.020216"], ["11908.90000", "1.06880000", "1596736841.521829", "r"]], "c": "840911587"}, "book-100", "XBT/USD"]
[270, {"a": [["11886.10000", "0.20910726", "1596737120.021512"]], "c": "840911587"}, "book-100", "XBT/USD"]
[270, {"a": [["11883.70000", "0.00000000", "1596737120.021618"], ["11909.10000", "1.00200000", "1596736809.784670", "r"]], "c": "840911587"}, "book-100", "XBT/USD"]
[270, {"a": [["11893.70000", "3.00000000", "1596737120.022833"]], "c": "840911587"}, "book-100", "XBT/USD"]
[270, {"a": [["11868.30000", "0.85540000", "1596737120.024376"]], "c": "567023001"}, "book-100", "XBT/USD"]
[270, {"a": [["11869.50000", "0.21906000", "1596737120.030529"]], "c": "2399195542"}, "book-100", "XBT/USD"]
[270, {"a": [["11874.90000", "0.00000000", "1596737120.031901"], ["11909.10000", "1.00200000", "1596736809.784670", "r"]], "c": "2399195542"}, "book-100", "XBT/USD"]
[270, {"a": [["11869.70000", "1.14272654", "1596737120.040761"]], "c": "4206163053"}, "book-100", "XBT/USD"]
[270, {"a": [["11866.70000", "0.01975816", "1596737120.040859"]], "c": "19644137"}, "book-100", "XBT/USD"]
[270, {"a": [["11868.30000", "1.25540000", "1596737120.046555"]], "c": "4218127756"}, "book-100", "XBT/USD"]
[270, {"a": [["11901.00000", "0.17065000", "1596737120.047779"]], "c": "4218127756"}, "book-100", "XBT/USD"]
[270, {"a": [["11869.70000", "1.84272654", "1596737120.047891"]], "c": "3946808090"}, "book-100", "XBT/USD"]
[270, {"a": [["11866.80000", "0.21906000", "1596737120.048372"]], "c": "420415652"}, "book-100", "XBT/USD"]
[270, {"a": [["11870.40000", "0.00500000", "1596737120.052343"]], "c": "420415652"}, "book-100", "XBT/USD"]
[270, {"b": [["11813.50000", "0.00000000", "1596737120.058576"], ["11807.80000", "1.06000000", "1596737111.250147", "r"]], "c": "420415652"}, "book-100", "XBT/USD"]
[270, {"a": [["11870.50000", "0.09621094", "1596737120.058930"]], "c": "420415652"}, "book-100", "XBT/USD"]
[270, {"b": [["11811.80000", "6.44244739", "1596737120.061239"]], "c": "420415652"}, "book-100", "XBT/USD"]
[270, {"a": [["11863.70000", "0.50000000", "1596737120.061340"]], "c": "3722826354"}, "book-100", "XBT/USD"]
[270, {"a": [["11869.80000", "9.44675061", "1596737120.062923"]], "c": "986483168"}, "book-100", "XBT/USD"]
[270, {"a": [["11866.30000", "2.00000000", "1596737120.064163"]], "c": "2959143519"}, "book-100", "XBT/USD"]
[270, {"a": [["11870.20000", "0.84275099", "1596737120.068967"]], "c": "2959143519"}, "book-100", "XBT/USD"]
[270, {"a": [["11869.50000", "0.70997884", "1596737120.085987"]], "c": "711556496"}, "book-100", "XBT/USD"]
[270, {"a": [["11873.90000", "0.01800000", "1596737120.086929"]], "c": "711556496"}, "book-100", "XBT/USD"]
[270, {"a": [["11865.60000", "2.00000000", "1596737120.093285"]], "c": "703689214"}, "book-100", "XBT/USD"]
[270, {"a": [["11869.70000", "1.14272654", "1596737120.095219"]], "c": "703689214"}, "book-100", "XBT/USD"]
[270, {"a": [["11863.70000", "0.91958290", "1596737120.111543"]], "c": "2728910623"}, "book-100", "XBT/USD"]
[270, {"a": [["11868.30000", "0.85540000", "1596737120.111721"]], "c": "2467856295"}, "book-100", "XBT/USD"]
[270, {"b": [["11859.30000", "0.17591678", "1596737120.119267"]], "c": "2467856295"}, "book-100", "XBT/USD"]
[270, {"a": [["11868.40000", "0.00000000", "1596737120.123616"], ["11907.00000", "8.54095785", "1596737002.155356", "r"]], "c": "2556561330"}, "book-100", "XBT/USD"]
[270, {"a": [["11873.60000", "0.00000000", "1596737120.133832"], ["11907.20000", "6.18638192", "1596736972.522950", "r"]], "c": "2556561330"}, "book-100", "XBT/USD"]
[270, {"a": [["11866.80000", "0.00000000", "1596737120.147483"], ["11907.50000", "3.26133727", "1596736967.970398", "r"]], "c": "3717169324"}, "book-100", "XBT/USD"]
[270, {"a": [["11866.00000", "0.70000000", "1596737120.147754"]], "c": "1206612954"}, "book-100", "XBT/USD"]
[270, {"a": [["11863.70000", "1.35458290", "1596737120.203026"]], "c": "349457270"}, "book-100", "XBT/USD"]
[270, {"b": [["11863.60000", "0.00000000", "1596737120.203265"], ["11807.80000", "1.06000000", "1596737111.250147", "r"]], "c": "1240641750"}, "book-100", "XBT/USD"]
[270, {"a": [["11869.80000", "5.23675061", "1596737120.209990"]], "c": "1240641750"}, "book-100", "XBT/USD"]
[270, {"a": [["11869.80000", "3.23675061", "1596737120.210768"]], "c": "1240641750"}, "book-100", "XBT/USD"]
[270, {"a": [["11863.70000", "3.35458290", "1596737120.211339"]], "c": "981459060"}, "book-100", "XBT/USD"]
[270, {"a": [["11884.10000", "1.38465530", "1596737120.255462"]], "c": "981459060"}, "book-100", "XBT/USD"]
[270, {"a": [["11881.70000", "0.69246749", "1596737120.258434"]], "c": "981459060"}, "book-100", "XBT/USD"]
[270, {"a": [["11878.30000", "0.32984081", "1596737120.259404"]], "c": "981459060"}, "book-100", "XBT/USD"]
[270, {"b": [["11858.10000", "0.00000000", "1596737120.261044"], ["11807.70000", "3.28855406", "1596736821.611246", "r"]], "c": "981459060"}, "book-100", "XBT/USD"]
[270, {"a": [["11863.70000", "3.57364290", "1596737120.267976"]], "c": "3112950682"}, "book-100", "XBT/USD"]
[270, {"b": [["11831.90000", "0.00000000", "1596737120.271640"], ["11807.50000", "2.19772556", "1596736916.776430", "r"]], "c": "3112950682"}, "book-100", "XBT/USD"]
[270, {"b": [["11856.60000", "0.00000000", "1596737120.275092"], ["11806.30000", "5.40000000", "1596737051.417403", "r"]], "c": "3112950682"}, "book-100", "XBT/USD"]
[270, {"a": [["11867.00000", "0.10100000", "1596737120.278096"]], "c": "3926755534"}, "book-100", "XBT/USD"]
[270, {"a": [["11869.30000", "0.64395440", "1596737120.330815"]], "c": "1342302950"}, "book-100", "XBT/USD"]
[270, {"a": [["11866.40000", "0.25000000", "1596737120.346106"]], "c": "256362287"}, "book-100", "XBT/USD"]
[270, {"a": [["11869.50000", "2.20997884", "1596737120.357785"]], "c": "256362287"}, "book-100", "XBT/USD"]
[270, {"a": [["11866.00000", "0.00000000", "1596737120.358137"], ["11904.60000", "0.02329731", "1596737116.563077", "r"]], "c": "2458213366"}, "book-100", "XBT/USD"]
[270, {"a": [["11870.30000", "1.03199714", "1596737120.360171"]], "c": "2458213366"}, "book-100", "XBT/USD"]
[270, {"a": [["11865.60000", "0.00000000", "1596737120.362763"], ["11904.70000", "1.24182769", "1596737083.484625", "r"]], "c": "1778232120"}, "book-100", "XBT/USD"]
[270, {"a": [["11865.50000", "0.04750000", "1596737120.363713"]], "c": "2072884857"}, "book-100", "XBT/USD"]
[270, {"a": [["11890.00000", "2.39643608", "1596737120.387704"]], "c": "2072884857"}, "book-100", "XBT/USD"]
[270, {"b": [["11855.50000", "0.00000000", "1596737120.406242"], ["11805.90000", "0.15000000", "1596735155.182015", "r"]], "c": "2072884857"}, "book-100", "XBT/USD"]
[270, {"a": [["11863.60000", "0.70000000", "1596737120.406880"]], "c": "3293994671"}, "book-100", "XBT/USD"]
[270, {"a": [["11869.50000", "1.71906000", "1596737120.410198"]], "c": "3293994671"}, "book-100", "XBT/USD"]
[270, {"b": [["11861.70000", "0.10000000", "1596737120.410403"]], "c": "2792542041"}, "book-100", "XBT/USD"]
[270, {"b": [["11859.50000", "6.65887727", "1596737120.417412"]], "c": "533500572"}, "book-100", "XBT/USD"]
[270, {"a": [["11863.70000", "3.35458290", "1596737120.422705"]], "c": "14082973"}, "book-100", "XBT/USD"]
[270, {"a": [["11866.40000", "4.45300000", "1596737120.428381"]], "c": "670728742"}, "book-100", "XBT/USD"]
[270, {"a": [["11895.80000", "7.48106248", "1596737120.466058"]], "c": "670728742"}, "book-100", "XBT/USD"]
[270, {"a": [["11863.70000", "2.85458290", "1596737120.482386"]], "c": "1384765238"}, "book-100", "XBT/USD"]
[270, {"a": [["11869.50000", "0.21906000", "1596737120.500383"]], "c": "1384765238"}, "book-100", "XBT/USD"]
[270, {"b": [["11830.00000", "7.11309542", "1596737120.512698"]], "c": "1384765238"}, "book-100", "XBT/USD"]
[270, {"b": [["11851.50000", "0.03427423", "1596737120.538027"]], "c": "1384765238"}, "book-100", "XBT/USD"]
[270, {"b": [["11853.10000", "0.07214444", "1596737120.539461"]], "c": "1384765238"}, "book-100", "XBT/USD"]
[270, {"b": [["11863.10000", "0.48000000", "1596737120.568209"]], "c": "182581305"}, "book-100", "XBT/USD"]
[270, {"a": [["11863.60000", "0.80000000", "1596737120.628265"]], "c": "3295450773"}, "book-100", "XBT/USD"]
[270, {"a": [["11869.60000", "0.21906000", "1596737120.638849"]], "c": "3295450773"}, "book-100", "XBT/USD"]
[270, {"b": [["11854.20000", "0.09700000", "1596737120.640310"]], "c": "3295450773"}, "book-100", "XBT/USD"]
[270, {"a": [["11866.80000", "1.50000000", "1596737120.646984"]], "c": "238092105"}, "book-100", "XBT/USD"]
[270, {"a": [["11865.50000", "0.26656000", "1596737120.649896"]], "c": "840121237"}, "book-100", "XBT/USD"]
[270, {"a": [["11863.50000", "0.01975817", "1596737120.707964"]], "c": "3572718024"}, "book-100", "XBT/USD"]
[270, {"a": [["11865.50000", "0.04750000", "1596737120.720077"]], "c": "2945663046"}, "book-100", "XBT/USD"]
[270, {"a": [["11863.70000", "2.41958290", "1596737120.726201"]], "c": "664233415"}, "book-100", "XBT/USD"]
[270, {"a": [["11863.50000", "0.22975817", "1596737120.730112"]], "c": "336109725"}, "book-100", "XBT/USD"]
[270, {"a": [["11863.20000", "0.14143852", "1596737120.736438"]], "c": "4205898349"}, "book-100", "XBT/USD"]
[270, {"a": [["11863.20000", "0.50000000", "1596737120.746364"]], "c": "3252296212"}, "book-100", "XBT/USD"]
[270, {"a": [["11863.50000", "0.72869991", "1596737120.746720"]], "c": "3360351356"}, "book-100", "XBT/USD"]
[270, {"a": [["11866.00000", "0.85540000", "1596737120.776355"]], "c": "2795237464"}, "book-100", "XBT/USD"]
[270, {"a": [["11868.30000", "0.00000000", "1596737120.781167"], ["11902.00000", "0.22739000", "1596736764.397858", "r"]], "c": "2795237464"}, "book-100", "XBT/USD"]
[270, {"a": [["11863.60000", "0.10000000", "1596737120.782880"]], "c": "247266865"}, "book-100", "XBT/USD"]
[270, {"a": [["11863.50000", "0.94775991", "1596737120.802392"]], "c": "1489538851"}, "book-100", "XBT/USD"]
[270, {"a": [["11863.40000", "0.70000000", "1596737120.828463"]], "c": "3992886178"}, "book-100", "XBT/USD"]
[270, {"a": [["11869.70000", "1.83496654", "1596737120.924494"]], "c": "3992886178"}, "book-100", "XBT/USD"]
[270, {"a": [["11863.20000", "1.17000000", "1596737120.957825"]], "c": "3381099134"}, "book-100", "XBT/USD"]
[270, {"a": [["11863.50000", "0.73775991", "1596737121.014785"]], "c": "1070475578"}, "book-100", "XBT/USD"]
[270, {"a": [["11863.50000", "0.23881817", "1596737121.016189"]], "c": "3181582574"}, "book-100", "XBT/USD"]
[270, {"a": [["11866.90000", "0.84275652", "1596737121.202598"]], "c": "3181582574"}, "book-100", "XBT/USD"]
[270, {"a": [["11864.90000", "0.63206739", "1596737121.203095"]], "c": "1839102077"}, "book-100", "XBT/USD"]
[270, {"a": [["11863.70000", "3.05165029", "1596737121.203327"]], "c": "3845477453"}, "book-100", "XBT/USD"]
[270, {"a": [["11867.60000", "0.84275652", "1596737121.203672"]], "c": "3845477453"}, "book-100", "XBT/USD"]
[270, {"a": [["11863.90000", "0.63206739", "1596737121.204800"]], "c": "3648204740"}, "book-100", "XBT/USD"]
[270, {"a": [["11863.50000", "0.01975817", "1596737121.227344"]], "c": "2106384459"}, "book-100", "XBT/USD"]
[270, {"a": [["11866.70000", "0.00000000", "1596737121.278358"], ["11900.00000", "12.71653131", "1596737075.897027", "r"]], "c": "2106384459"}, "book-100", "XBT/USD"]
[270, {"b": [["11830.90000", "0.00000000", "1596737121.294511"], ["11807.70000", "3.28855406", "1596736821.611246", "r"]], "c": "2106384459"}, "book-100", "XBT/USD"]
[270, {"b": [["11828.50000", "0.73612500", "1596737121.309314"]], "c": "2106384459"}, "book-100", "XBT/USD"]
[270, {"a": [["11893.70000", "3.73612500", "1596737121.310003"]], "c": "2106384459"}, "book-100", "XBT/USD"]
[270, {"a": [["11895.40000", "0.00000000", "1596737121.315059"], ["11900.30000", "0.73381520", "1596737116.696146", "r"]], "c": "2106384459"}, "book-100", "XBT/USD"]
[270, {"a": [["11863.20000", "1.18975816", "1596737121.351410"]], "c": "361885768"}, "book-100", "XBT/USD"]
[270, {"a": [["11863.20000", "1.61163478", "1596737121.354366"]], "c": "2305621051"}, "book-100", "XBT/USD"]
[270, {"a": [["11865.50000", "0.26655000", "1596737121.421062"]], "c": "2623662683"}, "book-100", "XBT/USD"]
[270, {"a": [["11890.80000", "3.09636836", "1596737121.433000"]], "c": "2623662683"}, "book-100", "XBT/USD"]
[270, {"b": [["11859.50000", "2.44887727", "1596737121.438698"]], "c": "2623662683"}, "book-100", "XBT/USD"]
[270, {"b": [["11852.60000", "0.00000000", "1596737121.654266"], ["11807.70000", "3.28855406", "1596736821.611246", "r"]], "c": "2623662683"}, "book-100", "XBT/USD"]
[270, {"a": [["11870.50000", "0.00000000", "1596737121.746035"], ["11900.30000", "0.73381520", "1596737116.696146", "r"]], "c": "2623662683"}, "book-100", "XBT/USD"]
[270, {"a": [["11863.60000", "0.00000000", "1596737121.781643"], ["11900.70000", "0.00500000", "1596736976.571243", "r"]], "c": "9907580"}, "book-100", "XBT/USD"]
[270, {"a": [["11876.60000", "0.00000000", "1596737121.794178"], ["11901.00000", "0.17065000", "1596737120.047779", "r"]], "c": "9907580"}, "book-100", "XBT/USD"]
[270, {"a": [["11866.70000", "0.48290196", "1596737121.794282"]], "c": "9907580"}, "book-100", "XBT/USD"]
[270, {"a": [["11863.50000", "0.00000000", "1596737121.835433"], ["11901.00000", "0.17065000", "1596737120.047779", "r"]], "c": "3536232214"}, "book-100", "XBT/USD"]
[270, {"a": [["11865.50000", "0.04750000", "1596737122.141130"]], "c": "4006379203"}, "book-100", "XBT/USD"]
[270, {"a": [["11863.20000", "2.11163478", "1596737122.155565"]], "c": "2821345293"}, "book-100", "XBT/USD"]
[270, {"b": [["11859.30000", "0.00000000", "1596737122.208741"], ["11807.50000", "2.19772556", "1596736916.776430", "r"]], "c": "2821345293"}, "book-100", "XBT/USD"]
[270, {"a": [["11863.30000", "0.21905000", "1596737122.223014"]], "c": "2971956809"}, "book-100", "XBT/USD"]
[270, {"b": [["11851.00000", "0.00000000", "1596737122.250613"], ["11806.30000", "5.40000000", "1596737051.417403", "r"]], "c": "2971956809"}, "book-100", "XBT/USD"]
[270, {"b": [["11857.50000", "4.20700000", "1596737122.260203"]], "c": "2971956809"}, "book-100", "XBT/USD"]
[270, {"a": [["11863.40000", "0.00000000", "1596737122.311241"], ["11901.00000", "0.17065000", "1596737120.047779", "r"]], "c": "302536070"}, "book-100", "XBT/USD"]
[270, {"a": [["11863.20000", "2.81163478", "1596737122.357811"]], "c": "3199596089"}, "book-100", "XBT/USD"]
[270, {"b": [["11857.60000", "0.17591670", "1596737122.404858"]], "c": "3199596089"}, "book-100", "XBT/USD"]
[270, {"a": [["11863.20000", "4.81163478", "1596737122.405301"]], "c": "1300206768"}, "book-100", "XBT/USD"]
[270, {"a": [["11863.20000", "4.11163478", "1596737122.407040"]], "c": "3787601679"}, "book-100", "XBT/USD"]
[270, {"a": [["11863.30000", "0.00000000", "1596737122.422129"], ["11902.00000", "0.22739000", "1596736764.397858", "r"]], "c": "3852395962"}, "book-100", "XBT/USD"]
[270, {"a": [["11863.60000", "0.70000000", "1596737122.494862"]], "c": "1498520524"}, "book-100", "XBT/USD"]
[270, {"a": [["11893.80000", "0.46913521", "1596737122.798239"]], "c": "1498520524"}, "book-100", "XBT/USD"]
[270, {"a": [["11870.90000", "0.00000000", "1596737122.913766"], ["11902.00000", "0.22739000", "1596736764.397858", "r"]], "c": "1498520524"}, "book-100", "XBT/USD"]
[270, {"a": [["11868.40000", "1.67900000", "1596737122.933452"]], "c": "1498520524"}, "book-100", "XBT/USD"]
[270, {"b": [["11822.20000", "0.00000000", "1596737123.202154"], ["11807.50000", "2.19772556", "1596736916.776430", "r"]], "c": "1498520524"}, "book-100", "XBT/USD"]
[270, {"b": [["11817.40000", "13.68771625", "1596737123.206701"]], "c": "1498520524"}, "book-100", "XBT/USD"]
[270, {"b": [["11827.90000", "0.00000000", "1596737123.216682"], ["11807.50000", "2.19772556", "1596736916.776430", "r"]], "c": "1498520524"}, "book-100", "XBT/USD"]
[270, {"a": [["11863.30000", "0.21905000", "1596737123.248524"]], "c": "1116490571"}, "book-100", "XBT/USD"]
[270, {"b": [["11861.70000", "0.00000000", "1596737123.291271"], ["11806.30000", "5.40000000", "1596737051.417403", "r"]], "c": "2917884202"}, "book-100", "XBT/USD"]
[270, {"a": [["11866.80000", "0.00000000", "1596737123.291390"], ["11901.00000", "0.17065000", "1596737120.047779", "r"]], "c": "2917884202"}, "book-100", "XBT/USD"]
[270, {"b": [["11855.40000", "0.00000000", "1596737123.292811"], ["11805.90000", "0.15000000", "1596735155.182015", "r"]], "c": "2917884202"}, "book-100", "XBT/USD"]
[270, {"a": [["11863.30000", "0.00000000", "1596737123.326468"], ["11902.00000", "0.22739000", "1596736764.397858", "r"]], "c": "3727469177"}, "book-100", "XBT/USD"]
[270, {"b": [["11827.90000", "5.47564234", "1596737123.347138"]], "c": "3727469177"}, "book-100", "XBT/USD"]
[270, {"a": [["11866.70000", "1.98290196", "1596737123.436330"]], "c": "3727469177"}, "book-100", "XBT/USD"]
[270, {"b": [["11853.10000", "0.08344379", "1596737123.449991"]], "c": "3727469177"}, "book-100", "XBT/USD"]
[270, {"b": [["11853.10000", "0.01129935", "1596737123.450488"]], "c": "3727469177"}, "book-100", "XBT/USD"]
[270, {"b": [["11860.50000", "0.10000000", "1596737123.468171"]], "c": "3181998028"}, "book-100", "XBT/USD"]
[270, {"a": [["11865.50000", "0.26655000", "1596737123.489699"]], "c": "2788617058"}, "book-100", "XBT/USD"]
[270, {"b": [["11853.10000", "0.00000000", "1596737123.574734"], ["11806.30000", "5.40000000", "1596737051.417403", "r"]], "c": "2788617058"}, "book-100", "XBT/USD"]
[270, {"b": [["11852.40000", "0.01632564", "1596737123.574990"]], "c": "2788617058"}, "book-100", "XBT/USD"]
[270, {"b": [["11852.40000", "0.08847434", "1596737123.921829"]], "c": "2788617058"}, "book-100", "XBT/USD"]
[270, {"b": [["11852.40000", "0.07214870", "1596737123.925493"]], "c": "2788617058"}, "book-100", "XBT/USD"]
[270, {"a": [["11869.70000", "1.16145367", "1596737124.007338"]], "c": "2788617058"}, "book-100", "XBT/USD"]
[270, {"a": [["11869.60000", "0.86818213", "1596737124.076998"]], "c": "2788617058"}, "book-100", "XBT/USD"]
[270, {"a": [["11893.00000", "0.50000000", "1596737124.102330"]], "c": "2788617058"}, "book-100", "XBT/USD"]
[270, {"b": [["11863.10000", "0.66000000", "1596737124.335382"]], "c": "2280456159"}, "book-100", "XBT/USD"]
[270, {"b": [["11851.90000", "0.00000000", "1596737125.329456"], ["11806.30000", "5.40000000", "1596737051.417403", "r"]], "c": "2280456159"}, "book-100", "XBT/USD"]
[270, {"b": [["11854.00000", "0.33046657", "1596737125.463791"]], "c": "2280456159"}, "book-100", "XBT/USD"]
[270, {"b": [["11850.60000", "0.69417889", "1596737125.905616"]], "c": "2280456159"}, "book-100", "XBT/USD"]
[270, {"b": [["11852.40000", "0.00000000", "1596737126.207262"], ["11807.50000", "2.19772556", "1596736916.776430", "r"]], "c": "2280456159"}, "book-100", "XBT/USD"]
[270, {"a": [["11865.50000", "0.04750000", "1596737126.215956"]], "c": "2624813937"}, "book-100", "XBT/USD"]
[270, {"b": [["11860.40000", "0.00000000", "1596737126.281721"], ["11806.30000", "5.40000000", "1596737051.417403", "r"]], "c": "3192506288"}, "book-100", "XBT/USD"]
[270, {"b": [["11851.60000", "0.07215357", "1596737126.306877"]], "c": "3192506288"}, "book-100", "XBT/USD"]
[270, {"a": [["11884.40000", "0.00438186", "1596737126.358485"]], "c": "3192506288"}, "book-100", "XBT/USD"]
[270, {"b": [["11843.90000", "0.00424942", "1596737126.359397"]], "c": "3192506288"}, "book-100", "XBT/USD"]
[270, {"a": [["11863.30000", "0.21904000", "1596737126.405445"]], "c": "1386101142"}, "book-100", "XBT/USD"]
[270, {"b": [["11845.30000", "0.00000000", "1596737126.422400"], ["11807.50000", "2.19772556", "1596736916.776430", "r"]], "c": "1386101142"}, "book-100", "XBT/USD"]
[270, {"a": [["11881.70000", "0.00000000", "1596737126.475981"], ["11900.70000", "0.00500000", "1596736976.571243", "r"]], "c": "1386101142"}, "book-100", "XBT/USD"]
[270, {"b": [["11860.10000", "0.33698879", "1596737126.506879"]], "c": "2214270896"}, "book-100", "XBT/USD"]
[270, {"a": [["11878.30000", "0.00000000", "1596737126.548159"], ["11901.00000", "0.17065000", "1596737120.047779", "r"]], "c": "2214270896"}, "book-100", "XBT/USD"]
[270, {"b": [["11858.10000", "0.23800000", "1596737126.696543"]], "c": "2214270896"}, "book-100", "XBT/USD"]
[270, {"b": [["11850.60000", "0.00000000", "1596737126.868291"], ["11807.50000", "2.19772556", "1596736916.776430", "r"]], "c": "2214270896"}, "book-100", "XBT/USD"]
[270, {"a": [["11884.00000", "0.69222790", "1596737127.073497"]], "c": "2214270896"}, "book-100", "XBT/USD"]
[270, {"a": [["11880.60000", "0.32972667", "1596737127.077626"]], "c": "2214270896"}, "book-100", "XBT/USD"]
[270, {"b": [["11843.90000", "0.00000000", "1596737127.126959"], ["11806.30000", "5.40000000", "1596737051.417403", "r"]], "c": "2214270896"}, "book-100", "XBT/USD"]
[270, {"b": [["11851.20000", "0.69414375", "1596737127.135367"]], "c": "2214270896"}, "book-100", "XBT/USD"]
[270, {"b": [["11860.00000", "0.00000000", "1596737127.205408"], ["11806.30000", "5.40000000", "1596737051.417403", "r"]], "c": "3682149988"}, "book-100", "XBT/USD"]
[270, {"b": [["11854.00000", "0.00000000", "1596737127.289361"], ["11805.90000", "0.15000000", "1596735155.182015", "r"]], "c": "3682149988"}, "book-100", "XBT/USD"]
[270, {"b": [["11851.20000", "0.00000000", "1596737127.320033"], ["11805.20000", "0.34533000", "1596735143.806373", "r"]], "c": "3682149988"}, "book-100", "XBT/USD"]
[270, {"b": [["11849.50000", "0.00000000", "1596737127.329938"], ["11805.00000", "0.17065000", "1596737093.803527", "r"]], "c": "3682149988"}, "book-100", "XBT/USD"]
[270, {"a": [["11884.00000", "0.00000000", "1596737127.332501"], ["11900.70000", "0.00500000", "1596736976.571243", "r"]], "c": "3682149988"}, "book-100", "XBT/USD"]
[270, {"a": [["11886.40000", "0.00000000", "1596737127.349026"], ["11901.00000", "0.17065000", "1596737120.047779", "r"]], "c": "3682149988"}, "book-100", "XBT/USD"]
[270, {"b": [["11848.40000", "0.00000000", "1596737127.383817"], ["11804.80000", "3.28996656", "1596736677.195153", "r"]], "c": "3682149988"}, "book-100", "XBT/USD"]
[270, {"a": [["11885.70000", "0.00000000", "1596737127.390449"], ["11902.00000", "0.22739000", "1596736764.397858", "r"]], "c": "3682149988"}, "book-100", "XBT/USD"]
[270, {"a": [["11880.60000", "0.00000000", "1596737127.391428"], ["11902.20000", "1.58369712", "1596737116.990726", "r"]], "c": "3682149988"}, "book-100", "XBT/USD"]
[270, {"a": [["11863.30000", "0.00000000", "1596737127.443242"], ["11903.90000", "1.59024654", "1596737096.689627", "r"]], "c": "934205506"}, "book-100", "XBT/USD"]
[270, {"a": [["11874.60000", "2.29818413", "1596737127.504735"]], "c": "934205506"}, "book-100", "XBT/USD"]
[270, {"b": [["11858.20000", "0.00000000", "1596737127.505149"], ["11803.70000", "0.01264419", "1596737126.359471", "r"]], "c": "934205506"}, "book-100", "XBT/USD"]
[270, {"b": [["11861.60000", "0.00000000", "1596737127.521450"], ["11803.60000", "3.21918392", "1596736692.311968", "r"]], "c": "2609245112"}, "book-100", "XBT/USD"]
[270, {"a": [["11866.50000", "0.63329000", "1596737127.526401"]], "c": "2609245112"}, "book-100", "XBT/USD"]
[270, {"b": [["11843.60000", "0.28656977", "1596737127.547781"]], "c": "2609245112"}, "book-100", "XBT/USD"]
[270, {"a": [["11885.40000", "0.58455308", "1596737127.574579"]], "c": "2609245112"}, "book-100", "XBT/USD"]
[270, {"b": [["11857.60000", "0.00000000", "1596737127.682906"], ["11803.60000", "3.21918392", "1596736692.311968", "r"]], "c": "2609245112"}, "book-100", "XBT/USD"]
[270, {"a": [["11881.80000", "0.00000000", "1596737127.713064"], ["11902.20000", "1.58369712", "1596737116.990726", "r"]], "c": "2609245112"}, "book-100", "XBT/USD"]
[270, {"a": [["11863.30000", "0.21904000", "1596737127.736726"]], "c": "2001868190"}, "book-100", "XBT/USD"]
[270, {"a": [["11881.80000", "5.89748378", "1596737127.796264"]], "c": "2001868190"}, "book-100", "XBT/USD"]
[270, {"a": [["11871.70000", "0.00000000", "1596737127.887351"], ["11902.00000", "0.22739000", "1596736764.397858", "r"]], "c": "2001868190"}, "book-100", "XBT/USD"]
[270, {"a": [["11872.20000", "0.07330046", "1596737127.902596"]], "c": "2001868190"}, "book-100", "XBT/USD"]
[270, {"b": [["11853.00000", "0.00000000", "1596737127.905651"], ["11803.30000", "0.95003592", "1596736676.897446", "r"]], "c": "2001868190"}, "book-100", "XBT/USD"]
[270, {"a": [["11884.20000", "0.00000000", "1596737127.907952"], ["11902.20000", "1.58369712", "1596737116.990726", "r"]], "c": "2001868190"}, "book-100", "XBT/USD"]
[270, {"a": [["11863.40000", "0.83557000", "1596737127.910693"]], "c": "3135899118"}, "book-100", "XBT/USD"]
[270, {"b": [["11847.90000", "0.83557000", "1596737127.949763"]], "c": "3135899118"}, "book-100", "XBT/USD"]
[270, {"b": [["11860.90000", "0.00000000", "1596737127.962496"], ["11803.30000", "0.95003592", "1596736676.897446", "r"]], "c": "4036948597"}, "book-100", "XBT/USD"]
[270, {"a": [["11885.40000", "0.00000000", "1596737127.980414"], ["11902.20000", "1.58369712", "1596737116.990726", "r"]], "c": "4036948597"}, "book-100", "XBT/USD"]
[270, {"a": [["11872.20000", "0.00000000", "1596737127.989695"], ["11903.90000", "1.59024654", "1596737096.689627", "r"]], "c": "4036948597"}, "book-100", "XBT/USD"]
[270, {"a": [["11863.60000", "0.00000000", "1596737128.012589"], ["11904.00000", "0.17065000", "1596737071.292235", "r"]], "c": "1947266692"}, "book-100", "XBT/USD"]
[270, {"b": [["11828.50000", "0.00000000", "1596737128.021873"], ["11802.00000", "7.67065000", "1596737087.435994", "r"]], "c": "1947266692"}, "book-100", "XBT/USD"]
[270, {"a": [["11893.80000", "1.20528544", "1596737128.024516"]], "c": "1947266692"}, "book-100", "XBT/USD"]
[270, {"b": [["11846.20000", "0.33712931", "1596737128.024650"]], "c": "1947266692"}, "book-100", "XBT/USD"]
[270, {"a": [["11893.70000", "3.00000000", "1596737128.034116"]], "c": "1947266692"}, "book-100", "XBT/USD"]
[270, {"b": [["11828.40000", "0.73615023", "1596737128.057716"]], "c": "1947266692"}, "book-100", "XBT/USD"]
[270, {"a": [["11863.20000", "4.81163478", "1596737128.061839"]], "c": "1485963804"}, "book-100", "XBT/USD"]
[270, {"b": [["11849.60000", "0.00000000", "1596737128.083552"], ["11803.30000", "0.95003592", "1596736676.897446", "r"]], "c": "1485963804"}, "book-100", "XBT/USD"]
[270, {"b": [["11842.10000", "0.00000000", "1596737128.119145"], ["11802.00000", "7.67065000", "1596737087.435994", "r"]], "c": "1485963804"}, "book-100", "XBT/USD"]
[270, {"a": [["11869.30000", "0.00000000", "1596737128.127904"], ["11904.60000", "0.02329731", "1596737116.563077", "r"]], "c": "1485963804"}, "book-100", "XBT/USD"]
[270, {"a": [["11869.60000", "0.21906000", "1596737128.142536"]], "c": "1485963804"}, "book-100", "XBT/USD"]
[270, {"a": [["11869.80000", "2.39438477", "1596737128.142850"]], "c": "1485963804"}, "book-100", "XBT/USD"]
[270, {"b": [["11846.10000", "0.33712931", "1596737128.157671"]], "c": "1485963804"}, "book-100", "XBT/USD"]
[270, {"a": [["11876.40000", "0.67256450", "1596737128.159483"]], "c": "1485963804"}, "book-100", "XBT/USD"]
[270, {"a": [["11884.00000", "0.49705003", "1596737128.162914"]], "c": "1485963804"}, "book-100", "XBT/USD"]
[270, {"b": [["11859.90000", "0.00000000", "1596737128.169325"], ["11802.00000", "7.67065000", "1596737087.435994", "r"]], "c": "3393669073"}, "book-100", "XBT/USD"]
[270, {"b": [["11854.50000", "0.50000000", "1596737128.215700"]], "c": "3393669073"}, "book-100", "XBT/USD"]
[270, {"a": [["11864.90000", "0.00000000", "1596737128.222449"], ["11904.00000", "0.17065000", "1596737071.292235", "r"]], "c": "1688166329"}, "book-100", "XBT/USD"]
[270, {"b": [["11859.80000", "0.00000000", "1596737128.224512"], ["11802.00000", "7.67065000", "1596737087.435994", "r"]], "c": "3427794577"}, "book-100", "XBT/USD"]
[270, {"a": [["11889.90000", "0.00000000", "1596737128.242785"], ["11904.60000", "0.02329731", "1596737116.563077", "r"]], "c": "3427794577"}, "book-100", "XBT/USD"]
[270, {"a": [["11884.00000", "1.43996555", "1596737128.262215"]], "c": "3427794577"}, "book-100", "XBT/USD"]
[270, {"a": [["11873.20000", "6.50000000", "1596737128.265401"]], "c": "3427794577"}, "book-100", "XBT/USD"]
[270, {"b": [["11846.90000", "0.94586838", "1596737128.265695"]], "c": "3427794577"}, "book-100", "XBT/USD"]
[270, {"a": [["11863.30000", "0.00000000", "1596737128.268385"], ["11904.70000", "1.24182769", "1596737083.484625", "r"]], "c": "1099558451"}, "book-100", "XBT/USD"]
[270, {"a": [["11872.80000", "0.00000000", "1596737128.271042"], ["11905.00000", "27.00000000", "1596736856.739074", "r"]], "c": "1099558451"}, "book-100", "XBT/USD"]
[270, {"a": [["11869.80000", "2.24438477", "1596737128.287331"]], "c": "1099558451"}, "book-100", "XBT/USD"]
[270, {"b": [["11857.50000", "0.00000000", "1596737128.306682"], ["11802.00000", "7.67065000", "1596737087.435994", "r"]], "c": "2276554892"}, "book-100", "XBT/USD"]
[270, {"b": [["11850.70000", "0.00000000", "1596737128.307778"], ["11801.90000", "4.67249674", "1596736908.903243", "r"]], "c": "2276554892"}, "book-100", "XBT/USD"]
[270, {"b": [["11845.30000", "1.00300000", "1596737128.310560"]], "c": "2276554892"}, "book-100", "XBT/USD"]
[270, {"a": [["11898.30000", "1.04890000", "1596737128.350068"]], "c": "2276554892"}, "book-100", "XBT/USD"]
[270, {"a": [["11884.00000", "0.94291552", "1596737128.377403"]], "c": "2276554892"}, "book-100", "XBT/USD"]
[270, {"a": [["11868.60000", "0.60685782", "1596737128.379927"]], "c": "2276554892"}, "book-100", "XBT/USD"]
[270, {"a": [["11875.10000", "0.38000000", "1596737128.464997"]], "c": "2276554892"}, "book-100", "XBT/USD"]
[270, {"b": [["11843.10000", "3.48949229", "1596737128.474911"]], "c": "2276554892"}, "book-100", "XBT/USD"]
[270, {"b": [["11847.60000", "0.00000000", "1596737128.477190"], ["11801.90000", "4.67249674", "1596736908.903243", "r"]], "c": "2276554892"}, "book-100", "XBT/USD"]
[270, {"a": [["11871.40000", "0.39240130", "1596737128.503000"]], "c": "2276554892"}, "book-100", "XBT/USD"]
[270, {"a": [["11866.40000", "4.20300000", "1596737128.506705"]], "c": "3765461152"}, "book-100", "XBT/USD"]
[270, {"b": [["11855.10000", "2.32024744", "1596737128.507394"]], "c": "3765461152"}, "book-100", "XBT/USD"]
[270, {"b": [["11827.00000", "4.30833693", "1596737128.511899"]], "c": "3765461152"}, "book-100", "XBT/USD"]
[270, {"b": [["11837.70000", "0.00000000", "1596737128.524685"], ["11801.90000", "4.67249674", "1596736908.903243", "r"]], "c": "3765461152"}, "book-100", "XBT/USD"]
[270, {"b": [["11857.40000", "4.48000000", "1596737128.542958"]], "c": "1241110038"}, "book-100", "XBT/USD"]
[270, {"a": [["11866.40000", "0.00000000", "1596737128.551847"], ["11904.60000", "0.02329731", "1596737116.563077", "r"]], "c": "3943737259"}, "book-100", "XBT/USD"]
[270, {"a": [["11869.20000", "0.64951161", "1596737128.571721"]], "c": "3943737259"}, "book-100", "XBT/USD"]
[270, {"a": [["11875.70000", "0.00000000", "1596737128.615241"], ["11904.60000", "0.02329731", "1596737116.563077", "r"]], "c": "3943737259"}, "book-100", "XBT/USD"]
[270, {"a": [["11898.60000", "0.00000000", "1596737128.619347"], ["11904.70000", "1.24182769", "1596737083.484625", "r"]], "c": "3943737259"}, "book-100", "XBT/USD"]
[270, {"a": [["11863.20000", "5.21163478", "1596737128.665353"]], "c": "1253812326"}, "book-100", "XBT/USD"]
[270, {"a": [["11864.90000", "4.21100000", "1596737128.665551"]], "c": "1630299426"}, "book-100", "XBT/USD"]
[270, {"a": [["11864.80000", "0.25000000", "1596737128.685595"]], "c": "2694900353"}, "book-100", "XBT/USD"]
[270, {"b": [["11848.10000", "0.00000000", "1596737128.717519"], ["11801.80000", "3.19470719", "1596736911.648608", "r"]], "c": "2694900353"}, "book-100", "XBT/USD"]
[270, {"b": [["11845.10000", "0.91706000", "1596737128.723650"]], "c": "2694900353"}, "book-100", "XBT/USD"]
[270, {"a": [["11873.80000", "0.00000000", "1596737128.723952"], ["11904.60000", "0.02329731", "1596737116.563077", "r"]], "c": "2694900353"}, "book-100", "XBT/USD"]
[270, {"a": [["11869.70000", "2.00418738", "1596737128.724470"]], "c": "2694900353"}, "book-100", "XBT/USD"]
[270, {"a": [["11880.30000", "0.97850000", "1596737128.724975"]], "c": "2694900353"}, "book-100", "XBT/USD"]
[270, {"b": [["11851.50000", "0.00000000", "1596737128.726462"], ["11801.80000", "3.19470719", "1596736911.648608", "r"]], "c": "2694900353"}, "book-100", "XBT/USD"]
[270, {"b": [["11859.50000", "0.00000000", "1596737128.729756"], ["11800.00000", "17.03324285", "1596736993.942623", "r"]], "c": "1926732710"}, "book-100", "XBT/USD"]
[270, {"b": [["11847.90000", "0.00000000", "1596737128.732602"], ["11799.20000", "23.14040000", "1596736141.974806", "r"]], "c": "1926732710"}, "book-100", "XBT/USD"]
[270, {"b": [["11860.10000", "0.00000000", "1596737128.734949"], ["11799.00000", "0.17065000", "1596736867.992954", "r"]], "c": "2706631175"}, "book-100", "XBT/USD"]
[270, {"a": [["11863.20000", "5.43663478", "1596737128.747930"]], "c": "2918357875"}, "book-100", "XBT/USD"]
[270, {"a": [["11866.10000", "0.00000000", "1596737128.762987"], ["11904.60000", "0.02329731", "1596737116.563077", "r"]], "c": "3797438575"}, "book-100", "XBT/USD"]
[270, {"a": [["11895.60000", "21.90000000", "1596737128.763374"]], "c": "3797438575"}, "book-100", "XBT/USD"]
[270, {"b": [["11805.00000", "0.00000000", "1596737128.768572"], ["11798.60000", "18.30000000", "1596737089.559503", "r"]], "c": "3797438575"}, "book-100", "XBT/USD"]
[270, {"a": [["11870.40000", "0.69848117", "1596737128.790816"]], "c": "3797438575"}, "book-100", "XBT/USD"]
[270, {"a": [["11872.10000", "0.00000000", "1596737128.795097"], ["11904.60000", "0.02329731", "1596737116.563077", "r"]], "c": "3797438575"}, "book-100", "XBT/USD"]
[270, {"b": [["11848.60000", "0.02300000", "1596737128.803430"]], "c": "3797438575"}, "book-100", "XBT/USD"]
[270, {"a": [["11895.70000", "2.16294979", "1596737128.821178"]], "c": "3797438575"}, "book-100", "XBT/USD"]
[270, {"b": [["11851.20000", "0.07215601", "1596737128.859466"]], "c": "3797438575"}, "book-100", "XBT/USD"]
[270, {"b": [["11841.30000", "0.94682048", "1596737128.859700"]], "c": "3797438575"}, "book-100", "XBT/USD"]
[270, {"b": [["11851.10000", "0.25411207", "1596737129.055909"]], "c": "3797438575"}, "book-100", "XBT/USD"]
[270, {"b": [["11857.40000", "4.20900000", "1596737129.091107"]], "c": "3442530998"}, "book-100", "XBT/USD"]
[270, {"a": [["11869.70000", "1.16145367", "1596737129.091363"]], "c": "3442530998"}, "book-100", "XBT/USD"]
[270, {"b": [["11851.60000", "0.00000000", "1596737129.094106"], ["11799.00000", "0.17065000", "1596736867.992954", "r"]], "c": "3442530998"}, "book-100", "XBT/USD"]
[270, {"a": [["11883.90000", "0.60274131", "1596737129.097311"]], "c": "3442530998"}, "book-100", "XBT/USD"]
[270, {"a": [["11871.30000", "2.48206900", "1596737129.112784"]], "c": "3442530998"}, "book-100", "XBT/USD"]
[270, {"b": [["11848.60000", "0.00000000", "1596737129.114055"], ["11798.60000", "18.30000000", "1596737089.559503", "r"]], "c": "3442530998"}, "book-100", "XBT/USD"]
[270, {"b": [["11847.30000", "0.04761701", "1596737129.175011"]], "c": "3442530998"}, "book-100", "XBT/USD"]
[270, {"a": [["11874.10000", "0.30000000", "1596737129.181090"]], "c": "3442530998"}, "book-100", "XBT/USD"]
[270, {"b": [["11857.40000", "5.88100000", "1596737129.201574"]], "c": "3562724076"}, "book-100", "XBT/USD"]
[270, {"a": [["11868.40000", "0.00000000", "1596737129.206442"], ["11902.20000", "1.58369712", "1596737116.990726", "r"]], "c": "3562724076"}, "book-100", "XBT/USD"]
[270, {"a": [["11865.80000", "1.67500000", "1596737129.221660"]], "c": "2141381332"}, "book-100", "XBT/USD"]
[270, {"a": [["11874.60000", "0.00000000", "1596737129.314426"], ["11902.20000", "1.58369712", "1596737116.990726", "r"]], "c": "2141381332"}, "book-100", "XBT/USD"]
[270, {"b": [["11848.50000", "0.34534859", "1596737129.354827"]], "c": "2141381332"}, "book-100", "XBT/USD"]
[270, {"b": [["11851.20000", "0.00000000", "1596737129.380105"], ["11798.60000", "18.30000000", "1596737089.559503", "r"]], "c": "2141381332"}, "book-100", "XBT/USD"]
[270, {"b": [["11847.80000", "0.02000496", "1596737129.382649"]], "c": "2141381332"}, "book-100", "XBT/USD"]
[270, {"a": [["11863.90000", "0.72827833", "1596737129.387506"]], "c": "594338564"}, "book-100", "XBT/USD"]
[270, {"b": [["11847.80000", "0.47908117", "1596737129.394658"]], "c": "594338564"}, "book-100", "XBT/USD"]
[270, {"a": [["11867.80000", "0.84271743", "1596737129.432008"]], "c": "594338564"}, "book-100", "XBT/USD"]
[270, {"b": [["11853.80000", "0.27100000", "1596737129.463616"]], "c": "594338564"}, "book-100", "XBT/USD"]
[270, {"a": [["11864.50000", "0.10100000", "1596737129.476800"]], "c": "1118263175"}, "book-100", "XBT/USD"]
[270, {"b": [["11858.80000", "0.00000000", "1596737129.508045"], ["11799.00000", "0.17065000", "1596736867.992954", "r"]], "c": "162961821"}, "book-100", "XBT/USD"]
[270, {"b": [["11855.80000", "0.00000000", "1596737129.512048"], ["11798.60000", "18.30000000", "1596737089.559503", "r"]], "c": "1984316941"}, "book-100", "XBT/USD"]
[270, {"b": [["11848.80000", "0.00000000", "1596737129.512547"], ["11797.90000", "6.30000000", "1596737122.404410", "r"]], "c": "1984316941"}, "book-100", "XBT/USD"]
[270, {"a": [["11864.80000", "0.00000000", "1596737129.512748"], ["11902.00000", "0.22739000", "1596736764.397858", "r"]], "c": "3869665193"}, "book-100", "XBT/USD"]
[270, {"a": [["11879.60000", "0.00000000", "1596737129.515633"], ["11902.20000", "1.58369712", "1596737116.990726", "r"]], "c": "3869665193"}, "book-100", "XBT/USD"]
[270, {"b": [["11847.70000", "0.00000000", "1596737129.515799"], ["11796.30000", "10.90540000", "1596736141.718106", "r"]], "c": "3869665193"}, "book-100", "XBT/USD"]
[270, {"b": [["11841.40000", "0.00000000", "1596737129.539164"], ["11796.00000", "0.17065000", "1596736856.488952", "r"]], "c": "3869665193"}, "book-100", "XBT/USD"]
[270, {"b": [["11847.20000", "7.10000000", "1596737129.543964"]], "c": "3869665193"}, "book-100", "XBT/USD"]
[270, {"b": [["11854.20000", "0.00000000", "1596737129.562812"], ["11795.30000", "2.20028792", "1596736851.216162", "r"]], "c": "2957085384"}, "book-100", "XBT/USD"]
[270, {"a": [["11863.20000", "5.93663478", "1596737129.568781"]], "c": "2510419566"}, "book-100", "XBT/USD"]
[270, {"a": [["11872.40000", "0.00000000", "1596737129.598192"], ["11903.90000", "1.59024654", "1596737096.689627", "r"]], "c": "2510419566"}, "book-100", "XBT/USD"]
[270, {"a": [["11863.20000", "6.03663478", "1596737129.607419"]], "c": "258755267"}, "book-100", "XBT/USD"]
[270, {"a": [["11883.90000", "0.00000000", "1596737129.609752"], ["11904.00000", "0.17065000", "1596737071.292235", "r"]], "c": "258755267"}, "book-100", "XBT/USD"]
[270, {"a": [["11868.70000", "0.50000000", "1596737129.612264"]], "c": "258755267"}, "book-100", "XBT/USD"]
[270, {"a": [["11879.30000", "0.00000000", "1596737129.617277"], ["11904.00000", "0.17065000", "1596737071.292235", "r"]], "c": "258755267"}, "book-100", "XBT/USD"]
[270, {"a": [["11863.90000", "0.09621094", "1596737129.744553"]], "c": "4175623415"}, "book-100", "XBT/USD"]
[270, {"b": [["11851.80000", "2.35250525", "1596737129.784317"]], "c": "4175623415"}, "book-100", "XBT/USD"]
[270, {"b": [["11847.20000", "0.00000000", "1596737129.801497"], ["11795.30000", "2.20028792", "1596736851.216162", "r"]], "c": "4175623415"}, "book-100", "XBT/USD"]
[270, {"b": [["11860.50000", "0.00000000", "1596737129.804293"], ["11795.00000", "0.80800000", "1596736676.791659", "r"]], "c": "533231349"}, "book-100", "XBT/USD"]
[270, {"b": [["11848.00000", "0.10936697", "1596737129.863440"]], "c": "533231349"}, "book-100", "XBT/USD"]
[270, {"a": [["11863.70000", "3.20165029", "1596737129.873541"]], "c": "2465576680"}, "book-100", "XBT/USD"]
[270, {"a": [["11896.70000", "0.00000000", "1596737129.889565"], ["11904.60000", "0.02329731", "1596737116.563077", "r"]], "c": "2465576680"}, "book-100", "XBT/USD"]
[270, {"b": [["11855.90000", "0.00000000", "1596737129.902208"], ["11795.00000", "0.80800000", "1596736676.791659", "r"]], "c": "3412181128"}, "book-100", "XBT/USD"]
[270, {"a": [["11863.70000", "2.56958290", "1596737129.903390"]], "c": "4180349078"}, "book-100", "XBT/USD"]
[270, {"b": [["11857.40000", "4.20900000", "1596737129.931724"]], "c": "1118995378"}, "book-100", "XBT/USD"]
[270, {"a": [["11869.20000", "0.00000000", "1596737129.939046"], ["11904.70000", "0.30000000", "1596737128.756257", "r"]], "c": "1118995378"}, "book-100", "XBT/USD"]
[270, {"b": [["11837.10000", "0.00000000", "1596737129.983131"], ["11793.00000", "0.17065000", "1596736873.693890", "r"]], "c": "1118995378"}, "book-100", "XBT/USD"]
[270, {"b": [["11830.10000", "0.00000000", "1596737129.985491"], ["11790.00000", "0.41815000", "1596737050.860342", "r"]], "c": "1118995378"}, "book-100", "XBT/USD"]
[270, {"b": [["11846.50000", "0.00000000", "1596737129.985804"], ["11789.40000", "2.00800000", "1596735513.212546", "r"]], "c": "1118995378"}, "book-100", "XBT/USD"]
[270, {"b": [["11850.80000", "0.00000000", "1596737129.986150"], ["11787.00000", "0.17065000", "1596737071.713970", "r"]], "c": "1118995378"}, "book-100", "XBT/USD"]
[270, {"a": [["11869.80000", "1.58154666", "1596737129.986976"]], "c": "1118995378"}, "book-100", "XBT/USD"]
[270, {"a": [["11870.40000", "0.00500000", "1596737129.987255"]], "c": "1118995378"}, "book-100", "XBT/USD"]
[270, {"b": [["11843.10000", "0.38000000", "1596737129.992951"]], "c": "1118995378"}, "book-100", "XBT/USD"]
[270, {"b": [["11853.80000", "0.00000000", "1596737129.993309"], ["11786.90000", "2.94564296", "1596737125.480097", "r"]], "c": "1735553398"}, "book-100", "XBT/USD"]
[270, {"a": [["11863.20000", "6.13963478", "1596737129.993560"]], "c": "2764706305"}, "book-100", "XBT/USD"]
[270, {"a": [["11870.30000", "0.73078254", "1596737129.996805"]], "c": "2764706305"}, "book-100", "XBT/USD"]
[270, {"b": [["11837.00000", "0.00000000", "1596737130.003136"], ["11785.60000", "0.03400000", "1596736849.625498", "r"]], "c": "2764706305"}, "book-100", "XBT/USD"]
[270, {"a": [["11871.00000", "0.00000000", "1596737130.027941"], ["11905.00000", "27.00000000", "1596736856.739074", "r"]], "c": "2764706305"}, "book-100", "XBT/USD"]
[270, {"a": [["11867.80000", "0.00000000", "1596737130.048628"], ["11906.00000", "0.05458243", "1596736960.945412", "r"]], "c": "2764706305"}, "book-100", "XBT/USD"]
[270, {"a": [["11863.20000", "6.63963478", "1596737130.049824"]], "c": "502886015"}, "book-100", "XBT/USD"]
[270, {"b": [["11845.20000", "0.00000000", "1596737130.063351"], ["11785.20000", "0.01400000", "1596736835.292810", "r"]], "c": "502886015"}, "book-100", "XBT/USD"]
[270, {"b": [["11855.10000", "0.00000000", "1596737130.067580"], ["11784.50000", "0.00200000", "1596736829.981217", "r"]], "c": "2627455606"}, "book-100", "XBT/USD"]
[270, {"a": [["11871.40000", "0.24250000", "1596737130.067977"]], "c": "2627455606"}, "book-100", "XBT/USD"]
[270, {"a": [["11870.30000", "0.59661894", "1596737130.068930"]], "c": "2627455606"}, "book-100", "XBT/USD"]
[270, {"b": [["11843.80000", "1.75350549", "1596737130.077487"]], "c": "2627455606"}, "book-100", "XBT/USD"]
[270, {"b": [["11842.90000", "0.00000000", "1596737130.077675"], ["11784.00000", "0.17065000", "1596737088.317848", "r"]], "c": "2627455606"}, "book-100", "XBT/USD"]
[270, {"a": [["11876.00000", "0.00000000", "1596737130.078027"], ["11907.00000", "8.54095785", "1596737002.155356", "r"]], "c": "2627455606"}, "book-100", "XBT/USD"]
[270, {"b": [["11839.30000", "0.00000000", "1596737130.087364"], ["11781.00000", "0.10000000", "1596736075.955466", "r"]], "c": "2627455606"}, "book-100", "XBT/USD"]
[270, {"a": [["11876.80000", "0.00000000", "1596737130.087605"], ["11907.20000", "6.18638192", "1596736972.522950", "r"]], "c": "2627455606"}, "book-100", "XBT/USD"]
[270, {"b": [["11845.50000", "0.00000000", "1596737130.096085"], ["11780.00000", "0.50000000", "1596734389.131980", "r"]], "c": "2627455606"}, "book-100", "XBT/USD"]
[270, {"a": [["11863.20000", "5.93963478", "1596737130.097628"]], "c": "2808676683"}, "book-100", "XBT/USD"]
[270, {"b": [["11837.20000", "6.50004343", "1596737130.099177"]], "c": "2808676683"}, "book-100", "XBT/USD"]
[270, {"a": [["11867.90000", "3.81919424", "1596737130.100920"]], "c": "2808676683"}, "book-100", "XBT/USD"]
[270, {"b": [["11848.00000", "0.00000000", "1596737130.106085"], ["11778.00000", "0.14434000", "1596737017.436335", "r"]], "c": "2808676683"}, "book-100", "XBT/USD"]
[270, {"b": [["11837.20000", "0.00000000", "1596737130.106193"], ["11777.00000", "0.00100000", "1596735197.730576", "r"]], "c": "2808676683"}, "book-100", "XBT/USD"]
[270, {"a": [["11870.30000", "0.21253134", "1596737130.108406"]], "c": "2808676683"}, "book-100", "XBT/USD"]
[270, {"a": [["11870.30000", "0.00000000", "1596737130.109817"], ["11907.20000", "6.18638192", "1596736972.522950", "r"]], "c": "2808676683"}, "book-100", "XBT/USD"]
[270, {"b": [["11843.60000", "0.00000000", "1596737130.110125"], ["11775.00000", "0.92000000", "1596736031.317852", "r"]], "c": "2808676683"}, "book-100", "XBT/USD"]
[270, {"b": [["11841.20000", "0.00000000", "1596737130.110496"], ["11772.90000", "2.20375182", "1596737056.454079", "r"]], "c": "2808676683"}, "book-100", "XBT/USD"]
[270, {"b": [["11857.40000", "0.00000000", "1596737130.112613"], ["11769.00000", "3.73835290", "1596736631.449390", "r"]], "c": "3079756070"}, "book-100", "XBT/USD"]
[270, {"b": [["11841.50000", "0.00000000", "1596737130.116527"], ["11768.80000", "1.67000789", "1596736630.663519", "r"]], "c": "3079756070"}, "book-100", "XBT/USD"]
[270, {"b": [["11833.70000", "0.00000000", "1596737130.118613"], ["11766.90000", "0.95277495", "1596737097.210623", "r"]], "c": "3079756070"}, "book-100", "XBT/USD"]
[270, {"a": [["11863.20000", "6.18963478", "1596737130.123089"]], "c": "2350892936"}, "book-100", "XBT/USD"]
[270, {"a": [["11869.70000", "0.91145367", "1596737130.124743"]], "c": "2350892936"}, "book-100", "XBT/USD"]
[270, {"a": [["11867.20000", "0.69357459", "1596737130.128763"]], "c": "2350892936"}, "book-100", "XBT/USD"]
[270, {"b": [["11843.80000", "0.00000000", "1596737130.129668"], ["11766.40000", "3.29928524", "1596737121.846223", "r"]], "c": "2350892936"}, "book-100", "XBT/USD"]
[270, {"b": [["11863.10000", "0.18000000", "1596737130.132771"]], "c": "1759879881"}, "book-100", "XBT/USD"]
[270, {"b": [["11835.80000", "3.21350000", "1596737130.137745"]], "c": "1759879881"}, "book-100", "XBT/USD"]
[270, {"b": [["11839.50000", "0.53066858", "1596737130.139912"]], "c": "1759879881"}, "book-100", "XBT/USD"]
[270, {"b": [["11841.10000", "0.00000000", "1596737130.143285"], ["11766.40000", "3.29928524", "1596737121.846223", "r"]], "c": "1759879881"}, "book-100", "XBT/USD"]
[270, {"b": [["11841.80000", "0.64062000", "1596737130.153621"]], "c": "1759879881"}, "book-100", "XBT/USD"]
[270, {"a": [["11873.30000", "0.00000000", "1596737130.157597"], ["11907.20000", "6.18638192", "1596736972.522950", "r"]], "c": "1759879881"}, "book-100", "XBT/USD"]
[270, {"a": [["11863.30000", "0.70000000", "1596737130.157940"]], "c": "3090694738"}, "book-100", "XBT/USD"]
[270, {"b": [["11785.60000", "0.00000000", "1596737130.158333"], ["11766.40000", "3.29928524", "1596737121.846223", "r"]], "c": "3090694738"}, "book-100", "XBT/USD"]
[270, {"b": [["11845.10000", "0.00000000", "1596737130.161247"], ["11763.00000", "0.00842254", "1596736532.316006", "r"]], "c": "3090694738"}, "book-100", "XBT/USD"]
[270, {"a": [["11869.80000", "0.93957572", "1596737130.164849"]], "c": "3090694738"}, "book-100", "XBT/USD"]
[270, {"a": [["11865.50000", "0.00000000", "1596737130.176168"], ["11907.20000", "6.18638192", "1596736972.522950", "r"]], "c": "2459626258"}, "book-100", "XBT/USD"]
[270, {"a": [["11904.70000", "0.00000000", "1596737130.181459"], ["11907.90000", "2.38150000", "1596736895.960018", "r"]], "c": "2459626258"}, "book-100", "XBT/USD"]
[270, {"b": [["11847.30000", "0.00000000", "1596737130.182001"], ["11760.00000", "0.04711202", "1596735559.775481", "r"]], "c": "2459626258"}, "book-100", "XBT/USD"]
[270, {"a": [["11868.50000", "0.67534049", "1596737130.185153"]], "c": "2459626258"}, "book-100", "XBT/USD"]
[270, {"a": [["11890.00000", "2.44869388", "1596737130.188037"]], "c": "2459626258"}, "book-100", "XBT/USD"]
[270, {"b": [["11854.30000", "1.68600000", "1596737130.190672"]], "c": "2414110124"}, "book-100", "XBT/USD"]
[270, {"b": [["11848.90000", "0.00000000", "1596737130.198896"], ["11760.00000", "0.04711202", "1596735559.775481", "r"]], "c": "2414110124"}, "book-100", "XBT/USD"]
[270, {"a": [["11868.60000", "0.00000000", "1596737130.206941"], ["11907.90000", "2.38150000", "1596736895.960018", "r"]], "c": "2414110124"}, "book-100", "XBT/USD"]
[270, {"b": [["11846.90000", "0.00000000", "1596737130.210945"], ["11758.90000", "0.01000000", "1596736714.822612", "r"]], "c": "2414110124"}, "book-100", "XBT/USD"]
[270, {"b": [["11847.80000", "0.50208117", "1596737130.213815"]], "c": "2414110124"}, "book-100", "XBT/USD"]
[270, {"a": [["11868.60000", "0.25500000", "1596737130.217891"]], "c": "2414110124"}, "book-100", "XBT/USD"]
[270, {"b": [["11839.10000", "0.00000000", "1596737130.219707"], ["11757.00000", "0.30000000", "1596735176.682759", "r"]], "c": "2414110124"}, "book-100", "XBT/USD"]
[270, {"a": [["11895.70000", "0.00000000", "1596737130.221572"], ["11907.90000", "2.38150000", "1596736895.960018", "r"]], "c": "2414110124"}, "book-100", "XBT/USD"]
[270, {"b": [["11836.90000", "0.00000000", "1596737130.221963"], ["11756.50000", "0.01696933", "1596734978.916212", "r"]], "c": "2414110124"}, "book-100", "XBT/USD"]
[270, {"b": [["11841.30000", "0.00000000", "1596737130.224274"], ["11756.00000", "0.10000000", "1596736706.773914", "r"]], "c": "2414110124"}, "book-100", "XBT/USD"]
[270, {"b": [["11826.70000", "0.73794670", "1596737130.239247"]], "c": "2414110124"}, "book-100", "XBT/USD"]
[270, {"b": [["11847.90000", "0.10000000", "1596737130.240440"]], "c": "2414110124"}, "book-100", "XBT/USD"]
[270, {"b": [["11768.20000", "0.03400000", "1596737130.244561"]], "c": "2414110124"}, "book-100", "XBT/USD"]
[270, {"a": [["11871.30000", "0.00000000", "1596737130.248169"], ["11908.90000", "1.06880000", "1596736841.521829", "r"]], "c": "2414110124"}, "book-100", "XBT/USD"]
[270, {"a": [["11863.20000", "6.85247289", "1596737130.277738"]], "c": "530906090"}, "book-100", "XBT/USD"]
[270, {"b": [["11843.20000", "0.04528646", "1596737130.283503"]], "c": "530906090"}, "book-100", "XBT/USD"]
[270, {"b": [["11802.00000", "7.50000000", "1596737130.293213"]], "c": "530906090"}, "book-100", "XBT/USD"]
[270, {"b": [["11854.60000", "0.10000000", "1596737130.306911"]], "c": "1921331691"}, "book-100", "XBT/USD"]
[270, {"b": [["11825.20000", "1.60003358", "1596737130.325843"]], "c": "1921331691"}, "book-100", "XBT/USD"]
[270, {"a": [["11868.50000", "0.00000000", "1596737130.330373"], ["11909.90000", "6.20000000", "1596736825.518690", "r"]], "c": "1921331691"}, "book-100", "XBT/USD"]
[270, {"b": [["11821.60000", "2.62752123", "1596737130.340862"]], "c": "1921331691"}, "book-100", "XBT/USD"]
[270, {"b": [["11825.90000", "1.06880000", "1596737130.346293"]], "c": "1921331691"}, "book-100", "XBT/USD"]
[270, {"b": [["11842.90000", "0.76599285", "1596737130.348847"]], "c": "1921331691"}, "book-100", "XBT/USD"]
[270, {"b": [["11847.90000", "0.00000000", "1596737130.358970"], ["11768.20000", "0.03400000", "1596737130.244561", "r"]], "c": "1921331691"}, "book-100", "XBT/USD"]
[270, {"a": [["11873.90000", "0.00000000", "1596737130.366079"], ["11910.00000", "0.36067000", "1596736968.148143", "r"]], "c": "1921331691"}, "book-100", "XBT/USD"]
[270, {"a": [["11863.20000", "7.10247289", "1596737130.377288"]], "c": "1980079632"}, "book-100", "XBT/USD"]
[270, {"b": [["11854.30000", "0.00000000", "1596737130.377738"], ["11766.90000", "0.95277495", "1596737097.210623", "r"]], "c": "3641875976"}, "book-100", "XBT/USD"]
[270, {"b": [["11811.80000", "2.20939231", "1596737130.412906"]], "c": "3641875976"}, "book-100", "XBT/USD"]
[270, {"a": [["11891.90000", "2.15856599", "1596737130.415227"]], "c": "3641875976"}, "book-100", "XBT/USD"]
[270, {"a": [["11869.90000", "0.01800000", "1596737130.419596"]], "c": "3641875976"}, "book-100", "XBT/USD"]
[270, {"b": [["11843.20000", "0.14528646", "1596737130.431525"]], "c": "3641875976"}, "book-100", "XBT/USD"]
[270, {"b": [["11847.80000", "0.47908117", "1596737130.432597"]], "c": "3641875976"}, "book-100", "XBT/USD"]
[270, {"a": [["11864.80000", "0.84289394", "1596737130.433658"]], "c": "4091719449"}, "book-100", "XBT/USD"]
[270, {"a": [["11879.90000", "0.56971564", "1596737130.438094"]], "c": "4091719449"}, "book-100", "XBT/USD"]
[270, {"b": [["11838.40000", "6.38000000", "1596737130.482128"]], "c": "4091719449"}, "book-100", "XBT/USD"]
[270, {"a": [["11863.20000", "7.72423697", "1596737130.485501"]], "c": "2375455861"}, "book-100", "XBT/USD"]
[270, {"a": [["11873.10000", "0.02101587", "1596737130.486333"]], "c": "2375455861"}, "book-100", "XBT/USD"]
[270, {"a": [["11878.10000", "0.00000000", "1596737130.488432"], ["11907.90000", "2.38150000", "1596736895.960018", "r"]], "c": "2375455861"}, "book-100", "XBT/USD"]
[270, {"b": [["11843.10000", "0.00000000", "1596737130.492052"], ["11766.40000", "3.29928524", "1596737121.846223", "r"]], "c": "2375455861"}, "book-100", "XBT/USD"]
[270, {"b": [["11806.30000", "6.15800000", "1596737130.496508"]], "c": "2375455861"}, "book-100", "XBT/USD"]
[270, {"a": [["11884.40000", "0.00000000", "1596737130.508991"], ["11908.90000", "1.06880000", "1596736841.521829", "r"]], "c": "2375455861"}, "book-100", "XBT/USD"]
[270, {"b": [["11803.70000", "0.00000000", "1596737130.509045"], ["11763.00000", "0.00842254", "1596736532.316006", "r"]], "c": "2375455861"}, "book-100", "XBT/USD"]
[270, {"a": [["11870.40000", "0.38500000", "1596737130.516616"]], "c": "2375455861"}, "book-100", "XBT/USD"]
[270, {"b": [["11843.20000", "0.16828646", "1596737130.526326"]], "c": "2375455861"}, "book-100", "XBT/USD"]
[270, {"b": [["11847.40000", "0.00000000", "1596737130.529668"], ["11760.00000", "0.04711202", "1596735559.775481", "r"]], "c": "2375455861"}, "book-100", "XBT/USD"]
[270, {"b": [["11792.50000", "5.30000000", "1596737130.530368"]], "c": "2375455861"}, "book-100", "XBT/USD"]
[270, {"a": [["11863.20000", "7.47423697", "1596737130.531801"]], "c": "2689252459"}, "book-100", "XBT/USD"]
[270, {"b": [["11848.10000", "0.10100000", "1596737130.536970"]], "c": "2689252459"}, "book-100", "XBT/USD"]
[270, {"a": [["11863.20000", "7.62374111", "1596737130.541167"]], "c": "2086561211"}, "book-100", "XBT/USD"]
[270, {"a": [["11863.20000", "7.83627245", "1596737130.555324"]], "c": "2323204847"}, "book-100", "XBT/USD"]
[270, {"b": [["11832.70000", "1.06194709", "1596737130.555763"]], "c": "2323204847"}, "book-100", "XBT/USD"]
[270, {"b": [["11823.30000", "1.59418708", "1596737130.556641"]], "c": "2323204847"}, "book-100", "XBT/USD"]
[270, {"a": [["11863.20000", "8.14332665", "1596737130.571908"]], "c": "3308009837"}, "book-100", "XBT/USD"]
[270, {"b": [["11821.50000", "0.00000000", "1596737130.575883"], ["11766.90000", "0.95277495", "1596737097.210623", "r"]], "c": "3308009837"}, "book-100", "XBT/USD"]
[270, {"b": [["11843.20000", "0.06828646", "1596737130.578626"]], "c": "3308009837"}, "book-100", "XBT/USD"]
[270, {"b": [["11837.40000", "0.28671987", "1596737130.585833"]], "c": "3308009837"}, "book-100", "XBT/USD"]
[270, {"b": [["11832.70000", "1.53317397", "1596737130.587886"]], "c": "3308009837"}, "book-100", "XBT/USD"]
[270, {"b": [["11841.00000", "0.20473764", "1596737130.598192"]], "c": "3308009837"}, "book-100", "XBT/USD"]
[270, {"b": [["11839.30000", "0.68090000", "1596737130.609768"]], "c": "3308009837"}, "book-100", "XBT/USD"]
[270, {"a": [["11863.20000", "8.51968143", "1596737130.614497"]], "c": "2011082137"}, "book-100", "XBT/USD"]
[270, {"a": [["11863.20000", "8.65083407", "1596737130.615715"]], "c": "2472920479"}, "book-100", "XBT/USD"]
[270, {"a": [["11863.20000", "9.06557230", "1596737130.617638"]], "c": "1642611443"}, "book-100", "XBT/USD"]
[270, {"b": [["11843.00000", "0.10000000", "1596737130.625969"]], "c": "1642611443"}, "book-100", "XBT/USD"]
[270, {"b": [["11806.40000", "4.23499119", "1596737130.639710"]], "c": "1642611443"}, "book-100", "XBT/USD"]
[270, {"b": [["11835.00000", "1.29115695", "1596737130.663660"]], "c": "1642611443"}, "book-100", "XBT/USD"]
[270, {"b": [["11843.30000", "0.10942385", "1596737130.674167"]], "c": "1642611443"}, "book-100", "XBT/USD"]
[270, {"a": [["11863.20000", "9.70754324", "1596737130.703750"]], "c": "1695544102"}, "book-100", "XBT/USD"]
[270, {"b": [["11843.00000", "0.00000000", "1596737130.753457"], ["11775.00000", "0.92000000", "1596736031.317852", "r"]], "c": "1695544102"}, "book-100", "XBT/USD"]
[270, {"a": [["11869.00000", "0.18315000", "1596737130.774042"]], "c": "1695544102"}, "book-100", "XBT/USD"]
[270, {"a": [["11867.50000", "0.67897394", "1596737130.787602"]], "c": "1695544102"}, "book-100", "XBT/USD"]
[270, {"a": [["11870.10000", "0.27100000", "1596737130.793490"]], "c": "1695544102"}, "book-100", "XBT/USD"]
[270, {"b": [["11843.40000", "0.10000000", "1596737130.820740"]], "c": "1695544102"}, "book-100", "XBT/USD"]
[270, {"a": [["11879.90000", "0.01000000", "1596737130.827013"]], "c": "1695544102"}, "book-100", "XBT/USD"]
[270, {"a": [["11869.00000", "6.78315000", "1596737130.882754"]], "c": "1695544102"}, "book-100", "XBT/USD"]
[270, {"b": [["11848.50000", "3.84688219", "1596737130.892660"]], "c": "1695544102"}, "book-100", "XBT/USD"]
[270, {"a": [["11873.10000", "0.04203173", "1596737130.916466"]], "c": "1695544102"}, "book-100", "XBT/USD"]
[270, {"a": [["11873.10000", "0.02101586", "1596737130.916985"]], "c": "1695544102"}, "book-100", "XBT/USD"]
[270, {"b": [["11811.80000", "0.00000000", "1596737130.923785"], ["11775.00000", "0.92000000", "1596736031.317852", "r"]], "c": "1695544102"}, "book-100", "XBT/USD"]
[270, {"a": [["11865.80000", "0.00000000", "1596737130.927076"], ["11907.20000", "6.18638192", "1596736972.522950", "r"]], "c": "3568372342"}, "book-100", "XBT/USD"]
[270, {"a": [["11863.20000", "11.38054324", "1596737130.929457"]], "c": "2885453903"}, "book-100", "XBT/USD"]
[270, {"b": [["11808.80000", "4.87064206", "1596737130.937069"]], "c": "2885453903"}, "book-100", "XBT/USD"]
[270, {"a": [["11871.90000", "0.10300000", "1596737130.939331"]], "c": "2885453903"}, "book-100", "XBT/USD"]
[270, {"b": [["11848.80000", "0.10000000", "1596737130.941070"]], "c": "2885453903"}, "book-100", "XBT/USD"]
[270, {"a": [["11901.80000", "0.75800000", "1596737130.968842"]], "c": "2885453903"}, "book-100", "XBT/USD"]
[270, {"a": [["11878.10000", "0.52180428", "1596737131.014606"]], "c": "2885453903"}, "book-100", "XBT/USD"]
[270, {"b": [["11799.00000", "0.00000000", "1596737131.041515"], ["11775.00000", "0.92000000", "1596736031.317852", "r"]], "c": "2885453903"}, "book-100", "XBT/USD"]
[270, {"b": [["11851.80000", "0.00000000", "1596737131.090652"], ["11772.90000", "2.20375182", "1596737056.454079", "r"]], "c": "665139447"}, "book-100", "XBT/USD"]
[270, {"b": [["11835.00000", "1.28115695", "1596737131.137737"]], "c": "665139447"}, "book-100", "XBT/USD"]
[270, {"b": [["11853.90000", "0.00000000", "1596737131.177783"], ["11769.00000", "3.73835290", "1596736631.449390", "r"]], "c": "3258381531"}, "book-100", "XBT/USD"]
[270, {"b": [["11851.10000", "0.00000000", "1596737131.198762"], ["11768.80000", "1.67000789", "1596736630.663519", "r"]], "c": "1181830333"}, "book-100", "XBT/USD"]
[270, {"a": [["11874.00000", "0.00000000", "1596737131.230155"], ["11906.00000", "0.05458243", "1596736960.945412", "r"]], "c": "1181830333"}, "book-100", "XBT/USD"]
[270, {"a": [["11863.20000", "12.22366430", "1596737131.244674"]], "c": "778430916"}, "book-100", "XBT/USD"]
[270, {"a": [["11863.30000", "1.54318111", "1596737131.244942"]], "c": "2458070364"}, "book-100", "XBT/USD"]
[270, {"b": [["11849.40000", "0.33731021", "1596737131.245325"]], "c": "3719854055"}, "book-100", "XBT/USD"]
[270, {"a": [["11863.50000", "0.63215226", "1596737131.246924"]], "c": "1210918085"}, "book-100", "XBT/USD"]
[270, {"b": [["11852.00000", "0.33722492", "1596737131.247077"]], "c": "1863799556"}, "book-100", "XBT/USD"]
[270, {"b": [["11840.30000", "0.33727244", "1596737131.249895"]], "c": "1863799556"}, "book-100", "XBT/USD"]
[270, {"b": [["11842.70000", "0.33720572", "1596737131.250286"]], "c": "1863799556"}, "book-100", "XBT/USD"]
[270, {"a": [["11863.60000", "0.84306230", "1596737131.250409"]], "c": "3835186887"}, "book-100", "XBT/USD"]
[270, {"a": [["11864.70000", "0.84286968", "1596737131.259312"]], "c": "3396066455"}, "book-100", "XBT/USD"]
[270, {"b": [["11846.10000", "0.00000000", "1596737131.284091"], ["11775.00000", "0.92000000", "1596736031.317852", "r"]], "c": "3396066455"}, "book-100", "XBT/USD"]
[270, {"a": [["11866.40000", "0.28399999", "1596737131.285660"]], "c": "3396066455"}, "book-100", "XBT/USD"]
[270, {"a": [["11867.50000", "0.00000000", "1596737131.290111"], ["11904.00000", "0.17065000", "1596737071.292235", "r"]], "c": "3396066455"}, "book-100", "XBT/USD"]
[270, {"a": [["11863.30000", "0.84318111", "1596737131.292864"]], "c": "3631638671"}, "book-100", "XBT/USD"]
[270, {"b": [["11848.70000", "0.00000000", "1596737131.299307"], ["11772.90000", "2.20375182", "1596737056.454079", "r"]], "c": "3631638671"}, "book-100", "XBT/USD"]
[270, {"b": [["11846.20000", "0.00000000", "1596737131.301995"], ["11769.00000", "3.73835290", "1596736631.449390", "r"]], "c": "3631638671"}, "book-100", "XBT/USD"]
[270, {"b": [["11839.00000", "0.33729003", "1596737131.315594"]], "c": "3631638671"}, "book-100", "XBT/USD"]
[270, {"a": [["11863.20000", "12.92366430", "1596737131.345264"]], "c": "716249830"}, "book-100", "XBT/USD"]
[270, {"b": [["11848.80000", "0.00000000", "1596737131.350099"], ["11769.00000", "3.73835290", "1596736631.449390", "r"]], "c": "1138791349"}, "book-100", "XBT/USD"]
[270, {"b": [["11840.30000", "0.00000000", "1596737131.361374"], ["11768.80000", "1.67000789", "1596736630.663519", "r"]], "c": "1138791349"}, "book-100", "XBT/USD"]
[270, {"b": [["11842.70000", "0.00000000", "1596737131.387843"], ["11768.20000", "0.03400000", "1596737130.244561", "r"]], "c": "1138791349"}, "book-100", "XBT/USD"]
[270, {"b": [["11854.50000", "0.00000000", "1596737131.389698"], ["11766.90000", "0.95277495", "1596737097.210623", "r"]], "c": "1099678563"}, "book-100", "XBT/USD"]
[270, {"a": [["11863.20000", "12.30190022", "1596737131.390209"]], "c": "2838553498"}, "book-100", "XBT/USD"]
[270, {"b": [["11848.60000", "0.10000000", "1596737131.398388"]], "c": "577040615"}, "book-100", "XBT/USD"]
[270, {"b": [["11847.00000", "0.46600000", "1596737131.398651"]], "c": "577040615"}, "book-100", "XBT/USD"]
[270, {"b": [["11845.30000", "0.00000000", "1596737131.410643"], ["11768.20000", "0.03400000", "1596737130.244561", "r"]], "c": "577040615"}, "book-100", "XBT/USD"]
[270, {"a": [["11880.30000", "0.00000000", "1596737131.412226"], ["11904.60000", "0.02329731", "1596737116.563077", "r"]], "c": "577040615"}, "book-100", "XBT/USD"]
[270, {"b": [["11839.20000", "0.98550000", "1596737131.412344"]], "c": "577040615"}, "book-100", "XBT/USD"]
[270, {"b": [["11845.40000", "0.25494312", "1596737131.437589"]], "c": "577040615"}, "book-100", "XBT/USD"]
[270, {"a": [["11875.10000", "0.00000000", "1596737131.454906"], ["11905.00000", "27.00000000", "1596736856.739074", "r"]], "c": "577040615"}, "book-100", "XBT/USD"]
[270, {"b": [["11854.60000", "0.00000000", "1596737131.482967"], ["11768.80000", "1.67000789", "1596736630.663519", "r"]], "c": "1547975048"}, "book-100", "XBT/USD"]
[270, {"b": [["11853.70000", "0.00000000", "1596737131.527627"], ["11768.20000", "0.03400000", "1596737130.244561", "r"]], "c": "2611599315"}, "book-100", "XBT/USD"]
[270, {"b": [["11832.00000", "0.01000000", "1596737131.552439"]], "c": "2611599315"}, "book-100", "XBT/USD"]
[270, {"b": [["11849.50000", "0.00703629", "1596737131.563894"]], "c": "2238027356"}, "book-100", "XBT/USD"]
[270, {"b": [["11847.80000", "0.45907621", "1596737131.565679"]], "c": "2238027356"}, "book-100", "XBT/USD"]
[270, {"b": [["11839.00000", "0.00000000", "1596737131.599301"], ["11768.80000", "1.67000789", "1596736630.663519", "r"]], "c": "2238027356"}, "book-100", "XBT/USD"]
[270, {"b": [["11796.00000", "0.00000000", "1596737131.603302"], ["11768.20000", "0.03400000", "1596737130.244561", "r"]], "c": "2238027356"}, "book-100", "XBT/USD"]
[270, {"b": [["11845.40000", "0.00000000", "1596737131.656702"], ["11766.90000", "0.95277495", "1596737097.210623", "r"]], "c": "2238027356"}, "book-100", "XBT/USD"]
[270, {"a": [["11885.80000", "0.00000000", "1596737131.666364"], ["11906.00000", "0.05458243", "1596736960.945412", "r"]], "c": "2238027356"}, "book-100", "XBT/USD"]
[270, {"a": [["11864.90000", "4.83658037", "1596737131.670035"]], "c": "2238027356"}, "book-100", "XBT/USD"]
[270, {"b": [["11850.70000", "0.10000000", "1596737131.676550"]], "c": "3368929862"}, "book-100", "XBT/USD"]
[270, {"b": [["11853.10000", "1.67300000", "1596737131.733031"]], "c": "1936150355"}, "book-100", "XBT/USD"]
[270, {"b": [["11858.10000", "0.00000000", "1596737131.784320"], ["11768.20000", "0.03400000", "1596737130.244561", "r"]], "c": "2394486359"}, "book-100", "XBT/USD"]
[270, {"a": [["11864.80000", "1.50533311", "1596737131.797605"]], "c": "3412113725"}, "book-100", "XBT/USD"]
[270, {"b": [["11848.50000", "3.75067125", "1596737131.855508"]], "c": "2782940350"}, "book-100", "XBT/USD"]
[270, {"b": [["11842.90000", "0.00000000", "1596737131.872354"], ["11766.90000", "0.95277495", "1596737097.210623", "r"]], "c": "2782940350"}, "book-100", "XBT/USD"]
[270, {"b": [["11838.50000", "0.25509171", "1596737131.885112"]], "c": "2782940350"}, "book-100", "XBT/USD"]
[270, {"b": [["11835.70000", "0.23800000", "1596737131.902729"]], "c": "2782940350"}, "book-100", "XBT/USD"]
[270, {"b": [["11781.00000", "0.27065000", "1596737131.905668"]], "c": "2782940350"}, "book-100", "XBT/USD"]
[270, {"a": [["11865.90000", "1.04962971", "1596737131.947564"]], "c": "2782940350"}, "book-100", "XBT/USD"]
[270, {"b": [["11827.10000", "0.00000000", "1596737131.972407"], ["11768.20000", "0.03400000", "1596737130.244561", "r"]], "c": "2782940350"}, "book-100", "XBT/USD"]
[270, {"b": [["11816.60000", "0.75800000", "1596737131.973322"]], "c": "2782940350"}, "book-100", "XBT/USD"]
[270, {"a": [["11864.90000", "4.21100000", "1596737131.980262"]], "c": "2782940350"}, "book-100", "XBT/USD"]
[270, {"a": [["11892.00000", "6.63990117", "1596737132.064311"]], "c": "2782940350"}, "book-100", "XBT/USD"]
[270, {"b": [["11848.70000", "0.27100000", "1596737132.177244"]], "c": "3957515304"}, "book-100", "XBT/USD"]
[270, {"b": [["11842.80000", "0.00000000", "1596737132.179656"], ["11768.80000", "1.67000789", "1596736630.663519", "r"]], "c": "3957515304"}, "book-100", "XBT/USD"]
[270, {"a": [["11864.10000", "0.62937882", "1596737132.199657"]], "c": "1403116237"}, "book-100", "XBT/USD"]
[270, {"b": [["11840.90000", "0.76612223", "1596737132.244428"]], "c": "1403116237"}, "book-100", "XBT/USD"]
[270, {"b": [["11852.00000", "0.00000000", "1596737132.255903"], ["11768.80000", "1.67000789", "1596736630.663519", "r"]], "c": "3316422532"}, "book-100", "XBT/USD"]
[270, {"b": [["11848.60000", "0.00000000", "1596737132.260853"], ["11768.20000", "0.03400000", "1596737130.244561", "r"]], "c": "3182629868"}, "book-100", "XBT/USD"]
[270, {"b": [["11811.50000", "13.69455344", "1596737132.288787"]], "c": "3182629868"}, "book-100", "XBT/USD"]
[270, {"b": [["11827.80000", "4.87488003", "1596737132.296854"]], "c": "3182629868"}, "book-100", "XBT/USD"]
[270, {"b": [["11841.00000", "0.00000000", "1596737132.297365"], ["11768.20000", "0.03400000", "1596737130.244561", "r"]], "c": "3182629868"}, "book-100", "XBT/USD"]
[270, {"b": [["11843.20000", "0.02300000", "1596737132.303045"]], "c": "3182629868"}, "book-100", "XBT/USD"]
[270, {"a": [["11893.00000", "0.00000000", "1596737132.303338"], ["11905.00000", "27.00000000", "1596736856.739074", "r"]], "c": "3182629868"}, "book-100", "XBT/USD"]
[270, {"b": [["11827.00000", "1.02440000", "1596737132.308766"]], "c": "3182629868"}, "book-100", "XBT/USD"]
[270, {"b": [["11827.80000", "2.74942760", "1596737132.311695"]], "c": "3182629868"}, "book-100", "XBT/USD"]
[270, {"a": [["11871.90000", "0.00000000", "1596737132.312711"], ["11906.00000", "0.05458243", "1596736960.945412", "r"]], "c": "3182629868"}, "book-100", "XBT/USD"]
[270, {"b": [["11827.80000", "0.00000000", "1596737132.313202"], ["11766.90000", "0.95277495", "1596737097.210623", "r"]], "c": "3182629868"}, "book-100", "XBT/USD"]
[270, {"a": [["11881.80000", "0.00000000", "1596737132.315242"], ["11907.00000", "8.54095785", "1596737002.155356", "r"]], "c": "3182629868"}, "book-100", "XBT/USD"]
[270, {"b": [["11836.20000", "0.05224265", "1596737132.324849"]], "c": "3182629868"}, "book-100", "XBT/USD"]
[270, {"b": [["11827.70000", "0.00000000", "1596737132.325318"], ["11766.40000", "3.29928524", "1596737121.846223", "r"]], "c": "3182629868"}, "book-100", "XBT/USD"]
[270, {"b": [["11843.30000", "0.00000000", "1596737132.333975"], ["11760.00000", "0.04711202", "1596735559.775481", "r"]], "c": "3182629868"}, "book-100", "XBT/USD"]
[270, {"a": [["11863.20000", "12.38619486", "1596737132.346216"]], "c": "2215092520"}, "book-100", "XBT/USD"]
[270, {"b": [["11852.30000", "0.00000000", "1596737132.351622"], ["11758.90000", "0.01000000", "1596736714.822612", "r"]], "c": "1367303182"}, "book-100", "XBT/USD"]
[270, {"b": [["11848.10000", "0.00000000", "1596737132.358861"], ["11757.00000", "0.30000000", "1596735176.682759", "r"]], "c": "4203387644"}, "book-100", "XBT/USD"]
[270, {"b": [["11813.30000", "0.00000000", "1596737132.371509"], ["11756.50000", "0.01696933", "1596734978.916212", "r"]], "c": "4203387644"}, "book-100", "XBT/USD"]
[270, {"b": [["11838.30000", "0.00000000", "1596737132.380828"], ["11756.00000", "0.10000000", "1596736706.773914", "r"]], "c": "4203387644"}, "book-100", "XBT/USD"]
[270, {"b": [["11844.90000", "2.87318822", "1596737132.383834"]], "c": "4203387644"}, "book-100", "XBT/USD"]
[270, {"b": [["11826.00000", "0.00000000", "1596737132.393778"], ["11756.00000", "0.10000000", "1596736706.773914", "r"]], "c": "4203387644"}, "book-100", "XBT/USD"]
[270, {"b": [["11827.90000", "0.00000000", "1596737132.399102"], ["11755.00000", "0.66169495", "1596736658.758080", "r"]], "c": "4203387644"}, "book-100", "XBT/USD"]
[270, {"b": [["11845.40000", "0.09621094", "1596737132.399712"]], "c": "4203387644"}, "book-100", "XBT/USD"]
[270, {"b": [["11834.20000", "0.04567701", "1596737132.402863"]], "c": "4203387644"}, "book-100", "XBT/USD"]
[270, {"b": [["11847.80000", "0.00000000", "1596737132.411664"], ["11756.00000", "0.10000000", "1596736706.773914", "r"]], "c": "1939437877"}, "book-100", "XBT/USD"]
[270, {"a": [["11878.10000", "0.00000000", "1596737132.427320"], ["11907.20000", "6.18638192", "1596736972.522950", "r"]], "c": "1939437877"}, "book-100", "XBT/USD"]
[270, {"a": [["11867.70000", "0.82000000", "1596737132.428700"]], "c": "1939437877"}, "book-100", "XBT/USD"]
[270, {"b": [["11843.40000", "0.00000000", "1596737132.438145"], ["11755.00000", "0.66169495", "1596736658.758080", "r"]], "c": "1939437877"}, "book-100", "XBT/USD"]
[271, [["11863.10000", "0.10000000", "1596737132.440005", "s", "l", ""]], "trade", "XBT/USD"]
[270, {"b": [["11863.10000", "0.08000000", "1596737132.440005"]], "c": "1853292168"}, "book-100", "XBT/USD"]
[270, {"a": [["11864.50000", "3.39549677", "1596737132.453016"]], "c": "3120294914"}, "book-100", "XBT/USD"]
[270, {"a": [["11874.50000", "1.91626822", "1596737132.464726"]], "c": "3120294914"}, "book-100", "XBT/USD"]
[270, {"b": [["11836.20000", "0.00000000", "1596737132.477247"], ["11751.00000", "1.00000000", "1596736642.630238", "r"]], "c": "3120294914"}, "book-100", "XBT/USD"]
[270, {"b": [["11817.50000", "5.16980198", "1596737132.479431"]], "c": "3120294914"}, "book-100", "XBT/USD"]
[270, {"b": [["11834.50000", "0.10600000", "1596737132.510617"]], "c": "3120294914"}, "book-100", "XBT/USD"]
[270, {"a": [["11863.20000", "11.88619486", "1596737132.512942"]], "c": "2530902194"}, "book-100", "XBT/USD"]
[270, {"b": [["11838.10000", "0.09700000", "1596737132.548803"]], "c": "2530902194"}, "book-100", "XBT/USD"]
[270, {"a": [["11891.90000", "0.00000000", "1596737132.548942"], ["11907.00000", "8.54095785", "1596737002.155356", "r"]], "c": "2530902194"}, "book-100", "XBT/USD"]
[270, {"a": [["11867.20000", "0.00000000", "1596737132.558760"], ["11907.20000", "6.18638192", "1596736972.522950", "r"]], "c": "2530902194"}, "book-100", "XBT/USD"]
[270, {"b": [["11828.30000", "0.00000000", "1596737132.559059"], ["11756.00000", "0.10000000", "1596736706.773914", "r"]], "c": "2530902194"}, "book-100", "XBT/USD"]
[270, {"b": [["11848.50000", "0.24913765", "1596737132.562330"]], "c": "1180418092"}, "book-100", "XBT/USD"]
[270, {"a": [["11873.10000", "5.63870064", "1596737132.562838"]], "c": "1180418092"}, "book-100", "XBT/USD"]
[270, {"b": [["11849.40000", "0.00000000", "1596737132.568868"], ["11755.00000", "0.66169495", "1596736658.758080", "r"]], "c": "894857361"}, "book-100", "XBT/USD"]
[270, {"b": [["11849.50000", "0.00000000", "1596737132.568978"], ["11751.00000", "1.00000000", "1596736642.630238", "r"]], "c": "3576958005"}, "book-100", "XBT/USD"]
[270, {"a": [["11875.00000", "0.00000000", "1596737132.569604"], ["11907.90000", "2.38150000", "1596736895.960018", "r"]], "c": "3576958005"}, "book-100", "XBT/USD"]
[270, {"b": [["11847.10000", "0.01379563", "1596737132.583739"]], "c": "1054351139"}, "book-100", "XBT/USD"]
[270, {"b": [["11842.70000", "0.33008393", "1596737132.611372"]], "c": "1054351139"}, "book-100", "XBT/USD"]
[270, {"b": [["11839.50000", "0.00000000", "1596737132.614994"], ["11755.00000", "0.66169495", "1596736658.758080", "r"]], "c": "1054351139"}, "book-100", "XBT/USD"]
[270, {"b": [["11839.30000", "1.37427531", "1596737132.615682"]], "c": "1054351139"}, "book-100", "XBT/USD"]
[270, {"b": [["11836.90000", "1.38703180", "1596737132.622174"]], "c": "1054351139"}, "book-100", "XBT/USD"]
[270, {"a": [["11881.30000", "0.69092426", "1596737132.623378"]], "c": "1054351139"}, "book-100", "XBT/USD"]
[270, {"b": [["11831.00000", "1.75117489", "1596737132.625924"]], "c": "1054351139"}, "book-100", "XBT/USD"]
[270, {"a": [["11888.80000", "0.00000000", "1596737132.663209"], ["11907.90000", "2.38150000", "1596736895.960018", "r"]], "c": "1054351139"}, "book-100", "XBT/USD"]
[270, {"b": [["11841.80000", "0.00000000", "1596737132.680188"], ["11756.00000", "0.10000000", "1596736706.773914", "r"]], "c": "1054351139"}, "book-100", "XBT/USD"]
[270, {"a": [["11868.00000", "10.00000000", "1596737132.702739"]], "c": "1054351139"}, "book-100", "XBT/USD"]
[270, {"a": [["11863.20000", "11.98619486", "1596737132.709675"]], "c": "1192679810"}, "book-100", "XBT/USD"]
[270, {"b": [["11794.00000", "1.01250000", "1596737132.711374"]], "c": "1192679810"}, "book-100", "XBT/USD"]
[270, {"b": [["11850.70000", "0.00000000", "1596737132.711441"], ["11756.00000", "0.10000000", "1596736706.773914", "r"]], "c": "3415712402"}, "book-100", "XBT/USD"]
[270, {"b": [["11787.80000", "6.80000000", "1596737132.726658"]], "c": "3415712402"}, "book-100", "XBT/USD"]
[270, {"a": [["11886.90000", "2.15227709", "1596737132.728692"]], "c": "3415712402"}, "book-100", "XBT/USD"]
[270, {"a": [["11874.40000", "0.46822470", "1596737132.729090"]], "c": "3415712402"}, "book-100", "XBT/USD"]
[270, {"a": [["11867.90000", "0.00000000", "1596737132.747300"], ["11907.00000", "8.54095785", "1596737002.155356", "r"]], "c": "3415712402"}, "book-100", "XBT/USD"]
[271, [["11863.10000", "0.08000000", "1596737132.749922", "s", "l", ""]], "trade", "XBT/USD"]
[270, {"a": [["11863.00000", "0.42000000", "1596737132.749266"]]}, {"b": [["11863.10000", "0.00000000", "1596737132.749922"], ["11756.00000", "0.10000000", "1596736706.773914", "r"]], "c": "3430452072"}, "book-100", "XBT/USD"]
[270, {"b": [["11840.90000", "0.00000000", "1596737132.754891"], ["11755.00000", "0.66169495", "1596736658.758080", "r"]], "c": "3430452072"}, "book-100", "XBT/USD"]
[270, {"b": [["11862.50000", "0.00000000", "1596737132.760179"], ["11751.00000", "1.00000000", "1596736642.630238", "r"]], "c": "1840452743"}, "book-100", "XBT/USD"]
[270, {"b": [["11838.90000", "0.93815000", "1596737132.762023"]], "c": "1840452743"}, "book-100", "XBT/USD"]
[270, {"b": [["11793.00000", "0.00000000", "1596737132.762406"], ["11751.00000", "1.00000000", "1596736642.630238", "r"]], "c": "1840452743"}, "book-100", "XBT/USD"]
[270, {"a": [["11877.80000", "0.32910850", "1596737132.767919"]], "c": "1840452743"}, "book-100", "XBT/USD"]
[270, {"b": [["11806.40000", "0.00000000", "1596737132.768640"], ["11750.10000", "0.10000000", "1596737011.409348", "r"]], "c": "1840452743"}, "book-100", "XBT/USD"]
[270, {"b": [["11760.10000", "0.66000000", "1596737132.782239"]], "c": "1840452743"}, "book-100", "XBT/USD"]
[270, {"a": [["11899.10000", "1.64182626", "1596737132.791349"]], "c": "1840452743"}, "book-100", "XBT/USD"]
[270, {"a": [["11873.50000", "0.00936530", "1596737132.792361"]], "c": "1840452743"}, "book-100", "XBT/USD"]
[270, {"b": [["11821.50000", "0.94800870", "1596737132.793737"]], "c": "1840452743"}, "book-100", "XBT/USD"]
[270, {"b": [["11833.30000", "0.94706336", "1596737132.799743"]], "c": "1840452743"}, "book-100", "XBT/USD"]
[270, {"b": [["11819.20000", "1.91829334", "1596737132.807008"]], "c": "1840452743"}, "book-100", "XBT/USD"]
[270, {"a": [["11863.20000", "11.62763338", "1596737132.808019"]], "c": "1960474738"}, "book-100", "XBT/USD"]
[270, {"a": [["11862.60000", "0.50000000", "1596737132.808373"]], "c": "938171591"}, "book-100", "XBT/USD"]
[270, {"a": [["11863.10000", "0.25000000", "1596737132.811994"]], "c": "3353574123"}, "book-100", "XBT/USD"]
[270, {"a": [["11863.20000", "11.37763338", "1596737132.812122"]], "c": "1240504671"}, "book-100", "XBT/USD"]
[270, {"a": [["11864.80000", "0.84289394", "1596737132.813429"]], "c": "1240504671"}, "book-100", "XBT/USD"]
[270, {"a": [["11887.20000", "0.94276910", "1596737132.813876"]], "c": "1240504671"}, "book-100", "XBT/USD"]
[270, {"a": [["11863.00000", "0.00000000", "1596737132.815523"], ["11903.90000", "1.59024654", "1596737096.689627", "r"]], "c": "1861549957"}, "book-100", "XBT/USD"]
[270, {"b": [["11828.50000", "0.94744767", "1596737132.818607"]], "c": "1861549957"}, "book-100", "XBT/USD"]
[270, {"b": [["11807.50000", "4.65625153", "1596737132.819245"]], "c": "1861549957"}, "book-100", "XBT/USD"]
[270, {"b": [["11836.80000", "0.94678332", "1596737132.821505"]], "c": "1861549957"}, "book-100", "XBT/USD"]
[270, {"a": [["11863.20000", "10.97763338", "1596737132.821603"]], "c": "2171438015"}, "book-100", "XBT/USD"]
[270, {"a": [["11863.20000", "10.83619486", "1596737132.821905"]], "c": "2331042944"}, "book-100", "XBT/USD"]
[270, {"a": [["11863.20000", "10.61119486", "1596737132.823199"]], "c": "2643708239"}, "book-100", "XBT/USD"]
[270, {"b": [["11805.60000", "0.48180000", "1596737132.833035"]], "c": "2643708239"}, "book-100", "XBT/USD"]
[270, {"a": [["11868.00000", "0.00000000", "1596737132.833506"], ["11904.00000", "0.17065000", "1596737071.292235", "r"]], "c": "2643708239"}, "book-100", "XBT/USD"]
[270, {"a": [["11862.90000", "0.01975817", "1596737132.834621"]], "c": "1155660597"}, "book-100", "XBT/USD"]
[270, {"b": [["11838.40000", "0.38000000", "1596737132.843058"]], "c": "1155660597"}, "book-100", "XBT/USD"]
[270, {"a": [["11863.10000", "0.29750000", "1596737132.850694"]], "c": "3928374582"}, "book-100", "XBT/USD"]
[270, {"b": [["11820.00000", "0.00000000", "1596737132.852429"], ["11758.90000", "0.01000000", "1596736714.822612", "r"]], "c": "3928374582"}, "book-100", "XBT/USD"]
[270, {"b": [["11837.00000", "0.20486330", "1596737132.858212"]], "c": "3928374582"}, "book-100", "XBT/USD"]
[270, {"a": [["11866.90000", "0.00000000", "1596737132.867152"], ["11904.00000", "0.17065000", "1596737071.292235", "r"]], "c": "3928374582"}, "book-100", "XBT/USD"]
[270, {"b": [["11817.40000", "0.00000000", "1596737132.867685"], ["11758.90000", "0.01000000", "1596736714.822612", "r"]], "c": "3928374582"}, "book-100", "XBT/USD"]
[270, {"b": [["11807.60000", "0.96525494", "1596737132.867960"]], "c": "3928374582"}, "book-100", "XBT/USD"]
[270, {"a": [["11867.60000", "0.00000000", "1596737132.868429"], ["11904.60000", "0.02329731", "1596737116.563077", "r"]], "c": "3928374582"}, "book-100", "XBT/USD"]
[270, {"a": [["11869.80000", "0.09700000", "1596737132.869091"]], "c": "3928374582"}, "book-100", "XBT/USD"]
[270, {"a": [["11863.50000", "0.00000000", "1596737132.870986"], ["11905.00000", "27.00000000", "1596736856.739074", "r"]], "c": "2825189097"}, "book-100", "XBT/USD"]
[270, {"a": [["11863.20000", "10.51119486", "1596737132.877105"]], "c": "1923383534"}, "book-100", "XBT/USD"]
[270, {"a": [["11858.90000", "0.40000000", "1596737132.879236"]], "c": "2102695635"}, "book-100", "XBT/USD"]
[270, {"b": [["11845.40000", "0.00000000", "1596737132.879445"], ["11758.90000", "0.01000000", "1596736714.822612", "r"]], "c": "810836948"}, "book-100", "XBT/USD"]
[270, {"b": [["11853.10000", "0.00000000", "1596737132.882627"], ["11757.00000", "0.30000000", "1596735176.682759", "r"]], "c": "2411426119"}, "book-100", "XBT/USD"]
[270, {"a": [["11869.80000", "0.00000000", "1596737132.886412"], ["11905.00000", "27.00000000", "1596736856.739074", "r"]], "c": "2411426119"}, "book-100", "XBT/USD"]
[270, {"b": [["11845.00000", "0.05140000", "1596737132.888394"]], "c": "2804653617"}, "book-100", "XBT/USD"]
[270, {"b": [["11839.30000", "1.84401268", "1596737132.895555"]], "c": "921807573"}, "book-100", "XBT/USD"]
[270, {"b": [["11825.20000", "3.79363871", "1596737132.900065"]], "c": "921807573"}, "book-100", "XBT/USD"]
[270, {"a": [["11862.90000", "0.71637778", "1596737132.902340"]], "c": "3945983404"}, "book-100", "XBT/USD"]
[270, {"a": [["11863.30000", "0.00000000", "1596737132.903931"], ["11906.00000", "0.05458243", "1596736960.945412", "r"]], "c": "2666464617"}, "book-100", "XBT/USD"]
[270, {"a": [["11876.40000", "0.00000000", "1596737132.913355"], ["11907.00000", "8.54095785", "1596737002.155356", "r"]], "c": "2666464617"}, "book-100", "XBT/USD"]
[270, {"a": [["11870.20000", "0.00000000", "1596737132.914660"], ["11907.20000", "6.18638192", "1596736972.522950", "r"]], "c": "2666464617"}, "book-100", "XBT/USD"]
[270, {"a": [["11862.60000", "0.72500000", "1596737132.914919"]], "c": "3464431383"}, "book-100", "XBT/USD"]
[270, {"b": [["11831.00000", "3.94370463", "1596737132.918083"]], "c": "3464431383"}, "book-100", "XBT/USD"]
[270, {"b": [["11790.00000", "0.24750000", "1596737132.922523"]], "c": "3464431383"}, "book-100", "XBT/USD"]
[270, {"a": [["11863.20000", "10.49143670", "1596737132.925819"]], "c": "122453187"}, "book-100", "XBT/USD"]
[270, {"a": [["11863.20000", "9.99143670", "1596737132.926235"]], "c": "1590486517"}, "book-100", "XBT/USD"]
[270, {"a": [["11863.70000", "2.41958290", "1596737132.926416"]], "c": "2561698768"}, "book-100", "XBT/USD"]
[270, {"b": [["11813.40000", "2.19579625", "1596737132.926897"]], "c": "2561698768"}, "book-100", "XBT/USD"]
[270, {"b": [["11807.60000", "3.71309573", "1596737132.934415"]], "c": "2561698768"}, "book-100", "XBT/USD"]
[270, {"a": [["11863.20000", "9.49143670", "1596737132.936530"]], "c": "3006690330"}, "book-100", "XBT/USD"]
[270, {"b": [["11850.00000", "0.40000000", "1596737132.938622"]], "c": "696387847"}, "book-100", "XBT/USD"]
[270, {"a": [["11863.20000", "8.82859859", "1596737132.952419"]], "c": "3613704826"}, "book-100", "XBT/USD"]
[270, {"b": [["11802.10000", "4.23653417", "1596737132.953878"]], "c": "3613704826"}, "book-100", "XBT/USD"]
[270, {"a": [["11863.20000", "8.15859859", "1596737132.954121"]], "c": "2951054764"}, "book-100", "XBT/USD"]
[270, {"a": [["11863.20000", "7.51662765", "1596737132.956997"]], "c": "777448552"}, "book-100", "XBT/USD"]
[270, {"a": [["11858.50000", "0.15000000", "1596737132.959640"]], "c": "3294192279"}, "book-100", "XBT/USD"]
[270, {"a": [["11863.20000", "7.30409631", "1596737132.960453"]], "c": "2933287913"}, "book-100", "XBT/USD"]
[270, {"a": [["11863.20000", "7.15459217", "1596737132.967261"]], "c": "3485956621"}, "book-100", "XBT/USD"]
[270, {"a": [["11862.10000", "2.00000000", "1596737132.970326"]], "c": "1135901823"}, "book-100", "XBT/USD"]
[270, {"a": [["11854.50000", "0.25000000", "1596737132.977829"]], "c": "1740262011"}, "book-100", "XBT/USD"]
[270, {"a": [["11864.90000", "0.00000000", "1596737132.980971"], ["11906.00000", "0.05458243", "1596736960.945412", "r"]], "c": "1740262011"}, "book-100", "XBT/USD"]
[270, {"a": [["11863.70000", "2.00000000", "1596737132.991204"]], "c": "1740262011"}, "book-100", "XBT/USD"]
[270, {"a": [["11863.20000", "6.73985394", "1596737132.993099"]], "c": "2168379963"}, "book-100", "XBT/USD"]
[270, {"a": [["11863.20000", "6.43279974", "1596737132.993378"]], "c": "1548273780"}, "book-100", "XBT/USD"]
[270, {"a": [["11862.60000", "0.82500000", "1596737132.997074"]], "c": "3025300406"}, "book-100", "XBT/USD"]
[270, {"a": [["11863.20000", "6.05644496", "1596737132.999883"]], "c": "4010567078"}, "book-100", "XBT/USD"]
[270, {"a": [["11858.90000", "0.00000000", "1596737133.003757"], ["11907.00000", "8.54095785", "1596737002.155356", "r"]]}, {"b": [["11850.00000", "0.00000000", "1596737133.003768"], ["11760.10000", "0.66000000", "1596737132.782239", "r"]], "c": "3332248266"}, "book-100", "XBT/USD"]
[270, {"a": [["11862.60000", "0.60000000", "1596737133.004580"]], "c": "626192386"}, "book-100", "XBT/USD"]
[270, {"b": [["11836.60000", "0.76640054", "1596737133.009766"]], "c": "626192386"}, "book-100", "XBT/USD"]
[270, {"a": [["11858.80000", "0.01975816", "1596737133.010862"]], "c": "1189177212"}, "book-100", "XBT/USD"]
[270, {"a": [["11863.20000", "5.63456834", "1596737133.012922"]], "c": "3429479066"}, "book-100", "XBT/USD"]
[270, {"a": [["11864.80000", "0.00000000", "1596737133.022101"], ["11907.00000", "8.54095785", "1596737002.155356", "r"]], "c": "3429479066"}, "book-100", "XBT/USD"]
[270, {"a": [["11863.20000", "5.50341570", "1596737133.022162"]], "c": "995335018"}, "book-100", "XBT/USD"]
[270, {"a": [["11858.40000", "0.84200000", "1596737133.025920"]], "c": "737626018"}, "book-100", "XBT/USD"]
[270, {"a": [["11862.50000", "0.50000000", "1596737133.030904"]], "c": "533719383"}, "book-100", "XBT/USD"]
[270, {"a": [["11862.90000", "0.01975817", "1596737133.031476"]], "c": "147140140"}, "book-100", "XBT/USD"]
[270, {"b": [["11837.40000", "0.00000000", "1596737133.033353"], ["11760.10000", "0.66000000", "1596737132.782239", "r"]], "c": "147140140"}, "book-100", "XBT/USD"]
[270, {"a": [["11866.00000", "0.00000000", "1596737133.042060"], ["11906.00000", "0.05458243", "1596736960.945412", "r"]], "c": "147140140"}, "book-100", "XBT/USD"]
[270, {"a": [["11862.50000", "1.60000000", "1596737133.059955"]], "c": "1416825869"}, "book-100", "XBT/USD"]
[270, {"a": [["11869.70000", "0.21921367", "1596737133.084476"]], "c": "1416825869"}, "book-100", "XBT/USD"]
[270, {"b": [["11838.90000", "0.00000000", "1596737133.084851"], ["11760.00000", "0.04711202", "1596735559.775481", "r"]], "c": "1416825869"}, "book-100", "XBT/USD"]
[270, {"b": [["11824.10000", "0.00000000", "1596737133.094215"], ["11758.90000", "0.01000000", "1596736714.822612", "r"]], "c": "1416825869"}, "book-100", "XBT/USD"]
[270, {"a": [["11864.10000", "0.00000000", "1596737133.097532"], ["11906.40000", "0.47990000", "1596737133.044226", "r"]], "c": "1416825869"}, "book-100", "XBT/USD"]
[270, {"a": [["11858.90000", "0.94858000", "1596737133.112630"]], "c": "2964264379"}, "book-100", "XBT/USD"]
[270, {"a": [["11863.70000", "0.00000000", "1596737133.115285"], ["11906.40000", "0.47990000", "1596737133.044226", "r"]], "c": "2964264379"}, "book-100", "XBT/USD"]
[270, {"a": [["11854.50000", "0.00000000", "1596737133.128197"], ["11907.00000", "8.54095785", "1596737002.155356", "r"]], "c": "3109780403"}, "book-100", "XBT/USD"]
[270, {"a": [["11858.00000", "2.00000000", "1596737133.130094"]], "c": "1085695041"}, "book-100", "XBT/USD"]
[270, {"a": [["11867.70000", "0.00000000", "1596737133.148015"], ["11907.00000", "8.54095785", "1596737002.155356", "r"]], "c": "1085695041"}, "book-100", "XBT/USD"]
[270, {"a": [["11856.80000", "0.22500000", "1596737133.151777"]], "c": "3026797322"}, "book-100", "XBT/USD"]
[270, {"a": [["11863.20000", "3.83041570", "1596737133.153390"]], "c": "3026797322"}, "book-100", "XBT/USD"]
[270, {"b": [["11850.70000", "0.67727354", "1596737133.168458"]], "c": "1888918055"}, "book-100", "XBT/USD"]
[270, {"a": [["11865.10000", "0.70479901", "1596737133.168692"]], "c": "1888918055"}, "book-100", "XBT/USD"]
[270, {"a": [["11858.30000", "0.68857168", "1596737133.174311"]], "c": "3499751401"}, "book-100", "XBT/USD"]
[270, {"a": [["11856.70000", "0.40000000", "1596737133.177139"]], "c": "987103828"}, "book-100", "XBT/USD"]
[270, {"a": [["11873.50000", "0.00000000", "1596737133.177350"], ["11905.00000", "27.00000000", "1596736856.739074", "r"]], "c": "987103828"}, "book-100", "XBT/USD"]
[270, {"b": [["11849.60000", "0.40000000", "1596737133.177682"]], "c": "3712796049"}, "book-100", "XBT/USD"]
[270, {"a": [["11874.50000", "0.00000000", "1596737133.177753"], ["11906.00000", "0.05458243", "1596736960.945412", "r"]], "c": "3712796049"}, "book-100", "XBT/USD"]
[270, {"a": [["11854.50000", "0.91032000", "1596737133.181384"]], "c": "2989073762"}, "book-100", "XBT/USD"]
[270, {"a": [["11868.60000", "0.00000000", "1596737133.189966"], ["11906.00000", "0.05458243", "1596736960.945412", "r"]], "c": "2989073762"}, "book-100", "XBT/USD"]
[270, {"a": [["11866.50000", "0.00000000", "1596737133.199134"], ["11906.40000", "0.47990000", "1596737133.044226", "r"]], "c": "2989073762"}, "book-100", "XBT/USD"]
[270, {"a": [["11863.20000", "3.73041570", "1596737133.214416"]], "c": "2989073762"}, "book-100", "XBT/USD"]
[270, {"a": [["11901.50000", "3.26167975", "1596737133.218332"]], "c": "2989073762"}, "book-100", "XBT/USD"]
[270, {"a": [["11862.50000", "0.50000000", "1596737133.218769"]], "c": "2989073762"}, "book-100", "XBT/USD"]
[270, {"b": [["11851.60000", "0.14280000", "1596737133.223666"]], "c": "4194834111"}, "book-100", "XBT/USD"]
[270, {"a": [["11862.50000", "0.00000000", "1596737133.224849"], ["11906.40000", "0.47990000", "1596737133.044226", "r"]], "c": "4194834111"}, "book-100", "XBT/USD"]
[270, {"b": [["11839.30000", "1.95347350", "1596737133.225550"]], "c": "4194834111"}, "book-100", "XBT/USD"]
[270, {"a": [["11873.10000", "5.61768478", "1596737133.227147"]], "c": "4194834111"}, "book-100", "XBT/USD"]
[270, {"b": [["11847.10000", "0.11379563", "1596737133.234406"]], "c": "1612602863"}, "book-100", "XBT/USD"]
[270, {"b": [["11807.50000", "7.94389764", "1596737133.235006"]], "c": "1612602863"}, "book-100", "XBT/USD"]
[270, {"b": [["11834.60000", "3.28011775", "1596737133.235406"]], "c": "1612602863"}, "book-100", "XBT/USD"]
[270, {"a": [["11862.60000", "0.10000000", "1596737133.235549"]], "c": "1612602863"}, "book-100", "XBT/USD"]
[270, {"b": [["11819.30000", "3.28436384", "1596737133.236803"]], "c": "1612602863"}, "book-100", "XBT/USD"]
[270, {"b": [["11828.70000", "3.28175383", "1596737133.245640"]], "c": "1612602863"}, "book-100", "XBT/USD"]
[270, {"a": [["11856.70000", "0.00000000", "1596737133.258154"], ["11907.00000", "8.54095785", "1596737002.155356", "r"]]}, {"b": [["11849.60000", "0.00000000", "1596737133.258165"], ["11768.20000", "0.03400000", "1596737130.244561", "r"]], "c": "2905749219"}, "book-100", "XBT/USD"]
[270, {"a": [["11856.80000", "0.00000000", "1596737133.266488"], ["11907.20000", "6.18638192", "1596736972.522950", "r"]], "c": "459961199"}, "book-100", "XBT/USD"]
[270, {"a": [["11861.40000", "0.84300000", "1596737133.277838"]], "c": "2389352286"}, "book-100", "XBT/USD"]
[270, {"a": [["11857.00000", "0.25000000", "1596737133.283420"]], "c": "2799273811"}, "book-100", "XBT/USD"]
[270, {"b": [["11832.00000", "0.00000000", "1596737133.289190"], ["11766.90000", "0.95277495", "1596737097.210623", "r"]], "c": "2799273811"}, "book-100", "XBT/USD"]
[270, {"a": [["11857.10000", "0.14918520", "1596737133.290131"]], "c": "2408369521"}, "book-100", "XBT/USD"]
[270, {"a": [["11866.70000", "0.48290196", "1596737133.293508"]], "c": "2408369521"}, "book-100", "XBT/USD"]
[270, {"a": [["11866.30000", "0.00000000", "1596737133.297628"], ["11906.40000", "0.47990000", "1596737133.044226", "r"]], "c": "2408369521"}, "book-100", "XBT/USD"]
[270, {"b": [["11833.70000", "0.28688860", "1596737133.303520"]], "c": "2408369521"}, "book-100", "XBT/USD"]
[270, {"b": [["11852.70000", "0.40000000", "1596737133.309326"]], "c": "1290604944"}, "book-100", "XBT/USD"]
[270, {"b": [["11808.10000", "0.94908451", "1596737133.312944"]], "c": "1290604944"}, "book-100", "XBT/USD"]
[270, {"a": [["11857.60000", "0.21253134", "1596737133.313425"]], "c": "4004635608"}, "book-100", "XBT/USD"]
[270, {"a": [["11858.30000", "2.37257168", "1596737133.328835"]], "c": "947148348"}, "book-100", "XBT/USD"]
[270, {"a": [["11863.20000", "3.03041570", "1596737133.343162"]], "c": "947148348"}, "book-100", "XBT/USD"]
[270, {"a": [["11864.10000", "0.20000000", "1596737133.350181"]], "c": "947148348"}, "book-100", "XBT/USD"]
[270, {"a": [["11854.40000", "0.57436109", "1596737133.351714"]], "c": "1655682284"}, "book-100", "XBT/USD"]
[270, {"b": [["11783.60000", "5.10000000", "1596737133.351875"]], "c": "1655682284"}, "book-100", "XBT/USD"]
[270, {"a": [["11860.90000", "0.61036967", "1596737133.355916"]], "c": "1655682284"}, "book-100", "XBT/USD"]
[270, {"a": [["11870.30000", "0.04440539", "1596737133.374227"]], "c": "1655682284"}, "book-100", "XBT/USD"]
[270, {"b": [["11849.00000", "1.67900000", "1596737133.375542"]], "c": "2698386831"}, "book-100", "XBT/USD"]
[270, {"a": [["11857.60000", "0.85450228", "1596737133.377198"]], "c": "666137741"}, "book-100", "XBT/USD"]
[270, {"a": [["11857.60000", "1.16412647", "1596737133.378540"]], "c": "1314479528"}, "book-100", "XBT/USD"]
[270, {"a": [["11854.50000", "1.13532000", "1596737133.382832"]], "c": "3940806522"}, "book-100", "XBT/USD"]
[270, {"a": [["11857.60000", "1.29662807", "1596737133.383509"]], "c": "3442355227"}, "book-100", "XBT/USD"]
[270, {"a": [["11857.70000", "0.40178922", "1596737133.387317"]], "c": "1576174194"}, "book-100", "XBT/USD"]
[270, {"a": [["11862.00000", "0.14499999", "1596737133.392340"]], "c": "1576174194"}, "book-100", "XBT/USD"]
[270, {"a": [["11857.60000", "1.67344921", "1596737133.401088"]], "c": "973483745"}, "book-100", "XBT/USD"]
[270, {"a": [["11863.20000", "1.03041570", "1596737133.416763"]], "c": "973483745"}, "book-100", "XBT/USD"]
[270, {"a": [["11874.40000", "0.00000000", "1596737133.428615"], ["11902.20000", "1.58369712", "1596737116.990726", "r"]], "c": "973483745"}, "book-100", "XBT/USD"]
[270, {"b": [["11850.70000", "0.00000000", "1596737133.432345"], ["11772.90000", "2.20375182", "1596737056.454079", "r"]], "c": "503600965"}, "book-100", "XBT/USD"]
[270, {"a": [["11889.00000", "10.52943856", "1596737133.432694"]], "c": "503600965"}, "book-100", "XBT/USD"]
[270, {"a": [["11854.00000", "2.00000000", "1596737133.434272"]], "c": "2661529338"}, "book-100", "XBT/USD"]
[270, {"a": [["11857.00000", "0.00000000", "1596737133.437239"], ["11902.00000", "0.22739000", "1596736764.397858", "r"]], "c": "134818135"}, "book-100", "XBT/USD"]
[270, {"a": [["11854.80000", "1.50000000", "1596737133.439864"]], "c": "3578617296"}, "book-100", "XBT/USD"]
[270, {"a": [["11863.10000", "0.99119489", "1596737133.452409"]], "c": "3578617296"}, "book-100", "XBT/USD"]
[270, {"a": [["11854.50000", "0.91032000", "1596737133.455769"]], "c": "1177028135"}, "book-100", "XBT/USD"]
[270, {"b": [["11851.60000", "0.00000000", "1596737133.469318"], ["11769.00000", "3.73835290", "1596736631.449390", "r"]], "c": "2792586571"}, "book-100", "XBT/USD"]
[270, {"b": [["11838.40000", "0.00000000", "1596737133.485335"], ["11768.80000", "1.67000789", "1596736630.663519", "r"]], "c": "2792586571"}, "book-100", "XBT/USD"]
[270, {"b": [["11833.50000", "0.38000000", "1596737133.488890"]], "c": "2792586571"}, "book-100", "XBT/USD"]
[270, {"a": [["11852.80000", "0.50000000", "1596737133.492174"]], "c": "958041047"}, "book-100", "XBT/USD"]
[270, {"a": [["11865.50000", "0.38000000", "1596737133.499044"]], "c": "958041047"}, "book-100", "XBT/USD"]
[270, {"a": [["11858.70000", "0.10300000", "1596737133.501766"]], "c": "958041047"}, "book-100", "XBT/USD"]
[270, {"a": [["11897.50000", "0.75800000", "1596737133.514960"]], "c": "958041047"}, "book-100", "XBT/USD"]
[270, {"a": [["11854.00000", "2.22500000", "1596737133.528970"]], "c": "2773237531"}, "book-100", "XBT/USD"]
[270, {"a": [["11870.30000", "0.00000000", "1596737133.533335"], ["11900.70000", "0.00500000", "1596736976.571243", "r"]], "c": "2773237531"}, "book-100", "XBT/USD"]
[270, {"a": [["11873.00000", "0.02101604", "1596737133.533908"]], "c": "2773237531"}, "book-100", "XBT/USD"]
[270, {"a": [["11898.70000", "0.01000000", "1596737133.560066"]], "c": "2773237531"}, "book-100", "XBT/USD"]
[270, {"b": [["11845.60000", "0.10100000", "1596737133.568884"]], "c": "211703612"}, "book-100", "XBT/USD"]
[270, {"a": [["11854.80000", "0.00000000", "1596737133.581807"], ["11900.70000", "0.00500000", "1596736976.571243", "r"]], "c": "4004431887"}, "book-100", "XBT/USD"]
[270, {"a": [["11857.10000", "0.39918520", "1596737133.598629"]], "c": "2660993805"}, "book-100", "XBT/USD"]
[270, {"a": [["11878.10000", "1.02164387", "1596737133.609936"]], "c": "2660993805"}, "book-100", "XBT/USD"]
[270, {"a": [["11854.00000", "2.00000000", "1596737133.647429"]], "c": "3240750793"}, "book-100", "XBT/USD"]
[270, {"b": [["11831.50000", "0.01000000", "1596737133.659804"]], "c": "3240750793"}, "book-100", "XBT/USD"]
[270, {"a": [["11854.40000", "0.00000000", "1596737133.669048"], ["11900.70000", "0.00500000", "1596736976.571243", "r"]], "c": "3456049641"}, "book-100", "XBT/USD"]
[270, {"a": [["11857.90000", "0.66283811", "1596737133.696405"]], "c": "3497317899"}, "book-100", "XBT/USD"]
[270, {"b": [["11838.40000", "5.50000000", "1596737133.704421"]], "c": "3497317899"}, "book-100", "XBT/USD"]
[270, {"b": [["11849.00000", "0.00000000", "1596737133.705302"], ["11775.00000", "0.92000000", "1596736031.317852", "r"]], "c": "1277704406"}, "book-100", "XBT/USD"]
[270, {"a": [["11862.00000", "0.00000000", "1596737133.706399"], ["11900.70000", "0.00500000", "1596736976.571243", "r"]], "c": "1277704406"}, "book-100", "XBT/USD"]
[270, {"a": [["11854.80000", "1.50000000", "1596737133.727089"]], "c": "2243683818"}, "book-100", "XBT/USD"]
[270, {"b": [["11852.70000", "0.00000000", "1596737133.756783"], ["11772.90000", "2.20375182", "1596737056.454079", "r"]], "c": "1360434269"}, "book-100", "XBT/USD"]
[270, {"a": [["11853.50000", "0.22500000", "1596737133.806742"]], "c": "4073936503"}, "book-100", "XBT/USD"]
[270, {"a": [["11852.80000", "0.00000000", "1596737133.808528"], ["11900.30000", "0.73381520", "1596737116.696146", "r"]], "c": "394629880"}, "book-100", "XBT/USD"]
[270, {"a": [["11893.80000", "0.46913521", "1596737133.811592"]], "c": "394629880"}, "book-100", "XBT/USD"]
[270, {"b": [["11828.40000", "0.00000000", "1596737133.811850"], ["11769.00000", "3.73835290", "1596736631.449390", "r"]], "c": "394629880"}, "book-100", "XBT/USD"]
[270, {"a": [["11857.10000", "0.14918520", "1596737133.831952"]], "c": "1739641338"}, "book-100", "XBT/USD"]
[270, {"a": [["11886.50000", "0.73646717", "1596737133.833515"]], "c": "1739641338"}, "book-100", "XBT/USD"]
[270, {"b": [["11852.60000", "0.13570000", "1596737133.836179"]], "c": "1516781163"}, "book-100", "XBT/USD"]
[270, {"a": [["11888.10000", "1.02857217", "1596737133.869092"]], "c": "1516781163"}, "book-100", "XBT/USD"]
[270, {"a": [["11853.50000", "0.00000000", "1596737133.874605"], ["11900.30000", "0.73381520", "1596737116.696146", "r"]], "c": "3483835626"}, "book-100", "XBT/USD"]
[270, {"a": [["11862.90000", "0.00000000", "1596737133.939723"], ["11900.70000", "0.00500000", "1596736976.571243", "r"]], "c": "3483835626"}, "book-100", "XBT/USD"]
[270, {"a": [["11854.00000", "2.22500000", "1596737133.943225"]], "c": "2817936468"}, "book-100", "XBT/USD"]
[270, {"a": [["11862.10000", "0.00000000", "1596737133.953368"], ["11901.00000", "0.17065000", "1596737120.047779", "r"]], "c": "2817936468"}, "book-100", "XBT/USD"]
[270, {"a": [["11852.80000", "0.42000000", "1596737133.953931"]], "c": "2428137576"}, "book-100", "XBT/USD"]
[270, {"a": [["11860.90000", "0.00000000", "1596737133.963086"], ["11901.00000", "0.17065000", "1596737120.047779", "r"]], "c": "2428137576"}, "book-100", "XBT/USD"]
[270, {"a": [["11859.10000", "0.14499999", "1596737133.976363"]], "c": "2428137576"}, "book-100", "XBT/USD"]
[270, {"b": [["11817.20000", "0.00000000", "1596737133.979963"], ["11769.00000", "3.73835290", "1596736631.449390", "r"]], "c": "2428137576"}, "book-100", "XBT/USD"]
[270, {"b": [["11800.80000", "1.51500000", "1596737133.991629"]], "c": "2428137576"}, "book-100", "XBT/USD"]
[270, {"a": [["11855.70000", "0.25000000", "1596737133.991704"]], "c": "136162791"}, "book-100", "XBT/USD"]
[270, {"a": [["11852.70000", "0.43216524", "1596737133.999824"]], "c": "4191985101"}, "book-100", "XBT/USD"]
[270, {"b": [["11821.60000", "0.00000000", "1596737134.008115"], ["11769.00000", "3.73835290", "1596736631.449390", "r"]], "c": "4191985101"}, "book-100", "XBT/USD"]
[270, {"b": [["11819.50000", "6.22941734", "1596737134.020774"]], "c": "4191985101"}, "book-100", "XBT/USD"]
[270, {"a": [["11853.90000", "0.01975817", "1596737134.023827"]], "c": "2545030323"}, "book-100", "XBT/USD"]
[270, {"b": [["11831.30000", "3.11160220", "1596737134.027851"]], "c": "2545030323"}, "book-100", "XBT/USD"]
[270, {"a": [["11886.10000", "0.00500329", "1596737134.043199"]], "c": "2545030323"}, "book-100", "XBT/USD"]
[270, {"b": [["11819.10000", "0.73646717", "1596737134.047480"]], "c": "2545030323"}, "book-100", "XBT/USD"]
[270, {"b": [["11850.30000", "0.40000000", "1596737134.054151"]], "c": "597948876"}, "book-100", "XBT/USD"]
[270, {"b": [["11783.60000", "0.00000000", "1596737134.065115"], ["11777.00000", "0.00100000", "1596735197.730576", "r"]], "c": "597948876"}, "book-100", "XBT/USD"]
[270, {"a": [["11864.50000", "10.49549677", "1596737134.065986"]], "c": "597948876"}, "book-100", "XBT/USD"]
[270, {"a": [["11852.80000", "0.00000000", "1596737134.066195"], ["11900.00000", "12.71653131", "1596737075.897027", "r"]], "c": "2672717603"}, "book-100", "XBT/USD"]
[270, {"a": [["11888.20000", "0.00000000", "1596737134.078971"], ["11900.30000", "0.73381520", "1596737116.696146", "r"]], "c": "2672717603"}, "book-100", "XBT/USD"]
[270, {"b": [["11825.10000", "7.85923142", "1596737134.100620"]], "c": "2672717603"}, "book-100", "XBT/USD"]
[270, {"b": [["11835.80000", "0.83200000", "1596737134.101324"]], "c": "2672717603"}, "book-100", "XBT/USD"]
[270, {"a": [["11858.80000", "0.00000000", "1596737134.104969"], ["11900.70000", "0.00500000", "1596736976.571243", "r"]], "c": "2672717603"}, "book-100", "XBT/USD"]
[270, {"a": [["11852.70000", "0.93216524", "1596737134.122017"]], "c": "3636572351"}, "book-100", "XBT/USD"]
[270, {"a": [["11862.60000", "0.00000000", "1596737134.125088"], ["11901.00000", "0.17065000", "1596737120.047779", "r"]], "c": "3636572351"}, "book-100", "XBT/USD"]
[270, {"b": [["11816.70000", "2.62988017", "1596737134.139418"]], "c": "3636572351"}, "book-100", "XBT/USD"]
[270, {"b": [["11847.10000", "4.32379563", "1596737134.160457"]], "c": "363939257"}, "book-100", "XBT/USD"]
[270, {"a": [["11859.10000", "0.00000000", "1596737134.165260"], ["11901.50000", "3.26167975", "1596737133.218332", "r"]], "c": "363939257"}, "book-100", "XBT/USD"]
[270, {"a": [["11854.00000", "2.00000000", "1596737134.177604"]], "c": "1193606884"}, "book-100", "XBT/USD"]
[270, {"a": [["11852.70000", "0.95192340", "1596737134.181672"]], "c": "2312486019"}, "book-100", "XBT/USD"]
[270, {"a": [["11854.50000", "1.54300661", "1596737134.190495"]], "c": "1268723598"}, "book-100", "XBT/USD"]
[270, {"b": [["11848.10000", "0.42163776", "1596737134.191867"]], "c": "3933022639"}, "book-100", "XBT/USD"]
[270, {"b": [["11849.50000", "0.31629507", "1596737134.191995"]], "c": "3502474060"}, "book-100", "XBT/USD"]
[270, {"a": [["11853.00000", "0.63265614", "1596737134.192123"]], "c": "2189671091"}, "book-100", "XBT/USD"]
[270, {"a": [["11854.60000", "0.63268661", "1596737134.199462"]], "c": "2751243429"}, "book-100", "XBT/USD"]
[270, {"b": [["11847.00000", "0.78234636", "1596737134.201420"]], "c": "3321922496"}, "book-100", "XBT/USD"]
[270, {"b": [["11845.50000", "0.42163776", "1596737134.208861"]], "c": "3779156616"}, "book-100", "XBT/USD"]
[270, {"a": [["11860.00000", "0.84359030", "1596737134.211187"]], "c": "3779156616"}, "book-100", "XBT/USD"]
[270, {"b": [["11840.50000", "0.42163776", "1596737134.211338"]], "c": "3779156616"}, "book-100", "XBT/USD"]
[270, {"a": [["11858.50000", "0.99359030", "1596737134.214959"]], "c": "3779156616"}, "book-100", "XBT/USD"]
[270, {"b": [["11843.00000", "0.42163776", "1596737134.219219"]], "c": "3779156616"}, "book-100", "XBT/USD"]
[270, {"b": [["11838.00000", "0.42163776", "1596737134.221980"]], "c": "3779156616"}, "book-100", "XBT/USD"]
[270, {"b": [["11833.70000", "0.70863426", "1596737134.222623"]], "c": "3779156616"}, "book-100", "XBT/USD"]
[270, {"b": [["11835.90000", "0.42166656", "1596737134.222726"]], "c": "3779156616"}, "book-100", "XBT/USD"]
[270, {"b": [["11825.80000", "2.38150000", "1596737134.227238"]], "c": "3779156616"}, "book-100", "XBT/USD"]
[270, {"a": [["11859.50000", "0.62209985", "1596737134.228455"]], "c": "3779156616"}, "book-100", "XBT/USD"]
[270, {"b": [["11847.10000", "4.31000000", "1596737134.232573"]], "c": "110188657"}, "book-100", "XBT/USD"]
[270, {"b": [["11847.20000", "0.00816380", "1596737134.240034"]], "c": "3916005655"}, "book-100", "XBT/USD"]
[270, {"a": [["11852.70000", "1.05192340", "1596737134.246768"]], "c": "1663642981"}, "book-100", "XBT/USD"]
[270, {"b": [["11795.50000", "1.06000000", "1596737134.250857"]], "c": "1663642981"}, "book-100", "XBT/USD"]
[270, {"a": [["11853.60000", "0.22500000", "1596737134.288043"]], "c": "4048955146"}, "book-100", "XBT/USD"]
[270, {"a": [["11854.80000", "0.00000000", "1596737134.292806"], ["11900.00000", "12.71653131", "1596737075.897027", "r"]], "c": "3016343278"}, "book-100", "XBT/USD"]
[270, {"b": [["11848.50000", "0.05063300", "1596737134.341270"]], "c": "54699197"}, "book-100", "XBT/USD"]
[270, {"a": [["11853.60000", "0.00000000", "1596737134.353710"], ["11900.30000", "0.73381520", "1596737116.696146", "r"]], "c": "2613674234"}, "book-100", "XBT/USD"]
[270, {"a": [["11854.30000", "1.50000000", "1596737134.443034"]], "c": "374748681"}, "book-100", "XBT/USD"]
[270, {"a": [["11870.40000", "0.00500000", "1596737134.474913"]], "c": "374748681"}, "book-100", "XBT/USD"]
[270, {"b": [["11835.00000", "1.81196955", "1596737134.610562"]], "c": "374748681"}, "book-100", "XBT/USD"]
[270, {"b": [["11807.90000", "2.12812342", "1596737134.614299"]], "c": "374748681"}, "book-100", "XBT/USD"]
[270, {"a": [["11858.40000", "1.68559030", "1596737134.648495"]], "c": "374748681"}, "book-100", "XBT/USD"]
[270, {"a": [["11855.70000", "0.00000000", "1596737134.652920"], ["11900.30000", "0.73381520", "1596737116.696146", "r"]], "c": "2722042568"}, "book-100", "XBT/USD"]
[270, {"a": [["11861.40000", "0.00000000", "1596737134.658336"], ["11900.70000", "0.00500000", "1596736976.571243", "r"]], "c": "2722042568"}, "book-100", "XBT/USD"]
[270, {"a": [["11853.00000", "0.00000000", "1596737134.712471"], ["11901.00000", "0.17065000", "1596737120.047779", "r"]], "c": "2341136219"}, "book-100", "XBT/USD"]
[270, {"b": [["11842.70000", "0.00000000", "1596737134.718756"], ["11790.00000", "0.24750000", "1596737132.922523", "r"]], "c": "2341136219"}, "book-100", "XBT/USD"]
[270, {"b": [["11839.30000", "1.26009819", "1596737134.729757"]], "c": "2341136219"}, "book-100", "XBT/USD"]
[270, {"b": [["11836.90000", "0.00000000", "1596737134.732185"], ["11789.40000", "2.00800000", "1596735513.212546", "r"]], "c": "2341136219"}, "book-100", "XBT/USD"]
[270, {"a": [["11858.30000", "0.68857168", "1596737134.732926"]], "c": "2341136219"}, "book-100", "XBT/USD"]
[270, {"b": [["11847.10000", "4.21000000", "1596737134.741876"]], "c": "2711805753"}, "book-100", "XBT/USD"]
[270, {"a": [["11883.70000", "0.20405824", "1596737134.742122"]], "c": "2711805753"}, "book-100", "XBT/USD"]
[270, {"a": [["11854.50000", "0.63268661", "1596737134.803758"]], "c": "1645900148"}, "book-100", "XBT/USD"]
[270, {"a": [["11857.10000", "0.39918520", "1596737134.811247"]], "c": "2641352639"}, "book-100", "XBT/USD"]
[270, {"a": [["11854.60000", "0.00000000", "1596737134.811404"], ["11901.00000", "0.17065000", "1596737120.047779", "r"]], "c": "1034346621"}, "book-100", "XBT/USD"]
[270, {"b": [["11847.00000", "0.46600000", "1596737134.811768"]], "c": "254510569"}, "book-100", "XBT/USD"]
[270, {"a": [["11885.80000", "3.26598811", "1596737134.820970"]], "c": "254510569"}, "book-100", "XBT/USD"]
[270, {"a": [["11886.80000", "10.52936829", "1596737134.847224"]], "c": "254510569"}, "book-100", "XBT/USD"]
[270, {"b": [["11807.80000", "0.00000000", "1596737134.877843"], ["11787.80000", "6.80000000", "1596737132.726658", "r"]], "c": "254510569"}, "book-100", "XBT/USD"]
[270, {"b": [["11848.20000", "0.00703700", "1596737134.916945"]], "c": "1361205015"}, "book-100", "XBT/USD"]
[270, {"b": [["11847.20000", "0.00000000", "1596737134.921571"], ["11787.80000", "6.80000000", "1596737132.726658", "r"]], "c": "2909912254"}, "book-100", "XBT/USD"]
[270, {"b": [["11848.20000", "0.10703700", "1596737134.938695"]], "c": "2705673852"}, "book-100", "XBT/USD"]
[270, {"b": [["11851.00000", "1.68600000", "1596737134.942625"]], "c": "3672076929"}, "book-100", "XBT/USD"]
[270, {"a": [["11860.60000", "0.84300000", "1596737134.963641"]], "c": "3672076929"}, "book-100", "XBT/USD"]
