[270, {"as": [["11872.70000", "0.58275302", "1596736921.584825"], ["11872.80000", "0.00500000", "1596736917.471599"], ["11873.00000", "0.83142270", "1596736901.488528"], ["11873.20000", "0.09621094", "1596736911.615321"], ["11873.40000", "0.63142120", "1596736896.788773"], ["11874.30000", "0.18435000", "1596736921.713892"], ["11874.50000", "0.18435000", "1596736921.560489"], ["11875.10000", "0.81577270", "1596736921.429447"], ["11875.30000", "0.16490000", "1596736882.409755"], ["11875.40000", "0.08690127", "1596736921.192555"], ["11875.50000", "0.04750000", "1596736910.317134"], ["11875.60000", "0.88740000", "1596736921.607247"], ["11875.70000", "0.25000000", "1596736921.296115"], ["11875.80000", "4.19800000", "1596736916.472166"], ["11876.00000", "0.10200000", "1596736909.811327"], ["11876.80000", "0.90958000", "1596736879.175575"], ["11876.90000", "0.84192960", "1596736891.656875"], ["11878.30000", "1.50000000", "1596736903.594582"], ["11878.60000", "1.12564964", "1596736919.698241"], ["11878.70000", "1.67200000", "1596736887.119174"], ["11879.40000", "0.84178808", "1596736852.528563"], ["11879.50000", "0.84183982", "1596736855.213335"], ["11879.90000", "0.01000000", "1596736851.686865"], ["11880.00000", "0.70000000", "1596736843.691882"], ["11880.30000", "0.64182575", "1596736916.927500"], ["11880.70000", "0.14918520", "1596736820.024834"], ["11881.10000", "0.79522000", "1596736916.827737"], ["11881.20000", "0.46895949", "1596736878.048946"], ["11882.10000", "1.15556188", "1596736874.680471"], ["11882.30000", "0.54440539", "1596736908.495461"], ["11882.40000", "0.10200000", "1596736888.714723"], ["11882.80000", "0.01464958", "1596736913.069002"], ["11883.00000", "2.04257694", "1596736844.015233"], ["11883.50000", "0.69309935", "1596736852.741079"], ["11883.70000", "0.07324792", "1596736913.208945"], ["11883.90000", "0.01800000", "1596736918.175654"], ["11884.70000", "0.17579500", "1596736913.366622"], ["11885.30000", "0.42191159", "1596736916.376709"], ["11885.60000", "0.04395015", "1596736878.637409"], ["11885.80000", "0.84192226", "1596736891.947169"], ["11886.10000", "2.00500329", "1596736887.443589"], ["11886.40000", "0.13183527", "1596736883.415917"], ["11887.20000", "1.04962971", "1596736917.892821"], ["11887.30000", "6.24189408", "1596736912.703093"], ["11887.60000", "0.01500000", "1596736886.629635"], ["11889.10000", "0.38000000", "1596736890.456231"], ["11890.00000", "0.65000000", "1596736826.106226"], ["11890.70000", "5.80000000", "1596736848.966516"], ["11891.30000", "0.32947695", "1596736917.430636"], ["11891.70000", "0.01000000", "1596736649.502363"], ["11891.80000", "1.04380000", "1596736809.783964"], ["11892.50000", "1.88230000", "1596736809.646675"], ["11894.00000", "5.76394652", "1596736899.643876"], ["11894.10000", "0.63777346", "1596736843.329215"], ["11894.70000", "0.30000000", "1596736817.824711"], ["11894.80000", "0.69169801", "1596736916.897061"], ["11895.00000", "0.25000000", "1596736822.592448"], ["11895.80000", "5.30000000", "1596736916.541675"], ["11896.10000", "0.44815750", "1596736918.105609"], ["11896.20000", "7.72516526", "1596736905.999444"], ["11896.30000", "7.54073617", "1596736879.318700"], ["11896.70000", "0.10898499", "1596736881.879549"], ["11897.00000", "0.02000000", "1596736823.323873"], ["11897.40000", "0.54100000", "1596736908.505403"], ["11897.50000", "1.38307503", "1596736910.283097"], ["11897.70000", "0.68090000", "1596736617.808601"], ["11898.70000", "0.01000000", "1596736445.338120"], ["11898.90000", "0.94224318", "1596736885.413304"], ["11899.00000", "2.81849664", "1596736909.741780"], ["11899.10000", "1.66664879", "1596736882.051545"], ["11899.20000", "0.05223289", "1596736805.577980"], ["11899.90000", "7.61000000", "1596736881.723539"], ["11900.00000", "12.71653131", "1596736857.321303"], ["11900.10000", "0.73580811", "1596736914.627716"], ["11900.70000", "0.00500000", "1596736837.842622"], ["11901.30000", "0.52802786", "1596736881.941730"], ["11901.40000", "3.26341993", "1596736882.109738"], ["11902.00000", "0.22739000", "1596736764.397858"], ["11902.40000", "0.94196611", "1596736885.410733"], ["11902.70000", "0.28538453", "1596736882.040548"], ["11904.00000", "0.17065000", "1596736902.015484"], ["11904.20000", "3.09359065", "1596736857.440538"], ["11904.50000", "1.75329979", "1596736858.262964"], ["11904.70000", "0.30000000", "1596736686.232393"], ["11904.80000", "6.46162365", "1596736858.366655"], ["11905.00000", "27.00000000", "1596736856.739074"], ["11905.50000", "2.17990581", "1596736920.696900"], ["11905.70000", "1.27434671", "1596736891.207419"], ["11907.00000", "0.17065000", "1596736918.845946"], ["11907.40000", "1.05546030", "1596736855.271577"], ["11907.70000", "0.09250000", "1596736864.624331"], ["11907.90000", "2.38150000", "1596736895.960018"], ["11908.00000", "3.26085487", "1596736823.112265"], ["11908.10000", "0.46854510", "1596736823.325393"], ["11908.40000", "0.94149879", "1596736824.171595"], ["11908.90000", "1.06880000", "1596736841.521829"], ["11909.10000", "1.00200000", "1596736809.784670"], ["11909.80000", "2.19473637", "1596736896.221437"], ["11909.90000", "6.20000000", "1596736825.518690"], ["11910.00000", "0.36067000", "1596736874.546981"]], "bs": [["11871.40000", "0.51144206", "1596736921.402594"], ["11871.20000", "0.01464958", "1596736921.384298"], ["11871.10000", "0.25256848", "1596736896.788286"], ["11871.00000", "0.25256628", "1596736905.292814"], ["11870.50000", "0.25257602", "1596736894.496299"], ["11870.30000", "0.42000000", "1596736904.558391"], ["11870.10000", "1.85779500", "1596736913.209297"], ["11869.00000", "3.57947779", "1596736899.050578"], ["11868.50000", "4.20000000", "1596736899.513260"], ["11868.40000", "0.31571469", "1596736888.664230"], ["11868.00000", "0.33675797", "1596736896.788455"], ["11867.60000", "0.46600000", "1596736887.930393"], ["11866.40000", "0.04394967", "1596736919.190493"], ["11865.90000", "0.42095292", "1596736911.489314"], ["11864.80000", "0.13184902", "1596736919.788378"], ["11864.70000", "0.42095292", "1596736919.000182"], ["11864.50000", "0.59832324", "1596736892.562978"], ["11864.40000", "0.09621094", "1596736911.476489"], ["11863.90000", "0.10200000", "1596736888.709823"], ["11863.30000", "0.23800000", "1596736913.368362"], ["11863.10000", "0.68795000", "1596736918.123032"], ["11862.30000", "0.42095292", "1596736888.664590"], ["11860.80000", "0.82373406", "1596736915.124950"], ["11860.70000", "0.69977000", "1596736899.745504"], ["11860.10000", "0.41130000", "1596736888.025253"], ["11860.00000", "0.35000000", "1596736892.345866"], ["11859.90000", "0.10000000", "1596736894.303685"], ["11859.50000", "0.42095515", "1596736891.948382"], ["11858.90000", "0.11357307", "1596736896.841380"], ["11858.80000", "0.38000000", "1596736889.444982"], ["11858.10000", "0.02300000", "1596736918.181241"], ["11857.70000", "0.69883174", "1596736885.142361"], ["11857.40000", "0.02337356", "1596736921.043074"], ["11857.30000", "1.39770347", "1596736879.701647"], ["11857.10000", "0.20458788", "1596736918.123882"], ["11857.00000", "0.76544926", "1596736889.670952"], ["11856.90000", "1.05511170", "1596736886.113055"], ["11856.10000", "1.04381765", "1596736893.054877"], ["11856.00000", "3.00000000", "1596736887.544802"], ["11855.90000", "0.09700000", "1596736887.653770"], ["11854.80000", "0.00444588", "1596736918.764464"], ["11854.70000", "8.27627573", "1596736879.670144"], ["11853.50000", "0.28651002", "1596736879.594789"], ["11853.40000", "0.94603751", "1596736879.782438"], ["11852.90000", "0.68090000", "1596736887.865733"], ["11852.80000", "0.53015045", "1596736834.008081"], ["11852.50000", "1.02195044", "1596736890.054172"], ["11851.40000", "3.95438918", "1596736879.736791"], ["11851.10000", "1.53414277", "1596736879.684701"], ["11851.00000", "6.70000000", "1596736768.862785"], ["11849.10000", "3.10827650", "1596736881.731687"], ["11849.00000", "6.49293489", "1596736882.318618"], ["11848.50000", "0.24913765", "1596736877.407921"], ["11847.20000", "7.10000000", "1596736616.995666"], ["11846.60000", "1.06100750", "1596736664.318618"], ["11846.50000", "0.47103451", "1596736830.330341"], ["11846.30000", "4.22550776", "1596736894.327763"], ["11846.10000", "2.38150000", "1596736685.211501"], ["11845.20000", "2.19123143", "1596736667.342929"], ["11844.40000", "0.01000000", "1596736858.870812"], ["11842.80000", "7.00000000", "1596736511.370562"], ["11841.40000", "0.78981184", "1596736857.017352"], ["11841.30000", "0.94697371", "1596736727.254484"], ["11839.30000", "1.92343678", "1596736833.136961"], ["11839.20000", "5.55162161", "1596736895.730470"], ["11839.10000", "1.06880000", "1596736690.612815"], ["11838.50000", "2.62537526", "1596736883.376616"], ["11838.40000", "6.73581521", "1596736920.383681"], ["11838.30000", "0.00700000", "1596736920.314372"], ["11837.70000", "1.02740000", "1596736845.633658"], ["11837.20000", "8.09281851", "1596736894.638834"], ["11837.10000", "1.59947305", "1596736773.815180"], ["11837.00000", "6.22321537", "1596736664.771551"], ["11836.90000", "3.28135470", "1596736822.057040"], ["11836.70000", "0.75800000", "1596736629.252689"], ["11836.50000", "19.90000000", "1596736758.180522"], ["11835.70000", "0.01248572", "1596736879.923239"], ["11834.70000", "0.10443040", "1596736685.107667"], ["11834.10000", "7.50000000", "1596736394.918895"], ["11833.70000", "2.19301772", "1596736880.302475"], ["11830.00000", "7.10000000", "1596736522.825678"], ["11828.10000", "13.67533399", "1596736886.926841"], ["11827.80000", "0.96443907", "1596736455.727705"], ["11827.70000", "2.41269140", "1596736455.609640"], ["11827.00000", "3.28393693", "1596736692.286648"], ["11826.70000", "1.68072981", "1596736915.495599"], ["11826.00000", "21.70000000", "1596736837.490904"], ["11825.70000", "0.94888321", "1596736502.975300"], ["11825.10000", "7.50000000", "1596736539.837485"], ["11824.00000", "0.08551909", "1596736745.547850"], ["11822.80000", "0.18908127", "1596736802.000136"], ["11821.50000", "0.75800000", "1596736528.431505"], ["11821.40000", "0.10000000", "1596736096.917280"], ["11820.70000", "2.12643506", "1596736887.632732"], ["11820.60000", "2.76416530", "1596736814.796571"], ["11820.50000", "2.20841175", "1596736910.069466"], ["11820.40000", "4.22997529", "1596736854.821226"], ["11820.30000", "5.90000000", "1596735205.963257"], ["11820.00000", "0.48150000", "1596736853.873337"], ["11817.60000", "1.06000000", "1596736530.234224"]]}, "book-100", "XBT/USD"]
[270, {"a": [["11874.20000", "0.18435000", "1596736921.903096"]], "c": "197371896"}, "book-100", "XBT/USD"]
[270, {"a": [["11879.00000", "0.65153463", "1596736921.960031"]], "c": "197371896"}, "book-100", "XBT/USD"]
[270, {"b": [["11858.10000", "0.00000000", "1596736921.961945"], ["11817.20000", "1.51500000", "1596736326.967282", "r"]], "c": "197371896"}, "book-100", "XBT/USD"]
[270, {"a": [["11883.90000", "0.00000000", "1596736921.962882"], ["11909.90000", "6.20000000", "1596736825.518690", "r"]], "c": "197371896"}, "book-100", "XBT/USD"]
[270, {"b": [["11859.10000", "0.02300000", "1596736922.017014"]], "c": "197371896"}, "book-100", "XBT/USD"]
[270, {"a": [["11884.90000", "0.01800000", "1596736922.019999"]], "c": "197371896"}, "book-100", "XBT/USD"]
[270, {"a": [["11875.00000", "0.88740000", "1596736922.023326"]], "c": "3104665991"}, "book-100", "XBT/USD"]
[270, {"a": [["11875.60000", "0.00000000", "1596736922.032267"], ["11909.80000", "2.19473637", "1596736896.221437", "r"]], "c": "3104665991"}, "book-100", "XBT/USD"]
[270, {"a": [["11872.20000", "2.00000000", "1596736922.149935"]], "c": "1751663009"}, "book-100", "XBT/USD"]
[270, {"a": [["11874.20000", "0.00000000", "1596736922.223250"], ["11909.80000", "2.19473637", "1596736896.221437", "r"]], "c": "3260420172"}, "book-100", "XBT/USD"]
[270, {"a": [["11872.10000", "0.01975816", "1596736922.224861"]], "c": "2851324244"}, "book-100", "XBT/USD"]
[270, {"a": [["11872.70000", "0.00000000", "1596736922.396356"], ["11909.80000", "2.19473637", "1596736896.221437", "r"]], "c": "679461326"}, "book-100", "XBT/USD"]
[270, {"a": [["11872.10000", "0.71975816", "1596736922.449206"]], "c": "2665556039"}, "book-100", "XBT/USD"]
[270, {"a": [["11884.90000", "0.00000000", "1596736922.455982"], ["11909.90000", "6.20000000", "1596736825.518690", "r"]], "c": "2665556039"}, "book-100", "XBT/USD"]
[270, {"b": [["11859.10000", "0.00000000", "1596736922.456522"], ["11817.20000", "1.51500000", "1596736326.967282", "r"]], "c": "2665556039"}, "book-100", "XBT/USD"]
[270, {"a": [["11873.80000", "0.18435000", "1596736922.510292"]], "c": "2858586353"}, "book-100", "XBT/USD"]
[270, {"b": [["11858.10000", "0.02300000", "1596736922.653170"]], "c": "2858586353"}, "book-100", "XBT/USD"]
[270, {"a": [["11883.90000", "0.01800000", "1596736922.656768"]], "c": "2858586353"}, "book-100", "XBT/USD"]
[270, {"a": [["11872.10000", "0.01975816", "1596736922.661877"]], "c": "486308216"}, "book-100", "XBT/USD"]
[270, {"a": [["11904.30000", "3.00000000", "1596736922.664321"]], "c": "486308216"}, "book-100", "XBT/USD"]
[270, {"a": [["11871.60000", "2.00000000", "1596736922.666207"]], "c": "3423600524"}, "book-100", "XBT/USD"]
[270, {"a": [["11872.00000", "0.59062534", "1596736922.714789"]], "c": "3175547632"}, "book-100", "XBT/USD"]
[270, {"a": [["11873.80000", "0.00000000", "1596736922.725400"], ["11908.40000", "0.94149879", "1596736824.171595", "r"]], "c": "3373239851"}, "book-100", "XBT/USD"]
[270, {"a": [["11871.50000", "0.01975817", "1596736922.740849"]], "c": "2385804613"}, "book-100", "XBT/USD"]
[270, {"a": [["11875.10000", "0.63142270", "1596736922.747400"]], "c": "2385804613"}, "book-100", "XBT/USD"]
[270, {"a": [["11874.30000", "0.00000000", "1596736922.748306"], ["11908.40000", "0.94149879", "1596736824.171595", "r"]], "c": "1895031327"}, "book-100", "XBT/USD"]
[270, {"a": [["11874.50000", "0.00000000", "1596736922.748938"], ["11908.90000", "1.06880000", "1596736841.521829", "r"]], "c": "3895989921"}, "book-100", "XBT/USD"]
[270, {"a": [["11872.00000", "0.00000000", "1596736923.348958"], ["11909.10000", "1.00200000", "1596736809.784670", "r"]], "c": "1818694068"}, "book-100", "XBT/USD"]
[270, {"b": [["11868.50000", "0.00000000", "1596736923.354064"], ["11817.20000", "1.51500000", "1596736326.967282", "r"]], "c": "2226097227"}, "book-100", "XBT/USD"]
[270, {"a": [["11884.70000", "0.00000000", "1596736923.363791"], ["11909.80000", "2.19473637", "1596736896.221437", "r"]], "c": "2226097227"}, "book-100", "XBT/USD"]
[270, {"a": [["11872.10000", "0.00000000", "1596736923.403096"], ["11909.90000", "6.20000000", "1596736825.518690", "r"]], "c": "1384315170"}, "book-100", "XBT/USD"]
[270, {"b": [["11868.50000", "4.20900000", "1596736923.499533"]], "c": "200785060"}, "book-100", "XBT/USD"]
[270, {"a": [["11886.20000", "0.17579051", "1596736923.547800"]], "c": "200785060"}, "book-100", "XBT/USD"]
[270, {"a": [["11872.20000", "0.00000000", "1596736923.559518"], ["11909.90000", "6.20000000", "1596736825.518690", "r"]], "c": "3842490044"}, "book-100", "XBT/USD"]
[270, {"a": [["11871.50000", "0.58062053", "1596736923.672923"]], "c": "2633491858"}, "book-100", "XBT/USD"]
[270, {"a": [["11894.00000", "0.00000000", "1596736923.676947"], ["11910.00000", "0.36067000", "1596736874.546981", "r"]], "c": "2633491858"}, "book-100", "XBT/USD"]
[270, {"a": [["11875.60000", "0.18435000", "1596736923.739468"]], "c": "2633491858"}, "book-100", "XBT/USD"]
[270, {"a": [["11895.70000", "5.54588129", "1596736923.762781"]], "c": "2633491858"}, "book-100", "XBT/USD"]
[270, {"a": [["11871.50000", "2.58062053", "1596736923.831260"]], "c": "761334599"}, "book-100", "XBT/USD"]
[270, {"a": [["11871.60000", "0.00000000", "1596736923.832037"], ["11909.90000", "6.20000000", "1596736825.518690", "r"]], "c": "2900201037"}, "book-100", "XBT/USD"]
[271, [["11871.40000", "0.33819415", "1596736924.398573", "s", "l", ""], ["11871.40000", "0.08630585", "1596736924.441967", "s", "l", ""]], "trade", "XBT/USD"]
[270, {"b": [["11871.40000", "0.17324791", "1596736924.398573"], ["11871.40000", "0.08694206", "1596736924.441967"]], "c": "115763359"}, "book-100", "XBT/USD"]
[270, {"a": [["11872.90000", "0.70000000", "1596736924.507075"]], "c": "2217006445"}, "book-100", "XBT/USD"]
[270, {"b": [["11871.00000", "0.00000000", "1596736924.710036"], ["11817.20000", "1.51500000", "1596736326.967282", "r"]], "c": "1271348610"}, "book-100", "XBT/USD"]
[270, {"b": [["11871.30000", "0.12000000", "1596736924.754070"]], "c": "4152269774"}, "book-100", "XBT/USD"]
[270, {"b": [["11871.40000", "0.07324791", "1596736924.767678"]], "c": "1367927132"}, "book-100", "XBT/USD"]
[270, {"b": [["11856.70000", "0.33677777", "1596736924.768334"]], "c": "1367927132"}, "book-100", "XBT/USD"]
[270, {"a": [["11872.90000", "0.00000000", "1596736924.773680"], ["11909.90000", "6.20000000", "1596736825.518690", "r"]], "c": "3544863918"}, "book-100", "XBT/USD"]
[270, {"a": [["11871.50000", "2.79143952", "1596736924.820191"]], "c": "3740481691"}, "book-100", "XBT/USD"]
[270, {"b": [["11871.40000", "0.17324791", "1596736925.268740"]], "c": "2049759874"}, "book-100", "XBT/USD"]
[270, {"a": [["11878.30000", "0.00000000", "1596736925.288087"], ["11910.00000", "0.36067000", "1596736874.546981", "r"]], "c": "2049759874"}, "book-100", "XBT/USD"]
[270, {"a": [["11877.80000", "1.50000000", "1596736925.476384"]], "c": "2049759874"}, "book-100", "XBT/USD"]
[270, {"a": [["11896.10000", "0.44377564", "1596736925.696464"]], "c": "2049759874"}, "book-100", "XBT/USD"]
[270, {"a": [["11871.50000", "3.08062053", "1596736925.877448"]], "c": "839012521"}, "book-100", "XBT/USD"]
[270, {"a": [["11896.20000", "7.72954712", "1596736925.882289"]], "c": "839012521"}, "book-100", "XBT/USD"]
[270, {"b": [["11866.40000", "0.00000000", "1596736926.277666"], ["11817.60000", "1.06000000", "1596736530.234224", "r"]], "c": "839012521"}, "book-100", "XBT/USD"]
[270, {"a": [["11872.90000", "0.38000000", "1596736926.441273"]], "c": "1718634561"}, "book-100", "XBT/USD"]
[270, {"b": [["11867.40000", "0.04394498", "1596736926.463848"]], "c": "1718634561"}, "book-100", "XBT/USD"]
[270, {"a": [["11872.80000", "0.38000000", "1596736926.541931"]], "c": "298499654"}, "book-100", "XBT/USD"]
[270, {"a": [["11872.90000", "0.00000000", "1596736926.636812"], ["11909.90000", "6.20000000", "1596736825.518690", "r"]], "c": "2412036520"}, "book-100", "XBT/USD"]
[270, {"b": [["11864.80000", "0.00000000", "1596736926.862204"], ["11817.60000", "1.06000000", "1596736530.234224", "r"]], "c": "2412036520"}, "book-100", "XBT/USD"]
[270, {"a": [["11875.50000", "0.23185000", "1596736926.950781"]], "c": "4084083239"}, "book-100", "XBT/USD"]
[270, {"b": [["11866.20000", "0.13183494", "1596736927.089247"]], "c": "4084083239"}, "book-100", "XBT/USD"]
[270, {"a": [["11896.10000", "0.00000000", "1596736927.165760"], ["11910.00000", "0.36067000", "1596736874.546981", "r"]], "c": "4084083239"}, "book-100", "XBT/USD"]
[270, {"a": [["11896.10000", "0.43260743", "1596736927.354526"]], "c": "4084083239"}, "book-100", "XBT/USD"]
[270, {"a": [["11878.70000", "0.00000000", "1596736927.460590"], ["11910.00000", "0.36067000", "1596736874.546981", "r"]], "c": "4084083239"}, "book-100", "XBT/USD"]
[270, {"a": [["11878.10000", "1.67500000", "1596736927.477883"]], "c": "4084083239"}, "book-100", "XBT/USD"]
[270, {"a": [["11878.60000", "0.28399999", "1596736927.629065"]], "c": "4084083239"}, "book-100", "XBT/USD"]
[270, {"a": [["11896.20000", "7.72516526", "1596736927.871721"]], "c": "4084083239"}, "book-100", "XBT/USD"]
[270, {"a": [["11880.30000", "1.48337527", "1596736927.883745"]], "c": "4084083239"}, "book-100", "XBT/USD"]
[270, {"a": [["11905.60000", "0.50000000", "1596736927.920908"]], "c": "4084083239"}, "book-100", "XBT/USD"]
[270, {"a": [["11896.10000", "0.43698929", "1596736928.058652"]], "c": "4084083239"}, "book-100", "XBT/USD"]
[270, {"a": [["11895.70000", "0.00000000", "1596736928.187616"], ["11909.90000", "6.20000000", "1596736825.518690", "r"]], "c": "4084083239"}, "book-100", "XBT/USD"]
[270, {"b": [["11839.20000", "0.00000000", "1596736928.353424"], ["11817.60000", "1.06000000", "1596736530.234224", "r"]], "c": "4084083239"}, "book-100", "XBT/USD"]
[270, {"b": [["11837.80000", "5.92029121", "1596736928.436680"]], "c": "4084083239"}, "book-100", "XBT/USD"]
[270, {"a": [["11890.60000", "5.54718762", "1596736928.514145"]], "c": "4084083239"}, "book-100", "XBT/USD"]
[270, {"a": [["11884.60000", "3.78671816", "1596736928.529404"]], "c": "4084083239"}, "book-100", "XBT/USD"]
[270, {"a": [["11896.10000", "0.43260743", "1596736928.564905"]], "c": "4084083239"}, "book-100", "XBT/USD"]
[270, {"a": [["11896.20000", "7.72954712", "1596736928.752072"]], "c": "4084083239"}, "book-100", "XBT/USD"]
[270, {"a": [["11896.10000", "0.00000000", "1596736929.919140"], ["11909.90000", "6.20000000", "1596736825.518690", "r"]], "c": "4084083239"}, "book-100", "XBT/USD"]
[270, {"b": [["11871.10000", "0.00000000", "1596736929.971006"], ["11817.60000", "1.06000000", "1596736530.234224", "r"]], "c": "3525402626"}, "book-100", "XBT/USD"]
[270, {"a": [["11873.00000", "0.20000000", "1596736929.972581"]], "c": "2707046737"}, "book-100", "XBT/USD"]
[270, {"a": [["11875.10000", "0.00000000", "1596736929.973884"], ["11910.00000", "0.36067000", "1596736874.546981", "r"]], "c": "3605497008"}, "book-100", "XBT/USD"]
[270, {"b": [["11863.10000", "0.00000000", "1596736929.973999"], ["11817.20000", "1.51500000", "1596736326.967282", "r"]], "c": "3605497008"}, "book-100", "XBT/USD"]
[270, {"a": [["11887.30000", "5.40000000", "1596736929.976836"]], "c": "3605497008"}, "book-100", "XBT/USD"]
[270, {"b": [["11856.90000", "0.94575826", "1596736929.977075"]], "c": "3605497008"}, "book-100", "XBT/USD"]
[270, {"a": [["11891.30000", "0.00000000", "1596736929.979361"], ["11910.20000", "0.02327607", "1596736875.192355", "r"]], "c": "3605497008"}, "book-100", "XBT/USD"]
[270, {"b": [["11857.70000", "0.00000000", "1596736929.979512"], ["11816.10000", "0.01263535", "1596736919.000104", "r"]], "c": "3605497008"}, "book-100", "XBT/USD"]
[270, {"a": [["11894.80000", "0.00000000", "1596736929.979771"], ["11910.50000", "1.68800000", "1596736473.841014", "r"]], "c": "3605497008"}, "book-100", "XBT/USD"]
[270, {"b": [["11870.50000", "0.00000000", "1596736929.980381"], ["11816.00000", "7.80000000", "1596736853.219959", "r"]], "c": "3124171984"}, "book-100", "XBT/USD"]
[270, {"a": [["11879.00000", "0.00000000", "1596736929.981175"], ["11910.80000", "2.17882206", "1596736882.030413", "r"]], "c": "3124171984"}, "book-100", "XBT/USD"]
[270, {"b": [["11860.80000", "0.49341154", "1596736929.982378"]], "c": "3124171984"}, "book-100", "XBT/USD"]
[270, {"b": [["11864.40000", "0.00000000", "1596736929.983109"], ["11815.00000", "0.15000000", "1596736658.818582", "r"]], "c": "3124171984"}, "book-100", "XBT/USD"]
[270, {"b": [["11868.60000", "1.68200000", "1596736929.984106"]], "c": "1866513288"}, "book-100", "XBT/USD"]
[270, {"b": [["11870.10000", "0.17579500", "1596736929.989348"]], "c": "1069005038"}, "book-100", "XBT/USD"]
[270, {"a": [["11874.20000", "1.00408000", "1596736929.989987"]], "c": "3554831106"}, "book-100", "XBT/USD"]
[270, {"b": [["11862.50000", "0.09621094", "1596736929.990966"]], "c": "3554831106"}, "book-100", "XBT/USD"]
[270, {"a": [["11878.10000", "0.00000000", "1596736929.991084"], ["11910.80000", "2.17882206", "1596736882.030413", "r"]], "c": "3554831106"}, "book-100", "XBT/USD"]
[270, {"a": [["11875.70000", "0.00000000", "1596736929.993344"], ["11911.20000", "0.73325384", "1596736529.292490", "r"]], "c": "3554831106"}, "book-100", "XBT/USD"]
[270, {"a": [["11877.00000", "1.68100000", "1596736929.994573"]], "c": "3554831106"}, "book-100", "XBT/USD"]
[270, {"a": [["11896.20000", "7.72516526", "1596736930.004208"]], "c": "3554831106"}, "book-100", "XBT/USD"]
[270, {"a": [["11872.70000", "0.70000000", "1596736930.028798"]], "c": "1957277275"}, "book-100", "XBT/USD"]
[270, {"a": [["11872.50000", "0.63151990", "1596736930.062913"]], "c": "3161693246"}, "book-100", "XBT/USD"]
[270, {"a": [["11876.20000", "0.84202654", "1596736930.065082"]], "c": "3161693246"}, "book-100", "XBT/USD"]
[270, {"b": [["11869.90000", "0.25260796", "1596736930.066089"]], "c": "2770982756"}, "book-100", "XBT/USD"]
[270, {"b": [["11869.30000", "0.25260796", "1596736930.071630"]], "c": "746852449"}, "book-100", "XBT/USD"]
[270, {"a": [["11871.90000", "0.63151990", "1596736930.073590"]], "c": "882230385"}, "book-100", "XBT/USD"]
[270, {"a": [["11872.70000", "0.00000000", "1596736930.082327"], ["11910.00000", "0.36067000", "1596736874.546981", "r"]], "c": "2244554603"}, "book-100", "XBT/USD"]
[270, {"a": [["11871.50000", "3.32062053", "1596736930.096643"]], "c": "2225135161"}, "book-100", "XBT/USD"]
[270, {"a": [["11909.80000", "2.10751275", "1596736930.118143"]], "c": "2225135161"}, "book-100", "XBT/USD"]
[270, {"b": [["11871.30000", "0.00000000", "1596736930.119125"], ["11817.20000", "1.51500000", "1596736326.967282", "r"]], "c": "2969760251"}, "book-100", "XBT/USD"]
[270, {"a": [["11898.80000", "0.56878156", "1596736930.120815"]], "c": "2969760251"}, "book-100", "XBT/USD"]
[270, {"a": [["11871.80000", "0.70000000", "1596736930.129497"]], "c": "1427007013"}, "book-100", "XBT/USD"]
[270, {"b": [["11868.50000", "0.00000000", "1596736930.151349"], ["11816.10000", "0.01263535", "1596736919.000104", "r"]], "c": "1973515866"}, "book-100", "XBT/USD"]
[270, {"a": [["11872.80000", "0.00500000", "1596736930.164863"]], "c": "1658785014"}, "book-100", "XBT/USD"]
[270, {"a": [["11871.80000", "0.00000000", "1596736930.180921"], ["11909.80000", "2.10751275", "1596736930.118143", "r"]], "c": "1799694128"}, "book-100", "XBT/USD"]
[270, {"a": [["11874.70000", "0.25000000", "1596736930.189557"]], "c": "274666234"}, "book-100", "XBT/USD"]
[270, {"a": [["11881.90000", "6.60000000", "1596736930.215290"]], "c": "274666234"}, "book-100", "XBT/USD"]
[270, {"a": [["11896.00000", "0.00438186", "1596736930.226712"]], "c": "274666234"}, "book-100", "XBT/USD"]
[270, {"a": [["11880.00000", "1.32496074", "1596736930.247095"]], "c": "274666234"}, "book-100", "XBT/USD"]
[270, {"b": [["11860.10000", "0.42704990", "1596736930.283440"]], "c": "274666234"}, "book-100", "XBT/USD"]
[270, {"a": [["11898.80000", "0.00000000", "1596736930.324925"], ["11908.90000", "1.06880000", "1596736841.521829", "r"]], "c": "274666234"}, "book-100", "XBT/USD"]
[270, {"b": [["11857.40000", "0.00000000", "1596736930.328748"], ["11816.00000", "7.80000000", "1596736853.219959", "r"]], "c": "274666234"}, "book-100", "XBT/USD"]
[270, {"b": [["11859.50000", "0.53027587", "1596736930.458876"]], "c": "274666234"}, "book-100", "XBT/USD"]
[270, {"a": [["11894.60000", "0.69171150", "1596736930.467873"]], "c": "274666234"}, "book-100", "XBT/USD"]
[270, {"b": [["11859.80000", "0.69374117", "1596736930.468140"]], "c": "274666234"}, "book-100", "XBT/USD"]
[270, {"b": [["11863.90000", "0.00000000", "1596736930.498529"], ["11816.00000", "7.80000000", "1596736853.219959", "r"]], "c": "274666234"}, "book-100", "XBT/USD"]
[270, {"b": [["11871.40000", "0.10000000", "1596736930.564482"]], "c": "3955490764"}, "book-100", "XBT/USD"]
[270, {"b": [["11865.60000", "2.90687502", "1596736930.590016"]], "c": "3955490764"}, "book-100", "XBT/USD"]
[270, {"b": [["11816.10000", "0.00000000", "1596736930.601837"], ["11816.00000", "7.80000000", "1596736853.219959", "r"]], "c": "3955490764"}, "book-100", "XBT/USD"]
[270, {"a": [["11871.50000", "3.72062053", "1596736930.633078"]], "c": "2721836008"}, "book-100", "XBT/USD"]
[270, {"a": [["11891.10000", "0.32948338", "1596736930.633544"]], "c": "2721836008"}, "book-100", "XBT/USD"]
[270, {"b": [["11869.90000", "0.00000000", "1596736930.633647"], ["11815.00000", "0.15000000", "1596736658.818582", "r"]], "c": "2238409058"}, "book-100", "XBT/USD"]
[270, {"a": [["11886.20000", "0.00000000", "1596736930.697549"], ["11908.40000", "0.94149879", "1596736824.171595", "r"]], "c": "2238409058"}, "book-100", "XBT/USD"]
[270, {"a": [["11901.40000", "0.00000000", "1596736930.700523"], ["11908.90000", "1.06880000", "1596736841.521829", "r"]], "c": "2238409058"}, "book-100", "XBT/USD"]
[270, {"a": [["11885.60000", "0.00000000", "1596736930.720816"], ["11909.10000", "1.00200000", "1596736809.784670", "r"]], "c": "2238409058"}, "book-100", "XBT/USD"]
[270, {"a": [["11886.40000", "0.00000000", "1596736930.721411"], ["11909.80000", "2.10751275", "1596736930.118143", "r"]], "c": "2238409058"}, "book-100", "XBT/USD"]
[270, {"a": [["11902.70000", "0.00000000", "1596736930.724173"], ["11909.90000", "6.20000000", "1596736825.518690", "r"]], "c": "2238409058"}, "book-100", "XBT/USD"]
[270, {"a": [["11899.10000", "1.46274103", "1596736930.727291"]], "c": "2238409058"}, "book-100", "XBT/USD"]
[270, {"b": [["11869.00000", "0.00000000", "1596736930.728741"], ["11814.70000", "15.09669614", "1596736905.495230", "r"]], "c": "3758073343"}, "book-100", "XBT/USD"]
[270, {"a": [["11899.10000", "0.70000000", "1596736930.741441"]], "c": "3758073343"}, "book-100", "XBT/USD"]
[270, {"b": [["11860.70000", "0.00000000", "1596736930.761201"], ["11813.30000", "0.99420000", "1596736809.783550", "r"]], "c": "3758073343"}, "book-100", "XBT/USD"]
[270, {"a": [["11901.30000", "0.00000000", "1596736930.763609"], ["11910.00000", "0.36067000", "1596736874.546981", "r"]], "c": "3758073343"}, "book-100", "XBT/USD"]
[270, {"a": [["11881.10000", "0.00000000", "1596736930.766296"], ["11910.20000", "0.02327607", "1596736875.192355", "r"]], "c": "3758073343"}, "book-100", "XBT/USD"]
[270, {"b": [["11857.80000", "0.87601000", "1596736930.767816"]], "c": "3758073343"}, "book-100", "XBT/USD"]
[270, {"b": [["11866.30000", "4.20600000", "1596736930.780033"]], "c": "3758073343"}, "book-100", "XBT/USD"]
[270, {"a": [["11875.80000", "0.00000000", "1596736930.801277"], ["11910.50000", "1.68800000", "1596736473.841014", "r"]], "c": "3758073343"}, "book-100", "XBT/USD"]
[270, {"b": [["11868.60000", "0.00000000", "1596736930.822229"], ["11814.70000", "15.09669614", "1596736905.495230", "r"]], "c": "2089692516"}, "book-100", "XBT/USD"]
[270, {"a": [["11874.70000", "0.00000000", "1596736930.826661"], ["11910.80000", "2.17882206", "1596736882.030413", "r"]], "c": "3017260619"}, "book-100", "XBT/USD"]
[270, {"b": [["11820.70000", "4.33493005", "1596736930.857853"]], "c": "3017260619"}, "book-100", "XBT/USD"]
[270, {"b": [["11820.50000", "0.00000000", "1596736930.864215"], ["11813.30000", "0.99420000", "1596736809.783550", "r"]], "c": "3017260619"}, "book-100", "XBT/USD"]
[270, {"a": [["11871.50000", "4.59663053", "1596736930.925013"]], "c": "674406849"}, "book-100", "XBT/USD"]
[270, {"a": [["11873.70000", "4.20400000", "1596736930.929707"]], "c": "2547538777"}, "book-100", "XBT/USD"]
[270, {"a": [["11884.40000", "0.04395142", "1596736930.936988"]], "c": "2547538777"}, "book-100", "XBT/USD"]
[270, {"a": [["11896.70000", "0.00000000", "1596736930.938220"], ["11910.50000", "1.68800000", "1596736473.841014", "r"]], "c": "2547538777"}, "book-100", "XBT/USD"]
[270, {"a": [["11885.80000", "0.00000000", "1596736930.941374"], ["11910.80000", "2.17882206", "1596736882.030413", "r"]], "c": "2547538777"}, "book-100", "XBT/USD"]
[270, {"a": [["11873.40000", "0.00000000", "1596736930.941795"], ["11911.20000", "0.73325384", "1596736529.292490", "r"]], "c": "1979758898"}, "book-100", "XBT/USD"]
[270, {"a": [["11896.70000", "0.76285221", "1596736930.951985"]], "c": "1979758898"}, "book-100", "XBT/USD"]
[270, {"a": [["11874.60000", "0.18441000", "1596736930.967519"]], "c": "4112161722"}, "book-100", "XBT/USD"]
[270, {"b": [["11854.80000", "0.00000000", "1596736930.975282"], ["11811.70000", "5.70000000", "1596736886.902857", "r"]], "c": "4112161722"}, "book-100", "XBT/USD"]
[270, {"a": [["11905.70000", "0.00000000", "1596736930.981824"], ["11910.80000", "2.17882206", "1596736882.030413", "r"]], "c": "4112161722"}, "book-100", "XBT/USD"]
[270, {"b": [["11858.10000", "0.00000000", "1596736930.987424"], ["11811.00000", "0.17065000", "1596736517.833952", "r"]], "c": "4112161722"}, "book-100", "XBT/USD"]
[270, {"a": [["11895.70000", "0.44141259", "1596736930.987847"]], "c": "4112161722"}, "book-100", "XBT/USD"]
[270, {"a": [["11905.50000", "0.00000000", "1596736930.988568"], ["11910.80000", "2.17882206", "1596736882.030413", "r"]], "c": "4112161722"}, "book-100", "XBT/USD"]
[270, {"b": [["11863.20000", "0.33025826", "1596736930.990101"]], "c": "4112161722"}, "book-100", "XBT/USD"]
[270, {"a": [["11874.70000", "0.18441000", "1596736931.008794"]], "c": "1907945737"}, "book-100", "XBT/USD"]
[270, {"a": [["11885.00000", "0.13185425", "1596736931.010744"]], "c": "1907945737"}, "book-100", "XBT/USD"]
[270, {"b": [["11857.10000", "0.22758788", "1596736931.063812"]], "c": "1907945737"}, "book-100", "XBT/USD"]
[270, {"b": [["11856.00000", "0.00000000", "1596736931.089189"], ["11811.00000", "0.17065000", "1596736517.833952", "r"]], "c": "1907945737"}, "book-100", "XBT/USD"]
[270, {"a": [["11883.70000", "0.00000000", "1596736931.101308"], ["11910.50000", "1.68800000", "1596736473.841014", "r"]], "c": "1907945737"}, "book-100", "XBT/USD"]
[270, {"a": [["11882.80000", "0.00000000", "1596736931.103901"], ["11910.80000", "2.17882206", "1596736882.030413", "r"]], "c": "1907945737"}, "book-100", "XBT/USD"]
[270, {"a": [["11898.80000", "0.52823572", "1596736931.126661"]], "c": "1907945737"}, "book-100", "XBT/USD"]
[270, {"a": [["11898.90000", "0.00000000", "1596736931.152655"], ["11910.80000", "2.17882206", "1596736882.030413", "r"]], "c": "1907945737"}, "book-100", "XBT/USD"]
[270, {"a": [["11902.40000", "0.00000000", "1596736931.161872"], ["11911.20000", "0.73325384", "1596736529.292490", "r"]], "c": "1907945737"}, "book-100", "XBT/USD"]
[270, {"a": [["11895.70000", "0.00000000", "1596736931.175279"], ["11913.00000", "0.17065000", "1596736890.849460", "r"]], "c": "1907945737"}, "book-100", "XBT/USD"]
[270, {"a": [["11908.10000", "0.00000000", "1596736931.182010"], ["11913.80000", "0.05459718", "1596736605.097915", "r"]], "c": "1907945737"}, "book-100", "XBT/USD"]
[270, {"a": [["11898.50000", "3.26340097", "1596736931.187119"]], "c": "1907945737"}, "book-100", "XBT/USD"]
[270, {"a": [["11897.50000", "0.00000000", "1596736931.191234"], ["11913.80000", "0.05459718", "1596736605.097915", "r"]], "c": "1907945737"}, "book-100", "XBT/USD"]
[270, {"a": [["11887.20000", "0.00000000", "1596736931.201608"], ["11913.90000", "3.25918268", "1596736931.174304", "r"]], "c": "1907945737"}, "book-100", "XBT/USD"]
[270, {"a": [["11908.40000", "0.00000000", "1596736931.203934"], ["11914.10000", "7.98435073", "1596736764.864707", "r"]], "c": "1907945737"}, "book-100", "XBT/USD"]
[270, {"a": [["11871.50000", "4.84663053", "1596736931.287292"]], "c": "1772509338"}, "book-100", "XBT/USD"]
[270, {"a": [["11873.00000", "0.00000000", "1596736931.290190"], ["11914.20000", "0.94104473", "1596736858.033785", "r"]], "c": "2036939779"}, "book-100", "XBT/USD"]
[270, {"a": [["11893.80000", "0.10902566", "1596736931.301594"]], "c": "2036939779"}, "book-100", "XBT/USD"]
[270, {"a": [["11902.10000", "1.27471069", "1596736931.305089"]], "c": "2036939779"}, "book-100", "XBT/USD"]
[270, {"a": [["11874.70000", "0.00000000", "1596736931.306739"], ["11914.10000", "7.98435073", "1596736764.864707", "r"]], "c": "1978698499"}, "book-100", "XBT/USD"]
[270, {"a": [["11901.90000", "2.18025850", "1596736931.319769"]], "c": "1978698499"}, "book-100", "XBT/USD"]
[270, {"a": [["11883.90000", "0.00000000", "1596736931.390391"], ["11914.10000", "7.98435073", "1596736764.864707", "r"]], "c": "1978698499"}, "book-100", "XBT/USD"]
[270, {"a": [["11896.00000", "0.94677356", "1596736931.400174"]], "c": "1978698499"}, "book-100", "XBT/USD"]
[270, {"a": [["11896.20000", "7.92906962", "1596736931.420828"]], "c": "1978698499"}, "book-100", "XBT/USD"]
[270, {"a": [["11899.70000", "0.28538214", "1596736931.422511"]], "c": "1978698499"}, "book-100", "XBT/USD"]
[270, {"a": [["11904.50000", "2.22195284", "1596736931.436247"]], "c": "1978698499"}, "book-100", "XBT/USD"]
[270, {"a": [["11894.10000", "0.00000000", "1596736931.436331"], ["11914.10000", "7.98435073", "1596736764.864707", "r"]], "c": "1978698499"}, "book-100", "XBT/USD"]
[270, {"a": [["11882.90000", "0.01800000", "1596736931.439407"]], "c": "1978698499"}, "book-100", "XBT/USD"]
[270, {"a": [["11908.00000", "0.00000000", "1596736931.462104"], ["11914.10000", "7.98435073", "1596736764.864707", "r"]], "c": "1978698499"}, "book-100", "XBT/USD"]
[270, {"a": [["11899.60000", "0.94210660", "1596736931.462972"]], "c": "1978698499"}, "book-100", "XBT/USD"]
[270, {"a": [["11886.70000", "0.67600628", "1596736931.687589"]], "c": "1978698499"}, "book-100", "XBT/USD"]
[270, {"a": [["11885.20000", "1.04962971", "1596736931.735346"]], "c": "1978698499"}, "book-100", "XBT/USD"]
[270, {"a": [["11872.60000", "0.18453000", "1596736931.735799"]], "c": "3341112776"}, "book-100", "XBT/USD"]
[270, {"a": [["11904.50000", "0.46865305", "1596736931.759833"]], "c": "3341112776"}, "book-100", "XBT/USD"]
[270, {"b": [["11859.50000", "0.42095515", "1596736931.770066"]], "c": "3341112776"}, "book-100", "XBT/USD"]
[270, {"a": [["11891.10000", "0.00000000", "1596736931.786086"], ["11913.00000", "0.17065000", "1596736890.849460", "r"]], "c": "3341112776"}, "book-100", "XBT/USD"]
[270, {"b": [["11863.20000", "0.00000000", "1596736931.789322"], ["11808.80000", "2.66090576", "1596736784.110515", "r"]], "c": "3341112776"}, "book-100", "XBT/USD"]
[270, {"a": [["11894.60000", "0.00000000", "1596736931.800061"], ["11913.80000", "0.05459718", "1596736605.097915", "r"]], "c": "3341112776"}, "book-100", "XBT/USD"]
[270, {"b": [["11859.80000", "0.00000000", "1596736931.800894"], ["11808.00000", "0.17065000", "1596736558.844046", "r"]], "c": "3341112776"}, "book-100", "XBT/USD"]
[270, {"a": [["11907.40000", "0.00000000", "1596736931.862114"], ["11913.90000", "3.25918268", "1596736931.174304", "r"]], "c": "3341112776"}, "book-100", "XBT/USD"]
[270, {"a": [["11904.80000", "0.00000000", "1596736931.867502"], ["11914.10000", "7.98435073", "1596736764.864707", "r"]], "c": "3341112776"}, "book-100", "XBT/USD"]
[270, {"a": [["11903.60000", "0.94179002", "1596736931.891564"]], "c": "3341112776"}, "book-100", "XBT/USD"]
[270, {"b": [["11857.00000", "0.87481330", "1596736931.956812"]], "c": "3341112776"}, "book-100", "XBT/USD"]
[270, {"a": [["11885.20000", "0.00000000", "1596736931.983489"], ["11914.10000", "7.98435073", "1596736764.864707", "r"]], "c": "3341112776"}, "book-100", "XBT/USD"]
[270, {"a": [["11874.20000", "1.25408000", "1596736932.085075"]], "c": "3121909444"}, "book-100", "XBT/USD"]
[270, {"a": [["11904.30000", "4.05598333", "1596736932.236426"]], "c": "3121909444"}, "book-100", "XBT/USD"]
[270, {"a": [["11884.30000", "1.04962971", "1596736932.605606"]], "c": "3121909444"}, "book-100", "XBT/USD"]
[270, {"a": [["11875.90000", "1.67700000", "1596736932.610684"]], "c": "3121909444"}, "book-100", "XBT/USD"]
[270, {"a": [["11872.60000", "0.00000000", "1596736932.614189"], ["11913.90000", "3.25918268", "1596736931.174304", "r"]], "c": "2302324128"}, "book-100", "XBT/USD"]
[270, {"a": [["11877.00000", "0.00000000", "1596736932.615767"], ["11914.10000", "7.98435073", "1596736764.864707", "r"]], "c": "2302324128"}, "book-100", "XBT/USD"]
[270, {"b": [["11867.50000", "1.68100000", "1596736932.620335"]], "c": "659145353"}, "book-100", "XBT/USD"]
[270, {"a": [["11886.10000", "0.00500329", "1596736932.661702"]], "c": "659145353"}, "book-100", "XBT/USD"]
[270, {"b": [["11861.50000", "0.09800000", "1596736932.706987"]], "c": "659145353"}, "book-100", "XBT/USD"]
[270, {"a": [["11871.80000", "0.70000000", "1596736932.760204"]], "c": "375266131"}, "book-100", "XBT/USD"]
[270, {"a": [["11898.90000", "0.73583472", "1596736932.902886"]], "c": "375266131"}, "book-100", "XBT/USD"]
[270, {"b": [["11838.40000", "6.00000000", "1596736932.904106"]], "c": "375266131"}, "book-100", "XBT/USD"]
[270, {"a": [["11900.10000", "0.00000000", "1596736932.904892"], ["11913.90000", "3.25918268", "1596736931.174304", "r"]], "c": "375266131"}, "book-100", "XBT/USD"]
[270, {"b": [["11839.30000", "2.65927150", "1596736932.908617"]], "c": "375266131"}, "book-100", "XBT/USD"]
[270, {"a": [["11875.90000", "0.00000000", "1596736932.941014"], ["11914.10000", "7.98435073", "1596736764.864707", "r"]], "c": "375266131"}, "book-100", "XBT/USD"]
[270, {"a": [["11871.80000", "0.00000000", "1596736932.987876"], ["11914.20000", "0.94104473", "1596736858.033785", "r"]], "c": "659145353"}, "book-100", "XBT/USD"]
[270, {"a": [["11913.80000", "1.96193224", "1596736933.165106"]], "c": "659145353"}, "book-100", "XBT/USD"]
[270, {"a": [["11901.90000", "3.92491075", "1596736933.165941"]], "c": "659145353"}, "book-100", "XBT/USD"]
[270, {"a": [["11890.10000", "0.32950636", "1596736933.172753"]], "c": "659145353"}, "book-100", "XBT/USD"]
[270, {"b": [["11860.70000", "0.33032313", "1596736933.172963"]], "c": "659145353"}, "book-100", "XBT/USD"]
[270, {"b": [["11857.30000", "2.09158095", "1596736933.175300"]], "c": "659145353"}, "book-100", "XBT/USD"]
[270, {"a": [["11895.90000", "1.38325194", "1596736933.181504"]], "c": "659145353"}, "book-100", "XBT/USD"]
[270, {"a": [["11893.60000", "0.69175972", "1596736933.188110"]], "c": "659145353"}, "book-100", "XBT/USD"]
[270, {"a": [["11873.70000", "5.04611290", "1596736933.199655"]], "c": "3024837438"}, "book-100", "XBT/USD"]
[270, {"b": [["11870.00000", "0.25262441", "1596736933.199848"]], "c": "2495437415"}, "book-100", "XBT/USD"]
[270, {"a": [["11871.50000", "5.47821520", "1596736933.200342"]], "c": "3463449238"}, "book-100", "XBT/USD"]
[270, {"a": [["11872.80000", "0.18956000", "1596736933.268522"]], "c": "3264587430"}, "book-100", "XBT/USD"]
[270, {"a": [["11901.00000", "0.17065000", "1596736933.287606"]], "c": "3264587430"}, "book-100", "XBT/USD"]
[270, {"a": [["11877.80000", "0.00000000", "1596736933.288913"], ["11913.80000", "1.96193224", "1596736933.165106", "r"]], "c": "3264587430"}, "book-100", "XBT/USD"]
[270, {"a": [["11875.30000", "1.66490000", "1596736933.433944"]], "c": "3819074042"}, "book-100", "XBT/USD"]
[270, {"a": [["11872.80000", "0.00500000", "1596736933.627768"]], "c": "3312952570"}, "book-100", "XBT/USD"]
[270, {"a": [["11896.00000", "0.94239170", "1596736933.796891"]], "c": "3312952570"}, "book-100", "XBT/USD"]
[270, {"a": [["11903.60000", "4.20382161", "1596736933.812635"]], "c": "3312952570"}, "book-100", "XBT/USD"]
[270, {"a": [["11872.80000", "0.18955000", "1596736934.269283"]], "c": "664232474"}, "book-100", "XBT/USD"]
[270, {"a": [["11895.80000", "5.72266785", "1596736934.398142"]], "c": "664232474"}, "book-100", "XBT/USD"]
[270, {"b": [["11853.40000", "1.81903751", "1596736934.415064"]], "c": "664232474"}, "book-100", "XBT/USD"]
[270, {"a": [["11897.40000", "0.00000000", "1596736934.446432"], ["11913.90000", "3.25918268", "1596736931.174304", "r"]], "c": "664232474"}, "book-100", "XBT/USD"]
[270, {"a": [["11896.00000", "1.86939170", "1596736934.496613"]], "c": "664232474"}, "book-100", "XBT/USD"]
[270, {"b": [["11857.30000", "1.39770347", "1596736934.729374"]], "c": "664232474"}, "book-100", "XBT/USD"]
[270, {"b": [["11860.70000", "0.00000000", "1596736934.736251"], ["11811.70000", "5.70000000", "1596736886.902857", "r"]], "c": "664232474"}, "book-100", "XBT/USD"]
[270, {"a": [["11913.30000", "6.18341193", "1596736935.389729"]], "c": "664232474"}, "book-100", "XBT/USD"]
[270, {"a": [["11910.20000", "0.00000000", "1596736935.391007"], ["11913.90000", "3.25918268", "1596736931.174304", "r"]], "c": "664232474"}, "book-100", "XBT/USD"]
[270, {"b": [["11858.80000", "1.07378971", "1596736935.508886"]], "c": "664232474"}, "book-100", "XBT/USD"]
[270, {"b": [["11862.20000", "0.33028136", "1596736935.509988"]], "c": "664232474"}, "book-100", "XBT/USD"]
[270, {"a": [["11890.60000", "0.00000000", "1596736935.587115"], ["11914.10000", "7.98435073", "1596736764.864707", "r"]], "c": "664232474"}, "book-100", "XBT/USD"]
[270, {"a": [["11887.20000", "5.54914826", "1596736935.682053"]], "c": "664232474"}, "book-100", "XBT/USD"]
[270, {"a": [["11910.50000", "1.71128370", "1596736935.716439"]], "c": "664232474"}, "book-100", "XBT/USD"]
[270, {"a": [["11910.80000", "0.00000000", "1596736935.793842"], ["11914.10000", "7.98435073", "1596736764.864707", "r"]], "c": "664232474"}, "book-100", "XBT/USD"]
[270, {"a": [["11890.10000", "0.00000000", "1596736935.809508"], ["11914.20000", "0.94104473", "1596736858.033785", "r"]], "c": "664232474"}, "book-100", "XBT/USD"]
[270, {"a": [["11904.20000", "0.00000000", "1596736935.809986"], ["11914.40000", "0.75800000", "1596736271.459783", "r"]], "c": "664232474"}, "book-100", "XBT/USD"]
[270, {"b": [["11870.00000", "0.00000000", "1596736935.813544"], ["11811.70000", "5.70000000", "1596736886.902857", "r"]], "c": "4161341638"}, "book-100", "XBT/USD"]
[270, {"a": [["11895.90000", "0.00000000", "1596736935.813700"], ["11914.70000", "0.30000000", "1596736822.699485", "r"]], "c": "4161341638"}, "book-100", "XBT/USD"]
[270, {"a": [["11893.60000", "0.00000000", "1596736935.814517"], ["11915.00000", "0.04000000", "1596736479.420327", "r"]], "c": "4161341638"}, "book-100", "XBT/USD"]
[270, {"a": [["11872.80000", "0.00500000", "1596736935.836467"]], "c": "2696281103"}, "book-100", "XBT/USD"]
[270, {"a": [["11896.70000", "0.00000000", "1596736935.840084"], ["11916.00000", "0.17065000", "1596736840.242690", "r"]], "c": "2696281103"}, "book-100", "XBT/USD"]
[270, {"a": [["11871.80000", "0.70000000", "1596736935.866431"]], "c": "1445196898"}, "book-100", "XBT/USD"]
[270, {"b": [["11855.10000", "0.33685110", "1596736935.873117"]], "c": "1445196898"}, "book-100", "XBT/USD"]
[270, {"b": [["11870.10000", "0.00000000", "1596736935.874305"], ["11811.70000", "5.70000000", "1596736886.902857", "r"]], "c": "2780305842"}, "book-100", "XBT/USD"]
[270, {"b": [["11871.20000", "0.00000000", "1596736935.874397"], ["11811.00000", "0.17065000", "1596736517.833952", "r"]], "c": "985863929"}, "book-100", "XBT/USD"]
[270, {"b": [["11863.30000", "0.00000000", "1596736935.877462"], ["11808.80000", "2.66090576", "1596736784.110515", "r"]], "c": "985863929"}, "book-100", "XBT/USD"]
[270, {"a": [["11883.60000", "2.00000000", "1596736935.880562"]], "c": "985863929"}, "book-100", "XBT/USD"]
[270, {"a": [["11883.50000", "0.00000000", "1596736935.897227"], ["11915.00000", "0.04000000", "1596736479.420327", "r"]], "c": "985863929"}, "book-100", "XBT/USD"]
[270, {"b": [["11851.90000", "0.23800000", "1596736935.926609"]], "c": "985863929"}, "book-100", "XBT/USD"]
[270, {"a": [["11872.20000", "0.19052000", "1596736935.929906"]], "c": "2048071865"}, "book-100", "XBT/USD"]
[270, {"a": [["11874.20000", "1.00408000", "1596736935.956376"]], "c": "1921700703"}, "book-100", "XBT/USD"]
[270, {"a": [["11901.90000", "1.74465225", "1596736935.956964"]], "c": "1921700703"}, "book-100", "XBT/USD"]
[270, {"a": [["11901.90000", "0.00000000", "1596736935.959784"], ["11915.00000", "0.04000000", "1596736479.420327", "r"]], "c": "1921700703"}, "book-100", "XBT/USD"]
[270, {"a": [["11881.20000", "2.48256172", "1596736935.960824"]], "c": "1921700703"}, "book-100", "XBT/USD"]
[270, {"a": [["11885.30000", "0.01000000", "1596736935.969196"]], "c": "1921700703"}, "book-100", "XBT/USD"]
[270, {"a": [["11899.70000", "0.00000000", "1596736935.970192"], ["11916.00000", "0.17065000", "1596736840.242690", "r"]], "c": "1921700703"}, "book-100", "XBT/USD"]
[270, {"a": [["11896.20000", "7.72516526", "1596736935.970659"]], "c": "1921700703"}, "book-100", "XBT/USD"]
[270, {"a": [["11880.00000", "0.70000000", "1596736935.978537"]], "c": "1921700703"}, "book-100", "XBT/USD"]
[270, {"a": [["11871.80000", "0.00000000", "1596736935.981350"], ["11916.50000", "0.00204079", "1596736766.937570", "r"]], "c": "4203035699"}, "book-100", "XBT/USD"]
[270, {"a": [["11898.80000", "0.00000000", "1596736935.988345"], ["11917.00000", "1.61047031", "1596736881.952678", "r"]], "c": "4203035699"}, "book-100", "XBT/USD"]
[270, {"a": [["11898.50000", "0.00000000", "1596736935.994057"], ["11917.80000", "2.20849499", "1596736930.931763", "r"]], "c": "4203035699"}, "book-100", "XBT/USD"]
[270, {"a": [["11893.80000", "0.00000000", "1596736935.997632"], ["11918.50000", "5.50000000", "1596736026.861456", "r"]], "c": "4203035699"}, "book-100", "XBT/USD"]
[270, {"b": [["11858.90000", "0.00000000", "1596736936.004280"], ["11808.80000", "2.66090576", "1596736784.110515", "r"]], "c": "4203035699"}, "book-100", "XBT/USD"]
[270, {"a": [["11899.60000", "0.00000000", "1596736936.056071"], ["11919.00000", "5.34781199", "1596736931.753226", "r"]], "c": "4203035699"}, "book-100", "XBT/USD"]
[270, {"b": [["11857.10000", "0.20458788", "1596736936.057121"]], "c": "4203035699"}, "book-100", "XBT/USD"]
[270, {"a": [["11882.90000", "0.00000000", "1596736936.057402"], ["11919.40000", "0.01076304", "1596736829.804607", "r"]], "c": "4203035699"}, "book-100", "XBT/USD"]
[270, {"b": [["11867.50000", "0.00000000", "1596736936.060152"], ["11808.00000", "0.17065000", "1596736558.844046", "r"]], "c": "510142503"}, "book-100", "XBT/USD"]
[270, {"a": [["11873.80000", "0.25000000", "1596736936.128159"]], "c": "3601744317"}, "book-100", "XBT/USD"]
[270, {"a": [["11880.30000", "0.64182575", "1596736936.171369"]], "c": "3601744317"}, "book-100", "XBT/USD"]
[270, {"a": [["11890.50000", "0.69194007", "1596736936.237394"]], "c": "3601744317"}, "book-100", "XBT/USD"]
[270, {"a": [["11884.60000", "0.00000000", "1596736936.259683"], ["11919.00000", "5.34781199", "1596736931.753226", "r"]], "c": "3601744317"}, "book-100", "XBT/USD"]
[270, {"b": [["11866.20000", "0.00000000", "1596736936.260513"], ["11807.70000", "3.28855406", "1596736821.611246", "r"]], "c": "1954089100"}, "book-100", "XBT/USD"]
[270, {"a": [["11904.80000", "2.17974464", "1596736936.262385"]], "c": "1954089100"}, "book-100", "XBT/USD"]
[270, {"a": [["11880.80000", "0.69317951", "1596736936.263119"]], "c": "1954089100"}, "book-100", "XBT/USD"]
[270, {"a": [["11902.10000", "0.00000000", "1596736936.264107"], ["11918.50000", "5.50000000", "1596736026.861456", "r"]], "c": "1954089100"}, "book-100", "XBT/USD"]
[270, {"b": [["11867.40000", "0.00000000", "1596736936.266321"], ["11807.50000", "2.19772556", "1596736916.776430", "r"]], "c": "1951942211"}, "book-100", "XBT/USD"]
[270, {"a": [["11914.20000", "0.00000000", "1596736936.266737"], ["11919.00000", "5.34781199", "1596736931.753226", "r"]], "c": "1951942211"}, "book-100", "XBT/USD"]
[270, {"a": [["11893.20000", "0.76321813", "1596736936.267812"]], "c": "1951942211"}, "book-100", "XBT/USD"]
[270, {"a": [["11872.20000", "0.00000000", "1596736936.272992"], ["11919.00000", "5.34781199", "1596736931.753226", "r"]], "c": "1789666139"}, "book-100", "XBT/USD"]
[270, {"a": [["11871.50000", "5.79774140", "1596736936.298040"]], "c": "3556690105"}, "book-100", "XBT/USD"]
[270, {"a": [["11873.70000", "0.84211290", "1596736936.337058"]], "c": "2794091467"}, "book-100", "XBT/USD"]
[270, {"a": [["11907.70000", "0.00000000", "1596736936.365641"], ["11919.40000", "0.01076304", "1596736829.804607", "r"]], "c": "2794091467"}, "book-100", "XBT/USD"]
[270, {"a": [["11872.50000", "4.83351990", "1596736936.395860"]], "c": "666764749"}, "book-100", "XBT/USD"]
[270, {"a": [["11878.60000", "1.12592341", "1596736936.402426"]], "c": "666764749"}, "book-100", "XBT/USD"]
[270, {"a": [["11873.10000", "0.19053000", "1596736936.435983"]], "c": "1219646635"}, "book-100", "XBT/USD"]
[270, {"b": [["11858.80000", "0.69378971", "1596736936.443346"]], "c": "1219646635"}, "book-100", "XBT/USD"]
[270, {"a": [["11898.20000", "0.28540722", "1596736936.456466"]], "c": "1219646635"}, "book-100", "XBT/USD"]
[270, {"a": [["11894.70000", "0.50392228", "1596736936.456687"]], "c": "1219646635"}, "book-100", "XBT/USD"]
[270, {"a": [["11892.90000", "1.38360087", "1596736936.489123"]], "c": "1219646635"}, "book-100", "XBT/USD"]
[270, {"a": [["11887.10000", "0.32958951", "1596736936.558005"]], "c": "1219646635"}, "book-100", "XBT/USD"]
[270, {"a": [["11910.00000", "1.30195553", "1596736936.587874"]], "c": "1219646635"}, "book-100", "XBT/USD"]
[270, {"a": [["11892.30000", "0.10903941", "1596736936.592572"]], "c": "1219646635"}, "book-100", "XBT/USD"]
[270, {"a": [["11906.10000", "0.09250000", "1596736936.610343"]], "c": "1219646635"}, "book-100", "XBT/USD"]
[270, {"a": [["11878.10000", "0.41675051", "1596736936.621132"]], "c": "1219646635"}, "book-100", "XBT/USD"]
[270, {"a": [["11873.10000", "0.00000000", "1596736936.624147"], ["11916.00000", "0.17065000", "1596736840.242690", "r"]], "c": "666764749"}, "book-100", "XBT/USD"]
[270, {"a": [["11896.90000", "3.26386867", "1596736936.655768"]], "c": "666764749"}, "book-100", "XBT/USD"]
[270, {"b": [["11857.90000", "0.02300000", "1596736936.686520"]], "c": "666764749"}, "book-100", "XBT/USD"]
[270, {"b": [["11862.20000", "0.00000000", "1596736936.686583"], ["11807.50000", "2.19772556", "1596736916.776430", "r"]], "c": "666764749"}, "book-100", "XBT/USD"]
[270, {"a": [["11896.00000", "0.92700000", "1596736936.704239"]], "c": "666764749"}, "book-100", "XBT/USD"]
[270, {"b": [["11860.10000", "0.41130000", "1596736936.713153"]], "c": "666764749"}, "book-100", "XBT/USD"]
[270, {"b": [["11856.20000", "0.02337356", "1596736936.714098"]], "c": "666764749"}, "book-100", "XBT/USD"]
[270, {"a": [["11872.30000", "0.19053000", "1596736936.714347"]], "c": "1911212943"}, "book-100", "XBT/USD"]
[270, {"a": [["11883.90000", "0.01800000", "1596736936.716417"]], "c": "1911212943"}, "book-100", "XBT/USD"]
[270, {"b": [["11853.60000", "0.38000000", "1596736936.727378"]], "c": "1911212943"}, "book-100", "XBT/USD"]
[270, {"a": [["11900.60000", "1.27487136", "1596736936.728236"]], "c": "1911212943"}, "book-100", "XBT/USD"]
[270, {"a": [["11878.10000", "1.03395490", "1596736936.731513"]], "c": "1911212943"}, "book-100", "XBT/USD"]
[270, {"a": [["11887.10000", "0.00000000", "1596736936.747501"], ["11914.40000", "0.75800000", "1596736271.459783", "r"]], "c": "1911212943"}, "book-100", "XBT/USD"]
[270, {"a": [["11871.80000", "0.70000000", "1596736936.775630"]], "c": "3507412082"}, "book-100", "XBT/USD"]
[270, {"b": [["11869.30000", "0.00000000", "1596736936.809868"], ["11807.70000", "3.28855406", "1596736821.611246", "r"]], "c": "250711842"}, "book-100", "XBT/USD"]
[270, {"a": [["11890.50000", "0.00000000", "1596736936.817557"], ["11914.40000", "0.75800000", "1596736271.459783", "r"]], "c": "250711842"}, "book-100", "XBT/USD"]
[270, {"a": [["11892.90000", "0.00000000", "1596736936.823270"], ["11914.70000", "0.30000000", "1596736822.699485", "r"]], "c": "250711842"}, "book-100", "XBT/USD"]
[270, {"a": [["11898.10000", "0.94222697", "1596736936.841758"]], "c": "250711842"}, "book-100", "XBT/USD"]
[270, {"a": [["11898.30000", "0.52813321", "1596736936.872037"]], "c": "250711842"}, "book-100", "XBT/USD"]
[270, {"a": [["11900.30000", "2.18056890", "1596736936.946756"]], "c": "250711842"}, "book-100", "XBT/USD"]
[270, {"b": [["11856.20000", "0.00000000", "1596736936.956661"], ["11807.50000", "2.19772556", "1596736916.776430", "r"]], "c": "250711842"}, "book-100", "XBT/USD"]
[270, {"b": [["11845.30000", "0.00424954", "1596736937.011322"]], "c": "250711842"}, "book-100", "XBT/USD"]
[270, {"a": [["11894.60000", "0.94250422", "1596736937.110357"]], "c": "250711842"}, "book-100", "XBT/USD"]
[270, {"a": [["11895.80000", "5.30000000", "1596736937.124006"]], "c": "250711842"}, "book-100", "XBT/USD"]
[270, {"b": [["11856.00000", "0.03969316", "1596736937.126970"]], "c": "250711842"}, "book-100", "XBT/USD"]
[270, {"b": [["11860.90000", "0.33031756", "1596736937.132593"]], "c": "250711842"}, "book-100", "XBT/USD"]
[270, {"a": [["11905.60000", "0.00000000", "1596736937.156663"], ["11913.90000", "3.25918268", "1596736931.174304", "r"]], "c": "250711842"}, "book-100", "XBT/USD"]
[270, {"a": [["11880.30000", "0.00000000", "1596736937.158538"], ["11914.10000", "7.98435073", "1596736764.864707", "r"]], "c": "250711842"}, "book-100", "XBT/USD"]
[270, {"a": [["11883.90000", "0.00000000", "1596736937.183280"], ["11914.40000", "0.75800000", "1596736271.459783", "r"]], "c": "250711842"}, "book-100", "XBT/USD"]
[270, {"b": [["11857.90000", "0.00000000", "1596736937.184230"], ["11808.00000", "0.17065000", "1596736558.844046", "r"]], "c": "250711842"}, "book-100", "XBT/USD"]
[270, {"a": [["11881.90000", "6.61800000", "1596736937.233399"]], "c": "250711842"}, "book-100", "XBT/USD"]
[270, {"b": [["11856.10000", "1.06681765", "1596736937.238211"]], "c": "250711842"}, "book-100", "XBT/USD"]
[270, {"a": [["11900.70000", "6.46928730", "1596736937.249530"]], "c": "250711842"}, "book-100", "XBT/USD"]
[270, {"a": [["11895.70000", "0.54554906", "1596736937.315136"]], "c": "250711842"}, "book-100", "XBT/USD"]
[270, {"a": [["11872.30000", "0.00000000", "1596736937.362739"], ["11914.40000", "0.75800000", "1596736271.459783", "r"]], "c": "1231506711"}, "book-100", "XBT/USD"]
[270, {"b": [["11871.40000", "0.00000000", "1596736937.458229"], ["11807.70000", "3.28855406", "1596736821.611246", "r"]], "c": "638617908"}, "book-100", "XBT/USD"]
[270, {"a": [["11879.90000", "0.68203910", "1596736937.461567"]], "c": "638617908"}, "book-100", "XBT/USD"]
[270, {"b": [["11856.10000", "1.04381765", "1596736937.510342"]], "c": "638617908"}, "book-100", "XBT/USD"]
[270, {"a": [["11871.50000", "5.50856039", "1596736937.511741"]], "c": "2504889399"}, "book-100", "XBT/USD"]
[270, {"a": [["11871.50000", "5.29774140", "1596736937.512003"]], "c": "1670665040"}, "book-100", "XBT/USD"]
[270, {"a": [["11870.40000", "0.50000000", "1596736937.513259"]], "c": "535589621"}, "book-100", "XBT/USD"]
[270, {"a": [["11871.80000", "0.00000000", "1596736937.514033"], ["11914.40000", "0.75800000", "1596736271.459783", "r"]], "c": "3782366916"}, "book-100", "XBT/USD"]
[270, {"a": [["11872.40000", "0.19053000", "1596736937.530750"]], "c": "1380800668"}, "book-100", "XBT/USD"]
[270, {"b": [["11856.80000", "0.02300000", "1596736937.563793"]], "c": "1380800668"}, "book-100", "XBT/USD"]
[270, {"a": [["11870.40000", "0.75000000", "1596736937.573882"]], "c": "2414362569"}, "book-100", "XBT/USD"]
[270, {"a": [["11871.50000", "5.04774140", "1596736937.575063"]], "c": "1491697757"}, "book-100", "XBT/USD"]
[270, {"a": [["11912.60000", "6.45782985", "1596736937.577118"]], "c": "1491697757"}, "book-100", "XBT/USD"]
[270, {"a": [["11870.40000", "0.76975816", "1596736937.593510"]], "c": "934634923"}, "book-100", "XBT/USD"]
[270, {"a": [["11871.50000", "4.80774140", "1596736937.602206"]], "c": "330525499"}, "book-100", "XBT/USD"]
[270, {"a": [["11871.50000", "4.78798323", "1596736937.661343"]], "c": "1236082579"}, "book-100", "XBT/USD"]
[270, {"a": [["11872.50000", "4.20200000", "1596736937.661611"]], "c": "3882611886"}, "book-100", "XBT/USD"]
[270, {"a": [["11870.40000", "2.76975816", "1596736937.665916"]], "c": "859512350"}, "book-100", "XBT/USD"]
[270, {"a": [["11870.40000", "3.86975816", "1596736937.666257"]], "c": "697233232"}, "book-100", "XBT/USD"]
[270, {"b": [["11856.80000", "0.00000000", "1596736937.713923"], ["11807.70000", "3.28855406", "1596736821.611246", "r"]], "c": "697233232"}, "book-100", "XBT/USD"]
[270, {"b": [["11811.00000", "0.00000000", "1596736937.717360"], ["11807.50000", "2.19772556", "1596736916.776430", "r"]], "c": "697233232"}, "book-100", "XBT/USD"]
[270, {"a": [["11872.40000", "0.00000000", "1596736937.727049"], ["11914.10000", "7.98435073", "1596736764.864707", "r"]], "c": "3271101872"}, "book-100", "XBT/USD"]
[270, {"a": [["11871.50000", "4.22712087", "1596736937.757737"]], "c": "1155890915"}, "book-100", "XBT/USD"]
[270, {"b": [["11856.00000", "0.00000000", "1596736937.796367"], ["11807.20000", "6.50000000", "1596736936.572585", "r"]], "c": "1155890915"}, "book-100", "XBT/USD"]
[270, {"b": [["11857.00000", "0.89056320", "1596736937.797383"]], "c": "1155890915"}, "book-100", "XBT/USD"]
[270, {"b": [["11870.30000", "0.52000000", "1596736937.811227"]], "c": "3508704883"}, "book-100", "XBT/USD"]
[270, {"a": [["11875.50000", "0.18435000", "1596736937.838776"]], "c": "3508704883"}, "book-100", "XBT/USD"]
[270, {"a": [["11873.60000", "0.19053000", "1596736937.875045"]], "c": "977434210"}, "book-100", "XBT/USD"]
[270, {"a": [["11874.50000", "0.04750000", "1596736937.961078"]], "c": "977434210"}, "book-100", "XBT/USD"]
[270, {"b": [["11856.10000", "1.06681765", "1596736938.007148"]], "c": "977434210"}, "book-100", "XBT/USD"]
[270, {"a": [["11870.40000", "4.42215841", "1596736938.082189"]], "c": "3728266345"}, "book-100", "XBT/USD"]
[270, {"a": [["11884.40000", "0.00000000", "1596736938.082410"], ["11913.90000", "3.25918268", "1596736931.174304", "r"]], "c": "3728266345"}, "book-100", "XBT/USD"]
[270, {"a": [["11885.00000", "0.00000000", "1596736938.086049"], ["11914.10000", "7.98435073", "1596736764.864707", "r"]], "c": "3728266345"}, "book-100", "XBT/USD"]
[270, {"a": [["11901.40000", "0.50000000", "1596736938.335056"]], "c": "3728266345"}, "book-100", "XBT/USD"]
[270, {"a": [["11879.90000", "0.01000000", "1596736938.403162"]], "c": "3728266345"}, "book-100", "XBT/USD"]
[270, {"a": [["11873.60000", "0.00000000", "1596736938.485325"], ["11914.10000", "7.98435073", "1596736764.864707", "r"]], "c": "1803030903"}, "book-100", "XBT/USD"]
[270, {"a": [["11879.30000", "0.67308864", "1596736938.516567"]], "c": "1803030903"}, "book-100", "XBT/USD"]
[270, {"b": [["11856.10000", "1.04381765", "1596736938.537595"]], "c": "1803030903"}, "book-100", "XBT/USD"]
[270, {"b": [["11856.80000", "0.02300000", "1596736938.590291"]], "c": "1803030903"}, "book-100", "XBT/USD"]
[270, {"a": [["11871.50000", "3.82712087", "1596736938.633130"]], "c": "2352985925"}, "book-100", "XBT/USD"]
[270, {"b": [["11856.90000", "0.00000000", "1596736938.667736"], ["11807.20000", "6.50000000", "1596736936.572585", "r"]], "c": "2352985925"}, "book-100", "XBT/USD"]
[270, {"b": [["11857.00000", "0.12511394", "1596736938.668123"]], "c": "2352985925"}, "book-100", "XBT/USD"]
[270, {"b": [["11857.30000", "0.00000000", "1596736938.674850"], ["11805.90000", "0.15000000", "1596735155.182015", "r"]], "c": "2352985925"}, "book-100", "XBT/USD"]
[270, {"b": [["11858.80000", "0.00000000", "1596736938.686953"], ["11805.20000", "0.34533000", "1596735143.806373", "r"]], "c": "2352985925"}, "book-100", "XBT/USD"]
[270, {"b": [["11857.00000", "0.10936404", "1596736938.803577"]], "c": "2352985925"}, "book-100", "XBT/USD"]
[270, {"b": [["11857.10000", "0.22796144", "1596736938.805176"]], "c": "2352985925"}, "book-100", "XBT/USD"]
[270, {"a": [["11873.80000", "0.00000000", "1596736938.818710"], ["11914.10000", "7.98435073", "1596736764.864707", "r"]], "c": "4105448974"}, "book-100", "XBT/USD"]
[270, {"b": [["11854.00000", "0.76553825", "1596736939.014607"]], "c": "4105448974"}, "book-100", "XBT/USD"]
[270, {"a": [["11873.00000", "0.25000000", "1596736939.075662"]], "c": "3470794184"}, "book-100", "XBT/USD"]
[270, {"b": [["11857.10000", "0.02337356", "1596736939.114213"]], "c": "3470794184"}, "book-100", "XBT/USD"]
[270, {"a": [["11872.50000", "4.39253000", "1596736939.145809"]], "c": "1515616334"}, "book-100", "XBT/USD"]
[270, {"a": [["11870.50000", "0.63162106", "1596736939.199125"]], "c": "1488677225"}, "book-100", "XBT/USD"]
[270, {"b": [["11866.80000", "0.25264842", "1596736939.202427"]], "c": "4108237079"}, "book-100", "XBT/USD"]
[270, {"a": [["11873.20000", "0.00000000", "1596736939.232537"], ["11913.90000", "3.25918268", "1596736931.174304", "r"]], "c": "2248434163"}, "book-100", "XBT/USD"]
[270, {"b": [["11856.90000", "0.02337356", "1596736939.243410"]], "c": "2248434163"}, "book-100", "XBT/USD"]
[270, {"b": [["11857.10000", "0.00000000", "1596736939.243479"], ["11807.20000", "6.50000000", "1596736936.572585", "r"]], "c": "2248434163"}, "book-100", "XBT/USD"]
[270, {"a": [["11898.30000", "1.26404023", "1596736939.258566"]], "c": "2248434163"}, "book-100", "XBT/USD"]
[270, {"a": [["11898.90000", "0.00000000", "1596736939.262331"], ["11914.10000", "7.98435073", "1596736764.864707", "r"]], "c": "2248434163"}, "book-100", "XBT/USD"]
[270, {"b": [["11837.80000", "6.65619823", "1596736939.341104"]], "c": "2248434163"}, "book-100", "XBT/USD"]
[270, {"a": [["11892.00000", "0.69187916", "1596736939.471657"]], "c": "2248434163"}, "book-100", "XBT/USD"]
[270, {"a": [["11900.30000", "3.92552222", "1596736939.474803"]], "c": "2248434163"}, "book-100", "XBT/USD"]
[270, {"b": [["11856.90000", "0.71730089", "1596736939.504440"]], "c": "2248434163"}, "book-100", "XBT/USD"]
[270, {"a": [["11888.60000", "0.32956049", "1596736939.507739"]], "c": "2248434163"}, "book-100", "XBT/USD"]
[270, {"b": [["11854.50000", "1.38813563", "1596736939.511946"]], "c": "2248434163"}, "book-100", "XBT/USD"]
[270, {"b": [["11854.20000", "0.20461899", "1596736939.564716"]], "c": "2248434163"}, "book-100", "XBT/USD"]
[270, {"a": [["11871.10000", "0.09621094", "1596736939.583199"]], "c": "406736365"}, "book-100", "XBT/USD"]
[270, {"b": [["11835.70000", "0.00000000", "1596736939.646454"], ["11807.50000", "2.19772556", "1596736916.776430", "r"]], "c": "406736365"}, "book-100", "XBT/USD"]
[270, {"b": [["11839.30000", "1.92343678", "1596736939.929330"]], "c": "406736365"}, "book-100", "XBT/USD"]
[270, {"a": [["11870.40000", "5.12215841", "1596736939.934007"]], "c": "1181693265"}, "book-100", "XBT/USD"]
[270, {"a": [["11894.40000", "1.38347910", "1596736939.964613"]], "c": "1181693265"}, "book-100", "XBT/USD"]
[270, {"b": [["11837.80000", "0.73590702", "1596736940.084909"]], "c": "1181693265"}, "book-100", "XBT/USD"]
[270, {"a": [["11898.30000", "0.73590702", "1596736940.112035"]], "c": "1181693265"}, "book-100", "XBT/USD"]
[270, {"b": [["11836.60000", "5.92169168", "1596736940.179875"]], "c": "1181693265"}, "book-100", "XBT/USD"]
[270, {"b": [["11860.90000", "0.00000000", "1596736940.292385"], ["11807.50000", "2.19772556", "1596736916.776430", "r"]], "c": "1181693265"}, "book-100", "XBT/USD"]
[270, {"b": [["11845.30000", "0.00000000", "1596736940.326255"], ["11807.20000", "6.50000000", "1596736936.572585", "r"]], "c": "1181693265"}, "book-100", "XBT/USD"]
[270, {"a": [["11895.80000", "5.82824420", "1596736940.355133"]], "c": "1181693265"}, "book-100", "XBT/USD"]
[270, {"a": [["11879.30000", "0.00000000", "1596736940.435911"], ["11913.30000", "6.18341193", "1596736935.389729", "r"]], "c": "1181693265"}, "book-100", "XBT/USD"]
[270, {"b": [["11854.10000", "0.94575191", "1596736940.441878"]], "c": "1181693265"}, "book-100", "XBT/USD"]
[270, {"a": [["11895.70000", "0.00000000", "1596736940.499042"], ["11913.80000", "1.96193224", "1596736933.165106", "r"]], "c": "1181693265"}, "book-100", "XBT/USD"]
[270, {"b": [["11835.00000", "0.01248782", "1596736940.554727"]], "c": "1181693265"}, "book-100", "XBT/USD"]
[270, {"b": [["11859.30000", "0.33037471", "1596736940.626081"]], "c": "1181693265"}, "book-100", "XBT/USD"]
[270, {"a": [["11878.50000", "0.63867117", "1596736940.654827"]], "c": "1181693265"}, "book-100", "XBT/USD"]
[270, {"a": [["11894.30000", "0.43469327", "1596736940.721317"]], "c": "1181693265"}, "book-100", "XBT/USD"]
[270, {"b": [["11820.70000", "2.12643506", "1596736941.327806"]], "c": "1181693265"}, "book-100", "XBT/USD"]
[270, {"b": [["11819.60000", "2.20872864", "1596736941.336077"]], "c": "1181693265"}, "book-100", "XBT/USD"]
[270, {"a": [["11901.40000", "3.59451658", "1596736941.439686"]], "c": "1181693265"}, "book-100", "XBT/USD"]
[270, {"b": [["11862.50000", "0.00000000", "1596736942.186833"], ["11808.00000", "0.17065000", "1596736558.844046", "r"]], "c": "1181693265"}, "book-100", "XBT/USD"]
[270, {"a": [["11872.50000", "4.20200000", "1596736942.326468"]], "c": "1940297089"}, "book-100", "XBT/USD"]
[270, {"b": [["11861.20000", "0.09621094", "1596736942.826184"]], "c": "1940297089"}, "book-100", "XBT/USD"]
[270, {"b": [["11856.80000", "0.00000000", "1596736942.877628"], ["11808.00000", "0.17065000", "1596736558.844046", "r"]], "c": "1940297089"}, "book-100", "XBT/USD"]
[270, {"b": [["11856.20000", "0.02300000", "1596736942.927661"]], "c": "1940297089"}, "book-100", "XBT/USD"]
[270, {"b": [["11851.90000", "0.00000000", "1596736943.158347"], ["11808.00000", "0.17065000", "1596736558.844046", "r"]], "c": "1940297089"}, "book-100", "XBT/USD"]
[270, {"b": [["11834.20000", "0.23800000", "1596736943.203403"]], "c": "1940297089"}, "book-100", "XBT/USD"]
[270, {"a": [["11894.30000", "0.00000000", "1596736943.320830"], ["11913.30000", "6.18341193", "1596736935.389729", "r"]], "c": "1940297089"}, "book-100", "XBT/USD"]
[270, {"a": [["11872.70000", "0.19071000", "1596736943.375888"]], "c": "88001577"}, "book-100", "XBT/USD"]
[270, {"b": [["11856.90000", "0.69392733", "1596736943.476249"]], "c": "88001577"}, "book-100", "XBT/USD"]
[270, {"b": [["11861.60000", "0.01733095", "1596736943.507717"]], "c": "88001577"}, "book-100", "XBT/USD"]
[270, {"a": [["11894.20000", "0.00438186", "1596736943.556737"]], "c": "88001577"}, "book-100", "XBT/USD"]
[270, {"b": [["11849.20000", "0.00453025", "1596736943.557927"]], "c": "88001577"}, "book-100", "XBT/USD"]
[270, {"b": [["11856.20000", "0.00000000", "1596736943.560126"], ["11811.70000", "5.70000000", "1596736886.902857", "r"]], "c": "88001577"}, "book-100", "XBT/USD"]
[270, {"b": [["11856.10000", "1.06681765", "1596736943.609718"]], "c": "88001577"}, "book-100", "XBT/USD"]
[270, {"b": [["11861.60000", "0.00000000", "1596736943.630325"], ["11808.90000", "0.01263652", "1596736943.558093", "r"]], "c": "88001577"}, "book-100", "XBT/USD"]
[270, {"b": [["11857.90000", "0.01823297", "1596736943.635627"]], "c": "88001577"}, "book-100", "XBT/USD"]
[270, {"b": [["11857.90000", "0.00000000", "1596736943.796657"], ["11808.90000", "0.01263652", "1596736943.558093", "r"]], "c": "88001577"}, "book-100", "XBT/USD"]
[270, {"b": [["11854.20000", "0.27675673", "1596736943.805699"]], "c": "88001577"}, "book-100", "XBT/USD"]
[270, {"a": [["11872.70000", "0.00000000", "1596736944.009042"], ["11913.00000", "0.17065000", "1596736890.849460", "r"]], "c": "1940297089"}, "book-100", "XBT/USD"]
[270, {"b": [["11859.30000", "0.00000000", "1596736944.045855"], ["11808.80000", "2.66090576", "1596736784.110515", "r"]], "c": "1940297089"}, "book-100", "XBT/USD"]
[270, {"b": [["11857.00000", "0.18148475", "1596736944.048119"]], "c": "1940297089"}, "book-100", "XBT/USD"]
[270, {"b": [["11854.20000", "0.20461899", "1596736944.048543"]], "c": "1940297089"}, "book-100", "XBT/USD"]
[270, {"a": [["11892.00000", "0.00000000", "1596736944.129942"], ["11913.30000", "6.18341193", "1596736935.389729", "r"]], "c": "1940297089"}, "book-100", "XBT/USD"]
[270, {"a": [["11888.60000", "0.00000000", "1596736944.134699"], ["11913.80000", "1.96193224", "1596736933.165106", "r"]], "c": "1940297089"}, "book-100", "XBT/USD"]
[270, {"a": [["11894.40000", "0.00000000", "1596736944.139812"], ["11913.90000", "3.25918268", "1596736931.174304", "r"]], "c": "1940297089"}, "book-100", "XBT/USD"]
[270, {"a": [["11910.70000", "1.58924162", "1596736944.279722"]], "c": "1940297089"}, "book-100", "XBT/USD"]
[270, {"b": [["11860.90000", "0.33033015", "1596736944.304937"]], "c": "1940297089"}, "book-100", "XBT/USD"]
[270, {"b": [["11854.60000", "0.01752071", "1596736944.307733"]], "c": "1940297089"}, "book-100", "XBT/USD"]
[270, {"b": [["11857.00000", "0.10936404", "1596736944.308479"]], "c": "1940297089"}, "book-100", "XBT/USD"]
[270, {"b": [["11849.20000", "0.00000000", "1596736944.363854"], ["11808.90000", "0.01263652", "1596736943.558093", "r"]], "c": "1940297089"}, "book-100", "XBT/USD"]
[270, {"a": [["11890.30000", "0.69197808", "1596736944.576813"]], "c": "1940297089"}, "book-100", "XBT/USD"]
[270, {"a": [["11892.70000", "1.38367686", "1596736944.586333"]], "c": "1940297089"}, "book-100", "XBT/USD"]
[270, {"a": [["11886.90000", "0.32960762", "1596736944.587581"]], "c": "1940297089"}, "book-100", "XBT/USD"]
[270, {"b": [["11836.60000", "0.00000000", "1596736944.595799"], ["11808.80000", "2.66090576", "1596736784.110515", "r"]], "c": "1940297089"}, "book-100", "XBT/USD"]
[270, {"a": [["11887.20000", "0.00000000", "1596736944.698900"], ["11913.00000", "0.17065000", "1596736890.849460", "r"]], "c": "1940297089"}, "book-100", "XBT/USD"]
[270, {"b": [["11854.60000", "0.03504125", "1596736944.741171"]], "c": "1940297089"}, "book-100", "XBT/USD"]
[270, {"b": [["11854.60000", "0.01752054", "1596736944.741487"]], "c": "1940297089"}, "book-100", "XBT/USD"]
[270, {"b": [["11834.20000", "6.16089261", "1596736944.782454"]], "c": "1940297089"}, "book-100", "XBT/USD"]
[270, {"a": [["11882.90000", "5.54998897", "1596736944.866215"]], "c": "1940297089"}, "book-100", "XBT/USD"]
[270, {"a": [["11872.40000", "0.19072000", "1596736945.011703"]], "c": "2841941933"}, "book-100", "XBT/USD"]
[270, {"b": [["11854.60000", "0.00000000", "1596736945.076967"], ["11808.00000", "0.17065000", "1596736558.844046", "r"]], "c": "2841941933"}, "book-100", "XBT/USD"]
[270, {"b": [["11855.20000", "0.00897521", "1596736945.078152"]], "c": "2841941933"}, "book-100", "XBT/USD"]
[270, {"b": [["11856.20000", "0.00897504", "1596736945.204212"]], "c": "2841941933"}, "book-100", "XBT/USD"]
[270, {"b": [["11855.20000", "0.00000000", "1596736945.204683"], ["11808.80000", "2.66090576", "1596736784.110515", "r"]], "c": "2841941933"}, "book-100", "XBT/USD"]
[270, {"b": [["11856.20000", "0.01794999", "1596736945.327912"]], "c": "2841941933"}, "book-100", "XBT/USD"]
[270, {"b": [["11856.20000", "0.00897495", "1596736945.328785"]], "c": "2841941933"}, "book-100", "XBT/USD"]
[270, {"a": [["11873.00000", "0.00000000", "1596736945.350212"], ["11912.60000", "6.45782985", "1596736937.577118", "r"]], "c": "4108572826"}, "book-100", "XBT/USD"]
[270, {"b": [["11856.10000", "1.04381765", "1596736945.386290"]], "c": "4108572826"}, "book-100", "XBT/USD"]
[270, {"b": [["11855.10000", "0.35985110", "1596736945.437966"]], "c": "4108572826"}, "book-100", "XBT/USD"]
[270, {"a": [["11878.10000", "0.41675051", "1596736945.478568"]], "c": "4108572826"}, "book-100", "XBT/USD"]
[270, {"b": [["11870.30000", "0.42000000", "1596736945.494011"]], "c": "75074614"}, "book-100", "XBT/USD"]
[270, {"a": [["11872.40000", "0.00000000", "1596736945.496617"], ["11913.00000", "0.17065000", "1596736890.849460", "r"]], "c": "1056511745"}, "book-100", "XBT/USD"]
[270, {"b": [["11868.00000", "0.00000000", "1596736945.523605"], ["11808.00000", "0.17065000", "1596736558.844046", "r"]], "c": "3695433747"}, "book-100", "XBT/USD"]
[270, {"a": [["11870.40000", "4.42215841", "1596736945.549666"]], "c": "1405250155"}, "book-100", "XBT/USD"]
[270, {"b": [["11868.40000", "0.00000000", "1596736945.560561"], ["11807.70000", "3.28855406", "1596736821.611246", "r"]], "c": "3330097229"}, "book-100", "XBT/USD"]
[270, {"a": [["11871.90000", "0.00000000", "1596736945.568140"], ["11913.30000", "6.18341193", "1596736935.389729", "r"]], "c": "2328542496"}, "book-100", "XBT/USD"]
[270, {"b": [["11865.90000", "0.00000000", "1596736945.580353"], ["11807.50000", "2.19772556", "1596736916.776430", "r"]], "c": "1632113978"}, "book-100", "XBT/USD"]
[270, {"a": [["11870.40000", "4.92215841", "1596736945.587136"]], "c": "2839424095"}, "book-100", "XBT/USD"]
[270, {"a": [["11872.40000", "0.25000000", "1596736945.588265"]], "c": "701696443"}, "book-100", "XBT/USD"]
[270, {"a": [["11871.80000", "0.19072000", "1596736945.588364"]], "c": "774788927"}, "book-100", "XBT/USD"]
[270, {"a": [["11871.40000", "0.70000000", "1596736945.597568"]], "c": "2978034261"}, "book-100", "XBT/USD"]
[270, {"a": [["11883.00000", "1.37973883", "1596736945.601472"]], "c": "2978034261"}, "book-100", "XBT/USD"]
[270, {"a": [["11881.90000", "6.60000000", "1596736945.606353"]], "c": "2978034261"}, "book-100", "XBT/USD"]
[270, {"a": [["11883.00000", "1.16720749", "1596736945.619644"]], "c": "2978034261"}, "book-100", "XBT/USD"]
[270, {"a": [["11883.00000", "0.52523655", "1596736945.620404"]], "c": "2978034261"}, "book-100", "XBT/USD"]
[270, {"a": [["11904.50000", "0.00000000", "1596736945.620642"], ["11912.60000", "6.45782985", "1596736937.577118", "r"]], "c": "2978034261"}, "book-100", "XBT/USD"]
[270, {"a": [["11883.00000", "0.39061135", "1596736945.621151"]], "c": "2978034261"}, "book-100", "XBT/USD"]
[270, {"a": [["11883.00000", "0.00000000", "1596736945.629127"], ["11913.00000", "0.17065000", "1596736890.849460", "r"]], "c": "2978034261"}, "book-100", "XBT/USD"]
[270, {"a": [["11904.30000", "3.00000000", "1596736945.636297"]], "c": "2978034261"}, "book-100", "XBT/USD"]
[270, {"b": [["11867.60000", "0.71866500", "1596736945.637792"]], "c": "1460495417"}, "book-100", "XBT/USD"]
[270, {"b": [["11853.10000", "0.33688667", "1596736945.637915"]], "c": "1460495417"}, "book-100", "XBT/USD"]
[270, {"a": [["11870.40000", "5.55385920", "1596736945.638081"]], "c": "1555509918"}, "book-100", "XBT/USD"]
[270, {"a": [["11870.40000", "5.95385920", "1596736945.652153"]], "c": "2260668146"}, "book-100", "XBT/USD"]
[270, {"b": [["11868.50000", "0.10000000", "1596736945.691110"]], "c": "3409998997"}, "book-100", "XBT/USD"]
[270, {"a": [["11892.30000", "0.00000000", "1596736945.741370"], ["11913.30000", "6.18341193", "1596736935.389729", "r"]], "c": "3409998997"}, "book-100", "XBT/USD"]
[270, {"a": [["11871.80000", "0.00000000", "1596736945.741500"], ["11913.80000", "1.96193224", "1596736933.165106", "r"]], "c": "1392444966"}, "book-100", "XBT/USD"]
[270, {"a": [["11877.10000", "0.61801043", "1596736945.742875"]], "c": "1392444966"}, "book-100", "XBT/USD"]
[270, {"b": [["11867.60000", "0.46600000", "1596736945.742961"]], "c": "582318582"}, "book-100", "XBT/USD"]
[270, {"b": [["11866.30000", "0.00000000", "1596736945.743414"], ["11807.70000", "3.28855406", "1596736821.611246", "r"]], "c": "2912327779"}, "book-100", "XBT/USD"]
[270, {"a": [["11901.40000", "0.50000000", "1596736945.744103"]], "c": "2912327779"}, "book-100", "XBT/USD"]
[270, {"a": [["11898.20000", "0.00000000", "1596736945.744519"], ["11913.80000", "1.96193224", "1596736933.165106", "r"]], "c": "2912327779"}, "book-100", "XBT/USD"]
[270, {"a": [["11880.90000", "0.01800000", "1596736945.744809"]], "c": "2912327779"}, "book-100", "XBT/USD"]
[270, {"a": [["11894.70000", "0.30000000", "1596736945.746232"]], "c": "2912327779"}, "book-100", "XBT/USD"]
[270, {"a": [["11873.50000", "0.09800000", "1596736945.749157"]], "c": "2195331069"}, "book-100", "XBT/USD"]
[270, {"b": [["11855.40000", "0.88165000", "1596736945.752054"]], "c": "2195331069"}, "book-100", "XBT/USD"]
[270, {"a": [["11896.90000", "0.00000000", "1596736945.752133"], ["11913.30000", "6.18341193", "1596736935.389729", "r"]], "c": "2195331069"}, "book-100", "XBT/USD"]
[270, {"b": [["11864.70000", "0.00000000", "1596736945.774073"], ["11807.70000", "3.28855406", "1596736821.611246", "r"]], "c": "2102767835"}, "book-100", "XBT/USD"]
[270, {"a": [["11871.40000", "0.00000000", "1596736945.789885"], ["11913.80000", "1.96193224", "1596736933.165106", "r"]], "c": "1727406336"}, "book-100", "XBT/USD"]
[270, {"a": [["11898.10000", "0.00000000", "1596736945.793888"], ["11913.90000", "3.25918268", "1596736931.174304", "r"]], "c": "1727406336"}, "book-100", "XBT/USD"]
[270, {"a": [["11894.60000", "0.00000000", "1596736945.809612"], ["11914.10000", "7.98435073", "1596736764.864707", "r"]], "c": "1727406336"}, "book-100", "XBT/USD"]
[270, {"a": [["11900.50000", "0.46880709", "1596736945.823613"]], "c": "1727406336"}, "book-100", "XBT/USD"]
[270, {"a": [["11870.40000", "6.65385920", "1596736945.837612"]], "c": "3115679706"}, "book-100", "XBT/USD"]
[270, {"a": [["11889.80000", "0.10904351", "1596736945.872880"]], "c": "3115679706"}, "book-100", "XBT/USD"]
[270, {"a": [["11870.40000", "5.95385920", "1596736945.887472"]], "c": "1727406336"}, "book-100", "XBT/USD"]
[270, {"b": [["11865.60000", "3.15954002", "1596736945.905087"]], "c": "1613429272"}, "book-100", "XBT/USD"]
[270, {"a": [["11876.70000", "0.21253134", "1596736945.911353"]], "c": "1613429272"}, "book-100", "XBT/USD"]
[270, {"a": [["11872.30000", "0.19072000", "1596736945.912540"]], "c": "4261339157"}, "book-100", "XBT/USD"]
[270, {"a": [["11876.70000", "0.34397570", "1596736945.917501"]], "c": "4261339157"}, "book-100", "XBT/USD"]
[270, {"b": [["11862.20000", "2.59587774", "1596736945.924700"]], "c": "2786000751"}, "book-100", "XBT/USD"]
[270, {"b": [["11852.50000", "0.37195044", "1596736945.958074"]], "c": "2786000751"}, "book-100", "XBT/USD"]
[270, {"a": [["11900.70000", "7.52538665", "1596736945.979557"]], "c": "2786000751"}, "book-100", "XBT/USD"]
[270, {"a": [["11876.70000", "1.00681381", "1596736946.019838"]], "c": "2786000751"}, "book-100", "XBT/USD"]
[270, {"a": [["11876.70000", "1.38378521", "1596736946.026884"]], "c": "2786000751"}, "book-100", "XBT/USD"]
[270, {"b": [["11865.60000", "0.25266500", "1596736946.060994"]], "c": "3662736017"}, "book-100", "XBT/USD"]
[270, {"a": [["11892.60000", "0.20396457", "1596736946.082225"]], "c": "3662736017"}, "book-100", "XBT/USD"]
[270, {"b": [["11861.50000", "0.59800000", "1596736946.117437"]], "c": "4275936821"}, "book-100", "XBT/USD"]
[270, {"b": [["11838.50000", "0.00000000", "1596736946.187258"], ["11807.70000", "3.28855406", "1596736821.611246", "r"]], "c": "4275936821"}, "book-100", "XBT/USD"]
[270, {"a": [["11894.30000", "3.26482597", "1596736946.198398"]], "c": "4275936821"}, "book-100", "XBT/USD"]
[270, {"b": [["11861.20000", "0.00000000", "1596736946.350910"], ["11807.50000", "2.19772556", "1596736916.776430", "r"]], "c": "1020906982"}, "book-100", "XBT/USD"]
[270, {"a": [["11870.40000", "6.65385920", "1596736946.407553"]], "c": "1509995890"}, "book-100", "XBT/USD"]
[270, {"a": [["11896.20000", "8.01062924", "1596736946.422944"]], "c": "1509995890"}, "book-100", "XBT/USD"]
[270, {"a": [["11878.50000", "0.00000000", "1596736946.441714"], ["11912.60000", "6.45782985", "1596736937.577118", "r"]], "c": "1509995890"}, "book-100", "XBT/USD"]
[270, {"a": [["11876.70000", "2.02575615", "1596736946.446661"]], "c": "1509995890"}, "book-100", "XBT/USD"]
[270, {"b": [["11857.80000", "0.00000000", "1596736946.451269"], ["11807.20000", "6.50000000", "1596736936.572585", "r"]], "c": "1509995890"}, "book-100", "XBT/USD"]
[270, {"b": [["11867.60000", "0.00000000", "1596736946.453777"], ["11805.90000", "0.15000000", "1596735155.182015", "r"]], "c": "2182028153"}, "book-100", "XBT/USD"]
[270, {"b": [["11856.20000", "0.00000000", "1596736946.524784"], ["11805.20000", "0.34533000", "1596735143.806373", "r"]], "c": "2182028153"}, "book-100", "XBT/USD"]
[270, {"b": [["11855.50000", "0.00897530", "1596736946.525434"]], "c": "2182028153"}, "book-100", "XBT/USD"]
[270, {"a": [["11901.40000", "0.00000000", "1596736946.544994"], ["11913.00000", "0.17065000", "1596736890.849460", "r"]], "c": "2182028153"}, "book-100", "XBT/USD"]
[270, {"a": [["11882.10000", "0.84217516", "1596736946.549739"]], "c": "2182028153"}, "book-100", "XBT/USD"]
[270, {"a": [["11895.70000", "0.94251246", "1596736946.627317"]], "c": "2182028153"}, "book-100", "XBT/USD"]
[270, {"b": [["11837.80000", "0.00000000", "1596736946.687440"], ["11805.20000", "0.34533000", "1596735143.806373", "r"]], "c": "2182028153"}, "book-100", "XBT/USD"]
[270, {"a": [["11898.30000", "0.00000000", "1596736946.696735"], ["11913.00000", "0.17065000", "1596736890.849460", "r"]], "c": "2182028153"}, "book-100", "XBT/USD"]
[270, {"a": [["11898.70000", "0.74591151", "1596736946.699002"]], "c": "2182028153"}, "book-100", "XBT/USD"]
[270, {"b": [["11837.00000", "6.95912688", "1596736946.699185"]], "c": "2182028153"}, "book-100", "XBT/USD"]
[270, {"b": [["11866.80000", "0.00000000", "1596736946.703316"], ["11805.00000", "0.17065000", "1596736564.657965", "r"]], "c": "1367920544"}, "book-100", "XBT/USD"]
[270, {"a": [["11882.10000", "0.00000000", "1596736946.706143"], ["11913.30000", "6.18341193", "1596736935.389729", "r"]], "c": "1367920544"}, "book-100", "XBT/USD"]
[270, {"b": [["11862.40000", "4.20600000", "1596736946.712555"]], "c": "1539397367"}, "book-100", "XBT/USD"]
[270, {"a": [["11872.50000", "0.00000000", "1596736946.721984"], ["11913.80000", "1.96193224", "1596736933.165106", "r"]], "c": "2091338390"}, "book-100", "XBT/USD"]
[270, {"a": [["11870.40000", "10.85885920", "1596736946.725000"]], "c": "2154316666"}, "book-100", "XBT/USD"]
[270, {"a": [["11876.80000", "1.57148569", "1596736946.748481"]], "c": "2154316666"}, "book-100", "XBT/USD"]
[270, {"b": [["11855.50000", "0.00000000", "1596736946.784235"], ["11805.00000", "0.17065000", "1596736564.657965", "r"]], "c": "2154316666"}, "book-100", "XBT/USD"]
[270, {"b": [["11844.40000", "0.00000000", "1596736946.843024"], ["11804.80000", "3.28996656", "1596736677.195153", "r"]], "c": "2154316666"}, "book-100", "XBT/USD"]
[270, {"a": [["11877.10000", "0.00000000", "1596736946.933988"], ["11913.90000", "3.25918268", "1596736931.174304", "r"]], "c": "2154316666"}, "book-100", "XBT/USD"]
[270, {"a": [["11884.30000", "1.42962971", "1596736946.947644"]], "c": "2154316666"}, "book-100", "XBT/USD"]
[270, {"b": [["11855.20000", "0.00897530", "1596736946.955439"]], "c": "2154316666"}, "book-100", "XBT/USD"]
[270, {"a": [["11893.10000", "0.43177124", "1596736946.957592"]], "c": "2154316666"}, "book-100", "XBT/USD"]
[270, {"a": [["11878.60000", "0.28399999", "1596736947.038846"]], "c": "2154316666"}, "book-100", "XBT/USD"]
[270, {"a": [["11872.30000", "0.00000000", "1596736947.120349"], ["11913.90000", "3.25918268", "1596736931.174304", "r"]], "c": "4038781742"}, "book-100", "XBT/USD"]
[270, {"b": [["11843.90000", "0.01000000", "1596736947.142849"]], "c": "4038781742"}, "book-100", "XBT/USD"]
[270, {"a": [["11875.20000", "0.60298951", "1596736947.190498"]], "c": "4038781742"}, "book-100", "XBT/USD"]
[270, {"a": [["11884.50000", "0.30000000", "1596736947.242513"]], "c": "4038781742"}, "book-100", "XBT/USD"]
[270, {"a": [["11875.30000", "0.16490000", "1596736947.290962"]], "c": "4038781742"}, "book-100", "XBT/USD"]
[270, {"a": [["11893.10000", "0.00000000", "1596736947.300708"], ["11913.80000", "1.96193224", "1596736933.165106", "r"]], "c": "4038781742"}, "book-100", "XBT/USD"]
[270, {"a": [["11875.50000", "1.02640112", "1596736947.302744"]], "c": "4038781742"}, "book-100", "XBT/USD"]
[270, {"b": [["11862.50000", "0.10000000", "1596736947.392533"]], "c": "3853021677"}, "book-100", "XBT/USD"]
[270, {"a": [["11892.10000", "0.94279778", "1596736947.393114"]], "c": "3853021677"}, "book-100", "XBT/USD"]
[270, {"a": [["11876.00000", "0.40210058", "1596736947.420809"]], "c": "3853021677"}, "book-100", "XBT/USD"]
[270, {"a": [["11871.80000", "0.19104000", "1596736947.429890"]], "c": "3712178354"}, "book-100", "XBT/USD"]
[270, {"a": [["11870.40000", "10.15885920", "1596736947.430395"]], "c": "3692668825"}, "book-100", "XBT/USD"]
[270, {"a": [["11889.10000", "0.00000000", "1596736947.461367"], ["11913.30000", "6.18341193", "1596736935.389729", "r"]], "c": "3692668825"}, "book-100", "XBT/USD"]
[270, {"a": [["11871.80000", "0.00000000", "1596736947.502026"], ["11913.80000", "1.96193224", "1596736933.165106", "r"]], "c": "1680235692"}, "book-100", "XBT/USD"]
[270, {"a": [["11876.80000", "0.90958000", "1596736947.508016"]], "c": "1680235692"}, "book-100", "XBT/USD"]
[270, {"a": [["11894.20000", "0.47506020", "1596736947.511952"]], "c": "1680235692"}, "book-100", "XBT/USD"]
[270, {"b": [["11863.90000", "1.67500000", "1596736947.531188"]], "c": "3726651192"}, "book-100", "XBT/USD"]
[270, {"a": [["11872.30000", "1.67400000", "1596736947.533672"]], "c": "1892914883"}, "book-100", "XBT/USD"]
[270, {"a": [["11897.90000", "3.09559045", "1596736947.720108"]], "c": "1892914883"}, "book-100", "XBT/USD"]
[270, {"a": [["11900.50000", "0.96880709", "1596736947.727824"]], "c": "1892914883"}, "book-100", "XBT/USD"]
[270, {"b": [["11808.90000", "0.00000000", "1596736947.750382"], ["11805.90000", "0.15000000", "1596735155.182015", "r"]], "c": "1892914883"}, "book-100", "XBT/USD"]
[270, {"b": [["11852.60000", "0.00422010", "1596736947.750649"]], "c": "1892914883"}, "book-100", "XBT/USD"]
[270, {"a": [["11894.20000", "0.47067834", "1596736947.750946"]], "c": "1892914883"}, "book-100", "XBT/USD"]
[270, {"a": [["11876.70000", "2.67932689", "1596736947.758644"]], "c": "1892914883"}, "book-100", "XBT/USD"]
[270, {"a": [["11872.80000", "1.50500000", "1596736947.835622"]], "c": "2501116616"}, "book-100", "XBT/USD"]
[270, {"b": [["11864.50000", "0.00000000", "1596736947.882922"], ["11805.90000", "0.15000000", "1596735155.182015", "r"]], "c": "3716197718"}, "book-100", "XBT/USD"]
[270, {"a": [["11909.80000", "0.00000000", "1596736947.911142"], ["11913.30000", "6.18341193", "1596736935.389729", "r"]], "c": "3716197718"}, "book-100", "XBT/USD"]
[270, {"a": [["11894.20000", "0.00000000", "1596736947.912523"], ["11913.80000", "1.96193224", "1596736933.165106", "r"]], "c": "3716197718"}, "book-100", "XBT/USD"]
[270, {"a": [["11874.50000", "0.00000000", "1596736948.012643"], ["11913.90000", "3.25918268", "1596736931.174304", "r"]], "c": "3716197718"}, "book-100", "XBT/USD"]
[270, {"a": [["11906.10000", "0.00000000", "1596736948.029409"], ["11914.10000", "7.98435073", "1596736764.864707", "r"]], "c": "3716197718"}, "book-100", "XBT/USD"]
[270, {"b": [["11826.70000", "0.00000000", "1596736948.071305"], ["11805.20000", "0.34533000", "1596735143.806373", "r"]], "c": "3716197718"}, "book-100", "XBT/USD"]
[270, {"a": [["11876.70000", "2.02575615", "1596736948.073061"]], "c": "3716197718"}, "book-100", "XBT/USD"]
[270, {"a": [["11872.70000", "0.04750000", "1596736948.134381"]], "c": "3020214842"}, "book-100", "XBT/USD"]
[270, {"a": [["11871.50000", "4.01827087", "1596736948.190296"]], "c": "1338723565"}, "book-100", "XBT/USD"]
[270, {"a": [["11873.00000", "0.84233923", "1596736948.198804"]], "c": "602956789"}, "book-100", "XBT/USD"]
[270, {"b": [["11865.20000", "0.25270177", "1596736948.199232"]], "c": "4012332833"}, "book-100", "XBT/USD"]
[270, {"b": [["11851.80000", "0.33692395", "1596736948.199315"]], "c": "4012332833"}, "book-100", "XBT/USD"]
[270, {"a": [["11904.30000", "3.09250000", "1596736948.253919"]], "c": "4012332833"}, "book-100", "XBT/USD"]
[270, {"a": [["11876.10000", "0.69855418", "1596736948.282011"]], "c": "4012332833"}, "book-100", "XBT/USD"]
[270, {"b": [["11857.60000", "0.09621094", "1596736948.331565"]], "c": "4012332833"}, "book-100", "XBT/USD"]
[270, {"b": [["11862.50000", "0.00000000", "1596736948.354815"], ["11807.20000", "6.50000000", "1596736936.572585", "r"]], "c": "4093686924"}, "book-100", "XBT/USD"]
[270, {"b": [["11864.30000", "0.25269296", "1596736948.408559"]], "c": "119224899"}, "book-100", "XBT/USD"]
[270, {"b": [["11862.40000", "0.00000000", "1596736948.495997"], ["11807.20000", "6.50000000", "1596736936.572585", "r"]], "c": "71231637"}, "book-100", "XBT/USD"]
[270, {"a": [["11890.30000", "0.00000000", "1596736948.672155"], ["11913.80000", "1.96193224", "1596736933.165106", "r"]], "c": "71231637"}, "book-100", "XBT/USD"]
[270, {"a": [["11900.30000", "2.18056890", "1596736948.674404"]], "c": "71231637"}, "book-100", "XBT/USD"]
[270, {"a": [["11886.90000", "0.00000000", "1596736948.678130"], ["11913.90000", "3.25918268", "1596736931.174304", "r"]], "c": "71231637"}, "book-100", "XBT/USD"]
[270, {"a": [["11900.70000", "1.06109935", "1596736948.681378"]], "c": "71231637"}, "book-100", "XBT/USD"]
[270, {"a": [["11903.60000", "0.94179002", "1596736948.704680"]], "c": "71231637"}, "book-100", "XBT/USD"]
[270, {"a": [["11895.80000", "5.30000000", "1596736948.708621"]], "c": "71231637"}, "book-100", "XBT/USD"]
[270, {"a": [["11876.10000", "0.00000000", "1596736948.720434"], ["11914.10000", "7.98435073", "1596736764.864707", "r"]], "c": "71231637"}, "book-100", "XBT/USD"]
[270, {"a": [["11900.30000", "0.00000000", "1596736948.725078"], ["11914.40000", "0.75800000", "1596736271.459783", "r"]], "c": "71231637"}, "book-100", "XBT/USD"]
[270, {"a": [["11872.30000", "0.00000000", "1596736948.774297"], ["11915.00000", "0.04000000", "1596736479.420327", "r"]], "c": "2773934513"}, "book-100", "XBT/USD"]
[270, {"a": [["11900.60000", "0.00000000", "1596736948.778410"], ["11916.00000", "0.17065000", "1596736840.242690", "r"]], "c": "2773934513"}, "book-100", "XBT/USD"]
[270, {"a": [["11875.90000", "0.65293311", "1596736948.790163"]], "c": "2773934513"}, "book-100", "XBT/USD"]
[270, {"a": [["11893.20000", "0.00000000", "1596736948.798856"], ["11916.00000", "0.17065000", "1596736840.242690", "r"]], "c": "2773934513"}, "book-100", "XBT/USD"]
[270, {"a": [["11903.60000", "0.00000000", "1596736948.800507"], ["11916.20000", "2.20872864", "1596736941.376383", "r"]], "c": "2773934513"}, "book-100", "XBT/USD"]
[270, {"a": [["11911.20000", "0.00000000", "1596736948.900391"], ["11916.50000", "0.00204079", "1596736766.937570", "r"]], "c": "2773934513"}, "book-100", "XBT/USD"]
[270, {"a": [["11914.10000", "6.40200000", "1596736948.913868"]], "c": "2773934513"}, "book-100", "XBT/USD"]
[270, {"a": [["11892.70000", "0.00000000", "1596736948.966128"], ["11917.00000", "0.02200000", "1596736944.127945", "r"]], "c": "2773934513"}, "book-100", "XBT/USD"]
[270, {"b": [["11852.50000", "0.00000000", "1596736949.000108"], ["11805.90000", "0.15000000", "1596735155.182015", "r"]], "c": "2773934513"}, "book-100", "XBT/USD"]
[270, {"a": [["11892.80000", "0.52842857", "1596736949.020506"]], "c": "2773934513"}, "book-100", "XBT/USD"]
[270, {"a": [["11888.00000", "0.69216208", "1596736949.046806"]], "c": "2773934513"}, "book-100", "XBT/USD"]
[270, {"a": [["11884.60000", "0.32969528", "1596736949.054486"]], "c": "2773934513"}, "book-100", "XBT/USD"]
[270, {"a": [["11896.30000", "9.28640262", "1596736949.070075"]], "c": "2773934513"}, "book-100", "XBT/USD"]
[270, {"a": [["11875.20000", "0.00000000", "1596736949.083396"], ["11916.20000", "2.20872864", "1596736941.376383", "r"]], "c": "2773934513"}, "book-100", "XBT/USD"]
[270, {"a": [["11906.10000", "0.73344696", "1596736949.094691"]], "c": "2773934513"}, "book-100", "XBT/USD"]
[270, {"a": [["11898.80000", "0.94226691", "1596736949.098297"]], "c": "2773934513"}, "book-100", "XBT/USD"]
[270, {"a": [["11898.80000", "4.20585816", "1596736949.098390"]], "c": "2773934513"}, "book-100", "XBT/USD"]
[270, {"b": [["11834.20000", "0.23800000", "1596736949.111709"]], "c": "2773934513"}, "book-100", "XBT/USD"]
[270, {"b": [["11864.30000", "4.45869296", "1596736949.119029"]], "c": "1830199344"}, "book-100", "XBT/USD"]
[270, {"a": [["11896.50000", "1.27509051", "1596736949.120743"]], "c": "1830199344"}, "book-100", "XBT/USD"]
[270, {"a": [["11890.60000", "0.76325320", "1596736949.122039"]], "c": "1830199344"}, "book-100", "XBT/USD"]
[270, {"b": [["11844.90000", "0.65000000", "1596736949.188086"]], "c": "1830199344"}, "book-100", "XBT/USD"]
[270, {"a": [["11890.40000", "1.38404474", "1596736949.268745"]], "c": "1830199344"}, "book-100", "XBT/USD"]
[270, {"a": [["11874.10000", "0.62285084", "1596736949.305892"]], "c": "1830199344"}, "book-100", "XBT/USD"]
[270, {"a": [["11908.30000", "1.58322230", "1596736949.361051"]], "c": "1830199344"}, "book-100", "XBT/USD"]
[270, {"a": [["11896.40000", "2.18151214", "1596736949.741348"]], "c": "1830199344"}, "book-100", "XBT/USD"]
[270, {"a": [["11898.00000", "0.17065000", "1596736949.743576"]], "c": "1830199344"}, "book-100", "XBT/USD"]
[270, {"b": [["11828.20000", "5.92494533", "1596736949.744508"]], "c": "1830199344"}, "book-100", "XBT/USD"]
[270, {"b": [["11855.20000", "0.00000000", "1596736949.861484"], ["11807.20000", "6.50000000", "1596736936.572585", "r"]], "c": "1830199344"}, "book-100", "XBT/USD"]
[270, {"b": [["11854.80000", "0.01017490", "1596736949.865567"]], "c": "1830199344"}, "book-100", "XBT/USD"]
[270, {"b": [["11870.30000", "0.53700000", "1596736949.907673"]], "c": "497620601"}, "book-100", "XBT/USD"]
[270, {"b": [["11854.80000", "0.00000000", "1596736949.990687"], ["11807.20000", "6.50000000", "1596736936.572585", "r"]], "c": "497620601"}, "book-100", "XBT/USD"]
[270, {"b": [["11854.30000", "0.03384389", "1596736950.018490"]], "c": "497620601"}, "book-100", "XBT/USD"]
[270, {"b": [["11854.30000", "0.05136541", "1596736950.147657"]], "c": "497620601"}, "book-100", "XBT/USD"]
[270, {"b": [["11858.70000", "0.33321802", "1596736950.386582"]], "c": "497620601"}, "book-100", "XBT/USD"]
[270, {"b": [["11854.30000", "0.01752152", "1596736950.398465"]], "c": "497620601"}, "book-100", "XBT/USD"]
[270, {"b": [["11854.80000", "0.01752152", "1596736950.612824"]], "c": "497620601"}, "book-100", "XBT/USD"]
[270, {"b": [["11854.30000", "0.00000000", "1596736950.623726"], ["11807.70000", "3.28855406", "1596736821.611246", "r"]], "c": "497620601"}, "book-100", "XBT/USD"]
[270, {"b": [["11860.90000", "0.00000000", "1596736950.663993"], ["11807.50000", "2.19772556", "1596736916.776430", "r"]], "c": "3802030139"}, "book-100", "XBT/USD"]
[270, {"a": [["11880.90000", "0.28900000", "1596736950.829499"]], "c": "3802030139"}, "book-100", "XBT/USD"]
[270, {"b": [["11861.40000", "0.27100000", "1596736950.883660"]], "c": "139948201"}, "book-100", "XBT/USD"]
[270, {"a": [["11882.30000", "0.50000000", "1596736951.128213"]], "c": "139948201"}, "book-100", "XBT/USD"]
[270, {"a": [["11878.50000", "0.02844492", "1596736951.130032"]], "c": "139948201"}, "book-100", "XBT/USD"]
[270, {"b": [["11852.60000", "0.00000000", "1596736951.143779"], ["11807.50000", "2.19772556", "1596736916.776430", "r"]], "c": "139948201"}, "book-100", "XBT/USD"]
[270, {"b": [["11859.80000", "0.33036931", "1596736951.210462"]], "c": "139948201"}, "book-100", "XBT/USD"]
[270, {"a": [["11892.70000", "0.46153683", "1596736951.288150"]], "c": "139948201"}, "book-100", "XBT/USD"]
[270, {"a": [["11904.90000", "2.13076852", "1596736951.288688"]], "c": "139948201"}, "book-100", "XBT/USD"]
[270, {"b": [["11857.60000", "0.00000000", "1596736951.401572"], ["11807.50000", "2.19772556", "1596736916.776430", "r"]], "c": "139948201"}, "book-100", "XBT/USD"]
[270, {"a": [["11871.10000", "0.00000000", "1596736951.682779"], ["11910.50000", "1.71128370", "1596736935.716439", "r"]], "c": "1082336462"}, "book-100", "XBT/USD"]
[270, {"b": [["11854.80000", "0.00000000", "1596736951.937884"], ["11807.20000", "6.50000000", "1596736936.572585", "r"]], "c": "1082336462"}, "book-100", "XBT/USD"]
[270, {"b": [["11825.20000", "1.58089780", "1596736951.965038"]], "c": "1082336462"}, "book-100", "XBT/USD"]
[270, {"b": [["11854.60000", "0.01752152", "1596736952.039648"]], "c": "1082336462"}, "book-100", "XBT/USD"]
[270, {"a": [["11871.40000", "0.70000000", "1596736952.052943"]], "c": "3573381052"}, "book-100", "XBT/USD"]
[270, {"a": [["11871.40000", "0.00000000", "1596736952.102409"], ["11910.50000", "1.71128370", "1596736935.716439", "r"]], "c": "1082336462"}, "book-100", "XBT/USD"]
[270, {"a": [["11878.50000", "0.00000000", "1596736952.113929"], ["11910.70000", "1.58924162", "1596736944.279722", "r"]], "c": "1082336462"}, "book-100", "XBT/USD"]
[270, {"a": [["11878.00000", "0.02013504", "1596736952.116743"]], "c": "1082336462"}, "book-100", "XBT/USD"]
[270, {"b": [["11854.60000", "0.03953095", "1596736952.167329"]], "c": "1082336462"}, "book-100", "XBT/USD"]
[270, {"b": [["11854.60000", "0.02200943", "1596736952.168227"]], "c": "1082336462"}, "book-100", "XBT/USD"]
[270, {"a": [["11878.00000", "0.00000000", "1596736952.241886"], ["11910.70000", "1.58924162", "1596736944.279722", "r"]], "c": "1082336462"}, "book-100", "XBT/USD"]
[270, {"a": [["11904.90000", "0.00000000", "1596736952.365932"], ["11912.60000", "6.45782985", "1596736937.577118", "r"]], "c": "1082336462"}, "book-100", "XBT/USD"]
[270, {"a": [["11879.30000", "0.02013284", "1596736952.521866"]], "c": "1082336462"}, "book-100", "XBT/USD"]
[270, {"a": [["11892.70000", "0.00000000", "1596736952.647308"], ["11912.60000", "6.45782985", "1596736937.577118", "r"]], "c": "1082336462"}, "book-100", "XBT/USD"]
[270, {"a": [["11879.30000", "0.00000000", "1596736952.713941"], ["11913.00000", "0.17065000", "1596736890.849460", "r"]], "c": "1082336462"}, "book-100", "XBT/USD"]
[270, {"a": [["11882.20000", "0.00711383", "1596736952.714387"]], "c": "1082336462"}, "book-100", "XBT/USD"]
[270, {"b": [["11854.60000", "0.02769649", "1596736952.859434"]], "c": "1082336462"}, "book-100", "XBT/USD"]
[270, {"b": [["11854.60000", "0.00568706", "1596736952.868815"]], "c": "1082336462"}, "book-100", "XBT/USD"]
[270, {"b": [["11860.00000", "0.00000000", "1596736953.044278"], ["11807.50000", "2.19772556", "1596736916.776430", "r"]], "c": "1082336462"}, "book-100", "XBT/USD"]
[270, {"a": [["11870.40000", "9.90885920", "1596736953.045146"]], "c": "1257971517"}, "book-100", "XBT/USD"]
[270, {"b": [["11854.60000", "0.02769649", "1596736953.109202"]], "c": "1257971517"}, "book-100", "XBT/USD"]
[270, {"b": [["11854.60000", "0.02200943", "1596736953.111860"]], "c": "1257971517"}, "book-100", "XBT/USD"]
[270, {"b": [["11858.10000", "0.70201000", "1596736953.116920"]], "c": "1257971517"}, "book-100", "XBT/USD"]
[270, {"b": [["11859.90000", "0.00000000", "1596736953.117340"], ["11807.50000", "2.19772556", "1596736916.776430", "r"]], "c": "1257971517"}, "book-100", "XBT/USD"]
[270, {"a": [["11872.40000", "0.00000000", "1596736953.120429"], ["11913.00000", "0.17065000", "1596736890.849460", "r"]], "c": "3897008073"}, "book-100", "XBT/USD"]
[270, {"b": [["11864.50000", "1.67200000", "1596736953.151306"]], "c": "602494504"}, "book-100", "XBT/USD"]
[270, {"b": [["11868.50000", "0.00000000", "1596736953.156467"], ["11807.50000", "2.19772556", "1596736916.776430", "r"]], "c": "813811015"}, "book-100", "XBT/USD"]
[270, {"a": [["11874.10000", "0.00000000", "1596736953.262224"], ["11913.30000", "6.18341193", "1596736935.389729", "r"]], "c": "2743110713"}, "book-100", "XBT/USD"]
[270, {"b": [["11863.90000", "0.00000000", "1596736953.289756"], ["11807.20000", "6.50000000", "1596736936.572585", "r"]], "c": "1071785440"}, "book-100", "XBT/USD"]
[270, {"a": [["11872.80000", "0.00500000", "1596736953.290279"]], "c": "101833078"}, "book-100", "XBT/USD"]
[270, {"b": [["11864.50000", "0.00000000", "1596736953.290443"], ["11805.90000", "0.15000000", "1596735155.182015", "r"]], "c": "4148817665"}, "book-100", "XBT/USD"]
[270, {"a": [["11875.50000", "0.18435000", "1596736953.294873"]], "c": "4148817665"}, "book-100", "XBT/USD"]
[270, {"a": [["11898.70000", "0.01000000", "1596736953.315052"]], "c": "4148817665"}, "book-100", "XBT/USD"]
[270, {"b": [["11835.80000", "0.73600541", "1596736953.315270"]], "c": "4148817665"}, "book-100", "XBT/USD"]
[270, {"b": [["11837.00000", "6.22321537", "1596736953.316096"]], "c": "4148817665"}, "book-100", "XBT/USD"]
[270, {"b": [["11819.60000", "0.00000000", "1596736953.320501"], ["11805.90000", "0.15000000", "1596735155.182015", "r"]], "c": "4148817665"}, "book-100", "XBT/USD"]
[270, {"b": [["11855.10000", "0.33685110", "1596736953.346196"]], "c": "4148817665"}, "book-100", "XBT/USD"]
[270, {"a": [["11898.60000", "0.73600541", "1596736953.385223"]], "c": "4148817665"}, "book-100", "XBT/USD"]
[270, {"b": [["11854.80000", "0.02200943", "1596736953.398877"]], "c": "4148817665"}, "book-100", "XBT/USD"]
[270, {"b": [["11854.80000", "0.04500943", "1596736953.400242"]], "c": "4148817665"}, "book-100", "XBT/USD"]
[270, {"b": [["11825.20000", "0.00000000", "1596736953.462689"], ["11805.90000", "0.15000000", "1596735155.182015", "r"]], "c": "4148817665"}, "book-100", "XBT/USD"]
[270, {"b": [["11854.80000", "0.02300000", "1596736953.521945"]], "c": "4148817665"}, "book-100", "XBT/USD"]
[270, {"a": [["11872.90000", "1.67300000", "1596736953.522361"]], "c": "3756816954"}, "book-100", "XBT/USD"]
[270, {"b": [["11858.20000", "0.00571771", "1596736953.527195"]], "c": "3756816954"}, "book-100", "XBT/USD"]
[270, {"a": [["11874.10000", "0.84207122", "1596736953.541144"]], "c": "1113894756"}, "book-100", "XBT/USD"]
[270, {"a": [["11871.40000", "0.70000000", "1596736953.577226"]], "c": "904672023"}, "book-100", "XBT/USD"]
[270, {"a": [["11880.90000", "0.27100000", "1596736953.577455"]], "c": "904672023"}, "book-100", "XBT/USD"]
[270, {"a": [["11871.40000", "0.00000000", "1596736953.625428"], ["11910.70000", "1.58924162", "1596736944.279722", "r"]], "c": "1113894756"}, "book-100", "XBT/USD"]
[270, {"a": [["11879.90000", "0.02800000", "1596736953.639513"]], "c": "1113894756"}, "book-100", "XBT/USD"]
[270, {"a": [["11870.40000", "9.50885920", "1596736953.652183"]], "c": "112888363"}, "book-100", "XBT/USD"]
[270, {"b": [["11854.90000", "0.02200943", "1596736953.655746"]], "c": "112888363"}, "book-100", "XBT/USD"]
[270, {"b": [["11858.20000", "0.00000000", "1596736953.656154"], ["11807.20000", "6.50000000", "1596736936.572585", "r"]], "c": "112888363"}, "book-100", "XBT/USD"]
[270, {"a": [["11871.00000", "0.25000000", "1596736953.678204"]], "c": "2348456022"}, "book-100", "XBT/USD"]
[270, {"b": [["11818.00000", "2.20901624", "1596736953.715129"]], "c": "2348456022"}, "book-100", "XBT/USD"]
[270, {"b": [["11865.80000", "0.10000000", "1596736953.716753"]], "c": "2374083955"}, "book-100", "XBT/USD"]
[270, {"a": [["11872.90000", "0.00000000", "1596736953.819287"], ["11910.70000", "1.58924162", "1596736944.279722", "r"]], "c": "1832804455"}, "book-100", "XBT/USD"]
[270, {"a": [["11871.10000", "0.09621094", "1596736953.975918"]], "c": "437592676"}, "book-100", "XBT/USD"]
[270, {"a": [["11871.00000", "0.00000000", "1596736953.999454"], ["11910.70000", "1.58924162", "1596736944.279722", "r"]], "c": "2826447639"}, "book-100", "XBT/USD"]
[270, {"b": [["11857.60000", "0.09621094", "1596736954.050281"]], "c": "2826447639"}, "book-100", "XBT/USD"]
[270, {"b": [["11854.80000", "0.00000000", "1596736954.103078"], ["11807.70000", "3.28855406", "1596736821.611246", "r"]], "c": "2826447639"}, "book-100", "XBT/USD"]
[270, {"a": [["11875.60000", "0.00000000", "1596736954.116197"], ["11912.60000", "6.45782985", "1596736937.577118", "r"]], "c": "2826447639"}, "book-100", "XBT/USD"]
[270, {"b": [["11854.60000", "0.00000000", "1596736954.137505"], ["11807.50000", "2.19772556", "1596736916.776430", "r"]], "c": "2826447639"}, "book-100", "XBT/USD"]
[270, {"b": [["11854.10000", "0.96875191", "1596736954.156364"]], "c": "2826447639"}, "book-100", "XBT/USD"]
[270, {"b": [["11854.90000", "0.00000000", "1596736954.181472"], ["11807.20000", "6.50000000", "1596736936.572585", "r"]], "c": "2826447639"}, "book-100", "XBT/USD"]
[270, {"b": [["11854.80000", "0.02200943", "1596736954.181923"]], "c": "2826447639"}, "book-100", "XBT/USD"]
[270, {"a": [["11870.40000", "9.70885920", "1596736954.229189"]], "c": "3771834340"}, "book-100", "XBT/USD"]
[270, {"b": [["11834.20000", "0.00000000", "1596736954.255870"], ["11807.20000", "6.50000000", "1596736936.572585", "r"]], "c": "3771834340"}, "book-100", "XBT/USD"]
[270, {"a": [["11870.40000", "11.20885920", "1596736954.267995"]], "c": "1974046773"}, "book-100", "XBT/USD"]
[270, {"a": [["11873.50000", "0.71377179", "1596736954.276148"]], "c": "4271537150"}, "book-100", "XBT/USD"]
[270, {"a": [["11896.50000", "7.74227931", "1596736954.302826"]], "c": "4271537150"}, "book-100", "XBT/USD"]
[270, {"b": [["11847.10000", "0.23800000", "1596736954.307658"]], "c": "4271537150"}, "book-100", "XBT/USD"]
[270, {"a": [["11879.90000", "0.01000000", "1596736954.321654"]], "c": "4271537150"}, "book-100", "XBT/USD"]
[270, {"b": [["11811.80000", "0.01263652", "1596736954.340329"]], "c": "4271537150"}, "book-100", "XBT/USD"]
[270, {"b": [["11854.10000", "0.94575191", "1596736954.351620"]], "c": "4271537150"}, "book-100", "XBT/USD"]
[270, {"a": [["11872.20000", "0.25000000", "1596736954.353494"]], "c": "2237767325"}, "book-100", "XBT/USD"]
[270, {"a": [["11878.90000", "0.01800000", "1596736954.373618"]], "c": "2237767325"}, "book-100", "XBT/USD"]
[270, {"b": [["11853.10000", "0.35988667", "1596736954.406597"]], "c": "2237767325"}, "book-100", "XBT/USD"]
[270, {"b": [["11854.80000", "0.00000000", "1596736954.435747"], ["11807.50000", "2.19772556", "1596736916.776430", "r"]], "c": "2237767325"}, "book-100", "XBT/USD"]
[270, {"a": [["11882.30000", "0.54440539", "1596736954.572917"]], "c": "2237767325"}, "book-100", "XBT/USD"]
[270, {"a": [["11882.20000", "0.00000000", "1596736954.574183"], ["11910.70000", "1.58924162", "1596736944.279722", "r"]], "c": "2237767325"}, "book-100", "XBT/USD"]
[270, {"b": [["11808.00000", "0.00000000", "1596736954.625470"], ["11807.20000", "6.50000000", "1596736936.572585", "r"]], "c": "2237767325"}, "book-100", "XBT/USD"]
[270, {"b": [["11854.60000", "0.02200943", "1596736954.671211"]], "c": "2237767325"}, "book-100", "XBT/USD"]
[270, {"a": [["11881.20000", "2.01360223", "1596736954.683180"]], "c": "2237767325"}, "book-100", "XBT/USD"]
[270, {"a": [["11871.40000", "0.46150353", "1596736954.683684"]], "c": "3761890051"}, "book-100", "XBT/USD"]
[270, {"b": [["11855.20000", "0.01632237", "1596736954.795587"]], "c": "3761890051"}, "book-100", "XBT/USD"]
[270, {"b": [["11854.60000", "0.00000000", "1596736954.799685"], ["11807.50000", "2.19772556", "1596736916.776430", "r"]], "c": "3761890051"}, "book-100", "XBT/USD"]
[270, {"b": [["11855.20000", "0.00000000", "1596736954.921141"], ["11807.20000", "6.50000000", "1596736936.572585", "r"]], "c": "3761890051"}, "book-100", "XBT/USD"]
[270, {"b": [["11860.90000", "0.00571771", "1596736954.922075"]], "c": "1207638475"}, "book-100", "XBT/USD"]
[270, {"b": [["11865.40000", "0.01465444", "1596736955.190166"]], "c": "3405217270"}, "book-100", "XBT/USD"]
[270, {"a": [["11877.80000", "0.01465444", "1596736955.190230"]], "c": "3405217270"}, "book-100", "XBT/USD"]
[270, {"a": [["11878.40000", "0.07327207", "1596736955.252420"]], "c": "3405217270"}, "book-100", "XBT/USD"]
[270, {"b": [["11864.90000", "0.07327207", "1596736955.298827"]], "c": "3768019251"}, "book-100", "XBT/USD"]
[270, {"b": [["11864.50000", "0.17585263", "1596736955.308385"]], "c": "1651586752"}, "book-100", "XBT/USD"]
[270, {"a": [["11880.00000", "0.87585263", "1596736955.311228"]], "c": "1651586752"}, "book-100", "XBT/USD"]
[270, {"a": [["11870.40000", "11.90885920", "1596736955.348140"]], "c": "4152406920"}, "book-100", "XBT/USD"]
[270, {"b": [["11855.20000", "0.01632237", "1596736955.617162"]], "c": "4152406920"}, "book-100", "XBT/USD"]
[270, {"b": [["11860.90000", "0.00000000", "1596736955.630525"], ["11811.70000", "5.70000000", "1596736886.902857", "r"]], "c": "4152406920"}, "book-100", "XBT/USD"]
[270, {"a": [["11904.20000", "2.12658834", "1596736956.017027"]], "c": "4152406920"}, "book-100", "XBT/USD"]
[270, {"a": [["11892.00000", "0.44940711", "1596736956.021317"]], "c": "4152406920"}, "book-100", "XBT/USD"]
[270, {"a": [["11900.50000", "0.46880709", "1596736956.313192"]], "c": "4152406920"}, "book-100", "XBT/USD"]
[270, {"b": [["11816.80000", "1.59982701", "1596736956.346601"]], "c": "4152406920"}, "book-100", "XBT/USD"]
[270, {"b": [["11853.70000", "0.07214079", "1596736957.071233"]], "c": "4152406920"}, "book-100", "XBT/USD"]
[270, {"b": [["11855.20000", "0.00000000", "1596736957.074177"], ["11811.80000", "0.01263652", "1596736954.340329", "r"]], "c": "4152406920"}, "book-100", "XBT/USD"]
[270, {"a": [["11875.50000", "0.00000000", "1596736957.419259"], ["11909.10000", "1.00200000", "1596736809.784670", "r"]], "c": "4152406920"}, "book-100", "XBT/USD"]
[270, {"a": [["11901.20000", "0.50000000", "1596736957.489574"]], "c": "4152406920"}, "book-100", "XBT/USD"]
[270, {"a": [["11891.70000", "0.01438186", "1596736957.556778"]], "c": "4152406920"}, "book-100", "XBT/USD"]
[270, {"b": [["11851.20000", "0.00425713", "1596736957.556879"]], "c": "4152406920"}, "book-100", "XBT/USD"]
[270, {"a": [["11872.70000", "0.00000000", "1596736958.885284"], ["11909.10000", "1.00200000", "1596736809.784670", "r"]], "c": "4265466807"}, "book-100", "XBT/USD"]
[270, {"a": [["11870.40000", "11.95635920", "1596736959.012611"]], "c": "3720081473"}, "book-100", "XBT/USD"]
[270, {"b": [["11858.20000", "0.07211341", "1596736959.075546"]], "c": "3720081473"}, "book-100", "XBT/USD"]
[270, {"b": [["11853.70000", "0.00000000", "1596736959.103668"], ["11813.30000", "0.99420000", "1596736809.783550", "r"]], "c": "3720081473"}, "book-100", "XBT/USD"]
[270, {"b": [["11858.20000", "0.13631953", "1596736959.282095"]], "c": "3720081473"}, "book-100", "XBT/USD"]
[270, {"b": [["11858.20000", "0.06420612", "1596736959.292709"]], "c": "3720081473"}, "book-100", "XBT/USD"]
[270, {"b": [["11835.80000", "0.00000000", "1596736959.603271"], ["11811.80000", "0.01263652", "1596736954.340329", "r"]], "c": "3720081473"}, "book-100", "XBT/USD"]
[270, {"a": [["11898.60000", "0.00000000", "1596736959.603659"], ["11909.90000", "6.20000000", "1596736825.518690", "r"]], "c": "3720081473"}, "book-100", "XBT/USD"]
[270, {"a": [["11898.50000", "0.73601168", "1596736959.605848"]], "c": "3720081473"}, "book-100", "XBT/USD"]
[270, {"b": [["11835.30000", "0.73601168", "1596736959.609065"]], "c": "3720081473"}, "book-100", "XBT/USD"]
[270, {"b": [["11863.20000", "0.04392693", "1596736960.698779"]], "c": "3592063634"}, "book-100", "XBT/USD"]
[270, {"a": [["11880.20000", "0.04392693", "1596736960.703074"]], "c": "3592063634"}, "book-100", "XBT/USD"]
[270, {"a": [["11896.00000", "0.00000000", "1596736960.862174"], ["11909.10000", "1.00200000", "1596736809.784670", "r"]], "c": "3592063634"}, "book-100", "XBT/USD"]
[270, {"b": [["11853.40000", "0.94603751", "1596736960.866946"]], "c": "3592063634"}, "book-100", "XBT/USD"]
[270, {"b": [["11851.20000", "0.00000000", "1596736960.897608"], ["11813.30000", "0.99420000", "1596736809.783550", "r"]], "c": "3592063634"}, "book-100", "XBT/USD"]
[270, {"a": [["11906.00000", "0.05458243", "1596736960.945412"]], "c": "3592063634"}, "book-100", "XBT/USD"]
[270, {"a": [["11874.60000", "0.00000000", "1596736961.103820"], ["11909.10000", "1.00200000", "1596736809.784670", "r"]], "c": "3592063634"}, "book-100", "XBT/USD"]
[270, {"b": [["11862.60000", "0.13178079", "1596736961.128180"]], "c": "2842798368"}, "book-100", "XBT/USD"]
[270, {"a": [["11870.40000", "11.25635920", "1596736961.150801"]], "c": "3888014312"}, "book-100", "XBT/USD"]
[270, {"a": [["11880.80000", "0.82496030", "1596736961.196012"]], "c": "3888014312"}, "book-100", "XBT/USD"]
[270, {"a": [["11870.40000", "11.95635920", "1596736961.198657"]], "c": "2842798368"}, "book-100", "XBT/USD"]
[270, {"a": [["11870.40000", "11.25635920", "1596736961.248108"]], "c": "3888014312"}, "book-100", "XBT/USD"]
[270, {"a": [["11904.30000", "3.00000000", "1596736961.452638"]], "c": "3888014312"}, "book-100", "XBT/USD"]
[270, {"b": [["11849.20000", "0.00457362", "1596736961.457452"]], "c": "3888014312"}, "book-100", "XBT/USD"]
[270, {"a": [["11870.40000", "11.95635920", "1596736961.482729"]], "c": "2842798368"}, "book-100", "XBT/USD"]
[270, {"a": [["11870.40000", "11.25635920", "1596736961.533243"]], "c": "3888014312"}, "book-100", "XBT/USD"]
[270, {"a": [["11902.70000", "0.09250000", "1596736961.660567"]], "c": "3888014312"}, "book-100", "XBT/USD"]
[270, {"a": [["11871.40000", "0.61150353", "1596736961.683902"]], "c": "2660558470"}, "book-100", "XBT/USD"]
[270, {"b": [["11865.40000", "0.00000000", "1596736962.298152"], ["11814.70000", "15.09669614", "1596736905.495230", "r"]], "c": "3072148146"}, "book-100", "XBT/USD"]
[270, {"a": [["11871.30000", "0.70000000", "1596736962.349124"]], "c": "2323413029"}, "book-100", "XBT/USD"]
[270, {"a": [["11880.00000", "0.70000000", "1596736962.426951"]], "c": "2323413029"}, "book-100", "XBT/USD"]
[270, {"b": [["11866.00000", "0.01465439", "1596736962.494996"]], "c": "991000621"}, "book-100", "XBT/USD"]
[270, {"b": [["11849.20000", "0.00000000", "1596736962.516495"], ["11814.70000", "15.09669614", "1596736905.495230", "r"]], "c": "991000621"}, "book-100", "XBT/USD"]
[270, {"a": [["11878.80000", "0.17585336", "1596736962.624000"]], "c": "991000621"}, "book-100", "XBT/USD"]
[270, {"a": [["11870.40000", "11.25837628", "1596736962.835127"]], "c": "3914163535"}, "book-100", "XBT/USD"]
[270, {"a": [["11879.50000", "0.00000000", "1596736963.221167"], ["11908.30000", "1.58322230", "1596736949.361051", "r"]], "c": "3914163535"}, "book-100", "XBT/USD"]
[270, {"a": [["11871.50000", "3.38668620", "1596736963.270710"]], "c": "3128051377"}, "book-100", "XBT/USD"]
[270, {"a": [["11871.00000", "0.84237502", "1596736963.329552"]], "c": "2216820618"}, "book-100", "XBT/USD"]
[270, {"a": [["11870.90000", "0.84237502", "1596736963.330989"]], "c": "4160087187"}, "book-100", "XBT/USD"]
[270, {"a": [["11871.30000", "0.00000000", "1596736963.376147"], ["11907.90000", "2.38150000", "1596736895.960018", "r"]], "c": "3178546297"}, "book-100", "XBT/USD"]
[270, {"a": [["11872.20000", "0.00000000", "1596736963.396508"], ["11908.30000", "1.58322230", "1596736949.361051", "r"]], "c": "2966943269"}, "book-100", "XBT/USD"]
[270, {"a": [["11878.00000", "7.60000000", "1596736963.422025"]], "c": "2966943269"}, "book-100", "XBT/USD"]
[270, {"a": [["11892.00000", "0.00000000", "1596736963.427248"], ["11908.30000", "1.58322230", "1596736949.361051", "r"]], "c": "2966943269"}, "book-100", "XBT/USD"]
[270, {"a": [["11870.40000", "11.75837628", "1596736963.462043"]], "c": "3249219012"}, "book-100", "XBT/USD"]
[270, {"b": [["11834.70000", "0.00000000", "1596736963.497875"], ["11813.30000", "0.99420000", "1596736809.783550", "r"]], "c": "3249219012"}, "book-100", "XBT/USD"]
[270, {"b": [["11863.40000", "1.67300000", "1596736963.507749"]], "c": "2385613470"}, "book-100", "XBT/USD"]
[270, {"a": [["11870.40000", "11.95156628", "1596736963.527559"]], "c": "3591534166"}, "book-100", "XBT/USD"]
[270, {"a": [["11871.90000", "0.25000000", "1596736963.589602"]], "c": "4287593668"}, "book-100", "XBT/USD"]
[270, {"b": [["11847.10000", "0.00000000", "1596736963.590505"], ["11813.30000", "0.99420000", "1596736809.783550", "r"]], "c": "4287593668"}, "book-100", "XBT/USD"]
[270, {"a": [["11890.50000", "0.44469511", "1596736963.611672"]], "c": "4287593668"}, "book-100", "XBT/USD"]
[270, {"b": [["11833.80000", "0.23800000", "1596736963.643925"]], "c": "4287593668"}, "book-100", "XBT/USD"]
[270, {"a": [["11898.50000", "0.00000000", "1596736963.730772"], ["11907.90000", "2.38150000", "1596736895.960018", "r"]], "c": "4287593668"}, "book-100", "XBT/USD"]
[270, {"a": [["11898.40000", "0.73601569", "1596736963.741539"]], "c": "4287593668"}, "book-100", "XBT/USD"]
[270, {"b": [["11818.00000", "0.00000000", "1596736963.741903"], ["11813.30000", "0.99420000", "1596736809.783550", "r"]], "c": "4287593668"}, "book-100", "XBT/USD"]
[270, {"b": [["11835.30000", "0.00000000", "1596736963.745231"], ["11811.70000", "5.70000000", "1596736886.902857", "r"]], "c": "4287593668"}, "book-100", "XBT/USD"]
[270, {"b": [["11817.40000", "2.20904710", "1596736963.748690"]], "c": "4287593668"}, "book-100", "XBT/USD"]
[270, {"a": [["11870.40000", "14.83146628", "1596736963.778244"]], "c": "3902617261"}, "book-100", "XBT/USD"]
[270, {"b": [["11835.20000", "0.73601569", "1596736963.780122"]], "c": "3902617261"}, "book-100", "XBT/USD"]
[270, {"a": [["11873.50000", "0.09800000", "1596736963.781406"]], "c": "3902617261"}, "book-100", "XBT/USD"]
[270, {"a": [["11874.10000", "0.00000000", "1596736963.876051"], ["11907.90000", "2.38150000", "1596736895.960018", "r"]], "c": "3902617261"}, "book-100", "XBT/USD"]
[270, {"b": [["11863.40000", "0.00000000", "1596736963.985378"], ["11813.30000", "0.99420000", "1596736809.783550", "r"]], "c": "1798626334"}, "book-100", "XBT/USD"]
[270, {"a": [["11875.90000", "0.00000000", "1596736964.029109"], ["11908.30000", "1.58322230", "1596736949.361051", "r"]], "c": "1798626334"}, "book-100", "XBT/USD"]
[270, {"a": [["11874.90000", "0.58078956", "1596736964.064119"]], "c": "1798626334"}, "book-100", "XBT/USD"]
[270, {"b": [["11848.00000", "0.88400000", "1596736964.108688"]], "c": "1798626334"}, "book-100", "XBT/USD"]
[270, {"a": [["11874.70000", "0.84225970", "1596736964.124835"]], "c": "1798626334"}, "book-100", "XBT/USD"]
[270, {"a": [["11874.90000", "1.22669302", "1596736964.172790"]], "c": "1798626334"}, "book-100", "XBT/USD"]
[270, {"b": [["11843.90000", "0.00000000", "1596736964.518337"], ["11813.30000", "0.99420000", "1596736809.783550", "r"]], "c": "1798626334"}, "book-100", "XBT/USD"]
[270, {"a": [["11874.90000", "0.58078956", "1596736964.615326"]], "c": "1798626334"}, "book-100", "XBT/USD"]
[270, {"a": [["11870.40000", "15.53146628", "1596736964.664056"]], "c": "2614471451"}, "book-100", "XBT/USD"]
[270, {"a": [["11874.60000", "0.67776648", "1596736964.681307"]], "c": "2614471451"}, "book-100", "XBT/USD"]
[270, {"a": [["11874.90000", "0.00000000", "1596736964.766007"], ["11907.00000", "0.17065000", "1596736918.845946", "r"]], "c": "2614471451"}, "book-100", "XBT/USD"]
[270, {"b": [["11839.90000", "0.01000000", "1596736964.903245"]], "c": "2614471451"}, "book-100", "XBT/USD"]
[270, {"a": [["11871.90000", "0.00000000", "1596736964.937393"], ["11907.90000", "2.38150000", "1596736895.960018", "r"]], "c": "1533746175"}, "book-100", "XBT/USD"]
[270, {"a": [["11870.40000", "15.03146628", "1596736964.967007"]], "c": "2520609723"}, "book-100", "XBT/USD"]
[270, {"a": [["11870.40000", "15.53146628", "1596736965.163809"]], "c": "1533746175"}, "book-100", "XBT/USD"]
[270, {"b": [["11854.50000", "0.00000000", "1596736965.648174"], ["11813.30000", "0.99420000", "1596736809.783550", "r"]], "c": "1533746175"}, "book-100", "XBT/USD"]
[270, {"a": [["11895.70000", "0.00000000", "1596736965.685762"], ["11908.30000", "1.58322230", "1596736949.361051", "r"]], "c": "1533746175"}, "book-100", "XBT/USD"]
[270, {"a": [["11874.60000", "0.00000000", "1596736965.695194"], ["11908.90000", "1.06880000", "1596736841.521829", "r"]], "c": "1533746175"}, "book-100", "XBT/USD"]
[270, {"a": [["11891.70000", "0.01000000", "1596736965.706799"]], "c": "1533746175"}, "book-100", "XBT/USD"]
[270, {"a": [["11874.10000", "0.67956905", "1596736965.761208"]], "c": "1533746175"}, "book-100", "XBT/USD"]
[270, {"a": [["11901.20000", "0.00000000", "1596736965.777906"], ["11908.90000", "1.06880000", "1596736841.521829", "r"]], "c": "1533746175"}, "book-100", "XBT/USD"]
[270, {"a": [["11872.20000", "1.68100000", "1596736965.903341"]], "c": "4029335674"}, "book-100", "XBT/USD"]
[270, {"a": [["11872.50000", "0.25000000", "1596736965.924876"]], "c": "2331566615"}, "book-100", "XBT/USD"]
[270, {"a": [["11892.10000", "0.00000000", "1596736965.925047"], ["11908.30000", "1.58322230", "1596736949.361051", "r"]], "c": "2331566615"}, "book-100", "XBT/USD"]
[270, {"a": [["11872.50000", "0.87776910", "1596736965.926755"]], "c": "3439639792"}, "book-100", "XBT/USD"]
[270, {"b": [["11859.80000", "0.00000000", "1596736965.928229"], ["11811.70000", "5.70000000", "1596736886.902857", "r"]], "c": "3439639792"}, "book-100", "XBT/USD"]
[270, {"b": [["11856.90000", "0.00000000", "1596736965.972459"], ["11808.80000", "2.66090576", "1596736784.110515", "r"]], "c": "3439639792"}, "book-100", "XBT/USD"]
[270, {"b": [["11828.30000", "0.10447794", "1596736966.059526"]], "c": "3439639792"}, "book-100", "XBT/USD"]
[270, {"b": [["11854.40000", "1.38821372", "1596736966.072363"]], "c": "3439639792"}, "book-100", "XBT/USD"]
[270, {"a": [["11872.20000", "0.00000000", "1596736966.083033"], ["11908.90000", "1.06880000", "1596736841.521829", "r"]], "c": "3875924976"}, "book-100", "XBT/USD"]
[270, {"a": [["11893.90000", "0.94268290", "1596736966.093318"]], "c": "3875924976"}, "book-100", "XBT/USD"]
[270, {"b": [["11860.20000", "0.33036544", "1596736966.316150"]], "c": "3875924976"}, "book-100", "XBT/USD"]
[270, {"a": [["11890.40000", "2.32700512", "1596736966.320402"]], "c": "3875924976"}, "book-100", "XBT/USD"]
[270, {"b": [["11856.80000", "0.69396636", "1596736966.322180"]], "c": "3875924976"}, "book-100", "XBT/USD"]
[270, {"a": [["11874.10000", "0.00000000", "1596736966.372609"], ["11908.90000", "1.06880000", "1596736841.521829", "r"]], "c": "3875924976"}, "book-100", "XBT/USD"]
[270, {"a": [["11877.80000", "0.00000000", "1596736966.470147"], ["11909.10000", "1.00200000", "1596736809.784670", "r"]], "c": "3875924976"}, "book-100", "XBT/USD"]
[270, {"a": [["11899.20000", "0.00000000", "1596736966.534664"], ["11909.90000", "6.20000000", "1596736825.518690", "r"]], "c": "3875924976"}, "book-100", "XBT/USD"]
[270, {"a": [["11874.70000", "0.00000000", "1596736966.539336"], ["11910.00000", "1.30195553", "1596736936.587874", "r"]], "c": "3875924976"}, "book-100", "XBT/USD"]
[270, {"a": [["11880.80000", "0.13178079", "1596736966.574552"]], "c": "3875924976"}, "book-100", "XBT/USD"]
[270, {"b": [["11863.20000", "0.00000000", "1596736966.580235"], ["11814.70000", "15.09669614", "1596736905.495230", "r"]], "c": "2378133702"}, "book-100", "XBT/USD"]
[270, {"b": [["11862.60000", "0.00000000", "1596736966.581128"], ["11813.30000", "0.99420000", "1596736809.783550", "r"]], "c": "3293666198"}, "book-100", "XBT/USD"]
[270, {"a": [["11896.20000", "7.72516526", "1596736966.581691"]], "c": "3293666198"}, "book-100", "XBT/USD"]
[270, {"a": [["11892.60000", "0.00000000", "1596736966.585428"], ["11910.50000", "1.71128370", "1596736935.716439", "r"]], "c": "3293666198"}, "book-100", "XBT/USD"]
[270, {"b": [["11864.50000", "0.00000000", "1596736966.599274"], ["11811.70000", "5.70000000", "1596736886.902857", "r"]], "c": "1186399333"}, "book-100", "XBT/USD"]
[270, {"a": [["11878.10000", "1.11000777", "1596736966.636141"]], "c": "1186399333"}, "book-100", "XBT/USD"]
[270, {"a": [["11879.60000", "0.01465383", "1596736966.670479"]], "c": "1186399333"}, "book-100", "XBT/USD"]
[270, {"a": [["11872.50000", "1.71978011", "1596736966.781287"]], "c": "1917252620"}, "book-100", "XBT/USD"]
[270, {"a": [["11873.60000", "0.69589916", "1596736966.799318"]], "c": "1917252620"}, "book-100", "XBT/USD"]
[270, {"b": [["11862.00000", "0.13175748", "1596736966.799384"]], "c": "4265284905"}, "book-100", "XBT/USD"]
[270, {"b": [["11862.60000", "0.04391916", "1596736966.800663"]], "c": "1339960571"}, "book-100", "XBT/USD"]
[270, {"b": [["11864.10000", "0.17581847", "1596736966.817198"]], "c": "572082614"}, "book-100", "XBT/USD"]
[270, {"a": [["11893.50000", "0.28554898", "1596736966.834471"]], "c": "572082614"}, "book-100", "XBT/USD"]
[270, {"a": [["11889.90000", "0.20402531", "1596736966.840088"]], "c": "572082614"}, "book-100", "XBT/USD"]
[270, {"a": [["11873.60000", "0.00000000", "1596736966.879819"], ["11909.10000", "1.00200000", "1596736809.784670", "r"]], "c": "572082614"}, "book-100", "XBT/USD"]
[270, {"a": [["11889.80000", "0.00000000", "1596736966.908394"], ["11909.90000", "6.20000000", "1596736825.518690", "r"]], "c": "572082614"}, "book-100", "XBT/USD"]
[270, {"a": [["11901.50000", "0.50000000", "1596736966.946085"]], "c": "572082614"}, "book-100", "XBT/USD"]
[270, {"a": [["11892.50000", "0.00000000", "1596736966.992854"], ["11909.90000", "6.20000000", "1596736825.518690", "r"]], "c": "572082614"}, "book-100", "XBT/USD"]
[270, {"a": [["11886.40000", "1.88230000", "1596736967.066876"]], "c": "572082614"}, "book-100", "XBT/USD"]
[270, {"b": [["11828.20000", "0.00000000", "1596736967.127750"], ["11814.70000", "15.09669614", "1596736905.495230", "r"]], "c": "572082614"}, "book-100", "XBT/USD"]
[270, {"b": [["11834.20000", "5.92289261", "1596736967.212359"]], "c": "572082614"}, "book-100", "XBT/USD"]
[270, {"a": [["11872.90000", "0.64954696", "1596736967.310744"]], "c": "3804620953"}, "book-100", "XBT/USD"]
[270, {"a": [["11884.60000", "0.00000000", "1596736967.333993"], ["11909.10000", "1.00200000", "1596736809.784670", "r"]], "c": "3804620953"}, "book-100", "XBT/USD"]
[270, {"b": [["11856.80000", "0.00000000", "1596736967.385293"], ["11814.70000", "15.09669614", "1596736905.495230", "r"]], "c": "3804620953"}, "book-100", "XBT/USD"]
[270, {"b": [["11863.60000", "1.68000000", "1596736967.504100"]], "c": "661627291"}, "book-100", "XBT/USD"]
[270, {"a": [["11872.70000", "1.68000000", "1596736967.517359"]], "c": "3152960671"}, "book-100", "XBT/USD"]
[270, {"b": [["11854.80000", "0.01541718", "1596736967.529617"]], "c": "3152960671"}, "book-100", "XBT/USD"]
[270, {"b": [["11860.20000", "0.00000000", "1596736967.942459"], ["11815.00000", "0.15000000", "1596736658.818582", "r"]], "c": "3152960671"}, "book-100", "XBT/USD"]
[270, {"b": [["11858.20000", "0.00000000", "1596736967.943784"], ["11814.70000", "15.09669614", "1596736905.495230", "r"]], "c": "3152960671"}, "book-100", "XBT/USD"]
[270, {"a": [["11887.50000", "0.10906853", "1596736967.950154"]], "c": "3152960671"}, "book-100", "XBT/USD"]
[270, {"a": [["11907.50000", "3.26133727", "1596736967.970398"]], "c": "3152960671"}, "book-100", "XBT/USD"]
[270, {"b": [["11864.90000", "0.00000000", "1596736967.991431"], ["11813.30000", "0.99420000", "1596736809.783550", "r"]], "c": "990085507"}, "book-100", "XBT/USD"]
[270, {"a": [["11872.90000", "0.00000000", "1596736967.997143"], ["11908.30000", "1.58322230", "1596736949.361051", "r"]], "c": "990085507"}, "book-100", "XBT/USD"]
[270, {"b": [["11854.70000", "5.00000000", "1596736968.147416"]], "c": "990085507"}, "book-100", "XBT/USD"]
[270, {"a": [["11888.00000", "0.00000000", "1596736968.170299"], ["11908.90000", "1.06880000", "1596736841.521829", "r"]], "c": "990085507"}, "book-100", "XBT/USD"]
[270, {"b": [["11864.00000", "0.07321988", "1596736968.186009"]], "c": "4223058669"}, "book-100", "XBT/USD"]
[270, {"b": [["11866.00000", "0.00000000", "1596736968.250259"], ["11813.30000", "0.99420000", "1596736809.783550", "r"]], "c": "3113301361"}, "book-100", "XBT/USD"]
[270, {"a": [["11872.60000", "0.64910807", "1596736968.331001"]], "c": "3488120475"}, "book-100", "XBT/USD"]
[270, {"a": [["11897.90000", "0.00000000", "1596736968.404156"], ["11908.90000", "1.06880000", "1596736841.521829", "r"]], "c": "3488120475"}, "book-100", "XBT/USD"]
[270, {"a": [["11894.30000", "0.00000000", "1596736968.406851"], ["11909.10000", "1.00200000", "1596736809.784670", "r"]], "c": "3488120475"}, "book-100", "XBT/USD"]
[270, {"b": [["11862.00000", "0.00000000", "1596736968.816462"], ["11811.70000", "5.70000000", "1596736886.902857", "r"]], "c": "3488120475"}, "book-100", "XBT/USD"]
[270, {"b": [["11862.60000", "0.00000000", "1596736968.817099"], ["11808.80000", "2.66090576", "1596736784.110515", "r"]], "c": "3954130339"}, "book-100", "XBT/USD"]
[270, {"a": [["11880.70000", "0.00000000", "1596736968.828637"], ["11909.90000", "6.20000000", "1596736825.518690", "r"]], "c": "3954130339"}, "book-100", "XBT/USD"]
[270, {"b": [["11856.10000", "0.03601765", "1596736968.831778"]], "c": "3954130339"}, "book-100", "XBT/USD"]
[270, {"a": [["11880.20000", "0.00000000", "1596736968.832249"], ["11910.00000", "0.36067000", "1596736968.148143", "r"]], "c": "3954130339"}, "book-100", "XBT/USD"]
[270, {"a": [["11880.80000", "0.00000000", "1596736968.832750"], ["11910.50000", "1.71128370", "1596736935.716439", "r"]], "c": "3954130339"}, "book-100", "XBT/USD"]
[270, {"b": [["11865.60000", "0.00000000", "1596736968.836278"], ["11807.70000", "3.28855406", "1596736821.611246", "r"]], "c": "1977468585"}, "book-100", "XBT/USD"]
[270, {"a": [["11870.40000", "15.03146628", "1596736968.836473"]], "c": "417267275"}, "book-100", "XBT/USD"]
[270, {"b": [["11850.60000", "1.03450000", "1596736968.837343"]], "c": "417267275"}, "book-100", "XBT/USD"]
[270, {"a": [["11870.40000", "15.43146628", "1596736968.837423"]], "c": "1770545507"}, "book-100", "XBT/USD"]
[270, {"b": [["11864.60000", "0.01464318", "1596736968.838607"]], "c": "806213787"}, "book-100", "XBT/USD"]
[270, {"b": [["11861.50000", "0.50000000", "1596736968.838808"]], "c": "806213787"}, "book-100", "XBT/USD"]
[270, {"b": [["11863.60000", "0.00000000", "1596736968.838860"], ["11808.80000", "2.66090576", "1596736784.110515", "r"]], "c": "3300542733"}, "book-100", "XBT/USD"]
[270, {"a": [["11891.80000", "0.00000000", "1596736968.838921"], ["11910.70000", "1.58924162", "1596736944.279722", "r"]], "c": "3300542733"}, "book-100", "XBT/USD"]
[270, {"b": [["11864.10000", "0.00000000", "1596736968.853531"], ["11807.70000", "3.28855406", "1596736821.611246", "r"]], "c": "1873563534"}, "book-100", "XBT/USD"]
[270, {"a": [["11907.00000", "2.07929897", "1596736968.971352"]], "c": "1873563534"}, "book-100", "XBT/USD"]
[270, {"b": [["11859.50000", "0.75135059", "1596736968.985409"]], "c": "1873563534"}, "book-100", "XBT/USD"]
[270, {"a": [["11877.90000", "3.04824999", "1596736968.989070"]], "c": "1873563534"}, "book-100", "XBT/USD"]
[270, {"a": [["11883.40000", "0.32973094", "1596736968.997307"]], "c": "1873563534"}, "book-100", "XBT/USD"]
[270, {"b": [["11856.10000", "0.73004704", "1596736969.008884"]], "c": "1873563534"}, "book-100", "XBT/USD"]
[270, {"b": [["11864.00000", "0.00000000", "1596736969.015489"], ["11807.50000", "2.19772556", "1596736916.776430", "r"]], "c": "1940491917"}, "book-100", "XBT/USD"]
[270, {"b": [["11860.20000", "0.09700000", "1596736969.016240"]], "c": "1940491917"}, "book-100", "XBT/USD"]
[270, {"a": [["11870.40000", "15.46110020", "1596736969.046984"]], "c": "2225093808"}, "book-100", "XBT/USD"]
[270, {"a": [["11882.30000", "0.50000000", "1596736969.053343"]], "c": "2225093808"}, "book-100", "XBT/USD"]
[270, {"b": [["11862.40000", "0.17571752", "1596736969.083911"]], "c": "2254928169"}, "book-100", "XBT/USD"]
[270, {"a": [["11873.50000", "0.24718520", "1596736969.110444"]], "c": "2254928169"}, "book-100", "XBT/USD"]
[270, {"a": [["11904.70000", "1.24182769", "1596736969.145969"]], "c": "2254928169"}, "book-100", "XBT/USD"]
[270, {"a": [["11881.20000", "0.00000000", "1596736969.158858"], ["11910.50000", "1.71128370", "1596736935.716439", "r"]], "c": "2254928169"}, "book-100", "XBT/USD"]
[270, {"b": [["11862.80000", "0.07321678", "1596736969.207012"]], "c": "1893916304"}, "book-100", "XBT/USD"]
[270, {"b": [["11828.10000", "0.00000000", "1596736969.211063"], ["11808.80000", "2.66090576", "1596736784.110515", "r"]], "c": "1893916304"}, "book-100", "XBT/USD"]
[270, {"a": [["11870.40000", "15.43146628", "1596736969.226186"]], "c": "453492228"}, "book-100", "XBT/USD"]
[270, {"b": [["11865.20000", "0.00000000", "1596736969.258753"], ["11807.70000", "3.28855406", "1596736821.611246", "r"]], "c": "654720096"}, "book-100", "XBT/USD"]
[270, {"a": [["11872.50000", "1.46978011", "1596736969.298524"]], "c": "3783018256"}, "book-100", "XBT/USD"]
[270, {"a": [["11886.80000", "0.69223692", "1596736969.302957"]], "c": "3783018256"}, "book-100", "XBT/USD"]
[270, {"a": [["11882.30000", "0.54440539", "1596736969.304137"]], "c": "3783018256"}, "book-100", "XBT/USD"]
[270, {"b": [["11862.50000", "0.25274618", "1596736969.314322"]], "c": "1153324014"}, "book-100", "XBT/USD"]
[270, {"b": [["11863.80000", "0.25274618", "1596736969.317975"]], "c": "1229421284"}, "book-100", "XBT/USD"]
[270, {"b": [["11853.60000", "0.00000000", "1596736969.451705"], ["11808.80000", "2.66090576", "1596736784.110515", "r"]], "c": "1229421284"}, "book-100", "XBT/USD"]
[270, {"b": [["11849.10000", "3.48827650", "1596736969.464992"]], "c": "1229421284"}, "book-100", "XBT/USD"]
[270, {"b": [["11862.50000", "0.00000000", "1596736969.484121"], ["11807.70000", "3.28855406", "1596736821.611246", "r"]], "c": "3103064534"}, "book-100", "XBT/USD"]
[270, {"a": [["11872.10000", "0.25000000", "1596736969.491240"]], "c": "1699405956"}, "book-100", "XBT/USD"]
[270, {"a": [["11878.60000", "0.00000000", "1596736969.581609"], ["11910.00000", "0.36067000", "1596736968.148143", "r"]], "c": "1699405956"}, "book-100", "XBT/USD"]
[270, {"a": [["11875.70000", "0.28399999", "1596736969.621592"]], "c": "1699405956"}, "book-100", "XBT/USD"]
[270, {"a": [["11875.70000", "0.55299999", "1596736969.624406"]], "c": "1699405956"}, "book-100", "XBT/USD"]
[270, {"a": [["11870.40000", "13.43146628", "1596736969.677289"]], "c": "2525004301"}, "book-100", "XBT/USD"]
[270, {"b": [["11854.80000", "0.00000000", "1596736969.680367"], ["11807.50000", "2.19772556", "1596736916.776430", "r"]], "c": "2525004301"}, "book-100", "XBT/USD"]
[270, {"a": [["11871.50000", "1.38668620", "1596736969.691813"]], "c": "3642755701"}, "book-100", "XBT/USD"]
[270, {"b": [["11854.80000", "0.03173955", "1596736969.696110"]], "c": "3642755701"}, "book-100", "XBT/USD"]
[270, {"a": [["11870.40000", "10.55156628", "1596736969.815346"]], "c": "3941477751"}, "book-100", "XBT/USD"]
[271, [["11870.40000", "0.00167557", "1596736969.965608", "b", "m", ""]], "trade", "XBT/USD"]
[270, {"a": [["11870.40000", "10.54989071", "1596736969.965608"]], "c": "2148810391"}, "book-100", "XBT/USD"]
[270, {"b": [["11836.70000", "0.00000000", "1596736969.980144"], ["11807.50000", "2.19772556", "1596736916.776430", "r"]], "c": "2148810391"}, "book-100", "XBT/USD"]
[270, {"a": [["11898.00000", "0.00000000", "1596736969.981627"], ["11910.00000", "0.36067000", "1596736968.148143", "r"]], "c": "2148810391"}, "book-100", "XBT/USD"]
[270, {"b": [["11827.10000", "0.75800000", "1596736969.981744"]], "c": "2148810391"}, "book-100", "XBT/USD"]
[270, {"b": [["11851.90000", "3.27669620", "1596736970.127656"]], "c": "2148810391"}, "book-100", "XBT/USD"]
[270, {"b": [["11854.80000", "0.00000000", "1596736970.138250"], ["11807.70000", "3.28855406", "1596736821.611246", "r"]], "c": "2148810391"}, "book-100", "XBT/USD"]
[270, {"b": [["11858.20000", "0.06420612", "1596736970.138575"]], "c": "2148810391"}, "book-100", "XBT/USD"]
[270, {"a": [["11892.50000", "3.26550984", "1596736970.236266"]], "c": "2148810391"}, "book-100", "XBT/USD"]
[270, {"a": [["11870.40000", "12.54989071", "1596736970.236733"]], "c": "3511820048"}, "book-100", "XBT/USD"]
[270, {"b": [["11854.80000", "0.03176834", "1596736970.265358"]], "c": "3511820048"}, "book-100", "XBT/USD"]
[270, {"b": [["11858.20000", "0.00000000", "1596736970.482171"], ["11808.80000", "2.66090576", "1596736784.110515", "r"]], "c": "3511820048"}, "book-100", "XBT/USD"]
[270, {"b": [["11854.80000", "0.00000000", "1596736970.574584"], ["11807.70000", "3.28855406", "1596736821.611246", "r"]], "c": "3511820048"}, "book-100", "XBT/USD"]
[270, {"b": [["11854.80000", "0.07213409", "1596736970.578878"]], "c": "3511820048"}, "book-100", "XBT/USD"]
[270, {"a": [["11890.50000", "0.00000000", "1596736970.661918"], ["11910.00000", "0.36067000", "1596736968.148143", "r"]], "c": "3511820048"}, "book-100", "XBT/USD"]
[270, {"a": [["11872.70000", "0.00000000", "1596736970.693651"], ["11910.50000", "1.71128370", "1596736935.716439", "r"]], "c": "3511820048"}, "book-100", "XBT/USD"]
[270, {"a": [["11872.40000", "1.68200000", "1596736970.717483"]], "c": "4165181087"}, "book-100", "XBT/USD"]
[270, {"a": [["11878.80000", "0.00000000", "1596736972.477731"], ["11910.50000", "1.71128370", "1596736935.716439", "r"]], "c": "4165181087"}, "book-100", "XBT/USD"]
[270, {"a": [["11895.30000", "3.09628537", "1596736972.485984"]], "c": "4165181087"}, "book-100", "XBT/USD"]
[270, {"a": [["11898.20000", "0.73600605", "1596736972.486981"]], "c": "4165181087"}, "book-100", "XBT/USD"]
[270, {"a": [["11889.90000", "0.73432130", "1596736972.487204"]], "c": "4165181087"}, "book-100", "XBT/USD"]
[270, {"a": [["11872.10000", "0.00000000", "1596736972.496807"], ["11910.00000", "0.36067000", "1596736968.148143", "r"]], "c": "3317055646"}, "book-100", "XBT/USD"]
[270, {"a": [["11907.20000", "6.18638192", "1596736972.522950"]], "c": "3317055646"}, "book-100", "XBT/USD"]
[270, {"a": [["11872.40000", "0.00000000", "1596736972.527453"], ["11910.00000", "0.36067000", "1596736968.148143", "r"]], "c": "1544465187"}, "book-100", "XBT/USD"]
[270, {"b": [["11808.90000", "0.01263652", "1596736972.528044"]], "c": "1544465187"}, "book-100", "XBT/USD"]
[270, {"b": [["11834.20000", "0.00000000", "1596736972.530686"], ["11808.80000", "2.66090576", "1596736784.110515", "r"]], "c": "1544465187"}, "book-100", "XBT/USD"]
[270, {"b": [["11834.80000", "0.73600605", "1596736972.533780"]], "c": "1544465187"}, "book-100", "XBT/USD"]
[270, {"b": [["11865.20000", "0.25273018", "1596736972.544485"]], "c": "2341238545"}, "book-100", "XBT/USD"]
[270, {"b": [["11822.20000", "13.68215882", "1596736972.557990"]], "c": "2341238545"}, "book-100", "XBT/USD"]
[270, {"b": [["11835.20000", "0.00000000", "1596736972.566266"], ["11811.70000", "5.70000000", "1596736886.902857", "r"]], "c": "2341238545"}, "book-100", "XBT/USD"]
[270, {"b": [["11848.60000", "0.00423915", "1596736972.575411"]], "c": "2341238545"}, "book-100", "XBT/USD"]
[270, {"a": [["11889.90000", "0.73870316", "1596736972.578076"]], "c": "2341238545"}, "book-100", "XBT/USD"]
[270, {"a": [["11898.40000", "0.00000000", "1596736972.579795"], ["11910.50000", "1.71128370", "1596736935.716439", "r"]], "c": "2341238545"}, "book-100", "XBT/USD"]
[270, {"b": [["11845.50000", "0.33714816", "1596736972.594938"]], "c": "2341238545"}, "book-100", "XBT/USD"]
[270, {"a": [["11902.70000", "0.00000000", "1596736972.629398"], ["11910.70000", "1.58924162", "1596736944.279722", "r"]], "c": "2341238545"}, "book-100", "XBT/USD"]
[270, {"a": [["11892.90000", "0.05223957", "1596736972.678025"]], "c": "2341238545"}, "book-100", "XBT/USD"]
[270, {"a": [["11904.20000", "0.00000000", "1596736972.694942"], ["11910.70000", "1.58924162", "1596736944.279722", "r"]], "c": "2341238545"}, "book-100", "XBT/USD"]
[270, {"a": [["11878.90000", "0.19377314", "1596736972.701180"]], "c": "2341238545"}, "book-100", "XBT/USD"]
[270, {"b": [["11820.40000", "0.00000000", "1596736972.701319"], ["11813.30000", "0.99420000", "1596736809.783550", "r"]], "c": "2341238545"}, "book-100", "XBT/USD"]
[270, {"a": [["11871.80000", "0.25000000", "1596736972.718365"]], "c": "2703424308"}, "book-100", "XBT/USD"]
[270, {"a": [["11889.90000", "0.20840717", "1596736972.723603"]], "c": "2703424308"}, "book-100", "XBT/USD"]
[270, {"a": [["11898.20000", "0.00000000", "1596736972.764965"], ["11910.70000", "1.58924162", "1596736944.279722", "r"]], "c": "2703424308"}, "book-100", "XBT/USD"]
[270, {"b": [["11834.80000", "0.00000000", "1596736972.783495"], ["11811.70000", "5.70000000", "1596736886.902857", "r"]], "c": "2703424308"}, "book-100", "XBT/USD"]
[270, {"b": [["11854.80000", "0.00000000", "1596736972.797358"], ["11808.90000", "0.01263652", "1596736972.528044", "r"]], "c": "2703424308"}, "book-100", "XBT/USD"]
[270, {"b": [["11854.80000", "0.03147737", "1596736972.807403"]], "c": "2703424308"}, "book-100", "XBT/USD"]
[270, {"a": [["11877.80000", "0.09250000", "1596736972.862976"]], "c": "2703424308"}, "book-100", "XBT/USD"]
[270, {"a": [["11898.00000", "0.73600899", "1596736972.925954"]], "c": "2703424308"}, "book-100", "XBT/USD"]
[270, {"b": [["11811.80000", "4.23305508", "1596736972.960659"]], "c": "2703424308"}, "book-100", "XBT/USD"]
[270, {"a": [["11895.70000", "0.48775434", "1596736972.962291"]], "c": "2703424308"}, "book-100", "XBT/USD"]
[270, {"a": [["11907.40000", "2.11462668", "1596736972.963075"]], "c": "2703424308"}, "book-100", "XBT/USD"]
[270, {"b": [["11834.60000", "0.73600899", "1596736972.968420"]], "c": "2703424308"}, "book-100", "XBT/USD"]
[270, {"b": [["11848.60000", "0.00000000", "1596736972.991140"], ["11811.80000", "4.23305508", "1596736972.960659", "r"]], "c": "2703424308"}, "book-100", "XBT/USD"]
[270, {"a": [["11895.70000", "0.00000000", "1596736973.160252"], ["11909.90000", "6.20000000", "1596736825.518690", "r"]], "c": "2703424308"}, "book-100", "XBT/USD"]
[270, {"b": [["11854.80000", "0.00000000", "1596736973.300187"], ["11811.70000", "5.70000000", "1596736886.902857", "r"]], "c": "2703424308"}, "book-100", "XBT/USD"]
[270, {"b": [["11854.80000", "0.01515500", "1596736973.342346"]], "c": "2703424308"}, "book-100", "XBT/USD"]
[270, {"a": [["11889.90000", "0.70329587", "1596736973.347302"]], "c": "2703424308"}, "book-100", "XBT/USD"]
[270, {"a": [["11878.40000", "0.00000000", "1596736973.696335"], ["11910.00000", "0.36067000", "1596736968.148143", "r"]], "c": "2703424308"}, "book-100", "XBT/USD"]
[270, {"a": [["11879.60000", "0.00000000", "1596736973.756811"], ["11910.50000", "1.71128370", "1596736935.716439", "r"]], "c": "2703424308"}, "book-100", "XBT/USD"]
[270, {"b": [["11864.20000", "1.68000000", "1596736973.924580"]], "c": "979047725"}, "book-100", "XBT/USD"]
[270, {"a": [["11872.80000", "1.68900000", "1596736973.948604"]], "c": "979047725"}, "book-100", "XBT/USD"]
[270, {"a": [["11870.40000", "11.84989071", "1596736973.985199"]], "c": "3918100693"}, "book-100", "XBT/USD"]
[270, {"a": [["11870.40000", "12.54989071", "1596736974.033182"]], "c": "979047725"}, "book-100", "XBT/USD"]
[270, {"b": [["11833.80000", "0.00000000", "1596736974.524025"], ["11811.80000", "4.23305508", "1596736972.960659", "r"]], "c": "979047725"}, "book-100", "XBT/USD"]
[270, {"b": [["11854.10000", "0.96274354", "1596736974.743022"]], "c": "979047725"}, "book-100", "XBT/USD"]
[270, {"b": [["11854.80000", "0.00000000", "1596736974.744792"], ["11811.70000", "5.70000000", "1596736886.902857", "r"]], "c": "979047725"}, "book-100", "XBT/USD"]
[270, {"b": [["11855.40000", "1.11965000", "1596736974.968040"]], "c": "979047725"}, "book-100", "XBT/USD"]
[270, {"b": [["11856.10000", "0.03601765", "1596736975.149281"]], "c": "979047725"}, "book-100", "XBT/USD"]
[270, {"b": [["11859.50000", "0.42095515", "1596736975.154634"]], "c": "979047725"}, "book-100", "XBT/USD"]
[270, {"b": [["11854.40000", "0.00000000", "1596736975.157035"], ["11808.80000", "2.66090576", "1596736784.110515", "r"]], "c": "979047725"}, "book-100", "XBT/USD"]
[270, {"a": [["11886.80000", "0.00000000", "1596736975.230039"], ["11910.70000", "1.58924162", "1596736944.279722", "r"]], "c": "979047725"}, "book-100", "XBT/USD"]
[270, {"b": [["11817.40000", "0.00000000", "1596736975.461939"], ["11807.70000", "3.28855406", "1596736821.611246", "r"]], "c": "979047725"}, "book-100", "XBT/USD"]
[270, {"b": [["11816.50000", "2.20904692", "1596736975.473541"]], "c": "979047725"}, "book-100", "XBT/USD"]
[270, {"a": [["11883.40000", "0.00000000", "1596736975.593497"], ["11912.60000", "6.45782985", "1596736937.577118", "r"]], "c": "979047725"}, "book-100", "XBT/USD"]
[270, {"b": [["11856.90000", "0.69398124", "1596736975.630647"]], "c": "979047725"}, "book-100", "XBT/USD"]
[270, {"a": [["11888.50000", "0.69213661", "1596736975.643672"]], "c": "979047725"}, "book-100", "XBT/USD"]
[270, {"b": [["11860.30000", "0.33037252", "1596736975.650664"]], "c": "979047725"}, "book-100", "XBT/USD"]
[270, {"b": [["11854.50000", "1.38824347", "1596736975.656516"]], "c": "979047725"}, "book-100", "XBT/USD"]
[270, {"b": [["11854.80000", "0.00791212", "1596736975.881632"]], "c": "979047725"}, "book-100", "XBT/USD"]
[270, {"b": [["11854.10000", "0.94575191", "1596736975.886404"]], "c": "979047725"}, "book-100", "XBT/USD"]
[270, {"a": [["11885.00000", "0.32968592", "1596736976.096251"]], "c": "979047725"}, "book-100", "XBT/USD"]
[270, {"a": [["11882.90000", "0.00000000", "1596736976.178045"], ["11910.70000", "1.58924162", "1596736944.279722", "r"]], "c": "979047725"}, "book-100", "XBT/USD"]
[270, {"b": [["11862.40000", "0.00000000", "1596736976.196286"], ["11813.30000", "0.99420000", "1596736809.783550", "r"]], "c": "846682244"}, "book-100", "XBT/USD"]
[270, {"a": [["11886.30000", "5.55054958", "1596736976.274845"]], "c": "846682244"}, "book-100", "XBT/USD"]
[270, {"a": [["11872.80000", "0.00500000", "1596736976.323975"]], "c": "846682244"}, "book-100", "XBT/USD"]
[270, {"b": [["11862.80000", "0.00000000", "1596736976.338665"], ["11811.80000", "4.23305508", "1596736972.960659", "r"]], "c": "3560685766"}, "book-100", "XBT/USD"]
[270, {"b": [["11834.20000", "5.92264238", "1596736976.353239"]], "c": "3560685766"}, "book-100", "XBT/USD"]
[270, {"a": [["11872.60000", "2.32410807", "1596736976.354766"]], "c": "2584507146"}, "book-100", "XBT/USD"]
[270, {"a": [["11870.40000", "11.84989071", "1596736976.377440"]], "c": "2572548003"}, "book-100", "XBT/USD"]
[270, {"a": [["11870.40000", "12.54989071", "1596736976.425046"]], "c": "2584507146"}, "book-100", "XBT/USD"]
[270, {"b": [["11853.40000", "0.00000000", "1596736976.550294"], ["11811.80000", "4.23305508", "1596736972.960659", "r"]], "c": "2584507146"}, "book-100", "XBT/USD"]
[270, {"b": [["11863.80000", "0.00000000", "1596736976.560729"], ["11811.70000", "5.70000000", "1596736886.902857", "r"]], "c": "4181301691"}, "book-100", "XBT/USD"]
[270, {"a": [["11900.70000", "0.00500000", "1596736976.571243"]], "c": "4181301691"}, "book-100", "XBT/USD"]
[270, {"a": [["11885.00000", "0.00000000", "1596736976.611298"], ["11910.70000", "1.58924162", "1596736944.279722", "r"]], "c": "4181301691"}, "book-100", "XBT/USD"]
[270, {"b": [["11856.90000", "0.00000000", "1596736976.611374"], ["11808.80000", "2.66090576", "1596736784.110515", "r"]], "c": "4181301691"}, "book-100", "XBT/USD"]
[270, {"a": [["11888.50000", "0.00000000", "1596736976.614462"], ["11912.60000", "6.45782985", "1596736937.577118", "r"]], "c": "4181301691"}, "book-100", "XBT/USD"]
[270, {"b": [["11865.70000", "0.25272512", "1596736976.614651"]], "c": "3323111524"}, "book-100", "XBT/USD"]
[270, {"b": [["11860.30000", "0.00000000", "1596736976.630063"], ["11808.80000", "2.66090576", "1596736784.110515", "r"]], "c": "3323111524"}, "book-100", "XBT/USD"]
[270, {"a": [["11889.90000", "0.69891401", "1596736976.708074"]], "c": "3323111524"}, "book-100", "XBT/USD"]
[270, {"a": [["11870.40000", "12.14989071", "1596736976.837466"]], "c": "3074701132"}, "book-100", "XBT/USD"]
[270, {"a": [["11872.60000", "0.64910807", "1596736976.841392"]], "c": "1866447596"}, "book-100", "XBT/USD"]
[270, {"b": [["11857.00000", "0.00000000", "1596736976.849021"], ["11807.70000", "3.28855406", "1596736821.611246", "r"]], "c": "1866447596"}, "book-100", "XBT/USD"]
[270, {"a": [["11870.40000", "11.44989071", "1596736976.890548"]], "c": "2501729191"}, "book-100", "XBT/USD"]
[270, {"a": [["11889.90000", "0.20402531", "1596736976.923785"]], "c": "2501729191"}, "book-100", "XBT/USD"]
[270, {"a": [["11898.30000", "1.05639111", "1596736976.930829"]], "c": "2501729191"}, "book-100", "XBT/USD"]
[270, {"b": [["11848.50000", "1.19560629", "1596736977.041072"]], "c": "2501729191"}, "book-100", "XBT/USD"]
[270, {"a": [["11890.50000", "0.44745409", "1596736977.102544"]], "c": "2501729191"}, "book-100", "XBT/USD"]
[270, {"a": [["11871.80000", "0.00000000", "1596736977.116971"], ["11910.70000", "1.58924162", "1596736944.279722", "r"]], "c": "2972565814"}, "book-100", "XBT/USD"]
[270, {"b": [["11854.60000", "0.10937215", "1596736977.191348"]], "c": "2972565814"}, "book-100", "XBT/USD"]
[270, {"a": [["11890.50000", "0.00000000", "1596736977.332697"], ["11912.60000", "6.45782985", "1596736937.577118", "r"]], "c": "2972565814"}, "book-100", "XBT/USD"]
[270, {"a": [["11872.60000", "0.89910807", "1596736977.481953"]], "c": "2662972110"}, "book-100", "XBT/USD"]
[270, {"a": [["11892.40000", "0.58821982", "1596736977.513185"]], "c": "2662972110"}, "book-100", "XBT/USD"]
[270, {"a": [["11870.40000", "12.14989071", "1596736977.543701"]], "c": "1082009905"}, "book-100", "XBT/USD"]
[270, {"a": [["11872.60000", "0.64910807", "1596736977.928748"]], "c": "1877627593"}, "book-100", "XBT/USD"]
[270, {"a": [["11870.40000", "11.44989071", "1596736977.976988"]], "c": "2972565814"}, "book-100", "XBT/USD"]
[270, {"a": [["11892.40000", "0.00000000", "1596736978.009273"], ["11912.60000", "6.45782985", "1596736937.577118", "r"]], "c": "2972565814"}, "book-100", "XBT/USD"]
[270, {"a": [["11890.30000", "0.42086948", "1596736978.192642"]], "c": "2972565814"}, "book-100", "XBT/USD"]
[270, {"a": [["11871.20000", "0.25000000", "1596736978.274865"]], "c": "1393176322"}, "book-100", "XBT/USD"]
[270, {"b": [["11854.80000", "0.03214661", "1596736978.443794"]], "c": "1393176322"}, "book-100", "XBT/USD"]
[270, {"b": [["11854.80000", "0.02423449", "1596736978.448858"]], "c": "1393176322"}, "book-100", "XBT/USD"]
[270, {"a": [["11890.40000", "0.94296038", "1596736978.872280"]], "c": "1393176322"}, "book-100", "XBT/USD"]
[270, {"a": [["11871.50000", "1.19553620", "1596736979.052692"]], "c": "863937425"}, "book-100", "XBT/USD"]
[270, {"a": [["11898.00000", "0.90665899", "1596736979.254143"]], "c": "863937425"}, "book-100", "XBT/USD"]
[270, {"a": [["11898.00000", "0.17065000", "1596736979.279140"]], "c": "863937425"}, "book-100", "XBT/USD"]
[270, {"b": [["11834.60000", "0.00000000", "1596736979.280513"], ["11807.70000", "3.28855406", "1596736821.611246", "r"]], "c": "863937425"}, "book-100", "XBT/USD"]
[270, {"a": [["11897.40000", "0.73601095", "1596736979.289629"]], "c": "863937425"}, "book-100", "XBT/USD"]
[270, {"b": [["11834.50000", "0.73601095", "1596736979.291696"]], "c": "863937425"}, "book-100", "XBT/USD"]
[270, {"a": [["11890.20000", "0.00438186", "1596736979.905290"]], "c": "863937425"}, "book-100", "XBT/USD"]
[270, {"b": [["11854.80000", "0.09636858", "1596736979.999607"]], "c": "863937425"}, "book-100", "XBT/USD"]
[270, {"b": [["11854.80000", "0.07213409", "1596736980.000342"]], "c": "863937425"}, "book-100", "XBT/USD"]
[270, {"b": [["11841.50000", "0.00425062", "1596736980.136051"]], "c": "863937425"}, "book-100", "XBT/USD"]
[270, {"b": [["11854.80000", "0.11269095", "1596736980.262910"]], "c": "863937425"}, "book-100", "XBT/USD"]
[270, {"b": [["11854.80000", "0.04055686", "1596736980.264513"]], "c": "863937425"}, "book-100", "XBT/USD"]
[270, {"b": [["11841.50000", "0.00000000", "1596736980.576000"], ["11808.80000", "2.66090576", "1596736784.110515", "r"]], "c": "863937425"}, "book-100", "XBT/USD"]
[270, {"b": [["11854.80000", "0.06479135", "1596736980.609223"]], "c": "863937425"}, "book-100", "XBT/USD"]
[270, {"b": [["11854.80000", "0.02423449", "1596736980.611817"]], "c": "863937425"}, "book-100", "XBT/USD"]
[270, {"a": [["11886.30000", "0.00000000", "1596736980.622915"], ["11910.00000", "0.36067000", "1596736968.148143", "r"]], "c": "863937425"}, "book-100", "XBT/USD"]
[270, {"a": [["11882.80000", "5.55054958", "1596736980.709295"]], "c": "863937425"}, "book-100", "XBT/USD"]
[270, {"a": [["11889.30000", "1.38408761", "1596736981.330824"]], "c": "863937425"}, "book-100", "XBT/USD"]
[270, {"a": [["11886.90000", "0.69218353", "1596736981.335945"]], "c": "863937425"}, "book-100", "XBT/USD"]
[270, {"b": [["11859.70000", "0.33036716", "1596736981.337569"]], "c": "863937425"}, "book-100", "XBT/USD"]
[270, {"b": [["11856.30000", "0.69396999", "1596736981.352641"]], "c": "863937425"}, "book-100", "XBT/USD"]
[270, {"a": [["11883.50000", "0.32970551", "1596736981.354317"]], "c": "863937425"}, "book-100", "XBT/USD"]
[270, {"b": [["11865.70000", "0.00000000", "1596736982.394477"], ["11811.70000", "5.70000000", "1596736886.902857", "r"]], "c": "206934606"}, "book-100", "XBT/USD"]
[270, {"b": [["11864.20000", "0.00000000", "1596736982.424440"], ["11808.80000", "2.66090576", "1596736784.110515", "r"]], "c": "2193859784"}, "book-100", "XBT/USD"]
[270, {"b": [["11863.40000", "0.25273316", "1596736982.453860"]], "c": "3944286010"}, "book-100", "XBT/USD"]
[270, {"b": [["11864.40000", "0.10000000", "1596736982.464480"]], "c": "412666226"}, "book-100", "XBT/USD"]
[270, {"b": [["11864.40000", "0.00000000", "1596736982.521273"], ["11811.70000", "5.70000000", "1596736886.902857", "r"]], "c": "3944286010"}, "book-100", "XBT/USD"]
[270, {"a": [["11870.40000", "12.14989071", "1596736982.701302"]], "c": "3334811428"}, "book-100", "XBT/USD"]
[270, {"a": [["11870.40000", "11.44989071", "1596736982.750290"]], "c": "3944286010"}, "book-100", "XBT/USD"]
[270, {"b": [["11854.80000", "0.00000000", "1596736983.069829"], ["11808.80000", "2.66090576", "1596736784.110515", "r"]], "c": "3944286010"}, "book-100", "XBT/USD"]
[270, {"b": [["11854.80000", "0.00791212", "1596736983.078835"]], "c": "3944286010"}, "book-100", "XBT/USD"]
[270, {"b": [["11835.00000", "0.00000000", "1596736983.652309"], ["11808.80000", "2.66090576", "1596736784.110515", "r"]], "c": "3944286010"}, "book-100", "XBT/USD"]
[270, {"a": [["11890.20000", "0.00000000", "1596736983.774487"], ["11908.90000", "1.06880000", "1596736841.521829", "r"]], "c": "3944286010"}, "book-100", "XBT/USD"]
[270, {"a": [["11904.30000", "0.00000000", "1596736984.531062"], ["11909.10000", "1.00200000", "1596736809.784670", "r"]], "c": "3944286010"}, "book-100", "XBT/USD"]
[270, {"a": [["11882.80000", "0.00000000", "1596736985.128307"], ["11909.50000", "0.00424000", "1596736984.920988", "r"]], "c": "3944286010"}, "book-100", "XBT/USD"]
[270, {"a": [["11886.30000", "5.54966200", "1596736985.209477"]], "c": "3944286010"}, "book-100", "XBT/USD"]
[270, {"b": [["11834.50000", "0.00000000", "1596736985.414777"], ["11807.70000", "3.28855406", "1596736821.611246", "r"]], "c": "3944286010"}, "book-100", "XBT/USD"]
[270, {"a": [["11897.40000", "0.00000000", "1596736985.414970"], ["11909.50000", "0.00424000", "1596736984.920988", "r"]], "c": "3944286010"}, "book-100", "XBT/USD"]
[270, {"b": [["11835.20000", "0.73599920", "1596736985.416505"]], "c": "3944286010"}, "book-100", "XBT/USD"]
[270, {"a": [["11897.30000", "0.73599920", "1596736985.420455"]], "c": "3944286010"}, "book-100", "XBT/USD"]
[270, {"b": [["11816.50000", "0.00000000", "1596736985.830296"], ["11807.70000", "3.28855406", "1596736821.611246", "r"]], "c": "3944286010"}, "book-100", "XBT/USD"]
[270, {"b": [["11817.30000", "2.20900501", "1596736985.855126"]], "c": "3944286010"}, "book-100", "XBT/USD"]
[270, {"a": [["11879.40000", "0.00000000", "1596736987.472037"], ["11909.50000", "0.00424000", "1596736984.920988", "r"]], "c": "3944286010"}, "book-100", "XBT/USD"]
[270, {"a": [["11870.60000", "0.84247116", "1596736987.531188"]], "c": "555992191"}, "book-100", "XBT/USD"]
[270, {"a": [["11870.40000", "12.14989071", "1596736987.584904"]], "c": "218098785"}, "book-100", "XBT/USD"]
[270, {"a": [["11898.80000", "7.20585816", "1596736987.741509"]], "c": "218098785"}, "book-100", "XBT/USD"]
[270, {"b": [["11854.80000", "0.00000000", "1596736988.414696"], ["11807.70000", "3.28855406", "1596736821.611246", "r"]], "c": "218098785"}, "book-100", "XBT/USD"]
[270, {"b": [["11853.60000", "0.01699163", "1596736988.415397"]], "c": "218098785"}, "book-100", "XBT/USD"]
[270, {"b": [["11848.00000", "0.00000000", "1596736988.643574"], ["11807.70000", "3.28855406", "1596736821.611246", "r"]], "c": "218098785"}, "book-100", "XBT/USD"]
[270, {"a": [["11891.60000", "0.68400000", "1596736988.644971"]], "c": "218098785"}, "book-100", "XBT/USD"]
[270, {"b": [["11853.60000", "0.04122698", "1596736988.666231"]], "c": "218098785"}, "book-100", "XBT/USD"]
[270, {"b": [["11853.60000", "0.02423535", "1596736988.667457"]], "c": "218098785"}, "book-100", "XBT/USD"]
[270, {"b": [["11853.60000", "0.00000000", "1596736989.073383"], ["11807.50000", "2.19772556", "1596736916.776430", "r"]], "c": "218098785"}, "book-100", "XBT/USD"]
[270, {"b": [["11853.60000", "0.07214140", "1596736989.074163"]], "c": "218098785"}, "book-100", "XBT/USD"]
[270, {"a": [["11901.50000", "0.00000000", "1596736989.196902"], ["11909.10000", "1.00200000", "1596736809.784670", "r"]], "c": "218098785"}, "book-100", "XBT/USD"]
[270, {"b": [["11853.60000", "0.00000000", "1596736989.200673"], ["11807.50000", "2.19772556", "1596736916.776430", "r"]], "c": "218098785"}, "book-100", "XBT/USD"]
[270, {"b": [["11853.60000", "0.02423535", "1596736989.201175"]], "c": "218098785"}, "book-100", "XBT/USD"]
[270, {"b": [["11853.60000", "0.00000000", "1596736989.348176"], ["11807.50000", "2.19772556", "1596736916.776430", "r"]], "c": "218098785"}, "book-100", "XBT/USD"]
[270, {"b": [["11853.60000", "0.00791298", "1596736989.349377"]], "c": "218098785"}, "book-100", "XBT/USD"]
[270, {"b": [["11853.60000", "0.03214833", "1596736989.595237"]], "c": "218098785"}, "book-100", "XBT/USD"]
[270, {"b": [["11853.60000", "0.02423535", "1596736989.596863"]], "c": "218098785"}, "book-100", "XBT/USD"]
[270, {"b": [["11834.20000", "0.00000000", "1596736989.625040"], ["11807.50000", "2.19772556", "1596736916.776430", "r"]], "c": "218098785"}, "book-100", "XBT/USD"]
[270, {"a": [["11886.30000", "0.00000000", "1596736989.717706"], ["11909.90000", "6.20000000", "1596736825.518690", "r"]], "c": "218098785"}, "book-100", "XBT/USD"]
[270, {"a": [["11882.70000", "5.55082992", "1596736989.808509"]], "c": "218098785"}, "book-100", "XBT/USD"]
[270, {"b": [["11827.90000", "5.92494533", "1596736989.901076"]], "c": "218098785"}, "book-100", "XBT/USD"]
[270, {"b": [["11808.90000", "0.01263652", "1596736990.175467"]], "c": "218098785"}, "book-100", "XBT/USD"]
[270, {"a": [["11889.20000", "0.00438186", "1596736990.175698"]], "c": "218098785"}, "book-100", "XBT/USD"]
[270, {"b": [["11848.60000", "0.00424997", "1596736990.176098"]], "c": "218098785"}, "book-100", "XBT/USD"]
[270, {"a": [["11900.80000", "0.50000000", "1596736990.370152"]], "c": "218098785"}, "book-100", "XBT/USD"]
[270, {"a": [["11871.20000", "0.00000000", "1596736990.668857"], ["11908.90000", "1.06880000", "1596736841.521829", "r"]], "c": "51210831"}, "book-100", "XBT/USD"]
[270, {"a": [["11871.50000", "1.44553620", "1596736990.908684"]], "c": "4208367960"}, "book-100", "XBT/USD"]
[270, {"b": [["11848.60000", "0.00000000", "1596736990.989473"], ["11808.80000", "2.66090576", "1596736784.110515", "r"]], "c": "4208367960"}, "book-100", "XBT/USD"]
[270, {"b": [["11853.60000", "0.00000000", "1596736991.700650"], ["11807.70000", "3.28855406", "1596736821.611246", "r"]], "c": "4208367960"}, "book-100", "XBT/USD"]
[270, {"b": [["11853.60000", "0.00791298", "1596736991.705866"]], "c": "4208367960"}, "book-100", "XBT/USD"]
[270, {"a": [["11897.30000", "0.00000000", "1596736991.757304"], ["11909.10000", "1.00200000", "1596736809.784670", "r"]], "c": "4208367960"}, "book-100", "XBT/USD"]
[270, {"b": [["11833.40000", "0.73604018", "1596736991.760555"]], "c": "4208367960"}, "book-100", "XBT/USD"]
[270, {"a": [["11897.10000", "0.73604018", "1596736991.769672"]], "c": "4208367960"}, "book-100", "XBT/USD"]
[270, {"b": [["11835.20000", "0.00000000", "1596736991.772783"], ["11808.80000", "2.66090576", "1596736784.110515", "r"]], "c": "4208367960"}, "book-100", "XBT/USD"]
[270, {"a": [["11872.80000", "0.00000000", "1596736993.123331"], ["11909.10000", "1.00200000", "1596736809.784670", "r"]], "c": "4208367960"}, "book-100", "XBT/USD"]
[270, {"a": [["11878.50000", "0.04388855", "1596736993.792534"]], "c": "4208367960"}, "book-100", "XBT/USD"]
[270, {"b": [["11862.20000", "2.63976629", "1596736993.794829"]], "c": "1645657326"}, "book-100", "XBT/USD"]
[270, {"b": [["11856.50000", "0.09621094", "1596736994.006977"]], "c": "1645657326"}, "book-100", "XBT/USD"]
[270, {"a": [["11871.10000", "0.19242188", "1596736994.024350"]], "c": "2349309996"}, "book-100", "XBT/USD"]
[270, {"a": [["11882.70000", "0.00000000", "1596736994.154250"], ["11909.10000", "1.00200000", "1596736809.784670", "r"]], "c": "2349309996"}, "book-100", "XBT/USD"]
[270, {"a": [["11886.30000", "5.83399322", "1596736994.234125"]], "c": "2349309996"}, "book-100", "XBT/USD"]
[270, {"a": [["11871.10000", "0.09621094", "1596736994.248898"]], "c": "1645657326"}, "book-100", "XBT/USD"]
[270, {"a": [["11879.10000", "0.13166566", "1596736994.279211"]], "c": "1645657326"}, "book-100", "XBT/USD"]
[270, {"b": [["11861.60000", "0.13166566", "1596736994.279917"]], "c": "1026409625"}, "book-100", "XBT/USD"]
[270, {"b": [["11848.60000", "0.00421924", "1596736994.368395"]], "c": "1026409625"}, "book-100", "XBT/USD"]
[270, {"b": [["11857.60000", "0.00000000", "1596736994.505692"], ["11811.70000", "5.70000000", "1596736886.902857", "r"]], "c": "1026409625"}, "book-100", "XBT/USD"]
[270, {"b": [["11862.70000", "1.68100000", "1596736994.787277"]], "c": "3181810639"}, "book-100", "XBT/USD"]
[270, {"a": [["11871.10000", "1.77421094", "1596736994.799654"]], "c": "2589650159"}, "book-100", "XBT/USD"]
[270, {"a": [["11878.90000", "0.01800000", "1596736994.886599"]], "c": "2589650159"}, "book-100", "XBT/USD"]
[270, {"a": [["11890.30000", "0.00000000", "1596736995.458064"], ["11908.90000", "1.06880000", "1596736841.521829", "r"]], "c": "2589650159"}, "book-100", "XBT/USD"]
[270, {"b": [["11861.40000", "0.00000000", "1596736995.468676"], ["11811.70000", "5.70000000", "1596736886.902857", "r"]], "c": "2589650159"}, "book-100", "XBT/USD"]
[270, {"a": [["11872.50000", "0.84201101", "1596736995.484655"]], "c": "1948773132"}, "book-100", "XBT/USD"]
[270, {"b": [["11825.70000", "0.00000000", "1596736995.515346"], ["11808.90000", "0.01263652", "1596736990.175467", "r"]], "c": "1948773132"}, "book-100", "XBT/USD"]
[270, {"a": [["11871.50000", "1.19553620", "1596736995.526266"]], "c": "2382108699"}, "book-100", "XBT/USD"]
[270, {"b": [["11848.60000", "0.00000000", "1596736995.560343"], ["11808.80000", "2.66090576", "1596736784.110515", "r"]], "c": "2382108699"}, "book-100", "XBT/USD"]
[270, {"b": [["11848.10000", "0.71100000", "1596736995.626455"]], "c": "2382108699"}, "book-100", "XBT/USD"]
[270, {"a": [["11870.40000", "12.39989071", "1596736995.752005"]], "c": "2127501907"}, "book-100", "XBT/USD"]
[270, {"a": [["11875.30000", "0.75963568", "1596736995.763042"]], "c": "2127501907"}, "book-100", "XBT/USD"]
[270, {"b": [["11865.80000", "0.00000000", "1596736995.940312"], ["11808.80000", "2.66090576", "1596736784.110515", "r"]], "c": "4206386604"}, "book-100", "XBT/USD"]
[270, {"a": [["11872.50000", "0.00000000", "1596736995.957821"], ["11909.10000", "1.00200000", "1596736809.784670", "r"]], "c": "1253154688"}, "book-100", "XBT/USD"]
[270, {"b": [["11858.10000", "0.00000000", "1596736995.966711"], ["11807.70000", "3.28855406", "1596736821.611246", "r"]], "c": "1253154688"}, "book-100", "XBT/USD"]
[270, {"a": [["11889.20000", "0.49592169", "1596736995.987527"]], "c": "1253154688"}, "book-100", "XBT/USD"]
[270, {"b": [["11848.60000", "0.00421389", "1596736995.989292"]], "c": "1253154688"}, "book-100", "XBT/USD"]
[270, {"a": [["11875.30000", "0.16490000", "1596736996.127933"]], "c": "1253154688"}, "book-100", "XBT/USD"]
[270, {"b": [["11865.30000", "0.10000000", "1596736996.166993"]], "c": "4116798950"}, "book-100", "XBT/USD"]
[270, {"a": [["11889.20000", "0.00438186", "1596736996.174258"]], "c": "4116798950"}, "book-100", "XBT/USD"]
[270, {"b": [["11848.60000", "0.00000000", "1596736996.187197"], ["11808.80000", "2.66090576", "1596736784.110515", "r"]], "c": "4116798950"}, "book-100", "XBT/USD"]
[270, {"a": [["11875.10000", "0.84234818", "1596736996.231231"]], "c": "4116798950"}, "book-100", "XBT/USD"]
[270, {"a": [["11906.70000", "0.02328490", "1596736996.316757"]], "c": "4116798950"}, "book-100", "XBT/USD"]
[270, {"a": [["11889.20000", "0.00000000", "1596736996.375079"], ["11908.90000", "1.06880000", "1596736841.521829", "r"]], "c": "4116798950"}, "book-100", "XBT/USD"]
[270, {"b": [["11824.10000", "0.94820044", "1596736996.466349"]], "c": "4116798950"}, "book-100", "XBT/USD"]
[270, {"b": [["11857.80000", "0.27100000", "1596736996.686248"]], "c": "4116798950"}, "book-100", "XBT/USD"]
[270, {"a": [["11882.30000", "0.50000000", "1596736996.947701"]], "c": "4116798950"}, "book-100", "XBT/USD"]
[270, {"a": [["11870.40000", "12.40489071", "1596736997.044315"]], "c": "1974834872"}, "book-100", "XBT/USD"]
[270, {"a": [["11883.60000", "0.00000000", "1596736997.046012"], ["11909.10000", "1.00200000", "1596736809.784670", "r"]], "c": "1974834872"}, "book-100", "XBT/USD"]
[270, {"a": [["11877.70000", "0.04440539", "1596736997.087004"]], "c": "1974834872"}, "book-100", "XBT/USD"]
[270, {"a": [["11874.10000", "0.59657623", "1596736997.095443"]], "c": "1974834872"}, "book-100", "XBT/USD"]
[270, {"b": [["11853.60000", "0.00000000", "1596736997.268405"], ["11808.90000", "0.01263652", "1596736990.175467", "r"]], "c": "1974834872"}, "book-100", "XBT/USD"]
[270, {"b": [["11853.60000", "0.00724372", "1596736997.270623"]], "c": "1974834872"}, "book-100", "XBT/USD"]
[271, [["11870.40000", "0.02544842", "1596736997.449710", "b", "m", ""]], "trade", "XBT/USD"]
[270, {"a": [["11870.40000", "12.37944229", "1596736997.449710"]], "c": "3184283954"}, "book-100", "XBT/USD"]
[270, {"a": [["11870.40000", "12.35968413", "1596736997.593546"]], "c": "2339844169"}, "book-100", "XBT/USD"]
[270, {"a": [["11890.60000", "1.19191943", "1596736997.700131"]], "c": "2339844169"}, "book-100", "XBT/USD"]
[270, {"b": [["11817.30000", "0.00000000", "1596736997.838308"], ["11808.90000", "0.01263652", "1596736990.175467", "r"]], "c": "2339844169"}, "book-100", "XBT/USD"]
[270, {"a": [["11890.60000", "0.76325320", "1596736997.881794"]], "c": "2339844169"}, "book-100", "XBT/USD"]
[270, {"a": [["11907.40000", "0.00000000", "1596736997.890332"], ["11908.90000", "1.06880000", "1596736841.521829", "r"]], "c": "2339844169"}, "book-100", "XBT/USD"]
[270, {"b": [["11815.70000", "2.20925201", "1596736997.991696"]], "c": "2339844169"}, "book-100", "XBT/USD"]
[270, {"a": [["11883.50000", "0.00000000", "1596736998.208549"], ["11909.10000", "1.00200000", "1596736809.784670", "r"]], "c": "2339844169"}, "book-100", "XBT/USD"]
[270, {"a": [["11904.80000", "0.00000000", "1596736998.208833"], ["11909.90000", "6.20000000", "1596736825.518690", "r"]], "c": "2339844169"}, "book-100", "XBT/USD"]
[270, {"a": [["11900.50000", "0.00000000", "1596736998.239111"], ["11910.00000", "0.36067000", "1596736968.148143", "r"]], "c": "2339844169"}, "book-100", "XBT/USD"]
[270, {"a": [["11890.60000", "0.00000000", "1596736998.316180"], ["11910.50000", "1.68800000", "1596736995.994117", "r"]], "c": "2339844169"}, "book-100", "XBT/USD"]
[270, {"b": [["11863.90000", "0.07324522", "1596736998.347804"]], "c": "994662885"}, "book-100", "XBT/USD"]
[270, {"a": [["11877.40000", "0.17578854", "1596736998.407060"]], "c": "994662885"}, "book-100", "XBT/USD"]
[270, {"b": [["11862.80000", "0.17578854", "1596736998.408195"]], "c": "2157829759"}, "book-100", "XBT/USD"]
[270, {"a": [["11877.00000", "0.07324522", "1596736998.411135"]], "c": "2157829759"}, "book-100", "XBT/USD"]
[270, {"a": [["11900.80000", "0.00000000", "1596736998.610015"], ["11910.00000", "0.36067000", "1596736968.148143", "r"]], "c": "2157829759"}, "book-100", "XBT/USD"]
[270, {"a": [["11897.60000", "0.46896163", "1596736998.613213"]], "c": "2157829759"}, "book-100", "XBT/USD"]
[270, {"a": [["11883.20000", "0.32971885", "1596736998.711352"]], "c": "2157829759"}, "book-100", "XBT/USD"]
[270, {"b": [["11827.90000", "0.00000000", "1596736998.733681"], ["11811.80000", "4.23305508", "1596736972.960659", "r"]], "c": "2157829759"}, "book-100", "XBT/USD"]
[270, {"a": [["11886.90000", "0.00000000", "1596736998.742534"], ["11909.90000", "6.20000000", "1596736825.518690", "r"]], "c": "2157829759"}, "book-100", "XBT/USD"]
[270, {"b": [["11833.80000", "5.93339103", "1596736998.816034"]], "c": "2157829759"}, "book-100", "XBT/USD"]
[270, {"a": [["11875.60000", "0.01464904", "1596736998.820940"]], "c": "2157829759"}, "book-100", "XBT/USD"]
[270, {"a": [["11889.30000", "2.14751239", "1596736998.864546"]], "c": "2157829759"}, "book-100", "XBT/USD"]
[270, {"a": [["11901.00000", "2.35123177", "1596736998.882430"]], "c": "2157829759"}, "book-100", "XBT/USD"]
[270, {"b": [["11859.70000", "0.00000000", "1596736999.023316"], ["11811.80000", "4.23305508", "1596736972.960659", "r"]], "c": "2157829759"}, "book-100", "XBT/USD"]
[271, [["11870.30000", "0.00604085", "1596736999.260252", "s", "l", ""]], "trade", "XBT/USD"]
[270, {"b": [["11870.30000", "0.53095915", "1596736999.260252"]], "c": "2427692409"}, "book-100", "XBT/USD"]
[270, {"a": [["11886.70000", "1.36821007", "1596736999.481107"]], "c": "2427692409"}, "book-100", "XBT/USD"]
[270, {"b": [["11859.60000", "0.33037406", "1596736999.485752"]], "c": "2427692409"}, "book-100", "XBT/USD"]
[270, {"a": [["11897.10000", "0.00000000", "1596736999.501169"], ["11909.90000", "6.20000000", "1596736825.518690", "r"]], "c": "2427692409"}, "book-100", "XBT/USD"]
[270, {"a": [["11896.80000", "0.73609056", "1596736999.504359"]], "c": "2427692409"}, "book-100", "XBT/USD"]
[270, {"a": [["11889.20000", "0.00438186", "1596736999.574507"]], "c": "2427692409"}, "book-100", "XBT/USD"]
[270, {"b": [["11848.60000", "0.00426162", "1596736999.575283"]], "c": "2427692409"}, "book-100", "XBT/USD"]
[270, {"a": [["11900.40000", "0.50000000", "1596736999.782704"]], "c": "2427692409"}, "book-100", "XBT/USD"]
[270, {"a": [["11870.40000", "12.10968413", "1596737000.194001"]], "c": "2339349861"}, "book-100", "XBT/USD"]
[270, {"b": [["11862.70000", "0.00000000", "1596737000.328863"], ["11813.30000", "0.99420000", "1596736809.783550", "r"]], "c": "1984085803"}, "book-100", "XBT/USD"]
[270, {"b": [["11863.00000", "1.68000000", "1596737000.338337"]], "c": "2932300410"}, "book-100", "XBT/USD"]
[270, {"a": [["11871.10000", "2.02421094", "1596737000.358513"]], "c": "3506855088"}, "book-100", "XBT/USD"]
[270, {"b": [["11831.60000", "0.01274937", "1596737000.384388"]], "c": "3506855088"}, "book-100", "XBT/USD"]
[270, {"b": [["11859.00000", "0.88519000", "1596737000.402714"]], "c": "3506855088"}, "book-100", "XBT/USD"]
[270, {"b": [["11863.00000", "0.00000000", "1596737000.506145"], ["11815.00000", "0.15000000", "1596736658.818582", "r"]], "c": "159627745"}, "book-100", "XBT/USD"]
[270, {"a": [["11877.40000", "0.00000000", "1596737000.583457"], ["11908.90000", "1.06880000", "1596736841.521829", "r"]], "c": "159627745"}, "book-100", "XBT/USD"]
[270, {"a": [["11874.10000", "0.00000000", "1596737000.615584"], ["11909.10000", "1.00200000", "1596736809.784670", "r"]], "c": "159627745"}, "book-100", "XBT/USD"]
[271, [["11870.30000", "0.01692433", "1596737000.620383", "s", "l", ""]], "trade", "XBT/USD"]
[270, {"b": [["11870.30000", "0.51403482", "1596737000.620383"]], "c": "4042125936"}, "book-100", "XBT/USD"]
[270, {"b": [["11816.80000", "0.00000000", "1596737000.653859"], ["11814.70000", "15.09669614", "1596736905.495230", "r"]], "c": "4042125936"}, "book-100", "XBT/USD"]
[270, {"a": [["11878.40000", "2.00000000", "1596737000.797153"]], "c": "4042125936"}, "book-100", "XBT/USD"]
[270, {"b": [["11853.60000", "0.00000000", "1596737000.829497"], ["11813.30000", "0.99420000", "1596736809.783550", "r"]], "c": "4042125936"}, "book-100", "XBT/USD"]
[270, {"b": [["11853.60000", "0.07214140", "1596737000.830900"]], "c": "4042125936"}, "book-100", "XBT/USD"]
[270, {"a": [["11872.80000", "0.59899960", "1596737000.864132"]], "c": "2804357988"}, "book-100", "XBT/USD"]
[270, {"a": [["11875.10000", "0.00000000", "1596737000.907684"], ["11908.90000", "1.06880000", "1596736841.521829", "r"]], "c": "2804357988"}, "book-100", "XBT/USD"]
[270, {"b": [["11853.60000", "0.07938512", "1596737000.958730"]], "c": "2804357988"}, "book-100", "XBT/USD"]
[270, {"b": [["11853.60000", "0.00724372", "1596737000.962115"]], "c": "2804357988"}, "book-100", "XBT/USD"]
[270, {"a": [["11878.80000", "0.17578986", "1596737001.092061"]], "c": "2804357988"}, "book-100", "XBT/USD"]
[270, {"a": [["11871.10000", "1.77421094", "1596737001.092678"]], "c": "3638959534"}, "book-100", "XBT/USD"]
[270, {"a": [["11872.80000", "1.44130577", "1596737001.150126"]], "c": "882966674"}, "book-100", "XBT/USD"]
[270, {"b": [["11853.60000", "0.07938512", "1596737001.227111"]], "c": "882966674"}, "book-100", "XBT/USD"]
[270, {"b": [["11853.60000", "0.07214140", "1596737001.227654"]], "c": "882966674"}, "book-100", "XBT/USD"]
[270, {"b": [["11853.60000", "0.07938512", "1596737001.353526"]], "c": "882966674"}, "book-100", "XBT/USD"]
[270, {"b": [["11853.60000", "0.00724372", "1596737001.353700"]], "c": "882966674"}, "book-100", "XBT/USD"]
[270, {"a": [["11870.40000", "12.35968413", "1596737001.457023"]], "c": "549159133"}, "book-100", "XBT/USD"]
[270, {"b": [["11855.40000", "0.88165000", "1596737001.518535"]], "c": "549159133"}, "book-100", "XBT/USD"]
[270, {"b": [["11859.80000", "0.23800000", "1596737001.565440"]], "c": "549159133"}, "book-100", "XBT/USD"]
[270, {"a": [["11907.00000", "8.54095785", "1596737002.155356"]], "c": "549159133"}, "book-100", "XBT/USD"]
[270, {"b": [["11865.20000", "0.00000000", "1596737002.204044"], ["11814.70000", "15.09669614", "1596736905.495230", "r"]], "c": "2435121499"}, "book-100", "XBT/USD"]
[270, {"b": [["11862.70000", "0.25274835", "1596737002.266146"]], "c": "2245710500"}, "book-100", "XBT/USD"]
[270, {"a": [["11872.80000", "0.84230617", "1596737002.838184"]], "c": "306325854"}, "book-100", "XBT/USD"]
[270, {"a": [["11870.40000", "12.85968413", "1596737002.917740"]], "c": "410393447"}, "book-100", "XBT/USD"]
[270, {"b": [["11861.60000", "0.00000000", "1596737002.970001"], ["11814.70000", "15.09669614", "1596736905.495230", "r"]], "c": "410393447"}, "book-100", "XBT/USD"]
[270, {"b": [["11864.30000", "4.20600000", "1596737003.052362"]], "c": "2122598605"}, "book-100", "XBT/USD"]
[270, {"a": [["11878.50000", "0.00000000", "1596737003.065989"], ["11908.90000", "1.06880000", "1596736841.521829", "r"]], "c": "2122598605"}, "book-100", "XBT/USD"]
[270, {"a": [["11872.00000", "0.59989200", "1596737003.098445"]], "c": "3985697391"}, "book-100", "XBT/USD"]
[270, {"b": [["11859.40000", "0.13168004", "1596737003.188445"]], "c": "3985697391"}, "book-100", "XBT/USD"]
[270, {"b": [["11862.30000", "0.00000000", "1596737003.202869"], ["11814.70000", "15.09669614", "1596736905.495230", "r"]], "c": "2405269624"}, "book-100", "XBT/USD"]
[270, {"b": [["11862.80000", "0.00000000", "1596737003.207480"], ["11813.30000", "0.99420000", "1596736809.783550", "r"]], "c": "1513223575"}, "book-100", "XBT/USD"]
[270, {"b": [["11856.10000", "0.00000000", "1596737003.248598"], ["11811.80000", "4.23305508", "1596736972.960659", "r"]], "c": "1513223575"}, "book-100", "XBT/USD"]
[270, {"b": [["11862.20000", "2.59587774", "1596737003.266701"]], "c": "3270627361"}, "book-100", "XBT/USD"]
[270, {"b": [["11863.90000", "0.00000000", "1596737003.280239"], ["11811.70000", "5.70000000", "1596736886.902857", "r"]], "c": "2960240964"}, "book-100", "XBT/USD"]
[270, {"a": [["11877.40000", "0.04389278", "1596737003.362843"]], "c": "2960240964"}, "book-100", "XBT/USD"]
[270, {"b": [["11861.90000", "0.17579315", "1596737003.412931"]], "c": "2216525531"}, "book-100", "XBT/USD"]
[270, {"a": [["11878.90000", "0.00000000", "1596737003.465803"], ["11908.30000", "1.58322230", "1596736949.361051", "r"]], "c": "2216525531"}, "book-100", "XBT/USD"]
[270, {"b": [["11853.10000", "0.33688667", "1596737003.466077"]], "c": "2216525531"}, "book-100", "XBT/USD"]
[270, {"b": [["11861.20000", "0.04393276", "1596737003.484267"]], "c": "538775550"}, "book-100", "XBT/USD"]
[270, {"b": [["11863.00000", "0.07324757", "1596737003.485339"]], "c": "2062806107"}, "book-100", "XBT/USD"]
[270, {"a": [["11877.80000", "0.00000000", "1596737003.489689"], ["11908.90000", "1.06880000", "1596736841.521829", "r"]], "c": "2062806107"}, "book-100", "XBT/USD"]
[270, {"b": [["11852.10000", "0.02300000", "1596737003.519708"]], "c": "2062806107"}, "book-100", "XBT/USD"]
[270, {"a": [["11877.90000", "3.06624999", "1596737003.519864"]], "c": "2062806107"}, "book-100", "XBT/USD"]
[270, {"b": [["11862.70000", "1.93274835", "1596737003.523304"]], "c": "1118393422"}, "book-100", "XBT/USD"]
[270, {"a": [["11880.20000", "0.38000000", "1596737003.532969"]], "c": "1118393422"}, "book-100", "XBT/USD"]
[270, {"b": [["11852.00000", "0.03643021", "1596737003.534003"]], "c": "1118393422"}, "book-100", "XBT/USD"]
[270, {"a": [["11877.80000", "0.04440539", "1596737003.624108"]], "c": "1118393422"}, "book-100", "XBT/USD"]
[270, {"a": [["11877.70000", "0.00000000", "1596737003.624942"], ["11908.30000", "1.58322230", "1596736949.361051", "r"]], "c": "1118393422"}, "book-100", "XBT/USD"]
[270, {"a": [["11870.40000", "12.87944229", "1596737003.685551"]], "c": "4202879460"}, "book-100", "XBT/USD"]
[270, {"b": [["11852.10000", "0.00000000", "1596737003.742503"], ["11815.00000", "0.15000000", "1596736658.818582", "r"]], "c": "4202879460"}, "book-100", "XBT/USD"]
[270, {"b": [["11859.00000", "0.00000000", "1596737003.779520"], ["11814.70000", "15.09669614", "1596736905.495230", "r"]], "c": "4202879460"}, "book-100", "XBT/USD"]
[270, {"b": [["11851.10000", "1.55714277", "1596737003.797244"]], "c": "4202879460"}, "book-100", "XBT/USD"]
[270, {"b": [["11846.10000", "0.00000000", "1596737003.806561"], ["11813.30000", "0.99420000", "1596736809.783550", "r"]], "c": "4202879460"}, "book-100", "XBT/USD"]
[270, {"a": [["11870.40000", "12.37944229", "1596737003.827893"]], "c": "2777507294"}, "book-100", "XBT/USD"]
[270, {"b": [["11835.80000", "2.38150000", "1596737003.889285"]], "c": "2777507294"}, "book-100", "XBT/USD"]
[270, {"a": [["11870.40000", "12.46368580", "1596737003.958550"]], "c": "3643446648"}, "book-100", "XBT/USD"]
[270, {"a": [["11877.90000", "3.04824999", "1596737004.020284"]], "c": "3643446648"}, "book-100", "XBT/USD"]
[270, {"a": [["11876.90000", "0.85992960", "1596737004.080726"]], "c": "3643446648"}, "book-100", "XBT/USD"]
[270, {"a": [["11871.10000", "0.09621094", "1596737004.132290"]], "c": "410914540"}, "book-100", "XBT/USD"]
[270, {"a": [["11876.60000", "0.09250000", "1596737004.381310"]], "c": "410914540"}, "book-100", "XBT/USD"]
[270, {"a": [["11884.30000", "1.04962971", "1596737004.455109"]], "c": "410914540"}, "book-100", "XBT/USD"]
[270, {"a": [["11870.40000", "12.56368580", "1596737004.506243"]], "c": "3117830996"}, "book-100", "XBT/USD"]
[270, {"a": [["11870.40000", "12.31368580", "1596737004.688272"]], "c": "2094843232"}, "book-100", "XBT/USD"]
[270, {"b": [["11853.60000", "0.00000000", "1596737004.720472"], ["11813.30000", "0.99420000", "1596736809.783550", "r"]], "c": "2094843232"}, "book-100", "XBT/USD"]
[270, {"b": [["11853.60000", "0.07214140", "1596737004.722828"]], "c": "2094843232"}, "book-100", "XBT/USD"]
[270, {"b": [["11853.60000", "0.00000000", "1596737004.868700"], ["11813.30000", "0.99420000", "1596736809.783550", "r"]], "c": "2094843232"}, "book-100", "XBT/USD"]
[270, {"b": [["11853.60000", "0.00724372", "1596737004.877349"]], "c": "2094843232"}, "book-100", "XBT/USD"]
[270, {"b": [["11859.60000", "0.00000000", "1596737005.081115"], ["11813.30000", "0.99420000", "1596736809.783550", "r"]], "c": "2094843232"}, "book-100", "XBT/USD"]
[270, {"b": [["11862.70000", "0.25274835", "1596737005.161199"]], "c": "1628772796"}, "book-100", "XBT/USD"]
[270, {"b": [["11859.40000", "0.46869510", "1596737005.198702"]], "c": "1628772796"}, "book-100", "XBT/USD"]
[270, {"b": [["11864.50000", "0.25274575", "1596737005.203180"]], "c": "2600188716"}, "book-100", "XBT/USD"]
[270, {"b": [["11863.00000", "1.74724757", "1596737005.216564"]], "c": "1068161011"}, "book-100", "XBT/USD"]
[270, {"b": [["11851.10000", "1.53414277", "1596737005.256318"]], "c": "1068161011"}, "book-100", "XBT/USD"]
[270, {"a": [["11870.40000", "11.61368580", "1596737005.265686"]], "c": "309788653"}, "book-100", "XBT/USD"]
[270, {"a": [["11870.40000", "11.52944229", "1596737005.275311"]], "c": "1405358108"}, "book-100", "XBT/USD"]
[270, {"a": [["11876.90000", "0.84192960", "1596737005.285592"]], "c": "1405358108"}, "book-100", "XBT/USD"]
[270, {"b": [["11853.10000", "0.35988667", "1596737005.309041"]], "c": "1405358108"}, "book-100", "XBT/USD"]
[270, {"a": [["11878.90000", "0.01800000", "1596737005.423009"]], "c": "1405358108"}, "book-100", "XBT/USD"]
[270, {"b": [["11858.70000", "0.66363392", "1596737005.464863"]], "c": "1405358108"}, "book-100", "XBT/USD"]
[270, {"b": [["11814.70000", "2.19669614", "1596737005.466015"]], "c": "1405358108"}, "book-100", "XBT/USD"]
[270, {"b": [["11832.20000", "0.73609222", "1596737005.997938"]], "c": "1405358108"}, "book-100", "XBT/USD"]
[270, {"a": [["11896.80000", "0.00000000", "1596737005.998150"], ["11907.90000", "2.38150000", "1596736895.960018", "r"]], "c": "1405358108"}, "book-100", "XBT/USD"]
[270, {"b": [["11833.40000", "0.00000000", "1596737005.999179"], ["11814.70000", "2.19669614", "1596737005.466015", "r"]], "c": "1405358108"}, "book-100", "XBT/USD"]
[270, {"a": [["11870.90000", "1.09237502", "1596737006.007122"]], "c": "910105346"}, "book-100", "XBT/USD"]
[270, {"a": [["11878.90000", "0.00000000", "1596737006.061599"], ["11908.30000", "1.58322230", "1596736949.361051", "r"]], "c": "910105346"}, "book-100", "XBT/USD"]
[270, {"b": [["11853.10000", "0.33688667", "1596737006.063418"]], "c": "910105346"}, "book-100", "XBT/USD"]
[270, {"a": [["11870.40000", "12.02944229", "1596737006.098451"]], "c": "3424516681"}, "book-100", "XBT/USD"]
[270, {"b": [["11864.50000", "0.00000000", "1596737006.112808"], ["11813.30000", "0.99420000", "1596736809.783550", "r"]], "c": "4215183952"}, "book-100", "XBT/USD"]
[270, {"b": [["11851.10000", "1.55714277", "1596737006.122133"]], "c": "4215183952"}, "book-100", "XBT/USD"]
[270, {"a": [["11870.90000", "0.84237502", "1596737006.185108"]], "c": "1228625947"}, "book-100", "XBT/USD"]
[270, {"a": [["11872.00000", "0.00000000", "1596737006.204388"], ["11908.90000", "1.06880000", "1596736841.521829", "r"]], "c": "3990017952"}, "book-100", "XBT/USD"]
[270, {"a": [["11895.30000", "3.83237759", "1596737006.228487"]], "c": "3990017952"}, "book-100", "XBT/USD"]
[270, {"a": [["11876.90000", "0.85992960", "1596737006.235352"]], "c": "3990017952"}, "book-100", "XBT/USD"]
[270, {"b": [["11865.30000", "0.00000000", "1596737006.237157"], ["11811.80000", "4.23305508", "1596736972.960659", "r"]], "c": "3930995578"}, "book-100", "XBT/USD"]
[270, {"a": [["11877.00000", "0.00000000", "1596737006.257750"], ["11909.10000", "1.00200000", "1596736809.784670", "r"]], "c": "3930995578"}, "book-100", "XBT/USD"]
[270, {"a": [["11870.40000", "12.27944229", "1596737006.391511"]], "c": "938171439"}, "book-100", "XBT/USD"]
[270, {"a": [["11871.30000", "0.59341925", "1596737006.457958"]], "c": "1489833786"}, "book-100", "XBT/USD"]
[270, {"a": [["11870.40000", "12.67944229", "1596737006.497969"]], "c": "3019862809"}, "book-100", "XBT/USD"]
[270, {"a": [["11876.80000", "0.98282792", "1596737006.505269"]], "c": "3019862809"}, "book-100", "XBT/USD"]
[270, {"b": [["11863.00000", "0.07324757", "1596737006.505843"]], "c": "1643464894"}, "book-100", "XBT/USD"]
[270, {"b": [["11851.10000", "1.53414277", "1596737006.529340"]], "c": "1643464894"}, "book-100", "XBT/USD"]
[270, {"a": [["11876.90000", "0.84192960", "1596737006.530093"]], "c": "1643464894"}, "book-100", "XBT/USD"]
[270, {"a": [["11870.40000", "13.37944229", "1596737006.559099"]], "c": "1136500530"}, "book-100", "XBT/USD"]
[270, {"a": [["11875.60000", "0.00000000", "1596737006.563760"], ["11909.10000", "1.00200000", "1596736809.784670", "r"]], "c": "1136500530"}, "book-100", "XBT/USD"]
[270, {"b": [["11850.10000", "0.02300000", "1596737006.582488"]], "c": "1136500530"}, "book-100", "XBT/USD"]
[270, {"a": [["11876.60000", "0.11050000", "1596737006.583226"]], "c": "1136500530"}, "book-100", "XBT/USD"]
[270, {"b": [["11857.90000", "0.90633000", "1596737006.697081"]], "c": "1136500530"}, "book-100", "XBT/USD"]
[270, {"a": [["11875.20000", "0.01464948", "1596737006.776808"]], "c": "1136500530"}, "book-100", "XBT/USD"]
[270, {"b": [["11848.60000", "0.00000000", "1596737006.876522"], ["11813.30000", "0.99420000", "1596736809.783550", "r"]], "c": "1136500530"}, "book-100", "XBT/USD"]
[270, {"b": [["11853.60000", "0.00000000", "1596737007.040546"], ["11811.80000", "4.23305508", "1596736972.960659", "r"]], "c": "1136500530"}, "book-100", "XBT/USD"]
[270, {"b": [["11853.60000", "0.00451000", "1596737007.040967"]], "c": "1136500530"}, "book-100", "XBT/USD"]
[270, {"b": [["11854.70000", "0.00000000", "1596737007.046667"], ["11811.80000", "4.23305508", "1596736972.960659", "r"]], "c": "1136500530"}, "book-100", "XBT/USD"]
[270, {"b": [["11848.20000", "0.00424286", "1596737007.060970"]], "c": "1136500530"}, "book-100", "XBT/USD"]
[270, {"a": [["11870.40000", "13.12944229", "1596737007.222164"]], "c": "1073653151"}, "book-100", "XBT/USD"]
[270, {"b": [["11848.20000", "0.00000000", "1596737007.403015"], ["11811.80000", "4.23305508", "1596736972.960659", "r"]], "c": "1073653151"}, "book-100", "XBT/USD"]
[270, {"a": [["11870.40000", "13.37944229", "1596737007.411169"]], "c": "1136500530"}, "book-100", "XBT/USD"]
[270, {"b": [["11861.70000", "1.67600000", "1596737007.507000"]], "c": "708676545"}, "book-100", "XBT/USD"]
[270, {"a": [["11870.40000", "12.67944229", "1596737007.557917"]], "c": "2780576185"}, "book-100", "XBT/USD"]
[270, {"b": [["11854.60000", "0.59308888", "1596737007.563138"]], "c": "2780576185"}, "book-100", "XBT/USD"]
[270, {"b": [["11847.30000", "0.00436540", "1596737007.589865"]], "c": "2780576185"}, "book-100", "XBT/USD"]
[270, {"b": [["11833.80000", "0.00000000", "1596737007.626839"], ["11813.30000", "0.99420000", "1596736809.783550", "r"]], "c": "2780576185"}, "book-100", "XBT/USD"]
[270, {"b": [["11859.50000", "0.00000000", "1596737007.655070"], ["11811.80000", "4.23305508", "1596736972.960659", "r"]], "c": "2780576185"}, "book-100", "XBT/USD"]
[270, {"b": [["11863.40000", "0.00000000", "1596737007.655370"], ["11811.70000", "5.70000000", "1596736886.902857", "r"]], "c": "3993087535"}, "book-100", "XBT/USD"]
[270, {"b": [["11862.70000", "0.00000000", "1596737007.655666"], ["11810.70000", "13.46787369", "1596737005.994208", "r"]], "c": "1446963530"}, "book-100", "XBT/USD"]
[270, {"a": [["11886.40000", "0.00000000", "1596737007.687196"], ["11909.10000", "1.00200000", "1596736809.784670", "r"]], "c": "1446963530"}, "book-100", "XBT/USD"]
[270, {"b": [["11830.10000", "5.93339103", "1596737007.705576"]], "c": "1446963530"}, "book-100", "XBT/USD"]
[270, {"a": [["11870.40000", "12.42944229", "1596737007.706898"]], "c": "4263867685"}, "book-100", "XBT/USD"]
[270, {"b": [["11853.50000", "0.00000000", "1596737007.712643"], ["11810.70000", "13.46787369", "1596737005.994208", "r"]], "c": "4263867685"}, "book-100", "XBT/USD"]
[270, {"a": [["11870.40000", "12.51368580", "1596737007.729558"]], "c": "4261703256"}, "book-100", "XBT/USD"]
[270, {"b": [["11849.20000", "0.33707461", "1596737007.729934"]], "c": "4261703256"}, "book-100", "XBT/USD"]
[270, {"b": [["11861.10000", "0.25280596", "1596737007.730498"]], "c": "385038600"}, "book-100", "XBT/USD"]
[270, {"b": [["11861.70000", "0.00000000", "1596737007.736128"], ["11811.70000", "5.70000000", "1596736886.902857", "r"]], "c": "1860944180"}, "book-100", "XBT/USD"]
[270, {"b": [["11861.20000", "0.00000000", "1596737007.740787"], ["11810.70000", "13.46787369", "1596737005.994208", "r"]], "c": "1723615548"}, "book-100", "XBT/USD"]
[270, {"b": [["11859.40000", "0.33701506", "1596737007.740913"]], "c": "1723615548"}, "book-100", "XBT/USD"]
[270, {"a": [["11878.10000", "0.69325726", "1596737007.755091"]], "c": "1723615548"}, "book-100", "XBT/USD"]
[270, {"b": [["11864.40000", "0.10000000", "1596737007.762660"]], "c": "532506450"}, "book-100", "XBT/USD"]
[270, {"b": [["11854.50000", "0.00000000", "1596737007.764190"], ["11810.70000", "13.46787369", "1596737005.994208", "r"]], "c": "532506450"}, "book-100", "XBT/USD"]
[270, {"b": [["11856.30000", "0.00000000", "1596737007.769031"], ["11808.80000", "2.66090576", "1596736784.110515", "r"]], "c": "532506450"}, "book-100", "XBT/USD"]
[270, {"b": [["11864.40000", "0.00000000", "1596737007.809002"], ["11807.70000", "3.28855406", "1596736821.611246", "r"]], "c": "1723615548"}, "book-100", "XBT/USD"]
[270, {"a": [["11879.10000", "0.00000000", "1596737007.811091"], ["11909.90000", "6.20000000", "1596736825.518690", "r"]], "c": "1723615548"}, "book-100", "XBT/USD"]
[270, {"b": [["11851.40000", "2.18974246", "1596737007.815234"]], "c": "1723615548"}, "book-100", "XBT/USD"]
[270, {"b": [["11858.70000", "0.33321802", "1596737007.817254"]], "c": "1723615548"}, "book-100", "XBT/USD"]
[270, {"b": [["11853.20000", "0.00451000", "1596737007.844255"]], "c": "1723615548"}, "book-100", "XBT/USD"]
[270, {"b": [["11853.60000", "0.00000000", "1596737007.851235"], ["11807.70000", "3.28855406", "1596736821.611246", "r"]], "c": "1723615548"}, "book-100", "XBT/USD"]
[270, {"a": [["11881.80000", "1.88230000", "1596737007.861927"]], "c": "1723615548"}, "book-100", "XBT/USD"]
[270, {"b": [["11864.60000", "0.00000000", "1596737007.863833"], ["11807.50000", "2.19772556", "1596736916.776430", "r"]], "c": "2939460213"}, "book-100", "XBT/USD"]
[270, {"a": [["11870.40000", "12.76368580", "1596737007.865125"]], "c": "601033736"}, "book-100", "XBT/USD"]
[270, {"b": [["11863.00000", "0.00000000", "1596737007.865297"], ["11807.20000", "6.50000000", "1596736936.572585", "r"]], "c": "109991902"}, "book-100", "XBT/USD"]
[270, {"b": [["11858.60000", "3.71000577", "1596737007.870555"]], "c": "109991902"}, "book-100", "XBT/USD"]
[270, {"b": [["11861.90000", "0.00000000", "1596737007.885953"], ["11807.20000", "6.50000000", "1596736936.572585", "r"]], "c": "2341360116"}, "book-100", "XBT/USD"]
[270, {"a": [["11878.80000", "0.00000000", "1596737007.895674"], ["11909.90000", "6.20000000", "1596736825.518690", "r"]], "c": "2341360116"}, "book-100", "XBT/USD"]
[270, {"b": [["11851.40000", "0.00000000", "1596737007.920911"], ["11805.90000", "0.15000000", "1596735155.182015", "r"]], "c": "2341360116"}, "book-100", "XBT/USD"]
[270, {"b": [["11864.30000", "0.00000000", "1596737007.921641"], ["11805.20000", "0.34533000", "1596735143.806373", "r"]], "c": "1801653487"}, "book-100", "XBT/USD"]
[270, {"a": [["11870.40000", "13.46368580", "1596737007.924228"]], "c": "1083710132"}, "book-100", "XBT/USD"]
[270, {"b": [["11864.40000", "0.10000000", "1596737007.931322"]], "c": "1362869611"}, "book-100", "XBT/USD"]
[270, {"a": [["11878.10000", "0.00000000", "1596737007.939980"], ["11910.00000", "0.36067000", "1596736968.148143", "r"]], "c": "1362869611"}, "book-100", "XBT/USD"]
[270, {"b": [["11859.20000", "0.04393665", "1596737007.952714"]], "c": "1362869611"}, "book-100", "XBT/USD"]
[270, {"b": [["11807.80000", "0.01263652", "1596737007.986199"]], "c": "1362869611"}, "book-100", "XBT/USD"]
[270, {"b": [["11864.40000", "0.00000000", "1596737007.991559"], ["11807.20000", "6.50000000", "1596736936.572585", "r"]], "c": "3510862501"}, "book-100", "XBT/USD"]
[270, {"a": [["11900.40000", "0.00000000", "1596737007.996248"], ["11910.50000", "1.68800000", "1596736995.994117", "r"]], "c": "3510862501"}, "book-100", "XBT/USD"]
[270, {"b": [["11853.70000", "0.69416607", "1596737007.997238"]], "c": "3510862501"}, "book-100", "XBT/USD"]
[270, {"a": [["11870.40000", "13.21368580", "1596737008.006207"]], "c": "2890995935"}, "book-100", "XBT/USD"]
[270, {"a": [["11874.50000", "0.69336240", "1596737008.012459"]], "c": "2890995935"}, "book-100", "XBT/USD"]
[270, {"b": [["11862.20000", "0.00000000", "1596737008.021188"], ["11807.20000", "6.50000000", "1596736936.572585", "r"]], "c": "1492965512"}, "book-100", "XBT/USD"]
[270, {"a": [["11872.80000", "0.00000000", "1596737008.023890"], ["11910.50000", "1.68800000", "1596736995.994117", "r"]], "c": "1492965512"}, "book-100", "XBT/USD"]
[270, {"b": [["11858.10000", "0.13180908", "1596737008.029155"]], "c": "1492965512"}, "book-100", "XBT/USD"]
[270, {"a": [["11877.80000", "0.17621447", "1596737008.030532"]], "c": "1492965512"}, "book-100", "XBT/USD"]
[270, {"b": [["11862.30000", "0.10000000", "1596737008.037289"]], "c": "215046398"}, "book-100", "XBT/USD"]
[270, {"b": [["11851.40000", "1.38860157", "1596737008.045131"]], "c": "215046398"}, "book-100", "XBT/USD"]
[270, {"b": [["11860.40000", "0.07325875", "1596737008.068813"]], "c": "4276994960"}, "book-100", "XBT/USD"]
[270, {"b": [["11860.00000", "0.17582099", "1596737008.069047"]], "c": "193696946"}, "book-100", "XBT/USD"]
[270, {"a": [["11875.40000", "0.26272226", "1596737008.069327"]], "c": "193696946"}, "book-100", "XBT/USD"]
[270, {"b": [["11862.50000", "0.01465175", "1596737008.069885"]], "c": "1967914810"}, "book-100", "XBT/USD"]
[270, {"b": [["11862.30000", "0.00000000", "1596737008.083796"], ["11810.70000", "13.46787369", "1596737005.994208", "r"]], "c": "3060260921"}, "book-100", "XBT/USD"]
[270, {"b": [["11841.40000", "0.73758895", "1596737008.147640"]], "c": "3060260921"}, "book-100", "XBT/USD"]
[270, {"b": [["11848.60000", "0.33702740", "1596737008.153375"]], "c": "3060260921"}, "book-100", "XBT/USD"]
[270, {"b": [["11860.40000", "0.32606471", "1596737008.154502"]], "c": "567203225"}, "book-100", "XBT/USD"]
[270, {"b": [["11854.10000", "0.00000000", "1596737008.154831"], ["11810.70000", "13.46787369", "1596737005.994208", "r"]], "c": "567203225"}, "book-100", "XBT/USD"]
[270, {"b": [["11860.80000", "0.00000000", "1596737008.156677"], ["11808.80000", "2.66090576", "1596736784.110515", "r"]], "c": "2657301507"}, "book-100", "XBT/USD"]
[270, {"b": [["11847.80000", "0.28668943", "1596737008.166338"]], "c": "2657301507"}, "book-100", "XBT/USD"]
[270, {"b": [["11847.30000", "0.00000000", "1596737008.172496"], ["11808.80000", "2.66090576", "1596736784.110515", "r"]], "c": "2657301507"}, "book-100", "XBT/USD"]
[270, {"b": [["11863.10000", "0.10000000", "1596737008.223497"]], "c": "3955876252"}, "book-100", "XBT/USD"]
[270, {"b": [["11862.50000", "0.00000000", "1596737008.269488"], ["11808.80000", "2.66090576", "1596736784.110515", "r"]], "c": "2946745872"}, "book-100", "XBT/USD"]
[270, {"a": [["11871.20000", "0.84234968", "1596737008.285655"]], "c": "658265987"}, "book-100", "XBT/USD"]
[270, {"b": [["11815.70000", "0.00000000", "1596737008.293931"], ["11807.80000", "0.01263652", "1596737007.986199", "r"]], "c": "658265987"}, "book-100", "XBT/USD"]
[270, {"a": [["11895.30000", "3.09628537", "1596737008.295274"]], "c": "658265987"}, "book-100", "XBT/USD"]
[270, {"b": [["11814.40000", "2.20927279", "1596737008.303291"]], "c": "658265987"}, "book-100", "XBT/USD"]
[270, {"b": [["11845.40000", "2.19081811", "1596737008.313532"]], "c": "658265987"}, "book-100", "XBT/USD"]
[270, {"a": [["11871.30000", "0.99255609", "1596737008.327476"]], "c": "1144311048"}, "book-100", "XBT/USD"]
[270, {"a": [["11895.10000", "0.73609089", "1596737008.341882"]], "c": "1144311048"}, "book-100", "XBT/USD"]
[270, {"b": [["11835.40000", "0.05224585", "1596737008.355437"]], "c": "1144311048"}, "book-100", "XBT/USD"]
[270, {"b": [["11861.60000", "4.20600000", "1596737008.361373"]], "c": "3757674573"}, "book-100", "XBT/USD"]
[270, {"b": [["11846.60000", "1.06523211", "1596737008.361459"]], "c": "3757674573"}, "book-100", "XBT/USD"]
[270, {"b": [["11861.70000", "0.10000000", "1596737008.412000"]], "c": "849538946"}, "book-100", "XBT/USD"]
[270, {"b": [["11860.10000", "0.00000000", "1596737008.443764"], ["11811.80000", "4.23305508", "1596736972.960659", "r"]], "c": "2633232524"}, "book-100", "XBT/USD"]
[270, {"b": [["11858.80000", "0.77100000", "1596737008.472499"]], "c": "2633232524"}, "book-100", "XBT/USD"]
[270, {"b": [["11851.00000", "7.64612039", "1596737008.546816"]], "c": "2633232524"}, "book-100", "XBT/USD"]
[270, {"b": [["11853.20000", "0.00000000", "1596737008.610023"], ["11811.80000", "4.23305508", "1596736972.960659", "r"]], "c": "2633232524"}, "book-100", "XBT/USD"]
[270, {"a": [["11880.90000", "0.00000000", "1596737008.652639"], ["11910.00000", "0.36067000", "1596736968.148143", "r"]], "c": "2633232524"}, "book-100", "XBT/USD"]
[270, {"b": [["11848.60000", "0.00000000", "1596737008.653588"], ["11811.70000", "5.70000000", "1596736886.902857", "r"]], "c": "2633232524"}, "book-100", "XBT/USD"]
[270, {"b": [["11853.20000", "0.00724372", "1596737008.654033"]], "c": "2633232524"}, "book-100", "XBT/USD"]
[270, {"b": [["11845.40000", "3.94398862", "1596737008.751020"]], "c": "2633232524"}, "book-100", "XBT/USD"]
[270, {"b": [["11861.10000", "0.26746346", "1596737008.802543"]], "c": "3684875851"}, "book-100", "XBT/USD"]
[270, {"b": [["11846.60000", "1.06100750", "1596737008.806561"]], "c": "3684875851"}, "book-100", "XBT/USD"]
[270, {"b": [["11857.20000", "0.33045770", "1596737008.813719"]], "c": "3684875851"}, "book-100", "XBT/USD"]
[270, {"b": [["11856.50000", "0.00000000", "1596737008.875366"], ["11811.80000", "4.23305508", "1596736972.960659", "r"]], "c": "3684875851"}, "book-100", "XBT/USD"]
[270, {"a": [["11875.70000", "0.82399999", "1596737008.888070"]], "c": "3684875851"}, "book-100", "XBT/USD"]
[270, {"a": [["11870.40000", "13.46368580", "1596737008.906491"]], "c": "1796158707"}, "book-100", "XBT/USD"]
[270, {"b": [["11836.50000", "0.00000000", "1596737008.974680"], ["11811.70000", "5.70000000", "1596736886.902857", "r"]], "c": "1796158707"}, "book-100", "XBT/USD"]
[270, {"a": [["11870.40000", "13.21368580", "1596737009.067245"]], "c": "3684875851"}, "book-100", "XBT/USD"]
[270, {"b": [["11857.90000", "0.00000000", "1596737009.106768"], ["11810.70000", "13.46787369", "1596737005.994208", "r"]], "c": "3684875851"}, "book-100", "XBT/USD"]
[270, {"a": [["11900.30000", "0.50000000", "1596737009.167615"]], "c": "3684875851"}, "book-100", "XBT/USD"]
[270, {"a": [["11889.20000", "0.00000000", "1596737009.188551"], ["11910.00000", "0.36067000", "1596736968.148143", "r"]], "c": "3684875851"}, "book-100", "XBT/USD"]
[270, {"b": [["11854.10000", "0.09621094", "1596737009.404944"]], "c": "3684875851"}, "book-100", "XBT/USD"]
