[270, {"a": [["11854.30000", "1.50000000", "1596737134.443034"]], "c": "374748681"}, "book-100", "XBT/USD"]
[270, {"a": [["11870.40000", "0.00500000", "1596737134.474913"]], "c": "374748681"}, "book-100", "XBT/USD"]
[270, {"b": [["11835.00000", "1.81196955", "1596737134.610562"]], "c": "374748681"}, "book-100", "XBT/USD"]
[270, {"b": [["11807.90000", "2.12812342", "1596737134.614299"]], "c": "374748681"}, "book-100", "XBT/USD"]
[270, {"a": [["11858.40000", "1.68559030", "1596737134.648495"]], "c": "374748681"}, "book-100", "XBT/USD"]
[270, {"a": [["11855.70000", "0.00000000", "1596737134.652920"], ["11900.30000", "0.73381520", "1596737116.696146", "r"]], "c": "2722042568"}, "book-100", "XBT/USD"]
[270, {"a": [["11861.40000", "0.00000000", "1596737134.658336"], ["11900.70000", "0.00500000", "1596736976.571243", "r"]], "c": "2722042568"}, "book-100", "XBT/USD"]
[270, {"a": [["11853.00000", "0.00000000", "1596737134.712471"], ["11901.00000", "0.17065000", "1596737120.047779", "r"]], "c": "2341136219"}, "book-100", "XBT/USD"]
[270, {"b": [["11842.70000", "0.00000000", "1596737134.718756"], ["11790.00000", "0.24750000", "1596737132.922523", "r"]], "c": "2341136219"}, "book-100", "XBT/USD"]
[270, {"b": [["11839.30000", "1.26009819", "1596737134.729757"]], "c": "2341136219"}, "book-100", "XBT/USD"]
[270, {"b": [["11836.90000", "0.00000000", "1596737134.732185"], ["11789.40000", "2.00800000", "1596735513.212546", "r"]], "c": "2341136219"}, "book-100", "XBT/USD"]
[270, {"a": [["11858.30000", "0.68857168", "1596737134.732926"]], "c": "2341136219"}, "book-100", "XBT/USD"]
[270, {"b": [["11847.10000", "4.21000000", "1596737134.741876"]], "c": "2711805753"}, "book-100", "XBT/USD"]
[270, {"a": [["11883.70000", "0.20405824", "1596737134.742122"]], "c": "2711805753"}, "book-100", "XBT/USD"]
[270, {"a": [["11854.50000", "0.63268661", "1596737134.803758"]], "c": "1645900148"}, "book-100", "XBT/USD"]
[270, {"a": [["11857.10000", "0.39918520", "1596737134.811247"]], "c": "2641352639"}, "book-100", "XBT/USD"]
[270, {"a": [["11854.60000", "0.00000000", "1596737134.811404"], ["11901.00000", "0.17065000", "1596737120.047779", "r"]], "c": "1034346621"}, "book-100", "XBT/USD"]
[270, {"b": [["11847.00000", "0.46600000", "1596737134.811768"]], "c": "254510569"}, "book-100", "XBT/USD"]
[270, {"a": [["11885.80000", "3.26598811", "1596737134.820970"]], "c": "254510569"}, "book-100", "XBT/USD"]
[270, {"a": [["11886.80000", "10.52936829", "1596737134.847224"]], "c": "254510569"}, "book-100", "XBT/USD"]
[270, {"b": [["11807.80000", "0.00000000", "1596737134.877843"], ["11787.80000", "6.80000000", "1596737132.726658", "r"]], "c": "254510569"}, "book-100", "XBT/USD"]
[270, {"b": [["11848.20000", "0.00703700", "1596737134.916945"]], "c": "1361205015"}, "book-100", "XBT/USD"]
[270, {"b": [["11847.20000", "0.00000000", "1596737134.921571"], ["11787.80000", "6.80000000", "1596737132.726658", "r"]], "c": "2909912254"}, "book-100", "XBT/USD"]
[270, {"b": [["11848.20000", "0.10703700", "1596737134.938695"]], "c": "2705673852"}, "book-100", "XBT/USD"]
[270, {"b": [["11851.00000", "1.68600000", "1596737134.942625"]], "c": "3672076929"}, "book-100", "XBT/USD"]
[270, {"a": [["11860.60000", "0.84300000", "1596737134.963641"]], "c": "3672076929"}, "book-100", "XBT/USD"]
[270, {"a": [["11889.00000", "0.00000000", "1596737134.972299"], ["11900.30000", "0.73381520", "1596737116.696146", "r"]], "c": "3672076929"}, "book-100", "XBT/USD"]
[270, {"b": [["11831.50000", "0.00000000", "1596737135.037227"], ["11787.80000", "6.80000000", "1596737132.726658", "r"]], "c": "3672076929"}, "book-100", "XBT/USD"]
[270, {"a": [["11853.90000", "0.00000000", "1596737135.113784"], ["11900.70000", "0.00500000", "1596736976.571243", "r"]], "c": "3950162542"}, "book-100", "XBT/USD"]
[270, {"b": [["11840.90000", "0.69328162", "1596737135.127573"]], "c": "3950162542"}, "book-100", "XBT/USD"]
[270, {"b": [["11838.60000", "1.38683262", "1596737135.132401"]], "c": "3950162542"}, "book-100", "XBT/USD"]
[270, {"a": [["11873.00000", "0.00000000", "1596737135.208326"], ["11901.00000", "0.17065000", "1596737120.047779", "r"]], "c": "3950162542"}, "book-100", "XBT/USD"]
[270, {"a": [["11868.60000", "0.04440539", "1596737135.209272"]], "c": "3950162542"}, "book-100", "XBT/USD"]
[270, {"b": [["11827.40000", "0.05228533", "1596737135.214256"]], "c": "3950162542"}, "book-100", "XBT/USD"]
[270, {"b": [["11827.00000", "1.03440000", "1596737135.270260"]], "c": "3950162542"}, "book-100", "XBT/USD"]
[270, {"a": [["11859.50000", "0.00000000", "1596737135.270733"], ["11901.00000", "0.17065000", "1596737120.047779", "r"]], "c": "3950162542"}, "book-100", "XBT/USD"]
[270, {"a": [["11854.50000", "0.00000000", "1596737135.330554"], ["11901.50000", "3.26167975", "1596737133.218332", "r"]], "c": "3087490960"}, "book-100", "XBT/USD"]
[270, {"a": [["11858.50000", "0.15000000", "1596737135.346430"]], "c": "3087490960"}, "book-100", "XBT/USD"]
[270, {"a": [["11892.20000", "0.00000000", "1596737135.349127"], ["11901.80000", "0.75800000", "1596737130.968842", "r"]], "c": "3087490960"}, "book-100", "XBT/USD"]
[270, {"a": [["11852.70000", "1.47150630", "1596737135.450514"]], "c": "757809180"}, "book-100", "XBT/USD"]
[270, {"a": [["11853.40000", "0.09621094", "1596737135.476924"]], "c": "942522786"}, "book-100", "XBT/USD"]
[270, {"b": [["11843.20000", "0.11921094", "1596737135.485442"]], "c": "942522786"}, "book-100", "XBT/USD"]
[270, {"a": [["11861.00000", "0.65493801", "1596737135.505838"]], "c": "942522786"}, "book-100", "XBT/USD"]
[270, {"b": [["11844.40000", "0.33003655", "1596737135.549898"]], "c": "942522786"}, "book-100", "XBT/USD"]
[270, {"a": [["11853.90000", "0.70000000", "1596737135.574657"]], "c": "2192644966"}, "book-100", "XBT/USD"]
[270, {"a": [["11863.90000", "0.00000000", "1596737135.592249"], ["11901.00000", "0.17065000", "1596737120.047779", "r"]], "c": "2192644966"}, "book-100", "XBT/USD"]
[270, {"b": [["11848.20000", "3.92676944", "1596737135.602312"]], "c": "3576416298"}, "book-100", "XBT/USD"]
[270, {"a": [["11853.90000", "0.00000000", "1596737135.622650"], ["11901.50000", "3.26167975", "1596737133.218332", "r"]], "c": "1234719321"}, "book-100", "XBT/USD"]
[270, {"b": [["11833.70000", "0.28688860", "1596737135.637807"]], "c": "1234719321"}, "book-100", "XBT/USD"]
[270, {"a": [["11858.40000", "0.84200000", "1596737135.638221"]], "c": "1234719321"}, "book-100", "XBT/USD"]
[270, {"a": [["11865.10000", "0.00000000", "1596737135.673966"], ["11901.80000", "0.75800000", "1596737130.968842", "r"]], "c": "1234719321"}, "book-100", "XBT/USD"]
[270, {"b": [["11851.00000", "0.00000000", "1596737135.693219"], ["11792.50000", "5.30000000", "1596737130.530368", "r"]], "c": "265870869"}, "book-100", "XBT/USD"]
[270, {"b": [["11852.60000", "1.81770000", "1596737135.709427"]], "c": "1358271902"}, "book-100", "XBT/USD"]
[270, {"a": [["11858.50000", "0.00000000", "1596737135.709867"], ["11902.00000", "0.22739000", "1596736764.397858", "r"]], "c": "1358271902"}, "book-100", "XBT/USD"]
[270, {"a": [["11861.80000", "1.68300000", "1596737135.713531"]], "c": "1358271902"}, "book-100", "XBT/USD"]
[270, {"b": [["11848.30000", "0.00703700", "1596737135.732738"]], "c": "778836592"}, "book-100", "XBT/USD"]
[270, {"b": [["11848.20000", "3.91973244", "1596737135.735260"]], "c": "776326845"}, "book-100", "XBT/USD"]
[270, {"b": [["11844.90000", "0.00000000", "1596737135.741175"], ["11792.50000", "5.30000000", "1596737130.530368", "r"]], "c": "776326845"}, "book-100", "XBT/USD"]
[270, {"a": [["11867.00000", "2.10100000", "1596737135.778642"]], "c": "776326845"}, "book-100", "XBT/USD"]
[270, {"a": [["11863.10000", "0.29750000", "1596737135.826458"]], "c": "776326845"}, "book-100", "XBT/USD"]
[270, {"b": [["11848.10000", "0.52163776", "1596737135.831806"]], "c": "2379474673"}, "book-100", "XBT/USD"]
[270, {"a": [["11857.10000", "0.14918520", "1596737135.858786"]], "c": "3529796596"}, "book-100", "XBT/USD"]
[270, {"a": [["11854.00000", "0.00000000", "1596737135.864748"], ["11902.00000", "0.22739000", "1596736764.397858", "r"]], "c": "2660778544"}, "book-100", "XBT/USD"]
[270, {"a": [["11889.10000", "2.46748868", "1596737135.864840"]], "c": "2660778544"}, "book-100", "XBT/USD"]
[270, {"a": [["11860.60000", "0.00000000", "1596737135.879007"], ["11902.20000", "1.58369712", "1596737116.990726", "r"]], "c": "2660778544"}, "book-100", "XBT/USD"]
[270, {"a": [["11867.40000", "0.69356940", "1596737135.889870"]], "c": "2660778544"}, "book-100", "XBT/USD"]
[270, {"a": [["11866.10000", "0.66614694", "1596737135.921696"]], "c": "2660778544"}, "book-100", "XBT/USD"]
[270, {"b": [["11820.80000", "6.50519029", "1596737135.943685"]], "c": "2660778544"}, "book-100", "XBT/USD"]
[270, {"a": [["11857.00000", "0.84200000", "1596737135.958804"]], "c": "2081600542"}, "book-100", "XBT/USD"]
[270, {"a": [["11858.40000", "0.00000000", "1596737135.963499"], ["11901.80000", "0.75800000", "1596737130.968842", "r"]], "c": "2081600542"}, "book-100", "XBT/USD"]
[270, {"a": [["11863.20000", "0.94612106", "1596737135.969909"]], "c": "2081600542"}, "book-100", "XBT/USD"]
[270, {"a": [["11854.30000", "0.00000000", "1596737136.065601"], ["11902.00000", "0.22739000", "1596736764.397858", "r"]], "c": "1764800395"}, "book-100", "XBT/USD"]
[270, {"b": [["11848.20000", "3.81973244", "1596737136.075428"]], "c": "964943191"}, "book-100", "XBT/USD"]
[270, {"a": [["11857.50000", "0.25000000", "1596737136.079316"]], "c": "3287011645"}, "book-100", "XBT/USD"]
[270, {"a": [["11852.70000", "0.97150630", "1596737136.083815"]], "c": "230437637"}, "book-100", "XBT/USD"]
[270, {"a": [["11862.30000", "0.84284479", "1596737136.108837"]], "c": "230437637"}, "book-100", "XBT/USD"]
[270, {"a": [["11863.20000", "1.03041641", "1596737136.122710"]], "c": "230437637"}, "book-100", "XBT/USD"]
[270, {"a": [["11866.10000", "0.00000000", "1596737136.177173"], ["11901.80000", "0.75800000", "1596737130.968842", "r"]], "c": "230437637"}, "book-100", "XBT/USD"]
[270, {"a": [["11852.70000", "0.53934106", "1596737136.177730"]], "c": "1424582374"}, "book-100", "XBT/USD"]
[270, {"a": [["11856.60000", "1.50000000", "1596737136.210627"]], "c": "260404239"}, "book-100", "XBT/USD"]
[270, {"a": [["11863.20000", "0.94612106", "1596737136.285255"]], "c": "260404239"}, "book-100", "XBT/USD"]
[270, {"a": [["11877.40000", "0.93000000", "1596737136.291079"]], "c": "260404239"}, "book-100", "XBT/USD"]
[270, {"b": [["11852.60000", "2.31770000", "1596737136.310108"]], "c": "2649995849"}, "book-100", "XBT/USD"]
[270, {"a": [["11858.90000", "0.00000000", "1596737136.377711"], ["11901.50000", "3.26167975", "1596737133.218332", "r"]], "c": "2649995849"}, "book-100", "XBT/USD"]
[270, {"a": [["11857.50000", "0.00000000", "1596737136.379462"], ["11901.80000", "0.75800000", "1596737130.968842", "r"]], "c": "313542750"}, "book-100", "XBT/USD"]
[270, {"b": [["11848.80000", "0.10000000", "1596737136.416700"]], "c": "274835471"}, "book-100", "XBT/USD"]
[270, {"a": [["11867.40000", "1.38220888", "1596737136.421214"]], "c": "274835471"}, "book-100", "XBT/USD"]
[270, {"a": [["11869.20000", "0.38000000", "1596737136.457347"]], "c": "274835471"}, "book-100", "XBT/USD"]
[270, {"a": [["11865.50000", "0.00000000", "1596737136.465997"], ["11901.80000", "0.75800000", "1596737130.968842", "r"]], "c": "274835471"}, "book-100", "XBT/USD"]
[270, {"b": [["11847.10000", "0.00000000", "1596737136.563751"], ["11794.00000", "1.01250000", "1596737132.711374", "r"]], "c": "2154096802"}, "book-100", "XBT/USD"]
[270, {"b": [["11850.40000", "4.20500000", "1596737136.565382"]], "c": "3419661127"}, "book-100", "XBT/USD"]
[270, {"b": [["11832.60000", "6.49870303", "1596737136.566753"]], "c": "3419661127"}, "book-100", "XBT/USD"]
[270, {"a": [["11886.90000", "0.00000000", "1596737136.570440"], ["11902.00000", "0.22739000", "1596736764.397858", "r"]], "c": "3419661127"}, "book-100", "XBT/USD"]
[270, {"a": [["11859.40000", "4.20800000", "1596737136.570630"]], "c": "3419661127"}, "book-100", "XBT/USD"]
[270, {"a": [["11857.90000", "0.91283811", "1596737136.598307"]], "c": "336243541"}, "book-100", "XBT/USD"]
[270, {"b": [["11852.60000", "2.63284697", "1596737136.599622"]], "c": "3755968861"}, "book-100", "XBT/USD"]
[270, {"b": [["11852.60000", "2.13284697", "1596737136.655086"]], "c": "272470567"}, "book-100", "XBT/USD"]
[270, {"a": [["11867.40000", "0.69356940", "1596737136.676762"]], "c": "272470567"}, "book-100", "XBT/USD"]
[270, {"a": [["11889.00000", "2.12275198", "1596737136.762115"]], "c": "272470567"}, "book-100", "XBT/USD"]
[270, {"b": [["11837.20000", "0.38000000", "1596737136.763826"]], "c": "272470567"}, "book-100", "XBT/USD"]
[270, {"a": [["11857.50000", "0.81630000", "1596737136.771016"]], "c": "3192368508"}, "book-100", "XBT/USD"]
[270, {"b": [["11839.30000", "1.15063737", "1596737136.773644"]], "c": "3192368508"}, "book-100", "XBT/USD"]
[270, {"b": [["11834.60000", "0.00000000", "1596737136.778576"], ["11795.30000", "2.20028792", "1596736851.216162", "r"]], "c": "3192368508"}, "book-100", "XBT/USD"]
[270, {"a": [["11857.00000", "0.00000000", "1596737136.778736"], ["11901.50000", "3.26167975", "1596737133.218332", "r"]], "c": "2994330393"}, "book-100", "XBT/USD"]
[270, {"b": [["11833.30000", "0.00000000", "1596737136.785777"], ["11795.00000", "0.80800000", "1596736676.791659", "r"]], "c": "2994330393"}, "book-100", "XBT/USD"]
[270, {"b": [["11836.80000", "0.00000000", "1596737136.788151"], ["11794.00000", "1.01250000", "1596737132.711374", "r"]], "c": "2994330393"}, "book-100", "XBT/USD"]
[270, {"b": [["11836.60000", "0.00000000", "1596737136.788315"], ["11792.50000", "5.30000000", "1596737130.530368", "r"]], "c": "2994330393"}, "book-100", "XBT/USD"]
[270, {"b": [["11837.00000", "0.00000000", "1596737136.804545"], ["11790.00000", "0.24750000", "1596737132.922523", "r"]], "c": "2994330393"}, "book-100", "XBT/USD"]
[270, {"b": [["11852.60000", "2.37927793", "1596737136.900413"]], "c": "887000398"}, "book-100", "XBT/USD"]
[270, {"a": [["11868.90000", "0.65602855", "1596737136.932754"]], "c": "887000398"}, "book-100", "XBT/USD"]
[270, {"b": [["11840.90000", "0.00000000", "1596737136.934504"], ["11789.40000", "2.00800000", "1596735513.212546", "r"]], "c": "887000398"}, "book-100", "XBT/USD"]
[270, {"a": [["11892.00000", "6.46925117", "1596737136.983958"]], "c": "887000398"}, "book-100", "XBT/USD"]
[270, {"b": [["11831.00000", "2.19252974", "1596737136.989577"]], "c": "887000398"}, "book-100", "XBT/USD"]
[270, {"b": [["11839.90000", "0.76561134", "1596737137.047490"]], "c": "887000398"}, "book-100", "XBT/USD"]
[270, {"b": [["11842.30000", "0.10935088", "1596737137.048403"]], "c": "887000398"}, "book-100", "XBT/USD"]
[270, {"b": [["11836.20000", "0.94683131", "1596737137.113929"]], "c": "887000398"}, "book-100", "XBT/USD"]
[270, {"a": [["11857.50000", "0.00000000", "1596737137.115262"], ["11901.50000", "3.26167975", "1596737133.218332", "r"]], "c": "2162895627"}, "book-100", "XBT/USD"]
[270, {"a": [["11857.00000", "0.84200000", "1596737137.115427"]], "c": "2526725232"}, "book-100", "XBT/USD"]
[270, {"b": [["11840.00000", "0.20481139", "1596737137.116152"]], "c": "2526725232"}, "book-100", "XBT/USD"]
[270, {"b": [["11837.50000", "3.27931417", "1596737137.193087"]], "c": "2526725232"}, "book-100", "XBT/USD"]
[270, {"a": [["11872.20000", "0.84331654", "1596737137.206041"]], "c": "2526725232"}, "book-100", "XBT/USD"]
[270, {"b": [["11852.50000", "0.31622545", "1596737137.206144"]], "c": "2152861348"}, "book-100", "XBT/USD"]
[270, {"a": [["11856.50000", "0.63252642", "1596737137.206272"]], "c": "2335664281"}, "book-100", "XBT/USD"]
[270, {"a": [["11858.10000", "0.63252642", "1596737137.206379"]], "c": "2335664281"}, "book-100", "XBT/USD"]
[270, {"b": [["11851.00000", "0.31626321", "1596737137.206489"]], "c": "3813770248"}, "book-100", "XBT/USD"]
[270, {"a": [["11858.80000", "0.63248740", "1596737137.206580"]], "c": "3813770248"}, "book-100", "XBT/USD"]
[270, {"a": [["11872.90000", "0.84326788", "1596737137.210618"]], "c": "3813770248"}, "book-100", "XBT/USD"]
[270, {"b": [["11833.70000", "0.00000000", "1596737137.224446"], ["11795.50000", "1.06000000", "1596737134.250857", "r"]], "c": "3813770248"}, "book-100", "XBT/USD"]
[270, {"b": [["11843.50000", "6.00000000", "1596737137.246639"]], "c": "3813770248"}, "book-100", "XBT/USD"]
[270, {"b": [["11847.10000", "0.00816380", "1596737137.247538"]], "c": "3813770248"}, "book-100", "XBT/USD"]
[270, {"b": [["11848.30000", "0.00000000", "1596737137.249411"], ["11796.30000", "10.90540000", "1596736141.718106", "r"]], "c": "296102576"}, "book-100", "XBT/USD"]
[270, {"a": [["11877.30000", "0.00438186", "1596737137.252228"]], "c": "296102576"}, "book-100", "XBT/USD"]
[270, {"a": [["11857.90000", "0.66283811", "1596737137.264843"]], "c": "1345901615"}, "book-100", "XBT/USD"]
[270, {"b": [["11832.80000", "0.00434537", "1596737137.298970"]], "c": "1345901615"}, "book-100", "XBT/USD"]
[270, {"b": [["11852.60000", "2.13284697", "1596737137.299286"]], "c": "667577818"}, "book-100", "XBT/USD"]
[270, {"b": [["11833.50000", "0.00000000", "1596737137.440228"], ["11796.30000", "10.90540000", "1596736141.718106", "r"]], "c": "667577818"}, "book-100", "XBT/USD"]
[270, {"a": [["11861.80000", "0.00000000", "1596737137.457359"], ["11899.10000", "1.64182626", "1596737132.791349", "r"]], "c": "667577818"}, "book-100", "XBT/USD"]
[270, {"a": [["11857.50000", "0.84200000", "1596737137.534623"]], "c": "3689943714"}, "book-100", "XBT/USD"]
[270, {"a": [["11857.00000", "0.00000000", "1596737137.539498"], ["11899.10000", "1.64182626", "1596737132.791349", "r"]], "c": "249685306"}, "book-100", "XBT/USD"]
[270, {"b": [["11835.00000", "1.28115695", "1596737137.561732"]], "c": "249685306"}, "book-100", "XBT/USD"]
[270, {"b": [["11839.70000", "0.94655142", "1596737137.563468"]], "c": "249685306"}, "book-100", "XBT/USD"]
[270, {"a": [["11863.20000", "1.03041641", "1596737137.564251"]], "c": "249685306"}, "book-100", "XBT/USD"]
[270, {"a": [["11857.10000", "0.39918520", "1596737137.583243"]], "c": "3768562005"}, "book-100", "XBT/USD"]
[270, {"b": [["11849.50000", "0.00000000", "1596737137.600253"], ["11796.30000", "10.90540000", "1596736141.718106", "r"]], "c": "4201735479"}, "book-100", "XBT/USD"]
[270, {"b": [["11832.80000", "0.00000000", "1596737137.661253"], ["11796.00000", "0.17065000", "1596737137.274179", "r"]], "c": "4201735479"}, "book-100", "XBT/USD"]
[270, {"b": [["11825.30000", "0.00432482", "1596737137.666560"]], "c": "4201735479"}, "book-100", "XBT/USD"]
[270, {"b": [["11844.40000", "0.00000000", "1596737137.672645"], ["11796.00000", "0.17065000", "1596737137.274179", "r"]], "c": "4201735479"}, "book-100", "XBT/USD"]
[270, {"b": [["11836.40000", "0.28682316", "1596737137.706342"]], "c": "4201735479"}, "book-100", "XBT/USD"]
[270, {"b": [["11843.50000", "6.57112023", "1596737137.728663"]], "c": "4201735479"}, "book-100", "XBT/USD"]
[270, {"a": [["11863.20000", "0.94612106", "1596737137.736381"]], "c": "4201735479"}, "book-100", "XBT/USD"]
[270, {"a": [["11852.70000", "1.03934106", "1596737137.748566"]], "c": "2883828408"}, "book-100", "XBT/USD"]
[271, [["11852.70000", "0.01975816", "1596737137.757196", "b", "m", ""], ["11852.70000", "0.10000000", "1596737137.760577", "b", "m", ""]], "trade", "XBT/USD"]
[270, {"a": [["11852.70000", "1.01958290", "1596737137.757196"], ["11852.70000", "0.91958290", "1596737137.760577"]], "c": "133446294"}, "book-100", "XBT/USD"]
[270, {"b": [["11845.70000", "0.07218951", "1596737137.770275"]], "c": "133446294"}, "book-100", "XBT/USD"]
[270, {"b": [["11847.10000", "0.00000000", "1596737137.770704"], ["11796.30000", "10.90540000", "1596736141.718106", "r"]], "c": "133446294"}, "book-100", "XBT/USD"]
[270, {"b": [["11831.30000", "0.00000000", "1596737137.960332"], ["11796.00000", "0.17065000", "1596737137.274179", "r"]], "c": "133446294"}, "book-100", "XBT/USD"]
[270, {"b": [["11838.60000", "0.00000000", "1596737137.965063"], ["11795.50000", "1.06000000", "1596737134.250857", "r"]], "c": "133446294"}, "book-100", "XBT/USD"]
[270, {"b": [["11838.20000", "0.53066912", "1596737138.004317"]], "c": "133446294"}, "book-100", "XBT/USD"]
[270, {"a": [["11857.00000", "0.83570000", "1596737138.022380"]], "c": "2510453566"}, "book-100", "XBT/USD"]
[270, {"a": [["11857.50000", "0.00000000", "1596737138.066507"], ["11899.10000", "1.64182626", "1596737132.791349", "r"]], "c": "1735776798"}, "book-100", "XBT/USD"]
[270, {"a": [["11863.20000", "1.03041641", "1596737138.136683"]], "c": "1735776798"}, "book-100", "XBT/USD"]
[270, {"b": [["11842.80000", "0.69312691", "1596737138.160143"]], "c": "1735776798"}, "book-100", "XBT/USD"]
[270, {"b": [["11834.60000", "1.75053238", "1596737138.168962"]], "c": "1735776798"}, "book-100", "XBT/USD"]
[270, {"b": [["11831.00000", "0.00000000", "1596737138.188685"], ["11796.30000", "10.90540000", "1596736141.718106", "r"]], "c": "1735776798"}, "book-100", "XBT/USD"]
[270, {"b": [["11846.30000", "0.32996292", "1596737138.237848"]], "c": "1735776798"}, "book-100", "XBT/USD"]
[270, {"a": [["11863.20000", "0.94612106", "1596737138.276621"]], "c": "1735776798"}, "book-100", "XBT/USD"]
[270, {"a": [["11856.40000", "0.70000000", "1596737138.294750"]], "c": "917609653"}, "book-100", "XBT/USD"]
[270, {"b": [["11850.50000", "0.10000000", "1596737138.294898"]], "c": "3761618445"}, "book-100", "XBT/USD"]
[270, {"a": [["11852.70000", "2.91958290", "1596737138.498847"]], "c": "1456007799"}, "book-100", "XBT/USD"]
[270, {"a": [["11853.40000", "0.00000000", "1596737138.528479"], ["11899.10000", "1.64182626", "1596737132.791349", "r"]], "c": "3046465941"}, "book-100", "XBT/USD"]
[270, {"b": [["11834.20000", "0.00000000", "1596737138.546309"], ["11797.90000", "6.30000000", "1596737122.404410", "r"]], "c": "3046465941"}, "book-100", "XBT/USD"]
[270, {"a": [["11871.40000", "0.15000000", "1596737138.550475"]], "c": "3046465941"}, "book-100", "XBT/USD"]
[270, {"b": [["11850.50000", "0.00000000", "1596737138.552406"], ["11796.30000", "10.90540000", "1596736141.718106", "r"]], "c": "1662075693"}, "book-100", "XBT/USD"]
[270, {"b": [["11843.20000", "0.02300000", "1596737138.557135"]], "c": "1662075693"}, "book-100", "XBT/USD"]
[270, {"b": [["11850.40000", "0.00000000", "1596737138.576039"], ["11796.00000", "0.17065000", "1596737137.274179", "r"]], "c": "4291826127"}, "book-100", "XBT/USD"]
[270, {"b": [["11845.60000", "0.17319012", "1596737138.578493"]], "c": "4291826127"}, "book-100", "XBT/USD"]
[270, {"b": [["11845.70000", "0.00000000", "1596737138.580820"], ["11795.50000", "1.06000000", "1596737134.250857", "r"]], "c": "4291826127"}, "book-100", "XBT/USD"]
[270, {"a": [["11856.60000", "0.00000000", "1596737138.618668"], ["11899.90000", "7.61000000", "1596737079.466913", "r"]], "c": "98184776"}, "book-100", "XBT/USD"]
[270, {"b": [["11834.50000", "2.29725533", "1596737138.623118"]], "c": "98184776"}, "book-100", "XBT/USD"]
[270, {"a": [["11852.70000", "0.91958290", "1596737138.627987"]], "c": "3005708850"}, "book-100", "XBT/USD"]
[270, {"a": [["11864.00000", "0.09250000", "1596737139.824527"]], "c": "3005708850"}, "book-100", "XBT/USD"]
[270, {"a": [["11859.00000", "1.50000000", "1596737139.827706"]], "c": "3005708850"}, "book-100", "XBT/USD"]
[270, {"b": [["11839.40000", "0.04549564", "1596737139.835649"]], "c": "3005708850"}, "book-100", "XBT/USD"]
[270, {"a": [["11857.00000", "0.00000000", "1596737139.843698"], ["11899.10000", "1.64182626", "1596737132.791349", "r"]], "c": "3153012971"}, "book-100", "XBT/USD"]
[270, {"b": [["11850.30000", "4.60900000", "1596737139.844083"]], "c": "3105250388"}, "book-100", "XBT/USD"]
[270, {"a": [["11864.50000", "3.39549677", "1596737139.846444"]], "c": "3105250388"}, "book-100", "XBT/USD"]
[270, {"b": [["11827.00000", "1.02440000", "1596737139.849172"]], "c": "3105250388"}, "book-100", "XBT/USD"]
[270, {"a": [["11867.00000", "0.10100000", "1596737139.852678"]], "c": "3105250388"}, "book-100", "XBT/USD"]
[270, {"b": [["11827.00000", "0.00000000", "1596737139.858961"], ["11795.50000", "1.06000000", "1596737134.250857", "r"]], "c": "3105250388"}, "book-100", "XBT/USD"]
[270, {"b": [["11839.20000", "0.00000000", "1596737139.870805"], ["11795.30000", "2.20028792", "1596736851.216162", "r"]], "c": "3105250388"}, "book-100", "XBT/USD"]
[270, {"a": [["11857.60000", "1.46091787", "1596737139.875973"]], "c": "4103189142"}, "book-100", "XBT/USD"]
[270, {"b": [["11848.80000", "0.00000000", "1596737139.876810"], ["11795.00000", "0.80800000", "1596736676.791659", "r"]], "c": "3866928091"}, "book-100", "XBT/USD"]
[270, {"a": [["11866.40000", "1.08155999", "1596737139.878164"]], "c": "3866928091"}, "book-100", "XBT/USD"]
[270, {"a": [["11857.70000", "0.00000000", "1596737139.878771"], ["11899.90000", "7.61000000", "1596737079.466913", "r"]], "c": "2084133846"}, "book-100", "XBT/USD"]
[270, {"a": [["11858.30000", "0.00000000", "1596737139.881034"], ["11900.00000", "12.71653131", "1596737075.897027", "r"]], "c": "1322359093"}, "book-100", "XBT/USD"]
[270, {"a": [["11857.90000", "0.00000000", "1596737139.887958"], ["11900.30000", "0.73381520", "1596737116.696146", "r"]], "c": "31028358"}, "book-100", "XBT/USD"]
[270, {"a": [["11857.60000", "1.32841627", "1596737139.889025"]], "c": "1372052121"}, "book-100", "XBT/USD"]
[270, {"a": [["11857.10000", "0.25000000", "1596737139.891591"]], "c": "1431335452"}, "book-100", "XBT/USD"]
[270, {"a": [["11863.40000", "0.00000000", "1596737139.891846"], ["11900.70000", "0.00500000", "1596736976.571243", "r"]], "c": "1431335452"}, "book-100", "XBT/USD"]
[270, {"b": [["11828.70000", "0.00000000", "1596737139.892567"], ["11792.50000", "5.30000000", "1596737130.530368", "r"]], "c": "1431335452"}, "book-100", "XBT/USD"]
[270, {"a": [["11895.00000", "0.25000000", "1596737139.894112"]], "c": "1431335452"}, "book-100", "XBT/USD"]
[270, {"b": [["11808.80000", "2.66090576", "1596737139.899320"]], "c": "1431335452"}, "book-100", "XBT/USD"]
[270, {"a": [["11889.80000", "0.73653060", "1596737139.900800"]], "c": "1431335452"}, "book-100", "XBT/USD"]
[270, {"a": [["11855.00000", "0.09621094", "1596737139.901723"]], "c": "2225745644"}, "book-100", "XBT/USD"]
[270, {"a": [["11857.10000", "0.00000000", "1596737139.902138"], ["11900.30000", "0.73381520", "1596737116.696146", "r"]], "c": "1968950843"}, "book-100", "XBT/USD"]
[270, {"b": [["11835.90000", "0.00000000", "1596737139.902880"], ["11790.00000", "0.24750000", "1596737132.922523", "r"]], "c": "1968950843"}, "book-100", "XBT/USD"]
[270, {"b": [["11834.50000", "2.19125533", "1596737139.904475"]], "c": "1968950843"}, "book-100", "XBT/USD"]
[270, {"a": [["11859.40000", "0.00000000", "1596737139.908609"], ["11900.70000", "0.00500000", "1596736976.571243", "r"]], "c": "1968950843"}, "book-100", "XBT/USD"]
[270, {"b": [["11848.80000", "0.15000000", "1596737139.909521"]], "c": "530901090"}, "book-100", "XBT/USD"]
[270, {"b": [["11834.60000", "4.86124735", "1596737139.928746"]], "c": "530901090"}, "book-100", "XBT/USD"]
[270, {"b": [["11846.20000", "0.09621094", "1596737139.931263"]], "c": "530901090"}, "book-100", "XBT/USD"]
[270, {"a": [["11890.80000", "0.00000000", "1596737139.932299"], ["11901.00000", "0.17065000", "1596737120.047779", "r"]], "c": "530901090"}, "book-100", "XBT/USD"]
[270, {"a": [["11857.60000", "1.01879208", "1596737139.935430"]], "c": "3402917724"}, "book-100", "XBT/USD"]
[270, {"a": [["11856.50000", "0.00000000", "1596737139.936609"], ["11901.40000", "1.90492467", "1596737138.167457", "r"]], "c": "3817282685"}, "book-100", "XBT/USD"]
[270, {"a": [["11864.50000", "0.10100000", "1596737139.937409"]], "c": "3817282685"}, "book-100", "XBT/USD"]
[270, {"a": [["11868.90000", "0.00000000", "1596737139.937889"], ["11901.50000", "3.26167975", "1596737133.218332", "r"]], "c": "3817282685"}, "book-100", "XBT/USD"]
[270, {"a": [["11857.50000", "0.83570000", "1596737139.938372"]], "c": "3751425667"}, "book-100", "XBT/USD"]
[270, {"a": [["11858.70000", "0.00000000", "1596737139.950555"], ["11901.50000", "3.26167975", "1596737133.218332", "r"]], "c": "2463484000"}, "book-100", "XBT/USD"]
[270, {"b": [["11852.60000", "0.45084697", "1596737139.952362"]], "c": "658213171"}, "book-100", "XBT/USD"]
[270, {"a": [["11860.00000", "0.00000000", "1596737139.952840"], ["11901.80000", "0.75800000", "1596737130.968842", "r"]], "c": "1536970211"}, "book-100", "XBT/USD"]
[270, {"a": [["11886.50000", "0.00000000", "1596737139.953318"], ["11902.00000", "0.22739000", "1596736764.397858", "r"]], "c": "1536970211"}, "book-100", "XBT/USD"]
[270, {"b": [["11812.90000", "0.73653060", "1596737139.954461"]], "c": "1536970211"}, "book-100", "XBT/USD"]
[270, {"a": [["11861.00000", "0.00000000", "1596737139.954532"], ["11902.20000", "1.58369712", "1596737116.990726", "r"]], "c": "792422156"}, "book-100", "XBT/USD"]
[270, {"b": [["11852.60000", "1.46181697", "1596737139.956954"]], "c": "458109776"}, "book-100", "XBT/USD"]
[270, {"b": [["11819.10000", "0.00000000", "1596737139.959053"], ["11795.00000", "0.80800000", "1596736676.791659", "r"]], "c": "458109776"}, "book-100", "XBT/USD"]
[270, {"a": [["11858.10000", "0.00000000", "1596737139.959417"], ["11903.90000", "1.59024654", "1596737096.689627", "r"]], "c": "2622807656"}, "book-100", "XBT/USD"]
[270, {"a": [["11857.60000", "0.64197094", "1596737139.959730"]], "c": "1652865031"}, "book-100", "XBT/USD"]
[270, {"b": [["11828.50000", "0.00000000", "1596737139.960031"], ["11792.50000", "5.30000000", "1596737130.530368", "r"]], "c": "1652865031"}, "book-100", "XBT/USD"]
[270, {"a": [["11852.70000", "0.41958290", "1596737139.968940"]], "c": "2837247451"}, "book-100", "XBT/USD"]
[270, {"b": [["11832.60000", "0.00000000", "1596737139.972744"], ["11790.00000", "0.24750000", "1596737132.922523", "r"]], "c": "2837247451"}, "book-100", "XBT/USD"]
[270, {"b": [["11852.60000", "1.66181697", "1596737139.973871"]], "c": "1507992250"}, "book-100", "XBT/USD"]
[270, {"a": [["11863.10000", "4.50250000", "1596737139.981190"]], "c": "1466960810"}, "book-100", "XBT/USD"]
[270, {"a": [["11859.00000", "0.00000000", "1596737139.982557"], ["11904.00000", "0.17065000", "1596737071.292235", "r"]], "c": "1616266817"}, "book-100", "XBT/USD"]
[270, {"a": [["11863.20000", "1.03041641", "1596737139.983213"]], "c": "4004558769"}, "book-100", "XBT/USD"]
[270, {"b": [["11851.60000", "2.14578928", "1596737139.983358"]], "c": "3674618839"}, "book-100", "XBT/USD"]
[270, {"a": [["11866.40000", "0.28399999", "1596737139.984821"]], "c": "3674618839"}, "book-100", "XBT/USD"]
[270, {"b": [["11795.10000", "2.21059251", "1596737139.986380"]], "c": "3674618839"}, "book-100", "XBT/USD"]
[270, {"a": [["11857.60000", "0.00000000", "1596737139.989012"], ["11904.60000", "0.02329731", "1596737116.563077", "r"]], "c": "4259574310"}, "book-100", "XBT/USD"]
[270, {"a": [["11857.00000", "0.83570000", "1596737139.999720"]], "c": "363558977"}, "book-100", "XBT/USD"]
[270, {"b": [["11852.60000", "1.74181697", "1596737140.001674"]], "c": "365951884"}, "book-100", "XBT/USD"]
[270, {"a": [["11898.30000", "0.00000000", "1596737140.006182"], ["11904.60000", "0.02329731", "1596737116.563077", "r"]], "c": "365951884"}, "book-100", "XBT/USD"]
[270, {"a": [["11867.90000", "3.81172698", "1596737140.020609"]], "c": "365951884"}, "book-100", "XBT/USD"]
[270, {"a": [["11857.50000", "0.00000000", "1596737140.030470"], ["11904.60000", "0.02329731", "1596737116.563077", "r"]], "c": "560852458"}, "book-100", "XBT/USD"]
[270, {"a": [["11852.70000", "0.42946198", "1596737140.030730"]], "c": "3439998764"}, "book-100", "XBT/USD"]
[270, {"a": [["11893.70000", "0.00000000", "1596737140.056423"], ["11905.00000", "27.00000000", "1596736856.739074", "r"]], "c": "3439998764"}, "book-100", "XBT/USD"]
[270, {"b": [["11851.20000", "0.10000000", "1596737140.063733"]], "c": "3325345687"}, "book-100", "XBT/USD"]
[270, {"a": [["11860.60000", "0.10100000", "1596737140.078962"]], "c": "49846360"}, "book-100", "XBT/USD"]
[270, {"b": [["11850.00000", "0.79756000", "1596737140.081051"]], "c": "2216002947"}, "book-100", "XBT/USD"]
[270, {"b": [["11850.30000", "0.40000000", "1596737140.088354"]], "c": "2885170324"}, "book-100", "XBT/USD"]
[270, {"a": [["11857.00000", "0.00000000", "1596737140.089042"], ["11905.00000", "27.00000000", "1596736856.739074", "r"]], "c": "2366641550"}, "book-100", "XBT/USD"]
[270, {"a": [["11857.50000", "0.83570000", "1596737140.089979"]], "c": "970116016"}, "book-100", "XBT/USD"]
[270, {"a": [["11858.00000", "0.00000000", "1596737140.091126"], ["11905.00000", "27.00000000", "1596736856.739074", "r"]], "c": "3431497783"}, "book-100", "XBT/USD"]
[270, {"a": [["11864.40000", "0.69931034", "1596737140.102813"]], "c": "3431497783"}, "book-100", "XBT/USD"]
[270, {"a": [["11860.70000", "1.50000000", "1596737140.133751"]], "c": "517014392"}, "book-100", "XBT/USD"]
[270, {"a": [["11872.20000", "1.52609782", "1596737140.200419"]], "c": "517014392"}, "book-100", "XBT/USD"]
[270, {"a": [["11889.00000", "0.00000000", "1596737140.205455"], ["11904.60000", "0.02329731", "1596737116.563077", "r"]], "c": "517014392"}, "book-100", "XBT/USD"]
[270, {"a": [["11861.50000", "0.25000000", "1596737140.210118"]], "c": "2319005131"}, "book-100", "XBT/USD"]
[270, {"b": [["11852.60000", "2.24181697", "1596737140.254685"]], "c": "2925221267"}, "book-100", "XBT/USD"]
[270, {"a": [["11863.20000", "0.94612106", "1596737140.256868"]], "c": "2925221267"}, "book-100", "XBT/USD"]
[270, {"b": [["11848.20000", "0.00000000", "1596737140.257370"], ["11795.10000", "2.21059251", "1596737139.986380", "r"]], "c": "2925221267"}, "book-100", "XBT/USD"]
[270, {"a": [["11865.40000", "0.41646576", "1596737140.264610"]], "c": "2925221267"}, "book-100", "XBT/USD"]
[270, {"a": [["11878.10000", "0.00000000", "1596737140.265501"], ["11904.00000", "0.17065000", "1596737071.292235", "r"]], "c": "2925221267"}, "book-100", "XBT/USD"]
[270, {"a": [["11865.40000", "1.05843670", "1596737140.329320"]], "c": "2925221267"}, "book-100", "XBT/USD"]
[270, {"b": [["11819.20000", "2.02285150", "1596737140.341840"]], "c": "2925221267"}, "book-100", "XBT/USD"]
[270, {"b": [["11833.10000", "3.28003602", "1596737140.344888"]], "c": "2925221267"}, "book-100", "XBT/USD"]
[270, {"a": [["11865.40000", "1.27484665", "1596737140.356947"]], "c": "2925221267"}, "book-100", "XBT/USD"]
[270, {"a": [["11865.40000", "1.66399673", "1596737140.369960"]], "c": "2925221267"}, "book-100", "XBT/USD"]
[270, {"a": [["11874.10000", "1.14312846", "1596737140.378774"]], "c": "2925221267"}, "book-100", "XBT/USD"]
[270, {"b": [["11849.50000", "0.42154067", "1596737140.384082"]], "c": "2429538643"}, "book-100", "XBT/USD"]
[270, {"a": [["11860.40000", "0.63227812", "1596737140.384629"]], "c": "2142681038"}, "book-100", "XBT/USD"]
[270, {"a": [["11865.40000", "1.79435155", "1596737140.387781"]], "c": "2142681038"}, "book-100", "XBT/USD"]
[270, {"b": [["11852.60000", "2.55800876", "1596737140.393338"]], "c": "997941774"}, "book-100", "XBT/USD"]
[270, {"a": [["11866.90000", "0.84308134", "1596737140.419784"]], "c": "997941774"}, "book-100", "XBT/USD"]
[270, {"a": [["11856.40000", "0.00000000", "1596737140.421736"], ["11903.90000", "1.59024654", "1596737096.689627", "r"]], "c": "2354811856"}, "book-100", "XBT/USD"]
[270, {"a": [["11871.60000", "2.89286386", "1596737140.434409"]], "c": "2354811856"}, "book-100", "XBT/USD"]
[270, {"b": [["11821.50000", "0.00000000", "1596737140.445384"], ["11795.30000", "2.20028792", "1596736851.216162", "r"]], "c": "2354811856"}, "book-100", "XBT/USD"]
[270, {"b": [["11839.70000", "0.00000000", "1596737140.447840"], ["11795.10000", "2.21059251", "1596737139.986380", "r"]], "c": "2354811856"}, "book-100", "XBT/USD"]
[270, {"b": [["11836.20000", "0.00000000", "1596737140.457221"], ["11795.00000", "0.80800000", "1596736676.791659", "r"]], "c": "2354811856"}, "book-100", "XBT/USD"]
[270, {"a": [["11869.20000", "0.00000000", "1596737140.468234"], ["11903.90000", "1.59024654", "1596737096.689627", "r"]], "c": "2354811856"}, "book-100", "XBT/USD"]
[270, {"b": [["11837.50000", "0.00000000", "1596737140.474430"], ["11792.50000", "5.30000000", "1596737130.530368", "r"]], "c": "2354811856"}, "book-100", "XBT/USD"]
[270, {"b": [["11840.90000", "0.38000000", "1596737140.475957"]], "c": "2354811856"}, "book-100", "XBT/USD"]
[270, {"b": [["11825.20000", "1.60003358", "1596737140.477488"]], "c": "2354811856"}, "book-100", "XBT/USD"]
[270, {"b": [["11842.80000", "0.00000000", "1596737140.479755"], ["11792.50000", "5.30000000", "1596737130.530368", "r"]], "c": "2354811856"}, "book-100", "XBT/USD"]
[270, {"b": [["11846.30000", "0.00000000", "1596737140.482612"], ["11790.00000", "0.24750000", "1596737132.922523", "r"]], "c": "2354811856"}, "book-100", "XBT/USD"]
[270, {"a": [["11893.80000", "0.00000000", "1596737140.485851"], ["11904.00000", "0.17065000", "1596737071.292235", "r"]], "c": "2354811856"}, "book-100", "XBT/USD"]
[270, {"a": [["11872.90000", "1.22326788", "1596737140.489876"]], "c": "2354811856"}, "book-100", "XBT/USD"]
[270, {"b": [["11840.00000", "0.00000000", "1596737140.490645"], ["11789.40000", "2.00800000", "1596735513.212546", "r"]], "c": "2354811856"}, "book-100", "XBT/USD"]
[270, {"b": [["11836.40000", "0.00000000", "1596737140.492594"], ["11787.00000", "0.17065000", "1596737071.713970", "r"]], "c": "2354811856"}, "book-100", "XBT/USD"]
[270, {"a": [["11878.10000", "0.46739120", "1596737140.497803"]], "c": "2354811856"}, "book-100", "XBT/USD"]
[270, {"a": [["11889.90000", "2.11585184", "1596737140.498010"]], "c": "2354811856"}, "book-100", "XBT/USD"]
[270, {"b": [["11839.90000", "0.00000000", "1596737140.498553"], ["11784.80000", "18.70000000", "1596737138.299998", "r"]], "c": "2354811856"}, "book-100", "XBT/USD"]
[270, {"a": [["11890.30000", "0.00000000", "1596737140.503980"], ["11903.90000", "1.59024654", "1596737096.689627", "r"]], "c": "2354811856"}, "book-100", "XBT/USD"]
[270, {"a": [["11883.20000", "0.00000000", "1596737140.507060"], ["11904.00000", "0.17065000", "1596737071.292235", "r"]], "c": "2354811856"}, "book-100", "XBT/USD"]
[270, {"a": [["11885.50000", "0.00000000", "1596737140.507862"], ["11904.60000", "0.02329731", "1596737116.563077", "r"]], "c": "2354811856"}, "book-100", "XBT/USD"]
[270, {"a": [["11889.10000", "2.18181523", "1596737140.510788"]], "c": "2354811856"}, "book-100", "XBT/USD"]
[270, {"b": [["11819.20000", "0.10455816", "1596737140.511996"]], "c": "2354811856"}, "book-100", "XBT/USD"]
[270, {"a": [["11883.70000", "0.00000000", "1596737140.513724"], ["11905.00000", "27.00000000", "1596736856.739074", "r"]], "c": "2354811856"}, "book-100", "XBT/USD"]
[270, {"b": [["11842.30000", "0.00000000", "1596737140.522903"], ["11784.50000", "0.00200000", "1596736829.981217", "r"]], "c": "2354811856"}, "book-100", "XBT/USD"]
[270, {"a": [["11858.70000", "0.83570000", "1596737140.527078"]], "c": "393838738"}, "book-100", "XBT/USD"]
[270, {"a": [["11885.80000", "0.00000000", "1596737140.530213"], ["11905.00000", "27.00000000", "1596736856.739074", "r"]], "c": "393838738"}, "book-100", "XBT/USD"]
[270, {"b": [["11819.30000", "0.00000000", "1596737140.530776"], ["11784.00000", "0.17065000", "1596737088.317848", "r"]], "c": "393838738"}, "book-100", "XBT/USD"]
[270, {"b": [["11852.60000", "6.76400876", "1596737140.532454"]], "c": "3466124541"}, "book-100", "XBT/USD"]
[270, {"a": [["11857.50000", "0.00000000", "1596737140.533611"], ["11906.40000", "0.47990000", "1596737133.044226", "r"]], "c": "3529129408"}, "book-100", "XBT/USD"]
[270, {"b": [["11834.60000", "3.11071497", "1596737140.546564"]], "c": "3529129408"}, "book-100", "XBT/USD"]
[270, {"a": [["11894.40000", "0.00000000", "1596737140.553488"], ["11907.00000", "0.17065000", "1596737135.727101", "r"]], "c": "3529129408"}, "book-100", "XBT/USD"]
[270, {"b": [["11838.20000", "0.00000000", "1596737140.557120"], ["11781.00000", "0.27065000", "1596737131.905668", "r"]], "c": "3529129408"}, "book-100", "XBT/USD"]
[270, {"a": [["11865.60000", "0.66283811", "1596737140.563183"]], "c": "3529129408"}, "book-100", "XBT/USD"]
[270, {"b": [["11834.50000", "0.00000000", "1596737140.570718"], ["11780.00000", "0.50000000", "1596734389.131980", "r"]], "c": "3529129408"}, "book-100", "XBT/USD"]
[270, {"b": [["11851.20000", "0.00000000", "1596737140.571752"], ["11778.00000", "0.14434000", "1596737017.436335", "r"]], "c": "2336303006"}, "book-100", "XBT/USD"]
[270, {"b": [["11819.50000", "0.00000000", "1596737140.572612"], ["11777.00000", "0.00100000", "1596735197.730576", "r"]], "c": "2336303006"}, "book-100", "XBT/USD"]
[270, {"b": [["11834.60000", "0.00000000", "1596737140.591278"], ["11775.00000", "0.92000000", "1596736031.317852", "r"]], "c": "2336303006"}, "book-100", "XBT/USD"]
[270, {"a": [["11865.60000", "0.81202331", "1596737140.594146"]], "c": "2336303006"}, "book-100", "XBT/USD"]
[270, {"a": [["11867.90000", "0.00000000", "1596737140.615132"], ["11907.00000", "0.17065000", "1596737135.727101", "r"]], "c": "2336303006"}, "book-100", "XBT/USD"]
[270, {"a": [["11872.20000", "0.84331654", "1596737140.699887"]], "c": "2336303006"}, "book-100", "XBT/USD"]
[270, {"a": [["11878.10000", "0.00000000", "1596737140.699959"], ["11907.60000", "2.21059251", "1596737139.986733", "r"]], "c": "2336303006"}, "book-100", "XBT/USD"]
[270, {"b": [["11843.50000", "6.77578687", "1596737140.705940"]], "c": "2336303006"}, "book-100", "XBT/USD"]
[270, {"a": [["11880.50000", "0.20402924", "1596737140.706959"]], "c": "2336303006"}, "book-100", "XBT/USD"]
[270, {"a": [["11884.00000", "1.22847233", "1596737140.707295"]], "c": "2336303006"}, "book-100", "XBT/USD"]
[270, {"a": [["11865.60000", "1.11699317", "1596737140.709574"]], "c": "2336303006"}, "book-100", "XBT/USD"]
[270, {"b": [["11839.90000", "0.28662042", "1596737140.709683"]], "c": "2336303006"}, "book-100", "XBT/USD"]
[270, {"a": [["11892.00000", "0.00000000", "1596737140.709971"], ["11907.60000", "2.21059251", "1596737139.986733", "r"]], "c": "2336303006"}, "book-100", "XBT/USD"]
[270, {"a": [["11888.80000", "0.46893963", "1596737140.710364"]], "c": "2336303006"}, "book-100", "XBT/USD"]
[270, {"a": [["11855.00000", "0.00000000", "1596737140.713252"], ["11907.60000", "2.21059251", "1596737139.986733", "r"]], "c": "3675298692"}, "book-100", "XBT/USD"]
[270, {"b": [["11843.20000", "0.96893767", "1596737140.727204"]], "c": "3675298692"}, "book-100", "XBT/USD"]
[270, {"b": [["11834.90000", "0.94660107", "1596737140.729925"]], "c": "3675298692"}, "book-100", "XBT/USD"]
[270, {"b": [["11827.90000", "0.94716129", "1596737140.738171"]], "c": "3675298692"}, "book-100", "XBT/USD"]
[270, {"b": [["11839.70000", "0.94621730", "1596737140.743365"]], "c": "3675298692"}, "book-100", "XBT/USD"]
[270, {"b": [["11835.00000", "0.00000000", "1596737140.756820"], ["11780.00000", "0.50000000", "1596734389.131980", "r"]], "c": "3675298692"}, "book-100", "XBT/USD"]
[270, {"a": [["11861.50000", "0.00000000", "1596737140.763291"], ["11907.80000", "0.17236827", "1596737139.936859", "r"]], "c": "4113996291"}, "book-100", "XBT/USD"]
[270, {"b": [["11849.80000", "0.32986546", "1596737140.824259"]], "c": "1304856216"}, "book-100", "XBT/USD"]
[270, {"b": [["11846.30000", "0.69292213", "1596737140.824351"]], "c": "1304856216"}, "book-100", "XBT/USD"]
[270, {"a": [["11893.90000", "0.00000000", "1596737140.824868"], ["11907.90000", "2.38150000", "1596736895.960018", "r"]], "c": "1304856216"}, "book-100", "XBT/USD"]
[270, {"b": [["11832.10000", "2.19169980", "1596737140.844021"]], "c": "1304856216"}, "book-100", "XBT/USD"]
[270, {"a": [["11887.20000", "0.00000000", "1596737140.849779"], ["11908.90000", "1.06880000", "1596736841.521829", "r"]], "c": "1304856216"}, "book-100", "XBT/USD"]
[270, {"a": [["11894.60000", "0.00000000", "1596737140.851103"], ["11909.90000", "6.20000000", "1596736825.518690", "r"]], "c": "1304856216"}, "book-100", "XBT/USD"]
[270, {"a": [["11884.00000", "0.28555681", "1596737140.856520"]], "c": "1304856216"}, "book-100", "XBT/USD"]
[270, {"a": [["11879.90000", "0.67107343", "1596737140.886498"]], "c": "1304856216"}, "book-100", "XBT/USD"]
[270, {"a": [["11871.20000", "0.70523690", "1596737140.929607"]], "c": "1304856216"}, "book-100", "XBT/USD"]
[270, {"b": [["11852.60000", "6.86400876", "1596737140.958281"]], "c": "1735016684"}, "book-100", "XBT/USD"]
[270, {"b": [["11838.00000", "2.61224523", "1596737140.984423"]], "c": "1735016684"}, "book-100", "XBT/USD"]
[270, {"b": [["11841.70000", "0.53052674", "1596737140.995751"]], "c": "1735016684"}, "book-100", "XBT/USD"]
[270, {"a": [["11860.30000", "0.83570000", "1596737141.045241"]], "c": "2989772181"}, "book-100", "XBT/USD"]
[270, {"a": [["11858.70000", "0.00000000", "1596737141.049703"], ["11908.90000", "1.06880000", "1596736841.521829", "r"]], "c": "3466466588"}, "book-100", "XBT/USD"]
[270, {"b": [["11825.30000", "0.00000000", "1596737141.065663"], ["11784.50000", "0.00200000", "1596736829.981217", "r"]], "c": "3466466588"}, "book-100", "XBT/USD"]
[270, {"a": [["11860.80000", "0.25000000", "1596737141.073136"]], "c": "220548844"}, "book-100", "XBT/USD"]
[270, {"a": [["11863.20000", "1.03041641", "1596737141.121904"]], "c": "530388979"}, "book-100", "XBT/USD"]
[270, {"b": [["11822.50000", "0.01000000", "1596737141.166389"]], "c": "530388979"}, "book-100", "XBT/USD"]
[270, {"a": [["11888.80000", "1.52578952", "1596737141.170264"]], "c": "530388979"}, "book-100", "XBT/USD"]
[270, {"b": [["11832.70000", "0.47122688", "1596737141.174678"]], "c": "530388979"}, "book-100", "XBT/USD"]
[270, {"b": [["11820.80000", "0.00000000", "1596737141.175467"], ["11784.50000", "0.00200000", "1596736829.981217", "r"]], "c": "530388979"}, "book-100", "XBT/USD"]
[270, {"a": [["11881.30000", "0.00000000", "1596737141.176150"], ["11908.90000", "1.06880000", "1596736841.521829", "r"]], "c": "530388979"}, "book-100", "XBT/USD"]
[270, {"a": [["11890.00000", "0.70225780", "1596737141.177959"]], "c": "530388979"}, "book-100", "XBT/USD"]
[270, {"a": [["11871.20000", "0.00000000", "1596737141.179278"], ["11909.90000", "6.20000000", "1596736825.518690", "r"]], "c": "530388979"}, "book-100", "XBT/USD"]
[270, {"a": [["11877.80000", "0.00000000", "1596737141.187534"], ["11910.00000", "0.36067000", "1596736968.148143", "r"]], "c": "530388979"}, "book-100", "XBT/USD"]
[270, {"b": [["11846.30000", "0.80223609", "1596737141.198867"]], "c": "530388979"}, "book-100", "XBT/USD"]
[270, {"a": [["11884.10000", "0.00000000", "1596737141.199142"], ["11910.50000", "1.68800000", "1596736995.994117", "r"]], "c": "530388979"}, "book-100", "XBT/USD"]
[270, {"a": [["11886.40000", "1.27465857", "1596737141.199337"]], "c": "530388979"}, "book-100", "XBT/USD"]
[270, {"b": [["11843.90000", "0.76535277", "1596737141.202075"]], "c": "530388979"}, "book-100", "XBT/USD"]
[270, {"a": [["11880.50000", "0.96702420", "1596737141.202347"]], "c": "530388979"}, "book-100", "XBT/USD"]
[270, {"b": [["11838.00000", "3.89211528", "1596737141.205000"]], "c": "530388979"}, "book-100", "XBT/USD"]
[270, {"b": [["11817.50000", "0.00000000", "1596737141.221793"], ["11784.50000", "0.00200000", "1596736829.981217", "r"]], "c": "530388979"}, "book-100", "XBT/USD"]
[270, {"a": [["11863.20000", "0.94612106", "1596737141.262683"]], "c": "220548844"}, "book-100", "XBT/USD"]
[270, {"b": [["11838.60000", "6.49579788", "1596737141.272455"]], "c": "220548844"}, "book-100", "XBT/USD"]
[270, {"b": [["11820.90000", "5.16984571", "1596737141.303345"]], "c": "220548844"}, "book-100", "XBT/USD"]
[270, {"b": [["11833.10000", "0.00000000", "1596737141.331964"], ["11784.80000", "18.70000000", "1596737138.299998", "r"]], "c": "220548844"}, "book-100", "XBT/USD"]
[270, {"b": [["11843.50000", "6.57112023", "1596737141.336540"]], "c": "220548844"}, "book-100", "XBT/USD"]
[270, {"b": [["11846.30000", "0.10931396", "1596737141.338216"]], "c": "220548844"}, "book-100", "XBT/USD"]
[270, {"b": [["11839.90000", "0.00000000", "1596737141.339126"], ["11784.50000", "0.00200000", "1596736829.981217", "r"]], "c": "220548844"}, "book-100", "XBT/USD"]
[270, {"b": [["11839.70000", "0.00000000", "1596737141.340595"], ["11784.00000", "0.17065000", "1596737088.317848", "r"]], "c": "220548844"}, "book-100", "XBT/USD"]
[270, {"b": [["11832.70000", "0.00000000", "1596737141.357315"], ["11781.00000", "0.27065000", "1596737131.905668", "r"]], "c": "220548844"}, "book-100", "XBT/USD"]
[270, {"b": [["11807.50000", "4.65625153", "1596737141.363479"]], "c": "220548844"}, "book-100", "XBT/USD"]
[270, {"b": [["11849.80000", "0.00000000", "1596737141.364204"], ["11780.00000", "0.50000000", "1596734389.131980", "r"]], "c": "3388311785"}, "book-100", "XBT/USD"]
[270, {"b": [["11813.40000", "0.00000000", "1596737141.372704"], ["11778.00000", "0.14434000", "1596737017.436335", "r"]], "c": "3388311785"}, "book-100", "XBT/USD"]
[270, {"b": [["11807.60000", "0.96525494", "1596737141.392771"]], "c": "3388311785"}, "book-100", "XBT/USD"]
[270, {"b": [["11807.50000", "2.19772556", "1596737141.423734"]], "c": "3388311785"}, "book-100", "XBT/USD"]
[270, {"a": [["11872.80000", "0.71123673", "1596737141.430444"]], "c": "3388311785"}, "book-100", "XBT/USD"]
[270, {"b": [["11837.20000", "0.00000000", "1596737141.464611"], ["11777.00000", "0.00100000", "1596735197.730576", "r"]], "c": "3388311785"}, "book-100", "XBT/USD"]
[270, {"b": [["11838.50000", "0.00000000", "1596737141.522859"], ["11775.00000", "0.92000000", "1596736031.317852", "r"]], "c": "3388311785"}, "book-100", "XBT/USD"]
[270, {"b": [["11843.20000", "0.02300000", "1596737141.621262"]], "c": "3388311785"}, "book-100", "XBT/USD"]
[270, {"a": [["11878.10000", "0.10902130", "1596737141.627420"]], "c": "3388311785"}, "book-100", "XBT/USD"]
[270, {"a": [["11898.30000", "6.46320506", "1596737141.628854"]], "c": "3388311785"}, "book-100", "XBT/USD"]
[270, {"b": [["11845.80000", "0.20462690", "1596737141.664367"]], "c": "3388311785"}, "book-100", "XBT/USD"]
[270, {"b": [["11842.30000", "0.28656233", "1596737141.670346"]], "c": "3388311785"}, "book-100", "XBT/USD"]
[270, {"b": [["11837.50000", "0.47097187", "1596737141.683276"]], "c": "3388311785"}, "book-100", "XBT/USD"]
[270, {"a": [["11858.70000", "0.83570000", "1596737141.721334"]], "c": "4046774554"}, "book-100", "XBT/USD"]
[270, {"a": [["11860.30000", "0.00000000", "1596737141.765790"], ["11907.90000", "2.38150000", "1596736895.960018", "r"]], "c": "2165189381"}, "book-100", "XBT/USD"]
[270, {"b": [["11838.70000", "0.25508740", "1596737141.771851"]], "c": "2165189381"}, "book-100", "XBT/USD"]
[270, {"a": [["11888.10000", "0.50000000", "1596737141.834698"]], "c": "2165189381"}, "book-100", "XBT/USD"]
[270, {"b": [["11852.60000", "7.26400876", "1596737142.000664"]], "c": "2524937415"}, "book-100", "XBT/USD"]
[270, {"b": [["11850.30000", "0.00000000", "1596737142.054181"], ["11780.00000", "0.50000000", "1596734389.131980", "r"]], "c": "2895667904"}, "book-100", "XBT/USD"]
[270, {"a": [["11863.20000", "1.03041641", "1596737142.142260"]], "c": "1109908357"}, "book-100", "XBT/USD"]
[270, {"a": [["11883.00000", "0.52868287", "1596737142.176973"]], "c": "1109908357"}, "book-100", "XBT/USD"]
[270, {"a": [["11863.20000", "0.94612106", "1596737142.288175"]], "c": "2895667904"}, "book-100", "XBT/USD"]
[270, {"b": [["11781.00000", "0.10000000", "1596737142.470910"]], "c": "2895667904"}, "book-100", "XBT/USD"]
[270, {"b": [["11815.00000", "2.60524489", "1596737142.548327"]], "c": "2895667904"}, "book-100", "XBT/USD"]
[270, {"b": [["11838.60000", "9.49579788", "1596737142.583132"]], "c": "2895667904"}, "book-100", "XBT/USD"]
[270, {"b": [["11805.00000", "0.17065000", "1596737142.629728"]], "c": "2895667904"}, "book-100", "XBT/USD"]
[270, {"a": [["11857.20000", "0.09621094", "1596737142.635013"]], "c": "2896361286"}, "book-100", "XBT/USD"]
[270, {"b": [["11848.40000", "0.09621094", "1596737142.664006"]], "c": "172861773"}, "book-100", "XBT/USD"]
[270, {"b": [["11846.20000", "0.00000000", "1596737142.667675"], ["11781.00000", "0.10000000", "1596737142.470910", "r"]], "c": "172861773"}, "book-100", "XBT/USD"]
[270, {"a": [["11860.30000", "0.70000000", "1596737142.683356"]], "c": "3728798593"}, "book-100", "XBT/USD"]
[270, {"a": [["11883.10000", "0.05000000", "1596737142.737160"]], "c": "3728798593"}, "book-100", "XBT/USD"]
[270, {"b": [["11835.70000", "0.00000000", "1596737142.892906"], ["11780.00000", "0.50000000", "1596734389.131980", "r"]], "c": "3728798593"}, "book-100", "XBT/USD"]
[270, {"b": [["11846.40000", "0.23800000", "1596737142.899503"]], "c": "3728798593"}, "book-100", "XBT/USD"]
[270, {"a": [["11863.10000", "4.45500000", "1596737143.023554"]], "c": "3728798593"}, "book-100", "XBT/USD"]
[270, {"a": [["11858.60000", "0.04750000", "1596737143.143952"]], "c": "1423687450"}, "book-100", "XBT/USD"]
[270, {"b": [["11820.80000", "2.19383325", "1596737143.531104"]], "c": "1423687450"}, "book-100", "XBT/USD"]
[270, {"b": [["11848.00000", "5.40000000", "1596737143.595261"]], "c": "1423687450"}, "book-100", "XBT/USD"]
[270, {"a": [["11874.70000", "0.32918401", "1596737143.602446"]], "c": "1423687450"}, "book-100", "XBT/USD"]
[270, {"b": [["11814.90000", "2.74605617", "1596737143.602593"]], "c": "1423687450"}, "book-100", "XBT/USD"]
[270, {"b": [["11850.20000", "0.32986459", "1596737143.611796"]], "c": "3384905090"}, "book-100", "XBT/USD"]
[270, {"b": [["11846.70000", "0.69292029", "1596737143.611983"]], "c": "3384905090"}, "book-100", "XBT/USD"]
[270, {"b": [["11844.40000", "1.38610969", "1596737143.622159"]], "c": "3384905090"}, "book-100", "XBT/USD"]
[270, {"b": [["11826.70000", "2.65496292", "1596737143.623017"]], "c": "3384905090"}, "book-100", "XBT/USD"]
[270, {"b": [["11838.50000", "1.75001014", "1596737143.624159"]], "c": "3384905090"}, "book-100", "XBT/USD"]
[270, {"a": [["11886.50000", "1.74294326", "1596737143.638336"]], "c": "3384905090"}, "book-100", "XBT/USD"]
[270, {"a": [["11878.20000", "7.89108272", "1596737143.647116"]], "c": "3384905090"}, "book-100", "XBT/USD"]
[270, {"a": [["11866.40000", "0.00000000", "1596737143.657268"], ["11904.60000", "0.02329731", "1596737116.563077", "r"]], "c": "3384905090"}, "book-100", "XBT/USD"]
[270, {"a": [["11869.00000", "0.18315000", "1596737143.659779"]], "c": "3384905090"}, "book-100", "XBT/USD"]
[270, {"a": [["11880.60000", "1.38188623", "1596737143.669963"]], "c": "3384905090"}, "book-100", "XBT/USD"]
[270, {"a": [["11881.70000", "0.28399999", "1596737143.696036"]], "c": "3384905090"}, "book-100", "XBT/USD"]
[270, {"a": [["11860.70000", "0.00000000", "1596737143.733147"], ["11904.00000", "0.17065000", "1596737071.292235", "r"]], "c": "3652685469"}, "book-100", "XBT/USD"]
[270, {"b": [["11851.70000", "0.10000000", "1596737143.790456"]], "c": "1543937695"}, "book-100", "XBT/USD"]
[270, {"a": [["11860.20000", "0.83570000", "1596737143.816299"]], "c": "2711442366"}, "book-100", "XBT/USD"]
[270, {"a": [["11858.80000", "0.00000000", "1596737143.822603"], ["11904.00000", "0.17065000", "1596737071.292235", "r"]], "c": "968061514"}, "book-100", "XBT/USD"]
[270, {"a": [["11858.70000", "0.00000000", "1596737143.823464"], ["11904.60000", "0.02329731", "1596737116.563077", "r"]], "c": "2670144113"}, "book-100", "XBT/USD"]
[270, {"b": [["11851.70000", "0.00000000", "1596737143.838250"], ["11792.50000", "5.30000000", "1596737130.530368", "r"]], "c": "4102930784"}, "book-100", "XBT/USD"]
[270, {"a": [["11863.60000", "2.34306230", "1596737143.878938"]], "c": "4102930784"}, "book-100", "XBT/USD"]
[270, {"a": [["11861.00000", "0.63225049", "1596737143.881072"]], "c": "2217272967"}, "book-100", "XBT/USD"]
[270, {"a": [["11888.10000", "0.00000000", "1596737143.933105"], ["11904.60000", "0.02329731", "1596737116.563077", "r"]], "c": "2217272967"}, "book-100", "XBT/USD"]
[270, {"b": [["11838.00000", "3.47047752", "1596737143.975850"]], "c": "2217272967"}, "book-100", "XBT/USD"]
[270, {"a": [["11862.30000", "0.00000000", "1596737144.004892"], ["11905.00000", "27.00000000", "1596736856.739074", "r"]], "c": "1404471252"}, "book-100", "XBT/USD"]
[270, {"b": [["11851.00000", "0.00000000", "1596737144.009857"], ["11790.00000", "0.24750000", "1596737132.922523", "r"]], "c": "3569289790"}, "book-100", "XBT/USD"]
[270, {"a": [["11889.20000", "1.62315639", "1596737144.137761"]], "c": "3569289790"}, "book-100", "XBT/USD"]
[270, {"a": [["11884.50000", "1.24262903", "1596737144.142103"]], "c": "3569289790"}, "book-100", "XBT/USD"]
[270, {"b": [["11848.30000", "0.54677033", "1596737144.145326"]], "c": "3569289790"}, "book-100", "XBT/USD"]
[270, {"b": [["11843.60000", "0.94588425", "1596737144.149882"]], "c": "3569289790"}, "book-100", "XBT/USD"]
[270, {"a": [["11880.90000", "0.94291465", "1596737144.162247"]], "c": "3569289790"}, "book-100", "XBT/USD"]
[270, {"b": [["11840.50000", "0.00000000", "1596737144.184430"], ["11792.50000", "5.30000000", "1596737130.530368", "r"]], "c": "3569289790"}, "book-100", "XBT/USD"]
[270, {"a": [["11889.90000", "0.00000000", "1596737144.196097"], ["11905.00000", "27.00000000", "1596736856.739074", "r"]], "c": "3569289790"}, "book-100", "XBT/USD"]
[270, {"a": [["11882.70000", "3.26640292", "1596737144.225992"]], "c": "3569289790"}, "book-100", "XBT/USD"]
[270, {"b": [["11841.30000", "3.27782305", "1596737144.227849"]], "c": "3569289790"}, "book-100", "XBT/USD"]
[270, {"b": [["11826.00000", "3.28206376", "1596737144.228248"]], "c": "3569289790"}, "book-100", "XBT/USD"]
[270, {"a": [["11888.70000", "3.26475443", "1596737144.228474"]], "c": "3569289790"}, "book-100", "XBT/USD"]
[270, {"b": [["11814.20000", "3.28534188", "1596737144.230828"]], "c": "3569289790"}, "book-100", "XBT/USD"]
[270, {"b": [["11835.40000", "3.27945706", "1596737144.236314"]], "c": "3569289790"}, "book-100", "XBT/USD"]
[270, {"a": [["11877.30000", "0.00000000", "1596737144.264059"], ["11904.60000", "0.02329731", "1596737116.563077", "r"]], "c": "3569289790"}, "book-100", "XBT/USD"]
[270, {"a": [["11864.70000", "1.68566053", "1596737144.359823"]], "c": "3569289790"}, "book-100", "XBT/USD"]
[270, {"a": [["11890.60000", "2.10815717", "1596737144.383808"]], "c": "3569289790"}, "book-100", "XBT/USD"]
[270, {"b": [["11840.10000", "0.94616386", "1596737144.426461"]], "c": "3569289790"}, "book-100", "XBT/USD"]
[270, {"a": [["11857.20000", "0.00000000", "1596737144.429933"], ["11904.60000", "0.02329731", "1596737116.563077", "r"]], "c": "3875977437"}, "book-100", "XBT/USD"]
[270, {"a": [["11860.80000", "0.00000000", "1596737144.524453"], ["11905.00000", "27.00000000", "1596736856.739074", "r"]], "c": "3592439536"}, "book-100", "XBT/USD"]
[270, {"b": [["11852.60000", "7.76400876", "1596737144.663203"]], "c": "2298842971"}, "book-100", "XBT/USD"]
[270, {"a": [["11861.80000", "0.25000000", "1596737144.684281"]], "c": "3879657064"}, "book-100", "XBT/USD"]
[270, {"b": [["11850.10000", "0.48799636", "1596737144.714398"]], "c": "1353949928"}, "book-100", "XBT/USD"]
[270, {"b": [["11839.30000", "0.68090000", "1596737144.714453"]], "c": "1353949928"}, "book-100", "XBT/USD"]
[271, [["11852.70000", "0.01470000", "1596737144.755628", "b", "l", ""]], "trade", "XBT/USD"]
[270, {"a": [["11852.70000", "0.41476198", "1596737144.755628"]], "c": "2480094660"}, "book-100", "XBT/USD"]
[270, {"a": [["11863.20000", "0.10300000", "1596737144.780712"]], "c": "959755344"}, "book-100", "XBT/USD"]
[270, {"a": [["11860.40000", "0.00000000", "1596737144.780821"], ["11905.00000", "27.00000000", "1596736856.739074", "r"]], "c": "3182102700"}, "book-100", "XBT/USD"]
[270, {"a": [["11858.60000", "0.00000000", "1596737144.791406"], ["11906.40000", "0.47990000", "1596737133.044226", "r"]], "c": "3521899740"}, "book-100", "XBT/USD"]
[270, {"b": [["11822.50000", "0.00000000", "1596737144.837290"], ["11796.00000", "0.17065000", "1596737137.274179", "r"]], "c": "3521899740"}, "book-100", "XBT/USD"]
[270, {"a": [["11863.60000", "1.50000000", "1596737144.918597"]], "c": "313471945"}, "book-100", "XBT/USD"]
[270, {"b": [["11825.00000", "11.10000000", "1596737145.042893"]], "c": "313471945"}, "book-100", "XBT/USD"]
[270, {"a": [["11890.60000", "0.00000000", "1596737145.045555"], ["11907.00000", "0.17065000", "1596737135.727101", "r"]], "c": "313471945"}, "book-100", "XBT/USD"]
[270, {"a": [["11860.90000", "0.04750000", "1596737145.048654"]], "c": "2861238385"}, "book-100", "XBT/USD"]
[270, {"a": [["11861.80000", "0.00000000", "1596737145.095518"], ["11907.00000", "0.17065000", "1596737135.727101", "r"]], "c": "2282950164"}, "book-100", "XBT/USD"]
[270, {"a": [["11867.40000", "0.00000000", "1596737145.097261"], ["11907.60000", "2.21059251", "1596737139.986733", "r"]], "c": "2282950164"}, "book-100", "XBT/USD"]
[270, {"a": [["11886.40000", "1.77465857", "1596737145.113659"]], "c": "2282950164"}, "book-100", "XBT/USD"]
[270, {"a": [["11869.60000", "0.91256441", "1596737145.167118"]], "c": "2282950164"}, "book-100", "XBT/USD"]
[270, {"a": [["11874.70000", "0.00000000", "1596737145.221585"], ["11907.80000", "0.17236827", "1596737139.936859", "r"]], "c": "2282950164"}, "book-100", "XBT/USD"]
[270, {"a": [["11895.50000", "2.33062072", "1596737145.230685"]], "c": "2282950164"}, "book-100", "XBT/USD"]
[270, {"a": [["11860.70000", "0.25000000", "1596737145.275076"]], "c": "1504076062"}, "book-100", "XBT/USD"]
[270, {"a": [["11863.60000", "0.00000000", "1596737145.298718"], ["11907.60000", "2.21059251", "1596737139.986733", "r"]], "c": "1658402983"}, "book-100", "XBT/USD"]
[270, {"a": [["11901.20000", "0.05455260", "1596737145.299909"]], "c": "1658402983"}, "book-100", "XBT/USD"]
[270, {"a": [["11860.30000", "0.00000000", "1596737145.395980"], ["11907.60000", "2.21059251", "1596737139.986733", "r"]], "c": "4281750072"}, "book-100", "XBT/USD"]
[270, {"a": [["11875.20000", "0.32917015", "1596737145.435330"]], "c": "4281750072"}, "book-100", "XBT/USD"]
[270, {"a": [["11860.50000", "0.83570000", "1596737145.454139"]], "c": "1426325368"}, "book-100", "XBT/USD"]
[270, {"a": [["11861.00000", "2.13225049", "1596737145.456338"]], "c": "1980118260"}, "book-100", "XBT/USD"]
[270, {"a": [["11860.20000", "0.00000000", "1596737145.458851"], ["11907.00000", "0.17065000", "1596737135.727101", "r"]], "c": "620973748"}, "book-100", "XBT/USD"]
[270, {"a": [["11864.00000", "0.00000000", "1596737145.523461"], ["11907.60000", "2.21059251", "1596737139.986733", "r"]], "c": "344352433"}, "book-100", "XBT/USD"]
[270, {"a": [["11868.50000", "0.09250000", "1596737145.650435"]], "c": "344352433"}, "book-100", "XBT/USD"]
[270, {"b": [["11848.40000", "0.00000000", "1596737145.744371"], ["11796.00000", "0.17065000", "1596737137.274179", "r"]], "c": "344352433"}, "book-100", "XBT/USD"]
[270, {"b": [["11823.50000", "0.01000000", "1596737145.748808"]], "c": "344352433"}, "book-100", "XBT/USD"]
[270, {"b": [["11836.20000", "1.06150180", "1596737145.770179"]], "c": "344352433"}, "book-100", "XBT/USD"]
[270, {"b": [["11826.70000", "8.88028622", "1596737145.802530"]], "c": "344352433"}, "book-100", "XBT/USD"]
[270, {"a": [["11899.10000", "7.82927162", "1596737145.805987"]], "c": "344352433"}, "book-100", "XBT/USD"]
[270, {"b": [["11838.50000", "4.85956925", "1596737145.806889"]], "c": "344352433"}, "book-100", "XBT/USD"]
[270, {"a": [["11887.20000", "3.09681974", "1596737145.808295"]], "c": "344352433"}, "book-100", "XBT/USD"]
[270, {"a": [["11860.70000", "0.00000000", "1596737145.909885"], ["11907.00000", "0.17065000", "1596737135.727101", "r"]], "c": "2795686748"}, "book-100", "XBT/USD"]
[270, {"a": [["11865.90000", "2.72462971", "1596737146.031724"]], "c": "2795686748"}, "book-100", "XBT/USD"]
[270, {"b": [["11852.60000", "7.26400876", "1596737146.062630"]], "c": "3891893493"}, "book-100", "XBT/USD"]
[270, {"a": [["11859.50000", "0.25000000", "1596737146.113758"]], "c": "2743428966"}, "book-100", "XBT/USD"]
[270, {"a": [["11889.80000", "0.00000000", "1596737146.157889"], ["11907.00000", "0.17065000", "1596737135.727101", "r"]], "c": "2743428966"}, "book-100", "XBT/USD"]
[270, {"b": [["11812.90000", "0.00000000", "1596737146.160736"], ["11796.30000", "10.90540000", "1596736141.718106", "r"]], "c": "2743428966"}, "book-100", "XBT/USD"]
[270, {"b": [["11813.70000", "0.73642765", "1596737146.187307"]], "c": "2743428966"}, "book-100", "XBT/USD"]
[270, {"b": [["11852.40000", "0.42147774", "1596737146.203231"]], "c": "2300084612"}, "book-100", "XBT/USD"]
[270, {"b": [["11840.70000", "0.42148310", "1596737146.203987"]], "c": "2300084612"}, "book-100", "XBT/USD"]
[270, {"b": [["11852.30000", "0.42147774", "1596737146.204382"]], "c": "2811332798"}, "book-100", "XBT/USD"]
[270, {"a": [["11862.20000", "0.63218875", "1596737146.206037"]], "c": "1736140051"}, "book-100", "XBT/USD"]
[270, {"a": [["11864.40000", "1.33146739", "1596737146.206160"]], "c": "1736140051"}, "book-100", "XBT/USD"]
[270, {"a": [["11893.20000", "0.73642765", "1596737146.214248"]], "c": "1736140051"}, "book-100", "XBT/USD"]
[270, {"a": [["11879.70000", "0.96100000", "1596737146.442496"]], "c": "1736140051"}, "book-100", "XBT/USD"]
[270, {"a": [["11865.90000", "1.04962971", "1596737146.452332"]], "c": "1736140051"}, "book-100", "XBT/USD"]
[270, {"b": [["11840.70000", "0.00000000", "1596737146.465924"], ["11799.20000", "23.14040000", "1596736141.974806", "r"]], "c": "1736140051"}, "book-100", "XBT/USD"]
[270, {"a": [["11863.10000", "0.25000000", "1596737146.472628"]], "c": "1370913164"}, "book-100", "XBT/USD"]
[270, {"b": [["11834.70000", "0.72400000", "1596737146.556711"]], "c": "1370913164"}, "book-100", "XBT/USD"]
[270, {"a": [["11866.60000", "0.84291834", "1596737146.601088"]], "c": "1370913164"}, "book-100", "XBT/USD"]
[270, {"b": [["11835.80000", "0.00000000", "1596737146.643855"], ["11799.20000", "23.14040000", "1596736141.974806", "r"]], "c": "1370913164"}, "book-100", "XBT/USD"]
[270, {"b": [["11827.20000", "6.50200425", "1596737146.651992"]], "c": "1370913164"}, "book-100", "XBT/USD"]
[270, {"b": [["11852.60000", "7.76400876", "1596737146.664412"]], "c": "4278008223"}, "book-100", "XBT/USD"]
[270, {"b": [["11823.50000", "0.00000000", "1596737146.741491"], ["11799.20000", "23.14040000", "1596736141.974806", "r"]], "c": "4278008223"}, "book-100", "XBT/USD"]
[270, {"a": [["11859.50000", "0.00000000", "1596737146.758857"], ["11904.60000", "0.02329731", "1596737116.563077", "r"]], "c": "482993254"}, "book-100", "XBT/USD"]
[270, {"b": [["11852.60000", "9.44300876", "1596737146.915148"]], "c": "3767445554"}, "book-100", "XBT/USD"]
[270, {"a": [["11864.40000", "0.69931034", "1596737146.915595"]], "c": "1354076995"}, "book-100", "XBT/USD"]
[270, {"a": [["11865.20000", "1.67900000", "1596737146.916782"]], "c": "1354076995"}, "book-100", "XBT/USD"]
[270, {"a": [["11859.60000", "0.25000000", "1596737146.951380"]], "c": "2869244645"}, "book-100", "XBT/USD"]
[270, {"b": [["11826.00000", "3.29206376", "1596737146.993790"]], "c": "2869244645"}, "book-100", "XBT/USD"]
[270, {"b": [["11839.40000", "0.00000000", "1596737146.998652"], ["11798.60000", "18.30000000", "1596737089.559503", "r"]], "c": "2869244645"}, "book-100", "XBT/USD"]
[270, {"a": [["11859.50000", "0.83570000", "1596737147.007049"]], "c": "214029059"}, "book-100", "XBT/USD"]
[270, {"a": [["11860.50000", "0.00000000", "1596737147.052304"], ["11903.90000", "1.59024654", "1596737096.689627", "r"]], "c": "699203359"}, "book-100", "XBT/USD"]
[270, {"b": [["11852.60000", "8.94300876", "1596737147.171953"]], "c": "56933030"}, "book-100", "XBT/USD"]
[270, {"b": [["11844.50000", "0.04464444", "1596737147.213949"]], "c": "56933030"}, "book-100", "XBT/USD"]
[270, {"b": [["11799.30000", "0.01265539", "1596737147.463086"]], "c": "56933030"}, "book-100", "XBT/USD"]
[270, {"a": [["11879.60000", "0.00438186", "1596737147.463621"]], "c": "56933030"}, "book-100", "XBT/USD"]
[270, {"b": [["11838.60000", "9.50003115", "1596737147.464597"]], "c": "56933030"}, "book-100", "XBT/USD"]
[270, {"b": [["11805.00000", "0.00000000", "1596737147.638479"], ["11799.20000", "23.14040000", "1596736141.974806", "r"]], "c": "56933030"}, "book-100", "XBT/USD"]
[270, {"a": [["11864.40000", "0.00000000", "1596737147.728427"], ["11903.90000", "1.59024654", "1596737096.689627", "r"]], "c": "56933030"}, "book-100", "XBT/USD"]
[270, {"a": [["11865.20000", "0.00000000", "1596737147.755499"], ["11904.00000", "0.17065000", "1596737071.292235", "r"]], "c": "56933030"}, "book-100", "XBT/USD"]
[270, {"a": [["11864.60000", "1.67800000", "1596737147.769458"]], "c": "56933030"}, "book-100", "XBT/USD"]
[270, {"b": [["11852.60000", "9.04300876", "1596737147.790365"]], "c": "320886684"}, "book-100", "XBT/USD"]
[270, {"a": [["11860.90000", "0.74750000", "1596737147.790435"]], "c": "1598957888"}, "book-100", "XBT/USD"]
[270, {"a": [["11873.00000", "0.68610503", "1596737148.235059"]], "c": "1598957888"}, "book-100", "XBT/USD"]
[270, {"a": [["11864.70000", "0.84286968", "1596737148.241418"]], "c": "1598957888"}, "book-100", "XBT/USD"]
[270, {"b": [["11802.00000", "7.67065000", "1596737148.460238"]], "c": "1598957888"}, "book-100", "XBT/USD"]
[270, {"a": [["11863.00000", "0.84281413", "1596737148.483722"]], "c": "3399188765"}, "book-100", "XBT/USD"]
[270, {"a": [["11861.90000", "4.20300000", "1596737148.561790"]], "c": "310876196"}, "book-100", "XBT/USD"]
[270, {"b": [["11852.60000", "8.94300876", "1596737148.613101"]], "c": "46363934"}, "book-100", "XBT/USD"]
[270, {"b": [["11852.60000", "8.86300876", "1596737148.722061"]], "c": "1715517470"}, "book-100", "XBT/USD"]
[270, {"a": [["11866.40000", "0.94075000", "1596737148.804462"]], "c": "1715517470"}, "book-100", "XBT/USD"]
[270, {"a": [["11873.00000", "0.00000000", "1596737148.863751"], ["11901.80000", "0.75800000", "1596737130.968842", "r"]], "c": "1715517470"}, "book-100", "XBT/USD"]
[270, {"b": [["11826.00000", "3.28206376", "1596737148.869012"]], "c": "1715517470"}, "book-100", "XBT/USD"]
[270, {"a": [["11859.60000", "0.00000000", "1596737148.935357"], ["11902.00000", "0.22739000", "1596736764.397858", "r"]], "c": "2433705027"}, "book-100", "XBT/USD"]
[270, {"a": [["11895.00000", "0.42065000", "1596737148.942463"]], "c": "2433705027"}, "book-100", "XBT/USD"]
[270, {"a": [["11859.50000", "0.00000000", "1596737149.044816"], ["11902.20000", "1.58369712", "1596737116.990726", "r"]], "c": "2914380755"}, "book-100", "XBT/USD"]
[270, {"a": [["11858.30000", "0.39500000", "1596737149.089216"]], "c": "42848570"}, "book-100", "XBT/USD"]
[270, {"b": [["11826.50000", "0.01000000", "1596737149.098310"]], "c": "42848570"}, "book-100", "XBT/USD"]
[270, {"a": [["11860.50000", "0.83570000", "1596737149.114026"]], "c": "526313194"}, "book-100", "XBT/USD"]
[270, {"a": [["11860.20000", "0.08436932", "1596737149.201054"]], "c": "3686135996"}, "book-100", "XBT/USD"]
[270, {"a": [["11858.20000", "0.83570000", "1596737149.204103"]], "c": "3901981929"}, "book-100", "XBT/USD"]
[270, {"a": [["11860.50000", "0.00000000", "1596737149.209349"], ["11901.50000", "3.26167975", "1596737133.218332", "r"]], "c": "4123698659"}, "book-100", "XBT/USD"]
[270, {"a": [["11871.50000", "0.96249122", "1596737149.247113"]], "c": "4123698659"}, "book-100", "XBT/USD"]
[270, {"a": [["11862.20000", "0.00000000", "1596737149.300151"], ["11901.80000", "0.75800000", "1596737130.968842", "r"]], "c": "2030038518"}, "book-100", "XBT/USD"]
[270, {"a": [["11858.60000", "0.25000000", "1596737149.317431"]], "c": "4144128451"}, "book-100", "XBT/USD"]
[270, {"a": [["11858.60000", "0.88232631", "1596737149.351895"]], "c": "3366129348"}, "book-100", "XBT/USD"]
[270, {"b": [["11840.50000", "0.42149237", "1596737149.352958"]], "c": "3366129348"}, "book-100", "XBT/USD"]
[270, {"a": [["11859.80000", "0.63227384", "1596737149.353528"]], "c": "3599550874"}, "book-100", "XBT/USD"]
[270, {"b": [["11852.40000", "0.43614236", "1596737149.534467"]], "c": "2750056787"}, "book-100", "XBT/USD"]
[270, {"b": [["11852.60000", "8.93633188", "1596737149.598586"]], "c": "3291071171"}, "book-100", "XBT/USD"]
[270, {"a": [["11889.10000", "0.00000000", "1596737149.619541"], ["11901.50000", "3.26167975", "1596737133.218332", "r"]], "c": "3291071171"}, "book-100", "XBT/USD"]
[270, {"a": [["11868.20000", "0.07332312", "1596737149.660505"]], "c": "3291071171"}, "book-100", "XBT/USD"]
[270, {"b": [["11852.60000", "9.11230737", "1596737149.665433"]], "c": "1047795165"}, "book-100", "XBT/USD"]
[270, {"a": [["11869.70000", "0.00015367", "1596737149.696563"]], "c": "1047795165"}, "book-100", "XBT/USD"]
[270, {"a": [["11867.60000", "0.01466462", "1596737149.699604"]], "c": "1047795165"}, "book-100", "XBT/USD"]
[270, {"a": [["11868.50000", "0.26847549", "1596737149.727317"]], "c": "1047795165"}, "book-100", "XBT/USD"]
[270, {"a": [["11858.30000", "0.00000000", "1596737149.869065"], ["11901.40000", "1.90492467", "1596737138.167457", "r"]], "c": "3955658483"}, "book-100", "XBT/USD"]
[270, {"a": [["11858.10000", "0.23000000", "1596737149.882250"]], "c": "1775671647"}, "book-100", "XBT/USD"]
[270, {"a": [["11858.50000", "0.83570000", "1596737149.927752"]], "c": "156339738"}, "book-100", "XBT/USD"]
[270, {"a": [["11859.20000", "0.17947000", "1596737149.933561"]], "c": "2852094406"}, "book-100", "XBT/USD"]
[270, {"a": [["11858.20000", "0.00000000", "1596737149.933880"], ["11901.00000", "0.17065000", "1596737120.047779", "r"]], "c": "1078697635"}, "book-100", "XBT/USD"]
[270, {"a": [["11869.60000", "0.69350441", "1596737149.934133"]], "c": "1078697635"}, "book-100", "XBT/USD"]
[270, {"b": [["11852.60000", "8.71230737", "1596737150.000729"]], "c": "2057549293"}, "book-100", "XBT/USD"]
[270, {"a": [["11861.90000", "0.00000000", "1596737150.005362"], ["11901.20000", "0.05455260", "1596737145.299909", "r"]], "c": "2057549293"}, "book-100", "XBT/USD"]
[270, {"b": [["11852.60000", "8.61230737", "1596737150.011134"]], "c": "4016332157"}, "book-100", "XBT/USD"]
[270, {"a": [["11858.00000", "0.83570000", "1596737150.029886"]], "c": "2538714815"}, "book-100", "XBT/USD"]
[270, {"a": [["11869.50000", "0.00000000", "1596737150.065567"], ["11901.20000", "0.05455260", "1596737145.299909", "r"]], "c": "2538714815"}, "book-100", "XBT/USD"]
[270, {"a": [["11858.50000", "0.00000000", "1596737150.070458"], ["11901.40000", "1.90492467", "1596737138.167457", "r"]], "c": "3987836074"}, "book-100", "XBT/USD"]
[270, {"a": [["11885.90000", "2.18169278", "1596737150.205152"]], "c": "3987836074"}, "book-100", "XBT/USD"]
[270, {"a": [["11860.90000", "0.04750000", "1596737150.297085"]], "c": "2855332646"}, "book-100", "XBT/USD"]
[270, {"b": [["11820.90000", "0.00000000", "1596737150.326508"], ["11799.30000", "0.01265539", "1596737147.463086", "r"]], "c": "2855332646"}, "book-100", "XBT/USD"]
[270, {"a": [["11860.50000", "4.20800000", "1596737150.331123"]], "c": "3279645908"}, "book-100", "XBT/USD"]
[270, {"b": [["11848.40000", "0.09621094", "1596737150.364970"]], "c": "3279645908"}, "book-100", "XBT/USD"]
[270, {"b": [["11838.60000", "9.49579788", "1596737150.382261"]], "c": "3279645908"}, "book-100", "XBT/USD"]
[270, {"a": [["11873.10000", "0.00000000", "1596737150.403287"], ["11901.20000", "0.05455260", "1596737145.299909", "r"]], "c": "3279645908"}, "book-100", "XBT/USD"]
[270, {"a": [["11857.20000", "0.09621094", "1596737150.407432"]], "c": "117282188"}, "book-100", "XBT/USD"]
[270, {"a": [["11897.80000", "1.58935366", "1596737150.426450"]], "c": "117282188"}, "book-100", "XBT/USD"]
[270, {"b": [["11827.30000", "5.16704837", "1596737150.481385"]], "c": "117282188"}, "book-100", "XBT/USD"]
[270, {"b": [["11852.60000", "8.69230737", "1596737150.484804"]], "c": "1963921230"}, "book-100", "XBT/USD"]
[270, {"b": [["11838.50000", "4.86380639", "1596737150.566446"]], "c": "1963921230"}, "book-100", "XBT/USD"]
[270, {"a": [["11859.70000", "0.17947000", "1596737150.589369"]], "c": "4122804538"}, "book-100", "XBT/USD"]
[270, {"a": [["11859.10000", "0.17947000", "1596737150.728043"]], "c": "3374451414"}, "book-100", "XBT/USD"]
[270, {"a": [["11859.10000", "0.00000000", "1596737150.832464"], ["11900.30000", "0.73381520", "1596737116.696146", "r"]], "c": "4122804538"}, "book-100", "XBT/USD"]
[270, {"a": [["11859.70000", "0.00000000", "1596737150.951009"], ["11900.70000", "0.00500000", "1596736976.571243", "r"]], "c": "1963921230"}, "book-100", "XBT/USD"]
[270, {"a": [["11878.10000", "5.72429323", "1596737150.959056"]], "c": "1963921230"}, "book-100", "XBT/USD"]
[270, {"a": [["11859.20000", "0.00000000", "1596737150.963445"], ["11901.00000", "0.17065000", "1596737120.047779", "r"]], "c": "2740916084"}, "book-100", "XBT/USD"]
[270, {"b": [["11838.50000", "4.85956925", "1596737150.980333"]], "c": "2740916084"}, "book-100", "XBT/USD"]
[270, {"b": [["11852.60000", "8.73630047", "1596737151.074250"]], "c": "4125105582"}, "book-100", "XBT/USD"]
[270, {"b": [["11852.60000", "8.78880047", "1596737151.084366"]], "c": "3659392468"}, "book-100", "XBT/USD"]
[270, {"a": [["11858.60000", "0.63232631", "1596737151.090134"]], "c": "3745199562"}, "book-100", "XBT/USD"]
[270, {"a": [["11860.50000", "4.38747000", "1596737151.108353"]], "c": "4288787965"}, "book-100", "XBT/USD"]
[270, {"a": [["11859.70000", "0.17947000", "1596737151.137163"]], "c": "2743151067"}, "book-100", "XBT/USD"]
[270, {"a": [["11859.10000", "0.17922000", "1596737151.237436"]], "c": "1191811127"}, "book-100", "XBT/USD"]
[270, {"a": [["11881.70000", "0.00000000", "1596737151.241022"], ["11900.70000", "0.00500000", "1596736976.571243", "r"]], "c": "1191811127"}, "book-100", "XBT/USD"]
[270, {"a": [["11860.90000", "0.33149999", "1596737151.308411"]], "c": "1191811127"}, "book-100", "XBT/USD"]
[270, {"a": [["11859.30000", "0.25000000", "1596737151.319573"]], "c": "1582608752"}, "book-100", "XBT/USD"]
[270, {"b": [["11852.60000", "8.70880047", "1596737151.344085"]], "c": "765864882"}, "book-100", "XBT/USD"]
[270, {"a": [["11870.20000", "0.04399454", "1596737151.382457"]], "c": "765864882"}, "book-100", "XBT/USD"]
[270, {"b": [["11852.60000", "8.84078260", "1596737151.662085"]], "c": "3562957698"}, "book-100", "XBT/USD"]
[270, {"a": [["11859.30000", "0.00000000", "1596737151.728060"], ["11900.30000", "0.73381520", "1596737116.696146", "r"]], "c": "3439542981"}, "book-100", "XBT/USD"]
[270, {"a": [["11857.90000", "0.40500000", "1596737151.732710"]], "c": "3291866514"}, "book-100", "XBT/USD"]
[270, {"a": [["11858.80000", "0.25000000", "1596737151.893771"]], "c": "911109620"}, "book-100", "XBT/USD"]
[270, {"a": [["11870.80000", "0.13197522", "1596737151.991548"]], "c": "911109620"}, "book-100", "XBT/USD"]
[270, {"b": [["11852.60000", "8.78828260", "1596737152.032415"]], "c": "1478794909"}, "book-100", "XBT/USD"]
[270, {"a": [["11871.50000", "0.31952620", "1596737152.036722"]], "c": "1478794909"}, "book-100", "XBT/USD"]
[270, {"a": [["11879.90000", "0.01000000", "1596737152.054761"]], "c": "1478794909"}, "book-100", "XBT/USD"]
[270, {"a": [["11858.10000", "0.00000000", "1596737152.088863"], ["11899.90000", "7.61000000", "1596737079.466913", "r"]], "c": "666507133"}, "book-100", "XBT/USD"]
[270, {"a": [["11857.80000", "0.83570000", "1596737152.103163"]], "c": "1372538835"}, "book-100", "XBT/USD"]
[270, {"a": [["11879.60000", "0.49960494", "1596737152.268194"]], "c": "1372538835"}, "book-100", "XBT/USD"]
[270, {"a": [["11870.30000", "0.65798488", "1596737152.376689"]], "c": "1372538835"}, "book-100", "XBT/USD"]
[270, {"a": [["11879.60000", "0.00438186", "1596737152.453344"]], "c": "1372538835"}, "book-100", "XBT/USD"]
[270, {"a": [["11858.00000", "0.00000000", "1596737152.519255"], ["11899.10000", "7.82927162", "1596737145.805987", "r"]], "c": "3375253743"}, "book-100", "XBT/USD"]
[270, {"a": [["11857.10000", "0.83570000", "1596737152.570632"]], "c": "4035890401"}, "book-100", "XBT/USD"]
[270, {"a": [["11857.80000", "0.00000000", "1596737152.578353"], ["11899.10000", "7.82927162", "1596737145.805987", "r"]], "c": "3952468836"}, "book-100", "XBT/USD"]
[270, {"b": [["11852.60000", "8.88828260", "1596737152.620695"]], "c": "3241747728"}, "book-100", "XBT/USD"]
[270, {"a": [["11870.30000", "0.00000000", "1596737152.637191"], ["11899.90000", "7.61000000", "1596737079.466913", "r"]], "c": "3241747728"}, "book-100", "XBT/USD"]
[270, {"a": [["11859.10000", "0.00000000", "1596737152.683883"], ["11900.00000", "12.71653131", "1596737075.897027", "r"]], "c": "424513043"}, "book-100", "XBT/USD"]
[270, {"a": [["11859.70000", "0.00000000", "1596737152.689017"], ["11900.30000", "0.73381520", "1596737116.696146", "r"]], "c": "2451913204"}, "book-100", "XBT/USD"]
[270, {"b": [["11852.60000", "8.78828260", "1596737152.732829"]], "c": "3096051584"}, "book-100", "XBT/USD"]
[270, {"a": [["11893.20000", "0.00000000", "1596737152.819998"], ["11900.70000", "0.00500000", "1596736976.571243", "r"]], "c": "3096051584"}, "book-100", "XBT/USD"]
[270, {"a": [["11879.60000", "0.51676565", "1596737152.941055"]], "c": "3096051584"}, "book-100", "XBT/USD"]
[270, {"a": [["11870.20000", "0.70878210", "1596737152.945306"]], "c": "3096051584"}, "book-100", "XBT/USD"]
[270, {"a": [["11860.20000", "0.00000000", "1596737153.261092"], ["11901.00000", "0.17065000", "1596737120.047779", "r"]], "c": "461823901"}, "book-100", "XBT/USD"]
[270, {"a": [["11893.00000", "0.73641207", "1596737153.295261"]], "c": "461823901"}, "book-100", "XBT/USD"]
[270, {"a": [["11886.40000", "1.27465857", "1596737153.318312"]], "c": "461823901"}, "book-100", "XBT/USD"]
[270, {"a": [["11857.80000", "0.83570000", "1596737153.617146"]], "c": "2546045621"}, "book-100", "XBT/USD"]
[270, {"a": [["11857.10000", "0.00000000", "1596737153.619436"], ["11900.70000", "0.00500000", "1596736976.571243", "r"]], "c": "2197145286"}, "book-100", "XBT/USD"]
[270, {"a": [["11857.10000", "0.83570000", "1596737154.022879"]], "c": "2546045621"}, "book-100", "XBT/USD"]
[270, {"a": [["11857.80000", "0.00000000", "1596737154.069185"], ["11900.70000", "0.00500000", "1596736976.571243", "r"]], "c": "461823901"}, "book-100", "XBT/USD"]
[270, {"a": [["11870.20000", "0.04399454", "1596737154.100534"]], "c": "461823901"}, "book-100", "XBT/USD"]
[270, {"a": [["11879.60000", "0.51238379", "1596737154.355949"]], "c": "461823901"}, "book-100", "XBT/USD"]
[270, {"b": [["11838.50000", "4.86379683", "1596737154.357617"]], "c": "461823901"}, "book-100", "XBT/USD"]
[270, {"a": [["11887.10000", "0.50000000", "1596737154.493022"]], "c": "461823901"}, "book-100", "XBT/USD"]
[270, {"a": [["11870.10000", "0.95567769", "1596737154.493274"]], "c": "461823901"}, "book-100", "XBT/USD"]
[270, {"a": [["11879.50000", "0.00438186", "1596737154.545227"]], "c": "461823901"}, "book-100", "XBT/USD"]
[270, {"a": [["11878.10000", "0.10902130", "1596737154.731077"]], "c": "461823901"}, "book-100", "XBT/USD"]
[270, {"a": [["11858.20000", "0.19022000", "1596737154.739063"]], "c": "2657013447"}, "book-100", "XBT/USD"]
[270, {"a": [["11860.40000", "0.70000000", "1596737154.791370"]], "c": "3309942030"}, "book-100", "XBT/USD"]
[270, {"b": [["11852.60000", "8.61230711", "1596737154.797127"]], "c": "1557631573"}, "book-100", "XBT/USD"]
[270, {"a": [["11873.00000", "5.61574487", "1596737154.811331"]], "c": "1557631573"}, "book-100", "XBT/USD"]
[270, {"a": [["11860.40000", "0.00000000", "1596737154.843224"], ["11899.10000", "7.82927162", "1596737145.805987", "r"]], "c": "130083228"}, "book-100", "XBT/USD"]
[270, {"a": [["11858.20000", "0.00000000", "1596737154.920712"], ["11899.90000", "7.61000000", "1596737079.466913", "r"]], "c": "2182674630"}, "book-100", "XBT/USD"]
[270, {"a": [["11879.60000", "0.00000000", "1596737155.023407"], ["11900.00000", "12.71653131", "1596737075.897027", "r"]], "c": "2182674630"}, "book-100", "XBT/USD"]
[270, {"b": [["11852.60000", "8.78828260", "1596737155.045559"]], "c": "461823901"}, "book-100", "XBT/USD"]
[270, {"a": [["11858.50000", "0.19022000", "1596737155.107433"]], "c": "927954631"}, "book-100", "XBT/USD"]
[270, {"a": [["11860.90000", "0.28399999", "1596737155.144720"]], "c": "927954631"}, "book-100", "XBT/USD"]
[270, {"a": [["11879.60000", "0.52561289", "1596737155.203245"]], "c": "927954631"}, "book-100", "XBT/USD"]
[270, {"b": [["11847.60000", "0.82051000", "1596737155.246669"]], "c": "927954631"}, "book-100", "XBT/USD"]
[270, {"b": [["11852.60000", "8.61230711", "1596737155.254136"]], "c": "2932953500"}, "book-100", "XBT/USD"]
[270, {"a": [["11874.10000", "0.30000000", "1596737155.268655"]], "c": "2932953500"}, "book-100", "XBT/USD"]
[270, {"a": [["11861.40000", "0.84318537", "1596737155.322057"]], "c": "2932953500"}, "book-100", "XBT/USD"]
[270, {"a": [["11879.50000", "0.00000000", "1596737155.345979"], ["11899.10000", "7.82927162", "1596737145.805987", "r"]], "c": "2932953500"}, "book-100", "XBT/USD"]
[270, {"a": [["11858.20000", "0.19018000", "1596737155.353264"]], "c": "3769047042"}, "book-100", "XBT/USD"]
[270, {"a": [["11859.70000", "0.04750000", "1596737155.375151"]], "c": "2867444021"}, "book-100", "XBT/USD"]
[270, {"a": [["11863.60000", "0.81268000", "1596737155.456699"]], "c": "2867444021"}, "book-100", "XBT/USD"]
[270, {"b": [["11850.00000", "0.00000000", "1596737155.457200"], ["11800.80000", "1.51500000", "1596737133.991629", "r"]], "c": "3019955391"}, "book-100", "XBT/USD"]
[270, {"a": [["11879.60000", "0.00000000", "1596737155.618364"], ["11898.70000", "0.01000000", "1596737133.560066", "r"]], "c": "3019955391"}, "book-100", "XBT/USD"]
[270, {"b": [["11851.20000", "0.17597549", "1596737155.641146"]], "c": "3883433279"}, "book-100", "XBT/USD"]
[270, {"a": [["11870.10000", "0.27100000", "1596737155.664055"]], "c": "3883433279"}, "book-100", "XBT/USD"]
[270, {"a": [["11868.50000", "0.17597549", "1596737155.739499"]], "c": "3883433279"}, "book-100", "XBT/USD"]
[270, {"a": [["11879.60000", "0.52748342", "1596737155.801902"]], "c": "3883433279"}, "book-100", "XBT/USD"]
[270, {"a": [["11869.60000", "0.00000000", "1596737155.946619"], ["11898.70000", "0.01000000", "1596737133.560066", "r"]], "c": "3883433279"}, "book-100", "XBT/USD"]
[270, {"a": [["11858.50000", "0.00000000", "1596737156.037163"], ["11899.00000", "2.81849664", "1596737063.692951", "r"]], "c": "1841026608"}, "book-100", "XBT/USD"]
[270, {"a": [["11858.20000", "0.00000000", "1596737156.042638"], ["11899.10000", "7.82927162", "1596737145.805987", "r"]], "c": "4086221364"}, "book-100", "XBT/USD"]
[270, {"a": [["11890.50000", "0.09250000", "1596737156.080002"]], "c": "4086221364"}, "book-100", "XBT/USD"]
[270, {"a": [["11868.90000", "0.63131654", "1596737156.080974"]], "c": "4086221364"}, "book-100", "XBT/USD"]
[270, {"a": [["11866.50000", "0.69359485", "1596737156.151635"]], "c": "4086221364"}, "book-100", "XBT/USD"]
[270, {"a": [["11868.90000", "0.00000000", "1596737156.200253"], ["11898.70000", "0.01000000", "1596737133.560066", "r"]], "c": "4086221364"}, "book-100", "XBT/USD"]
[270, {"a": [["11861.00000", "1.50000000", "1596737156.268242"]], "c": "4086221364"}, "book-100", "XBT/USD"]
[270, {"a": [["11861.00000", "0.00000000", "1596737156.290880"], ["11899.00000", "2.81849664", "1596737063.692951", "r"]], "c": "4086221364"}, "book-100", "XBT/USD"]
[270, {"a": [["11857.80000", "0.83570000", "1596737156.344125"]], "c": "3452620330"}, "book-100", "XBT/USD"]
[270, {"a": [["11857.10000", "0.00000000", "1596737156.351803"], ["11899.00000", "2.81849664", "1596737063.692951", "r"]], "c": "2311465783"}, "book-100", "XBT/USD"]
[270, {"a": [["11859.90000", "1.50000000", "1596737156.435964"]], "c": "103653388"}, "book-100", "XBT/USD"]
[270, {"b": [["11851.20000", "0.00000000", "1596737156.444352"], ["11800.80000", "1.51500000", "1596737133.991629", "r"]], "c": "1431634316"}, "book-100", "XBT/USD"]
[270, {"a": [["11857.80000", "0.00000000", "1596737156.532438"], ["11899.00000", "2.81849664", "1596737063.692951", "r"]], "c": "492264836"}, "book-100", "XBT/USD"]
[270, {"a": [["11857.10000", "0.83570000", "1596737156.534163"]], "c": "3425048791"}, "book-100", "XBT/USD"]
[270, {"a": [["11864.60000", "0.00000000", "1596737156.581727"], ["11899.00000", "2.81849664", "1596737063.692951", "r"]], "c": "3425048791"}, "book-100", "XBT/USD"]
[270, {"a": [["11861.20000", "1.68400000", "1596737156.599720"]], "c": "3425048791"}, "book-100", "XBT/USD"]
[270, {"b": [["11849.60000", "0.17597549", "1596737156.651548"]], "c": "3053556835"}, "book-100", "XBT/USD"]
[270, {"a": [["11868.60000", "0.67665645", "1596737156.676731"]], "c": "3053556835"}, "book-100", "XBT/USD"]
[270, {"a": [["11867.60000", "0.00000000", "1596737156.707583"], ["11899.00000", "2.81849664", "1596737063.692951", "r"]], "c": "3053556835"}, "book-100", "XBT/USD"]
[270, {"a": [["11868.20000", "0.00000000", "1596737156.771920"], ["11899.10000", "7.82927162", "1596737145.805987", "r"]], "c": "3053556835"}, "book-100", "XBT/USD"]
[270, {"b": [["11848.00000", "0.00000000", "1596737156.785534"], ["11800.80000", "1.51500000", "1596737133.991629", "r"]], "c": "3053556835"}, "book-100", "XBT/USD"]
[270, {"a": [["11868.50000", "0.00000000", "1596737156.835431"], ["11899.90000", "7.61000000", "1596737079.466913", "r"]], "c": "3053556835"}, "book-100", "XBT/USD"]
[270, {"a": [["11865.60000", "1.13165779", "1596737156.897991"]], "c": "3053556835"}, "book-100", "XBT/USD"]
[270, {"b": [["11852.60000", "8.48032498", "1596737156.965319"]], "c": "966365017"}, "book-100", "XBT/USD"]
[270, {"b": [["11852.60000", "8.43633188", "1596737156.965790"]], "c": "1315958548"}, "book-100", "XBT/USD"]
[270, {"a": [["11866.10000", "0.07332312", "1596737156.968066"]], "c": "1315958548"}, "book-100", "XBT/USD"]
[270, {"b": [["11852.30000", "0.00000000", "1596737156.971751"], ["11800.00000", "17.03324285", "1596736993.942623", "r"]], "c": "1551641775"}, "book-100", "XBT/USD"]
[270, {"b": [["11850.20000", "0.00000000", "1596737156.987712"], ["11799.30000", "0.01265539", "1596737147.463086", "r"]], "c": "80935849"}, "book-100", "XBT/USD"]
[270, {"b": [["11846.70000", "0.00000000", "1596737156.988887"], ["11799.20000", "23.14040000", "1596736141.974806", "r"]], "c": "80935849"}, "book-100", "XBT/USD"]
[270, {"b": [["11848.40000", "0.00000000", "1596737157.006448"], ["11799.00000", "0.17065000", "1596737154.640974", "r"]], "c": "80935849"}, "book-100", "XBT/USD"]
[270, {"a": [["11857.80000", "0.83570000", "1596737157.023074"]], "c": "125930175"}, "book-100", "XBT/USD"]
[270, {"b": [["11845.80000", "0.00000000", "1596737157.023471"], ["11798.60000", "18.30000000", "1596737089.559503", "r"]], "c": "125930175"}, "book-100", "XBT/USD"]
[270, {"a": [["11857.10000", "0.00000000", "1596737157.030146"], ["11899.10000", "7.82927162", "1596737145.805987", "r"]], "c": "2124028586"}, "book-100", "XBT/USD"]
[270, {"a": [["11866.50000", "0.86957034", "1596737157.035455"]], "c": "2124028586"}, "book-100", "XBT/USD"]
[270, {"a": [["11868.30000", "2.44146958", "1596737157.069916"]], "c": "2124028586"}, "book-100", "XBT/USD"]
[270, {"b": [["11852.50000", "0.00000000", "1596737157.096712"], ["11797.90000", "6.30000000", "1596737122.404410", "r"]], "c": "1349966572"}, "book-100", "XBT/USD"]
[270, {"a": [["11859.80000", "0.00000000", "1596737157.096777"], ["11899.10000", "7.82927162", "1596737145.805987", "r"]], "c": "208212392"}, "book-100", "XBT/USD"]
[270, {"a": [["11858.80000", "0.00000000", "1596737157.111111"], ["11899.90000", "7.61000000", "1596737079.466913", "r"]], "c": "1090675118"}, "book-100", "XBT/USD"]
[270, {"b": [["11848.10000", "0.42163776", "1596737157.111230"]], "c": "1090675118"}, "book-100", "XBT/USD"]
[270, {"a": [["11858.00000", "0.10100000", "1596737157.113005"]], "c": "4020523533"}, "book-100", "XBT/USD"]
[270, {"a": [["11863.00000", "0.00000000", "1596737157.123625"], ["11899.90000", "7.61000000", "1596737079.466913", "r"]], "c": "4020523533"}, "book-100", "XBT/USD"]
[270, {"a": [["11895.50000", "0.00000000", "1596737157.127214"], ["11900.00000", "12.71653131", "1596737075.897027", "r"]], "c": "4020523533"}, "book-100", "XBT/USD"]
[270, {"b": [["11852.60000", "8.36300876", "1596737157.148530"]], "c": "957900391"}, "book-100", "XBT/USD"]
[270, {"b": [["11850.20000", "0.04400274", "1596737157.164776"]], "c": "2289644160"}, "book-100", "XBT/USD"]
[270, {"b": [["11847.30000", "0.13200821", "1596737157.167104"]], "c": "2289644160"}, "book-100", "XBT/USD"]
[270, {"b": [["11852.40000", "0.01466462", "1596737157.198498"]], "c": "2854220019"}, "book-100", "XBT/USD"]
[270, {"a": [["11871.60000", "0.00000000", "1596737157.204581"], ["11900.30000", "0.73381520", "1596737116.696146", "r"]], "c": "2854220019"}, "book-100", "XBT/USD"]
[270, {"b": [["11852.60000", "6.68400876", "1596737157.259742"]], "c": "348067595"}, "book-100", "XBT/USD"]
[270, {"b": [["11842.80000", "0.20472227", "1596737157.301238"]], "c": "348067595"}, "book-100", "XBT/USD"]
[270, {"a": [["11856.70000", "0.25000000", "1596737157.301316"]], "c": "1678955389"}, "book-100", "XBT/USD"]
[270, {"a": [["11879.60000", "0.00000000", "1596737157.311740"], ["11900.30000", "0.73381520", "1596737116.696146", "r"]], "c": "1678955389"}, "book-100", "XBT/USD"]
[270, {"a": [["11878.10000", "0.56767424", "1596737157.312652"]], "c": "1678955389"}, "book-100", "XBT/USD"]
[270, {"b": [["11845.20000", "0.69330985", "1596737157.346697"]], "c": "1678955389"}, "book-100", "XBT/USD"]
[270, {"b": [["11848.60000", "0.33005281", "1596737157.349042"]], "c": "2559448902"}, "book-100", "XBT/USD"]
[270, {"a": [["11860.60000", "0.94381975", "1596737157.362573"]], "c": "2559448902"}, "book-100", "XBT/USD"]
[270, {"b": [["11851.40000", "0.07332312", "1596737157.364363"]], "c": "1924557279"}, "book-100", "XBT/USD"]
[270, {"a": [["11852.70000", "2.41476198", "1596737157.368990"]], "c": "897489651"}, "book-100", "XBT/USD"]
[270, {"a": [["11860.50000", "0.17947000", "1596737157.380178"]], "c": "427102766"}, "book-100", "XBT/USD"]
[270, {"b": [["11846.30000", "0.00000000", "1596737157.400746"], ["11800.00000", "17.03324285", "1596736993.942623", "r"]], "c": "427102766"}, "book-100", "XBT/USD"]
[270, {"a": [["11858.60000", "4.84132631", "1596737157.400827"]], "c": "477599026"}, "book-100", "XBT/USD"]
[270, {"b": [["11850.20000", "0.00000000", "1596737157.454932"], ["11799.30000", "0.01265539", "1596737147.463086", "r"]], "c": "496898902"}, "book-100", "XBT/USD"]
[270, {"a": [["11857.70000", "0.70000000", "1596737157.455143"]], "c": "3144280686"}, "book-100", "XBT/USD"]
[270, {"a": [["11857.90000", "0.00000000", "1596737157.468779"], ["11900.30000", "0.73381520", "1596737116.696146", "r"]], "c": "825449161"}, "book-100", "XBT/USD"]
[270, {"a": [["11890.60000", "2.15353762", "1596737157.492279"]], "c": "825449161"}, "book-100", "XBT/USD"]
[270, {"a": [["11852.70000", "0.41476198", "1596737157.507637"]], "c": "61669081"}, "book-100", "XBT/USD"]
[270, {"a": [["11856.60000", "0.83570000", "1596737157.522263"]], "c": "3315936752"}, "book-100", "XBT/USD"]
[270, {"a": [["11857.80000", "0.00000000", "1596737157.529184"], ["11900.00000", "12.71653131", "1596737075.897027", "r"]], "c": "3301485019"}, "book-100", "XBT/USD"]
[270, {"b": [["11847.60000", "0.00000000", "1596737157.567977"], ["11799.20000", "23.14040000", "1596736141.974806", "r"]], "c": "3301485019"}, "book-100", "XBT/USD"]
[270, {"a": [["11857.70000", "0.00000000", "1596737157.572413"], ["11900.30000", "0.73381520", "1596737116.696146", "r"]], "c": "3592925104"}, "book-100", "XBT/USD"]
[270, {"a": [["11860.50000", "0.99918000", "1596737157.574888"]], "c": "1167569873"}, "book-100", "XBT/USD"]
[270, {"b": [["11844.50000", "0.86435444", "1596737157.575837"]], "c": "1167569873"}, "book-100", "XBT/USD"]
[270, {"b": [["11849.80000", "0.04400089", "1596737157.666066"]], "c": "4259122232"}, "book-100", "XBT/USD"]
[270, {"b": [["11844.20000", "0.10935438", "1596737157.692103"]], "c": "4259122232"}, "book-100", "XBT/USD"]
[270, {"b": [["11802.00000", "7.50000000", "1596737157.927162"]], "c": "4259122232"}, "book-100", "XBT/USD"]
[270, {"a": [["11868.90000", "6.30000000", "1596737158.071149"]], "c": "4259122232"}, "book-100", "XBT/USD"]
[270, {"a": [["11872.90000", "0.38000000", "1596737158.099554"]], "c": "4259122232"}, "book-100", "XBT/USD"]
[270, {"a": [["11855.90000", "0.63247646", "1596737158.155908"]], "c": "2573780185"}, "book-100", "XBT/USD"]
[270, {"a": [["11857.30000", "0.63239743", "1596737158.156062"]], "c": "3477714048"}, "book-100", "XBT/USD"]
[270, {"b": [["11835.90000", "0.42165097", "1596737158.157160"]], "c": "3477714048"}, "book-100", "XBT/USD"]
[270, {"b": [["11836.90000", "0.42162124", "1596737158.157325"]], "c": "3477714048"}, "book-100", "XBT/USD"]
[270, {"a": [["11860.80000", "0.84332234", "1596737158.223197"]], "c": "3477714048"}, "book-100", "XBT/USD"]
[270, {"a": [["11868.60000", "0.04440539", "1596737158.270741"]], "c": "3477714048"}, "book-100", "XBT/USD"]
[270, {"a": [["11859.90000", "0.00000000", "1596737158.295926"], ["11899.10000", "7.82927162", "1596737145.805987", "r"]], "c": "4273245806"}, "book-100", "XBT/USD"]
[270, {"b": [["11852.60000", "2.47800876", "1596737158.372369"]], "c": "328549872"}, "book-100", "XBT/USD"]
[270, {"a": [["11870.20000", "0.00000000", "1596737158.505384"], ["11899.90000", "7.61000000", "1596737079.466913", "r"]], "c": "328549872"}, "book-100", "XBT/USD"]
[270, {"a": [["11867.00000", "0.00000000", "1596737158.587711"], ["11900.00000", "12.71653131", "1596737075.897027", "r"]], "c": "328549872"}, "book-100", "XBT/USD"]
[270, {"b": [["11848.20000", "2.10188250", "1596737158.603213"]], "c": "328549872"}, "book-100", "XBT/USD"]
[270, {"b": [["11844.40000", "0.00000000", "1596737158.653466"], ["11801.80000", "3.19470719", "1596736911.648608", "r"]], "c": "328549872"}, "book-100", "XBT/USD"]
[270, {"b": [["11848.60000", "0.00000000", "1596737158.655844"], ["11800.80000", "1.51500000", "1596737133.991629", "r"]], "c": "328549872"}, "book-100", "XBT/USD"]
[270, {"b": [["11835.90000", "0.00000000", "1596737158.686124"], ["11800.00000", "17.03324285", "1596736993.942623", "r"]], "c": "328549872"}, "book-100", "XBT/USD"]
[270, {"a": [["11866.90000", "0.88707798", "1596737158.692018"]], "c": "328549872"}, "book-100", "XBT/USD"]
[270, {"b": [["11851.60000", "0.00000000", "1596737158.736813"], ["11799.30000", "0.01265539", "1596737147.463086", "r"]], "c": "1048772642"}, "book-100", "XBT/USD"]
[270, {"b": [["11838.50000", "4.85956925", "1596737158.766329"]], "c": "1048772642"}, "book-100", "XBT/USD"]
[270, {"b": [["11799.30000", "0.00000000", "1596737158.766390"], ["11799.20000", "23.14040000", "1596736141.974806", "r"]], "c": "1048772642"}, "book-100", "XBT/USD"]
[270, {"a": [["11852.70000", "0.81476198", "1596737158.774823"]], "c": "2184037726"}, "book-100", "XBT/USD"]
[270, {"a": [["11855.80000", "0.83570000", "1596737158.824929"]], "c": "319190893"}, "book-100", "XBT/USD"]
[270, {"a": [["11856.60000", "0.00000000", "1596737158.874040"], ["11900.00000", "12.71653131", "1596737075.897027", "r"]], "c": "379443552"}, "book-100", "XBT/USD"]
[270, {"b": [["11836.00000", "0.42165097", "1596737158.884050"]], "c": "379443552"}, "book-100", "XBT/USD"]
[270, {"a": [["11858.60000", "4.20900000", "1596737158.893634"]], "c": "2185127432"}, "book-100", "XBT/USD"]
[270, {"a": [["11866.60000", "1.53739059", "1596737158.893949"]], "c": "2185127432"}, "book-100", "XBT/USD"]
[270, {"b": [["11851.40000", "0.00000000", "1596737158.894473"], ["11799.20000", "23.14040000", "1596736141.974806", "r"]], "c": "3784214243"}, "book-100", "XBT/USD"]
[270, {"a": [["11857.80000", "1.50000000", "1596737158.912515"]], "c": "3510994281"}, "book-100", "XBT/USD"]
[270, {"b": [["11849.70000", "0.06000000", "1596737158.955994"]], "c": "660143167"}, "book-100", "XBT/USD"]
[270, {"b": [["11849.10000", "4.20600000", "1596737158.972457"]], "c": "1456232560"}, "book-100", "XBT/USD"]
[270, {"a": [["11858.60000", "0.00000000", "1596737158.989393"], ["11900.00000", "12.71653131", "1596737075.897027", "r"]], "c": "4276290794"}, "book-100", "XBT/USD"]
[270, {"b": [["11842.30000", "0.00000000", "1596737159.002780"], ["11800.00000", "17.03324285", "1596736993.942623", "r"]], "c": "4276290794"}, "book-100", "XBT/USD"]
[270, {"b": [["11843.90000", "0.00000000", "1596737159.015117"], ["11799.20000", "23.14040000", "1596736141.974806", "r"]], "c": "4276290794"}, "book-100", "XBT/USD"]
[270, {"a": [["11871.40000", "0.00000000", "1596737159.030156"], ["11900.30000", "0.73381520", "1596737116.696146", "r"]], "c": "4276290794"}, "book-100", "XBT/USD"]
[270, {"b": [["11852.40000", "0.00000000", "1596737159.031229"], ["11799.00000", "0.17065000", "1596737154.640974", "r"]], "c": "1235241376"}, "book-100", "XBT/USD"]
[270, {"a": [["11856.60000", "0.83570000", "1596737159.109430"]], "c": "1679044673"}, "book-100", "XBT/USD"]
[270, {"b": [["11837.70000", "0.28673466", "1596737159.150992"]], "c": "1679044673"}, "book-100", "XBT/USD"]
[270, {"a": [["11855.80000", "0.00000000", "1596737159.153938"], ["11900.30000", "0.73381520", "1596737116.696146", "r"]], "c": "476355106"}, "book-100", "XBT/USD"]
[270, {"a": [["11857.30000", "4.83939743", "1596737159.172205"]], "c": "1922532579"}, "book-100", "XBT/USD"]
[270, {"a": [["11873.00000", "0.00000000", "1596737159.339758"], ["11900.70000", "0.00500000", "1596736976.571243", "r"]], "c": "1922532579"}, "book-100", "XBT/USD"]
[270, {"b": [["11841.20000", "0.76567456", "1596737159.366072"]], "c": "1922532579"}, "book-100", "XBT/USD"]
[270, {"b": [["11852.60000", "1.46703876", "1596737159.393406"]], "c": "1703498101"}, "book-100", "XBT/USD"]
[270, {"b": [["11827.30000", "0.00000000", "1596737159.421719"], ["11799.20000", "23.14040000", "1596736141.974806", "r"]], "c": "1703498101"}, "book-100", "XBT/USD"]
[270, {"a": [["11855.80000", "0.70000000", "1596737159.443802"]], "c": "2811090920"}, "book-100", "XBT/USD"]
[270, {"b": [["11849.70000", "0.00000000", "1596737159.469001"], ["11799.00000", "0.17065000", "1596737154.640974", "r"]], "c": "4245764375"}, "book-100", "XBT/USD"]
[270, {"b": [["11836.70000", "0.38000000", "1596737159.469954"]], "c": "4245764375"}, "book-100", "XBT/USD"]
[270, {"b": [["11825.30000", "5.16822813", "1596737159.499288"]], "c": "4245764375"}, "book-100", "XBT/USD"]
[270, {"a": [["11855.70000", "0.83570000", "1596737159.521002"]], "c": "2803490379"}, "book-100", "XBT/USD"]
[270, {"a": [["11856.60000", "0.00000000", "1596737159.528522"], ["11900.30000", "0.73381520", "1596737116.696146", "r"]], "c": "952469129"}, "book-100", "XBT/USD"]
[270, {"b": [["11845.20000", "0.00000000", "1596737159.579357"], ["11799.20000", "23.14040000", "1596736141.974806", "r"]], "c": "952469129"}, "book-100", "XBT/USD"]
[270, {"a": [["11855.80000", "0.00000000", "1596737159.580760"], ["11900.70000", "0.00500000", "1596736976.571243", "r"]], "c": "2677250752"}, "book-100", "XBT/USD"]
[270, {"a": [["11878.10000", "6.18384483", "1596737159.587038"]], "c": "2677250752"}, "book-100", "XBT/USD"]
[270, {"b": [["11840.90000", "0.00000000", "1596737159.592481"], ["11799.00000", "0.17065000", "1596737154.640974", "r"]], "c": "2677250752"}, "book-100", "XBT/USD"]
[270, {"b": [["11844.10000", "0.09621094", "1596737159.595748"]], "c": "2677250752"}, "book-100", "XBT/USD"]
[270, {"a": [["11870.80000", "0.00000000", "1596737159.598074"], ["11901.00000", "0.17065000", "1596737120.047779", "r"]], "c": "2677250752"}, "book-100", "XBT/USD"]
[270, {"a": [["11868.70000", "0.88000000", "1596737159.604068"]], "c": "2677250752"}, "book-100", "XBT/USD"]
[270, {"b": [["11849.70000", "0.06000000", "1596737159.635751"]], "c": "4164149172"}, "book-100", "XBT/USD"]
[270, {"a": [["11853.40000", "0.09621094", "1596737159.739322"]], "c": "1844227476"}, "book-100", "XBT/USD"]
[270, {"a": [["11878.10000", "5.72519189", "1596737159.759176"]], "c": "1844227476"}, "book-100", "XBT/USD"]
[270, {"a": [["11890.60000", "0.00000000", "1596737159.759883"], ["11901.00000", "0.17065000", "1596737120.047779", "r"]], "c": "1844227476"}, "book-100", "XBT/USD"]
[270, {"a": [["11879.90000", "0.44170718", "1596737159.943792"]], "c": "1844227476"}, "book-100", "XBT/USD"]
[270, {"a": [["11895.50000", "2.29444056", "1596737159.944547"]], "c": "1844227476"}, "book-100", "XBT/USD"]
[270, {"a": [["11855.80000", "0.83570000", "1596737160.025864"]], "c": "1900951236"}, "book-100", "XBT/USD"]
[270, {"a": [["11855.70000", "0.00000000", "1596737160.029739"], ["11900.70000", "0.00500000", "1596736976.571243", "r"]], "c": "2605304662"}, "book-100", "XBT/USD"]
[270, {"a": [["11852.70000", "0.81684157", "1596737160.048866"]], "c": "2571105705"}, "book-100", "XBT/USD"]
[270, {"a": [["11857.20000", "0.00000000", "1596737160.103225"], ["11901.00000", "0.17065000", "1596737120.047779", "r"]], "c": "942050948"}, "book-100", "XBT/USD"]
[270, {"b": [["11813.40000", "0.73646453", "1596737160.135101"]], "c": "942050948"}, "book-100", "XBT/USD"]
[270, {"b": [["11813.70000", "0.00000000", "1596737160.136397"], ["11800.00000", "17.03324285", "1596736993.942623", "r"]], "c": "942050948"}, "book-100", "XBT/USD"]
[270, {"a": [["11893.00000", "0.00000000", "1596737160.138253"], ["11901.20000", "0.05455260", "1596737145.299909", "r"]], "c": "942050948"}, "book-100", "XBT/USD"]
[270, {"a": [["11890.70000", "6.53646453", "1596737160.180051"]], "c": "942050948"}, "book-100", "XBT/USD"]
[270, {"a": [["11856.70000", "0.00000000", "1596737160.209803"], ["11901.40000", "1.90492467", "1596737138.167457", "r"]], "c": "1397660251"}, "book-100", "XBT/USD"]
[270, {"a": [["11872.90000", "0.00000000", "1596737160.457181"], ["11901.50000", "3.26167975", "1596737133.218332", "r"]], "c": "1397660251"}, "book-100", "XBT/USD"]
[270, {"a": [["11861.20000", "0.00000000", "1596737160.581005"], ["11901.80000", "0.75800000", "1596737130.968842", "r"]], "c": "1397660251"}, "book-100", "XBT/USD"]
[270, {"b": [["11851.50000", "1.68200000", "1596737160.584841"]], "c": "1517824944"}, "book-100", "XBT/USD"]
[270, {"a": [["11859.90000", "1.68500000", "1596737160.587637"]], "c": "3113338475"}, "book-100", "XBT/USD"]
[270, {"a": [["11857.20000", "0.83570000", "1596737160.643132"]], "c": "1049869158"}, "book-100", "XBT/USD"]
[270, {"a": [["11855.80000", "0.00000000", "1596737160.691249"], ["11901.50000", "3.26167975", "1596737133.218332", "r"]], "c": "3529029141"}, "book-100", "XBT/USD"]
[270, {"a": [["11857.50000", "0.25000000", "1596737160.725943"]], "c": "1074609583"}, "book-100", "XBT/USD"]
[270, {"a": [["11879.90000", "0.01000000", "1596737160.750765"]], "c": "1074609583"}, "book-100", "XBT/USD"]
[270, {"a": [["11892.00000", "0.17065000", "1596737160.751173"]], "c": "1074609583"}, "book-100", "XBT/USD"]
[270, {"a": [["11895.50000", "0.00000000", "1596737160.755964"], ["11901.40000", "1.90492467", "1596737138.167457", "r"]], "c": "1074609583"}, "book-100", "XBT/USD"]
[270, {"a": [["11859.90000", "0.00000000", "1596737160.758925"], ["11901.50000", "3.26167975", "1596737133.218332", "r"]], "c": "2853543870"}, "book-100", "XBT/USD"]
[270, {"b": [["11852.60000", "1.15084697", "1596737160.763400"]], "c": "1349928361"}, "book-100", "XBT/USD"]
[270, {"a": [["11857.30000", "4.20700000", "1596737160.767794"]], "c": "3982420422"}, "book-100", "XBT/USD"]
[270, {"b": [["11851.50000", "0.00000000", "1596737160.814883"], ["11800.00000", "17.03324285", "1596736993.942623", "r"]], "c": "2848019611"}, "book-100", "XBT/USD"]
[270, {"b": [["11843.60000", "0.00000000", "1596737160.840001"], ["11799.20000", "23.14040000", "1596736141.974806", "r"]], "c": "2848019611"}, "book-100", "XBT/USD"]
[270, {"a": [["11878.00000", "0.47707669", "1596737160.942627"]], "c": "2848019611"}, "book-100", "XBT/USD"]
[270, {"a": [["11890.60000", "2.15968996", "1596737160.942733"]], "c": "2848019611"}, "book-100", "XBT/USD"]
[270, {"b": [["11836.00000", "0.00000000", "1596737160.965557"], ["11799.00000", "0.17065000", "1596737154.640974", "r"]], "c": "2848019611"}, "book-100", "XBT/USD"]
[270, {"b": [["11851.00000", "0.31624588", "1596737161.021099"]], "c": "292346159"}, "book-100", "XBT/USD"]
[270, {"a": [["11855.80000", "0.83570000", "1596737161.021185"]], "c": "2488833907"}, "book-100", "XBT/USD"]
[270, {"a": [["11854.90000", "0.63251166", "1596737161.021275"]], "c": "2718040084"}, "book-100", "XBT/USD"]
[270, {"a": [["11856.10000", "0.63249176", "1596737161.021366"]], "c": "3741357391"}, "book-100", "XBT/USD"]
[270, {"b": [["11846.40000", "0.65967444", "1596737161.021734"]], "c": "3741357391"}, "book-100", "XBT/USD"]
[270, {"b": [["11836.20000", "1.48317624", "1596737161.022414"]], "c": "3741357391"}, "book-100", "XBT/USD"]
[270, {"a": [["11894.00000", "1.06880000", "1596737161.115493"]], "c": "3741357391"}, "book-100", "XBT/USD"]
[270, {"b": [["11836.20000", "1.06150180", "1596737161.180511"]], "c": "3741357391"}, "book-100", "XBT/USD"]
[270, {"a": [["11854.90000", "0.00000000", "1596737161.186433"], ["11900.30000", "0.73381520", "1596737116.696146", "r"]], "c": "2667890276"}, "book-100", "XBT/USD"]
[270, {"a": [["11857.50000", "0.00000000", "1596737161.300111"], ["11900.70000", "0.00500000", "1596736976.571243", "r"]], "c": "342199312"}, "book-100", "XBT/USD"]
[270, {"b": [["11849.70000", "0.00000000", "1596737161.323661"], ["11799.00000", "0.17065000", "1596737154.640974", "r"]], "c": "1060046915"}, "book-100", "XBT/USD"]
[270, {"a": [["11857.20000", "0.00000000", "1596737161.356571"], ["11901.00000", "0.17065000", "1596737120.047779", "r"]], "c": "3208109147"}, "book-100", "XBT/USD"]
[270, {"b": [["11849.70000", "0.06000000", "1596737161.492886"]], "c": "2491242504"}, "book-100", "XBT/USD"]
[270, {"a": [["11858.40000", "0.25000000", "1596737161.506140"]], "c": "831347534"}, "book-100", "XBT/USD"]
[270, {"b": [["11841.30000", "4.22396018", "1596737161.569211"]], "c": "831347534"}, "book-100", "XBT/USD"]
[270, {"b": [["11841.60000", "1.38702242", "1596737161.683449"]], "c": "831347534"}, "book-100", "XBT/USD"]
[270, {"b": [["11847.40000", "0.33008176", "1596737161.687702"]], "c": "831347534"}, "book-100", "XBT/USD"]
[270, {"b": [["11843.90000", "0.69337653", "1596737161.722208"]], "c": "831347534"}, "book-100", "XBT/USD"]
[270, {"b": [["11835.50000", "0.00436741", "1596737161.953281"]], "c": "831347534"}, "book-100", "XBT/USD"]
[270, {"a": [["11877.30000", "0.00438186", "1596737161.954425"]], "c": "831347534"}, "book-100", "XBT/USD"]
[270, {"a": [["11877.40000", "0.00000000", "1596737162.056780"], ["11900.70000", "0.00500000", "1596736976.571243", "r"]], "c": "831347534"}, "book-100", "XBT/USD"]
[270, {"a": [["11860.60000", "0.10100000", "1596737162.093509"]], "c": "831347534"}, "book-100", "XBT/USD"]
[270, {"a": [["11852.70000", "0.41684157", "1596737162.155882"]], "c": "1968406017"}, "book-100", "XBT/USD"]
[270, {"a": [["11856.00000", "0.83570000", "1596737162.160914"]], "c": "3597674126"}, "book-100", "XBT/USD"]
[270, {"a": [["11855.80000", "0.00000000", "1596737162.169549"], ["11900.70000", "0.00500000", "1596736976.571243", "r"]], "c": "69151979"}, "book-100", "XBT/USD"]
[270, {"b": [["11851.70000", "1.68200000", "1596737162.175436"]], "c": "2582894777"}, "book-100", "XBT/USD"]
[270, {"b": [["11836.90000", "0.00000000", "1596737162.193217"], ["11801.90000", "4.67249674", "1596736908.903243", "r"]], "c": "2582894777"}, "book-100", "XBT/USD"]
[270, {"a": [["11856.10000", "0.00000000", "1596737162.193461"], ["11901.00000", "0.17065000", "1596737120.047779", "r"]], "c": "1561339435"}, "book-100", "XBT/USD"]
[270, {"a": [["11860.30000", "1.67700000", "1596737162.196482"]], "c": "191631402"}, "book-100", "XBT/USD"]
[270, {"b": [["11849.70000", "0.00000000", "1596737162.292264"], ["11801.80000", "3.19470719", "1596736911.648608", "r"]], "c": "790133659"}, "book-100", "XBT/USD"]
[270, {"a": [["11855.90000", "0.00000000", "1596737162.318956"], ["11901.00000", "0.17065000", "1596737120.047779", "r"]], "c": "2059542153"}, "book-100", "XBT/USD"]
[270, {"a": [["11872.20000", "0.00000000", "1596737162.322985"], ["11901.20000", "0.05455260", "1596737145.299909", "r"]], "c": "2059542153"}, "book-100", "XBT/USD"]
[270, {"a": [["11860.30000", "0.00000000", "1596737162.325494"], ["11901.40000", "1.90492467", "1596737138.167457", "r"]], "c": "3079522267"}, "book-100", "XBT/USD"]
[270, {"a": [["11862.30000", "0.84285920", "1596737162.331879"]], "c": "3079522267"}, "book-100", "XBT/USD"]
[270, {"a": [["11857.30000", "0.00000000", "1596737162.376557"], ["11901.40000", "1.90492467", "1596737138.167457", "r"]], "c": "3548230706"}, "book-100", "XBT/USD"]
[270, {"a": [["11857.20000", "0.70000000", "1596737162.383501"]], "c": "352854835"}, "book-100", "XBT/USD"]
[270, {"b": [["11851.80000", "0.10000000", "1596737162.427353"]], "c": "3658058041"}, "book-100", "XBT/USD"]
[270, {"a": [["11857.20000", "0.00000000", "1596737162.433208"], ["11901.40000", "1.90492467", "1596737138.167457", "r"]], "c": "477896248"}, "book-100", "XBT/USD"]
[270, {"b": [["11850.20000", "0.10000000", "1596737162.465700"]], "c": "943493168"}, "book-100", "XBT/USD"]
[270, {"a": [["11857.10000", "0.83570000", "1596737162.523247"]], "c": "236208418"}, "book-100", "XBT/USD"]
[270, {"a": [["11857.80000", "0.00000000", "1596737162.537013"], ["11901.40000", "1.90492467", "1596737138.167457", "r"]], "c": "1852316752"}, "book-100", "XBT/USD"]
[270, {"b": [["11847.10000", "0.78056000", "1596737162.564601"]], "c": "1852316752"}, "book-100", "XBT/USD"]
[270, {"a": [["11856.00000", "0.00000000", "1596737162.567390"], ["11901.50000", "3.26167975", "1596737133.218332", "r"]], "c": "3670474431"}, "book-100", "XBT/USD"]
[270, {"a": [["11878.00000", "0.00000000", "1596737162.573141"], ["11901.80000", "0.75800000", "1596737130.968842", "r"]], "c": "3670474431"}, "book-100", "XBT/USD"]
[270, {"a": [["11859.00000", "1.50000000", "1596737162.683965"]], "c": "1595548158"}, "book-100", "XBT/USD"]
[270, {"b": [["11846.20000", "0.09621094", "1596737162.692114"]], "c": "1595548158"}, "book-100", "XBT/USD"]
[270, {"a": [["11887.10000", "0.00000000", "1596737162.695203"], ["11901.80000", "0.75800000", "1596737130.968842", "r"]], "c": "1595548158"}, "book-100", "XBT/USD"]
[270, {"b": [["11852.60000", "1.55084697", "1596737162.704482"]], "c": "1704364413"}, "book-100", "XBT/USD"]
[270, {"a": [["11858.00000", "0.00000000", "1596737162.727706"], ["11902.00000", "0.22739000", "1596736764.397858", "r"]], "c": "1253845322"}, "book-100", "XBT/USD"]
[270, {"b": [["11844.10000", "0.00000000", "1596737162.729687"], ["11802.10000", "4.23653417", "1596737132.953878", "r"]], "c": "1253845322"}, "book-100", "XBT/USD"]
[270, {"b": [["11848.10000", "0.52363776", "1596737162.733395"]], "c": "1253845322"}, "book-100", "XBT/USD"]
[270, {"a": [["11879.60000", "0.63050478", "1596737162.757285"]], "c": "1253845322"}, "book-100", "XBT/USD"]
[270, {"b": [["11851.70000", "4.51160388", "1596737162.809676"]], "c": "969487329"}, "book-100", "XBT/USD"]
[270, {"a": [["11877.30000", "0.00000000", "1596737162.809754"], ["11902.00000", "0.22739000", "1596736764.397858", "r"]], "c": "969487329"}, "book-100", "XBT/USD"]
[270, {"a": [["11866.90000", "0.84308134", "1596737162.824193"]], "c": "969487329"}, "book-100", "XBT/USD"]
[270, {"b": [["11851.10000", "0.69722000", "1596737162.914933"]], "c": "1885668664"}, "book-100", "XBT/USD"]
[270, {"a": [["11863.60000", "0.00000000", "1596737162.924991"], ["11902.20000", "1.58369712", "1596737116.990726", "r"]], "c": "1885668664"}, "book-100", "XBT/USD"]
[270, {"a": [["11860.50000", "0.17947000", "1596737162.925289"]], "c": "2992804331"}, "book-100", "XBT/USD"]
[270, {"a": [["11890.60000", "0.00000000", "1596737162.953810"], ["11904.00000", "0.17065000", "1596737071.292235", "r"]], "c": "2992804331"}, "book-100", "XBT/USD"]
[270, {"a": [["11864.20000", "1.68200000", "1596737162.969940"]], "c": "2992804331"}, "book-100", "XBT/USD"]
[270, {"a": [["11866.50000", "0.69359485", "1596737162.977008"]], "c": "2992804331"}, "book-100", "XBT/USD"]
[270, {"a": [["11866.10000", "0.00000000", "1596737162.977091"], ["11904.00000", "0.17065000", "1596737071.292235", "r"]], "c": "2992804331"}, "book-100", "XBT/USD"]
[270, {"b": [["11848.20000", "0.00000000", "1596737162.984029"], ["11802.10000", "4.23653417", "1596737132.953878", "r"]], "c": "2992804331"}, "book-100", "XBT/USD"]
[270, {"b": [["11835.50000", "0.00000000", "1596737162.994036"], ["11802.00000", "7.50000000", "1596737157.927162", "r"]], "c": "2992804331"}, "book-100", "XBT/USD"]
[270, {"a": [["11858.30000", "0.83570000", "1596737163.024435"]], "c": "2138883367"}, "book-100", "XBT/USD"]
[270, {"a": [["11857.10000", "0.00000000", "1596737163.029413"], ["11904.00000", "0.17065000", "1596737071.292235", "r"]], "c": "2825249773"}, "book-100", "XBT/USD"]
[270, {"b": [["11850.20000", "0.00000000", "1596737163.048854"], ["11801.90000", "4.67249674", "1596736908.903243", "r"]], "c": "1615431889"}, "book-100", "XBT/USD"]
[270, {"a": [["11859.00000", "0.00000000", "1596737163.063938"], ["11904.60000", "0.02329731", "1596737116.563077", "r"]], "c": "2134066188"}, "book-100", "XBT/USD"]
[270, {"a": [["11858.40000", "0.00000000", "1596737163.077459"], ["11905.00000", "27.00000000", "1596736856.739074", "r"]], "c": "2356368644"}, "book-100", "XBT/USD"]
[270, {"a": [["11862.30000", "0.00000000", "1596737163.116147"], ["11906.40000", "0.47990000", "1596737133.044226", "r"]], "c": "1745421861"}, "book-100", "XBT/USD"]
[270, {"a": [["11864.20000", "0.00000000", "1596737163.120928"], ["11907.00000", "0.17065000", "1596737135.727101", "r"]], "c": "1745421861"}, "book-100", "XBT/USD"]
[270, {"a": [["11895.50000", "2.33539521", "1596737163.137100"]], "c": "1745421861"}, "book-100", "XBT/USD"]
[270, {"a": [["11860.80000", "0.00000000", "1596737163.145640"], ["11907.00000", "0.17065000", "1596737135.727101", "r"]], "c": "527676508"}, "book-100", "XBT/USD"]
[270, {"b": [["11840.50000", "0.00000000", "1596737163.155394"], ["11801.80000", "3.19470719", "1596736911.648608", "r"]], "c": "527676508"}, "book-100", "XBT/USD"]
[270, {"b": [["11851.00000", "0.00000000", "1596737163.165826"], ["11800.80000", "1.51500000", "1596737133.991629", "r"]], "c": "1475627151"}, "book-100", "XBT/USD"]
[270, {"a": [["11865.60000", "1.11699317", "1596737163.192144"]], "c": "1475627151"}, "book-100", "XBT/USD"]
[270, {"a": [["11853.40000", "0.00000000", "1596737163.203845"], ["11907.90000", "4.59195838", "1596737162.188430", "r"]], "c": "2978506867"}, "book-100", "XBT/USD"]
[270, {"a": [["11861.20000", "1.50000000", "1596737163.212306"]], "c": "2248091285"}, "book-100", "XBT/USD"]
[270, {"a": [["11868.90000", "0.00000000", "1596737163.234955"], ["11907.90000", "4.59195838", "1596737162.188430", "r"]], "c": "2248091285"}, "book-100", "XBT/USD"]
[270, {"a": [["11860.00000", "0.25000000", "1596737163.243705"]], "c": "199949038"}, "book-100", "XBT/USD"]
[270, {"b": [["11852.60000", "1.65084697", "1596737163.254774"]], "c": "1859372319"}, "book-100", "XBT/USD"]
[270, {"a": [["11859.60000", "0.63238262", "1596737163.308537"]], "c": "48369458"}, "book-100", "XBT/USD"]
[270, {"b": [["11852.60000", "2.07234954", "1596737163.308980"]], "c": "2020617162"}, "book-100", "XBT/USD"]
[270, {"b": [["11852.50000", "0.42150257", "1596737163.309596"]], "c": "2709226659"}, "book-100", "XBT/USD"]
[270, {"a": [["11861.30000", "0.63229654", "1596737163.309714"]], "c": "2410419304"}, "book-100", "XBT/USD"]
[270, {"b": [["11841.40000", "0.42150257", "1596737163.312765"]], "c": "2410419304"}, "book-100", "XBT/USD"]
[270, {"a": [["11871.70000", "0.84324542", "1596737163.312870"]], "c": "2410419304"}, "book-100", "XBT/USD"]
[270, {"a": [["11872.20000", "0.84300515", "1596737163.312966"]], "c": "2410419304"}, "book-100", "XBT/USD"]
[270, {"b": [["11852.30000", "0.31620954", "1596737163.313769"]], "c": "4194175071"}, "book-100", "XBT/USD"]
[270, {"a": [["11861.80000", "0.63225386", "1596737163.313926"]], "c": "4194175071"}, "book-100", "XBT/USD"]
[270, {"b": [["11841.40000", "0.00000000", "1596737163.429833"], ["11801.90000", "4.67249674", "1596736908.903243", "r"]], "c": "4194175071"}, "book-100", "XBT/USD"]
[270, {"b": [["11852.30000", "0.00000000", "1596737163.446679"], ["11801.80000", "3.19470719", "1596736911.648608", "r"]], "c": "2410419304"}, "book-100", "XBT/USD"]
[270, {"a": [["11868.70000", "0.50000000", "1596737163.466395"]], "c": "2410419304"}, "book-100", "XBT/USD"]
[270, {"a": [["11872.90000", "0.38000000", "1596737163.480791"]], "c": "2410419304"}, "book-100", "XBT/USD"]
[270, {"b": [["11840.90000", "0.38000000", "1596737163.489897"]], "c": "2410419304"}, "book-100", "XBT/USD"]
[270, {"a": [["11859.50000", "0.83570000", "1596737163.525317"]], "c": "2243904473"}, "book-100", "XBT/USD"]
[270, {"a": [["11858.30000", "0.00000000", "1596737163.536486"], ["11902.00000", "0.22739000", "1596736764.397858", "r"]], "c": "1282863629"}, "book-100", "XBT/USD"]
[270, {"b": [["11841.60000", "0.00000000", "1596737163.575160"], ["11801.80000", "3.19470719", "1596736911.648608", "r"]], "c": "1282863629"}, "book-100", "XBT/USD"]
[270, {"b": [["11843.90000", "0.00000000", "1596737163.581011"], ["11800.80000", "1.51500000", "1596737133.991629", "r"]], "c": "1282863629"}, "book-100", "XBT/USD"]
[270, {"b": [["11847.40000", "0.00000000", "1596737163.583986"], ["11800.00000", "17.03324285", "1596736993.942623", "r"]], "c": "1282863629"}, "book-100", "XBT/USD"]
[270, {"a": [["11864.10000", "1.04280829", "1596737163.670793"]], "c": "1282863629"}, "book-100", "XBT/USD"]
[270, {"b": [["11849.60000", "0.00000000", "1596737163.711532"], ["11799.20000", "23.14040000", "1596736141.974806", "r"]], "c": "107728296"}, "book-100", "XBT/USD"]
[270, {"b": [["11847.90000", "5.70000000", "1596737163.721733"]], "c": "107728296"}, "book-100", "XBT/USD"]
[270, {"b": [["11841.30000", "3.27782305", "1596737163.724139"]], "c": "107728296"}, "book-100", "XBT/USD"]
[270, {"b": [["11837.70000", "0.00000000", "1596737163.736794"], ["11799.20000", "23.14040000", "1596736141.974806", "r"]], "c": "107728296"}, "book-100", "XBT/USD"]
[270, {"b": [["11841.20000", "0.00000000", "1596737163.752633"], ["11799.00000", "0.17065000", "1596737154.640974", "r"]], "c": "107728296"}, "book-100", "XBT/USD"]
[270, {"b": [["11849.10000", "0.00000000", "1596737163.762041"], ["11798.60000", "18.30000000", "1596737089.559503", "r"]], "c": "1915912535"}, "book-100", "XBT/USD"]
[270, {"b": [["11852.30000", "4.21300000", "1596737163.781634"]], "c": "1537109643"}, "book-100", "XBT/USD"]
[270, {"a": [["11862.30000", "4.20600000", "1596737163.789327"]], "c": "1537109643"}, "book-100", "XBT/USD"]
[270, {"b": [["11825.30000", "0.00000000", "1596737163.804551"], ["11798.60000", "18.30000000", "1596737089.559503", "r"]], "c": "1537109643"}, "book-100", "XBT/USD"]
[270, {"b": [["11844.20000", "0.00000000", "1596737163.807933"], ["11797.90000", "6.30000000", "1596737122.404410", "r"]], "c": "1537109643"}, "book-100", "XBT/USD"]
[270, {"a": [["11886.40000", "1.77465857", "1596737163.876875"]], "c": "1537109643"}, "book-100", "XBT/USD"]
[270, {"b": [["11840.90000", "0.66665915", "1596737163.978973"]], "c": "1537109643"}, "book-100", "XBT/USD"]
[270, {"a": [["11878.10000", "0.10902130", "1596737163.979299"]], "c": "1537109643"}, "book-100", "XBT/USD"]
[270, {"b": [["11844.40000", "0.76544998", "1596737163.997141"]], "c": "1537109643"}, "book-100", "XBT/USD"]
[270, {"a": [["11873.10000", "5.61782677", "1596737164.071076"]], "c": "1537109643"}, "book-100", "XBT/USD"]
[270, {"a": [["11871.60000", "3.14718552", "1596737164.077421"]], "c": "1537109643"}, "book-100", "XBT/USD"]
[270, {"a": [["11861.80000", "0.00000000", "1596737164.141342"], ["11901.50000", "3.26167975", "1596737133.218332", "r"]], "c": "1537109643"}, "book-100", "XBT/USD"]
[270, {"a": [["11868.30000", "0.00000000", "1596737164.224134"], ["11901.80000", "0.75800000", "1596737130.968842", "r"]], "c": "1537109643"}, "book-100", "XBT/USD"]
[270, {"b": [["11843.90000", "0.94598322", "1596737164.260003"]], "c": "1537109643"}, "book-100", "XBT/USD"]
[270, {"b": [["11844.20000", "1.38671794", "1596737164.261347"]], "c": "1537109643"}, "book-100", "XBT/USD"]
[270, {"b": [["11850.00000", "0.33000934", "1596737164.263645"]], "c": "3045782951"}, "book-100", "XBT/USD"]
[270, {"b": [["11846.30000", "0.10933246", "1596737164.291916"]], "c": "3045782951"}, "book-100", "XBT/USD"]
[270, {"b": [["11851.80000", "0.00000000", "1596737164.299264"], ["11800.00000", "17.03324285", "1596736993.942623", "r"]], "c": "619956223"}, "book-100", "XBT/USD"]
[270, {"b": [["11847.30000", "0.00000000", "1596737164.350130"], ["11799.20000", "23.14040000", "1596736141.974806", "r"]], "c": "619956223"}, "book-100", "XBT/USD"]
[270, {"b": [["11836.70000", "0.00000000", "1596737164.440474"], ["11799.00000", "0.17065000", "1596737154.640974", "r"]], "c": "619956223"}, "book-100", "XBT/USD"]
[270, {"a": [["11892.00000", "0.00000000", "1596737164.472352"], ["11902.00000", "0.22739000", "1596736764.397858", "r"]], "c": "619956223"}, "book-100", "XBT/USD"]
[270, {"b": [["11849.80000", "0.00000000", "1596737164.759399"], ["11798.60000", "18.30000000", "1596737089.559503", "r"]], "c": "1033162739"}, "book-100", "XBT/USD"]
[270, {"a": [["11860.00000", "0.00000000", "1596737164.984198"], ["11902.20000", "1.58369712", "1596737116.990726", "r"]], "c": "3492817123"}, "book-100", "XBT/USD"]
[270, {"a": [["11864.10000", "0.20000000", "1596737165.041373"]], "c": "3492817123"}, "book-100", "XBT/USD"]
[270, {"b": [["11846.60000", "0.69321850", "1596737165.064776"]], "c": "3492817123"}, "book-100", "XBT/USD"]
[270, {"b": [["11825.40000", "0.00700000", "1596737165.089801"]], "c": "3492817123"}, "book-100", "XBT/USD"]
[270, {"b": [["11816.80000", "5.16905865", "1596737165.106532"]], "c": "3492817123"}, "book-100", "XBT/USD"]
[270, {"a": [["11862.10000", "0.84281131", "1596737165.284280"]], "c": "3492817123"}, "book-100", "XBT/USD"]
[270, {"b": [["11852.60000", "2.15234954", "1596737165.469773"]], "c": "3495209774"}, "book-100", "XBT/USD"]
[270, {"a": [["11859.00000", "0.25000000", "1596737165.486005"]], "c": "2334708288"}, "book-100", "XBT/USD"]
[270, {"a": [["11858.90000", "0.83570000", "1596737165.541163"]], "c": "2219422904"}, "book-100", "XBT/USD"]
[270, {"a": [["11859.50000", "0.00000000", "1596737165.547416"], ["11901.80000", "0.75800000", "1596737130.968842", "r"]], "c": "2013501530"}, "book-100", "XBT/USD"]
[270, {"a": [["11866.40000", "0.00000000", "1596737165.671910"], ["11902.00000", "0.22739000", "1596736764.397858", "r"]], "c": "2013501530"}, "book-100", "XBT/USD"]
[271, [["11852.60000", "0.04250000", "1596737165.680303", "s", "m", ""], ["11852.60000", "0.09320000", "1596737165.708008", "s", "m", ""], ["11852.60000", "0.02655816", "1596737165.710803", "s", "m", ""]], "trade", "XBT/USD"]
[270, {"b": [["11852.60000", "2.10984954", "1596737165.680304"], ["11852.60000", "2.01664954", "1596737165.708008"], ["11852.60000", "1.99009138", "1596737165.710803"]], "c": "41096682"}, "book-100", "XBT/USD"]
[270, {"a": [["11856.90000", "0.09621094", "1596737165.729163"]], "c": "3483620010"}, "book-100", "XBT/USD"]
[270, {"b": [["11843.20000", "0.00000000", "1596737165.772134"], ["11799.20000", "23.14040000", "1596736141.974806", "r"]], "c": "3483620010"}, "book-100", "XBT/USD"]
[270, {"a": [["11869.90000", "0.00000000", "1596737165.772672"], ["11902.00000", "0.22739000", "1596736764.397858", "r"]], "c": "3483620010"}, "book-100", "XBT/USD"]
[270, {"b": [["11848.10000", "0.61984870", "1596737165.773032"]], "c": "3483620010"}, "book-100", "XBT/USD"]
[270, {"b": [["11842.30000", "0.98170000", "1596737165.780104"]], "c": "3483620010"}, "book-100", "XBT/USD"]
[270, {"a": [["11878.00000", "0.99480000", "1596737165.781683"]], "c": "3483620010"}, "book-100", "XBT/USD"]
[270, {"b": [["11824.00000", "1.11931909", "1596737165.784562"]], "c": "3483620010"}, "book-100", "XBT/USD"]
[270, {"b": [["11841.10000", "0.02300000", "1596737165.876132"]], "c": "3483620010"}, "book-100", "XBT/USD"]
[270, {"b": [["11843.00000", "0.00000000", "1596737166.064547"], ["11800.00000", "17.03324285", "1596736993.942623", "r"]], "c": "3483620010"}, "book-100", "XBT/USD"]
[270, {"a": [["11866.90000", "0.86108134", "1596737166.088193"]], "c": "3483620010"}, "book-100", "XBT/USD"]
[270, {"b": [["11845.50000", "0.00000000", "1596737166.093539"], ["11799.60000", "0.99110000", "1596737165.782615", "r"]], "c": "3483620010"}, "book-100", "XBT/USD"]
[270, {"b": [["11851.70000", "2.82960388", "1596737166.095195"]], "c": "393895369"}, "book-100", "XBT/USD"]
[270, {"b": [["11852.60000", "3.67109138", "1596737166.101741"]], "c": "3818952041"}, "book-100", "XBT/USD"]
[270, {"a": [["11864.20000", "1.67500000", "1596737166.145370"]], "c": "3818952041"}, "book-100", "XBT/USD"]
[270, {"a": [["11860.20000", "0.63225868", "1596737166.151633"]], "c": "1916420684"}, "book-100", "XBT/USD"]
[270, {"b": [["11852.20000", "0.31611222", "1596737166.152214"]], "c": "1511864506"}, "book-100", "XBT/USD"]
[270, {"b": [["11852.40000", "0.31611222", "1596737166.152364"]], "c": "3630594493"}, "book-100", "XBT/USD"]
[270, {"b": [["11852.30000", "4.63450257", "1596737166.152761"]], "c": "844525262"}, "book-100", "XBT/USD"]
[270, {"b": [["11852.10000", "0.31611222", "1596737166.152934"]], "c": "3557928847"}, "book-100", "XBT/USD"]
[270, {"a": [["11860.50000", "0.00000000", "1596737166.153241"], ["11901.50000", "3.26167975", "1596737133.218332", "r"]], "c": "2520866577"}, "book-100", "XBT/USD"]
[270, {"a": [["11879.50000", "0.00438186", "1596737166.194950"]], "c": "2520866577"}, "book-100", "XBT/USD"]
[270, {"b": [["11846.20000", "0.00000000", "1596737166.269317"], ["11800.80000", "1.51500000", "1596737133.991629", "r"]], "c": "2520866577"}, "book-100", "XBT/USD"]
[270, {"b": [["11802.00000", "7.67065000", "1596737166.365862"]], "c": "2520866577"}, "book-100", "XBT/USD"]
[270, {"b": [["11813.40000", "0.00000000", "1596737166.367518"], ["11800.00000", "17.03324285", "1596736993.942623", "r"]], "c": "2520866577"}, "book-100", "XBT/USD"]
[270, {"a": [["11889.80000", "0.73645366", "1596737166.368321"]], "c": "2520866577"}, "book-100", "XBT/USD"]
[270, {"a": [["11890.70000", "5.80000000", "1596737166.373409"]], "c": "2520866577"}, "book-100", "XBT/USD"]
[270, {"b": [["11815.40000", "0.73645366", "1596737166.374186"]], "c": "2520866577"}, "book-100", "XBT/USD"]
[270, {"a": [["11866.50000", "0.00000000", "1596737167.082390"], ["11901.40000", "1.90492467", "1596737138.167457", "r"]], "c": "2520866577"}, "book-100", "XBT/USD"]
[270, {"a": [["11869.20000", "0.69351519", "1596737167.144367"]], "c": "2520866577"}, "book-100", "XBT/USD"]
[270, {"a": [["11864.20000", "0.00000000", "1596737167.189946"], ["11901.40000", "1.90492467", "1596737138.167457", "r"]], "c": "2520866577"}, "book-100", "XBT/USD"]
[270, {"a": [["11861.20000", "0.00000000", "1596737167.296783"], ["11901.50000", "3.26167975", "1596737133.218332", "r"]], "c": "3160606633"}, "book-100", "XBT/USD"]
[270, {"a": [["11890.50000", "0.00000000", "1596737167.314043"], ["11901.80000", "0.75800000", "1596737130.968842", "r"]], "c": "3160606633"}, "book-100", "XBT/USD"]
[270, {"b": [["11852.60000", "3.77109138", "1596737167.345850"]], "c": "1291408133"}, "book-100", "XBT/USD"]
[270, {"a": [["11860.70000", "1.50000000", "1596737167.446881"]], "c": "3851307288"}, "book-100", "XBT/USD"]
[270, {"b": [["11852.20000", "0.00000000", "1596737167.539443"], ["11800.00000", "17.03324285", "1596736993.942623", "r"]], "c": "369805678"}, "book-100", "XBT/USD"]
[270, {"b": [["11852.10000", "0.00000000", "1596737167.539630"], ["11799.60000", "0.99110000", "1596737165.782615", "r"]], "c": "3455667664"}, "book-100", "XBT/USD"]
[270, {"b": [["11852.60000", "3.69109138", "1596737167.546653"]], "c": "2181576600"}, "book-100", "XBT/USD"]
[270, {"a": [["11868.50000", "0.09250000", "1596737167.574169"]], "c": "2181576600"}, "book-100", "XBT/USD"]
[270, {"a": [["11861.30000", "0.00000000", "1596737167.630328"], ["11901.50000", "3.26167975", "1596737133.218332", "r"]], "c": "2181576600"}, "book-100", "XBT/USD"]
[270, {"a": [["11859.00000", "0.00000000", "1596737167.658358"], ["11901.80000", "0.75800000", "1596737130.968842", "r"]], "c": "813471262"}, "book-100", "XBT/USD"]
[270, {"a": [["11859.50000", "0.82180000", "1596737167.712717"]], "c": "3259324373"}, "book-100", "XBT/USD"]
[270, {"a": [["11858.90000", "0.00000000", "1596737167.720322"], ["11901.80000", "0.75800000", "1596737130.968842", "r"]], "c": "2280077670"}, "book-100", "XBT/USD"]
[270, {"a": [["11863.90000", "1.67400000", "1596737167.744229"]], "c": "2280077670"}, "book-100", "XBT/USD"]
[270, {"a": [["11860.10000", "0.70000000", "1596737168.619655"]], "c": "1392369268"}, "book-100", "XBT/USD"]
[270, {"a": [["11858.00000", "0.25000000", "1596737168.622925"]], "c": "843706326"}, "book-100", "XBT/USD"]
[270, {"a": [["11873.10000", "0.00000000", "1596737168.725158"], ["11901.40000", "1.90492467", "1596737138.167457", "r"]], "c": "843706326"}, "book-100", "XBT/USD"]
[270, {"a": [["11860.10000", "0.00000000", "1596737168.731108"], ["11901.50000", "3.26167975", "1596737133.218332", "r"]], "c": "2717240138"}, "book-100", "XBT/USD"]
[270, {"a": [["11860.20000", "0.00000000", "1596737168.734891"], ["11901.80000", "0.75800000", "1596737130.968842", "r"]], "c": "3161221436"}, "book-100", "XBT/USD"]
[270, {"a": [["11869.10000", "6.00000000", "1596737168.739242"]], "c": "3161221436"}, "book-100", "XBT/USD"]
[270, {"b": [["11816.80000", "0.00000000", "1596737168.811845"], ["11799.20000", "23.14040000", "1596736141.974806", "r"]], "c": "3161221436"}, "book-100", "XBT/USD"]
[270, {"b": [["11842.60000", "0.42150360", "1596737168.819017"]], "c": "3161221436"}, "book-100", "XBT/USD"]
[270, {"b": [["11845.10000", "0.42150360", "1596737168.819201"]], "c": "3161221436"}, "book-100", "XBT/USD"]
[270, {"a": [["11858.30000", "0.63230586", "1596737168.819317"]], "c": "71353863"}, "book-100", "XBT/USD"]
[270, {"a": [["11859.00000", "0.63228998", "1596737168.819556"]], "c": "108188315"}, "book-100", "XBT/USD"]
[270, {"b": [["11848.10000", "0.52363776", "1596737168.852857"]], "c": "108188315"}, "book-100", "XBT/USD"]
[270, {"a": [["11857.90000", "0.82180000", "1596737168.873103"]], "c": "4265915103"}, "book-100", "XBT/USD"]
[270, {"a": [["11859.50000", "0.00000000", "1596737168.922453"], ["11901.20000", "0.05455260", "1596737145.299909", "r"]], "c": "3727742876"}, "book-100", "XBT/USD"]
[270, {"a": [["11858.20000", "0.82180000", "1596737169.143577"]], "c": "3540256137"}, "book-100", "XBT/USD"]
[270, {"a": [["11857.90000", "0.00000000", "1596737169.148225"], ["11901.20000", "0.05455260", "1596737145.299909", "r"]], "c": "3128384183"}, "book-100", "XBT/USD"]
[270, {"a": [["11858.00000", "0.00000000", "1596737169.911644"], ["11901.40000", "1.90492467", "1596737138.167457", "r"]], "c": "2099290962"}, "book-100", "XBT/USD"]
[270, {"a": [["11856.90000", "0.00000000", "1596737169.921627"], ["11901.50000", "3.26167975", "1596737133.218332", "r"]], "c": "3111835539"}, "book-100", "XBT/USD"]
[270, {"a": [["11863.90000", "0.00000000", "1596737170.061538"], ["11901.80000", "0.75800000", "1596737130.968842", "r"]], "c": "3111835539"}, "book-100", "XBT/USD"]
[270, {"a": [["11857.90000", "0.82180000", "1596737170.062226"]], "c": "65361716"}, "book-100", "XBT/USD"]
[270, {"a": [["11858.10000", "0.70000000", "1596737170.131089"]], "c": "1160512559"}, "book-100", "XBT/USD"]
[270, {"a": [["11858.20000", "0.00000000", "1596737170.133539"], ["11901.50000", "3.26167975", "1596737133.218332", "r"]], "c": "374654365"}, "book-100", "XBT/USD"]
[270, {"b": [["11838.60000", "6.49579788", "1596737170.143709"]], "c": "374654365"}, "book-100", "XBT/USD"]
[270, {"a": [["11859.10000", "0.25000000", "1596737170.149677"]], "c": "313124623"}, "book-100", "XBT/USD"]
[270, {"a": [["11862.10000", "1.50153149", "1596737170.174345"]], "c": "313124623"}, "book-100", "XBT/USD"]
[270, {"a": [["11858.10000", "0.00000000", "1596737170.179914"], ["11901.50000", "3.26167975", "1596737133.218332", "r"]], "c": "4151112620"}, "book-100", "XBT/USD"]
[270, {"a": [["11858.00000", "0.82180000", "1596737170.196720"]], "c": "4286845667"}, "book-100", "XBT/USD"]
[270, {"a": [["11857.90000", "0.00000000", "1596737170.203629"], ["11901.50000", "3.26167975", "1596737133.218332", "r"]], "c": "1411468917"}, "book-100", "XBT/USD"]
[270, {"b": [["11852.30000", "4.21300000", "1596737170.251334"]], "c": "3188807942"}, "book-100", "XBT/USD"]
[270, {"a": [["11858.30000", "0.00000000", "1596737170.251428"], ["11901.80000", "0.75800000", "1596737130.968842", "r"]], "c": "748422119"}, "book-100", "XBT/USD"]
[270, {"b": [["11842.60000", "0.00000000", "1596737170.253087"], ["11799.60000", "0.99110000", "1596737165.782615", "r"]], "c": "748422119"}, "book-100", "XBT/USD"]
[270, {"a": [["11858.90000", "0.82180000", "1596737170.524809"]], "c": "1437429356"}, "book-100", "XBT/USD"]
[270, {"a": [["11858.00000", "0.00000000", "1596737170.530964"], ["11901.80000", "0.75800000", "1596737130.968842", "r"]], "c": "1416696988"}, "book-100", "XBT/USD"]
[270, {"a": [["11879.60000", "0.00000000", "1596737170.549904"], ["11902.00000", "0.22739000", "1596736764.397858", "r"]], "c": "1416696988"}, "book-100", "XBT/USD"]
[270, {"b": [["11848.80000", "0.00000000", "1596737170.616240"], ["11799.20000", "23.14040000", "1596736141.974806", "r"]], "c": "2706179270"}, "book-100", "XBT/USD"]
[270, {"b": [["11852.60000", "3.77109138", "1596737170.669879"]], "c": "4005330574"}, "book-100", "XBT/USD"]
[270, {"b": [["11852.60000", "3.37109138", "1596737170.704520"]], "c": "2587304124"}, "book-100", "XBT/USD"]
[270, {"a": [["11882.60000", "0.47136236", "1596737170.733849"]], "c": "2587304124"}, "book-100", "XBT/USD"]
[270, {"b": [["11852.60000", "3.52109138", "1596737170.742086"]], "c": "2075300228"}, "book-100", "XBT/USD"]
[270, {"b": [["11838.60000", "9.12110907", "1596737170.997257"]], "c": "2075300228"}, "book-100", "XBT/USD"]
[270, {"b": [["11852.60000", "3.44109138", "1596737171.141387"]], "c": "1096465098"}, "book-100", "XBT/USD"]
[270, {"a": [["11882.60000", "0.00000000", "1596737171.143829"], ["11902.00000", "0.22739000", "1596736764.397858", "r"]], "c": "1096465098"}, "book-100", "XBT/USD"]
[270, {"a": [["11861.50000", "0.63223950", "1596737171.203720"]], "c": "1096465098"}, "book-100", "XBT/USD"]
[270, {"a": [["11879.60000", "0.52425065", "1596737171.333118"]], "c": "1096465098"}, "book-100", "XBT/USD"]
[270, {"b": [["11852.30000", "4.52911975", "1596737171.435626"]], "c": "3018373751"}, "book-100", "XBT/USD"]
[270, {"b": [["11852.20000", "0.31611975", "1596737171.436641"]], "c": "240804659"}, "book-100", "XBT/USD"]
[270, {"b": [["11852.20000", "0.00000000", "1596737171.493523"], ["11799.20000", "23.14040000", "1596736141.974806", "r"]], "c": "3018373751"}, "book-100", "XBT/USD"]
[270, {"b": [["11852.30000", "4.21300000", "1596737171.493794"]], "c": "1096465098"}, "book-100", "XBT/USD"]
[270, {"a": [["11879.60000", "0.00000000", "1596737171.834587"], ["11901.80000", "0.75800000", "1596737130.968842", "r"]], "c": "1096465098"}, "book-100", "XBT/USD"]
[270, {"b": [["11848.10000", "0.61984870", "1596737171.872546"]], "c": "1096465098"}, "book-100", "XBT/USD"]
[270, {"b": [["11852.60000", "3.52109138", "1596737172.023957"]], "c": "2075300228"}, "book-100", "XBT/USD"]
[270, {"a": [["11867.00000", "0.69328000", "1596737172.216041"]], "c": "2075300228"}, "book-100", "XBT/USD"]
[270, {"a": [["11886.50000", "8.21309526", "1596737172.417953"]], "c": "2075300228"}, "book-100", "XBT/USD"]
[270, {"a": [["11856.90000", "0.09621094", "1596737172.426508"]], "c": "2816910027"}, "book-100", "XBT/USD"]
[270, {"b": [["11815.40000", "0.00000000", "1596737172.526356"], ["11799.00000", "0.17065000", "1596737154.640974", "r"]], "c": "2816910027"}, "book-100", "XBT/USD"]
[270, {"b": [["11799.70000", "2.21032519", "1596737172.529407"]], "c": "2816910027"}, "book-100", "XBT/USD"]
[270, {"a": [["11889.80000", "0.00000000", "1596737172.535585"], ["11901.50000", "3.26167975", "1596737133.218332", "r"]], "c": "2816910027"}, "book-100", "XBT/USD"]
[270, {"a": [["11887.60000", "0.75144153", "1596737172.539741"]], "c": "2816910027"}, "book-100", "XBT/USD"]
[270, {"b": [["11817.50000", "0.73644153", "1596737172.540238"]], "c": "2816910027"}, "book-100", "XBT/USD"]
[270, {"a": [["11879.90000", "5.62342820", "1596737172.744319"]], "c": "2816910027"}, "book-100", "XBT/USD"]
[270, {"b": [["11827.30000", "5.16704837", "1596737172.823252"]], "c": "2816910027"}, "book-100", "XBT/USD"]
[270, {"b": [["11852.60000", "3.44109138", "1596737172.965684"]], "c": "2634975621"}, "book-100", "XBT/USD"]
[270, {"a": [["11869.70000", "0.00000000", "1596737173.175323"], ["11901.80000", "0.75800000", "1596737130.968842", "r"]], "c": "2634975621"}, "book-100", "XBT/USD"]
[270, {"b": [["11845.10000", "0.00000000", "1596737173.276526"], ["11799.60000", "0.99110000", "1596737165.782615", "r"]], "c": "2634975621"}, "book-100", "XBT/USD"]
[270, {"b": [["11834.20000", "0.00423821", "1596737173.369264"]], "c": "2634975621"}, "book-100", "XBT/USD"]
[270, {"a": [["11879.50000", "0.00000000", "1596737173.370994"], ["11902.00000", "0.22739000", "1596736764.397858", "r"]], "c": "2634975621"}, "book-100", "XBT/USD"]
[270, {"a": [["11879.60000", "0.00438186", "1596737173.376067"]], "c": "2634975621"}, "book-100", "XBT/USD"]
[270, {"a": [["11870.40000", "0.00000000", "1596737173.422101"], ["11902.00000", "0.22739000", "1596736764.397858", "r"]], "c": "2634975621"}, "book-100", "XBT/USD"]
[270, {"b": [["11834.20000", "0.00000000", "1596737173.751112"], ["11799.60000", "0.99110000", "1596737165.782615", "r"]], "c": "2634975621"}, "book-100", "XBT/USD"]
[270, {"b": [["11841.40000", "0.42152894", "1596737173.854226"]], "c": "2634975621"}, "book-100", "XBT/USD"]
[270, {"b": [["11843.80000", "0.42152894", "1596737173.854361"]], "c": "2634975621"}, "book-100", "XBT/USD"]
[270, {"b": [["11852.10000", "0.42150379", "1596737173.854956"]], "c": "2374403128"}, "book-100", "XBT/USD"]
[270, {"b": [["11841.10000", "0.00000000", "1596737173.912602"], ["11800.00000", "17.03324285", "1596736993.942623", "r"]], "c": "2374403128"}, "book-100", "XBT/USD"]
[270, {"b": [["11839.00000", "0.01981286", "1596737173.952961"]], "c": "2374403128"}, "book-100", "XBT/USD"]
[270, {"b": [["11843.10000", "0.02300000", "1596737173.960594"]], "c": "2374403128"}, "book-100", "XBT/USD"]
[270, {"a": [["11852.70000", "0.41476198", "1596737173.992779"]], "c": "3927831823"}, "book-100", "XBT/USD"]
[270, {"b": [["11846.40000", "0.42167444", "1596737174.215344"]], "c": "3927831823"}, "book-100", "XBT/USD"]
[270, {"b": [["11840.60000", "0.23800000", "1596737174.271065"]], "c": "3927831823"}, "book-100", "XBT/USD"]
[270, {"a": [["11866.90000", "0.84308134", "1596737174.779892"]], "c": "3927831823"}, "book-100", "XBT/USD"]
[270, {"a": [["11879.60000", "0.00000000", "1596737174.791200"], ["11902.20000", "1.58369712", "1596737116.990726", "r"]], "c": "3927831823"}, "book-100", "XBT/USD"]
[270, {"a": [["11868.90000", "0.01800000", "1596737174.831073"]], "c": "3927831823"}, "book-100", "XBT/USD"]
[270, {"b": [["11852.60000", "3.52109138", "1596737174.847786"]], "c": "3505774145"}, "book-100", "XBT/USD"]
[270, {"a": [["11862.30000", "0.00000000", "1596737174.872201"], ["11902.20000", "1.58369712", "1596737116.990726", "r"]], "c": "3505774145"}, "book-100", "XBT/USD"]
[270, {"a": [["11860.80000", "4.20900000", "1596737174.898034"]], "c": "423244267"}, "book-100", "XBT/USD"]
[270, {"a": [["11858.80000", "0.70000000", "1596737174.951064"]], "c": "645688664"}, "book-100", "XBT/USD"]
[270, {"a": [["11858.80000", "0.00000000", "1596737175.007469"], ["11902.00000", "0.22739000", "1596736764.397858", "r"]], "c": "423244267"}, "book-100", "XBT/USD"]
[270, {"a": [["11858.70000", "0.82180000", "1596737175.016784"]], "c": "1293395628"}, "book-100", "XBT/USD"]
[270, {"a": [["11858.90000", "0.00000000", "1596737175.020281"], ["11902.00000", "0.22739000", "1596736764.397858", "r"]], "c": "181464963"}, "book-100", "XBT/USD"]
[270, {"a": [["11858.80000", "0.70000000", "1596737175.059569"]], "c": "4095851938"}, "book-100", "XBT/USD"]
[270, {"a": [["11858.90000", "0.82180000", "1596737175.075851"]], "c": "1852693529"}, "book-100", "XBT/USD"]
[270, {"a": [["11858.70000", "0.00000000", "1596737175.082037"], ["11901.80000", "0.75800000", "1596737130.968842", "r"]], "c": "645688664"}, "book-100", "XBT/USD"]
[270, {"a": [["11858.80000", "0.00000000", "1596737175.106674"], ["11902.00000", "0.22739000", "1596736764.397858", "r"]], "c": "423244267"}, "book-100", "XBT/USD"]
[270, {"b": [["11852.60000", "3.44109138", "1596737175.200311"]], "c": "600971941"}, "book-100", "XBT/USD"]
[270, {"a": [["11895.50000", "0.00000000", "1596737175.221001"], ["11902.20000", "1.58369712", "1596737116.990726", "r"]], "c": "600971941"}, "book-100", "XBT/USD"]
[270, {"a": [["11859.10000", "0.00000000", "1596737175.390447"], ["11904.00000", "0.17065000", "1596737071.292235", "r"]], "c": "554123862"}, "book-100", "XBT/USD"]
[270, {"b": [["11838.70000", "0.27395984", "1596737175.391412"]], "c": "554123862"}, "book-100", "XBT/USD"]
[270, {"a": [["11885.80000", "0.55399882", "1596737175.436799"]], "c": "554123862"}, "book-100", "XBT/USD"]
[270, {"a": [["11858.30000", "0.25000000", "1596737175.551472"]], "c": "481884597"}, "book-100", "XBT/USD"]
[270, {"a": [["11858.20000", "0.82180000", "1596737175.611066"]], "c": "2280569002"}, "book-100", "XBT/USD"]
[270, {"a": [["11879.60000", "0.52243582", "1596737175.620171"]], "c": "2280569002"}, "book-100", "XBT/USD"]
[270, {"a": [["11885.80000", "0.00000000", "1596737175.621264"], ["11901.80000", "0.75800000", "1596737130.968842", "r"]], "c": "2280569002"}, "book-100", "XBT/USD"]
[270, {"a": [["11858.90000", "0.00000000", "1596737175.666870"], ["11902.00000", "0.22739000", "1596736764.397858", "r"]], "c": "2305382526"}, "book-100", "XBT/USD"]
[270, {"b": [["11851.10000", "0.00000000", "1596737175.689600"], ["11801.80000", "3.19470719", "1596736911.648608", "r"]], "c": "937602361"}, "book-100", "XBT/USD"]
[270, {"a": [["11864.30000", "0.93820000", "1596737175.726952"]], "c": "937602361"}, "book-100", "XBT/USD"]
[270, {"a": [["11861.50000", "0.00000000", "1596737175.864557"], ["11902.00000", "0.22739000", "1596736764.397858", "r"]], "c": "937602361"}, "book-100", "XBT/USD"]
[270, {"a": [["11858.20000", "1.45410272", "1596737175.926933"]], "c": "1798486922"}, "book-100", "XBT/USD"]
[270, {"a": [["11858.10000", "0.82180000", "1596737176.024860"]], "c": "1588873850"}, "book-100", "XBT/USD"]
[270, {"a": [["11858.20000", "0.63230272", "1596737176.034926"]], "c": "4029585907"}, "book-100", "XBT/USD"]
[270, {"a": [["11858.00000", "0.39500000", "1596737176.111649"]], "c": "4175900391"}, "book-100", "XBT/USD"]
[270, {"b": [["11838.60000", "9.25104076", "1596737176.180382"]], "c": "4175900391"}, "book-100", "XBT/USD"]
[270, {"b": [["11838.60000", "9.12110907", "1596737176.326046"]], "c": "4175900391"}, "book-100", "XBT/USD"]
[270, {"a": [["11862.90000", "1.67900000", "1596737176.443631"]], "c": "4175900391"}, "book-100", "XBT/USD"]
[270, {"b": [["11838.60000", "9.21939501", "1596737176.479934"]], "c": "4175900391"}, "book-100", "XBT/USD"]
[270, {"a": [["11857.90000", "0.82180000", "1596737176.526818"]], "c": "436337339"}, "book-100", "XBT/USD"]
[270, {"a": [["11858.10000", "0.00000000", "1596737176.530830"], ["11901.40000", "1.90492467", "1596737138.167457", "r"]], "c": "2359128830"}, "book-100", "XBT/USD"]
[270, {"a": [["11862.90000", "0.00000000", "1596737176.564949"], ["11901.50000", "3.26167975", "1596737133.218332", "r"]], "c": "2359128830"}, "book-100", "XBT/USD"]
[270, {"a": [["11894.30000", "0.02324925", "1596737176.928318"]], "c": "2359128830"}, "book-100", "XBT/USD"]
[271, [["11852.60000", "0.00500000", "1596737177.118071", "s", "l", ""]], "trade", "XBT/USD"]
[270, {"b": [["11852.60000", "3.43609138", "1596737177.118071"]], "c": "1664589749"}, "book-100", "XBT/USD"]
[270, {"b": [["11838.60000", "9.12110907", "1596737177.151821"]], "c": "1664589749"}, "book-100", "XBT/USD"]
[270, {"b": [["11838.60000", "6.49579788", "1596737177.152032"]], "c": "1664589749"}, "book-100", "XBT/USD"]
[270, {"a": [["11857.80000", "0.37500000", "1596737177.230136"]], "c": "853646849"}, "book-100", "XBT/USD"]
[270, {"a": [["11857.90000", "0.00000000", "1596737177.297654"], ["11901.40000", "1.90492467", "1596737138.167457", "r"]], "c": "3300113565"}, "book-100", "XBT/USD"]
[270, {"a": [["11858.00000", "0.00000000", "1596737177.382637"], ["11901.50000", "3.26167975", "1596737133.218332", "r"]], "c": "1858601763"}, "book-100", "XBT/USD"]
[270, {"a": [["11857.70000", "0.82180000", "1596737177.645586"]], "c": "795190371"}, "book-100", "XBT/USD"]
[270, {"b": [["11827.30000", "0.00000000", "1596737177.651220"], ["11800.80000", "1.51500000", "1596737133.991629", "r"]], "c": "795190371"}, "book-100", "XBT/USD"]
[270, {"b": [["11826.10000", "5.16757264", "1596737177.727318"]], "c": "795190371"}, "book-100", "XBT/USD"]
[270, {"a": [["11879.70000", "0.00000000", "1596737177.865394"], ["11901.50000", "3.26167975", "1596737133.218332", "r"]], "c": "795190371"}, "book-100", "XBT/USD"]
[270, {"b": [["11834.70000", "0.00000000", "1596737177.868791"], ["11800.80000", "1.51500000", "1596737133.991629", "r"]], "c": "795190371"}, "book-100", "XBT/USD"]
[270, {"b": [["11836.90000", "0.70900000", "1596737177.870184"]], "c": "795190371"}, "book-100", "XBT/USD"]
[270, {"a": [["11863.30000", "1.67600000", "1596737177.910972"]], "c": "795190371"}, "book-100", "XBT/USD"]
[270, {"b": [["11838.60000", "9.06627082", "1596737177.911600"]], "c": "795190371"}, "book-100", "XBT/USD"]
[270, {"a": [["11869.70000", "0.01000000", "1596737178.143532"]], "c": "795190371"}, "book-100", "XBT/USD"]
[270, {"a": [["11863.30000", "0.00000000", "1596737178.197859"], ["11901.40000", "1.90492467", "1596737138.167457", "r"]], "c": "795190371"}, "book-100", "XBT/USD"]
[270, {"a": [["11862.60000", "1.68500000", "1596737178.215739"]], "c": "795190371"}, "book-100", "XBT/USD"]
[270, {"a": [["11900.70000", "0.00000000", "1596737178.303072"], ["11901.40000", "1.90492467", "1596737138.167457", "r"]], "c": "795190371"}, "book-100", "XBT/USD"]
[270, {"a": [["11860.70000", "0.00000000", "1596737178.377181"], ["11901.50000", "3.26167975", "1596737133.218332", "r"]], "c": "795190371"}, "book-100", "XBT/USD"]
[270, {"a": [["11860.30000", "1.50000000", "1596737178.665588"]], "c": "1744705934"}, "book-100", "XBT/USD"]
[270, {"b": [["11838.60000", "9.08330197", "1596737178.889592"]], "c": "1744705934"}, "book-100", "XBT/USD"]
[270, {"b": [["11838.60000", "9.11444369", "1596737179.058305"]], "c": "1744705934"}, "book-100", "XBT/USD"]
[270, {"b": [["11838.60000", "9.09741254", "1596737179.083609"]], "c": "1744705934"}, "book-100", "XBT/USD"]
[270, {"a": [["11875.20000", "0.00000000", "1596737179.087780"], ["11901.50000", "3.26167975", "1596737133.218332", "r"]], "c": "1744705934"}, "book-100", "XBT/USD"]
[270, {"a": [["11886.40000", "1.27465857", "1596737179.096811"]], "c": "1744705934"}, "book-100", "XBT/USD"]
[270, {"b": [["11838.60000", "9.17125511", "1596737179.317083"]], "c": "1744705934"}, "book-100", "XBT/USD"]
[270, {"b": [["11838.60000", "9.25391507", "1596737179.330963"]], "c": "1744705934"}, "book-100", "XBT/USD"]
[270, {"b": [["11838.60000", "9.22277335", "1596737179.342427"]], "c": "1744705934"}, "book-100", "XBT/USD"]
[270, {"a": [["11887.60000", "0.01500000", "1596737179.462430"]], "c": "1744705934"}, "book-100", "XBT/USD"]
[270, {"b": [["11838.60000", "9.14893078", "1596737179.464726"]], "c": "1744705934"}, "book-100", "XBT/USD"]
[270, {"a": [["11884.60000", "0.73642331", "1596737179.467355"]], "c": "1744705934"}, "book-100", "XBT/USD"]
[270, {"b": [["11821.90000", "0.73642331", "1596737179.469078"]], "c": "1744705934"}, "book-100", "XBT/USD"]
[270, {"b": [["11838.60000", "9.06627082", "1596737179.478930"]], "c": "1744705934"}, "book-100", "XBT/USD"]
[270, {"b": [["11817.50000", "0.00000000", "1596737179.491803"], ["11801.80000", "3.19470719", "1596736911.648608", "r"]], "c": "1744705934"}, "book-100", "XBT/USD"]
[270, {"a": [["11873.70000", "0.32934293", "1596737179.516911"]], "c": "1744705934"}, "book-100", "XBT/USD"]
[270, {"b": [["11838.60000", "9.25391498", "1596737179.625043"]], "c": "1744705934"}, "book-100", "XBT/USD"]
[270, {"a": [["11900.30000", "0.00000000", "1596737180.019143"], ["11901.40000", "1.90492467", "1596737138.167457", "r"]], "c": "1744705934"}, "book-100", "XBT/USD"]
[270, {"a": [["11888.40000", "0.50000000", "1596737180.266784"]], "c": "1744705934"}, "book-100", "XBT/USD"]
[270, {"a": [["11856.80000", "0.38500000", "1596737180.356963"]], "c": "982885432"}, "book-100", "XBT/USD"]
[270, {"a": [["11857.80000", "0.00000000", "1596737180.412943"], ["11901.20000", "0.05455260", "1596737145.299909", "r"]], "c": "2435621430"}, "book-100", "XBT/USD"]
[270, {"a": [["11857.70000", "0.00000000", "1596737180.491142"], ["11901.40000", "1.90492467", "1596737138.167457", "r"]], "c": "316979853"}, "book-100", "XBT/USD"]
[270, {"b": [["11830.00000", "7.10000000", "1596737180.699653"]], "c": "316979853"}, "book-100", "XBT/USD"]
[270, {"a": [["11858.10000", "0.82180000", "1596737180.755835"]], "c": "1401130899"}, "book-100", "XBT/USD"]
[270, {"a": [["11858.00000", "0.82180000", "1596737180.813391"]], "c": "3265860195"}, "book-100", "XBT/USD"]
[270, {"a": [["11858.10000", "0.00000000", "1596737180.819535"], ["11901.20000", "0.05455260", "1596737145.299909", "r"]], "c": "1630796975"}, "book-100", "XBT/USD"]
[270, {"b": [["11818.50000", "0.01322842", "1596737180.965401"]], "c": "1630796975"}, "book-100", "XBT/USD"]
[270, {"a": [["11858.10000", "0.82180000", "1596737181.023420"]], "c": "3265860195"}, "book-100", "XBT/USD"]
[270, {"a": [["11858.00000", "0.00000000", "1596737181.071461"], ["11901.20000", "0.05455260", "1596737145.299909", "r"]], "c": "1401130899"}, "book-100", "XBT/USD"]
[270, {"a": [["11862.60000", "0.00000000", "1596737181.101079"], ["11901.40000", "1.90492467", "1596737138.167457", "r"]], "c": "1401130899"}, "book-100", "XBT/USD"]
[270, {"a": [["11895.00000", "1.15425357", "1596737181.418147"]], "c": "1401130899"}, "book-100", "XBT/USD"]
[270, {"b": [["11849.90000", "0.99012000", "1596737181.453271"]], "c": "1162380027"}, "book-100", "XBT/USD"]
[270, {"a": [["11858.30000", "0.00000000", "1596737181.512230"], ["11901.50000", "3.26167975", "1596737133.218332", "r"]], "c": "3969946860"}, "book-100", "XBT/USD"]
[270, {"a": [["11858.20000", "0.00000000", "1596737181.621121"], ["11901.80000", "0.75800000", "1596737130.968842", "r"]], "c": "726051326"}, "book-100", "XBT/USD"]
[270, {"a": [["11864.30000", "0.00000000", "1596737181.665237"], ["11902.00000", "0.22739000", "1596736764.397858", "r"]], "c": "726051326"}, "book-100", "XBT/USD"]
[270, {"a": [["11859.70000", "0.29750000", "1596737181.672683"]], "c": "1580605210"}, "book-100", "XBT/USD"]
[270, {"a": [["11858.90000", "0.82180000", "1596737181.679039"]], "c": "1625844732"}, "book-100", "XBT/USD"]
[270, {"a": [["11858.10000", "0.00000000", "1596737181.686173"], ["11902.00000", "0.22739000", "1596736764.397858", "r"]], "c": "2308592277"}, "book-100", "XBT/USD"]
[270, {"a": [["11860.80000", "4.84126777", "1596737181.700609"]], "c": "1242815419"}, "book-100", "XBT/USD"]
[270, {"b": [["11838.60000", "9.06627082", "1596737181.701592"]], "c": "1242815419"}, "book-100", "XBT/USD"]
[270, {"a": [["11858.80000", "0.70000000", "1596737181.737125"]], "c": "645271809"}, "book-100", "XBT/USD"]
[270, {"b": [["11852.60000", "3.51609138", "1596737181.742831"]], "c": "638751436"}, "book-100", "XBT/USD"]
[270, {"a": [["11858.80000", "0.00000000", "1596737181.786236"], ["11902.00000", "0.22739000", "1596736764.397858", "r"]], "c": "1249335414"}, "book-100", "XBT/USD"]
[270, {"a": [["11856.80000", "0.00000000", "1596737181.791525"], ["11902.20000", "1.58369712", "1596737116.990726", "r"]], "c": "159820222"}, "book-100", "XBT/USD"]
[270, {"a": [["11858.70000", "0.70000000", "1596737181.833360"]], "c": "559860658"}, "book-100", "XBT/USD"]
[270, {"a": [["11858.70000", "0.00000000", "1596737181.878853"], ["11902.20000", "1.58369712", "1596737116.990726", "r"]], "c": "159820222"}, "book-100", "XBT/USD"]
[270, {"a": [["11858.60000", "0.70000000", "1596737181.926555"]], "c": "3817476865"}, "book-100", "XBT/USD"]
[270, {"b": [["11844.50000", "0.04464444", "1596737181.930564"]], "c": "3817476865"}, "book-100", "XBT/USD"]
[270, {"b": [["11808.10000", "0.00000000", "1596737181.945052"], ["11801.90000", "4.67249674", "1596736908.903243", "r"]], "c": "3817476865"}, "book-100", "XBT/USD"]
[270, {"a": [["11873.70000", "0.00000000", "1596737181.947822"], ["11902.20000", "1.58369712", "1596737116.990726", "r"]], "c": "3817476865"}, "book-100", "XBT/USD"]
[270, {"b": [["11850.00000", "0.00000000", "1596737181.949749"], ["11801.80000", "3.19470719", "1596736911.648608", "r"]], "c": "1930572260"}, "book-100", "XBT/USD"]
[270, {"a": [["11878.20000", "7.20000000", "1596737181.951672"]], "c": "1930572260"}, "book-100", "XBT/USD"]
[270, {"b": [["11840.10000", "0.00000000", "1596737181.953604"], ["11800.80000", "1.51500000", "1596737133.991629", "r"]], "c": "1930572260"}, "book-100", "XBT/USD"]
[270, {"b": [["11844.20000", "0.00000000", "1596737181.955712"], ["11800.00000", "17.03324285", "1596736993.942623", "r"]], "c": "1930572260"}, "book-100", "XBT/USD"]
[270, {"a": [["11867.00000", "0.00000000", "1596737181.957563"], ["11903.50000", "2.17855852", "1596737179.380202", "r"]], "c": "1930572260"}, "book-100", "XBT/USD"]
[270, {"b": [["11843.90000", "0.00000000", "1596737181.959683"], ["11799.70000", "2.21032519", "1596737172.529407", "r"]], "c": "1930572260"}, "book-100", "XBT/USD"]
[270, {"a": [["11878.10000", "0.00000000", "1596737181.962151"], ["11904.00000", "0.17065000", "1596737071.292235", "r"]], "c": "1930572260"}, "book-100", "XBT/USD"]
[270, {"b": [["11844.40000", "0.00000000", "1596737181.963780"], ["11799.60000", "0.99110000", "1596737165.782615", "r"]], "c": "1930572260"}, "book-100", "XBT/USD"]
[270, {"b": [["11846.60000", "0.00000000", "1596737181.967780"], ["11799.20000", "23.14040000", "1596736141.974806", "r"]], "c": "1930572260"}, "book-100", "XBT/USD"]
[270, {"b": [["11841.30000", "0.00000000", "1596737181.969238"], ["11799.00000", "0.17065000", "1596737154.640974", "r"]], "c": "1930572260"}, "book-100", "XBT/USD"]
[270, {"b": [["11842.80000", "0.00000000", "1596737181.974649"], ["11798.60000", "18.30000000", "1596737089.559503", "r"]], "c": "1930572260"}, "book-100", "XBT/USD"]
[270, {"b": [["11840.90000", "0.38000000", "1596737181.976549"]], "c": "1930572260"}, "book-100", "XBT/USD"]
[270, {"b": [["11807.60000", "0.00000000", "1596737181.977464"], ["11797.90000", "6.30000000", "1596737122.404410", "r"]], "c": "1930572260"}, "book-100", "XBT/USD"]
[270, {"a": [["11858.60000", "0.00000000", "1596737181.983543"], ["11905.00000", "27.00000000", "1596736856.739074", "r"]], "c": "2568915803"}, "book-100", "XBT/USD"]
[270, {"b": [["11846.30000", "0.00000000", "1596737182.003154"], ["11796.30000", "10.90540000", "1596736141.718106", "r"]], "c": "2568915803"}, "book-100", "XBT/USD"]
[270, {"a": [["11858.50000", "0.82180000", "1596737182.028260"]], "c": "316068253"}, "book-100", "XBT/USD"]
[270, {"a": [["11858.90000", "0.00000000", "1596737182.032203"], ["11905.00000", "27.00000000", "1596736856.739074", "r"]], "c": "2226929608"}, "book-100", "XBT/USD"]
[270, {"b": [["11848.10000", "0.72915989", "1596737182.110987"]], "c": "2226929608"}, "book-100", "XBT/USD"]
[270, {"a": [["11879.70000", "0.10902042", "1596737182.111519"]], "c": "2226929608"}, "book-100", "XBT/USD"]
[270, {"b": [["11845.80000", "0.76532688", "1596737182.113722"]], "c": "2226929608"}, "book-100", "XBT/USD"]
[270, {"a": [["11863.90000", "1.67700000", "1596737182.157024"]], "c": "2226929608"}, "book-100", "XBT/USD"]
[270, {"b": [["11838.40000", "5.65305195", "1596737182.159036"]], "c": "2226929608"}, "book-100", "XBT/USD"]
[270, {"a": [["11895.50000", "2.33583970", "1596737182.183418"]], "c": "2226929608"}, "book-100", "XBT/USD"]
[270, {"b": [["11842.30000", "1.26825986", "1596737182.185223"]], "c": "2226929608"}, "book-100", "XBT/USD"]
[270, {"b": [["11816.40000", "0.96413102", "1596737182.186151"]], "c": "2226929608"}, "book-100", "XBT/USD"]
[270, {"b": [["11845.90000", "0.20462341", "1596737182.188387"]], "c": "2226929608"}, "book-100", "XBT/USD"]
[270, {"b": [["11816.20000", "0.94806613", "1596737182.275676"]], "c": "2226929608"}, "book-100", "XBT/USD"]
[270, {"b": [["11845.70000", "0.94570511", "1596737182.275992"]], "c": "2226929608"}, "book-100", "XBT/USD"]
[270, {"b": [["11838.40000", "5.50000000", "1596737182.305444"]], "c": "2226929608"}, "book-100", "XBT/USD"]
[270, {"b": [["11842.10000", "0.94599260", "1596737182.332957"]], "c": "2226929608"}, "book-100", "XBT/USD"]
[270, {"b": [["11843.40000", "3.27699954", "1596737182.344038"]], "c": "2226929608"}, "book-100", "XBT/USD"]
[270, {"b": [["11852.60000", "4.13586138", "1596737182.464011"]], "c": "3020121897"}, "book-100", "XBT/USD"]
[270, {"a": [["11863.10000", "0.00000000", "1596737182.520042"], ["11903.50000", "2.17855852", "1596737179.380202", "r"]], "c": "3020121897"}, "book-100", "XBT/USD"]
[270, {"a": [["11858.90000", "0.82180000", "1596737182.524472"]], "c": "577341820"}, "book-100", "XBT/USD"]
[270, {"a": [["11858.50000", "0.00000000", "1596737182.571810"], ["11903.50000", "2.17855852", "1596737179.380202", "r"]], "c": "2845955002"}, "book-100", "XBT/USD"]
[270, {"b": [["11838.60000", "6.49579788", "1596737182.612928"]], "c": "2845955002"}, "book-100", "XBT/USD"]
[270, {"b": [["11838.40000", "7.35043218", "1596737182.761681"]], "c": "2845955002"}, "book-100", "XBT/USD"]
[270, {"a": [["11874.50000", "0.32927964", "1596737182.804234"]], "c": "2845955002"}, "book-100", "XBT/USD"]
[270, {"b": [["11850.20000", "0.32995486", "1596737182.808127"]], "c": "2495900031"}, "book-100", "XBT/USD"]
[270, {"a": [["11877.90000", "0.69128932", "1596737182.808306"]], "c": "2495900031"}, "book-100", "XBT/USD"]
[270, {"b": [["11846.80000", "0.69310408", "1596737182.811584"]], "c": "2495900031"}, "book-100", "XBT/USD"]
[270, {"b": [["11852.40000", "0.33077684", "1596737182.958871"]], "c": "1294324236"}, "book-100", "XBT/USD"]
[270, {"b": [["11852.40000", "0.40409996", "1596737183.030999"]], "c": "2077929903"}, "book-100", "XBT/USD"]
[270, {"a": [["11867.70000", "0.01466462", "1596737183.031106"]], "c": "2077929903"}, "book-100", "XBT/USD"]
[270, {"b": [["11838.40000", "7.67789829", "1596737183.056061"]], "c": "2077929903"}, "book-100", "XBT/USD"]
[270, {"b": [["11850.80000", "0.17597549", "1596737183.094527"]], "c": "2597421814"}, "book-100", "XBT/USD"]
[270, {"a": [["11868.50000", "0.16582312", "1596737183.095852"]], "c": "2597421814"}, "book-100", "XBT/USD"]
[270, {"a": [["11869.50000", "0.17597549", "1596737183.160117"]], "c": "2597421814"}, "book-100", "XBT/USD"]
[270, {"a": [["11869.50000", "0.00000000", "1596737183.373710"], ["11901.80000", "0.75800000", "1596737130.968842", "r"]], "c": "2597421814"}, "book-100", "XBT/USD"]
[270, {"a": [["11870.80000", "0.17597549", "1596737183.584183"]], "c": "2597421814"}, "book-100", "XBT/USD"]
[270, {"a": [["11863.90000", "0.00000000", "1596737183.616761"], ["11901.80000", "0.75800000", "1596737130.968842", "r"]], "c": "2597421814"}, "book-100", "XBT/USD"]
[270, {"a": [["11863.00000", "1.68100000", "1596737183.745990"]], "c": "2597421814"}, "book-100", "XBT/USD"]
[270, {"a": [["11879.50000", "0.00438186", "1596737183.771899"]], "c": "2597421814"}, "book-100", "XBT/USD"]
[270, {"b": [["11838.70000", "0.27819576", "1596737183.771982"]], "c": "2597421814"}, "book-100", "XBT/USD"]
[270, {"b": [["11838.60000", "6.58561411", "1596737183.852296"]], "c": "2597421814"}, "book-100", "XBT/USD"]
[270, {"b": [["11838.60000", "6.73858633", "1596737183.853360"]], "c": "2597421814"}, "book-100", "XBT/USD"]
[270, {"b": [["11838.40000", "7.35043218", "1596737183.884261"]], "c": "2597421814"}, "book-100", "XBT/USD"]
[270, {"b": [["11838.40000", "5.50000000", "1596737183.884563"]], "c": "2597421814"}, "book-100", "XBT/USD"]
[270, {"a": [["11863.00000", "0.00000000", "1596737183.951720"], ["11901.50000", "3.26167975", "1596737133.218332", "r"]], "c": "2597421814"}, "book-100", "XBT/USD"]
[270, {"a": [["11858.80000", "0.70000000", "1596737184.020175"]], "c": "866597885"}, "book-100", "XBT/USD"]
[270, {"b": [["11838.60000", "8.91644783", "1596737184.040152"]], "c": "866597885"}, "book-100", "XBT/USD"]
[270, {"a": [["11858.70000", "0.82180000", "1596737184.079287"]], "c": "1576083150"}, "book-100", "XBT/USD"]
[270, {"a": [["11858.90000", "0.00000000", "1596737184.126548"], ["11901.40000", "1.90492467", "1596737138.167457", "r"]], "c": "1529295427"}, "book-100", "XBT/USD"]
[270, {"b": [["11840.60000", "0.00000000", "1596737184.208321"], ["11801.80000", "3.19470719", "1596736911.648608", "r"]], "c": "1529295427"}, "book-100", "XBT/USD"]
[270, {"a": [["11873.10000", "0.04400484", "1596737184.326448"]], "c": "1529295427"}, "book-100", "XBT/USD"]
[270, {"b": [["11838.60000", "8.97403688", "1596737184.495224"]], "c": "1529295427"}, "book-100", "XBT/USD"]
[270, {"b": [["11849.30000", "0.13201461", "1596737184.529953"]], "c": "1529295427"}, "book-100", "XBT/USD"]
[270, {"b": [["11852.40000", "0.44810477", "1596737184.570367"]], "c": "1289410745"}, "book-100", "XBT/USD"]
[270, {"a": [["11858.80000", "0.00000000", "1596737184.572369"], ["11901.40000", "1.90492467", "1596737138.167457", "r"]], "c": "3461770168"}, "book-100", "XBT/USD"]
[270, {"b": [["11838.60000", "6.79617538", "1596737184.580131"]], "c": "3461770168"}, "book-100", "XBT/USD"]
[270, {"b": [["11838.60000", "6.64320316", "1596737184.580399"]], "c": "3461770168"}, "book-100", "XBT/USD"]
[270, {"b": [["11852.60000", "4.37386138", "1596737184.586031"]], "c": "102892755"}, "book-100", "XBT/USD"]
[270, {"a": [["11863.10000", "1.67700000", "1596737184.587181"]], "c": "102892755"}, "book-100", "XBT/USD"]
[270, {"b": [["11838.60000", "6.58561411", "1596737184.642350"]], "c": "102892755"}, "book-100", "XBT/USD"]
[270, {"a": [["11858.90000", "0.82180000", "1596737184.649731"]], "c": "2420697734"}, "book-100", "XBT/USD"]
[270, {"a": [["11858.70000", "0.00000000", "1596737184.655490"], ["11901.20000", "0.05455260", "1596737145.299909", "r"]], "c": "1163396967"}, "book-100", "XBT/USD"]
[270, {"a": [["11883.10000", "0.78643045", "1596737184.698785"]], "c": "1163396967"}, "book-100", "XBT/USD"]
[270, {"a": [["11884.60000", "0.00000000", "1596737184.702251"], ["11901.40000", "1.90492467", "1596737138.167457", "r"]], "c": "1163396967"}, "book-100", "XBT/USD"]
[270, {"b": [["11821.00000", "0.73643045", "1596737184.702512"]], "c": "1163396967"}, "book-100", "XBT/USD"]
[270, {"b": [["11803.20000", "2.21029193", "1596737184.702699"]], "c": "1163396967"}, "book-100", "XBT/USD"]
[270, {"b": [["11821.90000", "0.00000000", "1596737184.702844"], ["11802.00000", "7.67065000", "1596737166.365862", "r"]], "c": "1163396967"}, "book-100", "XBT/USD"]
[270, {"a": [["11900.90000", "2.21029193", "1596737184.719140"]], "c": "1163396967"}, "book-100", "XBT/USD"]
[270, {"a": [["11879.60000", "0.00000000", "1596737184.759179"], ["11901.40000", "1.90492467", "1596737138.167457", "r"]], "c": "1163396967"}, "book-100", "XBT/USD"]
[270, {"b": [["11838.60000", "8.97401740", "1596737184.787092"]], "c": "1163396967"}, "book-100", "XBT/USD"]
[270, {"a": [["11859.70000", "0.04750000", "1596737184.829617"]], "c": "3262566205"}, "book-100", "XBT/USD"]
[270, {"a": [["11870.30000", "0.13201784", "1596737184.943484"]], "c": "3262566205"}, "book-100", "XBT/USD"]
[270, {"a": [["11879.80000", "0.54571311", "1596737184.945509"]], "c": "3262566205"}, "book-100", "XBT/USD"]
[270, {"a": [["11858.50000", "0.25000000", "1596737185.076566"]], "c": "415571968"}, "book-100", "XBT/USD"]
[270, {"b": [["11847.90000", "0.00000000", "1596737185.112321"], ["11801.90000", "4.67249674", "1596736908.903243", "r"]], "c": "415571968"}, "book-100", "XBT/USD"]
[270, {"a": [["11858.40000", "0.82180000", "1596737185.135568"]], "c": "571219232"}, "book-100", "XBT/USD"]
[270, {"a": [["11858.90000", "0.00000000", "1596737185.137284"], ["11900.90000", "2.21029193", "1596737184.719140", "r"]], "c": "1859660787"}, "book-100", "XBT/USD"]
[270, {"a": [["11868.30000", "2.43944939", "1596737185.185014"]], "c": "1859660787"}, "book-100", "XBT/USD"]
[270, {"b": [["11852.60000", "3.75409138", "1596737185.217951"]], "c": "1738423923"}, "book-100", "XBT/USD"]
[270, {"a": [["11863.50000", "0.95172000", "1596737185.219425"]], "c": "1738423923"}, "book-100", "XBT/USD"]
[270, {"b": [["11838.60000", "9.15874565", "1596737185.327355"]], "c": "1738423923"}, "book-100", "XBT/USD"]
[270, {"a": [["11871.60000", "0.00000000", "1596737185.329209"], ["11900.00000", "12.71653131", "1596737075.897027", "r"]], "c": "1738423923"}, "book-100", "XBT/USD"]
[270, {"a": [["11879.50000", "0.00000000", "1596737185.367871"], ["11900.90000", "2.21029193", "1596737184.719140", "r"]], "c": "1738423923"}, "book-100", "XBT/USD"]
[270, {"b": [["11838.70000", "0.27395984", "1596737185.368129"]], "c": "1738423923"}, "book-100", "XBT/USD"]
[270, {"a": [["11860.80000", "4.20900000", "1596737185.619069"]], "c": "2753017693"}, "book-100", "XBT/USD"]
[270, {"b": [["11852.60000", "3.67409138", "1596737185.635507"]], "c": "2759013520"}, "book-100", "XBT/USD"]
[270, {"a": [["11858.10000", "0.63230652", "1596737185.677160"]], "c": "2494966127"}, "book-100", "XBT/USD"]
[270, {"a": [["11858.00000", "0.82180000", "1596737185.729072"]], "c": "616439294"}, "book-100", "XBT/USD"]
[270, {"a": [["11858.40000", "0.00000000", "1596737185.736611"], ["11900.00000", "12.71653131", "1596737075.897027", "r"]], "c": "2296298488"}, "book-100", "XBT/USD"]
[270, {"b": [["11838.60000", "8.97401740", "1596737185.871356"]], "c": "2296298488"}, "book-100", "XBT/USD"]
[270, {"b": [["11838.60000", "6.58561411", "1596737185.871973"]], "c": "2296298488"}, "book-100", "XBT/USD"]
[270, {"b": [["11838.40000", "7.99963376", "1596737186.019865"]], "c": "2296298488"}, "book-100", "XBT/USD"]
[270, {"a": [["11863.10000", "0.00000000", "1596737186.123056"], ["11900.90000", "2.21029193", "1596737184.719140", "r"]], "c": "2296298488"}, "book-100", "XBT/USD"]
[270, {"b": [["11838.40000", "8.13659788", "1596737186.194949"]], "c": "2296298488"}, "book-100", "XBT/USD"]
[270, {"b": [["11844.40000", "1.38654735", "1596737186.302648"]], "c": "2296298488"}, "book-100", "XBT/USD"]
[270, {"b": [["11838.40000", "7.99963376", "1596737186.338949"]], "c": "2296298488"}, "book-100", "XBT/USD"]
[270, {"b": [["11838.60000", "6.71877984", "1596737186.484685"]], "c": "2296298488"}, "book-100", "XBT/USD"]
[270, {"b": [["11852.60000", "3.52409138", "1596737186.821398"]], "c": "3981049950"}, "book-100", "XBT/USD"]
[270, {"a": [["11857.90000", "0.70000000", "1596737186.872037"]], "c": "3068288031"}, "book-100", "XBT/USD"]
[270, {"b": [["11851.80000", "0.15000000", "1596737186.884730"]], "c": "2478927053"}, "book-100", "XBT/USD"]
[270, {"a": [["11858.30000", "0.39000000", "1596737186.888112"]], "c": "2201410688"}, "book-100", "XBT/USD"]
[270, {"b": [["11838.60000", "6.58561411", "1596737186.904620"]], "c": "2201410688"}, "book-100", "XBT/USD"]
[270, {"b": [["11838.40000", "5.50000000", "1596737186.904970"]], "c": "2201410688"}, "book-100", "XBT/USD"]
[270, {"a": [["11858.00000", "0.00000000", "1596737186.970640"], ["11900.00000", "12.71653131", "1596737075.897027", "r"]], "c": "679167792"}, "book-100", "XBT/USD"]
[270, {"a": [["11857.90000", "0.80200000", "1596737187.053238"]], "c": "2387492638"}, "book-100", "XBT/USD"]
[270, {"b": [["11838.60000", "9.34202607", "1596737187.111296"]], "c": "2387492638"}, "book-100", "XBT/USD"]
[270, {"a": [["11857.90000", "0.10200000", "1596737187.164993"]], "c": "4072757244"}, "book-100", "XBT/USD"]
[270, {"b": [["11838.60000", "6.58561411", "1596737187.264094"]], "c": "4072757244"}, "book-100", "XBT/USD"]
[270, {"b": [["11838.40000", "7.71123651", "1596737187.414306"]], "c": "4072757244"}, "book-100", "XBT/USD"]
[270, {"a": [["11866.60000", "0.84291834", "1596737187.459638"]], "c": "4072757244"}, "book-100", "XBT/USD"]
[270, {"b": [["11838.40000", "5.50000000", "1596737187.558696"]], "c": "4072757244"}, "book-100", "XBT/USD"]
[270, {"a": [["11869.00000", "0.87298445", "1596737187.650625"]], "c": "4072757244"}, "book-100", "XBT/USD"]
[270, {"a": [["11857.80000", "0.82180000", "1596737187.760543"]], "c": "1910590233"}, "book-100", "XBT/USD"]
[270, {"b": [["11848.10000", "0.62715989", "1596737187.790236"]], "c": "1910590233"}, "book-100", "XBT/USD"]
[270, {"a": [["11856.80000", "0.38500000", "1596737187.980269"]], "c": "3926022807"}, "book-100", "XBT/USD"]
[270, {"a": [["11869.00000", "0.18315000", "1596737188.029243"]], "c": "3926022807"}, "book-100", "XBT/USD"]
[270, {"a": [["11868.90000", "0.66496951", "1596737188.218420"]], "c": "3926022807"}, "book-100", "XBT/USD"]
[270, {"a": [["11858.30000", "0.00000000", "1596737188.405400"], ["11899.90000", "7.61000000", "1596737079.466913", "r"]], "c": "4110079189"}, "book-100", "XBT/USD"]
[270, {"a": [["11888.40000", "0.00000000", "1596737188.468995"], ["11900.00000", "12.71653131", "1596737075.897027", "r"]], "c": "4110079189"}, "book-100", "XBT/USD"]
[270, {"a": [["11856.80000", "1.20680000", "1596737188.574869"]], "c": "1687744234"}, "book-100", "XBT/USD"]
[270, {"a": [["11857.80000", "0.00000000", "1596737188.584605"], ["11900.90000", "2.21029193", "1596737184.719140", "r"]], "c": "2803425972"}, "book-100", "XBT/USD"]
[270, {"a": [["11868.90000", "0.01800000", "1596737188.641661"]], "c": "2803425972"}, "book-100", "XBT/USD"]
[270, {"a": [["11869.20000", "0.00000000", "1596737188.741995"], ["11901.00000", "0.17065000", "1596737120.047779", "r"]], "c": "2803425972"}, "book-100", "XBT/USD"]
[270, {"b": [["11845.70000", "0.00000000", "1596737188.790666"], ["11802.00000", "7.67065000", "1596737166.365862", "r"]], "c": "2803425972"}, "book-100", "XBT/USD"]
[270, {"a": [["11867.20000", "0.69357375", "1596737188.807797"]], "c": "2803425972"}, "book-100", "XBT/USD"]
[270, {"b": [["11848.10000", "0.51784870", "1596737188.810024"]], "c": "2803425972"}, "book-100", "XBT/USD"]
[270, {"b": [["11850.20000", "0.00000000", "1596737188.817892"], ["11801.90000", "4.67249674", "1596736908.903243", "r"]], "c": "3448884092"}, "book-100", "XBT/USD"]
[270, {"b": [["11849.90000", "0.00000000", "1596737188.914598"], ["11801.80000", "3.19470719", "1596736911.648608", "r"]], "c": "497036080"}, "book-100", "XBT/USD"]
[270, {"b": [["11852.60000", "3.42409138", "1596737189.002264"]], "c": "3980033948"}, "book-100", "XBT/USD"]
[270, {"a": [["11856.80000", "0.38500000", "1596737189.030502"]], "c": "1540108443"}, "book-100", "XBT/USD"]
[270, {"b": [["11843.60000", "0.94591268", "1596737189.038964"]], "c": "1540108443"}, "book-100", "XBT/USD"]
[270, {"a": [["11868.60000", "0.69416301", "1596737189.056830"]], "c": "1540108443"}, "book-100", "XBT/USD"]
[270, {"b": [["11846.20000", "0.10931951", "1596737189.119042"]], "c": "1540108443"}, "book-100", "XBT/USD"]
[270, {"b": [["11851.80000", "0.00000000", "1596737189.166471"], ["11801.90000", "4.67249674", "1596736908.903243", "r"]], "c": "3585274859"}, "book-100", "XBT/USD"]
[270, {"a": [["11861.10000", "0.84734000", "1596737189.205542"]], "c": "3585274859"}, "book-100", "XBT/USD"]
[270, {"b": [["11851.70000", "2.97960388", "1596737189.256587"]], "c": "1996015530"}, "book-100", "XBT/USD"]
[270, {"a": [["11862.10000", "3.18553149", "1596737189.275151"]], "c": "1996015530"}, "book-100", "XBT/USD"]
[270, {"b": [["11849.70000", "0.32998267", "1596737189.581585"]], "c": "3112754512"}, "book-100", "XBT/USD"]
[270, {"a": [["11856.70000", "0.82180000", "1596737189.585024"]], "c": "2314078396"}, "book-100", "XBT/USD"]
[270, {"a": [["11856.60000", "0.82180000", "1596737189.640633"]], "c": "3501907632"}, "book-100", "XBT/USD"]
[270, {"b": [["11825.40000", "0.00000000", "1596737189.641305"], ["11801.90000", "4.67249674", "1596736908.903243", "r"]], "c": "3501907632"}, "book-100", "XBT/USD"]
[270, {"a": [["11856.70000", "0.00000000", "1596737189.652314"], ["11899.90000", "7.61000000", "1596737079.466913", "r"]], "c": "2293685272"}, "book-100", "XBT/USD"]
[270, {"a": [["11888.30000", "0.50000000", "1596737189.653070"]], "c": "2293685272"}, "book-100", "XBT/USD"]
[270, {"a": [["11868.60000", "0.04440539", "1596737189.947068"]], "c": "2293685272"}, "book-100", "XBT/USD"]
[270, {"b": [["11843.10000", "0.00000000", "1596737189.948401"], ["11801.80000", "3.19470719", "1596736911.648608", "r"]], "c": "2293685272"}, "book-100", "XBT/USD"]
[270, {"a": [["11868.90000", "0.00000000", "1596737190.016477"], ["11899.90000", "7.61000000", "1596737079.466913", "r"]], "c": "2293685272"}, "book-100", "XBT/USD"]
[270, {"a": [["11857.80000", "0.82180000", "1596737190.024340"]], "c": "2880582800"}, "book-100", "XBT/USD"]
[270, {"a": [["11856.60000", "0.00000000", "1596737190.071542"], ["11899.90000", "7.61000000", "1596737079.466913", "r"]], "c": "1553769526"}, "book-100", "XBT/USD"]
[270, {"a": [["11856.50000", "0.70000000", "1596737190.079204"]], "c": "3130746837"}, "book-100", "XBT/USD"]
[270, {"a": [["11867.10000", "0.66226625", "1596737190.084326"]], "c": "3130746837"}, "book-100", "XBT/USD"]
[270, {"a": [["11868.90000", "0.01800000", "1596737190.108200"]], "c": "3130746837"}, "book-100", "XBT/USD"]
[270, {"a": [["11856.50000", "0.00000000", "1596737190.124927"], ["11899.00000", "2.81849664", "1596737063.692951", "r"]], "c": "1553769526"}, "book-100", "XBT/USD"]
[270, {"a": [["11867.70000", "0.00000000", "1596737190.137415"], ["11899.10000", "7.82927162", "1596737145.805987", "r"]], "c": "1553769526"}, "book-100", "XBT/USD"]
[270, {"b": [["11850.80000", "0.00000000", "1596737190.197922"], ["11800.80000", "1.51500000", "1596737133.991629", "r"]], "c": "1598156338"}, "book-100", "XBT/USD"]
[270, {"a": [["11868.50000", "0.09250000", "1596737190.198219"]], "c": "1598156338"}, "book-100", "XBT/USD"]
[270, {"a": [["11866.10000", "0.01466462", "1596737190.339233"]], "c": "1598156338"}, "book-100", "XBT/USD"]
[270, {"a": [["11866.80000", "0.07332312", "1596737190.398679"]], "c": "1598156338"}, "book-100", "XBT/USD"]
[270, {"a": [["11856.50000", "0.39500000", "1596737190.589920"]], "c": "1746434116"}, "book-100", "XBT/USD"]
[270, {"a": [["11857.80000", "0.00000000", "1596737190.663916"], ["11898.70000", "0.01000000", "1596737133.560066", "r"]], "c": "1174530915"}, "book-100", "XBT/USD"]
[270, {"a": [["11856.70000", "0.82180000", "1596737190.966916"]], "c": "319853156"}, "book-100", "XBT/USD"]
[270, {"a": [["11856.40000", "0.82180000", "1596737191.022406"]], "c": "989436447"}, "book-100", "XBT/USD"]
[270, {"b": [["11843.10000", "0.02300000", "1596737191.092956"]], "c": "989436447"}, "book-100", "XBT/USD"]
[270, {"b": [["11851.40000", "0.17597549", "1596737191.103068"]], "c": "3047482588"}, "book-100", "XBT/USD"]
[270, {"a": [["11870.80000", "0.00000000", "1596737191.115031"], ["11898.30000", "6.46320506", "1596737141.628854", "r"]], "c": "3047482588"}, "book-100", "XBT/USD"]
[270, {"a": [["11856.80000", "0.00000000", "1596737191.115165"], ["11898.70000", "0.01000000", "1596737133.560066", "r"]], "c": "1318992738"}, "book-100", "XBT/USD"]
[270, {"a": [["11883.10000", "0.05000000", "1596737191.139814"]], "c": "1318992738"}, "book-100", "XBT/USD"]
[270, {"b": [["11821.00000", "0.00000000", "1596737191.144401"], ["11801.80000", "3.19470719", "1596736911.648608", "r"]], "c": "1318992738"}, "book-100", "XBT/USD"]
[270, {"b": [["11821.70000", "0.73639959", "1596737191.146898"]], "c": "1318992738"}, "book-100", "XBT/USD"]
[270, {"a": [["11856.70000", "0.00000000", "1596737191.154940"], ["11899.00000", "2.81849664", "1596737063.692951", "r"]], "c": "340169329"}, "book-100", "XBT/USD"]
[270, {"a": [["11882.80000", "0.73639959", "1596737191.159481"]], "c": "340169329"}, "book-100", "XBT/USD"]
[270, {"a": [["11867.10000", "0.83824174", "1596737191.374691"]], "c": "340169329"}, "book-100", "XBT/USD"]
[270, {"a": [["11873.10000", "0.00000000", "1596737191.430315"], ["11899.00000", "2.81849664", "1596737063.692951", "r"]], "c": "340169329"}, "book-100", "XBT/USD"]
[270, {"a": [["11857.80000", "0.82180000", "1596737191.526271"]], "c": "374144706"}, "book-100", "XBT/USD"]
[270, {"a": [["11867.10000", "0.17597549", "1596737191.579902"]], "c": "374144706"}, "book-100", "XBT/USD"]
[270, {"b": [["11849.30000", "0.00000000", "1596737191.635303"], ["11801.80000", "3.19470719", "1596736911.648608", "r"]], "c": "374144706"}, "book-100", "XBT/USD"]
[270, {"a": [["11869.60000", "0.04400393", "1596737191.636221"]], "c": "374144706"}, "book-100", "XBT/USD"]
[270, {"a": [["11867.00000", "0.67003680", "1596737191.698856"]], "c": "374144706"}, "book-100", "XBT/USD"]
[270, {"b": [["11850.50000", "0.13201187", "1596737191.834837"]], "c": "281740699"}, "book-100", "XBT/USD"]
[270, {"a": [["11879.70000", "0.11340228", "1596737191.952802"]], "c": "281740699"}, "book-100", "XBT/USD"]
[270, {"a": [["11856.40000", "0.00000000", "1596737192.050537"], ["11898.30000", "6.46320506", "1596737141.628854", "r"]], "c": "38351192"}, "book-100", "XBT/USD"]
[270, {"a": [["11858.50000", "0.00000000", "1596737192.135453"], ["11898.70000", "0.01000000", "1596737133.560066", "r"]], "c": "1116461827"}, "book-100", "XBT/USD"]
[270, {"a": [["11872.20000", "0.00000000", "1596737192.146229"], ["11899.00000", "2.81849664", "1596737063.692951", "r"]], "c": "1116461827"}, "book-100", "XBT/USD"]
[270, {"a": [["11856.80000", "0.82180000", "1596737192.210382"]], "c": "4047347946"}, "book-100", "XBT/USD"]
[270, {"a": [["11852.70000", "0.81476198", "1596737192.253018"]], "c": "387588814"}, "book-100", "XBT/USD"]
[270, {"a": [["11857.80000", "0.00000000", "1596737192.266376"], ["11899.00000", "2.81849664", "1596737063.692951", "r"]], "c": "3406034345"}, "book-100", "XBT/USD"]
[270, {"b": [["11845.80000", "0.00000000", "1596737192.312079"], ["11801.80000", "3.19470719", "1596736911.648608", "r"]], "c": "3406034345"}, "book-100", "XBT/USD"]
[270, {"a": [["11857.90000", "0.35200000", "1596737192.314974"]], "c": "2206132449"}, "book-100", "XBT/USD"]
[270, {"a": [["11853.40000", "0.03374559", "1596737192.332726"]], "c": "934080175"}, "book-100", "XBT/USD"]
[270, {"b": [["11852.40000", "0.40409996", "1596737192.333944"]], "c": "542180437"}, "book-100", "XBT/USD"]
[270, {"a": [["11859.00000", "0.00000000", "1596737192.354319"], ["11899.00000", "2.81849664", "1596737063.692951", "r"]], "c": "3020864988"}, "book-100", "XBT/USD"]
[270, {"a": [["11871.70000", "0.00000000", "1596737192.354460"], ["11899.10000", "7.82927162", "1596737145.805987", "r"]], "c": "3020864988"}, "book-100", "XBT/USD"]
[270, {"a": [["11858.10000", "0.00000000", "1596737192.354739"], ["11899.90000", "7.61000000", "1596737079.466913", "r"]], "c": "1830448929"}, "book-100", "XBT/USD"]
[270, {"a": [["11868.50000", "0.00000000", "1596737192.378756"], ["11900.00000", "12.71653131", "1596737075.897027", "r"]], "c": "1830448929"}, "book-100", "XBT/USD"]
[270, {"a": [["11856.40000", "0.70000000", "1596737192.383387"]], "c": "3932586554"}, "book-100", "XBT/USD"]
[270, {"b": [["11848.10000", "0.42163776", "1596737192.398294"]], "c": "3932586554"}, "book-100", "XBT/USD"]
[270, {"b": [["11852.40000", "0.33077684", "1596737192.402587"]], "c": "3701072281"}, "book-100", "XBT/USD"]
[270, {"b": [["11847.10000", "0.00000000", "1596737192.457259"], ["11800.80000", "1.51500000", "1596737133.991629", "r"]], "c": "3701072281"}, "book-100", "XBT/USD"]
[270, {"b": [["11843.40000", "4.16328954", "1596737192.457415"]], "c": "3701072281"}, "book-100", "XBT/USD"]
[270, {"a": [["11856.40000", "0.00000000", "1596737192.478951"], ["11900.00000", "12.71653131", "1596737075.897027", "r"]], "c": "1541737602"}, "book-100", "XBT/USD"]
[270, {"a": [["11869.40000", "0.28399999", "1596737192.481399"]], "c": "1541737602"}, "book-100", "XBT/USD"]
[270, {"a": [["11860.80000", "0.00000000", "1596737192.485601"], ["11900.00000", "12.71653131", "1596737075.897027", "r"]], "c": "1541737602"}, "book-100", "XBT/USD"]
[270, {"b": [["11845.90000", "0.00000000", "1596737192.493060"], ["11800.00000", "17.03324285", "1596736993.942623", "r"]], "c": "1541737602"}, "book-100", "XBT/USD"]
[270, {"b": [["11849.70000", "0.00000000", "1596737192.493291"], ["11799.60000", "0.99110000", "1596737165.782615", "r"]], "c": "1368241258"}, "book-100", "XBT/USD"]
[270, {"a": [["11858.00000", "4.21600000", "1596737192.494013"]], "c": "1602719023"}, "book-100", "XBT/USD"]
[270, {"a": [["11856.80000", "0.00000000", "1596737192.531757"], ["11900.00000", "12.71653131", "1596737075.897027", "r"]], "c": "243233437"}, "book-100", "XBT/USD"]
[270, {"b": [["11852.60000", "1.74309138", "1596737192.569621"]], "c": "3667681692"}, "book-100", "XBT/USD"]
[270, {"a": [["11862.10000", "2.52681131", "1596737192.571277"]], "c": "3667681692"}, "book-100", "XBT/USD"]
[270, {"a": [["11890.50000", "0.09250000", "1596737192.580718"]], "c": "3667681692"}, "book-100", "XBT/USD"]
[270, {"a": [["11858.00000", "0.00000000", "1596737192.591126"], ["11900.00000", "12.71653131", "1596737075.897027", "r"]], "c": "202621968"}, "book-100", "XBT/USD"]
[270, {"a": [["11857.90000", "1.23829000", "1596737192.603129"]], "c": "409957999"}, "book-100", "XBT/USD"]
[270, {"b": [["11851.70000", "2.82960388", "1596737192.610153"]], "c": "3139781166"}, "book-100", "XBT/USD"]
[270, {"b": [["11850.00000", "0.04397887", "1596737192.615956"]], "c": "1152897599"}, "book-100", "XBT/USD"]
[270, {"b": [["11851.40000", "0.00000000", "1596737192.617250"], ["11799.60000", "0.99110000", "1596737165.782615", "r"]], "c": "3952431331"}, "book-100", "XBT/USD"]
[270, {"b": [["11850.50000", "0.00000000", "1596737192.623382"], ["11799.20000", "23.14040000", "1596736141.974806", "r"]], "c": "2397035555"}, "book-100", "XBT/USD"]
[270, {"a": [["11859.60000", "0.00000000", "1596737192.625666"], ["11900.90000", "2.21029193", "1596737184.719140", "r"]], "c": "2447626783"}, "book-100", "XBT/USD"]
[270, {"a": [["11856.30000", "0.82180000", "1596737192.637108"]], "c": "1455539923"}, "book-100", "XBT/USD"]
[270, {"a": [["11870.30000", "0.00000000", "1596737192.661210"], ["11900.90000", "2.21029193", "1596737184.719140", "r"]], "c": "1455539923"}, "book-100", "XBT/USD"]
[270, {"a": [["11855.80000", "0.63242201", "1596737192.687680"]], "c": "1867337185"}, "book-100", "XBT/USD"]
[270, {"a": [["11856.50000", "1.02742201", "1596737192.689009"]], "c": "4200379788"}, "book-100", "XBT/USD"]
[270, {"a": [["11861.60000", "0.84312415", "1596737192.690557"]], "c": "4200379788"}, "book-100", "XBT/USD"]
[270, {"a": [["11859.00000", "0.84322935", "1596737192.691056"]], "c": "1459995077"}, "book-100", "XBT/USD"]
[270, {"b": [["11843.40000", "4.36797545", "1596737192.732080"]], "c": "1459995077"}, "book-100", "XBT/USD"]
[270, {"b": [["11851.20000", "0.17597549", "1596737192.816044"]], "c": "3733910560"}, "book-100", "XBT/USD"]
[270, {"b": [["11846.80000", "0.00000000", "1596737192.822792"], ["11799.20000", "23.14040000", "1596736141.974806", "r"]], "c": "3733910560"}, "book-100", "XBT/USD"]
[270, {"b": [["11849.00000", "0.13202188", "1596737192.833296"]], "c": "3733910560"}, "book-100", "XBT/USD"]
[270, {"a": [["11867.90000", "0.13202188", "1596737192.834160"]], "c": "3733910560"}, "book-100", "XBT/USD"]
[270, {"a": [["11860.90000", "0.93645860", "1596737192.837588"]], "c": "3733910560"}, "book-100", "XBT/USD"]
[270, {"b": [["11848.50000", "0.38066299", "1596737192.894282"]], "c": "3733910560"}, "book-100", "XBT/USD"]
[270, {"a": [["11860.90000", "0.65245861", "1596737192.900985"]], "c": "3733910560"}, "book-100", "XBT/USD"]
[270, {"b": [["11851.20000", "0.32597549", "1596737192.959584"]], "c": "1919669871"}, "book-100", "XBT/USD"]
[270, {"b": [["11825.10000", "7.50000000", "1596737193.000084"]], "c": "1919669871"}, "book-100", "XBT/USD"]
[270, {"a": [["11856.30000", "0.00000000", "1596737193.030953"], ["11899.10000", "7.82927162", "1596737145.805987", "r"]], "c": "1317367924"}, "book-100", "XBT/USD"]
[270, {"a": [["11857.20000", "0.63234311", "1596737193.086494"]], "c": "2333219056"}, "book-100", "XBT/USD"]
[270, {"b": [["11851.40000", "0.07332312", "1596737193.121892"]], "c": "3017186839"}, "book-100", "XBT/USD"]
[270, {"b": [["11842.40000", "0.76553371", "1596737193.151732"]], "c": "3017186839"}, "book-100", "XBT/USD"]
[270, {"b": [["11852.60000", "1.82746070", "1596737193.205431"]], "c": "490445107"}, "book-100", "XBT/USD"]
[270, {"a": [["11855.70000", "0.82180000", "1596737193.206780"]], "c": "3235354818"}, "book-100", "XBT/USD"]
[270, {"a": [["11855.80000", "0.00000000", "1596737193.291079"], ["11899.00000", "2.81849664", "1596737063.692951", "r"]], "c": "3530811888"}, "book-100", "XBT/USD"]
[270, {"a": [["11892.00000", "0.17065000", "1596737193.303945"]], "c": "3530811888"}, "book-100", "XBT/USD"]
[270, {"a": [["11858.50000", "4.20400000", "1596737193.320449"]], "c": "3907458838"}, "book-100", "XBT/USD"]
[270, {"b": [["11845.40000", "0.69324436", "1596737193.394327"]], "c": "3907458838"}, "book-100", "XBT/USD"]
[270, {"a": [["11856.90000", "0.00000000", "1596737193.421759"], ["11898.70000", "0.01000000", "1596737133.560066", "r"]], "c": "2330529389"}, "book-100", "XBT/USD"]
[270, {"b": [["11845.70000", "0.09621094", "1596737193.445139"]], "c": "2330529389"}, "book-100", "XBT/USD"]
[270, {"a": [["11895.50000", "0.00000000", "1596737193.452099"], ["11899.00000", "2.81849664", "1596737063.692951", "r"]], "c": "2330529389"}, "book-100", "XBT/USD"]
[270, {"b": [["11851.20000", "0.15000000", "1596737193.497962"]], "c": "2439625535"}, "book-100", "XBT/USD"]
[270, {"a": [["11856.40000", "0.82180000", "1596737193.523033"]], "c": "2551759119"}, "book-100", "XBT/USD"]
[270, {"a": [["11855.70000", "0.00000000", "1596737193.531450"], ["11899.00000", "2.81849664", "1596737063.692951", "r"]], "c": "135063919"}, "book-100", "XBT/USD"]
[270, {"a": [["11859.70000", "0.00000000", "1596737193.544228"], ["11899.10000", "7.82927162", "1596737145.805987", "r"]], "c": "3975613502"}, "book-100", "XBT/USD"]
[270, {"a": [["11854.50000", "0.09621094", "1596737193.548781"]], "c": "2984579102"}, "book-100", "XBT/USD"]
[270, {"a": [["11890.60000", "2.10531638", "1596737193.634192"]], "c": "2984579102"}, "book-100", "XBT/USD"]
[270, {"a": [["11867.00000", "0.00000000", "1596737193.690078"], ["11899.00000", "2.81849664", "1596737063.692951", "r"]], "c": "2984579102"}, "book-100", "XBT/USD"]
[270, {"b": [["11850.50000", "0.17597549", "1596737193.744730"]], "c": "3034743105"}, "book-100", "XBT/USD"]
[270, {"a": [["11858.40000", "0.04750000", "1596737194.165520"]], "c": "2459239247"}, "book-100", "XBT/USD"]
[270, {"a": [["11866.60000", "1.53164508", "1596737194.215449"]], "c": "2459239247"}, "book-100", "XBT/USD"]
[270, {"a": [["11856.50000", "0.63242201", "1596737194.333958"]], "c": "1057898189"}, "book-100", "XBT/USD"]
[270, {"b": [["11802.00000", "7.50000000", "1596737194.335118"]], "c": "1057898189"}, "book-100", "XBT/USD"]
[270, {"b": [["11852.60000", "1.58946070", "1596737194.422635"]], "c": "593469503"}, "book-100", "XBT/USD"]
[270, {"b": [["11831.20000", "0.23800000", "1596737194.473608"]], "c": "593469503"}, "book-100", "XBT/USD"]
[270, {"a": [["11879.80000", "0.00000000", "1596737194.529216"], ["11899.00000", "2.81849664", "1596737063.692951", "r"]], "c": "593469503"}, "book-100", "XBT/USD"]
[270, {"a": [["11890.60000", "0.00000000", "1596737194.603084"], ["11899.10000", "7.82927162", "1596737145.805987", "r"]], "c": "593469503"}, "book-100", "XBT/USD"]
[271, [["11852.70000", "0.01092916", "1596737194.726585", "b", "l", ""]], "trade", "XBT/USD"]
[270, {"a": [["11852.70000", "0.80383282", "1596737194.726585"]], "c": "1732628610"}, "book-100", "XBT/USD"]
[270, {"a": [["11879.80000", "0.59810856", "1596737194.791298"]], "c": "1732628610"}, "book-100", "XBT/USD"]
[270, {"a": [["11890.60000", "2.11173316", "1596737194.792128"]], "c": "1732628610"}, "book-100", "XBT/USD"]
[270, {"a": [["11856.30000", "0.70000000", "1596737194.825849"]], "c": "3244240792"}, "book-100", "XBT/USD"]
[270, {"b": [["11852.30000", "5.89800000", "1596737194.879683"]], "c": "3514987925"}, "book-100", "XBT/USD"]
[270, {"a": [["11862.10000", "0.84281131", "1596737194.888635"]], "c": "3514987925"}, "book-100", "XBT/USD"]
[270, {"a": [["11856.40000", "0.00000000", "1596737194.889041"], ["11898.70000", "0.01000000", "1596737133.560066", "r"]], "c": "1628420873"}, "book-100", "XBT/USD"]
[270, {"a": [["11860.70000", "1.68300000", "1596737194.912335"]], "c": "1628420873"}, "book-100", "XBT/USD"]
[270, {"a": [["11856.30000", "0.00000000", "1596737194.940740"], ["11898.70000", "0.01000000", "1596737133.560066", "r"]], "c": "847285379"}, "book-100", "XBT/USD"]
[270, {"a": [["11856.20000", "0.82180000", "1596737194.980093"]], "c": "3627655175"}, "book-100", "XBT/USD"]
[270, {"a": [["11856.40000", "0.82180000", "1596737195.034639"]], "c": "1756655259"}, "book-100", "XBT/USD"]
[270, {"a": [["11856.20000", "0.00000000", "1596737195.041802"], ["11898.30000", "6.46320506", "1596737141.628854", "r"]], "c": "2006485647"}, "book-100", "XBT/USD"]
[270, {"a": [["11854.40000", "0.35500000", "1596737195.082369"]], "c": "3192490169"}, "book-100", "XBT/USD"]
[270, {"a": [["11879.70000", "0.10902042", "1596737195.139655"]], "c": "3192490169"}, "book-100", "XBT/USD"]
[270, {"b": [["11837.60000", "0.00429560", "1596737195.140692"]], "c": "3192490169"}, "book-100", "XBT/USD"]
[270, {"a": [["11860.70000", "0.00000000", "1596737195.141534"], ["11898.30000", "6.46320506", "1596737141.628854", "r"]], "c": "3192490169"}, "book-100", "XBT/USD"]
[270, {"a": [["11858.60000", "0.63238963", "1596737195.200457"]], "c": "3192490169"}, "book-100", "XBT/USD"]
[270, {"b": [["11803.60000", "5.42940469", "1596737195.329825"]], "c": "3192490169"}, "book-100", "XBT/USD"]
[270, {"b": [["11803.20000", "0.00000000", "1596737195.332794"], ["11802.10000", "4.23653417", "1596737132.953878", "r"]], "c": "3192490169"}, "book-100", "XBT/USD"]
[270, {"b": [["11848.30000", "0.00000000", "1596737196.161525"], ["11802.00000", "7.50000000", "1596737194.335118", "r"]], "c": "3192490169"}, "book-100", "XBT/USD"]
[270, {"b": [["11843.30000", "0.52738232", "1596737196.172652"]], "c": "3192490169"}, "book-100", "XBT/USD"]
[270, {"a": [["11858.60000", "0.00000000", "1596737196.228023"], ["11898.30000", "6.46320506", "1596737141.628854", "r"]], "c": "3192490169"}, "book-100", "XBT/USD"]
[270, {"a": [["11852.70000", "1.30383282", "1596737196.384834"]], "c": "51227539"}, "book-100", "XBT/USD"]
[270, {"b": [["11852.60000", "1.08946070", "1596737196.384917"]], "c": "2890328960"}, "book-100", "XBT/USD"]
[270, {"b": [["11851.20000", "0.00000000", "1596737196.385606"], ["11802.00000", "7.50000000", "1596737194.335118", "r"]], "c": "1081002751"}, "book-100", "XBT/USD"]
[270, {"b": [["11852.30000", "4.21300000", "1596737196.387314"]], "c": "1196334437"}, "book-100", "XBT/USD"]
[270, {"a": [["11857.20000", "0.00000000", "1596737196.389239"], ["11898.70000", "0.01000000", "1596737133.560066", "r"]], "c": "3303046778"}, "book-100", "XBT/USD"]
[270, {"b": [["11848.50000", "0.05063300", "1596737196.407321"]], "c": "3303046778"}, "book-100", "XBT/USD"]
[270, {"b": [["11845.40000", "0.00000000", "1596737196.410430"], ["11801.90000", "4.67249674", "1596736908.903243", "r"]], "c": "3303046778"}, "book-100", "XBT/USD"]
[270, {"b": [["11844.40000", "0.00000000", "1596737196.412070"], ["11801.80000", "3.19470719", "1596736911.648608", "r"]], "c": "3303046778"}, "book-100", "XBT/USD"]
[270, {"b": [["11846.20000", "0.00000000", "1596737196.428019"], ["11800.80000", "1.51500000", "1596737133.991629", "r"]], "c": "3303046778"}, "book-100", "XBT/USD"]
[270, {"a": [["11852.70000", "0.80383282", "1596737196.436623"]], "c": "1026640010"}, "book-100", "XBT/USD"]
[270, {"b": [["11852.60000", "1.58946070", "1596737196.460945"]], "c": "2087327523"}, "book-100", "XBT/USD"]
[270, {"a": [["11874.50000", "0.00000000", "1596737196.576030"], ["11899.00000", "2.81849664", "1596737063.692951", "r"]], "c": "2087327523"}, "book-100", "XBT/USD"]
[270, {"a": [["11877.90000", "0.00000000", "1596737196.587234"], ["11899.10000", "7.82927162", "1596737145.805987", "r"]], "c": "2087327523"}, "book-100", "XBT/USD"]
[270, {"a": [["11854.50000", "0.00000000", "1596737196.637356"], ["11899.90000", "7.61000000", "1596737079.466913", "r"]], "c": "3381912740"}, "book-100", "XBT/USD"]
[270, {"b": [["11844.20000", "0.10934718", "1596737196.708167"]], "c": "3381912740"}, "book-100", "XBT/USD"]
[270, {"b": [["11843.40000", "1.09097591", "1596737196.710580"]], "c": "3381912740"}, "book-100", "XBT/USD"]
[270, {"b": [["11844.30000", "0.69330874", "1596737196.840518"]], "c": "3381912740"}, "book-100", "XBT/USD"]
[270, {"b": [["11847.80000", "0.33004949", "1596737196.840615"]], "c": "3381912740"}, "book-100", "XBT/USD"]
[270, {"b": [["11842.00000", "1.38688679", "1596737196.846130"]], "c": "3381912740"}, "book-100", "XBT/USD"]
[270, {"a": [["11879.70000", "0.80026319", "1596737196.854074"]], "c": "3381912740"}, "book-100", "XBT/USD"]
[270, {"a": [["11876.20000", "0.32926023", "1596737197.289777"]], "c": "3381912740"}, "book-100", "XBT/USD"]
[270, {"b": [["11845.70000", "0.00000000", "1596737197.294652"], ["11802.00000", "7.50000000", "1596737194.335118", "r"]], "c": "3381912740"}, "book-100", "XBT/USD"]
[270, {"a": [["11869.70000", "0.01195000", "1596737197.344296"]], "c": "3381912740"}, "book-100", "XBT/USD"]
[270, {"b": [["11839.50000", "3.27835948", "1596737197.394850"]], "c": "3381912740"}, "book-100", "XBT/USD"]
[270, {"a": [["11866.10000", "0.00000000", "1596737197.404839"], ["11899.90000", "7.61000000", "1596737079.466913", "r"]], "c": "3381912740"}, "book-100", "XBT/USD"]
[270, {"a": [["11882.50000", "0.73642797", "1596737197.447799"]], "c": "3381912740"}, "book-100", "XBT/USD"]
[270, {"b": [["11821.70000", "0.00000000", "1596737197.448546"], ["11802.00000", "7.50000000", "1596737194.335118", "r"]], "c": "3381912740"}, "book-100", "XBT/USD"]
[270, {"b": [["11821.30000", "0.73642797", "1596737197.460393"]], "c": "3381912740"}, "book-100", "XBT/USD"]
[270, {"a": [["11866.80000", "0.00000000", "1596737197.487678"], ["11899.90000", "7.61000000", "1596737079.466913", "r"]], "c": "3381912740"}, "book-100", "XBT/USD"]
[270, {"a": [["11882.80000", "0.00000000", "1596737197.502538"], ["11900.00000", "12.71653131", "1596737075.897027", "r"]], "c": "3381912740"}, "book-100", "XBT/USD"]
[270, {"b": [["11851.70000", "2.97960388", "1596737197.528768"]], "c": "1149295985"}, "book-100", "XBT/USD"]
[270, {"a": [["11856.30000", "0.70000000", "1596737197.581460"]], "c": "4207515116"}, "book-100", "XBT/USD"]
[270, {"a": [["11864.20000", "0.01466462", "1596737197.614490"]], "c": "4207515116"}, "book-100", "XBT/USD"]
[270, {"a": [["11856.20000", "0.82180000", "1596737197.648816"]], "c": "2256032075"}, "book-100", "XBT/USD"]
[270, {"a": [["11865.10000", "0.07332312", "1596737197.678877"]], "c": "2256032075"}, "book-100", "XBT/USD"]
[270, {"a": [["11854.30000", "0.39500000", "1596737197.683736"]], "c": "3666251477"}, "book-100", "XBT/USD"]
[270, {"a": [["11856.30000", "0.00000000", "1596737197.695568"], ["11898.70000", "0.01000000", "1596737133.560066", "r"]], "c": "2738596226"}, "book-100", "XBT/USD"]
[270, {"a": [["11856.40000", "0.00000000", "1596737197.728322"], ["11899.00000", "2.81849664", "1596737063.692951", "r"]], "c": "3019047517"}, "book-100", "XBT/USD"]
[270, {"a": [["11856.00000", "0.63241577", "1596737197.734307"]], "c": "2639493763"}, "book-100", "XBT/USD"]
[270, {"a": [["11854.40000", "0.00000000", "1596737197.900683"], ["11899.00000", "2.81849664", "1596737063.692951", "r"]], "c": "3975924994"}, "book-100", "XBT/USD"]
[270, {"a": [["11857.90000", "1.87070127", "1596737197.916257"]], "c": "3523577312"}, "book-100", "XBT/USD"]
[270, {"a": [["11888.30000", "0.00000000", "1596737197.917263"], ["11899.10000", "7.82927162", "1596737145.805987", "r"]], "c": "3523577312"}, "book-100", "XBT/USD"]
[270, {"a": [["11855.90000", "0.82180000", "1596737198.028179"]], "c": "3390192074"}, "book-100", "XBT/USD"]
[270, {"a": [["11856.20000", "0.00000000", "1596737198.031354"], ["11899.10000", "7.82927162", "1596737145.805987", "r"]], "c": "662028027"}, "book-100", "XBT/USD"]
[270, {"a": [["11857.90000", "1.23829000", "1596737198.147351"]], "c": "428602905"}, "book-100", "XBT/USD"]
[270, {"b": [["11852.40000", "0.01466462", "1596737198.149705"]], "c": "1071539502"}, "book-100", "XBT/USD"]
[270, {"a": [["11857.90000", "0.98829000", "1596737198.173252"]], "c": "2039388105"}, "book-100", "XBT/USD"]
[270, {"b": [["11848.10000", "3.89375668", "1596737198.245065"]], "c": "2039388105"}, "book-100", "XBT/USD"]
[270, {"a": [["11879.70000", "0.10902042", "1596737198.321624"]], "c": "2039388105"}, "book-100", "XBT/USD"]
[270, {"a": [["11876.20000", "0.00000000", "1596737198.323748"], ["11899.90000", "7.61000000", "1596737079.466913", "r"]], "c": "2039388105"}, "book-100", "XBT/USD"]
