[270, {"b": [["11850.10000", "0.00000000", "1596737009.455683"], ["11810.70000", "13.46787369", "1596737005.994208", "r"]], "c": "3684875851"}, "book-100", "XBT/USD"]
[270, {"b": [["11848.10000", "0.73400000", "1596737009.511261"]], "c": "3684875851"}, "book-100", "XBT/USD"]
[270, {"b": [["11856.00000", "0.46600000", "1596737009.518706"]], "c": "3684875851"}, "book-100", "XBT/USD"]
[270, {"a": [["11876.60000", "0.09250000", "1596737009.519352"]], "c": "3684875851"}, "book-100", "XBT/USD"]
[270, {"b": [["11861.50000", "0.00000000", "1596737009.521079"], ["11810.70000", "13.46787369", "1596737005.994208", "r"]], "c": "3985485645"}, "book-100", "XBT/USD"]
[270, {"b": [["11844.90000", "0.00000000", "1596737009.521378"], ["11808.80000", "2.66090576", "1596736784.110515", "r"]], "c": "3985485645"}, "book-100", "XBT/USD"]
[270, {"a": [["11874.60000", "3.16676142", "1596737009.539441"]], "c": "3985485645"}, "book-100", "XBT/USD"]
[270, {"b": [["11859.80000", "0.00000000", "1596737009.548931"], ["11807.70000", "3.28855406", "1596736821.611246", "r"]], "c": "1124274203"}, "book-100", "XBT/USD"]
[270, {"a": [["11870.40000", "13.71368580", "1596737009.553496"]], "c": "411369782"}, "book-100", "XBT/USD"]
[270, {"a": [["11874.90000", "0.01800000", "1596737009.572065"]], "c": "411369782"}, "book-100", "XBT/USD"]
[270, {"b": [["11837.10000", "1.83747305", "1596737009.594754"]], "c": "411369782"}, "book-100", "XBT/USD"]
[270, {"b": [["11855.30000", "3.74174250", "1596737009.637505"]], "c": "411369782"}, "book-100", "XBT/USD"]
[270, {"a": [["11877.90000", "0.00000000", "1596737009.701140"], ["11909.90000", "6.20000000", "1596736825.518690", "r"]], "c": "411369782"}, "book-100", "XBT/USD"]
[270, {"a": [["11886.70000", "0.69220379", "1596737009.781562"]], "c": "411369782"}, "book-100", "XBT/USD"]
[270, {"b": [["11858.60000", "0.00000000", "1596737009.781757"], ["11807.70000", "3.28855406", "1596736821.611246", "r"]], "c": "411369782"}, "book-100", "XBT/USD"]
[270, {"b": [["11861.70000", "0.00000000", "1596737009.831379"], ["11807.50000", "2.19772556", "1596736916.776430", "r"]], "c": "7429150"}, "book-100", "XBT/USD"]
[270, {"b": [["11861.70000", "0.10000000", "1596737009.883473"]], "c": "411369782"}, "book-100", "XBT/USD"]
[270, {"b": [["11863.10000", "0.00000000", "1596737009.884000"], ["11807.50000", "2.19772556", "1596736916.776430", "r"]], "c": "2900642056"}, "book-100", "XBT/USD"]
[270, {"b": [["11861.70000", "0.00000000", "1596737009.934977"], ["11807.20000", "6.50000000", "1596736936.572585", "r"]], "c": "1522998091"}, "book-100", "XBT/USD"]
[270, {"a": [["11870.40000", "13.81068580", "1596737009.962753"]], "c": "1303793640"}, "book-100", "XBT/USD"]
[270, {"b": [["11860.20000", "0.00000000", "1596737009.970054"], ["11805.90000", "0.15000000", "1596735155.182015", "r"]], "c": "290585898"}, "book-100", "XBT/USD"]
[270, {"b": [["11861.70000", "0.10000000", "1596737009.981186"]], "c": "2419180816"}, "book-100", "XBT/USD"]
[270, {"b": [["11853.20000", "0.00000000", "1596737009.985760"], ["11805.90000", "0.15000000", "1596735155.182015", "r"]], "c": "2419180816"}, "book-100", "XBT/USD"]
[270, {"b": [["11853.20000", "0.00451000", "1596737009.987661"]], "c": "2419180816"}, "book-100", "XBT/USD"]
[270, {"a": [["11878.10000", "0.65992246", "1596737010.052177"]], "c": "2419180816"}, "book-100", "XBT/USD"]
[270, {"b": [["11861.70000", "0.20000000", "1596737010.067073"]], "c": "4213947778"}, "book-100", "XBT/USD"]
[270, {"a": [["11882.30000", "0.00000000", "1596737010.088930"], ["11909.90000", "6.20000000", "1596736825.518690", "r"]], "c": "4213947778"}, "book-100", "XBT/USD"]
[270, {"a": [["11873.10000", "0.50000000", "1596737010.095234"]], "c": "4213947778"}, "book-100", "XBT/USD"]
[270, {"a": [["11886.70000", "0.00000000", "1596737010.139316"], ["11909.90000", "6.20000000", "1596736825.518690", "r"]], "c": "4213947778"}, "book-100", "XBT/USD"]
[270, {"b": [["11854.20000", "0.00000000", "1596737010.154967"], ["11805.90000", "0.15000000", "1596735155.182015", "r"]], "c": "4213947778"}, "book-100", "XBT/USD"]
[270, {"a": [["11893.90000", "0.00000000", "1596737010.160142"], ["11910.00000", "0.36067000", "1596736968.148143", "r"]], "c": "4213947778"}, "book-100", "XBT/USD"]
[270, {"b": [["11851.10000", "0.25411207", "1596737010.179757"]], "c": "4213947778"}, "book-100", "XBT/USD"]
[270, {"a": [["11892.80000", "0.00000000", "1596737010.186851"], ["11910.50000", "1.68800000", "1596736995.994117", "r"]], "c": "4213947778"}, "book-100", "XBT/USD"]
[270, {"b": [["11861.10000", "0.01465750", "1596737010.191455"]], "c": "2974008633"}, "book-100", "XBT/USD"]
[270, {"b": [["11854.00000", "0.00000000", "1596737010.194939"], ["11805.20000", "0.34533000", "1596735143.806373", "r"]], "c": "2974008633"}, "book-100", "XBT/USD"]
[270, {"a": [["11890.40000", "0.00000000", "1596737010.210636"], ["11910.70000", "1.58924162", "1596736944.279722", "r"]], "c": "2974008633"}, "book-100", "XBT/USD"]
[270, {"b": [["11858.20000", "0.25283671", "1596737010.262362"]], "c": "2974008633"}, "book-100", "XBT/USD"]
[270, {"b": [["11846.70000", "0.33709493", "1596737010.262961"]], "c": "2974008633"}, "book-100", "XBT/USD"]
[270, {"b": [["11851.30000", "0.20471769", "1596737010.292034"]], "c": "2974008633"}, "book-100", "XBT/USD"]
[270, {"b": [["11859.20000", "0.00000000", "1596737010.378084"], ["11807.20000", "6.50000000", "1596736936.572585", "r"]], "c": "776013302"}, "book-100", "XBT/USD"]
[270, {"a": [["11877.40000", "0.00000000", "1596737010.380616"], ["11911.60000", "0.75800000", "1596737003.974614", "r"]], "c": "776013302"}, "book-100", "XBT/USD"]
[270, {"b": [["11845.30000", "1.28078857", "1596737010.383369"]], "c": "776013302"}, "book-100", "XBT/USD"]
[270, {"b": [["11852.70000", "0.80395000", "1596737010.396672"]], "c": "776013302"}, "book-100", "XBT/USD"]
[270, {"b": [["11855.40000", "0.00000000", "1596737010.399512"], ["11807.50000", "2.19772556", "1596736916.776430", "r"]], "c": "776013302"}, "book-100", "XBT/USD"]
[270, {"b": [["11852.80000", "0.00000000", "1596737010.407207"], ["11807.20000", "6.50000000", "1596736936.572585", "r"]], "c": "776013302"}, "book-100", "XBT/USD"]
[270, {"a": [["11870.40000", "13.31068580", "1596737010.423653"]], "c": "3699799967"}, "book-100", "XBT/USD"]
[270, {"a": [["11870.50000", "0.78162106", "1596737010.462279"]], "c": "3312515933"}, "book-100", "XBT/USD"]
[270, {"a": [["11891.40000", "0.94290603", "1596737010.479467"]], "c": "3312515933"}, "book-100", "XBT/USD"]
[270, {"a": [["11887.90000", "0.94318363", "1596737010.485123"]], "c": "3312515933"}, "book-100", "XBT/USD"]
[270, {"b": [["11861.70000", "0.10000000", "1596737010.511863"]], "c": "2926216143"}, "book-100", "XBT/USD"]
[270, {"a": [["11890.20000", "0.52855572", "1596737010.538060"]], "c": "2926216143"}, "book-100", "XBT/USD"]
[270, {"b": [["11848.90000", "0.53039803", "1596737010.542364"]], "c": "2926216143"}, "book-100", "XBT/USD"]
[270, {"b": [["11861.80000", "0.10000000", "1596737010.578166"]], "c": "149383773"}, "book-100", "XBT/USD"]
[270, {"b": [["11851.20000", "0.76590228", "1596737010.649056"]], "c": "149383773"}, "book-100", "XBT/USD"]
[270, {"a": [["11874.90000", "0.00000000", "1596737010.655948"], ["11910.50000", "1.68800000", "1596736995.994117", "r"]], "c": "149383773"}, "book-100", "XBT/USD"]
[270, {"b": [["11860.00000", "0.00000000", "1596737010.660351"], ["11807.70000", "3.28855406", "1596736821.611246", "r"]], "c": "837375809"}, "book-100", "XBT/USD"]
[270, {"b": [["11861.80000", "0.00000000", "1596737010.662180"], ["11807.50000", "2.19772556", "1596736916.776430", "r"]], "c": "3562931284"}, "book-100", "XBT/USD"]
[270, {"a": [["11874.40000", "0.01800000", "1596737010.706318"]], "c": "3562931284"}, "book-100", "XBT/USD"]
[270, {"b": [["11853.20000", "0.00000000", "1596737010.775421"], ["11807.20000", "6.50000000", "1596736936.572585", "r"]], "c": "3562931284"}, "book-100", "XBT/USD"]
[270, {"b": [["11851.90000", "3.28980287", "1596737010.778399"]], "c": "3562931284"}, "book-100", "XBT/USD"]
[270, {"b": [["11861.70000", "0.00000000", "1596737010.796662"], ["11805.90000", "0.15000000", "1596735155.182015", "r"]], "c": "1516586895"}, "book-100", "XBT/USD"]
[270, {"a": [["11870.40000", "13.81068580", "1596737010.834087"]], "c": "2829202918"}, "book-100", "XBT/USD"]
[270, {"b": [["11861.70000", "0.10000000", "1596737010.914224"]], "c": "647591485"}, "book-100", "XBT/USD"]
[270, {"b": [["11839.90000", "0.00000000", "1596737010.963290"], ["11805.90000", "0.15000000", "1596735155.182015", "r"]], "c": "647591485"}, "book-100", "XBT/USD"]
[270, {"b": [["11861.70000", "0.20000000", "1596737010.987421"]], "c": "1300434607"}, "book-100", "XBT/USD"]
[270, {"a": [["11885.50000", "0.69228225", "1596737011.092034"]], "c": "1300434607"}, "book-100", "XBT/USD"]
[270, {"b": [["11834.00000", "0.01000000", "1596737011.263331"]], "c": "1300434607"}, "book-100", "XBT/USD"]
[270, {"b": [["11852.90000", "0.00000000", "1596737011.311856"], ["11805.90000", "0.15000000", "1596735155.182015", "r"]], "c": "1300434607"}, "book-100", "XBT/USD"]
[270, {"b": [["11858.70000", "0.43021802", "1596737011.372878"]], "c": "2740989170"}, "book-100", "XBT/USD"]
[270, {"b": [["11845.30000", "1.96168857", "1596737011.401349"]], "c": "2740989170"}, "book-100", "XBT/USD"]
[270, {"b": [["11857.80000", "0.00000000", "1596737011.432181"], ["11805.20000", "0.34533000", "1596735143.806373", "r"]], "c": "2740989170"}, "book-100", "XBT/USD"]
[270, {"b": [["11858.70000", "2.11521802", "1596737011.528914"]], "c": "3301067970"}, "book-100", "XBT/USD"]
[270, {"a": [["11874.40000", "0.00000000", "1596737011.592473"], ["11910.00000", "0.36067000", "1596736968.148143", "r"]], "c": "3301067970"}, "book-100", "XBT/USD"]
[270, {"b": [["11848.10000", "0.71100000", "1596737011.593030"]], "c": "3301067970"}, "book-100", "XBT/USD"]
[270, {"b": [["11847.10000", "0.02300000", "1596737011.643666"]], "c": "3301067970"}, "book-100", "XBT/USD"]
[270, {"a": [["11873.40000", "0.01800000", "1596737011.643775"]], "c": "3301067970"}, "book-100", "XBT/USD"]
[270, {"b": [["11851.00000", "0.94612039", "1596737011.688600"]], "c": "3301067970"}, "book-100", "XBT/USD"]
[270, {"b": [["11854.10000", "0.36721094", "1596737011.706382"]], "c": "3301067970"}, "book-100", "XBT/USD"]
[270, {"b": [["11858.70000", "1.78200000", "1596737011.773822"]], "c": "2750984259"}, "book-100", "XBT/USD"]
[270, {"b": [["11853.70000", "1.27144185", "1596737011.850447"]], "c": "2750984259"}, "book-100", "XBT/USD"]
[270, {"a": [["11875.70000", "0.54000000", "1596737011.867973"]], "c": "2750984259"}, "book-100", "XBT/USD"]
[270, {"a": [["11875.70000", "0.27100000", "1596737011.877661"]], "c": "2750984259"}, "book-100", "XBT/USD"]
[270, {"a": [["11872.70000", "0.28399999", "1596737011.902929"]], "c": "2750984259"}, "book-100", "XBT/USD"]
[270, {"a": [["11892.00000", "0.17065000", "1596737011.953718"]], "c": "2750984259"}, "book-100", "XBT/USD"]
[270, {"a": [["11872.70000", "0.59299999", "1596737012.109592"]], "c": "2750984259"}, "book-100", "XBT/USD"]
[270, {"a": [["11870.40000", "14.81068580", "1596737012.492708"]], "c": "2502508841"}, "book-100", "XBT/USD"]
[270, {"a": [["11878.40000", "0.00000000", "1596737012.536947"], ["11909.10000", "1.00200000", "1596736809.784670", "r"]], "c": "2502508841"}, "book-100", "XBT/USD"]
[270, {"a": [["11895.70000", "2.10599327", "1596737012.648447"]], "c": "2502508841"}, "book-100", "XBT/USD"]
[270, {"a": [["11884.20000", "0.48577770", "1596737012.649321"]], "c": "2502508841"}, "book-100", "XBT/USD"]
[270, {"b": [["11852.30000", "0.09621094", "1596737012.681240"]], "c": "2502508841"}, "book-100", "XBT/USD"]
[270, {"b": [["11854.10000", "0.27100000", "1596737012.693451"]], "c": "2502508841"}, "book-100", "XBT/USD"]
[270, {"b": [["11833.80000", "0.65000000", "1596737012.752558"]], "c": "2502508841"}, "book-100", "XBT/USD"]
[270, {"a": [["11889.90000", "0.00000000", "1596737012.813224"], ["11908.90000", "1.06880000", "1596736841.521829", "r"]], "c": "2502508841"}, "book-100", "XBT/USD"]
[270, {"a": [["11896.50000", "1.27509051", "1596737012.816492"]], "c": "2502508841"}, "book-100", "XBT/USD"]
[270, {"a": [["11893.50000", "0.00000000", "1596737012.816881"], ["11909.10000", "1.00200000", "1596736809.784670", "r"]], "c": "2502508841"}, "book-100", "XBT/USD"]
[270, {"a": [["11896.40000", "0.00000000", "1596737012.820034"], ["11909.90000", "6.20000000", "1596736825.518690", "r"]], "c": "2502508841"}, "book-100", "XBT/USD"]
[270, {"a": [["11889.30000", "0.76342478", "1596737012.820698"]], "c": "2502508841"}, "book-100", "XBT/USD"]
[270, {"b": [["11854.60000", "0.48371673", "1596737012.820904"]], "c": "2502508841"}, "book-100", "XBT/USD"]
[270, {"a": [["11887.50000", "0.00000000", "1596737012.820991"], ["11910.00000", "0.36067000", "1596736968.148143", "r"]], "c": "2502508841"}, "book-100", "XBT/USD"]
[270, {"a": [["11883.20000", "0.00000000", "1596737012.822093"], ["11910.50000", "1.68800000", "1596736995.994117", "r"]], "c": "2502508841"}, "book-100", "XBT/USD"]
[270, {"a": [["11896.30000", "7.54073617", "1596737012.826128"]], "c": "2502508841"}, "book-100", "XBT/USD"]
[270, {"a": [["11896.50000", "0.00000000", "1596737012.828631"], ["11910.70000", "1.58924162", "1596736944.279722", "r"]], "c": "2502508841"}, "book-100", "XBT/USD"]
[270, {"b": [["11857.20000", "0.00000000", "1596737012.830555"], ["11807.20000", "6.50000000", "1596736936.572585", "r"]], "c": "2502508841"}, "book-100", "XBT/USD"]
[270, {"a": [["11884.30000", "0.00000000", "1596737012.895234"], ["11911.60000", "0.75800000", "1596737003.974614", "r"]], "c": "2502508841"}, "book-100", "XBT/USD"]
[270, {"a": [["11892.50000", "0.00000000", "1596737012.940422"], ["11911.70000", "0.01000000", "1596737011.251243", "r"]], "c": "2502508841"}, "book-100", "XBT/USD"]
[270, {"b": [["11855.40000", "0.76485000", "1596737012.941178"]], "c": "2502508841"}, "book-100", "XBT/USD"]
[270, {"a": [["11892.00000", "0.00000000", "1596737012.967507"], ["11912.90000", "2.20927279", "1596737008.300042", "r"]], "c": "2502508841"}, "book-100", "XBT/USD"]
[270, {"b": [["11851.90000", "0.01310667", "1596737012.978310"]], "c": "2502508841"}, "book-100", "XBT/USD"]
[270, {"a": [["11870.90000", "1.47237502", "1596737012.985141"]], "c": "2721589277"}, "book-100", "XBT/USD"]
[270, {"a": [["11887.40000", "0.20409715", "1596737013.022198"]], "c": "2721589277"}, "book-100", "XBT/USD"]
[270, {"a": [["11890.90000", "0.28565191", "1596737013.022449"]], "c": "2721589277"}, "book-100", "XBT/USD"]
[270, {"a": [["11884.20000", "0.00000000", "1596737013.120042"], ["11911.70000", "0.01000000", "1596737011.251243", "r"]], "c": "2721589277"}, "book-100", "XBT/USD"]
[270, {"a": [["11887.40000", "1.58844034", "1596737013.122992"]], "c": "2721589277"}, "book-100", "XBT/USD"]
[270, {"a": [["11893.30000", "1.27561946", "1596737013.123727"]], "c": "2721589277"}, "book-100", "XBT/USD"]
[270, {"b": [["11855.70000", "0.33048683", "1596737013.124068"]], "c": "2721589277"}, "book-100", "XBT/USD"]
[270, {"a": [["11885.00000", "0.10910344", "1596737013.124336"]], "c": "2721589277"}, "book-100", "XBT/USD"]
[270, {"a": [["11881.50000", "0.32976919", "1596737013.124758"]], "c": "2721589277"}, "book-100", "XBT/USD"]
[270, {"b": [["11858.70000", "0.09700000", "1596737013.128733"]], "c": "1123453257"}, "book-100", "XBT/USD"]
[270, {"b": [["11859.50000", "1.67500000", "1596737013.134044"]], "c": "809204026"}, "book-100", "XBT/USD"]
[270, {"a": [["11877.70000", "1.04962971", "1596737013.141342"]], "c": "809204026"}, "book-100", "XBT/USD"]
[270, {"b": [["11858.20000", "0.00000000", "1596737013.181344"], ["11807.70000", "3.28855406", "1596736821.611246", "r"]], "c": "3377369907"}, "book-100", "XBT/USD"]
[270, {"b": [["11847.30000", "3.27801686", "1596737013.223808"]], "c": "3377369907"}, "book-100", "XBT/USD"]
[270, {"a": [["11889.70000", "3.26632708", "1596737013.224925"]], "c": "3377369907"}, "book-100", "XBT/USD"]
[270, {"a": [["11893.30000", "3.45778547", "1596737013.278024"]], "c": "3377369907"}, "book-100", "XBT/USD"]
[270, {"a": [["11885.40000", "0.62124843", "1596737013.302482"]], "c": "3377369907"}, "book-100", "XBT/USD"]
[270, {"b": [["11861.00000", "0.25281326", "1596737013.312965"]], "c": "3069445874"}, "book-100", "XBT/USD"]
[270, {"a": [["11881.70000", "6.59390014", "1596737013.364159"]], "c": "3069445874"}, "book-100", "XBT/USD"]
[270, {"a": [["11893.30000", "5.20382813", "1596737013.439587"]], "c": "3069445874"}, "book-100", "XBT/USD"]
[270, {"b": [["11852.20000", "0.10940538", "1596737013.467640"]], "c": "3069445874"}, "book-100", "XBT/USD"]
[270, {"a": [["11895.70000", "0.00000000", "1596737013.485155"], ["11909.10000", "1.00200000", "1596736809.784670", "r"]], "c": "3069445874"}, "book-100", "XBT/USD"]
[270, {"a": [["11876.80000", "0.90958000", "1596737013.561871"]], "c": "3069445874"}, "book-100", "XBT/USD"]
[270, {"a": [["11870.40000", "15.06068580", "1596737013.588744"]], "c": "3370335280"}, "book-100", "XBT/USD"]
[270, {"a": [["11873.50000", "5.94718520", "1596737013.600762"]], "c": "3370335280"}, "book-100", "XBT/USD"]
[270, {"b": [["11846.70000", "0.00000000", "1596737013.627779"], ["11810.70000", "13.46787369", "1596737005.994208", "r"]], "c": "3370335280"}, "book-100", "XBT/USD"]
[270, {"a": [["11870.40000", "14.96368580", "1596737013.661274"]], "c": "2546402167"}, "book-100", "XBT/USD"]
[270, {"a": [["11870.40000", "14.56368580", "1596737013.663463"]], "c": "1910538579"}, "book-100", "XBT/USD"]
[270, {"a": [["11896.20000", "0.00000000", "1596737013.665304"], ["11909.90000", "6.20000000", "1596736825.518690", "r"]], "c": "1910538579"}, "book-100", "XBT/USD"]
[270, {"a": [["11873.50000", "0.24718520", "1596737013.671141"]], "c": "1910538579"}, "book-100", "XBT/USD"]
[270, {"b": [["11861.50000", "0.10000000", "1596737013.682060"]], "c": "1856330945"}, "book-100", "XBT/USD"]
[270, {"b": [["11858.70000", "3.51808650", "1596737013.685293"]], "c": "1856330945"}, "book-100", "XBT/USD"]
[270, {"a": [["11870.40000", "14.31368580", "1596737013.720971"]], "c": "1339335394"}, "book-100", "XBT/USD"]
[270, {"b": [["11860.40000", "0.07325875", "1596737013.742754"]], "c": "2367037795"}, "book-100", "XBT/USD"]
[270, {"a": [["11870.40000", "13.81368580", "1596737013.775439"]], "c": "2405158535"}, "book-100", "XBT/USD"]
[270, {"a": [["11873.40000", "0.00000000", "1596737013.775905"], ["11910.00000", "0.36067000", "1596736968.148143", "r"]], "c": "2405158535"}, "book-100", "XBT/USD"]
[270, {"b": [["11847.10000", "0.00000000", "1596737013.775979"], ["11810.70000", "13.46787369", "1596737005.994208", "r"]], "c": "2405158535"}, "book-100", "XBT/USD"]
[270, {"b": [["11859.60000", "0.78550000", "1596737013.794251"]], "c": "4249617982"}, "book-100", "XBT/USD"]
[270, {"a": [["11871.50000", "0.31952620", "1596737013.794381"]], "c": "1138649319"}, "book-100", "XBT/USD"]
[270, {"a": [["11873.50000", "0.14918520", "1596737013.798703"]], "c": "1138649319"}, "book-100", "XBT/USD"]
[270, {"a": [["11874.40000", "0.01800000", "1596737013.826668"]], "c": "1138649319"}, "book-100", "XBT/USD"]
[270, {"b": [["11855.30000", "0.00000000", "1596737013.826831"], ["11810.70000", "13.46787369", "1596737005.994208", "r"]], "c": "1138649319"}, "book-100", "XBT/USD"]
[270, {"b": [["11848.10000", "0.73400000", "1596737013.827603"]], "c": "1138649319"}, "book-100", "XBT/USD"]
[270, {"b": [["11861.00000", "0.00000000", "1596737013.842263"], ["11808.80000", "2.66090576", "1596736784.110515", "r"]], "c": "2276205471"}, "book-100", "XBT/USD"]
[270, {"a": [["11874.20000", "0.00000000", "1596737013.873693"], ["11910.00000", "0.36067000", "1596736968.148143", "r"]], "c": "2276205471"}, "book-100", "XBT/USD"]
[270, {"b": [["11862.30000", "0.71059000", "1596737013.977521"]], "c": "4213766739"}, "book-100", "XBT/USD"]
[270, {"a": [["11877.80000", "0.04440539", "1596737013.980606"]], "c": "4213766739"}, "book-100", "XBT/USD"]
[270, {"b": [["11852.70000", "0.00000000", "1596737013.986367"], ["11808.80000", "2.66090576", "1596736784.110515", "r"]], "c": "4213766739"}, "book-100", "XBT/USD"]
[270, {"a": [["11870.40000", "9.60868580", "1596737013.991569"]], "c": "4089345170"}, "book-100", "XBT/USD"]
[270, {"b": [["11861.80000", "0.63990000", "1596737014.040548"]], "c": "1910972521"}, "book-100", "XBT/USD"]
[270, {"b": [["11858.80000", "0.00000000", "1596737014.044981"], ["11808.80000", "2.66090576", "1596736784.110515", "r"]], "c": "1910972521"}, "book-100", "XBT/USD"]
[270, {"b": [["11861.70000", "0.10000000", "1596737014.099048"]], "c": "1934592849"}, "book-100", "XBT/USD"]
[270, {"b": [["11864.50000", "1.67200000", "1596737014.115980"]], "c": "345283685"}, "book-100", "XBT/USD"]
[270, {"b": [["11861.70000", "0.00000000", "1596737014.116216"], ["11808.80000", "2.66090576", "1596736784.110515", "r"]], "c": "3369389199"}, "book-100", "XBT/USD"]
[270, {"b": [["11859.50000", "0.00000000", "1596737014.121145"], ["11807.70000", "3.28855406", "1596736821.611246", "r"]], "c": "1585971632"}, "book-100", "XBT/USD"]
[270, {"a": [["11875.40000", "0.08690127", "1596737014.129208"]], "c": "1585971632"}, "book-100", "XBT/USD"]
[270, {"a": [["11877.90000", "2.53165550", "1596737014.130431"]], "c": "1585971632"}, "book-100", "XBT/USD"]
[270, {"b": [["11862.40000", "0.10000000", "1596737014.155010"]], "c": "1262289461"}, "book-100", "XBT/USD"]
[270, {"a": [["11876.80000", "0.00000000", "1596737014.191982"], ["11910.00000", "0.36067000", "1596736968.148143", "r"]], "c": "1262289461"}, "book-100", "XBT/USD"]
[270, {"b": [["11862.20000", "3.25883038", "1596737014.198026"]], "c": "1812174524"}, "book-100", "XBT/USD"]
[270, {"a": [["11874.60000", "0.00000000", "1596737014.265306"], ["11910.50000", "1.68800000", "1596736995.994117", "r"]], "c": "1812174524"}, "book-100", "XBT/USD"]
[270, {"a": [["11878.10000", "0.00000000", "1596737014.284027"], ["11910.70000", "1.58924162", "1596736944.279722", "r"]], "c": "1812174524"}, "book-100", "XBT/USD"]
[270, {"b": [["11862.40000", "0.20000000", "1596737014.286892"]], "c": "3108342215"}, "book-100", "XBT/USD"]
[270, {"b": [["11858.70000", "0.09700000", "1596737014.337673"]], "c": "3108342215"}, "book-100", "XBT/USD"]
[270, {"b": [["11851.00000", "8.34612039", "1596737014.349720"]], "c": "3108342215"}, "book-100", "XBT/USD"]
[270, {"a": [["11870.40000", "8.90868580", "1596737014.365938"]], "c": "2750445705"}, "book-100", "XBT/USD"]
[270, {"a": [["11876.60000", "0.00000000", "1596737014.391023"], ["11911.10000", "2.17890497", "1596737013.284792", "r"]], "c": "2750445705"}, "book-100", "XBT/USD"]
[270, {"a": [["11898.70000", "2.23149688", "1596737014.454928"]], "c": "2750445705"}, "book-100", "XBT/USD"]
[270, {"a": [["11872.30000", "0.25000000", "1596737014.472575"]], "c": "2750445705"}, "book-100", "XBT/USD"]
[270, {"b": [["11855.40000", "0.00000000", "1596737014.494277"], ["11808.80000", "2.66090576", "1596736784.110515", "r"]], "c": "2750445705"}, "book-100", "XBT/USD"]
[270, {"b": [["11849.20000", "0.00000000", "1596737014.494734"], ["11807.70000", "3.28855406", "1596736821.611246", "r"]], "c": "2750445705"}, "book-100", "XBT/USD"]
[270, {"b": [["11851.90000", "0.00000000", "1596737014.498506"], ["11807.50000", "2.19772556", "1596736916.776430", "r"]], "c": "2750445705"}, "book-100", "XBT/USD"]
[270, {"b": [["11851.50000", "0.07215418", "1596737014.506111"]], "c": "2750445705"}, "book-100", "XBT/USD"]
[270, {"b": [["11864.90000", "0.84100000", "1596737014.506761"]], "c": "2161030828"}, "book-100", "XBT/USD"]
[270, {"a": [["11880.00000", "1.34608790", "1596737014.533597"]], "c": "2161030828"}, "book-100", "XBT/USD"]
[270, {"b": [["11832.20000", "0.00000000", "1596737014.535815"], ["11807.70000", "3.28855406", "1596736821.611246", "r"]], "c": "2161030828"}, "book-100", "XBT/USD"]
[270, {"a": [["11895.10000", "0.00000000", "1596737014.536348"], ["11911.10000", "2.17890497", "1596737013.284792", "r"]], "c": "2161030828"}, "book-100", "XBT/USD"]
[270, {"a": [["11893.30000", "5.94009941", "1596737014.543723"]], "c": "2161030828"}, "book-100", "XBT/USD"]
[270, {"b": [["11830.40000", "0.73627128", "1596737014.566059"]], "c": "2161030828"}, "book-100", "XBT/USD"]
[270, {"a": [["11874.30000", "0.09250000", "1596737014.607663"]], "c": "2161030828"}, "book-100", "XBT/USD"]
[270, {"b": [["11862.50000", "0.63710000", "1596737014.624883"]], "c": "3409831742"}, "book-100", "XBT/USD"]
[270, {"a": [["11885.40000", "0.00000000", "1596737014.634557"], ["11911.10000", "2.17890497", "1596737013.284792", "r"]], "c": "3409831742"}, "book-100", "XBT/USD"]
[270, {"b": [["11861.80000", "0.00000000", "1596737014.673528"], ["11808.80000", "2.66090576", "1596736784.110515", "r"]], "c": "1738526841"}, "book-100", "XBT/USD"]
[270, {"b": [["11862.40000", "0.10000000", "1596737014.701314"]], "c": "2739000446"}, "book-100", "XBT/USD"]
[270, {"a": [["11870.40000", "8.40868580", "1596737014.708825"]], "c": "1522500814"}, "book-100", "XBT/USD"]
[270, {"b": [["11870.30000", "0.91403482", "1596737014.710036"]], "c": "3340920472"}, "book-100", "XBT/USD"]
[270, {"a": [["11879.30000", "0.83547000", "1596737014.721193"]], "c": "3340920472"}, "book-100", "XBT/USD"]
[270, {"a": [["11874.50000", "0.00000000", "1596737014.740180"], ["11911.10000", "2.17890497", "1596737013.284792", "r"]], "c": "3340920472"}, "book-100", "XBT/USD"]
[270, {"a": [["11872.70000", "2.26899999", "1596737014.756428"]], "c": "3340920472"}, "book-100", "XBT/USD"]
[270, {"b": [["11862.60000", "0.10000000", "1596737014.782474"]], "c": "3856091310"}, "book-100", "XBT/USD"]
[270, {"a": [["11874.40000", "0.00000000", "1596737014.793276"], ["11911.60000", "0.75800000", "1596737003.974614", "r"]], "c": "3856091310"}, "book-100", "XBT/USD"]
[270, {"a": [["11877.20000", "0.69328229", "1596737014.810302"]], "c": "3856091310"}, "book-100", "XBT/USD"]
[270, {"a": [["11873.10000", "0.00000000", "1596737014.815083"], ["11911.60000", "0.75800000", "1596737003.974614", "r"]], "c": "3856091310"}, "book-100", "XBT/USD"]
[270, {"a": [["11898.70000", "0.01000000", "1596737014.815746"]], "c": "3856091310"}, "book-100", "XBT/USD"]
[270, {"a": [["11893.20000", "0.58802384", "1596737014.819357"]], "c": "3856091310"}, "book-100", "XBT/USD"]
[270, {"b": [["11862.40000", "0.00000000", "1596737014.829445"], ["11808.80000", "2.66090576", "1596736784.110515", "r"]], "c": "1810495398"}, "book-100", "XBT/USD"]
[270, {"a": [["11880.10000", "0.50000000", "1596737014.836500"]], "c": "1810495398"}, "book-100", "XBT/USD"]
[270, {"a": [["11870.40000", "9.10868580", "1596737014.841371"]], "c": "901287706"}, "book-100", "XBT/USD"]
[270, {"b": [["11862.60000", "0.00000000", "1596737014.841714"], ["11807.70000", "3.28855406", "1596736821.611246", "r"]], "c": "1595980815"}, "book-100", "XBT/USD"]
[270, {"b": [["11851.80000", "0.00000000", "1596737014.844555"], ["11807.50000", "2.19772556", "1596736916.776430", "r"]], "c": "1595980815"}, "book-100", "XBT/USD"]
[270, {"a": [["11874.90000", "0.01800000", "1596737014.847830"]], "c": "1595980815"}, "book-100", "XBT/USD"]
[270, {"a": [["11879.30000", "0.00000000", "1596737014.848922"], ["11910.70000", "1.58924162", "1596736944.279722", "r"]], "c": "1595980815"}, "book-100", "XBT/USD"]
[270, {"a": [["11883.00000", "1.01391000", "1596737014.854963"]], "c": "1595980815"}, "book-100", "XBT/USD"]
[270, {"b": [["11862.60000", "0.10000000", "1596737014.888494"]], "c": "901287706"}, "book-100", "XBT/USD"]
[270, {"a": [["11870.40000", "8.40868580", "1596737014.889101"]], "c": "1810495398"}, "book-100", "XBT/USD"]
[270, {"a": [["11881.50000", "0.00000000", "1596737014.889682"], ["11910.70000", "1.58924162", "1596736944.279722", "r"]], "c": "1810495398"}, "book-100", "XBT/USD"]
[270, {"b": [["11859.60000", "0.00000000", "1596737014.904025"], ["11807.50000", "2.19772556", "1596736916.776430", "r"]], "c": "1810495398"}, "book-100", "XBT/USD"]
[270, {"b": [["11854.10000", "0.00000000", "1596737014.905868"], ["11807.20000", "6.50000000", "1596736936.572585", "r"]], "c": "1810495398"}, "book-100", "XBT/USD"]
[270, {"a": [["11872.70000", "0.59299999", "1596737014.909954"]], "c": "1810495398"}, "book-100", "XBT/USD"]
[270, {"b": [["11867.30000", "0.67882000", "1596737014.915018"]], "c": "511115633"}, "book-100", "XBT/USD"]
[270, {"b": [["11862.60000", "0.00000000", "1596737014.966667"], ["11807.20000", "6.50000000", "1596736936.572585", "r"]], "c": "4016229584"}, "book-100", "XBT/USD"]
[270, {"b": [["11863.00000", "0.10000000", "1596737014.988187"]], "c": "3303180291"}, "book-100", "XBT/USD"]
[270, {"a": [["11898.80000", "4.20585816", "1596737014.994642"]], "c": "3303180291"}, "book-100", "XBT/USD"]
[270, {"a": [["11887.20000", "0.52437308", "1596737015.005327"]], "c": "3303180291"}, "book-100", "XBT/USD"]
[270, {"a": [["11893.20000", "0.00000000", "1596737015.005898"], ["11910.70000", "1.58924162", "1596736944.279722", "r"]], "c": "3303180291"}, "book-100", "XBT/USD"]
[270, {"b": [["11862.60000", "0.10000000", "1596737015.016648"]], "c": "3672450020"}, "book-100", "XBT/USD"]
[270, {"a": [["11880.00000", "0.70000000", "1596737015.036087"]], "c": "3672450020"}, "book-100", "XBT/USD"]
[270, {"b": [["11862.60000", "0.00000000", "1596737015.065013"], ["11807.50000", "2.19772556", "1596736916.776430", "r"]], "c": "3303180291"}, "book-100", "XBT/USD"]
[270, {"b": [["11860.40000", "0.00000000", "1596737015.139044"], ["11807.20000", "6.50000000", "1596736936.572585", "r"]], "c": "3303180291"}, "book-100", "XBT/USD"]
[270, {"a": [["11875.20000", "0.00000000", "1596737015.142039"], ["11911.10000", "2.17890497", "1596737013.284792", "r"]], "c": "3303180291"}, "book-100", "XBT/USD"]
[270, {"b": [["11858.10000", "0.00000000", "1596737015.163010"], ["11805.90000", "0.15000000", "1596735155.182015", "r"]], "c": "3303180291"}, "book-100", "XBT/USD"]
[270, {"a": [["11898.70000", "2.12869259", "1596737015.186075"]], "c": "3303180291"}, "book-100", "XBT/USD"]
[270, {"a": [["11895.20000", "6.46795476", "1596737015.187899"]], "c": "3303180291"}, "book-100", "XBT/USD"]
[270, {"a": [["11880.50000", "0.69147266", "1596737015.287616"]], "c": "3303180291"}, "book-100", "XBT/USD"]
[270, {"a": [["11870.60000", "0.00000000", "1596737015.317983"], ["11910.70000", "1.58924162", "1596736944.279722", "r"]], "c": "4284049799"}, "book-100", "XBT/USD"]
[270, {"a": [["11898.00000", "0.00000000", "1596737015.388824"], ["11911.10000", "2.17890497", "1596737013.284792", "r"]], "c": "4284049799"}, "book-100", "XBT/USD"]
[270, {"b": [["11847.30000", "0.00000000", "1596737015.388914"], ["11805.20000", "0.34533000", "1596735143.806373", "r"]], "c": "4284049799"}, "book-100", "XBT/USD"]
[270, {"b": [["11848.90000", "0.00000000", "1596737015.390022"], ["11804.80000", "3.28996656", "1596736677.195153", "r"]], "c": "4284049799"}, "book-100", "XBT/USD"]
[270, {"a": [["11889.70000", "0.00000000", "1596737015.390537"], ["11911.60000", "0.75800000", "1596737003.974614", "r"]], "c": "4284049799"}, "book-100", "XBT/USD"]
[270, {"b": [["11841.50000", "0.00424199", "1596737015.392119"]], "c": "4284049799"}, "book-100", "XBT/USD"]
[270, {"a": [["11885.00000", "0.00000000", "1596737015.397580"], ["11911.70000", "0.01000000", "1596737011.251243", "r"]], "c": "4284049799"}, "book-100", "XBT/USD"]
[270, {"a": [["11887.10000", "0.00438186", "1596737015.399658"]], "c": "4284049799"}, "book-100", "XBT/USD"]
[270, {"b": [["11852.20000", "0.00000000", "1596737015.401186"], ["11804.80000", "3.28996656", "1596736677.195153", "r"]], "c": "4284049799"}, "book-100", "XBT/USD"]
[270, {"b": [["11859.40000", "0.60801506", "1596737015.402044"]], "c": "4284049799"}, "book-100", "XBT/USD"]
[270, {"b": [["11845.30000", "0.68090000", "1596737015.404534"]], "c": "4284049799"}, "book-100", "XBT/USD"]
[270, {"a": [["11887.90000", "0.00000000", "1596737015.412284"], ["11911.70000", "0.01000000", "1596737011.251243", "r"]], "c": "4284049799"}, "book-100", "XBT/USD"]
[270, {"b": [["11855.70000", "0.00000000", "1596737015.414722"], ["11803.60000", "3.21918392", "1596736692.311968", "r"]], "c": "4284049799"}, "book-100", "XBT/USD"]
[270, {"b": [["11851.20000", "0.00000000", "1596737015.417687"], ["11803.30000", "0.95003592", "1596736676.897446", "r"]], "c": "4284049799"}, "book-100", "XBT/USD"]
[270, {"a": [["11885.50000", "0.00000000", "1596737015.418389"], ["11912.90000", "2.20927279", "1596737008.300042", "r"]], "c": "4284049799"}, "book-100", "XBT/USD"]
[270, {"b": [["11853.70000", "0.57727578", "1596737015.425491"]], "c": "4284049799"}, "book-100", "XBT/USD"]
[270, {"a": [["11887.40000", "0.20409715", "1596737015.429752"]], "c": "4284049799"}, "book-100", "XBT/USD"]
[270, {"a": [["11887.40000", "0.00000000", "1596737015.470795"], ["11913.00000", "0.17065000", "1596736890.849460", "r"]], "c": "4284049799"}, "book-100", "XBT/USD"]
[270, {"a": [["11871.10000", "0.00000000", "1596737015.513878"], ["11914.10000", "6.40200000", "1596736948.913868", "r"]], "c": "90988994"}, "book-100", "XBT/USD"]
[270, {"b": [["11863.00000", "0.00000000", "1596737015.516951"], ["11802.30000", "0.01263652", "1596737015.392755", "r"]], "c": "9873134"}, "book-100", "XBT/USD"]
[270, {"b": [["11861.10000", "0.00000000", "1596737015.543746"], ["11802.20000", "6.20000000", "1596737007.234812", "r"]], "c": "1275754567"}, "book-100", "XBT/USD"]
[270, {"b": [["11852.10000", "0.53022015", "1596737015.577015"]], "c": "1275754567"}, "book-100", "XBT/USD"]
[270, {"a": [["11891.60000", "0.88802507", "1596737015.603298"]], "c": "1275754567"}, "book-100", "XBT/USD"]
[271, [["11870.30000", "0.00837586", "1596737015.618144", "s", "m", ""]], "trade", "XBT/USD"]
[270, {"b": [["11870.30000", "0.90565896", "1596737015.618145"]], "c": "2612796699"}, "book-100", "XBT/USD"]
[270, {"b": [["11852.30000", "0.00000000", "1596737015.640824"], ["11802.20000", "6.20000000", "1596737007.234812", "r"]], "c": "2612796699"}, "book-100", "XBT/USD"]
[270, {"a": [["11871.40000", "4.81650353", "1596737015.649642"]], "c": "2557605112"}, "book-100", "XBT/USD"]
[270, {"a": [["11873.30000", "0.09600000", "1596737015.670809"]], "c": "2557605112"}, "book-100", "XBT/USD"]
[270, {"b": [["11865.00000", "0.10000000", "1596737015.681413"]], "c": "210464643"}, "book-100", "XBT/USD"]
[270, {"a": [["11891.60000", "1.83093253", "1596737015.775781"]], "c": "210464643"}, "book-100", "XBT/USD"]
[270, {"a": [["11875.70000", "0.00000000", "1596737015.820320"], ["11914.10000", "6.40200000", "1596736948.913868", "r"]], "c": "210464643"}, "book-100", "XBT/USD"]
[270, {"a": [["11870.40000", "7.40868580", "1596737015.828867"]], "c": "3226837654"}, "book-100", "XBT/USD"]
[270, {"b": [["11854.80000", "0.10941184", "1596737015.852631"]], "c": "3226837654"}, "book-100", "XBT/USD"]
[270, {"b": [["11846.50000", "1.75204989", "1596737015.854613"]], "c": "3226837654"}, "book-100", "XBT/USD"]
[270, {"b": [["11852.40000", "0.76603794", "1596737015.856012"]], "c": "3226837654"}, "book-100", "XBT/USD"]
[270, {"a": [["11889.30000", "0.87251913", "1596737015.856272"]], "c": "3226837654"}, "book-100", "XBT/USD"]
[270, {"a": [["11870.40000", "7.38892764", "1596737015.899553"]], "c": "981270627"}, "book-100", "XBT/USD"]
[270, {"a": [["11891.60000", "1.14693253", "1596737015.928566"]], "c": "981270627"}, "book-100", "XBT/USD"]
[270, {"b": [["11848.10000", "0.02300000", "1596737015.935670"]], "c": "981270627"}, "book-100", "XBT/USD"]
[270, {"b": [["11853.10000", "0.00000000", "1596737015.959073"], ["11803.30000", "0.95003592", "1596736676.897446", "r"]], "c": "981270627"}, "book-100", "XBT/USD"]
[270, {"b": [["11841.50000", "0.00000000", "1596737015.988154"], ["11802.30000", "0.01263652", "1596737015.392755", "r"]], "c": "981270627"}, "book-100", "XBT/USD"]
[270, {"b": [["11860.10000", "0.33698879", "1596737016.049095"]], "c": "981270627"}, "book-100", "XBT/USD"]
[270, {"b": [["11857.80000", "0.09621094", "1596737016.049444"]], "c": "981270627"}, "book-100", "XBT/USD"]
[270, {"b": [["11862.30000", "1.04757879", "1596737016.050347"]], "c": "2883696565"}, "book-100", "XBT/USD"]
[270, {"a": [["11879.60000", "0.27100000", "1596737016.057378"]], "c": "2883696565"}, "book-100", "XBT/USD"]
[270, {"b": [["11866.90000", "0.25272696", "1596737016.065042"]], "c": "118805133"}, "book-100", "XBT/USD"]
[270, {"a": [["11883.60000", "0.84242320", "1596737016.066452"]], "c": "118805133"}, "book-100", "XBT/USD"]
[270, {"b": [["11866.20000", "0.25272696", "1596737016.069186"]], "c": "680966245"}, "book-100", "XBT/USD"]
[270, {"b": [["11862.90000", "0.33695747", "1596737016.069758"]], "c": "3169098406"}, "book-100", "XBT/USD"]
[270, {"b": [["11865.60000", "0.25274159", "1596737016.070036"]], "c": "1375236954"}, "book-100", "XBT/USD"]
[270, {"a": [["11871.10000", "0.09621094", "1596737016.167210"]], "c": "3809600392"}, "book-100", "XBT/USD"]
[270, {"a": [["11870.50000", "0.63162106", "1596737016.286740"]], "c": "4275273913"}, "book-100", "XBT/USD"]
[270, {"a": [["11880.50000", "0.00000000", "1596737016.295495"], ["11912.90000", "2.20927279", "1596737008.300042", "r"]], "c": "4275273913"}, "book-100", "XBT/USD"]
[270, {"a": [["11887.20000", "0.00000000", "1596737016.338037"], ["11913.00000", "0.17065000", "1596736890.849460", "r"]], "c": "4275273913"}, "book-100", "XBT/USD"]
[270, {"a": [["11898.70000", "0.01000000", "1596737016.338829"]], "c": "4275273913"}, "book-100", "XBT/USD"]
[270, {"b": [["11855.70000", "6.40000000", "1596737016.432066"]], "c": "4275273913"}, "book-100", "XBT/USD"]
[270, {"a": [["11887.20000", "0.52009573", "1596737016.520234"]], "c": "4275273913"}, "book-100", "XBT/USD"]
[270, {"a": [["11898.70000", "2.12761581", "1596737016.523689"]], "c": "4275273913"}, "book-100", "XBT/USD"]
[270, {"a": [["11881.00000", "0.68591980", "1596737016.569258"]], "c": "4275273913"}, "book-100", "XBT/USD"]
[270, {"b": [["11830.10000", "0.00000000", "1596737016.632819"], ["11807.20000", "6.50000000", "1596736936.572585", "r"]], "c": "4275273913"}, "book-100", "XBT/USD"]
[270, {"a": [["11886.30000", "0.00000000", "1596737016.710123"], ["11912.90000", "2.20927279", "1596737008.300042", "r"]], "c": "4275273913"}, "book-100", "XBT/USD"]
[270, {"b": [["11870.20000", "0.99950000", "1596737016.745612"]], "c": "4074546940"}, "book-100", "XBT/USD"]
[270, {"b": [["11827.90000", "5.95518987", "1596737016.834077"]], "c": "4074546940"}, "book-100", "XBT/USD"]
[270, {"a": [["11881.70000", "12.44937269", "1596737016.920294"]], "c": "4074546940"}, "book-100", "XBT/USD"]
[270, {"a": [["11870.90000", "0.63000000", "1596737016.977268"]], "c": "862359663"}, "book-100", "XBT/USD"]
[270, {"b": [["11865.60000", "0.00000000", "1596737016.977505"], ["11807.50000", "2.19772556", "1596736916.776430", "r"]], "c": "3176415114"}, "book-100", "XBT/USD"]
[270, {"a": [["11871.00000", "0.00000000", "1596737016.978233"], ["11913.00000", "0.17065000", "1596736890.849460", "r"]], "c": "3817942880"}, "book-100", "XBT/USD"]
[270, {"a": [["11891.60000", "0.94290746", "1596737016.982000"]], "c": "3817942880"}, "book-100", "XBT/USD"]
[270, {"a": [["11889.30000", "0.76342478", "1596737017.014246"]], "c": "3817942880"}, "book-100", "XBT/USD"]
[270, {"a": [["11889.00000", "0.20406969", "1596737017.116227"]], "c": "3817942880"}, "book-100", "XBT/USD"]
[270, {"a": [["11886.70000", "0.10911821", "1596737017.170800"]], "c": "3817942880"}, "book-100", "XBT/USD"]
[270, {"b": [["11870.30000", "1.08265896", "1596737017.224658"]], "c": "1360188179"}, "book-100", "XBT/USD"]
[270, {"a": [["11900.30000", "0.00000000", "1596737017.405299"], ["11912.90000", "2.20927279", "1596737008.300042", "r"]], "c": "1360188179"}, "book-100", "XBT/USD"]
[270, {"a": [["11889.40000", "1.38406445", "1596737017.467545"]], "c": "1360188179"}, "book-100", "XBT/USD"]
[270, {"a": [["11883.60000", "1.17212319", "1596737017.467626"]], "c": "1360188179"}, "book-100", "XBT/USD"]
[270, {"b": [["11856.30000", "0.33045915", "1596737017.468955"]], "c": "1360188179"}, "book-100", "XBT/USD"]
[270, {"b": [["11852.90000", "0.69416328", "1596737017.481402"]], "c": "1360188179"}, "book-100", "XBT/USD"]
[270, {"a": [["11887.10000", "0.69654799", "1596737017.481967"]], "c": "1360188179"}, "book-100", "XBT/USD"]
[270, {"a": [["11870.40000", "6.28892764", "1596737017.618490"]], "c": "2916083873"}, "book-100", "XBT/USD"]
[270, {"b": [["11863.00000", "4.21000000", "1596737017.618977"]], "c": "1967865488"}, "book-100", "XBT/USD"]
[270, {"b": [["11861.60000", "0.00000000", "1596737017.626202"], ["11808.80000", "2.66090576", "1596736784.110515", "r"]], "c": "1967865488"}, "book-100", "XBT/USD"]
[270, {"b": [["11865.00000", "0.20000000", "1596737017.672422"]], "c": "4120386334"}, "book-100", "XBT/USD"]
[270, {"b": [["11848.10000", "0.00000000", "1596737017.677912"], ["11808.00000", "0.17065000", "1596737017.603163", "r"]], "c": "4120386334"}, "book-100", "XBT/USD"]
[270, {"a": [["11874.90000", "0.00000000", "1596737017.678197"], ["11912.90000", "2.20927279", "1596737008.300042", "r"]], "c": "4120386334"}, "book-100", "XBT/USD"]
[270, {"b": [["11865.00000", "0.10000000", "1596737017.724330"]], "c": "1967865488"}, "book-100", "XBT/USD"]
[270, {"b": [["11849.10000", "3.51127650", "1596737017.732677"]], "c": "1967865488"}, "book-100", "XBT/USD"]
[270, {"a": [["11875.90000", "0.01800000", "1596737017.732925"]], "c": "1967865488"}, "book-100", "XBT/USD"]
[270, {"a": [["11887.20000", "0.00000000", "1596737017.757052"], ["11912.90000", "2.20927279", "1596737008.300042", "r"]], "c": "1967865488"}, "book-100", "XBT/USD"]
[270, {"b": [["11851.50000", "0.00000000", "1596737017.762447"], ["11807.70000", "3.28855406", "1596736821.611246", "r"]], "c": "1967865488"}, "book-100", "XBT/USD"]
[270, {"a": [["11881.00000", "0.00000000", "1596737017.789138"], ["11913.00000", "0.17065000", "1596736890.849460", "r"]], "c": "1967865488"}, "book-100", "XBT/USD"]
[270, {"b": [["11855.80000", "0.01373403", "1596737017.791603"]], "c": "1967865488"}, "book-100", "XBT/USD"]
[270, {"a": [["11877.70000", "0.00000000", "1596737017.793229"], ["11914.10000", "6.40200000", "1596736948.913868", "r"]], "c": "1967865488"}, "book-100", "XBT/USD"]
[270, {"a": [["11872.70000", "0.28399999", "1596737017.875073"]], "c": "1967865488"}, "book-100", "XBT/USD"]
[270, {"b": [["11855.80000", "0.00000000", "1596737017.922373"], ["11807.70000", "3.28855406", "1596736821.611246", "r"]], "c": "1967865488"}, "book-100", "XBT/USD"]
[270, {"a": [["11892.00000", "3.26537482", "1596737017.926517"]], "c": "1967865488"}, "book-100", "XBT/USD"]
[270, {"b": [["11848.10000", "3.27747380", "1596737017.931753"]], "c": "1967865488"}, "book-100", "XBT/USD"]
[270, {"a": [["11889.20000", "0.69223538", "1596737017.938693"]], "c": "1967865488"}, "book-100", "XBT/USD"]
[270, {"b": [["11854.70000", "0.02258635", "1596737018.012289"]], "c": "1967865488"}, "book-100", "XBT/USD"]
[270, {"a": [["11880.90000", "1.04962971", "1596737018.021562"]], "c": "1967865488"}, "book-100", "XBT/USD"]
[270, {"a": [["11881.40000", "0.70093929", "1596737018.038739"]], "c": "1967865488"}, "book-100", "XBT/USD"]
[270, {"a": [["11898.70000", "0.01000000", "1596737018.132782"]], "c": "1967865488"}, "book-100", "XBT/USD"]
[270, {"b": [["11854.70000", "0.00000000", "1596737018.138687"], ["11808.00000", "0.17065000", "1596737017.603163", "r"]], "c": "1967865488"}, "book-100", "XBT/USD"]
[270, {"b": [["11855.20000", "0.02258499", "1596737018.139038"]], "c": "1967865488"}, "book-100", "XBT/USD"]
[270, {"b": [["11867.80000", "0.25271069", "1596737018.201638"]], "c": "3152979548"}, "book-100", "XBT/USD"]
[270, {"a": [["11881.90000", "7.44236896", "1596737018.202908"]], "c": "3152979548"}, "book-100", "XBT/USD"]
[270, {"a": [["11878.00000", "0.00000000", "1596737018.231954"], ["11911.70000", "0.01000000", "1596737011.251243", "r"]], "c": "3152979548"}, "book-100", "XBT/USD"]
[270, {"a": [["11900.00000", "16.78653131", "1596737018.267784"]], "c": "3152979548"}, "book-100", "XBT/USD"]
[270, {"a": [["11884.30000", "0.84236896", "1596737018.270155"]], "c": "3152979548"}, "book-100", "XBT/USD"]
[270, {"a": [["11900.90000", "2.10253058", "1596737018.315806"]], "c": "3152979548"}, "book-100", "XBT/USD"]
[270, {"a": [["11870.50000", "0.80282106", "1596737018.462547"]], "c": "2889949293"}, "book-100", "XBT/USD"]
[270, {"a": [["11870.40000", "4.28892764", "1596737018.463001"]], "c": "2498392057"}, "book-100", "XBT/USD"]
[270, {"a": [["11870.40000", "4.09573764", "1596737018.463832"]], "c": "3234782752"}, "book-100", "XBT/USD"]
[270, {"a": [["11900.00000", "12.71653131", "1596737018.517776"]], "c": "3234782752"}, "book-100", "XBT/USD"]
[270, {"a": [["11881.70000", "5.85547255", "1596737018.530309"]], "c": "3234782752"}, "book-100", "XBT/USD"]
[270, {"a": [["11870.80000", "0.17120000", "1596737018.543219"]], "c": "2190491336"}, "book-100", "XBT/USD"]
[270, {"a": [["11898.90000", "0.50000000", "1596737018.582547"]], "c": "2190491336"}, "book-100", "XBT/USD"]
[270, {"b": [["11865.00000", "0.20000000", "1596737018.600259"]], "c": "3367915062"}, "book-100", "XBT/USD"]
[270, {"b": [["11865.00000", "0.10000000", "1596737018.604357"]], "c": "2190491336"}, "book-100", "XBT/USD"]
[270, {"a": [["11887.00000", "7.51492625", "1596737018.614685"]], "c": "2190491336"}, "book-100", "XBT/USD"]
[270, {"a": [["11870.90000", "0.80120000", "1596737018.712226"]], "c": "3038976420"}, "book-100", "XBT/USD"]
[270, {"a": [["11872.70000", "0.00000000", "1596737018.716301"], ["11910.50000", "1.68800000", "1596736995.994117", "r"]], "c": "3038976420"}, "book-100", "XBT/USD"]
[270, {"b": [["11855.20000", "0.02885006", "1596737018.748250"]], "c": "3038976420"}, "book-100", "XBT/USD"]
[270, {"b": [["11855.20000", "0.00626507", "1596737018.748505"]], "c": "3038976420"}, "book-100", "XBT/USD"]
[270, {"a": [["11872.30000", "0.00000000", "1596737018.818995"], ["11910.70000", "1.58924162", "1596736944.279722", "r"]], "c": "738535769"}, "book-100", "XBT/USD"]
[270, {"b": [["11866.30000", "0.10000000", "1596737018.843962"]], "c": "2093112535"}, "book-100", "XBT/USD"]
[270, {"b": [["11865.00000", "0.00000000", "1596737018.893001"], ["11810.70000", "13.46787369", "1596737005.994208", "r"]], "c": "1586981170"}, "book-100", "XBT/USD"]
[270, {"a": [["11892.20000", "0.28399999", "1596737018.907879"]], "c": "1586981170"}, "book-100", "XBT/USD"]
[270, {"a": [["11872.80000", "0.25000000", "1596737018.988131"]], "c": "1586981170"}, "book-100", "XBT/USD"]
[270, {"b": [["11814.40000", "0.00000000", "1596737019.144721"], ["11808.80000", "2.66090576", "1596736784.110515", "r"]], "c": "1586981170"}, "book-100", "XBT/USD"]
[270, {"b": [["11814.70000", "4.40575249", "1596737019.177378"]], "c": "1586981170"}, "book-100", "XBT/USD"]
[270, {"b": [["11857.80000", "0.00000000", "1596737019.236476"], ["11808.00000", "0.17065000", "1596737017.603163", "r"]], "c": "1586981170"}, "book-100", "XBT/USD"]
[270, {"a": [["11871.40000", "0.61150353", "1596737019.315469"]], "c": "2137873282"}, "book-100", "XBT/USD"]
[270, {"a": [["11887.10000", "0.69216613", "1596737019.374325"]], "c": "2137873282"}, "book-100", "XBT/USD"]
[270, {"b": [["11866.20000", "0.00000000", "1596737019.466860"], ["11807.70000", "3.28855406", "1596736821.611246", "r"]], "c": "3901249050"}, "book-100", "XBT/USD"]
[270, {"a": [["11873.00000", "0.00000000", "1596737019.467156"], ["11910.50000", "1.68800000", "1596736995.994117", "r"]], "c": "3901249050"}, "book-100", "XBT/USD"]
[270, {"a": [["11870.40000", "3.46403685", "1596737019.467220"]], "c": "1796308961"}, "book-100", "XBT/USD"]
[270, {"b": [["11855.10000", "0.00000000", "1596737019.469136"], ["11807.50000", "2.19772556", "1596736916.776430", "r"]], "c": "1796308961"}, "book-100", "XBT/USD"]
[270, {"a": [["11870.50000", "0.63162106", "1596737019.490716"]], "c": "1932070271"}, "book-100", "XBT/USD"]
[270, {"a": [["11870.80000", "0.00000000", "1596737019.490950"], ["11910.70000", "1.58924162", "1596736944.279722", "r"]], "c": "1555606098"}, "book-100", "XBT/USD"]
[270, {"a": [["11870.90000", "0.63000000", "1596737019.491040"]], "c": "231064418"}, "book-100", "XBT/USD"]
[270, {"a": [["11901.00000", "2.18058177", "1596737019.507098"]], "c": "231064418"}, "book-100", "XBT/USD"]
[270, {"b": [["11849.10000", "3.48827650", "1596737019.519977"]], "c": "231064418"}, "book-100", "XBT/USD"]
[270, {"a": [["11875.90000", "0.00000000", "1596737019.522483"], ["11911.10000", "2.17890497", "1596737013.284792", "r"]], "c": "231064418"}, "book-100", "XBT/USD"]
[270, {"a": [["11870.40000", "3.26403685", "1596737019.538570"]], "c": "4262437355"}, "book-100", "XBT/USD"]
[270, {"b": [["11866.90000", "1.92672696", "1596737019.540013"]], "c": "3437736188"}, "book-100", "XBT/USD"]
[270, {"b": [["11864.50000", "0.00000000", "1596737019.541486"], ["11807.20000", "6.50000000", "1596736936.572585", "r"]], "c": "3174986986"}, "book-100", "XBT/USD"]
[270, {"a": [["11875.30000", "1.84490000", "1596737019.547068"]], "c": "3174986986"}, "book-100", "XBT/USD"]
[270, {"a": [["11872.80000", "0.00000000", "1596737019.556582"], ["11911.60000", "0.75800000", "1596737003.974614", "r"]], "c": "3389503998"}, "book-100", "XBT/USD"]
[270, {"b": [["11850.10000", "0.02300000", "1596737019.571005"]], "c": "3389503998"}, "book-100", "XBT/USD"]
[270, {"a": [["11876.80000", "0.01800000", "1596737019.576303"]], "c": "3389503998"}, "book-100", "XBT/USD"]
[270, {"a": [["11871.10000", "0.00000000", "1596737019.581258"], ["11911.60000", "0.75800000", "1596737003.974614", "r"]], "c": "554625649"}, "book-100", "XBT/USD"]
[270, {"b": [["11854.90000", "0.00626507", "1596737019.599447"]], "c": "554625649"}, "book-100", "XBT/USD"]
[270, {"b": [["11855.20000", "0.00000000", "1596737019.600548"], ["11807.50000", "2.19772556", "1596736916.776430", "r"]], "c": "554625649"}, "book-100", "XBT/USD"]
[270, {"a": [["11870.40000", "3.17979334", "1596737019.621818"]], "c": "4106793692"}, "book-100", "XBT/USD"]
[270, {"b": [["11863.00000", "0.00000000", "1596737019.623124"], ["11807.20000", "6.50000000", "1596736936.572585", "r"]], "c": "1272662288"}, "book-100", "XBT/USD"]
[270, {"a": [["11891.50000", "0.92400000", "1596737019.636499"]], "c": "1272662288"}, "book-100", "XBT/USD"]
[270, {"a": [["11870.50000", "0.00000000", "1596737019.669543"], ["11911.60000", "0.75800000", "1596737003.974614", "r"]], "c": "1742065374"}, "book-100", "XBT/USD"]
[270, {"a": [["11872.50000", "0.17120000", "1596737019.689614"]], "c": "2269219603"}, "book-100", "XBT/USD"]
[270, {"a": [["11870.40000", "2.70691733", "1596737019.724537"]], "c": "1649597219"}, "book-100", "XBT/USD"]
[270, {"b": [["11854.90000", "0.00000000", "1596737019.725057"], ["11805.90000", "0.15000000", "1596735155.182015", "r"]], "c": "1649597219"}, "book-100", "XBT/USD"]
[270, {"a": [["11873.80000", "0.25000000", "1596737019.726572"]], "c": "1649597219"}, "book-100", "XBT/USD"]
[270, {"b": [["11870.30000", "1.58265896", "1596737019.739378"]], "c": "3863204285"}, "book-100", "XBT/USD"]
[270, {"a": [["11871.70000", "0.17120000", "1596737019.745230"]], "c": "2879493155"}, "book-100", "XBT/USD"]
[270, {"a": [["11900.90000", "0.00000000", "1596737019.748050"], ["11910.70000", "1.58924162", "1596736944.279722", "r"]], "c": "2879493155"}, "book-100", "XBT/USD"]
[270, {"b": [["11850.10000", "0.00000000", "1596737019.757003"], ["11805.20000", "0.34533000", "1596735143.806373", "r"]], "c": "2879493155"}, "book-100", "XBT/USD"]
[270, {"a": [["11876.80000", "0.00000000", "1596737019.757103"], ["11911.10000", "2.17890497", "1596737013.284792", "r"]], "c": "2879493155"}, "book-100", "XBT/USD"]
[270, {"b": [["11866.30000", "0.00000000", "1596737019.774877"], ["11804.80000", "3.28996656", "1596736677.195153", "r"]], "c": "2243713591"}, "book-100", "XBT/USD"]
[270, {"b": [["11837.10000", "1.59947305", "1596737019.779880"]], "c": "2243713591"}, "book-100", "XBT/USD"]
[270, {"a": [["11882.40000", "2.16677812", "1596737019.784109"]], "c": "2243713591"}, "book-100", "XBT/USD"]
[270, {"a": [["11871.90000", "0.17120000", "1596737019.785600"]], "c": "1348784316"}, "book-100", "XBT/USD"]
[270, {"a": [["11874.30000", "0.00000000", "1596737019.797459"], ["11911.10000", "2.17890497", "1596737013.284792", "r"]], "c": "1348784316"}, "book-100", "XBT/USD"]
[270, {"a": [["11879.50000", "0.01800000", "1596737019.806880"]], "c": "1348784316"}, "book-100", "XBT/USD"]
[270, {"b": [["11852.10000", "0.55322015", "1596737019.807133"]], "c": "1348784316"}, "book-100", "XBT/USD"]
[270, {"b": [["11866.90000", "1.67400000", "1596737019.815918"]], "c": "782826087"}, "book-100", "XBT/USD"]
[270, {"a": [["11870.40000", "2.20691733", "1596737019.826261"]], "c": "1135329925"}, "book-100", "XBT/USD"]
[270, {"b": [["11862.30000", "0.33698879", "1596737019.845729"]], "c": "1168819476"}, "book-100", "XBT/USD"]
[270, {"a": [["11890.90000", "0.00000000", "1596737019.889164"], ["11911.10000", "2.17890497", "1596737013.284792", "r"]], "c": "1168819476"}, "book-100", "XBT/USD"]
[270, {"a": [["11886.70000", "0.00000000", "1596737019.893093"], ["11911.60000", "0.75800000", "1596737003.974614", "r"]], "c": "1168819476"}, "book-100", "XBT/USD"]
[270, {"a": [["11875.30000", "0.16490000", "1596737019.895113"]], "c": "1168819476"}, "book-100", "XBT/USD"]
[270, {"a": [["11881.80000", "0.00000000", "1596737019.898906"], ["11911.70000", "0.01000000", "1596737011.251243", "r"]], "c": "1168819476"}, "book-100", "XBT/USD"]
[270, {"a": [["11887.10000", "0.00000000", "1596737019.912246"], ["11912.80000", "2.20905635", "1596737019.460690", "r"]], "c": "1168819476"}, "book-100", "XBT/USD"]
[270, {"a": [["11883.60000", "0.84242320", "1596737019.914212"]], "c": "1168819476"}, "book-100", "XBT/USD"]
[270, {"b": [["11859.70000", "0.23800000", "1596737019.918920"]], "c": "1168819476"}, "book-100", "XBT/USD"]
[270, {"a": [["11877.90000", "0.00000000", "1596737019.924408"], ["11913.00000", "0.17065000", "1596736890.849460", "r"]], "c": "1168819476"}, "book-100", "XBT/USD"]
[270, {"a": [["11904.90000", "2.30527932", "1596737019.928940"]], "c": "1168819476"}, "book-100", "XBT/USD"]
[270, {"a": [["11883.00000", "0.00000000", "1596737019.935941"], ["11913.00000", "0.17065000", "1596736890.849460", "r"]], "c": "1168819476"}, "book-100", "XBT/USD"]
[270, {"a": [["11887.70000", "1.88230000", "1596737019.952423"]], "c": "1168819476"}, "book-100", "XBT/USD"]
[270, {"a": [["11879.50000", "0.00000000", "1596737019.986662"], ["11913.00000", "0.17065000", "1596736890.849460", "r"]], "c": "1168819476"}, "book-100", "XBT/USD"]
[270, {"a": [["11877.70000", "0.09250000", "1596737020.052698"]], "c": "1168819476"}, "book-100", "XBT/USD"]
[270, {"a": [["11877.80000", "0.00000000", "1596737020.056561"], ["11913.00000", "0.17065000", "1596736890.849460", "r"]], "c": "1168819476"}, "book-100", "XBT/USD"]
[270, {"a": [["11879.40000", "0.04440539", "1596737020.059679"]], "c": "1168819476"}, "book-100", "XBT/USD"]
[270, {"b": [["11867.80000", "0.00000000", "1596737020.061480"], ["11804.80000", "3.28996656", "1596736677.195153", "r"]], "c": "2404179589"}, "book-100", "XBT/USD"]
[270, {"a": [["11889.00000", "0.00000000", "1596737020.096557"], ["11913.00000", "0.17065000", "1596736890.849460", "r"]], "c": "2404179589"}, "book-100", "XBT/USD"]
[270, {"a": [["11873.80000", "0.00000000", "1596737020.097749"], ["11914.10000", "6.40200000", "1596736948.913868", "r"]], "c": "2404179589"}, "book-100", "XBT/USD"]
[270, {"b": [["11856.10000", "0.00626469", "1596737020.100276"]], "c": "2404179589"}, "book-100", "XBT/USD"]
[270, {"b": [["11869.80000", "0.71832000", "1596737020.119120"]], "c": "2906331057"}, "book-100", "XBT/USD"]
[270, {"b": [["11865.70000", "3.72218814", "1596737020.176688"]], "c": "142217472"}, "book-100", "XBT/USD"]
[270, {"a": [["11888.80000", "0.10909894", "1596737020.201941"]], "c": "142217472"}, "book-100", "XBT/USD"]
[270, {"a": [["11870.90000", "0.00000000", "1596737020.236470"], ["11914.10000", "6.40200000", "1596736948.913868", "r"]], "c": "1776541034"}, "book-100", "XBT/USD"]
[270, {"a": [["11885.40000", "0.92568000", "1596737020.246622"]], "c": "1776541034"}, "book-100", "XBT/USD"]
[270, {"a": [["11877.20000", "0.00000000", "1596737020.253378"], ["11914.10000", "6.40200000", "1596736948.913868", "r"]], "c": "1776541034"}, "book-100", "XBT/USD"]
[270, {"a": [["11871.30000", "0.59341925", "1596737020.266977"]], "c": "4063859025"}, "book-100", "XBT/USD"]
[270, {"a": [["11874.10000", "0.25000000", "1596737020.273587"]], "c": "4063859025"}, "book-100", "XBT/USD"]
[270, {"b": [["11852.90000", "0.00000000", "1596737020.281229"], ["11805.90000", "0.15000000", "1596735155.182015", "r"]], "c": "4063859025"}, "book-100", "XBT/USD"]
[270, {"a": [["11881.40000", "0.00000000", "1596737020.287881"], ["11914.10000", "6.40200000", "1596736948.913868", "r"]], "c": "4063859025"}, "book-100", "XBT/USD"]
[270, {"b": [["11847.80000", "0.00000000", "1596737020.289740"], ["11805.20000", "0.34533000", "1596735143.806373", "r"]], "c": "4063859025"}, "book-100", "XBT/USD"]
[270, {"a": [["11891.40000", "0.00000000", "1596737020.293123"], ["11914.40000", "0.75800000", "1596736271.459783", "r"]], "c": "4063859025"}, "book-100", "XBT/USD"]
[270, {"a": [["11889.30000", "0.00000000", "1596737020.297687"], ["11915.00000", "0.04000000", "1596736997.854126", "r"]], "c": "4063859025"}, "book-100", "XBT/USD"]
[270, {"b": [["11851.30000", "0.00000000", "1596737020.307045"], ["11804.80000", "3.28996656", "1596736677.195153", "r"]], "c": "4063859025"}, "book-100", "XBT/USD"]
[270, {"a": [["11880.40000", "0.69319080", "1596737020.321921"]], "c": "4063859025"}, "book-100", "XBT/USD"]
[270, {"b": [["11862.20000", "0.00000000", "1596737020.323201"], ["11803.60000", "3.21918392", "1596736692.311968", "r"]], "c": "4063859025"}, "book-100", "XBT/USD"]
[270, {"a": [["11893.10000", "0.20396453", "1596737020.334976"]], "c": "4063859025"}, "book-100", "XBT/USD"]
[270, {"a": [["11889.40000", "0.00000000", "1596737020.336589"], ["11914.40000", "0.75800000", "1596736271.459783", "r"]], "c": "4063859025"}, "book-100", "XBT/USD"]
[270, {"a": [["11896.70000", "0.28546393", "1596737020.339029"]], "c": "4063859025"}, "book-100", "XBT/USD"]
[270, {"a": [["11890.20000", "0.00000000", "1596737020.345515"], ["11914.40000", "0.75800000", "1596736271.459783", "r"]], "c": "4063859025"}, "book-100", "XBT/USD"]
[270, {"a": [["11871.20000", "0.00000000", "1596737020.378723"], ["11915.00000", "0.04000000", "1596736997.854126", "r"]], "c": "2636965148"}, "book-100", "XBT/USD"]
[270, {"a": [["11889.20000", "0.00000000", "1596737020.386068"], ["11916.00000", "0.17065000", "1596736840.242690", "r"]], "c": "2636965148"}, "book-100", "XBT/USD"]
[270, {"a": [["11880.20000", "0.00000000", "1596737020.464937"], ["11916.50000", "0.00204079", "1596736766.937570", "r"]], "c": "2636965148"}, "book-100", "XBT/USD"]
[270, {"a": [["11886.20000", "0.32962787", "1596737020.465724"]], "c": "2636965148"}, "book-100", "XBT/USD"]
[270, {"a": [["11889.70000", "0.69201476", "1596737020.467395"]], "c": "2636965148"}, "book-100", "XBT/USD"]
[270, {"a": [["11884.30000", "1.22236896", "1596737020.474645"]], "c": "2636965148"}, "book-100", "XBT/USD"]
[270, {"b": [["11850.90000", "0.28656716", "1596737020.517584"]], "c": "2636965148"}, "book-100", "XBT/USD"]
[270, {"a": [["11883.50000", "0.66681099", "1596737020.560479"]], "c": "2636965148"}, "book-100", "XBT/USD"]
[270, {"a": [["11890.60000", "0.48717604", "1596737020.574754"]], "c": "2636965148"}, "book-100", "XBT/USD"]
[270, {"a": [["11872.60000", "0.00000000", "1596737020.606818"], ["11914.40000", "0.75800000", "1596736271.459783", "r"]], "c": "3251728311"}, "book-100", "XBT/USD"]
[270, {"a": [["11892.30000", "0.76346780", "1596737020.614858"]], "c": "3251728311"}, "book-100", "XBT/USD"]
[270, {"a": [["11873.60000", "0.84171803", "1596737020.629565"]], "c": "2638407014"}, "book-100", "XBT/USD"]
[270, {"b": [["11835.40000", "0.00000000", "1596737020.755462"], ["11803.60000", "3.21918392", "1596736692.311968", "r"]], "c": "2638407014"}, "book-100", "XBT/USD"]
[270, {"b": [["11834.00000", "0.00000000", "1596737020.763234"], ["11803.30000", "0.95003592", "1596736676.897446", "r"]], "c": "2638407014"}, "book-100", "XBT/USD"]
[270, {"a": [["11883.50000", "0.00000000", "1596737020.788618"], ["11914.10000", "6.40200000", "1596736948.913868", "r"]], "c": "2638407014"}, "book-100", "XBT/USD"]
[270, {"b": [["11856.70000", "0.00000000", "1596737020.794381"], ["11801.90000", "4.67249674", "1596736908.903243", "r"]], "c": "2638407014"}, "book-100", "XBT/USD"]
[270, {"a": [["11911.70000", "0.00000000", "1596737020.867574"], ["11914.40000", "0.75800000", "1596736271.459783", "r"]], "c": "2638407014"}, "book-100", "XBT/USD"]
[270, {"b": [["11865.90000", "0.33685197", "1596737020.867720"]], "c": "3121585414"}, "book-100", "XBT/USD"]
[270, {"b": [["11854.20000", "0.69408715", "1596737020.874022"]], "c": "3121585414"}, "book-100", "XBT/USD"]
[270, {"b": [["11869.30000", "0.25266619", "1596737020.874363"]], "c": "2586038448"}, "book-100", "XBT/USD"]
[270, {"a": [["11892.00000", "4.64913667", "1596737020.874429"]], "c": "2586038448"}, "book-100", "XBT/USD"]
[270, {"a": [["11876.00000", "1.24436350", "1596737020.874619"]], "c": "2586038448"}, "book-100", "XBT/USD"]
[270, {"a": [["11873.80000", "0.63159745", "1596737020.874902"]], "c": "2586038448"}, "book-100", "XBT/USD"]
[270, {"b": [["11870.00000", "0.25265323", "1596737020.879846"]], "c": "1960002759"}, "book-100", "XBT/USD"]
[270, {"b": [["11868.50000", "0.25267887", "1596737020.881557"]], "c": "25301553"}, "book-100", "XBT/USD"]
[270, {"a": [["11871.70000", "0.00000000", "1596737020.897297"], ["11914.40000", "0.75800000", "1596736271.459783", "r"]], "c": "123807847"}, "book-100", "XBT/USD"]
[270, {"b": [["11865.20000", "0.33690516", "1596737020.898038"]], "c": "123807847"}, "book-100", "XBT/USD"]
[270, {"b": [["11867.40000", "0.10000000", "1596737020.902926"]], "c": "4060087526"}, "book-100", "XBT/USD"]
[270, {"a": [["11870.40000", "0.70691733", "1596737020.903462"]], "c": "1825230797"}, "book-100", "XBT/USD"]
[270, {"a": [["11877.90000", "0.01800000", "1596737020.903667"]], "c": "1825230797"}, "book-100", "XBT/USD"]
[270, {"a": [["11871.30000", "0.00000000", "1596737020.912898"], ["11914.40000", "0.75800000", "1596736271.459783", "r"]], "c": "818184559"}, "book-100", "XBT/USD"]
[270, {"a": [["11904.00000", "0.00000000", "1596737020.914766"], ["11915.00000", "0.04000000", "1596736997.854126", "r"]], "c": "818184559"}, "book-100", "XBT/USD"]
[270, {"a": [["11895.70000", "0.94245039", "1596737020.947879"]], "c": "818184559"}, "book-100", "XBT/USD"]
[270, {"b": [["11870.30000", "1.68265896", "1596737020.952332"]], "c": "1442692766"}, "book-100", "XBT/USD"]
[270, {"a": [["11881.80000", "0.65392854", "1596737020.955303"]], "c": "1442692766"}, "book-100", "XBT/USD"]
[270, {"a": [["11871.90000", "0.00000000", "1596737020.966990"], ["11914.40000", "0.75800000", "1596736271.459783", "r"]], "c": "1985465154"}, "book-100", "XBT/USD"]
[270, {"a": [["11872.20000", "0.17097000", "1596737020.967152"]], "c": "786741352"}, "book-100", "XBT/USD"]
[270, {"a": [["11886.80000", "0.84217745", "1596737020.979022"]], "c": "786741352"}, "book-100", "XBT/USD"]
[270, {"b": [["11856.30000", "0.00000000", "1596737020.979861"], ["11807.20000", "6.50000000", "1596736936.572585", "r"]], "c": "786741352"}, "book-100", "XBT/USD"]
[270, {"a": [["11894.40000", "0.52834905", "1596737020.982643"]], "c": "786741352"}, "book-100", "XBT/USD"]
[270, {"b": [["11843.40000", "0.05222940", "1596737020.984099"]], "c": "786741352"}, "book-100", "XBT/USD"]
[270, {"b": [["11854.40000", "0.20463039", "1596737020.996568"]], "c": "786741352"}, "book-100", "XBT/USD"]
[270, {"a": [["11877.60000", "0.41011189", "1596737021.003672"]], "c": "786741352"}, "book-100", "XBT/USD"]
[270, {"a": [["11870.40000", "0.60691733", "1596737021.024257"]], "c": "2404181456"}, "book-100", "XBT/USD"]
[270, {"a": [["11883.60000", "1.49051220", "1596737021.042633"]], "c": "2404181456"}, "book-100", "XBT/USD"]
[270, {"a": [["11874.80000", "1.50000000", "1596737021.047373"]], "c": "2404181456"}, "book-100", "XBT/USD"]
[270, {"b": [["11852.10000", "0.53022015", "1596737021.054037"]], "c": "2404181456"}, "book-100", "XBT/USD"]
[270, {"a": [["11877.90000", "0.00000000", "1596737021.054373"], ["11911.60000", "0.75800000", "1596737003.974614", "r"]], "c": "2404181456"}, "book-100", "XBT/USD"]
[270, {"b": [["11870.30000", "1.58265896", "1596737021.098946"]], "c": "3933592097"}, "book-100", "XBT/USD"]
[270, {"b": [["11853.10000", "0.02300000", "1596737021.105397"]], "c": "3933592097"}, "book-100", "XBT/USD"]
[270, {"a": [["11879.90000", "0.02800000", "1596737021.107464"]], "c": "3933592097"}, "book-100", "XBT/USD"]
[270, {"a": [["11888.60000", "0.73941000", "1596737021.108869"]], "c": "3933592097"}, "book-100", "XBT/USD"]
[270, {"a": [["11885.40000", "0.00000000", "1596737021.111283"], ["11911.60000", "0.75800000", "1596737003.974614", "r"]], "c": "3933592097"}, "book-100", "XBT/USD"]
[270, {"b": [["11866.90000", "0.00000000", "1596737021.147460"], ["11807.70000", "3.28855406", "1596736821.611246", "r"]], "c": "2819763186"}, "book-100", "XBT/USD"]
[270, {"a": [["11874.00000", "0.70606787", "1596737021.148155"]], "c": "2819763186"}, "book-100", "XBT/USD"]
[270, {"b": [["11868.90000", "1.67000000", "1596737021.155140"]], "c": "1861301295"}, "book-100", "XBT/USD"]
[270, {"a": [["11873.30000", "0.26673000", "1596737021.165513"]], "c": "3444321167"}, "book-100", "XBT/USD"]
[270, {"a": [["11877.30000", "1.68400000", "1596737021.166147"]], "c": "3444321167"}, "book-100", "XBT/USD"]
[270, {"b": [["11827.90000", "0.00000000", "1596737021.178667"], ["11807.70000", "3.28855406", "1596736821.611246", "r"]], "c": "3444321167"}, "book-100", "XBT/USD"]
[270, {"a": [["11874.80000", "0.00000000", "1596737021.193917"], ["11911.10000", "2.17890497", "1596737013.284792", "r"]], "c": "3444321167"}, "book-100", "XBT/USD"]
[270, {"b": [["11835.00000", "0.01000000", "1596737021.217362"]], "c": "3444321167"}, "book-100", "XBT/USD"]
[270, {"b": [["11857.60000", "0.33042292", "1596737021.247544"]], "c": "3444321167"}, "book-100", "XBT/USD"]
[270, {"a": [["11881.70000", "0.00000000", "1596737021.271697"], ["11911.60000", "0.75800000", "1596737003.974614", "r"]], "c": "3444321167"}, "book-100", "XBT/USD"]
[270, {"a": [["11883.60000", "0.84242320", "1596737021.288441"]], "c": "3444321167"}, "book-100", "XBT/USD"]
[270, {"a": [["11879.90000", "0.01000000", "1596737021.297687"]], "c": "3444321167"}, "book-100", "XBT/USD"]
[270, {"a": [["11874.10000", "0.00000000", "1596737021.333501"], ["11912.80000", "2.20905635", "1596737019.460690", "r"]], "c": "3444321167"}, "book-100", "XBT/USD"]
[270, {"a": [["11874.80000", "1.50000000", "1596737021.347195"]], "c": "3444321167"}, "book-100", "XBT/USD"]
[270, {"a": [["11878.90000", "0.01800000", "1596737021.361825"]], "c": "3444321167"}, "book-100", "XBT/USD"]
[270, {"b": [["11833.90000", "5.95337854", "1596737021.367897"]], "c": "3444321167"}, "book-100", "XBT/USD"]
[270, {"b": [["11830.40000", "0.00000000", "1596737021.383074"], ["11808.80000", "2.66090576", "1596736784.110515", "r"]], "c": "3444321167"}, "book-100", "XBT/USD"]
[270, {"a": [["11893.30000", "5.20382813", "1596737021.394365"]], "c": "3444321167"}, "book-100", "XBT/USD"]
[270, {"a": [["11895.40000", "0.73596923", "1596737021.396233"]], "c": "3444321167"}, "book-100", "XBT/USD"]
[270, {"b": [["11867.40000", "0.00000000", "1596737021.422974"], ["11808.00000", "0.17065000", "1596737017.603163", "r"]], "c": "3528323997"}, "book-100", "XBT/USD"]
[270, {"b": [["11833.10000", "0.73596923", "1596737021.429601"]], "c": "3528323997"}, "book-100", "XBT/USD"]
[270, {"a": [["11887.20000", "5.85359986", "1596737021.446587"]], "c": "3528323997"}, "book-100", "XBT/USD"]
[270, {"b": [["11853.10000", "0.40300000", "1596737021.448863"]], "c": "3528323997"}, "book-100", "XBT/USD"]
[270, {"a": [["11884.20000", "0.67293447", "1596737021.540890"]], "c": "3528323997"}, "book-100", "XBT/USD"]
[270, {"a": [["11874.50000", "0.25000000", "1596737021.605742"]], "c": "3528323997"}, "book-100", "XBT/USD"]
[270, {"a": [["11873.60000", "0.00000000", "1596737021.633046"], ["11910.00000", "0.36067000", "1596736968.148143", "r"]], "c": "310353066"}, "book-100", "XBT/USD"]
[270, {"a": [["11873.70000", "0.00000000", "1596737021.872777"], ["11910.50000", "1.68800000", "1596736995.994117", "r"]], "c": "3060395517"}, "book-100", "XBT/USD"]
[270, {"a": [["11876.00000", "0.40210058", "1596737021.877259"]], "c": "3060395517"}, "book-100", "XBT/USD"]
[270, {"a": [["11886.80000", "0.00000000", "1596737021.877396"], ["11910.70000", "1.58924162", "1596736944.279722", "r"]], "c": "3060395517"}, "book-100", "XBT/USD"]
[270, {"a": [["11875.20000", "0.84174106", "1596737021.877485"]], "c": "3060395517"}, "book-100", "XBT/USD"]
[270, {"b": [["11868.50000", "4.46067887", "1596737021.958890"]], "c": "2293552373"}, "book-100", "XBT/USD"]
[270, {"a": [["11874.60000", "4.20400000", "1596737021.979877"]], "c": "2293552373"}, "book-100", "XBT/USD"]
[270, {"a": [["11870.40000", "0.55941733", "1596737022.112039"]], "c": "2644613909"}, "book-100", "XBT/USD"]
[270, {"a": [["11872.20000", "0.00000000", "1596737022.133356"], ["11910.50000", "1.68800000", "1596736995.994117", "r"]], "c": "174079986"}, "book-100", "XBT/USD"]
[270, {"a": [["11892.90000", "0.00000000", "1596737022.133486"], ["11910.70000", "1.58924162", "1596736944.279722", "r"]], "c": "174079986"}, "book-100", "XBT/USD"]
[270, {"a": [["11872.50000", "0.00000000", "1596737022.135141"], ["11911.10000", "2.17890497", "1596737013.284792", "r"]], "c": "3755629048"}, "book-100", "XBT/USD"]
[270, {"b": [["11852.00000", "0.00000000", "1596737022.171021"], ["11808.00000", "0.17065000", "1596737017.603163", "r"]], "c": "3755629048"}, "book-100", "XBT/USD"]
[270, {"a": [["11872.10000", "0.04750000", "1596737022.240602"]], "c": "2433349237"}, "book-100", "XBT/USD"]
[270, {"b": [["11849.10000", "3.10827650", "1596737022.443120"]], "c": "2433349237"}, "book-100", "XBT/USD"]
[270, {"b": [["11855.80000", "0.03470623", "1596737022.547674"]], "c": "2433349237"}, "book-100", "XBT/USD"]
[270, {"a": [["11872.80000", "0.17066000", "1596737022.569859"]], "c": "153792398"}, "book-100", "XBT/USD"]
[270, {"b": [["11870.30000", "1.18265896", "1596737022.710099"]], "c": "3247011152"}, "book-100", "XBT/USD"]
[270, {"b": [["11870.30000", "1.58265896", "1596737022.733772"]], "c": "153792398"}, "book-100", "XBT/USD"]
[270, {"b": [["11835.00000", "0.00000000", "1596737022.813428"], ["11808.00000", "0.17065000", "1596737017.603163", "r"]], "c": "153792398"}, "book-100", "XBT/USD"]
[270, {"b": [["11836.00000", "0.01000000", "1596737023.028992"]], "c": "153792398"}, "book-100", "XBT/USD"]
[270, {"a": [["11890.60000", "0.00000000", "1596737023.054235"], ["11910.70000", "1.58924162", "1596736944.279722", "r"]], "c": "153792398"}, "book-100", "XBT/USD"]
[270, {"a": [["11879.60000", "0.00000000", "1596737023.057186"], ["11911.10000", "2.17890497", "1596737013.284792", "r"]], "c": "153792398"}, "book-100", "XBT/USD"]
[270, {"a": [["11874.00000", "0.00000000", "1596737023.138455"], ["11911.60000", "0.75800000", "1596737003.974614", "r"]], "c": "1832665570"}, "book-100", "XBT/USD"]
[270, {"b": [["11840.80000", "17.00000000", "1596737023.161225"]], "c": "1832665570"}, "book-100", "XBT/USD"]
[270, {"a": [["11878.60000", "0.84210816", "1596737023.203691"]], "c": "1832665570"}, "book-100", "XBT/USD"]
[270, {"a": [["11877.30000", "2.52610816", "1596737023.204186"]], "c": "1832665570"}, "book-100", "XBT/USD"]
[270, {"a": [["11874.60000", "4.83558112", "1596737023.204883"]], "c": "1685450392"}, "book-100", "XBT/USD"]
[270, {"a": [["11891.40000", "0.48820095", "1596737023.238546"]], "c": "1685450392"}, "book-100", "XBT/USD"]
[270, {"a": [["11883.40000", "0.27100000", "1596737023.280637"]], "c": "1685450392"}, "book-100", "XBT/USD"]
[270, {"a": [["11875.40000", "0.78934399", "1596737023.369480"]], "c": "1685450392"}, "book-100", "XBT/USD"]
[270, {"b": [["11850.40000", "0.68500000", "1596737023.379270"]], "c": "1685450392"}, "book-100", "XBT/USD"]
[270, {"a": [["11874.40000", "0.70000000", "1596737023.422691"]], "c": "1486375151"}, "book-100", "XBT/USD"]
[270, {"a": [["11874.40000", "0.00000000", "1596737023.474897"], ["11910.50000", "1.68800000", "1596736995.994117", "r"]], "c": "1685450392"}, "book-100", "XBT/USD"]
[270, {"a": [["11872.90000", "0.17062000", "1596737023.568425"]], "c": "2501221299"}, "book-100", "XBT/USD"]
[270, {"b": [["11854.80000", "0.00000000", "1596737023.656342"], ["11810.70000", "13.46787369", "1596737005.994208", "r"]], "c": "2501221299"}, "book-100", "XBT/USD"]
[270, {"b": [["11852.40000", "0.00000000", "1596737023.656431"], ["11808.80000", "2.66090576", "1596736784.110515", "r"]], "c": "2501221299"}, "book-100", "XBT/USD"]
[270, {"b": [["11814.00000", "0.17065000", "1596737023.781347"]], "c": "2501221299"}, "book-100", "XBT/USD"]
[270, {"a": [["11872.80000", "0.00000000", "1596737023.799829"], ["11910.50000", "1.68800000", "1596736995.994117", "r"]], "c": "6828016"}, "book-100", "XBT/USD"]
[270, {"b": [["11857.50000", "0.10934297", "1596737023.821159"]], "c": "6828016"}, "book-100", "XBT/USD"]
[270, {"b": [["11855.10000", "0.76555574", "1596737023.821637"]], "c": "6828016"}, "book-100", "XBT/USD"]
[270, {"b": [["11856.10000", "0.00000000", "1596737023.927812"], ["11811.70000", "5.70000000", "1596736886.902857", "r"]], "c": "6828016"}, "book-100", "XBT/USD"]
[270, {"b": [["11856.10000", "0.07212618", "1596737023.941560"]], "c": "6828016"}, "book-100", "XBT/USD"]
[270, {"b": [["11856.10000", "0.00000000", "1596737024.069789"], ["11811.70000", "5.70000000", "1596736886.902857", "r"]], "c": "6828016"}, "book-100", "XBT/USD"]
[270, {"b": [["11856.10000", "0.00626469", "1596737024.071418"]], "c": "6828016"}, "book-100", "XBT/USD"]
[270, {"a": [["11904.80000", "3.00000000", "1596737024.143337"]], "c": "6828016"}, "book-100", "XBT/USD"]
[270, {"a": [["11885.90000", "0.79238000", "1596737024.160837"]], "c": "6828016"}, "book-100", "XBT/USD"]
[270, {"a": [["11873.10000", "0.17062000", "1596737024.265142"]], "c": "3546083081"}, "book-100", "XBT/USD"]
[270, {"a": [["11874.80000", "0.00000000", "1596737024.290364"], ["11909.90000", "6.20000000", "1596736825.518690", "r"]], "c": "3546083081"}, "book-100", "XBT/USD"]
[270, {"a": [["11873.30000", "1.76673000", "1596737024.437124"]], "c": "538802037"}, "book-100", "XBT/USD"]
[270, {"b": [["11848.10000", "0.00000000", "1596737024.440826"], ["11811.70000", "5.70000000", "1596736886.902857", "r"]], "c": "538802037"}, "book-100", "XBT/USD"]
[270, {"b": [["11845.40000", "2.19081811", "1596737024.552023"]], "c": "538802037"}, "book-100", "XBT/USD"]
[270, {"b": [["11836.00000", "0.00000000", "1596737024.554909"], ["11810.70000", "13.46787369", "1596737005.994208", "r"]], "c": "538802037"}, "book-100", "XBT/USD"]
[270, {"b": [["11845.40000", "0.00000000", "1596737024.557598"], ["11808.80000", "2.66090576", "1596736784.110515", "r"]], "c": "538802037"}, "book-100", "XBT/USD"]
[270, {"b": [["11851.40000", "0.00000000", "1596737024.558915"], ["11808.00000", "0.17065000", "1596737017.603163", "r"]], "c": "538802037"}, "book-100", "XBT/USD"]
[270, {"b": [["11810.70000", "1.66787369", "1596737024.568691"]], "c": "538802037"}, "book-100", "XBT/USD"]
[270, {"b": [["11860.00000", "5.30000000", "1596737024.568846"]], "c": "538802037"}, "book-100", "XBT/USD"]
[270, {"b": [["11854.20000", "0.00000000", "1596737024.627011"], ["11808.00000", "0.17065000", "1596737017.603163", "r"]], "c": "538802037"}, "book-100", "XBT/USD"]
[270, {"b": [["11814.00000", "0.00000000", "1596737024.642626"], ["11807.70000", "3.28855406", "1596736821.611246", "r"]], "c": "538802037"}, "book-100", "XBT/USD"]
[270, {"b": [["11857.60000", "0.00000000", "1596737024.679892"], ["11807.50000", "2.19772556", "1596736916.776430", "r"]], "c": "538802037"}, "book-100", "XBT/USD"]
[270, {"b": [["11853.00000", "3.27606908", "1596737024.759788"]], "c": "538802037"}, "book-100", "XBT/USD"]
[270, {"b": [["11848.50000", "0.24913765", "1596737024.768343"]], "c": "538802037"}, "book-100", "XBT/USD"]
[270, {"b": [["11855.70000", "7.78804904", "1596737024.777836"]], "c": "538802037"}, "book-100", "XBT/USD"]
[270, {"b": [["11849.70000", "1.75247259", "1596737024.779032"]], "c": "538802037"}, "book-100", "XBT/USD"]
[270, {"b": [["11838.50000", "0.01000000", "1596737024.783594"]], "c": "538802037"}, "book-100", "XBT/USD"]
[270, {"b": [["11849.60000", "2.18989402", "1596737024.791989"]], "c": "538802037"}, "book-100", "XBT/USD"]
[270, {"a": [["11872.90000", "0.00000000", "1596737024.801931"], ["11910.00000", "0.36067000", "1596736968.148143", "r"]], "c": "3974614562"}, "book-100", "XBT/USD"]
[270, {"a": [["11893.30000", "3.92820867", "1596737024.830058"]], "c": "3974614562"}, "book-100", "XBT/USD"]
[270, {"a": [["11888.80000", "0.00000000", "1596737024.832011"], ["11910.50000", "1.68800000", "1596736995.994117", "r"]], "c": "3974614562"}, "book-100", "XBT/USD"]
[270, {"b": [["11865.10000", "0.50000000", "1596737024.837948"]], "c": "3974614562"}, "book-100", "XBT/USD"]
[270, {"b": [["11856.00000", "0.00000000", "1596737024.838411"], ["11810.70000", "1.66787369", "1596737024.568691", "r"]], "c": "3974614562"}, "book-100", "XBT/USD"]
[270, {"a": [["11871.40000", "0.15000000", "1596737024.852667"]], "c": "1229758743"}, "book-100", "XBT/USD"]
[270, {"a": [["11876.60000", "0.45492987", "1596737024.854997"]], "c": "1229758743"}, "book-100", "XBT/USD"]
[270, {"a": [["11892.00000", "1.38376185", "1596737024.858082"]], "c": "1229758743"}, "book-100", "XBT/USD"]
[270, {"a": [["11893.30000", "1.74604266", "1596737024.867536"]], "c": "1229758743"}, "book-100", "XBT/USD"]
[270, {"a": [["11886.20000", "0.00000000", "1596737024.879705"], ["11910.50000", "1.68800000", "1596736995.994117", "r"]], "c": "1229758743"}, "book-100", "XBT/USD"]
[270, {"a": [["11889.70000", "0.00000000", "1596737024.881811"], ["11910.70000", "1.58924162", "1596736944.279722", "r"]], "c": "1229758743"}, "book-100", "XBT/USD"]
[270, {"a": [["11893.30000", "0.00000000", "1596737024.891169"], ["11911.10000", "2.17890497", "1596737013.284792", "r"]], "c": "1229758743"}, "book-100", "XBT/USD"]
[270, {"b": [["11851.00000", "7.40000000", "1596737024.897209"]], "c": "1229758743"}, "book-100", "XBT/USD"]
[270, {"a": [["11873.50000", "0.00000000", "1596737024.948945"], ["11911.60000", "0.75800000", "1596737003.974614", "r"]], "c": "136952101"}, "book-100", "XBT/USD"]
[270, {"b": [["11856.10000", "0.00000000", "1596737024.968260"], ["11808.80000", "2.66090576", "1596736784.110515", "r"]], "c": "136952101"}, "book-100", "XBT/USD"]
[270, {"b": [["11856.00000", "0.00626469", "1596737024.970261"]], "c": "136952101"}, "book-100", "XBT/USD"]
[270, {"b": [["11858.00000", "0.69388991", "1596737025.035902"]], "c": "136952101"}, "book-100", "XBT/USD"]
[270, {"b": [["11861.50000", "0.43032627", "1596737025.038834"]], "c": "136952101"}, "book-100", "XBT/USD"]
[270, {"b": [["11851.70000", "0.94592880", "1596737025.048267"]], "c": "136952101"}, "book-100", "XBT/USD"]
[270, {"a": [["11891.60000", "1.05193688", "1596737025.082256"]], "c": "136952101"}, "book-100", "XBT/USD"]
[270, {"a": [["11899.90000", "8.88475449", "1596737025.083669"]], "c": "136952101"}, "book-100", "XBT/USD"]
[270, {"b": [["11869.40000", "0.10000000", "1596737025.102396"]], "c": "696767078"}, "book-100", "XBT/USD"]
[270, {"a": [["11877.30000", "0.84210816", "1596737025.175890"]], "c": "696767078"}, "book-100", "XBT/USD"]
[270, {"a": [["11879.20000", "0.14951661", "1596737025.177128"]], "c": "696767078"}, "book-100", "XBT/USD"]
[270, {"a": [["11872.90000", "0.17062000", "1596737025.271938"]], "c": "3355763008"}, "book-100", "XBT/USD"]
[270, {"a": [["11887.90000", "0.32959270", "1596737025.275712"]], "c": "3355763008"}, "book-100", "XBT/USD"]
[270, {"a": [["11891.40000", "1.18014189", "1596737025.277632"]], "c": "3355763008"}, "book-100", "XBT/USD"]
[270, {"b": [["11855.20000", "0.94564954", "1596737025.283406"]], "c": "3355763008"}, "book-100", "XBT/USD"]
[270, {"a": [["11899.70000", "2.18067415", "1596737025.285693"]], "c": "3355763008"}, "book-100", "XBT/USD"]
[270, {"b": [["11854.60000", "0.00000000", "1596737025.325701"], ["11813.30000", "0.99420000", "1596736809.783550", "r"]], "c": "3355763008"}, "book-100", "XBT/USD"]
[270, {"a": [["11896.20000", "3.26417232", "1596737025.331181"]], "c": "3355763008"}, "book-100", "XBT/USD"]
[270, {"b": [["11868.90000", "0.00000000", "1596737025.374817"], ["11811.80000", "4.23305508", "1596736972.960659", "r"]], "c": "925576566"}, "book-100", "XBT/USD"]
[270, {"b": [["11870.30000", "1.68265896", "1596737025.451062"]], "c": "4260681411"}, "book-100", "XBT/USD"]
[270, {"a": [["11872.60000", "0.17062000", "1596737025.469772"]], "c": "625954231"}, "book-100", "XBT/USD"]
[270, {"b": [["11846.50000", "0.47103451", "1596737025.505670"]], "c": "625954231"}, "book-100", "XBT/USD"]
[270, {"b": [["11833.90000", "0.00000000", "1596737025.641770"], ["11811.70000", "5.70000000", "1596736886.902857", "r"]], "c": "625954231"}, "book-100", "XBT/USD"]
[270, {"a": [["11872.40000", "0.17062000", "1596737025.731755"]], "c": "4240683786"}, "book-100", "XBT/USD"]
[270, {"a": [["11872.60000", "0.00000000", "1596737025.734256"], ["11909.10000", "1.00200000", "1596736809.784670", "r"]], "c": "3926863498"}, "book-100", "XBT/USD"]
[270, {"b": [["11837.30000", "5.95161858", "1596737025.745995"]], "c": "3926863498"}, "book-100", "XBT/USD"]
[270, {"b": [["11850.70000", "0.00423026", "1596737025.777375"]], "c": "3926863498"}, "book-100", "XBT/USD"]
[270, {"a": [["11891.30000", "0.00438186", "1596737025.777458"]], "c": "3926863498"}, "book-100", "XBT/USD"]
[270, {"b": [["11850.10000", "1.28011164", "1596737025.777672"]], "c": "3926863498"}, "book-100", "XBT/USD"]
[270, {"b": [["11865.00000", "0.47216135", "1596737025.974044"]], "c": "3926863498"}, "book-100", "XBT/USD"]
[270, {"a": [["11896.70000", "0.33769056", "1596737026.130074"]], "c": "3926863498"}, "book-100", "XBT/USD"]
[270, {"a": [["11871.10000", "0.09621094", "1596737026.271330"]], "c": "324614117"}, "book-100", "XBT/USD"]
[270, {"b": [["11859.90000", "0.09621094", "1596737026.380267"]], "c": "324614117"}, "book-100", "XBT/USD"]
[270, {"a": [["11873.10000", "0.00000000", "1596737026.434198"], ["11908.90000", "1.06880000", "1596736841.521829", "r"]], "c": "296335672"}, "book-100", "XBT/USD"]
[270, {"a": [["11872.90000", "0.00000000", "1596737026.434776"], ["11909.10000", "1.00200000", "1596736809.784670", "r"]], "c": "2013844268"}, "book-100", "XBT/USD"]
[270, {"a": [["11872.40000", "0.00000000", "1596737026.495220"], ["11909.90000", "6.20000000", "1596736825.518690", "r"]], "c": "468258593"}, "book-100", "XBT/USD"]
[270, {"b": [["11869.70000", "0.20000000", "1596737026.558844"]], "c": "851313728"}, "book-100", "XBT/USD"]
[270, {"b": [["11870.30000", "1.58265896", "1596737026.775680"]], "c": "1468480433"}, "book-100", "XBT/USD"]
[270, {"a": [["11898.90000", "0.00000000", "1596737026.780366"], ["11910.00000", "0.36067000", "1596736968.148143", "r"]], "c": "1468480433"}, "book-100", "XBT/USD"]
[270, {"a": [["11870.40000", "0.55740025", "1596737027.058875"]], "c": "3229286669"}, "book-100", "XBT/USD"]
[270, {"b": [["11856.00000", "0.07839148", "1596737027.320991"]], "c": "3229286669"}, "book-100", "XBT/USD"]
[270, {"b": [["11856.00000", "0.07212679", "1596737027.322287"]], "c": "3229286669"}, "book-100", "XBT/USD"]
[270, {"a": [["11880.90000", "0.00000000", "1596737027.558676"], ["11910.50000", "1.68800000", "1596736995.994117", "r"]], "c": "3229286669"}, "book-100", "XBT/USD"]
[270, {"b": [["11856.00000", "0.00000000", "1596737027.588411"], ["11816.00000", "7.80000000", "1596736853.219959", "r"]], "c": "3229286669"}, "book-100", "XBT/USD"]
[270, {"b": [["11856.00000", "0.00626469", "1596737027.597144"]], "c": "3229286669"}, "book-100", "XBT/USD"]
[270, {"a": [["11875.20000", "0.00000000", "1596737027.613783"], ["11910.70000", "1.58924162", "1596736944.279722", "r"]], "c": "3229286669"}, "book-100", "XBT/USD"]
[270, {"b": [["11833.10000", "0.00000000", "1596737027.697888"], ["11816.00000", "7.80000000", "1596736853.219959", "r"]], "c": "3229286669"}, "book-100", "XBT/USD"]
[270, {"a": [["11895.40000", "0.00000000", "1596737027.701328"], ["11911.10000", "2.17890497", "1596737013.284792", "r"]], "c": "3229286669"}, "book-100", "XBT/USD"]
[270, {"b": [["11833.60000", "0.73590629", "1596737027.703076"]], "c": "3229286669"}, "book-100", "XBT/USD"]
[270, {"a": [["11896.10000", "0.73590629", "1596737027.706333"]], "c": "3229286669"}, "book-100", "XBT/USD"]
[270, {"a": [["11885.80000", "1.04962971", "1596737027.793595"]], "c": "3229286669"}, "book-100", "XBT/USD"]
[270, {"a": [["11877.00000", "0.84174104", "1596737027.923277"]], "c": "3229286669"}, "book-100", "XBT/USD"]
[270, {"a": [["11901.60000", "0.50000000", "1596737027.945403"]], "c": "3229286669"}, "book-100", "XBT/USD"]
[270, {"a": [["11875.40000", "0.08690127", "1596737028.391917"]], "c": "3229286669"}, "book-100", "XBT/USD"]
[270, {"a": [["11876.70000", "2.72781329", "1596737028.638371"]], "c": "3229286669"}, "book-100", "XBT/USD"]
[270, {"a": [["11900.00000", "14.46159887", "1596737029.032310"]], "c": "3229286669"}, "book-100", "XBT/USD"]
[270, {"a": [["11873.30000", "1.59600000", "1596737029.070123"]], "c": "362869642"}, "book-100", "XBT/USD"]
[270, {"a": [["11874.10000", "0.17036000", "1596737029.072738"]], "c": "975360803"}, "book-100", "XBT/USD"]
[270, {"a": [["11874.40000", "0.17036000", "1596737029.126769"]], "c": "3587695760"}, "book-100", "XBT/USD"]
[270, {"b": [["11869.40000", "0.00000000", "1596737029.181942"], ["11816.00000", "7.80000000", "1596736853.219959", "r"]], "c": "3151337980"}, "book-100", "XBT/USD"]
[270, {"a": [["11881.40000", "2.00000000", "1596737029.188318"]], "c": "3151337980"}, "book-100", "XBT/USD"]
[270, {"b": [["11870.30000", "1.68265896", "1596737029.189542"]], "c": "1896505929"}, "book-100", "XBT/USD"]
[270, {"b": [["11856.00000", "0.07839148", "1596737029.297661"]], "c": "1896505929"}, "book-100", "XBT/USD"]
[270, {"b": [["11856.00000", "0.07212679", "1596737029.303828"]], "c": "1896505929"}, "book-100", "XBT/USD"]
[270, {"a": [["11877.60000", "2.09311189", "1596737029.314962"]], "c": "1896505929"}, "book-100", "XBT/USD"]
[270, {"b": [["11869.20000", "1.68200000", "1596737029.345222"]], "c": "2450575263"}, "book-100", "XBT/USD"]
[270, {"b": [["11856.00000", "0.00000000", "1596737029.422869"], ["11816.00000", "7.80000000", "1596736853.219959", "r"]], "c": "2450575263"}, "book-100", "XBT/USD"]
[270, {"b": [["11856.00000", "0.00626469", "1596737029.428060"]], "c": "2450575263"}, "book-100", "XBT/USD"]
[270, {"b": [["11869.80000", "0.81832000", "1596737029.438709"]], "c": "1167400225"}, "book-100", "XBT/USD"]
[270, {"a": [["11904.00000", "0.17065000", "1596737029.512890"]], "c": "1167400225"}, "book-100", "XBT/USD"]
[270, {"b": [["11850.60000", "0.00000000", "1596737029.652747"], ["11816.00000", "7.80000000", "1596736853.219959", "r"]], "c": "1167400225"}, "book-100", "XBT/USD"]
[270, {"b": [["11855.80000", "0.00000000", "1596737029.698370"], ["11815.00000", "0.15000000", "1596736658.818582", "r"]], "c": "1167400225"}, "book-100", "XBT/USD"]
[270, {"b": [["11856.10000", "1.04540000", "1596737029.760971"]], "c": "1167400225"}, "book-100", "XBT/USD"]
[270, {"a": [["11892.20000", "0.00000000", "1596737029.943570"], ["11908.30000", "1.58322230", "1596736949.361051", "r"]], "c": "1167400225"}, "book-100", "XBT/USD"]
[270, {"b": [["11859.50000", "0.03498843", "1596737029.970356"]], "c": "1167400225"}, "book-100", "XBT/USD"]
[270, {"a": [["11877.80000", "0.28399999", "1596737029.981419"]], "c": "1167400225"}, "book-100", "XBT/USD"]
[270, {"b": [["11850.70000", "0.00000000", "1596737029.991120"], ["11816.00000", "7.80000000", "1596736853.219959", "r"]], "c": "1167400225"}, "book-100", "XBT/USD"]
[270, {"a": [["11877.70000", "0.00000000", "1596737030.055854"], ["11908.30000", "1.58322230", "1596736949.361051", "r"]], "c": "1167400225"}, "book-100", "XBT/USD"]
[270, {"a": [["11877.50000", "0.04440539", "1596737030.114104"]], "c": "1167400225"}, "book-100", "XBT/USD"]
[270, {"a": [["11879.40000", "0.00000000", "1596737030.120808"], ["11908.30000", "1.58322230", "1596736949.361051", "r"]], "c": "1167400225"}, "book-100", "XBT/USD"]
[270, {"b": [["11837.30000", "0.00000000", "1596737030.166915"], ["11815.80000", "2.20870553", "1596737029.795168", "r"]], "c": "1167400225"}, "book-100", "XBT/USD"]
[270, {"a": [["11904.00000", "0.26315000", "1596737030.179695"]], "c": "1167400225"}, "book-100", "XBT/USD"]
[270, {"b": [["11840.90000", "5.95086463", "1596737030.253647"]], "c": "1167400225"}, "book-100", "XBT/USD"]
[270, {"b": [["11850.50000", "0.00427658", "1596737030.378030"]], "c": "1167400225"}, "book-100", "XBT/USD"]
[270, {"a": [["11877.50000", "0.00000000", "1596737030.718067"], ["11908.90000", "1.06880000", "1596736841.521829", "r"]], "c": "1167400225"}, "book-100", "XBT/USD"]
[270, {"a": [["11874.30000", "0.01630411", "1596737030.726952"]], "c": "3386315257"}, "book-100", "XBT/USD"]
[270, {"b": [["11870.30000", "1.28265896", "1596737030.733791"]], "c": "3176943563"}, "book-100", "XBT/USD"]
[270, {"a": [["11874.30000", "0.18666411", "1596737030.824777"]], "c": "728623230"}, "book-100", "XBT/USD"]
[270, {"a": [["11877.60000", "0.41011189", "1596737030.969199"]], "c": "728623230"}, "book-100", "XBT/USD"]
[270, {"a": [["11880.40000", "0.00000000", "1596737031.182640"], ["11908.90000", "1.06880000", "1596736841.521829", "r"]], "c": "728623230"}, "book-100", "XBT/USD"]
[270, {"a": [["11883.00000", "0.69311499", "1596737031.243198"]], "c": "728623230"}, "book-100", "XBT/USD"]
[270, {"a": [["11874.10000", "0.00000000", "1596737031.267007"], ["11908.90000", "1.06880000", "1596736841.521829", "r"]], "c": "1903709708"}, "book-100", "XBT/USD"]
[270, {"a": [["11874.40000", "0.00000000", "1596737031.275766"], ["11909.10000", "1.00200000", "1596736809.784670", "r"]], "c": "4006690794"}, "book-100", "XBT/USD"]
[270, {"a": [["11891.60000", "0.10902942", "1596737031.285397"]], "c": "4006690794"}, "book-100", "XBT/USD"]
[270, {"b": [["11869.80000", "0.71832000", "1596737031.317196"]], "c": "961867092"}, "book-100", "XBT/USD"]
[270, {"a": [["11874.30000", "0.17036000", "1596737031.404509"]], "c": "2677458023"}, "book-100", "XBT/USD"]
[270, {"a": [["11874.60000", "5.00595112", "1596737031.411919"]], "c": "746592902"}, "book-100", "XBT/USD"]
[270, {"a": [["11874.40000", "0.01630398", "1596737031.413533"]], "c": "2536724930"}, "book-100", "XBT/USD"]
[270, {"a": [["11894.60000", "0.94251533", "1596737031.473013"]], "c": "2536724930"}, "book-100", "XBT/USD"]
[270, {"b": [["11869.90000", "0.10000000", "1596737031.543531"]], "c": "4294168735"}, "book-100", "XBT/USD"]
[270, {"a": [["11880.10000", "0.00000000", "1596737031.678103"], ["11908.90000", "1.06880000", "1596736841.521829", "r"]], "c": "4294168735"}, "book-100", "XBT/USD"]
[270, {"a": [["11885.70000", "0.50000000", "1596737031.686093"]], "c": "4294168735"}, "book-100", "XBT/USD"]
[270, {"b": [["11845.50000", "0.00000000", "1596737032.000070"], ["11817.20000", "1.51500000", "1596736326.967282", "r"]], "c": "4294168735"}, "book-100", "XBT/USD"]
[270, {"b": [["11869.90000", "0.00000000", "1596737032.501890"], ["11816.00000", "7.80000000", "1596736853.219959", "r"]], "c": "2536724930"}, "book-100", "XBT/USD"]
[270, {"a": [["11874.30000", "0.00000000", "1596737032.775950"], ["11908.90000", "1.06880000", "1596736841.521829", "r"]], "c": "2592338864"}, "book-100", "XBT/USD"]
[270, {"b": [["11869.90000", "0.10000000", "1596737032.845987"]], "c": "4064508653"}, "book-100", "XBT/USD"]
[270, {"a": [["11883.10000", "0.86893000", "1596737033.378909"]], "c": "4064508653"}, "book-100", "XBT/USD"]
[270, {"a": [["11870.40000", "1.05740025", "1596737033.667609"]], "c": "338342293"}, "book-100", "XBT/USD"]
[270, {"a": [["11874.20000", "0.17036000", "1596737033.667710"]], "c": "600513027"}, "book-100", "XBT/USD"]
[270, {"b": [["11870.30000", "0.78265896", "1596737033.672226"]], "c": "1623488060"}, "book-100", "XBT/USD"]
[270, {"a": [["11872.30000", "0.17036000", "1596737033.854570"]], "c": "3079531243"}, "book-100", "XBT/USD"]
[270, {"a": [["11872.90000", "0.17036000", "1596737033.861729"]], "c": "230322759"}, "book-100", "XBT/USD"]
[270, {"a": [["11873.20000", "0.17036000", "1596737033.901649"]], "c": "3372428533"}, "book-100", "XBT/USD"]
[270, {"a": [["11878.90000", "0.00000000", "1596737033.923759"], ["11907.20000", "6.18638192", "1596736972.522950", "r"]], "c": "3372428533"}, "book-100", "XBT/USD"]
[270, {"a": [["11870.40000", "0.55740025", "1596737033.956786"]], "c": "3281278394"}, "book-100", "XBT/USD"]
[270, {"b": [["11853.10000", "0.38000000", "1596737033.965625"]], "c": "3281278394"}, "book-100", "XBT/USD"]
[270, {"a": [["11879.90000", "0.02800000", "1596737033.988412"]], "c": "3281278394"}, "book-100", "XBT/USD"]
[270, {"b": [["11854.10000", "0.02300000", "1596737034.022920"]], "c": "3281278394"}, "book-100", "XBT/USD"]
[270, {"a": [["11898.20000", "0.73586713", "1596737034.053135"]], "c": "3281278394"}, "book-100", "XBT/USD"]
[270, {"b": [["11833.60000", "0.00000000", "1596737034.054032"], ["11817.20000", "1.51500000", "1596736326.967282", "r"]], "c": "3281278394"}, "book-100", "XBT/USD"]
[270, {"b": [["11834.90000", "0.73586713", "1596737034.058457"]], "c": "3281278394"}, "book-100", "XBT/USD"]
[270, {"a": [["11896.10000", "0.00000000", "1596737034.059968"], ["11907.20000", "6.18638192", "1596736972.522950", "r"]], "c": "3281278394"}, "book-100", "XBT/USD"]
[270, {"a": [["11873.20000", "0.00000000", "1596737034.073654"], ["11907.50000", "3.26133727", "1596736967.970398", "r"]], "c": "120392456"}, "book-100", "XBT/USD"]
[270, {"b": [["11856.20000", "0.00626463", "1596737034.129688"]], "c": "120392456"}, "book-100", "XBT/USD"]
[270, {"b": [["11856.00000", "0.00000000", "1596737034.135754"], ["11817.60000", "1.06000000", "1596736530.234224", "r"]], "c": "120392456"}, "book-100", "XBT/USD"]
[270, {"a": [["11872.90000", "0.00000000", "1596737034.385698"], ["11907.90000", "2.38150000", "1596736895.960018", "r"]], "c": "542802533"}, "book-100", "XBT/USD"]
[270, {"a": [["11872.30000", "0.00000000", "1596737034.385949"], ["11908.30000", "1.58322230", "1596736949.361051", "r"]], "c": "4145225394"}, "book-100", "XBT/USD"]
[270, {"b": [["11870.30000", "1.28265896", "1596737034.389602"]], "c": "693920588"}, "book-100", "XBT/USD"]
[270, {"b": [["11868.60000", "0.01465226", "1596737034.405263"]], "c": "1158827735"}, "book-100", "XBT/USD"]
[270, {"b": [["11856.20000", "0.01252870", "1596737034.445527"]], "c": "1158827735"}, "book-100", "XBT/USD"]
[270, {"b": [["11856.20000", "0.00626407", "1596737034.446326"]], "c": "1158827735"}, "book-100", "XBT/USD"]
[270, {"a": [["11880.30000", "0.01465226", "1596737034.472137"]], "c": "1158827735"}, "book-100", "XBT/USD"]
[270, {"b": [["11863.50000", "0.07326132", "1596737034.476752"]], "c": "1158827735"}, "book-100", "XBT/USD"]
[270, {"b": [["11862.80000", "0.17582716", "1596737034.539657"]], "c": "1158827735"}, "book-100", "XBT/USD"]
[270, {"a": [["11882.40000", "2.24003944", "1596737034.540272"]], "c": "1158827735"}, "book-100", "XBT/USD"]
[270, {"a": [["11883.90000", "0.17582883", "1596737034.605430"]], "c": "1158827735"}, "book-100", "XBT/USD"]
[270, {"a": [["11874.10000", "0.87820000", "1596737034.839124"]], "c": "2850693982"}, "book-100", "XBT/USD"]
[270, {"a": [["11875.00000", "0.00000000", "1596737034.843296"], ["11907.50000", "3.26133727", "1596736967.970398", "r"]], "c": "2850693982"}, "book-100", "XBT/USD"]
[270, {"b": [["11862.10000", "0.04394378", "1596737034.923573"]], "c": "2850693982"}, "book-100", "XBT/USD"]
[270, {"a": [["11882.90000", "0.04394421", "1596737035.186408"]], "c": "2850693982"}, "book-100", "XBT/USD"]
[270, {"a": [["11874.20000", "0.00000000", "1596737035.454791"], ["11907.50000", "3.26133727", "1596736967.970398", "r"]], "c": "479944598"}, "book-100", "XBT/USD"]
[270, {"a": [["11874.40000", "0.18666398", "1596737035.471830"]], "c": "2238139634"}, "book-100", "XBT/USD"]
[270, {"b": [["11870.30000", "1.18265896", "1596737035.503966"]], "c": "3764286211"}, "book-100", "XBT/USD"]
[270, {"a": [["11874.40000", "1.06486398", "1596737035.515239"]], "c": "2843323510"}, "book-100", "XBT/USD"]
[270, {"b": [["11854.10000", "0.00000000", "1596737035.525651"], ["11820.60000", "2.76416530", "1596736814.796571", "r"]], "c": "2843323510"}, "book-100", "XBT/USD"]
[270, {"a": [["11879.90000", "0.01000000", "1596737035.526665"]], "c": "2843323510"}, "book-100", "XBT/USD"]
[270, {"a": [["11874.60000", "4.83558112", "1596737035.542581"]], "c": "2843323510"}, "book-100", "XBT/USD"]
[270, {"a": [["11874.80000", "0.17036000", "1596737035.549046"]], "c": "2843323510"}, "book-100", "XBT/USD"]
[270, {"a": [["11873.20000", "0.70000000", "1596737035.567559"]], "c": "2856365467"}, "book-100", "XBT/USD"]
[270, {"a": [["11880.90000", "0.01800000", "1596737035.578845"]], "c": "2856365467"}, "book-100", "XBT/USD"]
[270, {"b": [["11855.10000", "0.78855574", "1596737035.578924"]], "c": "2856365467"}, "book-100", "XBT/USD"]
[270, {"b": [["11861.20000", "0.13183264", "1596737035.585535"]], "c": "2856365467"}, "book-100", "XBT/USD"]
[270, {"a": [["11873.20000", "0.00000000", "1596737035.618503"], ["11907.00000", "8.54095785", "1596737002.155356", "r"]], "c": "2843323510"}, "book-100", "XBT/USD"]
[270, {"a": [["11874.40000", "1.04856000", "1596737035.641396"]], "c": "2822837392"}, "book-100", "XBT/USD"]
[270, {"a": [["11874.30000", "0.01630411", "1596737035.646634"]], "c": "3189582776"}, "book-100", "XBT/USD"]
[270, {"b": [["11859.40000", "0.33701506", "1596737035.873676"]], "c": "3189582776"}, "book-100", "XBT/USD"]
[270, {"a": [["11883.50000", "0.13182969", "1596737035.926808"]], "c": "3189582776"}, "book-100", "XBT/USD"]
[270, {"a": [["11874.10000", "0.00000000", "1596737035.926873"], ["11906.70000", "0.02328490", "1596736996.316757", "r"]], "c": "1349095888"}, "book-100", "XBT/USD"]
[270, {"b": [["11870.30000", "1.28265896", "1596737035.983065"]], "c": "894479905"}, "book-100", "XBT/USD"]
[270, {"a": [["11874.30000", "0.89450411", "1596737035.983516"]], "c": "1656319988"}, "book-100", "XBT/USD"]
[270, {"a": [["11874.40000", "0.17036000", "1596737035.986463"]], "c": "1326670009"}, "book-100", "XBT/USD"]
[270, {"b": [["11870.30000", "1.18265896", "1596737036.047095"]], "c": "707419976"}, "book-100", "XBT/USD"]
[270, {"a": [["11875.20000", "0.17037000", "1596737036.047653"]], "c": "707419976"}, "book-100", "XBT/USD"]
[270, {"b": [["11864.80000", "0.27100000", "1596737036.069743"]], "c": "707419976"}, "book-100", "XBT/USD"]
[270, {"b": [["11870.30000", "1.28265896", "1596737036.105743"]], "c": "1326670009"}, "book-100", "XBT/USD"]
[270, {"a": [["11901.60000", "0.00000000", "1596737036.137507"], ["11906.70000", "0.02328490", "1596736996.316757", "r"]], "c": "1326670009"}, "book-100", "XBT/USD"]
[270, {"a": [["11874.40000", "0.00000000", "1596737038.119640"], ["11907.00000", "8.54095785", "1596737002.155356", "r"]], "c": "3351089741"}, "book-100", "XBT/USD"]
[270, {"a": [["11876.20000", "0.00000000", "1596737038.124073"], ["11907.20000", "6.18638192", "1596736972.522950", "r"]], "c": "3351089741"}, "book-100", "XBT/USD"]
[270, {"a": [["11880.30000", "0.00000000", "1596737038.125768"], ["11907.50000", "3.26133727", "1596736967.970398", "r"]], "c": "3351089741"}, "book-100", "XBT/USD"]
[270, {"a": [["11901.90000", "0.50000000", "1596737038.135885"]], "c": "3351089741"}, "book-100", "XBT/USD"]
[270, {"a": [["11873.30000", "1.50000000", "1596737038.176952"]], "c": "46374129"}, "book-100", "XBT/USD"]
[270, {"b": [["11869.90000", "0.00000000", "1596737038.182026"], ["11820.70000", "2.12643506", "1596736941.327806", "r"]], "c": "3007191042"}, "book-100", "XBT/USD"]
[270, {"a": [["11883.50000", "0.00000000", "1596737038.184839"], ["11907.50000", "3.26133727", "1596736967.970398", "r"]], "c": "3007191042"}, "book-100", "XBT/USD"]
[270, {"a": [["11891.40000", "0.69194094", "1596737038.190265"]], "c": "3007191042"}, "book-100", "XBT/USD"]
[270, {"a": [["11904.90000", "0.00000000", "1596737038.195182"], ["11907.90000", "2.38150000", "1596736895.960018", "r"]], "c": "3007191042"}, "book-100", "XBT/USD"]
[270, {"a": [["11874.80000", "0.00000000", "1596737038.204462"], ["11908.30000", "1.58322230", "1596736949.361051", "r"]], "c": "3007191042"}, "book-100", "XBT/USD"]
[270, {"a": [["11874.40000", "0.87820000", "1596737038.207731"]], "c": "80741266"}, "book-100", "XBT/USD"]
[270, {"a": [["11874.30000", "0.01630411", "1596737038.209509"]], "c": "366604711"}, "book-100", "XBT/USD"]
[270, {"a": [["11873.80000", "0.00000000", "1596737038.233851"], ["11908.30000", "1.58322230", "1596736949.361051", "r"]], "c": "3509569223"}, "book-100", "XBT/USD"]
[270, {"a": [["11874.40000", "0.89450398", "1596737038.260434"]], "c": "219770767"}, "book-100", "XBT/USD"]
[270, {"a": [["11874.30000", "0.00000000", "1596737038.261762"], ["11908.90000", "1.06880000", "1596736841.521829", "r"]], "c": "3248518623"}, "book-100", "XBT/USD"]
[270, {"a": [["11890.00000", "1.49199778", "1596737038.337213"]], "c": "3248518623"}, "book-100", "XBT/USD"]
[270, {"a": [["11875.10000", "0.63153400", "1596737038.350428"]], "c": "586324908"}, "book-100", "XBT/USD"]
[270, {"a": [["11882.00000", "0.01465183", "1596737038.367001"]], "c": "586324908"}, "book-100", "XBT/USD"]
[270, {"a": [["11874.90000", "0.17037000", "1596737038.383373"]], "c": "1420885149"}, "book-100", "XBT/USD"]
[270, {"a": [["11874.40000", "0.87820000", "1596737038.392379"]], "c": "731369044"}, "book-100", "XBT/USD"]
[270, {"b": [["11856.20000", "0.00000000", "1596737038.393078"], ["11820.60000", "2.76416530", "1596736814.796571", "r"]], "c": "731369044"}, "book-100", "XBT/USD"]
[270, {"b": [["11858.80000", "0.07210976", "1596737038.393916"]], "c": "731369044"}, "book-100", "XBT/USD"]
[270, {"a": [["11885.00000", "0.13184374", "1596737038.413722"]], "c": "731369044"}, "book-100", "XBT/USD"]
[270, {"a": [["11877.50000", "0.04440539", "1596737038.414394"]], "c": "731369044"}, "book-100", "XBT/USD"]
[270, {"b": [["11870.30000", "1.38265896", "1596737038.933441"]], "c": "3192923844"}, "book-100", "XBT/USD"]
[270, {"a": [["11887.90000", "0.00000000", "1596737038.939557"], ["11907.20000", "6.18638192", "1596736972.522950", "r"]], "c": "3192923844"}, "book-100", "XBT/USD"]
[270, {"a": [["11892.00000", "0.00000000", "1596737038.940201"], ["11907.50000", "3.26133727", "1596736967.970398", "r"]], "c": "3192923844"}, "book-100", "XBT/USD"]
[270, {"a": [["11891.40000", "0.00000000", "1596737038.940614"], ["11907.90000", "2.38150000", "1596736895.960018", "r"]], "c": "3192923844"}, "book-100", "XBT/USD"]
[270, {"a": [["11892.30000", "0.00000000", "1596737038.941601"], ["11908.30000", "1.58322230", "1596736949.361051", "r"]], "c": "3192923844"}, "book-100", "XBT/USD"]
[270, {"a": [["11891.70000", "0.29399999", "1596737038.947269"]], "c": "3192923844"}, "book-100", "XBT/USD"]
[270, {"a": [["11895.30000", "0.00000000", "1596737038.948084"], ["11908.90000", "1.06880000", "1596736841.521829", "r"]], "c": "3192923844"}, "book-100", "XBT/USD"]
[270, {"a": [["11877.80000", "0.00000000", "1596737038.961727"], ["11909.10000", "1.00200000", "1596736809.784670", "r"]], "c": "3192923844"}, "book-100", "XBT/USD"]
[271, [["11870.30000", "0.02650000", "1596737038.998966", "s", "m", ""]], "trade", "XBT/USD"]
[270, {"b": [["11870.30000", "1.35615896", "1596737038.998966"]], "c": "780772218"}, "book-100", "XBT/USD"]
[270, {"a": [["11895.20000", "0.00000000", "1596737039.011585"], ["11909.90000", "6.20000000", "1596736825.518690", "r"]], "c": "780772218"}, "book-100", "XBT/USD"]
[270, {"a": [["11875.00000", "0.17037000", "1596737039.014410"]], "c": "780772218"}, "book-100", "XBT/USD"]
[270, {"a": [["11881.40000", "0.00000000", "1596737039.017693"], ["11909.90000", "6.20000000", "1596736825.518690", "r"]], "c": "780772218"}, "book-100", "XBT/USD"]
[270, {"b": [["11858.80000", "0.00000000", "1596737039.103261"], ["11820.60000", "2.76416530", "1596736814.796571", "r"]], "c": "780772218"}, "book-100", "XBT/USD"]
[270, {"b": [["11858.80000", "0.00827471", "1596737039.104768"]], "c": "780772218"}, "book-100", "XBT/USD"]
[270, {"b": [["11858.80000", "0.01541942", "1596737039.717943"]], "c": "780772218"}, "book-100", "XBT/USD"]
[270, {"a": [["11891.30000", "0.00000000", "1596737039.719264"], ["11910.00000", "0.36067000", "1596736968.148143", "r"]], "c": "780772218"}, "book-100", "XBT/USD"]
[270, {"b": [["11858.80000", "0.00714471", "1596737039.719639"]], "c": "780772218"}, "book-100", "XBT/USD"]
[270, {"a": [["11889.80000", "0.32953997", "1596737039.816321"]], "c": "780772218"}, "book-100", "XBT/USD"]
[270, {"a": [["11895.70000", "2.32583180", "1596737039.821655"]], "c": "780772218"}, "book-100", "XBT/USD"]
[270, {"a": [["11893.30000", "0.69183028", "1596737039.821969"]], "c": "780772218"}, "book-100", "XBT/USD"]
[270, {"a": [["11895.70000", "3.08870401", "1596737039.823831"]], "c": "780772218"}, "book-100", "XBT/USD"]
[270, {"b": [["11858.80000", "0.01340796", "1596737039.860768"]], "c": "780772218"}, "book-100", "XBT/USD"]
[270, {"b": [["11858.80000", "0.00626325", "1596737039.860846"]], "c": "780772218"}, "book-100", "XBT/USD"]
[270, {"a": [["11891.40000", "0.00438186", "1596737039.907559"]], "c": "780772218"}, "book-100", "XBT/USD"]
[270, {"b": [["11850.50000", "0.00000000", "1596737040.099723"], ["11820.60000", "2.76416530", "1596736814.796571", "r"]], "c": "780772218"}, "book-100", "XBT/USD"]
[270, {"b": [["11841.50000", "0.00437695", "1596737040.100007"]], "c": "780772218"}, "book-100", "XBT/USD"]
[270, {"b": [["11841.50000", "0.00000000", "1596737040.294090"], ["11820.60000", "2.76416530", "1596736814.796571", "r"]], "c": "780772218"}, "book-100", "XBT/USD"]
[270, {"b": [["11837.30000", "0.00422160", "1596737040.295170"]], "c": "780772218"}, "book-100", "XBT/USD"]
[270, {"a": [["11898.20000", "0.00000000", "1596737040.425747"], ["11909.10000", "1.00200000", "1596736809.784670", "r"]], "c": "780772218"}, "book-100", "XBT/USD"]
[270, {"a": [["11872.10000", "0.00000000", "1596737040.429555"], ["11909.90000", "6.20000000", "1596736825.518690", "r"]], "c": "2842374853"}, "book-100", "XBT/USD"]
[270, {"b": [["11834.90000", "0.00000000", "1596737040.447009"], ["11820.60000", "2.76416530", "1596736814.796571", "r"]], "c": "2842374853"}, "book-100", "XBT/USD"]
[270, {"b": [["11837.30000", "0.00000000", "1596737040.478504"], ["11820.30000", "5.90000000", "1596735205.963257", "r"]], "c": "2842374853"}, "book-100", "XBT/USD"]
[270, {"b": [["11850.50000", "0.00427756", "1596737040.479121"]], "c": "2842374853"}, "book-100", "XBT/USD"]
[270, {"a": [["11898.60000", "0.73575836", "1596737040.495244"]], "c": "2842374853"}, "book-100", "XBT/USD"]
[270, {"b": [["11834.20000", "0.73575836", "1596737040.498892"]], "c": "2842374853"}, "book-100", "XBT/USD"]
[270, {"b": [["11858.80000", "0.01252644", "1596737040.547107"]], "c": "2842374853"}, "book-100", "XBT/USD"]
[270, {"b": [["11858.80000", "0.00626319", "1596737040.552486"]], "c": "2842374853"}, "book-100", "XBT/USD"]
[270, {"a": [["11873.20000", "0.04750000", "1596737040.672728"]], "c": "589096937"}, "book-100", "XBT/USD"]
[270, {"a": [["11882.90000", "0.00000000", "1596737040.761792"], ["11909.10000", "1.00200000", "1596736809.784670", "r"]], "c": "589096937"}, "book-100", "XBT/USD"]
[270, {"a": [["11883.10000", "0.00000000", "1596737040.823708"], ["11909.90000", "6.20000000", "1596736825.518690", "r"]], "c": "589096937"}, "book-100", "XBT/USD"]
[270, {"b": [["11858.00000", "0.00000000", "1596737040.939614"], ["11820.60000", "2.76416530", "1596736814.796571", "r"]], "c": "589096937"}, "book-100", "XBT/USD"]
[270, {"b": [["11861.50000", "0.10000000", "1596737040.941592"]], "c": "589096937"}, "book-100", "XBT/USD"]
[270, {"a": [["11884.30000", "1.26630306", "1596737040.958485"]], "c": "589096937"}, "book-100", "XBT/USD"]
[270, {"b": [["11859.40000", "1.03082293", "1596737041.305785"]], "c": "589096937"}, "book-100", "XBT/USD"]
[270, {"b": [["11862.80000", "0.50611717", "1596737041.316686"]], "c": "589096937"}, "book-100", "XBT/USD"]
[270, {"b": [["11863.50000", "0.00000000", "1596737041.571507"], ["11820.30000", "5.90000000", "1596735205.963257", "r"]], "c": "589096937"}, "book-100", "XBT/USD"]
[270, {"b": [["11862.80000", "0.33029001", "1596737041.639023"]], "c": "589096937"}, "book-100", "XBT/USD"]
[270, {"b": [["11855.70000", "6.40000000", "1596737041.672797"]], "c": "589096937"}, "book-100", "XBT/USD"]
[270, {"b": [["11865.70000", "3.79544720", "1596737041.792863"]], "c": "589096937"}, "book-100", "XBT/USD"]
[270, {"b": [["11865.10000", "0.67582169", "1596737041.888867"]], "c": "589096937"}, "book-100", "XBT/USD"]
[270, {"b": [["11862.10000", "0.00000000", "1596737041.989190"], ["11820.00000", "0.48150000", "1596736853.873337", "r"]], "c": "589096937"}, "book-100", "XBT/USD"]
[270, {"b": [["11864.30000", "0.04395728", "1596737042.183851"]], "c": "589096937"}, "book-100", "XBT/USD"]
[270, {"b": [["11857.30000", "1.38786539", "1596737042.458836"]], "c": "589096937"}, "book-100", "XBT/USD"]
[270, {"a": [["11874.40000", "0.00000000", "1596737042.622679"], ["11910.00000", "0.36067000", "1596736968.148143", "r"]], "c": "896143618"}, "book-100", "XBT/USD"]
[270, {"b": [["11868.60000", "0.00000000", "1596737042.668738"], ["11820.30000", "5.90000000", "1596735205.963257", "r"]], "c": "2471553591"}, "book-100", "XBT/USD"]
[270, {"b": [["11861.20000", "0.00000000", "1596737042.699872"], ["11820.00000", "0.48150000", "1596736853.873337", "r"]], "c": "2471553591"}, "book-100", "XBT/USD"]
[270, {"b": [["11855.20000", "0.00000000", "1596737042.805246"], ["11817.60000", "1.06000000", "1596736530.234224", "r"]], "c": "2471553591"}, "book-100", "XBT/USD"]
[270, {"a": [["11874.50000", "1.12820000", "1596737042.844188"]], "c": "143390724"}, "book-100", "XBT/USD"]
[270, {"b": [["11869.10000", "0.01465274", "1596737042.879589"]], "c": "2069730305"}, "book-100", "XBT/USD"]
[270, {"a": [["11874.40000", "0.87820000", "1596737043.023591"]], "c": "2967088192"}, "book-100", "XBT/USD"]
[270, {"a": [["11874.50000", "0.25000000", "1596737043.032837"]], "c": "3539722538"}, "book-100", "XBT/USD"]
[270, {"b": [["11863.60000", "0.13187090", "1596737043.043095"]], "c": "3539722538"}, "book-100", "XBT/USD"]
[270, {"b": [["11857.60000", "0.94531934", "1596737043.063940"]], "c": "3539722538"}, "book-100", "XBT/USD"]
[270, {"b": [["11850.90000", "0.00000000", "1596737043.370097"], ["11820.30000", "5.90000000", "1596735205.963257", "r"]], "c": "3539722538"}, "book-100", "XBT/USD"]
[270, {"b": [["11854.40000", "0.00000000", "1596737043.371819"], ["11820.00000", "0.48150000", "1596736853.873337", "r"]], "c": "3539722538"}, "book-100", "XBT/USD"]
[270, {"a": [["11901.40000", "3.09459558", "1596737043.396595"]], "c": "3539722538"}, "book-100", "XBT/USD"]
[270, {"b": [["11858.80000", "0.00000000", "1596737043.506465"], ["11817.60000", "1.06000000", "1596736530.234224", "r"]], "c": "3539722538"}, "book-100", "XBT/USD"]
[270, {"b": [["11858.80000", "0.02087874", "1596737043.506590"]], "c": "3539722538"}, "book-100", "XBT/USD"]
[270, {"b": [["11853.70000", "0.86371136", "1596737043.790995"]], "c": "3539722538"}, "book-100", "XBT/USD"]
[270, {"b": [["11857.30000", "1.59240011", "1596737043.795286"]], "c": "3539722538"}, "book-100", "XBT/USD"]
[270, {"b": [["11852.10000", "0.00000000", "1596737043.998116"], ["11817.60000", "1.06000000", "1596736530.234224", "r"]], "c": "3539722538"}, "book-100", "XBT/USD"]
[270, {"b": [["11859.40000", "0.69380787", "1596737044.042299"]], "c": "3539722538"}, "book-100", "XBT/USD"]
[270, {"a": [["11890.00000", "0.65000000", "1596737044.255591"]], "c": "3539722538"}, "book-100", "XBT/USD"]
[270, {"b": [["11854.70000", "0.53007165", "1596737044.418947"]], "c": "3539722538"}, "book-100", "XBT/USD"]
[270, {"b": [["11868.50000", "4.20800000", "1596737044.506868"]], "c": "787969078"}, "book-100", "XBT/USD"]
[270, {"b": [["11870.30000", "1.60877106", "1596737044.563022"]], "c": "3551140652"}, "book-100", "XBT/USD"]
[270, {"b": [["11868.30000", "0.33681614", "1596737044.563262"]], "c": "198558425"}, "book-100", "XBT/USD"]
[270, {"a": [["11873.90000", "0.63153954", "1596737044.565634"]], "c": "2790679591"}, "book-100", "XBT/USD"]
[270, {"a": [["11883.20000", "0.74236000", "1596737044.568281"]], "c": "2790679591"}, "book-100", "XBT/USD"]
[270, {"a": [["11873.80000", "0.87820000", "1596737044.645343"]], "c": "1874388045"}, "book-100", "XBT/USD"]
[270, {"a": [["11874.40000", "0.00000000", "1596737044.698290"], ["11908.30000", "1.58322230", "1596736949.361051", "r"]], "c": "1925979541"}, "book-100", "XBT/USD"]
[270, {"a": [["11883.70000", "2.00000000", "1596737044.725557"]], "c": "1925979541"}, "book-100", "XBT/USD"]
[270, {"a": [["11900.90000", "6.46388141", "1596737045.103296"]], "c": "1925979541"}, "book-100", "XBT/USD"]
[270, {"b": [["11869.20000", "0.00000000", "1596737045.237512"], ["11820.00000", "0.48150000", "1596736853.873337", "r"]], "c": "3649272057"}, "book-100", "XBT/USD"]
[270, {"b": [["11869.50000", "1.68200000", "1596737045.248220"]], "c": "2631590276"}, "book-100", "XBT/USD"]
[270, {"a": [["11877.90000", "1.67400000", "1596737045.253462"]], "c": "2631590276"}, "book-100", "XBT/USD"]
[270, {"b": [["11870.30000", "1.50877106", "1596737045.286007"]], "c": "4192460405"}, "book-100", "XBT/USD"]
[270, {"b": [["11870.30000", "1.60877106", "1596737045.333361"]], "c": "2631590276"}, "book-100", "XBT/USD"]
[270, {"a": [["11891.50000", "0.00000000", "1596737045.407070"], ["11907.50000", "3.26133727", "1596736967.970398", "r"]], "c": "2631590276"}, "book-100", "XBT/USD"]
[270, {"a": [["11876.70000", "2.02575615", "1596737045.629772"]], "c": "2631590276"}, "book-100", "XBT/USD"]
[270, {"a": [["11874.40000", "0.87820000", "1596737045.730391"]], "c": "2175670364"}, "book-100", "XBT/USD"]
[270, {"a": [["11873.80000", "0.00000000", "1596737045.735125"], ["11907.50000", "3.26133727", "1596736967.970398", "r"]], "c": "1212192822"}, "book-100", "XBT/USD"]
[270, {"a": [["11891.40000", "0.00000000", "1596737045.757847"], ["11907.90000", "2.38150000", "1596736895.960018", "r"]], "c": "1212192822"}, "book-100", "XBT/USD"]
[270, {"a": [["11877.90000", "2.38219524", "1596737045.849301"]], "c": "1212192822"}, "book-100", "XBT/USD"]
[270, {"a": [["11891.60000", "0.11341128", "1596737045.943460"]], "c": "1212192822"}, "book-100", "XBT/USD"]
[270, {"a": [["11873.80000", "0.87820000", "1596737046.057991"]], "c": "2175670364"}, "book-100", "XBT/USD"]
[270, {"a": [["11874.40000", "0.00000000", "1596737046.063761"], ["11907.90000", "2.38150000", "1596736895.960018", "r"]], "c": "2631590276"}, "book-100", "XBT/USD"]
[270, {"a": [["11901.90000", "0.00000000", "1596737046.339695"], ["11908.30000", "1.58322230", "1596736949.361051", "r"]], "c": "2631590276"}, "book-100", "XBT/USD"]
[270, {"a": [["11884.30000", "0.88630306", "1596737046.445342"]], "c": "2631590276"}, "book-100", "XBT/USD"]
[270, {"a": [["11888.10000", "0.38000000", "1596737046.469009"]], "c": "2631590276"}, "book-100", "XBT/USD"]
[270, {"a": [["11873.80000", "0.00000000", "1596737046.529437"], ["11908.30000", "1.58322230", "1596736949.361051", "r"]], "c": "2764583151"}, "book-100", "XBT/USD"]
[270, {"a": [["11874.40000", "0.87820000", "1596737046.553175"]], "c": "1212192822"}, "book-100", "XBT/USD"]
[270, {"b": [["11834.20000", "0.00000000", "1596737046.653880"], ["11820.00000", "0.48150000", "1596736853.873337", "r"]], "c": "1212192822"}, "book-100", "XBT/USD"]
[270, {"a": [["11898.90000", "0.73578920", "1596737046.655047"]], "c": "1212192822"}, "book-100", "XBT/USD"]
[270, {"b": [["11834.00000", "0.73578920", "1596737046.687672"]], "c": "1212192822"}, "book-100", "XBT/USD"]
[270, {"a": [["11898.60000", "0.00000000", "1596737046.723356"], ["11907.90000", "2.38150000", "1596736895.960018", "r"]], "c": "1212192822"}, "book-100", "XBT/USD"]
[270, {"b": [["11845.30000", "0.00000000", "1596737046.749540"], ["11820.00000", "0.48150000", "1596736853.873337", "r"]], "c": "1212192822"}, "book-100", "XBT/USD"]
[270, {"a": [["11874.70000", "0.17624000", "1596737046.789582"]], "c": "1212192822"}, "book-100", "XBT/USD"]
[270, {"b": [["11854.20000", "0.68090000", "1596737046.817356"]], "c": "1212192822"}, "book-100", "XBT/USD"]
[270, {"a": [["11874.40000", "0.00000000", "1596737047.030008"], ["11907.90000", "2.38150000", "1596736895.960018", "r"]], "c": "3466975553"}, "book-100", "XBT/USD"]
[270, {"a": [["11873.80000", "0.87820000", "1596737047.031027"]], "c": "2631590276"}, "book-100", "XBT/USD"]
[270, {"b": [["11858.80000", "0.00000000", "1596737047.069680"], ["11820.00000", "0.48150000", "1596736853.873337", "r"]], "c": "2631590276"}, "book-100", "XBT/USD"]
[270, {"b": [["11858.80000", "0.00626319", "1596737047.073760"]], "c": "2631590276"}, "book-100", "XBT/USD"]
[270, {"a": [["11902.20000", "0.50000000", "1596737047.517086"]], "c": "2631590276"}, "book-100", "XBT/USD"]
[270, {"b": [["11850.40000", "0.00000000", "1596737047.756799"], ["11820.00000", "0.48150000", "1596736853.873337", "r"]], "c": "2631590276"}, "book-100", "XBT/USD"]
[270, {"a": [["11874.40000", "0.87820000", "1596737048.039752"]], "c": "2175670364"}, "book-100", "XBT/USD"]
[270, {"a": [["11873.80000", "0.00000000", "1596737048.045366"], ["11907.20000", "6.18638192", "1596736972.522950", "r"]], "c": "1212192822"}, "book-100", "XBT/USD"]
[270, {"b": [["11850.50000", "0.00000000", "1596737048.103861"], ["11817.60000", "1.06000000", "1596736530.234224", "r"]], "c": "1212192822"}, "book-100", "XBT/USD"]
[270, {"b": [["11850.20000", "0.00433371", "1596737048.295425"]], "c": "1212192822"}, "book-100", "XBT/USD"]
[270, {"b": [["11858.80000", "0.00000000", "1596737048.441294"], ["11817.60000", "1.06000000", "1596736530.234224", "r"]], "c": "1212192822"}, "book-100", "XBT/USD"]
[270, {"b": [["11857.60000", "0.95688035", "1596737048.442304"]], "c": "1212192822"}, "book-100", "XBT/USD"]
[270, {"a": [["11873.80000", "0.87820000", "1596737048.527497"]], "c": "2175670364"}, "book-100", "XBT/USD"]
[270, {"a": [["11874.40000", "0.00000000", "1596737048.591181"], ["11907.20000", "6.18638192", "1596736972.522950", "r"]], "c": "2631590276"}, "book-100", "XBT/USD"]
[270, {"a": [["11874.60000", "5.01182112", "1596737048.776261"]], "c": "1529458654"}, "book-100", "XBT/USD"]
[270, {"a": [["11874.70000", "0.00000000", "1596737048.780466"], ["11907.50000", "3.26133727", "1596736967.970398", "r"]], "c": "1529458654"}, "book-100", "XBT/USD"]
[270, {"b": [["11865.70000", "3.72218814", "1596737048.890915"]], "c": "1529458654"}, "book-100", "XBT/USD"]
[270, {"b": [["11865.10000", "0.50000000", "1596737048.985025"]], "c": "1529458654"}, "book-100", "XBT/USD"]
[270, {"b": [["11866.70000", "0.17583650", "1596737049.192110"]], "c": "1529458654"}, "book-100", "XBT/USD"]
[270, {"b": [["11867.20000", "0.07326521", "1596737049.313798"]], "c": "1529458654"}, "book-100", "XBT/USD"]
[270, {"b": [["11864.30000", "0.00000000", "1596737049.320998"], ["11820.00000", "0.48150000", "1596736853.873337", "r"]], "c": "1529458654"}, "book-100", "XBT/USD"]
[270, {"b": [["11865.60000", "0.04395741", "1596737049.536187"]], "c": "1529458654"}, "book-100", "XBT/USD"]
[271, [["11870.30000", "0.36215896", "1596737049.794176", "s", "l", ""], ["11870.30000", "0.11700000", "1596737049.799178", "s", "l", ""], ["11870.30000", "0.17700000", "1596737049.801575", "s", "l", ""], ["11870.30000", "0.31384104", "1596737049.803403", "s", "l", ""]], "trade", "XBT/USD"]
[270, {"b": [["11870.30000", "1.24661210", "1596737049.794176"], ["11870.30000", "1.12961210", "1596737049.799178"], ["11870.30000", "0.95261210", "1596737049.801575"], ["11870.30000", "0.63877106", "1596737049.803403"]], "c": "3827575513"}, "book-100", "XBT/USD"]
[270, {"a": [["11870.40000", "2.55740025", "1596737049.967331"]], "c": "812957801"}, "book-100", "XBT/USD"]
[270, {"b": [["11863.60000", "0.00000000", "1596737049.988296"], ["11820.00000", "0.48150000", "1596736853.873337", "r"]], "c": "812957801"}, "book-100", "XBT/USD"]
[270, {"b": [["11858.80000", "0.00675183", "1596737050.043468"]], "c": "812957801"}, "book-100", "XBT/USD"]
[270, {"b": [["11859.70000", "0.00000000", "1596737050.043738"], ["11820.00000", "0.48150000", "1596736853.873337", "r"]], "c": "812957801"}, "book-100", "XBT/USD"]
[270, {"b": [["11870.30000", "0.53877106", "1596737050.045914"]], "c": "1431175064"}, "book-100", "XBT/USD"]
[270, {"b": [["11857.60000", "0.94531934", "1596737050.047280"]], "c": "1431175064"}, "book-100", "XBT/USD"]
[270, {"b": [["11863.90000", "0.23800000", "1596737050.049699"]], "c": "1431175064"}, "book-100", "XBT/USD"]
[270, {"b": [["11869.50000", "0.00000000", "1596737050.075421"], ["11820.00000", "0.48150000", "1596736853.873337", "r"]], "c": "1119740554"}, "book-100", "XBT/USD"]
[270, {"b": [["11865.10000", "0.63187245", "1596737050.189572"]], "c": "1119740554"}, "book-100", "XBT/USD"]
[270, {"a": [["11888.60000", "0.00000000", "1596737050.551739"], ["11907.90000", "2.38150000", "1596736895.960018", "r"]], "c": "1119740554"}, "book-100", "XBT/USD"]
[270, {"b": [["11858.80000", "0.00000000", "1596737050.560627"], ["11817.60000", "1.06000000", "1596736530.234224", "r"]], "c": "1119740554"}, "book-100", "XBT/USD"]
[270, {"b": [["11857.60000", "0.95207197", "1596737050.581609"]], "c": "1119740554"}, "book-100", "XBT/USD"]
[270, {"b": [["11869.80000", "0.00000000", "1596737050.582067"], ["11817.20000", "1.51500000", "1596736326.967282", "r"]], "c": "2644095648"}, "book-100", "XBT/USD"]
[270, {"a": [["11879.90000", "0.85165000", "1596737050.582937"]], "c": "2644095648"}, "book-100", "XBT/USD"]
[270, {"a": [["11874.60000", "4.83558112", "1596737050.604540"]], "c": "3097917203"}, "book-100", "XBT/USD"]
[270, {"a": [["11874.50000", "0.00000000", "1596737050.636023"], ["11908.30000", "1.58322230", "1596736949.361051", "r"]], "c": "3838295564"}, "book-100", "XBT/USD"]
[270, {"a": [["11874.70000", "0.17624000", "1596737050.670879"]], "c": "2773838325"}, "book-100", "XBT/USD"]
[270, {"a": [["11873.20000", "0.74750000", "1596737050.682970"]], "c": "2792598143"}, "book-100", "XBT/USD"]
[270, {"a": [["11874.60000", "5.01182112", "1596737050.712957"]], "c": "1185912296"}, "book-100", "XBT/USD"]
[270, {"a": [["11873.20000", "0.04750000", "1596737050.729628"]], "c": "1166628450"}, "book-100", "XBT/USD"]
[270, {"a": [["11874.70000", "0.00000000", "1596737050.749543"], ["11908.30000", "1.58322230", "1596736949.361051", "r"]], "c": "68911515"}, "book-100", "XBT/USD"]
[270, {"a": [["11873.10000", "0.70000000", "1596737050.779200"]], "c": "2995547769"}, "book-100", "XBT/USD"]
[270, {"a": [["11875.10000", "0.00000000", "1596737050.788126"], ["11908.30000", "1.58322230", "1596736949.361051", "r"]], "c": "2995547769"}, "book-100", "XBT/USD"]
[270, {"a": [["11874.60000", "4.83558112", "1596737050.789466"]], "c": "2545134538"}, "book-100", "XBT/USD"]
[270, {"a": [["11899.10000", "1.43578893", "1596737050.791195"]], "c": "2545134538"}, "book-100", "XBT/USD"]
[270, {"b": [["11834.00000", "0.00000000", "1596737050.793528"], ["11816.30000", "2.20827474", "1596737040.492780", "r"]], "c": "2545134538"}, "book-100", "XBT/USD"]
[270, {"b": [["11816.30000", "0.00000000", "1596737050.804816"], ["11816.00000", "10.00836652", "1596737050.794123", "r"]], "c": "2545134538"}, "book-100", "XBT/USD"]
[270, {"a": [["11873.10000", "0.00000000", "1596737050.827337"], ["11908.90000", "1.06880000", "1596736841.521829", "r"]], "c": "3838295564"}, "book-100", "XBT/USD"]
[270, {"a": [["11898.90000", "0.00000000", "1596737050.835946"], ["11909.10000", "1.00200000", "1596736809.784670", "r"]], "c": "3838295564"}, "book-100", "XBT/USD"]
[270, {"a": [["11873.10000", "0.63156528", "1596737050.862533"]], "c": "1369719173"}, "book-100", "XBT/USD"]
[270, {"a": [["11885.90000", "0.00000000", "1596737050.867443"], ["11909.10000", "1.00200000", "1596736809.784670", "r"]], "c": "1369719173"}, "book-100", "XBT/USD"]
[270, {"a": [["11873.00000", "0.70000000", "1596737050.873135"]], "c": "430085173"}, "book-100", "XBT/USD"]
[270, {"b": [["11867.30000", "0.00000000", "1596737050.887107"], ["11815.00000", "0.15000000", "1596736658.818582", "r"]], "c": "3588606050"}, "book-100", "XBT/USD"]
[270, {"a": [["11873.00000", "0.00000000", "1596737050.922639"], ["11909.10000", "1.00200000", "1596736809.784670", "r"]], "c": "2648907218"}, "book-100", "XBT/USD"]
[270, {"b": [["11868.50000", "0.00000000", "1596737050.960894"], ["11814.70000", "2.19669614", "1596737029.794129", "r"]], "c": "950464580"}, "book-100", "XBT/USD"]
[270, {"a": [["11877.90000", "1.67400000", "1596737050.961528"]], "c": "950464580"}, "book-100", "XBT/USD"]
[270, {"a": [["11877.30000", "1.47409816", "1596737050.965627"]], "c": "950464580"}, "book-100", "XBT/USD"]
[270, {"a": [["11872.90000", "0.70000000", "1596737050.968776"]], "c": "4123191407"}, "book-100", "XBT/USD"]
[270, {"b": [["11833.80000", "1.38578893", "1596737050.973533"]], "c": "4123191407"}, "book-100", "XBT/USD"]
[270, {"a": [["11872.80000", "0.25000000", "1596737050.982742"]], "c": "933702970"}, "book-100", "XBT/USD"]
[270, {"a": [["11895.70000", "1.70532260", "1596737051.019176"]], "c": "933702970"}, "book-100", "XBT/USD"]
[270, {"a": [["11889.80000", "0.00000000", "1596737051.022234"], ["11908.90000", "1.06880000", "1596736841.521829", "r"]], "c": "933702970"}, "book-100", "XBT/USD"]
[270, {"a": [["11893.30000", "0.00000000", "1596737051.032047"], ["11909.10000", "1.00200000", "1596736809.784670", "r"]], "c": "933702970"}, "book-100", "XBT/USD"]
[270, {"a": [["11872.90000", "0.00000000", "1596737051.032754"], ["11909.90000", "6.20000000", "1596736825.518690", "r"]], "c": "1752100317"}, "book-100", "XBT/USD"]
[270, {"a": [["11870.40000", "2.83337689", "1596737051.079812"]], "c": "2601123201"}, "book-100", "XBT/USD"]
[270, {"b": [["11870.30000", "0.35261210", "1596737051.080461"]], "c": "1640122171"}, "book-100", "XBT/USD"]
[270, {"a": [["11870.40000", "3.05740025", "1596737051.082642"]], "c": "2352324611"}, "book-100", "XBT/USD"]
[270, {"a": [["11870.40000", "3.52240025", "1596737051.083089"]], "c": "1686006222"}, "book-100", "XBT/USD"]
[270, {"a": [["11872.70000", "0.70000000", "1596737051.084898"]], "c": "779060832"}, "book-100", "XBT/USD"]
[270, {"a": [["11872.70000", "0.87624000", "1596737051.120440"]], "c": "621336567"}, "book-100", "XBT/USD"]
[270, {"b": [["11860.00000", "0.00000000", "1596737051.125315"], ["11813.30000", "0.99420000", "1596736809.783550", "r"]], "c": "621336567"}, "book-100", "XBT/USD"]
[270, {"a": [["11872.70000", "0.17624000", "1596737051.170547"]], "c": "1388795007"}, "book-100", "XBT/USD"]
[270, {"b": [["11870.00000", "0.00000000", "1596737051.216441"], ["11811.80000", "4.23305508", "1596736972.960659", "r"]], "c": "2920532974"}, "book-100", "XBT/USD"]
[270, {"a": [["11876.80000", "0.70261475", "1596737051.231556"]], "c": "2920532974"}, "book-100", "XBT/USD"]
[270, {"a": [["11872.80000", "0.00000000", "1596737051.242385"], ["11909.10000", "1.00200000", "1596736809.784670", "r"]], "c": "1580417064"}, "book-100", "XBT/USD"]
[270, {"a": [["11874.60000", "4.20400000", "1596737051.265952"]], "c": "1580417064"}, "book-100", "XBT/USD"]
[270, {"a": [["11873.10000", "0.00000000", "1596737051.266048"], ["11909.90000", "6.20000000", "1596736825.518690", "r"]], "c": "3702285896"}, "book-100", "XBT/USD"]
[270, {"a": [["11887.50000", "0.32959999", "1596737051.365539"]], "c": "3702285896"}, "book-100", "XBT/USD"]
[270, {"a": [["11893.30000", "1.38364485", "1596737051.367857"]], "c": "3702285896"}, "book-100", "XBT/USD"]
[270, {"b": [["11870.30000", "0.25261210", "1596737051.398679"]], "c": "2037844992"}, "book-100", "XBT/USD"]
[270, {"a": [["11872.70000", "0.00000000", "1596737051.457116"], ["11909.10000", "1.00200000", "1596736809.784670", "r"]], "c": "1106875964"}, "book-100", "XBT/USD"]
[270, {"a": [["11890.90000", "0.69196206", "1596737051.458024"]], "c": "1106875964"}, "book-100", "XBT/USD"]
[270, {"a": [["11891.70000", "0.01000000", "1596737051.493630"]], "c": "1106875964"}, "book-100", "XBT/USD"]
[270, {"a": [["11877.70000", "0.28399999", "1596737051.538337"]], "c": "1106875964"}, "book-100", "XBT/USD"]
[270, {"b": [["11869.80000", "0.10000000", "1596737051.567300"]], "c": "1242035034"}, "book-100", "XBT/USD"]
[270, {"a": [["11874.10000", "0.25000000", "1596737051.604312"]], "c": "1172812237"}, "book-100", "XBT/USD"]
[270, {"b": [["11865.80000", "4.20700000", "1596737051.628124"]], "c": "1172812237"}, "book-100", "XBT/USD"]
[270, {"a": [["11873.40000", "4.20600000", "1596737051.636292"]], "c": "3173429507"}, "book-100", "XBT/USD"]
[270, {"a": [["11874.60000", "0.00000000", "1596737051.643148"], ["11907.90000", "2.38150000", "1596736895.960018", "r"]], "c": "3173429507"}, "book-100", "XBT/USD"]
[270, {"a": [["11874.60000", "0.17624000", "1596737051.723587"]], "c": "3173429507"}, "book-100", "XBT/USD"]
[270, {"a": [["11891.60000", "0.10902942", "1596737051.844940"]], "c": "3173429507"}, "book-100", "XBT/USD"]
[270, {"a": [["11882.00000", "0.00000000", "1596737051.940986"], ["11907.90000", "2.38150000", "1596736895.960018", "r"]], "c": "3173429507"}, "book-100", "XBT/USD"]
[270, {"a": [["11885.00000", "0.00000000", "1596737052.045012"], ["11908.30000", "1.58322230", "1596736949.361051", "r"]], "c": "3173429507"}, "book-100", "XBT/USD"]
[270, {"a": [["11880.60000", "0.01465332", "1596737052.137903"]], "c": "3173429507"}, "book-100", "XBT/USD"]
[270, {"a": [["11893.80000", "0.57700000", "1596737052.679561"]], "c": "3173429507"}, "book-100", "XBT/USD"]
[270, {"a": [["11893.20000", "0.00438186", "1596737052.912339"]], "c": "3173429507"}, "book-100", "XBT/USD"]
[270, {"b": [["11857.40000", "0.00703158", "1596737053.255992"]], "c": "3173429507"}, "book-100", "XBT/USD"]
[270, {"b": [["11857.60000", "0.94531934", "1596737053.258001"]], "c": "3173429507"}, "book-100", "XBT/USD"]
[270, {"a": [["11904.70000", "3.45337572", "1596737053.447592"]], "c": "3173429507"}, "book-100", "XBT/USD"]
[270, {"b": [["11843.20000", "0.35801342", "1596737053.450947"]], "c": "3173429507"}, "book-100", "XBT/USD"]
[270, {"a": [["11890.80000", "0.44698750", "1596737053.455550"]], "c": "3173429507"}, "book-100", "XBT/USD"]
[270, {"b": [["11855.10000", "0.02300000", "1596737053.460848"]], "c": "3173429507"}, "book-100", "XBT/USD"]
[270, {"b": [["11857.50000", "0.00000000", "1596737053.464319"], ["11815.00000", "0.15000000", "1596736658.818582", "r"]], "c": "3173429507"}, "book-100", "XBT/USD"]
[270, {"b": [["11850.20000", "0.00000000", "1596737053.503686"], ["11814.70000", "2.19669614", "1596737029.794129", "r"]], "c": "3173429507"}, "book-100", "XBT/USD"]
[270, {"b": [["11849.70000", "1.75668622", "1596737053.689458"]], "c": "3173429507"}, "book-100", "XBT/USD"]
[270, {"b": [["11857.50000", "0.76509067", "1596737053.734006"]], "c": "3173429507"}, "book-100", "XBT/USD"]
[270, {"b": [["11859.90000", "0.20548749", "1596737053.736153"]], "c": "3173429507"}, "book-100", "XBT/USD"]
[270, {"a": [["11874.10000", "0.00000000", "1596737053.838158"], ["11907.20000", "6.18638192", "1596736972.522950", "r"]], "c": "2402263990"}, "book-100", "XBT/USD"]
[270, {"b": [["11849.70000", "1.75247259", "1596737053.873360"]], "c": "2402263990"}, "book-100", "XBT/USD"]
[270, {"a": [["11893.20000", "0.00000000", "1596737053.875970"], ["11907.50000", "3.26133727", "1596736967.970398", "r"]], "c": "2402263990"}, "book-100", "XBT/USD"]
[270, {"b": [["11826.10000", "0.00439396", "1596737053.876450"]], "c": "2402263990"}, "book-100", "XBT/USD"]
[270, {"a": [["11873.20000", "0.74750000", "1596737053.889360"]], "c": "240519574"}, "book-100", "XBT/USD"]
[270, {"b": [["11826.10000", "0.00000000", "1596737054.070445"], ["11815.00000", "0.15000000", "1596736658.818582", "r"]], "c": "240519574"}, "book-100", "XBT/USD"]
[270, {"a": [["11872.60000", "0.63163408", "1596737054.078696"]], "c": "168641883"}, "book-100", "XBT/USD"]
[270, {"b": [["11870.10000", "0.25263656", "1596737054.078810"]], "c": "3126090930"}, "book-100", "XBT/USD"]
[270, {"a": [["11874.80000", "0.63156142", "1596737054.079328"]], "c": "3126090930"}, "book-100", "XBT/USD"]
[270, {"a": [["11873.20000", "0.04750000", "1596737054.129628"]], "c": "3787703531"}, "book-100", "XBT/USD"]
[270, {"a": [["11875.90000", "0.25000000", "1596737054.139959"]], "c": "3787703531"}, "book-100", "XBT/USD"]
[270, {"a": [["11870.40000", "1.52240025", "1596737054.251457"]], "c": "3309293305"}, "book-100", "XBT/USD"]
[270, {"a": [["11887.20000", "0.00000000", "1596737054.269493"], ["11907.00000", "8.54095785", "1596737002.155356", "r"]], "c": "3309293305"}, "book-100", "XBT/USD"]
[270, {"a": [["11874.60000", "0.00000000", "1596737054.319962"], ["11907.20000", "6.18638192", "1596736972.522950", "r"]], "c": "3309293305"}, "book-100", "XBT/USD"]
[270, {"b": [["11840.90000", "0.00000000", "1596737054.364471"], ["11815.00000", "0.15000000", "1596736658.818582", "r"]], "c": "3309293305"}, "book-100", "XBT/USD"]
[270, {"a": [["11875.90000", "0.00000000", "1596737054.392483"], ["11907.50000", "3.26133727", "1596736967.970398", "r"]], "c": "3309293305"}, "book-100", "XBT/USD"]
[270, {"b": [["11837.30000", "5.95161858", "1596737054.445609"]], "c": "3309293305"}, "book-100", "XBT/USD"]
[270, {"a": [["11881.80000", "0.00000000", "1596737054.521188"], ["11907.90000", "2.38150000", "1596736895.960018", "r"]], "c": "3309293305"}, "book-100", "XBT/USD"]
[270, {"a": [["11886.90000", "5.85162990", "1596737054.525147"]], "c": "3309293305"}, "book-100", "XBT/USD"]
[270, {"b": [["11851.30000", "0.70700000", "1596737054.764769"]], "c": "3309293305"}, "book-100", "XBT/USD"]
[270, {"b": [["11857.40000", "0.00000000", "1596737054.764917"], ["11816.00000", "10.00836652", "1596737050.794123", "r"]], "c": "3309293305"}, "book-100", "XBT/USD"]
[270, {"b": [["11857.60000", "0.95207197", "1596737054.767457"]], "c": "3309293305"}, "book-100", "XBT/USD"]
[270, {"a": [["11881.80000", "0.69160747", "1596737054.853965"]], "c": "3309293305"}, "book-100", "XBT/USD"]
[270, {"a": [["11874.40000", "0.25000000", "1596737054.898418"]], "c": "3309293305"}, "book-100", "XBT/USD"]
[270, {"a": [["11874.80000", "0.00000000", "1596737054.939939"], ["11907.20000", "6.18638192", "1596736972.522950", "r"]], "c": "3309293305"}, "book-100", "XBT/USD"]
[270, {"a": [["11884.30000", "0.84236896", "1596737054.986278"]], "c": "3309293305"}, "book-100", "XBT/USD"]
[270, {"a": [["11872.50000", "0.17624000", "1596737055.318912"]], "c": "808082775"}, "book-100", "XBT/USD"]
[270, {"a": [["11873.20000", "0.91030000", "1596737055.380866"]], "c": "393549025"}, "book-100", "XBT/USD"]
[270, {"a": [["11873.80000", "0.00000000", "1596737055.385942"], ["11907.20000", "6.18638192", "1596736972.522950", "r"]], "c": "3191078493"}, "book-100", "XBT/USD"]
[270, {"a": [["11872.40000", "0.70000000", "1596737055.433304"]], "c": "2506960446"}, "book-100", "XBT/USD"]
[270, {"a": [["11872.40000", "0.00000000", "1596737055.479682"], ["11907.20000", "6.18638192", "1596736972.522950", "r"]], "c": "3191078493"}, "book-100", "XBT/USD"]
[270, {"b": [["11827.70000", "0.00000000", "1596737055.713924"], ["11815.00000", "0.15000000", "1596736658.818582", "r"]], "c": "3191078493"}, "book-100", "XBT/USD"]
[270, {"a": [["11902.20000", "0.00000000", "1596737055.717339"], ["11907.50000", "3.26133727", "1596736967.970398", "r"]], "c": "3191078493"}, "book-100", "XBT/USD"]
[270, {"b": [["11862.80000", "0.00000000", "1596737055.730244"], ["11814.70000", "2.19669614", "1596737029.794129", "r"]], "c": "3191078493"}, "book-100", "XBT/USD"]
[270, {"b": [["11846.60000", "0.00000000", "1596737055.739058"], ["11813.30000", "0.99420000", "1596736809.783550", "r"]], "c": "3191078493"}, "book-100", "XBT/USD"]
[270, {"b": [["11851.70000", "0.00000000", "1596737055.739690"], ["11811.80000", "4.23305508", "1596736972.960659", "r"]], "c": "3191078493"}, "book-100", "XBT/USD"]
[270, {"b": [["11846.30000", "3.27875095", "1596737055.739755"]], "c": "3191078493"}, "book-100", "XBT/USD"]
[270, {"b": [["11820.70000", "0.00000000", "1596737055.743219"], ["11811.70000", "5.70000000", "1596736886.902857", "r"]], "c": "3191078493"}, "book-100", "XBT/USD"]
[270, {"b": [["11846.50000", "0.00000000", "1596737055.753661"], ["11811.00000", "0.17065000", "1596737029.361409", "r"]], "c": "3191078493"}, "book-100", "XBT/USD"]
[270, {"b": [["11850.10000", "0.00000000", "1596737055.762570"], ["11810.70000", "1.66787369", "1596737024.568691", "r"]], "c": "3191078493"}, "book-100", "XBT/USD"]
[270, {"b": [["11859.40000", "0.00000000", "1596737055.766846"], ["11808.80000", "2.66090576", "1596736784.110515", "r"]], "c": "3191078493"}, "book-100", "XBT/USD"]
[270, {"b": [["11857.30000", "0.20453472", "1596737055.768032"]], "c": "3191078493"}, "book-100", "XBT/USD"]
[270, {"b": [["11820.60000", "0.00000000", "1596737055.773554"], ["11808.70000", "9.70000000", "1596737024.924486", "r"]], "c": "3191078493"}, "book-100", "XBT/USD"]
[270, {"b": [["11849.70000", "0.00000000", "1596737055.776583"], ["11808.00000", "0.17065000", "1596737017.603163", "r"]], "c": "3191078493"}, "book-100", "XBT/USD"]
[270, {"b": [["11853.00000", "0.00000000", "1596737055.790706"], ["11807.70000", "3.28855406", "1596736821.611246", "r"]], "c": "3191078493"}, "book-100", "XBT/USD"]
[270, {"b": [["11869.80000", "0.00000000", "1596737055.811608"], ["11807.50000", "2.19772556", "1596736916.776430", "r"]], "c": "143475679"}, "book-100", "XBT/USD"]
[270, {"b": [["11846.30000", "0.00000000", "1596737055.821466"], ["11806.30000", "5.40000000", "1596737051.417403", "r"]], "c": "143475679"}, "book-100", "XBT/USD"]
[270, {"b": [["11849.10000", "0.00000000", "1596737055.821701"], ["11805.90000", "0.15000000", "1596735155.182015", "r"]], "c": "143475679"}, "book-100", "XBT/USD"]
[270, {"b": [["11827.80000", "0.00000000", "1596737055.822634"], ["11805.20000", "0.34533000", "1596735143.806373", "r"]], "c": "143475679"}, "book-100", "XBT/USD"]
[270, {"b": [["11849.60000", "0.00000000", "1596737055.874458"], ["11805.00000", "0.17065000", "1596737034.949636", "r"]], "c": "143475679"}, "book-100", "XBT/USD"]
[270, {"b": [["11851.30000", "1.98646341", "1596737055.951058"]], "c": "143475679"}, "book-100", "XBT/USD"]
[270, {"b": [["11827.70000", "2.45445863", "1596737055.951124"]], "c": "143475679"}, "book-100", "XBT/USD"]
[270, {"b": [["11849.00000", "6.96371753", "1596737055.956588"]], "c": "143475679"}, "book-100", "XBT/USD"]
[270, {"b": [["11827.80000", "0.96375843", "1596737055.958667"]], "c": "143475679"}, "book-100", "XBT/USD"]
[270, {"b": [["11870.20000", "1.09950000", "1596737055.967796"]], "c": "3528527856"}, "book-100", "XBT/USD"]
[270, {"b": [["11849.00000", "0.47078264", "1596737055.989684"]], "c": "3528527856"}, "book-100", "XBT/USD"]
[270, {"b": [["11863.10000", "0.33027065", "1596737055.992485"]], "c": "3528527856"}, "book-100", "XBT/USD"]
[270, {"b": [["11859.70000", "0.69376719", "1596737055.998143"]], "c": "3528527856"}, "book-100", "XBT/USD"]
[270, {"b": [["11857.30000", "1.59234995", "1596737056.008297"]], "c": "3528527856"}, "book-100", "XBT/USD"]
[270, {"b": [["11827.80000", "3.71318603", "1596737056.055434"]], "c": "3528527856"}, "book-100", "XBT/USD"]
[270, {"b": [["11851.40000", "1.75216250", "1596737056.062692"]], "c": "3528527856"}, "book-100", "XBT/USD"]
[270, {"a": [["11906.70000", "0.00000000", "1596737056.081919"], ["11907.90000", "2.38150000", "1596736895.960018", "r"]], "c": "3528527856"}, "book-100", "XBT/USD"]
[270, {"b": [["11827.80000", "5.83863846", "1596737056.098879"]], "c": "3528527856"}, "book-100", "XBT/USD"]
[270, {"b": [["11849.00000", "1.53160745", "1596737056.110446"]], "c": "3528527856"}, "book-100", "XBT/USD"]
[270, {"a": [["11872.50000", "0.00000000", "1596737056.114667"], ["11908.30000", "1.58322230", "1596736949.361051", "r"]], "c": "4244401217"}, "book-100", "XBT/USD"]
[270, {"b": [["11851.30000", "4.17563673", "1596737056.125806"]], "c": "4244401217"}, "book-100", "XBT/USD"]
[270, {"b": [["11848.70000", "0.94601627", "1596737056.171152"]], "c": "4244401217"}, "book-100", "XBT/USD"]
[270, {"b": [["11853.40000", "0.94564116", "1596737056.177926"]], "c": "4244401217"}, "book-100", "XBT/USD"]
[270, {"a": [["11890.80000", "0.00000000", "1596737056.211005"], ["11908.90000", "1.06880000", "1596736841.521829", "r"]], "c": "4244401217"}, "book-100", "XBT/USD"]
[270, {"b": [["11848.80000", "3.27684361", "1596737056.320398"]], "c": "4244401217"}, "book-100", "XBT/USD"]
[270, {"b": [["11854.70000", "3.80528440", "1596737056.322000"]], "c": "4244401217"}, "book-100", "XBT/USD"]
[270, {"a": [["11890.80000", "0.44567053", "1596737056.401477"]], "c": "4244401217"}, "book-100", "XBT/USD"]
[270, {"b": [["11859.90000", "0.09621094", "1596737056.421691"]], "c": "4244401217"}, "book-100", "XBT/USD"]
[270, {"b": [["11863.10000", "0.00000000", "1596737056.427385"], ["11808.70000", "9.70000000", "1596737024.924486", "r"]], "c": "4244401217"}, "book-100", "XBT/USD"]
[270, {"b": [["11859.70000", "0.00000000", "1596737056.428810"], ["11808.00000", "0.17065000", "1596737017.603163", "r"]], "c": "4244401217"}, "book-100", "XBT/USD"]
[270, {"a": [["11894.60000", "0.00000000", "1596737056.439552"], ["11908.90000", "1.06880000", "1596736841.521829", "r"]], "c": "4244401217"}, "book-100", "XBT/USD"]
[270, {"a": [["11901.40000", "0.00000000", "1596737056.465973"], ["11909.10000", "1.00200000", "1596736809.784670", "r"]], "c": "4244401217"}, "book-100", "XBT/USD"]
[270, {"a": [["11887.50000", "0.00000000", "1596737056.470566"], ["11909.90000", "6.20000000", "1596736825.518690", "r"]], "c": "4244401217"}, "book-100", "XBT/USD"]
[270, {"a": [["11895.70000", "0.94245039", "1596737056.504569"]], "c": "4244401217"}, "book-100", "XBT/USD"]
[270, {"a": [["11906.70000", "0.02328140", "1596737056.573166"]], "c": "4244401217"}, "book-100", "XBT/USD"]
[270, {"b": [["11849.30000", "6.49198752", "1596737056.573369"]], "c": "4244401217"}, "book-100", "XBT/USD"]
[270, {"a": [["11893.30000", "2.14643252", "1596737056.709027"]], "c": "4244401217"}, "book-100", "XBT/USD"]
[270, {"b": [["11857.30000", "1.70165046", "1596737056.710519"]], "c": "4244401217"}, "book-100", "XBT/USD"]
[270, {"a": [["11893.40000", "0.94246077", "1596737056.827180"]], "c": "4244401217"}, "book-100", "XBT/USD"]
[270, {"a": [["11900.50000", "0.50000000", "1596737056.894264"]], "c": "4244401217"}, "book-100", "XBT/USD"]
[270, {"b": [["11857.60000", "0.94531934", "1596737056.920346"]], "c": "4244401217"}, "book-100", "XBT/USD"]
[270, {"b": [["11857.40000", "0.00703158", "1596737056.924279"]], "c": "4244401217"}, "book-100", "XBT/USD"]
[270, {"a": [["11899.00000", "3.55432013", "1596737057.102681"]], "c": "4244401217"}, "book-100", "XBT/USD"]
[270, {"a": [["11899.10000", "0.70000000", "1596737057.106483"]], "c": "4244401217"}, "book-100", "XBT/USD"]
[270, {"a": [["11872.10000", "0.63160688", "1596737057.198506"]], "c": "3038357338"}, "book-100", "XBT/USD"]
[270, {"b": [["11849.40000", "0.00449210", "1596737057.273587"]], "c": "3038357338"}, "book-100", "XBT/USD"]
[270, {"b": [["11810.80000", "0.01263652", "1596737057.274001"]], "c": "3038357338"}, "book-100", "XBT/USD"]
[270, {"a": [["11893.20000", "0.00438186", "1596737057.275555"]], "c": "3038357338"}, "book-100", "XBT/USD"]
[270, {"b": [["11854.70000", "3.27521275", "1596737057.398810"]], "c": "3038357338"}, "book-100", "XBT/USD"]
[270, {"b": [["11857.30000", "1.59234995", "1596737057.428496"]], "c": "3038357338"}, "book-100", "XBT/USD"]
[270, {"b": [["11857.30000", "0.20453472", "1596737057.438236"]], "c": "3038357338"}, "book-100", "XBT/USD"]
[270, {"b": [["11856.70000", "0.53006794", "1596737057.618569"]], "c": "3038357338"}, "book-100", "XBT/USD"]
[270, {"b": [["11861.30000", "0.10928808", "1596737057.772726"]], "c": "3038357338"}, "book-100", "XBT/USD"]
[270, {"b": [["11870.20000", "0.99950000", "1596737057.866656"]], "c": "2641306948"}, "book-100", "XBT/USD"]
[270, {"b": [["11849.30000", "0.00000000", "1596737057.898320"], ["11811.00000", "0.17065000", "1596737029.361409", "r"]], "c": "2641306948"}, "book-100", "XBT/USD"]
[270, {"a": [["11871.30000", "0.70000000", "1596737057.919051"]], "c": "2957554531"}, "book-100", "XBT/USD"]
[270, {"b": [["11857.40000", "0.00000000", "1596737057.922622"], ["11810.80000", "0.01263652", "1596737057.274001", "r"]], "c": "2957554531"}, "book-100", "XBT/USD"]
[270, {"b": [["11856.80000", "0.01631508", "1596737057.924586"]], "c": "2957554531"}, "book-100", "XBT/USD"]
[270, {"a": [["11872.10000", "0.00000000", "1596737057.924661"], ["11907.50000", "3.26133727", "1596736967.970398", "r"]], "c": "2145892862"}, "book-100", "XBT/USD"]
[270, {"b": [["11866.70000", "0.00000000", "1596737057.938822"], ["11810.80000", "0.01263652", "1596737057.274001", "r"]], "c": "1415498245"}, "book-100", "XBT/USD"]
[270, {"a": [["11871.30000", "0.00000000", "1596737057.967850"], ["11907.90000", "2.38150000", "1596736895.960018", "r"]], "c": "921555728"}, "book-100", "XBT/USD"]
[270, {"a": [["11874.70000", "0.17624000", "1596737057.990173"]], "c": "921555728"}, "book-100", "XBT/USD"]
[270, {"b": [["11870.30000", "0.35261210", "1596737057.998785"]], "c": "2469837144"}, "book-100", "XBT/USD"]
[270, {"b": [["11856.70000", "0.00000000", "1596737058.041837"], ["11810.70000", "1.66787369", "1596737024.568691", "r"]], "c": "2469837144"}, "book-100", "XBT/USD"]
[270, {"b": [["11861.30000", "0.00000000", "1596737058.042528"], ["11808.80000", "2.66090576", "1596736784.110515", "r"]], "c": "2469837144"}, "book-100", "XBT/USD"]
[270, {"b": [["11857.60000", "0.00000000", "1596737058.070854"], ["11808.70000", "9.70000000", "1596737024.924486", "r"]], "c": "2469837144"}, "book-100", "XBT/USD"]
[270, {"b": [["11857.20000", "0.10932587", "1596737058.262370"]], "c": "2469837144"}, "book-100", "XBT/USD"]
[270, {"b": [["11852.50000", "0.53025577", "1596737058.396918"]], "c": "2469837144"}, "book-100", "XBT/USD"]
[270, {"b": [["11854.60000", "0.94554544", "1596737058.502855"]], "c": "2469837144"}, "book-100", "XBT/USD"]
[270, {"b": [["11864.60000", "2.01826420", "1596737058.704866"]], "c": "2469837144"}, "book-100", "XBT/USD"]
[270, {"b": [["11849.40000", "0.00000000", "1596737058.876851"], ["11810.80000", "0.01263652", "1596737057.274001", "r"]], "c": "2469837144"}, "book-100", "XBT/USD"]
[270, {"a": [["11881.30000", "3.59508535", "1596737058.954819"]], "c": "2469837144"}, "book-100", "XBT/USD"]
[270, {"a": [["11874.40000", "0.00000000", "1596737058.989448"], ["11907.50000", "3.26133727", "1596736967.970398", "r"]], "c": "2530002700"}, "book-100", "XBT/USD"]
[270, {"b": [["11852.50000", "0.00000000", "1596737059.031625"], ["11810.70000", "1.66787369", "1596737024.568691", "r"]], "c": "2530002700"}, "book-100", "XBT/USD"]
[270, {"b": [["11849.10000", "0.00456223", "1596737059.064129"]], "c": "2530002700"}, "book-100", "XBT/USD"]
[270, {"a": [["11881.80000", "0.00000000", "1596737059.078945"], ["11907.90000", "2.38150000", "1596736895.960018", "r"]], "c": "2530002700"}, "book-100", "XBT/USD"]
[270, {"a": [["11875.00000", "0.42037000", "1596737059.144689"]], "c": "2530002700"}, "book-100", "XBT/USD"]
[270, {"b": [["11856.80000", "0.00000000", "1596737059.206052"], ["11810.70000", "1.66787369", "1596737024.568691", "r"]], "c": "2530002700"}, "book-100", "XBT/USD"]
[270, {"b": [["11854.60000", "0.00000000", "1596737059.226981"], ["11808.80000", "2.66090576", "1596736784.110515", "r"]], "c": "2530002700"}, "book-100", "XBT/USD"]
[270, {"b": [["11856.20000", "0.01631508", "1596737059.255935"]], "c": "2530002700"}, "book-100", "XBT/USD"]
[270, {"b": [["11856.20000", "0.00000000", "1596737059.380264"], ["11808.80000", "2.66090576", "1596736784.110515", "r"]], "c": "2530002700"}, "book-100", "XBT/USD"]
[270, {"b": [["11854.60000", "0.53016184", "1596737059.384567"]], "c": "2530002700"}, "book-100", "XBT/USD"]
[270, {"b": [["11865.70000", "0.00000000", "1596737059.446004"], ["11808.80000", "2.66090576", "1596736784.110515", "r"]], "c": "2530002700"}, "book-100", "XBT/USD"]
[270, {"b": [["11856.20000", "0.01156101", "1596737059.458299"]], "c": "2530002700"}, "book-100", "XBT/USD"]
[270, {"a": [["11872.50000", "0.70000000", "1596737059.495759"]], "c": "3252859551"}, "book-100", "XBT/USD"]
[270, {"b": [["11856.70000", "0.94531603", "1596737059.498160"]], "c": "3252859551"}, "book-100", "XBT/USD"]
[270, {"a": [["11882.40000", "0.17526132", "1596737059.583005"]], "c": "3252859551"}, "book-100", "XBT/USD"]
[270, {"a": [["11873.10000", "0.63158914", "1596737059.942620"]], "c": "1014468397"}, "book-100", "XBT/USD"]
[270, {"a": [["11881.20000", "0.66593994", "1596737060.002477"]], "c": "1014468397"}, "book-100", "XBT/USD"]
[270, {"b": [["11857.30000", "1.59226100", "1596737060.082113"]], "c": "1014468397"}, "book-100", "XBT/USD"]
[270, {"a": [["11887.60000", "0.34456884", "1596737060.088588"]], "c": "1014468397"}, "book-100", "XBT/USD"]
[270, {"b": [["11863.10000", "0.33024948", "1596737060.089320"]], "c": "1014468397"}, "book-100", "XBT/USD"]
[270, {"b": [["11859.70000", "0.69372273", "1596737060.091130"]], "c": "1014468397"}, "book-100", "XBT/USD"]
[270, {"b": [["11831.60000", "0.00000000", "1596737060.124324"], ["11811.00000", "0.17065000", "1596737029.361409", "r"]], "c": "1014468397"}, "book-100", "XBT/USD"]
[270, {"a": [["11874.50000", "0.18224000", "1596737060.181305"]], "c": "1014468397"}, "book-100", "XBT/USD"]
[270, {"a": [["11874.70000", "0.00000000", "1596737060.181400"], ["11907.00000", "8.54095785", "1596737002.155356", "r"]], "c": "1014468397"}, "book-100", "XBT/USD"]
[270, {"a": [["11872.50000", "0.00000000", "1596737060.229056"], ["11907.20000", "6.18638192", "1596736972.522950", "r"]], "c": "1604994434"}, "book-100", "XBT/USD"]
[270, {"a": [["11870.40000", "3.52240025", "1596737060.235444"]], "c": "3347839155"}, "book-100", "XBT/USD"]
[270, {"a": [["11874.50000", "0.00000000", "1596737060.268033"], ["11907.50000", "3.26133727", "1596736967.970398", "r"]], "c": "3347839155"}, "book-100", "XBT/USD"]
[270, {"a": [["11874.00000", "0.18224000", "1596737060.268610"]], "c": "3347839155"}, "book-100", "XBT/USD"]
[270, {"a": [["11880.90000", "0.00000000", "1596737060.286210"], ["11907.50000", "3.26133727", "1596736967.970398", "r"]], "c": "3347839155"}, "book-100", "XBT/USD"]
[270, {"b": [["11855.10000", "0.00000000", "1596737060.286958"], ["11810.80000", "0.01263652", "1596737057.274001", "r"]], "c": "3347839155"}, "book-100", "XBT/USD"]
[270, {"a": [["11875.00000", "0.17037000", "1596737060.299212"]], "c": "3347839155"}, "book-100", "XBT/USD"]
[270, {"a": [["11879.90000", "0.86965000", "1596737060.337708"]], "c": "3347839155"}, "book-100", "XBT/USD"]
[270, {"b": [["11854.10000", "0.02300000", "1596737060.339407"]], "c": "3347839155"}, "book-100", "XBT/USD"]
[270, {"a": [["11904.70000", "1.24182769", "1596737060.432757"]], "c": "3347839155"}, "book-100", "XBT/USD"]
[270, {"a": [["11890.80000", "0.00000000", "1596737060.432818"], ["11907.90000", "2.38150000", "1596736895.960018", "r"]], "c": "3347839155"}, "book-100", "XBT/USD"]
[270, {"b": [["11831.90000", "0.01294033", "1596737060.444788"]], "c": "3347839155"}, "book-100", "XBT/USD"]
[270, {"a": [["11876.80000", "0.00000000", "1596737060.488862"], ["11908.30000", "1.58322230", "1596736949.361051", "r"]], "c": "3347839155"}, "book-100", "XBT/USD"]
[270, {"a": [["11873.90000", "0.88153954", "1596737060.557180"]], "c": "2076967624"}, "book-100", "XBT/USD"]
[270, {"a": [["11890.80000", "0.44781372", "1596737060.616524"]], "c": "2076967624"}, "book-100", "XBT/USD"]
[270, {"a": [["11904.70000", "3.45367080", "1596737060.640996"]], "c": "2076967624"}, "book-100", "XBT/USD"]
[270, {"a": [["11881.20000", "0.00000000", "1596737060.664348"], ["11908.30000", "1.58322230", "1596736949.361051", "r"]], "c": "2076967624"}, "book-100", "XBT/USD"]
[270, {"a": [["11875.50000", "0.69373498", "1596737060.706018"]], "c": "2076967624"}, "book-100", "XBT/USD"]
[270, {"a": [["11873.10000", "0.00000000", "1596737060.949247"], ["11908.30000", "1.58322230", "1596736949.361051", "r"]], "c": "1139759547"}, "book-100", "XBT/USD"]
[270, {"a": [["11874.00000", "0.00000000", "1596737061.085984"], ["11908.90000", "1.06880000", "1596736841.521829", "r"]], "c": "2206623265"}, "book-100", "XBT/USD"]
[270, {"a": [["11879.90000", "1.55174019", "1596737061.141195"]], "c": "2206623265"}, "book-100", "XBT/USD"]
[270, {"a": [["11879.90000", "1.53374019", "1596737061.143736"]], "c": "2206623265"}, "book-100", "XBT/USD"]
[270, {"b": [["11854.10000", "0.00000000", "1596737061.144438"], ["11811.00000", "0.17065000", "1596737029.361409", "r"]], "c": "2206623265"}, "book-100", "XBT/USD"]
[270, {"b": [["11855.10000", "0.02300000", "1596737061.197126"]], "c": "2206623265"}, "book-100", "XBT/USD"]
[270, {"b": [["11868.20000", "1.68200000", "1596737061.204571"]], "c": "2157991942"}, "book-100", "XBT/USD"]
[270, {"b": [["11816.00000", "7.80000000", "1596737061.303764"]], "c": "2157991942"}, "book-100", "XBT/USD"]
[270, {"b": [["11816.80000", "2.20846997", "1596737061.305250"]], "c": "2157991942"}, "book-100", "XBT/USD"]
[270, {"b": [["11851.30000", "7.28301215", "1596737061.310627"]], "c": "2157991942"}, "book-100", "XBT/USD"]
[270, {"a": [["11899.50000", "3.09478871", "1596737061.311473"]], "c": "2157991942"}, "book-100", "XBT/USD"]
[270, {"a": [["11876.60000", "2.13592987", "1596737061.515177"]], "c": "2157991942"}, "book-100", "XBT/USD"]
[270, {"a": [["11880.90000", "0.01800000", "1596737061.565564"]], "c": "2157991942"}, "book-100", "XBT/USD"]
[270, {"a": [["11877.90000", "0.00000000", "1596737061.644416"], ["11908.30000", "1.58322230", "1596736949.361051", "r"]], "c": "2157991942"}, "book-100", "XBT/USD"]
[270, {"a": [["11904.70000", "1.24182769", "1596737061.654223"]], "c": "2157991942"}, "book-100", "XBT/USD"]
[270, {"a": [["11890.80000", "0.00000000", "1596737061.709821"], ["11908.90000", "1.06880000", "1596736841.521829", "r"]], "c": "2157991942"}, "book-100", "XBT/USD"]
[270, {"a": [["11890.80000", "0.44871412", "1596737061.895236"]], "c": "2157991942"}, "book-100", "XBT/USD"]
[270, {"a": [["11904.70000", "3.45399237", "1596737061.895547"]], "c": "2157991942"}, "book-100", "XBT/USD"]
[270, {"b": [["11856.20000", "0.08368658", "1596737061.929749"]], "c": "2157991942"}, "book-100", "XBT/USD"]
[270, {"b": [["11856.20000", "0.07212557", "1596737061.958230"]], "c": "2157991942"}, "book-100", "XBT/USD"]
[270, {"a": [["11870.40000", "1.52240025", "1596737062.163983"]], "c": "411166007"}, "book-100", "XBT/USD"]
[270, {"a": [["11872.50000", "0.70000000", "1596737062.212074"]], "c": "2122544835"}, "book-100", "XBT/USD"]
[270, {"a": [["11872.20000", "0.63160126", "1596737062.409765"]], "c": "39986855"}, "book-100", "XBT/USD"]
[270, {"a": [["11872.50000", "0.00000000", "1596737062.456399"], ["11907.90000", "2.38150000", "1596736895.960018", "r"]], "c": "2016510598"}, "book-100", "XBT/USD"]
[270, {"a": [["11883.90000", "0.00000000", "1596737062.628788"], ["11908.30000", "1.58322230", "1596736949.361051", "r"]], "c": "2016510598"}, "book-100", "XBT/USD"]
[270, {"b": [["11851.20000", "6.49084270", "1596737062.759320"]], "c": "2016510598"}, "book-100", "XBT/USD"]
[270, {"b": [["11868.20000", "0.00000000", "1596737062.868478"], ["11813.30000", "0.99420000", "1596736809.783550", "r"]], "c": "2065153185"}, "book-100", "XBT/USD"]
[270, {"b": [["11868.60000", "1.67900000", "1596737062.870527"]], "c": "773869064"}, "book-100", "XBT/USD"]
[270, {"a": [["11876.60000", "0.45492987", "1596737062.875494"]], "c": "773869064"}, "book-100", "XBT/USD"]
[270, {"a": [["11877.00000", "2.51174104", "1596737062.888924"]], "c": "773869064"}, "book-100", "XBT/USD"]
[270, {"a": [["11872.10000", "0.18224000", "1596737063.230436"]], "c": "1984988953"}, "book-100", "XBT/USD"]
[270, {"a": [["11899.00000", "2.81849664", "1596737063.692951"]], "c": "1984988953"}, "book-100", "XBT/USD"]
[270, {"a": [["11884.30000", "0.00000000", "1596737063.724993"], ["11908.30000", "1.58322230", "1596736949.361051", "r"]], "c": "1984988953"}, "book-100", "XBT/USD"]
[270, {"b": [["11833.80000", "0.65000000", "1596737063.859303"]], "c": "1984988953"}, "book-100", "XBT/USD"]
[270, {"b": [["11833.30000", "0.73581035", "1596737063.860096"]], "c": "1984988953"}, "book-100", "XBT/USD"]
[270, {"a": [["11896.50000", "0.73581035", "1596737063.861698"]], "c": "1984988953"}, "book-100", "XBT/USD"]
[270, {"a": [["11872.10000", "0.00000000", "1596737064.133326"], ["11908.30000", "1.58322230", "1596736949.361051", "r"]], "c": "773869064"}, "book-100", "XBT/USD"]
[270, {"a": [["11872.10000", "0.70000000", "1596737064.191780"]], "c": "715233270"}, "book-100", "XBT/USD"]
[270, {"a": [["11872.10000", "0.00000000", "1596737064.255963"], ["11908.30000", "1.58322230", "1596736949.361051", "r"]], "c": "773869064"}, "book-100", "XBT/USD"]
[270, {"a": [["11900.50000", "0.00000000", "1596737065.154077"], ["11908.90000", "1.06880000", "1596736841.521829", "r"]], "c": "773869064"}, "book-100", "XBT/USD"]
[270, {"a": [["11877.00000", "0.84174104", "1596737065.176535"]], "c": "773869064"}, "book-100", "XBT/USD"]
[270, {"a": [["11876.70000", "3.70475615", "1596737065.187040"]], "c": "773869064"}, "book-100", "XBT/USD"]
[270, {"a": [["11875.10000", "0.84212470", "1596737065.200474"]], "c": "773869064"}, "book-100", "XBT/USD"]
[270, {"b": [["11857.20000", "0.00000000", "1596737065.837061"], ["11814.70000", "2.19669614", "1596737029.794129", "r"]], "c": "773869064"}, "book-100", "XBT/USD"]
[270, {"b": [["11860.00000", "0.10928078", "1596737066.095706"]], "c": "773869064"}, "book-100", "XBT/USD"]
[270, {"b": [["11849.10000", "0.00000000", "1596737066.220725"], ["11814.70000", "2.19669614", "1596737029.794129", "r"]], "c": "773869064"}, "book-100", "XBT/USD"]
[270, {"b": [["11860.50000", "0.09621094", "1596737066.227754"]], "c": "773869064"}, "book-100", "XBT/USD"]
[270, {"a": [["11871.10000", "0.19242188", "1596737066.228105"]], "c": "3910122443"}, "book-100", "XBT/USD"]
[270, {"a": [["11875.20000", "0.00000000", "1596737066.230995"], ["11908.90000", "1.06880000", "1596736841.521829", "r"]], "c": "3910122443"}, "book-100", "XBT/USD"]
[270, {"b": [["11859.90000", "0.00000000", "1596737066.243889"], ["11814.70000", "2.19669614", "1596737029.794129", "r"]], "c": "3910122443"}, "book-100", "XBT/USD"]
[270, {"a": [["11871.10000", "0.09621094", "1596737066.346853"]], "c": "773869064"}, "book-100", "XBT/USD"]
[270, {"b": [["11845.30000", "0.00435436", "1596737066.413237"]], "c": "773869064"}, "book-100", "XBT/USD"]
[270, {"a": [["11901.00000", "2.35123177", "1596737066.509222"]], "c": "773869064"}, "book-100", "XBT/USD"]
[270, {"a": [["11872.10000", "0.70000000", "1596737066.541826"]], "c": "715233270"}, "book-100", "XBT/USD"]
[270, {"a": [["11899.20000", "0.50000000", "1596737066.545146"]], "c": "715233270"}, "book-100", "XBT/USD"]
[270, {"b": [["11868.60000", "0.00000000", "1596737066.710332"], ["11814.70000", "2.19669614", "1596737029.794129", "r"]], "c": "2140562783"}, "book-100", "XBT/USD"]
[270, {"b": [["11845.30000", "0.00000000", "1596737066.798226"], ["11813.30000", "0.99420000", "1596736809.783550", "r"]], "c": "2140562783"}, "book-100", "XBT/USD"]
[271, [["11870.40000", "0.30000000", "1596737067.011997", "b", "m", ""]], "trade", "XBT/USD"]
[270, {"a": [["11870.40000", "1.22240025", "1596737067.011997"]], "c": "3381604985"}, "book-100", "XBT/USD"]
[270, {"a": [["11901.00000", "2.18058177", "1596737067.326626"]], "c": "3381604985"}, "book-100", "XBT/USD"]
[270, {"a": [["11890.80000", "0.00000000", "1596737067.720436"], ["11908.30000", "1.58322230", "1596736949.361051", "r"]], "c": "3381604985"}, "book-100", "XBT/USD"]
[270, {"a": [["11877.00000", "0.00000000", "1596737067.741221"], ["11908.90000", "1.06880000", "1596736841.521829", "r"]], "c": "3381604985"}, "book-100", "XBT/USD"]
[270, {"a": [["11880.90000", "0.00000000", "1596737067.794456"], ["11909.10000", "1.00200000", "1596736809.784670", "r"]], "c": "3381604985"}, "book-100", "XBT/USD"]
[270, {"b": [["11863.90000", "0.00000000", "1596737067.799711"], ["11811.80000", "4.23305508", "1596736972.960659", "r"]], "c": "3381604985"}, "book-100", "XBT/USD"]
[270, {"a": [["11872.50000", "0.86020000", "1596737067.830477"]], "c": "1907090447"}, "book-100", "XBT/USD"]
[270, {"a": [["11870.40000", "3.22240025", "1596737067.833297"]], "c": "2184603981"}, "book-100", "XBT/USD"]
[270, {"a": [["11873.20000", "0.04750000", "1596737067.835808"]], "c": "2490907510"}, "book-100", "XBT/USD"]
[270, {"a": [["11879.90000", "1.55174019", "1596737067.844226"]], "c": "2490907510"}, "book-100", "XBT/USD"]
[270, {"b": [["11837.30000", "6.18961858", "1596737067.848188"]], "c": "2490907510"}, "book-100", "XBT/USD"]
[270, {"a": [["11882.40000", "0.10200000", "1596737067.853892"]], "c": "2490907510"}, "book-100", "XBT/USD"]
[270, {"a": [["11873.20000", "0.00000000", "1596737067.862646"], ["11909.10000", "1.00200000", "1596736809.784670", "r"]], "c": "3534885016"}, "book-100", "XBT/USD"]
[270, {"a": [["11872.10000", "0.00000000", "1596737067.882984"], ["11909.90000", "6.20000000", "1596736825.518690", "r"]], "c": "449481371"}, "book-100", "XBT/USD"]
[270, {"a": [["11875.50000", "0.00000000", "1596737067.893753"], ["11910.00000", "0.36067000", "1596736968.148143", "r"]], "c": "449481371"}, "book-100", "XBT/USD"]
[270, {"a": [["11872.00000", "0.18656000", "1596737067.897313"]], "c": "175783955"}, "book-100", "XBT/USD"]
[270, {"a": [["11873.90000", "0.25000000", "1596737068.004983"]], "c": "175783955"}, "book-100", "XBT/USD"]
[270, {"a": [["11875.60000", "0.84207418", "1596737068.023031"]], "c": "175783955"}, "book-100", "XBT/USD"]
[270, {"a": [["11893.20000", "0.56051698", "1596737068.025693"]], "c": "175783955"}, "book-100", "XBT/USD"]
[270, {"a": [["11872.20000", "0.00000000", "1596737068.039299"], ["11909.90000", "6.20000000", "1596736825.518690", "r"]], "c": "1094006328"}, "book-100", "XBT/USD"]
[270, {"b": [["11870.10000", "0.00000000", "1596737068.039621"], ["11811.70000", "5.70000000", "1596736886.902857", "r"]], "c": "3554634191"}, "book-100", "XBT/USD"]
[270, {"a": [["11871.90000", "0.04750000", "1596737068.137560"]], "c": "764023070"}, "book-100", "XBT/USD"]
[270, {"b": [["11856.20000", "0.07899258", "1596737068.140042"]], "c": "764023070"}, "book-100", "XBT/USD"]
[270, {"b": [["11870.30000", "0.25261210", "1596737068.185501"]], "c": "4233441849"}, "book-100", "XBT/USD"]
[270, {"a": [["11893.20000", "0.00438186", "1596737068.211303"]], "c": "4233441849"}, "book-100", "XBT/USD"]
[270, {"a": [["11883.00000", "0.00000000", "1596737068.226392"], ["11909.90000", "6.20000000", "1596736825.518690", "r"]], "c": "4233441849"}, "book-100", "XBT/USD"]
[270, {"a": [["11871.90000", "0.23406000", "1596737068.253372"]], "c": "2700650308"}, "book-100", "XBT/USD"]
[270, {"a": [["11887.60000", "0.01500000", "1596737068.254936"]], "c": "2700650308"}, "book-100", "XBT/USD"]
[270, {"a": [["11883.20000", "0.00000000", "1596737068.262473"], ["11910.00000", "0.36067000", "1596736968.148143", "r"]], "c": "2700650308"}, "book-100", "XBT/USD"]
[270, {"a": [["11874.60000", "0.87167000", "1596737068.267942"]], "c": "2700650308"}, "book-100", "XBT/USD"]
[270, {"b": [["11855.10000", "0.00000000", "1596737068.282406"], ["11811.00000", "0.17065000", "1596737066.352186", "r"]], "c": "2700650308"}, "book-100", "XBT/USD"]
[270, {"a": [["11873.90000", "0.00000000", "1596737068.287450"], ["11910.00000", "0.36067000", "1596736968.148143", "r"]], "c": "2700650308"}, "book-100", "XBT/USD"]
[270, {"a": [["11880.30000", "0.69319307", "1596737068.293559"]], "c": "2700650308"}, "book-100", "XBT/USD"]
[270, {"b": [["11854.10000", "0.02300000", "1596737068.331927"]], "c": "2700650308"}, "book-100", "XBT/USD"]
[270, {"b": [["11870.30000", "0.00000000", "1596737068.352240"], ["11811.00000", "0.17065000", "1596737066.352186", "r"]], "c": "4054700473"}, "book-100", "XBT/USD"]
[270, {"b": [["11868.40000", "0.10000000", "1596737068.354699"]], "c": "3166192775"}, "book-100", "XBT/USD"]
[270, {"b": [["11856.20000", "0.00686701", "1596737068.355272"]], "c": "3166192775"}, "book-100", "XBT/USD"]
[270, {"a": [["11890.60000", "0.43903152", "1596737068.394052"]], "c": "3166192775"}, "book-100", "XBT/USD"]
[270, {"b": [["11869.10000", "0.00000000", "1596737068.404557"], ["11811.00000", "0.17065000", "1596737066.352186", "r"]], "c": "1337579331"}, "book-100", "XBT/USD"]
[270, {"a": [["11870.40000", "2.94642361", "1596737068.407055"]], "c": "3495492288"}, "book-100", "XBT/USD"]
[270, {"a": [["11870.30000", "0.50000000", "1596737068.407935"]], "c": "1133508170"}, "book-100", "XBT/USD"]
[270, {"b": [["11855.90000", "0.43388307", "1596737068.411832"]], "c": "1133508170"}, "book-100", "XBT/USD"]
[270, {"a": [["11871.70000", "0.63165577", "1596737068.411973"]], "c": "2989740694"}, "book-100", "XBT/USD"]
[270, {"a": [["11871.10000", "0.72786671", "1596737068.412074"]], "c": "2647035276"}, "book-100", "XBT/USD"]
[270, {"a": [["11880.30000", "1.38638614", "1596737068.432204"]], "c": "2647035276"}, "book-100", "XBT/USD"]
[270, {"a": [["11874.90000", "0.00000000", "1596737068.468250"], ["11908.90000", "1.06880000", "1596736841.521829", "r"]], "c": "2647035276"}, "book-100", "XBT/USD"]
[270, {"a": [["11870.30000", "0.70000000", "1596737068.469620"]], "c": "1851457742"}, "book-100", "XBT/USD"]
[270, {"a": [["11870.40000", "2.48142361", "1596737068.497828"]], "c": "1639717242"}, "book-100", "XBT/USD"]
[270, {"b": [["11864.90000", "0.00000000", "1596737068.511614"], ["11808.80000", "2.66090576", "1596736784.110515", "r"]], "c": "1639717242"}, "book-100", "XBT/USD"]
[270, {"b": [["11856.20000", "0.00000000", "1596737068.512450"], ["11808.70000", "9.70000000", "1596737024.924486", "r"]], "c": "1639717242"}, "book-100", "XBT/USD"]
[270, {"a": [["11873.40000", "4.45600000", "1596737068.514851"]], "c": "1639717242"}, "book-100", "XBT/USD"]
[270, {"b": [["11857.60000", "0.00675263", "1596737068.517600"]], "c": "1639717242"}, "book-100", "XBT/USD"]
[270, {"a": [["11870.30000", "1.33500000", "1596737068.562218"]], "c": "4021263304"}, "book-100", "XBT/USD"]
[270, {"a": [["11870.30000", "2.03500000", "1596737068.646227"]], "c": "1551184034"}, "book-100", "XBT/USD"]
[270, {"b": [["11861.90000", "0.87167000", "1596737068.646889"]], "c": "1551184034"}, "book-100", "XBT/USD"]
[270, {"a": [["11870.30000", "4.03500000", "1596737068.657782"]], "c": "795275696"}, "book-100", "XBT/USD"]
[270, {"b": [["11867.20000", "0.00000000", "1596737068.688897"], ["11808.80000", "2.66090576", "1596736784.110515", "r"]], "c": "2202681151"}, "book-100", "XBT/USD"]
[270, {"a": [["11872.60000", "0.00000000", "1596737068.796299"], ["11909.10000", "1.00200000", "1596736809.784670", "r"]], "c": "810749190"}, "book-100", "XBT/USD"]
[270, {"b": [["11868.90000", "0.25266230", "1596737068.813554"]], "c": "3959429268"}, "book-100", "XBT/USD"]
[270, {"b": [["11865.80000", "0.00000000", "1596737068.819538"], ["11808.80000", "2.66090576", "1596736784.110515", "r"]], "c": "3732028674"}, "book-100", "XBT/USD"]
[270, {"b": [["11811.00000", "0.00000000", "1596737068.929595"], ["11808.70000", "9.70000000", "1596737024.924486", "r"]], "c": "3732028674"}, "book-100", "XBT/USD"]
[270, {"a": [["11874.70000", "0.66721254", "1596737068.945839"]], "c": "3732028674"}, "book-100", "XBT/USD"]
[270, {"a": [["11890.90000", "0.00000000", "1596737068.945901"], ["11909.10000", "1.00200000", "1596736809.784670", "r"]], "c": "3732028674"}, "book-100", "XBT/USD"]
[270, {"a": [["11870.40000", "2.25740025", "1596737068.951073"]], "c": "3986609623"}, "book-100", "XBT/USD"]
[270, {"b": [["11869.30000", "0.00000000", "1596737068.951598"], ["11808.00000", "0.17065000", "1596737017.603163", "r"]], "c": "1604791981"}, "book-100", "XBT/USD"]
[270, {"a": [["11879.90000", "0.86965000", "1596737068.979165"]], "c": "1604791981"}, "book-100", "XBT/USD"]
[270, {"b": [["11868.90000", "0.00000000", "1596737069.148087"], ["11807.70000", "3.28855406", "1596736821.611246", "r"]], "c": "2740392576"}, "book-100", "XBT/USD"]
[270, {"a": [["11870.30000", "4.43500000", "1596737069.237314"]], "c": "1214607011"}, "book-100", "XBT/USD"]
[270, {"a": [["11873.40000", "0.25000000", "1596737069.255268"]], "c": "1214607011"}, "book-100", "XBT/USD"]
[270, {"a": [["11871.30000", "4.20500000", "1596737069.256450"]], "c": "4281383538"}, "book-100", "XBT/USD"]
[270, {"b": [["11863.20000", "4.20600000", "1596737069.260844"]], "c": "4281383538"}, "book-100", "XBT/USD"]
[270, {"b": [["11868.40000", "0.00000000", "1596737069.320940"], ["11807.70000", "3.28855406", "1596736821.611246", "r"]], "c": "1030171037"}, "book-100", "XBT/USD"]
[270, {"a": [["11875.00000", "0.00000000", "1596737069.322111"], ["11909.10000", "1.00200000", "1596736809.784670", "r"]], "c": "1030171037"}, "book-100", "XBT/USD"]
[270, {"a": [["11870.30000", "4.45475816", "1596737069.323490"]], "c": "1540897344"}, "book-100", "XBT/USD"]
[270, {"a": [["11880.60000", "0.00000000", "1596737069.388554"], ["11909.90000", "6.20000000", "1596736825.518690", "r"]], "c": "1540897344"}, "book-100", "XBT/USD"]
[270, {"a": [["11877.20000", "0.67979987", "1596737069.389027"]], "c": "1540897344"}, "book-100", "XBT/USD"]
[270, {"b": [["11864.80000", "0.00000000", "1596737069.390642"], ["11807.50000", "2.19772556", "1596736916.776430", "r"]], "c": "3751535619"}, "book-100", "XBT/USD"]
[270, {"b": [["11860.50000", "0.00000000", "1596737069.405223"], ["11806.40000", "0.01263652", "1596737066.413126", "r"]], "c": "3751535619"}, "book-100", "XBT/USD"]
[270, {"b": [["11857.40000", "0.09621094", "1596737069.421550"]], "c": "3751535619"}, "book-100", "XBT/USD"]
[270, {"a": [["11880.30000", "0.69319307", "1596737069.429084"]], "c": "3751535619"}, "book-100", "XBT/USD"]
[270, {"a": [["11890.20000", "0.69195450", "1596737069.433779"]], "c": "3751535619"}, "book-100", "XBT/USD"]
[270, {"a": [["11886.80000", "0.32959639", "1596737069.435195"]], "c": "3751535619"}, "book-100", "XBT/USD"]
[270, {"b": [["11865.10000", "0.50000000", "1596737069.457268"]], "c": "3417220582"}, "book-100", "XBT/USD"]
[270, {"a": [["11877.20000", "0.00000000", "1596737069.480048"], ["11908.90000", "1.06880000", "1596736841.521829", "r"]], "c": "3417220582"}, "book-100", "XBT/USD"]
[270, {"a": [["11876.70000", "2.02575615", "1596737069.489166"]], "c": "3417220582"}, "book-100", "XBT/USD"]
[270, {"b": [["11866.70000", "0.10000000", "1596737069.617508"]], "c": "3444867520"}, "book-100", "XBT/USD"]
[270, {"b": [["11861.20000", "0.27100000", "1596737069.651049"]], "c": "3444867520"}, "book-100", "XBT/USD"]
[270, {"b": [["11837.30000", "0.23800000", "1596737069.651342"]], "c": "3444867520"}, "book-100", "XBT/USD"]
[270, {"b": [["11834.20000", "5.47337545", "1596737069.735186"]], "c": "3444867520"}, "book-100", "XBT/USD"]
[270, {"a": [["11879.30000", "0.11900000", "1596737069.850309"]], "c": "3444867520"}, "book-100", "XBT/USD"]
[270, {"a": [["11876.80000", "0.69634093", "1596737069.905842"]], "c": "3444867520"}, "book-100", "XBT/USD"]
[270, {"b": [["11849.10000", "0.00450279", "1596737070.317060"]], "c": "3444867520"}, "book-100", "XBT/USD"]
[270, {"a": [["11893.20000", "0.00000000", "1596737070.321546"], ["11908.30000", "1.58322230", "1596736949.361051", "r"]], "c": "3444867520"}, "book-100", "XBT/USD"]
[270, {"b": [["11868.30000", "0.00000000", "1596737070.321774"], ["11808.70000", "9.70000000", "1596737024.924486", "r"]], "c": "803021764"}, "book-100", "XBT/USD"]
[270, {"b": [["11857.60000", "0.00000000", "1596737070.448200"], ["11808.00000", "0.17065000", "1596737017.603163", "r"]], "c": "803021764"}, "book-100", "XBT/USD"]
[270, {"b": [["11854.20000", "0.68765458", "1596737070.450076"]], "c": "803021764"}, "book-100", "XBT/USD"]
[270, {"b": [["11859.70000", "0.00000000", "1596737070.640507"], ["11807.70000", "3.28855406", "1596736821.611246", "r"]], "c": "803021764"}, "book-100", "XBT/USD"]
[270, {"b": [["11863.10000", "0.00000000", "1596737070.643468"], ["11807.50000", "2.19772556", "1596736916.776430", "r"]], "c": "803021764"}, "book-100", "XBT/USD"]
[270, {"b": [["11854.20000", "0.68090000", "1596737070.660719"]], "c": "803021764"}, "book-100", "XBT/USD"]
[270, {"b": [["11854.30000", "0.00675452", "1596737070.663632"]], "c": "803021764"}, "book-100", "XBT/USD"]
[270, {"b": [["11860.00000", "0.00000000", "1596737070.676887"], ["11807.50000", "2.19772556", "1596736916.776430", "r"]], "c": "803021764"}, "book-100", "XBT/USD"]
[270, {"a": [["11871.80000", "0.18656000", "1596737070.690925"]], "c": "1219619103"}, "book-100", "XBT/USD"]
[270, {"b": [["11833.50000", "0.73586999", "1596737070.710412"]], "c": "1219619103"}, "book-100", "XBT/USD"]
[270, {"a": [["11896.10000", "0.73586999", "1596737070.712186"]], "c": "1219619103"}, "book-100", "XBT/USD"]
[270, {"a": [["11896.50000", "0.00000000", "1596737070.715205"], ["11907.90000", "2.38150000", "1596736895.960018", "r"]], "c": "1219619103"}, "book-100", "XBT/USD"]
[270, {"b": [["11833.30000", "0.00000000", "1596737070.715398"], ["11807.50000", "2.19772556", "1596736916.776430", "r"]], "c": "1219619103"}, "book-100", "XBT/USD"]
[270, {"b": [["11857.40000", "0.20552406", "1596737070.995671"]], "c": "1219619103"}, "book-100", "XBT/USD"]
[270, {"b": [["11861.10000", "0.33031054", "1596737071.010521"]], "c": "1219619103"}, "book-100", "XBT/USD"]
[270, {"b": [["11867.00000", "0.25269227", "1596737071.169357"]], "c": "3536814311"}, "book-100", "XBT/USD"]
[270, {"b": [["11866.90000", "0.25269474", "1596737071.169454"]], "c": "634066815"}, "book-100", "XBT/USD"]
[270, {"a": [["11870.30000", "5.08648883", "1596737071.169556"]], "c": "2923653448"}, "book-100", "XBT/USD"]
[270, {"b": [["11853.90000", "0.33690310", "1596737071.170795"]], "c": "2923653448"}, "book-100", "XBT/USD"]
[270, {"a": [["11904.00000", "0.17065000", "1596737071.292235"]], "c": "2923653448"}, "book-100", "XBT/USD"]
[270, {"b": [["11866.70000", "0.00000000", "1596737071.300990"], ["11808.70000", "9.70000000", "1596737024.924486", "r"]], "c": "1294194450"}, "book-100", "XBT/USD"]
[270, {"b": [["11857.70000", "0.69385103", "1596737071.335674"]], "c": "1294194450"}, "book-100", "XBT/USD"]
[270, {"b": [["11867.10000", "0.10000000", "1596737071.467120"]], "c": "1209350351"}, "book-100", "XBT/USD"]
[270, {"a": [["11893.80000", "0.00000000", "1596737071.540265"], ["11908.30000", "1.58322230", "1596736949.361051", "r"]], "c": "1209350351"}, "book-100", "XBT/USD"]
[270, {"a": [["11902.20000", "0.09250000", "1596737071.595573"]], "c": "1209350351"}, "book-100", "XBT/USD"]
[270, {"b": [["11866.90000", "0.00000000", "1596737071.714048"], ["11808.80000", "2.66090576", "1596736784.110515", "r"]], "c": "3464571507"}, "book-100", "XBT/USD"]
[270, {"a": [["11901.00000", "2.35123177", "1596737072.348993"]], "c": "3464571507"}, "book-100", "XBT/USD"]
[270, {"b": [["11857.50000", "0.00000000", "1596737072.353467"], ["11808.70000", "9.70000000", "1596737024.924486", "r"]], "c": "3464571507"}, "book-100", "XBT/USD"]
[270, {"b": [["11857.30000", "1.38772628", "1596737072.366072"]], "c": "3464571507"}, "book-100", "XBT/USD"]
[270, {"a": [["11871.60000", "0.18655000", "1596737072.449909"]], "c": "2566964983"}, "book-100", "XBT/USD"]
[270, {"b": [["11854.20000", "1.44629842", "1596737072.807964"]], "c": "2566964983"}, "book-100", "XBT/USD"]
[270, {"b": [["11816.80000", "0.00000000", "1596737072.859279"], ["11808.00000", "0.17065000", "1596737017.603163", "r"]], "c": "2566964983"}, "book-100", "XBT/USD"]
[270, {"b": [["11815.20000", "2.20879108", "1596737072.871784"]], "c": "2566964983"}, "book-100", "XBT/USD"]
[270, {"b": [["11854.30000", "0.21137822", "1596737072.895670"]], "c": "2566964983"}, "book-100", "XBT/USD"]
[270, {"b": [["11833.80000", "0.00000000", "1596737072.991367"], ["11808.00000", "0.17065000", "1596737017.603163", "r"]], "c": "2566964983"}, "book-100", "XBT/USD"]
[270, {"b": [["11854.40000", "0.00675445", "1596737073.689352"]], "c": "2566964983"}, "book-100", "XBT/USD"]
[270, {"b": [["11849.10000", "0.00000000", "1596737073.713539"], ["11808.00000", "0.17065000", "1596737017.603163", "r"]], "c": "2566964983"}, "book-100", "XBT/USD"]
[270, {"a": [["11890.60000", "0.44341338", "1596737073.719064"]], "c": "2566964983"}, "book-100", "XBT/USD"]
[270, {"b": [["11851.30000", "6.57601215", "1596737073.781799"]], "c": "2566964983"}, "book-100", "XBT/USD"]
[270, {"b": [["11854.30000", "0.20462370", "1596737073.782903"]], "c": "2566964983"}, "book-100", "XBT/USD"]
[270, {"b": [["11854.40000", "0.00000000", "1596737073.817044"], ["11807.70000", "3.28855406", "1596736821.611246", "r"]], "c": "2566964983"}, "book-100", "XBT/USD"]
[270, {"b": [["11854.40000", "0.07213653", "1596737073.819854"]], "c": "2566964983"}, "book-100", "XBT/USD"]
[270, {"b": [["11845.30000", "0.00448745", "1596737074.157562"]], "c": "2566964983"}, "book-100", "XBT/USD"]
[270, {"b": [["11867.60000", "0.25269474", "1596737074.200129"]], "c": "442915683"}, "book-100", "XBT/USD"]
[270, {"a": [["11871.60000", "0.00000000", "1596737074.238478"], ["11907.90000", "2.38150000", "1596736895.960018", "r"]], "c": "4081056279"}, "book-100", "XBT/USD"]
[270, {"b": [["11854.10000", "0.00000000", "1596737074.251760"], ["11808.70000", "9.70000000", "1596737024.924486", "r"]], "c": "4081056279"}, "book-100", "XBT/USD"]
[270, {"a": [["11879.90000", "0.85165000", "1596737074.252344"]], "c": "4081056279"}, "book-100", "XBT/USD"]
[270, {"a": [["11878.90000", "0.01800000", "1596737074.301779"]], "c": "4081056279"}, "book-100", "XBT/USD"]
[270, {"b": [["11853.10000", "0.40300000", "1596737074.301987"]], "c": "4081056279"}, "book-100", "XBT/USD"]
[270, {"a": [["11873.40000", "0.00000000", "1596737074.386615"], ["11907.90000", "2.38150000", "1596736895.960018", "r"]], "c": "4081056279"}, "book-100", "XBT/USD"]
[270, {"b": [["11867.10000", "0.00000000", "1596737074.432996"], ["11808.00000", "0.17065000", "1596737017.603163", "r"]], "c": "1692927579"}, "book-100", "XBT/USD"]
[270, {"b": [["11853.10000", "0.38000000", "1596737074.488168"]], "c": "1692927579"}, "book-100", "XBT/USD"]
[270, {"b": [["11854.10000", "0.02300000", "1596737074.539063"]], "c": "1692927579"}, "book-100", "XBT/USD"]
[270, {"a": [["11872.30000", "0.25000000", "1596737074.541126"]], "c": "1692927579"}, "book-100", "XBT/USD"]
[270, {"b": [["11860.80000", "2.60419696", "1596737074.715141"]], "c": "1692927579"}, "book-100", "XBT/USD"]
[270, {"b": [["11867.70000", "0.10000000", "1596737074.735397"]], "c": "2801152534"}, "book-100", "XBT/USD"]
[270, {"b": [["11864.60000", "0.00000000", "1596737074.854861"], ["11808.80000", "2.66090576", "1596736784.110515", "r"]], "c": "2801152534"}, "book-100", "XBT/USD"]
[270, {"a": [["11900.90000", "0.00000000", "1596737075.030136"], ["11907.90000", "2.38150000", "1596736895.960018", "r"]], "c": "2801152534"}, "book-100", "XBT/USD"]
[270, {"b": [["11845.30000", "0.00000000", "1596737075.127249"], ["11808.70000", "9.70000000", "1596737024.924486", "r"]], "c": "2801152534"}, "book-100", "XBT/USD"]
[270, {"a": [["11871.90000", "0.18656000", "1596737075.168530"]], "c": "85257237"}, "book-100", "XBT/USD"]
[270, {"a": [["11893.30000", "0.76278767", "1596737075.177960"]], "c": "85257237"}, "book-100", "XBT/USD"]
[270, {"a": [["11899.20000", "0.00000000", "1596737075.186859"], ["11908.30000", "1.58322230", "1596736949.361051", "r"]], "c": "85257237"}, "book-100", "XBT/USD"]
[270, {"a": [["11878.90000", "0.00000000", "1596737075.191588"], ["11908.90000", "1.06880000", "1596736841.521829", "r"]], "c": "85257237"}, "book-100", "XBT/USD"]
[270, {"a": [["11879.90000", "0.86965000", "1596737075.248349"]], "c": "85257237"}, "book-100", "XBT/USD"]
[270, {"b": [["11854.40000", "0.00000000", "1596737075.307017"], ["11808.00000", "0.17065000", "1596737017.603163", "r"]], "c": "85257237"}, "book-100", "XBT/USD"]
[270, {"a": [["11890.60000", "0.43903152", "1596737075.314986"]], "c": "85257237"}, "book-100", "XBT/USD"]
[270, {"b": [["11854.30000", "0.21149072", "1596737075.348887"]], "c": "85257237"}, "book-100", "XBT/USD"]
[270, {"b": [["11857.30000", "0.00000000", "1596737075.405310"], ["11807.70000", "3.28855406", "1596736821.611246", "r"]], "c": "85257237"}, "book-100", "XBT/USD"]
[270, {"b": [["11854.10000", "0.00000000", "1596737075.467016"], ["11807.50000", "2.19772556", "1596736916.776430", "r"]], "c": "85257237"}, "book-100", "XBT/USD"]
[270, {"b": [["11853.10000", "0.40300000", "1596737075.518109"]], "c": "85257237"}, "book-100", "XBT/USD"]
[270, {"a": [["11892.50000", "1.38400094", "1596737075.531091"]], "c": "85257237"}, "book-100", "XBT/USD"]
[270, {"a": [["11874.70000", "0.00000000", "1596737075.603761"], ["11908.90000", "1.06880000", "1596736841.521829", "r"]], "c": "85257237"}, "book-100", "XBT/USD"]
[270, {"a": [["11870.30000", "5.58648883", "1596737075.658867"]], "c": "1334758798"}, "book-100", "XBT/USD"]
[270, {"a": [["11871.70000", "0.81820577", "1596737075.732297"]], "c": "1072648976"}, "book-100", "XBT/USD"]
[270, {"a": [["11896.20000", "0.00000000", "1596737075.829495"], ["11909.10000", "1.00200000", "1596736809.784670", "r"]], "c": "1072648976"}, "book-100", "XBT/USD"]
[270, {"a": [["11873.50000", "0.66479919", "1596737075.830311"]], "c": "1072648976"}, "book-100", "XBT/USD"]
[270, {"a": [["11878.00000", "2.04948410", "1596737075.853956"]], "c": "1072648976"}, "book-100", "XBT/USD"]
[270, {"a": [["11900.00000", "12.71653131", "1596737075.897027"]], "c": "1072648976"}, "book-100", "XBT/USD"]
[270, {"a": [["11886.80000", "0.00000000", "1596737075.900334"], ["11908.90000", "1.06880000", "1596736841.521829", "r"]], "c": "1072648976"}, "book-100", "XBT/USD"]
[270, {"a": [["11890.20000", "0.00000000", "1596737075.904934"], ["11909.10000", "1.00200000", "1596736809.784670", "r"]], "c": "1072648976"}, "book-100", "XBT/USD"]
[270, {"b": [["11865.60000", "0.00000000", "1596737075.906658"], ["11806.30000", "5.40000000", "1596737051.417403", "r"]], "c": "2560752688"}, "book-100", "XBT/USD"]
[270, {"a": [["11879.90000", "0.02800000", "1596737075.970407"]], "c": "2560752688"}, "book-100", "XBT/USD"]
[270, {"a": [["11872.20000", "0.96463000", "1596737075.983817"]], "c": "2560752688"}, "book-100", "XBT/USD"]
[270, {"a": [["11881.30000", "0.00000000", "1596737075.990969"], ["11909.10000", "1.00200000", "1596736809.784670", "r"]], "c": "2560752688"}, "book-100", "XBT/USD"]
[270, {"a": [["11879.90000", "0.01000000", "1596737076.021342"]], "c": "2560752688"}, "book-100", "XBT/USD"]
[270, {"a": [["11892.50000", "0.00000000", "1596737076.030282"], ["11909.90000", "6.20000000", "1596736825.518690", "r"]], "c": "2560752688"}, "book-100", "XBT/USD"]
[270, {"a": [["11893.40000", "4.20725333", "1596737076.069276"]], "c": "2560752688"}, "book-100", "XBT/USD"]
[270, {"a": [["11878.90000", "0.01800000", "1596737076.083584"]], "c": "2560752688"}, "book-100", "XBT/USD"]
[270, {"a": [["11893.40000", "3.26479256", "1596737076.098463"]], "c": "2560752688"}, "book-100", "XBT/USD"]
[270, {"b": [["11855.00000", "1.38837885", "1596737076.139260"]], "c": "2560752688"}, "book-100", "XBT/USD"]
[270, {"b": [["11846.80000", "0.65000000", "1596737076.276067"]], "c": "2560752688"}, "book-100", "XBT/USD"]
[270, {"a": [["11890.80000", "1.38419881", "1596737076.370945"]], "c": "2560752688"}, "book-100", "XBT/USD"]
[270, {"a": [["11888.50000", "0.69223330", "1596737076.371341"]], "c": "2560752688"}, "book-100", "XBT/USD"]
[270, {"a": [["11896.80000", "1.74584613", "1596737076.409254"]], "c": "2560752688"}, "book-100", "XBT/USD"]
[270, {"a": [["11890.80000", "2.32698889", "1596737076.409703"]], "c": "2560752688"}, "book-100", "XBT/USD"]
[270, {"a": [["11885.00000", "0.32973198", "1596737076.410577"]], "c": "2560752688"}, "book-100", "XBT/USD"]
[270, {"a": [["11899.70000", "2.68067415", "1596737076.414495"]], "c": "2560752688"}, "book-100", "XBT/USD"]
[270, {"a": [["11876.80000", "0.00000000", "1596737076.420729"], ["11907.90000", "2.38150000", "1596736895.960018", "r"]], "c": "2560752688"}, "book-100", "XBT/USD"]
[270, {"a": [["11884.00000", "0.38000000", "1596737076.447418"]], "c": "2560752688"}, "book-100", "XBT/USD"]
[270, {"a": [["11873.70000", "1.67800000", "1596737076.497388"]], "c": "2560752688"}, "book-100", "XBT/USD"]
[270, {"b": [["11865.30000", "1.67300000", "1596737076.505218"]], "c": "1035245779"}, "book-100", "XBT/USD"]
[270, {"b": [["11862.60000", "0.04396887", "1596737076.528395"]], "c": "1035245779"}, "book-100", "XBT/USD"]
[270, {"a": [["11875.60000", "0.00000000", "1596737076.562719"], ["11907.50000", "3.26133727", "1596736967.970398", "r"]], "c": "1035245779"}, "book-100", "XBT/USD"]
[270, {"b": [["11865.30000", "0.00000000", "1596737076.635519"], ["11808.00000", "0.17065000", "1596737017.603163", "r"]], "c": "2560752688"}, "book-100", "XBT/USD"]
[270, {"a": [["11879.90000", "0.05396887", "1596737076.732917"]], "c": "2560752688"}, "book-100", "XBT/USD"]
[270, {"a": [["11873.30000", "2.34206388", "1596737076.783256"]], "c": "2560752688"}, "book-100", "XBT/USD"]
[270, {"a": [["11876.60000", "1.09798468", "1596737076.799459"]], "c": "2560752688"}, "book-100", "XBT/USD"]
[270, {"a": [["11899.70000", "0.50000000", "1596737076.938017"]], "c": "2560752688"}, "book-100", "XBT/USD"]
[270, {"a": [["11871.70000", "0.63165577", "1596737077.098738"]], "c": "1624544646"}, "book-100", "XBT/USD"]
[270, {"a": [["11870.30000", "5.18648883", "1596737077.237346"]], "c": "2278438082"}, "book-100", "XBT/USD"]
[270, {"b": [["11833.50000", "0.00000000", "1596737077.299893"], ["11807.70000", "3.28855406", "1596736821.611246", "r"]], "c": "2278438082"}, "book-100", "XBT/USD"]
[270, {"a": [["11896.10000", "0.00000000", "1596737077.302165"], ["11907.90000", "2.38150000", "1596736895.960018", "r"]], "c": "2278438082"}, "book-100", "XBT/USD"]
[270, {"a": [["11886.90000", "0.00000000", "1596737077.305384"], ["11908.30000", "1.58322230", "1596736949.361051", "r"]], "c": "2278438082"}, "book-100", "XBT/USD"]
[270, {"a": [["11897.20000", "0.73592006", "1596737077.307476"]], "c": "2278438082"}, "book-100", "XBT/USD"]
[270, {"b": [["11834.20000", "0.00000000", "1596737077.397124"], ["11807.50000", "2.19772556", "1596736916.776430", "r"]], "c": "2278438082"}, "book-100", "XBT/USD"]
[270, {"a": [["11896.50000", "2.18109894", "1596737077.511560"]], "c": "2278438082"}, "book-100", "XBT/USD"]
[270, {"a": [["11871.40000", "0.33658000", "1596737077.647287"]], "c": "1922946508"}, "book-100", "XBT/USD"]
[270, {"a": [["11888.10000", "0.00000000", "1596737077.649567"], ["11907.90000", "2.38150000", "1596736895.960018", "r"]], "c": "1922946508"}, "book-100", "XBT/USD"]
[270, {"b": [["11834.60000", "0.73592006", "1596737077.861043"]], "c": "1922946508"}, "book-100", "XBT/USD"]
[270, {"b": [["11863.80000", "1.67100000", "1596737077.966259"]], "c": "3067431636"}, "book-100", "XBT/USD"]
[270, {"a": [["11873.70000", "0.00000000", "1596737077.972567"], ["11908.30000", "1.58322230", "1596736949.361051", "r"]], "c": "3067431636"}, "book-100", "XBT/USD"]
[270, {"a": [["11872.20000", "2.63963000", "1596737077.984672"]], "c": "3067431636"}, "book-100", "XBT/USD"]
[270, {"b": [["11854.30000", "0.20462370", "1596737078.009814"]], "c": "3067431636"}, "book-100", "XBT/USD"]
[270, {"b": [["11854.30000", "0.21137822", "1596737078.010372"]], "c": "3067431636"}, "book-100", "XBT/USD"]
[270, {"b": [["11857.00000", "0.23800000", "1596737078.137736"]], "c": "3067431636"}, "book-100", "XBT/USD"]
[270, {"a": [["11871.40000", "0.15000000", "1596737078.305179"]], "c": "1132899290"}, "book-100", "XBT/USD"]
[270, {"a": [["11883.60000", "0.00000000", "1596737078.495858"], ["11908.90000", "1.06880000", "1596736841.521829", "r"]], "c": "1132899290"}, "book-100", "XBT/USD"]
[270, {"a": [["11872.80000", "0.84236293", "1596737078.559142"]], "c": "1132899290"}, "book-100", "XBT/USD"]
[270, {"a": [["11870.90000", "0.18658000", "1596737078.648513"]], "c": "1229482378"}, "book-100", "XBT/USD"]
[270, {"b": [["11837.30000", "0.00000000", "1596737078.682374"], ["11808.00000", "0.17065000", "1596737017.603163", "r"]], "c": "1229482378"}, "book-100", "XBT/USD"]
[270, {"a": [["11876.60000", "0.45492987", "1596737078.696811"]], "c": "1229482378"}, "book-100", "XBT/USD"]
[270, {"a": [["11876.50000", "0.64779014", "1596737078.904925"]], "c": "1229482378"}, "book-100", "XBT/USD"]
[270, {"b": [["11816.80000", "1.53134325", "1596737078.986452"]], "c": "1229482378"}, "book-100", "XBT/USD"]
[270, {"a": [["11872.20000", "0.96463000", "1596737079.036410"]], "c": "1229482378"}, "book-100", "XBT/USD"]
[270, {"a": [["11873.30000", "0.84206388", "1596737079.291654"]], "c": "1229482378"}, "book-100", "XBT/USD"]
[270, {"a": [["11870.90000", "0.00000000", "1596737079.306780"], ["11907.90000", "2.38150000", "1596736895.960018", "r"]], "c": "1132899290"}, "book-100", "XBT/USD"]
[270, {"b": [["11859.50000", "0.00000000", "1596737079.417250"], ["11808.00000", "0.17065000", "1596737017.603163", "r"]], "c": "1132899290"}, "book-100", "XBT/USD"]
[270, {"a": [["11871.80000", "1.68656000", "1596737079.436743"]], "c": "3973163594"}, "book-100", "XBT/USD"]
[270, {"a": [["11870.80000", "0.18658000", "1596737079.447183"]], "c": "1448309376"}, "book-100", "XBT/USD"]
[270, {"a": [["11893.30000", "0.00000000", "1596737079.451454"], ["11907.90000", "2.38150000", "1596736895.960018", "r"]], "c": "1448309376"}, "book-100", "XBT/USD"]
[270, {"a": [["11891.60000", "0.00000000", "1596737079.465945"], ["11908.30000", "1.58322230", "1596736949.361051", "r"]], "c": "1448309376"}, "book-100", "XBT/USD"]
[270, {"a": [["11899.90000", "7.61000000", "1596737079.466913"]], "c": "1448309376"}, "book-100", "XBT/USD"]
[270, {"b": [["11867.60000", "0.00000000", "1596737079.501864"], ["11807.70000", "3.28855406", "1596736821.611246", "r"]], "c": "2030012930"}, "book-100", "XBT/USD"]
[270, {"a": [["11872.10000", "1.68300000", "1596737079.572463"]], "c": "2030012930"}, "book-100", "XBT/USD"]
[270, {"a": [["11890.80000", "3.09008389", "1596737079.675649"]], "c": "2030012930"}, "book-100", "XBT/USD"]
[270, {"a": [["11896.70000", "1.61251679", "1596737079.676562"]], "c": "2030012930"}, "book-100", "XBT/USD"]
[270, {"a": [["11888.40000", "0.10903558", "1596737079.684647"]], "c": "2030012930"}, "book-100", "XBT/USD"]
[270, {"b": [["11854.30000", "0.20462370", "1596737079.699337"]], "c": "2030012930"}, "book-100", "XBT/USD"]
[270, {"a": [["11890.60000", "0.00000000", "1596737079.765256"], ["11907.90000", "2.38150000", "1596736895.960018", "r"]], "c": "2030012930"}, "book-100", "XBT/USD"]
[270, {"b": [["11867.70000", "0.00000000", "1596737079.786223"], ["11807.50000", "2.19772556", "1596736916.776430", "r"]], "c": "732472862"}, "book-100", "XBT/USD"]
[270, {"b": [["11855.80000", "0.03567188", "1596737079.811108"]], "c": "732472862"}, "book-100", "XBT/USD"]
[270, {"a": [["11872.10000", "0.00000000", "1596737079.838287"], ["11908.30000", "1.58322230", "1596736949.361051", "r"]], "c": "732472862"}, "book-100", "XBT/USD"]
[270, {"b": [["11870.20000", "0.00000000", "1596737079.869192"], ["11807.50000", "2.19772556", "1596736916.776430", "r"]], "c": "4275068927"}, "book-100", "XBT/USD"]
[270, {"a": [["11870.20000", "0.04750000", "1596737079.893638"]], "c": "2923665166"}, "book-100", "XBT/USD"]
[270, {"a": [["11870.30000", "5.58648883", "1596737079.914054"]], "c": "2913765651"}, "book-100", "XBT/USD"]
[270, {"a": [["11870.30000", "4.88648883", "1596737079.916938"]], "c": "1545572194"}, "book-100", "XBT/USD"]
[270, {"a": [["11870.30000", "4.38648883", "1596737079.925698"]], "c": "3249092961"}, "book-100", "XBT/USD"]
[270, {"a": [["11870.80000", "0.00000000", "1596737079.943759"], ["11908.30000", "1.58322230", "1596736949.361051", "r"]], "c": "105118979"}, "book-100", "XBT/USD"]
[270, {"a": [["11893.30000", "0.73904965", "1596737079.948338"]], "c": "105118979"}, "book-100", "XBT/USD"]
[270, {"a": [["11870.30000", "3.88648883", "1596737079.959965"]], "c": "2809079877"}, "book-100", "XBT/USD"]
[270, {"a": [["11871.70000", "0.00000000", "1596737079.960782"], ["11908.30000", "1.58322230", "1596736949.361051", "r"]], "c": "520215682"}, "book-100", "XBT/USD"]
[270, {"a": [["11870.10000", "0.01975817", "1596737079.962990"]], "c": "982080785"}, "book-100", "XBT/USD"]
[270, {"a": [["11870.20000", "0.74750000", "1596737079.963538"]], "c": "3519459825"}, "book-100", "XBT/USD"]
[270, {"b": [["11866.00000", "0.10000000", "1596737079.971510"]], "c": "2861258562"}, "book-100", "XBT/USD"]
[270, {"a": [["11870.30000", "3.25148883", "1596737079.998292"]], "c": "4029101799"}, "book-100", "XBT/USD"]
[270, {"a": [["11870.30000", "3.23173067", "1596737080.033540"]], "c": "472173444"}, "book-100", "XBT/USD"]
[270, {"a": [["11871.00000", "0.18658000", "1596737080.042947"]], "c": "2567055877"}, "book-100", "XBT/USD"]
[270, {"b": [["11853.50000", "0.03939567", "1596737080.074073"]], "c": "2567055877"}, "book-100", "XBT/USD"]
[270, {"a": [["11869.80000", "0.50000000", "1596737080.078573"]], "c": "819470426"}, "book-100", "XBT/USD"]
[270, {"b": [["11861.90000", "0.00000000", "1596737080.080075"], ["11807.70000", "3.28855406", "1596736821.611246", "r"]], "c": "819470426"}, "book-100", "XBT/USD"]
[270, {"a": [["11869.80000", "2.50000000", "1596737080.107898"]], "c": "80655103"}, "book-100", "XBT/USD"]
[270, {"a": [["11870.40000", "2.00500000", "1596737080.131821"]], "c": "2277225860"}, "book-100", "XBT/USD"]
[270, {"a": [["11869.80000", "2.70000000", "1596737080.136391"]], "c": "3205560848"}, "book-100", "XBT/USD"]
[270, {"a": [["11869.80000", "2.71975816", "1596737080.156447"]], "c": "1006682057"}, "book-100", "XBT/USD"]
[270, {"a": [["11871.00000", "0.00000000", "1596737080.165980"], ["11907.50000", "3.26133727", "1596736967.970398", "r"]], "c": "3087861341"}, "book-100", "XBT/USD"]
[270, {"b": [["11853.50000", "0.00000000", "1596737080.199548"], ["11807.50000", "2.19772556", "1596736916.776430", "r"]], "c": "3087861341"}, "book-100", "XBT/USD"]
[270, {"b": [["11853.80000", "0.00675479", "1596737080.211631"]], "c": "3087861341"}, "book-100", "XBT/USD"]
[270, {"a": [["11893.30000", "0.00000000", "1596737080.233582"], ["11907.90000", "2.38150000", "1596736895.960018", "r"]], "c": "3087861341"}, "book-100", "XBT/USD"]
[270, {"b": [["11867.80000", "0.35990000", "1596737080.239512"]], "c": "1454869311"}, "book-100", "XBT/USD"]
[270, {"a": [["11879.30000", "0.00000000", "1596737080.261030"], ["11908.30000", "1.58322230", "1596736949.361051", "r"]], "c": "1454869311"}, "book-100", "XBT/USD"]
[270, {"a": [["11870.30000", "3.03173067", "1596737080.297384"]], "c": "4220544518"}, "book-100", "XBT/USD"]
[270, {"a": [["11898.70000", "10.53942716", "1596737080.410127"]], "c": "4220544518"}, "book-100", "XBT/USD"]
[270, {"a": [["11889.90000", "0.46439766", "1596737080.415415"]], "c": "4220544518"}, "book-100", "XBT/USD"]
[270, {"b": [["11853.80000", "0.02982983", "1596737080.454100"]], "c": "4220544518"}, "book-100", "XBT/USD"]
[270, {"b": [["11853.80000", "0.02307504", "1596737080.454223"]], "c": "4220544518"}, "book-100", "XBT/USD"]
[270, {"a": [["11869.80000", "3.13186378", "1596737080.460428"]], "c": "1134137231"}, "book-100", "XBT/USD"]
[270, {"a": [["11870.80000", "0.18658000", "1596737080.487458"]], "c": "3014689049"}, "book-100", "XBT/USD"]
[270, {"b": [["11853.80000", "0.02982983", "1596737080.581245"]], "c": "3014689049"}, "book-100", "XBT/USD"]
[270, {"b": [["11853.80000", "0.00675479", "1596737080.586624"]], "c": "3014689049"}, "book-100", "XBT/USD"]
[270, {"a": [["11876.20000", "0.01465673", "1596737080.697721"]], "c": "3014689049"}, "book-100", "XBT/USD"]
[270, {"b": [["11864.70000", "0.01465673", "1596737080.697895"]], "c": "2846400059"}, "book-100", "XBT/USD"]
[270, {"b": [["11864.20000", "0.07328318", "1596737080.762824"]], "c": "1356889123"}, "book-100", "XBT/USD"]
[270, {"a": [["11896.60000", "6.46646188", "1596737080.816245"]], "c": "1356889123"}, "book-100", "XBT/USD"]
[270, {"a": [["11879.20000", "0.32539624", "1596737080.826386"]], "c": "1356889123"}, "book-100", "XBT/USD"]
[270, {"b": [["11863.80000", "1.84687963", "1596737080.849035"]], "c": "1356889123"}, "book-100", "XBT/USD"]
[270, {"a": [["11877.70000", "0.35728317", "1596737080.897567"]], "c": "1356889123"}, "book-100", "XBT/USD"]
[270, {"b": [["11853.50000", "0.02307526", "1596737080.916701"]], "c": "1356889123"}, "book-100", "XBT/USD"]
[270, {"b": [["11853.80000", "0.00000000", "1596737080.919064"], ["11808.80000", "2.66090576", "1596736784.110515", "r"]], "c": "1356889123"}, "book-100", "XBT/USD"]
[270, {"a": [["11891.40000", "0.90000000", "1596737081.037253"]], "c": "1356889123"}, "book-100", "XBT/USD"]
[270, {"b": [["11852.30000", "0.33695595", "1596737081.199274"]], "c": "1356889123"}, "book-100", "XBT/USD"]
[270, {"a": [["11870.00000", "0.63179242", "1596737081.200348"]], "c": "2321644495"}, "book-100", "XBT/USD"]
[270, {"a": [["11870.20000", "0.04750000", "1596737081.252459"]], "c": "3728041901"}, "book-100", "XBT/USD"]
[270, {"a": [["11885.70000", "6.39564730", "1596737081.296756"]], "c": "3728041901"}, "book-100", "XBT/USD"]
[270, {"a": [["11869.90000", "0.70000000", "1596737081.300419"]], "c": "29667398"}, "book-100", "XBT/USD"]
[270, {"b": [["11834.20000", "5.47337545", "1596737081.388107"]], "c": "29667398"}, "book-100", "XBT/USD"]
[270, {"a": [["11870.10000", "0.00000000", "1596737081.529837"], ["11906.10000", "0.73344696", "1596736949.094691", "r"]], "c": "4068720447"}, "book-100", "XBT/USD"]
[270, {"a": [["11870.40000", "2.00000000", "1596737081.679157"]], "c": "3474667090"}, "book-100", "XBT/USD"]
[270, {"b": [["11853.50000", "0.00000000", "1596737081.716492"], ["11811.70000", "5.70000000", "1596736886.902857", "r"]], "c": "3474667090"}, "book-100", "XBT/USD"]
[270, {"b": [["11849.10000", "0.00421511", "1596737081.904995"]], "c": "3474667090"}, "book-100", "XBT/USD"]
[270, {"a": [["11869.80000", "3.63186378", "1596737081.967215"]], "c": "2030199156"}, "book-100", "XBT/USD"]
[270, {"a": [["11870.80000", "0.00000000", "1596737082.038101"], ["11906.70000", "0.02328140", "1596737056.573166", "r"]], "c": "371055075"}, "book-100", "XBT/USD"]
[270, {"b": [["11848.40000", "0.81300000", "1596737082.054352"]], "c": "371055075"}, "book-100", "XBT/USD"]
[270, {"b": [["11863.80000", "0.17587963", "1596737082.060437"]], "c": "371055075"}, "book-100", "XBT/USD"]
[270, {"b": [["11853.50000", "0.00675485", "1596737082.074737"]], "c": "371055075"}, "book-100", "XBT/USD"]
[270, {"a": [["11889.90000", "0.00000000", "1596737082.286518"], ["11907.00000", "8.54095785", "1596737002.155356", "r"]], "c": "371055075"}, "book-100", "XBT/USD"]
[270, {"b": [["11861.10000", "0.00000000", "1596737082.461802"], ["11813.30000", "0.99420000", "1596736809.783550", "r"]], "c": "371055075"}, "book-100", "XBT/USD"]
[270, {"a": [["11885.00000", "0.00000000", "1596737082.465868"], ["11907.20000", "6.18638192", "1596736972.522950", "r"]], "c": "371055075"}, "book-100", "XBT/USD"]
[270, {"a": [["11889.90000", "0.45659220", "1596737082.466174"]], "c": "371055075"}, "book-100", "XBT/USD"]
[270, {"a": [["11894.40000", "0.00000000", "1596737082.473311"], ["11907.20000", "6.18638192", "1596736972.522950", "r"]], "c": "371055075"}, "book-100", "XBT/USD"]
[270, {"a": [["11888.50000", "0.00000000", "1596737082.479238"], ["11907.50000", "3.26133727", "1596736967.970398", "r"]], "c": "371055075"}, "book-100", "XBT/USD"]
[270, {"a": [["11893.10000", "0.00000000", "1596737082.486267"], ["11907.90000", "2.38150000", "1596736895.960018", "r"]], "c": "371055075"}, "book-100", "XBT/USD"]
[270, {"a": [["11899.50000", "0.00000000", "1596737082.493979"], ["11908.30000", "1.58322230", "1596736949.361051", "r"]], "c": "371055075"}, "book-100", "XBT/USD"]
[270, {"b": [["11856.70000", "0.00000000", "1596737082.496566"], ["11811.80000", "4.23305508", "1596736972.960659", "r"]], "c": "371055075"}, "book-100", "XBT/USD"]
[270, {"a": [["11895.70000", "0.00000000", "1596737082.504147"], ["11908.90000", "1.06880000", "1596736841.521829", "r"]], "c": "371055075"}, "book-100", "XBT/USD"]
[270, {"a": [["11898.00000", "0.17065000", "1596737082.737219"]], "c": "371055075"}, "book-100", "XBT/USD"]
[270, {"a": [["11891.90000", "0.52841197", "1596737082.786328"]], "c": "371055075"}, "book-100", "XBT/USD"]
[270, {"b": [["11853.70000", "1.80941804", "1596737082.816967"]], "c": "371055075"}, "book-100", "XBT/USD"]
[270, {"a": [["11893.20000", "0.94256578", "1596737082.821622"]], "c": "371055075"}, "book-100", "XBT/USD"]
[270, {"a": [["11889.80000", "0.20400744", "1596737082.954134"]], "c": "371055075"}, "book-100", "XBT/USD"]
[270, {"a": [["11871.00000", "0.18665000", "1596737083.029940"]], "c": "4273504998"}, "book-100", "XBT/USD"]
