[270, {"a": [["11878.10000", "0.44816512", "1596737198.606571"]], "c": "4208064313"}, "book-100", "XBT/USD"]
[270, {"b": [["11849.10000", "0.17597549", "1596737198.606798"]], "c": "267279997"}, "book-100", "XBT/USD"]
[270, {"a": [["11868.30000", "0.00000000", "1596737198.617893"], ["11901.00000", "0.17065000", "1596737120.047779", "r"]], "c": "267279997"}, "book-100", "XBT/USD"]
[270, {"b": [["11843.40000", "0.20468591", "1596737198.641215"]], "c": "267279997"}, "book-100", "XBT/USD"]
[270, {"b": [["11839.90000", "1.00772000", "1596737198.643413"]], "c": "267279997"}, "book-100", "XBT/USD"]
[270, {"a": [["11854.10000", "1.00772000", "1596737198.647588"]], "c": "2748602359"}, "book-100", "XBT/USD"]
[270, {"a": [["11863.50000", "0.00000000", "1596737198.653642"], ["11901.00000", "0.17065000", "1596737120.047779", "r"]], "c": "2748602359"}, "book-100", "XBT/USD"]
[270, {"b": [["11849.50000", "0.49486379", "1596737198.675309"]], "c": "1216349194"}, "book-100", "XBT/USD"]
[270, {"a": [["11864.00000", "0.17597549", "1596737198.679029"]], "c": "1216349194"}, "book-100", "XBT/USD"]
[270, {"a": [["11890.00000", "0.65000000", "1596737198.683064"]], "c": "1216349194"}, "book-100", "XBT/USD"]
[270, {"a": [["11865.30000", "0.67636997", "1596737198.743337"]], "c": "1216349194"}, "book-100", "XBT/USD"]
[270, {"b": [["11837.60000", "0.00000000", "1596737198.745645"], ["11800.80000", "1.51500000", "1596737133.991629", "r"]], "c": "1216349194"}, "book-100", "XBT/USD"]
[270, {"a": [["11874.60000", "0.32942424", "1596737198.752105"]], "c": "1216349194"}, "book-100", "XBT/USD"]
[270, {"a": [["11878.10000", "1.13975218", "1596737198.753578"]], "c": "1216349194"}, "book-100", "XBT/USD"]
[270, {"a": [["11869.60000", "0.00000000", "1596737198.791907"], ["11900.00000", "12.71653131", "1596737075.897027", "r"]], "c": "1216349194"}, "book-100", "XBT/USD"]
[270, {"a": [["11852.70000", "0.80383282", "1596737198.798961"]], "c": "256440102"}, "book-100", "XBT/USD"]
[270, {"b": [["11852.40000", "0.00000000", "1596737198.813612"], ["11800.00000", "17.03324285", "1596736993.942623", "r"]], "c": "2510904780"}, "book-100", "XBT/USD"]
[270, {"a": [["11870.10000", "0.00000000", "1596737198.834204"], ["11900.30000", "2.21022077", "1596737195.329532", "r"]], "c": "2510904780"}, "book-100", "XBT/USD"]
[270, {"b": [["11848.70000", "0.00000000", "1596737198.838754"], ["11799.60000", "0.99110000", "1596737165.782615", "r"]], "c": "2329323931"}, "book-100", "XBT/USD"]
[270, {"a": [["11852.70000", "1.30383282", "1596737198.867475"]], "c": "1929879403"}, "book-100", "XBT/USD"]
[270, {"b": [["11847.70000", "4.21000000", "1596737198.875932"]], "c": "183040730"}, "book-100", "XBT/USD"]
[270, {"b": [["11852.60000", "1.08946070", "1596737198.879289"]], "c": "2778970825"}, "book-100", "XBT/USD"]
[270, {"a": [["11883.10000", "0.10228363", "1596737198.902632"]], "c": "2778970825"}, "book-100", "XBT/USD"]
[270, {"a": [["11855.70000", "4.20700000", "1596737198.948560"]], "c": "2127157077"}, "book-100", "XBT/USD"]
[270, {"b": [["11849.90000", "0.00000000", "1596737198.962644"], ["11799.60000", "0.99110000", "1596737165.782615", "r"]], "c": "2597788653"}, "book-100", "XBT/USD"]
[270, {"a": [["11855.60000", "0.82180000", "1596737199.003722"]], "c": "246570165"}, "book-100", "XBT/USD"]
[270, {"a": [["11855.90000", "0.00000000", "1596737199.007728"], ["11900.00000", "12.71653131", "1596737075.897027", "r"]], "c": "2199021374"}, "book-100", "XBT/USD"]
[270, {"b": [["11850.50000", "0.01466462", "1596737199.017324"]], "c": "74071789"}, "book-100", "XBT/USD"]
[270, {"b": [["11849.20000", "0.15000000", "1596737199.036975"]], "c": "3985430347"}, "book-100", "XBT/USD"]
[270, {"a": [["11888.50000", "0.50000000", "1596737199.104657"]], "c": "3985430347"}, "book-100", "XBT/USD"]
[270, {"b": [["11849.10000", "0.00000000", "1596737199.162791"], ["11800.00000", "17.03324285", "1596736993.942623", "r"]], "c": "2402501780"}, "book-100", "XBT/USD"]
[270, {"a": [["11864.40000", "0.27100000", "1596737199.174569"]], "c": "2402501780"}, "book-100", "XBT/USD"]
[270, {"b": [["11842.10000", "0.00000000", "1596737199.225056"], ["11799.60000", "0.99110000", "1596737165.782615", "r"]], "c": "2402501780"}, "book-100", "XBT/USD"]
[270, {"b": [["11849.10000", "0.17597549", "1596737199.355332"]], "c": "3985430347"}, "book-100", "XBT/USD"]
[270, {"a": [["11856.90000", "0.00000000", "1596737199.379339"], ["11899.90000", "7.61000000", "1596737079.466913", "r"]], "c": "1395409502"}, "book-100", "XBT/USD"]
[270, {"b": [["11836.40000", "0.38000000", "1596737199.452920"]], "c": "1395409502"}, "book-100", "XBT/USD"]
[270, {"a": [["11868.40000", "0.38000000", "1596737199.458868"]], "c": "1395409502"}, "book-100", "XBT/USD"]
[270, {"b": [["11845.00000", "0.32240000", "1596737199.559653"]], "c": "1395409502"}, "book-100", "XBT/USD"]
[270, {"b": [["11840.90000", "0.00000000", "1596737199.562919"], ["11800.00000", "17.03324285", "1596736993.942623", "r"]], "c": "1395409502"}, "book-100", "XBT/USD"]
[270, {"a": [["11857.80000", "0.25000000", "1596737199.621602"]], "c": "2927382518"}, "book-100", "XBT/USD"]
[270, {"b": [["11837.10000", "0.94659172", "1596737199.624672"]], "c": "2927382518"}, "book-100", "XBT/USD"]
[270, {"b": [["11843.60000", "0.00000000", "1596737199.752066"], ["11800.00000", "17.03324285", "1596736993.942623", "r"]], "c": "2927382518"}, "book-100", "XBT/USD"]
[270, {"a": [["11854.00000", "0.70000000", "1596737199.847653"]], "c": "3892679946"}, "book-100", "XBT/USD"]
[270, {"b": [["11847.80000", "0.00000000", "1596737199.848567"], ["11799.60000", "0.99110000", "1596737165.782615", "r"]], "c": "311237472"}, "book-100", "XBT/USD"]
[270, {"a": [["11854.00000", "0.00000000", "1596737199.899604"], ["11899.00000", "2.81849664", "1596737063.692951", "r"]], "c": "2797657229"}, "book-100", "XBT/USD"]
[270, {"b": [["11840.50000", "0.94631991", "1596737199.919629"]], "c": "2797657229"}, "book-100", "XBT/USD"]
[270, {"a": [["11867.90000", "0.00000000", "1596737199.925929"], ["11899.10000", "7.82927162", "1596737145.805987", "r"]], "c": "2797657229"}, "book-100", "XBT/USD"]
[270, {"a": [["11852.70000", "1.29395374", "1596737200.030808"]], "c": "2340398512"}, "book-100", "XBT/USD"]
[270, {"b": [["11849.20000", "0.00000000", "1596737200.131573"], ["11799.60000", "0.99110000", "1596737165.782615", "r"]], "c": "2608864407"}, "book-100", "XBT/USD"]
[270, {"a": [["11857.80000", "0.00000000", "1596737200.136648"], ["11899.90000", "7.61000000", "1596737079.466913", "r"]], "c": "1131439936"}, "book-100", "XBT/USD"]
[270, {"b": [["11852.60000", "0.66795813", "1596737200.203915"]], "c": "4148662417"}, "book-100", "XBT/USD"]
[270, {"a": [["11856.00000", "0.00000000", "1596737200.205851"], ["11900.00000", "12.71653131", "1596737075.897027", "r"]], "c": "957282189"}, "book-100", "XBT/USD"]
[270, {"b": [["11848.70000", "0.15000000", "1596737200.225175"]], "c": "3536694852"}, "book-100", "XBT/USD"]
[270, {"a": [["11862.10000", "0.00000000", "1596737200.226985"], ["11900.30000", "2.21022077", "1596737195.329532", "r"]], "c": "3536694852"}, "book-100", "XBT/USD"]
[270, {"a": [["11860.90000", "0.00000000", "1596737200.239058"], ["11901.00000", "0.17065000", "1596737120.047779", "r"]], "c": "3536694852"}, "book-100", "XBT/USD"]
[270, {"a": [["11852.70000", "0.89395374", "1596737200.253034"], ["11852.70000", "1.29395374", "1596737200.254090"]], "c": "3536694852"}, "book-100", "XBT/USD"]
[270, {"a": [["11858.60000", "0.84333511", "1596737200.263265"]], "c": "2546022920"}, "book-100", "XBT/USD"]
[270, {"b": [["11838.10000", "0.51866755", "1596737200.263419"]], "c": "2546022920"}, "book-100", "XBT/USD"]
[270, {"a": [["11855.10000", "0.63246894", "1596737200.263511"]], "c": "3470350788"}, "book-100", "XBT/USD"]
[270, {"b": [["11851.00000", "0.31626542", "1596737200.264759"]], "c": "2873059942"}, "book-100", "XBT/USD"]
[270, {"a": [["11853.70000", "0.63253084", "1596737200.266259"]], "c": "35348622"}, "book-100", "XBT/USD"]
[270, {"a": [["11854.20000", "0.63250133", "1596737200.271596"]], "c": "1729902882"}, "book-100", "XBT/USD"]
[270, {"b": [["11838.70000", "0.69560580", "1596737200.272712"]], "c": "1729902882"}, "book-100", "XBT/USD"]
[270, {"a": [["11860.30000", "0.00000000", "1596737200.294832"], ["11899.90000", "7.61000000", "1596737079.466913", "r"]], "c": "1729902882"}, "book-100", "XBT/USD"]
[270, {"b": [["11846.40000", "0.75188286", "1596737200.308297"]], "c": "1729902882"}, "book-100", "XBT/USD"]
[270, {"a": [["11855.00000", "0.82180000", "1596737200.331021"]], "c": "2316238935"}, "book-100", "XBT/USD"]
[270, {"b": [["11849.10000", "0.00000000", "1596737200.334821"], ["11800.00000", "17.03324285", "1596736993.942623", "r"]], "c": "1638353612"}, "book-100", "XBT/USD"]
[270, {"a": [["11855.60000", "0.00000000", "1596737200.338828"], ["11899.90000", "7.61000000", "1596737079.466913", "r"]], "c": "4068142323"}, "book-100", "XBT/USD"]
[270, {"a": [["11857.80000", "1.50000000", "1596737200.443807"]], "c": "415558352"}, "book-100", "XBT/USD"]
[270, {"b": [["11852.60000", "0.38436932", "1596737200.453772"]], "c": "1116842809"}, "book-100", "XBT/USD"]
[270, {"a": [["11872.90000", "0.00000000", "1596737200.453900"], ["11899.90000", "7.61000000", "1596737079.466913", "r"]], "c": "1116842809"}, "book-100", "XBT/USD"]
[270, {"a": [["11856.90000", "0.25000000", "1596737200.507223"]], "c": "3844213713"}, "book-100", "XBT/USD"]
[270, {"a": [["11860.20000", "0.84298356", "1596737200.519228"]], "c": "3844213713"}, "book-100", "XBT/USD"]
[270, {"a": [["11859.50000", "0.65311086", "1596737200.520812"]], "c": "3844213713"}, "book-100", "XBT/USD"]
[270, {"a": [["11854.30000", "0.00000000", "1596737200.556481"], ["11899.00000", "2.81849664", "1596737063.692951", "r"]], "c": "1397433808"}, "book-100", "XBT/USD"]
[270, {"a": [["11872.70000", "7.77723333", "1596737200.696406"]], "c": "1397433808"}, "book-100", "XBT/USD"]
[270, {"a": [["11864.80000", "6.10000000", "1596737200.812134"]], "c": "1397433808"}, "book-100", "XBT/USD"]
[270, {"a": [["11852.70000", "1.88895374", "1596737201.097474"]], "c": "3473648603"}, "book-100", "XBT/USD"]
[270, {"a": [["11887.00000", "0.00000000", "1596737201.107146"], ["11898.70000", "0.01000000", "1596737133.560066", "r"]], "c": "3473648603"}, "book-100", "XBT/USD"]
[270, {"b": [["11826.10000", "0.00000000", "1596737201.373230"], ["11799.60000", "0.99110000", "1596737165.782615", "r"]], "c": "3473648603"}, "book-100", "XBT/USD"]
[270, {"a": [["11879.90000", "0.01000000", "1596737201.449884"]], "c": "3473648603"}, "book-100", "XBT/USD"]
[270, {"b": [["11842.30000", "0.00000000", "1596737201.552011"], ["11799.20000", "23.14040000", "1596736141.974806", "r"]], "c": "3473648603"}, "book-100", "XBT/USD"]
[270, {"b": [["11835.70000", "1.04870000", "1596737201.553851"]], "c": "3473648603"}, "book-100", "XBT/USD"]
[270, {"b": [["11852.10000", "0.00000000", "1596737201.579378"], ["11799.20000", "23.14040000", "1596736141.974806", "r"]], "c": "434865384"}, "book-100", "XBT/USD"]
[270, {"a": [["11852.70000", "2.30895374", "1596737201.605614"]], "c": "1417785381"}, "book-100", "XBT/USD"]
[270, {"a": [["11865.40000", "1.15238061", "1596737201.733719"]], "c": "1417785381"}, "book-100", "XBT/USD"]
[270, {"a": [["11865.60000", "0.81202331", "1596737201.733951"]], "c": "1417785381"}, "book-100", "XBT/USD"]
[270, {"b": [["11844.30000", "0.00000000", "1596737201.734577"], ["11798.60000", "18.30000000", "1596737089.559503", "r"]], "c": "1417785381"}, "book-100", "XBT/USD"]
[270, {"a": [["11865.40000", "0.93597066", "1596737201.734873"]], "c": "1417785381"}, "book-100", "XBT/USD"]
[270, {"a": [["11865.60000", "0.66283811", "1596737201.734925"]], "c": "1417785381"}, "book-100", "XBT/USD"]
[270, {"a": [["11865.40000", "0.80561584", "1596737201.735052"]], "c": "1417785381"}, "book-100", "XBT/USD"]
[270, {"a": [["11865.40000", "0.41646576", "1596737201.735136"]], "c": "1417785381"}, "book-100", "XBT/USD"]
[270, {"b": [["11843.40000", "0.00000000", "1596737201.735189"], ["11797.90000", "6.30000000", "1596737122.404410", "r"]], "c": "1417785381"}, "book-100", "XBT/USD"]
[270, {"a": [["11865.40000", "0.00000000", "1596737201.751082"], ["11899.00000", "2.81849664", "1596737063.692951", "r"]], "c": "1417785381"}, "book-100", "XBT/USD"]
[270, {"b": [["11816.80000", "6.06410354", "1596737201.769786"]], "c": "1417785381"}, "book-100", "XBT/USD"]
[270, {"a": [["11865.60000", "0.00000000", "1596737201.776853"], ["11899.10000", "7.82927162", "1596737145.805987", "r"]], "c": "1417785381"}, "book-100", "XBT/USD"]
[270, {"b": [["11841.70000", "0.00000000", "1596737201.830427"], ["11797.90000", "6.30000000", "1596737122.404410", "r"]], "c": "1417785381"}, "book-100", "XBT/USD"]
[270, {"b": [["11844.50000", "0.00000000", "1596737201.838522"], ["11796.30000", "10.90540000", "1596736141.718106", "r"]], "c": "1417785381"}, "book-100", "XBT/USD"]
[270, {"a": [["11873.10000", "6.24281582", "1596737201.852347"]], "c": "1417785381"}, "book-100", "XBT/USD"]
[270, {"a": [["11878.00000", "0.00000000", "1596737201.890589"], ["11899.10000", "7.82927162", "1596737145.805987", "r"]], "c": "1417785381"}, "book-100", "XBT/USD"]
[270, {"a": [["11865.30000", "0.00000000", "1596737201.890813"], ["11899.90000", "7.61000000", "1596737079.466913", "r"]], "c": "1417785381"}, "book-100", "XBT/USD"]
[270, {"b": [["11848.20000", "0.10000000", "1596737201.896509"]], "c": "240421505"}, "book-100", "XBT/USD"]
[270, {"a": [["11859.40000", "0.13454015", "1596737201.931480"]], "c": "240421505"}, "book-100", "XBT/USD"]
[270, {"a": [["11859.40000", "0.77651109", "1596737201.935031"]], "c": "240421505"}, "book-100", "XBT/USD"]
[270, {"b": [["11846.40000", "0.42167444", "1596737201.984282"]], "c": "240421505"}, "book-100", "XBT/USD"]
[270, {"a": [["11859.40000", "0.92724545", "1596737202.037608"]], "c": "240421505"}, "book-100", "XBT/USD"]
[270, {"b": [["11839.60000", "0.20477436", "1596737202.060555"]], "c": "240421505"}, "book-100", "XBT/USD"]
[270, {"a": [["11879.60000", "0.00000000", "1596737202.119129"], ["11899.90000", "7.61000000", "1596737079.466913", "r"]], "c": "240421505"}, "book-100", "XBT/USD"]
[270, {"b": [["11837.30000", "0.53074484", "1596737202.140613"]], "c": "240421505"}, "book-100", "XBT/USD"]
[270, {"a": [["11864.40000", "0.96086959", "1596737202.164487"]], "c": "240421505"}, "book-100", "XBT/USD"]
[270, {"b": [["11839.60000", "0.25182139", "1596737202.165493"]], "c": "240421505"}, "book-100", "XBT/USD"]
[270, {"b": [["11841.60000", "0.69371877", "1596737202.205029"]], "c": "240421505"}, "book-100", "XBT/USD"]
[270, {"a": [["11859.40000", "1.59008356", "1596737202.226807"]], "c": "240421505"}, "book-100", "XBT/USD"]
[270, {"a": [["11859.40000", "1.89787210", "1596737202.247040"]], "c": "240421505"}, "book-100", "XBT/USD"]
[270, {"a": [["11859.40000", "2.28080233", "1596737202.248433"]], "c": "240421505"}, "book-100", "XBT/USD"]
[270, {"b": [["11848.70000", "0.00000000", "1596737202.278296"], ["11799.20000", "23.14040000", "1596736141.974806", "r"]], "c": "4008929004"}, "book-100", "XBT/USD"]
[270, {"a": [["11852.70000", "2.31883282", "1596737202.325724"]], "c": "2126051424"}, "book-100", "XBT/USD"]
[270, {"a": [["11852.70000", "4.31883282", "1596737202.325933"]], "c": "3928951174"}, "book-100", "XBT/USD"]
[270, {"b": [["11838.10000", "0.09700000", "1596737202.347145"]], "c": "3928951174"}, "book-100", "XBT/USD"]
[270, {"a": [["11853.60000", "0.70000000", "1596737202.377271"]], "c": "892471219"}, "book-100", "XBT/USD"]
[270, {"b": [["11851.90000", "0.31626251", "1596737202.398130"]], "c": "393745379"}, "book-100", "XBT/USD"]
[270, {"b": [["11850.60000", "0.31626858", "1596737202.400068"]], "c": "3892564612"}, "book-100", "XBT/USD"]
[270, {"a": [["11859.40000", "2.49333367", "1596737202.403644"]], "c": "3892564612"}, "book-100", "XBT/USD"]
[270, {"b": [["11848.20000", "0.00000000", "1596737202.450065"], ["11799.60000", "0.99110000", "1596737165.782615", "r"]], "c": "2745465621"}, "book-100", "XBT/USD"]
[270, {"b": [["11845.70000", "0.33022794", "1596737202.506778"]], "c": "2745465621"}, "book-100", "XBT/USD"]
[270, {"a": [["11859.40000", "2.89039280", "1596737202.595611"]], "c": "2745465621"}, "book-100", "XBT/USD"]
[270, {"a": [["11890.50000", "0.00000000", "1596737202.630501"], ["11899.90000", "7.61000000", "1596737079.466913", "r"]], "c": "2745465621"}, "book-100", "XBT/USD"]
[270, {"a": [["11864.40000", "0.27100000", "1596737202.677668"]], "c": "2745465621"}, "book-100", "XBT/USD"]
[270, {"b": [["11843.20000", "0.09621094", "1596737202.700892"]], "c": "2745465621"}, "book-100", "XBT/USD"]
[270, {"a": [["11888.20000", "0.09250000", "1596737202.754673"]], "c": "2745465621"}, "book-100", "XBT/USD"]
[270, {"a": [["11853.40000", "0.12995653", "1596737202.764280"]], "c": "3669428854"}, "book-100", "XBT/USD"]
[270, {"a": [["11861.50000", "0.66005779", "1596737202.844458"]], "c": "3669428854"}, "book-100", "XBT/USD"]
[270, {"b": [["11850.10000", "0.00000000", "1596737202.845979"], ["11800.00000", "17.03324285", "1596736993.942623", "r"]], "c": "3405402352"}, "book-100", "XBT/USD"]
[270, {"b": [["11843.60000", "0.45326317", "1596737202.854954"]], "c": "3405402352"}, "book-100", "XBT/USD"]
[270, {"a": [["11870.60000", "2.00000000", "1596737202.969035"]], "c": "3405402352"}, "book-100", "XBT/USD"]
[270, {"a": [["11878.10000", "0.69158706", "1596737203.045023"]], "c": "3405402352"}, "book-100", "XBT/USD"]
[270, {"b": [["11848.20000", "0.15000000", "1596737203.095094"]], "c": "3497191915"}, "book-100", "XBT/USD"]
[270, {"a": [["11853.70000", "0.00000000", "1596737203.219885"], ["11899.00000", "2.81849664", "1596737063.692951", "r"]], "c": "363773024"}, "book-100", "XBT/USD"]
[270, {"a": [["11879.90000", "0.67748651", "1596737203.226957"]], "c": "363773024"}, "book-100", "XBT/USD"]
[270, {"b": [["11827.90000", "1.60716129", "1596737203.379922"]], "c": "363773024"}, "book-100", "XBT/USD"]
[270, {"b": [["11852.60000", "0.30000000", "1596737203.486683"]], "c": "533447583"}, "book-100", "XBT/USD"]
[270, {"b": [["11839.00000", "0.00000000", "1596737203.578361"], ["11800.80000", "1.51500000", "1596737133.991629", "r"]], "c": "533447583"}, "book-100", "XBT/USD"]
[270, {"b": [["11838.70000", "0.67673336", "1596737203.579187"]], "c": "533447583"}, "book-100", "XBT/USD"]
[270, {"b": [["11838.60000", "6.49579788", "1596737203.579382"]], "c": "533447583"}, "book-100", "XBT/USD"]
[270, {"a": [["11888.00000", "3.00000000", "1596737203.605917"]], "c": "533447583"}, "book-100", "XBT/USD"]
[270, {"a": [["11879.90000", "0.01000000", "1596737203.631538"]], "c": "533447583"}, "book-100", "XBT/USD"]
[270, {"a": [["11878.00000", "0.58048733", "1596737203.827678"]], "c": "533447583"}, "book-100", "XBT/USD"]
[270, {"a": [["11864.00000", "0.00000000", "1596737203.856751"], ["11898.70000", "0.01000000", "1596737133.560066", "r"]], "c": "533447583"}, "book-100", "XBT/USD"]
[270, {"a": [["11882.50000", "0.00000000", "1596737204.073559"], ["11899.00000", "2.81849664", "1596737063.692951", "r"]], "c": "533447583"}, "book-100", "XBT/USD"]
[270, {"b": [["11821.30000", "0.00000000", "1596737204.077240"], ["11800.00000", "17.03324285", "1596736993.942623", "r"]], "c": "533447583"}, "book-100", "XBT/USD"]
[270, {"b": [["11821.20000", "0.73644267", "1596737204.321870"]], "c": "533447583"}, "book-100", "XBT/USD"]
[270, {"a": [["11882.40000", "0.73644267", "1596737204.322597"]], "c": "533447583"}, "book-100", "XBT/USD"]
[270, {"b": [["11849.50000", "0.42154067", "1596737204.429921"]], "c": "3693877613"}, "book-100", "XBT/USD"]
[270, {"a": [["11853.60000", "0.00000000", "1596737204.471144"], ["11899.00000", "2.81849664", "1596737063.692951", "r"]], "c": "3070018296"}, "book-100", "XBT/USD"]
[270, {"a": [["11852.70000", "4.87027070", "1596737204.496860"]], "c": "3164462592"}, "book-100", "XBT/USD"]
[270, {"a": [["11858.40000", "0.00000000", "1596737204.570855"], ["11899.10000", "7.82927162", "1596737145.805987", "r"]], "c": "3164462592"}, "book-100", "XBT/USD"]
[270, {"a": [["11864.20000", "0.00000000", "1596737204.690686"], ["11899.90000", "7.61000000", "1596737079.466913", "r"]], "c": "3164462592"}, "book-100", "XBT/USD"]
[270, {"a": [["11865.10000", "0.00000000", "1596737204.751716"], ["11900.00000", "12.71653131", "1596737075.897027", "r"]], "c": "3164462592"}, "book-100", "XBT/USD"]
[270, {"a": [["11856.80000", "0.04750000", "1596737204.814615"]], "c": "3124023885"}, "book-100", "XBT/USD"]
[270, {"a": [["11889.00000", "0.17065000", "1596737204.860736"]], "c": "3124023885"}, "book-100", "XBT/USD"]
[270, {"b": [["11851.90000", "0.00000000", "1596737205.161382"], ["11800.00000", "17.03324285", "1596736993.942623", "r"]], "c": "162595548"}, "book-100", "XBT/USD"]
[270, {"a": [["11853.30000", "0.63258492", "1596737205.215021"]], "c": "403900446"}, "book-100", "XBT/USD"]
[270, {"b": [["11836.20000", "1.48322508", "1596737205.400342"]], "c": "403900446"}, "book-100", "XBT/USD"]
[270, {"a": [["11869.40000", "0.00000000", "1596737205.499226"], ["11899.10000", "7.82927162", "1596737145.805987", "r"]], "c": "403900446"}, "book-100", "XBT/USD"]
[270, {"a": [["11860.30000", "0.28399999", "1596737205.517377"]], "c": "403900446"}, "book-100", "XBT/USD"]
[270, {"b": [["11848.20000", "0.00000000", "1596737205.569873"], ["11799.60000", "0.99110000", "1596737165.782615", "r"]], "c": "3880757419"}, "book-100", "XBT/USD"]
[270, {"b": [["11848.10000", "4.04375668", "1596737205.687762"]], "c": "2806072277"}, "book-100", "XBT/USD"]
[270, {"b": [["11832.20000", "0.00452157", "1596737205.877384"]], "c": "2806072277"}, "book-100", "XBT/USD"]
[270, {"a": [["11873.10000", "0.00000000", "1596737205.891017"], ["11899.10000", "7.82927162", "1596737145.805987", "r"]], "c": "2806072277"}, "book-100", "XBT/USD"]
[270, {"a": [["11856.90000", "0.00000000", "1596737206.859494"], ["11899.90000", "7.61000000", "1596737079.466913", "r"]], "c": "1769207511"}, "book-100", "XBT/USD"]
[270, {"b": [["11833.60000", "0.94200000", "1596737206.931941"]], "c": "1769207511"}, "book-100", "XBT/USD"]
[270, {"b": [["11836.90000", "0.00000000", "1596737206.931997"], ["11800.00000", "17.03324285", "1596736993.942623", "r"]], "c": "1769207511"}, "book-100", "XBT/USD"]
[270, {"a": [["11877.90000", "0.00438186", "1596737206.934714"]], "c": "1769207511"}, "book-100", "XBT/USD"]
[270, {"b": [["11803.20000", "2.21035419", "1596737206.935471"]], "c": "1769207511"}, "book-100", "XBT/USD"]
[270, {"a": [["11874.60000", "0.00000000", "1596737206.935658"], ["11899.90000", "7.61000000", "1596737079.466913", "r"]], "c": "1769207511"}, "book-100", "XBT/USD"]
[270, {"b": [["11841.60000", "0.00000000", "1596737206.936634"], ["11800.00000", "17.03324285", "1596736993.942623", "r"]], "c": "1769207511"}, "book-100", "XBT/USD"]
[270, {"b": [["11803.60000", "3.21918392", "1596737206.938383"]], "c": "1769207511"}, "book-100", "XBT/USD"]
[270, {"a": [["11869.00000", "6.42833361", "1596737206.943561"]], "c": "1769207511"}, "book-100", "XBT/USD"]
[270, {"a": [["11854.00000", "0.70000000", "1596737206.948774"]], "c": "2130762067"}, "book-100", "XBT/USD"]
[270, {"a": [["11866.60000", "0.00000000", "1596737206.952044"], ["11899.90000", "7.61000000", "1596737079.466913", "r"]], "c": "2130762067"}, "book-100", "XBT/USD"]
[270, {"b": [["11845.70000", "0.00000000", "1596737206.957247"], ["11799.60000", "0.99110000", "1596737165.782615", "r"]], "c": "2130762067"}, "book-100", "XBT/USD"]
[270, {"a": [["11878.00000", "0.00000000", "1596737207.145050"], ["11900.00000", "12.71653131", "1596737075.897027", "r"]], "c": "2130762067"}, "book-100", "XBT/USD"]
[270, {"a": [["11890.60000", "0.00000000", "1596737207.145831"], ["11900.10000", "2.21035419", "1596737206.941612", "r"]], "c": "2130762067"}, "book-100", "XBT/USD"]
[270, {"b": [["11832.20000", "0.00000000", "1596737207.305044"], ["11799.20000", "23.14040000", "1596736141.974806", "r"]], "c": "2130762067"}, "book-100", "XBT/USD"]
[270, {"a": [["11877.90000", "0.00000000", "1596737207.305675"], ["11901.00000", "0.17065000", "1596737120.047779", "r"]], "c": "2130762067"}, "book-100", "XBT/USD"]
[270, {"a": [["11888.50000", "0.00000000", "1596737207.366200"], ["11901.20000", "0.05455260", "1596737145.299909", "r"]], "c": "2130762067"}, "book-100", "XBT/USD"]
[270, {"a": [["11888.60000", "2.11116456", "1596737207.411222"]], "c": "2130762067"}, "book-100", "XBT/USD"]
[270, {"a": [["11878.00000", "0.62373749", "1596737207.412334"]], "c": "2130762067"}, "book-100", "XBT/USD"]
[270, {"b": [["11842.30000", "0.69356089", "1596737207.444891"]], "c": "2130762067"}, "book-100", "XBT/USD"]
[270, {"a": [["11861.50000", "0.00000000", "1596737207.456470"], ["11901.00000", "0.17065000", "1596737120.047779", "r"]], "c": "2130762067"}, "book-100", "XBT/USD"]
[270, {"a": [["11876.20000", "0.32932436", "1596737207.461378"]], "c": "2130762067"}, "book-100", "XBT/USD"]
[270, {"a": [["11856.90000", "0.25000000", "1596737207.571958"]], "c": "2130762067"}, "book-100", "XBT/USD"]
[270, {"b": [["11845.70000", "0.33017229", "1596737207.819286"]], "c": "2130762067"}, "book-100", "XBT/USD"]
[270, {"a": [["11876.20000", "0.00000000", "1596737207.842585"], ["11900.10000", "2.21035419", "1596737206.941612", "r"]], "c": "2130762067"}, "book-100", "XBT/USD"]
[270, {"b": [["11838.50000", "1.75001014", "1596737207.854313"]], "c": "2130762067"}, "book-100", "XBT/USD"]
[270, {"b": [["11844.20000", "0.00000000", "1596737207.865170"], ["11799.60000", "0.99110000", "1596737165.782615", "r"]], "c": "2130762067"}, "book-100", "XBT/USD"]
[270, {"b": [["11838.00000", "2.19060747", "1596737207.866230"]], "c": "2130762067"}, "book-100", "XBT/USD"]
[270, {"b": [["11842.00000", "0.00000000", "1596737207.876906"], ["11799.20000", "23.14040000", "1596736141.974806", "r"]], "c": "2130762067"}, "book-100", "XBT/USD"]
[270, {"b": [["11842.40000", "0.00000000", "1596737207.881887"], ["11798.60000", "18.30000000", "1596737089.559503", "r"]], "c": "2130762067"}, "book-100", "XBT/USD"]
[270, {"b": [["11838.50000", "0.00000000", "1596737207.897308"], ["11797.90000", "6.30000000", "1596737122.404410", "r"]], "c": "2130762067"}, "book-100", "XBT/USD"]
[270, {"b": [["11837.50000", "0.00000000", "1596737207.899221"], ["11796.30000", "10.90540000", "1596736141.718106", "r"]], "c": "2130762067"}, "book-100", "XBT/USD"]
[270, {"b": [["11842.30000", "0.00000000", "1596737207.899431"], ["11796.00000", "0.17065000", "1596737137.274179", "r"]], "c": "2130762067"}, "book-100", "XBT/USD"]
[270, {"b": [["11848.20000", "0.10000000", "1596737207.925186"]], "c": "3104758993"}, "book-100", "XBT/USD"]
[270, {"b": [["11838.60000", "0.00000000", "1596737207.957399"], ["11796.00000", "0.17065000", "1596737137.274179", "r"]], "c": "3104758993"}, "book-100", "XBT/USD"]
[270, {"a": [["11861.30000", "0.68276005", "1596737207.971064"]], "c": "3104758993"}, "book-100", "XBT/USD"]
[270, {"b": [["11848.20000", "0.00000000", "1596737208.021417"], ["11795.50000", "1.06000000", "1596737134.250857", "r"]], "c": "2130762067"}, "book-100", "XBT/USD"]
[270, {"b": [["11845.70000", "0.00000000", "1596737208.045304"], ["11795.30000", "2.20028792", "1596736851.216162", "r"]], "c": "2130762067"}, "book-100", "XBT/USD"]
[270, {"b": [["11832.40000", "1.28081054", "1596737208.209592"]], "c": "2130762067"}, "book-100", "XBT/USD"]
[270, {"b": [["11838.30000", "0.76591500", "1596737208.209660"]], "c": "2130762067"}, "book-100", "XBT/USD"]
[270, {"b": [["11840.60000", "0.10939517", "1596737208.216266"]], "c": "2130762067"}, "book-100", "XBT/USD"]
[270, {"a": [["11859.50000", "0.00000000", "1596737208.242288"], ["11900.10000", "2.21035419", "1596737206.941612", "r"]], "c": "2130762067"}, "book-100", "XBT/USD"]
[270, {"a": [["11852.70000", "4.47027070", "1596737208.254060"]], "c": "2569493367"}, "book-100", "XBT/USD"]
[270, {"b": [["11830.00000", "7.57128700", "1596737208.274468"]], "c": "2569493367"}, "book-100", "XBT/USD"]
[270, {"a": [["11856.40000", "0.84342762", "1596737208.388734"]], "c": "1457755893"}, "book-100", "XBT/USD"]
[270, {"a": [["11857.80000", "0.00000000", "1596737208.391916"], ["11900.10000", "2.21035419", "1596737206.941612", "r"]], "c": "1457755893"}, "book-100", "XBT/USD"]
[270, {"a": [["11852.70000", "2.47027070", "1596737208.424632"]], "c": "3262408467"}, "book-100", "XBT/USD"]
[270, {"a": [["11858.50000", "0.64973047", "1596737208.458870"]], "c": "3262408467"}, "book-100", "XBT/USD"]
[270, {"a": [["11855.80000", "1.50000000", "1596737208.535995"]], "c": "2017586901"}, "book-100", "XBT/USD"]
[270, {"a": [["11884.70000", "0.50000000", "1596737208.537607"]], "c": "2017586901"}, "book-100", "XBT/USD"]
[270, {"a": [["11888.60000", "0.00000000", "1596737208.617955"], ["11899.90000", "7.61000000", "1596737079.466913", "r"]], "c": "2017586901"}, "book-100", "XBT/USD"]
[270, {"a": [["11890.60000", "2.19629440", "1596737208.801665"]], "c": "2017586901"}, "book-100", "XBT/USD"]
[270, {"a": [["11852.70000", "1.91883282", "1596737209.247813"]], "c": "3259624341"}, "book-100", "XBT/USD"]
[270, {"a": [["11886.70000", "0.00500000", "1596737209.439182"]], "c": "3259624341"}, "book-100", "XBT/USD"]
[270, {"b": [["11825.30000", "0.00700000", "1596737210.300336"]], "c": "3259624341"}, "book-100", "XBT/USD"]
[270, {"b": [["11834.00000", "1.75176133", "1596737210.308075"]], "c": "3259624341"}, "book-100", "XBT/USD"]
[270, {"b": [["11839.90000", "2.39521647", "1596737210.309501"]], "c": "3259624341"}, "book-100", "XBT/USD"]
[270, {"b": [["11842.30000", "0.69360764", "1596737210.310384"]], "c": "3259624341"}, "book-100", "XBT/USD"]
[270, {"b": [["11845.70000", "0.33019455", "1596737210.329647"]], "c": "3259624341"}, "book-100", "XBT/USD"]
[270, {"b": [["11848.20000", "0.10000000", "1596737210.381206"]], "c": "71822871"}, "book-100", "XBT/USD"]
[270, {"a": [["11875.00000", "0.32937984", "1596737210.476259"]], "c": "71822871"}, "book-100", "XBT/USD"]
[270, {"a": [["11852.70000", "1.49883282", "1596737210.999815"]], "c": "1370891158"}, "book-100", "XBT/USD"]
[270, {"b": [["11842.40000", "0.92444000", "1596737211.011184"]], "c": "1370891158"}, "book-100", "XBT/USD"]
[270, {"a": [["11856.90000", "0.00000000", "1596737211.027913"], ["11899.00000", "2.81849664", "1596737063.692951", "r"]], "c": "1370891158"}, "book-100", "XBT/USD"]
[270, {"a": [["11888.00000", "0.00000000", "1596737211.035833"], ["11899.10000", "7.82927162", "1596737145.805987", "r"]], "c": "1370891158"}, "book-100", "XBT/USD"]
[270, {"a": [["11868.90000", "0.00000000", "1596737211.051763"], ["11899.90000", "7.61000000", "1596737079.466913", "r"]], "c": "1370891158"}, "book-100", "XBT/USD"]
[270, {"b": [["11843.10000", "0.00000000", "1596737211.051881"], ["11800.00000", "17.03324285", "1596736993.942623", "r"]], "c": "1370891158"}, "book-100", "XBT/USD"]
[270, {"b": [["11821.00000", "0.73645902", "1596737211.058107"]], "c": "1370891158"}, "book-100", "XBT/USD"]
[270, {"b": [["11821.20000", "0.00000000", "1596737211.061695"], ["11800.00000", "17.03324285", "1596736993.942623", "r"]], "c": "1370891158"}, "book-100", "XBT/USD"]
[270, {"a": [["11853.30000", "0.00000000", "1596737211.061838"], ["11900.00000", "12.71653131", "1596737075.897027", "r"]], "c": "1560252359"}, "book-100", "XBT/USD"]
[270, {"b": [["11836.20000", "1.06150180", "1596737211.062818"]], "c": "1560252359"}, "book-100", "XBT/USD"]
[270, {"b": [["11852.60000", "0.70000000", "1596737211.064480"]], "c": "1694941862"}, "book-100", "XBT/USD"]
[270, {"a": [["11855.70000", "0.00000000", "1596737211.067601"], ["11900.10000", "2.21035419", "1596737206.941612", "r"]], "c": "1470224811"}, "book-100", "XBT/USD"]
[270, {"a": [["11864.80000", "0.00000000", "1596737211.084465"], ["11901.00000", "0.17065000", "1596737120.047779", "r"]], "c": "1470224811"}, "book-100", "XBT/USD"]
[270, {"b": [["11831.20000", "0.00000000", "1596737211.103021"], ["11799.60000", "0.99110000", "1596737165.782615", "r"]], "c": "1470224811"}, "book-100", "XBT/USD"]
[270, {"b": [["11839.10000", "0.02300000", "1596737211.104928"]], "c": "1470224811"}, "book-100", "XBT/USD"]
[270, {"a": [["11857.90000", "0.88629000", "1596737211.114162"]], "c": "1470224811"}, "book-100", "XBT/USD"]
[270, {"a": [["11854.00000", "0.00000000", "1596737211.119975"], ["11901.20000", "0.05455260", "1596737145.299909", "r"]], "c": "2811290228"}, "book-100", "XBT/USD"]
[270, {"b": [["11850.60000", "0.00000000", "1596737211.125357"], ["11799.60000", "0.99110000", "1596737165.782615", "r"]], "c": "1738166910"}, "book-100", "XBT/USD"]
[270, {"a": [["11854.20000", "0.00000000", "1596737211.125588"], ["11901.40000", "1.90492467", "1596737138.167457", "r"]], "c": "1028215259"}, "book-100", "XBT/USD"]
[270, {"a": [["11856.40000", "0.00000000", "1596737211.125668"], ["11901.50000", "3.26167975", "1596737133.218332", "r"]], "c": "454901230"}, "book-100", "XBT/USD"]
[270, {"b": [["11840.30000", "0.23800000", "1596737211.161394"]], "c": "454901230"}, "book-100", "XBT/USD"]
[270, {"b": [["11848.30000", "0.10000000", "1596737211.168984"]], "c": "1894646808"}, "book-100", "XBT/USD"]
[270, {"a": [["11855.70000", "0.82180000", "1596737211.193229"]], "c": "1633652396"}, "book-100", "XBT/USD"]
[270, {"b": [["11852.00000", "0.31624798", "1596737211.193475"]], "c": "1664765181"}, "book-100", "XBT/USD"]
[270, {"a": [["11855.90000", "0.63245911", "1596737211.194534"]], "c": "4120566128"}, "book-100", "XBT/USD"]
[270, {"a": [["11869.70000", "0.85522881", "1596737211.194724"]], "c": "4120566128"}, "book-100", "XBT/USD"]
[270, {"b": [["11851.90000", "0.31622955", "1596737211.194830"]], "c": "2595665974"}, "book-100", "XBT/USD"]
[270, {"a": [["11869.10000", "6.84332795", "1596737211.194924"]], "c": "2595665974"}, "book-100", "XBT/USD"]
[270, {"b": [["11852.60000", "0.98358881", "1596737211.204112"]], "c": "3563995775"}, "book-100", "XBT/USD"]
[270, {"a": [["11859.10000", "0.25000000", "1596737211.207858"]], "c": "3563995775"}, "book-100", "XBT/USD"]
[270, {"a": [["11854.10000", "0.00000000", "1596737211.210157"], ["11901.20000", "0.05455260", "1596737145.299909", "r"]], "c": "1062463811"}, "book-100", "XBT/USD"]
[270, {"a": [["11855.00000", "0.00000000", "1596737211.240447"], ["11901.40000", "1.90492467", "1596737138.167457", "r"]], "c": "2656153915"}, "book-100", "XBT/USD"]
[270, {"a": [["11858.50000", "0.00000000", "1596737211.253996"], ["11901.50000", "3.26167975", "1596737133.218332", "r"]], "c": "3423826569"}, "book-100", "XBT/USD"]
[270, {"b": [["11845.80000", "0.87691000", "1596737211.266372"]], "c": "3423826569"}, "book-100", "XBT/USD"]
[270, {"a": [["11878.00000", "0.00000000", "1596737211.270929"], ["11901.80000", "0.75800000", "1596737130.968842", "r"]], "c": "3423826569"}, "book-100", "XBT/USD"]
[270, {"a": [["11859.00000", "0.00000000", "1596737211.275425"], ["11902.00000", "0.22739000", "1596736764.397858", "r"]], "c": "1257206690"}, "book-100", "XBT/USD"]
[270, {"a": [["11855.10000", "0.00000000", "1596737211.275830"], ["11902.20000", "1.58369712", "1596737116.990726", "r"]], "c": "3565295127"}, "book-100", "XBT/USD"]
[270, {"b": [["11847.70000", "0.00000000", "1596737211.382570"], ["11801.90000", "4.67249674", "1596736908.903243", "r"]], "c": "3565295127"}, "book-100", "XBT/USD"]
[270, {"a": [["11869.50000", "3.74284416", "1596737211.382715"]], "c": "3565295127"}, "book-100", "XBT/USD"]
[270, {"b": [["11850.50000", "0.00000000", "1596737211.384140"], ["11801.80000", "3.19470719", "1596736911.648608", "r"]], "c": "177184461"}, "book-100", "XBT/USD"]
[270, {"a": [["11859.10000", "0.00000000", "1596737211.384359"], ["11902.20000", "1.58369712", "1596737116.990726", "r"]], "c": "1015961408"}, "book-100", "XBT/USD"]
[270, {"a": [["11857.90000", "0.00000000", "1596737211.386232"], ["11903.50000", "2.17855852", "1596737179.380202", "r"]], "c": "762814546"}, "book-100", "XBT/USD"]
[270, {"a": [["11855.90000", "0.00000000", "1596737211.408298"], ["11904.00000", "0.17065000", "1596737071.292235", "r"]], "c": "1993155729"}, "book-100", "XBT/USD"]
[270, {"a": [["11858.60000", "0.00000000", "1596737211.409016"], ["11905.00000", "27.00000000", "1596736856.739074", "r"]], "c": "4200717018"}, "book-100", "XBT/USD"]
[270, {"b": [["11848.20000", "0.00000000", "1596737211.442537"], ["11800.80000", "1.51500000", "1596737133.991629", "r"]], "c": "38213590"}, "book-100", "XBT/USD"]
[270, {"a": [["11855.60000", "0.70000000", "1596737211.442745"]], "c": "2739914837"}, "book-100", "XBT/USD"]
[270, {"a": [["11879.90000", "0.59700598", "1596737211.458424"]], "c": "2739914837"}, "book-100", "XBT/USD"]
[270, {"b": [["11851.60000", "2.27370302", "1596737211.461006"]], "c": "401314598"}, "book-100", "XBT/USD"]
[270, {"a": [["11860.40000", "0.66298361", "1596737211.487107"]], "c": "2690934174"}, "book-100", "XBT/USD"]
[270, {"b": [["11834.00000", "4.86279994", "1596737211.507974"]], "c": "2690934174"}, "book-100", "XBT/USD"]
[270, {"a": [["11855.80000", "0.00000000", "1596737211.529433"], ["11904.00000", "0.17065000", "1596737071.292235", "r"]], "c": "897598791"}, "book-100", "XBT/USD"]
[270, {"b": [["11852.60000", "1.48358881", "1596737211.563294"]], "c": "3020127435"}, "book-100", "XBT/USD"]
[270, {"a": [["11852.70000", "0.99883282", "1596737211.563420"]], "c": "2630849463"}, "book-100", "XBT/USD"]
[270, {"a": [["11858.30000", "0.25000000", "1596737211.566104"]], "c": "4014434811"}, "book-100", "XBT/USD"]
[270, {"b": [["11851.00000", "0.00000000", "1596737211.575655"], ["11800.80000", "1.51500000", "1596737133.991629", "r"]], "c": "3684025694"}, "book-100", "XBT/USD"]
[270, {"a": [["11859.30000", "0.82180000", "1596737211.580013"]], "c": "3612046160"}, "book-100", "XBT/USD"]
[270, {"b": [["11838.70000", "0.25508740", "1596737211.584452"]], "c": "3612046160"}, "book-100", "XBT/USD"]
[270, {"a": [["11864.90000", "0.01800000", "1596737211.600615"]], "c": "3612046160"}, "book-100", "XBT/USD"]
[270, {"b": [["11848.10000", "0.57163776", "1596737211.600894"]], "c": "3098010740"}, "book-100", "XBT/USD"]
[270, {"a": [["11855.70000", "0.00000000", "1596737211.628331"], ["11902.20000", "1.58369712", "1596737116.990726", "r"]], "c": "2809347385"}, "book-100", "XBT/USD"]
[270, {"a": [["11852.70000", "0.40383282", "1596737211.629064"]], "c": "1154759389"}, "book-100", "XBT/USD"]
[270, {"a": [["11864.50000", "0.10100000", "1596737211.636779"]], "c": "1154759389"}, "book-100", "XBT/USD"]
[270, {"a": [["11890.60000", "0.00000000", "1596737211.643380"], ["11903.50000", "2.17855852", "1596737179.380202", "r"]], "c": "1154759389"}, "book-100", "XBT/USD"]
[270, {"b": [["11845.70000", "0.00000000", "1596737211.661544"], ["11800.00000", "17.03324285", "1596736993.942623", "r"]], "c": "1154759389"}, "book-100", "XBT/USD"]
[270, {"b": [["11842.30000", "0.00000000", "1596737211.666990"], ["11799.60000", "0.99110000", "1596737165.782615", "r"]], "c": "1154759389"}, "book-100", "XBT/USD"]
[270, {"a": [["11859.30000", "2.32180000", "1596737211.674197"]], "c": "887769262"}, "book-100", "XBT/USD"]
[270, {"b": [["11839.90000", "1.00772000", "1596737211.678984"]], "c": "887769262"}, "book-100", "XBT/USD"]
[270, {"b": [["11840.60000", "0.00000000", "1596737211.710226"], ["11799.20000", "23.14040000", "1596736141.974806", "r"]], "c": "887769262"}, "book-100", "XBT/USD"]
[270, {"b": [["11839.90000", "0.00000000", "1596737211.713056"], ["11798.60000", "18.30000000", "1596737089.559503", "r"]], "c": "887769262"}, "book-100", "XBT/USD"]
[270, {"b": [["11849.30000", "0.70296000", "1596737211.715287"]], "c": "64380764"}, "book-100", "XBT/USD"]
[270, {"b": [["11852.10000", "4.20700000", "1596737211.734049"]], "c": "1991498761"}, "book-100", "XBT/USD"]
[270, {"a": [["11860.40000", "4.87498361", "1596737211.742784"]], "c": "1994942817"}, "book-100", "XBT/USD"]
[270, {"a": [["11856.80000", "0.00000000", "1596737211.762650"], ["11904.00000", "0.17065000", "1596737071.292235", "r"]], "c": "835924483"}, "book-100", "XBT/USD"]
[270, {"b": [["11839.10000", "0.00000000", "1596737211.765552"], ["11799.20000", "23.14040000", "1596736141.974806", "r"]], "c": "835924483"}, "book-100", "XBT/USD"]
[270, {"a": [["11864.90000", "0.00000000", "1596737211.766386"], ["11905.00000", "27.00000000", "1596736856.739074", "r"]], "c": "835924483"}, "book-100", "XBT/USD"]
[270, {"a": [["11863.50000", "0.74660000", "1596737211.779702"]], "c": "835924483"}, "book-100", "XBT/USD"]
[270, {"b": [["11841.50000", "0.02300000", "1596737211.820361"]], "c": "835924483"}, "book-100", "XBT/USD"]
[270, {"a": [["11867.90000", "0.01800000", "1596737211.821221"]], "c": "835924483"}, "book-100", "XBT/USD"]
[270, {"a": [["11895.50000", "2.33909453", "1596737211.824681"]], "c": "835924483"}, "book-100", "XBT/USD"]
[270, {"a": [["11861.10000", "0.00000000", "1596737211.830230"], ["11903.50000", "2.17855852", "1596737179.380202", "r"]], "c": "835924483"}, "book-100", "XBT/USD"]
[270, {"b": [["11845.50000", "0.09621094", "1596737211.932124"]], "c": "835924483"}, "book-100", "XBT/USD"]
[270, {"b": [["11847.10000", "0.33015553", "1596737211.933558"]], "c": "835924483"}, "book-100", "XBT/USD"]
[270, {"b": [["11838.30000", "0.00000000", "1596737211.935649"], ["11800.00000", "17.03324285", "1596736993.942623", "r"]], "c": "835924483"}, "book-100", "XBT/USD"]
[270, {"b": [["11843.20000", "0.00000000", "1596737211.936476"], ["11799.60000", "0.99110000", "1596737165.782615", "r"]], "c": "835924483"}, "book-100", "XBT/USD"]
[270, {"b": [["11843.60000", "0.56263063", "1596737211.941172"]], "c": "835924483"}, "book-100", "XBT/USD"]
[270, {"b": [["11841.50000", "0.00000000", "1596737211.988231"], ["11799.20000", "23.14040000", "1596736141.974806", "r"]], "c": "835924483"}, "book-100", "XBT/USD"]
[270, {"b": [["11832.40000", "0.00000000", "1596737212.004090"], ["11798.60000", "18.30000000", "1596737089.559503", "r"]], "c": "835924483"}, "book-100", "XBT/USD"]
[270, {"a": [["11858.20000", "0.82180000", "1596737212.024706"]], "c": "474230419"}, "book-100", "XBT/USD"]
[270, {"a": [["11859.30000", "1.50000000", "1596737212.031006"]], "c": "3468562946"}, "book-100", "XBT/USD"]
[270, {"a": [["11858.20000", "0.86930000", "1596737212.055236"]], "c": "3244882080"}, "book-100", "XBT/USD"]
[270, {"b": [["11842.50000", "0.02300000", "1596737212.196130"]], "c": "3244882080"}, "book-100", "XBT/USD"]
[270, {"a": [["11864.40000", "0.00000000", "1596737212.199984"], ["11903.50000", "2.17855852", "1596737179.380202", "r"]], "c": "3244882080"}, "book-100", "XBT/USD"]
[270, {"a": [["11872.80000", "0.00000000", "1596737212.254917"], ["11904.00000", "0.17065000", "1596737071.292235", "r"]], "c": "3244882080"}, "book-100", "XBT/USD"]
[270, {"b": [["11841.60000", "1.38729728", "1596737212.340517"]], "c": "3244882080"}, "book-100", "XBT/USD"]
[270, {"b": [["11841.50000", "0.76570802", "1596737212.360288"]], "c": "3244882080"}, "book-100", "XBT/USD"]
[270, {"b": [["11835.60000", "1.28046425", "1596737212.360578"]], "c": "3244882080"}, "book-100", "XBT/USD"]
[270, {"b": [["11844.00000", "0.69350808", "1596737212.428302"]], "c": "3244882080"}, "book-100", "XBT/USD"]
[270, {"a": [["11853.40000", "0.03374559", "1596737212.456332"]], "c": "2698879401"}, "book-100", "XBT/USD"]
[270, {"a": [["11871.80000", "0.67070715", "1596737212.500272"]], "c": "2698879401"}, "book-100", "XBT/USD"]
[270, {"a": [["11889.00000", "0.00000000", "1596737212.569333"], ["11904.00000", "0.17065000", "1596737071.292235", "r"]], "c": "2698879401"}, "book-100", "XBT/USD"]
[270, {"a": [["11868.60000", "0.31540539", "1596737212.858632"]], "c": "2698879401"}, "book-100", "XBT/USD"]
[270, {"a": [["11864.60000", "0.00000000", "1596737213.131971"], ["11905.00000", "27.00000000", "1596736856.739074", "r"]], "c": "2698879401"}, "book-100", "XBT/USD"]
[270, {"b": [["11842.50000", "0.00000000", "1596737213.192709"], ["11800.80000", "1.51500000", "1596737133.991629", "r"]], "c": "2698879401"}, "book-100", "XBT/USD"]
[270, {"a": [["11888.20000", "0.00000000", "1596737213.214182"], ["11906.40000", "0.47990000", "1596737133.044226", "r"]], "c": "2698879401"}, "book-100", "XBT/USD"]
[270, {"a": [["11867.90000", "0.00000000", "1596737213.217154"], ["11907.00000", "0.17065000", "1596737135.727101", "r"]], "c": "2698879401"}, "book-100", "XBT/USD"]
[270, {"a": [["11867.00000", "0.69357953", "1596737213.229103"]], "c": "2698879401"}, "book-100", "XBT/USD"]
[270, {"b": [["11835.60000", "7.77841841", "1596737213.240080"]], "c": "2698879401"}, "book-100", "XBT/USD"]
[270, {"b": [["11841.70000", "0.02300000", "1596737213.243763"]], "c": "2698879401"}, "book-100", "XBT/USD"]
[270, {"a": [["11868.30000", "0.01800000", "1596737213.285820"]], "c": "2698879401"}, "book-100", "XBT/USD"]
[270, {"a": [["11855.60000", "0.00000000", "1596737213.312295"], ["11906.40000", "0.47990000", "1596737133.044226", "r"]], "c": "1768925982"}, "book-100", "XBT/USD"]
[270, {"a": [["11865.80000", "0.09250000", "1596737213.382035"]], "c": "1768925982"}, "book-100", "XBT/USD"]
[270, {"a": [["11858.30000", "0.00000000", "1596737213.433717"], ["11906.40000", "0.47990000", "1596737133.044226", "r"]], "c": "3242042021"}, "book-100", "XBT/USD"]
[270, {"a": [["11858.20000", "0.04750000", "1596737213.499418"]], "c": "3599825549"}, "book-100", "XBT/USD"]
[270, {"a": [["11857.50000", "0.25000000", "1596737213.625178"]], "c": "3580463806"}, "book-100", "XBT/USD"]
[270, {"a": [["11857.90000", "0.63232071", "1596737213.636160"]], "c": "2016793858"}, "book-100", "XBT/USD"]
[270, {"b": [["11852.60000", "1.79975789", "1596737213.636436"]], "c": "3113878699"}, "book-100", "XBT/USD"]
[270, {"a": [["11857.20000", "0.63236331", "1596737213.636555"]], "c": "2360468129"}, "book-100", "XBT/USD"]
[270, {"a": [["11871.40000", "0.84317777", "1596737213.636833"]], "c": "2360468129"}, "book-100", "XBT/USD"]
[270, {"b": [["11851.70000", "0.42155877", "1596737213.636977"]], "c": "827355828"}, "book-100", "XBT/USD"]
[270, {"a": [["11858.90000", "0.63238333", "1596737213.640633"]], "c": "178926205"}, "book-100", "XBT/USD"]
[270, {"a": [["11865.90000", "0.00000000", "1596737213.643179"], ["11902.20000", "1.58369712", "1596737116.990726", "r"]], "c": "178926205"}, "book-100", "XBT/USD"]
[270, {"a": [["11868.30000", "0.00000000", "1596737213.687121"], ["11903.50000", "2.17855852", "1596737179.380202", "r"]], "c": "178926205"}, "book-100", "XBT/USD"]
[270, {"a": [["11867.90000", "0.01800000", "1596737213.736104"]], "c": "178926205"}, "book-100", "XBT/USD"]
[270, {"a": [["11860.30000", "0.00000000", "1596737213.855130"], ["11903.50000", "2.17855852", "1596737179.380202", "r"]], "c": "178926205"}, "book-100", "XBT/USD"]
[270, {"a": [["11865.70000", "1.04962971", "1596737213.867820"]], "c": "178926205"}, "book-100", "XBT/USD"]
[270, {"b": [["11848.30000", "0.00000000", "1596737213.907591"], ["11801.80000", "3.19470719", "1596736911.648608", "r"]], "c": "3739163614"}, "book-100", "XBT/USD"]
[270, {"a": [["11857.50000", "0.00000000", "1596737213.908461"], ["11903.50000", "2.17855852", "1596737179.380202", "r"]], "c": "1085667257"}, "book-100", "XBT/USD"]
[270, {"a": [["11858.90000", "0.00000000", "1596737213.985311"], ["11904.00000", "0.17065000", "1596737071.292235", "r"]], "c": "2879095903"}, "book-100", "XBT/USD"]
[270, {"a": [["11867.90000", "0.00000000", "1596737214.004451"], ["11905.00000", "27.00000000", "1596736856.739074", "r"]], "c": "2879095903"}, "book-100", "XBT/USD"]
[270, {"b": [["11841.70000", "0.00000000", "1596737214.004880"], ["11800.80000", "1.51500000", "1596737133.991629", "r"]], "c": "2879095903"}, "book-100", "XBT/USD"]
[270, {"a": [["11866.00000", "3.80797800", "1596737214.048177"]], "c": "2879095903"}, "book-100", "XBT/USD"]
[270, {"a": [["11868.30000", "0.01800000", "1596737214.054657"]], "c": "2879095903"}, "book-100", "XBT/USD"]
[270, {"b": [["11841.10000", "0.02300000", "1596737214.054748"]], "c": "2879095903"}, "book-100", "XBT/USD"]
[270, {"a": [["11871.40000", "0.00000000", "1596737214.073874"], ["11904.00000", "0.17065000", "1596737071.292235", "r"]], "c": "2879095903"}, "book-100", "XBT/USD"]
[270, {"b": [["11852.60000", "1.48358881", "1596737214.074582"]], "c": "1781814774"}, "book-100", "XBT/USD"]
[270, {"a": [["11857.90000", "0.00000000", "1596737214.075758"], ["11905.00000", "27.00000000", "1596736856.739074", "r"]], "c": "2719754920"}, "book-100", "XBT/USD"]
[270, {"a": [["11855.70000", "0.25000000", "1596737214.100891"]], "c": "266502838"}, "book-100", "XBT/USD"]
[270, {"b": [["11851.70000", "0.00000000", "1596737214.114201"], ["11800.80000", "1.51500000", "1596737133.991629", "r"]], "c": "2800654969"}, "book-100", "XBT/USD"]
[270, {"a": [["11861.10000", "0.86938000", "1596737214.146493"]], "c": "2800654969"}, "book-100", "XBT/USD"]
[270, {"b": [["11848.20000", "2.41568843", "1596737214.165339"]], "c": "2882658216"}, "book-100", "XBT/USD"]
[270, {"b": [["11851.80000", "1.68400000", "1596737214.176477"]], "c": "4073191083"}, "book-100", "XBT/USD"]
[270, {"a": [["11895.50000", "0.00000000", "1596737214.181830"], ["11904.00000", "0.17065000", "1596737071.292235", "r"]], "c": "4073191083"}, "book-100", "XBT/USD"]
[270, {"a": [["11869.70000", "0.01195000", "1596737214.205919"]], "c": "4073191083"}, "book-100", "XBT/USD"]
[270, {"b": [["11851.90000", "0.00000000", "1596737214.206763"], ["11801.80000", "3.19470719", "1596736911.648608", "r"]], "c": "1243385846"}, "book-100", "XBT/USD"]
[270, {"a": [["11868.30000", "0.00000000", "1596737214.223220"], ["11905.00000", "27.00000000", "1596736856.739074", "r"]], "c": "1243385846"}, "book-100", "XBT/USD"]
[270, {"b": [["11841.10000", "0.00000000", "1596737214.224571"], ["11800.80000", "1.51500000", "1596737133.991629", "r"]], "c": "1243385846"}, "book-100", "XBT/USD"]
[270, {"b": [["11849.30000", "0.00000000", "1596737214.270595"], ["11800.00000", "17.03324285", "1596736993.942623", "r"]], "c": "4138610734"}, "book-100", "XBT/USD"]
[270, {"a": [["11866.90000", "0.01800000", "1596737214.272038"]], "c": "4138610734"}, "book-100", "XBT/USD"]
[270, {"a": [["11869.50000", "0.00000000", "1596737214.286700"], ["11905.00000", "27.00000000", "1596736856.739074", "r"]], "c": "4138610734"}, "book-100", "XBT/USD"]
[270, {"a": [["11859.20000", "0.82180000", "1596737214.322932"]], "c": "1159604489"}, "book-100", "XBT/USD"]
[270, {"a": [["11852.70000", "2.40383282", "1596737214.326914"]], "c": "4241005413"}, "book-100", "XBT/USD"]
[270, {"b": [["11851.60000", "0.00000000", "1596737214.339576"], ["11799.60000", "0.99110000", "1596737165.782615", "r"]], "c": "3488558556"}, "book-100", "XBT/USD"]
[270, {"a": [["11890.60000", "2.10639749", "1596737214.368572"]], "c": "3488558556"}, "book-100", "XBT/USD"]
[270, {"a": [["11857.10000", "0.82180000", "1596737214.373391"]], "c": "2486384245"}, "book-100", "XBT/USD"]
[270, {"b": [["11852.60000", "1.08358881", "1596737214.374473"]], "c": "3770181703"}, "book-100", "XBT/USD"]
[270, {"a": [["11874.60000", "0.28399999", "1596737214.383301"]], "c": "3770181703"}, "book-100", "XBT/USD"]
[270, {"a": [["11857.20000", "0.00000000", "1596737214.384345"], ["11902.20000", "1.58369712", "1596737116.990726", "r"]], "c": "4280147702"}, "book-100", "XBT/USD"]
[270, {"a": [["11860.20000", "2.52398356", "1596737214.390755"]], "c": "1879672519"}, "book-100", "XBT/USD"]
[270, {"b": [["11841.70000", "0.02300000", "1596737214.401790"]], "c": "1879672519"}, "book-100", "XBT/USD"]
[270, {"a": [["11859.20000", "0.00000000", "1596737214.423591"], ["11903.50000", "2.17855852", "1596737179.380202", "r"]], "c": "3549971134"}, "book-100", "XBT/USD"]
[270, {"a": [["11860.40000", "0.66298361", "1596737214.443262"]], "c": "4091609196"}, "book-100", "XBT/USD"]
[270, {"b": [["11851.80000", "0.00000000", "1596737214.443350"], ["11799.60000", "0.99110000", "1596737165.782615", "r"]], "c": "2785031568"}, "book-100", "XBT/USD"]
[270, {"a": [["11852.70000", "0.40383282", "1596737214.470463"]], "c": "285041130"}, "book-100", "XBT/USD"]
[270, {"a": [["11855.70000", "0.00000000", "1596737214.471996"], ["11904.00000", "0.17065000", "1596737071.292235", "r"]], "c": "1224053736"}, "book-100", "XBT/USD"]
[270, {"a": [["11857.40000", "0.96548000", "1596737214.530070"]], "c": "3094401916"}, "book-100", "XBT/USD"]
[270, {"a": [["11855.60000", "0.82180000", "1596737214.530685"]], "c": "1301292297"}, "book-100", "XBT/USD"]
[270, {"b": [["11852.10000", "0.00000000", "1596737214.531755"], ["11799.30000", "0.01265539", "1596737214.391760", "r"]], "c": "582417042"}, "book-100", "XBT/USD"]
[270, {"a": [["11857.10000", "0.00000000", "1596737214.532284"], ["11903.50000", "2.17855852", "1596737179.380202", "r"]], "c": "2297032369"}, "book-100", "XBT/USD"]
[270, {"b": [["11845.80000", "0.00000000", "1596737214.576468"], ["11799.20000", "23.14040000", "1596736141.974806", "r"]], "c": "1063017434"}, "book-100", "XBT/USD"]
[270, {"b": [["11845.50000", "0.00000000", "1596737214.595069"], ["11798.60000", "18.30000000", "1596737089.559503", "r"]], "c": "1063017434"}, "book-100", "XBT/USD"]
[270, {"a": [["11890.60000", "0.00000000", "1596737214.597064"], ["11904.00000", "0.17065000", "1596737071.292235", "r"]], "c": "1063017434"}, "book-100", "XBT/USD"]
[270, {"a": [["11856.70000", "0.25000000", "1596737214.666654"]], "c": "2915268100"}, "book-100", "XBT/USD"]
[270, {"a": [["11857.90000", "0.09900000", "1596737214.700765"]], "c": "1848368251"}, "book-100", "XBT/USD"]
[270, {"a": [["11888.80000", "4.52578952", "1596737214.779689"]], "c": "1848368251"}, "book-100", "XBT/USD"]
[270, {"a": [["11869.00000", "0.18315000", "1596737214.851872"]], "c": "1848368251"}, "book-100", "XBT/USD"]
[271, [["11852.70000", "0.06127211", "1596737214.866620", "b", "m", ""], ["11852.70000", "0.33268163", "1596737214.874182", "b", "m", ""], ["11852.70000", "0.00987908", "1596737214.876208", "b", "m", ""], ["11853.40000", "0.03374559", "1596737214.878654", "b", "m", ""], ["11855.60000", "0.82180000", "1596737214.880291", "b", "m", ""], ["11856.70000", "0.25000000", "1596737214.882165", "b", "m", ""], ["11857.40000", "0.96548000", "1596737214.883694", "b", "m", ""], ["11857.90000", "0.09900000", "1596737214.885458", "b", "m", ""], ["11858.20000", "0.04750000", "1596737214.887110", "b", "m", ""]], "trade", "XBT/USD"]
[270, {"a": [["11852.70000", "0.34256071", "1596737214.866620"], ["11852.70000", "0.00987908", "1596737214.874182"], ["11852.70000", "0.00000000", "1596737214.876208"], ["11903.50000", "2.17855852", "1596737179.380202", "r"], ["11853.40000", "0.00000000", "1596737214.878654"], ["11904.00000", "0.17065000", "1596737071.292235", "r"], ["11855.60000", "0.00000000", "1596737214.880291"], ["11905.00000", "27.00000000", "1596736856.739074", "r"], ["11856.70000", "0.00000000", "1596737214.882165"], ["11906.40000", "0.47990000", "1596737133.044226", "r"], ["11857.40000", "0.00000000", "1596737214.883694"], ["11907.00000", "0.17065000", "1596737135.727101", "r"], ["11857.90000", "0.00000000", "1596737214.885458"], ["11907.90000", "2.38150000", "1596737172.530893", "r"], ["11858.20000", "0.00000000", "1596737214.887110"], ["11909.90000", "6.20000000", "1596736825.518690", "r"]], "c": "1347186155"}, "book-100", "XBT/USD"]
[270, {"a": [["11890.60000", "2.11054047", "1596737214.893602"]], "c": "1347186155"}, "book-100", "XBT/USD"]
[270, {"a": [["11872.60000", "6.24281582", "1596737214.925765"]], "c": "1347186155"}, "book-100", "XBT/USD"]
[270, {"a": [["11857.40000", "0.40000000", "1596737214.937318"]], "c": "1710990088"}, "book-100", "XBT/USD"]
[270, {"b": [["11849.60000", "4.21200000", "1596737214.942462"]], "c": "1200506846"}, "book-100", "XBT/USD"]
[270, {"a": [["11866.90000", "0.00000000", "1596737214.944113"], ["11907.00000", "0.17065000", "1596737135.727101", "r"]], "c": "1200506846"}, "book-100", "XBT/USD"]
[270, {"b": [["11852.60000", "0.58358881", "1596737214.945876"]], "c": "4098201070"}, "book-100", "XBT/USD"]
[270, {"a": [["11854.40000", "0.42000000", "1596737214.959535"]], "c": "163970605"}, "book-100", "XBT/USD"]
[270, {"a": [["11857.80000", "0.50000000", "1596737214.963265"]], "c": "774132062"}, "book-100", "XBT/USD"]
[270, {"b": [["11848.40000", "0.09600000", "1596737214.966124"]], "c": "3140563509"}, "book-100", "XBT/USD"]
[270, {"b": [["11843.60000", "0.65884157", "1596737214.974992"]], "c": "3140563509"}, "book-100", "XBT/USD"]
[270, {"a": [["11857.00000", "0.42000000", "1596737214.975148"]], "c": "1665556773"}, "book-100", "XBT/USD"]
[270, {"a": [["11868.30000", "0.01800000", "1596737214.994133"]], "c": "1665556773"}, "book-100", "XBT/USD"]
[270, {"b": [["11841.70000", "0.00000000", "1596737215.022883"], ["11799.20000", "23.14040000", "1596736141.974806", "r"]], "c": "1665556773"}, "book-100", "XBT/USD"]
[270, {"b": [["11849.60000", "0.00000000", "1596737215.024038"], ["11798.60000", "18.30000000", "1596737089.559503", "r"]], "c": "2910381868"}, "book-100", "XBT/USD"]
[270, {"b": [["11852.60000", "0.48358881", "1596737215.078254"]], "c": "144936292"}, "book-100", "XBT/USD"]
[270, {"b": [["11841.60000", "1.41029728", "1596737215.078346"]], "c": "144936292"}, "book-100", "XBT/USD"]
[270, {"b": [["11850.50000", "0.25000000", "1596737215.082836"]], "c": "3926817040"}, "book-100", "XBT/USD"]
[270, {"a": [["11859.20000", "0.04750000", "1596737215.098025"]], "c": "3599525879"}, "book-100", "XBT/USD"]
[270, {"a": [["11876.70000", "1.00000000", "1596737215.111569"]], "c": "3599525879"}, "book-100", "XBT/USD"]
[270, {"b": [["11852.60000", "0.20000000", "1596737215.118827"]], "c": "3067665465"}, "book-100", "XBT/USD"]
[270, {"a": [["11857.40000", "0.00000000", "1596737215.124044"], ["11902.20000", "1.58369712", "1596737116.990726", "r"]], "c": "1568100628"}, "book-100", "XBT/USD"]
[270, {"a": [["11853.40000", "0.09621094", "1596737215.126126"]], "c": "1998059945"}, "book-100", "XBT/USD"]
[270, {"a": [["11857.60000", "4.20900000", "1596737215.132828"]], "c": "3845850271"}, "book-100", "XBT/USD"]
[270, {"b": [["11848.50000", "1.05063300", "1596737215.136980"]], "c": "2149404133"}, "book-100", "XBT/USD"]
[270, {"a": [["11854.40000", "0.82000000", "1596737215.172101"]], "c": "2217504706"}, "book-100", "XBT/USD"]
[270, {"a": [["11876.70000", "0.00000000", "1596737215.188111"], ["11902.00000", "0.22739000", "1596736764.397858", "r"]], "c": "2217504706"}, "book-100", "XBT/USD"]
[270, {"a": [["11857.00000", "0.00000000", "1596737215.194996"], ["11902.20000", "1.58369712", "1596737116.990726", "r"]], "c": "3674572662"}, "book-100", "XBT/USD"]
[270, {"a": [["11852.70000", "0.39395374", "1596737215.198291"]], "c": "3884684237"}, "book-100", "XBT/USD"]
[270, {"a": [["11868.30000", "0.00000000", "1596737215.262734"], ["11902.20000", "1.58369712", "1596737116.990726", "r"]], "c": "3884684237"}, "book-100", "XBT/USD"]
[270, {"a": [["11866.90000", "0.01800000", "1596737215.322820"]], "c": "3884684237"}, "book-100", "XBT/USD"]
[270, {"b": [["11850.50000", "0.00000000", "1596737215.338081"], ["11798.60000", "18.30000000", "1596737089.559503", "r"]], "c": "1994827630"}, "book-100", "XBT/USD"]
[270, {"b": [["11852.60000", "0.50351224", "1596737215.355037"]], "c": "1121094206"}, "book-100", "XBT/USD"]
[270, {"b": [["11852.60000", "0.70000000", "1596737215.367628"]], "c": "3652052861"}, "book-100", "XBT/USD"]
[270, {"b": [["11852.60000", "0.80000000", "1596737215.398998"]], "c": "4076937481"}, "book-100", "XBT/USD"]
[270, {"b": [["11852.60000", "1.08358881", "1596737215.458258"]], "c": "4065953483"}, "book-100", "XBT/USD"]
[270, {"a": [["11859.20000", "0.13610000", "1596737215.479018"]], "c": "983044951"}, "book-100", "XBT/USD"]
[270, {"a": [["11856.90000", "0.34000000", "1596737215.480720"]], "c": "1381500807"}, "book-100", "XBT/USD"]
[270, {"b": [["11849.20000", "0.25000000", "1596737215.531727"]], "c": "1102589905"}, "book-100", "XBT/USD"]
[270, {"a": [["11859.20000", "0.04750000", "1596737215.537342"]], "c": "502411419"}, "book-100", "XBT/USD"]
[270, {"b": [["11848.50000", "0.05063300", "1596737215.900280"]], "c": "931092218"}, "book-100", "XBT/USD"]
[270, {"a": [["11852.70000", "0.00000000", "1596737215.923800"], ["11902.00000", "0.22739000", "1596736764.397858", "r"]], "c": "3338508514"}, "book-100", "XBT/USD"]
[270, {"b": [["11852.60000", "0.78007657", "1596737215.978959"]], "c": "1804433497"}, "book-100", "XBT/USD"]
[270, {"b": [["11852.60000", "0.58358881", "1596737215.981830"]], "c": "2691372092"}, "book-100", "XBT/USD"]
[270, {"a": [["11853.30000", "0.00987909", "1596737215.993288"]], "c": "1050984253"}, "book-100", "XBT/USD"]
[270, {"b": [["11852.60000", "0.48358881", "1596737216.112377"]], "c": "2608846197"}, "book-100", "XBT/USD"]
[270, {"b": [["11837.20000", "0.42167057", "1596737216.199891"]], "c": "2608846197"}, "book-100", "XBT/USD"]
[270, {"b": [["11852.10000", "0.31623116", "1596737216.200690"]], "c": "442996790"}, "book-100", "XBT/USD"]
[270, {"a": [["11855.60000", "0.63250585", "1596737216.200901"]], "c": "3185994728"}, "book-100", "XBT/USD"]
[270, {"a": [["11856.80000", "0.63249407", "1596737216.201014"]], "c": "3355846850"}, "book-100", "XBT/USD"]
[270, {"a": [["11857.80000", "1.13246233", "1596737216.201133"]], "c": "1969921160"}, "book-100", "XBT/USD"]
[270, {"a": [["11858.20000", "0.84334114", "1596737216.202603"]], "c": "3762792060"}, "book-100", "XBT/USD"]
[270, {"a": [["11858.40000", "0.84338377", "1596737216.222412"]], "c": "928408236"}, "book-100", "XBT/USD"]
[270, {"a": [["11890.60000", "0.00000000", "1596737216.236840"], ["11901.20000", "0.05455260", "1596737145.299909", "r"]], "c": "928408236"}, "book-100", "XBT/USD"]
[270, {"a": [["11858.70000", "0.94030000", "1596737216.319462"]], "c": "928408236"}, "book-100", "XBT/USD"]
[270, {"b": [["11853.20000", "0.31623116", "1596737216.324444"]], "c": "3707113846"}, "book-100", "XBT/USD"]
[270, {"b": [["11853.20000", "0.41623116", "1596737216.335010"]], "c": "320080396"}, "book-100", "XBT/USD"]
[270, {"a": [["11857.50000", "0.70000000", "1596737216.370041"]], "c": "2002814174"}, "book-100", "XBT/USD"]
[270, {"a": [["11866.90000", "0.00000000", "1596737216.388449"], ["11901.00000", "0.17065000", "1596737120.047779", "r"]], "c": "2002814174"}, "book-100", "XBT/USD"]
[270, {"a": [["11856.90000", "0.00000000", "1596737216.419349"], ["11901.20000", "0.05455260", "1596737145.299909", "r"]], "c": "3206238303"}, "book-100", "XBT/USD"]
[270, {"a": [["11895.50000", "2.29062494", "1596737216.424084"]], "c": "3206238303"}, "book-100", "XBT/USD"]
[270, {"a": [["11857.50000", "0.78900000", "1596737216.434476"]], "c": "1539474779"}, "book-100", "XBT/USD"]
[270, {"a": [["11867.90000", "0.01800000", "1596737216.436887"]], "c": "1539474779"}, "book-100", "XBT/USD"]
[270, {"b": [["11852.00000", "2.00124798", "1596737216.437547"]], "c": "799749126"}, "book-100", "XBT/USD"]
[270, {"b": [["11849.20000", "0.00000000", "1596737216.441082"], ["11799.60000", "0.99110000", "1596737165.782615", "r"]], "c": "3408955567"}, "book-100", "XBT/USD"]
[270, {"b": [["11849.50000", "4.63354067", "1596737216.540122"]], "c": "3308945078"}, "book-100", "XBT/USD"]
[270, {"b": [["11849.60000", "0.10000000", "1596737216.616300"]], "c": "2301885742"}, "book-100", "XBT/USD"]
[270, {"b": [["11849.50000", "0.42154067", "1596737216.622421"]], "c": "2439259337"}, "book-100", "XBT/USD"]
[270, {"b": [["11849.80000", "0.25000000", "1596737216.671966"]], "c": "3810387193"}, "book-100", "XBT/USD"]
[270, {"b": [["11849.60000", "0.00000000", "1596737216.672448"], ["11800.00000", "17.03324285", "1596736993.942623", "r"]], "c": "2915304753"}, "book-100", "XBT/USD"]
[270, {"a": [["11875.00000", "0.00000000", "1596737216.694803"], ["11901.00000", "0.17065000", "1596737120.047779", "r"]], "c": "2915304753"}, "book-100", "XBT/USD"]
[270, {"b": [["11837.30000", "0.00000000", "1596737216.720259"], ["11799.60000", "0.99110000", "1596737165.782615", "r"]], "c": "2915304753"}, "book-100", "XBT/USD"]
[270, {"b": [["11847.10000", "0.00000000", "1596737216.732202"], ["11799.30000", "0.01265539", "1596737214.391760", "r"]], "c": "2915304753"}, "book-100", "XBT/USD"]
[270, {"a": [["11884.70000", "0.00000000", "1596737216.737439"], ["11901.20000", "0.05455260", "1596737145.299909", "r"]], "c": "2915304753"}, "book-100", "XBT/USD"]
[270, {"b": [["11852.60000", "0.20000000", "1596737216.778472"]], "c": "1862213569"}, "book-100", "XBT/USD"]
[270, {"a": [["11895.50000", "0.00000000", "1596737216.832005"], ["11901.40000", "1.90492467", "1596737138.167457", "r"]], "c": "1862213569"}, "book-100", "XBT/USD"]
[270, {"b": [["11835.00000", "0.00423076", "1596737216.936035"]], "c": "1862213569"}, "book-100", "XBT/USD"]
[270, {"b": [["11852.00000", "1.68500000", "1596737216.936452"]], "c": "4120568884"}, "book-100", "XBT/USD"]
[270, {"a": [["11879.80000", "0.00438186", "1596737216.939034"]], "c": "4120568884"}, "book-100", "XBT/USD"]
[270, {"b": [["11839.00000", "0.53068646", "1596737217.056505"]], "c": "4120568884"}, "book-100", "XBT/USD"]
[270, {"b": [["11853.20000", "0.69980562", "1596737217.097272"]], "c": "1013916034"}, "book-100", "XBT/USD"]
[270, {"b": [["11821.00000", "0.00000000", "1596737217.249261"], ["11799.60000", "0.99110000", "1596737165.782615", "r"]], "c": "1013916034"}, "book-100", "XBT/USD"]
[270, {"b": [["11821.10000", "0.73644172", "1596737217.252195"]], "c": "1013916034"}, "book-100", "XBT/USD"]
[270, {"b": [["11803.20000", "0.00000000", "1596737217.252276"], ["11799.60000", "0.99110000", "1596737165.782615", "r"]], "c": "1013916034"}, "book-100", "XBT/USD"]
[270, {"a": [["11900.10000", "0.00000000", "1596737217.252405"], ["11901.40000", "1.90492467", "1596737138.167457", "r"]], "c": "1013916034"}, "book-100", "XBT/USD"]
[270, {"b": [["11803.30000", "3.16036168", "1596737217.254562"]], "c": "1013916034"}, "book-100", "XBT/USD"]
[270, {"a": [["11900.30000", "2.21032576", "1596737217.256382"]], "c": "1013916034"}, "book-100", "XBT/USD"]
[270, {"a": [["11882.50000", "0.73644172", "1596737217.271106"]], "c": "1013916034"}, "book-100", "XBT/USD"]
[270, {"b": [["11847.00000", "1.18003000", "1596737217.297717"]], "c": "1013916034"}, "book-100", "XBT/USD"]
[270, {"b": [["11835.00000", "0.00000000", "1596737217.310242"], ["11799.20000", "23.14040000", "1596736141.974806", "r"]], "c": "1013916034"}, "book-100", "XBT/USD"]
[270, {"b": [["11849.50000", "4.62654067", "1596737217.367281"]], "c": "3850590182"}, "book-100", "XBT/USD"]
[270, {"a": [["11882.40000", "0.00000000", "1596737217.382566"], ["11901.20000", "0.05455260", "1596737145.299909", "r"]], "c": "3850590182"}, "book-100", "XBT/USD"]
[270, {"a": [["11876.20000", "0.33214193", "1596737217.382726"]], "c": "3850590182"}, "book-100", "XBT/USD"]
[270, {"b": [["11847.20000", "0.33295496", "1596737217.383038"]], "c": "3850590182"}, "book-100", "XBT/USD"]
[270, {"a": [["11888.10000", "0.50000000", "1596737217.906371"]], "c": "3850590182"}, "book-100", "XBT/USD"]
[270, {"a": [["11855.60000", "0.00000000", "1596737217.928523"], ["11901.00000", "0.17065000", "1596737120.047779", "r"]], "c": "4104105725"}, "book-100", "XBT/USD"]
[270, {"b": [["11845.60000", "0.10100000", "1596737218.035629"]], "c": "4104105725"}, "book-100", "XBT/USD"]
[270, {"b": [["11844.10000", "0.04248978", "1596737218.038318"]], "c": "4104105725"}, "book-100", "XBT/USD"]
[270, {"b": [["11852.00000", "0.00000000", "1596737218.089427"], ["11799.60000", "0.99110000", "1596737165.782615", "r"]], "c": "915817237"}, "book-100", "XBT/USD"]
[270, {"b": [["11852.70000", "1.68100000", "1596737218.094818"]], "c": "2940939330"}, "book-100", "XBT/USD"]
[270, {"a": [["11860.20000", "0.84298356", "1596737218.108361"]], "c": "2940939330"}, "book-100", "XBT/USD"]
[270, {"a": [["11861.10000", "2.55238000", "1596737218.122992"]], "c": "2940939330"}, "book-100", "XBT/USD"]
[270, {"b": [["11844.10000", "0.00000000", "1596737218.163131"], ["11799.60000", "0.99110000", "1596737165.782615", "r"]], "c": "2940939330"}, "book-100", "XBT/USD"]
[270, {"b": [["11844.10000", "0.02141529", "1596737218.163422"]], "c": "2940939330"}, "book-100", "XBT/USD"]
[270, {"a": [["11858.20000", "0.00000000", "1596737218.203967"], ["11901.20000", "0.05455260", "1596737145.299909", "r"]], "c": "3645805082"}, "book-100", "XBT/USD"]
[270, {"a": [["11859.30000", "0.00000000", "1596737218.309389"], ["11901.40000", "1.90492467", "1596737138.167457", "r"]], "c": "3645805082"}, "book-100", "XBT/USD"]
[270, {"b": [["11852.80000", "0.10000000", "1596737218.361363"]], "c": "4037363043"}, "book-100", "XBT/USD"]
[270, {"b": [["11852.80000", "0.00000000", "1596737218.425448"], ["11800.00000", "17.03324285", "1596736993.942623", "r"]], "c": "3645805082"}, "book-100", "XBT/USD"]
[270, {"a": [["11857.30000", "1.50000000", "1596737218.453974"]], "c": "3410856957"}, "book-100", "XBT/USD"]
[270, {"a": [["11854.40000", "0.40000000", "1596737218.663309"]], "c": "1103300781"}, "book-100", "XBT/USD"]
[270, {"a": [["11857.80000", "0.63246233", "1596737218.664918"]], "c": "3405232510"}, "book-100", "XBT/USD"]
[270, {"b": [["11853.20000", "1.19980562", "1596737219.038863"]], "c": "2417362328"}, "book-100", "XBT/USD"]
[270, {"b": [["11840.30000", "0.00000000", "1596737219.066575"], ["11799.60000", "0.99110000", "1596737165.782615", "r"]], "c": "2417362328"}, "book-100", "XBT/USD"]
[270, {"b": [["11844.10000", "0.03466678", "1596737219.096881"]], "c": "2417362328"}, "book-100", "XBT/USD"]
[270, {"b": [["11844.10000", "0.01325149", "1596737219.098334"]], "c": "2417362328"}, "book-100", "XBT/USD"]
[270, {"b": [["11823.00000", "0.23800000", "1596737219.121853"]], "c": "2417362328"}, "book-100", "XBT/USD"]
[270, {"a": [["11872.60000", "0.00000000", "1596737219.257129"], ["11901.40000", "1.90492467", "1596737138.167457", "r"]], "c": "2417362328"}, "book-100", "XBT/USD"]
[270, {"a": [["11868.90000", "6.24286842", "1596737219.345675"]], "c": "2417362328"}, "book-100", "XBT/USD"]
[270, {"a": [["11858.40000", "0.00000000", "1596737219.616190"], ["11901.40000", "1.90492467", "1596737138.167457", "r"]], "c": "3213789302"}, "book-100", "XBT/USD"]
[270, {"b": [["11841.60000", "1.38729728", "1596737219.670557"]], "c": "3213789302"}, "book-100", "XBT/USD"]
[270, {"a": [["11858.70000", "1.57270884", "1596737219.670755"]], "c": "128292575"}, "book-100", "XBT/USD"]
[270, {"b": [["11853.10000", "0.31621513", "1596737219.671746"]], "c": "1373703229"}, "book-100", "XBT/USD"]
[270, {"a": [["11871.00000", "0.84321178", "1596737219.672107"]], "c": "1373703229"}, "book-100", "XBT/USD"]
[270, {"a": [["11871.40000", "0.84316930", "1596737219.673891"]], "c": "1373703229"}, "book-100", "XBT/USD"]
[270, {"b": [["11842.50000", "0.02300000", "1596737219.718822"]], "c": "1373703229"}, "book-100", "XBT/USD"]
[270, {"b": [["11838.10000", "0.10124713", "1596737220.149538"]], "c": "1373703229"}, "book-100", "XBT/USD"]
[270, {"a": [["11890.60000", "2.11468824", "1596737220.350912"]], "c": "1373703229"}, "book-100", "XBT/USD"]
[270, {"a": [["11861.10000", "0.86938000", "1596737220.455119"]], "c": "1373703229"}, "book-100", "XBT/USD"]
[270, {"a": [["11857.50000", "0.08900000", "1596737220.507721"]], "c": "1765745311"}, "book-100", "XBT/USD"]
[270, {"a": [["11890.60000", "0.00000000", "1596737220.550142"], ["11901.00000", "0.17065000", "1596737120.047779", "r"]], "c": "1765745311"}, "book-100", "XBT/USD"]
[270, {"b": [["11847.20000", "0.00000000", "1596737220.639917"], ["11800.80000", "1.51500000", "1596737133.991629", "r"]], "c": "1765745311"}, "book-100", "XBT/USD"]
[270, {"a": [["11876.20000", "0.00000000", "1596737220.643790"], ["11901.20000", "0.05455260", "1596737145.299909", "r"]], "c": "1765745311"}, "book-100", "XBT/USD"]
[270, {"a": [["11874.90000", "0.33217829", "1596737220.881470"]], "c": "1765745311"}, "book-100", "XBT/USD"]
[270, {"b": [["11845.90000", "0.33299150", "1596737220.888604"]], "c": "1765745311"}, "book-100", "XBT/USD"]
[270, {"b": [["11838.10000", "0.09700000", "1596737220.958082"]], "c": "1765745311"}, "book-100", "XBT/USD"]
[270, {"a": [["11853.40000", "0.00000000", "1596737221.078646"], ["11901.20000", "0.05455260", "1596737145.299909", "r"]], "c": "2726185724"}, "book-100", "XBT/USD"]
[270, {"a": [["11855.20000", "0.09621094", "1596737221.085834"]], "c": "1264588056"}, "book-100", "XBT/USD"]
[270, {"b": [["11843.60000", "0.56263063", "1596737221.098004"]], "c": "1264588056"}, "book-100", "XBT/USD"]
[270, {"b": [["11846.40000", "0.51788538", "1596737221.104817"]], "c": "1264588056"}, "book-100", "XBT/USD"]
[270, {"b": [["11845.90000", "0.00000000", "1596737221.113305"], ["11800.80000", "1.51500000", "1596737133.991629", "r"]], "c": "1264588056"}, "book-100", "XBT/USD"]
[270, {"a": [["11853.30000", "0.00000000", "1596737221.158012"], ["11901.20000", "0.05455260", "1596737145.299909", "r"]], "c": "1409132305"}, "book-100", "XBT/USD"]
[270, {"a": [["11854.30000", "0.00493954", "1596737221.228761"]], "c": "1912015397"}, "book-100", "XBT/USD"]
[270, {"a": [["11889.20000", "0.94225639", "1596737221.233054"]], "c": "1912015397"}, "book-100", "XBT/USD"]
[270, {"a": [["11856.70000", "0.57500000", "1596737221.296797"]], "c": "964237902"}, "book-100", "XBT/USD"]
[270, {"a": [["11879.10000", "0.68090000", "1596737221.297658"]], "c": "964237902"}, "book-100", "XBT/USD"]
[270, {"b": [["11853.20000", "0.69980562", "1596737221.353395"]], "c": "3093063493"}, "book-100", "XBT/USD"]
[270, {"a": [["11891.00000", "2.38150000", "1596737221.360796"]], "c": "3093063493"}, "book-100", "XBT/USD"]
[270, {"b": [["11853.20000", "0.59980562", "1596737221.451979"]], "c": "3714406580"}, "book-100", "XBT/USD"]
[270, {"b": [["11847.30000", "0.33295215", "1596737221.497046"]], "c": "3714406580"}, "book-100", "XBT/USD"]
[270, {"a": [["11858.70000", "0.94030000", "1596737221.517458"]], "c": "3969750946"}, "book-100", "XBT/USD"]
[270, {"b": [["11852.70000", "0.00000000", "1596737221.518927"], ["11800.80000", "1.51500000", "1596737133.991629", "r"]], "c": "3022242376"}, "book-100", "XBT/USD"]
[270, {"a": [["11871.40000", "0.00000000", "1596737221.557064"], ["11900.00000", "12.71653131", "1596737075.897027", "r"]], "c": "3022242376"}, "book-100", "XBT/USD"]
[270, {"b": [["11853.80000", "0.10000000", "1596737221.630537"]], "c": "3974282520"}, "book-100", "XBT/USD"]
[270, {"b": [["11837.10000", "0.00000000", "1596737221.813437"], ["11800.80000", "1.51500000", "1596737133.991629", "r"]], "c": "3974282520"}, "book-100", "XBT/USD"]
[270, {"b": [["11830.00000", "7.10000000", "1596737221.823068"]], "c": "3974282520"}, "book-100", "XBT/USD"]
[270, {"b": [["11840.50000", "0.00000000", "1596737221.828865"], ["11800.00000", "17.03324285", "1596736993.942623", "r"]], "c": "3974282520"}, "book-100", "XBT/USD"]
[270, {"a": [["11874.90000", "0.00000000", "1596737221.830515"], ["11900.30000", "2.21032576", "1596737217.256382", "r"]], "c": "3974282520"}, "book-100", "XBT/USD"]
[270, {"b": [["11844.00000", "0.00000000", "1596737221.831419"], ["11799.60000", "0.99110000", "1596737165.782615", "r"]], "c": "3974282520"}, "book-100", "XBT/USD"]
[270, {"b": [["11839.60000", "0.04704703", "1596737221.842266"]], "c": "3974282520"}, "book-100", "XBT/USD"]
[270, {"b": [["11847.30000", "0.00000000", "1596737221.852034"], ["11799.20000", "23.14040000", "1596736141.974806", "r"]], "c": "3974282520"}, "book-100", "XBT/USD"]
[270, {"b": [["11853.20000", "0.31623116", "1596737221.867869"]], "c": "560145015"}, "book-100", "XBT/USD"]
[270, {"b": [["11843.90000", "0.01325149", "1596737221.959903"]], "c": "560145015"}, "book-100", "XBT/USD"]
[270, {"b": [["11844.10000", "0.00000000", "1596737221.964411"], ["11799.20000", "23.14040000", "1596736141.974806", "r"]], "c": "560145015"}, "book-100", "XBT/USD"]
[270, {"b": [["11837.60000", "0.94652153", "1596737222.085701"]], "c": "560145015"}, "book-100", "XBT/USD"]
[270, {"b": [["11841.10000", "0.94624175", "1596737222.085777"]], "c": "560145015"}, "book-100", "XBT/USD"]
[270, {"b": [["11834.00000", "3.11103861", "1596737222.113305"]], "c": "560145015"}, "book-100", "XBT/USD"]
[270, {"b": [["11841.60000", "0.00000000", "1596737222.113381"], ["11799.60000", "0.99110000", "1596737165.782615", "r"]], "c": "560145015"}, "book-100", "XBT/USD"]
[270, {"a": [["11878.10000", "0.00000000", "1596737222.115959"], ["11901.00000", "0.17065000", "1596737120.047779", "r"]], "c": "560145015"}, "book-100", "XBT/USD"]
[270, {"b": [["11833.10000", "0.47134577", "1596737222.162174"]], "c": "560145015"}, "book-100", "XBT/USD"]
[270, {"b": [["11853.90000", "0.28355771", "1596737222.204115"]], "c": "222439126"}, "book-100", "XBT/USD"]
[270, {"b": [["11843.80000", "1.12093507", "1596737222.386513"]], "c": "222439126"}, "book-100", "XBT/USD"]
[270, {"a": [["11854.20000", "2.00000000", "1596737222.396299"]], "c": "3369044287"}, "book-100", "XBT/USD"]
[270, {"b": [["11842.50000", "0.00000000", "1596737222.445168"], ["11800.00000", "17.03324285", "1596736993.942623", "r"]], "c": "3369044287"}, "book-100", "XBT/USD"]
[270, {"a": [["11854.10000", "0.00493955", "1596737222.468901"]], "c": "3729740068"}, "book-100", "XBT/USD"]
[270, {"b": [["11849.50000", "0.42154067", "1596737222.476091"]], "c": "280284178"}, "book-100", "XBT/USD"]
[270, {"b": [["11841.60000", "0.02300000", "1596737222.493873"]], "c": "280284178"}, "book-100", "XBT/USD"]
[270, {"b": [["11853.80000", "0.00000000", "1596737222.497032"], ["11800.00000", "17.03324285", "1596736993.942623", "r"]], "c": "2524294931"}, "book-100", "XBT/USD"]
[270, {"a": [["11854.10000", "0.37993955", "1596737222.500279"]], "c": "692427902"}, "book-100", "XBT/USD"]
[270, {"a": [["11854.00000", "0.50000000", "1596737222.510323"]], "c": "606736888"}, "book-100", "XBT/USD"]
[270, {"b": [["11843.90000", "0.02037944", "1596737222.517089"]], "c": "606736888"}, "book-100", "XBT/USD"]
[270, {"a": [["11880.70000", "0.69738619", "1596737222.595074"]], "c": "606736888"}, "book-100", "XBT/USD"]
[270, {"b": [["11835.50000", "1.76679164", "1596737222.604704"]], "c": "606736888"}, "book-100", "XBT/USD"]
[270, {"b": [["11841.40000", "1.82093037", "1596737222.608050"]], "c": "606736888"}, "book-100", "XBT/USD"]
[270, {"b": [["11853.90000", "0.38355771", "1596737222.735960"]], "c": "2180086704"}, "book-100", "XBT/USD"]
[270, {"b": [["11843.90000", "0.00712795", "1596737222.758759"]], "c": "2180086704"}, "book-100", "XBT/USD"]
[270, {"a": [["11857.80000", "0.00000000", "1596737222.763631"], ["11899.90000", "7.61000000", "1596737079.466913", "r"]], "c": "2180086704"}, "book-100", "XBT/USD"]
[270, {"b": [["11843.80000", "0.42152894", "1596737222.774053"]], "c": "2180086704"}, "book-100", "XBT/USD"]
[270, {"b": [["11841.30000", "0.20479103", "1596737222.776227"]], "c": "2180086704"}, "book-100", "XBT/USD"]
[270, {"b": [["11847.20000", "0.33295496", "1596737222.776800"]], "c": "2180086704"}, "book-100", "XBT/USD"]
[270, {"a": [["11877.20000", "0.33211396", "1596737222.781818"]], "c": "2180086704"}, "book-100", "XBT/USD"]
[270, {"a": [["11880.70000", "0.00000000", "1596737222.781977"], ["11899.90000", "7.61000000", "1596737079.466913", "r"]], "c": "2180086704"}, "book-100", "XBT/USD"]
[270, {"a": [["11856.70000", "0.00000000", "1596737222.783866"], ["11900.00000", "12.71653131", "1596737075.897027", "r"]], "c": "926375703"}, "book-100", "XBT/USD"]
[270, {"a": [["11854.30000", "0.00000000", "1596737222.789299"], ["11900.30000", "2.21032576", "1596737217.256382", "r"]], "c": "1520925150"}, "book-100", "XBT/USD"]
[270, {"a": [["11854.00000", "2.50000000", "1596737222.825959"]], "c": "652015849"}, "book-100", "XBT/USD"]
[270, {"a": [["11855.10000", "0.63245988", "1596737222.828660"]], "c": "82974152"}, "book-100", "XBT/USD"]
[270, {"a": [["11855.70000", "0.63244699", "1596737222.832304"]], "c": "265750292"}, "book-100", "XBT/USD"]
[270, {"a": [["11859.00000", "0.84326266", "1596737222.836663"]], "c": "265750292"}, "book-100", "XBT/USD"]
[270, {"a": [["11867.90000", "0.00000000", "1596737222.889357"], ["11899.90000", "7.61000000", "1596737079.466913", "r"]], "c": "265750292"}, "book-100", "XBT/USD"]
[270, {"b": [["11848.20000", "6.63068843", "1596737222.891135"]], "c": "3612135935"}, "book-100", "XBT/USD"]
[270, {"a": [["11854.00000", "2.50493954", "1596737222.904206"]], "c": "1158440850"}, "book-100", "XBT/USD"]
[270, {"b": [["11847.20000", "0.00000000", "1596737222.957004"], ["11801.80000", "3.19470719", "1596736911.648608", "r"]], "c": "1158440850"}, "book-100", "XBT/USD"]
[270, {"a": [["11877.20000", "0.00000000", "1596737222.996530"], ["11900.00000", "12.71653131", "1596737075.897027", "r"]], "c": "1158440850"}, "book-100", "XBT/USD"]
[270, {"b": [["11847.00000", "0.46600000", "1596737223.023467"]], "c": "1158440850"}, "book-100", "XBT/USD"]
[270, {"a": [["11863.50000", "0.00000000", "1596737223.033110"], ["11900.30000", "2.21032576", "1596737217.256382", "r"]], "c": "1158440850"}, "book-100", "XBT/USD"]
[270, {"a": [["11856.30000", "0.95341000", "1596737223.033511"]], "c": "1309907937"}, "book-100", "XBT/USD"]
[270, {"b": [["11841.70000", "0.69968299", "1596737223.034966"]], "c": "1309907937"}, "book-100", "XBT/USD"]
[270, {"a": [["11878.60000", "0.69750948", "1596737223.038927"]], "c": "1309907937"}, "book-100", "XBT/USD"]
[270, {"a": [["11866.90000", "0.01800000", "1596737223.065647"]], "c": "1309907937"}, "book-100", "XBT/USD"]
[270, {"a": [["11854.40000", "0.00000000", "1596737223.172070"], ["11899.90000", "7.61000000", "1596737079.466913", "r"]], "c": "2336074777"}, "book-100", "XBT/USD"]
[270, {"b": [["11841.60000", "0.00000000", "1596737223.227247"], ["11801.80000", "3.19470719", "1596736911.648608", "r"]], "c": "2336074777"}, "book-100", "XBT/USD"]
[270, {"b": [["11841.80000", "0.02300000", "1596737223.276662"]], "c": "2336074777"}, "book-100", "XBT/USD"]
[270, {"b": [["11853.90000", "0.10000000", "1596737223.278280"]], "c": "1747686740"}, "book-100", "XBT/USD"]
[270, {"b": [["11847.20000", "0.33302770", "1596737223.379121"]], "c": "1747686740"}, "book-100", "XBT/USD"]
[270, {"a": [["11875.10000", "0.33224526", "1596737223.386712"]], "c": "1747686740"}, "book-100", "XBT/USD"]
[270, {"b": [["11821.10000", "0.00000000", "1596737223.439727"], ["11801.90000", "4.67249674", "1596736908.903243", "r"]], "c": "1747686740"}, "book-100", "XBT/USD"]
[270, {"b": [["11841.70000", "0.00000000", "1596737223.440310"], ["11801.80000", "3.19470719", "1596736911.648608", "r"]], "c": "1747686740"}, "book-100", "XBT/USD"]
[270, {"a": [["11882.50000", "0.00000000", "1596737223.450697"], ["11899.90000", "7.61000000", "1596737079.466913", "r"]], "c": "1747686740"}, "book-100", "XBT/USD"]
[270, {"a": [["11854.00000", "3.20493954", "1596737223.454563"]], "c": "1855932618"}, "book-100", "XBT/USD"]
[270, {"a": [["11856.80000", "0.00000000", "1596737223.495957"], ["11900.00000", "12.71653131", "1596737075.897027", "r"]], "c": "521251069"}, "book-100", "XBT/USD"]
[270, {"b": [["11853.20000", "0.00000000", "1596737223.496275"], ["11800.80000", "1.51500000", "1596737133.991629", "r"]], "c": "3108082341"}, "book-100", "XBT/USD"]
[270, {"b": [["11841.80000", "0.00000000", "1596737223.509295"], ["11800.00000", "17.03324285", "1596736993.942623", "r"]], "c": "3108082341"}, "book-100", "XBT/USD"]
[270, {"b": [["11823.20000", "0.34593419", "1596737223.536889"]], "c": "3108082341"}, "book-100", "XBT/USD"]
[270, {"a": [["11882.40000", "0.73645841", "1596737223.565948"]], "c": "3108082341"}, "book-100", "XBT/USD"]
[270, {"a": [["11854.10000", "0.37500000", "1596737223.577225"]], "c": "1794217241"}, "book-100", "XBT/USD"]
[270, {"b": [["11841.60000", "0.02300000", "1596737223.587906"]], "c": "1794217241"}, "book-100", "XBT/USD"]
[270, {"b": [["11821.00000", "0.73645841", "1596737223.594927"]], "c": "1794217241"}, "book-100", "XBT/USD"]
[270, {"a": [["11868.90000", "0.00000000", "1596737223.762448"], ["11900.00000", "12.71653131", "1596737075.897027", "r"]], "c": "1794217241"}, "book-100", "XBT/USD"]
[270, {"a": [["11872.50000", "6.24281582", "1596737223.846244"]], "c": "1794217241"}, "book-100", "XBT/USD"]
[270, {"b": [["11851.40000", "1.67700000", "1596737223.852002"]], "c": "765472785"}, "book-100", "XBT/USD"]
[270, {"a": [["11859.80000", "1.67400000", "1596737223.862075"]], "c": "765472785"}, "book-100", "XBT/USD"]
[270, {"b": [["11849.40000", "0.04401441", "1596737223.865524"]], "c": "2200516101"}, "book-100", "XBT/USD"]
[270, {"b": [["11843.80000", "1.12108787", "1596737223.901936"]], "c": "2200516101"}, "book-100", "XBT/USD"]
[270, {"b": [["11841.60000", "0.00000000", "1596737223.918425"], ["11802.00000", "7.50000000", "1596737194.335118", "r"]], "c": "2200516101"}, "book-100", "XBT/USD"]
[270, {"a": [["11890.60000", "2.12936548", "1596737223.919983"]], "c": "2200516101"}, "book-100", "XBT/USD"]
[270, {"b": [["11841.50000", "0.78870802", "1596737223.969216"]], "c": "2200516101"}, "book-100", "XBT/USD"]
[270, {"b": [["11841.60000", "0.02141871", "1596737224.064890"]], "c": "2200516101"}, "book-100", "XBT/USD"]
[270, {"b": [["11843.90000", "0.00000000", "1596737224.065104"], ["11802.00000", "7.50000000", "1596737194.335118", "r"]], "c": "2200516101"}, "book-100", "XBT/USD"]
[270, {"b": [["11841.50000", "0.76570802", "1596737224.118181"]], "c": "2200516101"}, "book-100", "XBT/USD"]
[270, {"a": [["11865.40000", "0.04401584", "1596737224.130425"]], "c": "2200516101"}, "book-100", "XBT/USD"]
[270, {"b": [["11841.10000", "0.96924175", "1596737224.168771"]], "c": "2200516101"}, "book-100", "XBT/USD"]
[270, {"a": [["11879.90000", "0.01000000", "1596737224.326792"]], "c": "2200516101"}, "book-100", "XBT/USD"]
[270, {"a": [["11879.80000", "0.00000000", "1596737224.349157"], ["11899.00000", "2.81849664", "1596737063.692951", "r"]], "c": "2200516101"}, "book-100", "XBT/USD"]
[270, {"b": [["11849.60000", "0.13204324", "1596737224.397553"]], "c": "3642252238"}, "book-100", "XBT/USD"]
[270, {"a": [["11865.70000", "0.00000000", "1596737224.516630"], ["11899.10000", "7.82927162", "1596737145.805987", "r"]], "c": "3642252238"}, "book-100", "XBT/USD"]
[270, {"a": [["11878.50000", "0.45761017", "1596737224.533979"]], "c": "3642252238"}, "book-100", "XBT/USD"]
[270, {"b": [["11841.60000", "0.03467232", "1596737224.612151"]], "c": "3642252238"}, "book-100", "XBT/USD"]
[270, {"b": [["11841.60000", "0.01325361", "1596737224.612395"]], "c": "3642252238"}, "book-100", "XBT/USD"]
[270, {"a": [["11865.90000", "0.13204461", "1596737224.652293"]], "c": "3642252238"}, "book-100", "XBT/USD"]
[270, {"a": [["11863.10000", "1.04962971", "1596737224.744564"]], "c": "3642252238"}, "book-100", "XBT/USD"]
[270, {"b": [["11851.50000", "0.01466462", "1596737224.812052"]], "c": "1279373932"}, "book-100", "XBT/USD"]
[270, {"a": [["11863.40000", "0.01466462", "1596737224.813406"]], "c": "1279373932"}, "book-100", "XBT/USD"]
[270, {"b": [["11841.60000", "0.00000000", "1596737224.864148"], ["11802.10000", "4.23653417", "1596737132.953878", "r"]], "c": "1279373932"}, "book-100", "XBT/USD"]
[270, {"a": [["11864.00000", "0.07332312", "1596737224.882318"]], "c": "1279373932"}, "book-100", "XBT/USD"]
[270, {"b": [["11841.60000", "0.02141871", "1596737224.896298"]], "c": "1279373932"}, "book-100", "XBT/USD"]
[270, {"b": [["11850.90000", "0.07332312", "1596737224.898403"]], "c": "3495329632"}, "book-100", "XBT/USD"]
[270, {"b": [["11849.20000", "0.17597549", "1596737224.940424"]], "c": "3495329632"}, "book-100", "XBT/USD"]
[270, {"a": [["11864.30000", "0.17597549", "1596737224.940538"]], "c": "3495329632"}, "book-100", "XBT/USD"]
[270, {"a": [["11854.50000", "0.63249163", "1596737225.206181"]], "c": "2143615754"}, "book-100", "XBT/USD"]
[270, {"b": [["11850.60000", "0.25299665", "1596737225.207406"]], "c": "2283113300"}, "book-100", "XBT/USD"]
[270, {"a": [["11855.90000", "0.17787000", "1596737225.731316"]], "c": "1983279713"}, "book-100", "XBT/USD"]
[270, {"b": [["11823.00000", "0.00000000", "1596737225.877354"], ["11804.80000", "3.28996656", "1596736677.195153", "r"]], "c": "1983279713"}, "book-100", "XBT/USD"]
[270, {"b": [["11845.10000", "0.23800000", "1596737225.924134"]], "c": "1983279713"}, "book-100", "XBT/USD"]
[270, {"a": [["11854.10000", "0.00000000", "1596737225.929618"], ["11897.00000", "0.02000000", "1596736823.323873", "r"]], "c": "2977512121"}, "book-100", "XBT/USD"]
[270, {"a": [["11854.00000", "3.62493954", "1596737225.940989"]], "c": "2955450990"}, "book-100", "XBT/USD"]
[270, {"a": [["11859.20000", "0.00000000", "1596737225.971631"], ["11897.50000", "0.75800000", "1596737133.514960", "r"]], "c": "2955450990"}, "book-100", "XBT/USD"]
[270, {"a": [["11854.00000", "4.03155623", "1596737225.991554"]], "c": "1546547003"}, "book-100", "XBT/USD"]
[270, {"a": [["11856.20000", "0.17787000", "1596737226.011202"]], "c": "2089176315"}, "book-100", "XBT/USD"]
[270, {"b": [["11841.60000", "0.03467232", "1596737226.097637"]], "c": "2089176315"}, "book-100", "XBT/USD"]
[270, {"b": [["11841.60000", "0.01325361", "1596737226.101918"]], "c": "2089176315"}, "book-100", "XBT/USD"]
[270, {"a": [["11857.40000", "0.04750000", "1596737226.107666"]], "c": "2089176315"}, "book-100", "XBT/USD"]
[270, {"a": [["11888.10000", "0.00000000", "1596737226.128135"], ["11897.00000", "0.02000000", "1596736823.323873", "r"]], "c": "2089176315"}, "book-100", "XBT/USD"]
[270, {"b": [["11841.60000", "0.00000000", "1596737226.347429"], ["11804.80000", "3.28996656", "1596736677.195153", "r"]], "c": "2089176315"}, "book-100", "XBT/USD"]
[270, {"b": [["11841.60000", "0.02141871", "1596737226.348043"]], "c": "2089176315"}, "book-100", "XBT/USD"]
[270, {"a": [["11874.60000", "0.00000000", "1596737226.629189"], ["11897.50000", "0.75800000", "1596737133.514960", "r"]], "c": "2089176315"}, "book-100", "XBT/USD"]
[270, {"a": [["11861.50000", "0.28399999", "1596737226.683668"]], "c": "2089176315"}, "book-100", "XBT/USD"]
[270, {"b": [["11851.50000", "0.00000000", "1596737227.031758"], ["11804.80000", "3.28996656", "1596736677.195153", "r"]], "c": "3758044549"}, "book-100", "XBT/USD"]
[270, {"a": [["11878.50000", "0.00000000", "1596737227.073805"], ["11897.50000", "0.75800000", "1596737133.514960", "r"]], "c": "3758044549"}, "book-100", "XBT/USD"]
[270, {"a": [["11890.60000", "0.00000000", "1596737227.073863"], ["11897.80000", "1.58935366", "1596737150.426450", "r"]], "c": "3758044549"}, "book-100", "XBT/USD"]
[270, {"a": [["11856.20000", "0.00000000", "1596737227.084345"], ["11898.00000", "0.17065000", "1596737088.466567", "r"]], "c": "353742103"}, "book-100", "XBT/USD"]
[270, {"a": [["11855.90000", "0.00000000", "1596737227.090072"], ["11898.30000", "6.46320506", "1596737141.628854", "r"]], "c": "1869525606"}, "book-100", "XBT/USD"]
[270, {"b": [["11846.50000", "0.01466462", "1596737227.232484"]], "c": "1869525606"}, "book-100", "XBT/USD"]
[270, {"a": [["11886.30000", "0.50000000", "1596737227.300542"]], "c": "1869525606"}, "book-100", "XBT/USD"]
[270, {"b": [["11841.60000", "0.00000000", "1596737227.348067"], ["11804.80000", "3.28996656", "1596736677.195153", "r"]], "c": "1869525606"}, "book-100", "XBT/USD"]
[270, {"b": [["11841.60000", "0.01325361", "1596737227.351248"]], "c": "1869525606"}, "book-100", "XBT/USD"]
[270, {"a": [["11878.10000", "0.00438186", "1596737227.546059"]], "c": "1869525606"}, "book-100", "XBT/USD"]
[270, {"b": [["11837.80000", "0.00425918", "1596737227.547092"]], "c": "1869525606"}, "book-100", "XBT/USD"]
[270, {"a": [["11854.00000", "2.03155623", "1596737227.746577"]], "c": "2696487905"}, "book-100", "XBT/USD"]
[270, {"a": [["11854.20000", "0.00000000", "1596737227.761238"], ["11898.00000", "0.17065000", "1596737088.466567", "r"]], "c": "2993481970"}, "book-100", "XBT/USD"]
[270, {"a": [["11854.00000", "1.33155623", "1596737227.816559"]], "c": "247311370"}, "book-100", "XBT/USD"]
[270, {"a": [["11856.20000", "0.17787000", "1596737227.817511"]], "c": "1662374544"}, "book-100", "XBT/USD"]
[270, {"a": [["11854.40000", "0.70000000", "1596737227.862579"]], "c": "3874227757"}, "book-100", "XBT/USD"]
[270, {"a": [["11856.30000", "1.13128000", "1596737227.883828"]], "c": "2763013631"}, "book-100", "XBT/USD"]
[270, {"a": [["11856.20000", "0.00000000", "1596737227.899362"], ["11897.80000", "1.58935366", "1596737150.426450", "r"]], "c": "4000225011"}, "book-100", "XBT/USD"]
[270, {"a": [["11854.00000", "0.91155623", "1596737227.956970"]], "c": "1022806903"}, "book-100", "XBT/USD"]
[270, {"a": [["11854.50000", "0.00000000", "1596737227.998835"], ["11898.00000", "0.17065000", "1596737088.466567", "r"]], "c": "3925771958"}, "book-100", "XBT/USD"]
[270, {"b": [["11849.80000", "0.00000000", "1596737228.009476"], ["11805.20000", "0.34533000", "1596735143.806373", "r"]], "c": "3659334579"}, "book-100", "XBT/USD"]
[270, {"a": [["11858.60000", "0.17787000", "1596737228.021441"]], "c": "3659334579"}, "book-100", "XBT/USD"]
[270, {"a": [["11859.80000", "0.00000000", "1596737228.022623"], ["11898.00000", "0.17065000", "1596737088.466567", "r"]], "c": "3659334579"}, "book-100", "XBT/USD"]
[270, {"a": [["11856.30000", "0.95341000", "1596737228.024721"]], "c": "1726913468"}, "book-100", "XBT/USD"]
[270, {"a": [["11864.30000", "0.00000000", "1596737228.047870"], ["11898.30000", "6.46320506", "1596737141.628854", "r"]], "c": "1726913468"}, "book-100", "XBT/USD"]
[270, {"a": [["11864.00000", "0.00000000", "1596737228.048470"], ["11898.70000", "0.01000000", "1596737133.560066", "r"]], "c": "1726913468"}, "book-100", "XBT/USD"]
[270, {"b": [["11841.10000", "0.94624175", "1596737228.048708"]], "c": "1726913468"}, "book-100", "XBT/USD"]
[270, {"a": [["11866.90000", "0.00000000", "1596737228.048915"], ["11899.00000", "2.81849664", "1596737063.692951", "r"]], "c": "1726913468"}, "book-100", "XBT/USD"]
[270, {"a": [["11857.50000", "0.72144323", "1596737228.052503"]], "c": "2695653039"}, "book-100", "XBT/USD"]
[270, {"a": [["11854.40000", "0.00000000", "1596737228.053286"], ["11899.10000", "7.82927162", "1596737145.805987", "r"]], "c": "54919764"}, "book-100", "XBT/USD"]
[270, {"a": [["11865.40000", "0.00000000", "1596737228.073495"], ["11899.90000", "7.61000000", "1596737079.466913", "r"]], "c": "54919764"}, "book-100", "XBT/USD"]
[270, {"a": [["11865.90000", "0.00000000", "1596737228.074038"], ["11900.00000", "12.71653131", "1596737075.897027", "r"]], "c": "54919764"}, "book-100", "XBT/USD"]
[270, {"a": [["11854.00000", "0.50493954", "1596737228.077183"]], "c": "3998581373"}, "book-100", "XBT/USD"]
[270, {"b": [["11842.10000", "0.02300000", "1596737228.098082"]], "c": "3998581373"}, "book-100", "XBT/USD"]
[270, {"a": [["11857.20000", "0.17787000", "1596737228.160992"]], "c": "1623240535"}, "book-100", "XBT/USD"]
[270, {"a": [["11854.00000", "0.92493954", "1596737228.173213"]], "c": "4066453448"}, "book-100", "XBT/USD"]
[270, {"a": [["11882.40000", "0.00000000", "1596737228.200056"], ["11900.00000", "12.71653131", "1596737075.897027", "r"]], "c": "4066453448"}, "book-100", "XBT/USD"]
[270, {"b": [["11821.00000", "0.00000000", "1596737228.201736"], ["11805.20000", "0.34533000", "1596735143.806373", "r"]], "c": "4066453448"}, "book-100", "XBT/USD"]
[270, {"a": [["11882.10000", "0.73651140", "1596737228.204895"]], "c": "4066453448"}, "book-100", "XBT/USD"]
[270, {"b": [["11821.40000", "0.83651140", "1596737228.207528"]], "c": "4066453448"}, "book-100", "XBT/USD"]
[270, {"a": [["11899.80000", "2.21053489", "1596737228.207700"]], "c": "4066453448"}, "book-100", "XBT/USD"]
[270, {"a": [["11865.00000", "0.07332312", "1596737228.245525"]], "c": "4066453448"}, "book-100", "XBT/USD"]
[270, {"a": [["11865.30000", "0.17597549", "1596737228.247213"]], "c": "4066453448"}, "book-100", "XBT/USD"]
[270, {"a": [["11867.90000", "0.01800000", "1596737228.262960"]], "c": "4066453448"}, "book-100", "XBT/USD"]
[270, {"a": [["11872.50000", "0.00000000", "1596737228.270791"], ["11899.00000", "2.81849664", "1596737063.692951", "r"]], "c": "4066453448"}, "book-100", "XBT/USD"]
[270, {"a": [["11866.30000", "0.04401137", "1596737228.276949"]], "c": "4066453448"}, "book-100", "XBT/USD"]
[270, {"a": [["11867.00000", "0.82561365", "1596737228.277432"]], "c": "4066453448"}, "book-100", "XBT/USD"]
[270, {"a": [["11869.00000", "6.42759677", "1596737228.355130"]], "c": "4066453448"}, "book-100", "XBT/USD"]
[270, {"b": [["11850.90000", "0.32332312", "1596737228.420694"]], "c": "1544372823"}, "book-100", "XBT/USD"]
[270, {"a": [["11885.80000", "10.52941283", "1596737228.438029"]], "c": "1544372823"}, "book-100", "XBT/USD"]
[270, {"a": [["11855.00000", "0.70000000", "1596737228.471165"]], "c": "2194646957"}, "book-100", "XBT/USD"]
[270, {"b": [["11842.10000", "0.00000000", "1596737228.479399"], ["11804.80000", "3.28996656", "1596736677.195153", "r"]], "c": "2194646957"}, "book-100", "XBT/USD"]
[270, {"a": [["11867.90000", "0.00000000", "1596737228.479639"], ["11898.30000", "6.46320506", "1596737141.628854", "r"]], "c": "2194646957"}, "book-100", "XBT/USD"]
[270, {"b": [["11841.10000", "0.96924175", "1596737228.551570"]], "c": "2194646957"}, "book-100", "XBT/USD"]
[270, {"a": [["11866.90000", "0.01800000", "1596737228.552105"]], "c": "2194646957"}, "book-100", "XBT/USD"]
[270, {"a": [["11886.80000", "0.00000000", "1596737228.581925"], ["11898.30000", "6.46320506", "1596737141.628854", "r"]], "c": "2194646957"}, "book-100", "XBT/USD"]
[270, {"b": [["11850.90000", "0.07332312", "1596737228.708846"]], "c": "2333743141"}, "book-100", "XBT/USD"]
[270, {"a": [["11895.80000", "5.30000000", "1596737228.832641"]], "c": "2333743141"}, "book-100", "XBT/USD"]
[270, {"a": [["11857.20000", "0.00000000", "1596737229.240741"], ["11898.70000", "0.01000000", "1596737133.560066", "r"]], "c": "1599394373"}, "book-100", "XBT/USD"]
[270, {"a": [["11880.60000", "0.00000000", "1596737229.315227"], ["11899.00000", "2.81849664", "1596737063.692951", "r"]], "c": "1599394373"}, "book-100", "XBT/USD"]
[270, {"a": [["11878.60000", "0.00000000", "1596737229.317334"], ["11899.10000", "7.82927162", "1596737145.805987", "r"]], "c": "1599394373"}, "book-100", "XBT/USD"]
[270, {"a": [["11875.10000", "0.00000000", "1596737229.317718"], ["11899.80000", "2.21053489", "1596737228.207700", "r"]], "c": "1599394373"}, "book-100", "XBT/USD"]
[270, {"a": [["11890.90000", "2.18115278", "1596737229.374313"]], "c": "1599394373"}, "book-100", "XBT/USD"]
[270, {"a": [["11856.60000", "0.17787000", "1596737229.388783"]], "c": "3181785787"}, "book-100", "XBT/USD"]
[270, {"b": [["11850.20000", "0.25000000", "1596737229.388950"]], "c": "935702688"}, "book-100", "XBT/USD"]
[270, {"a": [["11868.60000", "0.27100000", "1596737229.510163"]], "c": "935702688"}, "book-100", "XBT/USD"]
[270, {"a": [["11858.90000", "0.04440539", "1596737229.522520"]], "c": "935702688"}, "book-100", "XBT/USD"]
[270, {"a": [["11879.10000", "2.07561563", "1596737229.548719"]], "c": "935702688"}, "book-100", "XBT/USD"]
[270, {"a": [["11873.20000", "6.83224016", "1596737229.549828"]], "c": "935702688"}, "book-100", "XBT/USD"]
[270, {"a": [["11876.70000", "0.69749873", "1596737229.553586"]], "c": "935702688"}, "book-100", "XBT/USD"]
[270, {"a": [["11879.70000", "0.00000000", "1596737229.725561"], ["11898.70000", "0.01000000", "1596737133.560066", "r"]], "c": "935702688"}, "book-100", "XBT/USD"]
[270, {"a": [["11876.70000", "0.80658003", "1596737230.015801"]], "c": "935702688"}, "book-100", "XBT/USD"]
[270, {"a": [["11860.00000", "1.68600000", "1596737230.128459"]], "c": "935702688"}, "book-100", "XBT/USD"]
[270, {"b": [["11841.60000", "0.03467232", "1596737230.214500"]], "c": "935702688"}, "book-100", "XBT/USD"]
[270, {"b": [["11841.60000", "0.02141871", "1596737230.215703"]], "c": "935702688"}, "book-100", "XBT/USD"]
[270, {"a": [["11890.60000", "2.11925673", "1596737230.447375"]], "c": "935702688"}, "book-100", "XBT/USD"]
[270, {"a": [["11879.00000", "0.50571261", "1596737230.447848"]], "c": "935702688"}, "book-100", "XBT/USD"]
[270, {"b": [["11849.40000", "0.00000000", "1596737230.965346"], ["11804.80000", "3.28996656", "1596736677.195153", "r"]], "c": "935702688"}, "book-100", "XBT/USD"]
[270, {"b": [["11850.10000", "0.04402009", "1596737231.165977"]], "c": "3044374218"}, "book-100", "XBT/USD"]
[270, {"a": [["11854.00000", "2.92493954", "1596737231.184807"]], "c": "3168000302"}, "book-100", "XBT/USD"]
[270, {"b": [["11850.60000", "0.00000000", "1596737231.322294"], ["11804.80000", "3.28996656", "1596736677.195153", "r"]], "c": "829715377"}, "book-100", "XBT/USD"]
[270, {"b": [["11853.70000", "0.25297499", "1596737231.384559"]], "c": "3656003294"}, "book-100", "XBT/USD"]
[270, {"b": [["11849.20000", "0.00000000", "1596737232.136891"], ["11804.80000", "3.28996656", "1596736677.195153", "r"]], "c": "3656003294"}, "book-100", "XBT/USD"]
[270, {"b": [["11835.90000", "0.72000000", "1596737232.308488"]], "c": "3656003294"}, "book-100", "XBT/USD"]
[270, {"b": [["11833.60000", "0.00000000", "1596737232.312210"], ["11804.80000", "3.28996656", "1596736677.195153", "r"]], "c": "3656003294"}, "book-100", "XBT/USD"]
[270, {"b": [["11841.60000", "0.00000000", "1596737233.638395"], ["11803.60000", "5.42971881", "1596737228.200910", "r"]], "c": "3656003294"}, "book-100", "XBT/USD"]
[270, {"a": [["11869.00000", "0.18315000", "1596737233.641106"]], "c": "3656003294"}, "book-100", "XBT/USD"]
[270, {"b": [["11841.60000", "0.01325361", "1596737233.679394"]], "c": "3656003294"}, "book-100", "XBT/USD"]
[270, {"b": [["11853.70000", "0.00000000", "1596737233.683729"], ["11803.60000", "5.42971881", "1596737228.200910", "r"]], "c": "829715377"}, "book-100", "XBT/USD"]
[270, {"a": [["11857.30000", "0.00000000", "1596737233.703505"], ["11898.00000", "0.17065000", "1596737088.466567", "r"]], "c": "3412665926"}, "book-100", "XBT/USD"]
[270, {"b": [["11846.40000", "0.42167444", "1596737233.724887"]], "c": "3412665926"}, "book-100", "XBT/USD"]
[270, {"a": [["11855.20000", "0.00000000", "1596737233.730081"], ["11898.30000", "6.46320506", "1596737141.628854", "r"]], "c": "1547996915"}, "book-100", "XBT/USD"]
[270, {"b": [["11845.80000", "0.09621094", "1596737233.731191"]], "c": "1547996915"}, "book-100", "XBT/USD"]
[271, [["11854.00000", "0.00200000", "1596737233.742746", "b", "l", ""]], "trade", "XBT/USD"]
[270, {"a": [["11854.00000", "2.92293954", "1596737233.742746"]], "c": "1891845914"}, "book-100", "XBT/USD"]
[270, {"b": [["11816.80000", "0.00000000", "1596737233.749969"], ["11803.60000", "5.42971881", "1596737228.200910", "r"]], "c": "1891845914"}, "book-100", "XBT/USD"]
[270, {"a": [["11856.60000", "0.00000000", "1596737233.762843"], ["11898.70000", "0.01000000", "1596737133.560066", "r"]], "c": "2037623040"}, "book-100", "XBT/USD"]
[270, {"b": [["11851.00000", "0.25299224", "1596737233.768564"]], "c": "328923556"}, "book-100", "XBT/USD"]
[270, {"a": [["11854.70000", "0.09621094", "1596737233.771608"]], "c": "901919093"}, "book-100", "XBT/USD"]
[270, {"b": [["11841.60000", "0.00000000", "1596737233.810502"], ["11803.60000", "5.42971881", "1596737228.200910", "r"]], "c": "901919093"}, "book-100", "XBT/USD"]
[270, {"b": [["11841.60000", "0.02141871", "1596737233.811114"]], "c": "901919093"}, "book-100", "XBT/USD"]
[270, {"a": [["11858.00000", "1.50000000", "1596737233.851885"]], "c": "3244019213"}, "book-100", "XBT/USD"]
[270, {"b": [["11846.50000", "0.00000000", "1596737235.960247"], ["11803.60000", "5.42971881", "1596737228.200910", "r"]], "c": "3244019213"}, "book-100", "XBT/USD"]
[270, {"a": [["11857.40000", "0.22537000", "1596737235.995400"]], "c": "3498592295"}, "book-100", "XBT/USD"]
[270, {"b": [["11837.80000", "0.00000000", "1596737235.996311"], ["11803.30000", "0.95003592", "1596737228.202295", "r"]], "c": "3498592295"}, "book-100", "XBT/USD"]
[270, {"a": [["11854.00000", "0.92293954", "1596737236.016509"]], "c": "2901657872"}, "book-100", "XBT/USD"]
[270, {"a": [["11881.80000", "0.73650472", "1596737236.023027"]], "c": "2901657872"}, "book-100", "XBT/USD"]
[270, {"b": [["11821.40000", "0.10000000", "1596737236.024861"]], "c": "2901657872"}, "book-100", "XBT/USD"]
[270, {"a": [["11882.10000", "0.00000000", "1596737236.031282"], ["11898.00000", "0.17065000", "1596737088.466567", "r"]], "c": "2901657872"}, "book-100", "XBT/USD"]
[270, {"b": [["11845.30000", "0.61703000", "1596737236.034005"]], "c": "2901657872"}, "book-100", "XBT/USD"]
[270, {"a": [["11855.10000", "0.00000000", "1596737236.034093"], ["11898.30000", "6.46320506", "1596737141.628854", "r"]], "c": "2067046124"}, "book-100", "XBT/USD"]
[270, {"a": [["11890.60000", "0.00000000", "1596737236.039999"], ["11898.70000", "0.01000000", "1596737133.560066", "r"]], "c": "2067046124"}, "book-100", "XBT/USD"]
[270, {"b": [["11841.10000", "0.94624175", "1596737236.042726"]], "c": "2067046124"}, "book-100", "XBT/USD"]
[270, {"b": [["11851.00000", "0.00000000", "1596737236.043730"], ["11803.30000", "0.95003592", "1596737228.202295", "r"]], "c": "299748936"}, "book-100", "XBT/USD"]
[270, {"b": [["11848.10000", "0.42163776", "1596737236.045756"]], "c": "299748936"}, "book-100", "XBT/USD"]
[270, {"a": [["11857.60000", "4.38687000", "1596737236.050094"]], "c": "960256520"}, "book-100", "XBT/USD"]
[270, {"b": [["11821.60000", "0.73650472", "1596737236.054337"]], "c": "960256520"}, "book-100", "XBT/USD"]
[270, {"a": [["11866.90000", "0.00000000", "1596737236.085581"], ["11899.00000", "2.81849664", "1596737063.692951", "r"]], "c": "960256520"}, "book-100", "XBT/USD"]
[270, {"b": [["11853.90000", "0.38355771", "1596737236.091514"]], "c": "3660211013"}, "book-100", "XBT/USD"]
[270, {"a": [["11879.00000", "0.00000000", "1596737236.093312"], ["11899.10000", "7.82927162", "1596737145.805987", "r"]], "c": "3660211013"}, "book-100", "XBT/USD"]
[270, {"a": [["11878.10000", "0.00000000", "1596737236.093453"], ["11899.80000", "2.21053489", "1596737228.207700", "r"]], "c": "3660211013"}, "book-100", "XBT/USD"]
[270, {"a": [["11886.30000", "0.00000000", "1596737236.103386"], ["11899.90000", "7.61000000", "1596737079.466913", "r"]], "c": "3660211013"}, "book-100", "XBT/USD"]
[270, {"a": [["11855.00000", "0.00000000", "1596737236.119347"], ["11900.00000", "12.71653131", "1596737075.897027", "r"]], "c": "3026518927"}, "book-100", "XBT/USD"]
[270, {"b": [["11842.10000", "0.02300000", "1596737236.134692"]], "c": "3026518927"}, "book-100", "XBT/USD"]
[270, {"b": [["11841.60000", "0.00000000", "1596737236.148537"], ["11803.60000", "5.42971881", "1596737228.200910", "r"]], "c": "3026518927"}, "book-100", "XBT/USD"]
[270, {"a": [["11856.60000", "0.63242614", "1596737236.148688"]], "c": "3468461242"}, "book-100", "XBT/USD"]
[270, {"a": [["11867.90000", "0.01800000", "1596737236.161960"]], "c": "3468461242"}, "book-100", "XBT/USD"]
[270, {"b": [["11853.90000", "0.63652816", "1596737236.177117"]], "c": "1113018364"}, "book-100", "XBT/USD"]
[270, {"a": [["11855.60000", "0.70000000", "1596737236.183756"]], "c": "2477175960"}, "book-100", "XBT/USD"]
[270, {"b": [["11841.60000", "0.01325361", "1596737236.203325"]], "c": "2477175960"}, "book-100", "XBT/USD"]
[270, {"b": [["11852.20000", "0.15000000", "1596737236.301188"]], "c": "2778679584"}, "book-100", "XBT/USD"]
[270, {"a": [["11865.30000", "0.00000000", "1596737236.324484"], ["11899.80000", "2.21053489", "1596737228.207700", "r"]], "c": "2778679584"}, "book-100", "XBT/USD"]
[270, {"a": [["11867.90000", "0.00000000", "1596737236.416039"], ["11899.90000", "7.61000000", "1596737079.466913", "r"]], "c": "2778679584"}, "book-100", "XBT/USD"]
[270, {"b": [["11842.10000", "0.00000000", "1596737236.434943"], ["11804.80000", "3.28996656", "1596736677.195153", "r"]], "c": "2778679584"}, "book-100", "XBT/USD"]
[270, {"a": [["11866.90000", "0.01800000", "1596737236.484850"]], "c": "2778679584"}, "book-100", "XBT/USD"]
[270, {"b": [["11841.10000", "0.96924175", "1596737236.524745"]], "c": "2778679584"}, "book-100", "XBT/USD"]
[270, {"b": [["11841.60000", "0.03467232", "1596737236.564606"]], "c": "2778679584"}, "book-100", "XBT/USD"]
[270, {"b": [["11841.60000", "0.02141871", "1596737236.592686"]], "c": "2778679584"}, "book-100", "XBT/USD"]
[270, {"a": [["11867.00000", "0.69357953", "1596737236.592750"]], "c": "2778679584"}, "book-100", "XBT/USD"]
[270, {"a": [["11881.80000", "0.00000000", "1596737236.627836"], ["11899.90000", "7.61000000", "1596737079.466913", "r"]], "c": "2778679584"}, "book-100", "XBT/USD"]
[270, {"b": [["11821.60000", "0.00000000", "1596737236.680930"], ["11803.60000", "5.42971881", "1596737228.200910", "r"]], "c": "2778679584"}, "book-100", "XBT/USD"]
[270, {"a": [["11867.70000", "0.13206224", "1596737236.790807"]], "c": "2778679584"}, "book-100", "XBT/USD"]
[270, {"b": [["11843.80000", "0.42152894", "1596737236.853172"]], "c": "2778679584"}, "book-100", "XBT/USD"]
[270, {"b": [["11847.20000", "0.00000000", "1596737236.853581"], ["11803.30000", "0.95003592", "1596737228.202295", "r"]], "c": "2778679584"}, "book-100", "XBT/USD"]
[270, {"b": [["11821.80000", "0.73650047", "1596737237.001622"]], "c": "2778679584"}, "book-100", "XBT/USD"]
[270, {"a": [["11881.90000", "7.33650047", "1596737237.006759"]], "c": "2778679584"}, "book-100", "XBT/USD"]
[270, {"a": [["11894.30000", "0.00000000", "1596737237.035106"], ["11899.90000", "7.61000000", "1596737079.466913", "r"]], "c": "2778679584"}, "book-100", "XBT/USD"]
[270, {"a": [["11857.40000", "0.04750000", "1596737237.240339"]], "c": "914317870"}, "book-100", "XBT/USD"]
[270, {"a": [["11886.50000", "8.71309526", "1596737237.279091"]], "c": "914317870"}, "book-100", "XBT/USD"]
[270, {"a": [["11890.60000", "0.02324775", "1596737237.290038"]], "c": "914317870"}, "book-100", "XBT/USD"]
[270, {"b": [["11848.20000", "2.41568843", "1596737237.341749"]], "c": "914317870"}, "book-100", "XBT/USD"]
[270, {"b": [["11841.60000", "0.03467232", "1596737237.346583"]], "c": "914317870"}, "book-100", "XBT/USD"]
[270, {"b": [["11816.90000", "6.06405224", "1596737237.352685"]], "c": "914317870"}, "book-100", "XBT/USD"]
[270, {"b": [["11841.60000", "0.01325361", "1596737237.360156"]], "c": "914317870"}, "book-100", "XBT/USD"]
[270, {"b": [["11843.80000", "1.12094647", "1596737237.380674"]], "c": "914317870"}, "book-100", "XBT/USD"]
[270, {"b": [["11847.20000", "0.33296038", "1596737237.438300"]], "c": "914317870"}, "book-100", "XBT/USD"]
[270, {"a": [["11868.90000", "6.24392057", "1596737237.444331"]], "c": "914317870"}, "book-100", "XBT/USD"]
[270, {"b": [["11849.60000", "4.34704324", "1596737237.454942"]], "c": "618363536"}, "book-100", "XBT/USD"]
[270, {"b": [["11847.20000", "0.00000000", "1596737237.939675"], ["11804.80000", "3.28996656", "1596736677.195153", "r"]], "c": "618363536"}, "book-100", "XBT/USD"]
[270, {"b": [["11852.20000", "0.00000000", "1596737237.947439"], ["11803.60000", "5.42971881", "1596737228.200910", "r"]], "c": "4110805416"}, "book-100", "XBT/USD"]
[270, {"a": [["11856.70000", "0.17787000", "1596737237.985445"]], "c": "4236120421"}, "book-100", "XBT/USD"]
[270, {"b": [["11849.50000", "0.57154067", "1596737238.241324"]], "c": "1659649628"}, "book-100", "XBT/USD"]
[270, {"a": [["11861.00000", "0.04440539", "1596737238.519859"]], "c": "1659649628"}, "book-100", "XBT/USD"]
[270, {"a": [["11858.90000", "0.00000000", "1596737238.526392"], ["11899.00000", "2.81849664", "1596737063.692951", "r"]], "c": "1659649628"}, "book-100", "XBT/USD"]
[270, {"a": [["11856.70000", "0.00000000", "1596737238.586037"], ["11899.10000", "7.82927162", "1596737145.805987", "r"]], "c": "1805108881"}, "book-100", "XBT/USD"]
[270, {"b": [["11803.60000", "3.21918392", "1596737239.027602"]], "c": "1805108881"}, "book-100", "XBT/USD"]
[270, {"b": [["11804.10000", "2.21050448", "1596737239.027835"]], "c": "1805108881"}, "book-100", "XBT/USD"]
[270, {"a": [["11857.40000", "0.22537000", "1596737239.257953"]], "c": "2361134013"}, "book-100", "XBT/USD"]
[270, {"b": [["11847.20000", "0.33296038", "1596737239.283685"]], "c": "2361134013"}, "book-100", "XBT/USD"]
[270, {"a": [["11884.50000", "0.30000000", "1596737240.005238"]], "c": "2361134013"}, "book-100", "XBT/USD"]
[270, {"a": [["11880.90000", "0.00000000", "1596737240.005674"], ["11899.60000", "2.21050448", "1596737239.032827", "r"]], "c": "2361134013"}, "book-100", "XBT/USD"]
[270, {"a": [["11882.00000", "0.94301119", "1596737240.322600"]], "c": "2361134013"}, "book-100", "XBT/USD"]
[270, {"a": [["11878.50000", "0.94328905", "1596737240.435483"]], "c": "2361134013"}, "book-100", "XBT/USD"]
[270, {"a": [["11856.30000", "0.00000000", "1596737240.952332"], ["11899.10000", "7.82927162", "1596737145.805987", "r"]], "c": "1783780440"}, "book-100", "XBT/USD"]
[270, {"a": [["11866.90000", "0.00000000", "1596737241.005718"], ["11899.60000", "2.21050448", "1596737239.032827", "r"]], "c": "1783780440"}, "book-100", "XBT/USD"]
[270, {"a": [["11855.60000", "0.00000000", "1596737241.011625"], ["11899.90000", "7.61000000", "1596737079.466913", "r"]], "c": "412421535"}, "book-100", "XBT/USD"]
[270, {"b": [["11818.50000", "0.00000000", "1596737241.051625"], ["11804.10000", "2.21050448", "1596737239.027835", "r"]], "c": "412421535"}, "book-100", "XBT/USD"]
[270, {"a": [["11867.90000", "0.01800000", "1596737241.056664"]], "c": "412421535"}, "book-100", "XBT/USD"]
[270, {"a": [["11855.50000", "0.70000000", "1596737241.058284"]], "c": "105344459"}, "book-100", "XBT/USD"]
[270, {"a": [["11855.50000", "0.00000000", "1596737241.103632"], ["11899.60000", "2.21050448", "1596737239.032827", "r"]], "c": "412421535"}, "book-100", "XBT/USD"]
[270, {"a": [["11854.00000", "0.50293954", "1596737241.111672"]], "c": "221184761"}, "book-100", "XBT/USD"]
[270, {"a": [["11855.40000", "0.70000000", "1596737241.149655"]], "c": "2166454243"}, "book-100", "XBT/USD"]
[270, {"a": [["11855.40000", "0.00000000", "1596737241.196319"], ["11899.60000", "2.21050448", "1596737239.032827", "r"]], "c": "221184761"}, "book-100", "XBT/USD"]
[270, {"a": [["11855.30000", "0.70000000", "1596737241.246235"]], "c": "3419869579"}, "book-100", "XBT/USD"]
[270, {"a": [["11855.30000", "0.00000000", "1596737241.300319"], ["11899.60000", "2.21050448", "1596737239.032827", "r"]], "c": "221184761"}, "book-100", "XBT/USD"]
[270, {"b": [["11816.90000", "6.07737075", "1596737241.300656"]], "c": "221184761"}, "book-100", "XBT/USD"]
[270, {"a": [["11855.20000", "0.70000000", "1596737241.344611"]], "c": "1493894341"}, "book-100", "XBT/USD"]
[270, {"a": [["11855.20000", "0.00000000", "1596737241.393597"], ["11899.60000", "2.21050448", "1596737239.032827", "r"]], "c": "221184761"}, "book-100", "XBT/USD"]
[270, {"a": [["11868.90000", "0.00000000", "1596737242.119142"], ["11899.90000", "7.61000000", "1596737079.466913", "r"]], "c": "221184761"}, "book-100", "XBT/USD"]
[270, {"b": [["11837.20000", "0.00000000", "1596737242.274983"], ["11803.60000", "3.21918392", "1596737239.027602", "r"]], "c": "221184761"}, "book-100", "XBT/USD"]
[270, {"a": [["11872.60000", "6.24281582", "1596737242.276720"]], "c": "221184761"}, "book-100", "XBT/USD"]
[270, {"b": [["11841.60000", "0.00000000", "1596737242.284967"], ["11803.30000", "0.95003592", "1596737228.202295", "r"]], "c": "221184761"}, "book-100", "XBT/USD"]
[270, {"b": [["11841.60000", "0.02141871", "1596737242.290741"]], "c": "221184761"}, "book-100", "XBT/USD"]
[270, {"b": [["11853.80000", "0.25296708", "1596737242.332037"]], "c": "2937854269"}, "book-100", "XBT/USD"]
[270, {"a": [["11857.30000", "0.70000000", "1596737242.382331"]], "c": "897925508"}, "book-100", "XBT/USD"]
[270, {"b": [["11841.10000", "0.94624175", "1596737242.385906"]], "c": "897925508"}, "book-100", "XBT/USD"]
[270, {"b": [["11842.10000", "0.02300000", "1596737242.438857"]], "c": "897925508"}, "book-100", "XBT/USD"]
[270, {"a": [["11857.60000", "4.20900000", "1596737242.487288"]], "c": "1131536768"}, "book-100", "XBT/USD"]
[270, {"a": [["11857.40000", "0.04750000", "1596737242.493985"]], "c": "1713237286"}, "book-100", "XBT/USD"]
[270, {"b": [["11841.60000", "0.00000000", "1596737242.693505"], ["11804.10000", "2.21050448", "1596737239.027835", "r"]], "c": "1713237286"}, "book-100", "XBT/USD"]
[270, {"b": [["11841.60000", "0.00816510", "1596737242.694860"]], "c": "1713237286"}, "book-100", "XBT/USD"]
[270, {"a": [["11860.00000", "0.00000000", "1596737242.840733"], ["11899.60000", "2.21050448", "1596737239.032827", "r"]], "c": "1713237286"}, "book-100", "XBT/USD"]
[270, {"a": [["11855.70000", "0.00000000", "1596737242.880279"], ["11899.90000", "7.61000000", "1596737079.466913", "r"]], "c": "3974181907"}, "book-100", "XBT/USD"]
[270, {"a": [["11857.30000", "0.00000000", "1596737242.928554"], ["11900.00000", "12.71653131", "1596737075.897027", "r"]], "c": "3534265164"}, "book-100", "XBT/USD"]
[270, {"b": [["11850.20000", "0.00000000", "1596737243.151427"], ["11804.10000", "2.21050448", "1596737239.027835", "r"]], "c": "2117609796"}, "book-100", "XBT/USD"]
[270, {"a": [["11881.90000", "6.60000000", "1596737243.229718"]], "c": "2117609796"}, "book-100", "XBT/USD"]
[270, {"b": [["11821.80000", "0.00000000", "1596737243.266221"], ["11803.60000", "3.21918392", "1596737239.027602", "r"]], "c": "2117609796"}, "book-100", "XBT/USD"]
[270, {"a": [["11881.80000", "0.73651651", "1596737243.328442"]], "c": "2117609796"}, "book-100", "XBT/USD"]
[270, {"b": [["11821.90000", "0.73651651", "1596737243.390581"]], "c": "2117609796"}, "book-100", "XBT/USD"]
[270, {"b": [["11841.60000", "0.00000000", "1596737243.390984"], ["11803.60000", "3.21918392", "1596737239.027602", "r"]], "c": "2117609796"}, "book-100", "XBT/USD"]
[270, {"b": [["11841.20000", "0.02107804", "1596737243.400626"]], "c": "2117609796"}, "book-100", "XBT/USD"]
[270, {"b": [["11851.40000", "1.92700000", "1596737243.556438"]], "c": "3643972042"}, "book-100", "XBT/USD"]
[270, {"b": [["11841.20000", "0.05032118", "1596737243.641952"]], "c": "3643972042"}, "book-100", "XBT/USD"]
[270, {"b": [["11841.20000", "0.02924314", "1596737243.642214"]], "c": "3643972042"}, "book-100", "XBT/USD"]
[270, {"b": [["11849.60000", "0.13204324", "1596737244.005224"]], "c": "2256585494"}, "book-100", "XBT/USD"]
[270, {"b": [["11851.40000", "6.13400000", "1596737244.015664"]], "c": "2795152341"}, "book-100", "XBT/USD"]
[270, {"b": [["11851.40000", "1.92700000", "1596737244.094529"]], "c": "2256585494"}, "book-100", "XBT/USD"]
[270, {"a": [["11854.00000", "0.00493954", "1596737244.170832"]], "c": "2224145883"}, "book-100", "XBT/USD"]
[270, {"a": [["11854.00000", "0.00000000", "1596737244.245249"], ["11900.00000", "12.71653131", "1596737075.897027", "r"]], "c": "1411423874"}, "book-100", "XBT/USD"]
[270, {"a": [["11854.60000", "0.00493955", "1596737244.249943"]], "c": "985092902"}, "book-100", "XBT/USD"]
[270, {"a": [["11858.00000", "0.00000000", "1596737244.296431"], ["11900.00000", "12.71653131", "1596737075.897027", "r"]], "c": "1439764974"}, "book-100", "XBT/USD"]
[270, {"a": [["11863.40000", "0.00000000", "1596737244.334125"], ["11901.00000", "0.17065000", "1596737120.047779", "r"]], "c": "1439764974"}, "book-100", "XBT/USD"]
[270, {"a": [["11858.30000", "1.50000000", "1596737244.440466"]], "c": "2054070060"}, "book-100", "XBT/USD"]
[270, {"b": [["11851.40000", "0.25000000", "1596737244.553843"]], "c": "3243582230"}, "book-100", "XBT/USD"]
[270, {"a": [["11861.30000", "2.35576005", "1596737244.578554"]], "c": "3243582230"}, "book-100", "XBT/USD"]
[270, {"b": [["11852.90000", "1.68500000", "1596737244.585174"]], "c": "3313515958"}, "book-100", "XBT/USD"]
[270, {"a": [["11856.20000", "0.63240308", "1596737244.897480"]], "c": "371837694"}, "book-100", "XBT/USD"]
[270, {"a": [["11856.10000", "0.70000000", "1596737244.951089"]], "c": "1274211909"}, "book-100", "XBT/USD"]
[270, {"a": [["11857.30000", "0.17787000", "1596737244.991123"]], "c": "1783760654"}, "book-100", "XBT/USD"]
[270, {"a": [["11856.00000", "0.23000000", "1596737245.091370"]], "c": "4203018515"}, "book-100", "XBT/USD"]
[270, {"a": [["11856.10000", "0.00000000", "1596737245.144504"], ["11899.10000", "7.82927162", "1596737145.805987", "r"]], "c": "3060543041"}, "book-100", "XBT/USD"]
[270, {"a": [["11857.30000", "0.00000000", "1596737245.153481"], ["11899.60000", "2.21050448", "1596737239.032827", "r"]], "c": "2546779914"}, "book-100", "XBT/USD"]
[270, {"a": [["11858.60000", "0.00000000", "1596737245.153735"], ["11899.90000", "7.61000000", "1596737079.466913", "r"]], "c": "1725088643"}, "book-100", "XBT/USD"]
[270, {"a": [["11896.20000", "1.58439645", "1596737245.153887"]], "c": "1725088643"}, "book-100", "XBT/USD"]
[270, {"a": [["11858.80000", "0.17787000", "1596737245.274538"]], "c": "1725088643"}, "book-100", "XBT/USD"]
[270, {"a": [["11886.50000", "8.21309526", "1596737245.486679"]], "c": "1725088643"}, "book-100", "XBT/USD"]
[270, {"b": [["11839.10000", "0.02924840", "1596737245.582404"]], "c": "1725088643"}, "book-100", "XBT/USD"]
[270, {"b": [["11852.90000", "0.00000000", "1596737245.613561"], ["11804.80000", "3.28996656", "1596736677.195153", "r"]], "c": "799761012"}, "book-100", "XBT/USD"]
[270, {"a": [["11861.30000", "0.68276005", "1596737245.624622"]], "c": "799761012"}, "book-100", "XBT/USD"]
[270, {"a": [["11858.60000", "0.18387000", "1596737245.782689"]], "c": "3543396038"}, "book-100", "XBT/USD"]
[270, {"a": [["11854.30000", "0.42000000", "1596737245.810765"]], "c": "2367478980"}, "book-100", "XBT/USD"]
[270, {"b": [["11845.00000", "0.27100000", "1596737245.819564"]], "c": "2367478980"}, "book-100", "XBT/USD"]
[270, {"b": [["11853.80000", "0.00000000", "1596737245.824878"], ["11804.10000", "2.21050448", "1596737239.027835", "r"]], "c": "4257947059"}, "book-100", "XBT/USD"]
[270, {"a": [["11854.20000", "0.40000000", "1596737245.871386"]], "c": "419379286"}, "book-100", "XBT/USD"]
[270, {"a": [["11867.70000", "0.00000000", "1596737245.881785"], ["11898.70000", "0.01000000", "1596737133.560066", "r"]], "c": "419379286"}, "book-100", "XBT/USD"]
[270, {"b": [["11851.40000", "0.00000000", "1596737245.882184"], ["11803.60000", "3.21918392", "1596737239.027602", "r"]], "c": "247805359"}, "book-100", "XBT/USD"]
[270, {"a": [["11856.00000", "0.00000000", "1596737245.901661"], ["11899.00000", "2.81849664", "1596737063.692951", "r"]], "c": "1398522601"}, "book-100", "XBT/USD"]
[270, {"a": [["11854.60000", "2.00493955", "1596737245.902287"]], "c": "3385256398"}, "book-100", "XBT/USD"]
[270, {"a": [["11871.00000", "0.00000000", "1596737245.913319"], ["11899.10000", "7.82927162", "1596737145.805987", "r"]], "c": "3385256398"}, "book-100", "XBT/USD"]
[270, {"b": [["11838.80000", "0.02924899", "1596737245.923045"]], "c": "3385256398"}, "book-100", "XBT/USD"]
[270, {"a": [["11865.00000", "0.00000000", "1596737245.941999"], ["11899.60000", "2.21050448", "1596737239.032827", "r"]], "c": "3385256398"}, "book-100", "XBT/USD"]
[270, {"a": [["11856.60000", "0.00000000", "1596737245.946729"], ["11899.90000", "7.61000000", "1596737079.466913", "r"]], "c": "1680013186"}, "book-100", "XBT/USD"]
[270, {"a": [["11858.10000", "0.10100000", "1596737245.956922"]], "c": "3165483183"}, "book-100", "XBT/USD"]
[270, {"a": [["11854.30000", "0.00000000", "1596737245.959930"], ["11899.90000", "7.61000000", "1596737079.466913", "r"]], "c": "2774742522"}, "book-100", "XBT/USD"]
[270, {"b": [["11848.40000", "0.00000000", "1596737245.960244"], ["11803.60000", "3.21918392", "1596737239.027602", "r"]], "c": "1999383695"}, "book-100", "XBT/USD"]
[270, {"a": [["11854.00000", "0.50000000", "1596737245.981192"]], "c": "3609761411"}, "book-100", "XBT/USD"]
[270, {"a": [["11856.20000", "0.00000000", "1596737245.998333"], ["11899.90000", "7.61000000", "1596737079.466913", "r"]], "c": "1290855920"}, "book-100", "XBT/USD"]
[270, {"b": [["11852.10000", "0.00000000", "1596737246.029987"], ["11803.30000", "0.95003592", "1596737228.202295", "r"]], "c": "4281784172"}, "book-100", "XBT/USD"]
[270, {"a": [["11858.90000", "0.17787000", "1596737246.030248"]], "c": "4281784172"}, "book-100", "XBT/USD"]
[270, {"a": [["11854.00000", "2.50000000", "1596737246.031941"]], "c": "1482184610"}, "book-100", "XBT/USD"]
[270, {"a": [["11869.10000", "6.00000000", "1596737246.032623"]], "c": "1482184610"}, "book-100", "XBT/USD"]
[270, {"b": [["11841.20000", "0.00000000", "1596737246.032699"], ["11802.10000", "4.23653417", "1596737132.953878", "r"]], "c": "1482184610"}, "book-100", "XBT/USD"]
[270, {"a": [["11857.50000", "0.08900000", "1596737246.038894"]], "c": "420525441"}, "book-100", "XBT/USD"]
[270, {"b": [["11839.10000", "0.00000000", "1596737246.043349"], ["11802.00000", "7.50000000", "1596737194.335118", "r"]], "c": "420525441"}, "book-100", "XBT/USD"]
[270, {"b": [["11848.60000", "0.25000000", "1596737246.046068"]], "c": "1094970371"}, "book-100", "XBT/USD"]
[270, {"b": [["11842.10000", "0.00000000", "1596737246.047706"], ["11802.00000", "7.50000000", "1596737194.335118", "r"]], "c": "1094970371"}, "book-100", "XBT/USD"]
[270, {"a": [["11867.90000", "0.00000000", "1596737246.048314"], ["11899.90000", "7.61000000", "1596737079.466913", "r"]], "c": "1094970371"}, "book-100", "XBT/USD"]
[270, {"b": [["11838.10000", "0.10516731", "1596737246.049841"]], "c": "1094970371"}, "book-100", "XBT/USD"]
[270, {"b": [["11838.80000", "0.00000000", "1596737246.053608"], ["11801.90000", "4.67249674", "1596736908.903243", "r"]], "c": "1094970371"}, "book-100", "XBT/USD"]
[270, {"b": [["11853.90000", "0.35297045", "1596737246.072826"]], "c": "2483865150"}, "book-100", "XBT/USD"]
[270, {"b": [["11850.10000", "0.00000000", "1596737246.088590"], ["11801.80000", "3.19470719", "1596736911.648608", "r"]], "c": "2031868743"}, "book-100", "XBT/USD"]
[270, {"b": [["11849.60000", "0.00000000", "1596737246.088659"], ["11800.80000", "1.51500000", "1596737133.991629", "r"]], "c": "1886988365"}, "book-100", "XBT/USD"]
[270, {"a": [["11866.30000", "0.00000000", "1596737246.090696"], ["11900.00000", "12.71653131", "1596737075.897027", "r"]], "c": "1886988365"}, "book-100", "XBT/USD"]
[270, {"a": [["11864.90000", "0.01800000", "1596737246.096415"]], "c": "1886988365"}, "book-100", "XBT/USD"]
[270, {"b": [["11839.10000", "0.02300000", "1596737246.097879"]], "c": "1886988365"}, "book-100", "XBT/USD"]
[270, {"b": [["11852.30000", "1.68100000", "1596737246.118293"]], "c": "2127245914"}, "book-100", "XBT/USD"]
[270, {"b": [["11850.90000", "0.00000000", "1596737246.124318"], ["11801.80000", "3.19470719", "1596736911.648608", "r"]], "c": "2747906614"}, "book-100", "XBT/USD"]
[270, {"a": [["11866.70000", "0.00000000", "1596737246.126140"], ["11900.00000", "12.71653131", "1596737075.897027", "r"]], "c": "2747906614"}, "book-100", "XBT/USD"]
[270, {"b": [["11848.30000", "0.81600000", "1596737246.130432"]], "c": "3101542796"}, "book-100", "XBT/USD"]
[270, {"a": [["11860.70000", "1.67600000", "1596737246.138435"]], "c": "3101542796"}, "book-100", "XBT/USD"]
[270, {"a": [["11854.00000", "3.25000000", "1596737246.141161"]], "c": "3942194337"}, "book-100", "XBT/USD"]
[270, {"a": [["11854.20000", "0.40493954", "1596737246.142059"]], "c": "2089263059"}, "book-100", "XBT/USD"]
[270, {"b": [["11853.10000", "0.00000000", "1596737246.142112"], ["11801.80000", "3.19470719", "1596736911.648608", "r"]], "c": "1963426377"}, "book-100", "XBT/USD"]
[270, {"a": [["11857.60000", "0.00000000", "1596737246.143517"], ["11900.00000", "12.71653131", "1596737075.897027", "r"]], "c": "2653417152"}, "book-100", "XBT/USD"]
[270, {"b": [["11853.90000", "0.10000000", "1596737246.158596"]], "c": "2346397177"}, "book-100", "XBT/USD"]
[270, {"a": [["11856.30000", "0.78525000", "1596737246.159557"]], "c": "1288061839"}, "book-100", "XBT/USD"]
[270, {"a": [["11865.80000", "0.00000000", "1596737246.165497"], ["11900.00000", "12.71653131", "1596737075.897027", "r"]], "c": "1288061839"}, "book-100", "XBT/USD"]
[270, {"a": [["11856.50000", "0.49344391", "1596737246.176106"]], "c": "1949022266"}, "book-100", "XBT/USD"]
[270, {"b": [["11845.30000", "0.00000000", "1596737246.181255"], ["11800.80000", "1.51500000", "1596737133.991629", "r"]], "c": "1949022266"}, "book-100", "XBT/USD"]
[270, {"b": [["11849.50000", "0.15000000", "1596737246.222980"]], "c": "2098007793"}, "book-100", "XBT/USD"]
[270, {"a": [["11858.80000", "0.00000000", "1596737246.230272"], ["11900.00000", "12.71653131", "1596737075.897027", "r"]], "c": "2098007793"}, "book-100", "XBT/USD"]
[270, {"a": [["11858.60000", "0.00000000", "1596737246.230692"], ["11901.00000", "0.17065000", "1596737120.047779", "r"]], "c": "2098007793"}, "book-100", "XBT/USD"]
[270, {"a": [["11888.80000", "1.52578952", "1596737246.233546"]], "c": "2098007793"}, "book-100", "XBT/USD"]
[270, {"a": [["11858.90000", "0.00000000", "1596737246.238487"], ["11901.20000", "0.05455260", "1596737145.299909", "r"]], "c": "2098007793"}, "book-100", "XBT/USD"]
[270, {"b": [["11845.80000", "0.00000000", "1596737246.266258"], ["11800.00000", "17.03324285", "1596736993.942623", "r"]], "c": "2098007793"}, "book-100", "XBT/USD"]
[270, {"b": [["11839.10000", "0.00000000", "1596737246.276027"], ["11799.60000", "0.99110000", "1596737165.782615", "r"]], "c": "2098007793"}, "book-100", "XBT/USD"]
[270, {"a": [["11864.90000", "0.00000000", "1596737246.277510"], ["11901.40000", "1.90492467", "1596737138.167457", "r"]], "c": "2098007793"}, "book-100", "XBT/USD"]
[270, {"b": [["11852.30000", "0.00000000", "1596737246.287964"], ["11799.20000", "23.14040000", "1596736141.974806", "r"]], "c": "3401309918"}, "book-100", "XBT/USD"]
[270, {"b": [["11842.40000", "0.00000000", "1596737246.301732"], ["11799.00000", "0.17065000", "1596737216.062845", "r"]], "c": "3401309918"}, "book-100", "XBT/USD"]
[270, {"a": [["11854.60000", "2.00000000", "1596737246.309506"]], "c": "1314789421"}, "book-100", "XBT/USD"]
[270, {"a": [["11865.90000", "0.01800000", "1596737246.329666"]], "c": "1314789421"}, "book-100", "XBT/USD"]
[270, {"b": [["11840.10000", "0.02300000", "1596737246.352091"]], "c": "1314789421"}, "book-100", "XBT/USD"]
[270, {"a": [["11854.00000", "3.25493955", "1596737246.383964"]], "c": "2448579124"}, "book-100", "XBT/USD"]
[270, {"a": [["11857.40000", "0.00000000", "1596737246.388385"], ["11901.40000", "1.90492467", "1596737138.167457", "r"]], "c": "2736493747"}, "book-100", "XBT/USD"]
[270, {"a": [["11864.00000", "0.09250000", "1596737246.388813"]], "c": "2736493747"}, "book-100", "XBT/USD"]
[270, {"a": [["11868.60000", "0.00000000", "1596737246.389228"], ["11901.40000", "1.90492467", "1596737138.167457", "r"]], "c": "2736493747"}, "book-100", "XBT/USD"]
[270, {"a": [["11860.10000", "0.18392000", "1596737246.467750"]], "c": "2736493747"}, "book-100", "XBT/USD"]
[270, {"a": [["11854.00000", "3.74087904", "1596737246.501560"]], "c": "2395655556"}, "book-100", "XBT/USD"]
[270, {"b": [["11840.10000", "0.00000000", "1596737246.521693"], ["11799.00000", "0.17065000", "1596737216.062845", "r"]], "c": "2395655556"}, "book-100", "XBT/USD"]
[270, {"a": [["11860.40000", "0.00000000", "1596737246.544634"], ["11901.40000", "1.90492467", "1596737138.167457", "r"]], "c": "2395655556"}, "book-100", "XBT/USD"]
[270, {"a": [["11856.20000", "0.04750000", "1596737246.626597"]], "c": "1731871581"}, "book-100", "XBT/USD"]
[270, {"a": [["11886.60000", "0.50000000", "1596737246.672737"]], "c": "1731871581"}, "book-100", "XBT/USD"]
[270, {"b": [["11839.60000", "0.07004703", "1596737246.706550"]], "c": "1731871581"}, "book-100", "XBT/USD"]
[270, {"a": [["11859.40000", "3.53048296", "1596737246.811982"]], "c": "1731871581"}, "book-100", "XBT/USD"]
[270, {"a": [["11865.90000", "0.00000000", "1596737246.867545"], ["11901.20000", "0.05455260", "1596737145.299909", "r"]], "c": "1731871581"}, "book-100", "XBT/USD"]
[270, {"b": [["11839.60000", "0.04704703", "1596737246.867743"]], "c": "1731871581"}, "book-100", "XBT/USD"]
[270, {"b": [["11799.00000", "0.00000000", "1596737246.915619"], ["11798.60000", "18.30000000", "1596737089.559503", "r"]], "c": "1731871581"}, "book-100", "XBT/USD"]
[270, {"a": [["11864.90000", "0.01800000", "1596737246.918355"]], "c": "1731871581"}, "book-100", "XBT/USD"]
[270, {"b": [["11839.40000", "0.02300000", "1596737246.918674"]], "c": "1731871581"}, "book-100", "XBT/USD"]
[270, {"b": [["11852.60000", "0.00000000", "1596737247.001807"], ["11798.60000", "18.30000000", "1596737089.559503", "r"]], "c": "3914683552"}, "book-100", "XBT/USD"]
[270, {"a": [["11862.30000", "0.27100000", "1596737247.050309"]], "c": "3914683552"}, "book-100", "XBT/USD"]
[270, {"b": [["11848.20000", "6.63068843", "1596737247.085361"]], "c": "2538849174"}, "book-100", "XBT/USD"]
[270, {"a": [["11855.10000", "4.21700000", "1596737247.102361"]], "c": "3630050615"}, "book-100", "XBT/USD"]
[270, {"a": [["11864.70000", "0.00000000", "1596737247.117408"], ["11900.00000", "12.71653131", "1596737075.897027", "r"]], "c": "3630050615"}, "book-100", "XBT/USD"]
[270, {"a": [["11862.70000", "3.09530734", "1596737247.126836"]], "c": "3630050615"}, "book-100", "XBT/USD"]
[270, {"a": [["11854.00000", "4.37344401", "1596737247.169927"]], "c": "1693985991"}, "book-100", "XBT/USD"]
[270, {"a": [["11854.70000", "0.72870387", "1596737247.171180"]], "c": "832222788"}, "book-100", "XBT/USD"]
[270, {"b": [["11850.70000", "0.25304316", "1596737247.171266"]], "c": "4009668411"}, "book-100", "XBT/USD"]
[270, {"a": [["11855.00000", "0.84349672", "1596737247.171354"]], "c": "1772564887"}, "book-100", "XBT/USD"]
[270, {"a": [["11858.90000", "0.84332391", "1596737247.171478"]], "c": "1772564887"}, "book-100", "XBT/USD"]
[270, {"a": [["11854.10000", "0.63252896", "1596737247.171650"]], "c": "4146384150"}, "book-100", "XBT/USD"]
[270, {"b": [["11849.10000", "0.25304316", "1596737247.171769"]], "c": "372956962"}, "book-100", "XBT/USD"]
[270, {"b": [["11837.10000", "0.33739089", "1596737247.171898"]], "c": "372956962"}, "book-100", "XBT/USD"]
[270, {"b": [["11849.80000", "0.25302598", "1596737247.171983"]], "c": "592242944"}, "book-100", "XBT/USD"]
[270, {"a": [["11857.00000", "0.84337195", "1596737247.172077"]], "c": "592242944"}, "book-100", "XBT/USD"]
[270, {"b": [["11839.90000", "0.33730984", "1596737247.172654"]], "c": "592242944"}, "book-100", "XBT/USD"]
[270, {"a": [["11854.20000", "0.40000000", "1596737247.239999"]], "c": "425077786"}, "book-100", "XBT/USD"]
[270, {"b": [["11839.40000", "0.00000000", "1596737247.301563"], ["11800.80000", "1.51500000", "1596737133.991629", "r"]], "c": "425077786"}, "book-100", "XBT/USD"]
[270, {"a": [["11866.00000", "0.00000000", "1596737247.301897"], ["11899.00000", "2.81849664", "1596737063.692951", "r"]], "c": "425077786"}, "book-100", "XBT/USD"]
[270, {"a": [["11863.10000", "0.00000000", "1596737247.311697"], ["11899.10000", "7.82927162", "1596737145.805987", "r"]], "c": "425077786"}, "book-100", "XBT/USD"]
[270, {"b": [["11839.10000", "0.02300000", "1596737247.351572"]], "c": "425077786"}, "book-100", "XBT/USD"]
[270, {"a": [["11859.30000", "0.18392000", "1596737247.372136"]], "c": "425077786"}, "book-100", "XBT/USD"]
[270, {"a": [["11862.20000", "1.04962971", "1596737247.536774"]], "c": "425077786"}, "book-100", "XBT/USD"]
[270, {"b": [["11847.20000", "0.00000000", "1596737247.647020"], ["11800.80000", "1.51500000", "1596737133.991629", "r"]], "c": "425077786"}, "book-100", "XBT/USD"]
[270, {"a": [["11861.30000", "0.00000000", "1596737247.692586"], ["11899.00000", "2.81849664", "1596737063.692951", "r"]], "c": "425077786"}, "book-100", "XBT/USD"]
[270, {"b": [["11848.40000", "0.10000000", "1596737247.696587"]], "c": "4202348404"}, "book-100", "XBT/USD"]
[270, {"a": [["11854.00000", "5.07344401", "1596737247.697717"]], "c": "115919902"}, "book-100", "XBT/USD"]
[270, {"b": [["11848.40000", "0.00000000", "1596737247.747020"], ["11800.80000", "1.51500000", "1596737133.991629", "r"]], "c": "3854851952"}, "book-100", "XBT/USD"]
[270, {"b": [["11849.10000", "1.92704316", "1596737247.755700"]], "c": "796254891"}, "book-100", "XBT/USD"]
[270, {"a": [["11860.70000", "0.00000000", "1596737247.778584"], ["11899.10000", "7.82927162", "1596737145.805987", "r"]], "c": "796254891"}, "book-100", "XBT/USD"]
[270, {"a": [["11859.00000", "1.02875266", "1596737247.901204"]], "c": "796254891"}, "book-100", "XBT/USD"]
[270, {"a": [["11857.50000", "1.76800000", "1596737247.901559"]], "c": "796254891"}, "book-100", "XBT/USD"]
[270, {"a": [["11854.00000", "5.49344401", "1596737247.949933"]], "c": "4093615792"}, "book-100", "XBT/USD"]
[270, {"b": [["11846.40000", "0.75467522", "1596737248.053390"]], "c": "4093615792"}, "book-100", "XBT/USD"]
[270, {"a": [["11860.10000", "0.84617928", "1596737248.058731"]], "c": "4093615792"}, "book-100", "XBT/USD"]
[270, {"a": [["11864.60000", "7.30000000", "1596737248.163423"]], "c": "4093615792"}, "book-100", "XBT/USD"]
[270, {"a": [["11860.10000", "0.18392000", "1596737248.210283"]], "c": "4093615792"}, "book-100", "XBT/USD"]
[270, {"a": [["11859.30000", "0.83552665", "1596737248.571446"]], "c": "4093615792"}, "book-100", "XBT/USD"]
[270, {"b": [["11844.90000", "3.40069188", "1596737248.730664"]], "c": "4093615792"}, "book-100", "XBT/USD"]
[270, {"b": [["11843.60000", "0.65884157", "1596737248.752553"]], "c": "4093615792"}, "book-100", "XBT/USD"]
[270, {"b": [["11848.20000", "4.21500000", "1596737248.861323"]], "c": "3774272309"}, "book-100", "XBT/USD"]
[270, {"a": [["11889.20000", "0.00000000", "1596737248.902867"], ["11899.10000", "6.88744536", "1596737248.898748", "r"]], "c": "3774272309"}, "book-100", "XBT/USD"]
[270, {"a": [["11866.90000", "0.04440539", "1596737249.035720"]], "c": "3774272309"}, "book-100", "XBT/USD"]
[270, {"a": [["11861.00000", "0.00000000", "1596737249.036426"], ["11899.10000", "6.88744536", "1596737248.898748", "r"]], "c": "3774272309"}, "book-100", "XBT/USD"]
[270, {"a": [["11868.30000", "0.02799870", "1596737249.162890"]], "c": "3774272309"}, "book-100", "XBT/USD"]
[270, {"a": [["11866.90000", "0.00000000", "1596737249.166040"], ["11899.10000", "6.88744536", "1596737248.898748", "r"]], "c": "3774272309"}, "book-100", "XBT/USD"]
[270, {"a": [["11886.50000", "1.74294326", "1596737249.342518"]], "c": "3774272309"}, "book-100", "XBT/USD"]
[270, {"a": [["11892.10000", "0.94230755", "1596737249.353897"]], "c": "3774272309"}, "book-100", "XBT/USD"]
[270, {"a": [["11885.00000", "0.94287047", "1596737249.360133"]], "c": "3774272309"}, "book-100", "XBT/USD"]
[270, {"a": [["11873.20000", "6.50000000", "1596737249.382793"]], "c": "3774272309"}, "book-100", "XBT/USD"]
[270, {"a": [["11886.50000", "0.00000000", "1596737249.385885"], ["11899.00000", "2.81849664", "1596737063.692951", "r"]], "c": "3774272309"}, "book-100", "XBT/USD"]
[270, {"a": [["11879.10000", "0.68090000", "1596737249.386082"]], "c": "3774272309"}, "book-100", "XBT/USD"]
[270, {"a": [["11876.70000", "0.10908130", "1596737249.402322"]], "c": "3774272309"}, "book-100", "XBT/USD"]
[270, {"a": [["11883.60000", "3.00000000", "1596737249.459426"]], "c": "3774272309"}, "book-100", "XBT/USD"]
[270, {"a": [["11889.00000", "0.17065000", "1596737249.471824"]], "c": "3774272309"}, "book-100", "XBT/USD"]
[270, {"a": [["11874.20000", "0.69766442", "1596737249.641742"]], "c": "3774272309"}, "book-100", "XBT/USD"]
[270, {"a": [["11870.70000", "0.33231910", "1596737249.644724"]], "c": "3774272309"}, "book-100", "XBT/USD"]
[270, {"a": [["11894.40000", "1.92361029", "1596737249.645698"]], "c": "3774272309"}, "book-100", "XBT/USD"]
[270, {"a": [["11876.60000", "1.39504687", "1596737249.647238"]], "c": "3774272309"}, "book-100", "XBT/USD"]
[270, {"a": [["11882.50000", "1.75954219", "1596737249.647716"]], "c": "3774272309"}, "book-100", "XBT/USD"]
[270, {"a": [["11882.70000", "0.00000000", "1596737249.704053"], ["11897.00000", "0.02000000", "1596736823.323873", "r"]], "c": "3774272309"}, "book-100", "XBT/USD"]
[270, {"a": [["11888.70000", "0.00000000", "1596737249.706657"], ["11897.50000", "0.75800000", "1596737133.514960", "r"]], "c": "3774272309"}, "book-100", "XBT/USD"]
[270, {"a": [["11885.90000", "0.00000000", "1596737249.775850"], ["11897.80000", "1.58935366", "1596737150.426450", "r"]], "c": "3774272309"}, "book-100", "XBT/USD"]
[270, {"a": [["11894.40000", "5.18731448", "1596737250.318638"]], "c": "3774272309"}, "book-100", "XBT/USD"]
[270, {"a": [["11882.30000", "2.18264109", "1596737250.330656"]], "c": "3774272309"}, "book-100", "XBT/USD"]
[270, {"a": [["11884.90000", "3.26631298", "1596737250.333190"]], "c": "3774272309"}, "book-100", "XBT/USD"]
[270, {"a": [["11879.00000", "3.26793528", "1596737250.333359"]], "c": "3774272309"}, "book-100", "XBT/USD"]
[270, {"a": [["11876.50000", "0.54759874", "1596737251.232376"]], "c": "3774272309"}, "book-100", "XBT/USD"]
[270, {"a": [["11890.60000", "2.28413061", "1596737251.233620"]], "c": "3774272309"}, "book-100", "XBT/USD"]
[270, {"b": [["11842.00000", "0.97556000", "1596737251.551977"]], "c": "3774272309"}, "book-100", "XBT/USD"]
[270, {"a": [["11859.40000", "2.89039280", "1596737251.747138"]], "c": "3774272309"}, "book-100", "XBT/USD"]
[270, {"b": [["11838.20000", "0.07223524", "1596737251.804740"]], "c": "3774272309"}, "book-100", "XBT/USD"]
[270, {"b": [["11838.10000", "0.09700000", "1596737251.815445"]], "c": "3774272309"}, "book-100", "XBT/USD"]
[270, {"a": [["11888.80000", "0.46893963", "1596737251.929594"]], "c": "3774272309"}, "book-100", "XBT/USD"]
[270, {"a": [["11883.00000", "0.00000000", "1596737251.956090"], ["11896.30000", "7.54073617", "1596737012.826128", "r"]], "c": "3774272309"}, "book-100", "XBT/USD"]
[270, {"b": [["11838.20000", "0.00000000", "1596737251.974649"], ["11801.90000", "4.67249674", "1596736908.903243", "r"]], "c": "3774272309"}, "book-100", "XBT/USD"]
[270, {"b": [["11838.20000", "0.00816731", "1596737251.977289"]], "c": "3774272309"}, "book-100", "XBT/USD"]
[270, {"a": [["11858.30000", "2.14963239", "1596737251.992573"]], "c": "3774272309"}, "book-100", "XBT/USD"]
[270, {"b": [["11849.20000", "0.10000000", "1596737252.044564"]], "c": "1207726129"}, "book-100", "XBT/USD"]
[270, {"a": [["11879.00000", "3.79685252", "1596737252.236945"]], "c": "1207726129"}, "book-100", "XBT/USD"]
[270, {"a": [["11884.90000", "4.32362233", "1596737252.241194"]], "c": "1207726129"}, "book-100", "XBT/USD"]
[270, {"a": [["11887.20000", "0.00000000", "1596737252.313215"], ["11897.00000", "0.02000000", "1596736823.323873", "r"]], "c": "1207726129"}, "book-100", "XBT/USD"]
[270, {"a": [["11884.00000", "0.00000000", "1596737252.553600"], ["11897.50000", "0.75800000", "1596737133.514960", "r"]], "c": "1207726129"}, "book-100", "XBT/USD"]
[270, {"a": [["11880.50000", "0.76299496", "1596737252.554587"]], "c": "1207726129"}, "book-100", "XBT/USD"]
[270, {"a": [["11888.80000", "0.00000000", "1596737252.554819"], ["11897.80000", "1.58935366", "1596737150.426450", "r"]], "c": "1207726129"}, "book-100", "XBT/USD"]
[270, {"a": [["11886.40000", "0.00000000", "1596737252.561282"], ["11898.00000", "0.17065000", "1596737088.466567", "r"]], "c": "1207726129"}, "book-100", "XBT/USD"]
[270, {"a": [["11876.70000", "0.00000000", "1596737252.563102"], ["11898.30000", "6.46320506", "1596737141.628854", "r"]], "c": "1207726129"}, "book-100", "XBT/USD"]
[270, {"a": [["11880.50000", "0.00000000", "1596737252.565169"], ["11898.70000", "0.01000000", "1596737133.560066", "r"]], "c": "1207726129"}, "book-100", "XBT/USD"]
[270, {"b": [["11849.50000", "0.00000000", "1596737253.021009"], ["11802.00000", "7.50000000", "1596737194.335118", "r"]], "c": "3143043973"}, "book-100", "XBT/USD"]
[270, {"b": [["11845.10000", "0.00000000", "1596737253.049164"], ["11801.90000", "4.67249674", "1596736908.903243", "r"]], "c": "3143043973"}, "book-100", "XBT/USD"]
[270, {"a": [["11883.10000", "1.37814349", "1596737253.053293"]], "c": "3143043973"}, "book-100", "XBT/USD"]
[270, {"a": [["11874.80000", "0.10912407", "1596737253.053935"]], "c": "3143043973"}, "book-100", "XBT/USD"]
[270, {"b": [["11840.60000", "0.23800000", "1596737253.095858"]], "c": "3143043973"}, "book-100", "XBT/USD"]
[270, {"a": [["11876.40000", "0.00438186", "1596737253.121006"]], "c": "3143043973"}, "book-100", "XBT/USD"]
[270, {"b": [["11835.00000", "0.00426392", "1596737253.123241"]], "c": "3143043973"}, "book-100", "XBT/USD"]
[270, {"a": [["11877.10000", "0.20417778", "1596737253.166478"]], "c": "3143043973"}, "book-100", "XBT/USD"]
[270, {"a": [["11880.70000", "0.28576228", "1596737253.170841"]], "c": "3143043973"}, "book-100", "XBT/USD"]
[270, {"a": [["11885.50000", "0.46927700", "1596737253.180228"]], "c": "3143043973"}, "book-100", "XBT/USD"]
[270, {"a": [["11877.20000", "0.76371414", "1596737253.348612"]], "c": "3143043973"}, "book-100", "XBT/USD"]
[270, {"a": [["11882.70000", "3.09846298", "1596737253.471181"]], "c": "3143043973"}, "book-100", "XBT/USD"]
[270, {"b": [["11837.80000", "0.07223769", "1596737253.564388"]], "c": "3143043973"}, "book-100", "XBT/USD"]
[270, {"b": [["11838.20000", "0.00000000", "1596737253.566280"], ["11802.10000", "4.23653417", "1596737132.953878", "r"]], "c": "3143043973"}, "book-100", "XBT/USD"]
[270, {"a": [["11854.20000", "0.00000000", "1596737253.871419"], ["11896.30000", "7.54073617", "1596737012.826128", "r"]], "c": "1755159318"}, "book-100", "XBT/USD"]
[270, {"a": [["11854.00000", "4.79344401", "1596737253.922340"]], "c": "3305537827"}, "book-100", "XBT/USD"]
[270, {"a": [["11854.50000", "0.70000000", "1596737253.969109"]], "c": "2386363831"}, "book-100", "XBT/USD"]
[270, {"b": [["11849.20000", "0.25000000", "1596737253.997443"]], "c": "2714036426"}, "book-100", "XBT/USD"]
[270, {"b": [["11835.00000", "0.00000000", "1596737254.089147"], ["11802.00000", "7.50000000", "1596737194.335118", "r"]], "c": "2714036426"}, "book-100", "XBT/USD"]
[270, {"b": [["11849.20000", "0.10000000", "1596737254.405635"]], "c": "2386363831"}, "book-100", "XBT/USD"]
[270, {"b": [["11834.20000", "0.00435966", "1596737254.570516"]], "c": "2386363831"}, "book-100", "XBT/USD"]
[270, {"b": [["11826.50000", "0.00000000", "1596737254.851994"], ["11802.00000", "7.50000000", "1596737194.335118", "r"]], "c": "2386363831"}, "book-100", "XBT/USD"]
[270, {"a": [["11854.70000", "0.63249293", "1596737254.886611"]], "c": "655261151"}, "book-100", "XBT/USD"]
[270, {"b": [["11849.10000", "2.07704316", "1596737254.995485"]], "c": "298417569"}, "book-100", "XBT/USD"]
[270, {"a": [["11882.30000", "8.65575943", "1596737255.412535"]], "c": "298417569"}, "book-100", "XBT/USD"]
[271, [["11853.90000", "0.00200000", "1596737255.582023", "s", "l", ""]], "trade", "XBT/USD"]
[270, {"b": [["11853.90000", "0.09800000", "1596737255.582023"]], "c": "3538962284"}, "book-100", "XBT/USD"]
[270, {"a": [["11886.60000", "0.00000000", "1596737255.607430"], ["11896.30000", "7.54073617", "1596737012.826128", "r"]], "c": "3538962284"}, "book-100", "XBT/USD"]
[270, {"a": [["11854.70000", "0.72870387", "1596737255.615541"]], "c": "1562803328"}, "book-100", "XBT/USD"]
[270, {"a": [["11858.30000", "0.64963239", "1596737255.675288"]], "c": "1562803328"}, "book-100", "XBT/USD"]
[270, {"b": [["11834.20000", "0.00000000", "1596737255.706630"], ["11801.90000", "4.67249674", "1596736908.903243", "r"]], "c": "1562803328"}, "book-100", "XBT/USD"]
[270, {"a": [["11856.80000", "1.50000000", "1596737255.823809"]], "c": "1562803328"}, "book-100", "XBT/USD"]
[270, {"b": [["11853.90000", "0.00000000", "1596737255.963502"], ["11801.80000", "3.19470719", "1596736911.648608", "r"]], "c": "1782452672"}, "book-100", "XBT/USD"]
[270, {"a": [["11854.50000", "0.00000000", "1596737256.017351"], ["11896.30000", "7.54073617", "1596737012.826128", "r"]], "c": "1745960582"}, "book-100", "XBT/USD"]
[270, {"a": [["11854.00000", "4.29344401", "1596737256.019578"]], "c": "3066902419"}, "book-100", "XBT/USD"]
[270, {"b": [["11848.60000", "0.00000000", "1596737256.103854"], ["11800.80000", "1.51500000", "1596737133.991629", "r"]], "c": "1254048913"}, "book-100", "XBT/USD"]
[270, {"a": [["11854.00000", "3.54344401", "1596737256.118059"]], "c": "1270364896"}, "book-100", "XBT/USD"]
[270, {"b": [["11852.80000", "0.10000000", "1596737256.151023"]], "c": "1305239768"}, "book-100", "XBT/USD"]
[270, {"a": [["11853.90000", "0.70000000", "1596737256.262019"]], "c": "1151834395"}, "book-100", "XBT/USD"]
[270, {"a": [["11852.90000", "0.50000000", "1596737256.271698"]], "c": "11851721"}, "book-100", "XBT/USD"]
[270, {"a": [["11854.00000", "3.12344401", "1596737256.326584"]], "c": "1089556335"}, "book-100", "XBT/USD"]
[270, {"a": [["11853.80000", "0.00493954", "1596737256.336936"]], "c": "2334020344"}, "book-100", "XBT/USD"]
[270, {"a": [["11854.70000", "0.09621094", "1596737256.364038"]], "c": "3832133231"}, "book-100", "XBT/USD"]
[270, {"a": [["11854.10000", "0.00000000", "1596737256.364626"], ["11895.80000", "5.30000000", "1596737228.832641", "r"]], "c": "154941165"}, "book-100", "XBT/USD"]
[270, {"a": [["11868.30000", "0.00000000", "1596737256.390375"], ["11896.20000", "1.58439645", "1596737245.153887", "r"]], "c": "154941165"}, "book-100", "XBT/USD"]
[270, {"a": [["11854.00000", "3.11850446", "1596737256.400926"]], "c": "2011708415"}, "book-100", "XBT/USD"]
[270, {"a": [["11853.40000", "2.00000000", "1596737256.410335"]], "c": "948484929"}, "book-100", "XBT/USD"]
[270, {"a": [["11852.90000", "1.13262567", "1596737256.419846"]], "c": "3378355368"}, "book-100", "XBT/USD"]
[270, {"a": [["11853.10000", "0.63262567", "1596737256.420483"]], "c": "608923468"}, "book-100", "XBT/USD"]
[270, {"a": [["11852.90000", "3.13262567", "1596737256.421983"]], "c": "1472610286"}, "book-100", "XBT/USD"]
[270, {"a": [["11854.60000", "0.00000000", "1596737256.426607"], ["11895.80000", "5.30000000", "1596737228.832641", "r"]], "c": "996630989"}, "book-100", "XBT/USD"]
[270, {"a": [["11853.90000", "0.00000000", "1596737256.459942"], ["11896.20000", "1.58439645", "1596737245.153887", "r"]], "c": "310033125"}, "book-100", "XBT/USD"]
[270, {"a": [["11852.90000", "3.13756522", "1596737256.483222"]], "c": "3428350815"}, "book-100", "XBT/USD"]
[270, {"a": [["11854.00000", "2.63256497", "1596737256.507885"]], "c": "788393198"}, "book-100", "XBT/USD"]
[270, {"a": [["11853.00000", "0.70000000", "1596737256.509113"]], "c": "248413985"}, "book-100", "XBT/USD"]
[270, {"a": [["11853.40000", "0.00000000", "1596737256.538432"], ["11896.20000", "1.58439645", "1596737245.153887", "r"]], "c": "1508928961"}, "book-100", "XBT/USD"]
[270, {"b": [["11850.10000", "0.01466462", "1596737256.577385"]], "c": "1455675515"}, "book-100", "XBT/USD"]
[270, {"a": [["11853.00000", "0.00000000", "1596737256.607019"], ["11896.30000", "7.54073617", "1596737012.826128", "r"]], "c": "4219541943"}, "book-100", "XBT/USD"]
[270, {"b": [["11849.20000", "0.27597549", "1596737256.707885"]], "c": "3533477821"}, "book-100", "XBT/USD"]
[270, {"a": [["11863.00000", "0.07332312", "1596737256.708071"]], "c": "3533477821"}, "book-100", "XBT/USD"]
[270, {"a": [["11864.60000", "7.47597549", "1596737256.764193"]], "c": "3533477821"}, "book-100", "XBT/USD"]
[270, {"b": [["11821.90000", "0.00000000", "1596737256.852513"], ["11801.80000", "3.19470719", "1596736911.648608", "r"]], "c": "3533477821"}, "book-100", "XBT/USD"]
[270, {"a": [["11881.50000", "0.73662303", "1596737256.857041"]], "c": "3533477821"}, "book-100", "XBT/USD"]
[270, {"b": [["11849.00000", "0.25000000", "1596737256.957383"]], "c": "895281567"}, "book-100", "XBT/USD"]
[270, {"a": [["11868.30000", "0.02799869", "1596737257.002732"]], "c": "895281567"}, "book-100", "XBT/USD"]
[270, {"a": [["11852.90000", "3.72772380", "1596737257.008228"]], "c": "3217203948"}, "book-100", "XBT/USD"]
[270, {"b": [["11821.50000", "0.73662303", "1596737257.008449"]], "c": "3217203948"}, "book-100", "XBT/USD"]
[270, {"a": [["11862.20000", "1.06429433", "1596737257.099593"]], "c": "3217203948"}, "book-100", "XBT/USD"]
[270, {"b": [["11849.50000", "0.07332312", "1596737257.099752"]], "c": "4064087852"}, "book-100", "XBT/USD"]
[270, {"a": [["11881.80000", "0.00000000", "1596737257.100163"], ["11895.80000", "5.30000000", "1596737228.832641", "r"]], "c": "4064087852"}, "book-100", "XBT/USD"]
[270, {"a": [["11884.40000", "0.50000000", "1596737257.131629"]], "c": "4064087852"}, "book-100", "XBT/USD"]
[270, {"b": [["11826.00000", "3.29206376", "1596737257.297042"]], "c": "4064087852"}, "book-100", "XBT/USD"]
[270, {"a": [["11853.20000", "0.42000000", "1596737258.317547"]], "c": "743797431"}, "book-100", "XBT/USD"]
[270, {"a": [["11853.80000", "0.00000000", "1596737258.387344"], ["11895.60000", "21.90000000", "1596737128.763374", "r"]], "c": "2207572375"}, "book-100", "XBT/USD"]
[270, {"b": [["11849.10000", "0.40304316", "1596737258.419779"]], "c": "1296443557"}, "book-100", "XBT/USD"]
[270, {"b": [["11849.20000", "0.17597549", "1596737258.434254"]], "c": "2437787990"}, "book-100", "XBT/USD"]
[270, {"b": [["11849.00000", "0.00000000", "1596737258.691873"], ["11802.00000", "7.50000000", "1596737194.335118", "r"]], "c": "2650929787"}, "book-100", "XBT/USD"]
[270, {"b": [["11843.80000", "0.42152894", "1596737258.724678"]], "c": "2650929787"}, "book-100", "XBT/USD"]
[270, {"b": [["11846.40000", "0.42167444", "1596737258.733666"]], "c": "2650929787"}, "book-100", "XBT/USD"]
[270, {"b": [["11842.90000", "0.69955449", "1596737258.936019"]], "c": "2650929787"}, "book-100", "XBT/USD"]
[270, {"b": [["11846.40000", "0.75469720", "1596737258.939786"]], "c": "2650929787"}, "book-100", "XBT/USD"]
[270, {"b": [["11848.10000", "0.67163776", "1596737259.134359"]], "c": "2650929787"}, "book-100", "XBT/USD"]
[270, {"b": [["11833.80000", "0.66800000", "1596737259.190647"]], "c": "2650929787"}, "book-100", "XBT/USD"]
[270, {"b": [["11835.90000", "0.00000000", "1596737259.191611"], ["11802.10000", "4.23653417", "1596737132.953878", "r"]], "c": "2650929787"}, "book-100", "XBT/USD"]
[270, {"a": [["11853.30000", "0.87920000", "1596737259.215310"]], "c": "1683643506"}, "book-100", "XBT/USD"]
[270, {"a": [["11861.10000", "0.00000000", "1596737259.236565"], ["11895.60000", "21.90000000", "1596737128.763374", "r"]], "c": "1683643506"}, "book-100", "XBT/USD"]
[270, {"b": [["11850.70000", "0.00000000", "1596737259.271371"], ["11802.00000", "7.50000000", "1596737194.335118", "r"]], "c": "400952962"}, "book-100", "XBT/USD"]
[270, {"b": [["11847.90000", "0.25305170", "1596737259.329585"]], "c": "400952962"}, "book-100", "XBT/USD"]
[270, {"a": [["11883.10000", "1.32585986", "1596737260.095602"]], "c": "400952962"}, "book-100", "XBT/USD"]
[270, {"b": [["11819.20000", "0.00000000", "1596737260.515629"], ["11802.00000", "7.50000000", "1596737194.335118", "r"]], "c": "400952962"}, "book-100", "XBT/USD"]
[270, {"b": [["11827.40000", "0.00000000", "1596737260.726360"], ["11801.90000", "4.67249674", "1596736908.903243", "r"]], "c": "400952962"}, "book-100", "XBT/USD"]
[270, {"a": [["11886.00000", "0.17065000", "1596737260.810109"]], "c": "400952962"}, "book-100", "XBT/USD"]
[270, {"a": [["11860.20000", "0.00000000", "1596737261.169699"], ["11895.60000", "21.90000000", "1596737128.763374", "r"]], "c": "400952962"}, "book-100", "XBT/USD"]
[270, {"b": [["11842.00000", "0.00000000", "1596737261.209198"], ["11801.80000", "3.19470719", "1596736911.648608", "r"]], "c": "400952962"}, "book-100", "XBT/USD"]
[270, {"b": [["11849.20000", "0.00000000", "1596737261.213944"], ["11800.80000", "1.51500000", "1596737133.991629", "r"]], "c": "1175595106"}, "book-100", "XBT/USD"]
[270, {"b": [["11848.40000", "0.10000000", "1596737261.273324"]], "c": "727531761"}, "book-100", "XBT/USD"]
[270, {"b": [["11803.70000", "2.21082455", "1596737261.274601"]], "c": "727531761"}, "book-100", "XBT/USD"]
[270, {"b": [["11804.10000", "0.00000000", "1596737261.280833"], ["11801.80000", "3.19470719", "1596736911.648608", "r"]], "c": "727531761"}, "book-100", "XBT/USD"]
[270, {"b": [["11848.40000", "0.00000000", "1596737261.322309"], ["11800.80000", "1.51500000", "1596737133.991629", "r"]], "c": "1175595106"}, "book-100", "XBT/USD"]
[270, {"a": [["11876.40000", "0.00000000", "1596737261.333675"], ["11895.80000", "5.30000000", "1596737228.832641", "r"]], "c": "1175595106"}, "book-100", "XBT/USD"]
[270, {"a": [["11858.40000", "0.84299376", "1596737261.414884"]], "c": "1175595106"}, "book-100", "XBT/USD"]
[270, {"b": [["11847.10000", "0.17597549", "1596737261.451174"]], "c": "1175595106"}, "book-100", "XBT/USD"]
[270, {"a": [["11852.90000", "4.12772380", "1596737261.580258"]], "c": "3767725640"}, "book-100", "XBT/USD"]
[270, {"b": [["11849.10000", "0.25304316", "1596737261.646648"]], "c": "1030529263"}, "book-100", "XBT/USD"]
[270, {"b": [["11849.50000", "0.00000000", "1596737261.711717"], ["11800.80000", "1.51500000", "1596737133.991629", "r"]], "c": "4139048158"}, "book-100", "XBT/USD"]
[270, {"a": [["11867.00000", "0.00000000", "1596737261.729388"], ["11895.80000", "5.30000000", "1596737228.832641", "r"]], "c": "4139048158"}, "book-100", "XBT/USD"]
[270, {"a": [["11853.20000", "0.00000000", "1596737261.749932"], ["11896.20000", "1.58439645", "1596737245.153887", "r"]], "c": "903817981"}, "book-100", "XBT/USD"]
[270, {"b": [["11842.60000", "1.76340000", "1596737261.762732"]], "c": "903817981"}, "book-100", "XBT/USD"]
[270, {"b": [["11849.80000", "0.00000000", "1596737261.769226"], ["11800.80000", "1.51500000", "1596737133.991629", "r"]], "c": "147491740"}, "book-100", "XBT/USD"]
[270, {"b": [["11848.10000", "0.25000000", "1596737261.769771"]], "c": "676982981"}, "book-100", "XBT/USD"]
[270, {"b": [["11839.30000", "1.55606000", "1596737261.774535"]], "c": "676982981"}, "book-100", "XBT/USD"]
[270, {"b": [["11850.10000", "0.00000000", "1596737261.777125"], ["11800.00000", "17.03324285", "1596736993.942623", "r"]], "c": "3163787851"}, "book-100", "XBT/USD"]
[270, {"b": [["11848.10000", "0.00000000", "1596737261.782844"], ["11799.60000", "0.99110000", "1596737165.782615", "r"]], "c": "1182567679"}, "book-100", "XBT/USD"]
[270, {"b": [["11847.70000", "0.15000000", "1596737261.789501"]], "c": "3764716607"}, "book-100", "XBT/USD"]
[270, {"a": [["11863.90000", "0.69367027", "1596737261.797019"]], "c": "3764716607"}, "book-100", "XBT/USD"]
[270, {"b": [["11846.90000", "0.25307091", "1596737261.838874"]], "c": "210708438"}, "book-100", "XBT/USD"]
[270, {"a": [["11856.20000", "0.00000000", "1596737261.841716"], ["11896.20000", "1.58439645", "1596737245.153887", "r"]], "c": "4280091798"}, "book-100", "XBT/USD"]
[270, {"b": [["11834.50000", "0.33742788", "1596737261.841846"]], "c": "4280091798"}, "book-100", "XBT/USD"]
[270, {"a": [["11864.00000", "0.00000000", "1596737261.842306"], ["11896.30000", "7.54073617", "1596737012.826128", "r"]], "c": "4280091798"}, "book-100", "XBT/USD"]
[270, {"b": [["11843.50000", "0.57112023", "1596737261.910217"]], "c": "4280091798"}, "book-100", "XBT/USD"]
[270, {"b": [["11847.40000", "0.07332312", "1596737261.913140"]], "c": "3118216324"}, "book-100", "XBT/USD"]
[270, {"b": [["11846.30000", "0.25000000", "1596737261.953541"]], "c": "3118216324"}, "book-100", "XBT/USD"]
[270, {"b": [["11841.50000", "0.00000000", "1596737261.957665"], ["11801.90000", "4.67249674", "1596736908.903243", "r"]], "c": "3118216324"}, "book-100", "XBT/USD"]
[270, {"b": [["11848.00000", "0.01466462", "1596737261.975344"]], "c": "1511570113"}, "book-100", "XBT/USD"]
[270, {"b": [["11846.40000", "0.42167444", "1596737261.976408"]], "c": "1511570113"}, "book-100", "XBT/USD"]
[270, {"b": [["11842.90000", "0.00000000", "1596737261.980739"], ["11801.90000", "4.67249674", "1596736908.903243", "r"]], "c": "1511570113"}, "book-100", "XBT/USD"]
[270, {"b": [["11847.10000", "0.00000000", "1596737261.982700"], ["11801.80000", "3.19470719", "1596736911.648608", "r"]], "c": "1680994745"}, "book-100", "XBT/USD"]
[270, {"a": [["11852.90000", "4.54772380", "1596737261.984574"]], "c": "897577802"}, "book-100", "XBT/USD"]
[270, {"b": [["11847.70000", "0.00000000", "1596737262.001113"], ["11800.80000", "1.51500000", "1596737133.991629", "r"]], "c": "2464350823"}, "book-100", "XBT/USD"]
[270, {"b": [["11843.60000", "0.54947411", "1596737262.017924"]], "c": "2464350823"}, "book-100", "XBT/USD"]
[270, {"a": [["11878.50000", "0.00000000", "1596737262.039710"], ["11897.00000", "0.02000000", "1596736823.323873", "r"]], "c": "2464350823"}, "book-100", "XBT/USD"]
[270, {"a": [["11882.00000", "0.00000000", "1596737262.041384"], ["11897.50000", "0.75800000", "1596737133.514960", "r"]], "c": "2464350823"}, "book-100", "XBT/USD"]
[270, {"b": [["11852.80000", "0.00000000", "1596737262.057362"], ["11800.00000", "17.03324285", "1596736993.942623", "r"]], "c": "1207782492"}, "book-100", "XBT/USD"]
[270, {"a": [["11854.60000", "0.04750000", "1596737262.078274"]], "c": "1461316228"}, "book-100", "XBT/USD"]
[270, {"a": [["11862.60000", "0.09250000", "1596737262.079851"]], "c": "1461316228"}, "book-100", "XBT/USD"]
[270, {"a": [["11852.90000", "4.04772380", "1596737262.111011"]], "c": "262593083"}, "book-100", "XBT/USD"]
[270, {"b": [["11847.00000", "0.61600000", "1596737262.125623"]], "c": "1442606175"}, "book-100", "XBT/USD"]
[270, {"a": [["11854.90000", "0.10300000", "1596737262.132527"]], "c": "2270420186"}, "book-100", "XBT/USD"]
[270, {"b": [["11845.60000", "0.00000000", "1596737262.138020"], ["11799.60000", "0.99110000", "1596737165.782615", "r"]], "c": "2270420186"}, "book-100", "XBT/USD"]
[270, {"b": [["11838.40000", "6.26614036", "1596737262.143905"]], "c": "2270420186"}, "book-100", "XBT/USD"]
[270, {"b": [["11840.80000", "0.10942644", "1596737262.146797"]], "c": "2270420186"}, "book-100", "XBT/USD"]
[270, {"b": [["11845.40000", "0.17597549", "1596737262.182350"]], "c": "2270420186"}, "book-100", "XBT/USD"]
[270, {"b": [["11846.30000", "0.00000000", "1596737262.201108"], ["11800.00000", "17.03324285", "1596736993.942623", "r"]], "c": "2270420186"}, "book-100", "XBT/USD"]
[270, {"b": [["11851.10000", "0.10000000", "1596737262.221004"]], "c": "4118212254"}, "book-100", "XBT/USD"]
[270, {"a": [["11861.50000", "0.00000000", "1596737262.251620"], ["11896.30000", "7.54073617", "1596737012.826128", "r"]], "c": "4118212254"}, "book-100", "XBT/USD"]
[270, {"a": [["11851.20000", "0.50000000", "1596737262.274882"]], "c": "3744972043"}, "book-100", "XBT/USD"]
[270, {"a": [["11859.30000", "0.18392000", "1596737262.276542"]], "c": "3744972043"}, "book-100", "XBT/USD"]
[270, {"b": [["11839.30000", "0.68090000", "1596737262.278834"]], "c": "3744972043"}, "book-100", "XBT/USD"]
[270, {"a": [["11853.50000", "4.20800000", "1596737262.288372"]], "c": "2982192606"}, "book-100", "XBT/USD"]
[270, {"a": [["11857.20000", "0.28399999", "1596737262.300854"]], "c": "2982192606"}, "book-100", "XBT/USD"]
[270, {"b": [["11843.90000", "0.10200000", "1596737262.303357"]], "c": "2982192606"}, "book-100", "XBT/USD"]
[270, {"a": [["11853.10000", "0.00000000", "1596737262.336131"], ["11895.80000", "5.30000000", "1596737228.832641", "r"]], "c": "2476953658"}, "book-100", "XBT/USD"]
[270, {"a": [["11854.00000", "2.00000000", "1596737262.340432"]], "c": "2498656244"}, "book-100", "XBT/USD"]
[270, {"a": [["11852.90000", "3.62772380", "1596737262.340910"]], "c": "3268557434"}, "book-100", "XBT/USD"]
[270, {"a": [["11851.20000", "0.50493954", "1596737262.347816"]], "c": "4047726377"}, "book-100", "XBT/USD"]
[270, {"b": [["11841.10000", "0.00000000", "1596737262.349572"], ["11800.80000", "1.51500000", "1596737133.991629", "r"]], "c": "4047726377"}, "book-100", "XBT/USD"]
[270, {"b": [["11846.80000", "0.25000000", "1596737262.361233"]], "c": "4047726377"}, "book-100", "XBT/USD"]
[270, {"b": [["11841.30000", "0.00000000", "1596737262.365530"], ["11800.80000", "1.51500000", "1596737133.991629", "r"]], "c": "4047726377"}, "book-100", "XBT/USD"]
[270, {"b": [["11841.40000", "0.42152894", "1596737262.369591"]], "c": "4047726377"}, "book-100", "XBT/USD"]
[270, {"a": [["11864.50000", "0.00000000", "1596737262.376738"], ["11896.20000", "1.58439645", "1596737245.153887", "r"]], "c": "4047726377"}, "book-100", "XBT/USD"]
[270, {"a": [["11855.10000", "0.00000000", "1596737262.382431"], ["11896.30000", "7.54073617", "1596737012.826128", "r"]], "c": "2030106807"}, "book-100", "XBT/USD"]
[270, {"b": [["11838.00000", "0.00000000", "1596737262.389356"], ["11800.00000", "17.03324285", "1596736993.942623", "r"]], "c": "2030106807"}, "book-100", "XBT/USD"]
[270, {"a": [["11874.20000", "0.00000000", "1596737262.409882"], ["11897.00000", "0.02000000", "1596736823.323873", "r"]], "c": "2030106807"}, "book-100", "XBT/USD"]
[270, {"a": [["11852.90000", "3.62278425", "1596737262.413318"]], "c": "1592262724"}, "book-100", "XBT/USD"]
[270, {"a": [["11851.20000", "2.50493954", "1596737262.442156"]], "c": "1012201363"}, "book-100", "XBT/USD"]
[270, {"a": [["11875.40000", "0.94372487", "1596737262.467642"]], "c": "1012201363"}, "book-100", "XBT/USD"]
[270, {"a": [["11879.00000", "4.74029138", "1596737262.468801"]], "c": "1012201363"}, "book-100", "XBT/USD"]
[270, {"b": [["11840.40000", "0.69970219", "1596737262.469851"]], "c": "1012201363"}, "book-100", "XBT/USD"]
[270, {"b": [["11843.90000", "0.43509306", "1596737262.473986"]], "c": "1012201363"}, "book-100", "XBT/USD"]
[270, {"a": [["11852.90000", "3.03262567", "1596737262.532821"]], "c": "2252942171"}, "book-100", "XBT/USD"]
[270, {"a": [["11873.10000", "0.69777512", "1596737262.626114"]], "c": "2252942171"}, "book-100", "XBT/USD"]
[270, {"b": [["11838.10000", "1.49667627", "1596737262.631059"]], "c": "2252942171"}, "book-100", "XBT/USD"]
[270, {"b": [["11832.20000", "2.19229588", "1596737262.648517"]], "c": "2252942171"}, "book-100", "XBT/USD"]
[270, {"b": [["11842.60000", "0.00000000", "1596737262.707431"], ["11800.80000", "1.51500000", "1596737133.991629", "r"]], "c": "2252942171"}, "book-100", "XBT/USD"]
[270, {"b": [["11837.30000", "0.94676238", "1596737262.739036"]], "c": "2252942171"}, "book-100", "XBT/USD"]
[270, {"b": [["11839.50000", "0.00000000", "1596737262.757158"], ["11800.80000", "1.51500000", "1596737133.991629", "r"]], "c": "2252942171"}, "book-100", "XBT/USD"]
[270, {"b": [["11839.00000", "2.29408646", "1596737262.769331"]], "c": "2252942171"}, "book-100", "XBT/USD"]
[270, {"b": [["11837.80000", "0.27710705", "1596737262.795419"]], "c": "2252942171"}, "book-100", "XBT/USD"]
[270, {"a": [["11851.20000", "2.95311140", "1596737262.856268"]], "c": "1031829262"}, "book-100", "XBT/USD"]
[270, {"b": [["11847.00000", "0.46600000", "1596737263.015125"]], "c": "3868901577"}, "book-100", "XBT/USD"]
[270, {"b": [["11846.10000", "0.15000000", "1596737263.102173"]], "c": "3868901577"}, "book-100", "XBT/USD"]
[270, {"b": [["11839.00000", "1.76340000", "1596737263.112977"]], "c": "3868901577"}, "book-100", "XBT/USD"]
[270, {"b": [["11836.20000", "0.00000000", "1596737263.113443"], ["11800.80000", "1.51500000", "1596737133.991629", "r"]], "c": "3868901577"}, "book-100", "XBT/USD"]
[270, {"b": [["11834.90000", "4.22694801", "1596737263.186822"]], "c": "3868901577"}, "book-100", "XBT/USD"]
[270, {"b": [["11839.00000", "0.00000000", "1596737263.189924"], ["11800.00000", "17.03324285", "1596736993.942623", "r"]], "c": "3868901577"}, "book-100", "XBT/USD"]
[270, {"b": [["11849.40000", "0.40000000", "1596737263.235064"]], "c": "485799555"}, "book-100", "XBT/USD"]
[270, {"b": [["11841.60000", "1.76340000", "1596737263.255497"]], "c": "485799555"}, "book-100", "XBT/USD"]
[270, {"b": [["11848.20000", "0.00000000", "1596737263.263143"], ["11800.80000", "1.51500000", "1596737133.991629", "r"]], "c": "1387311941"}, "book-100", "XBT/USD"]
[270, {"b": [["11829.10000", "1.06227261", "1596737263.300584"]], "c": "1387311941"}, "book-100", "XBT/USD"]
[270, {"b": [["11835.00000", "0.53087152", "1596737263.300692"]], "c": "1387311941"}, "book-100", "XBT/USD"]
[270, {"b": [["11821.50000", "0.00000000", "1596737263.322603"], ["11801.80000", "3.19470719", "1596736911.648608", "r"]], "c": "1387311941"}, "book-100", "XBT/USD"]
[270, {"a": [["11881.50000", "0.00000000", "1596737263.327433"], ["11896.30000", "7.54073617", "1596737012.826128", "r"]], "c": "1387311941"}, "book-100", "XBT/USD"]
[270, {"a": [["11881.10000", "0.73661412", "1596737263.329646"]], "c": "1387311941"}, "book-100", "XBT/USD"]
[270, {"a": [["11870.60000", "0.00000000", "1596737263.372599"], ["11896.30000", "7.54073617", "1596737012.826128", "r"]], "c": "1387311941"}, "book-100", "XBT/USD"]
[270, {"b": [["11820.90000", "0.73661412", "1596737263.398979"]], "c": "1387311941"}, "book-100", "XBT/USD"]
[270, {"a": [["11859.20000", "0.63631870", "1596737263.403643"]], "c": "1387311941"}, "book-100", "XBT/USD"]
[270, {"b": [["11839.10000", "0.00000000", "1596737263.458356"], ["11801.80000", "3.19470719", "1596736911.648608", "r"]], "c": "1387311941"}, "book-100", "XBT/USD"]
[270, {"a": [["11864.90000", "0.00000000", "1596737263.458836"], ["11896.30000", "7.54073617", "1596737012.826128", "r"]], "c": "1387311941"}, "book-100", "XBT/USD"]
[270, {"b": [["11838.10000", "1.51967627", "1596737263.509099"]], "c": "1387311941"}, "book-100", "XBT/USD"]
[270, {"a": [["11863.90000", "0.71167027", "1596737263.509713"]], "c": "1387311941"}, "book-100", "XBT/USD"]
[270, {"b": [["11845.00000", "0.31502714", "1596737263.532825"]], "c": "1387311941"}, "book-100", "XBT/USD"]
[270, {"a": [["11851.20000", "0.95311140", "1596737263.571921"]], "c": "861584153"}, "book-100", "XBT/USD"]
[270, {"a": [["11852.80000", "0.70000000", "1596737263.585156"]], "c": "4127916098"}, "book-100", "XBT/USD"]
[270, {"a": [["11861.90000", "0.04402697", "1596737263.665922"]], "c": "4127916098"}, "book-100", "XBT/USD"]
[270, {"a": [["11862.20000", "1.04962971", "1596737263.671157"]], "c": "4127916098"}, "book-100", "XBT/USD"]
[270, {"a": [["11863.00000", "0.00000000", "1596737263.798780"], ["11896.20000", "1.58439645", "1596737245.153887", "r"]], "c": "4127916098"}, "book-100", "XBT/USD"]
[270, {"b": [["11846.90000", "4.46307091", "1596737263.858689"]], "c": "2551952696"}, "book-100", "XBT/USD"]
[270, {"a": [["11860.00000", "0.01466462", "1596737263.860919"]], "c": "2551952696"}, "book-100", "XBT/USD"]
[270, {"a": [["11864.60000", "7.30000000", "1596737263.861493"]], "c": "2551952696"}, "book-100", "XBT/USD"]
[270, {"a": [["11851.20000", "1.37311140", "1596737263.963676"]], "c": "2404491173"}, "book-100", "XBT/USD"]
[270, {"a": [["11860.50000", "0.07332312", "1596737263.993416"]], "c": "2404491173"}, "book-100", "XBT/USD"]
[270, {"b": [["11845.70000", "0.13208058", "1596737263.999661"]], "c": "2404491173"}, "book-100", "XBT/USD"]
[270, {"a": [["11862.00000", "0.17597549", "1596737264.059459"]], "c": "2404491173"}, "book-100", "XBT/USD"]
[270, {"a": [["11851.90000", "0.09621094", "1596737264.071844"]], "c": "676656771"}, "book-100", "XBT/USD"]
[270, {"a": [["11854.70000", "0.00000000", "1596737264.099465"], ["11895.00000", "1.15425357", "1596737181.418147", "r"]], "c": "1075037320"}, "book-100", "XBT/USD"]
[270, {"a": [["11862.60000", "0.22458058", "1596737264.149525"]], "c": "1075037320"}, "book-100", "XBT/USD"]
[270, {"a": [["11851.20000", "2.00582518", "1596737264.201672"]], "c": "3952378413"}, "book-100", "XBT/USD"]
[270, {"a": [["11851.60000", "0.63271378", "1596737264.201818"]], "c": "2790453744"}, "book-100", "XBT/USD"]
[270, {"b": [["11843.30000", "0.00000000", "1596737264.264194"], ["11801.80000", "3.19470719", "1596736911.648608", "r"]], "c": "2790453744"}, "book-100", "XBT/USD"]
[270, {"a": [["11859.20000", "0.00000000", "1596737264.352871"], ["11895.00000", "1.15425357", "1596737181.418147", "r"]], "c": "2790453744"}, "book-100", "XBT/USD"]
[270, {"b": [["11824.80000", "0.19638346", "1596737264.373337"]], "c": "2790453744"}, "book-100", "XBT/USD"]
[270, {"a": [["11858.90000", "1.51381911", "1596737264.424187"]], "c": "2790453744"}, "book-100", "XBT/USD"]
[270, {"a": [["11875.30000", "0.16928186", "1596737264.532340"]], "c": "2790453744"}, "book-100", "XBT/USD"]
[270, {"a": [["11883.60000", "0.00000000", "1596737264.701618"], ["11895.60000", "21.90000000", "1596737128.763374", "r"]], "c": "2790453744"}, "book-100", "XBT/USD"]
[270, {"a": [["11851.20000", "1.55765332", "1596737264.819919"]], "c": "2012916460"}, "book-100", "XBT/USD"]
[270, {"a": [["11862.00000", "0.00000000", "1596737264.987425"], ["11895.80000", "5.30000000", "1596737228.832641", "r"]], "c": "2012916460"}, "book-100", "XBT/USD"]
[270, {"a": [["11863.60000", "0.17597549", "1596737265.211619"]], "c": "2012916460"}, "book-100", "XBT/USD"]
[270, {"a": [["11884.40000", "0.00000000", "1596737265.336728"], ["11895.80000", "5.30000000", "1596737228.832641", "r"]], "c": "2012916460"}, "book-100", "XBT/USD"]
[270, {"a": [["11872.60000", "0.00000000", "1596737265.893849"], ["11896.20000", "1.58439645", "1596737245.153887", "r"]], "c": "2012916460"}, "book-100", "XBT/USD"]
[270, {"a": [["11862.60000", "0.09250000", "1596737265.970730"]], "c": "2012916460"}, "book-100", "XBT/USD"]
[270, {"a": [["11869.00000", "6.42833361", "1596737265.978367"]], "c": "2012916460"}, "book-100", "XBT/USD"]
[270, {"b": [["11846.90000", "4.21000000", "1596737265.985822"]], "c": "3384040493"}, "book-100", "XBT/USD"]
[270, {"a": [["11851.60000", "0.00000000", "1596737265.986290"], ["11896.30000", "7.54073617", "1596737012.826128", "r"]], "c": "2222075888"}, "book-100", "XBT/USD"]
[270, {"a": [["11851.20000", "0.92493954", "1596737266.001326"]], "c": "3229600798"}, "book-100", "XBT/USD"]
[270, {"b": [["11847.90000", "0.00000000", "1596737266.003565"], ["11801.80000", "3.19470719", "1596736911.648608", "r"]], "c": "3377309707"}, "book-100", "XBT/USD"]
[270, {"a": [["11860.50000", "0.00000000", "1596737266.053925"], ["11897.00000", "0.02000000", "1596736823.323873", "r"]], "c": "3377309707"}, "book-100", "XBT/USD"]
[270, {"a": [["11851.20000", "1.95493954", "1596737266.083519"]], "c": "833917043"}, "book-100", "XBT/USD"]
[270, {"a": [["11863.90000", "0.69367027", "1596737266.146466"]], "c": "833917043"}, "book-100", "XBT/USD"]
[270, {"b": [["11851.10000", "0.38362471", "1596737266.167786"]], "c": "3956258373"}, "book-100", "XBT/USD"]
[270, {"a": [["11864.30000", "0.13207909", "1596737266.168973"]], "c": "3956258373"}, "book-100", "XBT/USD"]
[270, {"a": [["11864.90000", "0.01800000", "1596737266.210439"]], "c": "3956258373"}, "book-100", "XBT/USD"]
[270, {"a": [["11861.80000", "0.07332312", "1596737266.250405"]], "c": "3956258373"}, "book-100", "XBT/USD"]
[270, {"a": [["11856.80000", "0.00000000", "1596737266.295121"], ["11896.20000", "1.58439645", "1596737245.153887", "r"]], "c": "3956258373"}, "book-100", "XBT/USD"]
[270, {"b": [["11838.10000", "1.49667627", "1596737266.296767"]], "c": "3956258373"}, "book-100", "XBT/USD"]
[270, {"b": [["11839.10000", "0.02300000", "1596737266.344595"]], "c": "3956258373"}, "book-100", "XBT/USD"]
[270, {"b": [["11846.10000", "0.00000000", "1596737266.379021"], ["11801.80000", "3.19470719", "1596736911.648608", "r"]], "c": "3956258373"}, "book-100", "XBT/USD"]
[270, {"a": [["11855.80000", "1.50000000", "1596737266.448505"]], "c": "3956258373"}, "book-100", "XBT/USD"]
[270, {"a": [["11865.20000", "2.00000000", "1596737266.591439"]], "c": "3956258373"}, "book-100", "XBT/USD"]
[270, {"a": [["11882.40000", "0.50000000", "1596737266.876498"]], "c": "3956258373"}, "book-100", "XBT/USD"]
[270, {"b": [["11848.50000", "1.72863300", "1596737266.987220"]], "c": "3955353043"}, "book-100", "XBT/USD"]
[270, {"a": [["11857.50000", "0.08900000", "1596737266.996015"]], "c": "3955353043"}, "book-100", "XBT/USD"]
[270, {"a": [["11856.90000", "1.68600000", "1596737267.009869"]], "c": "3955353043"}, "book-100", "XBT/USD"]
[270, {"b": [["11848.50000", "0.05063300", "1596737267.107893"]], "c": "3956258373"}, "book-100", "XBT/USD"]
[270, {"b": [["11848.90000", "0.25306569", "1596737267.206856"]], "c": "4149029178"}, "book-100", "XBT/USD"]
[270, {"a": [["11853.30000", "1.51182675", "1596737267.230311"]], "c": "242429887"}, "book-100", "XBT/USD"]
[270, {"b": [["11851.10000", "0.78336831", "1596737267.306069"]], "c": "859753373"}, "book-100", "XBT/USD"]
[270, {"b": [["11839.70000", "0.97356000", "1596737267.509771"]], "c": "859753373"}, "book-100", "XBT/USD"]
[270, {"a": [["11866.30000", "0.84355232", "1596737267.617551"]], "c": "859753373"}, "book-100", "XBT/USD"]
[270, {"a": [["11851.20000", "1.53493954", "1596737267.619102"]], "c": "451211492"}, "book-100", "XBT/USD"]
[270, {"b": [["11850.20000", "0.25305070", "1596737267.633213"]], "c": "1209971417"}, "book-100", "XBT/USD"]
[270, {"a": [["11861.90000", "0.00000000", "1596737267.701347"], ["11894.70000", "0.30000000", "1596737103.373511", "r"]], "c": "1209971417"}, "book-100", "XBT/USD"]
[270, {"b": [["11834.60000", "0.00423675", "1596737267.729338"]], "c": "1209971417"}, "book-100", "XBT/USD"]
[270, {"b": [["11838.10000", "0.09700000", "1596737267.767338"]], "c": "1209971417"}, "book-100", "XBT/USD"]
[270, {"b": [["11843.90000", "0.10200000", "1596737267.787616"]], "c": "1209971417"}, "book-100", "XBT/USD"]
[270, {"b": [["11840.40000", "0.00000000", "1596737267.808576"], ["11802.10000", "4.23653417", "1596737132.953878", "r"]], "c": "1209971417"}, "book-100", "XBT/USD"]
[270, {"b": [["11848.50000", "1.73263300", "1596737267.845004"]], "c": "1862015421"}, "book-100", "XBT/USD"]
[270, {"a": [["11856.90000", "0.00000000", "1596737267.850300"], ["11895.00000", "1.15425357", "1596737181.418147", "r"]], "c": "1862015421"}, "book-100", "XBT/USD"]
[270, {"b": [["11845.50000", "0.15000000", "1596737267.899374"]], "c": "1862015421"}, "book-100", "XBT/USD"]
[270, {"a": [["11863.40000", "0.04402807", "1596737267.902190"]], "c": "1862015421"}, "book-100", "XBT/USD"]
[270, {"b": [["11834.90000", "0.94660107", "1596737267.926492"]], "c": "1862015421"}, "book-100", "XBT/USD"]
[270, {"b": [["11837.30000", "0.00000000", "1596737267.937407"], ["11802.10000", "4.23653417", "1596737132.953878", "r"]], "c": "1862015421"}, "book-100", "XBT/USD"]
[270, {"b": [["11837.80000", "0.07223769", "1596737267.939328"]], "c": "1862015421"}, "book-100", "XBT/USD"]
[270, {"b": [["11835.00000", "0.00000000", "1596737267.986108"], ["11802.00000", "7.50000000", "1596737194.335118", "r"]], "c": "1862015421"}, "book-100", "XBT/USD"]
[270, {"b": [["11839.30000", "1.62731945", "1596737268.124573"]], "c": "1862015421"}, "book-100", "XBT/USD"]
[270, {"b": [["11837.30000", "0.53076346", "1596737268.174148"]], "c": "1862015421"}, "book-100", "XBT/USD"]
[270, {"b": [["11837.10000", "3.61659872", "1596737268.188717"]], "c": "1862015421"}, "book-100", "XBT/USD"]
[270, {"b": [["11839.60000", "0.25184287", "1596737268.214487"]], "c": "1862015421"}, "book-100", "XBT/USD"]
[270, {"b": [["11842.00000", "0.69951335", "1596737268.397279"]], "c": "1862015421"}, "book-100", "XBT/USD"]
[270, {"b": [["11845.40000", "0.50898147", "1596737268.403213"]], "c": "1862015421"}, "book-100", "XBT/USD"]
[270, {"b": [["11839.60000", "1.65115317", "1596737268.404645"]], "c": "1862015421"}, "book-100", "XBT/USD"]
[270, {"b": [["11848.50000", "0.05063300", "1596737268.482744"]], "c": "1209971417"}, "book-100", "XBT/USD"]
[270, {"b": [["11847.40000", "0.00000000", "1596737269.008078"], ["11802.10000", "4.23653417", "1596737132.953878", "r"]], "c": "1752753306"}, "book-100", "XBT/USD"]
[270, {"b": [["11848.00000", "0.00000000", "1596737269.047079"], ["11802.00000", "7.50000000", "1596737194.335118", "r"]], "c": "777170508"}, "book-100", "XBT/USD"]
[270, {"b": [["11848.60000", "0.01466462", "1596737269.245442"]], "c": "2529903906"}, "book-100", "XBT/USD"]
[270, {"b": [["11848.00000", "0.07332312", "1596737269.245532"]], "c": "2173810397"}, "book-100", "XBT/USD"]
[270, {"a": [["11853.30000", "0.63262675", "1596737269.349236"]], "c": "584721440"}, "book-100", "XBT/USD"]
[270, {"b": [["11842.10000", "0.96214000", "1596737269.350245"]], "c": "584721440"}, "book-100", "XBT/USD"]
[270, {"a": [["11852.90000", "2.63262567", "1596737269.578573"]], "c": "293910392"}, "book-100", "XBT/USD"]
[270, {"b": [["11845.40000", "0.33300598", "1596737269.648991"]], "c": "293910392"}, "book-100", "XBT/USD"]
[270, {"b": [["11846.60000", "0.17597549", "1596737269.978487"]], "c": "293910392"}, "book-100", "XBT/USD"]
[270, {"a": [["11880.80000", "0.73665205", "1596737269.979442"]], "c": "293910392"}, "book-100", "XBT/USD"]
[270, {"b": [["11820.90000", "0.00000000", "1596737269.981237"], ["11803.60000", "3.21918392", "1596737239.027602", "r"]], "c": "293910392"}, "book-100", "XBT/USD"]
[270, {"a": [["11881.10000", "0.00000000", "1596737269.987915"], ["11894.70000", "0.30000000", "1596737103.373511", "r"]], "c": "293910392"}, "book-100", "XBT/USD"]
[270, {"b": [["11818.80000", "0.73665205", "1596737269.988794"]], "c": "293910392"}, "book-100", "XBT/USD"]
[270, {"a": [["11854.90000", "0.00000000", "1596737269.993310"], ["11895.00000", "1.15425357", "1596737181.418147", "r"]], "c": "3310224343"}, "book-100", "XBT/USD"]
[270, {"b": [["11848.40000", "1.68600000", "1596737271.060472"]], "c": "2276263083"}, "book-100", "XBT/USD"]
[270, {"a": [["11856.80000", "1.68300000", "1596737271.081199"]], "c": "2276263083"}, "book-100", "XBT/USD"]
[270, {"b": [["11816.90000", "0.01331851", "1596737271.109354"]], "c": "2276263083"}, "book-100", "XBT/USD"]
[270, {"b": [["11845.00000", "0.27100000", "1596737271.116034"]], "c": "2276263083"}, "book-100", "XBT/USD"]
[270, {"b": [["11849.40000", "0.00000000", "1596737271.235078"], ["11803.70000", "2.21082455", "1596737261.274601", "r"]], "c": "1576474631"}, "book-100", "XBT/USD"]
[270, {"a": [["11876.50000", "0.00000000", "1596737271.331512"], ["11895.00000", "1.15425357", "1596737181.418147", "r"]], "c": "1576474631"}, "book-100", "XBT/USD"]
[270, {"a": [["11890.60000", "0.02324775", "1596737271.484142"]], "c": "1576474631"}, "book-100", "XBT/USD"]
[270, {"b": [["11845.90000", "0.04402566", "1596737271.661723"]], "c": "1576474631"}, "book-100", "XBT/USD"]
[270, {"a": [["11890.60000", "2.27905023", "1596737271.677657"]], "c": "1576474631"}, "book-100", "XBT/USD"]
[270, {"a": [["11885.10000", "3.00000000", "1596737271.786469"]], "c": "1576474631"}, "book-100", "XBT/USD"]
[270, {"a": [["11876.50000", "0.53337376", "1596737271.831518"]], "c": "1576474631"}, "book-100", "XBT/USD"]
[270, {"a": [["11851.20000", "3.53493954", "1596737271.959758"]], "c": "3319178550"}, "book-100", "XBT/USD"]
[270, {"b": [["11848.40000", "0.00000000", "1596737271.992803"], ["11803.70000", "2.21082455", "1596737261.274601", "r"]], "c": "766671630"}, "book-100", "XBT/USD"]
[270, {"b": [["11834.60000", "0.00000000", "1596737271.995159"], ["11803.60000", "3.21918392", "1596737239.027602", "r"]], "c": "766671630"}, "book-100", "XBT/USD"]
[270, {"b": [["11818.60000", "0.73665417", "1596737272.000984"]], "c": "766671630"}, "book-100", "XBT/USD"]
[270, {"b": [["11818.80000", "0.00000000", "1596737272.002558"], ["11803.60000", "3.21918392", "1596737239.027602", "r"]], "c": "766671630"}, "book-100", "XBT/USD"]
[270, {"b": [["11803.70000", "0.00000000", "1596737272.006982"], ["11803.30000", "0.95003592", "1596737228.202295", "r"]], "c": "766671630"}, "book-100", "XBT/USD"]
[270, {"a": [["11880.80000", "0.00000000", "1596737272.018716"], ["11894.70000", "0.30000000", "1596737103.373511", "r"]], "c": "766671630"}, "book-100", "XBT/USD"]
[270, {"a": [["11881.00000", "0.73665417", "1596737272.044596"]], "c": "766671630"}, "book-100", "XBT/USD"]
[270, {"b": [["11825.00000", "0.00000000", "1596737272.052961"], ["11802.10000", "4.23653417", "1596737132.953878", "r"]], "c": "766671630"}, "book-100", "XBT/USD"]
[270, {"a": [["11863.60000", "0.00000000", "1596737272.334443"], ["11894.70000", "0.30000000", "1596737103.373511", "r"]], "c": "766671630"}, "book-100", "XBT/USD"]
[270, {"a": [["11861.80000", "0.24929861", "1596737272.522599"]], "c": "766671630"}, "book-100", "XBT/USD"]
[270, {"a": [["11856.80000", "0.00000000", "1596737272.999708"], ["11895.00000", "1.15425357", "1596737181.418147", "r"]], "c": "766671630"}, "book-100", "XBT/USD"]
[270, {"a": [["11861.80000", "0.07332312", "1596737273.493190"]], "c": "766671630"}, "book-100", "XBT/USD"]
[270, {"b": [["11848.90000", "0.00000000", "1596737273.504883"], ["11802.00000", "7.50000000", "1596737194.335118", "r"]], "c": "917523047"}, "book-100", "XBT/USD"]
[270, {"a": [["11851.20000", "1.53493954", "1596737273.507429"]], "c": "2928801622"}, "book-100", "XBT/USD"]
[270, {"b": [["11846.80000", "0.00000000", "1596737273.554637"], ["11801.90000", "1.21262510", "1596737269.024963", "r"]], "c": "2518063388"}, "book-100", "XBT/USD"]
[270, {"b": [["11850.10000", "0.25303837", "1596737273.560896"]], "c": "2374343275"}, "book-100", "XBT/USD"]
[270, {"a": [["11863.30000", "0.17597549", "1596737273.847368"]], "c": "2374343275"}, "book-100", "XBT/USD"]
[270, {"b": [["11848.10000", "0.25000000", "1596737274.132718"]], "c": "1278191722"}, "book-100", "XBT/USD"]
[270, {"b": [["11848.10000", "0.00000000", "1596737274.511451"], ["11802.00000", "7.50000000", "1596737194.335118", "r"]], "c": "2374343275"}, "book-100", "XBT/USD"]
[270, {"b": [["11850.10000", "0.00000000", "1596737274.513012"], ["11801.90000", "1.21262510", "1596737269.024963", "r"]], "c": "2518063388"}, "book-100", "XBT/USD"]
[270, {"a": [["11869.00000", "0.18315000", "1596737274.797353"]], "c": "2518063388"}, "book-100", "XBT/USD"]
[270, {"b": [["11844.90000", "4.30727188", "1596737274.825542"]], "c": "2518063388"}, "book-100", "XBT/USD"]
[270, {"b": [["11826.10000", "0.00426621", "1596737274.853416"]], "c": "2518063388"}, "book-100", "XBT/USD"]
[270, {"b": [["11816.80000", "5.49346689", "1596737274.885430"]], "c": "2518063388"}, "book-100", "XBT/USD"]
[270, {"b": [["11847.40000", "0.25000000", "1596737274.888290"]], "c": "1192075429"}, "book-100", "XBT/USD"]
[270, {"a": [["11869.00000", "5.61208277", "1596737274.968627"]], "c": "1192075429"}, "book-100", "XBT/USD"]
[270, {"a": [["11882.40000", "0.00000000", "1596737275.089369"], ["11895.00000", "1.15425357", "1596737181.418147", "r"]], "c": "1192075429"}, "book-100", "XBT/USD"]
[270, {"b": [["11834.50000", "0.00000000", "1596737275.374706"], ["11802.10000", "4.23653417", "1596737132.953878", "r"]], "c": "1192075429"}, "book-100", "XBT/USD"]
[270, {"a": [["11866.30000", "0.00000000", "1596737275.661319"], ["11895.60000", "21.90000000", "1596737128.763374", "r"]], "c": "1192075429"}, "book-100", "XBT/USD"]
[270, {"b": [["11850.90000", "0.25303674", "1596737275.721748"]], "c": "3583097711"}, "book-100", "XBT/USD"]
[270, {"a": [["11855.10000", "0.63259082", "1596737275.722410"]], "c": "900912981"}, "book-100", "XBT/USD"]
[270, {"b": [["11846.70000", "0.33738233", "1596737275.728096"]], "c": "900912981"}, "book-100", "XBT/USD"]
[270, {"a": [["11882.40000", "0.50000000", "1596737276.259113"]], "c": "900912981"}, "book-100", "XBT/USD"]
[270, {"a": [["11860.10000", "0.00000000", "1596737276.580868"], ["11895.00000", "1.15425357", "1596737181.418147", "r"]], "c": "900912981"}, "book-100", "XBT/USD"]
[270, {"a": [["11862.70000", "0.00000000", "1596737276.664039"], ["11895.60000", "21.90000000", "1596737128.763374", "r"]], "c": "900912981"}, "book-100", "XBT/USD"]
[270, {"a": [["11864.20000", "2.40192655", "1596737276.848601"]], "c": "900912981"}, "book-100", "XBT/USD"]
[270, {"b": [["11844.90000", "3.40069188", "1596737277.076408"]], "c": "900912981"}, "book-100", "XBT/USD"]
[270, {"b": [["11845.40000", "0.00000000", "1596737277.231566"], ["11803.30000", "0.95003592", "1596737228.202295", "r"]], "c": "900912981"}, "book-100", "XBT/USD"]
[270, {"b": [["11803.30000", "0.00000000", "1596737277.389003"], ["11802.10000", "4.23653417", "1596737132.953878", "r"]], "c": "900912981"}, "book-100", "XBT/USD"]
[270, {"a": [["11857.20000", "1.95899999", "1596737277.393998"]], "c": "900912981"}, "book-100", "XBT/USD"]
[270, {"b": [["11804.80000", "0.00000000", "1596737277.411403"], ["11802.00000", "7.50000000", "1596737194.335118", "r"]], "c": "900912981"}, "book-100", "XBT/USD"]
[270, {"b": [["11848.60000", "0.00000000", "1596737277.421470"], ["11801.90000", "1.21262510", "1596737269.024963", "r"]], "c": "1266631304"}, "book-100", "XBT/USD"]
[270, {"b": [["11844.60000", "0.33375953", "1596737277.562772"]], "c": "1266631304"}, "book-100", "XBT/USD"]
[270, {"b": [["11846.60000", "0.00000000", "1596737277.572016"], ["11801.90000", "1.21262510", "1596737269.024963", "r"]], "c": "1266631304"}, "book-100", "XBT/USD"]
[270, {"a": [["11859.30000", "0.00000000", "1596737277.584282"], ["11895.60000", "21.90000000", "1596737128.763374", "r"]], "c": "1266631304"}, "book-100", "XBT/USD"]
[270, {"b": [["11848.00000", "0.00000000", "1596737277.617912"], ["11801.80000", "3.19470719", "1596736911.648608", "r"]], "c": "1324815071"}, "book-100", "XBT/USD"]
[270, {"a": [["11854.10000", "0.20451000", "1596737277.639244"]], "c": "2373876518"}, "book-100", "XBT/USD"]
[270, {"b": [["11848.80000", "1.67900000", "1596737277.664996"]], "c": "3529719790"}, "book-100", "XBT/USD"]
[270, {"a": [["11876.50000", "0.00000000", "1596737277.730343"], ["11895.60000", "21.90000000", "1596737128.763374", "r"]], "c": "3529719790"}, "book-100", "XBT/USD"]
[270, {"a": [["11870.70000", "0.00000000", "1596737277.844839"], ["11895.80000", "5.30000000", "1596737228.832641", "r"]], "c": "3529719790"}, "book-100", "XBT/USD"]
[270, {"a": [["11877.10000", "0.00000000", "1596737277.893417"], ["11896.20000", "1.58439645", "1596737245.153887", "r"]], "c": "3529719790"}, "book-100", "XBT/USD"]
[270, {"a": [["11880.70000", "0.00000000", "1596737277.904194"], ["11896.30000", "7.54073617", "1596737012.826128", "r"]], "c": "3529719790"}, "book-100", "XBT/USD"]
[270, {"a": [["11874.80000", "0.00000000", "1596737277.904872"], ["11897.00000", "0.02000000", "1596736823.323873", "r"]], "c": "3529719790"}, "book-100", "XBT/USD"]
[270, {"a": [["11876.50000", "0.53754801", "1596737277.912547"]], "c": "3529719790"}, "book-100", "XBT/USD"]
[270, {"a": [["11877.20000", "0.00000000", "1596737277.912682"], ["11897.00000", "0.02000000", "1596736823.323873", "r"]], "c": "3529719790"}, "book-100", "XBT/USD"]
[270, {"a": [["11868.80000", "0.33307901", "1596737278.041049"]], "c": "3529719790"}, "book-100", "XBT/USD"]
[270, {"b": [["11834.20000", "0.00434652", "1596737278.057885"]], "c": "3529719790"}, "book-100", "XBT/USD"]
[270, {"a": [["11890.90000", "0.00000000", "1596737278.132402"], ["11897.00000", "0.02000000", "1596736823.323873", "r"]], "c": "3529719790"}, "book-100", "XBT/USD"]
[270, {"a": [["11876.60000", "0.00000000", "1596737278.154978"], ["11897.50000", "0.75800000", "1596737133.514960", "r"]], "c": "3529719790"}, "book-100", "XBT/USD"]
[270, {"b": [["11826.10000", "0.00000000", "1596737278.163063"], ["11801.90000", "1.21262510", "1596737269.024963", "r"]], "c": "3529719790"}, "book-100", "XBT/USD"]
[270, {"a": [["11878.80000", "0.28576605", "1596737278.186706"]], "c": "3529719790"}, "book-100", "XBT/USD"]
[270, {"a": [["11875.30000", "0.93298716", "1596737278.222706"]], "c": "3529719790"}, "book-100", "XBT/USD"]
[270, {"a": [["11872.90000", "0.10912281", "1596737278.222848"]], "c": "3529719790"}, "book-100", "XBT/USD"]
[270, {"a": [["11876.50000", "0.00000000", "1596737278.379705"], ["11897.00000", "0.02000000", "1596736823.323873", "r"]], "c": "3529719790"}, "book-100", "XBT/USD"]
[270, {"a": [["11886.90000", "2.18180426", "1596737278.443388"]], "c": "3529719790"}, "book-100", "XBT/USD"]
[270, {"a": [["11881.00000", "0.00000000", "1596737278.494089"], ["11897.00000", "0.02000000", "1596736823.323873", "r"]], "c": "3529719790"}, "book-100", "XBT/USD"]
[270, {"b": [["11818.50000", "0.73666035", "1596737278.497886"]], "c": "3529719790"}, "book-100", "XBT/USD"]
[270, {"b": [["11818.60000", "0.00000000", "1596737278.498813"], ["11801.90000", "1.21262510", "1596737269.024963", "r"]], "c": "3529719790"}, "book-100", "XBT/USD"]
[270, {"a": [["11875.30000", "1.13716593", "1596737278.508135"]], "c": "3529719790"}, "book-100", "XBT/USD"]
[270, {"a": [["11881.50000", "0.73666035", "1596737278.510593"]], "c": "3529719790"}, "book-100", "XBT/USD"]
[270, {"b": [["11845.90000", "0.00000000", "1596737278.524610"], ["11801.80000", "3.19470719", "1596736911.648608", "r"]], "c": "3529719790"}, "book-100", "XBT/USD"]
[270, {"a": [["11875.10000", "1.39818968", "1596737278.557168"]], "c": "3529719790"}, "book-100", "XBT/USD"]
[270, {"a": [["11878.10000", "0.62083971", "1596737278.560861"]], "c": "3529719790"}, "book-100", "XBT/USD"]
[270, {"a": [["11859.00000", "0.84326266", "1596737278.580385"]], "c": "3529719790"}, "book-100", "XBT/USD"]
[270, {"b": [["11846.40000", "0.46570127", "1596737278.719806"]], "c": "3529719790"}, "book-100", "XBT/USD"]
[270, {"a": [["11893.10000", "6.46652346", "1596737279.111037"]], "c": "3529719790"}, "book-100", "XBT/USD"]
[270, {"a": [["11869.00000", "0.18315000", "1596737279.404765"]], "c": "3529719790"}, "book-100", "XBT/USD"]
[270, {"a": [["11853.30000", "0.00000000", "1596737279.442638"], ["11895.80000", "5.30000000", "1596737228.832641", "r"]], "c": "1573716228"}, "book-100", "XBT/USD"]
[270, {"a": [["11871.70000", "5.42865824", "1596737279.488145"]], "c": "1573716228"}, "book-100", "XBT/USD"]
[270, {"a": [["11852.50000", "0.63261305", "1596737279.502894"]], "c": "162659008"}, "book-100", "XBT/USD"]
[270, {"a": [["11852.80000", "0.00000000", "1596737279.563064"], ["11895.60000", "21.90000000", "1596737128.763374", "r"]], "c": "2245928724"}, "book-100", "XBT/USD"]
[270, {"a": [["11854.60000", "0.25189000", "1596737279.581747"]], "c": "2224434833"}, "book-100", "XBT/USD"]
[270, {"a": [["11852.40000", "0.70000000", "1596737279.614092"]], "c": "184571135"}, "book-100", "XBT/USD"]
[270, {"a": [["11854.10000", "0.00000000", "1596737279.876934"], ["11895.60000", "21.90000000", "1596737128.763374", "r"]], "c": "3922434816"}, "book-100", "XBT/USD"]
[270, {"a": [["11868.30000", "0.00000000", "1596737280.110748"], ["11895.80000", "5.30000000", "1596737228.832641", "r"]], "c": "3922434816"}, "book-100", "XBT/USD"]
[270, {"a": [["11868.30000", "0.04440539", "1596737280.113955"]], "c": "3922434816"}, "book-100", "XBT/USD"]
[270, {"a": [["11857.20000", "0.28399999", "1596737280.197470"]], "c": "3922434816"}, "book-100", "XBT/USD"]
[270, {"b": [["11844.60000", "1.00589953", "1596737280.323333"]], "c": "3922434816"}, "book-100", "XBT/USD"]
[270, {"a": [["11851.20000", "1.03493954", "1596737280.887193"]], "c": "924291605"}, "book-100", "XBT/USD"]
[270, {"a": [["11863.90000", "0.00000000", "1596737280.921084"], ["11895.80000", "5.30000000", "1596737228.832641", "r"]], "c": "924291605"}, "book-100", "XBT/USD"]
[270, {"b": [["11851.10000", "1.28336831", "1596737280.939805"]], "c": "3115664784"}, "book-100", "XBT/USD"]
[270, {"a": [["11853.50000", "0.00000000", "1596737280.969252"], ["11896.20000", "1.58439645", "1596737245.153887", "r"]], "c": "3877052184"}, "book-100", "XBT/USD"]
[270, {"a": [["11854.00000", "2.20439000", "1596737280.972103"]], "c": "3533081483"}, "book-100", "XBT/USD"]
[270, {"a": [["11851.20000", "1.53493954", "1596737280.992128"]], "c": "3214259049"}, "book-100", "XBT/USD"]
[270, {"a": [["11852.90000", "0.63262567", "1596737280.992630"]], "c": "1839830730"}, "book-100", "XBT/USD"]
[270, {"a": [["11867.00000", "0.69358064", "1596737280.992855"]], "c": "1839830730"}, "book-100", "XBT/USD"]
[270, {"a": [["11854.00000", "0.20439000", "1596737281.005637"]], "c": "2868979266"}, "book-100", "XBT/USD"]
[270, {"a": [["11863.30000", "0.00000000", "1596737281.014118"], ["11896.20000", "1.58439645", "1596737245.153887", "r"]], "c": "2868979266"}, "book-100", "XBT/USD"]
[270, {"a": [["11852.90000", "0.00000000", "1596737281.018674"], ["11896.30000", "7.54073617", "1596737012.826128", "r"]], "c": "1432985959"}, "book-100", "XBT/USD"]
[270, {"a": [["11852.50000", "0.00000000", "1596737281.020142"], ["11897.00000", "0.02000000", "1596736823.323873", "r"]], "c": "705353150"}, "book-100", "XBT/USD"]
[270, {"a": [["11852.40000", "0.00000000", "1596737281.021087"], ["11897.50000", "0.75800000", "1596737133.514960", "r"]], "c": "5490560"}, "book-100", "XBT/USD"]
[270, {"a": [["11854.60000", "0.04750000", "1596737281.034868"]], "c": "798821617"}, "book-100", "XBT/USD"]
[270, {"a": [["11854.00000", "0.00000000", "1596737281.036450"], ["11897.80000", "1.58935366", "1596737150.426450", "r"]], "c": "2811737971"}, "book-100", "XBT/USD"]
[270, {"b": [["11849.20000", "0.10000000", "1596737281.054106"]], "c": "1909558193"}, "book-100", "XBT/USD"]
[270, {"b": [["11847.40000", "0.00000000", "1596737281.062604"], ["11801.80000", "3.19470719", "1596736911.648608", "r"]], "c": "1255366623"}, "book-100", "XBT/USD"]
[270, {"a": [["11854.90000", "0.70000000", "1596737281.073095"]], "c": "1298405444"}, "book-100", "XBT/USD"]
[270, {"a": [["11857.50000", "0.00000000", "1596737281.087226"], ["11897.80000", "1.58935366", "1596737150.426450", "r"]], "c": "1298405444"}, "book-100", "XBT/USD"]
[270, {"b": [["11849.20000", "0.00000000", "1596737281.102304"], ["11800.80000", "3.72596341", "1596737272.019086", "r"]], "c": "4010275610"}, "book-100", "XBT/USD"]
[270, {"b": [["11837.10000", "3.27920783", "1596737281.133768"]], "c": "4010275610"}, "book-100", "XBT/USD"]
[270, {"b": [["11851.10000", "1.76336831", "1596737281.148323"]], "c": "4211294522"}, "book-100", "XBT/USD"]
[270, {"b": [["11849.30000", "0.10000000", "1596737281.148627"]], "c": "3425899034"}, "book-100", "XBT/USD"]
[270, {"b": [["11848.30000", "4.59607833", "1596737281.150824"]], "c": "3531635840"}, "book-100", "XBT/USD"]
[270, {"a": [["11856.30000", "0.00000000", "1596737281.153754"], ["11898.00000", "0.17065000", "1596737088.466567", "r"]], "c": "2055401993"}, "book-100", "XBT/USD"]
[270, {"a": [["11854.90000", "0.00000000", "1596737281.200938"], ["11898.70000", "0.01000000", "1596737133.560066", "r"]], "c": "2068420210"}, "book-100", "XBT/USD"]
[270, {"a": [["11851.20000", "1.03493954", "1596737281.201775"]], "c": "484329119"}, "book-100", "XBT/USD"]
[270, {"b": [["11848.30000", "4.84607833", "1596737281.219511"]], "c": "1222477884"}, "book-100", "XBT/USD"]
[270, {"a": [["11856.90000", "0.20438000", "1596737281.227152"]], "c": "214637116"}, "book-100", "XBT/USD"]
[270, {"a": [["11863.40000", "0.00000000", "1596737281.289105"], ["11898.70000", "0.01000000", "1596737133.560066", "r"]], "c": "214637116"}, "book-100", "XBT/USD"]
[270, {"a": [["11855.00000", "0.00000000", "1596737281.289331"], ["11898.80000", "2.21096341", "1596737272.002476", "r"]], "c": "3920797649"}, "book-100", "XBT/USD"]
[270, {"b": [["11849.30000", "0.00000000", "1596737281.290200"], ["11800.80000", "3.72596341", "1596737272.019086", "r"]], "c": "1502778691"}, "book-100", "XBT/USD"]
[270, {"b": [["11851.10000", "1.26336831", "1596737281.293276"]], "c": "3716390877"}, "book-100", "XBT/USD"]
[270, {"a": [["11851.20000", "0.00493954", "1596737281.308019"]], "c": "2210340160"}, "book-100", "XBT/USD"]
[270, {"b": [["11844.90000", "0.00000000", "1596737281.333960"], ["11800.00000", "17.03324285", "1596736993.942623", "r"]], "c": "2210340160"}, "book-100", "XBT/USD"]
[270, {"b": [["11849.20000", "0.10000000", "1596737281.341312"]], "c": "2226591825"}, "book-100", "XBT/USD"]
[270, {"b": [["11851.10000", "1.76336831", "1596737281.351115"]], "c": "10883791"}, "book-100", "XBT/USD"]
[270, {"b": [["11846.90000", "0.00000000", "1596737281.365790"], ["11800.00000", "17.03324285", "1596736993.942623", "r"]], "c": "448910910"}, "book-100", "XBT/USD"]
[270, {"a": [["11851.20000", "0.00000000", "1596737281.375649"], ["11899.00000", "2.81849664", "1596737063.692951", "r"]], "c": "629364864"}, "book-100", "XBT/USD"]
[270, {"a": [["11851.80000", "0.00493955", "1596737281.377772"]], "c": "826564833"}, "book-100", "XBT/USD"]
[270, {"b": [["11849.10000", "4.46004316", "1596737281.381041"]], "c": "3612370267"}, "book-100", "XBT/USD"]
[270, {"a": [["11855.70000", "0.70000000", "1596737281.392439"]], "c": "3567974958"}, "book-100", "XBT/USD"]
[270, {"a": [["11857.00000", "5.05737195", "1596737281.395768"]], "c": "961329772"}, "book-100", "XBT/USD"]
[270, {"b": [["11849.20000", "0.00000000", "1596737281.415243"], ["11799.60000", "0.99110000", "1596737165.782615", "r"]], "c": "1756172102"}, "book-100", "XBT/USD"]
[270, {"a": [["11864.30000", "0.00000000", "1596737281.423419"], ["11898.80000", "2.21096341", "1596737272.002476", "r"]], "c": "1756172102"}, "book-100", "XBT/USD"]
[270, {"a": [["11861.80000", "0.00000000", "1596737281.423505"], ["11899.00000", "2.81849664", "1596737063.692951", "r"]], "c": "1756172102"}, "book-100", "XBT/USD"]
[270, {"b": [["11845.70000", "0.00000000", "1596737281.427017"], ["11799.20000", "23.14040000", "1596736141.974806", "r"]], "c": "1756172102"}, "book-100", "XBT/USD"]
[270, {"b": [["11851.70000", "0.50000000", "1596737281.434750"]], "c": "3692758965"}, "book-100", "XBT/USD"]
[270, {"b": [["11851.10000", "1.26336831", "1596737281.435610"]], "c": "4209018913"}, "book-100", "XBT/USD"]
[270, {"a": [["11858.90000", "0.84332391", "1596737281.441334"]], "c": "4209018913"}, "book-100", "XBT/USD"]
[270, {"a": [["11855.70000", "0.00000000", "1596737281.443730"], ["11899.10000", "0.70000000", "1596737277.853255", "r"]], "c": "3646125482"}, "book-100", "XBT/USD"]
[270, {"a": [["11857.00000", "4.21400000", "1596737281.447896"]], "c": "3680138723"}, "book-100", "XBT/USD"]
[270, {"b": [["11850.20000", "0.00000000", "1596737281.450130"], ["11799.20000", "23.14040000", "1596736141.974806", "r"]], "c": "2361969703"}, "book-100", "XBT/USD"]
[270, {"a": [["11855.80000", "1.70438000", "1596737281.450364"]], "c": "1069471756"}, "book-100", "XBT/USD"]
