[270, {"a": [["11675.70000", "6.06919978", "1596666780.283083"]], "c": "2559528461"}, "book-100", "XBT/USD"]
[270, {"b": [["11645.90000", "2.24827012", "1596666780.288847"]], "c": "2559528461"}, "book-100", "XBT/USD"]
[270, {"a": [["11673.40000", "0.00000000", "1596666780.292251"], ["11715.30000", "6.10000000", "1596666635.445451", "r"]], "c": "2559528461"}, "book-100", "XBT/USD"]
[270, {"a": [["11680.50000", "0.69936398", "1596666780.298841"]], "c": "2559528461"}, "book-100", "XBT/USD"]
[270, {"a": [["11681.00000", "0.97090000", "1596666780.299921"]], "c": "2559528461"}, "book-100", "XBT/USD"]
[270, {"a": [["11669.40000", "0.41352978", "1596666780.321439"]], "c": "297771283"}, "book-100", "XBT/USD"]
[270, {"b": [["11635.80000", "1.49635613", "1596666780.329400"]], "c": "297771283"}, "book-100", "XBT/USD"]
[270, {"a": [["11667.50000", "0.00000000", "1596666780.344682"], ["11713.80000", "0.37309062", "1596666771.863547", "r"]], "c": "311270620"}, "book-100", "XBT/USD"]
[270, {"a": [["11672.00000", "0.00000000", "1596666780.365321"], ["11715.00000", "0.17085000", "1596666778.029752", "r"]], "c": "311270620"}, "book-100", "XBT/USD"]
[270, {"b": [["11651.30000", "1.66980000", "1596666780.399868"]], "c": "311270620"}, "book-100", "XBT/USD"]
[270, {"a": [["11674.90000", "0.00000000", "1596666780.399923"], ["11715.30000", "6.10000000", "1596666635.445451", "r"]], "c": "311270620"}, "book-100", "XBT/USD"]
[270, {"a": [["11685.40000", "2.39067470", "1596666780.403578"]], "c": "311270620"}, "book-100", "XBT/USD"]
[270, {"a": [["11679.60000", "0.00000000", "1596666780.414496"], ["11715.40000", "1.98115543", "1596666777.329829", "r"]], "c": "311270620"}, "book-100", "XBT/USD"]
[270, {"b": [["11649.30000", "0.00000000", "1596666780.420093"], ["11596.40000", "4.31168293", "1596666764.100846", "r"]], "c": "311270620"}, "book-100", "XBT/USD"]
[270, {"b": [["11611.90000", "1.06000000", "1596666780.430510"]], "c": "311270620"}, "book-100", "XBT/USD"]
[270, {"a": [["11674.80000", "0.75551922", "1596666780.446562"]], "c": "311270620"}, "book-100", "XBT/USD"]
[270, {"b": [["11656.60000", "6.95724552", "1596666780.482290"]], "c": "2085956877"}, "book-100", "XBT/USD"]
[270, {"a": [["11674.80000", "0.00000000", "1596666780.491691"], ["11715.40000", "1.98115543", "1596666777.329829", "r"]], "c": "2085956877"}, "book-100", "XBT/USD"]
[270, {"a": [["11675.60000", "1.23358408", "1596666780.538103"]], "c": "2085956877"}, "book-100", "XBT/USD"]
[270, {"b": [["11602.10000", "11.25550194", "1596666780.609892"]], "c": "2085956877"}, "book-100", "XBT/USD"]
[270, {"b": [["11646.10000", "3.54206893", "1596666780.618450"]], "c": "2085956877"}, "book-100", "XBT/USD"]
[270, {"b": [["11636.80000", "3.54489972", "1596666780.620699"]], "c": "2085956877"}, "book-100", "XBT/USD"]
[270, {"b": [["11613.60000", "3.55198121", "1596666780.634357"]], "c": "2085956877"}, "book-100", "XBT/USD"]
[270, {"a": [["11671.20000", "4.27800000", "1596666780.640411"]], "c": "2085956877"}, "book-100", "XBT/USD"]
[270, {"a": [["11680.60000", "0.66267095", "1596666780.668424"]], "c": "2085956877"}, "book-100", "XBT/USD"]
[270, {"a": [["11675.60000", "0.47806486", "1596666780.691392"]], "c": "2085956877"}, "book-100", "XBT/USD"]
[270, {"a": [["11674.90000", "0.75551922", "1596666780.736524"]], "c": "2085956877"}, "book-100", "XBT/USD"]
[270, {"a": [["11676.40000", "0.00000000", "1596666780.767403"], ["11715.00000", "0.17085000", "1596666778.029752", "r"]], "c": "2085956877"}, "book-100", "XBT/USD"]
[270, {"b": [["11651.90000", "3.54030579", "1596666780.768626"]], "c": "2085956877"}, "book-100", "XBT/USD"]
[270, {"b": [["11624.20000", "1.99713250", "1596666780.768760"]], "c": "2085956877"}, "book-100", "XBT/USD"]
[270, {"a": [["11670.20000", "0.00000000", "1596666780.770945"], ["11715.30000", "6.10000000", "1596666635.445451", "r"]], "c": "2084082191"}, "book-100", "XBT/USD"]
[270, {"a": [["11679.10000", "0.00000000", "1596666780.776378"], ["11715.40000", "1.98115543", "1596666777.329829", "r"]], "c": "2084082191"}, "book-100", "XBT/USD"]
[270, {"b": [["11650.00000", "0.01692336", "1596666780.788646"]], "c": "2084082191"}, "book-100", "XBT/USD"]
[270, {"a": [["11715.00000", "0.00000000", "1596666780.849410"], ["11717.80000", "1.99812614", "1596666759.535617", "r"]], "c": "2084082191"}, "book-100", "XBT/USD"]
[270, {"a": [["11680.20000", "0.00000000", "1596666780.870714"], ["11718.00000", "0.17085000", "1596666772.517182", "r"]], "c": "2084082191"}, "book-100", "XBT/USD"]
[270, {"b": [["11656.50000", "0.85724552", "1596666780.877648"]], "c": "4001602248"}, "book-100", "XBT/USD"]
[270, {"b": [["11658.20000", "0.33897014", "1596666780.895649"]], "c": "3041062657"}, "book-100", "XBT/USD"]
[270, {"b": [["11625.20000", "3.54843693", "1596666780.900277"]], "c": "3041062657"}, "book-100", "XBT/USD"]
[270, {"b": [["11651.30000", "0.00000000", "1596666780.909770"], ["11602.00000", "1.06000000", "1596666760.274147", "r"]], "c": "3041062657"}, "book-100", "XBT/USD"]
[270, {"b": [["11658.90000", "13.04317130", "1596666780.912289"]], "c": "3623060451"}, "book-100", "XBT/USD"]
[270, {"a": [["11680.60000", "0.00000000", "1596666780.913851"], ["11718.50000", "24.30000000", "1596666641.380470", "r"]], "c": "3623060451"}, "book-100", "XBT/USD"]
[270, {"b": [["11650.00000", "0.00000000", "1596666780.923763"], ["11601.10000", "3.00166376", "1596666779.976375", "r"]], "c": "3623060451"}, "book-100", "XBT/USD"]
[270, {"b": [["11651.10000", "0.12229850", "1596666780.928706"]], "c": "3623060451"}, "book-100", "XBT/USD"]
[270, {"a": [["11676.10000", "0.42924049", "1596666780.954273"]], "c": "3623060451"}, "book-100", "XBT/USD"]
[270, {"b": [["11651.10000", "0.02329850", "1596666780.963472"]], "c": "3623060451"}, "book-100", "XBT/USD"]
[270, {"a": [["11669.40000", "0.00000000", "1596666780.969315"], ["11718.50000", "24.30000000", "1596666641.380470", "r"]], "c": "3507755729"}, "book-100", "XBT/USD"]
[270, {"a": [["11671.20000", "4.68148588", "1596666780.990073"]], "c": "1131031988"}, "book-100", "XBT/USD"]
[270, {"a": [["11674.90000", "0.00000000", "1596666781.021050"], ["11719.60000", "1.46521891", "1596666747.719598", "r"]], "c": "1131031988"}, "book-100", "XBT/USD"]
[270, {"a": [["11674.80000", "0.75551922", "1596666781.066084"]], "c": "1131031988"}, "book-100", "XBT/USD"]
[270, {"a": [["11668.10000", "0.41352978", "1596666781.115891"]], "c": "3656442681"}, "book-100", "XBT/USD"]
[270, {"a": [["11674.80000", "0.00000000", "1596666781.116829"], ["11718.50000", "24.30000000", "1596666641.380470", "r"]], "c": "3656442681"}, "book-100", "XBT/USD"]
[270, {"a": [["11672.80000", "0.09621094", "1596666781.141120"]], "c": "3656442681"}, "book-100", "XBT/USD"]
[270, {"b": [["11651.20000", "0.02329827", "1596666781.157859"]], "c": "3656442681"}, "book-100", "XBT/USD"]
[270, {"a": [["11674.90000", "0.75551922", "1596666781.162143"]], "c": "3656442681"}, "book-100", "XBT/USD"]
[270, {"a": [["11674.00000", "0.64577467", "1596666781.163024"]], "c": "3656442681"}, "book-100", "XBT/USD"]
[270, {"a": [["11689.70000", "2.10312776", "1596666781.163125"]], "c": "3656442681"}, "book-100", "XBT/USD"]
[270, {"a": [["11676.20000", "2.95924155", "1596666781.163298"]], "c": "3656442681"}, "book-100", "XBT/USD"]
[270, {"a": [["11687.50000", "0.85703289", "1596666781.231783"]], "c": "3656442681"}, "book-100", "XBT/USD"]
[270, {"a": [["11674.60000", "0.64266903", "1596666781.232152"]], "c": "3656442681"}, "book-100", "XBT/USD"]
[270, {"a": [["11679.90000", "0.66996743", "1596666781.233361"]], "c": "3656442681"}, "book-100", "XBT/USD"]
[270, {"a": [["11675.00000", "0.01821000", "1596666781.235196"]], "c": "3656442681"}, "book-100", "XBT/USD"]
[270, {"a": [["11681.60000", "0.98624000", "1596666781.235754"]], "c": "3656442681"}, "book-100", "XBT/USD"]
[270, {"b": [["11602.00000", "0.00000000", "1596666781.236883"], ["11601.10000", "3.00166376", "1596666779.976375", "r"]], "c": "3656442681"}, "book-100", "XBT/USD"]
[270, {"b": [["11658.00000", "9.99987003", "1596666781.239328"]], "c": "3986347267"}, "book-100", "XBT/USD"]
[270, {"a": [["11688.70000", "3.82915970", "1596666781.240265"]], "c": "3986347267"}, "book-100", "XBT/USD"]
[270, {"b": [["11649.40000", "0.00000000", "1596666781.240499"], ["11601.10000", "3.00166376", "1596666779.976375", "r"]], "c": "3986347267"}, "book-100", "XBT/USD"]
[270, {"a": [["11668.10000", "0.00000000", "1596666781.263174"], ["11713.80000", "0.37309062", "1596666771.863547", "r"]], "c": "2114564176"}, "book-100", "XBT/USD"]
[270, {"a": [["11678.10000", "1.36988661", "1596666781.293059"]], "c": "2114564176"}, "book-100", "XBT/USD"]
[270, {"b": [["11645.40000", "6.10000000", "1596666781.293407"]], "c": "2114564176"}, "book-100", "XBT/USD"]
[270, {"a": [["11701.50000", "0.00000000", "1596666781.299359"], ["11713.80000", "0.37309062", "1596666771.863547", "r"]], "c": "2114564176"}, "book-100", "XBT/USD"]
[270, {"a": [["11674.90000", "0.00000000", "1596666781.300947"], ["11715.30000", "6.10000000", "1596666635.445451", "r"]], "c": "2114564176"}, "book-100", "XBT/USD"]
[270, {"a": [["11676.10000", "0.00000000", "1596666781.303140"], ["11715.40000", "1.98115543", "1596666777.329829", "r"]], "c": "2114564176"}, "book-100", "XBT/USD"]
[270, {"a": [["11665.90000", "0.00000000", "1596666781.303461"], ["11717.80000", "1.99812614", "1596666759.535617", "r"]], "c": "1347517715"}, "book-100", "XBT/USD"]
[270, {"a": [["11693.00000", "0.00000000", "1596666781.305312"], ["11718.00000", "0.17085000", "1596666772.517182", "r"]], "c": "1347517715"}, "book-100", "XBT/USD"]
[270, {"a": [["11687.10000", "0.00000000", "1596666781.307947"], ["11718.50000", "24.30000000", "1596666641.380470", "r"]], "c": "1347517715"}, "book-100", "XBT/USD"]
[270, {"a": [["11670.90000", "1.50000000", "1596666781.308631"]], "c": "2761851798"}, "book-100", "XBT/USD"]
[270, {"a": [["11689.40000", "0.00000000", "1596666781.309486"], ["11718.50000", "24.30000000", "1596666641.380470", "r"]], "c": "2761851798"}, "book-100", "XBT/USD"]
[270, {"b": [["11654.90000", "1.61003885", "1596666781.309763"]], "c": "2761851798"}, "book-100", "XBT/USD"]
[270, {"a": [["11686.20000", "3.04013577", "1596666781.310995"]], "c": "2761851798"}, "book-100", "XBT/USD"]
[270, {"a": [["11686.20000", "2.31784912", "1596666781.314279"]], "c": "2761851798"}, "book-100", "XBT/USD"]
[270, {"a": [["11683.80000", "0.10320500", "1596666781.318764"]], "c": "2761851798"}, "book-100", "XBT/USD"]
[270, {"a": [["11683.80000", "0.00000000", "1596666781.318928"], ["11719.60000", "1.46521891", "1596666747.719598", "r"]], "c": "2761851798"}, "book-100", "XBT/USD"]
[270, {"a": [["11691.70000", "0.00000000", "1596666781.321224"], ["11719.70000", "3.50602221", "1596666743.346655", "r"]], "c": "2761851798"}, "book-100", "XBT/USD"]
[270, {"b": [["11651.10000", "0.00000000", "1596666781.321700"], ["11601.00000", "0.17085000", "1596666771.979393", "r"]], "c": "2761851798"}, "book-100", "XBT/USD"]
[270, {"a": [["11686.20000", "1.41990927", "1596666781.322215"]], "c": "2761851798"}, "book-100", "XBT/USD"]
[270, {"a": [["11691.40000", "3.52743743", "1596666781.322845"]], "c": "2761851798"}, "book-100", "XBT/USD"]
[270, {"a": [["11687.20000", "0.00000000", "1596666781.326423"], ["11721.00000", "0.80800000", "1596666761.523908", "r"]], "c": "2761851798"}, "book-100", "XBT/USD"]
[270, {"a": [["11689.00000", "0.89812376", "1596666781.335160"]], "c": "2761851798"}, "book-100", "XBT/USD"]
[270, {"a": [["11689.00000", "0.00000000", "1596666781.335657"], ["11721.70000", "2.47549182", "1596666772.357495", "r"]], "c": "2761851798"}, "book-100", "XBT/USD"]
[270, {"a": [["11711.20000", "20.00000000", "1596666781.337735"]], "c": "2761851798"}, "book-100", "XBT/USD"]
[270, {"b": [["11636.90000", "7.10502766", "1596666781.338176"]], "c": "2761851798"}, "book-100", "XBT/USD"]
[270, {"a": [["11711.10000", "0.00000000", "1596666781.338281"], ["11722.10000", "7.70000000", "1596666696.315517", "r"]], "c": "2761851798"}, "book-100", "XBT/USD"]
[270, {"a": [["11680.40000", "0.00000000", "1596666781.340080"], ["11722.20000", "3.01549629", "1596666746.821117", "r"]], "c": "2761851798"}, "book-100", "XBT/USD"]
[270, {"a": [["11688.90000", "0.00000000", "1596666781.340818"], ["11722.80000", "2.99776021", "1596666772.637183", "r"]], "c": "2761851798"}, "book-100", "XBT/USD"]
[271, [["11659.00000", "0.98921523", "1596666781.341622", "b", "l", ""], ["11659.00000", "0.28869893", "1596666781.359104", "b", "l", ""]], "trade", "XBT/USD"]
[270, {"a": [["11659.00000", "0.56070000", "1596666781.341622"], ["11659.00000", "0.27200107", "1596666781.359104"]], "c": "3738923379"}, "book-100", "XBT/USD"]
[270, {"a": [["11686.20000", "0.00000000", "1596666781.365203"], ["11725.30000", "0.01286565", "1596666778.917799", "r"]], "c": "3738923379"}, "book-100", "XBT/USD"]
[270, {"a": [["11670.50000", "0.07440000", "1596666781.366504"]], "c": "284979979"}, "book-100", "XBT/USD"]
[270, {"a": [["11686.70000", "0.00000000", "1596666781.366572"], ["11725.30000", "0.01286565", "1596666778.917799", "r"]], "c": "284979979"}, "book-100", "XBT/USD"]
[270, {"a": [["11675.40000", "0.75551922", "1596666781.366729"]], "c": "284979979"}, "book-100", "XBT/USD"]
[270, {"a": [["11684.90000", "2.29920000", "1596666781.368011"]], "c": "284979979"}, "book-100", "XBT/USD"]
[270, {"a": [["11711.00000", "0.00000000", "1596666781.368661"], ["11722.80000", "2.99776021", "1596666772.637183", "r"]], "c": "284979979"}, "book-100", "XBT/USD"]
[270, {"b": [["11651.10000", "0.02329827", "1596666781.369650"]], "c": "284979979"}, "book-100", "XBT/USD"]
[270, {"b": [["11651.20000", "0.00000000", "1596666781.370833"], ["11601.10000", "3.00166376", "1596666779.976375", "r"]], "c": "284979979"}, "book-100", "XBT/USD"]
[270, {"a": [["11679.00000", "0.00000000", "1596666781.371132"], ["11725.30000", "0.01286565", "1596666778.917799", "r"]], "c": "284979979"}, "book-100", "XBT/USD"]
[270, {"a": [["11680.30000", "0.00000000", "1596666781.373175"], ["11725.40000", "1.99666304", "1596666743.823724", "r"]], "c": "284979979"}, "book-100", "XBT/USD"]
[270, {"a": [["11673.30000", "0.70560000", "1596666781.378702"]], "c": "284979979"}, "book-100", "XBT/USD"]
[270, {"b": [["11648.50000", "7.09795222", "1596666781.380483"]], "c": "284979979"}, "book-100", "XBT/USD"]
[270, {"a": [["11675.50000", "0.00000000", "1596666781.383603"], ["11725.40000", "1.99666304", "1596666743.823724", "r"]], "c": "284979979"}, "book-100", "XBT/USD"]
[270, {"a": [["11681.70000", "0.50000000", "1596666781.394902"]], "c": "284979979"}, "book-100", "XBT/USD"]
[270, {"a": [["11665.60000", "0.00000000", "1596666781.404922"], ["11725.40000", "1.99666304", "1596666743.823724", "r"]], "c": "2831303080"}, "book-100", "XBT/USD"]
[270, {"a": [["11675.40000", "0.00000000", "1596666781.417926"], ["11725.50000", "1.06000000", "1596666771.224459", "r"]], "c": "2831303080"}, "book-100", "XBT/USD"]
[270, {"b": [["11658.00000", "0.00000000", "1596666781.422220"], ["11601.10000", "3.00166376", "1596666779.976375", "r"]], "c": "1580743956"}, "book-100", "XBT/USD"]
[270, {"b": [["11658.90000", "13.39217130", "1596666781.423503"]], "c": "1655966194"}, "book-100", "XBT/USD"]
[270, {"a": [["11702.80000", "1.11290000", "1596666781.426679"]], "c": "1655966194"}, "book-100", "XBT/USD"]
[270, {"b": [["11658.90000", "18.69217130", "1596666781.432041"]], "c": "1499812821"}, "book-100", "XBT/USD"]
[270, {"b": [["11653.60000", "0.50000000", "1596666781.437309"]], "c": "1499812821"}, "book-100", "XBT/USD"]
[270, {"b": [["11639.60000", "0.00000000", "1596666781.441292"], ["11601.10000", "3.00166376", "1596666779.976375", "r"]], "c": "1499812821"}, "book-100", "XBT/USD"]
[270, {"a": [["11693.80000", "0.00000000", "1596666781.442339"], ["11725.50000", "1.06000000", "1596666771.224459", "r"]], "c": "1499812821"}, "book-100", "XBT/USD"]
[270, {"a": [["11669.80000", "0.41352978", "1596666781.449074"]], "c": "1444240016"}, "book-100", "XBT/USD"]
[270, {"b": [["11658.90000", "13.39217130", "1596666781.510631"]], "c": "1841561783"}, "book-100", "XBT/USD"]
[270, {"b": [["11647.00000", "0.59486365", "1596666781.533487"]], "c": "1841561783"}, "book-100", "XBT/USD"]
[270, {"b": [["11612.50000", "0.00857706", "1596666781.571939"]], "c": "1841561783"}, "book-100", "XBT/USD"]
[270, {"a": [["11670.00000", "0.07830000", "1596666781.579202"]], "c": "3174765270"}, "book-100", "XBT/USD"]
[270, {"a": [["11695.20000", "1.20641206", "1596666781.592769"]], "c": "3174765270"}, "book-100", "XBT/USD"]
[270, {"a": [["11697.50000", "0.99230894", "1596666781.593863"]], "c": "3174765270"}, "book-100", "XBT/USD"]
[270, {"a": [["11689.40000", "0.72214313", "1596666781.595272"]], "c": "3174765270"}, "book-100", "XBT/USD"]
[270, {"a": [["11670.50000", "0.00000000", "1596666781.596683"], ["11722.20000", "3.01549629", "1596666746.821117", "r"]], "c": "2328051646"}, "book-100", "XBT/USD"]
[270, {"a": [["11687.00000", "0.10318449", "1596666781.599040"]], "c": "2328051646"}, "book-100", "XBT/USD"]
[270, {"b": [["11647.00000", "1.82127787", "1596666781.599569"]], "c": "2328051646"}, "book-100", "XBT/USD"]
[270, {"b": [["11645.90000", "2.16612816", "1596666781.626232"]], "c": "2328051646"}, "book-100", "XBT/USD"]
[270, {"b": [["11651.10000", "0.00000000", "1596666781.636398"], ["11602.10000", "11.25550194", "1596666780.609892", "r"]], "c": "2328051646"}, "book-100", "XBT/USD"]
[270, {"b": [["11651.10000", "0.04220352", "1596666781.636741"]], "c": "2328051646"}, "book-100", "XBT/USD"]
[270, {"a": [["11687.00000", "0.81326763", "1596666781.649520"]], "c": "2328051646"}, "book-100", "XBT/USD"]
[270, {"a": [["11683.60000", "0.33823323", "1596666781.651341"]], "c": "2328051646"}, "book-100", "XBT/USD"]
[270, {"a": [["11669.80000", "0.00000000", "1596666781.654114"], ["11722.10000", "7.70000000", "1596666696.315517", "r"]], "c": "2176462882"}, "book-100", "XBT/USD"]
[270, {"a": [["11683.50000", "0.11270374", "1596666781.654990"]], "c": "2176462882"}, "book-100", "XBT/USD"]
[270, {"a": [["11679.90000", "0.00000000", "1596666781.660977"], ["11722.10000", "7.70000000", "1596666696.315517", "r"]], "c": "2176462882"}, "book-100", "XBT/USD"]
[270, {"a": [["11689.40000", "2.14201783", "1596666781.662139"]], "c": "2176462882"}, "book-100", "XBT/USD"]
[270, {"a": [["11679.80000", "0.55981534", "1596666781.682359"]], "c": "2176462882"}, "book-100", "XBT/USD"]
[270, {"a": [["11670.50000", "0.25833490", "1596666781.710192"]], "c": "1451024605"}, "book-100", "XBT/USD"]
[270, {"a": [["11670.10000", "0.00000000", "1596666781.710626"], ["11721.70000", "2.47549182", "1596666772.357495", "r"]], "c": "573406558"}, "book-100", "XBT/USD"]
[270, {"b": [["11657.50000", "0.00000000", "1596666781.761099"], ["11602.10000", "11.25550194", "1596666780.609892", "r"]], "c": "1413975947"}, "book-100", "XBT/USD"]
[270, {"a": [["11673.90000", "0.00000000", "1596666781.770359"], ["11722.10000", "7.70000000", "1596666696.315517", "r"]], "c": "1413975947"}, "book-100", "XBT/USD"]
[270, {"b": [["11647.00000", "2.26637793", "1596666781.770643"]], "c": "1413975947"}, "book-100", "XBT/USD"]
[270, {"a": [["11704.80000", "0.89674240", "1596666781.770732"]], "c": "1413975947"}, "book-100", "XBT/USD"]
[270, {"a": [["11689.60000", "0.89790844", "1596666781.771090"]], "c": "1413975947"}, "book-100", "XBT/USD"]
[270, {"b": [["11647.00000", "2.34385778", "1596666781.773332"]], "c": "1413975947"}, "book-100", "XBT/USD"]
[270, {"a": [["11671.10000", "0.41352978", "1596666781.800734"]], "c": "1837332849"}, "book-100", "XBT/USD"]
[271, [["11659.00000", "0.27200107", "1596666781.805576", "b", "l", ""]], "trade", "XBT/USD"]
[270, {"a": [["11659.00000", "0.00000000", "1596666781.805576"], ["11721.00000", "0.80800000", "1596666761.523908", "r"]]}, {"b": [["11659.00000", "1.24699893", "1596666781.804988"]], "c": "3934922153"}, "book-100", "XBT/USD"]
[270, {"b": [["11647.00000", "2.42903793", "1596666781.815951"]], "c": "3934922153"}, "book-100", "XBT/USD"]
[270, {"a": [["11695.40000", "7.06948855", "1596666781.828338"]], "c": "3934922153"}, "book-100", "XBT/USD"]
[270, {"a": [["11707.10000", "7.06242335", "1596666781.831440"]], "c": "3934922153"}, "book-100", "XBT/USD"]
[270, {"b": [["11658.90000", "23.39204133", "1596666781.852758"]], "c": "1235196783"}, "book-100", "XBT/USD"]
[270, {"b": [["11659.00000", "5.09699893", "1596666781.876287"]], "c": "4282636119"}, "book-100", "XBT/USD"]
[270, {"b": [["11658.90000", "22.00365099", "1596666781.877630"]], "c": "2377315821"}, "book-100", "XBT/USD"]
[270, {"a": [["11678.10000", "0.00000000", "1596666781.878629"], ["11719.70000", "3.50602221", "1596666743.346655", "r"]], "c": "2377315821"}, "book-100", "XBT/USD"]
[270, {"b": [["11658.80000", "0.00000000", "1596666781.880341"], ["11602.10000", "11.25550194", "1596666780.609892", "r"]], "c": "2984101623"}, "book-100", "XBT/USD"]
[270, {"b": [["11658.90000", "21.36071685", "1596666781.880459"]], "c": "1541746669"}, "book-100", "XBT/USD"]
[270, {"b": [["11658.70000", "0.00000000", "1596666781.880736"], ["11601.10000", "3.00166376", "1596666779.976375", "r"]], "c": "4111193834"}, "book-100", "XBT/USD"]
[270, {"a": [["11713.70000", "0.00000000", "1596666781.882300"], ["11721.00000", "0.80800000", "1596666761.523908", "r"]], "c": "4111193834"}, "book-100", "XBT/USD"]
[270, {"b": [["11653.20000", "0.24981620", "1596666781.883391"]], "c": "4111193834"}, "book-100", "XBT/USD"]
[270, {"b": [["11659.00000", "5.32199893", "1596666781.884323"]], "c": "850828977"}, "book-100", "XBT/USD"]
[270, {"b": [["11658.90000", "20.86071685", "1596666781.889514"]], "c": "3227083418"}, "book-100", "XBT/USD"]
[270, {"a": [["11688.60000", "0.00000000", "1596666781.898041"], ["11721.70000", "2.47549182", "1596666772.357495", "r"]], "c": "3227083418"}, "book-100", "XBT/USD"]
[270, {"b": [["11652.80000", "0.00000000", "1596666781.898895"], ["11601.00000", "0.17085000", "1596666771.979393", "r"]], "c": "3227083418"}, "book-100", "XBT/USD"]
[270, {"b": [["11654.50000", "0.00000000", "1596666781.912499"], ["11600.40000", "0.90458128", "1596666777.993986", "r"]], "c": "3227083418"}, "book-100", "XBT/USD"]
[270, {"a": [["11681.70000", "1.18043178", "1596666781.913457"]], "c": "3227083418"}, "book-100", "XBT/USD"]
[270, {"a": [["11679.80000", "0.00000000", "1596666781.916416"], ["11722.10000", "7.70000000", "1596666696.315517", "r"]], "c": "3227083418"}, "book-100", "XBT/USD"]
[270, {"b": [["11659.10000", "1.29264719", "1596666781.937668"]], "c": "1651814361"}, "book-100", "XBT/USD"]
[270, {"a": [["11678.70000", "1.69734649", "1596666781.950085"]], "c": "1651814361"}, "book-100", "XBT/USD"]
[270, {"b": [["11658.90000", "20.63071685", "1596666781.953697"]], "c": "3292108732"}, "book-100", "XBT/USD"]
[270, {"b": [["11665.60000", "0.25000000", "1596666781.958007"]], "c": "1107465381"}, "book-100", "XBT/USD"]
[270, {"b": [["11659.30000", "1.00000000", "1596666781.960868"]], "c": "692877808"}, "book-100", "XBT/USD"]
[270, {"b": [["11658.90000", "10.63084682", "1596666781.960999"]], "c": "2490665824"}, "book-100", "XBT/USD"]
[270, {"b": [["11623.60000", "0.75800000", "1596666781.974861"]], "c": "2490665824"}, "book-100", "XBT/USD"]
[270, {"b": [["11659.00000", "5.55199893", "1596666781.981937"]], "c": "3233651602"}, "book-100", "XBT/USD"]
[270, {"b": [["11659.00000", "1.70199893", "1596666781.982095"]], "c": "2286843015"}, "book-100", "XBT/USD"]
[270, {"b": [["11658.90000", "10.53084682", "1596666781.998039"]], "c": "378575796"}, "book-100", "XBT/USD"]
[270, {"a": [["11716.10000", "0.30235286", "1596666782.002327"]], "c": "378575796"}, "book-100", "XBT/USD"]
[270, {"a": [["11694.50000", "2.00143583", "1596666782.005692"]], "c": "378575796"}, "book-100", "XBT/USD"]
[270, {"b": [["11618.90000", "0.48560000", "1596666782.022335"]], "c": "378575796"}, "book-100", "XBT/USD"]
[270, {"b": [["11658.90000", "10.13084682", "1596666782.022403"]], "c": "456591793"}, "book-100", "XBT/USD"]
[270, {"b": [["11662.00000", "0.09700000", "1596666782.032979"]], "c": "3405369101"}, "book-100", "XBT/USD"]
[270, {"b": [["11606.10000", "0.00000000", "1596666782.034543"], ["11603.20000", "2.50039088", "1596666777.334144", "r"]], "c": "3405369101"}, "book-100", "XBT/USD"]
[270, {"a": [["11718.00000", "0.00000000", "1596666782.036491"], ["11721.70000", "2.47549182", "1596666772.357495", "r"]], "c": "3405369101"}, "book-100", "XBT/USD"]
[270, {"a": [["11678.70000", "0.30000000", "1596666782.054070"]], "c": "3405369101"}, "book-100", "XBT/USD"]
[270, {"b": [["11658.90000", "9.64864102", "1596666782.056192"]], "c": "2412619855"}, "book-100", "XBT/USD"]
[270, {"b": [["11651.00000", "0.00000000", "1596666782.070434"], ["11602.20000", "2.01681621", "1596666634.588713", "r"]], "c": "2412619855"}, "book-100", "XBT/USD"]
[270, {"b": [["11665.70000", "0.30000000", "1596666782.098580"]], "c": "4275164778"}, "book-100", "XBT/USD"]
[270, {"a": [["11671.10000", "0.00000000", "1596666782.103494"], ["11722.10000", "7.70000000", "1596666696.315517", "r"]], "c": "874641465"}, "book-100", "XBT/USD"]
[270, {"b": [["11659.10000", "6.54264719", "1596666782.105732"]], "c": "1073547342"}, "book-100", "XBT/USD"]
[270, {"b": [["11666.10000", "0.50000000", "1596666782.128681"]], "c": "637547052"}, "book-100", "XBT/USD"]
[270, {"a": [["11694.70000", "2.33204127", "1596666782.137314"]], "c": "637547052"}, "book-100", "XBT/USD"]
[270, {"b": [["11658.90000", "9.49864102", "1596666782.142970"]], "c": "3924850424"}, "book-100", "XBT/USD"]
[270, {"a": [["11670.70000", "0.00000000", "1596666782.147409"], ["11722.10000", "7.70000000", "1596666696.315517", "r"]], "c": "54800541"}, "book-100", "XBT/USD"]
[270, {"b": [["11659.80000", "0.10000000", "1596666782.160594"]], "c": "2134438195"}, "book-100", "XBT/USD"]
[270, {"b": [["11612.50000", "2.30777706", "1596666782.171350"]], "c": "2134438195"}, "book-100", "XBT/USD"]
[270, {"b": [["11650.60000", "0.00257000", "1596666782.173622"]], "c": "2134438195"}, "book-100", "XBT/USD"]
[270, {"b": [["11665.60000", "1.20568000", "1596666782.186801"]], "c": "2824975666"}, "book-100", "XBT/USD"]
[270, {"b": [["11647.00000", "2.35155808", "1596666782.191627"]], "c": "2824975666"}, "book-100", "XBT/USD"]
[270, {"b": [["11647.00000", "2.26637793", "1596666782.191700"]], "c": "2824975666"}, "book-100", "XBT/USD"]
[270, {"b": [["11647.00000", "1.03996371", "1596666782.192184"]], "c": "2824975666"}, "book-100", "XBT/USD"]
[270, {"b": [["11647.00000", "0.44510006", "1596666782.192263"]], "c": "2824975666"}, "book-100", "XBT/USD"]
[270, {"b": [["11651.10000", "0.00000000", "1596666782.199433"], ["11604.00000", "0.17085000", "1596666711.074347", "r"]], "c": "2824975666"}, "book-100", "XBT/USD"]
[270, {"b": [["11651.00000", "0.04220388", "1596666782.200031"]], "c": "2824975666"}, "book-100", "XBT/USD"]
[270, {"b": [["11658.90000", "8.49864102", "1596666782.203277"]], "c": "1333531557"}, "book-100", "XBT/USD"]
[270, {"b": [["11658.90000", "8.06964102", "1596666782.204260"]], "c": "3433543747"}, "book-100", "XBT/USD"]
[270, {"b": [["11659.10000", "1.29264719", "1596666782.206962"]], "c": "214441291"}, "book-100", "XBT/USD"]
[270, {"b": [["11647.00000", "0.00000000", "1596666782.214619"], ["11604.00000", "0.17085000", "1596666711.074347", "r"]], "c": "214441291"}, "book-100", "XBT/USD"]
[270, {"a": [["11696.70000", "0.89736340", "1596666782.239907"]], "c": "214441291"}, "book-100", "XBT/USD"]
[270, {"a": [["11671.90000", "0.41352978", "1596666782.255338"]], "c": "278764566"}, "book-100", "XBT/USD"]
[270, {"b": [["11653.80000", "0.00000000", "1596666782.280357"], ["11603.20000", "2.50039088", "1596666777.334144", "r"]], "c": "278764566"}, "book-100", "XBT/USD"]
[270, {"b": [["11659.10000", "1.84294719", "1596666782.282587"]], "c": "320644842"}, "book-100", "XBT/USD"]
[270, {"a": [["11676.90000", "0.46597777", "1596666782.292815"]], "c": "320644842"}, "book-100", "XBT/USD"]
[270, {"a": [["11681.60000", "0.00000000", "1596666782.313479"], ["11721.00000", "0.80800000", "1596666761.523908", "r"]], "c": "320644842"}, "book-100", "XBT/USD"]
[270, {"b": [["11633.30000", "0.00000000", "1596666782.348214"], ["11602.20000", "2.01681621", "1596666634.588713", "r"]], "c": "320644842"}, "book-100", "XBT/USD"]
[270, {"a": [["11694.70000", "0.00000000", "1596666782.375745"], ["11721.70000", "2.47549182", "1596666772.357495", "r"]], "c": "320644842"}, "book-100", "XBT/USD"]
[270, {"b": [["11666.10000", "1.02639713", "1596666782.380162"]], "c": "4219302954"}, "book-100", "XBT/USD"]
[270, {"b": [["11664.50000", "9.99987003", "1596666782.416344"]], "c": "3443521519"}, "book-100", "XBT/USD"]
[270, {"b": [["11665.80000", "0.42800000", "1596666782.453555"]], "c": "1781966580"}, "book-100", "XBT/USD"]
[270, {"b": [["11659.10000", "1.92868475", "1596666782.458438"]], "c": "2022353407"}, "book-100", "XBT/USD"]
[270, {"a": [["11670.50000", "0.00000000", "1596666782.470351"], ["11722.10000", "7.70000000", "1596666696.315517", "r"]], "c": "325095566"}, "book-100", "XBT/USD"]
[270, {"b": [["11659.00000", "1.47199893", "1596666782.472399"]], "c": "1481157091"}, "book-100", "XBT/USD"]
[270, {"b": [["11651.70000", "1.27142529", "1596666782.488226"]], "c": "1481157091"}, "book-100", "XBT/USD"]
[270, {"b": [["11642.90000", "0.00000000", "1596666782.488516"], ["11603.20000", "2.50039088", "1596666777.334144", "r"]], "c": "1481157091"}, "book-100", "XBT/USD"]
[270, {"a": [["11671.80000", "0.25831673", "1596666782.492602"]], "c": "1202483494"}, "book-100", "XBT/USD"]
[270, {"b": [["11658.90000", "3.79064102", "1596666782.513613"]], "c": "1202483494"}, "book-100", "XBT/USD"]
[270, {"b": [["11659.10000", "0.63603756", "1596666782.522118"]], "c": "1813847493"}, "book-100", "XBT/USD"]
[270, {"a": [["11676.90000", "0.00000000", "1596666782.523305"], ["11722.10000", "7.70000000", "1596666696.315517", "r"]], "c": "1813847493"}, "book-100", "XBT/USD"]
[270, {"b": [["11662.00000", "0.24700000", "1596666782.540778"]], "c": "3589144376"}, "book-100", "XBT/USD"]
[270, {"b": [["11643.90000", "0.05287598", "1596666782.575097"]], "c": "3589144376"}, "book-100", "XBT/USD"]
[270, {"a": [["11694.30000", "3.19567636", "1596666782.586090"]], "c": "3589144376"}, "book-100", "XBT/USD"]
[270, {"b": [["11636.00000", "8.48337540", "1596666782.590058"]], "c": "3589144376"}, "book-100", "XBT/USD"]
[270, {"b": [["11647.60000", "3.20848914", "1596666782.592356"]], "c": "3589144376"}, "book-100", "XBT/USD"]
[270, {"a": [["11694.40000", "2.32474034", "1596666782.610121"]], "c": "3589144376"}, "book-100", "XBT/USD"]
[270, {"a": [["11676.90000", "0.43161459", "1596666782.707589"]], "c": "3589144376"}, "book-100", "XBT/USD"]
[270, {"b": [["11655.80000", "0.00000000", "1596666782.734572"], ["11604.00000", "0.17085000", "1596666711.074347", "r"]], "c": "3589144376"}, "book-100", "XBT/USD"]
[270, {"a": [["11708.50000", "2.88000000", "1596666782.790225"]], "c": "3589144376"}, "book-100", "XBT/USD"]
[270, {"a": [["11694.40000", "0.00000000", "1596666782.849112"], ["11719.70000", "3.50602221", "1596666743.346655", "r"]], "c": "3589144376"}, "book-100", "XBT/USD"]
[270, {"a": [["11676.90000", "0.00000000", "1596666782.936699"], ["11721.00000", "0.80800000", "1596666761.523908", "r"]], "c": "3589144376"}, "book-100", "XBT/USD"]
[270, {"b": [["11659.80000", "0.00000000", "1596666782.960009"], ["11603.20000", "2.50039088", "1596666777.334144", "r"]], "c": "2210835154"}, "book-100", "XBT/USD"]
[270, {"b": [["11659.40000", "1.34459613", "1596666782.965310"]], "c": "3450811047"}, "book-100", "XBT/USD"]
[270, {"a": [["11705.30000", "0.00000000", "1596666782.965817"], ["11721.70000", "2.47549182", "1596666772.357495", "r"]], "c": "3450811047"}, "book-100", "XBT/USD"]
[270, {"b": [["11613.90000", "0.02884034", "1596666782.969718"]], "c": "3450811047"}, "book-100", "XBT/USD"]
[270, {"a": [["11719.60000", "2.98021891", "1596666782.974175"]], "c": "3450811047"}, "book-100", "XBT/USD"]
[270, {"b": [["11664.60000", "4.27700000", "1596666783.018662"]], "c": "329591410"}, "book-100", "XBT/USD"]
[270, {"a": [["11694.20000", "2.30766000", "1596666783.093055"]], "c": "329591410"}, "book-100", "XBT/USD"]
[270, {"b": [["11652.90000", "0.46946633", "1596666783.098162"]], "c": "329591410"}, "book-100", "XBT/USD"]
[270, {"b": [["11651.70000", "0.72442529", "1596666783.126962"]], "c": "329591410"}, "book-100", "XBT/USD"]
[270, {"a": [["11691.00000", "0.00000000", "1596666783.129538"], ["11721.70000", "2.47549182", "1596666772.357495", "r"]], "c": "329591410"}, "book-100", "XBT/USD"]
[270, {"b": [["11665.60000", "0.95568000", "1596666783.212071"]], "c": "3862634449"}, "book-100", "XBT/USD"]
[270, {"b": [["11664.70000", "0.25000000", "1596666783.385055"]], "c": "4145219829"}, "book-100", "XBT/USD"]
[270, {"a": [["11676.90000", "0.05313798", "1596666783.419461"]], "c": "4145219829"}, "book-100", "XBT/USD"]
[270, {"a": [["11675.60000", "0.47089902", "1596666783.423713"]], "c": "4145219829"}, "book-100", "XBT/USD"]
[270, {"a": [["11673.30000", "0.00000000", "1596666783.468694"], ["11721.70000", "2.47549182", "1596666772.357495", "r"]], "c": "4145219829"}, "book-100", "XBT/USD"]
[270, {"a": [["11685.30000", "0.00000000", "1596666783.493915"], ["11722.10000", "7.70000000", "1596666696.315517", "r"]], "c": "4145219829"}, "book-100", "XBT/USD"]
[270, {"a": [["11675.10000", "0.00000000", "1596666783.534262"], ["11722.20000", "3.01549629", "1596666746.821117", "r"]], "c": "4145219829"}, "book-100", "XBT/USD"]
[270, {"a": [["11679.50000", "0.70560000", "1596666783.539376"]], "c": "4145219829"}, "book-100", "XBT/USD"]
[270, {"b": [["11608.30000", "0.00000000", "1596666783.553089"], ["11604.10000", "1.51500000", "1596666763.121463", "r"]], "c": "4145219829"}, "book-100", "XBT/USD"]
[270, {"a": [["11677.90000", "0.10500000", "1596666783.554979"]], "c": "4145219829"}, "book-100", "XBT/USD"]
[270, {"a": [["11685.40000", "1.64160000", "1596666783.556156"]], "c": "4145219829"}, "book-100", "XBT/USD"]
[270, {"b": [["11611.70000", "0.74881696", "1596666783.561776"]], "c": "4145219829"}, "book-100", "XBT/USD"]
[270, {"a": [["11701.20000", "0.43900000", "1596666783.567428"]], "c": "4145219829"}, "book-100", "XBT/USD"]
[270, {"a": [["11690.40000", "0.74881696", "1596666783.581749"]], "c": "4145219829"}, "book-100", "XBT/USD"]
[270, {"b": [["11649.50000", "0.00000000", "1596666783.643066"], ["11604.10000", "1.51500000", "1596666763.121463", "r"]], "c": "4145219829"}, "book-100", "XBT/USD"]
[270, {"b": [["11628.00000", "0.17085000", "1596666783.705003"]], "c": "4145219829"}, "book-100", "XBT/USD"]
[270, {"b": [["11664.70000", "0.00000000", "1596666783.790978"], ["11604.10000", "1.51500000", "1596666763.121463", "r"]], "c": "3862634449"}, "book-100", "XBT/USD"]
[270, {"a": [["11671.90000", "0.00000000", "1596666783.794119"], ["11721.00000", "0.80800000", "1596666761.523908", "r"]], "c": "2365836412"}, "book-100", "XBT/USD"]
[270, {"b": [["11666.10000", "1.25139713", "1596666783.848187"]], "c": "2640054009"}, "book-100", "XBT/USD"]
[270, {"a": [["11721.00000", "0.97885000", "1596666783.855310"]], "c": "2640054009"}, "book-100", "XBT/USD"]
[270, {"b": [["11664.50000", "0.00000000", "1596666783.855994"], ["11603.20000", "2.50039088", "1596666777.334144", "r"]], "c": "1813091925"}, "book-100", "XBT/USD"]
[270, {"b": [["11664.00000", "0.25000000", "1596666783.927587"]], "c": "835692195"}, "book-100", "XBT/USD"]
[270, {"b": [["11664.60000", "0.00000000", "1596666783.945640"], ["11603.20000", "2.50039088", "1596666777.334144", "r"]], "c": "3221954832"}, "book-100", "XBT/USD"]
[270, {"a": [["11671.30000", "0.41352978", "1596666783.946132"]], "c": "3000730732"}, "book-100", "XBT/USD"]
[270, {"a": [["11692.70000", "0.00000000", "1596666783.949532"], ["11721.00000", "0.97885000", "1596666783.855310", "r"]], "c": "3000730732"}, "book-100", "XBT/USD"]
[270, {"b": [["11653.70000", "0.04219410", "1596666783.984727"]], "c": "3000730732"}, "book-100", "XBT/USD"]
[270, {"b": [["11651.00000", "0.00000000", "1596666783.987051"], ["11603.20000", "2.50039088", "1596666777.334144", "r"]], "c": "3000730732"}, "book-100", "XBT/USD"]
[270, {"a": [["11716.10000", "0.00000000", "1596666784.004392"], ["11721.70000", "2.47549182", "1596666772.357495", "r"]], "c": "3000730732"}, "book-100", "XBT/USD"]
[270, {"b": [["11662.10000", "1.00000000", "1596666784.039332"]], "c": "2066288653"}, "book-100", "XBT/USD"]
[270, {"a": [["11719.70000", "3.80837507", "1596666784.059808"]], "c": "2066288653"}, "book-100", "XBT/USD"]
[270, {"b": [["11658.30000", "0.00000000", "1596666784.100382"], ["11603.20000", "2.50039088", "1596666777.334144", "r"]], "c": "2066288653"}, "book-100", "XBT/USD"]
[270, {"b": [["11664.50000", "0.09621094", "1596666784.105474"]], "c": "1036545013"}, "book-100", "XBT/USD"]
[270, {"b": [["11659.30000", "0.00000000", "1596666784.113351"], ["11603.20000", "2.50039088", "1596666777.334144", "r"]], "c": "290652090"}, "book-100", "XBT/USD"]
[270, {"b": [["11639.60000", "0.90031324", "1596666784.125775"]], "c": "290652090"}, "book-100", "XBT/USD"]
[270, {"b": [["11625.70000", "1.17681430", "1596666784.127703"]], "c": "290652090"}, "book-100", "XBT/USD"]
[270, {"b": [["11646.60000", "0.57485441", "1596666784.129257"]], "c": "290652090"}, "book-100", "XBT/USD"]
[270, {"a": [["11703.80000", "0.89537466", "1596666784.131217"]], "c": "290652090"}, "book-100", "XBT/USD"]
[270, {"a": [["11696.80000", "0.62529458", "1596666784.139085"]], "c": "290652090"}, "book-100", "XBT/USD"]
[270, {"a": [["11688.60000", "0.24903862", "1596666784.144554"]], "c": "290652090"}, "book-100", "XBT/USD"]
[270, {"b": [["11664.00000", "10.24987003", "1596666784.170350"]], "c": "1471486163"}, "book-100", "XBT/USD"]
[270, {"b": [["11662.20000", "0.10000000", "1596666784.172050"]], "c": "3677238282"}, "book-100", "XBT/USD"]
[270, {"b": [["11665.80000", "1.07066165", "1596666784.209404"]], "c": "1371452952"}, "book-100", "XBT/USD"]
[270, {"b": [["11662.30000", "0.85688220", "1596666784.209579"]], "c": "380401179"}, "book-100", "XBT/USD"]
[270, {"b": [["11662.20000", "0.95688220", "1596666784.209752"]], "c": "4258419499"}, "book-100", "XBT/USD"]
[270, {"b": [["11665.70000", "0.94266165", "1596666784.209897"]], "c": "2837755831"}, "book-100", "XBT/USD"]
[270, {"b": [["11659.90000", "0.85688220", "1596666784.210070"]], "c": "2837755831"}, "book-100", "XBT/USD"]
[270, {"b": [["11650.60000", "0.00000000", "1596666784.210148"], ["11609.80000", "21.20000000", "1596666704.766154", "r"]], "c": "2837755831"}, "book-100", "XBT/USD"]
[270, {"b": [["11665.90000", "0.64266165", "1596666784.210719"]], "c": "254004798"}, "book-100", "XBT/USD"]
[270, {"a": [["11685.80000", "0.00000000", "1596666784.244929"], ["11721.00000", "0.97885000", "1596666783.855310", "r"]], "c": "254004798"}, "book-100", "XBT/USD"]
[270, {"b": [["11662.20000", "0.99938220", "1596666784.273760"]], "c": "416714709"}, "book-100", "XBT/USD"]
[270, {"b": [["11662.20000", "1.08188220", "1596666784.274061"]], "c": "4193817209"}, "book-100", "XBT/USD"]
[270, {"a": [["11688.60000", "6.47756487", "1596666784.338183"]], "c": "4193817209"}, "book-100", "XBT/USD"]
[270, {"a": [["11680.30000", "8.10000000", "1596666784.355078"]], "c": "4193817209"}, "book-100", "XBT/USD"]
[270, {"b": [["11666.10000", "1.33710860", "1596666784.380611"]], "c": "2616418109"}, "book-100", "XBT/USD"]
[270, {"b": [["11666.10000", "1.56710860", "1596666784.476959"]], "c": "805994841"}, "book-100", "XBT/USD"]
[270, {"a": [["11671.80000", "0.00000000", "1596666784.567144"], ["11721.00000", "0.97885000", "1596666783.855310", "r"]], "c": "1713795379"}, "book-100", "XBT/USD"]
[270, {"a": [["11672.80000", "1.79521094", "1596666784.606205"]], "c": "813179003"}, "book-100", "XBT/USD"]
[270, {"b": [["11658.90000", "3.44164102", "1596666784.618170"]], "c": "813179003"}, "book-100", "XBT/USD"]
[270, {"b": [["11666.10000", "3.15210860", "1596666784.643444"]], "c": "1389716456"}, "book-100", "XBT/USD"]
[270, {"b": [["11659.00000", "0.22500000", "1596666784.658811"]], "c": "1389716456"}, "book-100", "XBT/USD"]
[270, {"a": [["11670.80000", "1.97411093", "1596666784.666687"]], "c": "1566036819"}, "book-100", "XBT/USD"]
[270, {"b": [["11617.30000", "0.00000000", "1596666784.684470"], ["11609.80000", "21.20000000", "1596666704.766154", "r"]], "c": "1566036819"}, "book-100", "XBT/USD"]
[270, {"b": [["11662.20000", "0.98188220", "1596666784.701310"]], "c": "659974149"}, "book-100", "XBT/USD"]
[270, {"b": [["11625.60000", "0.70560000", "1596666784.757487"]], "c": "659974149"}, "book-100", "XBT/USD"]
[270, {"a": [["11671.20000", "0.40348588", "1596666784.795819"]], "c": "3030691705"}, "book-100", "XBT/USD"]
[270, {"a": [["11672.80000", "0.09621094", "1596666784.801765"]], "c": "3688190605"}, "book-100", "XBT/USD"]
[270, {"a": [["11685.90000", "2.00000000", "1596666784.948451"]], "c": "3688190605"}, "book-100", "XBT/USD"]
[270, {"a": [["11670.90000", "0.00000000", "1596666784.971478"], ["11721.00000", "0.97885000", "1596666783.855310", "r"]], "c": "3537869699"}, "book-100", "XBT/USD"]
[270, {"a": [["11669.50000", "1.50000000", "1596666785.127534"]], "c": "3775980104"}, "book-100", "XBT/USD"]
[270, {"a": [["11675.60000", "0.00000000", "1596666785.177207"], ["11721.00000", "0.97885000", "1596666783.855310", "r"]], "c": "3775980104"}, "book-100", "XBT/USD"]
[270, {"a": [["11672.00000", "0.09700000", "1596666785.223240"]], "c": "4158584847"}, "book-100", "XBT/USD"]
[270, {"b": [["11666.10000", "1.56710860", "1596666785.234440"]], "c": "2273358931"}, "book-100", "XBT/USD"]
[270, {"b": [["11664.00000", "0.25000000", "1596666785.433144"]], "c": "4193190542"}, "book-100", "XBT/USD"]
[270, {"b": [["11665.70000", "5.21566165", "1596666785.449680"]], "c": "2072257054"}, "book-100", "XBT/USD"]
[270, {"b": [["11620.80000", "0.02000000", "1596666785.453825"]], "c": "2072257054"}, "book-100", "XBT/USD"]
[270, {"a": [["11672.70000", "4.27700000", "1596666785.484260"]], "c": "184448778"}, "book-100", "XBT/USD"]
[270, {"b": [["11665.70000", "0.94266165", "1596666785.538240"]], "c": "843030474"}, "book-100", "XBT/USD"]
[270, {"a": [["11676.10000", "0.45757311", "1596666785.550420"]], "c": "843030474"}, "book-100", "XBT/USD"]
[270, {"b": [["11651.90000", "4.17930579", "1596666785.563572"]], "c": "843030474"}, "book-100", "XBT/USD"]
[270, {"b": [["11662.00000", "0.15000000", "1596666785.589778"]], "c": "843030474"}, "book-100", "XBT/USD"]
[270, {"a": [["11672.70000", "0.00000000", "1596666785.623906"], ["11719.60000", "2.98021891", "1596666782.974175", "r"]], "c": "4193190542"}, "book-100", "XBT/USD"]
[270, {"b": [["11663.00000", "9.99987003", "1596666785.670838"]], "c": "3518622052"}, "book-100", "XBT/USD"]
[270, {"b": [["11649.00000", "0.00000000", "1596666785.729431"], ["11611.70000", "0.74881696", "1596666783.561776", "r"]], "c": "3518622052"}, "book-100", "XBT/USD"]
[270, {"b": [["11652.50000", "0.00000000", "1596666785.735575"], ["11610.00000", "0.17085000", "1596666698.121910", "r"]], "c": "3518622052"}, "book-100", "XBT/USD"]
[270, {"b": [["11664.00000", "0.00000000", "1596666785.856518"], ["11609.80000", "21.20000000", "1596666704.766154", "r"]], "c": "684742123"}, "book-100", "XBT/USD"]
[270, {"a": [["11671.30000", "0.00000000", "1596666785.867653"], ["11719.70000", "3.80837507", "1596666784.059808", "r"]], "c": "652080862"}, "book-100", "XBT/USD"]
[270, {"b": [["11651.60000", "0.00000000", "1596666786.022065"], ["11607.70000", "8.40000000", "1596666777.775135", "r"]], "c": "652080862"}, "book-100", "XBT/USD"]
[270, {"a": [["11672.10000", "0.41352978", "1596666786.022482"]], "c": "1776968801"}, "book-100", "XBT/USD"]
[270, {"b": [["11664.90000", "0.25000000", "1596666786.024062"]], "c": "3051890046"}, "book-100", "XBT/USD"]
[270, {"a": [["11680.50000", "0.00000000", "1596666786.073273"], ["11719.70000", "3.80837507", "1596666784.059808", "r"]], "c": "3051890046"}, "book-100", "XBT/USD"]
[270, {"a": [["11670.80000", "1.71578367", "1596666786.096958"]], "c": "1844582458"}, "book-100", "XBT/USD"]
[270, {"a": [["11682.30000", "0.69931240", "1596666786.141490"]], "c": "1844582458"}, "book-100", "XBT/USD"]
[270, {"a": [["11671.90000", "0.25831681", "1596666786.151154"]], "c": "1078452368"}, "book-100", "XBT/USD"]
[270, {"b": [["11658.20000", "0.00000000", "1596666786.175444"], ["11607.70000", "8.40000000", "1596666777.775135", "r"]], "c": "1078452368"}, "book-100", "XBT/USD"]
[270, {"b": [["11654.90000", "0.89800000", "1596666786.182045"]], "c": "1078452368"}, "book-100", "XBT/USD"]
[270, {"b": [["11649.70000", "0.00000000", "1596666786.183595"], ["11607.00000", "0.17085000", "1596666720.750083", "r"]], "c": "1078452368"}, "book-100", "XBT/USD"]
[270, {"b": [["11653.20000", "0.00000000", "1596666786.185509"], ["11606.60000", "0.36139355", "1596666776.377050", "r"]], "c": "1078452368"}, "book-100", "XBT/USD"]
[270, {"b": [["11654.00000", "0.00000000", "1596666786.202936"], ["11604.10000", "1.51500000", "1596666763.121463", "r"]], "c": "1078452368"}, "book-100", "XBT/USD"]
[270, {"b": [["11651.70000", "0.00000000", "1596666786.205539"], ["11603.20000", "2.50039088", "1596666777.334144", "r"]], "c": "1078452368"}, "book-100", "XBT/USD"]
[270, {"b": [["11665.80000", "5.35166165", "1596666786.223993"]], "c": "3047751133"}, "book-100", "XBT/USD"]
[270, {"a": [["11672.00000", "4.37000000", "1596666786.233671"]], "c": "3544084810"}, "book-100", "XBT/USD"]
[270, {"b": [["11654.00000", "1.42406771", "1596666786.341542"]], "c": "3544084810"}, "book-100", "XBT/USD"]
[270, {"b": [["11663.10000", "2.00000000", "1596666786.359174"]], "c": "2720531085"}, "book-100", "XBT/USD"]
[270, {"a": [["11676.90000", "0.52127785", "1596666786.363885"]], "c": "2720531085"}, "book-100", "XBT/USD"]
[270, {"b": [["11654.20000", "4.21001399", "1596666786.374399"]], "c": "2720531085"}, "book-100", "XBT/USD"]
[270, {"b": [["11656.50000", "0.96072733", "1596666786.383143"]], "c": "2720531085"}, "book-100", "XBT/USD"]
[270, {"a": [["11685.10000", "0.38000000", "1596666786.480664"]], "c": "2720531085"}, "book-100", "XBT/USD"]
[270, {"b": [["11653.60000", "0.88000000", "1596666786.481695"]], "c": "2720531085"}, "book-100", "XBT/USD"]
[270, {"a": [["11681.20000", "0.02573600", "1596666786.487009"]], "c": "2720531085"}, "book-100", "XBT/USD"]
[270, {"b": [["11655.80000", "0.24973942", "1596666786.540532"]], "c": "2720531085"}, "book-100", "XBT/USD"]
[270, {"b": [["11652.30000", "0.34974021", "1596666786.544727"]], "c": "2720531085"}, "book-100", "XBT/USD"]
[270, {"b": [["11659.70000", "0.33889798", "1596666786.587849"]], "c": "2720531085"}, "book-100", "XBT/USD"]
[270, {"b": [["11656.40000", "0.71188725", "1596666786.588636"]], "c": "2720531085"}, "book-100", "XBT/USD"]
[270, {"b": [["11646.00000", "0.00432378", "1596666786.683116"]], "c": "2720531085"}, "book-100", "XBT/USD"]
[270, {"a": [["11688.40000", "0.00438186", "1596666786.683617"]], "c": "2720531085"}, "book-100", "XBT/USD"]
[270, {"b": [["11652.90000", "0.00000000", "1596666786.742254"], ["11610.00000", "0.17085000", "1596666698.121910", "r"]], "c": "2720531085"}, "book-100", "XBT/USD"]
[270, {"b": [["11663.10000", "2.46897416", "1596666786.742890"]], "c": "2962261100"}, "book-100", "XBT/USD"]
[271, [["11666.10000", "0.02332266", "1596666786.760338", "s", "l", ""]], "trade", "XBT/USD"]
[270, {"b": [["11666.10000", "1.54378594", "1596666786.760338"]], "c": "3113957570"}, "book-100", "XBT/USD"]
[270, {"a": [["11687.00000", "0.71008314", "1596666786.808314"]], "c": "3113957570"}, "book-100", "XBT/USD"]
[270, {"a": [["11689.40000", "1.41987470", "1596666786.810641"]], "c": "3113957570"}, "book-100", "XBT/USD"]
[270, {"a": [["11683.50000", "0.00000000", "1596666786.825785"], ["11717.80000", "1.99812614", "1596666759.535617", "r"]], "c": "3113957570"}, "book-100", "XBT/USD"]
[270, {"a": [["11689.60000", "0.00000000", "1596666786.890496"], ["11718.50000", "24.30000000", "1596666641.380470", "r"]], "c": "3113957570"}, "book-100", "XBT/USD"]
[270, {"b": [["11656.40000", "0.00000000", "1596666786.911483"], ["11609.80000", "21.20000000", "1596666704.766154", "r"]], "c": "3113957570"}, "book-100", "XBT/USD"]
[270, {"a": [["11687.00000", "0.00000000", "1596666786.913342"], ["11719.60000", "2.98021891", "1596666782.974175", "r"]], "c": "3113957570"}, "book-100", "XBT/USD"]
[270, {"b": [["11659.70000", "0.00000000", "1596666786.913480"], ["11607.70000", "8.40000000", "1596666777.775135", "r"]], "c": "3113957570"}, "book-100", "XBT/USD"]
[270, {"a": [["11689.40000", "0.00000000", "1596666786.915474"], ["11719.70000", "3.80837507", "1596666784.059808", "r"]], "c": "3113957570"}, "book-100", "XBT/USD"]
[270, {"a": [["11683.60000", "0.00000000", "1596666786.979003"], ["11721.00000", "0.97885000", "1596666783.855310", "r"]], "c": "3113957570"}, "book-100", "XBT/USD"]
[270, {"a": [["11684.20000", "0.10323648", "1596666787.024966"]], "c": "3113957570"}, "book-100", "XBT/USD"]
[270, {"a": [["11686.50000", "0.72251316", "1596666787.031201"]], "c": "3113957570"}, "book-100", "XBT/USD"]
[270, {"b": [["11650.00000", "0.90088504", "1596666787.090727"]], "c": "3113957570"}, "book-100", "XBT/USD"]
[270, {"a": [["11680.80000", "0.96910958", "1596666787.117478"]], "c": "3113957570"}, "book-100", "XBT/USD"]
[270, {"b": [["11653.50000", "0.90061447", "1596666787.121574"]], "c": "3113957570"}, "book-100", "XBT/USD"]
[270, {"a": [["11686.70000", "0.89805597", "1596666787.157112"]], "c": "3113957570"}, "book-100", "XBT/USD"]
[270, {"a": [["11675.60000", "1.31984895", "1596666787.211398"]], "c": "3113957570"}, "book-100", "XBT/USD"]
[270, {"b": [["11646.90000", "0.04472750", "1596666787.328623"]], "c": "3113957570"}, "book-100", "XBT/USD"]
[270, {"a": [["11672.10000", "0.00000000", "1596666787.361379"], ["11718.50000", "24.30000000", "1596666641.380470", "r"]], "c": "1949880773"}, "book-100", "XBT/USD"]
[270, {"b": [["11632.50000", "0.49800000", "1596666787.370369"]], "c": "1949880773"}, "book-100", "XBT/USD"]
[270, {"b": [["11664.90000", "0.00000000", "1596666787.378587"], ["11611.70000", "0.74881696", "1596666783.561776", "r"]], "c": "2287263334"}, "book-100", "XBT/USD"]
[270, {"a": [["11677.20000", "0.04472750", "1596666787.391255"]], "c": "2287263334"}, "book-100", "XBT/USD"]
[270, {"b": [["11648.90000", "0.00000000", "1596666787.460756"], ["11610.00000", "0.17085000", "1596666698.121910", "r"]], "c": "2287263334"}, "book-100", "XBT/USD"]
[270, {"a": [["11671.00000", "0.41352978", "1596666787.517143"]], "c": "328114843"}, "book-100", "XBT/USD"]
[270, {"b": [["11663.80000", "0.25000000", "1596666787.520788"]], "c": "402876401"}, "book-100", "XBT/USD"]
[270, {"b": [["11647.10000", "0.13418331", "1596666787.789054"]], "c": "402876401"}, "book-100", "XBT/USD"]
[270, {"a": [["11676.80000", "0.03391692", "1596666787.830400"]], "c": "402876401"}, "book-100", "XBT/USD"]
[270, {"a": [["11676.90000", "0.46813987", "1596666787.834341"]], "c": "402876401"}, "book-100", "XBT/USD"]
[270, {"a": [["11678.90000", "0.13418250", "1596666787.934327"]], "c": "402876401"}, "book-100", "XBT/USD"]
[270, {"b": [["11666.10000", "1.31378594", "1596666787.961265"]], "c": "4186363593"}, "book-100", "XBT/USD"]
[270, {"a": [["11676.20000", "2.31657252", "1596666788.112862"]], "c": "4186363593"}, "book-100", "XBT/USD"]
[270, {"a": [["11680.40000", "0.78685000", "1596666788.157393"]], "c": "4186363593"}, "book-100", "XBT/USD"]
[270, {"a": [["11672.30000", "0.64272437", "1596666788.170481"]], "c": "4186363593"}, "book-100", "XBT/USD"]
[270, {"a": [["11672.40000", "2.77320055", "1596666788.191372"]], "c": "4186363593"}, "book-100", "XBT/USD"]
[270, {"b": [["11665.70000", "0.64266165", "1596666788.219458"]], "c": "1904641576"}, "book-100", "XBT/USD"]
[270, {"a": [["11671.90000", "0.00000000", "1596666788.239301"], ["11710.70000", "3.52183532", "1596666711.393054", "r"]], "c": "65547827"}, "book-100", "XBT/USD"]
[270, {"b": [["11663.00000", "0.00000000", "1596666788.257074"], ["11611.70000", "0.74881696", "1596666783.561776", "r"]], "c": "4061974937"}, "book-100", "XBT/USD"]
[270, {"b": [["11663.80000", "0.00000000", "1596666788.311877"], ["11610.00000", "0.17085000", "1596666698.121910", "r"]], "c": "540213427"}, "book-100", "XBT/USD"]
[270, {"a": [["11674.60000", "0.00000000", "1596666788.315772"], ["11711.20000", "20.00000000", "1596666781.337735", "r"]], "c": "540213427"}, "book-100", "XBT/USD"]
[270, {"a": [["11676.20000", "0.00000000", "1596666788.323995"], ["11713.80000", "0.37309062", "1596666771.863547", "r"]], "c": "540213427"}, "book-100", "XBT/USD"]
[270, {"a": [["11669.90000", "0.25834753", "1596666788.324218"]], "c": "1267206890"}, "book-100", "XBT/USD"]
[270, {"a": [["11671.00000", "0.00000000", "1596666788.348242"], ["11713.80000", "0.37309062", "1596666771.863547", "r"]], "c": "2675622086"}, "book-100", "XBT/USD"]
[270, {"b": [["11658.90000", "1.74064102", "1596666788.350122"]], "c": "2675622086"}, "book-100", "XBT/USD"]
[270, {"a": [["11675.60000", "0.00000000", "1596666788.365472"], ["11715.30000", "6.10000000", "1596666635.445451", "r"]], "c": "2675622086"}, "book-100", "XBT/USD"]
[270, {"b": [["11659.40000", "0.00000000", "1596666788.366326"], ["11609.80000", "21.20000000", "1596666704.766154", "r"]], "c": "2675622086"}, "book-100", "XBT/USD"]
[270, {"b": [["11665.80000", "1.07066165", "1596666788.403336"]], "c": "2548175606"}, "book-100", "XBT/USD"]
[270, {"b": [["11653.70000", "0.06282247", "1596666788.450440"]], "c": "2548175606"}, "book-100", "XBT/USD"]
[270, {"b": [["11653.70000", "0.02062837", "1596666788.450712"]], "c": "2548175606"}, "book-100", "XBT/USD"]
[270, {"a": [["11670.90000", "0.41352978", "1596666788.507735"]], "c": "319469838"}, "book-100", "XBT/USD"]
[270, {"b": [["11663.80000", "0.25000000", "1596666788.528636"]], "c": "3367537140"}, "book-100", "XBT/USD"]
[270, {"a": [["11666.20000", "0.10237722", "1596666788.565116"]], "c": "758744231"}, "book-100", "XBT/USD"]
[270, {"b": [["11653.70000", "0.00000000", "1596666788.590068"], ["11609.80000", "21.20000000", "1596666704.766154", "r"]], "c": "758744231"}, "book-100", "XBT/USD"]
[270, {"b": [["11652.40000", "0.04219881", "1596666788.605148"]], "c": "758744231"}, "book-100", "XBT/USD"]
[270, {"b": [["11624.80000", "0.00000000", "1596666788.610561"], ["11609.80000", "21.20000000", "1596666704.766154", "r"]], "c": "758744231"}, "book-100", "XBT/USD"]
[270, {"b": [["11658.70000", "1.70000000", "1596666788.611175"]], "c": "758744231"}, "book-100", "XBT/USD"]
[270, {"a": [["11675.40000", "1.71100000", "1596666788.621422"]], "c": "758744231"}, "book-100", "XBT/USD"]
[270, {"b": [["11628.00000", "0.00000000", "1596666788.670790"], ["11609.80000", "21.20000000", "1596666704.766154", "r"]], "c": "758744231"}, "book-100", "XBT/USD"]
[270, {"b": [["11624.80000", "6.62492438", "1596666788.693476"]], "c": "758744231"}, "book-100", "XBT/USD"]
[270, {"b": [["11663.10000", "0.46897416", "1596666788.696482"]], "c": "3778816117"}, "book-100", "XBT/USD"]
[270, {"b": [["11656.60000", "0.85724552", "1596666788.699240"]], "c": "3778816117"}, "book-100", "XBT/USD"]
[270, {"a": [["11685.90000", "0.00000000", "1596666788.707375"], ["11713.80000", "0.37309062", "1596666771.863547", "r"]], "c": "3778816117"}, "book-100", "XBT/USD"]
[270, {"a": [["11670.90000", "0.00000000", "1596666788.708871"], ["11715.30000", "6.10000000", "1596666635.445451", "r"]], "c": "3101562944"}, "book-100", "XBT/USD"]
[270, {"b": [["11663.80000", "0.00000000", "1596666788.709129"], ["11609.80000", "21.20000000", "1596666704.766154", "r"]], "c": "3181219416"}, "book-100", "XBT/USD"]
[270, {"b": [["11644.90000", "0.30000000", "1596666788.719137"]], "c": "3181219416"}, "book-100", "XBT/USD"]
[270, {"a": [["11669.40000", "0.75551922", "1596666788.758905"]], "c": "778467353"}, "book-100", "XBT/USD"]
[270, {"b": [["11660.00000", "1.30846207", "1596666788.812228"]], "c": "778467353"}, "book-100", "XBT/USD"]
[271, [["11666.10000", "0.02332266", "1596666788.813299", "s", "l", ""]], "trade", "XBT/USD"]
[270, {"b": [["11666.10000", "1.29046328", "1596666788.813299"]], "c": "2959480711"}, "book-100", "XBT/USD"]
[270, {"a": [["11672.20000", "1.26642162", "1596666788.825431"]], "c": "2959480711"}, "book-100", "XBT/USD"]
[270, {"a": [["11669.40000", "0.00000000", "1596666788.868720"], ["11713.80000", "0.37309062", "1596666771.863547", "r"]], "c": "649957520"}, "book-100", "XBT/USD"]
[270, {"b": [["11663.10000", "0.00000000", "1596666788.868901"], ["11610.00000", "0.17085000", "1596666698.121910", "r"]], "c": "2119496993"}, "book-100", "XBT/USD"]
[270, {"b": [["11662.40000", "0.25000000", "1596666788.874653"]], "c": "4074459546"}, "book-100", "XBT/USD"]
[270, {"a": [["11669.50000", "1.91352978", "1596666788.874746"]], "c": "3433937396"}, "book-100", "XBT/USD"]
[270, {"a": [["11669.30000", "0.75551922", "1596666788.916073"]], "c": "3159146617"}, "book-100", "XBT/USD"]
[270, {"a": [["11669.30000", "0.00000000", "1596666788.962700"], ["11713.80000", "0.37309062", "1596666771.863547", "r"]], "c": "3433937396"}, "book-100", "XBT/USD"]
[270, {"a": [["11669.20000", "0.75551922", "1596666789.013899"]], "c": "3211515077"}, "book-100", "XBT/USD"]
[270, {"b": [["11665.60000", "0.00000000", "1596666789.016481"], ["11610.00000", "0.17085000", "1596666698.121910", "r"]], "c": "219401015"}, "book-100", "XBT/USD"]
[270, {"a": [["11701.20000", "0.00000000", "1596666789.019713"], ["11713.80000", "0.37309062", "1596666771.863547", "r"]], "c": "219401015"}, "book-100", "XBT/USD"]
[270, {"a": [["11677.40000", "0.93025000", "1596666789.021228"]], "c": "219401015"}, "book-100", "XBT/USD"]
[270, {"a": [["11669.20000", "0.00000000", "1596666789.060970"], ["11713.80000", "0.37309062", "1596666771.863547", "r"]], "c": "2127930886"}, "book-100", "XBT/USD"]
[270, {"a": [["11677.90000", "0.54400000", "1596666789.073265"]], "c": "2127930886"}, "book-100", "XBT/USD"]
[270, {"a": [["11669.10000", "0.75551922", "1596666789.109628"]], "c": "142276339"}, "book-100", "XBT/USD"]
[270, {"b": [["11658.80000", "0.47000511", "1596666789.149732"]], "c": "142276339"}, "book-100", "XBT/USD"]
[270, {"a": [["11669.10000", "0.00000000", "1596666789.154675"], ["11713.80000", "0.37309062", "1596666771.863547", "r"]], "c": "2127930886"}, "book-100", "XBT/USD"]
[270, {"b": [["11658.90000", "1.65487000", "1596666789.161301"]], "c": "2127930886"}, "book-100", "XBT/USD"]
[270, {"b": [["11625.00000", "0.42085000", "1596666789.195888"]], "c": "2127930886"}, "book-100", "XBT/USD"]
[270, {"a": [["11669.40000", "0.75551922", "1596666789.200084"]], "c": "130134207"}, "book-100", "XBT/USD"]
[270, {"a": [["11669.50000", "1.50000000", "1596666789.340110"]], "c": "3598240127"}, "book-100", "XBT/USD"]
[270, {"b": [["11662.40000", "0.00000000", "1596666789.352033"], ["11610.00000", "0.17085000", "1596666698.121910", "r"]], "c": "2171734075"}, "book-100", "XBT/USD"]
[270, {"b": [["11665.70000", "0.00000000", "1596666789.352492"], ["11609.80000", "21.20000000", "1596666704.766154", "r"]], "c": "3470998234"}, "book-100", "XBT/USD"]
[270, {"a": [["11669.10000", "0.09800000", "1596666789.369303"]], "c": "3044336703"}, "book-100", "XBT/USD"]
[270, {"b": [["11662.00000", "0.00000000", "1596666789.376313"], ["11607.70000", "8.40000000", "1596666777.775135", "r"]], "c": "905118292"}, "book-100", "XBT/USD"]
[270, {"b": [["11666.10000", "1.20475181", "1596666789.387052"]], "c": "3757244733"}, "book-100", "XBT/USD"]
[270, {"a": [["11674.00000", "0.00300000", "1596666789.387841"]], "c": "3757244733"}, "book-100", "XBT/USD"]
[270, {"b": [["11658.70000", "0.00000000", "1596666789.391222"], ["11607.00000", "0.17085000", "1596666720.750083", "r"]], "c": "3757244733"}, "book-100", "XBT/USD"]
[270, {"a": [["11682.30000", "0.00000000", "1596666789.416491"], ["11711.20000", "20.00000000", "1596666781.337735", "r"]], "c": "3757244733"}, "book-100", "XBT/USD"]
[270, {"b": [["11662.50000", "4.28400000", "1596666789.422564"]], "c": "1874288621"}, "book-100", "XBT/USD"]
[270, {"b": [["11652.40000", "0.00000000", "1596666789.424300"], ["11607.00000", "0.17085000", "1596666720.750083", "r"]], "c": "1874288621"}, "book-100", "XBT/USD"]
[270, {"a": [["11685.40000", "0.00000000", "1596666789.428714"], ["11713.80000", "0.37309062", "1596666771.863547", "r"]], "c": "1874288621"}, "book-100", "XBT/USD"]
[270, {"a": [["11672.00000", "0.09700000", "1596666789.430653"]], "c": "1874288621"}, "book-100", "XBT/USD"]
[270, {"a": [["11676.80000", "0.08705490", "1596666789.437651"]], "c": "1874288621"}, "book-100", "XBT/USD"]
[270, {"a": [["11671.20000", "0.00000000", "1596666789.459238"], ["11715.30000", "6.10000000", "1596666635.445451", "r"]], "c": "3764852733"}, "book-100", "XBT/USD"]
[270, {"a": [["11689.70000", "1.24623572", "1596666789.463386"]], "c": "3764852733"}, "book-100", "XBT/USD"]
[270, {"a": [["11669.40000", "0.00000000", "1596666789.475901"], ["11715.40000", "1.98115543", "1596666777.329829", "r"]], "c": "1154026898"}, "book-100", "XBT/USD"]
[270, {"b": [["11665.80000", "0.42800000", "1596666789.478362"]], "c": "1136082679"}, "book-100", "XBT/USD"]
[270, {"a": [["11668.10000", "0.41352978", "1596666789.480898"]], "c": "921788644"}, "book-100", "XBT/USD"]
[270, {"b": [["11654.90000", "0.80000000", "1596666789.483408"]], "c": "921788644"}, "book-100", "XBT/USD"]
[270, {"a": [["11678.50000", "0.69942393", "1596666789.485005"]], "c": "921788644"}, "book-100", "XBT/USD"]
[270, {"b": [["11661.20000", "0.25000000", "1596666789.489814"]], "c": "4240235530"}, "book-100", "XBT/USD"]
[270, {"b": [["11650.70000", "2.48369431", "1596666789.503046"]], "c": "4240235530"}, "book-100", "XBT/USD"]
[270, {"b": [["11665.90000", "0.64619206", "1596666789.509708"]], "c": "1556109665"}, "book-100", "XBT/USD"]
[270, {"a": [["11679.00000", "1.64160000", "1596666789.512973"]], "c": "1556109665"}, "book-100", "XBT/USD"]
[270, {"b": [["11660.00000", "0.00000000", "1596666789.519239"], ["11607.70000", "8.40000000", "1596666777.775135", "r"]], "c": "2751352851"}, "book-100", "XBT/USD"]
[270, {"a": [["11670.50000", "0.55030000", "1596666789.528345"]], "c": "3900736561"}, "book-100", "XBT/USD"]
[270, {"b": [["11666.10000", "0.67835468", "1596666789.561991"]], "c": "3451187034"}, "book-100", "XBT/USD"]
[270, {"a": [["11676.80000", "0.05313798", "1596666789.644017"]], "c": "3451187034"}, "book-100", "XBT/USD"]
[270, {"b": [["11654.20000", "1.62415562", "1596666789.644273"]], "c": "3451187034"}, "book-100", "XBT/USD"]
[270, {"a": [["11666.20000", "3.25237722", "1596666789.714771"]], "c": "1412017124"}, "book-100", "XBT/USD"]
[270, {"a": [["11670.80000", "2.08921444", "1596666789.720273"]], "c": "2180488077"}, "book-100", "XBT/USD"]
[270, {"b": [["11661.70000", "0.93025000", "1596666789.756176"]], "c": "2553788712"}, "book-100", "XBT/USD"]
[270, {"a": [["11674.00000", "1.03384000", "1596666789.759187"]], "c": "2553788712"}, "book-100", "XBT/USD"]
[270, {"b": [["11652.00000", "0.04220026", "1596666789.765912"]], "c": "2553788712"}, "book-100", "XBT/USD"]
[270, {"a": [["11666.20000", "0.10237722", "1596666789.773565"]], "c": "27983254"}, "book-100", "XBT/USD"]
[270, {"b": [["11664.50000", "0.00000000", "1596666789.779292"], ["11609.80000", "21.20000000", "1596666704.766154", "r"]], "c": "3167501217"}, "book-100", "XBT/USD"]
[270, {"a": [["11703.40000", "0.00000000", "1596666789.788572"], ["11711.20000", "20.00000000", "1596666781.337735", "r"]], "c": "3167501217"}, "book-100", "XBT/USD"]
[270, {"a": [["11710.00000", "2.24757793", "1596666789.792766"]], "c": "3167501217"}, "book-100", "XBT/USD"]
[270, {"b": [["11655.40000", "0.00000000", "1596666789.842495"], ["11607.70000", "8.40000000", "1596666777.775135", "r"]], "c": "3167501217"}, "book-100", "XBT/USD"]
[270, {"b": [["11646.00000", "0.00000000", "1596666789.892176"], ["11607.00000", "0.17085000", "1596666720.750083", "r"]], "c": "3167501217"}, "book-100", "XBT/USD"]
[270, {"a": [["11688.40000", "0.00000000", "1596666789.892322"], ["11711.20000", "20.00000000", "1596666781.337735", "r"]], "c": "3167501217"}, "book-100", "XBT/USD"]
[270, {"b": [["11652.00000", "0.08042864", "1596666789.897363"]], "c": "3167501217"}, "book-100", "XBT/USD"]
[270, {"b": [["11651.00000", "1.25442795", "1596666789.897852"]], "c": "3167501217"}, "book-100", "XBT/USD"]
[270, {"b": [["11652.00000", "0.03822838", "1596666789.897988"]], "c": "3167501217"}, "book-100", "XBT/USD"]
[270, {"b": [["11658.90000", "0.62200000", "1596666789.930212"]], "c": "3167501217"}, "book-100", "XBT/USD"]
[270, {"b": [["11661.70000", "0.00000000", "1596666789.951505"], ["11607.00000", "0.17085000", "1596666720.750083", "r"]], "c": "2060909656"}, "book-100", "XBT/USD"]
[270, {"a": [["11670.80000", "1.71578367", "1596666789.999513"]], "c": "1315830676"}, "book-100", "XBT/USD"]
[270, {"a": [["11672.30000", "0.00000000", "1596666790.019830"], ["11713.80000", "0.37309062", "1596666771.863547", "r"]], "c": "1315830676"}, "book-100", "XBT/USD"]
[270, {"a": [["11675.40000", "0.00000000", "1596666790.102048"], ["11715.30000", "6.10000000", "1596666635.445451", "r"]], "c": "1315830676"}, "book-100", "XBT/USD"]
[270, {"b": [["11662.10000", "0.00000000", "1596666790.134868"], ["11606.60000", "0.36139355", "1596666776.377050", "r"]], "c": "1260954485"}, "book-100", "XBT/USD"]
[270, {"b": [["11656.30000", "1.71300000", "1596666790.222247"]], "c": "1260954485"}, "book-100", "XBT/USD"]
[270, {"b": [["11625.00000", "0.25000000", "1596666790.235283"]], "c": "1260954485"}, "book-100", "XBT/USD"]
[270, {"a": [["11672.80000", "1.79821094", "1596666790.236221"]], "c": "1260954485"}, "book-100", "XBT/USD"]
[270, {"a": [["11669.10000", "0.49047486", "1596666790.251298"]], "c": "698759844"}, "book-100", "XBT/USD"]
[270, {"b": [["11660.90000", "0.09621094", "1596666790.254565"]], "c": "3874986590"}, "book-100", "XBT/USD"]
[270, {"a": [["11672.80000", "1.70200000", "1596666790.254898"]], "c": "3874986590"}, "book-100", "XBT/USD"]
[270, {"a": [["11666.20000", "0.62220699", "1596666790.290898"]], "c": "3915848974"}, "book-100", "XBT/USD"]
[270, {"a": [["11669.70000", "0.09621094", "1596666790.292152"]], "c": "1310251523"}, "book-100", "XBT/USD"]
[270, {"a": [["11670.70000", "4.28200000", "1596666790.294733"]], "c": "1310251523"}, "book-100", "XBT/USD"]
[270, {"a": [["11670.00000", "0.00000000", "1596666790.334320"], ["11713.80000", "0.37309062", "1596666771.863547", "r"]], "c": "3400699826"}, "book-100", "XBT/USD"]
[270, {"a": [["11669.00000", "2.33898188", "1596666790.338043"]], "c": "1743713627"}, "book-100", "XBT/USD"]
[270, {"a": [["11692.90000", "0.74885472", "1596666790.352290"]], "c": "1743713627"}, "book-100", "XBT/USD"]
[270, {"a": [["11669.40000", "0.75551922", "1596666790.354886"]], "c": "2377635125"}, "book-100", "XBT/USD"]
[270, {"b": [["11611.70000", "0.00000000", "1596666790.370278"], ["11607.00000", "0.17085000", "1596666720.750083", "r"]], "c": "2377635125"}, "book-100", "XBT/USD"]
[270, {"b": [["11610.60000", "0.74885472", "1596666790.370815"]], "c": "2377635125"}, "book-100", "XBT/USD"]
[270, {"b": [["11664.50000", "0.97500000", "1596666790.391284"]], "c": "3397382735"}, "book-100", "XBT/USD"]
[270, {"a": [["11690.40000", "0.00000000", "1596666790.391929"], ["11710.70000", "3.52183532", "1596666711.393054", "r"]], "c": "3397382735"}, "book-100", "XBT/USD"]
[270, {"a": [["11669.90000", "0.00000000", "1596666790.401979"], ["11711.20000", "20.00000000", "1596666781.337735", "r"]], "c": "2190311032"}, "book-100", "XBT/USD"]
[270, {"a": [["11669.40000", "0.00000000", "1596666790.402092"], ["11713.80000", "0.37309062", "1596666771.863547", "r"]], "c": "3974079081"}, "book-100", "XBT/USD"]
[270, {"b": [["11651.00000", "0.00000000", "1596666790.409446"], ["11607.70000", "8.40000000", "1596666777.775135", "r"]], "c": "3974079081"}, "book-100", "XBT/USD"]
[270, {"a": [["11668.90000", "0.75551922", "1596666790.455915"]], "c": "3983859326"}, "book-100", "XBT/USD"]
[270, {"b": [["11656.30000", "0.00000000", "1596666790.457369"], ["11607.00000", "0.17085000", "1596666720.750083", "r"]], "c": "3983859326"}, "book-100", "XBT/USD"]
[270, {"b": [["11666.10000", "0.45335468", "1596666790.463039"]], "c": "497765482"}, "book-100", "XBT/USD"]
[270, {"b": [["11653.60000", "0.50000000", "1596666790.474194"]], "c": "497765482"}, "book-100", "XBT/USD"]
[270, {"a": [["11672.40000", "0.00000000", "1596666790.484005"], ["11713.80000", "0.37309062", "1596666771.863547", "r"]], "c": "497765482"}, "book-100", "XBT/USD"]
[270, {"b": [["11649.70000", "0.38000000", "1596666790.491844"]], "c": "497765482"}, "book-100", "XBT/USD"]
[270, {"a": [["11667.90000", "0.25839231", "1596666790.498527"]], "c": "2869864812"}, "book-100", "XBT/USD"]
[270, {"a": [["11680.40000", "0.00000000", "1596666790.499761"], ["11713.80000", "0.37309062", "1596666771.863547", "r"]], "c": "2869864812"}, "book-100", "XBT/USD"]
[270, {"a": [["11681.20000", "0.40573600", "1596666790.510499"]], "c": "2869864812"}, "book-100", "XBT/USD"]
[270, {"b": [["11656.00000", "0.00000000", "1596666790.513421"], ["11607.00000", "0.17085000", "1596666720.750083", "r"]], "c": "2869864812"}, "book-100", "XBT/USD"]
[270, {"a": [["11671.60000", "0.79178000", "1596666790.520337"]], "c": "2869864812"}, "book-100", "XBT/USD"]
[270, {"b": [["11644.60000", "0.43900000", "1596666790.526541"]], "c": "2869864812"}, "book-100", "XBT/USD"]
[270, {"b": [["11651.00000", "1.25199170", "1596666790.535406"]], "c": "2869864812"}, "book-100", "XBT/USD"]
[270, {"b": [["11665.80000", "0.65300000", "1596666790.539010"]], "c": "256596073"}, "book-100", "XBT/USD"]
[270, {"a": [["11687.50000", "0.00000000", "1596666790.543074"], ["11713.80000", "0.37309062", "1596666771.863547", "r"]], "c": "256596073"}, "book-100", "XBT/USD"]
[270, {"b": [["11664.50000", "0.00000000", "1596666790.547475"], ["11607.70000", "8.40000000", "1596666777.775135", "r"]], "c": "1216577299"}, "book-100", "XBT/USD"]
[270, {"a": [["11668.90000", "0.00000000", "1596666790.572359"], ["11715.30000", "6.10000000", "1596666635.445451", "r"]], "c": "3560166450"}, "book-100", "XBT/USD"]
[270, {"b": [["11665.90000", "0.00353041", "1596666790.574406"]], "c": "1521892470"}, "book-100", "XBT/USD"]
[270, {"b": [["11654.90000", "0.30000000", "1596666790.622400"]], "c": "1521892470"}, "book-100", "XBT/USD"]
[270, {"a": [["11668.90000", "0.75551922", "1596666790.646746"]], "c": "2448093440"}, "book-100", "XBT/USD"]
[270, {"a": [["11678.50000", "0.00000000", "1596666790.673031"], ["11715.30000", "6.10000000", "1596666635.445451", "r"]], "c": "2448093440"}, "book-100", "XBT/USD"]
[270, {"a": [["11669.10000", "0.09800000", "1596666790.681720"]], "c": "2327515464"}, "book-100", "XBT/USD"]
[270, {"a": [["11668.00000", "0.65291516", "1596666790.687783"]], "c": "3652836098"}, "book-100", "XBT/USD"]
[270, {"a": [["11668.90000", "0.00000000", "1596666790.700337"], ["11715.40000", "1.98115543", "1596666777.329829", "r"]], "c": "3505046708"}, "book-100", "XBT/USD"]
[270, {"a": [["11669.20000", "0.64286199", "1596666790.700938"]], "c": "4205130556"}, "book-100", "XBT/USD"]
[270, {"a": [["11670.50000", "1.19312220", "1596666790.703266"]], "c": "3490435668"}, "book-100", "XBT/USD"]
[270, {"b": [["11649.40000", "0.85709627", "1596666790.703699"]], "c": "3490435668"}, "book-100", "XBT/USD"]
[270, {"a": [["11673.80000", "0.85714932", "1596666790.704484"]], "c": "3490435668"}, "book-100", "XBT/USD"]
[270, {"a": [["11673.60000", "0.85717311", "1596666790.704753"]], "c": "3490435668"}, "book-100", "XBT/USD"]
[270, {"b": [["11649.10000", "0.85722022", "1596666790.705812"]], "c": "3490435668"}, "book-100", "XBT/USD"]
[270, {"b": [["11663.90000", "0.64286199", "1596666790.719976"]], "c": "2083794151"}, "book-100", "XBT/USD"]
[270, {"a": [["11675.80000", "0.69950528", "1596666790.733326"]], "c": "2083794151"}, "book-100", "XBT/USD"]
[270, {"a": [["11668.90000", "0.77622000", "1596666790.759869"]], "c": "2217772531"}, "book-100", "XBT/USD"]
[270, {"b": [["11665.90000", "0.00000000", "1596666790.772791"], ["11610.00000", "0.17085000", "1596666698.121910", "r"]], "c": "1314246538"}, "book-100", "XBT/USD"]
[270, {"b": [["11655.80000", "0.00000000", "1596666790.773070"], ["11609.80000", "21.20000000", "1596666704.766154", "r"]], "c": "1314246538"}, "book-100", "XBT/USD"]
[270, {"b": [["11662.50000", "0.00000000", "1596666790.797469"], ["11607.70000", "8.40000000", "1596666777.775135", "r"]], "c": "1042933604"}, "book-100", "XBT/USD"]
[270, {"b": [["11654.20000", "0.89964000", "1596666790.799997"]], "c": "1042933604"}, "book-100", "XBT/USD"]
[270, {"b": [["11656.50000", "0.85724552", "1596666790.801876"]], "c": "1042933604"}, "book-100", "XBT/USD"]
[270, {"a": [["11672.20000", "0.00000000", "1596666790.834974"], ["11710.70000", "3.52183532", "1596666711.393054", "r"]], "c": "1042933604"}, "book-100", "XBT/USD"]
[270, {"b": [["11654.00000", "0.00000000", "1596666790.865012"], ["11607.00000", "0.17085000", "1596666720.750083", "r"]], "c": "1042933604"}, "book-100", "XBT/USD"]
[271, [["11666.10000", "0.02332266", "1596666790.897196", "s", "l", ""]], "trade", "XBT/USD"]
[270, {"b": [["11666.10000", "0.43003202", "1596666790.897196"]], "c": "814621642"}, "book-100", "XBT/USD"]
[270, {"b": [["11652.30000", "0.59951253", "1596666790.901969"]], "c": "814621642"}, "book-100", "XBT/USD"]
[270, {"b": [["11651.00000", "0.00000000", "1596666790.915085"], ["11606.60000", "0.36139355", "1596666776.377050", "r"]], "c": "814621642"}, "book-100", "XBT/USD"]
[270, {"a": [["11667.90000", "1.61217219", "1596666790.915648"]], "c": "1254110395"}, "book-100", "XBT/USD"]
[270, {"b": [["11658.80000", "0.00000000", "1596666790.916350"], ["11604.10000", "1.51500000", "1596666763.121463", "r"]], "c": "1254110395"}, "book-100", "XBT/USD"]
[270, {"b": [["11666.10000", "0.00000000", "1596666790.964446"], ["11603.20000", "2.50039088", "1596666777.334144", "r"]], "c": "1396121825"}, "book-100", "XBT/USD"]
[270, {"b": [["11652.00000", "0.50324185", "1596666790.980762"]], "c": "1396121825"}, "book-100", "XBT/USD"]
[270, {"a": [["11677.40000", "0.00000000", "1596666790.984831"], ["11711.20000", "20.00000000", "1596666781.337735", "r"]], "c": "1396121825"}, "book-100", "XBT/USD"]
[270, {"b": [["11653.30000", "0.10351023", "1596666790.986761"]], "c": "1396121825"}, "book-100", "XBT/USD"]
[270, {"b": [["11661.20000", "0.00000000", "1596666790.987050"], ["11603.20000", "2.50039088", "1596666777.334144", "r"]], "c": "2652363192"}, "book-100", "XBT/USD"]
[270, {"a": [["11669.40000", "0.39693579", "1596666790.993065"]], "c": "3354868151"}, "book-100", "XBT/USD"]
[270, {"b": [["11651.00000", "0.72471462", "1596666790.993161"]], "c": "3354868151"}, "book-100", "XBT/USD"]
[270, {"a": [["11666.20000", "0.91220699", "1596666791.002129"]], "c": "1073240064"}, "book-100", "XBT/USD"]
[270, {"b": [["11659.80000", "4.28300000", "1596666791.020862"]], "c": "333279880"}, "book-100", "XBT/USD"]
[270, {"a": [["11670.70000", "0.00000000", "1596666791.023922"], ["11711.20000", "20.00000000", "1596666781.337735", "r"]], "c": "333279880"}, "book-100", "XBT/USD"]
[270, {"a": [["11665.90000", "0.50000000", "1596666791.025735"]], "c": "3311118039"}, "book-100", "XBT/USD"]
[270, {"b": [["11660.00000", "0.10000000", "1596666791.025840"]], "c": "264629479"}, "book-100", "XBT/USD"]
[270, {"b": [["11665.80000", "0.42800000", "1596666791.032897"]], "c": "2688530264"}, "book-100", "XBT/USD"]
[270, {"a": [["11679.00000", "0.00000000", "1596666791.038112"], ["11711.20000", "20.00000000", "1596666781.337735", "r"]], "c": "2688530264"}, "book-100", "XBT/USD"]
[270, {"a": [["11668.10000", "4.69652978", "1596666791.038716"]], "c": "2773077792"}, "book-100", "XBT/USD"]
[270, {"b": [["11660.00000", "1.10000000", "1596666791.062325"]], "c": "2868387478"}, "book-100", "XBT/USD"]
[270, {"a": [["11665.90000", "0.56996798", "1596666791.086635"]], "c": "1716583561"}, "book-100", "XBT/USD"]
[270, {"a": [["11668.10000", "4.28300000", "1596666791.099921"]], "c": "1627446025"}, "book-100", "XBT/USD"]
[270, {"a": [["11675.50000", "1.64160000", "1596666791.110006"]], "c": "1627446025"}, "book-100", "XBT/USD"]
[270, {"b": [["11664.90000", "0.22500000", "1596666791.148987"]], "c": "2659078338"}, "book-100", "XBT/USD"]
[270, {"b": [["11660.00000", "0.10000000", "1596666791.173814"]], "c": "2285667210"}, "book-100", "XBT/USD"]
[270, {"b": [["11664.60000", "0.08572029", "1596666791.189612"]], "c": "1885492739"}, "book-100", "XBT/USD"]
[270, {"a": [["11667.20000", "0.41352978", "1596666791.237070"]], "c": "532257422"}, "book-100", "XBT/USD"]
[270, {"a": [["11666.20000", "0.39237722", "1596666791.311271"]], "c": "415698003"}, "book-100", "XBT/USD"]
[270, {"b": [["11654.40000", "0.00000000", "1596666791.311853"], ["11607.70000", "8.40000000", "1596666777.775135", "r"]], "c": "415698003"}, "book-100", "XBT/USD"]
[270, {"b": [["11660.90000", "0.00000000", "1596666791.317150"], ["11607.00000", "0.17085000", "1596666720.750083", "r"]], "c": "1841951149"}, "book-100", "XBT/USD"]
[270, {"a": [["11680.90000", "0.00000000", "1596666791.336595"], ["11710.70000", "3.52183532", "1596666711.393054", "r"]], "c": "1841951149"}, "book-100", "XBT/USD"]
[270, {"a": [["11675.80000", "6.89950528", "1596666791.395818"]], "c": "1841951149"}, "book-100", "XBT/USD"]
[270, {"a": [["11708.50000", "0.00000000", "1596666791.409731"], ["11711.20000", "20.00000000", "1596666781.337735", "r"]], "c": "1841951149"}, "book-100", "XBT/USD"]
[270, {"a": [["11667.20000", "0.00000000", "1596666791.426255"], ["11713.80000", "0.37309062", "1596666771.863547", "r"]], "c": "4272936444"}, "book-100", "XBT/USD"]
[270, {"a": [["11685.10000", "0.00000000", "1596666791.464884"], ["11715.30000", "6.10000000", "1596666635.445451", "r"]], "c": "4272936444"}, "book-100", "XBT/USD"]
[270, {"a": [["11714.90000", "0.30235286", "1596666791.504328"]], "c": "4272936444"}, "book-100", "XBT/USD"]
[270, {"b": [["11663.90000", "0.00000000", "1596666791.510504"], ["11606.60000", "0.36139355", "1596666776.377050", "r"]], "c": "849048934"}, "book-100", "XBT/USD"]
[270, {"b": [["11653.60000", "0.00000000", "1596666791.515209"], ["11604.10000", "1.51500000", "1596666763.121463", "r"]], "c": "849048934"}, "book-100", "XBT/USD"]
[270, {"b": [["11644.80000", "0.50000000", "1596666791.527292"]], "c": "849048934"}, "book-100", "XBT/USD"]
[270, {"a": [["11669.40000", "0.00000000", "1596666791.533716"], ["11715.30000", "6.10000000", "1596666635.445451", "r"]], "c": "1154922473"}, "book-100", "XBT/USD"]
[270, {"b": [["11651.90000", "0.63900000", "1596666791.584937"]], "c": "1154922473"}, "book-100", "XBT/USD"]
[270, {"b": [["11652.30000", "0.24977232", "1596666791.596833"]], "c": "1154922473"}, "book-100", "XBT/USD"]
[270, {"a": [["11669.20000", "0.00000000", "1596666791.604621"], ["11715.40000", "1.98115543", "1596666777.329829", "r"]], "c": "3381923713"}, "book-100", "XBT/USD"]
[270, {"a": [["11667.80000", "0.75551922", "1596666791.613012"]], "c": "2872872014"}, "book-100", "XBT/USD"]
[270, {"a": [["11665.90000", "0.99565885", "1596666791.623823"]], "c": "4141014435"}, "book-100", "XBT/USD"]
[270, {"b": [["11654.20000", "0.00000000", "1596666791.624696"], ["11604.10000", "1.51500000", "1596666763.121463", "r"]], "c": "4141014435"}, "book-100", "XBT/USD"]
[270, {"b": [["11659.70000", "0.25000000", "1596666791.631282"]], "c": "1038659847"}, "book-100", "XBT/USD"]
[270, {"a": [["11666.20000", "0.39000000", "1596666791.637388"]], "c": "480760753"}, "book-100", "XBT/USD"]
[270, {"a": [["11680.90000", "0.33822591", "1596666791.639370"]], "c": "480760753"}, "book-100", "XBT/USD"]
[270, {"b": [["11654.70000", "0.33898625", "1596666791.657481"]], "c": "480760753"}, "book-100", "XBT/USD"]
[270, {"b": [["11651.30000", "0.71207886", "1596666791.657881"]], "c": "480760753"}, "book-100", "XBT/USD"]
[270, {"b": [["11649.00000", "1.42443890", "1596666791.661803"]], "c": "480760753"}, "book-100", "XBT/USD"]
[270, {"b": [["11653.70000", "1.24049485", "1596666791.665598"]], "c": "480760753"}, "book-100", "XBT/USD"]
[270, {"a": [["11670.50000", "0.55030000", "1596666791.666636"]], "c": "480760753"}, "book-100", "XBT/USD"]
[270, {"a": [["11668.80000", "0.01491632", "1596666791.681698"]], "c": "330179561"}, "book-100", "XBT/USD"]
[270, {"b": [["11655.60000", "0.01491632", "1596666791.681830"]], "c": "330179561"}, "book-100", "XBT/USD"]
[270, {"b": [["11664.90000", "0.00000000", "1596666791.702862"], ["11610.00000", "0.17085000", "1596666698.121910", "r"]], "c": "3051528786"}, "book-100", "XBT/USD"]
[270, {"a": [["11684.30000", "0.71006773", "1596666791.708521"]], "c": "3051528786"}, "book-100", "XBT/USD"]
[270, {"b": [["11654.60000", "0.07458201", "1596666791.752788"]], "c": "3051528786"}, "book-100", "XBT/USD"]
[270, {"a": [["11669.40000", "0.07458201", "1596666791.753192"]], "c": "3051528786"}, "book-100", "XBT/USD"]
[270, {"a": [["11667.80000", "0.00000000", "1596666791.755020"], ["11711.20000", "20.00000000", "1596666781.337735", "r"]], "c": "1456936116"}, "book-100", "XBT/USD"]
[270, {"a": [["11668.30000", "0.39506153", "1596666791.778471"]], "c": "2756138988"}, "book-100", "XBT/USD"]
[270, {"b": [["11652.00000", "0.46501347", "1596666791.784842"]], "c": "2756138988"}, "book-100", "XBT/USD"]
[270, {"a": [["11666.00000", "0.63592000", "1596666791.838437"]], "c": "2419404232"}, "book-100", "XBT/USD"]
[270, {"b": [["11650.90000", "0.54233893", "1596666791.868228"]], "c": "2419404232"}, "book-100", "XBT/USD"]
[270, {"a": [["11674.00000", "0.00300000", "1596666791.920660"]], "c": "2419404232"}, "book-100", "XBT/USD"]
[270, {"a": [["11666.40000", "0.41352978", "1596666791.963782"]], "c": "693425206"}, "book-100", "XBT/USD"]
[270, {"b": [["11659.80000", "0.00000000", "1596666791.966114"], ["11610.00000", "0.17085000", "1596666698.121910", "r"]], "c": "3157770710"}, "book-100", "XBT/USD"]
[270, {"a": [["11665.90000", "1.49565885", "1596666791.968032"]], "c": "1735063707"}, "book-100", "XBT/USD"]
[270, {"a": [["11670.90000", "0.17899682", "1596666791.972806"]], "c": "1735063707"}, "book-100", "XBT/USD"]
[270, {"a": [["11665.90000", "1.99565885", "1596666791.995893"]], "c": "1517951861"}, "book-100", "XBT/USD"]
[270, {"a": [["11681.70000", "0.68043178", "1596666791.998343"]], "c": "1517951861"}, "book-100", "XBT/USD"]
[270, {"b": [["11650.90000", "0.04420000", "1596666792.016853"]], "c": "1517951861"}, "book-100", "XBT/USD"]
[270, {"a": [["11669.50000", "0.00000000", "1596666792.068459"], ["11710.40000", "1.16811308", "1596666772.597033", "r"]], "c": "1517951861"}, "book-100", "XBT/USD"]
[270, {"a": [["11680.80000", "0.11164617", "1596666792.100362"]], "c": "1517951861"}, "book-100", "XBT/USD"]
[270, {"b": [["11653.70000", "0.00000000", "1596666792.117415"], ["11609.80000", "21.20000000", "1596666704.766154", "r"]], "c": "1517951861"}, "book-100", "XBT/USD"]
[270, {"b": [["11660.00000", "0.00000000", "1596666792.183789"], ["11607.70000", "8.40000000", "1596666777.775135", "r"]], "c": "1228653307"}, "book-100", "XBT/USD"]
[270, {"b": [["11662.20000", "0.12500000", "1596666792.187313"]], "c": "3966128370"}, "book-100", "XBT/USD"]
[270, {"b": [["11640.30000", "1.03370000", "1596666792.205566"]], "c": "3966128370"}, "book-100", "XBT/USD"]
[270, {"b": [["11646.30000", "0.17899764", "1596666792.217735"]], "c": "3966128370"}, "book-100", "XBT/USD"]
[270, {"b": [["11662.30000", "0.00000000", "1596666792.234638"], ["11609.80000", "21.20000000", "1596666704.766154", "r"]], "c": "1822348928"}, "book-100", "XBT/USD"]
[270, {"a": [["11671.60000", "1.29178000", "1596666792.251424"]], "c": "1822348928"}, "book-100", "XBT/USD"]
[270, {"a": [["11675.40000", "1.01730000", "1596666792.306649"]], "c": "1822348928"}, "book-100", "XBT/USD"]
[270, {"b": [["11645.90000", "1.21142816", "1596666792.328123"]], "c": "1822348928"}, "book-100", "XBT/USD"]
[270, {"a": [["11692.20000", "0.00000000", "1596666792.378053"], ["11710.40000", "1.16811308", "1596666772.597033", "r"]], "c": "1822348928"}, "book-100", "XBT/USD"]
[270, {"b": [["11665.80000", "0.00000000", "1596666792.456736"], ["11607.70000", "8.40000000", "1596666777.775135", "r"]], "c": "3555958367"}, "book-100", "XBT/USD"]
[270, {"a": [["11666.20000", "0.10000000", "1596666792.459147"]], "c": "9423506"}, "book-100", "XBT/USD"]
[270, {"a": [["11681.00000", "0.00000000", "1596666792.494408"], ["11710.60000", "2.80039129", "1596666770.582883", "r"]], "c": "9423506"}, "book-100", "XBT/USD"]
[270, {"b": [["11653.30000", "0.00000000", "1596666792.494822"], ["11607.00000", "0.17085000", "1596666720.750083", "r"]], "c": "9423506"}, "book-100", "XBT/USD"]
[270, {"a": [["11686.70000", "2.31789979", "1596666792.495916"]], "c": "9423506"}, "book-100", "XBT/USD"]
[270, {"b": [["11622.00000", "0.00000000", "1596666792.500004"], ["11604.10000", "1.51500000", "1596666763.121463", "r"]], "c": "9423506"}, "book-100", "XBT/USD"]
[270, {"a": [["11681.70000", "0.00000000", "1596666792.500138"], ["11710.70000", "3.52183532", "1596666711.393054", "r"]], "c": "9423506"}, "book-100", "XBT/USD"]
[270, {"b": [["11653.50000", "0.00000000", "1596666792.500494"], ["11603.20000", "2.50039088", "1596666777.334144", "r"]], "c": "9423506"}, "book-100", "XBT/USD"]
[270, {"b": [["11664.60000", "0.00000000", "1596666792.501736"], ["11602.60000", "1.48021868", "1596666784.125874", "r"]], "c": "919881253"}, "book-100", "XBT/USD"]
[270, {"a": [["11666.10000", "1.50000000", "1596666792.506420"]], "c": "1266258213"}, "book-100", "XBT/USD"]
[270, {"b": [["11652.60000", "2.00000000", "1596666792.507650"]], "c": "1266258213"}, "book-100", "XBT/USD"]
[270, {"b": [["11655.60000", "0.00000000", "1596666792.512476"], ["11602.60000", "1.48021868", "1596666784.125874", "r"]], "c": "3170213541"}, "book-100", "XBT/USD"]
[270, {"a": [["11675.50000", "0.00000000", "1596666792.517204"], ["11710.70000", "3.52183532", "1596666711.393054", "r"]], "c": "3170213541"}, "book-100", "XBT/USD"]
[270, {"a": [["11675.80000", "6.20000000", "1596666792.521054"]], "c": "3170213541"}, "book-100", "XBT/USD"]
[270, {"a": [["11668.10000", "0.00000000", "1596666792.529442"], ["11711.20000", "20.00000000", "1596666781.337735", "r"]], "c": "19048040"}, "book-100", "XBT/USD"]
[270, {"b": [["11662.20000", "0.08250000", "1596666792.531070"]], "c": "2106895839"}, "book-100", "XBT/USD"]
[270, {"a": [["11665.90000", "1.49565885", "1596666792.540097"]], "c": "3051525306"}, "book-100", "XBT/USD"]
[270, {"b": [["11650.00000", "0.00000000", "1596666792.540311"], ["11602.20000", "2.01681621", "1596666634.588713", "r"]], "c": "3051525306"}, "book-100", "XBT/USD"]
[270, {"a": [["11665.90000", "1.42569087", "1596666792.541396"]], "c": "2134180632"}, "book-100", "XBT/USD"]
[270, {"b": [["11654.70000", "0.00000000", "1596666792.542520"], ["11602.10000", "11.25550194", "1596666780.609892", "r"]], "c": "2134180632"}, "book-100", "XBT/USD"]
[270, {"b": [["11649.10000", "2.16643801", "1596666792.542696"]], "c": "2134180632"}, "book-100", "XBT/USD"]
[270, {"b": [["11652.00000", "0.00000000", "1596666792.544762"], ["11601.10000", "3.00166376", "1596666779.976375", "r"]], "c": "2134180632"}, "book-100", "XBT/USD"]
[270, {"a": [["11672.70000", "1.64160000", "1596666792.548127"]], "c": "2134180632"}, "book-100", "XBT/USD"]
[270, {"a": [["11678.30000", "2.00000000", "1596666792.550455"]], "c": "2134180632"}, "book-100", "XBT/USD"]
[270, {"a": [["11665.90000", "0.92569087", "1596666792.550834"]], "c": "2579863602"}, "book-100", "XBT/USD"]
[270, {"b": [["11650.20000", "0.45989690", "1596666792.553826"]], "c": "2579863602"}, "book-100", "XBT/USD"]
[270, {"b": [["11659.70000", "0.00000000", "1596666792.555029"], ["11601.10000", "3.00166376", "1596666779.976375", "r"]], "c": "2693264279"}, "book-100", "XBT/USD"]
[270, {"b": [["11663.10000", "0.22500000", "1596666792.558949"]], "c": "2699093363"}, "book-100", "XBT/USD"]
[270, {"b": [["11654.60000", "0.00000000", "1596666792.559032"], ["11601.10000", "3.00166376", "1596666779.976375", "r"]], "c": "2699093363"}, "book-100", "XBT/USD"]
[270, {"a": [["11676.90000", "0.00000000", "1596666792.561829"], ["11710.70000", "3.52183532", "1596666711.393054", "r"]], "c": "2699093363"}, "book-100", "XBT/USD"]
[270, {"a": [["11667.90000", "1.35377988", "1596666792.571564"]], "c": "2783346401"}, "book-100", "XBT/USD"]
[270, {"a": [["11673.50000", "0.48047057", "1596666792.572757"]], "c": "2783346401"}, "book-100", "XBT/USD"]
[270, {"b": [["11651.00000", "0.00000000", "1596666792.577197"], ["11600.40000", "0.90458128", "1596666777.993986", "r"]], "c": "2783346401"}, "book-100", "XBT/USD"]
[270, {"b": [["11656.70000", "0.10000000", "1596666792.582460"]], "c": "3117723136"}, "book-100", "XBT/USD"]
[270, {"b": [["11652.30000", "0.00000000", "1596666792.582572"], ["11600.40000", "0.90458128", "1596666777.993986", "r"]], "c": "3117723136"}, "book-100", "XBT/USD"]
[270, {"a": [["11673.20000", "0.69958361", "1596666792.587264"]], "c": "3117723136"}, "book-100", "XBT/USD"]
[270, {"a": [["11665.80000", "0.55030000", "1596666792.603426"]], "c": "2662577630"}, "book-100", "XBT/USD"]
[270, {"a": [["11666.40000", "0.00000000", "1596666792.616034"], ["11710.40000", "1.16811308", "1596666772.597033", "r"]], "c": "766787"}, "book-100", "XBT/USD"]
[270, {"b": [["11658.10000", "4.28000000", "1596666792.625119"]], "c": "3928066802"}, "book-100", "XBT/USD"]
[270, {"b": [["11649.10000", "0.85722022", "1596666792.644331"]], "c": "3928066802"}, "book-100", "XBT/USD"]
[270, {"a": [["11663.20000", "0.06996798", "1596666792.652693"]], "c": "3247739913"}, "book-100", "XBT/USD"]
[270, {"a": [["11663.20000", "0.56996798", "1596666792.655637"]], "c": "4266195638"}, "book-100", "XBT/USD"]
[270, {"b": [["11647.60000", "0.00000000", "1596666792.659226"], ["11600.40000", "0.90458128", "1596666777.993986", "r"]], "c": "4266195638"}, "book-100", "XBT/USD"]
[270, {"a": [["11665.90000", "0.42569087", "1596666792.666119"]], "c": "3333492598"}, "book-100", "XBT/USD"]
[270, {"a": [["11665.70000", "0.25847626", "1596666792.668752"]], "c": "3036713133"}, "book-100", "XBT/USD"]
[270, {"b": [["11645.50000", "0.34988544", "1596666792.674656"]], "c": "3036713133"}, "book-100", "XBT/USD"]
[270, {"a": [["11668.00000", "0.01000000", "1596666792.679730"]], "c": "593187151"}, "book-100", "XBT/USD"]
[270, {"b": [["11663.10000", "0.00000000", "1596666792.684180"], ["11600.40000", "0.90458128", "1596666777.993986", "r"]], "c": "2914669584"}, "book-100", "XBT/USD"]
[270, {"a": [["11665.00000", "0.40000000", "1596666792.706178"]], "c": "3979440455"}, "book-100", "XBT/USD"]
[270, {"b": [["11647.70000", "0.04221583", "1596666792.713359"]], "c": "3979440455"}, "book-100", "XBT/USD"]
[270, {"a": [["11670.50000", "0.00000000", "1596666792.718529"], ["11710.00000", "2.24757793", "1596666789.792766", "r"]], "c": "3979440455"}, "book-100", "XBT/USD"]
[270, {"b": [["11636.00000", "6.42337540", "1596666792.719222"]], "c": "3979440455"}, "book-100", "XBT/USD"]
[270, {"b": [["11646.50000", "2.59712626", "1596666792.723800"]], "c": "3979440455"}, "book-100", "XBT/USD"]
[270, {"a": [["11663.20000", "0.50000000", "1596666792.750096"]], "c": "2814731307"}, "book-100", "XBT/USD"]
[270, {"a": [["11678.20000", "0.00000000", "1596666792.750294"], ["11710.10000", "0.89650546", "1596666771.484931", "r"]], "c": "2814731307"}, "book-100", "XBT/USD"]
[270, {"a": [["11676.10000", "0.00000000", "1596666792.751608"], ["11710.40000", "1.16811308", "1596666772.597033", "r"]], "c": "2814731307"}, "book-100", "XBT/USD"]
[270, {"a": [["11670.80000", "1.86578367", "1596666792.751923"]], "c": "2814731307"}, "book-100", "XBT/USD"]
[270, {"a": [["11663.20000", "1.00000000", "1596666792.753090"]], "c": "1385345055"}, "book-100", "XBT/USD"]
[270, {"b": [["11658.20000", "0.25000000", "1596666792.753789"]], "c": "4272723157"}, "book-100", "XBT/USD"]
[270, {"b": [["11658.90000", "0.52500000", "1596666792.756148"]], "c": "828407969"}, "book-100", "XBT/USD"]
[270, {"a": [["11665.80000", "1.04738592", "1596666792.756550"]], "c": "4003560004"}, "book-100", "XBT/USD"]
[270, {"a": [["11666.40000", "0.09700000", "1596666792.756611"]], "c": "1082375696"}, "book-100", "XBT/USD"]
[270, {"a": [["11663.20000", "0.50000000", "1596666792.760805"]], "c": "1640111473"}, "book-100", "XBT/USD"]
[270, {"b": [["11662.20000", "0.29673000", "1596666792.767192"]], "c": "1400295148"}, "book-100", "XBT/USD"]
[270, {"a": [["11686.00000", "0.59128653", "1596666792.767382"]], "c": "1400295148"}, "book-100", "XBT/USD"]
[270, {"b": [["11652.60000", "2.07459264", "1596666792.767990"]], "c": "1400295148"}, "book-100", "XBT/USD"]
[270, {"b": [["11658.10000", "0.00000000", "1596666792.768162"], ["11602.10000", "11.25550194", "1596666780.609892", "r"]], "c": "832283701"}, "book-100", "XBT/USD"]
[270, {"a": [["11668.30000", "0.00000000", "1596666792.768666"], ["11710.10000", "0.89650546", "1596666771.484931", "r"]], "c": "832283701"}, "book-100", "XBT/USD"]
[270, {"b": [["11653.30000", "0.01491853", "1596666792.768836"]], "c": "832283701"}, "book-100", "XBT/USD"]
[270, {"a": [["11665.90000", "0.42804584", "1596666792.771563"]], "c": "2590797406"}, "book-100", "XBT/USD"]
[270, {"a": [["11664.70000", "0.41352978", "1596666792.775059"]], "c": "1310129633"}, "book-100", "XBT/USD"]
[270, {"a": [["11676.90000", "0.05313798", "1596666792.780016"]], "c": "1310129633"}, "book-100", "XBT/USD"]
[270, {"a": [["11668.70000", "0.04051069", "1596666792.791240"]], "c": "1310129633"}, "book-100", "XBT/USD"]
[270, {"b": [["11659.20000", "0.04250000", "1596666792.797051"]], "c": "1661260003"}, "book-100", "XBT/USD"]
[270, {"b": [["11650.80000", "1.24229655", "1596666792.797336"]], "c": "1661260003"}, "book-100", "XBT/USD"]
[270, {"a": [["11662.30000", "0.06996798", "1596666792.844359"]], "c": "625373213"}, "book-100", "XBT/USD"]
[270, {"b": [["11659.90000", "0.94261277", "1596666792.845044"]], "c": "3413352579"}, "book-100", "XBT/USD"]
[270, {"b": [["11649.20000", "0.10300000", "1596666792.845883"]], "c": "3413352579"}, "book-100", "XBT/USD"]
[270, {"b": [["11647.70000", "0.00000000", "1596666792.847399"], ["11603.20000", "2.50039088", "1596666777.334144", "r"]], "c": "3413352579"}, "book-100", "XBT/USD"]
[270, {"b": [["11647.20000", "0.02682839", "1596666792.847691"]], "c": "3413352579"}, "book-100", "XBT/USD"]
[270, {"a": [["11677.90000", "0.43900000", "1596666792.847888"]], "c": "3413352579"}, "book-100", "XBT/USD"]
[270, {"b": [["11645.30000", "0.81436000", "1596666792.848640"]], "c": "3413352579"}, "book-100", "XBT/USD"]
[270, {"b": [["11648.60000", "0.90099331", "1596666792.850078"]], "c": "3413352579"}, "book-100", "XBT/USD"]
[270, {"b": [["11657.40000", "0.00000000", "1596666792.850167"], ["11607.00000", "0.17085000", "1596666720.750083", "r"]], "c": "552851491"}, "book-100", "XBT/USD"]
[270, {"a": [["11671.60000", "0.50000000", "1596666792.873974"]], "c": "552851491"}, "book-100", "XBT/USD"]
[270, {"b": [["11650.70000", "0.00000000", "1596666792.879459"], ["11604.10000", "1.51500000", "1596666763.121463", "r"]], "c": "552851491"}, "book-100", "XBT/USD"]
[270, {"a": [["11663.20000", "1.49138000", "1596666792.885618"]], "c": "2264451568"}, "book-100", "XBT/USD"]
[270, {"a": [["11665.90000", "0.00235497", "1596666792.886952"]], "c": "596723906"}, "book-100", "XBT/USD"]
[270, {"b": [["11658.20000", "0.00000000", "1596666792.892301"], ["11603.20000", "2.50039088", "1596666777.334144", "r"]], "c": "2689607060"}, "book-100", "XBT/USD"]
[270, {"b": [["11651.30000", "0.00000000", "1596666792.915683"], ["11602.60000", "1.48021868", "1596666784.125874", "r"]], "c": "2689607060"}, "book-100", "XBT/USD"]
[270, {"a": [["11663.20000", "0.99138000", "1596666792.915880"]], "c": "3723909808"}, "book-100", "XBT/USD"]
[270, {"a": [["11673.80000", "1.54309417", "1596666792.935782"]], "c": "3723909808"}, "book-100", "XBT/USD"]
[270, {"a": [["11662.30000", "0.56996798", "1596666792.957212"]], "c": "4143312462"}, "book-100", "XBT/USD"]
[270, {"a": [["11673.50000", "0.00000000", "1596666792.959824"], ["11709.70000", "7.20507863", "1596666620.257365", "r"]], "c": "4143312462"}, "book-100", "XBT/USD"]
[271, [["11662.20000", "0.00944688", "1596666792.970446", "s", "l", ""]], "trade", "XBT/USD"]
[270, {"b": [["11662.20000", "0.28728312", "1596666792.970446"]], "c": "3161932438"}, "book-100", "XBT/USD"]
[270, {"a": [["11662.30000", "1.06996798", "1596666792.985426"]], "c": "2174063569"}, "book-100", "XBT/USD"]
[270, {"a": [["11664.10000", "0.64309436", "1596666792.985694"]], "c": "143719737"}, "book-100", "XBT/USD"]
[270, {"a": [["11669.80000", "0.85741077", "1596666792.985806"]], "c": "143719737"}, "book-100", "XBT/USD"]
[270, {"b": [["11658.70000", "0.64305808", "1596666792.986770"]], "c": "2787149319"}, "book-100", "XBT/USD"]
[270, {"a": [["11676.90000", "0.00000000", "1596666792.988755"], ["11707.10000", "7.06242335", "1596666781.831440", "r"]], "c": "2787149319"}, "book-100", "XBT/USD"]
[270, {"b": [["11659.90000", "0.85688220", "1596666792.993897"]], "c": "2977500564"}, "book-100", "XBT/USD"]
[270, {"b": [["11647.20000", "0.88413547", "1596666792.996402"]], "c": "2977500564"}, "book-100", "XBT/USD"]
[270, {"a": [["11664.70000", "1.05662414", "1596666792.997237"]], "c": "3652327392"}, "book-100", "XBT/USD"]
[270, {"b": [["11662.20000", "0.71528312", "1596666792.999285"]], "c": "2811057753"}, "book-100", "XBT/USD"]
[270, {"b": [["11647.20000", "0.85730708", "1596666793.013197"]], "c": "2811057753"}, "book-100", "XBT/USD"]
[270, {"a": [["11664.70000", "0.64309436", "1596666793.015131"]], "c": "3953572601"}, "book-100", "XBT/USD"]
[270, {"b": [["11643.80000", "0.85755260", "1596666793.018278"]], "c": "3953572601"}, "book-100", "XBT/USD"]
[270, {"a": [["11670.50000", "0.85730708", "1596666793.018849"]], "c": "3953572601"}, "book-100", "XBT/USD"]
[270, {"b": [["11653.30000", "0.00000000", "1596666793.037040"], ["11603.20000", "2.50039088", "1596666777.334144", "r"]], "c": "3953572601"}, "book-100", "XBT/USD"]
[270, {"a": [["11665.80000", "0.49708592", "1596666793.044336"]], "c": "1401986758"}, "book-100", "XBT/USD"]
[270, {"a": [["11664.90000", "0.55030000", "1596666793.045135"]], "c": "798056990"}, "book-100", "XBT/USD"]
[270, {"a": [["11667.00000", "0.85750663", "1596666793.045849"]], "c": "798056990"}, "book-100", "XBT/USD"]
[270, {"b": [["11644.90000", "1.20127959", "1596666793.045939"]], "c": "798056990"}, "book-100", "XBT/USD"]
[270, {"b": [["11659.90000", "0.00000000", "1596666793.051838"], ["11602.60000", "1.48021868", "1596666784.125874", "r"]], "c": "4127858465"}, "book-100", "XBT/USD"]
[270, {"b": [["11649.10000", "0.96076520", "1596666793.055575"]], "c": "4127858465"}, "book-100", "XBT/USD"]
[270, {"b": [["11646.10000", "0.00000000", "1596666793.059138"], ["11602.20000", "2.01681621", "1596666634.588713", "r"]], "c": "4127858465"}, "book-100", "XBT/USD"]
[270, {"b": [["11662.20000", "0.50105312", "1596666793.062028"]], "c": "2117233944"}, "book-100", "XBT/USD"]
[270, {"b": [["11645.90000", "0.00000000", "1596666793.064629"], ["11602.10000", "11.25550194", "1596666780.609892", "r"]], "c": "2117233944"}, "book-100", "XBT/USD"]
[270, {"a": [["11673.20000", "0.00000000", "1596666793.066982"], ["11705.20000", "0.75800000", "1596666760.546082", "r"]], "c": "2117233944"}, "book-100", "XBT/USD"]
[270, {"a": [["11670.80000", "1.36473524", "1596666793.069870"]], "c": "2117233944"}, "book-100", "XBT/USD"]
[270, {"b": [["11656.70000", "0.35000000", "1596666793.071462"]], "c": "2566771771"}, "book-100", "XBT/USD"]
[270, {"b": [["11645.70000", "0.00000000", "1596666793.072384"], ["11601.10000", "3.00166376", "1596666779.976375", "r"]], "c": "2566771771"}, "book-100", "XBT/USD"]
[270, {"a": [["11662.30000", "1.29996798", "1596666793.073314"]], "c": "284825791"}, "book-100", "XBT/USD"]
[270, {"b": [["11659.10000", "0.55030000", "1596666793.084435"]], "c": "2725198765"}, "book-100", "XBT/USD"]
[270, {"b": [["11645.10000", "0.00000000", "1596666793.084799"], ["11600.40000", "0.90458128", "1596666777.993986", "r"]], "c": "2725198765"}, "book-100", "XBT/USD"]
[270, {"b": [["11646.60000", "0.00000000", "1596666793.087294"], ["11600.10000", "0.05000000", "1596666747.910313", "r"]], "c": "2725198765"}, "book-100", "XBT/USD"]
[270, {"a": [["11670.80000", "1.02554945", "1596666793.098045"]], "c": "2725198765"}, "book-100", "XBT/USD"]
[270, {"b": [["11645.20000", "0.03000000", "1596666793.099542"]], "c": "2725198765"}, "book-100", "XBT/USD"]
[270, {"b": [["11652.60000", "2.00000000", "1596666793.100131"]], "c": "2725198765"}, "book-100", "XBT/USD"]
[270, {"a": [["11670.80000", "0.15000000", "1596666793.100291"]], "c": "2725198765"}, "book-100", "XBT/USD"]
[270, {"b": [["11649.00000", "0.00000000", "1596666793.105674"], ["11600.10000", "0.05000000", "1596666747.910313", "r"]], "c": "2725198765"}, "book-100", "XBT/USD"]
[270, {"b": [["11647.10000", "0.00000000", "1596666793.105772"], ["11600.00000", "0.02931034", "1596666720.289823", "r"]], "c": "2725198765"}, "book-100", "XBT/USD"]
[270, {"b": [["11646.70000", "0.72496419", "1596666793.109255"]], "c": "2725198765"}, "book-100", "XBT/USD"]
[270, {"b": [["11645.80000", "0.00000000", "1596666793.111744"], ["11600.00000", "0.02931034", "1596666720.289823", "r"]], "c": "2725198765"}, "book-100", "XBT/USD"]
[270, {"a": [["11670.60000", "0.00000000", "1596666793.115593"], ["11705.70000", "0.48380000", "1596666770.726024", "r"]], "c": "2725198765"}, "book-100", "XBT/USD"]
[270, {"a": [["11688.60000", "0.24903862", "1596666793.134680"]], "c": "2725198765"}, "book-100", "XBT/USD"]
[270, {"b": [["11650.40000", "0.33911136", "1596666793.136295"]], "c": "2725198765"}, "book-100", "XBT/USD"]
[270, {"a": [["11679.50000", "0.00000000", "1596666793.137180"], ["11707.10000", "7.06242335", "1596666781.831440", "r"]], "c": "2725198765"}, "book-100", "XBT/USD"]
[270, {"a": [["11670.70000", "0.69965937", "1596666793.140159"]], "c": "2725198765"}, "book-100", "XBT/USD"]
[270, {"b": [["11647.10000", "0.24988384", "1596666793.146647"]], "c": "2725198765"}, "book-100", "XBT/USD"]
[270, {"a": [["11672.60000", "0.45182323", "1596666793.149758"]], "c": "2725198765"}, "book-100", "XBT/USD"]
[270, {"b": [["11619.00000", "7.00000000", "1596666793.167773"]], "c": "2725198765"}, "book-100", "XBT/USD"]
[270, {"b": [["11656.70000", "1.35000000", "1596666793.168817"]], "c": "3442069243"}, "book-100", "XBT/USD"]
[270, {"a": [["11663.90000", "0.41352978", "1596666793.169830"]], "c": "1336981174"}, "book-100", "XBT/USD"]
[270, {"b": [["11650.80000", "0.00000000", "1596666793.183218"], ["11600.10000", "0.05000000", "1596666747.910313", "r"]], "c": "1336981174"}, "book-100", "XBT/USD"]
[270, {"b": [["11648.50000", "0.00000000", "1596666793.201142"], ["11600.00000", "0.02931034", "1596666720.289823", "r"]], "c": "1336981174"}, "book-100", "XBT/USD"]
[270, {"a": [["11691.30000", "6.55978100", "1596666793.215486"]], "c": "1336981174"}, "book-100", "XBT/USD"]
[270, {"a": [["11662.30000", "1.87190819", "1596666793.222968"]], "c": "1668273549"}, "book-100", "XBT/USD"]
[270, {"b": [["11645.40000", "6.11341419", "1596666793.226966"]], "c": "1668273549"}, "book-100", "XBT/USD"]
[270, {"b": [["11645.20000", "0.00000000", "1596666793.229624"], ["11599.60000", "3.04585670", "1596666779.021471", "r"]], "c": "1668273549"}, "book-100", "XBT/USD"]
[270, {"a": [["11670.70000", "1.40525937", "1596666793.231087"]], "c": "1668273549"}, "book-100", "XBT/USD"]
[270, {"a": [["11665.80000", "0.00000000", "1596666793.238396"], ["11704.80000", "0.89674240", "1596666781.770732", "r"]], "c": "2485246603"}, "book-100", "XBT/USD"]
[270, {"b": [["11656.70000", "1.25000000", "1596666793.247155"]], "c": "574241531"}, "book-100", "XBT/USD"]
[270, {"b": [["11643.90000", "0.00000000", "1596666793.266947"], ["11598.80000", "10.88860000", "1596666792.969132", "r"]], "c": "574241531"}, "book-100", "XBT/USD"]
[270, {"b": [["11656.70000", "0.25000000", "1596666793.271549"]], "c": "2942155937"}, "book-100", "XBT/USD"]
[270, {"b": [["11646.30000", "0.31327683", "1596666793.271705"]], "c": "2942155937"}, "book-100", "XBT/USD"]
[270, {"b": [["11659.20000", "0.25568000", "1596666793.289409"]], "c": "2400398840"}, "book-100", "XBT/USD"]
[270, {"a": [["11667.90000", "0.00000000", "1596666793.291695"], ["11705.20000", "0.75800000", "1596666760.546082", "r"]], "c": "2400398840"}, "book-100", "XBT/USD"]
[270, {"b": [["11649.50000", "1.30845396", "1596666793.292990"]], "c": "2400398840"}, "book-100", "XBT/USD"]
[270, {"a": [["11670.70000", "1.55525937", "1596666793.304346"]], "c": "2400398840"}, "book-100", "XBT/USD"]
[270, {"a": [["11669.70000", "0.54975423", "1596666793.305439"]], "c": "2400398840"}, "book-100", "XBT/USD"]
[270, {"a": [["11669.70000", "0.45354329", "1596666793.320558"]], "c": "2400398840"}, "book-100", "XBT/USD"]
[270, {"b": [["11640.00000", "8.31242334", "1596666793.368932"]], "c": "2400398840"}, "book-100", "XBT/USD"]
[270, {"b": [["11638.30000", "1.00000000", "1596666793.381670"]], "c": "2400398840"}, "book-100", "XBT/USD"]
[270, {"a": [["11663.20000", "1.79138000", "1596666793.384590"]], "c": "745219502"}, "book-100", "XBT/USD"]
[270, {"b": [["11639.60000", "2.69927112", "1596666793.402492"]], "c": "745219502"}, "book-100", "XBT/USD"]
[270, {"b": [["11645.40000", "7.53829344", "1596666793.403717"]], "c": "745219502"}, "book-100", "XBT/USD"]
[270, {"a": [["11676.80000", "0.00000000", "1596666793.409505"], ["11705.70000", "0.48380000", "1596666770.726024", "r"]], "c": "745219502"}, "book-100", "XBT/USD"]
[270, {"a": [["11666.80000", "0.42202576", "1596666793.409623"]], "c": "745219502"}, "book-100", "XBT/USD"]
[270, {"a": [["11662.70000", "0.64316445", "1596666793.410689"]], "c": "2605578679"}, "book-100", "XBT/USD"]
[270, {"b": [["11647.70000", "0.71229894", "1596666793.413332"]], "c": "2605578679"}, "book-100", "XBT/USD"]
[270, {"b": [["11655.00000", "4.28000000", "1596666793.415520"]], "c": "2739123340"}, "book-100", "XBT/USD"]
[270, {"a": [["11675.70000", "6.07561598", "1596666793.419596"]], "c": "2739123340"}, "book-100", "XBT/USD"]
[270, {"a": [["11663.90000", "0.74797895", "1596666793.420243"]], "c": "2152624908"}, "book-100", "XBT/USD"]
[270, {"a": [["11663.10000", "4.28300000", "1596666793.423336"]], "c": "1030026336"}, "book-100", "XBT/USD"]
[270, {"a": [["11663.90000", "0.96645925", "1596666793.436672"]], "c": "1224332333"}, "book-100", "XBT/USD"]
[270, {"a": [["11663.20000", "0.99138000", "1596666793.450792"]], "c": "828204951"}, "book-100", "XBT/USD"]
[270, {"b": [["11637.00000", "0.05290228", "1596666793.470575"]], "c": "828204951"}, "book-100", "XBT/USD"]
[270, {"b": [["11638.30000", "0.00000000", "1596666793.478024"], ["11600.40000", "0.90458128", "1596666777.993986", "r"]], "c": "828204951"}, "book-100", "XBT/USD"]
[270, {"b": [["11649.70000", "0.00000000", "1596666793.491614"], ["11600.10000", "0.05000000", "1596666747.910313", "r"]], "c": "828204951"}, "book-100", "XBT/USD"]
[270, {"b": [["11643.80000", "1.23755260", "1596666793.498224"]], "c": "828204951"}, "book-100", "XBT/USD"]
[270, {"a": [["11675.20000", "0.38000000", "1596666793.520779"]], "c": "828204951"}, "book-100", "XBT/USD"]
[270, {"a": [["11673.50000", "0.00641741", "1596666793.547197"]], "c": "828204951"}, "book-100", "XBT/USD"]
[270, {"a": [["11675.70000", "6.06919978", "1596666793.547470"]], "c": "828204951"}, "book-100", "XBT/USD"]
[270, {"b": [["11639.00000", "0.57513280", "1596666793.553863"]], "c": "828204951"}, "book-100", "XBT/USD"]
[270, {"a": [["11664.20000", "0.86449562", "1596666793.594686"]], "c": "183454335"}, "book-100", "XBT/USD"]
[270, {"a": [["11689.20000", "0.96300000", "1596666793.736012"]], "c": "183454335"}, "book-100", "XBT/USD"]
[270, {"a": [["11664.60000", "1.25632169", "1596666793.762251"]], "c": "124225929"}, "book-100", "XBT/USD"]
[270, {"b": [["11649.50000", "0.00000000", "1596666793.813213"], ["11600.10000", "0.05000000", "1596666747.910313", "r"]], "c": "124225929"}, "book-100", "XBT/USD"]
[270, {"b": [["11650.10000", "0.00000000", "1596666793.821451"], ["11600.00000", "0.02931034", "1596666720.289823", "r"]], "c": "124225929"}, "book-100", "XBT/USD"]
[270, {"a": [["11665.90000", "0.00000000", "1596666793.864645"], ["11702.80000", "1.11290000", "1596666781.426679", "r"]], "c": "124225929"}, "book-100", "XBT/USD"]
[270, {"b": [["11654.50000", "0.09700000", "1596666793.882611"]], "c": "124225929"}, "book-100", "XBT/USD"]
[270, {"a": [["11678.30000", "0.00000000", "1596666793.905775"], ["11703.70000", "1.48735197", "1596666777.331546", "r"]], "c": "124225929"}, "book-100", "XBT/USD"]
[270, {"b": [["11659.20000", "0.21318000", "1596666793.987107"]], "c": "3824818404"}, "book-100", "XBT/USD"]
[270, {"a": [["11668.70000", "0.00000000", "1596666793.988671"], ["11703.80000", "0.89537466", "1596666784.131217", "r"]], "c": "3824818404"}, "book-100", "XBT/USD"]
[270, {"b": [["11640.20000", "2.01094638", "1596666793.995825"]], "c": "3824818404"}, "book-100", "XBT/USD"]
[270, {"b": [["11637.90000", "0.99730499", "1596666794.052941"]], "c": "3824818404"}, "book-100", "XBT/USD"]
[270, {"b": [["11643.70000", "0.49840410", "1596666794.056587"]], "c": "3824818404"}, "book-100", "XBT/USD"]
[270, {"b": [["11643.90000", "4.00000000", "1596666794.061823"]], "c": "3824818404"}, "book-100", "XBT/USD"]
[270, {"a": [["11663.50000", "2.15930462", "1596666794.156589"]], "c": "2469032418"}, "book-100", "XBT/USD"]
[270, {"a": [["11662.30000", "1.87426316", "1596666794.182654"]], "c": "141622611"}, "book-100", "XBT/USD"]
[270, {"b": [["11645.40000", "7.52487925", "1596666794.186140"]], "c": "141622611"}, "book-100", "XBT/USD"]
[270, {"b": [["11643.90000", "4.04222961", "1596666794.191649"]], "c": "141622611"}, "book-100", "XBT/USD"]
[270, {"b": [["11655.00000", "0.00000000", "1596666794.247314"], ["11602.10000", "11.25550194", "1596666780.609892", "r"]], "c": "2033811352"}, "book-100", "XBT/USD"]
[270, {"b": [["11656.30000", "4.28700000", "1596666794.261216"]], "c": "2020180553"}, "book-100", "XBT/USD"]
[270, {"a": [["11674.50000", "0.66800000", "1596666794.263396"]], "c": "2020180553"}, "book-100", "XBT/USD"]
[270, {"b": [["11652.70000", "0.04250000", "1596666794.283396"]], "c": "2020180553"}, "book-100", "XBT/USD"]
[270, {"a": [["11663.80000", "0.04250000", "1596666794.283910"]], "c": "3247649949"}, "book-100", "XBT/USD"]
[270, {"b": [["11662.20000", "0.42800000", "1596666794.284086"]], "c": "1406249862"}, "book-100", "XBT/USD"]
[270, {"a": [["11669.00000", "0.00000000", "1596666794.297332"], ["11703.70000", "1.48735197", "1596666777.331546", "r"]], "c": "1406249862"}, "book-100", "XBT/USD"]
[270, {"b": [["11650.20000", "1.82369692", "1596666794.298048"]], "c": "1406249862"}, "book-100", "XBT/USD"]
[270, {"a": [["11662.60000", "0.75551922", "1596666794.305307"]], "c": "4167626501"}, "book-100", "XBT/USD"]
[270, {"b": [["11616.00000", "0.00000000", "1596666794.355296"], ["11602.20000", "2.01681621", "1596666634.588713", "r"]], "c": "4167626501"}, "book-100", "XBT/USD"]
[270, {"b": [["11641.10000", "7.13166894", "1596666794.422539"]], "c": "4167626501"}, "book-100", "XBT/USD"]
[270, {"a": [["11662.60000", "0.00000000", "1596666794.442334"], ["11703.70000", "1.48735197", "1596666777.331546", "r"]], "c": "1406249862"}, "book-100", "XBT/USD"]
[270, {"a": [["11670.60000", "0.15000000", "1596666794.461277"]], "c": "1406249862"}, "book-100", "XBT/USD"]
[270, {"a": [["11677.20000", "0.00000000", "1596666794.462366"], ["11703.70000", "1.48735197", "1596666777.331546", "r"]], "c": "1406249862"}, "book-100", "XBT/USD"]
[270, {"a": [["11681.20000", "0.02573600", "1596666794.475160"]], "c": "1406249862"}, "book-100", "XBT/USD"]
[270, {"b": [["11661.70000", "0.42000000", "1596666794.515890"]], "c": "766599121"}, "book-100", "XBT/USD"]
[270, {"a": [["11662.30000", "1.88226316", "1596666794.548324"]], "c": "1036561659"}, "book-100", "XBT/USD"]
[270, {"b": [["11655.00000", "0.08250000", "1596666794.548736"]], "c": "1036561659"}, "book-100", "XBT/USD"]
[270, {"a": [["11693.50000", "0.08250000", "1596666794.592525"]], "c": "1036561659"}, "book-100", "XBT/USD"]
[270, {"a": [["11664.20000", "1.35797863", "1596666794.626858"]], "c": "1364996687"}, "book-100", "XBT/USD"]
[270, {"b": [["11640.00000", "11.52247904", "1596666794.662192"]], "c": "1364996687"}, "book-100", "XBT/USD"]
[270, {"a": [["11667.60000", "0.04476617", "1596666794.671111"]], "c": "1364996687"}, "book-100", "XBT/USD"]
[270, {"a": [["11665.70000", "0.00000000", "1596666794.744649"], ["11702.80000", "1.11290000", "1596666781.426679", "r"]], "c": "1364996687"}, "book-100", "XBT/USD"]
[270, {"a": [["11662.30000", "2.14078631", "1596666794.845767"]], "c": "4157088605"}, "book-100", "XBT/USD"]
[270, {"b": [["11614.20000", "0.75800000", "1596666795.670468"]], "c": "4157088605"}, "book-100", "XBT/USD"]
[270, {"b": [["11623.60000", "0.00000000", "1596666795.670790"], ["11603.20000", "2.50039088", "1596666777.334144", "r"]], "c": "4157088605"}, "book-100", "XBT/USD"]
[270, {"a": [["11664.70000", "0.00000000", "1596666795.672258"], ["11703.70000", "1.48735197", "1596666777.331546", "r"]], "c": "4157088605"}, "book-100", "XBT/USD"]
[270, {"a": [["11678.90000", "0.00000000", "1596666795.674680"], ["11703.80000", "0.89537466", "1596666784.131217", "r"]], "c": "4157088605"}, "book-100", "XBT/USD"]
[270, {"b": [["11656.70000", "0.00000000", "1596666795.677964"], ["11602.60000", "1.48021868", "1596666784.125874", "r"]], "c": "4189782635"}, "book-100", "XBT/USD"]
[270, {"a": [["11663.90000", "0.55292947", "1596666795.685043"]], "c": "1742053650"}, "book-100", "XBT/USD"]
[270, {"b": [["11632.50000", "0.00000000", "1596666795.711339"], ["11602.20000", "2.01681621", "1596666634.588713", "r"]], "c": "1742053650"}, "book-100", "XBT/USD"]
[270, {"a": [["11663.00000", "0.75551922", "1596666795.721452"]], "c": "17448103"}, "book-100", "XBT/USD"]
[270, {"b": [["11650.20000", "0.45989690", "1596666795.721665"]], "c": "17448103"}, "book-100", "XBT/USD"]
[270, {"b": [["11655.60000", "0.09621094", "1596666795.727030"]], "c": "17448103"}, "book-100", "XBT/USD"]
[270, {"a": [["11672.60000", "0.00000000", "1596666795.745176"], ["11703.80000", "0.89537466", "1596666784.131217", "r"]], "c": "17448103"}, "book-100", "XBT/USD"]
[270, {"b": [["11657.90000", "0.64319702", "1596666795.766692"]], "c": "2521505791"}, "book-100", "XBT/USD"]
[270, {"a": [["11662.80000", "0.64322565", "1596666795.770463"]], "c": "2455872297"}, "book-100", "XBT/USD"]
[270, {"a": [["11664.20000", "1.45418957", "1596666795.793249"]], "c": "2455872297"}, "book-100", "XBT/USD"]
[270, {"b": [["11646.90000", "0.00000000", "1596666795.798083"], ["11602.60000", "1.48021868", "1596666784.125874", "r"]], "c": "2455872297"}, "book-100", "XBT/USD"]
[270, {"a": [["11663.00000", "0.00000000", "1596666795.802000"], ["11703.80000", "0.89537466", "1596666784.131217", "r"]], "c": "3487220358"}, "book-100", "XBT/USD"]
[270, {"a": [["11662.30000", "2.64078631", "1596666795.839092"]], "c": "4178260972"}, "book-100", "XBT/USD"]
[270, {"a": [["11670.00000", "0.13430265", "1596666795.868077"]], "c": "4178260972"}, "book-100", "XBT/USD"]
[270, {"b": [["11645.50000", "1.65810333", "1596666795.889972"]], "c": "4178260972"}, "book-100", "XBT/USD"]
[270, {"b": [["11617.90000", "0.00000000", "1596666795.937903"], ["11602.20000", "2.01681621", "1596666634.588713", "r"]], "c": "4178260972"}, "book-100", "XBT/USD"]
[270, {"b": [["11657.30000", "0.25000000", "1596666795.946767"]], "c": "2452771227"}, "book-100", "XBT/USD"]
[270, {"a": [["11672.70000", "2.07826217", "1596666795.947344"]], "c": "2452771227"}, "book-100", "XBT/USD"]
[270, {"a": [["11664.40000", "0.41352978", "1596666795.959499"]], "c": "2452771227"}, "book-100", "XBT/USD"]
[270, {"a": [["11666.10000", "0.00000000", "1596666795.973600"], ["11703.70000", "1.48735197", "1596666777.331546", "r"]], "c": "2452771227"}, "book-100", "XBT/USD"]
[270, {"b": [["11647.30000", "0.04476436", "1596666796.017620"]], "c": "2452771227"}, "book-100", "XBT/USD"]
[271, [["11662.30000", "0.02000000", "1596666797.170494", "b", "m", ""]], "trade", "XBT/USD"]
[270, {"a": [["11662.30000", "2.62078631", "1596666797.170494"]], "c": "3777073289"}, "book-100", "XBT/USD"]
[270, {"a": [["11662.30000", "4.12078631", "1596666797.204611"]], "c": "1130860549"}, "book-100", "XBT/USD"]
[270, {"b": [["11611.70000", "0.37132924", "1596666797.216118"]], "c": "1130860549"}, "book-100", "XBT/USD"]
[270, {"a": [["11680.20000", "0.00438186", "1596666797.225521"]], "c": "1130860549"}, "book-100", "XBT/USD"]
[270, {"a": [["11698.10000", "10.19785222", "1596666797.232046"]], "c": "1130860549"}, "book-100", "XBT/USD"]
[270, {"b": [["11658.70000", "0.00000000", "1596666797.236631"], ["11603.20000", "2.50039088", "1596666777.334144", "r"]], "c": "3136076288"}, "book-100", "XBT/USD"]
[270, {"b": [["11624.80000", "0.00000000", "1596666797.250711"], ["11602.60000", "1.48021868", "1596666784.125874", "r"]], "c": "3136076288"}, "book-100", "XBT/USD"]
[270, {"a": [["11692.90000", "0.00000000", "1596666797.254998"], ["11702.80000", "1.11290000", "1596666781.426679", "r"]], "c": "3136076288"}, "book-100", "XBT/USD"]
[270, {"b": [["11606.00000", "0.74921971", "1596666797.264674"]], "c": "3136076288"}, "book-100", "XBT/USD"]
[270, {"a": [["11697.50000", "0.00000000", "1596666797.271368"], ["11703.70000", "1.48735197", "1596666777.331546", "r"]], "c": "3136076288"}, "book-100", "XBT/USD"]
[270, {"a": [["11677.00000", "0.00000000", "1596666797.282879"], ["11703.80000", "0.89537466", "1596666784.131217", "r"]], "c": "3136076288"}, "book-100", "XBT/USD"]
[270, {"b": [["11650.40000", "0.00000000", "1596666797.283261"], ["11602.60000", "1.48021868", "1596666784.125874", "r"]], "c": "3136076288"}, "book-100", "XBT/USD"]
[270, {"a": [["11664.60000", "0.00000000", "1596666797.285866"], ["11704.10000", "8.30000000", "1596666665.290916", "r"]], "c": "3136076288"}, "book-100", "XBT/USD"]
[270, {"b": [["11604.20000", "0.01286201", "1596666797.288649"]], "c": "3136076288"}, "book-100", "XBT/USD"]
[270, {"a": [["11665.00000", "0.00000000", "1596666797.295633"], ["11704.60000", "2.30891053", "1596666760.872896", "r"]], "c": "3136076288"}, "book-100", "XBT/USD"]
[270, {"a": [["11672.70000", "1.64160000", "1596666797.300468"]], "c": "3136076288"}, "book-100", "XBT/USD"]
[270, {"a": [["11694.50000", "0.00000000", "1596666797.303647"], ["11704.80000", "0.89674240", "1596666781.770732", "r"]], "c": "3136076288"}, "book-100", "XBT/USD"]
[270, {"a": [["11688.50000", "0.00000000", "1596666797.309155"], ["11705.20000", "0.75800000", "1596666760.546082", "r"]], "c": "3136076288"}, "book-100", "XBT/USD"]
[270, {"a": [["11687.80000", "0.74921971", "1596666797.313092"]], "c": "3136076288"}, "book-100", "XBT/USD"]
[270, {"a": [["11662.60000", "0.25851442", "1596666797.316650"]], "c": "3380032365"}, "book-100", "XBT/USD"]
[270, {"b": [["11651.90000", "0.00000000", "1596666797.317360"], ["11602.60000", "1.48021868", "1596666784.125874", "r"]], "c": "3380032365"}, "book-100", "XBT/USD"]
[270, {"b": [["11610.60000", "0.00000000", "1596666797.318894"], ["11602.20000", "2.01681621", "1596666634.588713", "r"]], "c": "3380032365"}, "book-100", "XBT/USD"]
[270, {"a": [["11662.30000", "3.86226316", "1596666797.321411"]], "c": "1470264017"}, "book-100", "XBT/USD"]
[270, {"a": [["11691.30000", "0.00000000", "1596666797.357418"], ["11704.80000", "0.89674240", "1596666781.770732", "r"]], "c": "1470264017"}, "book-100", "XBT/USD"]
[270, {"a": [["11688.70000", "0.30000000", "1596666797.365233"]], "c": "1470264017"}, "book-100", "XBT/USD"]
[270, {"a": [["11691.40000", "0.00000000", "1596666797.365410"], ["11705.20000", "0.75800000", "1596666760.546082", "r"]], "c": "1470264017"}, "book-100", "XBT/USD"]
[270, {"a": [["11694.80000", "0.00000000", "1596666797.367059"], ["11705.70000", "0.48380000", "1596666770.726024", "r"]], "c": "1470264017"}, "book-100", "XBT/USD"]
[270, {"a": [["11688.60000", "0.00000000", "1596666797.422791"], ["11707.10000", "7.06242335", "1596666781.831440", "r"]], "c": "1470264017"}, "book-100", "XBT/USD"]
[270, {"a": [["11676.50000", "2.00000000", "1596666797.468383"]], "c": "1470264017"}, "book-100", "XBT/USD"]
[270, {"a": [["11670.40000", "0.15000000", "1596666797.468580"]], "c": "1470264017"}, "book-100", "XBT/USD"]
[270, {"a": [["11695.20000", "0.00000000", "1596666797.489693"], ["11705.70000", "0.48380000", "1596666770.726024", "r"]], "c": "1470264017"}, "book-100", "XBT/USD"]
[270, {"a": [["11694.30000", "0.00000000", "1596666797.496659"], ["11707.10000", "7.06242335", "1596666781.831440", "r"]], "c": "1470264017"}, "book-100", "XBT/USD"]
[270, {"a": [["11664.10000", "1.75373734", "1596666797.514749"]], "c": "4011751239"}, "book-100", "XBT/USD"]
[270, {"a": [["11696.80000", "0.05290732", "1596666797.546996"]], "c": "4011751239"}, "book-100", "XBT/USD"]
[270, {"a": [["11672.60000", "0.57650981", "1596666797.555215"]], "c": "4011751239"}, "book-100", "XBT/USD"]
[270, {"a": [["11686.70000", "1.41984382", "1596666797.584491"]], "c": "4011751239"}, "book-100", "XBT/USD"]
[270, {"a": [["11696.70000", "0.00000000", "1596666797.599430"], ["11707.10000", "7.06242335", "1596666781.831440", "r"]], "c": "4011751239"}, "book-100", "XBT/USD"]
[270, {"b": [["11641.20000", "0.00476390", "1596666797.605951"]], "c": "4011751239"}, "book-100", "XBT/USD"]
[270, {"a": [["11689.70000", "0.34856472", "1596666797.623206"]], "c": "4011751239"}, "book-100", "XBT/USD"]
[270, {"b": [["11645.50000", "0.34988544", "1596666797.626544"]], "c": "4011751239"}, "book-100", "XBT/USD"]
[270, {"a": [["11704.80000", "0.00000000", "1596666797.631838"], ["11709.00000", "0.17085000", "1596666795.991184", "r"]], "c": "4011751239"}, "book-100", "XBT/USD"]
[270, {"a": [["11692.50000", "0.99264791", "1596666797.662067"]], "c": "4011751239"}, "book-100", "XBT/USD"]
[270, {"b": [["11657.00000", "0.09800000", "1596666797.666101"]], "c": "3960080813"}, "book-100", "XBT/USD"]
[270, {"b": [["11612.40000", "13.92935293", "1596666797.693332"]], "c": "3960080813"}, "book-100", "XBT/USD"]
[270, {"a": [["11672.60000", "0.00000000", "1596666797.739504"], ["11709.00000", "0.17085000", "1596666795.991184", "r"]], "c": "3960080813"}, "book-100", "XBT/USD"]
[270, {"a": [["11686.00000", "0.00000000", "1596666797.742314"], ["11709.70000", "7.20507863", "1596666620.257365", "r"]], "c": "3960080813"}, "book-100", "XBT/USD"]
[270, {"a": [["11688.10000", "2.00298529", "1596666797.779067"]], "c": "3960080813"}, "book-100", "XBT/USD"]
[270, {"a": [["11682.30000", "2.00397973", "1596666797.779425"]], "c": "3960080813"}, "book-100", "XBT/USD"]
[270, {"a": [["11664.10000", "0.64309436", "1596666797.786522"]], "c": "3987378330"}, "book-100", "XBT/USD"]
[270, {"b": [["11649.50000", "1.18671928", "1596666797.786777"]], "c": "3987378330"}, "book-100", "XBT/USD"]
[270, {"a": [["11690.10000", "1.20722728", "1596666797.815848"]], "c": "3987378330"}, "book-100", "XBT/USD"]
[270, {"a": [["11686.60000", "0.49657453", "1596666797.816784"]], "c": "3987378330"}, "book-100", "XBT/USD"]
[270, {"b": [["11632.60000", "0.00000000", "1596666797.901126"], ["11604.10000", "1.51500000", "1596666763.121463", "r"]], "c": "3987378330"}, "book-100", "XBT/USD"]
[270, {"a": [["11684.30000", "0.95915600", "1596666797.920200"]], "c": "3987378330"}, "book-100", "XBT/USD"]
[270, {"b": [["11641.20000", "0.00000000", "1596666797.922117"], ["11603.20000", "2.50039088", "1596666777.334144", "r"]], "c": "3987378330"}, "book-100", "XBT/USD"]
[270, {"b": [["11604.20000", "0.00000000", "1596666797.922887"], ["11602.60000", "1.48021868", "1596666784.125874", "r"]], "c": "3987378330"}, "book-100", "XBT/USD"]
[270, {"a": [["11692.50000", "1.56514914", "1596666797.922995"]], "c": "3987378330"}, "book-100", "XBT/USD"]
[270, {"a": [["11672.70000", "2.79342136", "1596666798.012328"]], "c": "3987378330"}, "book-100", "XBT/USD"]
[270, {"b": [["11651.70000", "0.33907353", "1596666798.020545"]], "c": "3987378330"}, "book-100", "XBT/USD"]
[270, {"a": [["11680.80000", "0.00000000", "1596666798.029722"], ["11705.70000", "0.48380000", "1596666770.726024", "r"]], "c": "3987378330"}, "book-100", "XBT/USD"]
[270, {"a": [["11695.40000", "0.00000000", "1596666798.032923"], ["11709.00000", "0.17085000", "1596666795.991184", "r"]], "c": "3987378330"}, "book-100", "XBT/USD"]
[270, {"a": [["11680.00000", "0.89870764", "1596666798.057050"]], "c": "3987378330"}, "book-100", "XBT/USD"]
[270, {"a": [["11684.60000", "0.89835384", "1596666798.057344"]], "c": "3987378330"}, "book-100", "XBT/USD"]
[270, {"a": [["11691.60000", "0.89781597", "1596666798.065594"]], "c": "3987378330"}, "book-100", "XBT/USD"]
[270, {"a": [["11686.70000", "0.00000000", "1596666798.068065"], ["11705.20000", "0.75800000", "1596666760.546082", "r"]], "c": "3987378330"}, "book-100", "XBT/USD"]
[270, {"a": [["11680.90000", "0.00000000", "1596666798.068346"], ["11705.70000", "0.48380000", "1596666770.726024", "r"]], "c": "3987378330"}, "book-100", "XBT/USD"]
[270, {"a": [["11684.30000", "0.24908827", "1596666798.071505"]], "c": "3987378330"}, "book-100", "XBT/USD"]
[270, {"a": [["11666.40000", "0.00000000", "1596666798.087072"], ["11709.00000", "0.17085000", "1596666795.991184", "r"]], "c": "3987378330"}, "book-100", "XBT/USD"]
[270, {"b": [["11646.50000", "4.26262626", "1596666798.089627"]], "c": "3987378330"}, "book-100", "XBT/USD"]
[270, {"a": [["11692.00000", "0.00000000", "1596666798.092318"], ["11709.70000", "7.20507863", "1596666620.257365", "r"]], "c": "3987378330"}, "book-100", "XBT/USD"]
[270, {"a": [["11676.50000", "2.89897703", "1596666798.126350"]], "c": "3987378330"}, "book-100", "XBT/USD"]
[270, {"a": [["11666.80000", "0.00000000", "1596666798.189090"], ["11709.90000", "3.52186457", "1596666773.954225", "r"]], "c": "3987378330"}, "book-100", "XBT/USD"]
[270, {"a": [["11666.00000", "1.49356595", "1596666798.201874"]], "c": "3987378330"}, "book-100", "XBT/USD"]
[270, {"b": [["11642.10000", "0.85764595", "1596666798.202622"]], "c": "3987378330"}, "book-100", "XBT/USD"]
[270, {"b": [["11646.50000", "2.59712626", "1596666798.308891"]], "c": "3987378330"}, "book-100", "XBT/USD"]
[270, {"a": [["11670.60000", "0.26170193", "1596666798.318217"]], "c": "3987378330"}, "book-100", "XBT/USD"]
[270, {"a": [["11686.60000", "0.00000000", "1596666798.339112"], ["11710.10000", "0.89650546", "1596666771.484931", "r"]], "c": "3987378330"}, "book-100", "XBT/USD"]
[270, {"a": [["11692.50000", "0.57250123", "1596666798.342970"]], "c": "3987378330"}, "book-100", "XBT/USD"]
[270, {"a": [["11703.70000", "0.00000000", "1596666798.356458"], ["11710.40000", "1.16811308", "1596666772.597033", "r"]], "c": "3987378330"}, "book-100", "XBT/USD"]
[270, {"b": [["11642.10000", "0.00000000", "1596666798.369905"], ["11603.20000", "2.50039088", "1596666777.334144", "r"]], "c": "3987378330"}, "book-100", "XBT/USD"]
[270, {"a": [["11670.40000", "0.00000000", "1596666798.395373"], ["11710.60000", "2.80039129", "1596666770.582883", "r"]], "c": "3987378330"}, "book-100", "XBT/USD"]
[270, {"a": [["11665.70000", "0.41844585", "1596666798.426337"]], "c": "3987378330"}, "book-100", "XBT/USD"]
[270, {"b": [["11649.10000", "1.75137520", "1596666798.452242"]], "c": "3987378330"}, "book-100", "XBT/USD"]
[270, {"a": [["11670.70000", "1.89378088", "1596666798.463313"]], "c": "3987378330"}, "book-100", "XBT/USD"]
[270, {"a": [["11682.30000", "3.79636223", "1596666798.465702"]], "c": "3987378330"}, "book-100", "XBT/USD"]
[270, {"a": [["11684.20000", "0.00000000", "1596666798.465839"], ["11710.60000", "2.80039129", "1596666770.582883", "r"]], "c": "3987378330"}, "book-100", "XBT/USD"]
[270, {"a": [["11686.50000", "0.00000000", "1596666798.466297"], ["11710.70000", "3.52183532", "1596666711.393054", "r"]], "c": "3987378330"}, "book-100", "XBT/USD"]
[270, {"a": [["11690.10000", "0.00000000", "1596666798.468557"], ["11711.20000", "0.30235286", "1596666794.347286", "r"]], "c": "3987378330"}, "book-100", "XBT/USD"]
[270, {"a": [["11676.50000", "4.32006115", "1596666798.473427"]], "c": "3987378330"}, "book-100", "XBT/USD"]
[270, {"a": [["11674.10000", "0.71068814", "1596666798.473486"]], "c": "3987378330"}, "book-100", "XBT/USD"]
[270, {"a": [["11694.00000", "1.48878088", "1596666798.491073"]], "c": "3987378330"}, "book-100", "XBT/USD"]
[270, {"a": [["11678.80000", "6.63953493", "1596666798.491835"]], "c": "3987378330"}, "book-100", "XBT/USD"]
[270, {"a": [["11684.60000", "1.89167289", "1596666798.494004"]], "c": "3987378330"}, "book-100", "XBT/USD"]
[270, {"a": [["11689.70000", "0.00000000", "1596666798.518776"], ["11710.70000", "3.52183532", "1596666711.393054", "r"]], "c": "3987378330"}, "book-100", "XBT/USD"]
[270, {"a": [["11703.80000", "0.00000000", "1596666798.521427"], ["11711.20000", "0.30235286", "1596666794.347286", "r"]], "c": "3987378330"}, "book-100", "XBT/USD"]
[270, {"a": [["11692.50000", "0.00000000", "1596666798.522752"], ["11711.50000", "1.99898326", "1596666797.632161", "r"]], "c": "3987378330"}, "book-100", "XBT/USD"]
[270, {"a": [["11684.30000", "0.00000000", "1596666798.525137"], ["11713.80000", "0.37309062", "1596666771.863547", "r"]], "c": "3987378330"}, "book-100", "XBT/USD"]
[270, {"a": [["11670.10000", "0.15000000", "1596666798.559901"]], "c": "3987378330"}, "book-100", "XBT/USD"]
[270, {"a": [["11676.50000", "2.32006115", "1596666798.585954"]], "c": "3987378330"}, "book-100", "XBT/USD"]
[271, [["11662.30000", "0.04996798", "1596666798.782035", "b", "m", ""], ["11662.30000", "0.50000000", "1596666798.787724", "b", "m", ""], ["11662.30000", "0.50000000", "1596666798.789401", "b", "m", ""], ["11662.30000", "0.23000000", "1596666798.790779", "b", "m", ""], ["11662.30000", "0.57194021", "1596666798.792234", "b", "m", ""], ["11662.30000", "0.00235497", "1596666798.793849", "b", "m", ""], ["11662.30000", "0.00798882", "1596666798.795261", "b", "m", ""], ["11662.30000", "0.00001116", "1596666798.796873", "b", "m", ""], ["11662.30000", "0.00000002", "1596666798.798122", "b", "m", ""], ["11662.30000", "0.50000000", "1596666798.800216", "b", "m", ""], ["11662.30000", "1.50000000", "1596666798.801814", "b", "m", ""], ["11662.60000", "0.13773684", "1596666798.803194", "b", "m", ""]], "trade", "XBT/USD"]
[270, {"a": [["11662.30000", "3.81229518", "1596666798.782035"], ["11662.30000", "3.31229518", "1596666798.787724"], ["11662.30000", "2.81229518", "1596666798.789401"], ["11662.30000", "2.58229518", "1596666798.790779"], ["11662.30000", "2.01035497", "1596666798.792234"], ["11662.30000", "2.00800000", "1596666798.793849"], ["11662.30000", "2.00001118", "1596666798.795261"], ["11662.30000", "2.00000002", "1596666798.796873"], ["11662.30000", "2.00000000", "1596666798.798122"], ["11662.30000", "1.50000000", "1596666798.800216"], ["11662.30000", "0.00000000", "1596666798.801814"], ["11713.80000", "0.37309062", "1596666771.863547", "r"], ["11662.60000", "0.12077758", "1596666798.803194"]], "c": "2873761102"}, "book-100", "XBT/USD"]
[270, {"a": [["11668.80000", "0.00000000", "1596666798.807883"], ["11715.30000", "6.10000000", "1596666635.445451", "r"]], "c": "2873761102"}, "book-100", "XBT/USD"]
[270, {"a": [["11676.50000", "3.04361599", "1596666798.808396"]], "c": "2873761102"}, "book-100", "XBT/USD"]
[270, {"a": [["11682.30000", "5.00513204", "1596666798.808556"]], "c": "2873761102"}, "book-100", "XBT/USD"]
[270, {"a": [["11669.40000", "0.00000000", "1596666798.862031"], ["11717.80000", "1.99812614", "1596666759.535617", "r"]], "c": "2873761102"}, "book-100", "XBT/USD"]
[270, {"a": [["11672.70000", "1.64160000", "1596666798.865743"]], "c": "2873761102"}, "book-100", "XBT/USD"]
[270, {"a": [["11670.10000", "0.00000000", "1596666798.874644"], ["11718.00000", "0.17085000", "1596666789.369605", "r"]], "c": "2873761102"}, "book-100", "XBT/USD"]
[270, {"a": [["11673.50000", "0.00000000", "1596666798.945550"], ["11718.50000", "24.30000000", "1596666641.380470", "r"]], "c": "2873761102"}, "book-100", "XBT/USD"]
[270, {"a": [["11671.90000", "0.00641829", "1596666798.965328"]], "c": "2873761102"}, "book-100", "XBT/USD"]
[270, {"b": [["11646.30000", "0.13427919", "1596666798.980928"]], "c": "2873761102"}, "book-100", "XBT/USD"]
[270, {"a": [["11663.20000", "0.00000000", "1596666799.036569"], ["11718.50000", "24.30000000", "1596666641.380470", "r"]], "c": "526393234"}, "book-100", "XBT/USD"]
[270, {"a": [["11665.90000", "1.10349656", "1596666799.050993"]], "c": "526393234"}, "book-100", "XBT/USD"]
[270, {"a": [["11662.60000", "1.62077758", "1596666799.105545"]], "c": "2836859344"}, "book-100", "XBT/USD"]
[270, {"a": [["11662.50000", "0.75551922", "1596666799.159796"]], "c": "3458523466"}, "book-100", "XBT/USD"]
[270, {"a": [["11670.40000", "0.15000000", "1596666799.173937"]], "c": "3458523466"}, "book-100", "XBT/USD"]
[270, {"a": [["11697.50000", "10.19786236", "1596666799.194056"]], "c": "3458523466"}, "book-100", "XBT/USD"]
[270, {"a": [["11694.00000", "8.55792434", "1596666799.261380"]], "c": "3458523466"}, "book-100", "XBT/USD"]
[270, {"a": [["11678.80000", "10.17108077", "1596666799.284495"]], "c": "3458523466"}, "book-100", "XBT/USD"]
[270, {"a": [["11670.90000", "0.00000000", "1596666799.286464"], ["11715.30000", "6.10000000", "1596666635.445451", "r"]], "c": "3458523466"}, "book-100", "XBT/USD"]
[270, {"b": [["11645.00000", "3.54179627", "1596666799.290893"]], "c": "3458523466"}, "book-100", "XBT/USD"]
[270, {"a": [["11674.10000", "0.81407437", "1596666799.291939"]], "c": "3458523466"}, "book-100", "XBT/USD"]
[270, {"a": [["11662.30000", "0.50000000", "1596666799.292415"]], "c": "1718526697"}, "book-100", "XBT/USD"]
[270, {"a": [["11684.60000", "5.42146575", "1596666799.293874"]], "c": "1718526697"}, "book-100", "XBT/USD"]
[270, {"a": [["11682.30000", "12.08135536", "1596666799.296007"]], "c": "1718526697"}, "book-100", "XBT/USD"]
[270, {"a": [["11662.60000", "0.12077758", "1596666799.302223"]], "c": "2277969176"}, "book-100", "XBT/USD"]
[270, {"a": [["11705.60000", "1.98337449", "1596666799.303428"]], "c": "2277969176"}, "book-100", "XBT/USD"]
[270, {"a": [["11664.40000", "0.00000000", "1596666799.320462"], ["11713.80000", "0.37309062", "1596666771.863547", "r"]], "c": "2277969176"}, "book-100", "XBT/USD"]
[270, {"b": [["11657.30000", "0.00000000", "1596666799.320546"], ["11603.20000", "2.50039088", "1596666777.334144", "r"]], "c": "1434486769"}, "book-100", "XBT/USD"]
[270, {"b": [["11639.20000", "3.54356121", "1596666799.342595"]], "c": "1434486769"}, "book-100", "XBT/USD"]
[270, {"a": [["11662.30000", "2.60000000", "1596666799.354908"]], "c": "1264304157"}, "book-100", "XBT/USD"]
[270, {"a": [["11682.30000", "15.28008585", "1596666799.439027"]], "c": "1264304157"}, "book-100", "XBT/USD"]
[270, {"a": [["11662.60000", "1.62077758", "1596666799.451802"]], "c": "495672596"}, "book-100", "XBT/USD"]
[270, {"a": [["11662.50000", "0.00000000", "1596666799.460614"], ["11715.30000", "6.10000000", "1596666635.445451", "r"]], "c": "2271588489"}, "book-100", "XBT/USD"]
[270, {"a": [["11698.10000", "0.00000000", "1596666799.464023"], ["11717.80000", "1.99812614", "1596666759.535617", "r"]], "c": "2271588489"}, "book-100", "XBT/USD"]
[270, {"a": [["11662.30000", "0.50000000", "1596666799.468502"]], "c": "2635515521"}, "book-100", "XBT/USD"]
[270, {"b": [["11658.20000", "0.25000000", "1596666799.503451"]], "c": "1550729307"}, "book-100", "XBT/USD"]
[270, {"a": [["11665.30000", "0.41352978", "1596666799.508052"]], "c": "1550729307"}, "book-100", "XBT/USD"]
[270, {"a": [["11662.60000", "0.12077758", "1596666799.596424"]], "c": "2879171547"}, "book-100", "XBT/USD"]
[270, {"a": [["11697.90000", "10.19785560", "1596666799.641080"]], "c": "2879171547"}, "book-100", "XBT/USD"]
[270, {"a": [["11662.30000", "2.00000000", "1596666799.747006"]], "c": "1898782685"}, "book-100", "XBT/USD"]
[270, {"b": [["11623.60000", "0.00900000", "1596666799.763167"]], "c": "1898782685"}, "book-100", "XBT/USD"]
[270, {"a": [["11697.50000", "0.00000000", "1596666799.783915"], ["11715.30000", "6.10000000", "1596666635.445451", "r"]], "c": "1898782685"}, "book-100", "XBT/USD"]
[270, {"a": [["11662.30000", "2.00233043", "1596666799.869477"]], "c": "2706961074"}, "book-100", "XBT/USD"]
[270, {"b": [["11651.70000", "1.83907353", "1596666799.888290"]], "c": "2706961074"}, "book-100", "XBT/USD"]
[270, {"a": [["11665.90000", "0.00000000", "1596666799.927056"], ["11717.80000", "1.99812614", "1596666759.535617", "r"]], "c": "2706961074"}, "book-100", "XBT/USD"]
[270, {"a": [["11662.30000", "2.51390424", "1596666800.003642"]], "c": "658392890"}, "book-100", "XBT/USD"]
[270, {"a": [["11665.60000", "1.10537229", "1596666800.065081"]], "c": "658392890"}, "book-100", "XBT/USD"]
[270, {"b": [["11613.00000", "0.00000000", "1596666800.087046"], ["11606.00000", "0.74921971", "1596666797.264674", "r"]], "c": "658392890"}, "book-100", "XBT/USD"]
[270, {"b": [["11626.70000", "2.06000000", "1596666800.090944"]], "c": "658392890"}, "book-100", "XBT/USD"]
[270, {"b": [["11643.50000", "0.72800000", "1596666800.147322"]], "c": "658392890"}, "book-100", "XBT/USD"]
[270, {"a": [["11662.30000", "1.01390424", "1596666800.171908"]], "c": "4193899717"}, "book-100", "XBT/USD"]
[270, {"b": [["11662.20000", "0.00000000", "1596666800.173709"], ["11607.00000", "0.17085000", "1596666720.750083", "r"]], "c": "3337212724"}, "book-100", "XBT/USD"]
[270, {"a": [["11662.30000", "0.51390424", "1596666800.239160"]], "c": "2282083670"}, "book-100", "XBT/USD"]
[270, {"a": [["11661.80000", "0.50000000", "1596666800.306621"]], "c": "4112871699"}, "book-100", "XBT/USD"]
[270, {"a": [["11698.90000", "4.22885702", "1596666800.312473"]], "c": "4112871699"}, "book-100", "XBT/USD"]
[270, {"a": [["11666.30000", "1.50000000", "1596666800.318994"]], "c": "4112871699"}, "book-100", "XBT/USD"]
[270, {"b": [["11646.30000", "0.00000000", "1596666800.369869"], ["11606.00000", "0.74921971", "1596666797.264674", "r"]], "c": "4112871699"}, "book-100", "XBT/USD"]
[270, {"b": [["11649.50000", "0.00000000", "1596666800.393166"], ["11604.10000", "1.51500000", "1596666763.121463", "r"]], "c": "4112871699"}, "book-100", "XBT/USD"]
[270, {"a": [["11665.60000", "0.00000000", "1596666800.397814"], ["11713.80000", "0.37309062", "1596666771.863547", "r"]], "c": "4112871699"}, "book-100", "XBT/USD"]
[270, {"a": [["11661.80000", "2.60000000", "1596666800.407529"]], "c": "3722071837"}, "book-100", "XBT/USD"]
[270, {"b": [["11661.30000", "0.42900000", "1596666800.418860"]], "c": "3140624393"}, "book-100", "XBT/USD"]
[270, {"a": [["11668.00000", "0.00000000", "1596666800.453446"], ["11715.30000", "6.10000000", "1596666635.445451", "r"]], "c": "3140624393"}, "book-100", "XBT/USD"]
[270, {"b": [["11641.10000", "7.10066894", "1596666800.454178"]], "c": "3140624393"}, "book-100", "XBT/USD"]
[270, {"b": [["11639.10000", "0.03100000", "1596666800.508728"]], "c": "3140624393"}, "book-100", "XBT/USD"]
[270, {"a": [["11661.80000", "0.50000000", "1596666800.521367"]], "c": "2479693319"}, "book-100", "XBT/USD"]
[270, {"a": [["11662.30000", "0.00233043", "1596666800.530599"]], "c": "4131998936"}, "book-100", "XBT/USD"]
[270, {"a": [["11664.80000", "0.01000000", "1596666800.532421"]], "c": "4131998936"}, "book-100", "XBT/USD"]
[270, {"b": [["11646.70000", "0.85925497", "1596666800.543576"]], "c": "4131998936"}, "book-100", "XBT/USD"]
[270, {"b": [["11619.10000", "6.62920004", "1596666800.614871"]], "c": "4131998936"}, "book-100", "XBT/USD"]
[270, {"a": [["11666.60000", "0.09700000", "1596666800.653747"]], "c": "4131998936"}, "book-100", "XBT/USD"]
[270, {"b": [["11644.00000", "0.01341419", "1596666800.796951"]], "c": "4131998936"}, "book-100", "XBT/USD"]
[270, {"b": [["11643.90000", "4.00000000", "1596666800.797865"]], "c": "4131998936"}, "book-100", "XBT/USD"]
[270, {"a": [["11661.80000", "0.96059821", "1596666800.855242"]], "c": "2125510426"}, "book-100", "XBT/USD"]
[270, {"a": [["11662.30000", "0.00000000", "1596666800.879305"], ["11713.80000", "0.37309062", "1596666771.863547", "r"]], "c": "148228619"}, "book-100", "XBT/USD"]
[270, {"b": [["11644.00000", "0.00000000", "1596666800.925357"], ["11607.70000", "8.40000000", "1596666777.775135", "r"]], "c": "148228619"}, "book-100", "XBT/USD"]
[270, {"b": [["11641.20000", "0.04223941", "1596666800.926577"]], "c": "148228619"}, "book-100", "XBT/USD"]
[270, {"a": [["11663.80000", "0.00000000", "1596666800.926819"], ["11715.30000", "6.10000000", "1596666635.445451", "r"]], "c": "1125442202"}, "book-100", "XBT/USD"]
[270, {"b": [["11652.70000", "0.00000000", "1596666800.927921"], ["11607.70000", "8.40000000", "1596666777.775135", "r"]], "c": "1125442202"}, "book-100", "XBT/USD"]
[270, {"a": [["11680.20000", "6.56888043", "1596666801.061507"]], "c": "1125442202"}, "book-100", "XBT/USD"]
[270, {"a": [["11687.80000", "0.00000000", "1596666801.132704"], ["11717.80000", "1.99812614", "1596666759.535617", "r"]], "c": "1125442202"}, "book-100", "XBT/USD"]
[270, {"b": [["11654.60000", "0.04250000", "1596666801.186704"]], "c": "1125442202"}, "book-100", "XBT/USD"]
[270, {"b": [["11653.20000", "0.85757576", "1596666801.202008"]], "c": "1125442202"}, "book-100", "XBT/USD"]
[270, {"a": [["11661.80000", "0.96292864", "1596666801.202514"]], "c": "1546724401"}, "book-100", "XBT/USD"]
[270, {"a": [["11687.20000", "0.74922720", "1596666801.251606"]], "c": "1546724401"}, "book-100", "XBT/USD"]
[270, {"a": [["11704.70000", "2.24869958", "1596666801.254199"]], "c": "1546724401"}, "book-100", "XBT/USD"]
[270, {"a": [["11684.50000", "0.53173084", "1596666801.257159"]], "c": "1546724401"}, "book-100", "XBT/USD"]
[270, {"a": [["11680.20000", "6.56449857", "1596666801.308901"]], "c": "1546724401"}, "book-100", "XBT/USD"]
[270, {"a": [["11672.60000", "0.54342195", "1596666801.377044"]], "c": "1546724401"}, "book-100", "XBT/USD"]
[270, {"b": [["11661.70000", "0.00000000", "1596666801.428014"], ["11609.80000", "21.20000000", "1596666704.766154", "r"]], "c": "2885318698"}, "book-100", "XBT/USD"]
[270, {"b": [["11626.70000", "0.00000000", "1596666801.428841"], ["11608.40000", "0.74922720", "1596666801.278856", "r"]], "c": "2885318698"}, "book-100", "XBT/USD"]
[270, {"a": [["11664.10000", "0.00000000", "1596666801.502447"], ["11711.50000", "1.99898326", "1596666797.632161", "r"]], "c": "2433255636"}, "book-100", "XBT/USD"]
[270, {"a": [["11661.80000", "0.46292864", "1596666801.518763"]], "c": "3599193928"}, "book-100", "XBT/USD"]
[270, {"a": [["11661.40000", "0.50000000", "1596666801.583957"]], "c": "230007836"}, "book-100", "XBT/USD"]
[270, {"a": [["11663.80000", "0.04250000", "1596666801.612813"]], "c": "701759761"}, "book-100", "XBT/USD"]
[270, {"a": [["11670.40000", "0.00000000", "1596666801.612882"], ["11711.20000", "0.30235286", "1596666794.347286", "r"]], "c": "701759761"}, "book-100", "XBT/USD"]
[270, {"b": [["11658.20000", "0.00000000", "1596666801.616298"], ["11607.70000", "8.40000000", "1596666777.775135", "r"]], "c": "2638334168"}, "book-100", "XBT/USD"]
[270, {"a": [["11698.90000", "1.95885702", "1596666801.622228"]], "c": "2638334168"}, "book-100", "XBT/USD"]
[270, {"a": [["11661.40000", "2.60000000", "1596666801.682684"]], "c": "3981249257"}, "book-100", "XBT/USD"]
[270, {"a": [["11670.40000", "0.15000000", "1596666801.749179"]], "c": "3981249257"}, "book-100", "XBT/USD"]
[270, {"a": [["11661.40000", "0.50000000", "1596666801.752281"]], "c": "2638334168"}, "book-100", "XBT/USD"]
[270, {"a": [["11662.30000", "0.99702000", "1596666801.776049"]], "c": "1337106244"}, "book-100", "XBT/USD"]
[270, {"a": [["11661.80000", "0.00233043", "1596666801.810618"]], "c": "2525121322"}, "book-100", "XBT/USD"]
[270, {"b": [["11649.10000", "0.96076520", "1596666802.803119"]], "c": "2525121322"}, "book-100", "XBT/USD"]
[270, {"b": [["11657.30000", "0.25000000", "1596666802.824752"]], "c": "387863594"}, "book-100", "XBT/USD"]
[270, {"a": [["11672.10000", "2.00000000", "1596666802.869797"]], "c": "387863594"}, "book-100", "XBT/USD"]
[270, {"a": [["11692.60000", "0.89623231", "1596666802.874109"]], "c": "387863594"}, "book-100", "XBT/USD"]
[270, {"a": [["11681.00000", "0.34888091", "1596666802.874886"]], "c": "387863594"}, "book-100", "XBT/USD"]
[270, {"a": [["11672.60000", "0.00000000", "1596666802.875029"], ["11710.10000", "0.89650546", "1596666771.484931", "r"]], "c": "387863594"}, "book-100", "XBT/USD"]
[270, {"a": [["11665.30000", "0.00000000", "1596666802.876090"], ["11710.40000", "1.16811308", "1596666772.597033", "r"]], "c": "387863594"}, "book-100", "XBT/USD"]
[270, {"a": [["11685.60000", "0.57293587", "1596666802.879405"]], "c": "387863594"}, "book-100", "XBT/USD"]
[270, {"b": [["11657.90000", "0.00000000", "1596666802.881673"], ["11607.70000", "8.40000000", "1596666777.775135", "r"]], "c": "1895869716"}, "book-100", "XBT/USD"]
[270, {"b": [["11617.00000", "0.00000000", "1596666802.885768"], ["11607.00000", "0.17085000", "1596666720.750083", "r"]], "c": "1895869716"}, "book-100", "XBT/USD"]
[270, {"a": [["11661.40000", "0.92553525", "1596666802.925157"]], "c": "2405877721"}, "book-100", "XBT/USD"]
[270, {"a": [["11677.40000", "0.24927747", "1596666802.928278"]], "c": "2405877721"}, "book-100", "XBT/USD"]
[270, {"a": [["11662.80000", "0.00000000", "1596666802.933573"], ["11710.10000", "0.89650546", "1596666771.484931", "r"]], "c": "2171022410"}, "book-100", "XBT/USD"]
[270, {"a": [["11662.60000", "0.00000000", "1596666802.942918"], ["11710.40000", "1.16811308", "1596666772.597033", "r"]], "c": "3387400846"}, "book-100", "XBT/USD"]
[270, {"a": [["11661.80000", "0.00000000", "1596666802.943251"], ["11710.60000", "2.80039129", "1596666770.582883", "r"]], "c": "1367766766"}, "book-100", "XBT/USD"]
[270, {"a": [["11662.20000", "0.25851849", "1596666802.948003"]], "c": "322202332"}, "book-100", "XBT/USD"]
[270, {"b": [["11630.90000", "1.11290000", "1596666803.019284"]], "c": "322202332"}, "book-100", "XBT/USD"]
[270, {"a": [["11674.00000", "0.45975138", "1596666803.071136"]], "c": "322202332"}, "book-100", "XBT/USD"]
[270, {"a": [["11664.00000", "0.41352978", "1596666803.085779"]], "c": "164020841"}, "book-100", "XBT/USD"]
[270, {"b": [["11613.00000", "0.17085000", "1596666803.224745"]], "c": "164020841"}, "book-100", "XBT/USD"]
[270, {"a": [["11674.00000", "0.00300000", "1596666803.262744"]], "c": "164020841"}, "book-100", "XBT/USD"]
[270, {"a": [["11684.50000", "0.00000000", "1596666803.263226"], ["11710.40000", "1.16811308", "1596666772.597033", "r"]], "c": "164020841"}, "book-100", "XBT/USD"]
[270, {"a": [["11661.40000", "0.92786568", "1596666803.396342"]], "c": "4111127680"}, "book-100", "XBT/USD"]
[270, {"a": [["11703.00000", "0.17085000", "1596666803.415332"]], "c": "4111127680"}, "book-100", "XBT/USD"]
[270, {"b": [["11657.30000", "0.00000000", "1596666803.587237"], ["11607.70000", "8.40000000", "1596666777.775135", "r"]], "c": "25345480"}, "book-100", "XBT/USD"]
[270, {"a": [["11670.70000", "1.19412151", "1596666803.608253"]], "c": "25345480"}, "book-100", "XBT/USD"]
[270, {"b": [["11661.10000", "0.08647022", "1596666803.613312"]], "c": "3323164359"}, "book-100", "XBT/USD"]
[270, {"b": [["11647.30000", "0.00000000", "1596666803.661895"], ["11607.70000", "8.40000000", "1596666777.775135", "r"]], "c": "3323164359"}, "book-100", "XBT/USD"]
[270, {"b": [["11659.50000", "0.09800000", "1596666803.666229"]], "c": "3966473792"}, "book-100", "XBT/USD"]
[270, {"a": [["11670.40000", "0.00000000", "1596666803.667893"], ["11710.40000", "1.16811308", "1596666772.597033", "r"]], "c": "3966473792"}, "book-100", "XBT/USD"]
[270, {"b": [["11658.10000", "0.64318934", "1596666803.669308"]], "c": "2513117786"}, "book-100", "XBT/USD"]
[270, {"a": [["11661.60000", "0.64322852", "1596666803.669414"]], "c": "131544665"}, "book-100", "XBT/USD"]
[270, {"a": [["11661.40000", "1.57114290", "1596666803.669742"]], "c": "916956342"}, "book-100", "XBT/USD"]
[270, {"a": [["11661.40000", "1.07114290", "1596666803.674123"]], "c": "1847104521"}, "book-100", "XBT/USD"]
[270, {"a": [["11664.00000", "0.00000000", "1596666803.675056"], ["11710.40000", "1.16811308", "1596666772.597033", "r"]], "c": "1208443637"}, "book-100", "XBT/USD"]
[270, {"a": [["11666.60000", "0.00000000", "1596666803.675715"], ["11710.60000", "2.80039129", "1596666770.582883", "r"]], "c": "1208443637"}, "book-100", "XBT/USD"]
[270, {"a": [["11676.40000", "0.69948755", "1596666803.676613"]], "c": "1208443637"}, "book-100", "XBT/USD"]
[270, {"b": [["11639.10000", "0.00000000", "1596666803.676680"], ["11608.40000", "0.74922720", "1596666801.278856", "r"]], "c": "1208443637"}, "book-100", "XBT/USD"]
[270, {"b": [["11658.00000", "9.99987003", "1596666803.725730"]], "c": "212910692"}, "book-100", "XBT/USD"]
[270, {"b": [["11638.10000", "0.03100000", "1596666803.727028"]], "c": "212910692"}, "book-100", "XBT/USD"]
[270, {"a": [["11671.90000", "0.00000000", "1596666803.728984"], ["11710.60000", "2.80039129", "1596666770.582883", "r"]], "c": "212910692"}, "book-100", "XBT/USD"]
[270, {"a": [["11667.70000", "2.26304045", "1596666803.731535"]], "c": "212910692"}, "book-100", "XBT/USD"]
[270, {"b": [["11643.80000", "0.38000000", "1596666803.732446"]], "c": "212910692"}, "book-100", "XBT/USD"]
[270, {"a": [["11667.60000", "0.00000000", "1596666803.735644"], ["11710.60000", "2.80039129", "1596666770.582883", "r"]], "c": "212910692"}, "book-100", "XBT/USD"]
[270, {"b": [["11661.10000", "0.00000000", "1596666803.738521"], ["11609.80000", "21.20000000", "1596666704.766154", "r"]], "c": "3167522527"}, "book-100", "XBT/USD"]
[270, {"a": [["11675.80000", "0.00000000", "1596666803.742547"], ["11710.70000", "3.52183532", "1596666711.393054", "r"]], "c": "3167522527"}, "book-100", "XBT/USD"]
[270, {"b": [["11661.30000", "0.82900000", "1596666803.745544"]], "c": "1757310139"}, "book-100", "XBT/USD"]
[270, {"a": [["11674.10000", "0.71068814", "1596666803.746628"]], "c": "1757310139"}, "book-100", "XBT/USD"]
[270, {"a": [["11676.50000", "2.32006115", "1596666803.747818"]], "c": "1757310139"}, "book-100", "XBT/USD"]
[270, {"a": [["11676.50000", "0.89897703", "1596666803.749698"]], "c": "1757310139"}, "book-100", "XBT/USD"]
[270, {"a": [["11673.50000", "0.00641741", "1596666803.750795"]], "c": "1757310139"}, "book-100", "XBT/USD"]
[270, {"a": [["11677.40000", "0.00000000", "1596666803.754167"], ["11710.70000", "3.52183532", "1596666711.393054", "r"]], "c": "1757310139"}, "book-100", "XBT/USD"]
[270, {"a": [["11663.10000", "0.00000000", "1596666803.755728"], ["11711.20000", "0.30235286", "1596666794.347286", "r"]], "c": "3709611731"}, "book-100", "XBT/USD"]
[270, {"a": [["11661.40000", "0.42786568", "1596666803.758026"]], "c": "2120780256"}, "book-100", "XBT/USD"]
[270, {"a": [["11676.40000", "0.00000000", "1596666803.759268"], ["11711.50000", "1.99898326", "1596666797.632161", "r"]], "c": "2120780256"}, "book-100", "XBT/USD"]
[270, {"a": [["11676.50000", "0.00000000", "1596666803.760242"], ["11713.80000", "0.37309062", "1596666771.863547", "r"]], "c": "2120780256"}, "book-100", "XBT/USD"]
[270, {"b": [["11657.10000", "0.57230000", "1596666803.760972"]], "c": "2238140118"}, "book-100", "XBT/USD"]
[270, {"a": [["11662.70000", "0.00000000", "1596666803.763507"], ["11715.30000", "6.10000000", "1596666635.445451", "r"]], "c": "3868067438"}, "book-100", "XBT/USD"]
[270, {"b": [["11647.20000", "0.00000000", "1596666803.764118"], ["11609.80000", "21.20000000", "1596666704.766154", "r"]], "c": "3868067438"}, "book-100", "XBT/USD"]
[270, {"a": [["11672.70000", "0.00000000", "1596666803.764203"], ["11717.80000", "1.99812614", "1596666759.535617", "r"]], "c": "3868067438"}, "book-100", "XBT/USD"]
[270, {"b": [["11659.10000", "0.00000000", "1596666803.769427"], ["11608.40000", "0.74922720", "1596666801.278856", "r"]], "c": "3223330201"}, "book-100", "XBT/USD"]
[270, {"a": [["11670.60000", "0.15000000", "1596666803.769512"]], "c": "3223330201"}, "book-100", "XBT/USD"]
[270, {"a": [["11670.70000", "0.85560000", "1596666803.774138"]], "c": "3223330201"}, "book-100", "XBT/USD"]
[270, {"a": [["11669.10000", "0.00000000", "1596666803.786720"], ["11718.00000", "0.17085000", "1596666789.369605", "r"]], "c": "3223330201"}, "book-100", "XBT/USD"]
[270, {"b": [["11645.10000", "0.04222526", "1596666803.795836"]], "c": "3223330201"}, "book-100", "XBT/USD"]
[270, {"b": [["11649.20000", "0.00000000", "1596666803.801623"], ["11608.40000", "0.74922720", "1596666801.278856", "r"]], "c": "3223330201"}, "book-100", "XBT/USD"]
[270, {"a": [["11681.00000", "0.00000000", "1596666803.804043"], ["11718.50000", "24.30000000", "1596666641.380470", "r"]], "c": "3223330201"}, "book-100", "XBT/USD"]
[270, {"a": [["11680.00000", "0.00000000", "1596666803.804985"], ["11719.60000", "2.98021891", "1596666782.974175", "r"]], "c": "3223330201"}, "book-100", "XBT/USD"]
[270, {"a": [["11666.00000", "0.63592000", "1596666803.805417"]], "c": "3223330201"}, "book-100", "XBT/USD"]
[270, {"a": [["11669.70000", "0.00000000", "1596666803.808247"], ["11719.70000", "3.50602221", "1596666789.365232", "r"]], "c": "3223330201"}, "book-100", "XBT/USD"]
[270, {"a": [["11670.10000", "0.41352978", "1596666803.809060"]], "c": "3223330201"}, "book-100", "XBT/USD"]
[270, {"a": [["11663.50000", "0.00000000", "1596666803.810559"], ["11719.70000", "3.50602221", "1596666789.365232", "r"]], "c": "3971485467"}, "book-100", "XBT/USD"]
[270, {"a": [["11665.70000", "0.00000000", "1596666803.812477"], ["11721.00000", "0.97885000", "1596666783.855310", "r"]], "c": "4032446480"}, "book-100", "XBT/USD"]
[270, {"a": [["11670.00000", "0.00000000", "1596666803.814890"], ["11721.70000", "2.47549182", "1596666772.357495", "r"]], "c": "4032446480"}, "book-100", "XBT/USD"]
[270, {"a": [["11679.50000", "0.50000000", "1596666803.815780"]], "c": "4032446480"}, "book-100", "XBT/USD"]
[270, {"a": [["11672.80000", "0.00000000", "1596666803.816684"], ["11721.70000", "2.47549182", "1596666772.357495", "r"]], "c": "4032446480"}, "book-100", "XBT/USD"]
[270, {"a": [["11662.20000", "0.00000000", "1596666803.822802"], ["11722.10000", "7.70000000", "1596666696.315517", "r"]], "c": "3986900954"}, "book-100", "XBT/USD"]
[270, {"a": [["11661.60000", "0.00000000", "1596666803.825040"], ["11722.20000", "3.01549629", "1596666746.821117", "r"]], "c": "1141793196"}, "book-100", "XBT/USD"]
[270, {"a": [["11663.40000", "0.25849758", "1596666803.826475"]], "c": "1962950458"}, "book-100", "XBT/USD"]
[270, {"a": [["11670.40000", "0.15000000", "1596666803.827542"]], "c": "1962950458"}, "book-100", "XBT/USD"]
[270, {"a": [["11678.80000", "6.63953493", "1596666803.829486"]], "c": "1962950458"}, "book-100", "XBT/USD"]
[270, {"b": [["11661.30000", "1.32900000", "1596666803.830092"]], "c": "2457082970"}, "book-100", "XBT/USD"]
[270, {"b": [["11661.30000", "1.43200000", "1596666803.832091"]], "c": "3024152137"}, "book-100", "XBT/USD"]
[270, {"b": [["11641.20000", "0.00000000", "1596666803.832152"], ["11607.70000", "8.40000000", "1596666777.775135", "r"]], "c": "3024152137"}, "book-100", "XBT/USD"]
[270, {"b": [["11658.10000", "0.00000000", "1596666803.832547"], ["11607.00000", "0.17085000", "1596666720.750083", "r"]], "c": "3303239067"}, "book-100", "XBT/USD"]
[270, {"a": [["11667.00000", "0.00000000", "1596666803.833926"], ["11722.10000", "7.70000000", "1596666696.315517", "r"]], "c": "3303239067"}, "book-100", "XBT/USD"]
[270, {"a": [["11678.80000", "6.14262875", "1596666803.834895"]], "c": "3303239067"}, "book-100", "XBT/USD"]
[270, {"a": [["11679.30000", "0.69940253", "1596666803.835134"]], "c": "3303239067"}, "book-100", "XBT/USD"]
[270, {"a": [["11661.40000", "0.00233043", "1596666803.837629"]], "c": "1352865143"}, "book-100", "XBT/USD"]
[270, {"a": [["11672.00000", "0.89494000", "1596666803.838056"]], "c": "1352865143"}, "book-100", "XBT/USD"]
[270, {"a": [["11668.90000", "0.00000000", "1596666803.840753"], ["11722.10000", "7.70000000", "1596666696.315517", "r"]], "c": "1352865143"}, "book-100", "XBT/USD"]
[270, {"a": [["11679.50000", "2.14160000", "1596666803.843570"]], "c": "1352865143"}, "book-100", "XBT/USD"]
[270, {"a": [["11682.30000", "14.07131604", "1596666803.851199"]], "c": "1352865143"}, "book-100", "XBT/USD"]
[270, {"a": [["11682.30000", "6.99509272", "1596666803.853198"]], "c": "1352865143"}, "book-100", "XBT/USD"]
[270, {"a": [["11682.30000", "4.99111299", "1596666803.857178"]], "c": "1352865143"}, "book-100", "XBT/USD"]
[270, {"b": [["11650.90000", "2.92800682", "1596666803.859713"]], "c": "1352865143"}, "book-100", "XBT/USD"]
[270, {"a": [["11662.30000", "0.00000000", "1596666803.869879"], ["11722.20000", "3.01549629", "1596666746.821117", "r"]], "c": "4217385414"}, "book-100", "XBT/USD"]
[270, {"a": [["11663.40000", "0.00000000", "1596666803.875924"], ["11725.40000", "1.99666304", "1596666743.823724", "r"]], "c": "3269092199"}, "book-100", "XBT/USD"]
[270, {"b": [["11638.10000", "0.00000000", "1596666803.877321"], ["11604.10000", "1.51500000", "1596666763.121463", "r"]], "c": "3269092199"}, "book-100", "XBT/USD"]
[270, {"a": [["11664.80000", "0.00000000", "1596666803.878048"], ["11725.50000", "1.06000000", "1596666771.224459", "r"]], "c": "963785490"}, "book-100", "XBT/USD"]
[270, {"a": [["11682.30000", "1.79238250", "1596666803.881794"]], "c": "963785490"}, "book-100", "XBT/USD"]
[270, {"a": [["11666.00000", "0.00000000", "1596666803.884722"], ["11726.30000", "1.78600000", "1596666787.006488", "r"]], "c": "2353008526"}, "book-100", "XBT/USD"]
[270, {"b": [["11660.50000", "0.15000000", "1596666803.884990"]], "c": "2922035996"}, "book-100", "XBT/USD"]
[270, {"a": [["11674.10000", "0.00000000", "1596666803.906982"], ["11726.60000", "0.00700000", "1596666737.891214", "r"]], "c": "2922035996"}, "book-100", "XBT/USD"]
[270, {"a": [["11674.50000", "0.57000000", "1596666803.909056"]], "c": "2922035996"}, "book-100", "XBT/USD"]
[270, {"a": [["11671.60000", "0.00000000", "1596666803.912099"], ["11727.00000", "0.17085000", "1596665935.290778", "r"]], "c": "2922035996"}, "book-100", "XBT/USD"]
[270, {"a": [["11674.40000", "0.47434910", "1596666803.912310"]], "c": "2922035996"}, "book-100", "XBT/USD"]
[270, {"b": [["11661.30000", "1.68200000", "1596666803.913729"]], "c": "2947615896"}, "book-100", "XBT/USD"]
[270, {"a": [["11670.60000", "0.00000000", "1596666803.918824"], ["11727.00000", "0.17085000", "1596665935.290778", "r"]], "c": "2947615896"}, "book-100", "XBT/USD"]
[270, {"a": [["11670.70000", "0.70560000", "1596666803.920993"]], "c": "2947615896"}, "book-100", "XBT/USD"]
[270, {"a": [["11682.30000", "0.00000000", "1596666803.922699"], ["11727.40000", "7.40000000", "1596666699.130230", "r"]], "c": "2947615896"}, "book-100", "XBT/USD"]
[270, {"b": [["11661.30000", "1.98200000", "1596666803.923473"]], "c": "1323259493"}, "book-100", "XBT/USD"]
[270, {"a": [["11670.40000", "0.00000000", "1596666803.926192"], ["11728.00000", "2.99792678", "1596666801.269211", "r"]], "c": "1323259493"}, "book-100", "XBT/USD"]
[270, {"b": [["11647.70000", "0.00000000", "1596666803.927329"], ["11604.10000", "1.51500000", "1596666763.121463", "r"]], "c": "1323259493"}, "book-100", "XBT/USD"]
[270, {"a": [["11674.40000", "0.47785850", "1596666803.928407"]], "c": "1323259493"}, "book-100", "XBT/USD"]
[270, {"b": [["11642.10000", "0.03100000", "1596666803.929474"]], "c": "1323259493"}, "book-100", "XBT/USD"]
[270, {"a": [["11673.50000", "0.00000000", "1596666803.931161"], ["11728.90000", "4.26297436", "1596666773.365922", "r"]], "c": "1323259493"}, "book-100", "XBT/USD"]
[270, {"b": [["11649.10000", "0.10354498", "1596666803.954774"]], "c": "1323259493"}, "book-100", "XBT/USD"]
[270, {"a": [["11663.80000", "0.00000000", "1596666803.959491"], ["11729.00000", "9.29631056", "1596665758.165359", "r"]], "c": "2675906905"}, "book-100", "XBT/USD"]
[270, {"a": [["11668.80000", "0.01000000", "1596666803.961162"]], "c": "88077255"}, "book-100", "XBT/USD"]
[270, {"a": [["11674.50000", "0.00000000", "1596666803.961234"], ["11729.00000", "9.29631056", "1596665758.165359", "r"]], "c": "88077255"}, "book-100", "XBT/USD"]
[270, {"b": [["11654.60000", "0.00000000", "1596666803.963402"], ["11604.10000", "1.51500000", "1596666763.121463", "r"]], "c": "88077255"}, "book-100", "XBT/USD"]
[270, {"a": [["11674.40000", "1.38720850", "1596666803.976262"]], "c": "88077255"}, "book-100", "XBT/USD"]
[270, {"a": [["11663.90000", "0.21848030", "1596666803.993702"]], "c": "3230122951"}, "book-100", "XBT/USD"]
[270, {"a": [["11672.00000", "0.09700000", "1596666803.998573"]], "c": "3230122951"}, "book-100", "XBT/USD"]
[270, {"a": [["11664.20000", "0.58969395", "1596666804.006608"]], "c": "3517932483"}, "book-100", "XBT/USD"]
[270, {"a": [["11686.40000", "0.34871970", "1596666804.016009"]], "c": "3517932483"}, "book-100", "XBT/USD"]
[270, {"b": [["11645.40000", "6.10000000", "1596666804.021784"]], "c": "3517932483"}, "book-100", "XBT/USD"]
[270, {"a": [["11685.00000", "0.59671777", "1596666804.025151"]], "c": "3517932483"}, "book-100", "XBT/USD"]
[270, {"a": [["11673.20000", "1.97230682", "1596666804.025260"]], "c": "3517932483"}, "book-100", "XBT/USD"]
[270, {"b": [["11659.60000", "0.57230000", "1596666804.027784"]], "c": "1645143136"}, "book-100", "XBT/USD"]
[270, {"a": [["11663.90000", "0.00000000", "1596666804.027952"], ["11728.90000", "4.26297436", "1596666773.365922", "r"]], "c": "2610287371"}, "book-100", "XBT/USD"]
[270, {"a": [["11682.90000", "0.24916012", "1596666804.032800"]], "c": "2610287371"}, "book-100", "XBT/USD"]
[270, {"a": [["11697.50000", "10.19786236", "1596666804.043236"]], "c": "2610287371"}, "book-100", "XBT/USD"]
[270, {"a": [["11670.10000", "0.00000000", "1596666804.052839"], ["11728.00000", "2.99792678", "1596666801.269211", "r"]], "c": "420830601"}, "book-100", "XBT/USD"]
[270, {"b": [["11661.30000", "1.73200000", "1596666804.055536"]], "c": "3439069289"}, "book-100", "XBT/USD"]
[270, {"b": [["11661.30000", "2.23200000", "1596666804.057911"]], "c": "440399514"}, "book-100", "XBT/USD"]
[270, {"b": [["11645.10000", "0.00000000", "1596666804.062156"], ["11604.10000", "1.51500000", "1596666763.121463", "r"]], "c": "440399514"}, "book-100", "XBT/USD"]
[270, {"b": [["11661.30000", "2.73200000", "1596666804.064485"]], "c": "1159348017"}, "book-100", "XBT/USD"]
[270, {"b": [["11646.60000", "0.04221982", "1596666804.065030"]], "c": "1159348017"}, "book-100", "XBT/USD"]
[270, {"b": [["11657.10000", "0.00000000", "1596666804.075356"], ["11604.10000", "1.51500000", "1596666763.121463", "r"]], "c": "3189110791"}, "book-100", "XBT/USD"]
[270, {"a": [["11672.00000", "0.00000000", "1596666804.098466"], ["11728.90000", "4.26297436", "1596666773.365922", "r"]], "c": "3189110791"}, "book-100", "XBT/USD"]
[270, {"b": [["11646.50000", "0.00000000", "1596666804.099184"], ["11603.20000", "2.50039088", "1596666777.334144", "r"]], "c": "3189110791"}, "book-100", "XBT/USD"]
[270, {"a": [["11670.80000", "0.00000000", "1596666804.099778"], ["11729.00000", "9.29631056", "1596665758.165359", "r"]], "c": "3189110791"}, "book-100", "XBT/USD"]
[270, {"a": [["11666.30000", "0.00000000", "1596666804.100512"], ["11730.00000", "0.17085000", "1596666259.012402", "r"]], "c": "1387113656"}, "book-100", "XBT/USD"]
[270, {"a": [["11664.20000", "0.09621094", "1596666804.101036"]], "c": "954971596"}, "book-100", "XBT/USD"]
[270, {"a": [["11669.80000", "0.00000000", "1596666804.106996"], ["11731.20000", "0.01000000", "1596665559.440935", "r"]], "c": "970086864"}, "book-100", "XBT/USD"]
[270, {"a": [["11664.20000", "0.00000000", "1596666804.110940"], ["11732.30000", "19.70000000", "1596666762.007788", "r"]], "c": "3892638395"}, "book-100", "XBT/USD"]
[270, {"a": [["11687.10000", "2.00375648", "1596666804.124098"]], "c": "3892638395"}, "book-100", "XBT/USD"]
[270, {"a": [["11673.80000", "0.85714932", "1596666804.132466"]], "c": "3892638395"}, "book-100", "XBT/USD"]
[270, {"a": [["11674.40000", "1.38369910", "1596666804.143603"]], "c": "3892638395"}, "book-100", "XBT/USD"]
[270, {"a": [["11677.10000", "0.11168090", "1596666804.149121"]], "c": "3892638395"}, "book-100", "XBT/USD"]
[270, {"a": [["11673.10000", "0.75551922", "1596666804.153814"]], "c": "407706431"}, "book-100", "XBT/USD"]
[270, {"b": [["11649.40000", "0.00000000", "1596666804.159148"], ["11602.60000", "1.48021868", "1596666784.125874", "r"]], "c": "407706431"}, "book-100", "XBT/USD"]
[270, {"a": [["11677.80000", "0.05313798", "1596666804.162905"]], "c": "407706431"}, "book-100", "XBT/USD"]
[270, {"a": [["11677.30000", "0.78878000", "1596666804.164471"]], "c": "407706431"}, "book-100", "XBT/USD"]
[270, {"a": [["11670.50000", "0.00000000", "1596666804.167886"], ["11728.90000", "4.26297436", "1596666773.365922", "r"]], "c": "742530829"}, "book-100", "XBT/USD"]
[270, {"a": [["11672.50000", "0.86059682", "1596666804.169229"]], "c": "3838510442"}, "book-100", "XBT/USD"]
[270, {"a": [["11667.70000", "0.00000000", "1596666804.171606"], ["11728.90000", "4.26297436", "1596666773.365922", "r"]], "c": "4176095283"}, "book-100", "XBT/USD"]
[270, {"b": [["11661.30000", "3.31917546", "1596666804.174454"]], "c": "1083375378"}, "book-100", "XBT/USD"]
[270, {"a": [["11669.40000", "0.43966375", "1596666804.191984"]], "c": "409006554"}, "book-100", "XBT/USD"]
[270, {"a": [["11668.70000", "0.04250000", "1596666804.194360"]], "c": "3270262747"}, "book-100", "XBT/USD"]
[270, {"b": [["11659.30000", "0.04250000", "1596666804.196821"]], "c": "1001363523"}, "book-100", "XBT/USD"]
[270, {"b": [["11656.30000", "0.00000000", "1596666804.206943"], ["11602.60000", "1.48021868", "1596666784.125874", "r"]], "c": "1001363523"}, "book-100", "XBT/USD"]
[270, {"a": [["11674.40000", "0.47434910", "1596666804.223571"]], "c": "1001363523"}, "book-100", "XBT/USD"]
[270, {"a": [["11668.70000", "0.30090333", "1596666804.228260"]], "c": "3269344206"}, "book-100", "XBT/USD"]
[270, {"a": [["11672.70000", "0.33295341", "1596666804.228925"]], "c": "3960052346"}, "book-100", "XBT/USD"]
[270, {"b": [["11656.90000", "3.37648415", "1596666804.255989"]], "c": "3960052346"}, "book-100", "XBT/USD"]
[270, {"a": [["11681.60000", "1.42070308", "1596666804.270973"]], "c": "3960052346"}, "book-100", "XBT/USD"]
[270, {"a": [["11670.60000", "0.41352978", "1596666804.277019"]], "c": "425508963"}, "book-100", "XBT/USD"]
[270, {"a": [["11672.00000", "1.00000000", "1596666804.278784"]], "c": "2674518310"}, "book-100", "XBT/USD"]
[270, {"a": [["11675.80000", "0.33843067", "1596666804.278867"]], "c": "2674518310"}, "book-100", "XBT/USD"]
[270, {"a": [["11681.20000", "0.92461023", "1596666804.282908"]], "c": "2674518310"}, "book-100", "XBT/USD"]
[270, {"a": [["11681.40000", "0.72317043", "1596666804.295550"]], "c": "2674518310"}, "book-100", "XBT/USD"]
[270, {"a": [["11679.10000", "0.10333041", "1596666804.296612"]], "c": "2674518310"}, "book-100", "XBT/USD"]
[270, {"a": [["11687.20000", "1.95735507", "1596666804.298417"]], "c": "2674518310"}, "book-100", "XBT/USD"]
[270, {"a": [["11680.30000", "0.00000000", "1596666804.304192"], ["11722.20000", "3.01549629", "1596666746.821117", "r"]], "c": "2674518310"}, "book-100", "XBT/USD"]
[270, {"a": [["11673.10000", "0.00000000", "1596666804.308643"], ["11725.40000", "1.99666304", "1596666743.823724", "r"]], "c": "2674518310"}, "book-100", "XBT/USD"]
[270, {"a": [["11711.20000", "0.00000000", "1596666804.310262"], ["11725.50000", "1.06000000", "1596666771.224459", "r"]], "c": "2674518310"}, "book-100", "XBT/USD"]
[270, {"a": [["11675.40000", "0.00000000", "1596666804.324086"], ["11726.30000", "1.78600000", "1596666787.006488", "r"]], "c": "2674518310"}, "book-100", "XBT/USD"]
[270, {"b": [["11640.30000", "0.00000000", "1596666804.324370"], ["11602.60000", "1.48021868", "1596666784.125874", "r"]], "c": "2674518310"}, "book-100", "XBT/USD"]
[270, {"a": [["11681.20000", "1.94541023", "1596666804.329920"]], "c": "2674518310"}, "book-100", "XBT/USD"]
[270, {"b": [["11646.00000", "0.96390000", "1596666804.330961"]], "c": "2674518310"}, "book-100", "XBT/USD"]
[270, {"a": [["11677.10000", "0.00000000", "1596666804.331582"], ["11726.60000", "0.00700000", "1596666737.891214", "r"]], "c": "2674518310"}, "book-100", "XBT/USD"]
[270, {"a": [["11697.90000", "0.00000000", "1596666804.334298"], ["11727.00000", "0.17085000", "1596665935.290778", "r"]], "c": "2674518310"}, "book-100", "XBT/USD"]
[270, {"a": [["11713.70000", "0.30235286", "1596666804.365232"]], "c": "2674518310"}, "book-100", "XBT/USD"]
[270, {"b": [["11650.90000", "0.04420000", "1596666804.385291"]], "c": "2674518310"}, "book-100", "XBT/USD"]
[270, {"a": [["11670.30000", "1.50000000", "1596666804.392859"]], "c": "930879313"}, "book-100", "XBT/USD"]
[270, {"a": [["11668.70000", "0.04250000", "1596666804.392940"]], "c": "2760677743"}, "book-100", "XBT/USD"]
[270, {"a": [["11701.40000", "0.00000000", "1596666804.418988"], ["11726.60000", "0.00700000", "1596666737.891214", "r"]], "c": "2760677743"}, "book-100", "XBT/USD"]
[270, {"b": [["11660.60000", "0.45902833", "1596666804.442348"]], "c": "3798717499"}, "book-100", "XBT/USD"]
[270, {"a": [["11678.20000", "0.71594945", "1596666804.444736"]], "c": "3798717499"}, "book-100", "XBT/USD"]
[270, {"b": [["11650.20000", "0.00000000", "1596666804.444792"], ["11603.20000", "2.50039088", "1596666777.334144", "r"]], "c": "3798717499"}, "book-100", "XBT/USD"]
[270, {"a": [["11675.20000", "0.00000000", "1596666804.454734"], ["11726.60000", "0.00700000", "1596666737.891214", "r"]], "c": "3798717499"}, "book-100", "XBT/USD"]
[270, {"a": [["11677.30000", "0.00000000", "1596666804.459327"], ["11727.00000", "0.17085000", "1596665935.290778", "r"]], "c": "3798717499"}, "book-100", "XBT/USD"]
[270, {"a": [["11680.50000", "0.38000000", "1596666804.462895"]], "c": "3798717499"}, "book-100", "XBT/USD"]
[270, {"b": [["11649.00000", "0.38000000", "1596666804.468270"]], "c": "3798717499"}, "book-100", "XBT/USD"]
[270, {"a": [["11680.90000", "0.71039411", "1596666804.472266"]], "c": "3798717499"}, "book-100", "XBT/USD"]
[270, {"a": [["11689.10000", "1.79164169", "1596666804.474818"]], "c": "3798717499"}, "book-100", "XBT/USD"]
[270, {"a": [["11675.80000", "0.00000000", "1596666804.479857"], ["11726.30000", "1.78600000", "1596666787.006488", "r"]], "c": "3798717499"}, "book-100", "XBT/USD"]
[270, {"b": [["11647.00000", "1.42492359", "1596666804.495021"]], "c": "3798717499"}, "book-100", "XBT/USD"]
[270, {"a": [["11661.40000", "0.00000000", "1596666804.495668"], ["11726.60000", "0.00700000", "1596666737.891214", "r"]], "c": "3282602333"}, "book-100", "XBT/USD"]
[270, {"a": [["11669.40000", "0.00000000", "1596666804.507476"], ["11727.00000", "0.17085000", "1596665935.290778", "r"]], "c": "1161895978"}, "book-100", "XBT/USD"]
[270, {"a": [["11672.70000", "0.55436772", "1596666804.524350"]], "c": "1161895978"}, "book-100", "XBT/USD"]
[270, {"b": [["11648.70000", "0.00444030", "1596666804.524707"]], "c": "1161895978"}, "book-100", "XBT/USD"]
[270, {"b": [["11609.90000", "0.01286300", "1596666804.525088"]], "c": "1161895978"}, "book-100", "XBT/USD"]
[270, {"a": [["11686.00000", "0.00438186", "1596666804.525154"]], "c": "1161895978"}, "book-100", "XBT/USD"]
[270, {"a": [["11681.60000", "0.00000000", "1596666804.526247"], ["11727.00000", "0.17085000", "1596665935.290778", "r"]], "c": "1161895978"}, "book-100", "XBT/USD"]
[270, {"a": [["11725.30000", "0.01286300", "1596666804.528425"]], "c": "1161895978"}, "book-100", "XBT/USD"]
[270, {"a": [["11668.70000", "0.00000000", "1596666804.529272"], ["11727.00000", "0.17085000", "1596665935.290778", "r"]], "c": "2001473565"}, "book-100", "XBT/USD"]
[270, {"b": [["11659.30000", "0.00000000", "1596666804.531609"], ["11607.70000", "8.40000000", "1596666777.775135", "r"]], "c": "4207262935"}, "book-100", "XBT/USD"]
[270, {"a": [["11684.60000", "4.42814670", "1596666804.534421"]], "c": "4207262935"}, "book-100", "XBT/USD"]
[270, {"a": [["11684.60000", "3.52979286", "1596666804.538133"]], "c": "4207262935"}, "book-100", "XBT/USD"]
[270, {"a": [["11670.30000", "0.00000000", "1596666804.543195"], ["11727.40000", "7.40000000", "1596666699.130230", "r"]], "c": "1647723592"}, "book-100", "XBT/USD"]
[270, {"a": [["11681.20000", "1.04653600", "1596666804.547916"]], "c": "1647723592"}, "book-100", "XBT/USD"]
[270, {"a": [["11685.60000", "0.00000000", "1596666804.553090"], ["11728.00000", "2.99792678", "1596666801.269211", "r"]], "c": "1647723592"}, "book-100", "XBT/USD"]
[270, {"b": [["11661.30000", "2.81917546", "1596666804.553163"]], "c": "17084318"}, "book-100", "XBT/USD"]
[270, {"b": [["11661.30000", "3.27917546", "1596666804.563421"]], "c": "1321004561"}, "book-100", "XBT/USD"]
[270, {"a": [["11684.60000", "0.00000000", "1596666804.566876"], ["11728.90000", "4.26297436", "1596666773.365922", "r"]], "c": "1321004561"}, "book-100", "XBT/USD"]
[270, {"b": [["11661.30000", "2.77917546", "1596666804.567619"]], "c": "1765487986"}, "book-100", "XBT/USD"]
[270, {"b": [["11652.60000", "0.00000000", "1596666804.567905"], ["11607.00000", "0.17085000", "1596666720.750083", "r"]], "c": "1765487986"}, "book-100", "XBT/USD"]
[270, {"a": [["11678.20000", "0.82763002", "1596666804.576709"]], "c": "1765487986"}, "book-100", "XBT/USD"]
[270, {"a": [["11673.80000", "0.00000000", "1596666804.593264"], ["11729.00000", "9.29631056", "1596665758.165359", "r"]], "c": "1765487986"}, "book-100", "XBT/USD"]
[270, {"a": [["11709.00000", "0.00000000", "1596666804.602586"], ["11730.00000", "0.17085000", "1596666259.012402", "r"]], "c": "1765487986"}, "book-100", "XBT/USD"]
[270, {"b": [["11660.70000", "0.09621094", "1596666804.613668"]], "c": "2537371670"}, "book-100", "XBT/USD"]
[270, {"a": [["11679.10000", "0.00000000", "1596666804.616570"], ["11731.20000", "0.01000000", "1596665559.440935", "r"]], "c": "2537371670"}, "book-100", "XBT/USD"]
[270, {"a": [["11671.90000", "0.75551922", "1596666804.652518"]], "c": "2278213113"}, "book-100", "XBT/USD"]
[270, {"b": [["11655.00000", "0.00000000", "1596666804.652756"], ["11607.00000", "0.17085000", "1596666720.750083", "r"]], "c": "2278213113"}, "book-100", "XBT/USD"]
[270, {"a": [["11693.50000", "0.00000000", "1596666804.653607"], ["11731.20000", "0.01000000", "1596665559.440935", "r"]], "c": "2278213113"}, "book-100", "XBT/USD"]
[270, {"b": [["11660.50000", "0.00000000", "1596666804.653895"], ["11604.10000", "1.51500000", "1596666763.121463", "r"]], "c": "3822180018"}, "book-100", "XBT/USD"]
[270, {"b": [["11663.50000", "0.50000000", "1596666804.654485"]], "c": "1506980797"}, "book-100", "XBT/USD"]
[270, {"a": [["11681.40000", "0.00000000", "1596666804.655914"], ["11732.30000", "19.70000000", "1596666762.007788", "r"]], "c": "1506980797"}, "book-100", "XBT/USD"]
[270, {"a": [["11677.90000", "0.00000000", "1596666804.656374"], ["11732.70000", "10.88860000", "1596666182.526075", "r"]], "c": "1506980797"}, "book-100", "XBT/USD"]
[270, {"a": [["11672.00000", "5.28100000", "1596666804.661625"]], "c": "2277827475"}, "book-100", "XBT/USD"]
[270, {"a": [["11684.20000", "0.84050000", "1596666804.664778"]], "c": "2277827475"}, "book-100", "XBT/USD"]
[270, {"a": [["11686.00000", "0.44338186", "1596666804.687523"]], "c": "2277827475"}, "book-100", "XBT/USD"]
[270, {"a": [["11678.20000", "0.11168057", "1596666804.689093"]], "c": "2277827475"}, "book-100", "XBT/USD"]
[270, {"a": [["11673.90000", "1.50000000", "1596666804.691122"]], "c": "2277827475"}, "book-100", "XBT/USD"]
[270, {"b": [["11664.40000", "0.10200000", "1596666804.692973"]], "c": "2556666798"}, "book-100", "XBT/USD"]
[270, {"a": [["11671.90000", "0.00000000", "1596666804.707902"], ["11732.30000", "19.70000000", "1596666762.007788", "r"]], "c": "2391666799"}, "book-100", "XBT/USD"]
[270, {"a": [["11672.70000", "1.04989469", "1596666804.712305"]], "c": "2110825181"}, "book-100", "XBT/USD"]
[270, {"b": [["11663.50000", "0.00000000", "1596666804.716381"], ["11607.00000", "0.17085000", "1596666720.750083", "r"]], "c": "1279732822"}, "book-100", "XBT/USD"]
[270, {"b": [["11661.30000", "2.37917546", "1596666804.717295"]], "c": "1190438569"}, "book-100", "XBT/USD"]
[270, {"b": [["11661.40000", "0.57230000", "1596666804.719103"]], "c": "818990606"}, "book-100", "XBT/USD"]
[270, {"a": [["11671.90000", "0.25830801", "1596666804.719285"]], "c": "2425351912"}, "book-100", "XBT/USD"]
[270, {"b": [["11661.30000", "1.87917546", "1596666804.726070"]], "c": "1823941624"}, "book-100", "XBT/USD"]
[270, {"a": [["11673.60000", "0.00000000", "1596666804.733845"], ["11732.30000", "19.70000000", "1596666762.007788", "r"]], "c": "1823941624"}, "book-100", "XBT/USD"]
[270, {"b": [["11660.60000", "0.00000000", "1596666804.746208"], ["11607.00000", "0.17085000", "1596666720.750083", "r"]], "c": "795787691"}, "book-100", "XBT/USD"]
[270, {"b": [["11661.30000", "2.91036546", "1596666804.753953"]], "c": "1014247105"}, "book-100", "XBT/USD"]
[270, {"a": [["11703.00000", "0.00000000", "1596666804.762638"], ["11732.70000", "10.88860000", "1596666182.526075", "r"]], "c": "1014247105"}, "book-100", "XBT/USD"]
[270, {"b": [["11659.60000", "0.00000000", "1596666804.763048"], ["11604.10000", "1.51500000", "1596666763.121463", "r"]], "c": "1926037701"}, "book-100", "XBT/USD"]
[270, {"a": [["11672.10000", "0.00000000", "1596666804.769215"], ["11733.00000", "7.57085000", "1596666755.121828", "r"]], "c": "1017338438"}, "book-100", "XBT/USD"]
[270, {"b": [["11656.60000", "0.00000000", "1596666804.770685"], ["11603.20000", "2.50039088", "1596666777.334144", "r"]], "c": "1017338438"}, "book-100", "XBT/USD"]
[270, {"b": [["11656.50000", "0.00000000", "1596666804.775174"], ["11602.60000", "1.48021868", "1596666784.125874", "r"]], "c": "1017338438"}, "book-100", "XBT/USD"]
[270, {"b": [["11654.80000", "0.00000000", "1596666804.775792"], ["11602.20000", "2.01681621", "1596666634.588713", "r"]], "c": "1017338438"}, "book-100", "XBT/USD"]
[270, {"b": [["11664.70000", "0.50000000", "1596666804.790369"]], "c": "301033169"}, "book-100", "XBT/USD"]
[270, {"a": [["11692.80000", "0.57258307", "1596666804.790448"]], "c": "301033169"}, "book-100", "XBT/USD"]
[270, {"a": [["11678.10000", "0.05313798", "1596666804.792681"]], "c": "301033169"}, "book-100", "XBT/USD"]
[270, {"b": [["11664.80000", "0.50000000", "1596666804.794360"]], "c": "2628255172"}, "book-100", "XBT/USD"]
[270, {"a": [["11677.80000", "0.00000000", "1596666804.796952"], ["11732.70000", "10.88860000", "1596666182.526075", "r"]], "c": "2628255172"}, "book-100", "XBT/USD"]
[270, {"a": [["11678.70000", "0.00000000", "1596666804.802755"], ["11733.00000", "7.57085000", "1596666755.121828", "r"]], "c": "2628255172"}, "book-100", "XBT/USD"]
[270, {"a": [["11686.40000", "0.00000000", "1596666804.803898"], ["11736.00000", "0.17085000", "1596666281.745758", "r"]], "c": "2628255172"}, "book-100", "XBT/USD"]
[270, {"a": [["11670.20000", "0.42450576", "1596666804.809052"]], "c": "3850314798"}, "book-100", "XBT/USD"]
[270, {"a": [["11684.20000", "0.00000000", "1596666804.815086"], ["11736.00000", "0.17085000", "1596666281.745758", "r"]], "c": "3850314798"}, "book-100", "XBT/USD"]
[270, {"a": [["11687.20000", "0.74922720", "1596666804.815870"]], "c": "3850314798"}, "book-100", "XBT/USD"]
[270, {"a": [["11672.00000", "1.00000000", "1596666804.817054"]], "c": "3605103558"}, "book-100", "XBT/USD"]
[270, {"a": [["11678.20000", "0.00000000", "1596666804.817259"], ["11737.90000", "6.10000000", "1596666760.752863", "r"]], "c": "3605103558"}, "book-100", "XBT/USD"]
[270, {"a": [["11694.00000", "7.06914346", "1596666804.820711"]], "c": "3605103558"}, "book-100", "XBT/USD"]
[270, {"a": [["11694.00000", "0.00000000", "1596666804.829345"], ["11739.00000", "0.17085000", "1596666453.706886", "r"]], "c": "3605103558"}, "book-100", "XBT/USD"]
[270, {"a": [["11685.00000", "0.10000000", "1596666804.835534"]], "c": "3605103558"}, "book-100", "XBT/USD"]
[270, {"a": [["11687.10000", "0.00000000", "1596666804.841106"], ["11741.00000", "3.94700000", "1596666780.723860", "r"]], "c": "3605103558"}, "book-100", "XBT/USD"]
[270, {"a": [["11682.90000", "0.00000000", "1596666804.841199"], ["11741.10000", "0.89396994", "1596666782.214899", "r"]], "c": "3605103558"}, "book-100", "XBT/USD"]
[270, {"a": [["11692.60000", "0.00000000", "1596666804.843935"], ["11741.90000", "2.96567007", "1596666781.600798", "r"]], "c": "3605103558"}, "book-100", "XBT/USD"]
[270, {"a": [["11680.90000", "0.00000000", "1596666804.845979"], ["11742.00000", "0.17085000", "1596666316.082825", "r"]], "c": "3605103558"}, "book-100", "XBT/USD"]
[270, {"b": [["11664.70000", "0.00000000", "1596666804.853766"], ["11602.60000", "1.48021868", "1596666784.125874", "r"]], "c": "1472439945"}, "book-100", "XBT/USD"]
[270, {"b": [["11654.50000", "0.00000000", "1596666804.861093"], ["11602.20000", "2.01681621", "1596666634.588713", "r"]], "c": "1472439945"}, "book-100", "XBT/USD"]
[270, {"a": [["11688.10000", "0.00000000", "1596666804.864055"], ["11742.20000", "3.51308009", "1596666781.747430", "r"]], "c": "1472439945"}, "book-100", "XBT/USD"]
[270, {"a": [["11674.60000", "0.09700000", "1596666804.872623"]], "c": "1472439945"}, "book-100", "XBT/USD"]
[270, {"b": [["11661.30000", "2.32319000", "1596666804.890654"]], "c": "563028710"}, "book-100", "XBT/USD"]
[270, {"b": [["11661.30000", "1.86319000", "1596666804.896354"]], "c": "2958977079"}, "book-100", "XBT/USD"]
[270, {"b": [["11664.40000", "0.87064000", "1596666804.900517"]], "c": "732684749"}, "book-100", "XBT/USD"]
[270, {"a": [["11691.60000", "0.00000000", "1596666804.912124"], ["11742.20000", "3.51308009", "1596666781.747430", "r"]], "c": "732684749"}, "book-100", "XBT/USD"]
[270, {"a": [["11690.50000", "3.52831387", "1596666804.916044"]], "c": "732684749"}, "book-100", "XBT/USD"]
[270, {"a": [["11679.50000", "0.50000000", "1596666804.916226"]], "c": "732684749"}, "book-100", "XBT/USD"]
[270, {"b": [["11661.30000", "1.43419000", "1596666804.918261"]], "c": "1636204907"}, "book-100", "XBT/USD"]
[270, {"b": [["11664.80000", "1.00000000", "1596666804.922561"]], "c": "975469826"}, "book-100", "XBT/USD"]
[270, {"b": [["11644.60000", "0.00000000", "1596666804.926467"], ["11602.10000", "11.25550194", "1596666780.609892", "r"]], "c": "975469826"}, "book-100", "XBT/USD"]
[270, {"b": [["11664.80000", "1.00800000", "1596666804.936882"]], "c": "40401791"}, "book-100", "XBT/USD"]
[270, {"b": [["11660.30000", "3.34383211", "1596666804.937038"]], "c": "3950820996"}, "book-100", "XBT/USD"]
[270, {"a": [["11674.40000", "0.00000000", "1596666804.938500"], ["11742.20000", "3.51308009", "1596666781.747430", "r"]], "c": "3950820996"}, "book-100", "XBT/USD"]
[270, {"b": [["11661.40000", "1.04375329", "1596666804.938614"]], "c": "1989423515"}, "book-100", "XBT/USD"]
[270, {"a": [["11692.50000", "0.89800553", "1596666804.939124"]], "c": "1989423515"}, "book-100", "XBT/USD"]
[270, {"a": [["11684.40000", "0.89862806", "1596666804.940788"]], "c": "1989423515"}, "book-100", "XBT/USD"]
[270, {"a": [["11682.20000", "0.71474013", "1596666804.941699"]], "c": "1989423515"}, "book-100", "XBT/USD"]
[270, {"b": [["11656.20000", "0.43900000", "1596666804.941956"]], "c": "1989423515"}, "book-100", "XBT/USD"]
[270, {"a": [["11687.30000", "1.64160000", "1596666804.962990"]], "c": "1989423515"}, "book-100", "XBT/USD"]
[270, {"a": [["11671.90000", "0.00000000", "1596666805.003765"], ["11741.10000", "0.89396994", "1596666782.214899", "r"]], "c": "943274306"}, "book-100", "XBT/USD"]
[270, {"a": [["11686.70000", "0.49668195", "1596666805.009261"]], "c": "943274306"}, "book-100", "XBT/USD"]
[270, {"a": [["11673.90000", "0.00000000", "1596666805.023468"], ["11741.10000", "0.89396994", "1596666782.214899", "r"]], "c": "943274306"}, "book-100", "XBT/USD"]
[270, {"b": [["11661.50000", "0.57230000", "1596666805.024919"]], "c": "2621477040"}, "book-100", "XBT/USD"]
[270, {"a": [["11678.10000", "0.00000000", "1596666805.043221"], ["11741.90000", "2.96567007", "1596666781.600798", "r"]], "c": "2621477040"}, "book-100", "XBT/USD"]
[270, {"a": [["11678.70000", "0.00641455", "1596666805.045561"]], "c": "2621477040"}, "book-100", "XBT/USD"]
[270, {"b": [["11661.40000", "0.47145329", "1596666805.067997"]], "c": "1276151865"}, "book-100", "XBT/USD"]
[270, {"a": [["11679.50000", "0.00000000", "1596666805.090028"], ["11741.90000", "2.96567007", "1596666781.600798", "r"]], "c": "1276151865"}, "book-100", "XBT/USD"]
[270, {"b": [["11656.90000", "0.00000000", "1596666805.091635"], ["11602.60000", "1.48021868", "1596666784.125874", "r"]], "c": "1276151865"}, "book-100", "XBT/USD"]
[270, {"b": [["11657.50000", "1.00000000", "1596666805.092970"]], "c": "1276151865"}, "book-100", "XBT/USD"]
[270, {"a": [["11693.60000", "0.50000000", "1596666805.099731"]], "c": "1276151865"}, "book-100", "XBT/USD"]
[270, {"b": [["11641.20000", "2.00000000", "1596666805.101961"]], "c": "1276151865"}, "book-100", "XBT/USD"]
[270, {"b": [["11658.00000", "0.00000000", "1596666805.116314"], ["11603.20000", "2.50039088", "1596666777.334144", "r"]], "c": "1276151865"}, "book-100", "XBT/USD"]
[270, {"b": [["11653.20000", "0.00000000", "1596666805.117370"], ["11602.60000", "1.48021868", "1596666784.125874", "r"]], "c": "1276151865"}, "book-100", "XBT/USD"]
[270, {"a": [["11670.60000", "0.00000000", "1596666805.117428"], ["11741.90000", "2.96567007", "1596666781.600798", "r"]], "c": "3712668774"}, "book-100", "XBT/USD"]
[270, {"b": [["11649.40000", "0.71231502", "1596666805.118024"]], "c": "3712668774"}, "book-100", "XBT/USD"]
[270, {"a": [["11679.30000", "0.00000000", "1596666805.126575"], ["11742.00000", "0.17085000", "1596666316.082825", "r"]], "c": "3712668774"}, "book-100", "XBT/USD"]
[270, {"a": [["11680.50000", "1.21048000", "1596666805.127774"]], "c": "3712668774"}, "book-100", "XBT/USD"]
[270, {"a": [["11684.70000", "0.89860499", "1596666805.128204"]], "c": "3712668774"}, "book-100", "XBT/USD"]
[270, {"a": [["11693.20000", "0.02825988", "1596666805.132859"]], "c": "3712668774"}, "book-100", "XBT/USD"]
[270, {"b": [["11661.40000", "4.74645329", "1596666805.133068"]], "c": "1194295185"}, "book-100", "XBT/USD"]
[270, {"a": [["11692.60000", "0.99286265", "1596666805.137914"]], "c": "1194295185"}, "book-100", "XBT/USD"]
[270, {"a": [["11684.40000", "0.00000000", "1596666805.140009"], ["11741.10000", "0.89396994", "1596666782.214899", "r"]], "c": "1194295185"}, "book-100", "XBT/USD"]
[270, {"b": [["11655.60000", "0.00000000", "1596666805.141965"], ["11602.60000", "1.48021868", "1596666784.125874", "r"]], "c": "1194295185"}, "book-100", "XBT/USD"]
[270, {"a": [["11672.50000", "0.95680776", "1596666805.142847"]], "c": "1304465861"}, "book-100", "XBT/USD"]
[270, {"a": [["11680.50000", "0.38000000", "1596666805.146648"]], "c": "1304465861"}, "book-100", "XBT/USD"]
[270, {"a": [["11694.20000", "4.31019992", "1596666805.157825"]], "c": "1304465861"}, "book-100", "XBT/USD"]
[270, {"a": [["11700.10000", "2.00153010", "1596666805.160785"]], "c": "1304465861"}, "book-100", "XBT/USD"]
[270, {"a": [["11676.30000", "1.50000000", "1596666805.172643"]], "c": "1304465861"}, "book-100", "XBT/USD"]
[270, {"a": [["11682.20000", "0.00000000", "1596666805.192148"], ["11741.00000", "3.94700000", "1596666780.723860", "r"]], "c": "1304465861"}, "book-100", "XBT/USD"]
[270, {"a": [["11683.60000", "0.69927058", "1596666805.195480"]], "c": "1304465861"}, "book-100", "XBT/USD"]
[270, {"b": [["11664.80000", "1.60074596", "1596666805.206457"]], "c": "3858155836"}, "book-100", "XBT/USD"]
[270, {"a": [["11686.00000", "0.43900000", "1596666805.207634"]], "c": "3858155836"}, "book-100", "XBT/USD"]
[270, {"a": [["11673.90000", "0.25827470", "1596666805.214198"]], "c": "4017487905"}, "book-100", "XBT/USD"]
[270, {"a": [["11672.00000", "0.00000000", "1596666805.241865"], ["11739.00000", "0.17085000", "1596666453.706886", "r"]], "c": "571488388"}, "book-100", "XBT/USD"]
[270, {"b": [["11646.60000", "0.00000000", "1596666805.244719"], ["11602.20000", "2.01681621", "1596666634.588713", "r"]], "c": "571488388"}, "book-100", "XBT/USD"]
[270, {"b": [["11649.20000", "0.04221040", "1596666805.246557"]], "c": "571488388"}, "book-100", "XBT/USD"]
[270, {"b": [["11661.40000", "4.27500000", "1596666805.258596"]], "c": "2903896110"}, "book-100", "XBT/USD"]
[270, {"a": [["11678.70000", "0.46890328", "1596666805.260862"]], "c": "2903896110"}, "book-100", "XBT/USD"]
[270, {"b": [["11659.70000", "0.10000000", "1596666805.277999"]], "c": "1849196699"}, "book-100", "XBT/USD"]
[270, {"a": [["11678.70000", "0.46248873", "1596666805.282813"]], "c": "1849196699"}, "book-100", "XBT/USD"]
[270, {"a": [["11680.40000", "0.02539323", "1596666805.284061"]], "c": "1849196699"}, "book-100", "XBT/USD"]
[270, {"b": [["11664.80000", "1.90074596", "1596666805.303054"]], "c": "1150568175"}, "book-100", "XBT/USD"]
[270, {"a": [["11682.10000", "0.11167940", "1596666805.304301"]], "c": "1150568175"}, "book-100", "XBT/USD"]
[270, {"a": [["11670.70000", "0.00000000", "1596666805.307460"], ["11737.90000", "6.10000000", "1596666760.752863", "r"]], "c": "474442857"}, "book-100", "XBT/USD"]
[270, {"a": [["11673.90000", "0.67180448", "1596666805.313019"]], "c": "2610640233"}, "book-100", "XBT/USD"]
[270, {"a": [["11684.70000", "0.00000000", "1596666805.316857"], ["11739.00000", "0.17085000", "1596666453.706886", "r"]], "c": "2610640233"}, "book-100", "XBT/USD"]
[270, {"a": [["11676.30000", "0.00000000", "1596666805.317862"], ["11741.00000", "3.94700000", "1596666780.723860", "r"]], "c": "2610640233"}, "book-100", "XBT/USD"]
[270, {"b": [["11661.60000", "1.00000000", "1596666805.329400"]], "c": "992551552"}, "book-100", "XBT/USD"]
[270, {"a": [["11697.50000", "0.00000000", "1596666805.337335"], ["11741.10000", "0.89396994", "1596666782.214899", "r"]], "c": "992551552"}, "book-100", "XBT/USD"]
[270, {"a": [["11680.80000", "0.50000000", "1596666805.351187"]], "c": "992551552"}, "book-100", "XBT/USD"]
[270, {"a": [["11677.30000", "2.07662955", "1596666805.355519"]], "c": "992551552"}, "book-100", "XBT/USD"]
[270, {"a": [["11677.60000", "0.70560000", "1596666805.373503"]], "c": "992551552"}, "book-100", "XBT/USD"]
[270, {"b": [["11648.70000", "0.00000000", "1596666805.394138"], ["11603.20000", "2.50039088", "1596666777.334144", "r"]], "c": "992551552"}, "book-100", "XBT/USD"]
[270, {"b": [["11651.10000", "1.53253397", "1596666805.417680"]], "c": "992551552"}, "book-100", "XBT/USD"]
[270, {"b": [["11643.50000", "0.00000000", "1596666805.419139"], ["11603.20000", "2.50039088", "1596666777.334144", "r"]], "c": "992551552"}, "book-100", "XBT/USD"]
[270, {"a": [["11718.00000", "0.00000000", "1596666805.440299"], ["11739.00000", "0.17085000", "1596666453.706886", "r"]], "c": "992551552"}, "book-100", "XBT/USD"]
[270, {"b": [["11661.50000", "1.03598437", "1596666805.444537"]], "c": "2671748475"}, "book-100", "XBT/USD"]
[270, {"b": [["11661.40000", "0.00000000", "1596666805.453561"], ["11602.60000", "1.48021868", "1596666784.125874", "r"]], "c": "4108010859"}, "book-100", "XBT/USD"]
[270, {"b": [["11664.80000", "6.18074596", "1596666805.458735"]], "c": "464972335"}, "book-100", "XBT/USD"]
[270, {"a": [["11678.20000", "1.50000000", "1596666805.465538"]], "c": "464972335"}, "book-100", "XBT/USD"]
[270, {"a": [["11674.90000", "4.27400000", "1596666805.479212"]], "c": "464972335"}, "book-100", "XBT/USD"]
[270, {"b": [["11643.80000", "0.00000000", "1596666805.495137"], ["11602.20000", "2.01681621", "1596666634.588713", "r"]], "c": "464972335"}, "book-100", "XBT/USD"]
[270, {"a": [["11673.20000", "0.00000000", "1596666805.498011"], ["11737.90000", "6.10000000", "1596666760.752863", "r"]], "c": "3978649282"}, "book-100", "XBT/USD"]
[270, {"b": [["11664.80000", "6.43074596", "1596666805.525396"]], "c": "2031368875"}, "book-100", "XBT/USD"]
[270, {"a": [["11680.40000", "0.00000000", "1596666805.532213"], ["11739.00000", "0.17085000", "1596666453.706886", "r"]], "c": "2031368875"}, "book-100", "XBT/USD"]
[270, {"a": [["11680.10000", "0.00939368", "1596666805.539884"]], "c": "2031368875"}, "book-100", "XBT/USD"]
[270, {"b": [["11664.80000", "6.51647359", "1596666805.540283"]], "c": "1306420742"}, "book-100", "XBT/USD"]
[270, {"b": [["11651.80000", "0.04220098", "1596666805.549210"]], "c": "1306420742"}, "book-100", "XBT/USD"]
[270, {"a": [["11673.90000", "0.25827470", "1596666805.598674"]], "c": "1903503529"}, "book-100", "XBT/USD"]
[270, {"a": [["11721.00000", "0.80800000", "1596666805.599144"]], "c": "1903503529"}, "book-100", "XBT/USD"]
[270, {"b": [["11664.80000", "16.51634362", "1596666805.664622"]], "c": "763444683"}, "book-100", "XBT/USD"]
[270, {"a": [["11693.60000", "3.69589013", "1596666805.668354"]], "c": "763444683"}, "book-100", "XBT/USD"]
[270, {"b": [["11664.80000", "16.26634362", "1596666805.686488"]], "c": "3428847422"}, "book-100", "XBT/USD"]
[270, {"b": [["11664.80000", "16.72634362", "1596666805.730068"]], "c": "1929227555"}, "book-100", "XBT/USD"]
[270, {"a": [["11673.00000", "0.41352978", "1596666805.750881"]], "c": "1109062483"}, "book-100", "XBT/USD"]
[270, {"a": [["11672.50000", "0.86059682", "1596666805.770176"]], "c": "3989448355"}, "book-100", "XBT/USD"]
[270, {"a": [["11708.70000", "0.30000000", "1596666805.810173"]], "c": "3989448355"}, "book-100", "XBT/USD"]
[270, {"a": [["11674.00000", "0.00000000", "1596666805.814881"], ["11736.00000", "0.17085000", "1596666281.745758", "r"]], "c": "3415411084"}, "book-100", "XBT/USD"]
[270, {"a": [["11680.40000", "0.02539323", "1596666805.815276"]], "c": "3415411084"}, "book-100", "XBT/USD"]
[270, {"a": [["11677.70000", "0.10300000", "1596666805.823106"]], "c": "3415411084"}, "book-100", "XBT/USD"]
[270, {"a": [["11674.80000", "0.75551922", "1596666805.829684"]], "c": "2984757515"}, "book-100", "XBT/USD"]
[270, {"b": [["11651.10000", "1.98098934", "1596666805.842083"]], "c": "2984757515"}, "book-100", "XBT/USD"]
[270, {"b": [["11664.80000", "17.22634362", "1596666805.850248"]], "c": "3932599810"}, "book-100", "XBT/USD"]
[270, {"a": [["11673.00000", "0.00000000", "1596666805.885549"], ["11732.70000", "10.88860000", "1596666182.526075", "r"]], "c": "2960645393"}, "book-100", "XBT/USD"]
[270, {"a": [["11689.20000", "0.00000000", "1596666805.887497"], ["11733.00000", "7.57085000", "1596666755.121828", "r"]], "c": "2960645393"}, "book-100", "XBT/USD"]
[270, {"a": [["11680.80000", "0.00000000", "1596666805.917335"], ["11736.00000", "0.17085000", "1596666281.745758", "r"]], "c": "2960645393"}, "book-100", "XBT/USD"]
[270, {"a": [["11693.60000", "3.19589013", "1596666805.923169"]], "c": "2960645393"}, "book-100", "XBT/USD"]
[270, {"a": [["11686.10000", "6.64909189", "1596666805.943063"]], "c": "2960645393"}, "book-100", "XBT/USD"]
[270, {"a": [["11701.90000", "1.48811037", "1596666805.943268"]], "c": "2960645393"}, "book-100", "XBT/USD"]
[270, {"b": [["11664.80000", "17.64914521", "1596666805.945219"]], "c": "1369378130"}, "book-100", "XBT/USD"]
[270, {"a": [["11680.50000", "0.00000000", "1596666805.946982"], ["11736.00000", "0.17085000", "1596666281.745758", "r"]], "c": "1369378130"}, "book-100", "XBT/USD"]
[270, {"a": [["11684.30000", "0.63700717", "1596666805.947406"]], "c": "1369378130"}, "book-100", "XBT/USD"]
[270, {"b": [["11664.40000", "0.76864000", "1596666805.948790"]], "c": "3698688047"}, "book-100", "XBT/USD"]
[270, {"a": [["11693.90000", "3.52728801", "1596666805.953645"]], "c": "3698688047"}, "book-100", "XBT/USD"]
[270, {"a": [["11702.40000", "10.19786497", "1596666805.960045"]], "c": "3698688047"}, "book-100", "XBT/USD"]
[270, {"a": [["11686.70000", "0.00000000", "1596666805.969113"], ["11732.70000", "10.88860000", "1596666182.526075", "r"]], "c": "3698688047"}, "book-100", "XBT/USD"]
[270, {"a": [["11701.00000", "0.00000000", "1596666805.981153"], ["11733.00000", "7.57085000", "1596666755.121828", "r"]], "c": "3698688047"}, "book-100", "XBT/USD"]
[270, {"b": [["11627.10000", "0.75800000", "1596666805.982048"]], "c": "3698688047"}, "book-100", "XBT/USD"]
[270, {"a": [["11708.00000", "7.06128545", "1596666805.984669"]], "c": "3698688047"}, "book-100", "XBT/USD"]
[270, {"a": [["11689.50000", "0.50000000", "1596666806.001512"]], "c": "3698688047"}, "book-100", "XBT/USD"]
[270, {"a": [["11689.10000", "0.00000000", "1596666806.005190"], ["11732.70000", "10.88860000", "1596666182.526075", "r"]], "c": "3698688047"}, "book-100", "XBT/USD"]
[270, {"a": [["11682.10000", "0.00000000", "1596666806.059176"], ["11733.00000", "7.57085000", "1596666755.121828", "r"]], "c": "3698688047"}, "book-100", "XBT/USD"]
[270, {"a": [["11680.40000", "0.00000000", "1596666806.136146"], ["11736.00000", "0.17085000", "1596666281.745758", "r"]], "c": "3698688047"}, "book-100", "XBT/USD"]
[270, {"a": [["11674.00000", "0.41352978", "1596666806.147952"]], "c": "2291544704"}, "book-100", "XBT/USD"]
[270, {"a": [["11676.80000", "0.64262282", "1596666806.224498"]], "c": "2291544704"}, "book-100", "XBT/USD"]
[270, {"a": [["11679.20000", "0.85745244", "1596666806.226008"]], "c": "2291544704"}, "book-100", "XBT/USD"]
[270, {"a": [["11679.80000", "0.64248788", "1596666806.226329"]], "c": "2291544704"}, "book-100", "XBT/USD"]
[270, {"a": [["11680.30000", "0.85734812", "1596666806.226498"]], "c": "2291544704"}, "book-100", "XBT/USD"]
[270, {"b": [["11664.20000", "0.85676324", "1596666806.226868"]], "c": "3407105236"}, "book-100", "XBT/USD"]
[270, {"a": [["11677.70000", "0.74557243", "1596666806.227141"]], "c": "3407105236"}, "book-100", "XBT/USD"]
[270, {"b": [["11663.10000", "0.64262282", "1596666806.228242"]], "c": "1835955338"}, "book-100", "XBT/USD"]
[270, {"a": [["11686.90000", "0.85693171", "1596666806.235908"]], "c": "1835955338"}, "book-100", "XBT/USD"]
[270, {"a": [["11688.70000", "1.15683042", "1596666806.236051"]], "c": "1835955338"}, "book-100", "XBT/USD"]
[270, {"a": [["11683.40000", "0.85711766", "1596666806.247950"]], "c": "1835955338"}, "book-100", "XBT/USD"]
[270, {"a": [["11684.50000", "0.85711766", "1596666806.249045"]], "c": "1835955338"}, "book-100", "XBT/USD"]
[270, {"b": [["11662.90000", "0.64262282", "1596666806.252699"]], "c": "551060069"}, "book-100", "XBT/USD"]
[270, {"b": [["11660.40000", "0.85711766", "1596666806.258500"]], "c": "2281250665"}, "book-100", "XBT/USD"]
[270, {"b": [["11660.30000", "4.20094977", "1596666806.278655"]], "c": "2281250665"}, "book-100", "XBT/USD"]
[270, {"b": [["11649.20000", "0.00000000", "1596666806.305371"], ["11607.70000", "8.40000000", "1596666777.775135", "r"]], "c": "2281250665"}, "book-100", "XBT/USD"]
[270, {"a": [["11674.90000", "0.00000000", "1596666806.315209"], ["11728.90000", "4.26297436", "1596666773.365922", "r"]], "c": "2281250665"}, "book-100", "XBT/USD"]
[270, {"a": [["11673.40000", "4.27500000", "1596666806.328264"]], "c": "2713018432"}, "book-100", "XBT/USD"]
[270, {"a": [["11696.40000", "7.06828854", "1596666806.329251"]], "c": "2713018432"}, "book-100", "XBT/USD"]
[270, {"b": [["11664.80000", "17.79914521", "1596666806.329463"]], "c": "2340234745"}, "book-100", "XBT/USD"]
[270, {"a": [["11686.10000", "6.40000000", "1596666806.331123"]], "c": "2340234745"}, "book-100", "XBT/USD"]
[270, {"b": [["11664.80000", "17.37634362", "1596666806.332022"]], "c": "529310908"}, "book-100", "XBT/USD"]
[270, {"b": [["11664.10000", "0.85676324", "1596666806.332742"]], "c": "1045655545"}, "book-100", "XBT/USD"]
[270, {"b": [["11659.80000", "0.85717205", "1596666806.333341"]], "c": "1045655545"}, "book-100", "XBT/USD"]
[270, {"b": [["11663.00000", "0.64262282", "1596666806.335625"]], "c": "1775830297"}, "book-100", "XBT/USD"]
[270, {"a": [["11680.10000", "0.00000000", "1596666806.337305"], ["11728.00000", "2.99792678", "1596666801.269211", "r"]], "c": "1775830297"}, "book-100", "XBT/USD"]
[270, {"a": [["11711.10000", "0.75800000", "1596666806.349295"]], "c": "1775830297"}, "book-100", "XBT/USD"]
[270, {"b": [["11663.30000", "0.85676324", "1596666806.360607"]], "c": "1370963734"}, "book-100", "XBT/USD"]
[270, {"a": [["11674.80000", "0.00000000", "1596666806.360769"], ["11728.00000", "2.99792678", "1596666801.269211", "r"]], "c": "1370963734"}, "book-100", "XBT/USD"]
[270, {"a": [["11713.70000", "0.00000000", "1596666806.371202"], ["11728.90000", "4.26297436", "1596666773.365922", "r"]], "c": "1370963734"}, "book-100", "XBT/USD"]
[270, {"b": [["11612.40000", "0.00000000", "1596666806.375636"], ["11609.90000", "0.01286300", "1596666804.525088", "r"]], "c": "1370963734"}, "book-100", "XBT/USD"]
[270, {"a": [["11719.80000", "0.30235286", "1596666806.428536"]], "c": "1370963734"}, "book-100", "XBT/USD"]
[270, {"a": [["11684.70000", "0.11167862", "1596666806.460724"]], "c": "1370963734"}, "book-100", "XBT/USD"]
[270, {"b": [["11654.40000", "0.38000000", "1596666806.466372"]], "c": "1370963734"}, "book-100", "XBT/USD"]
[270, {"a": [["11674.00000", "0.00000000", "1596666806.490021"], ["11728.00000", "2.99792678", "1596666801.269211", "r"]], "c": "812778800"}, "book-100", "XBT/USD"]
[270, {"a": [["11685.90000", "0.38000000", "1596666806.492326"]], "c": "812778800"}, "book-100", "XBT/USD"]
[270, {"b": [["11650.30000", "8.30000000", "1596666806.500491"]], "c": "812778800"}, "book-100", "XBT/USD"]
